{
    DataVersion: 3953,
    size: [12, 6, 10],
    data: [
        {pos: [0, 0, 3], state: "minecraft:deepslate_bricks"},
        {pos: [0, 0, 4], state: "minecraft:deepslate_bricks"},
        {pos: [1, 0, 2], state: "minecraft:cobbled_deepslate"},
        {pos: [1, 0, 3], state: "minecraft:cobbled_deepslate"},
        {pos: [1, 0, 4], state: "minecraft:deepslate_bricks"},
        {pos: [1, 0, 5], state: "minecraft:cobbled_deepslate"},
        {pos: [1, 0, 6], state: "minecraft:cobbled_deepslate"},
        {pos: [2, 0, 1], state: "minecraft:cobbled_deepslate"},
        {pos: [2, 0, 2], state: "minecraft:deepslate_bricks"},
        {pos: [2, 0, 3], state: "minecraft:deepslate_bricks"},
        {pos: [2, 0, 4], state: "minecraft:deepslate_bricks"},
        {pos: [2, 0, 5], state: "minecraft:deepslate_bricks"},
        {pos: [2, 0, 6], state: "minecraft:cobbled_deepslate"},
        {pos: [3, 0, 0], state: "minecraft:polished_deepslate"},
        {pos: [3, 0, 1], state: "minecraft:deepslate_bricks"},
        {pos: [3, 0, 2], state: "minecraft:deepslate_bricks"},
        {pos: [3, 0, 3], state: "minecraft:deepslate_bricks"},
        {pos: [3, 0, 4], state: "minecraft:deepslate_bricks"},
        {pos: [3, 0, 5], state: "minecraft:deepslate_bricks"},
        {pos: [3, 0, 6], state: "minecraft:deepslate_bricks"},
        {pos: [3, 0, 7], state: "minecraft:deepslate_bricks"},
        {pos: [4, 0, 1], state: "minecraft:cobbled_deepslate"},
        {pos: [4, 0, 2], state: "minecraft:cobbled_deepslate"},
        {pos: [4, 0, 3], state: "minecraft:deepslate_bricks"},
        {pos: [4, 0, 4], state: "minecraft:cobbled_deepslate"},
        {pos: [4, 0, 5], state: "minecraft:deepslate_bricks"},
        {pos: [4, 0, 6], state: "minecraft:deepslate_bricks"},
        {pos: [4, 0, 7], state: "minecraft:deepslate_bricks"},
        {pos: [5, 0, 3], state: "minecraft:polished_deepslate"},
        {pos: [5, 0, 4], state: "minecraft:cobbled_deepslate"},
        {pos: [5, 0, 5], state: "minecraft:cobbled_deepslate"},
        {pos: [5, 0, 6], state: "minecraft:deepslate_bricks"},
        {pos: [5, 0, 7], state: "minecraft:deepslate_bricks"},
        {pos: [6, 0, 2], state: "minecraft:cobbled_deepslate"},
        {pos: [6, 0, 3], state: "minecraft:cobbled_deepslate"},
        {pos: [6, 0, 4], state: "minecraft:cobbled_deepslate"},
        {pos: [6, 0, 5], state: "minecraft:cobbled_deepslate"},
        {pos: [6, 0, 6], state: "minecraft:cobbled_deepslate"},
        {pos: [6, 0, 7], state: "minecraft:deepslate_bricks"},
        {pos: [7, 0, 1], state: "minecraft:cobbled_deepslate"},
        {pos: [7, 0, 2], state: "minecraft:deepslate_bricks"},
        {pos: [7, 0, 3], state: "minecraft:deepslate_bricks"},
        {pos: [7, 0, 4], state: "minecraft:deepslate_bricks"},
        {pos: [7, 0, 5], state: "minecraft:magma_block"},
        {pos: [7, 0, 6], state: "minecraft:cobbled_deepslate"},
        {pos: [7, 0, 7], state: "minecraft:deepslate_bricks"},
        {pos: [7, 0, 8], state: "minecraft:deepslate_bricks"},
        {pos: [8, 0, 1], state: "minecraft:cobbled_deepslate"},
        {pos: [8, 0, 2], state: "minecraft:deepslate_bricks"},
        {pos: [8, 0, 3], state: "minecraft:deepslate_bricks"},
        {pos: [8, 0, 4], state: "minecraft:deepslate_bricks"},
        {pos: [8, 0, 5], state: "minecraft:deepslate_bricks"},
        {pos: [8, 0, 6], state: "minecraft:magma_block"},
        {pos: [8, 0, 7], state: "minecraft:cobbled_deepslate"},
        {pos: [8, 0, 8], state: "minecraft:deepslate_bricks"},
        {pos: [8, 0, 9], state: "minecraft:deepslate_bricks"},
        {pos: [9, 0, 3], state: "minecraft:deepslate_bricks"},
        {pos: [9, 0, 4], state: "minecraft:deepslate_bricks"},
        {pos: [9, 0, 5], state: "minecraft:cobbled_deepslate"},
        {pos: [9, 0, 6], state: "minecraft:cobbled_deepslate"},
        {pos: [9, 0, 7], state: "minecraft:deepslate_bricks"},
        {pos: [9, 0, 8], state: "minecraft:deepslate_bricks"},
        {pos: [9, 0, 9], state: "minecraft:deepslate_bricks"},
        {pos: [10, 0, 4], state: "minecraft:deepslate_bricks"},
        {pos: [10, 0, 5], state: "minecraft:deepslate_bricks"},
        {pos: [10, 0, 6], state: "minecraft:cobbled_deepslate"},
        {pos: [10, 0, 7], state: "minecraft:deepslate_bricks"},
        {pos: [10, 0, 8], state: "minecraft:deepslate_bricks"},
        {pos: [11, 0, 6], state: "minecraft:cobbled_deepslate"},
        {pos: [11, 0, 7], state: "minecraft:cobbled_deepslate"},
        {pos: [0, 1, 3], state: "minecraft:gravel"},
        {pos: [0, 1, 4], state: "minecraft:gravel"},
        {pos: [1, 1, 2], state: "minecraft:gravel"},
        {pos: [1, 1, 3], state: "minecraft:gravel"},
        {pos: [1, 1, 4], state: "minecraft:gravel"},
        {pos: [1, 1, 5], state: "minecraft:cobbled_deepslate"},
        {pos: [1, 1, 6], state: "minecraft:gravel"},
        {pos: [2, 1, 1], state: "minecraft:gravel"},
        {pos: [2, 1, 2], state: "minecraft:gravel"},
        {pos: [2, 1, 3], state: "minecraft:gravel"},
        {pos: [2, 1, 4], state: "minecraft:deepslate_bricks"},
        {pos: [2, 1, 5], state: "minecraft:deepslate_bricks"},
        {pos: [2, 1, 6], state: "minecraft:gravel"},
        {pos: [3, 1, 0], state: "minecraft:gravel"},
        {pos: [3, 1, 1], state: "minecraft:gravel"},
        {pos: [3, 1, 2], state: "minecraft:gravel"},
        {pos: [3, 1, 3], state: "minecraft:gravel"},
        {pos: [3, 1, 4], state: "minecraft:deepslate_bricks"},
        {pos: [3, 1, 5], state: "minecraft:deepslate_bricks"},
        {pos: [3, 1, 6], state: "minecraft:gravel"},
        {pos: [3, 1, 7], state: "minecraft:gravel"},
        {pos: [4, 1, 1], state: "minecraft:gravel"},
        {pos: [4, 1, 2], state: "minecraft:gravel"},
        {pos: [4, 1, 3], state: "minecraft:gravel"},
        {pos: [4, 1, 4], state: "minecraft:gravel"},
        {pos: [4, 1, 5], state: "minecraft:gravel"},
        {pos: [4, 1, 6], state: "minecraft:gravel"},
        {pos: [4, 1, 7], state: "minecraft:gravel"},
        {pos: [5, 1, 3], state: "minecraft:gravel"},
        {pos: [5, 1, 4], state: "minecraft:gravel"},
        {pos: [5, 1, 5], state: "minecraft:gravel"},
        {pos: [5, 1, 6], state: "minecraft:chipped_anvil{facing:south}"},
        {pos: [5, 1, 7], state: "minecraft:gravel"},
        {pos: [6, 1, 2], state: "minecraft:gravel"},
        {pos: [6, 1, 3], state: "minecraft:cobbled_deepslate"},
        {pos: [6, 1, 4], state: "minecraft:cobbled_deepslate"},
        {pos: [6, 1, 5], state: "minecraft:cobbled_deepslate"},
        {pos: [6, 1, 6], state: "minecraft:deepslate_bricks"},
        {pos: [6, 1, 7], state: "minecraft:deepslate_bricks"},
        {pos: [7, 1, 1], state: "minecraft:gravel"},
        {pos: [7, 1, 2], state: "minecraft:gravel"},
        {pos: [7, 1, 3], state: "minecraft:cobbled_deepslate"},
        {pos: [7, 1, 4], state: "minecraft:deepslate_bricks"},
        {pos: [7, 1, 5], state: "minecraft:gravel"},
        {pos: [7, 1, 6], state: "minecraft:gravel"},
        {pos: [7, 1, 7], state: "minecraft:deepslate_bricks"},
        {pos: [7, 1, 8], state: "minecraft:gravel"},
        {pos: [8, 1, 1], state: "minecraft:gravel"},
        {pos: [8, 1, 2], state: "minecraft:gravel"},
        {pos: [8, 1, 3], state: "minecraft:cobbled_deepslate"},
        {pos: [8, 1, 4], state: "minecraft:gravel"},
        {pos: [8, 1, 5], state: "minecraft:gravel"},
        {pos: [8, 1, 6], state: "minecraft:gravel"},
        {pos: [8, 1, 7], state: "minecraft:cobbled_deepslate"},
        {pos: [8, 1, 8], state: "minecraft:deepslate_bricks"},
        {pos: [8, 1, 9], state: "minecraft:gravel"},
        {pos: [9, 1, 3], state: "minecraft:cobbled_deepslate"},
        {pos: [9, 1, 4], state: "minecraft:cobbled_deepslate"},
        {pos: [9, 1, 5], state: "minecraft:cobbled_deepslate"},
        {pos: [9, 1, 6], state: "minecraft:cobbled_deepslate"},
        {pos: [9, 1, 7], state: "minecraft:deepslate_bricks"},
        {pos: [9, 1, 8], state: "minecraft:deepslate_bricks"},
        {pos: [9, 1, 9], state: "minecraft:gravel"},
        {pos: [10, 1, 4], state: "minecraft:gravel"},
        {pos: [10, 1, 5], state: "minecraft:gravel"},
        {pos: [10, 1, 6], state: "minecraft:gravel"},
        {pos: [10, 1, 7], state: "minecraft:gravel"},
        {pos: [10, 1, 8], state: "minecraft:gravel"},
        {pos: [11, 1, 6], state: "minecraft:gravel"},
        {pos: [11, 1, 7], state: "minecraft:gravel"},
        {pos: [0, 2, 4], state: "minecraft:gravel"},
        {pos: [1, 2, 3], state: "minecraft:gravel"},
        {pos: [1, 2, 4], state: "minecraft:gravel"},
        {pos: [1, 2, 5], state: "minecraft:gravel"},
        {pos: [1, 2, 6], state: "minecraft:gravel"},
        {pos: [2, 2, 2], state: "minecraft:gravel"},
        {pos: [2, 2, 3], state: "minecraft:gravel"},
        {pos: [2, 2, 4], state: "minecraft:deepslate_bricks"},
        {pos: [2, 2, 5], state: "minecraft:deepslate_bricks"},
        {pos: [2, 2, 6], state: "minecraft:gravel"},
        {pos: [3, 2, 2], state: "minecraft:gravel"},
        {pos: [3, 2, 3], state: "minecraft:gravel"},
        {pos: [3, 2, 4], state: "minecraft:cobbled_deepslate"},
        {pos: [3, 2, 5], state: "minecraft:gravel"},
        {pos: [3, 2, 6], state: "minecraft:gravel"},
        {pos: [3, 2, 7], state: "minecraft:gravel"},
        {pos: [4, 2, 3], state: "minecraft:gravel"},
        {pos: [4, 2, 4], state: "minecraft:gravel"},
        {pos: [4, 2, 5], state: "minecraft:gravel"},
        {pos: [4, 2, 6], state: "minecraft:gravel"},
        {pos: [4, 2, 7], state: "minecraft:gravel"},
        {pos: [5, 2, 4], state: "minecraft:gravel"},
        {pos: [5, 2, 5], state: "minecraft:gravel"},
        {pos: [5, 2, 6], state: "minecraft:gravel"},
        {pos: [5, 2, 7], state: "minecraft:gravel"},
        {pos: [6, 2, 3], state: "minecraft:gravel"},
        {pos: [6, 2, 4], state: "minecraft:gravel"},
        {pos: [6, 2, 5], state: "minecraft:gravel"},
        {pos: [6, 2, 6], state: "minecraft:gravel"},
        {pos: [6, 2, 7], state: "minecraft:gravel"},
        {pos: [7, 2, 1], state: "minecraft:gravel"},
        {pos: [7, 2, 2], state: "minecraft:gravel"},
        {pos: [7, 2, 3], state: "minecraft:gravel"},
        {pos: [7, 2, 4], state: "minecraft:gravel"},
        {pos: [7, 2, 5], state: "minecraft:gravel"},
        {pos: [7, 2, 6], state: "minecraft:gravel"},
        {pos: [7, 2, 7], state: "minecraft:gravel"},
        {pos: [7, 2, 8], state: "minecraft:gravel"},
        {pos: [8, 2, 2], state: "minecraft:gravel"},
        {pos: [8, 2, 3], state: "minecraft:gravel"},
        {pos: [8, 2, 4], state: "minecraft:gravel"},
        {pos: [8, 2, 5], state: "minecraft:gravel"},
        {pos: [8, 2, 6], state: "minecraft:gravel"},
        {pos: [8, 2, 7], state: "minecraft:cobbled_deepslate"},
        {pos: [8, 2, 8], state: "minecraft:cobbled_deepslate"},
        {pos: [8, 2, 9], state: "minecraft:gravel"},
        {pos: [9, 2, 3], state: "minecraft:gravel"},
        {pos: [9, 2, 4], state: "minecraft:gravel"},
        {pos: [9, 2, 5], state: "minecraft:gravel"},
        {pos: [9, 2, 6], state: "minecraft:gravel"},
        {pos: [9, 2, 7], state: "minecraft:deepslate_bricks"},
        {pos: [9, 2, 8], state: "minecraft:deepslate_bricks"},
        {pos: [9, 2, 9], state: "minecraft:gravel"},
        {pos: [10, 2, 4], state: "minecraft:gravel"},
        {pos: [10, 2, 5], state: "minecraft:gravel"},
        {pos: [10, 2, 6], state: "minecraft:gravel"},
        {pos: [10, 2, 7], state: "minecraft:gravel"},
        {pos: [10, 2, 8], state: "minecraft:gravel"},
        {pos: [11, 2, 6], state: "minecraft:gravel"},
        {pos: [11, 2, 7], state: "minecraft:gravel"},
        {pos: [0, 3, 4], state: "minecraft:gravel"},
        {pos: [1, 3, 4], state: "minecraft:gravel"},
        {pos: [1, 3, 5], state: "minecraft:gravel"},
        {pos: [1, 3, 6], state: "minecraft:gravel"},
        {pos: [2, 3, 3], state: "minecraft:gravel"},
        {pos: [2, 3, 4], state: "minecraft:deepslate_bricks"},
        {pos: [2, 3, 5], state: "minecraft:deepslate_bricks"},
        {pos: [2, 3, 6], state: "minecraft:gravel"},
        {pos: [3, 3, 3], state: "minecraft:gravel"},
        {pos: [3, 3, 4], state: "minecraft:gravel"},
        {pos: [3, 3, 5], state: "minecraft:gravel"},
        {pos: [3, 3, 6], state: "minecraft:gravel"},
        {pos: [3, 3, 7], state: "minecraft:gravel"},
        {pos: [4, 3, 4], state: "minecraft:gravel"},
        {pos: [4, 3, 5], state: "minecraft:gravel"},
        {pos: [4, 3, 6], state: "minecraft:gravel"},
        {pos: [4, 3, 7], state: "minecraft:gravel"},
        {pos: [5, 3, 4], state: "minecraft:gravel"},
        {pos: [5, 3, 5], state: "minecraft:gravel"},
        {pos: [5, 3, 6], state: "minecraft:gravel"},
        {pos: [5, 3, 7], state: "minecraft:gravel"},
        {pos: [6, 3, 4], state: "minecraft:gravel"},
        {pos: [6, 3, 5], state: "minecraft:gravel"},
        {pos: [6, 3, 6], state: "minecraft:gravel"},
        {pos: [6, 3, 7], state: "minecraft:gravel"},
        {pos: [7, 3, 4], state: "minecraft:gravel"},
        {pos: [7, 3, 5], state: "minecraft:gravel"},
        {pos: [7, 3, 6], state: "minecraft:gravel"},
        {pos: [7, 3, 7], state: "minecraft:gravel"},
        {pos: [7, 3, 8], state: "minecraft:gravel"},
        {pos: [8, 3, 3], state: "minecraft:gravel"},
        {pos: [8, 3, 4], state: "minecraft:gravel"},
        {pos: [8, 3, 5], state: "minecraft:gravel"},
        {pos: [8, 3, 6], state: "minecraft:gravel"},
        {pos: [8, 3, 7], state: "minecraft:deepslate_bricks"},
        {pos: [8, 3, 8], state: "minecraft:deepslate_bricks"},
        {pos: [8, 3, 9], state: "minecraft:gravel"},
        {pos: [9, 3, 4], state: "minecraft:gravel"},
        {pos: [9, 3, 5], state: "minecraft:gravel"},
        {pos: [9, 3, 6], state: "minecraft:gravel"},
        {pos: [9, 3, 7], state: "minecraft:deepslate_bricks"},
        {pos: [9, 3, 8], state: "minecraft:cobbled_deepslate"},
        {pos: [9, 3, 9], state: "minecraft:gravel"},
        {pos: [10, 3, 6], state: "minecraft:gravel"},
        {pos: [10, 3, 7], state: "minecraft:gravel"},
        {pos: [10, 3, 8], state: "minecraft:gravel"},
        {pos: [1, 4, 5], state: "minecraft:gravel"},
        {pos: [2, 4, 3], state: "minecraft:gravel"},
        {pos: [2, 4, 4], state: "minecraft:gravel"},
        {pos: [2, 4, 5], state: "minecraft:deepslate_bricks"},
        {pos: [2, 4, 6], state: "minecraft:gravel"},
        {pos: [3, 4, 3], state: "minecraft:gravel"},
        {pos: [3, 4, 4], state: "minecraft:deepslate_bricks"},
        {pos: [3, 4, 5], state: "minecraft:deepslate_bricks"},
        {pos: [3, 4, 6], state: "minecraft:gravel"},
        {pos: [4, 4, 4], state: "minecraft:gravel"},
        {pos: [4, 4, 5], state: "minecraft:gravel"},
        {pos: [4, 4, 6], state: "minecraft:gravel"},
        {pos: [4, 4, 7], state: "minecraft:gravel"},
        {pos: [5, 4, 5], state: "minecraft:gravel"},
        {pos: [5, 4, 6], state: "minecraft:gravel"},
        {pos: [5, 4, 7], state: "minecraft:gravel"},
        {pos: [6, 4, 5], state: "minecraft:gravel"},
        {pos: [6, 4, 6], state: "minecraft:gravel"},
        {pos: [6, 4, 7], state: "minecraft:gravel"},
        {pos: [7, 4, 5], state: "minecraft:gravel"},
        {pos: [7, 4, 6], state: "minecraft:gravel"},
        {pos: [7, 4, 7], state: "minecraft:gravel"},
        {pos: [7, 4, 8], state: "minecraft:gravel"},
        {pos: [8, 4, 6], state: "minecraft:gravel"},
        {pos: [8, 4, 7], state: "minecraft:deepslate_bricks"},
        {pos: [8, 4, 8], state: "minecraft:deepslate_bricks"},
        {pos: [8, 4, 9], state: "minecraft:gravel"},
        {pos: [9, 4, 6], state: "minecraft:gravel"},
        {pos: [9, 4, 7], state: "minecraft:deepslate_bricks"},
        {pos: [9, 4, 8], state: "minecraft:deepslate_bricks"},
        {pos: [9, 4, 9], state: "minecraft:gravel"},
        {pos: [10, 4, 7], state: "minecraft:gravel"},
        {pos: [10, 4, 8], state: "minecraft:gravel"},
        {pos: [2, 5, 5], state: "minecraft:deepslate_bricks"},
        {pos: [3, 5, 4], state: "minecraft:deepslate_bricks"},
        {pos: [3, 5, 5], state: "minecraft:deepslate_bricks"},
        {pos: [3, 5, 6], state: "minecraft:gravel"},
        {pos: [4, 5, 5], state: "minecraft:deepslate_bricks"},
        {pos: [8, 5, 7], state: "minecraft:gravel"},
        {pos: [9, 5, 7], state: "minecraft:deepslate_bricks"},
        {pos: [9, 5, 8], state: "minecraft:deepslate_bricks"}
    ],
    entities: [],
    palette: [
        "minecraft:deepslate_bricks",
        "minecraft:cobbled_deepslate",
        "minecraft:polished_deepslate",
        "minecraft:magma_block",
        "minecraft:gravel",
        "minecraft:chipped_anvil{facing:south}"
    ],
    trailiertales_DataVersion: 2
}
