{
    DataVersion: 3953,
    size: [9, 5, 9],
    data: [
        {pos: [0, 0, 3], state: "minecraft:cobbled_deepslate"},
        {pos: [0, 0, 4], state: "minecraft:deepslate_bricks"},
        {pos: [0, 0, 5], state: "minecraft:cobbled_deepslate"},
        {pos: [1, 0, 2], state: "minecraft:cobbled_deepslate"},
        {pos: [1, 0, 3], state: "minecraft:cobbled_deepslate"},
        {pos: [1, 0, 4], state: "minecraft:deepslate_bricks"},
        {pos: [1, 0, 5], state: "minecraft:cobbled_deepslate"},
        {pos: [1, 0, 6], state: "minecraft:cobbled_deepslate"},
        {pos: [2, 0, 1], state: "minecraft:cobbled_deepslate"},
        {pos: [2, 0, 2], state: "minecraft:cobbled_deepslate"},
        {pos: [2, 0, 3], state: "minecraft:cobbled_deepslate"},
        {pos: [2, 0, 4], state: "minecraft:deepslate_bricks"},
        {pos: [2, 0, 5], state: "minecraft:deepslate_bricks"},
        {pos: [2, 0, 6], state: "minecraft:deepslate_bricks"},
        {pos: [2, 0, 7], state: "minecraft:deepslate_bricks"},
        {pos: [3, 0, 1], state: "minecraft:cobbled_deepslate"},
        {pos: [3, 0, 2], state: "minecraft:deepslate_bricks"},
        {pos: [3, 0, 3], state: "minecraft:cobbled_deepslate"},
        {pos: [3, 0, 4], state: "minecraft:cobbled_deepslate"},
        {pos: [3, 0, 5], state: "minecraft:deepslate_bricks"},
        {pos: [3, 0, 6], state: "minecraft:deepslate_bricks"},
        {pos: [3, 0, 7], state: "minecraft:deepslate_bricks"},
        {pos: [4, 0, 0], state: "minecraft:cobbled_deepslate"},
        {pos: [4, 0, 1], state: "minecraft:cobbled_deepslate"},
        {pos: [4, 0, 2], state: "minecraft:deepslate_bricks"},
        {pos: [4, 0, 3], state: "minecraft:cobbled_deepslate"},
        {pos: [4, 0, 4], state: "minecraft:cobbled_deepslate"},
        {pos: [4, 0, 5], state: "minecraft:cobbled_deepslate"},
        {pos: [4, 0, 6], state: "minecraft:deepslate_bricks"},
        {pos: [4, 0, 7], state: "minecraft:cobbled_deepslate"},
        {pos: [4, 0, 8], state: "minecraft:cobbled_deepslate"},
        {pos: [5, 0, 1], state: "minecraft:cobbled_deepslate"},
        {pos: [5, 0, 2], state: "minecraft:cobbled_deepslate"},
        {pos: [5, 0, 3], state: "minecraft:cobbled_deepslate"},
        {pos: [5, 0, 4], state: "minecraft:cobbled_deepslate"},
        {pos: [5, 0, 5], state: "minecraft:cobbled_deepslate"},
        {pos: [5, 0, 6], state: "minecraft:deepslate_bricks"},
        {pos: [5, 0, 7], state: "minecraft:cobbled_deepslate"},
        {pos: [6, 0, 1], state: "minecraft:cobbled_deepslate"},
        {pos: [6, 0, 2], state: "minecraft:cobbled_deepslate"},
        {pos: [6, 0, 3], state: "minecraft:deepslate_bricks"},
        {pos: [6, 0, 4], state: "minecraft:deepslate_bricks"},
        {pos: [6, 0, 5], state: "minecraft:deepslate_bricks"},
        {pos: [6, 0, 6], state: "minecraft:deepslate_bricks"},
        {pos: [6, 0, 7], state: "minecraft:cobbled_deepslate"},
        {pos: [7, 0, 2], state: "minecraft:cobbled_deepslate"},
        {pos: [7, 0, 3], state: "minecraft:deepslate_bricks"},
        {pos: [7, 0, 4], state: "minecraft:deepslate_bricks"},
        {pos: [7, 0, 5], state: "minecraft:deepslate_bricks"},
        {pos: [7, 0, 6], state: "minecraft:deepslate_bricks"},
        {pos: [8, 0, 4], state: "minecraft:deepslate_bricks"},
        {pos: [8, 0, 5], state: "minecraft:deepslate_bricks"},
        {pos: [0, 1, 2], state: "minecraft:cobbled_deepslate"},
        {pos: [0, 1, 3], state: "minecraft:gravel"},
        {pos: [0, 1, 4], state: "minecraft:gravel"},
        {pos: [0, 1, 5], state: "minecraft:gravel"},
        {pos: [0, 1, 6], state: "minecraft:deepslate_bricks"},
        {pos: [1, 1, 2], state: "minecraft:cobbled_deepslate"},
        {pos: [1, 1, 3], state: "minecraft:crafting_table"},
        {pos: [1, 1, 4], state: "minecraft:gray_bed{facing:south,occupied:false,part:foot}", nbt: {id: "minecraft:bed"}},
        {pos: [1, 1, 5], state: "minecraft:gray_bed{facing:south,occupied:false,part:head}", nbt: {id: "minecraft:bed"}},
        {pos: [1, 1, 6], state: "minecraft:cobbled_deepslate"},
        {pos: [2, 1, 1], state: "minecraft:deepslate_bricks"},
        {pos: [2, 1, 2], state: "minecraft:cobbled_deepslate"},
        {pos: [2, 1, 3], state: "minecraft:oak_fence{east:true,north:true,south:true,waterlogged:false,west:true}"},
        {pos: [2, 1, 4], state: "minecraft:gravel"},
        {pos: [2, 1, 5], state: "minecraft:oak_fence{east:true,north:true,south:true,waterlogged:false,west:false}"},
        {pos: [2, 1, 6], state: "minecraft:deepslate_bricks"},
        {pos: [2, 1, 7], state: "minecraft:deepslate_bricks"},
        {pos: [3, 1, 0], state: "minecraft:deepslate_bricks"},
        {pos: [3, 1, 1], state: "minecraft:gravel"},
        {pos: [3, 1, 2], state: "minecraft:oak_fence{east:true,north:true,south:true,waterlogged:false,west:true}"},
        {pos: [3, 1, 3], state: "minecraft:gravel"},
        {pos: [3, 1, 4], state: "minecraft:gravel"},
        {pos: [3, 1, 5], state: "minecraft:gravel"},
        {pos: [3, 1, 6], state: "minecraft:oak_fence{east:true,north:true,south:true,waterlogged:false,west:true}"},
        {pos: [3, 1, 7], state: "minecraft:gravel"},
        {pos: [3, 1, 8], state: "minecraft:deepslate_bricks"},
        {pos: [4, 1, 0], state: "minecraft:deepslate_bricks"},
        {pos: [4, 1, 1], state: "minecraft:gravel"},
        {pos: [4, 1, 2], state: "minecraft:gravel"},
        {pos: [4, 1, 3], state: "minecraft:gravel"},
        {pos: [4, 1, 4], state: "minecraft:gravel"},
        {pos: [4, 1, 5], state: "minecraft:gravel"},
        {pos: [4, 1, 6], state: "minecraft:gravel"},
        {pos: [4, 1, 7], state: "minecraft:gravel"},
        {pos: [4, 1, 8], state: "minecraft:cobbled_deepslate"},
        {pos: [5, 1, 0], state: "minecraft:cobbled_deepslate"},
        {pos: [5, 1, 1], state: "minecraft:gravel"},
        {pos: [5, 1, 2], state: "minecraft:oak_fence{east:true,north:true,south:true,waterlogged:false,west:true}"},
        {pos: [5, 1, 3], state: "minecraft:gravel"},
        {pos: [5, 1, 4], state: "minecraft:gravel"},
        {pos: [5, 1, 5], state: "minecraft:gravel"},
        {pos: [5, 1, 6], state: "minecraft:oak_fence{east:true,north:true,south:true,waterlogged:false,west:true}"},
        {pos: [5, 1, 7], state: "minecraft:gravel"},
        {pos: [5, 1, 8], state: "minecraft:cobbled_deepslate"},
        {pos: [6, 1, 0], state: "minecraft:cobbled_deepslate"},
        {pos: [6, 1, 1], state: "minecraft:cobbled_deepslate"},
        {pos: [6, 1, 2], state: "minecraft:cobbled_deepslate"},
        {pos: [6, 1, 3], state: "minecraft:oak_fence{east:true,north:true,south:true,waterlogged:false,west:true}"},
        {pos: [6, 1, 4], state: "minecraft:gravel"},
        {pos: [6, 1, 5], state: "minecraft:oak_fence{east:true,north:true,south:true,waterlogged:false,west:true}"},
        {pos: [6, 1, 6], state: "minecraft:deepslate_bricks"},
        {pos: [6, 1, 7], state: "minecraft:cobbled_deepslate"},
        {pos: [7, 1, 2], state: "minecraft:cobbled_deepslate"},
        {pos: [7, 1, 3], state: "minecraft:gravel"},
        {pos: [7, 1, 4], state: "minecraft:gravel"},
        {pos: [7, 1, 5], state: "minecraft:gravel"},
        {pos: [7, 1, 6], state: "minecraft:cobbled_deepslate"},
        {pos: [8, 1, 2], state: "minecraft:cobbled_deepslate"},
        {pos: [8, 1, 3], state: "minecraft:polished_deepslate"},
        {pos: [8, 1, 4], state: "minecraft:deepslate_bricks"},
        {pos: [8, 1, 5], state: "minecraft:deepslate_bricks"},
        {pos: [8, 1, 6], state: "minecraft:cobbled_deepslate"},
        {pos: [0, 2, 2], state: "minecraft:gravel"},
        {pos: [0, 2, 3], state: "minecraft:gravel"},
        {pos: [0, 2, 4], state: "minecraft:gravel"},
        {pos: [0, 2, 5], state: "minecraft:gravel"},
        {pos: [0, 2, 6], state: "minecraft:gravel"},
        {pos: [1, 2, 2], state: "minecraft:cobbled_deepslate"},
        {pos: [1, 2, 3], state: "minecraft:gravel"},
        {pos: [1, 2, 4], state: "minecraft:gravel"},
        {pos: [1, 2, 5], state: "minecraft:gravel"},
        {pos: [1, 2, 6], state: "minecraft:deepslate_bricks"},
        {pos: [2, 2, 1], state: "minecraft:deepslate_bricks"},
        {pos: [2, 2, 2], state: "minecraft:cobbled_deepslate"},
        {pos: [2, 2, 3], state: "minecraft:oak_fence{east:true,north:true,south:true,waterlogged:false,west:true}"},
        {pos: [2, 2, 4], state: "minecraft:gravel"},
        {pos: [2, 2, 5], state: "minecraft:oak_fence{east:true,north:true,south:true,waterlogged:false,west:true}"},
        {pos: [2, 2, 6], state: "minecraft:cobbled_deepslate"},
        {pos: [2, 2, 7], state: "minecraft:deepslate_bricks"},
        {pos: [3, 2, 0], state: "minecraft:cobbled_deepslate"},
        {pos: [3, 2, 1], state: "minecraft:gravel"},
        {pos: [3, 2, 2], state: "minecraft:oak_fence{east:false,north:true,south:true,waterlogged:false,west:true}"},
        {pos: [3, 2, 3], state: "minecraft:gravel"},
        {pos: [3, 2, 4], state: "minecraft:gravel"},
        {pos: [3, 2, 5], state: "minecraft:gravel"},
        {pos: [3, 2, 6], state: "minecraft:oak_fence{east:true,north:true,south:true,waterlogged:false,west:true}"},
        {pos: [3, 2, 7], state: "minecraft:gravel"},
        {pos: [3, 2, 8], state: "minecraft:deepslate_bricks"},
        {pos: [4, 2, 0], state: "minecraft:cobbled_deepslate"},
        {pos: [4, 2, 1], state: "minecraft:gravel"},
        {pos: [4, 2, 3], state: "minecraft:gravel"},
        {pos: [4, 2, 4], state: "minecraft:gravel"},
        {pos: [4, 2, 5], state: "minecraft:gravel"},
        {pos: [4, 2, 6], state: "minecraft:gravel"},
        {pos: [4, 2, 7], state: "minecraft:gravel"},
        {pos: [4, 2, 8], state: "minecraft:deepslate_bricks"},
        {pos: [5, 2, 0], state: "minecraft:cobbled_deepslate"},
        {pos: [5, 2, 1], state: "minecraft:gravel"},
        {pos: [5, 2, 2], state: "minecraft:oak_fence{east:true,north:true,south:true,waterlogged:false,west:false}"},
        {pos: [5, 2, 3], state: "minecraft:gravel"},
        {pos: [5, 2, 4], state: "minecraft:gravel"},
        {pos: [5, 2, 5], state: "minecraft:gravel"},
        {pos: [5, 2, 6], state: "minecraft:oak_fence{east:true,north:true,south:true,waterlogged:false,west:true}"},
        {pos: [5, 2, 7], state: "minecraft:gravel"},
        {pos: [5, 2, 8], state: "minecraft:gravel"},
        {pos: [6, 2, 0], state: "minecraft:gravel"},
        {pos: [6, 2, 1], state: "minecraft:cobbled_deepslate"},
        {pos: [6, 2, 2], state: "minecraft:cobbled_deepslate"},
        {pos: [6, 2, 3], state: "minecraft:oak_fence{east:true,north:true,south:true,waterlogged:false,west:true}"},
        {pos: [6, 2, 4], state: "minecraft:gravel"},
        {pos: [6, 2, 5], state: "minecraft:oak_fence{east:true,north:true,south:true,waterlogged:false,west:true}"},
        {pos: [6, 2, 6], state: "minecraft:cobbled_deepslate"},
        {pos: [6, 2, 7], state: "minecraft:cobbled_deepslate"},
        {pos: [7, 2, 2], state: "minecraft:cobbled_deepslate"},
        {pos: [7, 2, 3], state: "minecraft:gravel"},
        {pos: [7, 2, 4], state: "minecraft:gravel"},
        {pos: [7, 2, 5], state: "minecraft:gravel"},
        {pos: [7, 2, 6], state: "minecraft:cobbled_deepslate"},
        {pos: [8, 2, 2], state: "minecraft:gravel"},
        {pos: [8, 2, 3], state: "minecraft:cobbled_deepslate"},
        {pos: [8, 2, 4], state: "minecraft:cobbled_deepslate"},
        {pos: [8, 2, 5], state: "minecraft:deepslate_bricks"},
        {pos: [8, 2, 6], state: "minecraft:gravel"},
        {pos: [0, 3, 3], state: "minecraft:gravel"},
        {pos: [0, 3, 4], state: "minecraft:gravel"},
        {pos: [0, 3, 5], state: "minecraft:gravel"},
        {pos: [1, 3, 2], state: "minecraft:gravel"},
        {pos: [1, 3, 3], state: "minecraft:cobbled_deepslate"},
        {pos: [1, 3, 4], state: "minecraft:cobbled_deepslate"},
        {pos: [1, 3, 5], state: "minecraft:deepslate_bricks"},
        {pos: [1, 3, 6], state: "minecraft:gravel"},
        {pos: [2, 3, 1], state: "minecraft:gravel"},
        {pos: [2, 3, 2], state: "minecraft:gravel"},
        {pos: [2, 3, 3], state: "minecraft:oak_planks"},
        {pos: [2, 3, 4], state: "minecraft:oak_planks"},
        {pos: [2, 3, 5], state: "minecraft:oak_planks"},
        {pos: [2, 3, 6], state: "minecraft:cobbled_deepslate"},
        {pos: [2, 3, 7], state: "minecraft:gravel"},
        {pos: [3, 3, 0], state: "minecraft:gravel"},
        {pos: [3, 3, 1], state: "minecraft:deepslate_bricks"},
        {pos: [3, 3, 2], state: "minecraft:oak_planks"},
        {pos: [3, 3, 3], state: "minecraft:gravel"},
        {pos: [3, 3, 4], state: "minecraft:gravel"},
        {pos: [3, 3, 5], state: "minecraft:gravel"},
        {pos: [3, 3, 6], state: "minecraft:oak_planks"},
        {pos: [3, 3, 7], state: "minecraft:cobbled_deepslate"},
        {pos: [3, 3, 8], state: "minecraft:gravel"},
        {pos: [4, 3, 0], state: "minecraft:gravel"},
        {pos: [4, 3, 1], state: "minecraft:cobbled_deepslate"},
        {pos: [4, 3, 2], state: "minecraft:oak_planks"},
        {pos: [4, 3, 3], state: "minecraft:gravel"},
        {pos: [4, 3, 4], state: "minecraft:gravel"},
        {pos: [4, 3, 5], state: "minecraft:gravel"},
        {pos: [4, 3, 6], state: "minecraft:oak_planks"},
        {pos: [4, 3, 7], state: "minecraft:cobbled_deepslate"},
        {pos: [4, 3, 8], state: "minecraft:gravel"},
        {pos: [5, 3, 0], state: "minecraft:gravel"},
        {pos: [5, 3, 1], state: "minecraft:cobbled_deepslate"},
        {pos: [5, 3, 2], state: "minecraft:oak_planks"},
        {pos: [5, 3, 3], state: "minecraft:gravel"},
        {pos: [5, 3, 4], state: "minecraft:gravel"},
        {pos: [5, 3, 5], state: "minecraft:gravel"},
        {pos: [5, 3, 6], state: "minecraft:oak_planks"},
        {pos: [5, 3, 7], state: "minecraft:cobbled_deepslate"},
        {pos: [6, 3, 1], state: "minecraft:gravel"},
        {pos: [6, 3, 2], state: "minecraft:gravel"},
        {pos: [6, 3, 3], state: "minecraft:oak_planks"},
        {pos: [6, 3, 4], state: "minecraft:oak_planks"},
        {pos: [6, 3, 5], state: "minecraft:oak_planks"},
        {pos: [6, 3, 6], state: "minecraft:gravel"},
        {pos: [6, 3, 7], state: "minecraft:gravel"},
        {pos: [7, 3, 2], state: "minecraft:gravel"},
        {pos: [7, 3, 3], state: "minecraft:polished_deepslate"},
        {pos: [7, 3, 4], state: "minecraft:cobbled_deepslate"},
        {pos: [7, 3, 5], state: "minecraft:cobbled_deepslate"},
        {pos: [7, 3, 6], state: "minecraft:gravel"},
        {pos: [8, 3, 3], state: "minecraft:gravel"},
        {pos: [8, 3, 4], state: "minecraft:gravel"},
        {pos: [8, 3, 5], state: "minecraft:gravel"},
        {pos: [1, 4, 3], state: "minecraft:gravel"},
        {pos: [1, 4, 4], state: "minecraft:gravel"},
        {pos: [1, 4, 5], state: "minecraft:gravel"},
        {pos: [2, 4, 3], state: "minecraft:gravel"},
        {pos: [2, 4, 4], state: "minecraft:gravel"},
        {pos: [2, 4, 5], state: "minecraft:gravel"},
        {pos: [2, 4, 6], state: "minecraft:gravel"},
        {pos: [3, 4, 1], state: "minecraft:gravel"},
        {pos: [3, 4, 2], state: "minecraft:gravel"},
        {pos: [3, 4, 3], state: "minecraft:gravel"},
        {pos: [3, 4, 4], state: "minecraft:gravel"},
        {pos: [3, 4, 5], state: "minecraft:gravel"},
        {pos: [3, 4, 6], state: "minecraft:gravel"},
        {pos: [3, 4, 7], state: "minecraft:gravel"},
        {pos: [4, 4, 1], state: "minecraft:gravel"},
        {pos: [4, 4, 2], state: "minecraft:gravel"},
        {pos: [4, 4, 3], state: "minecraft:gravel"},
        {pos: [4, 4, 4], state: "minecraft:gravel"},
        {pos: [4, 4, 5], state: "minecraft:gravel"},
        {pos: [4, 4, 6], state: "minecraft:gravel"},
        {pos: [4, 4, 7], state: "minecraft:gravel"},
        {pos: [5, 4, 1], state: "minecraft:gravel"},
        {pos: [5, 4, 2], state: "minecraft:gravel"},
        {pos: [5, 4, 3], state: "minecraft:gravel"},
        {pos: [5, 4, 4], state: "minecraft:gravel"},
        {pos: [5, 4, 5], state: "minecraft:gravel"},
        {pos: [5, 4, 6], state: "minecraft:gravel"},
        {pos: [5, 4, 7], state: "minecraft:gravel"},
        {pos: [6, 4, 2], state: "minecraft:gravel"},
        {pos: [6, 4, 3], state: "minecraft:gravel"},
        {pos: [6, 4, 4], state: "minecraft:gravel"},
        {pos: [6, 4, 5], state: "minecraft:gravel"},
        {pos: [7, 4, 3], state: "minecraft:gravel"},
        {pos: [7, 4, 4], state: "minecraft:gravel"},
        {pos: [7, 4, 5], state: "minecraft:gravel"}
    ],
    entities: [],
    palette: [
        "minecraft:cobbled_deepslate",
        "minecraft:deepslate_bricks",
        "minecraft:gravel",
        "minecraft:crafting_table",
        "minecraft:polished_deepslate",
        "minecraft:oak_planks",
        "minecraft:oak_fence{east:true,north:true,south:true,waterlogged:false,west:true}",
        "minecraft:oak_fence{east:true,north:true,south:true,waterlogged:false,west:false}",
        "minecraft:oak_fence{east:false,north:true,south:true,waterlogged:false,west:true}",
        "minecraft:gray_bed{facing:south,occupied:false,part:foot}",
        "minecraft:gray_bed{facing:south,occupied:false,part:head}"
    ],
    trailiertales_DataVersion: 2
}
