{
    DataVersion: 3953,
    size: [9, 12, 9],
    data: [
        {pos: [0, 0, 4], state: "minecraft:deepslate_bricks"},
        {pos: [0, 0, 5], state: "minecraft:deepslate_bricks"},
        {pos: [1, 0, 3], state: "minecraft:deepslate_bricks"},
        {pos: [1, 0, 4], state: "minecraft:deepslate_bricks"},
        {pos: [1, 0, 5], state: "minecraft:cobbled_deepslate"},
        {pos: [1, 0, 6], state: "minecraft:deepslate_bricks"},
        {pos: [2, 0, 2], state: "minecraft:cobbled_deepslate"},
        {pos: [2, 0, 3], state: "minecraft:deepslate_bricks"},
        {pos: [2, 0, 4], state: "minecraft:deepslate_bricks"},
        {pos: [2, 0, 5], state: "minecraft:deepslate_bricks"},
        {pos: [2, 0, 6], state: "minecraft:deepslate_bricks"},
        {pos: [2, 0, 7], state: "minecraft:deepslate_bricks"},
        {pos: [3, 0, 1], state: "minecraft:cobbled_deepslate"},
        {pos: [3, 0, 2], state: "minecraft:cobbled_deepslate"},
        {pos: [3, 0, 3], state: "minecraft:deepslate_bricks"},
        {pos: [3, 0, 4], state: "minecraft:deepslate_bricks"},
        {pos: [3, 0, 5], state: "minecraft:deepslate_bricks"},
        {pos: [3, 0, 6], state: "minecraft:deepslate_bricks"},
        {pos: [3, 0, 7], state: "minecraft:deepslate_bricks"},
        {pos: [3, 0, 8], state: "minecraft:deepslate_bricks"},
        {pos: [4, 0, 1], state: "minecraft:cobbled_deepslate"},
        {pos: [4, 0, 2], state: "minecraft:cobbled_deepslate"},
        {pos: [4, 0, 3], state: "minecraft:deepslate_bricks"},
        {pos: [4, 0, 4], state: "minecraft:deepslate_bricks"},
        {pos: [4, 0, 5], state: "minecraft:gravel"},
        {pos: [4, 0, 6], state: "minecraft:deepslate_bricks"},
        {pos: [4, 0, 7], state: "minecraft:deepslate_bricks"},
        {pos: [4, 0, 8], state: "minecraft:deepslate_bricks"},
        {pos: [5, 0, 1], state: "minecraft:cobbled_deepslate"},
        {pos: [5, 0, 2], state: "minecraft:polished_deepslate"},
        {pos: [5, 0, 3], state: "minecraft:deepslate_bricks"},
        {pos: [5, 0, 4], state: "minecraft:cobbled_deepslate"},
        {pos: [5, 0, 5], state: "minecraft:deepslate_bricks"},
        {pos: [5, 0, 6], state: "minecraft:deepslate_bricks"},
        {pos: [5, 0, 7], state: "minecraft:cobbled_deepslate"},
        {pos: [5, 0, 8], state: "minecraft:deepslate_bricks"},
        {pos: [6, 0, 0], state: "minecraft:deepslate_bricks"},
        {pos: [6, 0, 1], state: "minecraft:deepslate_bricks"},
        {pos: [6, 0, 2], state: "minecraft:deepslate_bricks"},
        {pos: [6, 0, 3], state: "minecraft:cobbled_deepslate"},
        {pos: [6, 0, 4], state: "minecraft:cobbled_deepslate"},
        {pos: [6, 0, 5], state: "minecraft:cobbled_deepslate"},
        {pos: [6, 0, 6], state: "minecraft:deepslate_bricks"},
        {pos: [6, 0, 7], state: "minecraft:deepslate_bricks"},
        {pos: [6, 0, 8], state: "minecraft:deepslate_bricks"},
        {pos: [7, 0, 1], state: "minecraft:deepslate_bricks"},
        {pos: [7, 0, 2], state: "minecraft:deepslate_bricks"},
        {pos: [7, 0, 3], state: "minecraft:deepslate_bricks"},
        {pos: [7, 0, 4], state: "minecraft:cobbled_deepslate"},
        {pos: [7, 0, 5], state: "minecraft:deepslate_bricks"},
        {pos: [7, 0, 6], state: "minecraft:deepslate_bricks"},
        {pos: [7, 0, 7], state: "minecraft:deepslate_bricks"},
        {pos: [8, 0, 3], state: "minecraft:deepslate_bricks"},
        {pos: [8, 0, 4], state: "minecraft:deepslate_bricks"},
        {pos: [8, 0, 5], state: "minecraft:deepslate_bricks"},
        {pos: [8, 0, 6], state: "minecraft:deepslate_bricks"},
        {pos: [0, 1, 4], state: "minecraft:deepslate_bricks"},
        {pos: [0, 1, 5], state: "minecraft:deepslate_bricks"},
        {pos: [1, 1, 3], state: "minecraft:deepslate_bricks"},
        {pos: [1, 1, 4], state: "minecraft:gravel"},
        {pos: [1, 1, 5], state: "minecraft:gravel"},
        {pos: [1, 1, 6], state: "minecraft:cobbled_deepslate"},
        {pos: [2, 1, 2], state: "minecraft:cobbled_deepslate"},
        {pos: [2, 1, 3], state: "minecraft:gravel"},
        {pos: [2, 1, 4], state: "minecraft:gravel"},
        {pos: [2, 1, 5], state: "minecraft:gravel"},
        {pos: [2, 1, 6], state: "minecraft:gravel"},
        {pos: [2, 1, 7], state: "minecraft:deepslate_bricks"},
        {pos: [3, 1, 1], state: "minecraft:cobbled_deepslate"},
        {pos: [3, 1, 2], state: "minecraft:gravel"},
        {pos: [3, 1, 3], state: "minecraft:gravel"},
        {pos: [3, 1, 4], state: "minecraft:gravel"},
        {pos: [3, 1, 5], state: "minecraft:deepslate_bricks"},
        {pos: [3, 1, 6], state: "minecraft:deepslate_bricks"},
        {pos: [3, 1, 7], state: "minecraft:gravel"},
        {pos: [3, 1, 8], state: "minecraft:gravel"},
        {pos: [4, 1, 1], state: "minecraft:gravel"},
        {pos: [4, 1, 2], state: "minecraft:gravel"},
        {pos: [4, 1, 3], state: "minecraft:gravel"},
        {pos: [4, 1, 4], state: "minecraft:gravel"},
        {pos: [4, 1, 5], state: "minecraft:gravel"},
        {pos: [4, 1, 6], state: "minecraft:cobbled_deepslate"},
        {pos: [4, 1, 7], state: "minecraft:gravel"},
        {pos: [4, 1, 8], state: "minecraft:deepslate_bricks"},
        {pos: [5, 1, 1], state: "minecraft:gravel"},
        {pos: [5, 1, 2], state: "minecraft:gravel"},
        {pos: [5, 1, 3], state: "minecraft:gravel"},
        {pos: [5, 1, 4], state: "minecraft:deepslate_brick_stairs{facing:south,half:bottom,shape:straight,waterlogged:false}"},
        {pos: [5, 1, 5], state: "minecraft:cobbled_deepslate"},
        {pos: [5, 1, 6], state: "minecraft:cobbled_deepslate"},
        {pos: [5, 1, 7], state: "minecraft:gravel"},
        {pos: [5, 1, 8], state: "minecraft:cobbled_deepslate"},
        {pos: [6, 1, 0], state: "minecraft:gravel"},
        {pos: [6, 1, 1], state: "minecraft:deepslate_bricks"},
        {pos: [6, 1, 2], state: "minecraft:gravel"},
        {pos: [6, 1, 3], state: "minecraft:gravel"},
        {pos: [6, 1, 4], state: "minecraft:gravel"},
        {pos: [6, 1, 5], state: "minecraft:gravel"},
        {pos: [6, 1, 6], state: "minecraft:gravel"},
        {pos: [6, 1, 7], state: "minecraft:gravel"},
        {pos: [6, 1, 8], state: "minecraft:cobbled_deepslate"},
        {pos: [7, 1, 1], state: "minecraft:gravel"},
        {pos: [7, 1, 2], state: "minecraft:cobbled_deepslate"},
        {pos: [7, 1, 3], state: "minecraft:deepslate_brick_stairs{facing:east,half:top,shape:straight,waterlogged:false}"},
        {pos: [7, 1, 4], state: "minecraft:deepslate_brick_stairs{facing:east,half:top,shape:straight,waterlogged:false}"},
        {pos: [7, 1, 5], state: "minecraft:gravel"},
        {pos: [7, 1, 6], state: "minecraft:gravel"},
        {pos: [7, 1, 7], state: "minecraft:deepslate_bricks"},
        {pos: [8, 1, 3], state: "minecraft:deepslate_bricks"},
        {pos: [8, 1, 4], state: "minecraft:deepslate_bricks"},
        {pos: [8, 1, 5], state: "minecraft:deepslate_bricks"},
        {pos: [8, 1, 6], state: "minecraft:deepslate_bricks"},
        {pos: [0, 2, 4], state: "minecraft:deepslate_bricks"},
        {pos: [0, 2, 5], state: "minecraft:deepslate_bricks"},
        {pos: [1, 2, 3], state: "minecraft:deepslate_bricks"},
        {pos: [1, 2, 4], state: "minecraft:gravel"},
        {pos: [1, 2, 5], state: "minecraft:gravel"},
        {pos: [1, 2, 6], state: "minecraft:gravel"},
        {pos: [2, 2, 2], state: "minecraft:gravel"},
        {pos: [2, 2, 3], state: "minecraft:gravel"},
        {pos: [2, 2, 4], state: "minecraft:gravel"},
        {pos: [2, 2, 5], state: "minecraft:gravel"},
        {pos: [2, 2, 6], state: "minecraft:gravel"},
        {pos: [2, 2, 7], state: "minecraft:cobbled_deepslate"},
        {pos: [3, 2, 1], state: "minecraft:cobbled_deepslate"},
        {pos: [3, 2, 2], state: "minecraft:gravel"},
        {pos: [3, 2, 3], state: "minecraft:gravel"},
        {pos: [3, 2, 4], state: "minecraft:gravel"},
        {pos: [3, 2, 5], state: "minecraft:deepslate_bricks"},
        {pos: [3, 2, 6], state: "minecraft:deepslate_bricks"},
        {pos: [3, 2, 7], state: "minecraft:gravel"},
        {pos: [3, 2, 8], state: "minecraft:gravel"},
        {pos: [4, 2, 1], state: "minecraft:gravel"},
        {pos: [4, 2, 2], state: "minecraft:gravel"},
        {pos: [4, 2, 3], state: "minecraft:gravel"},
        {pos: [4, 2, 4], state: "minecraft:gravel"},
        {pos: [4, 2, 5], state: "minecraft:deepslate_bricks"},
        {pos: [4, 2, 6], state: "minecraft:cobbled_deepslate"},
        {pos: [4, 2, 7], state: "minecraft:gravel"},
        {pos: [4, 2, 8], state: "minecraft:gravel"},
        {pos: [5, 2, 1], state: "minecraft:gravel"},
        {pos: [5, 2, 2], state: "minecraft:gravel"},
        {pos: [5, 2, 3], state: "minecraft:gravel"},
        {pos: [5, 2, 4], state: "minecraft:gravel"},
        {pos: [5, 2, 5], state: "minecraft:gravel"},
        {pos: [5, 2, 6], state: "minecraft:gravel"},
        {pos: [5, 2, 7], state: "minecraft:gravel"},
        {pos: [5, 2, 8], state: "minecraft:cobbled_deepslate"},
        {pos: [6, 2, 0], state: "minecraft:gravel"},
        {pos: [6, 2, 1], state: "minecraft:deepslate_bricks"},
        {pos: [6, 2, 2], state: "minecraft:gravel"},
        {pos: [6, 2, 3], state: "minecraft:gravel"},
        {pos: [6, 2, 4], state: "minecraft:gravel"},
        {pos: [6, 2, 5], state: "minecraft:gravel"},
        {pos: [6, 2, 6], state: "minecraft:gravel"},
        {pos: [6, 2, 7], state: "minecraft:gravel"},
        {pos: [6, 2, 8], state: "minecraft:cobbled_deepslate"},
        {pos: [7, 2, 1], state: "minecraft:gravel"},
        {pos: [7, 2, 2], state: "minecraft:cobbled_deepslate"},
        {pos: [7, 2, 3], state: "minecraft:gravel"},
        {pos: [7, 2, 4], state: "minecraft:gravel"},
        {pos: [7, 2, 5], state: "minecraft:gravel"},
        {pos: [7, 2, 6], state: "minecraft:gravel"},
        {pos: [7, 2, 7], state: "minecraft:polished_deepslate"},
        {pos: [8, 2, 3], state: "minecraft:deepslate_bricks"},
        {pos: [8, 2, 4], state: "minecraft:deepslate_bricks"},
        {pos: [8, 2, 5], state: "minecraft:cobbled_deepslate"},
        {pos: [8, 2, 6], state: "minecraft:deepslate_bricks"},
        {pos: [0, 3, 4], state: "minecraft:deepslate_bricks"},
        {pos: [0, 3, 5], state: "minecraft:deepslate_bricks"},
        {pos: [1, 3, 3], state: "minecraft:gravel"},
        {pos: [1, 3, 4], state: "minecraft:gravel"},
        {pos: [1, 3, 5], state: "minecraft:gravel"},
        {pos: [1, 3, 6], state: "minecraft:gravel"},
        {pos: [2, 3, 2], state: "minecraft:deepslate_bricks"},
        {pos: [2, 3, 3], state: "minecraft:gravel"},
        {pos: [2, 3, 4], state: "minecraft:gravel"},
        {pos: [2, 3, 5], state: "minecraft:gravel"},
        {pos: [2, 3, 6], state: "minecraft:gravel"},
        {pos: [2, 3, 7], state: "minecraft:cobbled_deepslate"},
        {pos: [3, 3, 1], state: "minecraft:deepslate_bricks"},
        {pos: [3, 3, 2], state: "minecraft:gravel"},
        {pos: [3, 3, 3], state: "minecraft:gravel"},
        {pos: [3, 3, 4], state: "minecraft:deepslate_bricks"},
        {pos: [3, 3, 5], state: "minecraft:deepslate_bricks"},
        {pos: [3, 3, 6], state: "minecraft:gravel"},
        {pos: [3, 3, 7], state: "minecraft:gravel"},
        {pos: [3, 3, 8], state: "minecraft:gravel"},
        {pos: [4, 3, 1], state: "minecraft:gravel"},
        {pos: [4, 3, 2], state: "minecraft:gravel"},
        {pos: [4, 3, 3], state: "minecraft:gravel"},
        {pos: [4, 3, 4], state: "minecraft:deepslate_bricks"},
        {pos: [4, 3, 5], state: "minecraft:cobbled_deepslate"},
        {pos: [4, 3, 6], state: "minecraft:gravel"},
        {pos: [4, 3, 7], state: "minecraft:gravel"},
        {pos: [4, 3, 8], state: "minecraft:gravel"},
        {pos: [5, 3, 1], state: "minecraft:deepslate_bricks"},
        {pos: [5, 3, 2], state: "minecraft:gravel"},
        {pos: [5, 3, 3], state: "minecraft:gravel"},
        {pos: [5, 3, 4], state: "minecraft:gravel"},
        {pos: [5, 3, 5], state: "minecraft:gravel"},
        {pos: [5, 3, 6], state: "minecraft:gravel"},
        {pos: [5, 3, 7], state: "minecraft:gravel"},
        {pos: [5, 3, 8], state: "minecraft:gravel"},
        {pos: [6, 3, 0], state: "minecraft:gravel"},
        {pos: [6, 3, 1], state: "minecraft:deepslate_bricks"},
        {pos: [6, 3, 2], state: "minecraft:gravel"},
        {pos: [6, 3, 3], state: "minecraft:gravel"},
        {pos: [6, 3, 4], state: "minecraft:gravel"},
        {pos: [6, 3, 5], state: "minecraft:gravel"},
        {pos: [6, 3, 6], state: "minecraft:gravel"},
        {pos: [6, 3, 7], state: "minecraft:gravel"},
        {pos: [6, 3, 8], state: "minecraft:cobbled_deepslate"},
        {pos: [7, 3, 1], state: "minecraft:gravel"},
        {pos: [7, 3, 2], state: "minecraft:deepslate_bricks"},
        {pos: [7, 3, 3], state: "minecraft:gravel"},
        {pos: [7, 3, 4], state: "minecraft:gravel"},
        {pos: [7, 3, 5], state: "minecraft:gravel"},
        {pos: [7, 3, 6], state: "minecraft:gravel"},
        {pos: [7, 3, 7], state: "minecraft:cobbled_deepslate"},
        {pos: [8, 3, 3], state: "minecraft:deepslate_bricks"},
        {pos: [8, 3, 4], state: "minecraft:polished_deepslate"},
        {pos: [8, 3, 5], state: "minecraft:cobbled_deepslate"},
        {pos: [8, 3, 6], state: "minecraft:cobbled_deepslate"},
        {pos: [0, 4, 4], state: "minecraft:deepslate_bricks"},
        {pos: [0, 4, 5], state: "minecraft:cobbled_deepslate"},
        {pos: [1, 4, 3], state: "minecraft:deepslate_bricks"},
        {pos: [1, 4, 4], state: "minecraft:gravel"},
        {pos: [1, 4, 5], state: "minecraft:gravel"},
        {pos: [1, 4, 6], state: "minecraft:cobbled_deepslate"},
        {pos: [2, 4, 2], state: "minecraft:deepslate_bricks"},
        {pos: [2, 4, 3], state: "minecraft:gravel"},
        {pos: [2, 4, 4], state: "minecraft:gravel"},
        {pos: [2, 4, 5], state: "minecraft:gravel"},
        {pos: [2, 4, 6], state: "minecraft:gravel"},
        {pos: [2, 4, 7], state: "minecraft:cobbled_deepslate"},
        {pos: [3, 4, 1], state: "minecraft:deepslate_bricks"},
        {pos: [3, 4, 2], state: "minecraft:gravel"},
        {pos: [3, 4, 3], state: "minecraft:gravel"},
        {pos: [3, 4, 4], state: "minecraft:deepslate_bricks"},
        {pos: [3, 4, 5], state: "minecraft:gravel"},
        {pos: [3, 4, 6], state: "minecraft:gravel"},
        {pos: [3, 4, 7], state: "minecraft:gravel"},
        {pos: [3, 4, 8], state: "minecraft:polished_deepslate"},
        {pos: [4, 4, 1], state: "minecraft:deepslate_bricks"},
        {pos: [4, 4, 2], state: "minecraft:gravel"},
        {pos: [4, 4, 3], state: "minecraft:gravel"},
        {pos: [4, 4, 4], state: "minecraft:deepslate_bricks"},
        {pos: [4, 4, 5], state: "minecraft:cobbled_deepslate"},
        {pos: [4, 4, 6], state: "minecraft:gravel"},
        {pos: [4, 4, 7], state: "minecraft:gravel"},
        {pos: [4, 4, 8], state: "minecraft:gravel"},
        {pos: [5, 4, 1], state: "minecraft:deepslate_bricks"},
        {pos: [5, 4, 2], state: "minecraft:gravel"},
        {pos: [5, 4, 3], state: "minecraft:gravel"},
        {pos: [5, 4, 4], state: "minecraft:deepslate_brick_stairs{facing:west,half:top,shape:straight,waterlogged:false}"},
        {pos: [5, 4, 5], state: "minecraft:gravel"},
        {pos: [5, 4, 6], state: "minecraft:gravel"},
        {pos: [5, 4, 7], state: "minecraft:gravel"},
        {pos: [5, 4, 8], state: "minecraft:cobbled_deepslate"},
        {pos: [6, 4, 1], state: "minecraft:gravel"},
        {pos: [6, 4, 2], state: "minecraft:gravel"},
        {pos: [6, 4, 3], state: "minecraft:gravel"},
        {pos: [6, 4, 4], state: "minecraft:gravel"},
        {pos: [6, 4, 5], state: "minecraft:gravel"},
        {pos: [6, 4, 6], state: "minecraft:gravel"},
        {pos: [6, 4, 7], state: "minecraft:gravel"},
        {pos: [6, 4, 8], state: "minecraft:gravel"},
        {pos: [7, 4, 2], state: "minecraft:deepslate_bricks"},
        {pos: [7, 4, 3], state: "minecraft:gravel"},
        {pos: [7, 4, 4], state: "minecraft:gravel"},
        {pos: [7, 4, 5], state: "minecraft:gravel"},
        {pos: [7, 4, 6], state: "minecraft:gravel"},
        {pos: [7, 4, 7], state: "minecraft:cobbled_deepslate"},
        {pos: [8, 4, 3], state: "minecraft:cobbled_deepslate"},
        {pos: [8, 4, 4], state: "minecraft:cobbled_deepslate"},
        {pos: [8, 4, 5], state: "minecraft:deepslate_bricks"},
        {pos: [8, 4, 6], state: "minecraft:cobbled_deepslate"},
        {pos: [0, 5, 4], state: "minecraft:deepslate_bricks"},
        {pos: [0, 5, 5], state: "minecraft:polished_deepslate"},
        {pos: [1, 5, 3], state: "minecraft:deepslate_bricks"},
        {pos: [1, 5, 4], state: "minecraft:gravel"},
        {pos: [1, 5, 5], state: "minecraft:gravel"},
        {pos: [1, 5, 6], state: "minecraft:cobbled_deepslate"},
        {pos: [2, 5, 2], state: "minecraft:deepslate_bricks"},
        {pos: [2, 5, 3], state: "minecraft:gravel"},
        {pos: [2, 5, 4], state: "minecraft:gravel"},
        {pos: [2, 5, 5], state: "minecraft:gravel"},
        {pos: [2, 5, 6], state: "minecraft:gravel"},
        {pos: [2, 5, 7], state: "minecraft:cobbled_deepslate"},
        {pos: [3, 5, 1], state: "minecraft:polished_deepslate"},
        {pos: [3, 5, 2], state: "minecraft:gravel"},
        {pos: [3, 5, 3], state: "minecraft:gravel"},
        {pos: [3, 5, 4], state: "minecraft:gravel"},
        {pos: [3, 5, 5], state: "minecraft:gravel"},
        {pos: [3, 5, 6], state: "minecraft:gravel"},
        {pos: [3, 5, 7], state: "minecraft:gravel"},
        {pos: [3, 5, 8], state: "minecraft:cobbled_deepslate"},
        {pos: [4, 5, 1], state: "minecraft:cobbled_deepslate"},
        {pos: [4, 5, 2], state: "minecraft:gravel"},
        {pos: [4, 5, 3], state: "minecraft:gravel"},
        {pos: [4, 5, 4], state: "minecraft:gravel"},
        {pos: [4, 5, 5], state: "minecraft:cobbled_deepslate"},
        {pos: [4, 5, 6], state: "minecraft:gravel"},
        {pos: [4, 5, 7], state: "minecraft:gravel"},
        {pos: [4, 5, 8], state: "minecraft:deepslate_bricks"},
        {pos: [5, 5, 1], state: "minecraft:gravel"},
        {pos: [5, 5, 2], state: "minecraft:gravel"},
        {pos: [5, 5, 3], state: "minecraft:gravel"},
        {pos: [5, 5, 4], state: "minecraft:deepslate_bricks"},
        {pos: [5, 5, 5], state: "minecraft:deepslate_bricks"},
        {pos: [5, 5, 6], state: "minecraft:gravel"},
        {pos: [5, 5, 7], state: "minecraft:gravel"},
        {pos: [5, 5, 8], state: "minecraft:cobbled_deepslate"},
        {pos: [6, 5, 1], state: "minecraft:gravel"},
        {pos: [6, 5, 2], state: "minecraft:gravel"},
        {pos: [6, 5, 3], state: "minecraft:gravel"},
        {pos: [6, 5, 4], state: "minecraft:gravel"},
        {pos: [6, 5, 5], state: "minecraft:gravel"},
        {pos: [6, 5, 6], state: "minecraft:gravel"},
        {pos: [6, 5, 7], state: "minecraft:gravel"},
        {pos: [6, 5, 8], state: "minecraft:cobbled_deepslate"},
        {pos: [7, 5, 2], state: "minecraft:deepslate_bricks"},
        {pos: [7, 5, 3], state: "minecraft:gravel"},
        {pos: [7, 5, 4], state: "minecraft:gravel"},
        {pos: [7, 5, 5], state: "minecraft:gravel"},
        {pos: [7, 5, 6], state: "minecraft:gravel"},
        {pos: [7, 5, 7], state: "minecraft:cobbled_deepslate"},
        {pos: [8, 5, 3], state: "minecraft:cobbled_deepslate"},
        {pos: [8, 5, 4], state: "minecraft:cobbled_deepslate"},
        {pos: [8, 5, 5], state: "minecraft:deepslate_bricks"},
        {pos: [8, 5, 6], state: "minecraft:deepslate_bricks"},
        {pos: [0, 6, 4], state: "minecraft:polished_deepslate"},
        {pos: [0, 6, 5], state: "minecraft:cobbled_deepslate"},
        {pos: [1, 6, 3], state: "minecraft:deepslate_bricks"},
        {pos: [1, 6, 4], state: "minecraft:cobbled_deepslate"},
        {pos: [1, 6, 5], state: "minecraft:cobbled_deepslate"},
        {pos: [1, 6, 6], state: "minecraft:polished_deepslate"},
        {pos: [2, 6, 2], state: "minecraft:deepslate_bricks"},
        {pos: [2, 6, 3], state: "minecraft:deepslate_bricks"},
        {pos: [2, 6, 4], state: "minecraft:deepslate_bricks"},
        {pos: [2, 6, 5], state: "minecraft:cobbled_deepslate"},
        {pos: [2, 6, 6], state: "minecraft:cobbled_deepslate"},
        {pos: [2, 6, 7], state: "minecraft:cobbled_deepslate"},
        {pos: [3, 6, 1], state: "minecraft:cobbled_deepslate"},
        {pos: [3, 6, 2], state: "minecraft:cobbled_deepslate"},
        {pos: [3, 6, 3], state: "minecraft:deepslate_bricks"},
        {pos: [3, 6, 4], state: "minecraft:gravel"},
        {pos: [3, 6, 5], state: "minecraft:gravel"},
        {pos: [3, 6, 6], state: "minecraft:cobbled_deepslate"},
        {pos: [3, 6, 7], state: "minecraft:cobbled_deepslate"},
        {pos: [3, 6, 8], state: "minecraft:cobbled_deepslate"},
        {pos: [4, 6, 1], state: "minecraft:polished_deepslate"},
        {pos: [4, 6, 2], state: "minecraft:cobbled_deepslate"},
        {pos: [4, 6, 3], state: "minecraft:deepslate_bricks"},
        {pos: [4, 6, 4], state: "minecraft:gravel"},
        {pos: [4, 6, 5], state: "minecraft:deepslate_bricks"},
        {pos: [4, 6, 6], state: "minecraft:deepslate_bricks"},
        {pos: [4, 6, 7], state: "minecraft:cobbled_deepslate"},
        {pos: [4, 6, 8], state: "minecraft:deepslate_bricks"},
        {pos: [5, 6, 1], state: "minecraft:deepslate_bricks"},
        {pos: [5, 6, 2], state: "minecraft:deepslate_bricks"},
        {pos: [5, 6, 3], state: "minecraft:deepslate_bricks"},
        {pos: [5, 6, 4], state: "minecraft:gravel"},
        {pos: [5, 6, 5], state: "minecraft:gravel"},
        {pos: [5, 6, 6], state: "minecraft:deepslate_bricks"},
        {pos: [5, 6, 7], state: "minecraft:cobbled_deepslate"},
        {pos: [5, 6, 8], state: "minecraft:polished_deepslate"},
        {pos: [6, 6, 1], state: "minecraft:gravel"},
        {pos: [6, 6, 2], state: "minecraft:cobbled_deepslate"},
        {pos: [6, 6, 3], state: "minecraft:deepslate_bricks"},
        {pos: [6, 6, 4], state: "minecraft:deepslate_bricks"},
        {pos: [6, 6, 5], state: "minecraft:deepslate_bricks"},
        {pos: [6, 6, 6], state: "minecraft:cobbled_deepslate"},
        {pos: [6, 6, 7], state: "minecraft:cobbled_deepslate"},
        {pos: [6, 6, 8], state: "minecraft:cobbled_deepslate"},
        {pos: [7, 6, 2], state: "minecraft:deepslate_bricks"},
        {pos: [7, 6, 3], state: "minecraft:cobbled_deepslate"},
        {pos: [7, 6, 4], state: "minecraft:cobbled_deepslate"},
        {pos: [7, 6, 5], state: "minecraft:cobbled_deepslate"},
        {pos: [7, 6, 6], state: "minecraft:deepslate_bricks"},
        {pos: [7, 6, 7], state: "minecraft:cobbled_deepslate"},
        {pos: [8, 6, 3], state: "minecraft:cobbled_deepslate"},
        {pos: [8, 6, 4], state: "minecraft:cobbled_deepslate"},
        {pos: [8, 6, 5], state: "minecraft:deepslate_bricks"},
        {pos: [8, 6, 6], state: "minecraft:deepslate_bricks"},
        {pos: [0, 7, 4], state: "minecraft:cobbled_deepslate"},
        {pos: [0, 7, 5], state: "minecraft:deepslate_bricks"},
        {pos: [1, 7, 3], state: "minecraft:deepslate_bricks"},
        {pos: [1, 7, 4], state: "minecraft:deepslate_brick_stairs{facing:west,half:top,shape:straight,waterlogged:false}"},
        {pos: [1, 7, 5], state: "minecraft:deepslate_brick_stairs{facing:west,half:top,shape:straight,waterlogged:false}"},
        {pos: [1, 7, 6], state: "minecraft:polished_deepslate"},
        {pos: [2, 7, 2], state: "minecraft:deepslate_bricks"},
        {pos: [2, 7, 3], state: "minecraft:gravel"},
        {pos: [2, 7, 4], state: "minecraft:gravel"},
        {pos: [2, 7, 5], state: "minecraft:gravel"},
        {pos: [2, 7, 6], state: "minecraft:gravel"},
        {pos: [2, 7, 7], state: "minecraft:polished_deepslate"},
        {pos: [3, 7, 1], state: "minecraft:gravel"},
        {pos: [3, 7, 2], state: "minecraft:gravel"},
        {pos: [3, 7, 3], state: "minecraft:gravel"},
        {pos: [3, 7, 4], state: "minecraft:gravel"},
        {pos: [3, 7, 5], state: "minecraft:gravel"},
        {pos: [3, 7, 6], state: "minecraft:gravel"},
        {pos: [3, 7, 7], state: "minecraft:cobbled_deepslate"},
        {pos: [3, 7, 8], state: "minecraft:cobbled_deepslate"},
        {pos: [4, 7, 1], state: "minecraft:cobbled_deepslate"},
        {pos: [4, 7, 2], state: "minecraft:gravel"},
        {pos: [4, 7, 3], state: "minecraft:gravel"},
        {pos: [4, 7, 4], state: "minecraft:gravel"},
        {pos: [4, 7, 5], state: "minecraft:cobbled_deepslate"},
        {pos: [4, 7, 6], state: "minecraft:deepslate_brick_stairs{facing:north,half:top,shape:straight,waterlogged:false}"},
        {pos: [4, 7, 7], state: "minecraft:gravel"},
        {pos: [4, 7, 8], state: "minecraft:deepslate_bricks"},
        {pos: [5, 7, 1], state: "minecraft:deepslate_bricks"},
        {pos: [5, 7, 2], state: "minecraft:gravel"},
        {pos: [5, 7, 3], state: "minecraft:gravel"},
        {pos: [5, 7, 4], state: "minecraft:gravel"},
        {pos: [5, 7, 5], state: "minecraft:gravel"},
        {pos: [5, 7, 6], state: "minecraft:gravel"},
        {pos: [5, 7, 7], state: "minecraft:gravel"},
        {pos: [5, 7, 8], state: "minecraft:polished_deepslate"},
        {pos: [6, 7, 1], state: "minecraft:deepslate_bricks"},
        {pos: [6, 7, 2], state: "minecraft:gravel"},
        {pos: [6, 7, 3], state: "minecraft:gravel"},
        {pos: [6, 7, 4], state: "minecraft:gravel"},
        {pos: [6, 7, 5], state: "minecraft:gravel"},
        {pos: [6, 7, 6], state: "minecraft:gravel"},
        {pos: [6, 7, 7], state: "minecraft:cobbled_deepslate"},
        {pos: [6, 7, 8], state: "minecraft:cobbled_deepslate"},
        {pos: [7, 7, 2], state: "minecraft:deepslate_bricks"},
        {pos: [7, 7, 3], state: "minecraft:gravel"},
        {pos: [7, 7, 4], state: "minecraft:gravel"},
        {pos: [7, 7, 5], state: "minecraft:gravel"},
        {pos: [7, 7, 6], state: "minecraft:cobbled_deepslate"},
        {pos: [7, 7, 7], state: "minecraft:cobbled_deepslate"},
        {pos: [8, 7, 3], state: "minecraft:cobbled_deepslate"},
        {pos: [8, 7, 4], state: "minecraft:deepslate_bricks"},
        {pos: [8, 7, 5], state: "minecraft:deepslate_bricks"},
        {pos: [8, 7, 6], state: "minecraft:deepslate_bricks"},
        {pos: [0, 8, 4], state: "minecraft:deepslate_bricks"},
        {pos: [0, 8, 5], state: "minecraft:deepslate_bricks"},
        {pos: [1, 8, 3], state: "minecraft:cobbled_deepslate"},
        {pos: [1, 8, 4], state: "minecraft:gravel"},
        {pos: [1, 8, 5], state: "minecraft:gravel"},
        {pos: [1, 8, 6], state: "minecraft:deepslate_bricks"},
        {pos: [2, 8, 2], state: "minecraft:deepslate_bricks"},
        {pos: [2, 8, 3], state: "minecraft:gravel"},
        {pos: [2, 8, 4], state: "minecraft:gravel"},
        {pos: [2, 8, 5], state: "minecraft:gravel"},
        {pos: [2, 8, 6], state: "minecraft:gravel"},
        {pos: [2, 8, 7], state: "minecraft:polished_deepslate"},
        {pos: [3, 8, 1], state: "minecraft:gravel"},
        {pos: [3, 8, 2], state: "minecraft:gravel"},
        {pos: [3, 8, 3], state: "minecraft:gravel"},
        {pos: [3, 8, 4], state: "minecraft:gravel"},
        {pos: [3, 8, 5], state: "minecraft:gravel"},
        {pos: [3, 8, 6], state: "minecraft:gravel"},
        {pos: [3, 8, 7], state: "minecraft:gravel"},
        {pos: [3, 8, 8], state: "minecraft:cobbled_deepslate"},
        {pos: [4, 8, 1], state: "minecraft:deepslate_bricks"},
        {pos: [4, 8, 2], state: "minecraft:gravel"},
        {pos: [4, 8, 3], state: "minecraft:gravel"},
        {pos: [4, 8, 4], state: "minecraft:gravel"},
        {pos: [4, 8, 5], state: "minecraft:polished_deepslate"},
        {pos: [4, 8, 6], state: "minecraft:gravel"},
        {pos: [4, 8, 7], state: "minecraft:gravel"},
        {pos: [4, 8, 8], state: "minecraft:deepslate_bricks"},
        {pos: [5, 8, 1], state: "minecraft:deepslate_bricks"},
        {pos: [5, 8, 2], state: "minecraft:gravel"},
        {pos: [5, 8, 3], state: "minecraft:gravel"},
        {pos: [5, 8, 4], state: "minecraft:gravel"},
        {pos: [5, 8, 5], state: "minecraft:gravel"},
        {pos: [5, 8, 6], state: "minecraft:gravel"},
        {pos: [5, 8, 7], state: "minecraft:gravel"},
        {pos: [5, 8, 8], state: "minecraft:deepslate_bricks"},
        {pos: [6, 8, 1], state: "minecraft:deepslate_bricks"},
        {pos: [6, 8, 2], state: "minecraft:gravel"},
        {pos: [6, 8, 3], state: "minecraft:gravel"},
        {pos: [6, 8, 4], state: "minecraft:gravel"},
        {pos: [6, 8, 5], state: "minecraft:gravel"},
        {pos: [6, 8, 6], state: "minecraft:gravel"},
        {pos: [6, 8, 7], state: "minecraft:polished_deepslate"},
        {pos: [6, 8, 8], state: "minecraft:cobbled_deepslate"},
        {pos: [7, 8, 2], state: "minecraft:cobbled_deepslate"},
        {pos: [7, 8, 3], state: "minecraft:gravel"},
        {pos: [7, 8, 4], state: "minecraft:gravel"},
        {pos: [7, 8, 5], state: "minecraft:gravel"},
        {pos: [7, 8, 6], state: "minecraft:gravel"},
        {pos: [7, 8, 7], state: "minecraft:cobbled_deepslate"},
        {pos: [8, 8, 3], state: "minecraft:cobbled_deepslate"},
        {pos: [8, 8, 4], state: "minecraft:cobbled_deepslate"},
        {pos: [8, 8, 5], state: "minecraft:cobbled_deepslate"},
        {pos: [8, 8, 6], state: "minecraft:deepslate_bricks"},
        {pos: [0, 9, 4], state: "minecraft:cobbled_deepslate"},
        {pos: [0, 9, 5], state: "minecraft:cobbled_deepslate"},
        {pos: [1, 9, 3], state: "minecraft:cobbled_deepslate"},
        {pos: [1, 9, 4], state: "minecraft:gravel"},
        {pos: [1, 9, 5], state: "minecraft:gravel"},
        {pos: [1, 9, 6], state: "minecraft:deepslate_bricks"},
        {pos: [2, 9, 2], state: "minecraft:cobbled_deepslate"},
        {pos: [2, 9, 3], state: "minecraft:gravel"},
        {pos: [2, 9, 4], state: "minecraft:gravel"},
        {pos: [2, 9, 5], state: "minecraft:gravel"},
        {pos: [2, 9, 6], state: "minecraft:gravel"},
        {pos: [2, 9, 7], state: "minecraft:cobbled_deepslate"},
        {pos: [3, 9, 1], state: "minecraft:deepslate_bricks"},
        {pos: [3, 9, 2], state: "minecraft:gravel"},
        {pos: [3, 9, 3], state: "minecraft:gravel"},
        {pos: [3, 9, 4], state: "minecraft:gravel"},
        {pos: [3, 9, 5], state: "minecraft:gravel"},
        {pos: [3, 9, 6], state: "minecraft:gravel"},
        {pos: [3, 9, 7], state: "minecraft:gravel"},
        {pos: [3, 9, 8], state: "minecraft:deepslate_bricks"},
        {pos: [4, 9, 1], state: "minecraft:deepslate_bricks"},
        {pos: [4, 9, 2], state: "minecraft:gravel"},
        {pos: [4, 9, 3], state: "minecraft:gravel"},
        {pos: [4, 9, 4], state: "minecraft:gravel"},
        {pos: [4, 9, 5], state: "minecraft:cobbled_deepslate"},
        {pos: [4, 9, 6], state: "minecraft:gravel"},
        {pos: [4, 9, 7], state: "minecraft:gravel"},
        {pos: [4, 9, 8], state: "minecraft:deepslate_bricks"},
        {pos: [5, 9, 1], state: "minecraft:deepslate_bricks"},
        {pos: [5, 9, 2], state: "minecraft:gravel"},
        {pos: [5, 9, 3], state: "minecraft:gravel"},
        {pos: [5, 9, 4], state: "minecraft:gravel"},
        {pos: [5, 9, 5], state: "minecraft:gravel"},
        {pos: [5, 9, 6], state: "minecraft:gravel"},
        {pos: [5, 9, 7], state: "minecraft:gravel"},
        {pos: [5, 9, 8], state: "minecraft:deepslate_bricks"},
        {pos: [6, 9, 1], state: "minecraft:cobbled_deepslate"},
        {pos: [6, 9, 2], state: "minecraft:gravel"},
        {pos: [6, 9, 3], state: "minecraft:gravel"},
        {pos: [6, 9, 4], state: "minecraft:gravel"},
        {pos: [6, 9, 5], state: "minecraft:gravel"},
        {pos: [6, 9, 6], state: "minecraft:gravel"},
        {pos: [6, 9, 7], state: "minecraft:gravel"},
        {pos: [6, 9, 8], state: "minecraft:deepslate_bricks"},
        {pos: [7, 9, 2], state: "minecraft:cobbled_deepslate"},
        {pos: [7, 9, 3], state: "minecraft:gravel"},
        {pos: [7, 9, 4], state: "minecraft:gravel"},
        {pos: [7, 9, 5], state: "minecraft:gravel"},
        {pos: [7, 9, 6], state: "minecraft:gravel"},
        {pos: [7, 9, 7], state: "minecraft:cobbled_deepslate"},
        {pos: [8, 9, 3], state: "minecraft:deepslate_bricks"},
        {pos: [8, 9, 4], state: "minecraft:deepslate_bricks"},
        {pos: [8, 9, 5], state: "minecraft:deepslate_bricks"},
        {pos: [8, 9, 6], state: "minecraft:deepslate_bricks"},
        {pos: [0, 10, 4], state: "minecraft:gravel"},
        {pos: [0, 10, 5], state: "minecraft:gravel"},
        {pos: [1, 10, 3], state: "minecraft:gravel"},
        {pos: [1, 10, 4], state: "minecraft:cobbled_deepslate"},
        {pos: [1, 10, 5], state: "minecraft:cobbled_deepslate"},
        {pos: [1, 10, 6], state: "minecraft:gravel"},
        {pos: [2, 10, 2], state: "minecraft:gravel"},
        {pos: [2, 10, 3], state: "minecraft:cobbled_deepslate"},
        {pos: [2, 10, 4], state: "minecraft:deepslate_bricks"},
        {pos: [2, 10, 5], state: "minecraft:deepslate_bricks"},
        {pos: [2, 10, 6], state: "minecraft:cobbled_deepslate"},
        {pos: [2, 10, 7], state: "minecraft:gravel"},
        {pos: [3, 10, 1], state: "minecraft:gravel"},
        {pos: [3, 10, 2], state: "minecraft:cobbled_deepslate"},
        {pos: [3, 10, 3], state: "minecraft:deepslate_bricks"},
        {pos: [3, 10, 4], state: "minecraft:gravel"},
        {pos: [3, 10, 5], state: "minecraft:deepslate_bricks"},
        {pos: [3, 10, 6], state: "minecraft:polished_deepslate"},
        {pos: [3, 10, 7], state: "minecraft:cobbled_deepslate"},
        {pos: [3, 10, 8], state: "minecraft:gravel"},
        {pos: [4, 10, 1], state: "minecraft:gravel"},
        {pos: [4, 10, 2], state: "minecraft:polished_deepslate"},
        {pos: [4, 10, 3], state: "minecraft:deepslate_bricks"},
        {pos: [4, 10, 4], state: "minecraft:cobbled_deepslate"},
        {pos: [4, 10, 5], state: "minecraft:cobbled_deepslate"},
        {pos: [4, 10, 6], state: "minecraft:cobbled_deepslate"},
        {pos: [4, 10, 7], state: "minecraft:deepslate_bricks"},
        {pos: [4, 10, 8], state: "minecraft:gravel"},
        {pos: [5, 10, 1], state: "minecraft:gravel"},
        {pos: [5, 10, 2], state: "minecraft:cobbled_deepslate"},
        {pos: [5, 10, 3], state: "minecraft:deepslate_bricks"},
        {pos: [5, 10, 4], state: "minecraft:cobbled_deepslate"},
        {pos: [5, 10, 5], state: "minecraft:gravel"},
        {pos: [5, 10, 6], state: "minecraft:gravel"},
        {pos: [5, 10, 7], state: "minecraft:deepslate_bricks"},
        {pos: [5, 10, 8], state: "minecraft:gravel"},
        {pos: [6, 10, 1], state: "minecraft:gravel"},
        {pos: [6, 10, 2], state: "minecraft:cobbled_deepslate"},
        {pos: [6, 10, 3], state: "minecraft:deepslate_bricks"},
        {pos: [6, 10, 4], state: "minecraft:gravel"},
        {pos: [6, 10, 5], state: "minecraft:gravel"},
        {pos: [6, 10, 6], state: "minecraft:deepslate_bricks"},
        {pos: [6, 10, 7], state: "minecraft:deepslate_bricks"},
        {pos: [6, 10, 8], state: "minecraft:gravel"},
        {pos: [7, 10, 2], state: "minecraft:gravel"},
        {pos: [7, 10, 3], state: "minecraft:deepslate_bricks"},
        {pos: [7, 10, 4], state: "minecraft:deepslate_bricks"},
        {pos: [7, 10, 5], state: "minecraft:deepslate_bricks"},
        {pos: [7, 10, 6], state: "minecraft:deepslate_bricks"},
        {pos: [7, 10, 7], state: "minecraft:gravel"},
        {pos: [8, 10, 3], state: "minecraft:gravel"},
        {pos: [8, 10, 4], state: "minecraft:gravel"},
        {pos: [0, 11, 5], state: "minecraft:gravel"},
        {pos: [1, 11, 4], state: "minecraft:gravel"},
        {pos: [1, 11, 5], state: "minecraft:gravel"},
        {pos: [1, 11, 6], state: "minecraft:gravel"},
        {pos: [2, 11, 5], state: "minecraft:cobbled_deepslate"},
        {pos: [2, 11, 6], state: "minecraft:cobbled_deepslate"},
        {pos: [2, 11, 7], state: "minecraft:gravel"},
        {pos: [3, 11, 5], state: "minecraft:cobbled_deepslate"},
        {pos: [3, 11, 6], state: "minecraft:cobbled_deepslate"},
        {pos: [3, 11, 7], state: "minecraft:cobbled_deepslate"},
        {pos: [4, 11, 2], state: "minecraft:deepslate_bricks"},
        {pos: [4, 11, 6], state: "minecraft:polished_deepslate"},
        {pos: [4, 11, 7], state: "minecraft:gravel"},
        {pos: [5, 11, 1], state: "minecraft:gravel"},
        {pos: [5, 11, 2], state: "minecraft:polished_deepslate"},
        {pos: [5, 11, 3], state: "minecraft:deepslate_bricks"},
        {pos: [5, 11, 7], state: "minecraft:gravel"},
        {pos: [6, 11, 1], state: "minecraft:gravel"},
        {pos: [6, 11, 2], state: "minecraft:cobbled_deepslate"},
        {pos: [6, 11, 3], state: "minecraft:deepslate_bricks"},
        {pos: [7, 11, 3], state: "minecraft:gravel"},
        {pos: [7, 11, 4], state: "minecraft:gravel"}
    ],
    entities: [],
    palette: [
        "minecraft:deepslate_bricks",
        "minecraft:cobbled_deepslate",
        "minecraft:gravel",
        "minecraft:polished_deepslate",
        "minecraft:deepslate_brick_stairs{facing:south,half:bottom,shape:straight,waterlogged:false}",
        "minecraft:deepslate_brick_stairs{facing:east,half:top,shape:straight,waterlogged:false}",
        "minecraft:deepslate_brick_stairs{facing:west,half:top,shape:straight,waterlogged:false}",
        "minecraft:deepslate_brick_stairs{facing:north,half:top,shape:straight,waterlogged:false}"
    ],
    trailiertales_DataVersion: 2
}
