{
    DataVersion: 3953,
    size: [4, 5, 6],
    data: [
        {pos: [0, 0, 1], state: "minecraft:cobbled_deepslate"},
        {pos: [0, 0, 2], state: "minecraft:cobbled_deepslate"},
        {pos: [0, 0, 3], state: "minecraft:cobbled_deepslate"},
        {pos: [0, 0, 4], state: "minecraft:deepslate{axis:y}"},
        {pos: [1, 0, 0], state: "minecraft:cobbled_deepslate"},
        {pos: [1, 0, 1], state: "minecraft:cobbled_deepslate"},
        {pos: [1, 0, 2], state: "minecraft:gravel"},
        {pos: [1, 0, 3], state: "minecraft:deepslate{axis:y}"},
        {pos: [1, 0, 4], state: "minecraft:deepslate{axis:y}"},
        {pos: [1, 0, 5], state: "minecraft:deepslate{axis:y}"},
        {pos: [2, 0, 1], state: "minecraft:cobbled_deepslate"},
        {pos: [2, 0, 2], state: "minecraft:cobbled_deepslate"},
        {pos: [2, 0, 3], state: "minecraft:deepslate{axis:y}"},
        {pos: [2, 0, 4], state: "minecraft:deepslate{axis:y}"},
        {pos: [2, 0, 5], state: "minecraft:deepslate{axis:y}"},
        {pos: [3, 0, 2], state: "minecraft:cobbled_deepslate"},
        {pos: [3, 0, 3], state: "minecraft:deepslate{axis:y}"},
        {pos: [0, 1, 1], state: "minecraft:gravel"},
        {pos: [0, 1, 2], state: "minecraft:gravel"},
        {pos: [0, 1, 3], state: "minecraft:deepslate{axis:y}"},
        {pos: [0, 1, 4], state: "minecraft:deepslate{axis:y}"},
        {pos: [1, 1, 0], state: "minecraft:gravel"},
        {pos: [1, 1, 1], state: "minecraft:gravel"},
        {pos: [1, 1, 2], state: "minecraft:gravel"},
        {pos: [1, 1, 3], state: "minecraft:deepslate{axis:y}"},
        {pos: [1, 1, 4], state: "minecraft:deepslate{axis:y}"},
        {pos: [1, 1, 5], state: "minecraft:deepslate{axis:y}"},
        {pos: [2, 1, 1], state: "minecraft:gravel"},
        {pos: [2, 1, 2], state: "minecraft:deepslate{axis:y}"},
        {pos: [2, 1, 3], state: "minecraft:deepslate{axis:y}"},
        {pos: [2, 1, 4], state: "minecraft:deepslate{axis:y}"},
        {pos: [2, 1, 5], state: "minecraft:deepslate{axis:y}"},
        {pos: [3, 1, 2], state: "minecraft:gravel"},
        {pos: [3, 1, 3], state: "minecraft:deepslate{axis:y}"},
        {pos: [0, 2, 3], state: "minecraft:gravel"},
        {pos: [0, 2, 4], state: "minecraft:deepslate{axis:y}"},
        {pos: [1, 2, 2], state: "minecraft:gravel"},
        {pos: [1, 2, 3], state: "minecraft:deepslate{axis:y}"},
        {pos: [1, 2, 4], state: "minecraft:deepslate{axis:y}"},
        {pos: [1, 2, 5], state: "minecraft:deepslate{axis:y}"},
        {pos: [2, 2, 2], state: "minecraft:gravel"},
        {pos: [2, 2, 3], state: "minecraft:deepslate{axis:y}"},
        {pos: [2, 2, 4], state: "minecraft:deepslate{axis:y}"},
        {pos: [2, 2, 5], state: "minecraft:gravel"},
        {pos: [3, 2, 2], state: "minecraft:gravel"},
        {pos: [3, 2, 3], state: "minecraft:gravel"},
        {pos: [1, 3, 3], state: "minecraft:deepslate{axis:y}"},
        {pos: [1, 3, 4], state: "minecraft:deepslate{axis:y}"},
        {pos: [1, 3, 5], state: "minecraft:gravel"},
        {pos: [2, 3, 3], state: "minecraft:deepslate{axis:y}"},
        {pos: [2, 3, 4], state: "minecraft:deepslate{axis:y}"},
        {pos: [3, 3, 3], state: "minecraft:gravel"},
        {pos: [1, 4, 3], state: "minecraft:deepslate{axis:y}"},
        {pos: [1, 4, 4], state: "minecraft:deepslate{axis:y}"},
        {pos: [2, 4, 3], state: "minecraft:deepslate{axis:y}"}
    ],
    entities: [],
    palette: [
        "minecraft:cobbled_deepslate",
        "minecraft:deepslate{axis:y}",
        "minecraft:gravel"
    ],
    trailiertales_DataVersion: 2
}
