{
    DataVersion: 3953,
    size: [14, 5, 11],
    data: [
        {pos: [0, 0, 4], state: "minecraft:deepslate_bricks"},
        {pos: [0, 0, 5], state: "minecraft:deepslate_bricks"},
        {pos: [1, 0, 3], state: "minecraft:cobbled_deepslate"},
        {pos: [1, 0, 4], state: "minecraft:cobbled_deepslate"},
        {pos: [1, 0, 5], state: "minecraft:deepslate_bricks"},
        {pos: [1, 0, 6], state: "minecraft:deepslate_bricks"},
        {pos: [2, 0, 3], state: "minecraft:polished_deepslate"},
        {pos: [2, 0, 4], state: "minecraft:cobbled_deepslate"},
        {pos: [2, 0, 5], state: "minecraft:cobbled_deepslate"},
        {pos: [2, 0, 6], state: "minecraft:deepslate_bricks"},
        {pos: [2, 0, 9], state: "minecraft:deepslate_bricks"},
        {pos: [2, 0, 10], state: "minecraft:deepslate_bricks"},
        {pos: [3, 0, 1], state: "minecraft:deepslate_bricks"},
        {pos: [3, 0, 2], state: "minecraft:deepslate_bricks"},
        {pos: [3, 0, 3], state: "minecraft:deepslate_bricks"},
        {pos: [3, 0, 4], state: "minecraft:polished_deepslate"},
        {pos: [3, 0, 5], state: "minecraft:cobbled_deepslate"},
        {pos: [3, 0, 6], state: "minecraft:cobbled_deepslate"},
        {pos: [3, 0, 7], state: "minecraft:deepslate_bricks"},
        {pos: [3, 0, 8], state: "minecraft:deepslate_bricks"},
        {pos: [3, 0, 9], state: "minecraft:deepslate_bricks"},
        {pos: [3, 0, 10], state: "minecraft:deepslate_bricks"},
        {pos: [4, 0, 1], state: "minecraft:deepslate_bricks"},
        {pos: [4, 0, 2], state: "minecraft:cobbled_deepslate"},
        {pos: [4, 0, 3], state: "minecraft:deepslate_bricks"},
        {pos: [4, 0, 5], state: "minecraft:cobbled_deepslate"},
        {pos: [4, 0, 6], state: "minecraft:deepslate_bricks"},
        {pos: [4, 0, 7], state: "minecraft:deepslate_bricks"},
        {pos: [4, 0, 8], state: "minecraft:deepslate_bricks"},
        {pos: [4, 0, 9], state: "minecraft:deepslate_bricks"},
        {pos: [5, 0, 1], state: "minecraft:cobbled_deepslate"},
        {pos: [5, 0, 2], state: "minecraft:cobbled_deepslate"},
        {pos: [5, 0, 6], state: "minecraft:cobbled_deepslate"},
        {pos: [5, 0, 7], state: "minecraft:deepslate_bricks"},
        {pos: [5, 0, 8], state: "minecraft:cobbled_deepslate"},
        {pos: [5, 0, 9], state: "minecraft:cobbled_deepslate"},
        {pos: [6, 0, 1], state: "minecraft:cobbled_deepslate"},
        {pos: [6, 0, 2], state: "minecraft:cobbled_deepslate"},
        {pos: [6, 0, 3], state: "minecraft:deepslate_bricks"},
        {pos: [6, 0, 8], state: "minecraft:cobbled_deepslate"},
        {pos: [6, 0, 9], state: "minecraft:deepslate_bricks"},
        {pos: [7, 0, 1], state: "minecraft:cobbled_deepslate"},
        {pos: [7, 0, 2], state: "minecraft:polished_deepslate"},
        {pos: [7, 0, 3], state: "minecraft:deepslate_bricks"},
        {pos: [7, 0, 4], state: "minecraft:deepslate_bricks"},
        {pos: [7, 0, 6], state: "minecraft:cobbled_deepslate"},
        {pos: [7, 0, 7], state: "minecraft:cobbled_deepslate"},
        {pos: [7, 0, 8], state: "minecraft:cobbled_deepslate"},
        {pos: [7, 0, 9], state: "minecraft:deepslate_bricks"},
        {pos: [7, 0, 10], state: "minecraft:cobbled_deepslate"},
        {pos: [8, 0, 0], state: "minecraft:cobbled_deepslate"},
        {pos: [8, 0, 1], state: "minecraft:cobbled_deepslate"},
        {pos: [8, 0, 2], state: "minecraft:cobbled_deepslate"},
        {pos: [8, 0, 3], state: "minecraft:deepslate_bricks"},
        {pos: [8, 0, 4], state: "minecraft:deepslate_bricks"},
        {pos: [8, 0, 5], state: "minecraft:deepslate_bricks"},
        {pos: [8, 0, 6], state: "minecraft:cobbled_deepslate"},
        {pos: [8, 0, 7], state: "minecraft:cobbled_deepslate"},
        {pos: [8, 0, 8], state: "minecraft:polished_deepslate"},
        {pos: [8, 0, 9], state: "minecraft:deepslate_bricks"},
        {pos: [9, 0, 0], state: "minecraft:cobbled_deepslate"},
        {pos: [9, 0, 1], state: "minecraft:cobbled_deepslate"},
        {pos: [9, 0, 2], state: "minecraft:deepslate_bricks"},
        {pos: [9, 0, 3], state: "minecraft:deepslate_bricks"},
        {pos: [9, 0, 6], state: "minecraft:cobbled_deepslate"},
        {pos: [9, 0, 7], state: "minecraft:polished_deepslate"},
        {pos: [10, 0, 1], state: "minecraft:cobbled_deepslate"},
        {pos: [10, 0, 2], state: "minecraft:cobbled_deepslate"},
        {pos: [11, 0, 4], state: "minecraft:cobbled_deepslate"},
        {pos: [11, 0, 5], state: "minecraft:deepslate_bricks"},
        {pos: [12, 0, 3], state: "minecraft:deepslate_bricks"},
        {pos: [12, 0, 4], state: "minecraft:gravel"},
        {pos: [12, 0, 5], state: "minecraft:deepslate_bricks"},
        {pos: [13, 0, 2], state: "minecraft:cobbled_deepslate"},
        {pos: [13, 0, 3], state: "minecraft:cobbled_deepslate"},
        {pos: [13, 0, 4], state: "minecraft:cobbled_deepslate"},
        {pos: [0, 1, 4], state: "minecraft:deepslate_bricks"},
        {pos: [0, 1, 5], state: "minecraft:deepslate_bricks"},
        {pos: [1, 1, 3], state: "minecraft:gravel"},
        {pos: [1, 1, 4], state: "minecraft:gravel"},
        {pos: [1, 1, 5], state: "minecraft:gravel"},
        {pos: [1, 1, 6], state: "minecraft:cobbled_deepslate"},
        {pos: [2, 1, 3], state: "minecraft:gravel"},
        {pos: [2, 1, 4], state: "minecraft:gravel"},
        {pos: [2, 1, 5], state: "minecraft:gravel"},
        {pos: [2, 1, 6], state: "minecraft:gravel"},
        {pos: [2, 1, 9], state: "minecraft:gravel"},
        {pos: [2, 1, 10], state: "minecraft:gravel"},
        {pos: [3, 1, 1], state: "minecraft:gravel"},
        {pos: [3, 1, 2], state: "minecraft:gravel"},
        {pos: [3, 1, 3], state: "minecraft:gravel"},
        {pos: [3, 1, 4], state: "minecraft:gravel"},
        {pos: [3, 1, 5], state: "minecraft:gravel"},
        {pos: [3, 1, 6], state: "minecraft:gravel"},
        {pos: [3, 1, 7], state: "minecraft:gravel"},
        {pos: [3, 1, 8], state: "minecraft:deepslate_bricks"},
        {pos: [3, 1, 9], state: "minecraft:deepslate_bricks"},
        {pos: [3, 1, 10], state: "minecraft:deepslate_brick_stairs{facing:north,half:top,shape:straight,waterlogged:false}"},
        {pos: [4, 1, 1], state: "minecraft:deepslate_bricks"},
        {pos: [4, 1, 2], state: "minecraft:gravel"},
        {pos: [4, 1, 3], state: "minecraft:gravel"},
        {pos: [4, 1, 5], state: "minecraft:gravel"},
        {pos: [4, 1, 6], state: "minecraft:gravel"},
        {pos: [4, 1, 7], state: "minecraft:gravel"},
        {pos: [4, 1, 8], state: "minecraft:gravel"},
        {pos: [4, 1, 9], state: "minecraft:deepslate_bricks"},
        {pos: [5, 1, 1], state: "minecraft:soul_sand"},
        {pos: [5, 1, 2], state: "minecraft:deepslate_brick_stairs{facing:north,half:top,shape:straight,waterlogged:false}"},
        {pos: [5, 1, 6], state: "minecraft:gravel"},
        {pos: [5, 1, 7], state: "minecraft:gravel"},
        {pos: [5, 1, 8], state: "minecraft:gravel"},
        {pos: [5, 1, 9], state: "minecraft:gravel"},
        {pos: [6, 1, 1], state: "minecraft:soul_sand"},
        {pos: [6, 1, 2], state: "minecraft:deepslate_brick_stairs{facing:north,half:top,shape:straight,waterlogged:false}"},
        {pos: [6, 1, 3], state: "minecraft:gravel"},
        {pos: [6, 1, 8], state: "minecraft:gravel"},
        {pos: [6, 1, 9], state: "minecraft:gravel"},
        {pos: [7, 1, 1], state: "minecraft:soul_sand"},
        {pos: [7, 1, 2], state: "minecraft:deepslate_bricks"},
        {pos: [7, 1, 3], state: "minecraft:gravel"},
        {pos: [7, 1, 4], state: "minecraft:gravel"},
        {pos: [7, 1, 6], state: "minecraft:gravel"},
        {pos: [7, 1, 7], state: "minecraft:gravel"},
        {pos: [7, 1, 8], state: "minecraft:deepslate_brick_stairs{facing:south,half:top,shape:straight,waterlogged:false}"},
        {pos: [7, 1, 9], state: "minecraft:deepslate_bricks"},
        {pos: [7, 1, 10], state: "minecraft:gravel"},
        {pos: [8, 1, 0], state: "minecraft:gravel"},
        {pos: [8, 1, 1], state: "minecraft:deepslate_bricks"},
        {pos: [8, 1, 2], state: "minecraft:deepslate_bricks"},
        {pos: [8, 1, 3], state: "minecraft:gravel"},
        {pos: [8, 1, 4], state: "minecraft:gravel"},
        {pos: [8, 1, 5], state: "minecraft:gravel"},
        {pos: [8, 1, 6], state: "minecraft:gravel"},
        {pos: [8, 1, 7], state: "minecraft:gravel"},
        {pos: [8, 1, 8], state: "minecraft:cobbled_deepslate"},
        {pos: [8, 1, 9], state: "minecraft:deepslate_bricks"},
        {pos: [9, 1, 0], state: "minecraft:gravel"},
        {pos: [9, 1, 1], state: "minecraft:gravel"},
        {pos: [9, 1, 2], state: "minecraft:gravel"},
        {pos: [9, 1, 3], state: "minecraft:gravel"},
        {pos: [9, 1, 6], state: "minecraft:gravel"},
        {pos: [9, 1, 7], state: "minecraft:gravel"},
        {pos: [10, 1, 1], state: "minecraft:gravel"},
        {pos: [10, 1, 2], state: "minecraft:gravel"},
        {pos: [11, 1, 4], state: "minecraft:gravel"},
        {pos: [11, 1, 5], state: "minecraft:gravel"},
        {pos: [12, 1, 3], state: "minecraft:cobbled_deepslate"},
        {pos: [12, 1, 4], state: "minecraft:gravel"},
        {pos: [12, 1, 5], state: "minecraft:gravel"},
        {pos: [13, 1, 2], state: "minecraft:gravel"},
        {pos: [13, 1, 3], state: "minecraft:deepslate_bricks"},
        {pos: [13, 1, 4], state: "minecraft:gravel"},
        {pos: [0, 2, 4], state: "minecraft:deepslate_bricks"},
        {pos: [0, 2, 5], state: "minecraft:cobbled_deepslate"},
        {pos: [1, 2, 3], state: "minecraft:gravel"},
        {pos: [1, 2, 4], state: "minecraft:gravel"},
        {pos: [1, 2, 5], state: "minecraft:gravel"},
        {pos: [1, 2, 6], state: "minecraft:cobbled_deepslate"},
        {pos: [2, 2, 3], state: "minecraft:gravel"},
        {pos: [2, 2, 4], state: "minecraft:gravel"},
        {pos: [2, 2, 5], state: "minecraft:gravel"},
        {pos: [2, 2, 6], state: "minecraft:gravel"},
        {pos: [2, 2, 9], state: "minecraft:gravel"},
        {pos: [2, 2, 10], state: "minecraft:gravel"},
        {pos: [3, 2, 3], state: "minecraft:gravel"},
        {pos: [3, 2, 4], state: "minecraft:gravel"},
        {pos: [3, 2, 5], state: "minecraft:gravel"},
        {pos: [3, 2, 6], state: "minecraft:gravel"},
        {pos: [3, 2, 7], state: "minecraft:gravel"},
        {pos: [3, 2, 8], state: "minecraft:gravel"},
        {pos: [3, 2, 9], state: "minecraft:deepslate_bricks"},
        {pos: [3, 2, 10], state: "minecraft:gravel"},
        {pos: [4, 2, 1], state: "minecraft:gravel"},
        {pos: [4, 2, 2], state: "minecraft:gravel"},
        {pos: [4, 2, 3], state: "minecraft:gravel"},
        {pos: [4, 2, 5], state: "minecraft:gravel"},
        {pos: [4, 2, 6], state: "minecraft:gravel"},
        {pos: [4, 2, 7], state: "minecraft:gravel"},
        {pos: [4, 2, 8], state: "minecraft:gravel"},
        {pos: [4, 2, 9], state: "minecraft:deepslate_bricks"},
        {pos: [5, 2, 1], state: "minecraft:soul_fire"},
        {pos: [5, 2, 2], state: "minecraft:gravel"},
        {pos: [5, 2, 6], state: "minecraft:gravel"},
        {pos: [5, 2, 7], state: "minecraft:gravel"},
        {pos: [5, 2, 8], state: "minecraft:gravel"},
        {pos: [5, 2, 9], state: "minecraft:gravel"},
        {pos: [6, 2, 1], state: "minecraft:soul_fire"},
        {pos: [6, 2, 2], state: "minecraft:deepslate_brick_stairs{facing:north,half:top,shape:straight,waterlogged:false}"},
        {pos: [6, 2, 3], state: "minecraft:gravel"},
        {pos: [6, 2, 8], state: "minecraft:gravel"},
        {pos: [6, 2, 9], state: "minecraft:gravel"},
        {pos: [7, 2, 1], state: "minecraft:soul_fire"},
        {pos: [7, 2, 3], state: "minecraft:gravel"},
        {pos: [7, 2, 4], state: "minecraft:gravel"},
        {pos: [7, 2, 6], state: "minecraft:gravel"},
        {pos: [7, 2, 7], state: "minecraft:gravel"},
        {pos: [7, 2, 8], state: "minecraft:gravel"},
        {pos: [7, 2, 9], state: "minecraft:deepslate_bricks"},
        {pos: [7, 2, 10], state: "minecraft:gravel"},
        {pos: [8, 2, 0], state: "minecraft:gravel"},
        {pos: [8, 2, 1], state: "minecraft:cobbled_deepslate"},
        {pos: [8, 2, 2], state: "minecraft:gravel"},
        {pos: [8, 2, 3], state: "minecraft:gravel"},
        {pos: [8, 2, 4], state: "minecraft:gravel"},
        {pos: [8, 2, 5], state: "minecraft:gravel"},
        {pos: [8, 2, 6], state: "minecraft:gravel"},
        {pos: [8, 2, 7], state: "minecraft:gravel"},
        {pos: [8, 2, 8], state: "minecraft:gravel"},
        {pos: [8, 2, 9], state: "minecraft:deepslate_bricks"},
        {pos: [9, 2, 0], state: "minecraft:gravel"},
        {pos: [9, 2, 1], state: "minecraft:gravel"},
        {pos: [9, 2, 2], state: "minecraft:gravel"},
        {pos: [9, 2, 3], state: "minecraft:gravel"},
        {pos: [9, 2, 6], state: "minecraft:gravel"},
        {pos: [9, 2, 7], state: "minecraft:gravel"},
        {pos: [10, 2, 1], state: "minecraft:gravel"},
        {pos: [12, 2, 3], state: "minecraft:deepslate_bricks"},
        {pos: [12, 2, 4], state: "minecraft:cobbled_deepslate"},
        {pos: [12, 2, 5], state: "minecraft:gravel"},
        {pos: [13, 2, 2], state: "minecraft:gravel"},
        {pos: [13, 2, 3], state: "minecraft:gravel"},
        {pos: [13, 2, 4], state: "minecraft:gravel"},
        {pos: [0, 3, 4], state: "minecraft:gravel"},
        {pos: [0, 3, 5], state: "minecraft:cobbled_deepslate"},
        {pos: [1, 3, 3], state: "minecraft:gravel"},
        {pos: [1, 3, 4], state: "minecraft:gravel"},
        {pos: [1, 3, 5], state: "minecraft:gravel"},
        {pos: [1, 3, 6], state: "minecraft:gravel"},
        {pos: [2, 3, 9], state: "minecraft:gravel"},
        {pos: [2, 3, 10], state: "minecraft:gravel"},
        {pos: [3, 3, 7], state: "minecraft:gravel"},
        {pos: [3, 3, 8], state: "minecraft:gravel"},
        {pos: [3, 3, 9], state: "minecraft:deepslate_bricks"},
        {pos: [3, 3, 10], state: "minecraft:gravel"},
        {pos: [4, 3, 1], state: "minecraft:gravel"},
        {pos: [4, 3, 7], state: "minecraft:gravel"},
        {pos: [4, 3, 8], state: "minecraft:gravel"},
        {pos: [4, 3, 9], state: "minecraft:gravel"},
        {pos: [5, 3, 1], state: "minecraft:deepslate_bricks"},
        {pos: [5, 3, 2], state: "minecraft:gravel"},
        {pos: [6, 3, 1], state: "minecraft:deepslate_bricks"},
        {pos: [6, 3, 2], state: "minecraft:deepslate_bricks"},
        {pos: [6, 3, 8], state: "minecraft:gravel"},
        {pos: [6, 3, 9], state: "minecraft:gravel"},
        {pos: [7, 3, 1], state: "minecraft:cobbled_deepslate"},
        {pos: [7, 3, 2], state: "minecraft:cobbled_deepslate"},
        {pos: [7, 3, 3], state: "minecraft:gravel"},
        {pos: [7, 3, 8], state: "minecraft:gravel"},
        {pos: [7, 3, 9], state: "minecraft:deepslate_bricks"},
        {pos: [8, 3, 1], state: "minecraft:cobbled_deepslate"},
        {pos: [8, 3, 2], state: "minecraft:gravel"},
        {pos: [8, 3, 3], state: "minecraft:gravel"},
        {pos: [8, 3, 4], state: "minecraft:gravel"},
        {pos: [8, 3, 7], state: "minecraft:gravel"},
        {pos: [8, 3, 8], state: "minecraft:gravel"},
        {pos: [8, 3, 9], state: "minecraft:deepslate_bricks"},
        {pos: [12, 3, 3], state: "minecraft:gravel"},
        {pos: [12, 3, 4], state: "minecraft:gravel"},
        {pos: [3, 4, 9], state: "minecraft:gravel"},
        {pos: [8, 4, 9], state: "minecraft:deepslate_bricks"}
    ],
    entities: [],
    palette: [
        "minecraft:deepslate_bricks",
        "minecraft:cobbled_deepslate",
        "minecraft:polished_deepslate",
        "minecraft:gravel",
        "minecraft:deepslate_brick_stairs{facing:north,half:top,shape:straight,waterlogged:false}",
        "minecraft:soul_sand",
        "minecraft:deepslate_brick_stairs{facing:south,half:top,shape:straight,waterlogged:false}",
        "minecraft:soul_fire"
    ],
    trailiertales_DataVersion: 2
}
