{
    DataVersion: 3953,
    size: [15, 11, 5],
    data: [
        {pos: [5, 0, 0], state: "minecraft:deepslate{axis:y}"},
        {pos: [5, 0, 1], state: "minecraft:deepslate{axis:y}"},
        {pos: [5, 0, 2], state: "minecraft:deepslate{axis:y}"},
        {pos: [5, 0, 3], state: "minecraft:deepslate{axis:y}"},
        {pos: [5, 0, 4], state: "minecraft:deepslate{axis:y}"},
        {pos: [6, 0, 0], state: "minecraft:deepslate{axis:y}"},
        {pos: [6, 0, 1], state: "minecraft:deepslate{axis:y}"},
        {pos: [6, 0, 2], state: "minecraft:deepslate{axis:y}"},
        {pos: [6, 0, 3], state: "minecraft:deepslate{axis:y}"},
        {pos: [6, 0, 4], state: "minecraft:deepslate{axis:y}"},
        {pos: [7, 0, 0], state: "minecraft:deepslate{axis:y}"},
        {pos: [7, 0, 1], state: "minecraft:deepslate{axis:y}"},
        {pos: [7, 0, 2], state: "minecraft:deepslate{axis:y}"},
        {pos: [7, 0, 3], state: "minecraft:deepslate{axis:y}"},
        {pos: [7, 0, 4], state: "minecraft:deepslate{axis:y}"},
        {pos: [8, 0, 0], state: "minecraft:deepslate{axis:y}"},
        {pos: [8, 0, 1], state: "minecraft:deepslate{axis:y}"},
        {pos: [8, 0, 2], state: "minecraft:deepslate{axis:y}"},
        {pos: [8, 0, 3], state: "minecraft:deepslate{axis:y}"},
        {pos: [8, 0, 4], state: "minecraft:deepslate{axis:y}"},
        {pos: [9, 0, 0], state: "minecraft:deepslate{axis:y}"},
        {pos: [9, 0, 1], state: "minecraft:deepslate{axis:y}"},
        {pos: [9, 0, 2], state: "minecraft:deepslate{axis:y}"},
        {pos: [9, 0, 3], state: "minecraft:deepslate{axis:y}"},
        {pos: [9, 0, 4], state: "minecraft:deepslate{axis:y}"},
        {pos: [5, 1, 0], state: "minecraft:deepslate_bricks"},
        {pos: [5, 1, 1], state: "minecraft:deepslate_bricks"},
        {pos: [5, 1, 2], state: "minecraft:deepslate_bricks"},
        {pos: [5, 1, 3], state: "minecraft:deepslate_bricks"},
        {pos: [5, 1, 4], state: "minecraft:deepslate_bricks"},
        {pos: [6, 1, 0], state: "minecraft:deepslate_bricks"},
        {pos: [6, 1, 1], state: "minecraft:deepslate_bricks"},
        {pos: [6, 1, 2], state: "minecraft:deepslate_bricks"},
        {pos: [6, 1, 3], state: "minecraft:deepslate_bricks"},
        {pos: [6, 1, 4], state: "minecraft:deepslate_bricks"},
        {pos: [7, 1, 0], state: "minecraft:deepslate_bricks"},
        {pos: [7, 1, 1], state: "minecraft:deepslate_bricks"},
        {pos: [7, 1, 2], state: "minecraft:deepslate_bricks"},
        {pos: [7, 1, 3], state: "minecraft:deepslate_bricks"},
        {pos: [7, 1, 4], state: "minecraft:deepslate_bricks"},
        {pos: [8, 1, 0], state: "minecraft:deepslate_bricks"},
        {pos: [8, 1, 1], state: "minecraft:deepslate_bricks"},
        {pos: [8, 1, 2], state: "minecraft:deepslate_bricks"},
        {pos: [8, 1, 3], state: "minecraft:deepslate_bricks"},
        {pos: [8, 1, 4], state: "minecraft:deepslate_bricks"},
        {pos: [9, 1, 0], state: "minecraft:deepslate_bricks"},
        {pos: [9, 1, 1], state: "minecraft:deepslate_bricks"},
        {pos: [9, 1, 2], state: "minecraft:deepslate_bricks"},
        {pos: [9, 1, 3], state: "minecraft:deepslate_bricks"},
        {pos: [9, 1, 4], state: "minecraft:deepslate_bricks"},
        {pos: [5, 2, 0], state: "minecraft:deepslate_bricks"},
        {pos: [5, 2, 1], state: "minecraft:deepslate_bricks"},
        {pos: [5, 2, 2], state: "minecraft:deepslate_bricks"},
        {pos: [5, 2, 3], state: "minecraft:deepslate_bricks"},
        {pos: [5, 2, 4], state: "minecraft:deepslate_bricks"},
        {pos: [6, 2, 0], state: "minecraft:deepslate_bricks"},
        {pos: [6, 2, 1], state: "minecraft:pointed_dripstone{thickness:frustum,vertical_direction:up,waterlogged:false}"},
        {pos: [6, 2, 2], state: "minecraft:pointed_dripstone{thickness:frustum,vertical_direction:up,waterlogged:false}"},
        {pos: [6, 2, 3], state: "minecraft:pointed_dripstone{thickness:frustum,vertical_direction:up,waterlogged:false}"},
        {pos: [6, 2, 4], state: "minecraft:deepslate_bricks"},
        {pos: [7, 2, 0], state: "minecraft:deepslate_bricks"},
        {pos: [7, 2, 1], state: "minecraft:pointed_dripstone{thickness:frustum,vertical_direction:up,waterlogged:false}"},
        {pos: [7, 2, 2], state: "minecraft:pointed_dripstone{thickness:frustum,vertical_direction:up,waterlogged:false}"},
        {pos: [7, 2, 3], state: "minecraft:pointed_dripstone{thickness:frustum,vertical_direction:up,waterlogged:false}"},
        {pos: [7, 2, 4], state: "minecraft:deepslate_bricks"},
        {pos: [8, 2, 0], state: "minecraft:deepslate_bricks"},
        {pos: [8, 2, 1], state: "minecraft:pointed_dripstone{thickness:frustum,vertical_direction:up,waterlogged:false}"},
        {pos: [8, 2, 2], state: "minecraft:pointed_dripstone{thickness:frustum,vertical_direction:up,waterlogged:false}"},
        {pos: [8, 2, 3], state: "minecraft:pointed_dripstone{thickness:frustum,vertical_direction:up,waterlogged:false}"},
        {pos: [8, 2, 4], state: "minecraft:deepslate_bricks"},
        {pos: [9, 2, 0], state: "minecraft:deepslate_bricks"},
        {pos: [9, 2, 1], state: "minecraft:deepslate_bricks"},
        {pos: [9, 2, 2], state: "minecraft:deepslate_bricks"},
        {pos: [9, 2, 3], state: "minecraft:deepslate_bricks"},
        {pos: [9, 2, 4], state: "minecraft:deepslate_bricks"},
        {pos: [5, 3, 0], state: "minecraft:deepslate_bricks"},
        {pos: [5, 3, 1], state: "minecraft:deepslate_bricks"},
        {pos: [5, 3, 2], state: "minecraft:deepslate_bricks"},
        {pos: [5, 3, 3], state: "minecraft:deepslate_bricks"},
        {pos: [5, 3, 4], state: "minecraft:deepslate_bricks"},
        {pos: [6, 3, 0], state: "minecraft:deepslate_bricks"},
        {pos: [6, 3, 1], state: "minecraft:pointed_dripstone{thickness:tip,vertical_direction:up,waterlogged:false}"},
        {pos: [6, 3, 2], state: "minecraft:pointed_dripstone{thickness:tip,vertical_direction:up,waterlogged:false}"},
        {pos: [6, 3, 3], state: "minecraft:pointed_dripstone{thickness:tip,vertical_direction:up,waterlogged:false}"},
        {pos: [6, 3, 4], state: "minecraft:deepslate_bricks"},
        {pos: [7, 3, 0], state: "minecraft:deepslate_bricks"},
        {pos: [7, 3, 1], state: "minecraft:pointed_dripstone{thickness:tip,vertical_direction:up,waterlogged:false}"},
        {pos: [7, 3, 2], state: "minecraft:pointed_dripstone{thickness:tip,vertical_direction:up,waterlogged:false}"},
        {pos: [7, 3, 3], state: "minecraft:pointed_dripstone{thickness:tip,vertical_direction:up,waterlogged:false}"},
        {pos: [7, 3, 4], state: "minecraft:deepslate_bricks"},
        {pos: [8, 3, 0], state: "minecraft:deepslate_bricks"},
        {pos: [8, 3, 1], state: "minecraft:pointed_dripstone{thickness:tip,vertical_direction:up,waterlogged:false}"},
        {pos: [8, 3, 2], state: "minecraft:pointed_dripstone{thickness:tip,vertical_direction:up,waterlogged:false}"},
        {pos: [8, 3, 3], state: "minecraft:pointed_dripstone{thickness:tip,vertical_direction:up,waterlogged:false}"},
        {pos: [8, 3, 4], state: "minecraft:deepslate_bricks"},
        {pos: [9, 3, 0], state: "minecraft:deepslate_bricks"},
        {pos: [9, 3, 1], state: "minecraft:deepslate_bricks"},
        {pos: [9, 3, 2], state: "minecraft:deepslate_bricks"},
        {pos: [9, 3, 3], state: "minecraft:deepslate_bricks"},
        {pos: [9, 3, 4], state: "minecraft:deepslate_bricks"},
        {pos: [5, 4, 0], state: "minecraft:deepslate_bricks"},
        {pos: [5, 4, 1], state: "minecraft:deepslate_bricks"},
        {pos: [5, 4, 2], state: "minecraft:deepslate_bricks"},
        {pos: [5, 4, 3], state: "minecraft:deepslate_bricks"},
        {pos: [5, 4, 4], state: "minecraft:deepslate_bricks"},
        {pos: [6, 4, 0], state: "minecraft:deepslate_bricks"},
        {pos: [6, 4, 1], state: "minecraft:cave_air"},
        {pos: [6, 4, 2], state: "minecraft:cave_air"},
        {pos: [6, 4, 3], state: "minecraft:cave_air"},
        {pos: [6, 4, 4], state: "minecraft:deepslate_bricks"},
        {pos: [7, 4, 0], state: "minecraft:deepslate_bricks"},
        {pos: [7, 4, 1], state: "minecraft:cave_air"},
        {pos: [7, 4, 2], state: "minecraft:cave_air"},
        {pos: [7, 4, 3], state: "minecraft:cave_air"},
        {pos: [7, 4, 4], state: "minecraft:deepslate_bricks"},
        {pos: [8, 4, 0], state: "minecraft:deepslate_bricks"},
        {pos: [8, 4, 1], state: "minecraft:cave_air"},
        {pos: [8, 4, 2], state: "minecraft:cave_air"},
        {pos: [8, 4, 3], state: "minecraft:cave_air"},
        {pos: [8, 4, 4], state: "minecraft:deepslate_bricks"},
        {pos: [9, 4, 0], state: "minecraft:deepslate_bricks"},
        {pos: [9, 4, 1], state: "minecraft:deepslate_bricks"},
        {pos: [9, 4, 2], state: "minecraft:deepslate_bricks"},
        {pos: [9, 4, 3], state: "minecraft:deepslate_bricks"},
        {pos: [9, 4, 4], state: "minecraft:deepslate_bricks"},
        {pos: [0, 5, 0], state: "minecraft:deepslate{axis:y}"},
        {pos: [0, 5, 1], state: "minecraft:deepslate{axis:y}"},
        {pos: [0, 5, 2], state: "minecraft:deepslate{axis:y}"},
        {pos: [0, 5, 3], state: "minecraft:deepslate{axis:y}"},
        {pos: [0, 5, 4], state: "minecraft:deepslate{axis:y}"},
        {pos: [1, 5, 0], state: "minecraft:deepslate{axis:y}"},
        {pos: [1, 5, 1], state: "minecraft:deepslate{axis:y}"},
        {pos: [1, 5, 2], state: "minecraft:deepslate{axis:y}"},
        {pos: [1, 5, 3], state: "minecraft:deepslate{axis:y}"},
        {pos: [1, 5, 4], state: "minecraft:deepslate{axis:y}"},
        {pos: [2, 5, 0], state: "minecraft:deepslate{axis:y}"},
        {pos: [2, 5, 1], state: "minecraft:deepslate{axis:y}"},
        {pos: [2, 5, 2], state: "minecraft:deepslate{axis:y}"},
        {pos: [2, 5, 3], state: "minecraft:deepslate{axis:y}"},
        {pos: [2, 5, 4], state: "minecraft:deepslate{axis:y}"},
        {pos: [3, 5, 0], state: "minecraft:deepslate{axis:y}"},
        {pos: [3, 5, 1], state: "minecraft:deepslate{axis:y}"},
        {pos: [3, 5, 2], state: "minecraft:deepslate{axis:y}"},
        {pos: [3, 5, 3], state: "minecraft:deepslate{axis:y}"},
        {pos: [3, 5, 4], state: "minecraft:deepslate{axis:y}"},
        {pos: [4, 5, 0], state: "minecraft:deepslate{axis:y}"},
        {pos: [4, 5, 1], state: "minecraft:deepslate{axis:y}"},
        {pos: [4, 5, 2], state: "minecraft:deepslate{axis:y}"},
        {pos: [4, 5, 3], state: "minecraft:deepslate{axis:y}"},
        {pos: [4, 5, 4], state: "minecraft:deepslate{axis:y}"},
        {pos: [5, 5, 0], state: "minecraft:deepslate_bricks"},
        {pos: [5, 5, 1], state: "minecraft:deepslate_bricks"},
        {pos: [5, 5, 2], state: "minecraft:deepslate_bricks"},
        {pos: [5, 5, 3], state: "minecraft:deepslate_bricks"},
        {pos: [5, 5, 4], state: "minecraft:deepslate_bricks"},
        {pos: [6, 5, 0], state: "minecraft:deepslate_bricks"},
        {pos: [6, 5, 1], state: "minecraft:cave_air"},
        {pos: [6, 5, 2], state: "minecraft:cave_air"},
        {pos: [6, 5, 3], state: "minecraft:cave_air"},
        {pos: [6, 5, 4], state: "minecraft:deepslate_bricks"},
        {pos: [7, 5, 0], state: "minecraft:deepslate_bricks"},
        {pos: [7, 5, 1], state: "minecraft:cave_air"},
        {pos: [7, 5, 2], state: "minecraft:cave_air"},
        {pos: [7, 5, 3], state: "minecraft:cave_air"},
        {pos: [7, 5, 4], state: "minecraft:deepslate_bricks"},
        {pos: [8, 5, 0], state: "minecraft:deepslate_bricks"},
        {pos: [8, 5, 1], state: "minecraft:cave_air"},
        {pos: [8, 5, 2], state: "minecraft:cave_air"},
        {pos: [8, 5, 3], state: "minecraft:cave_air"},
        {pos: [8, 5, 4], state: "minecraft:deepslate_bricks"},
        {pos: [9, 5, 0], state: "minecraft:deepslate_bricks"},
        {pos: [9, 5, 1], state: "minecraft:deepslate_bricks"},
        {pos: [9, 5, 2], state: "minecraft:deepslate_bricks"},
        {pos: [9, 5, 3], state: "minecraft:deepslate_bricks"},
        {pos: [9, 5, 4], state: "minecraft:deepslate_bricks"},
        {pos: [10, 5, 0], state: "minecraft:deepslate{axis:y}"},
        {pos: [10, 5, 1], state: "minecraft:deepslate{axis:y}"},
        {pos: [10, 5, 2], state: "minecraft:deepslate{axis:y}"},
        {pos: [10, 5, 3], state: "minecraft:deepslate{axis:y}"},
        {pos: [10, 5, 4], state: "minecraft:deepslate{axis:y}"},
        {pos: [11, 5, 0], state: "minecraft:deepslate{axis:y}"},
        {pos: [11, 5, 1], state: "minecraft:deepslate{axis:y}"},
        {pos: [11, 5, 2], state: "minecraft:deepslate{axis:y}"},
        {pos: [11, 5, 3], state: "minecraft:deepslate{axis:y}"},
        {pos: [11, 5, 4], state: "minecraft:deepslate{axis:y}"},
        {pos: [12, 5, 0], state: "minecraft:deepslate{axis:y}"},
        {pos: [12, 5, 1], state: "minecraft:deepslate{axis:y}"},
        {pos: [12, 5, 2], state: "minecraft:deepslate{axis:y}"},
        {pos: [12, 5, 3], state: "minecraft:deepslate{axis:y}"},
        {pos: [12, 5, 4], state: "minecraft:deepslate{axis:y}"},
        {pos: [13, 5, 0], state: "minecraft:deepslate{axis:y}"},
        {pos: [13, 5, 1], state: "minecraft:deepslate{axis:y}"},
        {pos: [13, 5, 2], state: "minecraft:deepslate{axis:y}"},
        {pos: [13, 5, 3], state: "minecraft:deepslate{axis:y}"},
        {pos: [13, 5, 4], state: "minecraft:deepslate{axis:y}"},
        {pos: [14, 5, 0], state: "minecraft:deepslate{axis:y}"},
        {pos: [14, 5, 1], state: "minecraft:deepslate{axis:y}"},
        {pos: [14, 5, 2], state: "minecraft:deepslate{axis:y}"},
        {pos: [14, 5, 3], state: "minecraft:deepslate{axis:y}"},
        {pos: [14, 5, 4], state: "minecraft:deepslate{axis:y}"},
        {pos: [0, 6, 0], state: "minecraft:deepslate_bricks"},
        {pos: [0, 6, 1], state: "minecraft:gravel"},
        {pos: [0, 6, 2], state: "minecraft:gravel"},
        {pos: [0, 6, 3], state: "minecraft:gravel"},
        {pos: [0, 6, 4], state: "minecraft:deepslate_bricks"},
        {pos: [1, 6, 0], state: "minecraft:deepslate_bricks"},
        {pos: [1, 6, 1], state: "minecraft:gravel"},
        {pos: [1, 6, 2], state: "minecraft:gravel"},
        {pos: [1, 6, 3], state: "minecraft:gravel"},
        {pos: [1, 6, 4], state: "minecraft:deepslate_bricks"},
        {pos: [2, 6, 0], state: "minecraft:deepslate_bricks"},
        {pos: [2, 6, 1], state: "minecraft:gravel"},
        {pos: [2, 6, 2], state: "minecraft:gravel"},
        {pos: [2, 6, 3], state: "minecraft:gravel"},
        {pos: [2, 6, 4], state: "minecraft:deepslate_bricks"},
        {pos: [3, 6, 0], state: "minecraft:deepslate_bricks"},
        {pos: [3, 6, 1], state: "minecraft:gravel"},
        {pos: [3, 6, 2], state: "minecraft:gravel"},
        {pos: [3, 6, 3], state: "minecraft:gravel"},
        {pos: [3, 6, 4], state: "minecraft:deepslate_bricks"},
        {pos: [4, 6, 0], state: "minecraft:deepslate_bricks"},
        {pos: [4, 6, 1], state: "minecraft:gravel"},
        {pos: [4, 6, 2], state: "minecraft:gravel"},
        {pos: [4, 6, 3], state: "minecraft:gravel"},
        {pos: [4, 6, 4], state: "minecraft:deepslate_bricks"},
        {pos: [5, 6, 0], state: "minecraft:deepslate_bricks"},
        {pos: [5, 6, 1], state: "minecraft:gravel"},
        {pos: [5, 6, 2], state: "minecraft:gravel"},
        {pos: [5, 6, 3], state: "minecraft:gravel"},
        {pos: [5, 6, 4], state: "minecraft:deepslate_bricks"},
        {pos: [6, 6, 0], state: "minecraft:deepslate_bricks"},
        {pos: [6, 6, 1], state: "minecraft:cave_air"},
        {pos: [6, 6, 2], state: "minecraft:cave_air"},
        {pos: [6, 6, 3], state: "minecraft:cave_air"},
        {pos: [6, 6, 4], state: "minecraft:deepslate_bricks"},
        {pos: [7, 6, 0], state: "minecraft:deepslate_bricks"},
        {pos: [7, 6, 1], state: "minecraft:cave_air"},
        {pos: [7, 6, 2], state: "minecraft:cave_air"},
        {pos: [7, 6, 3], state: "minecraft:cave_air"},
        {pos: [7, 6, 4], state: "minecraft:deepslate_bricks"},
        {pos: [8, 6, 0], state: "minecraft:deepslate_bricks"},
        {pos: [8, 6, 1], state: "minecraft:cave_air"},
        {pos: [8, 6, 2], state: "minecraft:cave_air"},
        {pos: [8, 6, 3], state: "minecraft:cave_air"},
        {pos: [8, 6, 4], state: "minecraft:deepslate_bricks"},
        {pos: [9, 6, 0], state: "minecraft:deepslate_bricks"},
        {pos: [9, 6, 1], state: "minecraft:gravel"},
        {pos: [9, 6, 2], state: "minecraft:gravel"},
        {pos: [9, 6, 3], state: "minecraft:gravel"},
        {pos: [9, 6, 4], state: "minecraft:deepslate_bricks"},
        {pos: [10, 6, 0], state: "minecraft:deepslate_bricks"},
        {pos: [10, 6, 1], state: "minecraft:gravel"},
        {pos: [10, 6, 2], state: "minecraft:gravel"},
        {pos: [10, 6, 3], state: "minecraft:gravel"},
        {pos: [10, 6, 4], state: "minecraft:deepslate_bricks"},
        {pos: [11, 6, 0], state: "minecraft:deepslate_bricks"},
        {pos: [11, 6, 1], state: "minecraft:gravel"},
        {pos: [11, 6, 2], state: "minecraft:gravel"},
        {pos: [11, 6, 3], state: "minecraft:gravel"},
        {pos: [11, 6, 4], state: "minecraft:deepslate_bricks"},
        {pos: [12, 6, 0], state: "minecraft:deepslate_bricks"},
        {pos: [12, 6, 1], state: "minecraft:gravel"},
        {pos: [12, 6, 2], state: "minecraft:gravel"},
        {pos: [12, 6, 3], state: "minecraft:gravel"},
        {pos: [12, 6, 4], state: "minecraft:deepslate_bricks"},
        {pos: [13, 6, 0], state: "minecraft:deepslate_bricks"},
        {pos: [13, 6, 1], state: "minecraft:gravel"},
        {pos: [13, 6, 2], state: "minecraft:gravel"},
        {pos: [13, 6, 3], state: "minecraft:gravel"},
        {pos: [13, 6, 4], state: "minecraft:deepslate_bricks"},
        {pos: [14, 6, 0], state: "minecraft:deepslate_bricks"},
        {pos: [14, 6, 1], state: "minecraft:gravel"},
        {pos: [14, 6, 2], state: "minecraft:gravel"},
        {pos: [14, 6, 3], state: "minecraft:gravel"},
        {pos: [14, 6, 4], state: "minecraft:deepslate_bricks"},
        {pos: [0, 7, 0], state: "minecraft:deepslate_bricks"},
        {pos: [0, 7, 1], state: "minecraft:cave_air"},
        {pos: [0, 7, 2], state: "minecraft:jigsaw{orientation:west_up}", nbt: {final_state: "minecraft:cave_air", id: "minecraft:jigsaw", joint: "rollable", name: "trailiertales:corridor", placement_priority: 0, pool: "trailiertales:catacombs/corridor", selection_priority: 0, target: "trailiertales:corridor"}},
        {pos: [0, 7, 3], state: "minecraft:cave_air"},
        {pos: [0, 7, 4], state: "minecraft:deepslate_bricks"},
        {pos: [1, 7, 0], state: "minecraft:deepslate_bricks"},
        {pos: [1, 7, 1], state: "minecraft:cave_air"},
        {pos: [1, 7, 2], state: "minecraft:cave_air"},
        {pos: [1, 7, 3], state: "minecraft:cave_air"},
        {pos: [1, 7, 4], state: "minecraft:deepslate_bricks"},
        {pos: [2, 7, 0], state: "minecraft:deepslate_bricks"},
        {pos: [2, 7, 1], state: "minecraft:cave_air"},
        {pos: [2, 7, 2], state: "minecraft:cave_air"},
        {pos: [2, 7, 3], state: "minecraft:cave_air"},
        {pos: [2, 7, 4], state: "minecraft:deepslate_bricks"},
        {pos: [3, 7, 0], state: "minecraft:deepslate_bricks"},
        {pos: [3, 7, 1], state: "minecraft:cave_air"},
        {pos: [3, 7, 2], state: "minecraft:cave_air"},
        {pos: [3, 7, 3], state: "minecraft:cave_air"},
        {pos: [3, 7, 4], state: "minecraft:deepslate_bricks"},
        {pos: [4, 7, 0], state: "minecraft:deepslate_bricks"},
        {pos: [4, 7, 1], state: "minecraft:cave_air"},
        {pos: [4, 7, 2], state: "minecraft:cave_air"},
        {pos: [4, 7, 3], state: "minecraft:cave_air"},
        {pos: [4, 7, 4], state: "minecraft:deepslate_bricks"},
        {pos: [5, 7, 0], state: "minecraft:deepslate_bricks"},
        {pos: [5, 7, 1], state: "minecraft:cave_air"},
        {pos: [5, 7, 2], state: "minecraft:cave_air"},
        {pos: [5, 7, 3], state: "minecraft:cave_air"},
        {pos: [5, 7, 4], state: "minecraft:deepslate_bricks"},
        {pos: [6, 7, 0], state: "minecraft:deepslate_bricks"},
        {pos: [6, 7, 1], state: "minecraft:cave_air"},
        {pos: [6, 7, 2], state: "minecraft:cave_air"},
        {pos: [6, 7, 3], state: "minecraft:cave_air"},
        {pos: [6, 7, 4], state: "minecraft:deepslate_bricks"},
        {pos: [7, 7, 0], state: "minecraft:deepslate_bricks"},
        {pos: [7, 7, 1], state: "minecraft:cave_air"},
        {pos: [7, 7, 2], state: "minecraft:cave_air"},
        {pos: [7, 7, 3], state: "minecraft:cave_air"},
        {pos: [7, 7, 4], state: "minecraft:deepslate_bricks"},
        {pos: [8, 7, 0], state: "minecraft:deepslate_bricks"},
        {pos: [8, 7, 1], state: "minecraft:cave_air"},
        {pos: [8, 7, 2], state: "minecraft:cave_air"},
        {pos: [8, 7, 3], state: "minecraft:cave_air"},
        {pos: [8, 7, 4], state: "minecraft:deepslate_bricks"},
        {pos: [9, 7, 0], state: "minecraft:deepslate_bricks"},
        {pos: [9, 7, 1], state: "minecraft:cave_air"},
        {pos: [9, 7, 2], state: "minecraft:cave_air"},
        {pos: [9, 7, 3], state: "minecraft:cave_air"},
        {pos: [9, 7, 4], state: "minecraft:deepslate_bricks"},
        {pos: [10, 7, 0], state: "minecraft:deepslate_bricks"},
        {pos: [10, 7, 1], state: "minecraft:cave_air"},
        {pos: [10, 7, 2], state: "minecraft:cave_air"},
        {pos: [10, 7, 3], state: "minecraft:cave_air"},
        {pos: [10, 7, 4], state: "minecraft:deepslate_bricks"},
        {pos: [11, 7, 0], state: "minecraft:deepslate_bricks"},
        {pos: [11, 7, 1], state: "minecraft:cave_air"},
        {pos: [11, 7, 2], state: "minecraft:cave_air"},
        {pos: [11, 7, 3], state: "minecraft:cave_air"},
        {pos: [11, 7, 4], state: "minecraft:deepslate_bricks"},
        {pos: [12, 7, 0], state: "minecraft:deepslate_bricks"},
        {pos: [12, 7, 1], state: "minecraft:cave_air"},
        {pos: [12, 7, 2], state: "minecraft:cave_air"},
        {pos: [12, 7, 3], state: "minecraft:cave_air"},
        {pos: [12, 7, 4], state: "minecraft:deepslate_bricks"},
        {pos: [13, 7, 0], state: "minecraft:deepslate_bricks"},
        {pos: [13, 7, 1], state: "minecraft:cave_air"},
        {pos: [13, 7, 2], state: "minecraft:cave_air"},
        {pos: [13, 7, 3], state: "minecraft:cave_air"},
        {pos: [13, 7, 4], state: "minecraft:deepslate_bricks"},
        {pos: [14, 7, 0], state: "minecraft:deepslate_bricks"},
        {pos: [14, 7, 1], state: "minecraft:cave_air"},
        {pos: [14, 7, 2], state: "minecraft:jigsaw{orientation:east_up}", nbt: {final_state: "minecraft:cave_air", id: "minecraft:jigsaw", joint: "rollable", name: "trailiertales:corridor", placement_priority: 0, pool: "trailiertales:catacombs/corridor", selection_priority: 0, target: "trailiertales:corridor"}},
        {pos: [14, 7, 3], state: "minecraft:cave_air"},
        {pos: [14, 7, 4], state: "minecraft:deepslate_bricks"},
        {pos: [0, 8, 0], state: "minecraft:deepslate_bricks"},
        {pos: [0, 8, 1], state: "minecraft:cave_air"},
        {pos: [0, 8, 2], state: "minecraft:cave_air"},
        {pos: [0, 8, 3], state: "minecraft:cave_air"},
        {pos: [0, 8, 4], state: "minecraft:deepslate_bricks"},
        {pos: [1, 8, 0], state: "minecraft:polished_deepslate"},
        {pos: [1, 8, 1], state: "minecraft:cave_air"},
        {pos: [1, 8, 2], state: "minecraft:cave_air"},
        {pos: [1, 8, 3], state: "minecraft:cave_air"},
        {pos: [1, 8, 4], state: "minecraft:polished_deepslate"},
        {pos: [2, 8, 0], state: "minecraft:deepslate_bricks"},
        {pos: [2, 8, 1], state: "minecraft:cave_air"},
        {pos: [2, 8, 2], state: "minecraft:cave_air"},
        {pos: [2, 8, 3], state: "minecraft:cave_air"},
        {pos: [2, 8, 4], state: "minecraft:deepslate_bricks"},
        {pos: [3, 8, 0], state: "minecraft:deepslate_bricks"},
        {pos: [3, 8, 1], state: "minecraft:cave_air"},
        {pos: [3, 8, 2], state: "minecraft:cave_air"},
        {pos: [3, 8, 3], state: "minecraft:cave_air"},
        {pos: [3, 8, 4], state: "minecraft:deepslate_bricks"},
        {pos: [4, 8, 0], state: "minecraft:deepslate_bricks"},
        {pos: [4, 8, 1], state: "minecraft:cave_air"},
        {pos: [4, 8, 2], state: "minecraft:cave_air"},
        {pos: [4, 8, 3], state: "minecraft:cave_air"},
        {pos: [4, 8, 4], state: "minecraft:deepslate_bricks"},
        {pos: [5, 8, 0], state: "minecraft:deepslate_bricks"},
        {pos: [5, 8, 1], state: "minecraft:cave_air"},
        {pos: [5, 8, 2], state: "minecraft:cave_air"},
        {pos: [5, 8, 3], state: "minecraft:cave_air"},
        {pos: [5, 8, 4], state: "minecraft:deepslate_bricks"},
        {pos: [6, 8, 0], state: "minecraft:deepslate_bricks"},
        {pos: [6, 8, 1], state: "minecraft:cave_air"},
        {pos: [6, 8, 2], state: "minecraft:cave_air"},
        {pos: [6, 8, 3], state: "minecraft:cave_air"},
        {pos: [6, 8, 4], state: "minecraft:deepslate_bricks"},
        {pos: [7, 8, 0], state: "minecraft:deepslate_bricks"},
        {pos: [7, 8, 1], state: "minecraft:cave_air"},
        {pos: [7, 8, 2], state: "minecraft:cave_air"},
        {pos: [7, 8, 3], state: "minecraft:cave_air"},
        {pos: [7, 8, 4], state: "minecraft:deepslate_bricks"},
        {pos: [8, 8, 0], state: "minecraft:deepslate_bricks"},
        {pos: [8, 8, 1], state: "minecraft:cave_air"},
        {pos: [8, 8, 2], state: "minecraft:cave_air"},
        {pos: [8, 8, 3], state: "minecraft:cave_air"},
        {pos: [8, 8, 4], state: "minecraft:deepslate_bricks"},
        {pos: [9, 8, 0], state: "minecraft:deepslate_bricks"},
        {pos: [9, 8, 1], state: "minecraft:cave_air"},
        {pos: [9, 8, 2], state: "minecraft:cave_air"},
        {pos: [9, 8, 3], state: "minecraft:cave_air"},
        {pos: [9, 8, 4], state: "minecraft:deepslate_bricks"},
        {pos: [10, 8, 0], state: "minecraft:deepslate_bricks"},
        {pos: [10, 8, 1], state: "minecraft:cave_air"},
        {pos: [10, 8, 2], state: "minecraft:cave_air"},
        {pos: [10, 8, 3], state: "minecraft:cave_air"},
        {pos: [10, 8, 4], state: "minecraft:deepslate_bricks"},
        {pos: [11, 8, 0], state: "minecraft:deepslate_bricks"},
        {pos: [11, 8, 1], state: "minecraft:cave_air"},
        {pos: [11, 8, 2], state: "minecraft:cave_air"},
        {pos: [11, 8, 3], state: "minecraft:cave_air"},
        {pos: [11, 8, 4], state: "minecraft:deepslate_bricks"},
        {pos: [12, 8, 0], state: "minecraft:deepslate_bricks"},
        {pos: [12, 8, 1], state: "minecraft:cave_air"},
        {pos: [12, 8, 2], state: "minecraft:cave_air"},
        {pos: [12, 8, 3], state: "minecraft:cave_air"},
        {pos: [12, 8, 4], state: "minecraft:deepslate_bricks"},
        {pos: [13, 8, 0], state: "minecraft:polished_deepslate"},
        {pos: [13, 8, 1], state: "minecraft:cave_air"},
        {pos: [13, 8, 2], state: "minecraft:cave_air"},
        {pos: [13, 8, 3], state: "minecraft:cave_air"},
        {pos: [13, 8, 4], state: "minecraft:polished_deepslate"},
        {pos: [14, 8, 0], state: "minecraft:deepslate_bricks"},
        {pos: [14, 8, 1], state: "minecraft:cave_air"},
        {pos: [14, 8, 2], state: "minecraft:cave_air"},
        {pos: [14, 8, 3], state: "minecraft:cave_air"},
        {pos: [14, 8, 4], state: "minecraft:deepslate_bricks"},
        {pos: [0, 9, 0], state: "minecraft:deepslate_bricks"},
        {pos: [0, 9, 1], state: "minecraft:cave_air"},
        {pos: [0, 9, 2], state: "minecraft:cave_air"},
        {pos: [0, 9, 3], state: "minecraft:cave_air"},
        {pos: [0, 9, 4], state: "minecraft:deepslate_bricks"},
        {pos: [1, 9, 0], state: "minecraft:deepslate_bricks"},
        {pos: [1, 9, 1], state: "minecraft:cave_air"},
        {pos: [1, 9, 2], state: "minecraft:cave_air"},
        {pos: [1, 9, 3], state: "minecraft:cave_air"},
        {pos: [1, 9, 4], state: "minecraft:deepslate_bricks"},
        {pos: [2, 9, 0], state: "minecraft:deepslate_bricks"},
        {pos: [2, 9, 1], state: "minecraft:cave_air"},
        {pos: [2, 9, 2], state: "minecraft:cave_air"},
        {pos: [2, 9, 3], state: "minecraft:cave_air"},
        {pos: [2, 9, 4], state: "minecraft:deepslate_bricks"},
        {pos: [3, 9, 0], state: "minecraft:deepslate_bricks"},
        {pos: [3, 9, 1], state: "minecraft:cave_air"},
        {pos: [3, 9, 2], state: "minecraft:cave_air"},
        {pos: [3, 9, 3], state: "minecraft:cave_air"},
        {pos: [3, 9, 4], state: "minecraft:deepslate_bricks"},
        {pos: [4, 9, 0], state: "minecraft:deepslate_bricks"},
        {pos: [4, 9, 1], state: "minecraft:cave_air"},
        {pos: [4, 9, 2], state: "minecraft:cave_air"},
        {pos: [4, 9, 3], state: "minecraft:cave_air"},
        {pos: [4, 9, 4], state: "minecraft:deepslate_bricks"},
        {pos: [5, 9, 0], state: "minecraft:deepslate_bricks"},
        {pos: [5, 9, 1], state: "minecraft:cave_air"},
        {pos: [5, 9, 2], state: "minecraft:cave_air"},
        {pos: [5, 9, 3], state: "minecraft:cave_air"},
        {pos: [5, 9, 4], state: "minecraft:deepslate_bricks"},
        {pos: [6, 9, 0], state: "minecraft:deepslate_bricks"},
        {pos: [6, 9, 1], state: "minecraft:cave_air"},
        {pos: [6, 9, 2], state: "minecraft:cave_air"},
        {pos: [6, 9, 3], state: "minecraft:cave_air"},
        {pos: [6, 9, 4], state: "minecraft:deepslate_bricks"},
        {pos: [7, 9, 0], state: "minecraft:deepslate_bricks"},
        {pos: [7, 9, 1], state: "minecraft:cave_air"},
        {pos: [7, 9, 2], state: "minecraft:cave_air"},
        {pos: [7, 9, 3], state: "minecraft:cave_air"},
        {pos: [7, 9, 4], state: "minecraft:deepslate_bricks"},
        {pos: [8, 9, 0], state: "minecraft:deepslate_bricks"},
        {pos: [8, 9, 1], state: "minecraft:cave_air"},
        {pos: [8, 9, 2], state: "minecraft:cave_air"},
        {pos: [8, 9, 3], state: "minecraft:cave_air"},
        {pos: [8, 9, 4], state: "minecraft:deepslate_bricks"},
        {pos: [9, 9, 0], state: "minecraft:deepslate_bricks"},
        {pos: [9, 9, 1], state: "minecraft:cave_air"},
        {pos: [9, 9, 2], state: "minecraft:cave_air"},
        {pos: [9, 9, 3], state: "minecraft:cave_air"},
        {pos: [9, 9, 4], state: "minecraft:deepslate_bricks"},
        {pos: [10, 9, 0], state: "minecraft:deepslate_bricks"},
        {pos: [10, 9, 1], state: "minecraft:cave_air"},
        {pos: [10, 9, 2], state: "minecraft:cave_air"},
        {pos: [10, 9, 3], state: "minecraft:cave_air"},
        {pos: [10, 9, 4], state: "minecraft:deepslate_bricks"},
        {pos: [11, 9, 0], state: "minecraft:deepslate_bricks"},
        {pos: [11, 9, 1], state: "minecraft:cave_air"},
        {pos: [11, 9, 2], state: "minecraft:cave_air"},
        {pos: [11, 9, 3], state: "minecraft:cave_air"},
        {pos: [11, 9, 4], state: "minecraft:deepslate_bricks"},
        {pos: [12, 9, 0], state: "minecraft:deepslate_bricks"},
        {pos: [12, 9, 1], state: "minecraft:cave_air"},
        {pos: [12, 9, 2], state: "minecraft:cave_air"},
        {pos: [12, 9, 3], state: "minecraft:cave_air"},
        {pos: [12, 9, 4], state: "minecraft:deepslate_bricks"},
        {pos: [13, 9, 0], state: "minecraft:deepslate_bricks"},
        {pos: [13, 9, 1], state: "minecraft:cave_air"},
        {pos: [13, 9, 2], state: "minecraft:cave_air"},
        {pos: [13, 9, 3], state: "minecraft:cave_air"},
        {pos: [13, 9, 4], state: "minecraft:deepslate_bricks"},
        {pos: [14, 9, 0], state: "minecraft:deepslate_bricks"},
        {pos: [14, 9, 1], state: "minecraft:cave_air"},
        {pos: [14, 9, 2], state: "minecraft:cave_air"},
        {pos: [14, 9, 3], state: "minecraft:cave_air"},
        {pos: [14, 9, 4], state: "minecraft:deepslate_bricks"},
        {pos: [0, 10, 0], state: "minecraft:deepslate_bricks"},
        {pos: [0, 10, 1], state: "minecraft:deepslate_bricks"},
        {pos: [0, 10, 2], state: "minecraft:deepslate_bricks"},
        {pos: [0, 10, 3], state: "minecraft:deepslate_bricks"},
        {pos: [0, 10, 4], state: "minecraft:deepslate_bricks"},
        {pos: [1, 10, 0], state: "minecraft:deepslate_bricks"},
        {pos: [1, 10, 1], state: "minecraft:deepslate_bricks"},
        {pos: [1, 10, 2], state: "minecraft:deepslate_bricks"},
        {pos: [1, 10, 3], state: "minecraft:deepslate_bricks"},
        {pos: [1, 10, 4], state: "minecraft:deepslate_bricks"},
        {pos: [2, 10, 0], state: "minecraft:deepslate_bricks"},
        {pos: [2, 10, 1], state: "minecraft:deepslate_bricks"},
        {pos: [2, 10, 2], state: "minecraft:deepslate_bricks"},
        {pos: [2, 10, 3], state: "minecraft:deepslate_bricks"},
        {pos: [2, 10, 4], state: "minecraft:deepslate_bricks"},
        {pos: [3, 10, 0], state: "minecraft:deepslate_bricks"},
        {pos: [3, 10, 1], state: "minecraft:deepslate_bricks"},
        {pos: [3, 10, 2], state: "minecraft:deepslate_bricks"},
        {pos: [3, 10, 3], state: "minecraft:deepslate_bricks"},
        {pos: [3, 10, 4], state: "minecraft:deepslate_bricks"},
        {pos: [4, 10, 0], state: "minecraft:deepslate_bricks"},
        {pos: [4, 10, 1], state: "minecraft:deepslate_bricks"},
        {pos: [4, 10, 2], state: "minecraft:deepslate_bricks"},
        {pos: [4, 10, 3], state: "minecraft:deepslate_bricks"},
        {pos: [4, 10, 4], state: "minecraft:deepslate_bricks"},
        {pos: [5, 10, 0], state: "minecraft:deepslate_bricks"},
        {pos: [5, 10, 1], state: "minecraft:deepslate_bricks"},
        {pos: [5, 10, 2], state: "minecraft:deepslate_bricks"},
        {pos: [5, 10, 3], state: "minecraft:deepslate_bricks"},
        {pos: [5, 10, 4], state: "minecraft:deepslate_bricks"},
        {pos: [6, 10, 0], state: "minecraft:deepslate_bricks"},
        {pos: [6, 10, 1], state: "minecraft:deepslate_bricks"},
        {pos: [6, 10, 2], state: "minecraft:deepslate_bricks"},
        {pos: [6, 10, 3], state: "minecraft:deepslate_bricks"},
        {pos: [6, 10, 4], state: "minecraft:deepslate_bricks"},
        {pos: [7, 10, 0], state: "minecraft:deepslate_bricks"},
        {pos: [7, 10, 1], state: "minecraft:deepslate_bricks"},
        {pos: [7, 10, 2], state: "minecraft:deepslate_bricks"},
        {pos: [7, 10, 3], state: "minecraft:deepslate_bricks"},
        {pos: [7, 10, 4], state: "minecraft:deepslate_bricks"},
        {pos: [8, 10, 0], state: "minecraft:deepslate_bricks"},
        {pos: [8, 10, 1], state: "minecraft:deepslate_bricks"},
        {pos: [8, 10, 2], state: "minecraft:deepslate_bricks"},
        {pos: [8, 10, 3], state: "minecraft:deepslate_bricks"},
        {pos: [8, 10, 4], state: "minecraft:deepslate_bricks"},
        {pos: [9, 10, 0], state: "minecraft:deepslate_bricks"},
        {pos: [9, 10, 1], state: "minecraft:deepslate_bricks"},
        {pos: [9, 10, 2], state: "minecraft:deepslate_bricks"},
        {pos: [9, 10, 3], state: "minecraft:deepslate_bricks"},
        {pos: [9, 10, 4], state: "minecraft:deepslate_bricks"},
        {pos: [10, 10, 0], state: "minecraft:deepslate_bricks"},
        {pos: [10, 10, 1], state: "minecraft:deepslate_bricks"},
        {pos: [10, 10, 2], state: "minecraft:deepslate_bricks"},
        {pos: [10, 10, 3], state: "minecraft:deepslate_bricks"},
        {pos: [10, 10, 4], state: "minecraft:deepslate_bricks"},
        {pos: [11, 10, 0], state: "minecraft:deepslate_bricks"},
        {pos: [11, 10, 1], state: "minecraft:deepslate_bricks"},
        {pos: [11, 10, 2], state: "minecraft:deepslate_bricks"},
        {pos: [11, 10, 3], state: "minecraft:deepslate_bricks"},
        {pos: [11, 10, 4], state: "minecraft:deepslate_bricks"},
        {pos: [12, 10, 0], state: "minecraft:deepslate_bricks"},
        {pos: [12, 10, 1], state: "minecraft:deepslate_bricks"},
        {pos: [12, 10, 2], state: "minecraft:deepslate_bricks"},
        {pos: [12, 10, 3], state: "minecraft:deepslate_bricks"},
        {pos: [12, 10, 4], state: "minecraft:deepslate_bricks"},
        {pos: [13, 10, 0], state: "minecraft:deepslate_bricks"},
        {pos: [13, 10, 1], state: "minecraft:deepslate_bricks"},
        {pos: [13, 10, 2], state: "minecraft:deepslate_bricks"},
        {pos: [13, 10, 3], state: "minecraft:deepslate_bricks"},
        {pos: [13, 10, 4], state: "minecraft:deepslate_bricks"},
        {pos: [14, 10, 0], state: "minecraft:deepslate_bricks"},
        {pos: [14, 10, 1], state: "minecraft:deepslate_bricks"},
        {pos: [14, 10, 2], state: "minecraft:deepslate_bricks"},
        {pos: [14, 10, 3], state: "minecraft:deepslate_bricks"},
        {pos: [14, 10, 4], state: "minecraft:deepslate_bricks"}
    ],
    entities: [],
    palette: [
        "minecraft:deepslate{axis:y}",
        "minecraft:deepslate_bricks",
        "minecraft:polished_deepslate",
        "minecraft:pointed_dripstone{thickness:frustum,vertical_direction:up,waterlogged:false}",
        "minecraft:pointed_dripstone{thickness:tip,vertical_direction:up,waterlogged:false}",
        "minecraft:cave_air",
        "minecraft:gravel",
        "minecraft:jigsaw{orientation:west_up}",
        "minecraft:jigsaw{orientation:east_up}"
    ],
    trailiertales_DataVersion: 3
}
