{
    DataVersion: 3953,
    size: [15, 6, 5],
    data: [
        {pos: [0, 0, 0], state: "minecraft:deepslate{axis:y}"},
        {pos: [0, 0, 1], state: "minecraft:deepslate{axis:y}"},
        {pos: [0, 0, 2], state: "minecraft:deepslate{axis:y}"},
        {pos: [0, 0, 3], state: "minecraft:deepslate{axis:y}"},
        {pos: [0, 0, 4], state: "minecraft:deepslate{axis:y}"},
        {pos: [1, 0, 0], state: "minecraft:deepslate{axis:y}"},
        {pos: [1, 0, 1], state: "minecraft:deepslate{axis:y}"},
        {pos: [1, 0, 2], state: "minecraft:deepslate{axis:y}"},
        {pos: [1, 0, 3], state: "minecraft:deepslate{axis:y}"},
        {pos: [1, 0, 4], state: "minecraft:deepslate{axis:y}"},
        {pos: [2, 0, 0], state: "minecraft:deepslate{axis:y}"},
        {pos: [2, 0, 1], state: "minecraft:deepslate{axis:y}"},
        {pos: [2, 0, 2], state: "minecraft:deepslate{axis:y}"},
        {pos: [2, 0, 3], state: "minecraft:deepslate{axis:y}"},
        {pos: [2, 0, 4], state: "minecraft:deepslate{axis:y}"},
        {pos: [3, 0, 0], state: "minecraft:deepslate{axis:y}"},
        {pos: [3, 0, 1], state: "minecraft:deepslate{axis:y}"},
        {pos: [3, 0, 2], state: "minecraft:deepslate{axis:y}"},
        {pos: [3, 0, 3], state: "minecraft:deepslate{axis:y}"},
        {pos: [3, 0, 4], state: "minecraft:deepslate{axis:y}"},
        {pos: [4, 0, 0], state: "minecraft:deepslate{axis:y}"},
        {pos: [4, 0, 1], state: "minecraft:deepslate{axis:y}"},
        {pos: [4, 0, 2], state: "minecraft:deepslate{axis:y}"},
        {pos: [4, 0, 3], state: "minecraft:deepslate{axis:y}"},
        {pos: [4, 0, 4], state: "minecraft:deepslate{axis:y}"},
        {pos: [5, 0, 0], state: "minecraft:deepslate{axis:y}"},
        {pos: [5, 0, 1], state: "minecraft:deepslate{axis:y}"},
        {pos: [5, 0, 2], state: "minecraft:deepslate{axis:y}"},
        {pos: [5, 0, 3], state: "minecraft:deepslate{axis:y}"},
        {pos: [5, 0, 4], state: "minecraft:deepslate{axis:y}"},
        {pos: [6, 0, 0], state: "minecraft:deepslate{axis:y}"},
        {pos: [6, 0, 1], state: "minecraft:deepslate{axis:y}"},
        {pos: [6, 0, 2], state: "minecraft:deepslate{axis:y}"},
        {pos: [6, 0, 3], state: "minecraft:deepslate{axis:y}"},
        {pos: [6, 0, 4], state: "minecraft:deepslate{axis:y}"},
        {pos: [7, 0, 0], state: "minecraft:deepslate{axis:y}"},
        {pos: [7, 0, 1], state: "minecraft:deepslate{axis:y}"},
        {pos: [7, 0, 2], state: "minecraft:deepslate{axis:y}"},
        {pos: [7, 0, 3], state: "minecraft:deepslate{axis:y}"},
        {pos: [7, 0, 4], state: "minecraft:deepslate{axis:y}"},
        {pos: [8, 0, 0], state: "minecraft:deepslate{axis:y}"},
        {pos: [8, 0, 1], state: "minecraft:deepslate{axis:y}"},
        {pos: [8, 0, 2], state: "minecraft:deepslate{axis:y}"},
        {pos: [8, 0, 3], state: "minecraft:deepslate{axis:y}"},
        {pos: [8, 0, 4], state: "minecraft:deepslate{axis:y}"},
        {pos: [9, 0, 0], state: "minecraft:deepslate{axis:y}"},
        {pos: [9, 0, 1], state: "minecraft:deepslate{axis:y}"},
        {pos: [9, 0, 2], state: "minecraft:deepslate{axis:y}"},
        {pos: [9, 0, 3], state: "minecraft:deepslate{axis:y}"},
        {pos: [9, 0, 4], state: "minecraft:deepslate{axis:y}"},
        {pos: [10, 0, 0], state: "minecraft:deepslate{axis:y}"},
        {pos: [10, 0, 1], state: "minecraft:deepslate{axis:y}"},
        {pos: [10, 0, 2], state: "minecraft:deepslate{axis:y}"},
        {pos: [10, 0, 3], state: "minecraft:deepslate{axis:y}"},
        {pos: [10, 0, 4], state: "minecraft:deepslate{axis:y}"},
        {pos: [11, 0, 0], state: "minecraft:deepslate{axis:y}"},
        {pos: [11, 0, 1], state: "minecraft:deepslate{axis:y}"},
        {pos: [11, 0, 2], state: "minecraft:deepslate{axis:y}"},
        {pos: [11, 0, 3], state: "minecraft:deepslate{axis:y}"},
        {pos: [11, 0, 4], state: "minecraft:deepslate{axis:y}"},
        {pos: [12, 0, 0], state: "minecraft:deepslate{axis:y}"},
        {pos: [12, 0, 1], state: "minecraft:deepslate{axis:y}"},
        {pos: [12, 0, 2], state: "minecraft:deepslate{axis:y}"},
        {pos: [12, 0, 3], state: "minecraft:deepslate{axis:y}"},
        {pos: [12, 0, 4], state: "minecraft:deepslate{axis:y}"},
        {pos: [13, 0, 0], state: "minecraft:deepslate{axis:y}"},
        {pos: [13, 0, 1], state: "minecraft:deepslate{axis:y}"},
        {pos: [13, 0, 2], state: "minecraft:deepslate{axis:y}"},
        {pos: [13, 0, 3], state: "minecraft:deepslate{axis:y}"},
        {pos: [13, 0, 4], state: "minecraft:deepslate{axis:y}"},
        {pos: [14, 0, 0], state: "minecraft:deepslate{axis:y}"},
        {pos: [14, 0, 1], state: "minecraft:deepslate{axis:y}"},
        {pos: [14, 0, 2], state: "minecraft:deepslate{axis:y}"},
        {pos: [14, 0, 3], state: "minecraft:deepslate{axis:y}"},
        {pos: [14, 0, 4], state: "minecraft:deepslate{axis:y}"},
        {pos: [0, 1, 0], state: "minecraft:deepslate_bricks"},
        {pos: [0, 1, 1], state: "minecraft:gravel"},
        {pos: [0, 1, 2], state: "minecraft:gravel"},
        {pos: [0, 1, 3], state: "minecraft:gravel"},
        {pos: [0, 1, 4], state: "minecraft:deepslate_bricks"},
        {pos: [1, 1, 0], state: "minecraft:deepslate_bricks"},
        {pos: [1, 1, 1], state: "minecraft:gravel"},
        {pos: [1, 1, 2], state: "minecraft:gravel"},
        {pos: [1, 1, 3], state: "minecraft:gravel"},
        {pos: [1, 1, 4], state: "minecraft:deepslate_bricks"},
        {pos: [2, 1, 0], state: "minecraft:deepslate_bricks"},
        {pos: [2, 1, 1], state: "minecraft:gravel"},
        {pos: [2, 1, 2], state: "minecraft:gravel"},
        {pos: [2, 1, 3], state: "minecraft:gravel"},
        {pos: [2, 1, 4], state: "minecraft:deepslate_bricks"},
        {pos: [3, 1, 0], state: "minecraft:deepslate_bricks"},
        {pos: [3, 1, 1], state: "minecraft:gravel"},
        {pos: [3, 1, 2], state: "minecraft:gravel"},
        {pos: [3, 1, 3], state: "minecraft:gravel"},
        {pos: [3, 1, 4], state: "minecraft:deepslate_bricks"},
        {pos: [4, 1, 0], state: "minecraft:deepslate_bricks"},
        {pos: [4, 1, 1], state: "minecraft:gravel"},
        {pos: [4, 1, 2], state: "minecraft:gravel"},
        {pos: [4, 1, 3], state: "minecraft:gravel"},
        {pos: [4, 1, 4], state: "minecraft:deepslate_bricks"},
        {pos: [5, 1, 0], state: "minecraft:deepslate_bricks"},
        {pos: [5, 1, 1], state: "minecraft:gravel"},
        {pos: [5, 1, 2], state: "minecraft:gravel"},
        {pos: [5, 1, 3], state: "minecraft:gravel"},
        {pos: [5, 1, 4], state: "minecraft:deepslate_bricks"},
        {pos: [6, 1, 0], state: "minecraft:deepslate_bricks"},
        {pos: [6, 1, 1], state: "minecraft:gravel"},
        {pos: [6, 1, 2], state: "minecraft:gravel"},
        {pos: [6, 1, 3], state: "minecraft:gravel"},
        {pos: [6, 1, 4], state: "minecraft:deepslate_bricks"},
        {pos: [7, 1, 0], state: "minecraft:deepslate_bricks"},
        {pos: [7, 1, 1], state: "minecraft:gravel"},
        {pos: [7, 1, 2], state: "minecraft:gravel"},
        {pos: [7, 1, 3], state: "minecraft:gravel"},
        {pos: [7, 1, 4], state: "minecraft:deepslate_bricks"},
        {pos: [8, 1, 0], state: "minecraft:deepslate_bricks"},
        {pos: [8, 1, 1], state: "minecraft:gravel"},
        {pos: [8, 1, 2], state: "minecraft:gravel"},
        {pos: [8, 1, 3], state: "minecraft:gravel"},
        {pos: [8, 1, 4], state: "minecraft:deepslate_bricks"},
        {pos: [9, 1, 0], state: "minecraft:deepslate_bricks"},
        {pos: [9, 1, 1], state: "minecraft:gravel"},
        {pos: [9, 1, 2], state: "minecraft:gravel"},
        {pos: [9, 1, 3], state: "minecraft:gravel"},
        {pos: [9, 1, 4], state: "minecraft:deepslate_bricks"},
        {pos: [10, 1, 0], state: "minecraft:deepslate_bricks"},
        {pos: [10, 1, 1], state: "minecraft:gravel"},
        {pos: [10, 1, 2], state: "minecraft:gravel"},
        {pos: [10, 1, 3], state: "minecraft:gravel"},
        {pos: [10, 1, 4], state: "minecraft:deepslate_bricks"},
        {pos: [11, 1, 0], state: "minecraft:deepslate_bricks"},
        {pos: [11, 1, 1], state: "minecraft:gravel"},
        {pos: [11, 1, 2], state: "minecraft:gravel"},
        {pos: [11, 1, 3], state: "minecraft:gravel"},
        {pos: [11, 1, 4], state: "minecraft:deepslate_bricks"},
        {pos: [12, 1, 0], state: "minecraft:deepslate_bricks"},
        {pos: [12, 1, 1], state: "minecraft:gravel"},
        {pos: [12, 1, 2], state: "minecraft:gravel"},
        {pos: [12, 1, 3], state: "minecraft:gravel"},
        {pos: [12, 1, 4], state: "minecraft:deepslate_bricks"},
        {pos: [13, 1, 0], state: "minecraft:deepslate_bricks"},
        {pos: [13, 1, 1], state: "minecraft:gravel"},
        {pos: [13, 1, 2], state: "minecraft:gravel"},
        {pos: [13, 1, 3], state: "minecraft:gravel"},
        {pos: [13, 1, 4], state: "minecraft:deepslate_bricks"},
        {pos: [14, 1, 0], state: "minecraft:deepslate_bricks"},
        {pos: [14, 1, 1], state: "minecraft:gravel"},
        {pos: [14, 1, 2], state: "minecraft:gravel"},
        {pos: [14, 1, 3], state: "minecraft:gravel"},
        {pos: [14, 1, 4], state: "minecraft:deepslate_bricks"},
        {pos: [0, 2, 0], state: "minecraft:deepslate_bricks"},
        {pos: [0, 2, 1], state: "minecraft:cave_air"},
        {pos: [0, 2, 2], state: "minecraft:jigsaw{orientation:west_up}", nbt: {final_state: "minecraft:cave_air", id: "minecraft:jigsaw", joint: "rollable", name: "trailiertales:corridor", placement_priority: 0, pool: "trailiertales:catacombs/corridor", selection_priority: 0, target: "trailiertales:corridor"}},
        {pos: [0, 2, 3], state: "minecraft:cave_air"},
        {pos: [0, 2, 4], state: "minecraft:deepslate_bricks"},
        {pos: [1, 2, 0], state: "minecraft:deepslate_bricks"},
        {pos: [1, 2, 1], state: "minecraft:candle{candles:4,lit:false,waterlogged:false}"},
        {pos: [1, 2, 2], state: "minecraft:cave_air"},
        {pos: [1, 2, 3], state: "minecraft:candle{candles:4,lit:false,waterlogged:false}"},
        {pos: [1, 2, 4], state: "minecraft:deepslate_bricks"},
        {pos: [2, 2, 0], state: "minecraft:deepslate_bricks"},
        {pos: [2, 2, 1], state: "minecraft:deepslate_bricks"},
        {pos: [2, 2, 2], state: "minecraft:iron_door{facing:west,half:lower,hinge:left,open:false,powered:false}"},
        {pos: [2, 2, 3], state: "minecraft:deepslate_bricks"},
        {pos: [2, 2, 4], state: "minecraft:deepslate_bricks"},
        {pos: [3, 2, 0], state: "minecraft:deepslate_bricks"},
        {pos: [3, 2, 1], state: "minecraft:candle{candles:4,lit:false,waterlogged:false}"},
        {pos: [3, 2, 2], state: "minecraft:cave_air"},
        {pos: [3, 2, 3], state: "minecraft:candle{candles:4,lit:false,waterlogged:false}"},
        {pos: [3, 2, 4], state: "minecraft:deepslate_bricks"},
        {pos: [4, 2, 0], state: "minecraft:deepslate_bricks"},
        {pos: [4, 2, 1], state: "minecraft:deepslate_brick_stairs{facing:north,half:top,shape:straight,waterlogged:false}"},
        {pos: [4, 2, 2], state: "minecraft:cave_air"},
        {pos: [4, 2, 3], state: "minecraft:deepslate_brick_stairs{facing:south,half:top,shape:straight,waterlogged:false}"},
        {pos: [4, 2, 4], state: "minecraft:deepslate_bricks"},
        {pos: [5, 2, 0], state: "minecraft:deepslate_bricks"},
        {pos: [5, 2, 1], state: "minecraft:deepslate_brick_stairs{facing:north,half:top,shape:straight,waterlogged:false}"},
        {pos: [5, 2, 2], state: "minecraft:cave_air"},
        {pos: [5, 2, 3], state: "minecraft:deepslate_brick_stairs{facing:south,half:top,shape:straight,waterlogged:false}"},
        {pos: [5, 2, 4], state: "minecraft:deepslate_bricks"},
        {pos: [6, 2, 0], state: "minecraft:deepslate_bricks"},
        {pos: [6, 2, 1], state: "minecraft:candle{candles:4,lit:false,waterlogged:false}"},
        {pos: [6, 2, 2], state: "minecraft:cave_air"},
        {pos: [6, 2, 3], state: "minecraft:candle{candles:4,lit:false,waterlogged:false}"},
        {pos: [6, 2, 4], state: "minecraft:deepslate_bricks"},
        {pos: [7, 2, 0], state: "minecraft:deepslate_bricks"},
        {pos: [7, 2, 1], state: "minecraft:deepslate_bricks"},
        {pos: [7, 2, 2], state: "minecraft:iron_door{facing:west,half:lower,hinge:left,open:false,powered:false}"},
        {pos: [7, 2, 3], state: "minecraft:deepslate_bricks"},
        {pos: [7, 2, 4], state: "minecraft:deepslate_bricks"},
        {pos: [8, 2, 0], state: "minecraft:deepslate_bricks"},
        {pos: [8, 2, 1], state: "minecraft:candle{candles:4,lit:false,waterlogged:false}"},
        {pos: [8, 2, 2], state: "minecraft:cave_air"},
        {pos: [8, 2, 3], state: "minecraft:candle{candles:4,lit:false,waterlogged:false}"},
        {pos: [8, 2, 4], state: "minecraft:deepslate_bricks"},
        {pos: [9, 2, 0], state: "minecraft:deepslate_bricks"},
        {pos: [9, 2, 1], state: "minecraft:deepslate_brick_stairs{facing:north,half:top,shape:straight,waterlogged:false}"},
        {pos: [9, 2, 2], state: "minecraft:cave_air"},
        {pos: [9, 2, 3], state: "minecraft:deepslate_brick_stairs{facing:south,half:top,shape:straight,waterlogged:false}"},
        {pos: [9, 2, 4], state: "minecraft:deepslate_bricks"},
        {pos: [10, 2, 0], state: "minecraft:deepslate_bricks"},
        {pos: [10, 2, 1], state: "minecraft:deepslate_brick_stairs{facing:north,half:top,shape:straight,waterlogged:false}"},
        {pos: [10, 2, 2], state: "minecraft:cave_air"},
        {pos: [10, 2, 3], state: "minecraft:deepslate_brick_stairs{facing:south,half:top,shape:straight,waterlogged:false}"},
        {pos: [10, 2, 4], state: "minecraft:deepslate_bricks"},
        {pos: [11, 2, 0], state: "minecraft:deepslate_bricks"},
        {pos: [11, 2, 1], state: "minecraft:candle{candles:4,lit:false,waterlogged:false}"},
        {pos: [11, 2, 2], state: "minecraft:cave_air"},
        {pos: [11, 2, 3], state: "minecraft:candle{candles:4,lit:false,waterlogged:false}"},
        {pos: [11, 2, 4], state: "minecraft:deepslate_bricks"},
        {pos: [12, 2, 0], state: "minecraft:deepslate_bricks"},
        {pos: [12, 2, 1], state: "minecraft:deepslate_bricks"},
        {pos: [12, 2, 2], state: "minecraft:iron_door{facing:west,half:lower,hinge:left,open:false,powered:false}"},
        {pos: [12, 2, 3], state: "minecraft:deepslate_bricks"},
        {pos: [12, 2, 4], state: "minecraft:deepslate_bricks"},
        {pos: [13, 2, 0], state: "minecraft:deepslate_bricks"},
        {pos: [13, 2, 1], state: "minecraft:candle{candles:4,lit:false,waterlogged:false}"},
        {pos: [13, 2, 2], state: "minecraft:cave_air"},
        {pos: [13, 2, 3], state: "minecraft:candle{candles:4,lit:false,waterlogged:false}"},
        {pos: [13, 2, 4], state: "minecraft:deepslate_bricks"},
        {pos: [14, 2, 0], state: "minecraft:deepslate_bricks"},
        {pos: [14, 2, 1], state: "minecraft:cave_air"},
        {pos: [14, 2, 2], state: "minecraft:jigsaw{orientation:east_up}", nbt: {final_state: "minecraft:cave_air", id: "minecraft:jigsaw", joint: "rollable", name: "trailiertales:corridor", placement_priority: 0, pool: "trailiertales:catacombs/corridor", selection_priority: 0, target: "trailiertales:corridor"}},
        {pos: [14, 2, 3], state: "minecraft:cave_air"},
        {pos: [14, 2, 4], state: "minecraft:deepslate_bricks"},
        {pos: [0, 3, 0], state: "minecraft:deepslate_bricks"},
        {pos: [0, 3, 1], state: "minecraft:cave_air"},
        {pos: [0, 3, 2], state: "minecraft:cave_air"},
        {pos: [0, 3, 3], state: "minecraft:cave_air"},
        {pos: [0, 3, 4], state: "minecraft:deepslate_bricks"},
        {pos: [1, 3, 0], state: "minecraft:polished_deepslate"},
        {pos: [1, 3, 1], state: "minecraft:cave_air"},
        {pos: [1, 3, 2], state: "minecraft:cave_air"},
        {pos: [1, 3, 3], state: "minecraft:cave_air"},
        {pos: [1, 3, 4], state: "minecraft:polished_deepslate"},
        {pos: [2, 3, 0], state: "minecraft:deepslate_bricks"},
        {pos: [2, 3, 1], state: "minecraft:deepslate_bricks"},
        {pos: [2, 3, 2], state: "minecraft:iron_door{facing:west,half:upper,hinge:left,open:false,powered:false}"},
        {pos: [2, 3, 3], state: "minecraft:deepslate_bricks"},
        {pos: [2, 3, 4], state: "minecraft:deepslate_bricks"},
        {pos: [3, 3, 0], state: "minecraft:deepslate_bricks"},
        {pos: [3, 3, 1], state: "minecraft:cave_air"},
        {pos: [3, 3, 2], state: "minecraft:cave_air"},
        {pos: [3, 3, 3], state: "minecraft:cave_air"},
        {pos: [3, 3, 4], state: "minecraft:deepslate_bricks"},
        {pos: [4, 3, 0], state: "minecraft:deepslate_bricks"},
        {pos: [4, 3, 1], state: "minecraft:skeleton_skull{powered:false,rotation:8}", nbt: {id: "minecraft:skull"}},
        {pos: [4, 3, 2], state: "minecraft:cave_air"},
        {pos: [4, 3, 3], state: "minecraft:skeleton_skull{powered:false,rotation:0}", nbt: {id: "minecraft:skull"}},
        {pos: [4, 3, 4], state: "minecraft:deepslate_bricks"},
        {pos: [5, 3, 0], state: "minecraft:deepslate_bricks"},
        {pos: [5, 3, 1], state: "minecraft:skeleton_skull{powered:false,rotation:8}", nbt: {id: "minecraft:skull"}},
        {pos: [5, 3, 2], state: "minecraft:cave_air"},
        {pos: [5, 3, 3], state: "minecraft:skeleton_skull{powered:false,rotation:0}", nbt: {id: "minecraft:skull"}},
        {pos: [5, 3, 4], state: "minecraft:deepslate_bricks"},
        {pos: [6, 3, 0], state: "minecraft:deepslate_bricks"},
        {pos: [6, 3, 1], state: "minecraft:cave_air"},
        {pos: [6, 3, 2], state: "minecraft:cave_air"},
        {pos: [6, 3, 3], state: "minecraft:cave_air"},
        {pos: [6, 3, 4], state: "minecraft:deepslate_bricks"},
        {pos: [7, 3, 0], state: "minecraft:deepslate_bricks"},
        {pos: [7, 3, 1], state: "minecraft:deepslate_bricks"},
        {pos: [7, 3, 2], state: "minecraft:iron_door{facing:west,half:upper,hinge:left,open:false,powered:false}"},
        {pos: [7, 3, 3], state: "minecraft:deepslate_bricks"},
        {pos: [7, 3, 4], state: "minecraft:deepslate_bricks"},
        {pos: [8, 3, 0], state: "minecraft:deepslate_bricks"},
        {pos: [8, 3, 1], state: "minecraft:cave_air"},
        {pos: [8, 3, 2], state: "minecraft:cave_air"},
        {pos: [8, 3, 3], state: "minecraft:cave_air"},
        {pos: [8, 3, 4], state: "minecraft:deepslate_bricks"},
        {pos: [9, 3, 0], state: "minecraft:deepslate_bricks"},
        {pos: [9, 3, 1], state: "minecraft:skeleton_skull{powered:false,rotation:8}", nbt: {id: "minecraft:skull"}},
        {pos: [9, 3, 2], state: "minecraft:cave_air"},
        {pos: [9, 3, 3], state: "minecraft:skeleton_skull{powered:false,rotation:0}", nbt: {id: "minecraft:skull"}},
        {pos: [9, 3, 4], state: "minecraft:deepslate_bricks"},
        {pos: [10, 3, 0], state: "minecraft:deepslate_bricks"},
        {pos: [10, 3, 1], state: "minecraft:skeleton_skull{powered:false,rotation:8}", nbt: {id: "minecraft:skull"}},
        {pos: [10, 3, 2], state: "minecraft:cave_air"},
        {pos: [10, 3, 3], state: "minecraft:skeleton_skull{powered:false,rotation:0}", nbt: {id: "minecraft:skull"}},
        {pos: [10, 3, 4], state: "minecraft:deepslate_bricks"},
        {pos: [11, 3, 0], state: "minecraft:deepslate_bricks"},
        {pos: [11, 3, 1], state: "minecraft:cave_air"},
        {pos: [11, 3, 2], state: "minecraft:cave_air"},
        {pos: [11, 3, 3], state: "minecraft:cave_air"},
        {pos: [11, 3, 4], state: "minecraft:deepslate_bricks"},
        {pos: [12, 3, 0], state: "minecraft:deepslate_bricks"},
        {pos: [12, 3, 1], state: "minecraft:deepslate_bricks"},
        {pos: [12, 3, 2], state: "minecraft:iron_door{facing:west,half:upper,hinge:left,open:false,powered:false}"},
        {pos: [12, 3, 3], state: "minecraft:deepslate_bricks"},
        {pos: [12, 3, 4], state: "minecraft:deepslate_bricks"},
        {pos: [13, 3, 0], state: "minecraft:polished_deepslate"},
        {pos: [13, 3, 1], state: "minecraft:cave_air"},
        {pos: [13, 3, 2], state: "minecraft:cave_air"},
        {pos: [13, 3, 3], state: "minecraft:cave_air"},
        {pos: [13, 3, 4], state: "minecraft:polished_deepslate"},
        {pos: [14, 3, 0], state: "minecraft:deepslate_bricks"},
        {pos: [14, 3, 1], state: "minecraft:cave_air"},
        {pos: [14, 3, 2], state: "minecraft:cave_air"},
        {pos: [14, 3, 3], state: "minecraft:cave_air"},
        {pos: [14, 3, 4], state: "minecraft:deepslate_bricks"},
        {pos: [0, 4, 0], state: "minecraft:deepslate_bricks"},
        {pos: [0, 4, 1], state: "minecraft:cave_air"},
        {pos: [0, 4, 2], state: "minecraft:cave_air"},
        {pos: [0, 4, 3], state: "minecraft:cave_air"},
        {pos: [0, 4, 4], state: "minecraft:deepslate_bricks"},
        {pos: [1, 4, 0], state: "minecraft:deepslate_bricks"},
        {pos: [1, 4, 1], state: "minecraft:cave_air"},
        {pos: [1, 4, 2], state: "minecraft:lever{face:wall,facing:west,powered:false}"},
        {pos: [1, 4, 3], state: "minecraft:cave_air"},
        {pos: [1, 4, 4], state: "minecraft:deepslate_bricks"},
        {pos: [2, 4, 0], state: "minecraft:deepslate_bricks"},
        {pos: [2, 4, 1], state: "minecraft:deepslate_bricks"},
        {pos: [2, 4, 2], state: "minecraft:deepslate_bricks"},
        {pos: [2, 4, 3], state: "minecraft:deepslate_bricks"},
        {pos: [2, 4, 4], state: "minecraft:deepslate_bricks"},
        {pos: [3, 4, 0], state: "minecraft:deepslate_bricks"},
        {pos: [3, 4, 1], state: "minecraft:cave_air"},
        {pos: [3, 4, 2], state: "minecraft:lever{face:wall,facing:east,powered:false}"},
        {pos: [3, 4, 3], state: "minecraft:cave_air"},
        {pos: [3, 4, 4], state: "minecraft:deepslate_bricks"},
        {pos: [4, 4, 0], state: "minecraft:deepslate_bricks"},
        {pos: [4, 4, 1], state: "minecraft:cave_air"},
        {pos: [4, 4, 2], state: "minecraft:cave_air"},
        {pos: [4, 4, 3], state: "minecraft:cave_air"},
        {pos: [4, 4, 4], state: "minecraft:deepslate_bricks"},
        {pos: [5, 4, 0], state: "minecraft:deepslate_bricks"},
        {pos: [5, 4, 1], state: "minecraft:cave_air"},
        {pos: [5, 4, 2], state: "minecraft:cave_air"},
        {pos: [5, 4, 3], state: "minecraft:cave_air"},
        {pos: [5, 4, 4], state: "minecraft:deepslate_bricks"},
        {pos: [6, 4, 0], state: "minecraft:deepslate_bricks"},
        {pos: [6, 4, 1], state: "minecraft:cave_air"},
        {pos: [6, 4, 2], state: "minecraft:lever{face:wall,facing:west,powered:false}"},
        {pos: [6, 4, 3], state: "minecraft:cave_air"},
        {pos: [6, 4, 4], state: "minecraft:deepslate_bricks"},
        {pos: [7, 4, 0], state: "minecraft:deepslate_bricks"},
        {pos: [7, 4, 1], state: "minecraft:deepslate_bricks"},
        {pos: [7, 4, 2], state: "minecraft:deepslate_bricks"},
        {pos: [7, 4, 3], state: "minecraft:deepslate_bricks"},
        {pos: [7, 4, 4], state: "minecraft:deepslate_bricks"},
        {pos: [8, 4, 0], state: "minecraft:deepslate_bricks"},
        {pos: [8, 4, 1], state: "minecraft:cave_air"},
        {pos: [8, 4, 2], state: "minecraft:lever{face:wall,facing:east,powered:false}"},
        {pos: [8, 4, 3], state: "minecraft:cave_air"},
        {pos: [8, 4, 4], state: "minecraft:deepslate_bricks"},
        {pos: [9, 4, 0], state: "minecraft:deepslate_bricks"},
        {pos: [9, 4, 1], state: "minecraft:cave_air"},
        {pos: [9, 4, 2], state: "minecraft:cave_air"},
        {pos: [9, 4, 3], state: "minecraft:cave_air"},
        {pos: [9, 4, 4], state: "minecraft:deepslate_bricks"},
        {pos: [10, 4, 0], state: "minecraft:deepslate_bricks"},
        {pos: [10, 4, 1], state: "minecraft:cave_air"},
        {pos: [10, 4, 2], state: "minecraft:cave_air"},
        {pos: [10, 4, 3], state: "minecraft:cave_air"},
        {pos: [10, 4, 4], state: "minecraft:deepslate_bricks"},
        {pos: [11, 4, 0], state: "minecraft:deepslate_bricks"},
        {pos: [11, 4, 1], state: "minecraft:cave_air"},
        {pos: [11, 4, 2], state: "minecraft:lever{face:wall,facing:west,powered:false}"},
        {pos: [11, 4, 3], state: "minecraft:cave_air"},
        {pos: [11, 4, 4], state: "minecraft:deepslate_bricks"},
        {pos: [12, 4, 0], state: "minecraft:deepslate_bricks"},
        {pos: [12, 4, 1], state: "minecraft:deepslate_bricks"},
        {pos: [12, 4, 2], state: "minecraft:deepslate_bricks"},
        {pos: [12, 4, 3], state: "minecraft:deepslate_bricks"},
        {pos: [12, 4, 4], state: "minecraft:deepslate_bricks"},
        {pos: [13, 4, 0], state: "minecraft:deepslate_bricks"},
        {pos: [13, 4, 1], state: "minecraft:cave_air"},
        {pos: [13, 4, 2], state: "minecraft:lever{face:wall,facing:east,powered:false}"},
        {pos: [13, 4, 3], state: "minecraft:cave_air"},
        {pos: [13, 4, 4], state: "minecraft:deepslate_bricks"},
        {pos: [14, 4, 0], state: "minecraft:deepslate_bricks"},
        {pos: [14, 4, 1], state: "minecraft:cave_air"},
        {pos: [14, 4, 2], state: "minecraft:cave_air"},
        {pos: [14, 4, 3], state: "minecraft:cave_air"},
        {pos: [14, 4, 4], state: "minecraft:deepslate_bricks"},
        {pos: [0, 5, 0], state: "minecraft:deepslate_bricks"},
        {pos: [0, 5, 1], state: "minecraft:deepslate_bricks"},
        {pos: [0, 5, 2], state: "minecraft:deepslate_bricks"},
        {pos: [0, 5, 3], state: "minecraft:deepslate_bricks"},
        {pos: [0, 5, 4], state: "minecraft:deepslate_bricks"},
        {pos: [1, 5, 0], state: "minecraft:deepslate_bricks"},
        {pos: [1, 5, 1], state: "minecraft:deepslate_bricks"},
        {pos: [1, 5, 2], state: "minecraft:deepslate_bricks"},
        {pos: [1, 5, 3], state: "minecraft:deepslate_bricks"},
        {pos: [1, 5, 4], state: "minecraft:deepslate_bricks"},
        {pos: [2, 5, 0], state: "minecraft:deepslate_bricks"},
        {pos: [2, 5, 1], state: "minecraft:deepslate_bricks"},
        {pos: [2, 5, 2], state: "minecraft:deepslate_bricks"},
        {pos: [2, 5, 3], state: "minecraft:deepslate_bricks"},
        {pos: [2, 5, 4], state: "minecraft:deepslate_bricks"},
        {pos: [3, 5, 0], state: "minecraft:deepslate_bricks"},
        {pos: [3, 5, 1], state: "minecraft:deepslate_bricks"},
        {pos: [3, 5, 2], state: "minecraft:deepslate_bricks"},
        {pos: [3, 5, 3], state: "minecraft:deepslate_bricks"},
        {pos: [3, 5, 4], state: "minecraft:deepslate_bricks"},
        {pos: [4, 5, 0], state: "minecraft:deepslate_bricks"},
        {pos: [4, 5, 1], state: "minecraft:deepslate_bricks"},
        {pos: [4, 5, 2], state: "minecraft:deepslate_bricks"},
        {pos: [4, 5, 3], state: "minecraft:deepslate_bricks"},
        {pos: [4, 5, 4], state: "minecraft:deepslate_bricks"},
        {pos: [5, 5, 0], state: "minecraft:deepslate_bricks"},
        {pos: [5, 5, 1], state: "minecraft:deepslate_bricks"},
        {pos: [5, 5, 2], state: "minecraft:deepslate_bricks"},
        {pos: [5, 5, 3], state: "minecraft:deepslate_bricks"},
        {pos: [5, 5, 4], state: "minecraft:deepslate_bricks"},
        {pos: [6, 5, 0], state: "minecraft:deepslate_bricks"},
        {pos: [6, 5, 1], state: "minecraft:deepslate_bricks"},
        {pos: [6, 5, 2], state: "minecraft:deepslate_bricks"},
        {pos: [6, 5, 3], state: "minecraft:deepslate_bricks"},
        {pos: [6, 5, 4], state: "minecraft:deepslate_bricks"},
        {pos: [7, 5, 0], state: "minecraft:deepslate_bricks"},
        {pos: [7, 5, 1], state: "minecraft:deepslate_bricks"},
        {pos: [7, 5, 2], state: "minecraft:deepslate_bricks"},
        {pos: [7, 5, 3], state: "minecraft:deepslate_bricks"},
        {pos: [7, 5, 4], state: "minecraft:deepslate_bricks"},
        {pos: [8, 5, 0], state: "minecraft:deepslate_bricks"},
        {pos: [8, 5, 1], state: "minecraft:deepslate_bricks"},
        {pos: [8, 5, 2], state: "minecraft:deepslate_bricks"},
        {pos: [8, 5, 3], state: "minecraft:deepslate_bricks"},
        {pos: [8, 5, 4], state: "minecraft:deepslate_bricks"},
        {pos: [9, 5, 0], state: "minecraft:deepslate_bricks"},
        {pos: [9, 5, 1], state: "minecraft:deepslate_bricks"},
        {pos: [9, 5, 2], state: "minecraft:deepslate_bricks"},
        {pos: [9, 5, 3], state: "minecraft:deepslate_bricks"},
        {pos: [9, 5, 4], state: "minecraft:deepslate_bricks"},
        {pos: [10, 5, 0], state: "minecraft:deepslate_bricks"},
        {pos: [10, 5, 1], state: "minecraft:deepslate_bricks"},
        {pos: [10, 5, 2], state: "minecraft:deepslate_bricks"},
        {pos: [10, 5, 3], state: "minecraft:deepslate_bricks"},
        {pos: [10, 5, 4], state: "minecraft:deepslate_bricks"},
        {pos: [11, 5, 0], state: "minecraft:deepslate_bricks"},
        {pos: [11, 5, 1], state: "minecraft:deepslate_bricks"},
        {pos: [11, 5, 2], state: "minecraft:deepslate_bricks"},
        {pos: [11, 5, 3], state: "minecraft:deepslate_bricks"},
        {pos: [11, 5, 4], state: "minecraft:deepslate_bricks"},
        {pos: [12, 5, 0], state: "minecraft:deepslate_bricks"},
        {pos: [12, 5, 1], state: "minecraft:deepslate_bricks"},
        {pos: [12, 5, 2], state: "minecraft:deepslate_bricks"},
        {pos: [12, 5, 3], state: "minecraft:deepslate_bricks"},
        {pos: [12, 5, 4], state: "minecraft:deepslate_bricks"},
        {pos: [13, 5, 0], state: "minecraft:deepslate_bricks"},
        {pos: [13, 5, 1], state: "minecraft:deepslate_bricks"},
        {pos: [13, 5, 2], state: "minecraft:deepslate_bricks"},
        {pos: [13, 5, 3], state: "minecraft:deepslate_bricks"},
        {pos: [13, 5, 4], state: "minecraft:deepslate_bricks"},
        {pos: [14, 5, 0], state: "minecraft:deepslate_bricks"},
        {pos: [14, 5, 1], state: "minecraft:deepslate_bricks"},
        {pos: [14, 5, 2], state: "minecraft:deepslate_bricks"},
        {pos: [14, 5, 3], state: "minecraft:deepslate_bricks"},
        {pos: [14, 5, 4], state: "minecraft:deepslate_bricks"}
    ],
    entities: [],
    palette: [
        "minecraft:deepslate{axis:y}",
        "minecraft:deepslate_bricks",
        "minecraft:gravel",
        "minecraft:polished_deepslate",
        "minecraft:cave_air",
        "minecraft:candle{candles:4,lit:false,waterlogged:false}",
        "minecraft:iron_door{facing:west,half:lower,hinge:left,open:false,powered:false}",
        "minecraft:deepslate_brick_stairs{facing:north,half:top,shape:straight,waterlogged:false}",
        "minecraft:deepslate_brick_stairs{facing:south,half:top,shape:straight,waterlogged:false}",
        "minecraft:iron_door{facing:west,half:upper,hinge:left,open:false,powered:false}",
        "minecraft:lever{face:wall,facing:west,powered:false}",
        "minecraft:lever{face:wall,facing:east,powered:false}",
        "minecraft:jigsaw{orientation:west_up}",
        "minecraft:jigsaw{orientation:east_up}",
        "minecraft:skeleton_skull{powered:false,rotation:8}",
        "minecraft:skeleton_skull{powered:false,rotation:0}"
    ],
    trailiertales_DataVersion: 3
}
