{
    DataVersion: 3955,
    size: [21, 16, 23],
    data: [
        {pos: [8, 1, 10], state: "minecraft:deepslate_bricks"},
        {pos: [8, 1, 11], state: "minecraft:deepslate_bricks"},
        {pos: [8, 1, 12], state: "minecraft:deepslate_bricks"},
        {pos: [8, 1, 13], state: "minecraft:deepslate_bricks"},
        {pos: [8, 1, 14], state: "minecraft:deepslate_bricks"},
        {pos: [9, 1, 10], state: "minecraft:deepslate_bricks"},
        {pos: [9, 1, 11], state: "minecraft:deepslate_bricks"},
        {pos: [9, 1, 12], state: "minecraft:deepslate_bricks"},
        {pos: [9, 1, 13], state: "minecraft:deepslate_bricks"},
        {pos: [9, 1, 14], state: "minecraft:deepslate_bricks"},
        {pos: [10, 1, 10], state: "minecraft:deepslate_bricks"},
        {pos: [10, 1, 11], state: "minecraft:deepslate_bricks"},
        {pos: [10, 1, 12], state: "minecraft:deepslate_bricks"},
        {pos: [10, 1, 13], state: "minecraft:deepslate_bricks"},
        {pos: [10, 1, 14], state: "minecraft:deepslate_bricks"},
        {pos: [11, 1, 10], state: "minecraft:deepslate_bricks"},
        {pos: [11, 1, 11], state: "minecraft:deepslate_bricks"},
        {pos: [11, 1, 12], state: "minecraft:deepslate_bricks"},
        {pos: [11, 1, 13], state: "minecraft:deepslate_bricks"},
        {pos: [11, 1, 14], state: "minecraft:deepslate_bricks"},
        {pos: [12, 1, 10], state: "minecraft:deepslate_bricks"},
        {pos: [12, 1, 11], state: "minecraft:deepslate_bricks"},
        {pos: [12, 1, 12], state: "minecraft:deepslate_bricks"},
        {pos: [12, 1, 13], state: "minecraft:deepslate_bricks"},
        {pos: [12, 1, 14], state: "minecraft:deepslate_bricks"},
        {pos: [7, 2, 0], state: "minecraft:deepslate_bricks"},
        {pos: [7, 2, 1], state: "minecraft:deepslate_bricks"},
        {pos: [7, 2, 2], state: "minecraft:deepslate_bricks"},
        {pos: [7, 2, 3], state: "minecraft:deepslate_bricks"},
        {pos: [7, 2, 4], state: "minecraft:deepslate_bricks"},
        {pos: [7, 2, 5], state: "minecraft:deepslate_bricks"},
        {pos: [7, 2, 6], state: "minecraft:deepslate_bricks"},
        {pos: [7, 2, 7], state: "minecraft:deepslate_bricks"},
        {pos: [7, 2, 8], state: "minecraft:deepslate_bricks"},
        {pos: [7, 2, 9], state: "minecraft:deepslate_bricks"},
        {pos: [8, 2, 0], state: "minecraft:deepslate_bricks"},
        {pos: [8, 2, 1], state: "minecraft:deepslate_bricks"},
        {pos: [8, 2, 2], state: "minecraft:deepslate_bricks"},
        {pos: [8, 2, 3], state: "minecraft:deepslate_bricks"},
        {pos: [8, 2, 4], state: "minecraft:deepslate_bricks"},
        {pos: [8, 2, 5], state: "minecraft:deepslate_bricks"},
        {pos: [8, 2, 6], state: "minecraft:deepslate_bricks"},
        {pos: [8, 2, 7], state: "minecraft:deepslate_bricks"},
        {pos: [8, 2, 8], state: "minecraft:deepslate_bricks"},
        {pos: [8, 2, 9], state: "minecraft:deepslate_bricks"},
        {pos: [8, 2, 10], state: "minecraft:deepslate_bricks"},
        {pos: [8, 2, 11], state: "minecraft:deepslate_bricks"},
        {pos: [8, 2, 12], state: "minecraft:deepslate_bricks"},
        {pos: [8, 2, 13], state: "minecraft:deepslate_bricks"},
        {pos: [8, 2, 14], state: "minecraft:deepslate_bricks"},
        {pos: [9, 2, 0], state: "minecraft:deepslate_bricks"},
        {pos: [9, 2, 1], state: "minecraft:deepslate_bricks"},
        {pos: [9, 2, 2], state: "minecraft:deepslate_bricks"},
        {pos: [9, 2, 3], state: "minecraft:deepslate_bricks"},
        {pos: [9, 2, 4], state: "minecraft:deepslate_bricks"},
        {pos: [9, 2, 5], state: "minecraft:deepslate_bricks"},
        {pos: [9, 2, 6], state: "minecraft:deepslate_bricks"},
        {pos: [9, 2, 7], state: "minecraft:deepslate_bricks"},
        {pos: [9, 2, 8], state: "minecraft:deepslate_bricks"},
        {pos: [9, 2, 9], state: "minecraft:deepslate_bricks"},
        {pos: [9, 2, 10], state: "minecraft:deepslate_bricks"},
        {pos: [9, 2, 11], state: "minecraft:gravel"},
        {pos: [9, 2, 12], state: "minecraft:gravel"},
        {pos: [9, 2, 13], state: "minecraft:gravel"},
        {pos: [9, 2, 14], state: "minecraft:deepslate_bricks"},
        {pos: [10, 2, 0], state: "minecraft:deepslate_bricks"},
        {pos: [10, 2, 1], state: "minecraft:deepslate_bricks"},
        {pos: [10, 2, 2], state: "minecraft:deepslate_bricks"},
        {pos: [10, 2, 5], state: "minecraft:deepslate_bricks"},
        {pos: [10, 2, 6], state: "minecraft:deepslate_bricks"},
        {pos: [10, 2, 7], state: "minecraft:deepslate_bricks"},
        {pos: [10, 2, 8], state: "minecraft:deepslate_bricks"},
        {pos: [10, 2, 9], state: "minecraft:deepslate_bricks"},
        {pos: [10, 2, 10], state: "minecraft:deepslate_bricks"},
        {pos: [10, 2, 11], state: "minecraft:gravel"},
        {pos: [10, 2, 12], state: "minecraft:chest{facing:south,type:single,waterlogged:false}", nbt: {id: "minecraft:chest"}},
        {pos: [10, 2, 13], state: "minecraft:gravel"},
        {pos: [10, 2, 14], state: "minecraft:deepslate_bricks"},
        {pos: [11, 2, 0], state: "minecraft:deepslate_bricks"},
        {pos: [11, 2, 1], state: "minecraft:deepslate_bricks"},
        {pos: [11, 2, 2], state: "minecraft:deepslate_bricks"},
        {pos: [11, 2, 5], state: "minecraft:deepslate_bricks"},
        {pos: [11, 2, 6], state: "minecraft:deepslate_bricks"},
        {pos: [11, 2, 7], state: "minecraft:deepslate_bricks"},
        {pos: [11, 2, 8], state: "minecraft:deepslate_bricks"},
        {pos: [11, 2, 9], state: "minecraft:deepslate_bricks"},
        {pos: [11, 2, 10], state: "minecraft:deepslate_bricks"},
        {pos: [11, 2, 11], state: "minecraft:gravel"},
        {pos: [11, 2, 12], state: "minecraft:gravel"},
        {pos: [11, 2, 13], state: "minecraft:gravel"},
        {pos: [11, 2, 14], state: "minecraft:deepslate_bricks"},
        {pos: [12, 2, 10], state: "minecraft:deepslate_bricks"},
        {pos: [12, 2, 11], state: "minecraft:deepslate_bricks"},
        {pos: [12, 2, 12], state: "minecraft:deepslate_bricks"},
        {pos: [12, 2, 13], state: "minecraft:deepslate_bricks"},
        {pos: [12, 2, 14], state: "minecraft:deepslate_bricks"},
        {pos: [7, 3, 0], state: "minecraft:deepslate_bricks"},
        {pos: [7, 3, 1], state: "minecraft:deepslate_bricks"},
        {pos: [7, 3, 2], state: "minecraft:deepslate_bricks"},
        {pos: [7, 3, 3], state: "minecraft:deepslate_bricks"},
        {pos: [7, 3, 4], state: "minecraft:deepslate_bricks"},
        {pos: [7, 3, 5], state: "minecraft:deepslate_bricks"},
        {pos: [7, 3, 6], state: "minecraft:deepslate_bricks"},
        {pos: [7, 3, 7], state: "minecraft:deepslate_bricks"},
        {pos: [7, 3, 8], state: "minecraft:deepslate_bricks"},
        {pos: [7, 3, 9], state: "minecraft:deepslate_bricks"},
        {pos: [8, 3, 0], state: "minecraft:deepslate_bricks"},
        {pos: [8, 3, 1], state: "minecraft:deepslate_bricks"},
        {pos: [8, 3, 2], state: "minecraft:deepslate_bricks"},
        {pos: [8, 3, 3], state: "minecraft:redstone_wire{east:none,north:up,power:0,south:side,west:none}"},
        {pos: [8, 3, 4], state: "minecraft:redstone_wire{east:none,north:side,power:0,south:side,west:none}"},
        {pos: [8, 3, 5], state: "minecraft:repeater{delay:1,facing:north,locked:false,powered:false}"},
        {pos: [8, 3, 6], state: "minecraft:redstone_wire{east:none,north:side,power:0,south:side,west:none}"},
        {pos: [8, 3, 7], state: "minecraft:redstone_wire{east:none,north:side,power:0,south:side,west:none}"},
        {pos: [8, 3, 8], state: "minecraft:redstone_wire{east:side,north:side,power:0,south:none,west:none}"},
        {pos: [8, 3, 9], state: "minecraft:deepslate_bricks"},
        {pos: [8, 3, 10], state: "minecraft:deepslate_bricks"},
        {pos: [8, 3, 11], state: "minecraft:deepslate_bricks"},
        {pos: [8, 3, 12], state: "minecraft:deepslate_bricks"},
        {pos: [8, 3, 13], state: "minecraft:deepslate_bricks"},
        {pos: [8, 3, 14], state: "minecraft:deepslate_bricks"},
        {pos: [9, 3, 0], state: "minecraft:deepslate_bricks"},
        {pos: [9, 3, 1], state: "minecraft:deepslate_bricks"},
        {pos: [9, 3, 2], state: "minecraft:deepslate_bricks"},
        {pos: [9, 3, 3], state: "minecraft:deepslate_bricks"},
        {pos: [9, 3, 4], state: "minecraft:deepslate_bricks"},
        {pos: [9, 3, 5], state: "minecraft:deepslate_bricks"},
        {pos: [9, 3, 6], state: "minecraft:deepslate_bricks"},
        {pos: [9, 3, 7], state: "minecraft:deepslate_bricks"},
        {pos: [9, 3, 8], state: "minecraft:repeater{delay:1,facing:west,locked:false,powered:false}"},
        {pos: [9, 3, 9], state: "minecraft:deepslate_bricks"},
        {pos: [9, 3, 10], state: "minecraft:deepslate_bricks"},
        {pos: [9, 3, 11], state: "minecraft:gravel"},
        {pos: [9, 3, 12], state: "minecraft:gravel"},
        {pos: [9, 3, 13], state: "minecraft:gravel"},
        {pos: [9, 3, 14], state: "minecraft:deepslate_bricks"},
        {pos: [10, 3, 0], state: "minecraft:deepslate_bricks"},
        {pos: [10, 3, 1], state: "minecraft:deepslate_bricks"},
        {pos: [10, 3, 2], state: "minecraft:deepslate_bricks"},
        {pos: [10, 3, 5], state: "minecraft:deepslate_bricks"},
        {pos: [10, 3, 6], state: "minecraft:deepslate_bricks"},
        {pos: [10, 3, 7], state: "minecraft:redstone_wall_torch{facing:north,lit:true}"},
        {pos: [10, 3, 8], state: "minecraft:deepslate_bricks"},
        {pos: [10, 3, 9], state: "minecraft:deepslate_bricks"},
        {pos: [10, 3, 10], state: "minecraft:deepslate_bricks"},
        {pos: [10, 3, 11], state: "minecraft:gravel"},
        {pos: [10, 3, 12], state: "minecraft:gravel"},
        {pos: [10, 3, 13], state: "minecraft:gravel"},
        {pos: [10, 3, 14], state: "minecraft:deepslate_bricks"},
        {pos: [11, 3, 0], state: "minecraft:deepslate_bricks"},
        {pos: [11, 3, 1], state: "minecraft:deepslate_bricks"},
        {pos: [11, 3, 2], state: "minecraft:deepslate_bricks"},
        {pos: [11, 3, 5], state: "minecraft:deepslate_bricks"},
        {pos: [11, 3, 6], state: "minecraft:deepslate_bricks"},
        {pos: [11, 3, 7], state: "minecraft:deepslate_bricks"},
        {pos: [11, 3, 8], state: "minecraft:deepslate_bricks"},
        {pos: [11, 3, 9], state: "minecraft:deepslate_bricks"},
        {pos: [11, 3, 10], state: "minecraft:deepslate_bricks"},
        {pos: [11, 3, 11], state: "minecraft:gravel"},
        {pos: [11, 3, 12], state: "minecraft:gravel"},
        {pos: [11, 3, 13], state: "minecraft:gravel"},
        {pos: [11, 3, 14], state: "minecraft:deepslate_bricks"},
        {pos: [12, 3, 10], state: "minecraft:deepslate_bricks"},
        {pos: [12, 3, 11], state: "minecraft:deepslate_bricks"},
        {pos: [12, 3, 12], state: "minecraft:deepslate_bricks"},
        {pos: [12, 3, 13], state: "minecraft:deepslate_bricks"},
        {pos: [12, 3, 14], state: "minecraft:deepslate_bricks"},
        {pos: [7, 4, 0], state: "minecraft:deepslate_bricks"},
        {pos: [7, 4, 1], state: "minecraft:deepslate_bricks"},
        {pos: [7, 4, 2], state: "minecraft:deepslate_bricks"},
        {pos: [7, 4, 3], state: "minecraft:deepslate_bricks"},
        {pos: [7, 4, 4], state: "minecraft:deepslate_bricks"},
        {pos: [7, 4, 5], state: "minecraft:deepslate_bricks"},
        {pos: [7, 4, 6], state: "minecraft:deepslate_bricks"},
        {pos: [7, 4, 7], state: "minecraft:deepslate_bricks"},
        {pos: [7, 4, 8], state: "minecraft:deepslate_bricks"},
        {pos: [7, 4, 9], state: "minecraft:deepslate_bricks"},
        {pos: [8, 4, 0], state: "minecraft:deepslate_bricks"},
        {pos: [8, 4, 1], state: "minecraft:deepslate_bricks"},
        {pos: [8, 4, 2], state: "minecraft:redstone_wire{east:none,north:up,power:0,south:side,west:none}"},
        {pos: [8, 4, 3], state: "minecraft:cave_air"},
        {pos: [8, 4, 4], state: "minecraft:deepslate_bricks"},
        {pos: [8, 4, 5], state: "minecraft:deepslate_bricks"},
        {pos: [8, 4, 6], state: "minecraft:deepslate_bricks"},
        {pos: [8, 4, 7], state: "minecraft:deepslate_bricks"},
        {pos: [8, 4, 8], state: "minecraft:deepslate_bricks"},
        {pos: [8, 4, 9], state: "minecraft:deepslate_bricks"},
        {pos: [8, 4, 10], state: "minecraft:deepslate_bricks"},
        {pos: [8, 4, 11], state: "minecraft:deepslate_bricks"},
        {pos: [8, 4, 12], state: "minecraft:deepslate_bricks"},
        {pos: [8, 4, 13], state: "minecraft:deepslate_bricks"},
        {pos: [8, 4, 14], state: "minecraft:deepslate_bricks"},
        {pos: [9, 4, 0], state: "minecraft:deepslate_bricks"},
        {pos: [9, 4, 1], state: "minecraft:deepslate_bricks"},
        {pos: [9, 4, 2], state: "minecraft:deepslate_bricks"},
        {pos: [9, 4, 3], state: "minecraft:deepslate_bricks"},
        {pos: [9, 4, 4], state: "minecraft:deepslate_bricks"},
        {pos: [9, 4, 5], state: "minecraft:deepslate_bricks"},
        {pos: [9, 4, 6], state: "minecraft:deepslate_bricks"},
        {pos: [9, 4, 7], state: "minecraft:deepslate_bricks"},
        {pos: [9, 4, 8], state: "minecraft:deepslate_bricks"},
        {pos: [9, 4, 9], state: "minecraft:deepslate_bricks"},
        {pos: [9, 4, 10], state: "minecraft:deepslate_bricks"},
        {pos: [9, 4, 11], state: "minecraft:gravel"},
        {pos: [9, 4, 12], state: "minecraft:gravel"},
        {pos: [9, 4, 13], state: "minecraft:gravel"},
        {pos: [9, 4, 14], state: "minecraft:deepslate_bricks"},
        {pos: [10, 4, 0], state: "minecraft:deepslate_bricks"},
        {pos: [10, 4, 1], state: "minecraft:deepslate_bricks"},
        {pos: [10, 4, 2], state: "minecraft:deepslate_bricks"},
        {pos: [10, 4, 5], state: "minecraft:deepslate_bricks"},
        {pos: [10, 4, 6], state: "minecraft:redstone_wall_torch{facing:north,lit:false}"},
        {pos: [10, 4, 7], state: "minecraft:deepslate_bricks"},
        {pos: [10, 4, 8], state: "minecraft:deepslate_bricks"},
        {pos: [10, 4, 9], state: "minecraft:deepslate_bricks"},
        {pos: [10, 4, 10], state: "minecraft:deepslate_bricks"},
        {pos: [10, 4, 11], state: "minecraft:gravel"},
        {pos: [10, 4, 12], state: "minecraft:gravel"},
        {pos: [10, 4, 13], state: "minecraft:gravel"},
        {pos: [10, 4, 14], state: "minecraft:deepslate_bricks"},
        {pos: [11, 4, 0], state: "minecraft:deepslate_bricks"},
        {pos: [11, 4, 1], state: "minecraft:deepslate_bricks"},
        {pos: [11, 4, 2], state: "minecraft:deepslate_bricks"},
        {pos: [11, 4, 5], state: "minecraft:deepslate_bricks"},
        {pos: [11, 4, 6], state: "minecraft:deepslate_bricks"},
        {pos: [11, 4, 7], state: "minecraft:deepslate_bricks"},
        {pos: [11, 4, 8], state: "minecraft:deepslate_bricks"},
        {pos: [11, 4, 9], state: "minecraft:deepslate_bricks"},
        {pos: [11, 4, 10], state: "minecraft:deepslate_bricks"},
        {pos: [11, 4, 11], state: "minecraft:gravel"},
        {pos: [11, 4, 12], state: "minecraft:gravel"},
        {pos: [11, 4, 13], state: "minecraft:gravel"},
        {pos: [11, 4, 14], state: "minecraft:deepslate_bricks"},
        {pos: [12, 4, 10], state: "minecraft:deepslate_bricks"},
        {pos: [12, 4, 11], state: "minecraft:deepslate_bricks"},
        {pos: [12, 4, 12], state: "minecraft:deepslate_bricks"},
        {pos: [12, 4, 13], state: "minecraft:deepslate_bricks"},
        {pos: [12, 4, 14], state: "minecraft:deepslate_bricks"},
        {pos: [0, 5, 5], state: "minecraft:deepslate{axis:y}"},
        {pos: [0, 5, 6], state: "minecraft:deepslate{axis:y}"},
        {pos: [0, 5, 7], state: "minecraft:deepslate{axis:y}"},
        {pos: [0, 5, 8], state: "minecraft:deepslate{axis:y}"},
        {pos: [0, 5, 9], state: "minecraft:deepslate{axis:y}"},
        {pos: [0, 5, 10], state: "minecraft:deepslate{axis:y}"},
        {pos: [0, 5, 11], state: "minecraft:deepslate{axis:y}"},
        {pos: [0, 5, 12], state: "minecraft:deepslate{axis:y}"},
        {pos: [0, 5, 13], state: "minecraft:deepslate{axis:y}"},
        {pos: [0, 5, 14], state: "minecraft:deepslate{axis:y}"},
        {pos: [0, 5, 15], state: "minecraft:deepslate{axis:y}"},
        {pos: [0, 5, 16], state: "minecraft:deepslate{axis:y}"},
        {pos: [0, 5, 17], state: "minecraft:deepslate{axis:y}"},
        {pos: [0, 5, 18], state: "minecraft:deepslate{axis:y}"},
        {pos: [0, 5, 19], state: "minecraft:deepslate{axis:y}"},
        {pos: [1, 5, 5], state: "minecraft:deepslate{axis:y}"},
        {pos: [1, 5, 6], state: "minecraft:deepslate{axis:y}"},
        {pos: [1, 5, 7], state: "minecraft:deepslate{axis:y}"},
        {pos: [1, 5, 8], state: "minecraft:deepslate{axis:y}"},
        {pos: [1, 5, 9], state: "minecraft:deepslate{axis:y}"},
        {pos: [1, 5, 10], state: "minecraft:deepslate{axis:y}"},
        {pos: [1, 5, 11], state: "minecraft:deepslate{axis:y}"},
        {pos: [1, 5, 12], state: "minecraft:deepslate{axis:y}"},
        {pos: [1, 5, 13], state: "minecraft:deepslate{axis:y}"},
        {pos: [1, 5, 14], state: "minecraft:deepslate{axis:y}"},
        {pos: [1, 5, 15], state: "minecraft:deepslate{axis:y}"},
        {pos: [1, 5, 16], state: "minecraft:deepslate{axis:y}"},
        {pos: [1, 5, 17], state: "minecraft:deepslate{axis:y}"},
        {pos: [1, 5, 18], state: "minecraft:deepslate{axis:y}"},
        {pos: [1, 5, 19], state: "minecraft:deepslate{axis:y}"},
        {pos: [2, 5, 5], state: "minecraft:deepslate{axis:y}"},
        {pos: [2, 5, 6], state: "minecraft:deepslate{axis:y}"},
        {pos: [2, 5, 7], state: "minecraft:deepslate{axis:y}"},
        {pos: [2, 5, 8], state: "minecraft:deepslate{axis:y}"},
        {pos: [2, 5, 9], state: "minecraft:deepslate{axis:y}"},
        {pos: [2, 5, 10], state: "minecraft:deepslate{axis:y}"},
        {pos: [2, 5, 11], state: "minecraft:deepslate{axis:y}"},
        {pos: [2, 5, 12], state: "minecraft:deepslate{axis:y}"},
        {pos: [2, 5, 13], state: "minecraft:deepslate{axis:y}"},
        {pos: [2, 5, 14], state: "minecraft:deepslate{axis:y}"},
        {pos: [2, 5, 15], state: "minecraft:deepslate{axis:y}"},
        {pos: [2, 5, 16], state: "minecraft:deepslate{axis:y}"},
        {pos: [2, 5, 17], state: "minecraft:deepslate{axis:y}"},
        {pos: [2, 5, 18], state: "minecraft:deepslate{axis:y}"},
        {pos: [2, 5, 19], state: "minecraft:deepslate{axis:y}"},
        {pos: [3, 5, 5], state: "minecraft:deepslate{axis:y}"},
        {pos: [3, 5, 6], state: "minecraft:deepslate{axis:y}"},
        {pos: [3, 5, 7], state: "minecraft:deepslate{axis:y}"},
        {pos: [3, 5, 8], state: "minecraft:deepslate{axis:y}"},
        {pos: [3, 5, 9], state: "minecraft:deepslate{axis:y}"},
        {pos: [3, 5, 10], state: "minecraft:deepslate{axis:y}"},
        {pos: [3, 5, 11], state: "minecraft:deepslate{axis:y}"},
        {pos: [3, 5, 12], state: "minecraft:deepslate{axis:y}"},
        {pos: [3, 5, 13], state: "minecraft:deepslate{axis:y}"},
        {pos: [3, 5, 14], state: "minecraft:deepslate{axis:y}"},
        {pos: [3, 5, 15], state: "minecraft:deepslate{axis:y}"},
        {pos: [3, 5, 16], state: "minecraft:deepslate{axis:y}"},
        {pos: [3, 5, 17], state: "minecraft:deepslate{axis:y}"},
        {pos: [3, 5, 18], state: "minecraft:deepslate{axis:y}"},
        {pos: [3, 5, 19], state: "minecraft:deepslate{axis:y}"},
        {pos: [4, 5, 5], state: "minecraft:deepslate{axis:y}"},
        {pos: [4, 5, 6], state: "minecraft:deepslate{axis:y}"},
        {pos: [4, 5, 7], state: "minecraft:deepslate{axis:y}"},
        {pos: [4, 5, 8], state: "minecraft:deepslate{axis:y}"},
        {pos: [4, 5, 9], state: "minecraft:deepslate{axis:y}"},
        {pos: [4, 5, 10], state: "minecraft:deepslate{axis:y}"},
        {pos: [4, 5, 11], state: "minecraft:deepslate{axis:y}"},
        {pos: [4, 5, 12], state: "minecraft:deepslate{axis:y}"},
        {pos: [4, 5, 13], state: "minecraft:deepslate{axis:y}"},
        {pos: [4, 5, 14], state: "minecraft:deepslate{axis:y}"},
        {pos: [4, 5, 15], state: "minecraft:deepslate{axis:y}"},
        {pos: [4, 5, 16], state: "minecraft:deepslate{axis:y}"},
        {pos: [4, 5, 17], state: "minecraft:deepslate{axis:y}"},
        {pos: [4, 5, 18], state: "minecraft:deepslate{axis:y}"},
        {pos: [4, 5, 19], state: "minecraft:deepslate{axis:y}"},
        {pos: [5, 5, 5], state: "minecraft:deepslate{axis:y}"},
        {pos: [5, 5, 6], state: "minecraft:deepslate{axis:y}"},
        {pos: [5, 5, 7], state: "minecraft:deepslate{axis:y}"},
        {pos: [5, 5, 8], state: "minecraft:deepslate{axis:y}"},
        {pos: [5, 5, 9], state: "minecraft:deepslate{axis:y}"},
        {pos: [5, 5, 10], state: "minecraft:deepslate{axis:y}"},
        {pos: [5, 5, 11], state: "minecraft:deepslate{axis:y}"},
        {pos: [5, 5, 12], state: "minecraft:deepslate{axis:y}"},
        {pos: [5, 5, 13], state: "minecraft:deepslate{axis:y}"},
        {pos: [5, 5, 14], state: "minecraft:deepslate{axis:y}"},
        {pos: [5, 5, 15], state: "minecraft:deepslate{axis:y}"},
        {pos: [5, 5, 16], state: "minecraft:deepslate{axis:y}"},
        {pos: [5, 5, 17], state: "minecraft:deepslate{axis:y}"},
        {pos: [5, 5, 18], state: "minecraft:deepslate{axis:y}"},
        {pos: [5, 5, 19], state: "minecraft:deepslate{axis:y}"},
        {pos: [6, 5, 2], state: "minecraft:deepslate{axis:y}"},
        {pos: [6, 5, 3], state: "minecraft:deepslate{axis:y}"},
        {pos: [6, 5, 4], state: "minecraft:deepslate{axis:y}"},
        {pos: [6, 5, 5], state: "minecraft:deepslate{axis:y}"},
        {pos: [6, 5, 6], state: "minecraft:deepslate{axis:y}"},
        {pos: [6, 5, 7], state: "minecraft:deepslate{axis:y}"},
        {pos: [6, 5, 8], state: "minecraft:deepslate{axis:y}"},
        {pos: [6, 5, 9], state: "minecraft:deepslate{axis:y}"},
        {pos: [6, 5, 10], state: "minecraft:deepslate{axis:y}"},
        {pos: [6, 5, 11], state: "minecraft:deepslate{axis:y}"},
        {pos: [6, 5, 12], state: "minecraft:deepslate{axis:y}"},
        {pos: [6, 5, 13], state: "minecraft:deepslate{axis:y}"},
        {pos: [6, 5, 14], state: "minecraft:deepslate{axis:y}"},
        {pos: [6, 5, 15], state: "minecraft:deepslate{axis:y}"},
        {pos: [6, 5, 16], state: "minecraft:deepslate{axis:y}"},
        {pos: [6, 5, 17], state: "minecraft:deepslate{axis:y}"},
        {pos: [6, 5, 18], state: "minecraft:deepslate{axis:y}"},
        {pos: [6, 5, 19], state: "minecraft:deepslate{axis:y}"},
        {pos: [6, 5, 20], state: "minecraft:deepslate{axis:y}"},
        {pos: [6, 5, 21], state: "minecraft:deepslate{axis:y}"},
        {pos: [6, 5, 22], state: "minecraft:deepslate{axis:y}"},
        {pos: [7, 5, 0], state: "minecraft:deepslate_bricks"},
        {pos: [7, 5, 1], state: "minecraft:deepslate_bricks"},
        {pos: [7, 5, 2], state: "minecraft:deepslate{axis:y}"},
        {pos: [7, 5, 3], state: "minecraft:deepslate{axis:y}"},
        {pos: [7, 5, 4], state: "minecraft:deepslate{axis:y}"},
        {pos: [7, 5, 5], state: "minecraft:deepslate{axis:y}"},
        {pos: [7, 5, 6], state: "minecraft:deepslate{axis:y}"},
        {pos: [7, 5, 7], state: "minecraft:deepslate{axis:y}"},
        {pos: [7, 5, 8], state: "minecraft:deepslate{axis:y}"},
        {pos: [7, 5, 9], state: "minecraft:deepslate{axis:y}"},
        {pos: [7, 5, 10], state: "minecraft:deepslate{axis:y}"},
        {pos: [7, 5, 11], state: "minecraft:deepslate{axis:y}"},
        {pos: [7, 5, 12], state: "minecraft:deepslate{axis:y}"},
        {pos: [7, 5, 13], state: "minecraft:deepslate{axis:y}"},
        {pos: [7, 5, 14], state: "minecraft:deepslate{axis:y}"},
        {pos: [7, 5, 15], state: "minecraft:deepslate{axis:y}"},
        {pos: [7, 5, 16], state: "minecraft:deepslate{axis:y}"},
        {pos: [7, 5, 17], state: "minecraft:deepslate{axis:y}"},
        {pos: [7, 5, 18], state: "minecraft:deepslate{axis:y}"},
        {pos: [7, 5, 19], state: "minecraft:deepslate{axis:y}"},
        {pos: [7, 5, 20], state: "minecraft:deepslate{axis:y}"},
        {pos: [7, 5, 21], state: "minecraft:deepslate{axis:y}"},
        {pos: [7, 5, 22], state: "minecraft:deepslate{axis:y}"},
        {pos: [8, 5, 0], state: "minecraft:deepslate_bricks"},
        {pos: [8, 5, 1], state: "minecraft:redstone_wire{east:up,north:none,power:0,south:side,west:none}"},
        {pos: [8, 5, 2], state: "minecraft:cave_air"},
        {pos: [8, 5, 3], state: "minecraft:deepslate{axis:y}"},
        {pos: [8, 5, 4], state: "minecraft:deepslate{axis:y}"},
        {pos: [8, 5, 5], state: "minecraft:deepslate{axis:y}"},
        {pos: [8, 5, 6], state: "minecraft:deepslate{axis:y}"},
        {pos: [8, 5, 7], state: "minecraft:deepslate{axis:y}"},
        {pos: [8, 5, 8], state: "minecraft:deepslate{axis:y}"},
        {pos: [8, 5, 9], state: "minecraft:deepslate{axis:y}"},
        {pos: [8, 5, 10], state: "minecraft:deepslate{axis:y}"},
        {pos: [8, 5, 11], state: "minecraft:deepslate_bricks"},
        {pos: [8, 5, 12], state: "minecraft:deepslate_bricks"},
        {pos: [8, 5, 13], state: "minecraft:deepslate_bricks"},
        {pos: [8, 5, 14], state: "minecraft:deepslate{axis:y}"},
        {pos: [8, 5, 15], state: "minecraft:deepslate{axis:y}"},
        {pos: [8, 5, 16], state: "minecraft:deepslate{axis:y}"},
        {pos: [8, 5, 17], state: "minecraft:deepslate{axis:y}"},
        {pos: [8, 5, 18], state: "minecraft:deepslate{axis:y}"},
        {pos: [8, 5, 19], state: "minecraft:deepslate{axis:y}"},
        {pos: [8, 5, 20], state: "minecraft:deepslate{axis:y}"},
        {pos: [8, 5, 21], state: "minecraft:deepslate{axis:y}"},
        {pos: [8, 5, 22], state: "minecraft:deepslate{axis:y}"},
        {pos: [9, 5, 0], state: "minecraft:deepslate_bricks"},
        {pos: [9, 5, 1], state: "minecraft:deepslate_bricks"},
        {pos: [9, 5, 2], state: "minecraft:deepslate{axis:y}"},
        {pos: [9, 5, 3], state: "minecraft:deepslate{axis:y}"},
        {pos: [9, 5, 4], state: "minecraft:deepslate{axis:y}"},
        {pos: [9, 5, 5], state: "minecraft:deepslate{axis:y}"},
        {pos: [9, 5, 6], state: "minecraft:deepslate{axis:y}"},
        {pos: [9, 5, 7], state: "minecraft:deepslate{axis:y}"},
        {pos: [9, 5, 8], state: "minecraft:deepslate{axis:y}"},
        {pos: [9, 5, 9], state: "minecraft:deepslate{axis:y}"},
        {pos: [9, 5, 10], state: "minecraft:deepslate_bricks"},
        {pos: [9, 5, 11], state: "minecraft:gravel"},
        {pos: [9, 5, 12], state: "minecraft:gravel"},
        {pos: [9, 5, 13], state: "minecraft:gravel"},
        {pos: [9, 5, 14], state: "minecraft:deepslate_bricks"},
        {pos: [9, 5, 15], state: "minecraft:deepslate{axis:y}"},
        {pos: [9, 5, 16], state: "minecraft:deepslate{axis:y}"},
        {pos: [9, 5, 17], state: "minecraft:deepslate{axis:y}"},
        {pos: [9, 5, 18], state: "minecraft:deepslate{axis:y}"},
        {pos: [9, 5, 19], state: "minecraft:deepslate{axis:y}"},
        {pos: [9, 5, 20], state: "minecraft:deepslate{axis:y}"},
        {pos: [9, 5, 21], state: "minecraft:deepslate{axis:y}"},
        {pos: [9, 5, 22], state: "minecraft:deepslate{axis:y}"},
        {pos: [10, 5, 0], state: "minecraft:deepslate_bricks"},
        {pos: [10, 5, 1], state: "minecraft:deepslate_bricks"},
        {pos: [10, 5, 2], state: "minecraft:deepslate{axis:y}"},
        {pos: [10, 5, 3], state: "minecraft:deepslate{axis:y}"},
        {pos: [10, 5, 4], state: "minecraft:deepslate{axis:y}"},
        {pos: [10, 5, 5], state: "minecraft:redstone_wall_torch{facing:north,lit:true}"},
        {pos: [10, 5, 6], state: "minecraft:deepslate_bricks"},
        {pos: [10, 5, 7], state: "minecraft:deepslate{axis:y}"},
        {pos: [10, 5, 8], state: "minecraft:deepslate{axis:y}"},
        {pos: [10, 5, 9], state: "minecraft:deepslate{axis:y}"},
        {pos: [10, 5, 10], state: "minecraft:deepslate_bricks"},
        {pos: [10, 5, 11], state: "minecraft:gravel"},
        {pos: [10, 5, 12], state: "minecraft:gravel"},
        {pos: [10, 5, 13], state: "minecraft:gravel"},
        {pos: [10, 5, 14], state: "minecraft:deepslate_bricks"},
        {pos: [10, 5, 15], state: "minecraft:deepslate{axis:y}"},
        {pos: [10, 5, 16], state: "minecraft:deepslate{axis:y}"},
        {pos: [10, 5, 17], state: "minecraft:deepslate{axis:y}"},
        {pos: [10, 5, 18], state: "minecraft:deepslate{axis:y}"},
        {pos: [10, 5, 19], state: "minecraft:deepslate{axis:y}"},
        {pos: [10, 5, 20], state: "minecraft:deepslate{axis:y}"},
        {pos: [10, 5, 21], state: "minecraft:deepslate{axis:y}"},
        {pos: [10, 5, 22], state: "minecraft:deepslate{axis:y}"},
        {pos: [11, 5, 0], state: "minecraft:deepslate_bricks"},
        {pos: [11, 5, 1], state: "minecraft:deepslate_bricks"},
        {pos: [11, 5, 2], state: "minecraft:deepslate{axis:y}"},
        {pos: [11, 5, 3], state: "minecraft:deepslate{axis:y}"},
        {pos: [11, 5, 4], state: "minecraft:deepslate{axis:y}"},
        {pos: [11, 5, 5], state: "minecraft:deepslate{axis:y}"},
        {pos: [11, 5, 6], state: "minecraft:deepslate{axis:y}"},
        {pos: [11, 5, 7], state: "minecraft:deepslate{axis:y}"},
        {pos: [11, 5, 8], state: "minecraft:deepslate{axis:y}"},
        {pos: [11, 5, 9], state: "minecraft:deepslate{axis:y}"},
        {pos: [11, 5, 10], state: "minecraft:deepslate_bricks"},
        {pos: [11, 5, 11], state: "minecraft:gravel"},
        {pos: [11, 5, 12], state: "minecraft:gravel"},
        {pos: [11, 5, 13], state: "minecraft:gravel"},
        {pos: [11, 5, 14], state: "minecraft:deepslate_bricks"},
        {pos: [11, 5, 15], state: "minecraft:deepslate{axis:y}"},
        {pos: [11, 5, 16], state: "minecraft:deepslate{axis:y}"},
        {pos: [11, 5, 17], state: "minecraft:deepslate{axis:y}"},
        {pos: [11, 5, 18], state: "minecraft:deepslate{axis:y}"},
        {pos: [11, 5, 19], state: "minecraft:deepslate{axis:y}"},
        {pos: [11, 5, 20], state: "minecraft:deepslate{axis:y}"},
        {pos: [11, 5, 21], state: "minecraft:deepslate{axis:y}"},
        {pos: [11, 5, 22], state: "minecraft:deepslate{axis:y}"},
        {pos: [12, 5, 2], state: "minecraft:deepslate{axis:y}"},
        {pos: [12, 5, 3], state: "minecraft:deepslate{axis:y}"},
        {pos: [12, 5, 4], state: "minecraft:deepslate{axis:y}"},
        {pos: [12, 5, 5], state: "minecraft:deepslate{axis:y}"},
        {pos: [12, 5, 6], state: "minecraft:deepslate{axis:y}"},
        {pos: [12, 5, 7], state: "minecraft:deepslate{axis:y}"},
        {pos: [12, 5, 8], state: "minecraft:deepslate{axis:y}"},
        {pos: [12, 5, 9], state: "minecraft:deepslate{axis:y}"},
        {pos: [12, 5, 10], state: "minecraft:deepslate{axis:y}"},
        {pos: [12, 5, 11], state: "minecraft:deepslate_bricks"},
        {pos: [12, 5, 12], state: "minecraft:deepslate_bricks"},
        {pos: [12, 5, 13], state: "minecraft:deepslate_bricks"},
        {pos: [12, 5, 14], state: "minecraft:deepslate{axis:y}"},
        {pos: [12, 5, 15], state: "minecraft:deepslate{axis:y}"},
        {pos: [12, 5, 16], state: "minecraft:deepslate{axis:y}"},
        {pos: [12, 5, 17], state: "minecraft:deepslate{axis:y}"},
        {pos: [12, 5, 18], state: "minecraft:deepslate{axis:y}"},
        {pos: [12, 5, 19], state: "minecraft:deepslate{axis:y}"},
        {pos: [12, 5, 20], state: "minecraft:deepslate{axis:y}"},
        {pos: [12, 5, 21], state: "minecraft:deepslate{axis:y}"},
        {pos: [12, 5, 22], state: "minecraft:deepslate{axis:y}"},
        {pos: [13, 5, 2], state: "minecraft:deepslate{axis:y}"},
        {pos: [13, 5, 3], state: "minecraft:deepslate{axis:y}"},
        {pos: [13, 5, 4], state: "minecraft:deepslate{axis:y}"},
        {pos: [13, 5, 5], state: "minecraft:deepslate{axis:y}"},
        {pos: [13, 5, 6], state: "minecraft:deepslate{axis:y}"},
        {pos: [13, 5, 7], state: "minecraft:deepslate{axis:y}"},
        {pos: [13, 5, 8], state: "minecraft:deepslate{axis:y}"},
        {pos: [13, 5, 9], state: "minecraft:deepslate{axis:y}"},
        {pos: [13, 5, 10], state: "minecraft:deepslate{axis:y}"},
        {pos: [13, 5, 11], state: "minecraft:deepslate{axis:y}"},
        {pos: [13, 5, 12], state: "minecraft:deepslate{axis:y}"},
        {pos: [13, 5, 13], state: "minecraft:deepslate{axis:y}"},
        {pos: [13, 5, 14], state: "minecraft:deepslate{axis:y}"},
        {pos: [13, 5, 15], state: "minecraft:deepslate{axis:y}"},
        {pos: [13, 5, 16], state: "minecraft:deepslate{axis:y}"},
        {pos: [13, 5, 17], state: "minecraft:deepslate{axis:y}"},
        {pos: [13, 5, 18], state: "minecraft:deepslate{axis:y}"},
        {pos: [13, 5, 19], state: "minecraft:deepslate{axis:y}"},
        {pos: [13, 5, 20], state: "minecraft:deepslate{axis:y}"},
        {pos: [13, 5, 21], state: "minecraft:deepslate{axis:y}"},
        {pos: [13, 5, 22], state: "minecraft:deepslate{axis:y}"},
        {pos: [14, 5, 2], state: "minecraft:deepslate{axis:y}"},
        {pos: [14, 5, 3], state: "minecraft:deepslate{axis:y}"},
        {pos: [14, 5, 4], state: "minecraft:deepslate{axis:y}"},
        {pos: [14, 5, 5], state: "minecraft:deepslate{axis:y}"},
        {pos: [14, 5, 6], state: "minecraft:deepslate{axis:y}"},
        {pos: [14, 5, 7], state: "minecraft:deepslate{axis:y}"},
        {pos: [14, 5, 8], state: "minecraft:deepslate{axis:y}"},
        {pos: [14, 5, 9], state: "minecraft:deepslate{axis:y}"},
        {pos: [14, 5, 10], state: "minecraft:deepslate{axis:y}"},
        {pos: [14, 5, 11], state: "minecraft:deepslate{axis:y}"},
        {pos: [14, 5, 12], state: "minecraft:deepslate{axis:y}"},
        {pos: [14, 5, 13], state: "minecraft:deepslate{axis:y}"},
        {pos: [14, 5, 14], state: "minecraft:deepslate{axis:y}"},
        {pos: [14, 5, 15], state: "minecraft:deepslate{axis:y}"},
        {pos: [14, 5, 16], state: "minecraft:deepslate{axis:y}"},
        {pos: [14, 5, 17], state: "minecraft:deepslate{axis:y}"},
        {pos: [14, 5, 18], state: "minecraft:deepslate{axis:y}"},
        {pos: [14, 5, 19], state: "minecraft:deepslate{axis:y}"},
        {pos: [14, 5, 20], state: "minecraft:deepslate{axis:y}"},
        {pos: [14, 5, 21], state: "minecraft:deepslate{axis:y}"},
        {pos: [14, 5, 22], state: "minecraft:deepslate{axis:y}"},
        {pos: [15, 5, 5], state: "minecraft:deepslate{axis:y}"},
        {pos: [15, 5, 6], state: "minecraft:deepslate{axis:y}"},
        {pos: [15, 5, 7], state: "minecraft:deepslate{axis:y}"},
        {pos: [15, 5, 8], state: "minecraft:deepslate{axis:y}"},
        {pos: [15, 5, 9], state: "minecraft:deepslate{axis:y}"},
        {pos: [15, 5, 10], state: "minecraft:deepslate{axis:y}"},
        {pos: [15, 5, 11], state: "minecraft:deepslate{axis:y}"},
        {pos: [15, 5, 12], state: "minecraft:deepslate{axis:y}"},
        {pos: [15, 5, 13], state: "minecraft:deepslate{axis:y}"},
        {pos: [15, 5, 14], state: "minecraft:deepslate{axis:y}"},
        {pos: [15, 5, 15], state: "minecraft:deepslate{axis:y}"},
        {pos: [15, 5, 16], state: "minecraft:deepslate{axis:y}"},
        {pos: [15, 5, 17], state: "minecraft:deepslate{axis:y}"},
        {pos: [15, 5, 18], state: "minecraft:deepslate{axis:y}"},
        {pos: [15, 5, 19], state: "minecraft:deepslate{axis:y}"},
        {pos: [16, 5, 5], state: "minecraft:deepslate{axis:y}"},
        {pos: [16, 5, 6], state: "minecraft:deepslate{axis:y}"},
        {pos: [16, 5, 7], state: "minecraft:deepslate{axis:y}"},
        {pos: [16, 5, 8], state: "minecraft:deepslate{axis:y}"},
        {pos: [16, 5, 9], state: "minecraft:deepslate{axis:y}"},
        {pos: [16, 5, 10], state: "minecraft:deepslate{axis:y}"},
        {pos: [16, 5, 11], state: "minecraft:deepslate{axis:y}"},
        {pos: [16, 5, 12], state: "minecraft:deepslate{axis:y}"},
        {pos: [16, 5, 13], state: "minecraft:deepslate{axis:y}"},
        {pos: [16, 5, 14], state: "minecraft:deepslate{axis:y}"},
        {pos: [16, 5, 15], state: "minecraft:deepslate{axis:y}"},
        {pos: [16, 5, 16], state: "minecraft:deepslate{axis:y}"},
        {pos: [16, 5, 17], state: "minecraft:deepslate{axis:y}"},
        {pos: [16, 5, 18], state: "minecraft:deepslate{axis:y}"},
        {pos: [16, 5, 19], state: "minecraft:deepslate{axis:y}"},
        {pos: [17, 5, 5], state: "minecraft:deepslate{axis:y}"},
        {pos: [17, 5, 6], state: "minecraft:deepslate{axis:y}"},
        {pos: [17, 5, 7], state: "minecraft:deepslate{axis:y}"},
        {pos: [17, 5, 8], state: "minecraft:deepslate{axis:y}"},
        {pos: [17, 5, 9], state: "minecraft:deepslate{axis:y}"},
        {pos: [17, 5, 10], state: "minecraft:deepslate{axis:y}"},
        {pos: [17, 5, 11], state: "minecraft:deepslate{axis:y}"},
        {pos: [17, 5, 12], state: "minecraft:deepslate{axis:y}"},
        {pos: [17, 5, 13], state: "minecraft:deepslate{axis:y}"},
        {pos: [17, 5, 14], state: "minecraft:deepslate{axis:y}"},
        {pos: [17, 5, 15], state: "minecraft:deepslate{axis:y}"},
        {pos: [17, 5, 16], state: "minecraft:deepslate{axis:y}"},
        {pos: [17, 5, 17], state: "minecraft:deepslate{axis:y}"},
        {pos: [17, 5, 18], state: "minecraft:deepslate{axis:y}"},
        {pos: [17, 5, 19], state: "minecraft:deepslate{axis:y}"},
        {pos: [18, 5, 5], state: "minecraft:deepslate{axis:y}"},
        {pos: [18, 5, 6], state: "minecraft:deepslate{axis:y}"},
        {pos: [18, 5, 7], state: "minecraft:deepslate{axis:y}"},
        {pos: [18, 5, 8], state: "minecraft:deepslate{axis:y}"},
        {pos: [18, 5, 9], state: "minecraft:deepslate{axis:y}"},
        {pos: [18, 5, 10], state: "minecraft:deepslate{axis:y}"},
        {pos: [18, 5, 11], state: "minecraft:deepslate{axis:y}"},
        {pos: [18, 5, 12], state: "minecraft:deepslate{axis:y}"},
        {pos: [18, 5, 13], state: "minecraft:deepslate{axis:y}"},
        {pos: [18, 5, 14], state: "minecraft:deepslate{axis:y}"},
        {pos: [18, 5, 15], state: "minecraft:deepslate{axis:y}"},
        {pos: [18, 5, 16], state: "minecraft:deepslate{axis:y}"},
        {pos: [18, 5, 17], state: "minecraft:deepslate{axis:y}"},
        {pos: [18, 5, 18], state: "minecraft:deepslate{axis:y}"},
        {pos: [18, 5, 19], state: "minecraft:deepslate{axis:y}"},
        {pos: [19, 5, 5], state: "minecraft:deepslate{axis:y}"},
        {pos: [19, 5, 6], state: "minecraft:deepslate{axis:y}"},
        {pos: [19, 5, 7], state: "minecraft:deepslate{axis:y}"},
        {pos: [19, 5, 8], state: "minecraft:deepslate{axis:y}"},
        {pos: [19, 5, 9], state: "minecraft:deepslate{axis:y}"},
        {pos: [19, 5, 10], state: "minecraft:deepslate{axis:y}"},
        {pos: [19, 5, 11], state: "minecraft:deepslate{axis:y}"},
        {pos: [19, 5, 12], state: "minecraft:deepslate{axis:y}"},
        {pos: [19, 5, 13], state: "minecraft:deepslate{axis:y}"},
        {pos: [19, 5, 14], state: "minecraft:deepslate{axis:y}"},
        {pos: [19, 5, 15], state: "minecraft:deepslate{axis:y}"},
        {pos: [19, 5, 16], state: "minecraft:deepslate{axis:y}"},
        {pos: [19, 5, 17], state: "minecraft:deepslate{axis:y}"},
        {pos: [19, 5, 18], state: "minecraft:deepslate{axis:y}"},
        {pos: [20, 5, 5], state: "minecraft:deepslate{axis:y}"},
        {pos: [20, 5, 6], state: "minecraft:deepslate{axis:y}"},
        {pos: [20, 5, 7], state: "minecraft:deepslate{axis:y}"},
        {pos: [20, 5, 8], state: "minecraft:deepslate{axis:y}"},
        {pos: [20, 5, 9], state: "minecraft:deepslate{axis:y}"},
        {pos: [20, 5, 10], state: "minecraft:deepslate{axis:y}"},
        {pos: [20, 5, 11], state: "minecraft:deepslate{axis:y}"},
        {pos: [20, 5, 12], state: "minecraft:deepslate{axis:y}"},
        {pos: [20, 5, 13], state: "minecraft:deepslate{axis:y}"},
        {pos: [20, 5, 14], state: "minecraft:deepslate{axis:y}"},
        {pos: [20, 5, 15], state: "minecraft:deepslate{axis:y}"},
        {pos: [20, 5, 16], state: "minecraft:deepslate{axis:y}"},
        {pos: [20, 5, 17], state: "minecraft:deepslate{axis:y}"},
        {pos: [20, 5, 18], state: "minecraft:deepslate{axis:y}"},
        {pos: [0, 6, 5], state: "minecraft:deepslate_bricks"},
        {pos: [0, 6, 6], state: "minecraft:deepslate_bricks"},
        {pos: [0, 6, 7], state: "minecraft:deepslate_bricks"},
        {pos: [0, 6, 8], state: "minecraft:deepslate_bricks"},
        {pos: [0, 6, 9], state: "minecraft:deepslate_bricks"},
        {pos: [0, 6, 10], state: "minecraft:deepslate_bricks"},
        {pos: [0, 6, 11], state: "minecraft:gravel"},
        {pos: [0, 6, 12], state: "minecraft:gravel"},
        {pos: [0, 6, 13], state: "minecraft:gravel"},
        {pos: [0, 6, 14], state: "minecraft:deepslate_bricks"},
        {pos: [0, 6, 15], state: "minecraft:deepslate_bricks"},
        {pos: [0, 6, 16], state: "minecraft:deepslate_bricks"},
        {pos: [0, 6, 17], state: "minecraft:deepslate_bricks"},
        {pos: [0, 6, 18], state: "minecraft:deepslate_bricks"},
        {pos: [0, 6, 19], state: "minecraft:deepslate_bricks"},
        {pos: [1, 6, 5], state: "minecraft:deepslate_bricks"},
        {pos: [1, 6, 6], state: "minecraft:gravel"},
        {pos: [1, 6, 7], state: "minecraft:gravel"},
        {pos: [1, 6, 8], state: "minecraft:gravel"},
        {pos: [1, 6, 9], state: "minecraft:gravel"},
        {pos: [1, 6, 10], state: "minecraft:gravel"},
        {pos: [1, 6, 11], state: "minecraft:gravel"},
        {pos: [1, 6, 12], state: "minecraft:gravel"},
        {pos: [1, 6, 13], state: "minecraft:gravel"},
        {pos: [1, 6, 14], state: "minecraft:gravel"},
        {pos: [1, 6, 15], state: "minecraft:gravel"},
        {pos: [1, 6, 16], state: "minecraft:gravel"},
        {pos: [1, 6, 17], state: "minecraft:gravel"},
        {pos: [1, 6, 18], state: "minecraft:gravel"},
        {pos: [1, 6, 19], state: "minecraft:deepslate_bricks"},
        {pos: [2, 6, 5], state: "minecraft:deepslate_bricks"},
        {pos: [2, 6, 6], state: "minecraft:gravel"},
        {pos: [2, 6, 7], state: "minecraft:gravel"},
        {pos: [2, 6, 8], state: "minecraft:gravel"},
        {pos: [2, 6, 9], state: "minecraft:gravel"},
        {pos: [2, 6, 10], state: "minecraft:gravel"},
        {pos: [2, 6, 11], state: "minecraft:gravel"},
        {pos: [2, 6, 12], state: "minecraft:gravel"},
        {pos: [2, 6, 13], state: "minecraft:gravel"},
        {pos: [2, 6, 14], state: "minecraft:gravel"},
        {pos: [2, 6, 15], state: "minecraft:gravel"},
        {pos: [2, 6, 16], state: "minecraft:gravel"},
        {pos: [2, 6, 17], state: "minecraft:gravel"},
        {pos: [2, 6, 18], state: "minecraft:gravel"},
        {pos: [2, 6, 19], state: "minecraft:deepslate_bricks"},
        {pos: [3, 6, 5], state: "minecraft:deepslate_bricks"},
        {pos: [3, 6, 6], state: "minecraft:gravel"},
        {pos: [3, 6, 7], state: "minecraft:gravel"},
        {pos: [3, 6, 8], state: "minecraft:gravel"},
        {pos: [3, 6, 9], state: "minecraft:gravel"},
        {pos: [3, 6, 10], state: "minecraft:gravel"},
        {pos: [3, 6, 11], state: "minecraft:gravel"},
        {pos: [3, 6, 12], state: "minecraft:gravel"},
        {pos: [3, 6, 13], state: "minecraft:gravel"},
        {pos: [3, 6, 14], state: "minecraft:gravel"},
        {pos: [3, 6, 15], state: "minecraft:gravel"},
        {pos: [3, 6, 16], state: "minecraft:gravel"},
        {pos: [3, 6, 17], state: "minecraft:gravel"},
        {pos: [3, 6, 18], state: "minecraft:gravel"},
        {pos: [3, 6, 19], state: "minecraft:deepslate_bricks"},
        {pos: [4, 6, 5], state: "minecraft:deepslate_bricks"},
        {pos: [4, 6, 6], state: "minecraft:gravel"},
        {pos: [4, 6, 7], state: "minecraft:gravel"},
        {pos: [4, 6, 8], state: "minecraft:gravel"},
        {pos: [4, 6, 9], state: "minecraft:gravel"},
        {pos: [4, 6, 10], state: "minecraft:gravel"},
        {pos: [4, 6, 11], state: "minecraft:gravel"},
        {pos: [4, 6, 12], state: "minecraft:gravel"},
        {pos: [4, 6, 13], state: "minecraft:gravel"},
        {pos: [4, 6, 14], state: "minecraft:gravel"},
        {pos: [4, 6, 15], state: "minecraft:gravel"},
        {pos: [4, 6, 16], state: "minecraft:gravel"},
        {pos: [4, 6, 17], state: "minecraft:gravel"},
        {pos: [4, 6, 18], state: "minecraft:gravel"},
        {pos: [4, 6, 19], state: "minecraft:deepslate_bricks"},
        {pos: [5, 6, 5], state: "minecraft:deepslate_bricks"},
        {pos: [5, 6, 6], state: "minecraft:gravel"},
        {pos: [5, 6, 7], state: "minecraft:gravel"},
        {pos: [5, 6, 8], state: "minecraft:gravel"},
        {pos: [5, 6, 9], state: "minecraft:gravel"},
        {pos: [5, 6, 10], state: "minecraft:gravel"},
        {pos: [5, 6, 11], state: "minecraft:gravel"},
        {pos: [5, 6, 12], state: "minecraft:gravel"},
        {pos: [5, 6, 13], state: "minecraft:gravel"},
        {pos: [5, 6, 14], state: "minecraft:gravel"},
        {pos: [5, 6, 15], state: "minecraft:gravel"},
        {pos: [5, 6, 16], state: "minecraft:gravel"},
        {pos: [5, 6, 17], state: "minecraft:gravel"},
        {pos: [5, 6, 18], state: "minecraft:gravel"},
        {pos: [5, 6, 19], state: "minecraft:deepslate_bricks"},
        {pos: [6, 6, 2], state: "minecraft:deepslate_bricks"},
        {pos: [6, 6, 3], state: "minecraft:deepslate_bricks"},
        {pos: [6, 6, 4], state: "minecraft:deepslate_bricks"},
        {pos: [6, 6, 5], state: "minecraft:gravel"},
        {pos: [6, 6, 6], state: "minecraft:gravel"},
        {pos: [6, 6, 7], state: "minecraft:gravel"},
        {pos: [6, 6, 8], state: "minecraft:gravel"},
        {pos: [6, 6, 9], state: "minecraft:gravel"},
        {pos: [6, 6, 10], state: "minecraft:gravel"},
        {pos: [6, 6, 11], state: "minecraft:gravel"},
        {pos: [6, 6, 12], state: "minecraft:gravel"},
        {pos: [6, 6, 13], state: "minecraft:gravel"},
        {pos: [6, 6, 14], state: "minecraft:gravel"},
        {pos: [6, 6, 15], state: "minecraft:gravel"},
        {pos: [6, 6, 16], state: "minecraft:gravel"},
        {pos: [6, 6, 17], state: "minecraft:gravel"},
        {pos: [6, 6, 18], state: "minecraft:gravel"},
        {pos: [6, 6, 19], state: "minecraft:gravel"},
        {pos: [6, 6, 20], state: "minecraft:deepslate_bricks"},
        {pos: [6, 6, 21], state: "minecraft:deepslate_bricks"},
        {pos: [6, 6, 22], state: "minecraft:deepslate_bricks"},
        {pos: [7, 6, 0], state: "minecraft:deepslate_bricks"},
        {pos: [7, 6, 1], state: "minecraft:deepslate_bricks"},
        {pos: [7, 6, 2], state: "minecraft:deepslate_bricks"},
        {pos: [7, 6, 3], state: "minecraft:gravel"},
        {pos: [7, 6, 4], state: "minecraft:gravel"},
        {pos: [7, 6, 5], state: "minecraft:gravel"},
        {pos: [7, 6, 6], state: "minecraft:deepslate_bricks"},
        {pos: [7, 6, 7], state: "minecraft:deepslate_bricks"},
        {pos: [7, 6, 8], state: "minecraft:deepslate_bricks"},
        {pos: [7, 6, 9], state: "minecraft:deepslate_bricks"},
        {pos: [7, 6, 10], state: "minecraft:gravel"},
        {pos: [7, 6, 11], state: "minecraft:gravel"},
        {pos: [7, 6, 12], state: "minecraft:gravel"},
        {pos: [7, 6, 13], state: "minecraft:gravel"},
        {pos: [7, 6, 14], state: "minecraft:gravel"},
        {pos: [7, 6, 15], state: "minecraft:deepslate_bricks"},
        {pos: [7, 6, 16], state: "minecraft:deepslate_bricks"},
        {pos: [7, 6, 17], state: "minecraft:deepslate_bricks"},
        {pos: [7, 6, 18], state: "minecraft:deepslate_bricks"},
        {pos: [7, 6, 19], state: "minecraft:gravel"},
        {pos: [7, 6, 20], state: "minecraft:gravel"},
        {pos: [7, 6, 21], state: "minecraft:gravel"},
        {pos: [7, 6, 22], state: "minecraft:deepslate_bricks"},
        {pos: [8, 6, 0], state: "minecraft:deepslate_bricks"},
        {pos: [8, 6, 1], state: "minecraft:cave_air"},
        {pos: [8, 6, 2], state: "minecraft:deepslate_bricks"},
        {pos: [8, 6, 3], state: "minecraft:gravel"},
        {pos: [8, 6, 4], state: "minecraft:gravel"},
        {pos: [8, 6, 5], state: "minecraft:gravel"},
        {pos: [8, 6, 6], state: "minecraft:gravel"},
        {pos: [8, 6, 7], state: "minecraft:gravel"},
        {pos: [8, 6, 8], state: "minecraft:gravel"},
        {pos: [8, 6, 9], state: "minecraft:gravel"},
        {pos: [8, 6, 10], state: "minecraft:gravel"},
        {pos: [8, 6, 11], state: "minecraft:gravel"},
        {pos: [8, 6, 12], state: "minecraft:gravel"},
        {pos: [8, 6, 13], state: "minecraft:gravel"},
        {pos: [8, 6, 14], state: "minecraft:gravel"},
        {pos: [8, 6, 15], state: "minecraft:gravel"},
        {pos: [8, 6, 16], state: "minecraft:gravel"},
        {pos: [8, 6, 17], state: "minecraft:gravel"},
        {pos: [8, 6, 18], state: "minecraft:gravel"},
        {pos: [8, 6, 19], state: "minecraft:gravel"},
        {pos: [8, 6, 20], state: "minecraft:gravel"},
        {pos: [8, 6, 21], state: "minecraft:gravel"},
        {pos: [8, 6, 22], state: "minecraft:deepslate_bricks"},
        {pos: [9, 6, 0], state: "minecraft:deepslate_bricks"},
        {pos: [9, 6, 1], state: "minecraft:redstone_wire{east:up,north:none,power:0,south:none,west:side}"},
        {pos: [9, 6, 2], state: "minecraft:deepslate_bricks"},
        {pos: [9, 6, 3], state: "minecraft:gravel"},
        {pos: [9, 6, 4], state: "minecraft:gravel"},
        {pos: [9, 6, 5], state: "minecraft:gravel"},
        {pos: [9, 6, 6], state: "minecraft:gravel"},
        {pos: [9, 6, 7], state: "minecraft:gravel"},
        {pos: [9, 6, 8], state: "minecraft:gravel"},
        {pos: [9, 6, 9], state: "minecraft:gravel"},
        {pos: [9, 6, 10], state: "minecraft:gravel"},
        {pos: [9, 6, 11], state: "minecraft:gravel"},
        {pos: [9, 6, 12], state: "minecraft:gravel"},
        {pos: [9, 6, 13], state: "minecraft:gravel"},
        {pos: [9, 6, 14], state: "minecraft:gravel"},
        {pos: [9, 6, 15], state: "minecraft:gravel"},
        {pos: [9, 6, 16], state: "minecraft:gravel"},
        {pos: [9, 6, 17], state: "minecraft:gravel"},
        {pos: [9, 6, 18], state: "minecraft:gravel"},
        {pos: [9, 6, 19], state: "minecraft:gravel"},
        {pos: [9, 6, 20], state: "minecraft:gravel"},
        {pos: [9, 6, 21], state: "minecraft:gravel"},
        {pos: [9, 6, 22], state: "minecraft:deepslate_bricks"},
        {pos: [10, 6, 0], state: "minecraft:deepslate_bricks"},
        {pos: [10, 6, 1], state: "minecraft:deepslate_bricks"},
        {pos: [10, 6, 2], state: "minecraft:deepslate_bricks"},
        {pos: [10, 6, 3], state: "minecraft:gravel"},
        {pos: [10, 6, 4], state: "minecraft:gravel"},
        {pos: [10, 6, 5], state: "minecraft:sticky_piston{extended:true,facing:up}"},
        {pos: [10, 6, 6], state: "minecraft:gravel"},
        {pos: [10, 6, 7], state: "minecraft:gravel"},
        {pos: [10, 6, 8], state: "minecraft:gravel"},
        {pos: [10, 6, 9], state: "minecraft:gravel"},
        {pos: [10, 6, 10], state: "minecraft:gravel"},
        {pos: [10, 6, 11], state: "minecraft:gravel"},
        {pos: [10, 6, 12], state: "minecraft:gravel"},
        {pos: [10, 6, 13], state: "minecraft:gravel"},
        {pos: [10, 6, 14], state: "minecraft:gravel"},
        {pos: [10, 6, 15], state: "minecraft:gravel"},
        {pos: [10, 6, 16], state: "minecraft:gravel"},
        {pos: [10, 6, 17], state: "minecraft:gravel"},
        {pos: [10, 6, 18], state: "minecraft:gravel"},
        {pos: [10, 6, 19], state: "minecraft:gravel"},
        {pos: [10, 6, 20], state: "minecraft:gravel"},
        {pos: [10, 6, 21], state: "minecraft:gravel"},
        {pos: [10, 6, 22], state: "minecraft:deepslate_bricks"},
        {pos: [11, 6, 0], state: "minecraft:deepslate_bricks"},
        {pos: [11, 6, 1], state: "minecraft:deepslate_bricks"},
        {pos: [11, 6, 2], state: "minecraft:deepslate_bricks"},
        {pos: [11, 6, 3], state: "minecraft:gravel"},
        {pos: [11, 6, 4], state: "minecraft:gravel"},
        {pos: [11, 6, 5], state: "minecraft:gravel"},
        {pos: [11, 6, 6], state: "minecraft:gravel"},
        {pos: [11, 6, 7], state: "minecraft:gravel"},
        {pos: [11, 6, 8], state: "minecraft:gravel"},
        {pos: [11, 6, 9], state: "minecraft:gravel"},
        {pos: [11, 6, 10], state: "minecraft:gravel"},
        {pos: [11, 6, 11], state: "minecraft:gravel"},
        {pos: [11, 6, 12], state: "minecraft:gravel"},
        {pos: [11, 6, 13], state: "minecraft:gravel"},
        {pos: [11, 6, 14], state: "minecraft:gravel"},
        {pos: [11, 6, 15], state: "minecraft:gravel"},
        {pos: [11, 6, 16], state: "minecraft:gravel"},
        {pos: [11, 6, 17], state: "minecraft:gravel"},
        {pos: [11, 6, 18], state: "minecraft:gravel"},
        {pos: [11, 6, 19], state: "minecraft:gravel"},
        {pos: [11, 6, 20], state: "minecraft:gravel"},
        {pos: [11, 6, 21], state: "minecraft:gravel"},
        {pos: [11, 6, 22], state: "minecraft:deepslate_bricks"},
        {pos: [12, 6, 2], state: "minecraft:deepslate_bricks"},
        {pos: [12, 6, 3], state: "minecraft:gravel"},
        {pos: [12, 6, 4], state: "minecraft:gravel"},
        {pos: [12, 6, 5], state: "minecraft:gravel"},
        {pos: [12, 6, 6], state: "minecraft:gravel"},
        {pos: [12, 6, 7], state: "minecraft:gravel"},
        {pos: [12, 6, 8], state: "minecraft:gravel"},
        {pos: [12, 6, 9], state: "minecraft:gravel"},
        {pos: [12, 6, 10], state: "minecraft:gravel"},
        {pos: [12, 6, 11], state: "minecraft:gravel"},
        {pos: [12, 6, 12], state: "minecraft:gravel"},
        {pos: [12, 6, 13], state: "minecraft:gravel"},
        {pos: [12, 6, 14], state: "minecraft:gravel"},
        {pos: [12, 6, 15], state: "minecraft:gravel"},
        {pos: [12, 6, 16], state: "minecraft:gravel"},
        {pos: [12, 6, 17], state: "minecraft:gravel"},
        {pos: [12, 6, 18], state: "minecraft:gravel"},
        {pos: [12, 6, 19], state: "minecraft:gravel"},
        {pos: [12, 6, 20], state: "minecraft:deepslate_bricks"},
        {pos: [12, 6, 21], state: "minecraft:gravel"},
        {pos: [12, 6, 22], state: "minecraft:deepslate_bricks"},
        {pos: [13, 6, 2], state: "minecraft:deepslate_bricks"},
        {pos: [13, 6, 3], state: "minecraft:gravel"},
        {pos: [13, 6, 4], state: "minecraft:gravel"},
        {pos: [13, 6, 5], state: "minecraft:gravel"},
        {pos: [13, 6, 6], state: "minecraft:deepslate_bricks"},
        {pos: [13, 6, 7], state: "minecraft:deepslate_bricks"},
        {pos: [13, 6, 8], state: "minecraft:deepslate_bricks"},
        {pos: [13, 6, 9], state: "minecraft:deepslate_bricks"},
        {pos: [13, 6, 10], state: "minecraft:gravel"},
        {pos: [13, 6, 11], state: "minecraft:gravel"},
        {pos: [13, 6, 12], state: "minecraft:gravel"},
        {pos: [13, 6, 13], state: "minecraft:gravel"},
        {pos: [13, 6, 14], state: "minecraft:gravel"},
        {pos: [13, 6, 15], state: "minecraft:deepslate_bricks"},
        {pos: [13, 6, 16], state: "minecraft:deepslate_bricks"},
        {pos: [13, 6, 17], state: "minecraft:deepslate_bricks"},
        {pos: [13, 6, 18], state: "minecraft:deepslate_bricks"},
        {pos: [13, 6, 19], state: "minecraft:gravel"},
        {pos: [13, 6, 20], state: "minecraft:gravel"},
        {pos: [13, 6, 21], state: "minecraft:gravel"},
        {pos: [13, 6, 22], state: "minecraft:deepslate_bricks"},
        {pos: [14, 6, 2], state: "minecraft:deepslate_bricks"},
        {pos: [14, 6, 3], state: "minecraft:deepslate_bricks"},
        {pos: [14, 6, 4], state: "minecraft:deepslate_bricks"},
        {pos: [14, 6, 5], state: "minecraft:gravel"},
        {pos: [14, 6, 6], state: "minecraft:gravel"},
        {pos: [14, 6, 7], state: "minecraft:gravel"},
        {pos: [14, 6, 8], state: "minecraft:gravel"},
        {pos: [14, 6, 9], state: "minecraft:gravel"},
        {pos: [14, 6, 10], state: "minecraft:gravel"},
        {pos: [14, 6, 11], state: "minecraft:gravel"},
        {pos: [14, 6, 12], state: "minecraft:gravel"},
        {pos: [14, 6, 13], state: "minecraft:gravel"},
        {pos: [14, 6, 14], state: "minecraft:gravel"},
        {pos: [14, 6, 15], state: "minecraft:gravel"},
        {pos: [14, 6, 16], state: "minecraft:gravel"},
        {pos: [14, 6, 17], state: "minecraft:gravel"},
        {pos: [14, 6, 18], state: "minecraft:gravel"},
        {pos: [14, 6, 19], state: "minecraft:gravel"},
        {pos: [14, 6, 20], state: "minecraft:deepslate_bricks"},
        {pos: [14, 6, 21], state: "minecraft:deepslate_bricks"},
        {pos: [14, 6, 22], state: "minecraft:deepslate_bricks"},
        {pos: [15, 6, 5], state: "minecraft:deepslate_bricks"},
        {pos: [15, 6, 6], state: "minecraft:gravel"},
        {pos: [15, 6, 7], state: "minecraft:gravel"},
        {pos: [15, 6, 8], state: "minecraft:gravel"},
        {pos: [15, 6, 9], state: "minecraft:gravel"},
        {pos: [15, 6, 10], state: "minecraft:gravel"},
        {pos: [15, 6, 11], state: "minecraft:gravel"},
        {pos: [15, 6, 12], state: "minecraft:gravel"},
        {pos: [15, 6, 13], state: "minecraft:gravel"},
        {pos: [15, 6, 14], state: "minecraft:gravel"},
        {pos: [15, 6, 15], state: "minecraft:gravel"},
        {pos: [15, 6, 16], state: "minecraft:gravel"},
        {pos: [15, 6, 17], state: "minecraft:gravel"},
        {pos: [15, 6, 18], state: "minecraft:gravel"},
        {pos: [15, 6, 19], state: "minecraft:deepslate_bricks"},
        {pos: [16, 6, 5], state: "minecraft:deepslate_bricks"},
        {pos: [16, 6, 6], state: "minecraft:gravel"},
        {pos: [16, 6, 7], state: "minecraft:gravel"},
        {pos: [16, 6, 8], state: "minecraft:gravel"},
        {pos: [16, 6, 9], state: "minecraft:gravel"},
        {pos: [16, 6, 10], state: "minecraft:gravel"},
        {pos: [16, 6, 11], state: "minecraft:gravel"},
        {pos: [16, 6, 12], state: "minecraft:gravel"},
        {pos: [16, 6, 13], state: "minecraft:gravel"},
        {pos: [16, 6, 14], state: "minecraft:gravel"},
        {pos: [16, 6, 15], state: "minecraft:gravel"},
        {pos: [16, 6, 16], state: "minecraft:gravel"},
        {pos: [16, 6, 17], state: "minecraft:gravel"},
        {pos: [16, 6, 18], state: "minecraft:gravel"},
        {pos: [16, 6, 19], state: "minecraft:deepslate_bricks"},
        {pos: [17, 6, 5], state: "minecraft:deepslate_bricks"},
        {pos: [17, 6, 6], state: "minecraft:gravel"},
        {pos: [17, 6, 7], state: "minecraft:gravel"},
        {pos: [17, 6, 8], state: "minecraft:gravel"},
        {pos: [17, 6, 9], state: "minecraft:gravel"},
        {pos: [17, 6, 10], state: "minecraft:gravel"},
        {pos: [17, 6, 11], state: "minecraft:gravel"},
        {pos: [17, 6, 12], state: "minecraft:gravel"},
        {pos: [17, 6, 13], state: "minecraft:gravel"},
        {pos: [17, 6, 14], state: "minecraft:gravel"},
        {pos: [17, 6, 15], state: "minecraft:gravel"},
        {pos: [17, 6, 16], state: "minecraft:gravel"},
        {pos: [17, 6, 17], state: "minecraft:gravel"},
        {pos: [17, 6, 18], state: "minecraft:gravel"},
        {pos: [17, 6, 19], state: "minecraft:deepslate_bricks"},
        {pos: [18, 6, 5], state: "minecraft:deepslate_bricks"},
        {pos: [18, 6, 6], state: "minecraft:gravel"},
        {pos: [18, 6, 7], state: "minecraft:gravel"},
        {pos: [18, 6, 8], state: "minecraft:gravel"},
        {pos: [18, 6, 9], state: "minecraft:gravel"},
        {pos: [18, 6, 10], state: "minecraft:gravel"},
        {pos: [18, 6, 11], state: "minecraft:gravel"},
        {pos: [18, 6, 12], state: "minecraft:gravel"},
        {pos: [18, 6, 13], state: "minecraft:gravel"},
        {pos: [18, 6, 14], state: "minecraft:gravel"},
        {pos: [18, 6, 15], state: "minecraft:gravel"},
        {pos: [18, 6, 16], state: "minecraft:gravel"},
        {pos: [18, 6, 17], state: "minecraft:gravel"},
        {pos: [18, 6, 18], state: "minecraft:gravel"},
        {pos: [18, 6, 19], state: "minecraft:deepslate_bricks"},
        {pos: [19, 6, 5], state: "minecraft:deepslate_bricks"},
        {pos: [19, 6, 6], state: "minecraft:gravel"},
        {pos: [19, 6, 7], state: "minecraft:gravel"},
        {pos: [19, 6, 8], state: "minecraft:gravel"},
        {pos: [19, 6, 9], state: "minecraft:gravel"},
        {pos: [19, 6, 10], state: "minecraft:gravel"},
        {pos: [19, 6, 11], state: "minecraft:gravel"},
        {pos: [19, 6, 12], state: "minecraft:gravel"},
        {pos: [19, 6, 13], state: "minecraft:gravel"},
        {pos: [19, 6, 14], state: "minecraft:gravel"},
        {pos: [19, 6, 15], state: "minecraft:gravel"},
        {pos: [19, 6, 16], state: "minecraft:gravel"},
        {pos: [19, 6, 17], state: "minecraft:gravel"},
        {pos: [19, 6, 18], state: "minecraft:deepslate_bricks"},
        {pos: [20, 6, 5], state: "minecraft:deepslate_bricks"},
        {pos: [20, 6, 6], state: "minecraft:deepslate_bricks"},
        {pos: [20, 6, 7], state: "minecraft:deepslate_bricks"},
        {pos: [20, 6, 8], state: "minecraft:deepslate_bricks"},
        {pos: [20, 6, 9], state: "minecraft:deepslate_bricks"},
        {pos: [20, 6, 10], state: "minecraft:deepslate_bricks"},
        {pos: [20, 6, 11], state: "minecraft:gravel"},
        {pos: [20, 6, 12], state: "minecraft:gravel"},
        {pos: [20, 6, 13], state: "minecraft:gravel"},
        {pos: [20, 6, 14], state: "minecraft:deepslate_bricks"},
        {pos: [20, 6, 15], state: "minecraft:deepslate_bricks"},
        {pos: [20, 6, 16], state: "minecraft:deepslate_bricks"},
        {pos: [20, 6, 17], state: "minecraft:deepslate_bricks"},
        {pos: [20, 6, 18], state: "minecraft:deepslate_bricks"},
        {pos: [0, 7, 5], state: "minecraft:deepslate_bricks"},
        {pos: [0, 7, 6], state: "minecraft:deepslate_bricks"},
        {pos: [0, 7, 7], state: "minecraft:deepslate_bricks"},
        {pos: [0, 7, 8], state: "minecraft:deepslate_bricks"},
        {pos: [0, 7, 9], state: "minecraft:deepslate_bricks"},
        {pos: [0, 7, 10], state: "minecraft:deepslate_bricks"},
        {pos: [0, 7, 11], state: "minecraft:candle{candles:4,lit:false,waterlogged:false}"},
        {pos: [0, 7, 12], state: "minecraft:jigsaw{orientation:west_up}", nbt: {final_state: "minecraft:cave_air", id: "minecraft:jigsaw", joint: "rollable", name: "trailiertales:corridor", placement_priority: 0, pool: "trailiertales:catacombs/corridor_connector", selection_priority: 0, target: "trailiertales:corridor"}},
        {pos: [0, 7, 13], state: "minecraft:candle{candles:4,lit:false,waterlogged:false}"},
        {pos: [0, 7, 14], state: "minecraft:deepslate_bricks"},
        {pos: [0, 7, 15], state: "minecraft:deepslate_bricks"},
        {pos: [0, 7, 16], state: "minecraft:deepslate_bricks"},
        {pos: [0, 7, 17], state: "minecraft:deepslate_bricks"},
        {pos: [0, 7, 18], state: "minecraft:deepslate_bricks"},
        {pos: [0, 7, 19], state: "minecraft:deepslate_bricks"},
        {pos: [1, 7, 5], state: "minecraft:deepslate_bricks"},
        {pos: [1, 7, 6], state: "minecraft:deepslate_bricks"},
        {pos: [1, 7, 7], state: "minecraft:deepslate_bricks"},
        {pos: [1, 7, 8], state: "minecraft:deepslate_bricks"},
        {pos: [1, 7, 9], state: "minecraft:deepslate_bricks"},
        {pos: [1, 7, 10], state: "minecraft:deepslate_bricks"},
        {pos: [1, 7, 11], state: "minecraft:candle{candles:4,lit:false,waterlogged:false}"},
        {pos: [1, 7, 12], state: "minecraft:cave_air"},
        {pos: [1, 7, 13], state: "minecraft:candle{candles:4,lit:false,waterlogged:false}"},
        {pos: [1, 7, 14], state: "minecraft:deepslate_bricks"},
        {pos: [1, 7, 15], state: "minecraft:deepslate_bricks"},
        {pos: [1, 7, 16], state: "minecraft:deepslate_bricks"},
        {pos: [1, 7, 17], state: "minecraft:deepslate_bricks"},
        {pos: [1, 7, 18], state: "minecraft:deepslate_bricks"},
        {pos: [1, 7, 19], state: "minecraft:deepslate_bricks"},
        {pos: [2, 7, 5], state: "minecraft:deepslate_bricks"},
        {pos: [2, 7, 6], state: "minecraft:deepslate_bricks"},
        {pos: [2, 7, 7], state: "minecraft:deepslate_bricks"},
        {pos: [2, 7, 8], state: "minecraft:deepslate_bricks"},
        {pos: [2, 7, 9], state: "minecraft:deepslate_bricks"},
        {pos: [2, 7, 10], state: "minecraft:deepslate_bricks"},
        {pos: [2, 7, 11], state: "minecraft:candle{candles:4,lit:false,waterlogged:false}"},
        {pos: [2, 7, 12], state: "minecraft:cave_air"},
        {pos: [2, 7, 13], state: "minecraft:candle{candles:4,lit:false,waterlogged:false}"},
        {pos: [2, 7, 14], state: "minecraft:deepslate_bricks"},
        {pos: [2, 7, 15], state: "minecraft:deepslate_bricks"},
        {pos: [2, 7, 16], state: "minecraft:deepslate_bricks"},
        {pos: [2, 7, 17], state: "minecraft:deepslate_bricks"},
        {pos: [2, 7, 18], state: "minecraft:deepslate_bricks"},
        {pos: [2, 7, 19], state: "minecraft:deepslate_bricks"},
        {pos: [3, 7, 5], state: "minecraft:deepslate_bricks"},
        {pos: [3, 7, 6], state: "minecraft:deepslate_brick_stairs{facing:north,half:top,shape:straight,waterlogged:false}"},
        {pos: [3, 7, 7], state: "minecraft:decorated_pot{cracked:false,facing:west,waterlogged:false}", nbt: {id: "minecraft:decorated_pot"}},
        {pos: [3, 7, 8], state: "minecraft:candle{candles:4,lit:false,waterlogged:false}"},
        {pos: [3, 7, 9], state: "minecraft:candle{candles:4,lit:false,waterlogged:false}"},
        {pos: [3, 7, 10], state: "minecraft:candle{candles:4,lit:false,waterlogged:false}"},
        {pos: [3, 7, 11], state: "minecraft:cave_air"},
        {pos: [3, 7, 12], state: "minecraft:cave_air"},
        {pos: [3, 7, 13], state: "minecraft:cave_air"},
        {pos: [3, 7, 14], state: "minecraft:decorated_pot{cracked:false,facing:west,waterlogged:false}", nbt: {id: "minecraft:decorated_pot"}},
        {pos: [3, 7, 15], state: "minecraft:candle{candles:4,lit:false,waterlogged:false}"},
        {pos: [3, 7, 16], state: "minecraft:candle{candles:4,lit:false,waterlogged:false}"},
        {pos: [3, 7, 17], state: "minecraft:candle{candles:4,lit:false,waterlogged:false}"},
        {pos: [3, 7, 18], state: "minecraft:deepslate_brick_stairs{facing:south,half:top,shape:straight,waterlogged:false}"},
        {pos: [3, 7, 19], state: "minecraft:deepslate_bricks"},
        {pos: [4, 7, 5], state: "minecraft:deepslate_bricks"},
        {pos: [4, 7, 6], state: "minecraft:deepslate_brick_stairs{facing:north,half:top,shape:straight,waterlogged:false}"},
        {pos: [4, 7, 7], state: "minecraft:candle{candles:4,lit:false,waterlogged:false}"},
        {pos: [4, 7, 8], state: "minecraft:cave_air"},
        {pos: [4, 7, 9], state: "minecraft:cave_air"},
        {pos: [4, 7, 10], state: "minecraft:cave_air"},
        {pos: [4, 7, 11], state: "minecraft:cave_air"},
        {pos: [4, 7, 12], state: "minecraft:cave_air"},
        {pos: [4, 7, 13], state: "minecraft:cave_air"},
        {pos: [4, 7, 14], state: "minecraft:cave_air"},
        {pos: [4, 7, 15], state: "minecraft:cave_air"},
        {pos: [4, 7, 16], state: "minecraft:cave_air"},
        {pos: [4, 7, 17], state: "minecraft:candle{candles:4,lit:false,waterlogged:false}"},
        {pos: [4, 7, 18], state: "minecraft:deepslate_brick_stairs{facing:south,half:top,shape:straight,waterlogged:false}"},
        {pos: [4, 7, 19], state: "minecraft:deepslate_bricks"},
        {pos: [5, 7, 5], state: "minecraft:deepslate_bricks"},
        {pos: [5, 7, 6], state: "minecraft:deepslate_brick_stairs{facing:north,half:top,shape:straight,waterlogged:false}"},
        {pos: [5, 7, 7], state: "minecraft:skeleton_skull{powered:false,rotation:8}", nbt: {id: "minecraft:skull"}},
        {pos: [5, 7, 8], state: "minecraft:candle{candles:4,lit:false,waterlogged:false}"},
        {pos: [5, 7, 9], state: "minecraft:candle{candles:4,lit:false,waterlogged:false}"},
        {pos: [5, 7, 10], state: "minecraft:candle{candles:4,lit:false,waterlogged:false}"},
        {pos: [5, 7, 11], state: "minecraft:cave_air"},
        {pos: [5, 7, 12], state: "minecraft:cave_air"},
        {pos: [5, 7, 13], state: "minecraft:cave_air"},
        {pos: [5, 7, 14], state: "minecraft:candle{candles:4,lit:false,waterlogged:false}"},
        {pos: [5, 7, 15], state: "minecraft:candle{candles:4,lit:false,waterlogged:false}"},
        {pos: [5, 7, 16], state: "minecraft:candle{candles:4,lit:false,waterlogged:false}"},
        {pos: [5, 7, 17], state: "minecraft:candle{candles:4,lit:false,waterlogged:false}"},
        {pos: [5, 7, 18], state: "minecraft:deepslate_brick_stairs{facing:south,half:top,shape:straight,waterlogged:false}"},
        {pos: [5, 7, 19], state: "minecraft:deepslate_bricks"},
        {pos: [6, 7, 2], state: "minecraft:deepslate_bricks"},
        {pos: [6, 7, 3], state: "minecraft:deepslate_bricks"},
        {pos: [6, 7, 4], state: "minecraft:deepslate_bricks"},
        {pos: [6, 7, 5], state: "minecraft:deepslate_bricks"},
        {pos: [6, 7, 6], state: "minecraft:deepslate_bricks"},
        {pos: [6, 7, 7], state: "minecraft:deepslate_bricks"},
        {pos: [6, 7, 8], state: "minecraft:deepslate_bricks"},
        {pos: [6, 7, 9], state: "minecraft:deepslate_bricks"},
        {pos: [6, 7, 10], state: "minecraft:deepslate_bricks"},
        {pos: [6, 7, 11], state: "minecraft:candle{candles:4,lit:false,waterlogged:false}"},
        {pos: [6, 7, 12], state: "minecraft:cave_air"},
        {pos: [6, 7, 13], state: "minecraft:candle{candles:4,lit:false,waterlogged:false}"},
        {pos: [6, 7, 14], state: "minecraft:deepslate_bricks"},
        {pos: [6, 7, 15], state: "minecraft:deepslate_bricks"},
        {pos: [6, 7, 16], state: "minecraft:deepslate_bricks"},
        {pos: [6, 7, 17], state: "minecraft:deepslate_bricks"},
        {pos: [6, 7, 18], state: "minecraft:deepslate_bricks"},
        {pos: [6, 7, 19], state: "minecraft:deepslate_bricks"},
        {pos: [6, 7, 20], state: "minecraft:deepslate_bricks"},
        {pos: [6, 7, 21], state: "minecraft:deepslate_bricks"},
        {pos: [6, 7, 22], state: "minecraft:deepslate_bricks"},
        {pos: [7, 7, 0], state: "minecraft:deepslate_bricks"},
        {pos: [7, 7, 1], state: "minecraft:deepslate_bricks"},
        {pos: [7, 7, 2], state: "minecraft:deepslate_bricks"},
        {pos: [7, 7, 3], state: "minecraft:deepslate_bricks"},
        {pos: [7, 7, 4], state: "minecraft:deepslate_bricks"},
        {pos: [7, 7, 5], state: "minecraft:deepslate_bricks"},
        {pos: [7, 7, 6], state: "minecraft:cave_air"},
        {pos: [7, 7, 7], state: "minecraft:cave_air"},
        {pos: [7, 7, 8], state: "minecraft:cave_air"},
        {pos: [7, 7, 9], state: "minecraft:cave_air"},
        {pos: [7, 7, 10], state: "minecraft:deepslate_bricks"},
        {pos: [7, 7, 11], state: "minecraft:candle{candles:4,lit:false,waterlogged:false}"},
        {pos: [7, 7, 12], state: "minecraft:cave_air"},
        {pos: [7, 7, 13], state: "minecraft:candle{candles:4,lit:false,waterlogged:false}"},
        {pos: [7, 7, 14], state: "minecraft:deepslate_bricks"},
        {pos: [7, 7, 15], state: "minecraft:cave_air"},
        {pos: [7, 7, 16], state: "minecraft:cave_air"},
        {pos: [7, 7, 17], state: "minecraft:cave_air"},
        {pos: [7, 7, 18], state: "minecraft:cave_air"},
        {pos: [7, 7, 19], state: "minecraft:deepslate_bricks"},
        {pos: [7, 7, 20], state: "minecraft:deepslate_bricks"},
        {pos: [7, 7, 21], state: "minecraft:deepslate_bricks"},
        {pos: [7, 7, 22], state: "minecraft:deepslate_bricks"},
        {pos: [8, 7, 0], state: "minecraft:deepslate_bricks"},
        {pos: [8, 7, 1], state: "minecraft:deepslate_bricks"},
        {pos: [8, 7, 2], state: "minecraft:deepslate_bricks"},
        {pos: [8, 7, 3], state: "minecraft:deepslate_bricks"},
        {pos: [8, 7, 4], state: "minecraft:deepslate_bricks"},
        {pos: [8, 7, 5], state: "minecraft:deepslate_bricks"},
        {pos: [8, 7, 6], state: "minecraft:deepslate_bricks"},
        {pos: [8, 7, 7], state: "minecraft:deepslate_bricks"},
        {pos: [8, 7, 8], state: "minecraft:deepslate_bricks"},
        {pos: [8, 7, 9], state: "minecraft:deepslate_bricks"},
        {pos: [8, 7, 10], state: "minecraft:deepslate_bricks"},
        {pos: [8, 7, 11], state: "minecraft:candle{candles:4,lit:false,waterlogged:false}"},
        {pos: [8, 7, 12], state: "minecraft:cave_air"},
        {pos: [8, 7, 13], state: "minecraft:candle{candles:4,lit:false,waterlogged:false}"},
        {pos: [8, 7, 14], state: "minecraft:deepslate_bricks"},
        {pos: [8, 7, 15], state: "minecraft:deepslate_bricks"},
        {pos: [8, 7, 16], state: "minecraft:deepslate_bricks"},
        {pos: [8, 7, 17], state: "minecraft:deepslate_bricks"},
        {pos: [8, 7, 18], state: "minecraft:deepslate_bricks"},
        {pos: [8, 7, 19], state: "minecraft:deepslate_bricks"},
        {pos: [8, 7, 20], state: "minecraft:deepslate_bricks"},
        {pos: [8, 7, 21], state: "minecraft:deepslate_bricks"},
        {pos: [8, 7, 22], state: "minecraft:deepslate_bricks"},
        {pos: [9, 7, 0], state: "minecraft:deepslate_bricks"},
        {pos: [9, 7, 1], state: "minecraft:cave_air"},
        {pos: [9, 7, 2], state: "minecraft:deepslate_bricks"},
        {pos: [9, 7, 3], state: "minecraft:deepslate_bricks"},
        {pos: [9, 7, 4], state: "minecraft:deepslate_bricks"},
        {pos: [9, 7, 5], state: "minecraft:deepslate_bricks"},
        {pos: [9, 7, 6], state: "minecraft:deepslate_brick_stairs{facing:north,half:top,shape:straight,waterlogged:false}"},
        {pos: [9, 7, 7], state: "minecraft:decorated_pot{cracked:false,facing:north,waterlogged:false}", nbt: {id: "minecraft:decorated_pot"}},
        {pos: [9, 7, 8], state: "minecraft:candle{candles:4,lit:false,waterlogged:false}"},
        {pos: [9, 7, 9], state: "minecraft:candle{candles:4,lit:false,waterlogged:false}"},
        {pos: [9, 7, 10], state: "minecraft:candle{candles:4,lit:false,waterlogged:false}"},
        {pos: [9, 7, 11], state: "minecraft:cave_air"},
        {pos: [9, 7, 12], state: "minecraft:cave_air"},
        {pos: [9, 7, 13], state: "minecraft:skeleton_skull{powered:false,rotation:3}", nbt: {id: "minecraft:skull"}},
        {pos: [9, 7, 14], state: "minecraft:candle{candles:4,lit:false,waterlogged:false}"},
        {pos: [9, 7, 15], state: "minecraft:candle{candles:4,lit:false,waterlogged:false}"},
        {pos: [9, 7, 16], state: "minecraft:candle{candles:4,lit:false,waterlogged:false}"},
        {pos: [9, 7, 17], state: "minecraft:skeleton_skull{powered:false,rotation:0}", nbt: {id: "minecraft:skull"}},
        {pos: [9, 7, 18], state: "minecraft:deepslate_brick_stairs{facing:south,half:top,shape:straight,waterlogged:false}"},
        {pos: [9, 7, 19], state: "minecraft:deepslate_bricks"},
        {pos: [9, 7, 20], state: "minecraft:deepslate_bricks"},
        {pos: [9, 7, 21], state: "minecraft:deepslate_bricks"},
        {pos: [9, 7, 22], state: "minecraft:deepslate_bricks"},
        {pos: [10, 7, 0], state: "minecraft:deepslate_bricks"},
        {pos: [10, 7, 1], state: "minecraft:redstone_wire{east:none,north:none,power:0,south:up,west:side}"},
        {pos: [10, 7, 2], state: "minecraft:deepslate_bricks"},
        {pos: [10, 7, 3], state: "minecraft:deepslate_bricks"},
        {pos: [10, 7, 4], state: "minecraft:chest{facing:south,type:single,waterlogged:false}", nbt: {id: "minecraft:chest"}},
        {pos: [10, 7, 5], state: "minecraft:piston_head{facing:up,short:false,type:sticky}"},
        {pos: [10, 7, 6], state: "minecraft:deepslate_brick_stairs{facing:north,half:top,shape:straight,waterlogged:false}"},
        {pos: [10, 7, 7], state: "minecraft:candle{candles:4,lit:false,waterlogged:false}"},
        {pos: [10, 7, 8], state: "minecraft:cave_air"},
        {pos: [10, 7, 9], state: "minecraft:cave_air"},
        {pos: [10, 7, 10], state: "minecraft:cave_air"},
        {pos: [10, 7, 11], state: "minecraft:cave_air"},
        {pos: [10, 7, 12], state: "minecraft:cave_air"},
        {pos: [10, 7, 13], state: "minecraft:cave_air"},
        {pos: [10, 7, 14], state: "minecraft:cave_air"},
        {pos: [10, 7, 15], state: "minecraft:cave_air"},
        {pos: [10, 7, 16], state: "minecraft:cave_air"},
        {pos: [10, 7, 17], state: "minecraft:candle{candles:4,lit:false,waterlogged:false}"},
        {pos: [10, 7, 18], state: "minecraft:deepslate_brick_stairs{facing:south,half:top,shape:straight,waterlogged:false}"},
        {pos: [10, 7, 19], state: "minecraft:deepslate_bricks"},
        {pos: [10, 7, 20], state: "minecraft:deepslate_bricks"},
        {pos: [10, 7, 21], state: "minecraft:deepslate_bricks"},
        {pos: [10, 7, 22], state: "minecraft:deepslate_bricks"},
        {pos: [11, 7, 0], state: "minecraft:deepslate_bricks"},
        {pos: [11, 7, 1], state: "minecraft:deepslate_bricks"},
        {pos: [11, 7, 2], state: "minecraft:deepslate_bricks"},
        {pos: [11, 7, 3], state: "minecraft:deepslate_bricks"},
        {pos: [11, 7, 4], state: "minecraft:deepslate_bricks"},
        {pos: [11, 7, 5], state: "minecraft:deepslate_bricks"},
        {pos: [11, 7, 6], state: "minecraft:deepslate_brick_stairs{facing:north,half:top,shape:straight,waterlogged:false}"},
        {pos: [11, 7, 7], state: "minecraft:candle{candles:4,lit:false,waterlogged:false}"},
        {pos: [11, 7, 8], state: "minecraft:candle{candles:4,lit:false,waterlogged:false}"},
        {pos: [11, 7, 9], state: "minecraft:candle{candles:4,lit:false,waterlogged:false}"},
        {pos: [11, 7, 10], state: "minecraft:candle{candles:4,lit:false,waterlogged:false}"},
        {pos: [11, 7, 11], state: "minecraft:cave_air"},
        {pos: [11, 7, 12], state: "minecraft:cave_air"},
        {pos: [11, 7, 13], state: "minecraft:cave_air"},
        {pos: [11, 7, 14], state: "minecraft:candle{candles:4,lit:false,waterlogged:false}"},
        {pos: [11, 7, 15], state: "minecraft:candle{candles:4,lit:false,waterlogged:false}"},
        {pos: [11, 7, 16], state: "minecraft:candle{candles:4,lit:false,waterlogged:false}"},
        {pos: [11, 7, 17], state: "minecraft:candle{candles:4,lit:false,waterlogged:false}"},
        {pos: [11, 7, 18], state: "minecraft:deepslate_brick_stairs{facing:south,half:top,shape:straight,waterlogged:false}"},
        {pos: [11, 7, 19], state: "minecraft:deepslate_bricks"},
        {pos: [11, 7, 20], state: "minecraft:deepslate_bricks"},
        {pos: [11, 7, 21], state: "minecraft:deepslate_bricks"},
        {pos: [11, 7, 22], state: "minecraft:deepslate_bricks"},
        {pos: [12, 7, 2], state: "minecraft:deepslate_bricks"},
        {pos: [12, 7, 3], state: "minecraft:deepslate_bricks"},
        {pos: [12, 7, 4], state: "minecraft:deepslate_bricks"},
        {pos: [12, 7, 5], state: "minecraft:deepslate_bricks"},
        {pos: [12, 7, 6], state: "minecraft:deepslate_bricks"},
        {pos: [12, 7, 7], state: "minecraft:deepslate_bricks"},
        {pos: [12, 7, 8], state: "minecraft:deepslate_bricks"},
        {pos: [12, 7, 9], state: "minecraft:deepslate_bricks"},
        {pos: [12, 7, 10], state: "minecraft:deepslate_bricks"},
        {pos: [12, 7, 11], state: "minecraft:candle{candles:4,lit:false,waterlogged:false}"},
        {pos: [12, 7, 12], state: "minecraft:cave_air"},
        {pos: [12, 7, 13], state: "minecraft:candle{candles:4,lit:false,waterlogged:false}"},
        {pos: [12, 7, 14], state: "minecraft:deepslate_bricks"},
        {pos: [12, 7, 15], state: "minecraft:deepslate_bricks"},
        {pos: [12, 7, 16], state: "minecraft:deepslate_bricks"},
        {pos: [12, 7, 17], state: "minecraft:deepslate_bricks"},
        {pos: [12, 7, 18], state: "minecraft:deepslate_bricks"},
        {pos: [12, 7, 19], state: "minecraft:deepslate_bricks"},
        {pos: [12, 7, 20], state: "minecraft:deepslate_bricks"},
        {pos: [12, 7, 21], state: "minecraft:deepslate_bricks"},
        {pos: [12, 7, 22], state: "minecraft:deepslate_bricks"},
        {pos: [13, 7, 2], state: "minecraft:deepslate_bricks"},
        {pos: [13, 7, 3], state: "minecraft:deepslate_bricks"},
        {pos: [13, 7, 4], state: "minecraft:deepslate_bricks"},
        {pos: [13, 7, 5], state: "minecraft:deepslate_bricks"},
        {pos: [13, 7, 6], state: "minecraft:cave_air"},
        {pos: [13, 7, 7], state: "minecraft:cave_air"},
        {pos: [13, 7, 8], state: "minecraft:cave_air"},
        {pos: [13, 7, 9], state: "minecraft:cave_air"},
        {pos: [13, 7, 10], state: "minecraft:deepslate_bricks"},
        {pos: [13, 7, 11], state: "minecraft:candle{candles:4,lit:false,waterlogged:false}"},
        {pos: [13, 7, 12], state: "minecraft:cave_air"},
        {pos: [13, 7, 13], state: "minecraft:candle{candles:4,lit:false,waterlogged:false}"},
        {pos: [13, 7, 14], state: "minecraft:deepslate_bricks"},
        {pos: [13, 7, 15], state: "minecraft:cave_air"},
        {pos: [13, 7, 16], state: "minecraft:cave_air"},
        {pos: [13, 7, 17], state: "minecraft:cave_air"},
        {pos: [13, 7, 18], state: "minecraft:cave_air"},
        {pos: [13, 7, 19], state: "minecraft:deepslate_bricks"},
        {pos: [13, 7, 20], state: "minecraft:deepslate_bricks"},
        {pos: [13, 7, 21], state: "minecraft:deepslate_bricks"},
        {pos: [13, 7, 22], state: "minecraft:deepslate_bricks"},
        {pos: [14, 7, 2], state: "minecraft:deepslate_bricks"},
        {pos: [14, 7, 3], state: "minecraft:deepslate_bricks"},
        {pos: [14, 7, 4], state: "minecraft:deepslate_bricks"},
        {pos: [14, 7, 5], state: "minecraft:deepslate_bricks"},
        {pos: [14, 7, 6], state: "minecraft:deepslate_bricks"},
        {pos: [14, 7, 7], state: "minecraft:deepslate_bricks"},
        {pos: [14, 7, 8], state: "minecraft:deepslate_bricks"},
        {pos: [14, 7, 9], state: "minecraft:deepslate_bricks"},
        {pos: [14, 7, 10], state: "minecraft:deepslate_bricks"},
        {pos: [14, 7, 11], state: "minecraft:candle{candles:4,lit:false,waterlogged:false}"},
        {pos: [14, 7, 12], state: "minecraft:cave_air"},
        {pos: [14, 7, 13], state: "minecraft:candle{candles:4,lit:false,waterlogged:false}"},
        {pos: [14, 7, 14], state: "minecraft:deepslate_bricks"},
        {pos: [14, 7, 15], state: "minecraft:deepslate_bricks"},
        {pos: [14, 7, 16], state: "minecraft:deepslate_bricks"},
        {pos: [14, 7, 17], state: "minecraft:deepslate_bricks"},
        {pos: [14, 7, 18], state: "minecraft:deepslate_bricks"},
        {pos: [14, 7, 19], state: "minecraft:deepslate_bricks"},
        {pos: [14, 7, 20], state: "minecraft:deepslate_bricks"},
        {pos: [14, 7, 21], state: "minecraft:deepslate_bricks"},
        {pos: [14, 7, 22], state: "minecraft:deepslate_bricks"},
        {pos: [15, 7, 5], state: "minecraft:deepslate_bricks"},
        {pos: [15, 7, 6], state: "minecraft:deepslate_brick_stairs{facing:north,half:top,shape:straight,waterlogged:false}"},
        {pos: [15, 7, 7], state: "minecraft:candle{candles:4,lit:false,waterlogged:false}"},
        {pos: [15, 7, 8], state: "minecraft:candle{candles:4,lit:false,waterlogged:false}"},
        {pos: [15, 7, 9], state: "minecraft:candle{candles:4,lit:false,waterlogged:false}"},
        {pos: [15, 7, 10], state: "minecraft:candle{candles:4,lit:false,waterlogged:false}"},
        {pos: [15, 7, 11], state: "minecraft:cave_air"},
        {pos: [15, 7, 12], state: "minecraft:cave_air"},
        {pos: [15, 7, 13], state: "minecraft:cave_air"},
        {pos: [15, 7, 14], state: "minecraft:candle{candles:4,lit:false,waterlogged:false}"},
        {pos: [15, 7, 15], state: "minecraft:candle{candles:4,lit:false,waterlogged:false}"},
        {pos: [15, 7, 16], state: "minecraft:candle{candles:4,lit:false,waterlogged:false}"},
        {pos: [15, 7, 17], state: "minecraft:candle{candles:4,lit:false,waterlogged:false}"},
        {pos: [15, 7, 18], state: "minecraft:deepslate_brick_stairs{facing:south,half:top,shape:straight,waterlogged:false}"},
        {pos: [15, 7, 19], state: "minecraft:deepslate_bricks"},
        {pos: [16, 7, 5], state: "minecraft:deepslate_bricks"},
        {pos: [16, 7, 6], state: "minecraft:deepslate_brick_stairs{facing:north,half:top,shape:straight,waterlogged:false}"},
        {pos: [16, 7, 7], state: "minecraft:candle{candles:4,lit:false,waterlogged:false}"},
        {pos: [16, 7, 8], state: "minecraft:cave_air"},
        {pos: [16, 7, 9], state: "minecraft:cave_air"},
        {pos: [16, 7, 10], state: "minecraft:cave_air"},
        {pos: [16, 7, 11], state: "minecraft:cave_air"},
        {pos: [16, 7, 12], state: "minecraft:cave_air"},
        {pos: [16, 7, 13], state: "minecraft:cave_air"},
        {pos: [16, 7, 14], state: "minecraft:cave_air"},
        {pos: [16, 7, 15], state: "minecraft:cave_air"},
        {pos: [16, 7, 16], state: "minecraft:cave_air"},
        {pos: [16, 7, 17], state: "minecraft:candle{candles:4,lit:false,waterlogged:false}"},
        {pos: [16, 7, 18], state: "minecraft:deepslate_brick_stairs{facing:south,half:top,shape:straight,waterlogged:false}"},
        {pos: [16, 7, 19], state: "minecraft:deepslate_bricks"},
        {pos: [17, 7, 5], state: "minecraft:deepslate_bricks"},
        {pos: [17, 7, 6], state: "minecraft:deepslate_brick_stairs{facing:north,half:top,shape:straight,waterlogged:false}"},
        {pos: [17, 7, 7], state: "minecraft:decorated_pot{cracked:false,facing:east,waterlogged:false}", nbt: {id: "minecraft:decorated_pot"}},
        {pos: [17, 7, 8], state: "minecraft:candle{candles:4,lit:false,waterlogged:false}"},
        {pos: [17, 7, 9], state: "minecraft:candle{candles:4,lit:false,waterlogged:false}"},
        {pos: [17, 7, 10], state: "minecraft:candle{candles:4,lit:false,waterlogged:false}"},
        {pos: [17, 7, 11], state: "minecraft:cave_air"},
        {pos: [17, 7, 12], state: "minecraft:cave_air"},
        {pos: [17, 7, 13], state: "minecraft:skeleton_skull{powered:false,rotation:0}", nbt: {id: "minecraft:skull"}},
        {pos: [17, 7, 14], state: "minecraft:decorated_pot{cracked:false,facing:east,waterlogged:false}", nbt: {id: "minecraft:decorated_pot"}},
        {pos: [17, 7, 15], state: "minecraft:candle{candles:4,lit:false,waterlogged:false}"},
        {pos: [17, 7, 16], state: "minecraft:candle{candles:4,lit:false,waterlogged:false}"},
        {pos: [17, 7, 17], state: "minecraft:skeleton_skull{powered:false,rotation:12}", nbt: {id: "minecraft:skull"}},
        {pos: [17, 7, 18], state: "minecraft:deepslate_brick_stairs{facing:south,half:top,shape:straight,waterlogged:false}"},
        {pos: [17, 7, 19], state: "minecraft:deepslate_bricks"},
        {pos: [18, 7, 5], state: "minecraft:deepslate_bricks"},
        {pos: [18, 7, 6], state: "minecraft:deepslate_bricks"},
        {pos: [18, 7, 7], state: "minecraft:deepslate_bricks"},
        {pos: [18, 7, 8], state: "minecraft:deepslate_bricks"},
        {pos: [18, 7, 9], state: "minecraft:deepslate_bricks"},
        {pos: [18, 7, 10], state: "minecraft:deepslate_bricks"},
        {pos: [18, 7, 11], state: "minecraft:candle{candles:4,lit:false,waterlogged:false}"},
        {pos: [18, 7, 12], state: "minecraft:cave_air"},
        {pos: [18, 7, 13], state: "minecraft:candle{candles:4,lit:false,waterlogged:false}"},
        {pos: [18, 7, 14], state: "minecraft:deepslate_bricks"},
        {pos: [18, 7, 15], state: "minecraft:deepslate_bricks"},
        {pos: [18, 7, 16], state: "minecraft:deepslate_bricks"},
        {pos: [18, 7, 17], state: "minecraft:deepslate_bricks"},
        {pos: [18, 7, 18], state: "minecraft:deepslate_bricks"},
        {pos: [18, 7, 19], state: "minecraft:deepslate_bricks"},
        {pos: [19, 7, 5], state: "minecraft:deepslate_bricks"},
        {pos: [19, 7, 6], state: "minecraft:deepslate_bricks"},
        {pos: [19, 7, 7], state: "minecraft:deepslate_bricks"},
        {pos: [19, 7, 8], state: "minecraft:deepslate_bricks"},
        {pos: [19, 7, 9], state: "minecraft:deepslate_bricks"},
        {pos: [19, 7, 10], state: "minecraft:deepslate_bricks"},
        {pos: [19, 7, 11], state: "minecraft:candle{candles:4,lit:false,waterlogged:false}"},
        {pos: [19, 7, 12], state: "minecraft:cave_air"},
        {pos: [19, 7, 13], state: "minecraft:candle{candles:4,lit:false,waterlogged:false}"},
        {pos: [19, 7, 14], state: "minecraft:deepslate_bricks"},
        {pos: [19, 7, 15], state: "minecraft:deepslate_bricks"},
        {pos: [19, 7, 16], state: "minecraft:deepslate_bricks"},
        {pos: [19, 7, 17], state: "minecraft:deepslate_bricks"},
        {pos: [19, 7, 18], state: "minecraft:deepslate_bricks"},
        {pos: [20, 7, 5], state: "minecraft:deepslate_bricks"},
        {pos: [20, 7, 6], state: "minecraft:deepslate_bricks"},
        {pos: [20, 7, 7], state: "minecraft:deepslate_bricks"},
        {pos: [20, 7, 8], state: "minecraft:deepslate_bricks"},
        {pos: [20, 7, 9], state: "minecraft:deepslate_bricks"},
        {pos: [20, 7, 10], state: "minecraft:deepslate_bricks"},
        {pos: [20, 7, 11], state: "minecraft:candle{candles:4,lit:false,waterlogged:false}"},
        {pos: [20, 7, 12], state: "minecraft:jigsaw{orientation:east_up}", nbt: {final_state: "minecraft:cave_air", id: "minecraft:jigsaw", joint: "rollable", name: "trailiertales:corridor", placement_priority: 0, pool: "trailiertales:catacombs/corridor_connector", selection_priority: 0, target: "trailiertales:corridor"}},
        {pos: [20, 7, 13], state: "minecraft:candle{candles:4,lit:false,waterlogged:false}"},
        {pos: [20, 7, 14], state: "minecraft:deepslate_bricks"},
        {pos: [20, 7, 15], state: "minecraft:deepslate_bricks"},
        {pos: [20, 7, 16], state: "minecraft:deepslate_bricks"},
        {pos: [20, 7, 17], state: "minecraft:deepslate_bricks"},
        {pos: [20, 7, 18], state: "minecraft:deepslate_bricks"},
        {pos: [0, 8, 5], state: "minecraft:deepslate_bricks"},
        {pos: [0, 8, 6], state: "minecraft:deepslate_bricks"},
        {pos: [0, 8, 7], state: "minecraft:deepslate_bricks"},
        {pos: [0, 8, 8], state: "minecraft:deepslate_bricks"},
        {pos: [0, 8, 9], state: "minecraft:deepslate_bricks"},
        {pos: [0, 8, 10], state: "minecraft:deepslate_bricks"},
        {pos: [0, 8, 11], state: "minecraft:cave_air"},
        {pos: [0, 8, 12], state: "minecraft:cave_air"},
        {pos: [0, 8, 13], state: "minecraft:cave_air"},
        {pos: [0, 8, 14], state: "minecraft:deepslate_bricks"},
        {pos: [0, 8, 15], state: "minecraft:deepslate_bricks"},
        {pos: [0, 8, 16], state: "minecraft:deepslate_bricks"},
        {pos: [0, 8, 17], state: "minecraft:deepslate_bricks"},
        {pos: [0, 8, 18], state: "minecraft:deepslate_bricks"},
        {pos: [0, 8, 19], state: "minecraft:deepslate_bricks"},
        {pos: [1, 8, 5], state: "minecraft:deepslate_bricks"},
        {pos: [1, 8, 6], state: "minecraft:deepslate_bricks"},
        {pos: [1, 8, 7], state: "minecraft:deepslate_bricks"},
        {pos: [1, 8, 8], state: "minecraft:deepslate_bricks"},
        {pos: [1, 8, 9], state: "minecraft:deepslate_bricks"},
        {pos: [1, 8, 10], state: "minecraft:deepslate_bricks"},
        {pos: [1, 8, 11], state: "minecraft:cave_air"},
        {pos: [1, 8, 12], state: "minecraft:cave_air"},
        {pos: [1, 8, 13], state: "minecraft:cave_air"},
        {pos: [1, 8, 14], state: "minecraft:deepslate_bricks"},
        {pos: [1, 8, 15], state: "minecraft:deepslate_bricks"},
        {pos: [1, 8, 16], state: "minecraft:deepslate_bricks"},
        {pos: [1, 8, 17], state: "minecraft:deepslate_bricks"},
        {pos: [1, 8, 18], state: "minecraft:deepslate_bricks"},
        {pos: [1, 8, 19], state: "minecraft:deepslate_bricks"},
        {pos: [2, 8, 5], state: "minecraft:deepslate_bricks"},
        {pos: [2, 8, 6], state: "minecraft:deepslate_bricks"},
        {pos: [2, 8, 7], state: "minecraft:deepslate_bricks"},
        {pos: [2, 8, 8], state: "minecraft:deepslate_bricks"},
        {pos: [2, 8, 9], state: "minecraft:deepslate_bricks"},
        {pos: [2, 8, 10], state: "minecraft:deepslate_bricks"},
        {pos: [2, 8, 11], state: "minecraft:cave_air"},
        {pos: [2, 8, 12], state: "minecraft:cave_air"},
        {pos: [2, 8, 13], state: "minecraft:cave_air"},
        {pos: [2, 8, 14], state: "minecraft:deepslate_bricks"},
        {pos: [2, 8, 15], state: "minecraft:deepslate_bricks"},
        {pos: [2, 8, 16], state: "minecraft:deepslate_bricks"},
        {pos: [2, 8, 17], state: "minecraft:deepslate_bricks"},
        {pos: [2, 8, 18], state: "minecraft:deepslate_bricks"},
        {pos: [2, 8, 19], state: "minecraft:deepslate_bricks"},
        {pos: [3, 8, 5], state: "minecraft:deepslate_bricks"},
        {pos: [3, 8, 6], state: "minecraft:candle{candles:4,lit:false,waterlogged:false}"},
        {pos: [3, 8, 7], state: "minecraft:cave_air"},
        {pos: [3, 8, 8], state: "minecraft:cave_air"},
        {pos: [3, 8, 9], state: "minecraft:cave_air"},
        {pos: [3, 8, 10], state: "minecraft:cave_air"},
        {pos: [3, 8, 11], state: "minecraft:cave_air"},
        {pos: [3, 8, 12], state: "minecraft:cave_air"},
        {pos: [3, 8, 13], state: "minecraft:cave_air"},
        {pos: [3, 8, 14], state: "minecraft:cave_air"},
        {pos: [3, 8, 15], state: "minecraft:cave_air"},
        {pos: [3, 8, 16], state: "minecraft:cave_air"},
        {pos: [3, 8, 17], state: "minecraft:cobweb"},
        {pos: [3, 8, 18], state: "minecraft:skeleton_skull{powered:false,rotation:0}", nbt: {id: "minecraft:skull"}},
        {pos: [3, 8, 19], state: "minecraft:deepslate_bricks"},
        {pos: [4, 8, 5], state: "minecraft:deepslate_bricks"},
        {pos: [4, 8, 6], state: "minecraft:skeleton_skull{powered:false,rotation:8}", nbt: {id: "minecraft:skull"}},
        {pos: [4, 8, 7], state: "minecraft:cave_air"},
        {pos: [4, 8, 8], state: "minecraft:cave_air"},
        {pos: [4, 8, 9], state: "minecraft:cave_air"},
        {pos: [4, 8, 10], state: "minecraft:cave_air"},
        {pos: [4, 8, 11], state: "minecraft:cave_air"},
        {pos: [4, 8, 12], state: "minecraft:cave_air"},
        {pos: [4, 8, 13], state: "minecraft:cave_air"},
        {pos: [4, 8, 14], state: "minecraft:cave_air"},
        {pos: [4, 8, 15], state: "minecraft:cave_air"},
        {pos: [4, 8, 16], state: "minecraft:cave_air"},
        {pos: [4, 8, 17], state: "minecraft:cave_air"},
        {pos: [4, 8, 18], state: "minecraft:skeleton_skull{powered:false,rotation:0}", nbt: {id: "minecraft:skull"}},
        {pos: [4, 8, 19], state: "minecraft:deepslate_bricks"},
        {pos: [5, 8, 5], state: "minecraft:deepslate_bricks"},
        {pos: [5, 8, 6], state: "minecraft:skeleton_skull{powered:false,rotation:8}", nbt: {id: "minecraft:skull"}},
        {pos: [5, 8, 7], state: "minecraft:cave_air"},
        {pos: [5, 8, 8], state: "minecraft:cave_air"},
        {pos: [5, 8, 9], state: "minecraft:cave_air"},
        {pos: [5, 8, 10], state: "minecraft:cave_air"},
        {pos: [5, 8, 11], state: "minecraft:cave_air"},
        {pos: [5, 8, 12], state: "minecraft:cave_air"},
        {pos: [5, 8, 13], state: "minecraft:cave_air"},
        {pos: [5, 8, 14], state: "minecraft:cave_air"},
        {pos: [5, 8, 15], state: "minecraft:cave_air"},
        {pos: [5, 8, 16], state: "minecraft:cave_air"},
        {pos: [5, 8, 17], state: "minecraft:cave_air"},
        {pos: [5, 8, 18], state: "minecraft:skeleton_skull{powered:false,rotation:0}", nbt: {id: "minecraft:skull"}},
        {pos: [5, 8, 19], state: "minecraft:deepslate_bricks"},
        {pos: [6, 8, 2], state: "minecraft:deepslate_bricks"},
        {pos: [6, 8, 3], state: "minecraft:deepslate_bricks"},
        {pos: [6, 8, 4], state: "minecraft:deepslate_bricks"},
        {pos: [6, 8, 5], state: "minecraft:deepslate_bricks"},
        {pos: [6, 8, 6], state: "minecraft:deepslate_bricks"},
        {pos: [6, 8, 7], state: "minecraft:candle{candles:4,lit:false,waterlogged:false}"},
        {pos: [6, 8, 8], state: "minecraft:candle{candles:4,lit:false,waterlogged:false}"},
        {pos: [6, 8, 9], state: "minecraft:candle{candles:4,lit:false,waterlogged:false}"},
        {pos: [6, 8, 10], state: "minecraft:skeleton_skull{powered:false,rotation:8}", nbt: {id: "minecraft:skull"}},
        {pos: [6, 8, 11], state: "minecraft:cave_air"},
        {pos: [6, 8, 12], state: "minecraft:cave_air"},
        {pos: [6, 8, 13], state: "minecraft:cave_air"},
        {pos: [6, 8, 14], state: "minecraft:candle{candles:4,lit:false,waterlogged:false}"},
        {pos: [6, 8, 15], state: "minecraft:candle{candles:4,lit:false,waterlogged:false}"},
        {pos: [6, 8, 16], state: "minecraft:candle{candles:4,lit:false,waterlogged:false}"},
        {pos: [6, 8, 17], state: "minecraft:candle{candles:4,lit:false,waterlogged:false}"},
        {pos: [6, 8, 18], state: "minecraft:deepslate_bricks"},
        {pos: [6, 8, 19], state: "minecraft:deepslate_bricks"},
        {pos: [6, 8, 20], state: "minecraft:deepslate_bricks"},
        {pos: [6, 8, 21], state: "minecraft:deepslate_bricks"},
        {pos: [6, 8, 22], state: "minecraft:deepslate_bricks"},
        {pos: [7, 8, 0], state: "minecraft:deepslate_bricks"},
        {pos: [7, 8, 1], state: "minecraft:deepslate_bricks"},
        {pos: [7, 8, 2], state: "minecraft:deepslate_bricks"},
        {pos: [7, 8, 3], state: "minecraft:deepslate_bricks"},
        {pos: [7, 8, 4], state: "minecraft:deepslate_bricks"},
        {pos: [7, 8, 5], state: "minecraft:deepslate_bricks"},
        {pos: [7, 8, 6], state: "minecraft:cave_air"},
        {pos: [7, 8, 7], state: "minecraft:cave_air"},
        {pos: [7, 8, 8], state: "minecraft:cave_air"},
        {pos: [7, 8, 9], state: "minecraft:cave_air"},
        {pos: [7, 8, 10], state: "minecraft:candle{candles:4,lit:false,waterlogged:false}"},
        {pos: [7, 8, 11], state: "minecraft:cave_air"},
        {pos: [7, 8, 12], state: "minecraft:cave_air"},
        {pos: [7, 8, 13], state: "minecraft:cave_air"},
        {pos: [7, 8, 14], state: "minecraft:candle{candles:4,lit:false,waterlogged:false}"},
        {pos: [7, 8, 15], state: "minecraft:cave_air"},
        {pos: [7, 8, 16], state: "minecraft:cave_air"},
        {pos: [7, 8, 17], state: "minecraft:cave_air"},
        {pos: [7, 8, 18], state: "minecraft:cave_air"},
        {pos: [7, 8, 19], state: "minecraft:deepslate_bricks"},
        {pos: [7, 8, 20], state: "minecraft:deepslate_bricks"},
        {pos: [7, 8, 21], state: "minecraft:deepslate_bricks"},
        {pos: [7, 8, 22], state: "minecraft:deepslate_bricks"},
        {pos: [8, 8, 0], state: "minecraft:deepslate_bricks"},
        {pos: [8, 8, 1], state: "minecraft:deepslate_bricks"},
        {pos: [8, 8, 2], state: "minecraft:deepslate_bricks"},
        {pos: [8, 8, 3], state: "minecraft:deepslate_bricks"},
        {pos: [8, 8, 4], state: "minecraft:deepslate_bricks"},
        {pos: [8, 8, 5], state: "minecraft:deepslate_bricks"},
        {pos: [8, 8, 6], state: "minecraft:deepslate_bricks"},
        {pos: [8, 8, 7], state: "minecraft:skeleton_skull{powered:false,rotation:4}", nbt: {id: "minecraft:skull"}},
        {pos: [8, 8, 8], state: "minecraft:candle{candles:4,lit:false,waterlogged:false}"},
        {pos: [8, 8, 9], state: "minecraft:candle{candles:4,lit:false,waterlogged:false}"},
        {pos: [8, 8, 10], state: "minecraft:candle{candles:2,lit:false,waterlogged:false}"},
        {pos: [8, 8, 11], state: "minecraft:cave_air"},
        {pos: [8, 8, 12], state: "minecraft:cave_air"},
        {pos: [8, 8, 13], state: "minecraft:cave_air"},
        {pos: [8, 8, 14], state: "minecraft:candle{candles:4,lit:false,waterlogged:false}"},
        {pos: [8, 8, 15], state: "minecraft:candle{candles:4,lit:false,waterlogged:false}"},
        {pos: [8, 8, 16], state: "minecraft:skeleton_skull{powered:false,rotation:4}", nbt: {id: "minecraft:skull"}},
        {pos: [8, 8, 17], state: "minecraft:candle{candles:4,lit:false,waterlogged:false}"},
        {pos: [8, 8, 18], state: "minecraft:deepslate_bricks"},
        {pos: [8, 8, 19], state: "minecraft:deepslate_bricks"},
        {pos: [8, 8, 20], state: "minecraft:deepslate_bricks"},
        {pos: [8, 8, 21], state: "minecraft:deepslate_bricks"},
        {pos: [8, 8, 22], state: "minecraft:deepslate_bricks"},
        {pos: [9, 8, 0], state: "minecraft:deepslate_bricks"},
