{
    DataVersion: 3953,
    size: [22, 6, 12],
    data: [
        {pos: [0, 0, 4], state: "minecraft:red_sandstone"},
        {pos: [0, 0, 5], state: "minecraft:red_sandstone"},
        {pos: [0, 0, 6], state: "minecraft:red_sandstone"},
        {pos: [0, 0, 7], state: "minecraft:red_sandstone"},
        {pos: [0, 0, 8], state: "minecraft:red_sandstone"},
        {pos: [0, 0, 9], state: "minecraft:red_sandstone"},
        {pos: [0, 0, 10], state: "minecraft:red_sandstone"},
        {pos: [1, 0, 4], state: "minecraft:red_sandstone"},
        {pos: [1, 0, 5], state: "minecraft:red_sandstone"},
        {pos: [1, 0, 6], state: "minecraft:red_sandstone"},
        {pos: [1, 0, 7], state: "minecraft:red_sandstone"},
        {pos: [1, 0, 8], state: "minecraft:red_sandstone"},
        {pos: [1, 0, 9], state: "minecraft:red_sandstone"},
        {pos: [1, 0, 10], state: "minecraft:red_sandstone"},
        {pos: [2, 0, 4], state: "minecraft:red_sandstone"},
        {pos: [2, 0, 5], state: "minecraft:red_sandstone"},
        {pos: [2, 0, 6], state: "minecraft:red_sandstone"},
        {pos: [2, 0, 7], state: "minecraft:red_sandstone"},
        {pos: [2, 0, 8], state: "minecraft:red_sandstone"},
        {pos: [2, 0, 9], state: "minecraft:red_sandstone"},
        {pos: [2, 0, 10], state: "minecraft:red_sandstone"},
        {pos: [3, 0, 3], state: "minecraft:red_sandstone"},
        {pos: [3, 0, 4], state: "minecraft:red_sandstone"},
        {pos: [3, 0, 5], state: "minecraft:red_sandstone"},
        {pos: [3, 0, 6], state: "minecraft:red_sandstone"},
        {pos: [3, 0, 7], state: "minecraft:red_sandstone"},
        {pos: [3, 0, 8], state: "minecraft:red_sandstone"},
        {pos: [3, 0, 9], state: "minecraft:red_sandstone"},
        {pos: [3, 0, 10], state: "minecraft:red_sandstone"},
        {pos: [4, 0, 3], state: "minecraft:red_sandstone"},
        {pos: [4, 0, 4], state: "minecraft:red_sandstone"},
        {pos: [4, 0, 5], state: "minecraft:red_sandstone"},
        {pos: [4, 0, 6], state: "minecraft:red_sandstone"},
        {pos: [4, 0, 7], state: "minecraft:red_sandstone"},
        {pos: [4, 0, 8], state: "minecraft:red_sandstone"},
        {pos: [4, 0, 9], state: "minecraft:red_sandstone"},
        {pos: [4, 0, 10], state: "minecraft:red_sandstone"},
        {pos: [4, 0, 11], state: "minecraft:red_sandstone"},
        {pos: [5, 0, 3], state: "minecraft:red_sandstone"},
        {pos: [5, 0, 4], state: "minecraft:red_sandstone"},
        {pos: [5, 0, 5], state: "minecraft:red_sandstone"},
        {pos: [5, 0, 6], state: "minecraft:red_sandstone"},
        {pos: [5, 0, 7], state: "minecraft:red_sandstone"},
        {pos: [5, 0, 8], state: "minecraft:red_sandstone"},
        {pos: [5, 0, 9], state: "minecraft:red_sandstone"},
        {pos: [5, 0, 10], state: "minecraft:red_sandstone"},
        {pos: [5, 0, 11], state: "minecraft:red_sandstone"},
        {pos: [6, 0, 3], state: "minecraft:red_sandstone"},
        {pos: [6, 0, 4], state: "minecraft:red_sandstone"},
        {pos: [6, 0, 5], state: "minecraft:red_sandstone"},
        {pos: [6, 0, 6], state: "minecraft:red_sandstone"},
        {pos: [6, 0, 7], state: "minecraft:red_sandstone"},
        {pos: [6, 0, 8], state: "minecraft:red_sandstone"},
        {pos: [6, 0, 9], state: "minecraft:red_sandstone"},
        {pos: [6, 0, 10], state: "minecraft:red_sandstone"},
        {pos: [6, 0, 11], state: "minecraft:red_sandstone"},
        {pos: [7, 0, 3], state: "minecraft:red_sandstone"},
        {pos: [7, 0, 4], state: "minecraft:red_sandstone"},
        {pos: [7, 0, 5], state: "minecraft:red_sandstone"},
        {pos: [7, 0, 6], state: "minecraft:red_sandstone"},
        {pos: [7, 0, 7], state: "minecraft:red_sandstone"},
        {pos: [7, 0, 8], state: "minecraft:red_sandstone"},
        {pos: [7, 0, 9], state: "minecraft:red_sandstone"},
        {pos: [7, 0, 10], state: "minecraft:red_sandstone"},
        {pos: [7, 0, 11], state: "minecraft:red_sandstone"},
        {pos: [8, 0, 3], state: "minecraft:red_sandstone"},
        {pos: [8, 0, 4], state: "minecraft:red_sandstone"},
        {pos: [8, 0, 5], state: "minecraft:red_sandstone"},
        {pos: [8, 0, 6], state: "minecraft:red_sandstone"},
        {pos: [8, 0, 7], state: "minecraft:red_sandstone"},
        {pos: [8, 0, 8], state: "minecraft:red_sandstone"},
        {pos: [8, 0, 9], state: "minecraft:red_sandstone"},
        {pos: [8, 0, 10], state: "minecraft:red_sandstone"},
        {pos: [8, 0, 11], state: "minecraft:red_sandstone"},
        {pos: [9, 0, 0], state: "minecraft:red_sandstone"},
        {pos: [9, 0, 1], state: "minecraft:red_sandstone"},
        {pos: [9, 0, 2], state: "minecraft:red_sandstone"},
        {pos: [9, 0, 3], state: "minecraft:red_sandstone"},
        {pos: [9, 0, 4], state: "minecraft:red_sandstone"},
        {pos: [9, 0, 5], state: "minecraft:red_sandstone"},
        {pos: [9, 0, 6], state: "minecraft:red_sandstone"},
        {pos: [9, 0, 7], state: "minecraft:red_sandstone"},
        {pos: [9, 0, 8], state: "minecraft:red_sandstone"},
        {pos: [9, 0, 9], state: "minecraft:red_sandstone"},
        {pos: [9, 0, 10], state: "minecraft:red_sandstone"},
        {pos: [9, 0, 11], state: "minecraft:red_sandstone"},
        {pos: [10, 0, 0], state: "minecraft:red_sandstone"},
        {pos: [10, 0, 1], state: "minecraft:red_sandstone"},
        {pos: [10, 0, 2], state: "minecraft:red_sandstone"},
        {pos: [10, 0, 3], state: "minecraft:red_sandstone"},
        {pos: [10, 0, 4], state: "minecraft:red_sandstone"},
        {pos: [10, 0, 5], state: "minecraft:red_sandstone"},
        {pos: [10, 0, 6], state: "minecraft:red_sandstone"},
        {pos: [10, 0, 7], state: "minecraft:red_sandstone"},
        {pos: [10, 0, 8], state: "minecraft:red_sandstone"},
        {pos: [10, 0, 9], state: "minecraft:red_sandstone"},
        {pos: [10, 0, 10], state: "minecraft:red_sandstone"},
        {pos: [10, 0, 11], state: "minecraft:red_sandstone"},
        {pos: [11, 0, 0], state: "minecraft:red_sandstone"},
        {pos: [11, 0, 1], state: "minecraft:red_sandstone"},
        {pos: [11, 0, 2], state: "minecraft:red_sandstone"},
        {pos: [11, 0, 3], state: "minecraft:red_sandstone"},
        {pos: [11, 0, 4], state: "minecraft:red_sandstone"},
        {pos: [11, 0, 5], state: "minecraft:red_sandstone"},
        {pos: [11, 0, 6], state: "minecraft:red_sandstone"},
        {pos: [11, 0, 7], state: "minecraft:red_sandstone"},
        {pos: [11, 0, 8], state: "minecraft:red_sandstone"},
        {pos: [11, 0, 9], state: "minecraft:red_sandstone"},
        {pos: [11, 0, 10], state: "minecraft:red_sandstone"},
        {pos: [11, 0, 11], state: "minecraft:red_sandstone"},
        {pos: [12, 0, 0], state: "minecraft:red_sandstone"},
        {pos: [12, 0, 1], state: "minecraft:red_sandstone"},
        {pos: [12, 0, 2], state: "minecraft:red_sandstone"},
        {pos: [12, 0, 3], state: "minecraft:yellow_glazed_terracotta{facing:north}"},
        {pos: [12, 0, 4], state: "minecraft:yellow_glazed_terracotta{facing:west}"},
        {pos: [12, 0, 5], state: "minecraft:red_sandstone"},
        {pos: [12, 0, 6], state: "minecraft:red_sandstone"},
        {pos: [12, 0, 7], state: "minecraft:red_sandstone"},
        {pos: [13, 0, 0], state: "minecraft:red_sandstone"},
        {pos: [13, 0, 1], state: "minecraft:red_sandstone"},
        {pos: [13, 0, 2], state: "minecraft:red_sandstone"},
        {pos: [13, 0, 3], state: "minecraft:yellow_glazed_terracotta{facing:east}"},
        {pos: [13, 0, 4], state: "minecraft:yellow_glazed_terracotta{facing:south}"},
        {pos: [13, 0, 5], state: "minecraft:red_sandstone"},
        {pos: [13, 0, 6], state: "minecraft:red_sandstone"},
        {pos: [13, 0, 7], state: "minecraft:red_sandstone"},
        {pos: [14, 0, 0], state: "minecraft:red_sandstone"},
        {pos: [14, 0, 1], state: "minecraft:red_sandstone"},
        {pos: [14, 0, 2], state: "minecraft:red_sandstone"},
        {pos: [14, 0, 3], state: "minecraft:red_sandstone"},
        {pos: [14, 0, 4], state: "minecraft:red_sandstone"},
        {pos: [14, 0, 5], state: "minecraft:red_sandstone"},
        {pos: [14, 0, 6], state: "minecraft:red_sandstone"},
        {pos: [14, 0, 7], state: "minecraft:red_sandstone"},
        {pos: [15, 0, 0], state: "minecraft:red_sandstone"},
        {pos: [15, 0, 1], state: "minecraft:red_sandstone"},
        {pos: [15, 0, 2], state: "minecraft:red_sandstone"},
        {pos: [15, 0, 3], state: "minecraft:red_sandstone"},
        {pos: [15, 0, 4], state: "minecraft:red_sandstone"},
        {pos: [15, 0, 5], state: "minecraft:red_sandstone"},
        {pos: [15, 0, 6], state: "minecraft:red_sandstone"},
        {pos: [15, 0, 7], state: "minecraft:red_sandstone"},
        {pos: [16, 0, 0], state: "minecraft:red_sandstone"},
        {pos: [16, 0, 1], state: "minecraft:red_sandstone"},
        {pos: [16, 0, 2], state: "minecraft:red_sandstone"},
        {pos: [16, 0, 3], state: "minecraft:red_sandstone"},
        {pos: [16, 0, 4], state: "minecraft:red_sandstone"},
        {pos: [16, 0, 5], state: "minecraft:red_sandstone"},
        {pos: [16, 0, 6], state: "minecraft:red_sandstone"},
        {pos: [16, 0, 7], state: "minecraft:red_sandstone"},
        {pos: [17, 0, 0], state: "minecraft:red_sandstone"},
        {pos: [17, 0, 1], state: "minecraft:red_sandstone"},
        {pos: [17, 0, 2], state: "minecraft:red_sandstone"},
        {pos: [17, 0, 3], state: "minecraft:red_sandstone"},
        {pos: [17, 0, 4], state: "minecraft:red_sandstone"},
        {pos: [17, 0, 5], state: "minecraft:red_sandstone"},
        {pos: [17, 0, 6], state: "minecraft:red_sandstone"},
        {pos: [17, 0, 7], state: "minecraft:red_sandstone"},
        {pos: [18, 0, 0], state: "minecraft:red_sandstone"},
        {pos: [18, 0, 1], state: "minecraft:red_sandstone"},
        {pos: [18, 0, 2], state: "minecraft:red_sandstone"},
        {pos: [18, 0, 3], state: "minecraft:red_sandstone"},
        {pos: [18, 0, 4], state: "minecraft:red_sandstone"},
        {pos: [18, 0, 5], state: "minecraft:red_sandstone"},
        {pos: [18, 0, 6], state: "minecraft:red_sandstone"},
        {pos: [18, 0, 7], state: "minecraft:red_sandstone"},
        {pos: [19, 0, 1], state: "minecraft:red_sandstone"},
        {pos: [19, 0, 2], state: "minecraft:red_sandstone"},
        {pos: [19, 0, 3], state: "minecraft:red_sandstone"},
        {pos: [19, 0, 4], state: "minecraft:red_sandstone"},
        {pos: [19, 0, 5], state: "minecraft:red_sandstone"},
        {pos: [19, 0, 6], state: "minecraft:red_sandstone"},
        {pos: [19, 0, 7], state: "minecraft:red_sandstone"},
        {pos: [20, 0, 1], state: "minecraft:red_sandstone"},
        {pos: [20, 0, 2], state: "minecraft:red_sandstone"},
        {pos: [20, 0, 3], state: "minecraft:red_sandstone"},
        {pos: [20, 0, 4], state: "minecraft:red_sandstone"},
        {pos: [20, 0, 5], state: "minecraft:red_sandstone"},
        {pos: [20, 0, 6], state: "minecraft:red_sandstone"},
        {pos: [20, 0, 7], state: "minecraft:red_sandstone"},
        {pos: [21, 0, 1], state: "minecraft:red_sandstone"},
        {pos: [21, 0, 2], state: "minecraft:red_sandstone"},
        {pos: [21, 0, 3], state: "minecraft:red_sandstone"},
        {pos: [21, 0, 4], state: "minecraft:red_sandstone"},
        {pos: [21, 0, 5], state: "minecraft:red_sandstone"},
        {pos: [21, 0, 6], state: "minecraft:red_sandstone"},
        {pos: [21, 0, 7], state: "minecraft:red_sandstone"},
        {pos: [0, 1, 4], state: "minecraft:red_sand"},
        {pos: [0, 1, 5], state: "minecraft:smooth_red_sandstone"},
        {pos: [0, 1, 6], state: "minecraft:smooth_red_sandstone"},
        {pos: [0, 1, 7], state: "minecraft:smooth_red_sandstone"},
        {pos: [0, 1, 8], state: "minecraft:smooth_red_sandstone"},
        {pos: [0, 1, 9], state: "minecraft:red_terracotta"},
        {pos: [0, 1, 10], state: "minecraft:red_terracotta"},
        {pos: [1, 1, 4], state: "minecraft:red_sand"},
        {pos: [1, 1, 5], state: "minecraft:smooth_red_sandstone"},
        {pos: [1, 1, 6], state: "minecraft:smooth_red_sandstone"},
        {pos: [1, 1, 7], state: "minecraft:smooth_red_sandstone"},
        {pos: [1, 1, 8], state: "minecraft:smooth_red_sandstone"},
        {pos: [1, 1, 9], state: "minecraft:red_terracotta"},
        {pos: [1, 1, 10], state: "minecraft:red_terracotta"},
        {pos: [2, 1, 4], state: "minecraft:red_sandstone_stairs{facing:south,half:bottom,shape:straight,waterlogged:false}"},
        {pos: [2, 1, 5], state: "minecraft:smooth_red_sandstone"},
        {pos: [2, 1, 6], state: "minecraft:smooth_red_sandstone"},
        {pos: [2, 1, 7], state: "minecraft:smooth_red_sandstone"},
        {pos: [2, 1, 8], state: "minecraft:smooth_red_sandstone"},
        {pos: [2, 1, 9], state: "minecraft:red_terracotta"},
        {pos: [2, 1, 10], state: "minecraft:red_terracotta"},
        {pos: [3, 1, 3], state: "minecraft:red_sandstone_stairs{facing:south,half:top,shape:straight,waterlogged:false}"},
        {pos: [3, 1, 4], state: "minecraft:red_terracotta"},
        {pos: [3, 1, 5], state: "minecraft:red_terracotta"},
        {pos: [3, 1, 6], state: "minecraft:smooth_red_sandstone"},
        {pos: [3, 1, 7], state: "minecraft:smooth_red_sandstone"},
        {pos: [3, 1, 8], state: "minecraft:smooth_red_sandstone"},
        {pos: [3, 1, 9], state: "minecraft:red_terracotta"},
        {pos: [3, 1, 10], state: "minecraft:red_terracotta"},
        {pos: [4, 1, 3], state: "minecraft:red_sandstone_stairs{facing:south,half:top,shape:straight,waterlogged:false}"},
        {pos: [4, 1, 4], state: "minecraft:red_terracotta"},
        {pos: [4, 1, 5], state: "minecraft:red_terracotta"},
        {pos: [4, 1, 6], state: "minecraft:smooth_red_sandstone"},
        {pos: [4, 1, 7], state: "minecraft:smooth_red_sandstone"},
        {pos: [4, 1, 8], state: "minecraft:smooth_red_sandstone"},
        {pos: [4, 1, 9], state: "minecraft:red_terracotta"},
        {pos: [4, 1, 10], state: "minecraft:red_terracotta"},
        {pos: [4, 1, 11], state: "minecraft:red_terracotta"},
        {pos: [5, 1, 3], state: "minecraft:red_sandstone_stairs{facing:south,half:top,shape:straight,waterlogged:false}"},
        {pos: [5, 1, 4], state: "minecraft:red_terracotta"},
        {pos: [5, 1, 5], state: "minecraft:red_terracotta"},
        {pos: [5, 1, 6], state: "minecraft:smooth_red_sandstone"},
        {pos: [5, 1, 7], state: "minecraft:smooth_red_sandstone"},
        {pos: [5, 1, 8], state: "minecraft:smooth_red_sandstone"},
        {pos: [5, 1, 9], state: "minecraft:red_terracotta"},
        {pos: [5, 1, 10], state: "minecraft:red_terracotta"},
        {pos: [5, 1, 11], state: "minecraft:red_terracotta"},
        {pos: [6, 1, 3], state: "minecraft:red_terracotta"},
        {pos: [6, 1, 4], state: "minecraft:red_terracotta"},
        {pos: [6, 1, 5], state: "minecraft:red_terracotta"},
        {pos: [6, 1, 6], state: "minecraft:red_terracotta"},
        {pos: [6, 1, 7], state: "minecraft:red_terracotta"},
        {pos: [6, 1, 8], state: "minecraft:red_terracotta"},
        {pos: [6, 1, 9], state: "minecraft:red_terracotta"},
        {pos: [6, 1, 10], state: "minecraft:red_terracotta"},
        {pos: [6, 1, 11], state: "minecraft:red_terracotta"},
        {pos: [7, 1, 3], state: "minecraft:red_terracotta"},
        {pos: [7, 1, 4], state: "minecraft:red_sandstone_stairs{facing:west,half:top,shape:straight,waterlogged:false}"},
        {pos: [7, 1, 5], state: "minecraft:red_sandstone_stairs{facing:west,half:top,shape:straight,waterlogged:false}"},
        {pos: [7, 1, 6], state: "minecraft:red_sandstone_stairs{facing:west,half:top,shape:straight,waterlogged:false}"},
        {pos: [7, 1, 7], state: "minecraft:red_sand"},
        {pos: [7, 1, 8], state: "minecraft:red_sand"},
        {pos: [7, 1, 9], state: "minecraft:red_sand"},
        {pos: [7, 1, 10], state: "minecraft:red_sand"},
        {pos: [7, 1, 11], state: "minecraft:red_terracotta"},
        {pos: [8, 1, 3], state: "minecraft:red_terracotta"},
        {pos: [8, 1, 4], state: "minecraft:red_sand"},
        {pos: [8, 1, 5], state: "minecraft:red_sand"},
        {pos: [8, 1, 6], state: "minecraft:red_sand"},
        {pos: [8, 1, 7], state: "minecraft:red_sand"},
        {pos: [8, 1, 8], state: "minecraft:red_sand"},
        {pos: [8, 1, 9], state: "minecraft:orange_bed{facing:south,occupied:false,part:foot}", nbt: {id: "minecraft:bed"}},
        {pos: [8, 1, 10], state: "minecraft:orange_bed{facing:south,occupied:false,part:head}", nbt: {id: "minecraft:bed"}},
        {pos: [8, 1, 11], state: "minecraft:red_terracotta"},
        {pos: [9, 1, 0], state: "minecraft:red_terracotta"},
        {pos: [9, 1, 1], state: "minecraft:red_terracotta"},
        {pos: [9, 1, 2], state: "minecraft:red_terracotta"},
        {pos: [9, 1, 3], state: "minecraft:red_terracotta"},
        {pos: [9, 1, 4], state: "minecraft:red_sand"},
        {pos: [9, 1, 5], state: "minecraft:red_sand"},
        {pos: [9, 1, 6], state: "minecraft:red_sand"},
        {pos: [9, 1, 7], state: "minecraft:red_sand"},
        {pos: [9, 1, 8], state: "minecraft:red_sand"},
        {pos: [9, 1, 9], state: "minecraft:red_sand"},
        {pos: [9, 1, 10], state: "minecraft:red_sand"},
        {pos: [9, 1, 11], state: "minecraft:red_terracotta"},
        {pos: [10, 1, 0], state: "minecraft:red_terracotta"},
        {pos: [10, 1, 1], state: "minecraft:red_sandstone_stairs{facing:west,half:top,shape:straight,waterlogged:false}"},
        {pos: [10, 1, 2], state: "minecraft:red_sandstone_stairs{facing:west,half:top,shape:straight,waterlogged:false}"},
        {pos: [10, 1, 3], state: "minecraft:red_sandstone_stairs{facing:west,half:top,shape:straight,waterlogged:false}"},
        {pos: [10, 1, 4], state: "minecraft:red_sand"},
        {pos: [10, 1, 5], state: "minecraft:red_sand"},
        {pos: [10, 1, 6], state: "minecraft:red_sandstone_stairs{facing:south,half:top,shape:straight,waterlogged:false}"},
        {pos: [10, 1, 7], state: "minecraft:red_terracotta"},
        {pos: [10, 1, 8], state: "minecraft:red_terracotta"},
        {pos: [10, 1, 9], state: "minecraft:red_terracotta"},
        {pos: [10, 1, 10], state: "minecraft:red_terracotta"},
        {pos: [10, 1, 11], state: "minecraft:red_terracotta"},
        {pos: [11, 1, 0], state: "minecraft:red_terracotta"},
        {pos: [11, 1, 1], state: "minecraft:red_sand"},
        {pos: [11, 1, 2], state: "minecraft:red_sand"},
        {pos: [11, 1, 3], state: "minecraft:red_sand"},
        {pos: [11, 1, 4], state: "minecraft:red_sand"},
        {pos: [11, 1, 5], state: "minecraft:red_sand"},
        {pos: [11, 1, 6], state: "minecraft:red_sandstone_stairs{facing:south,half:top,shape:straight,waterlogged:false}"},
        {pos: [11, 1, 7], state: "minecraft:red_terracotta"},
        {pos: [11, 1, 8], state: "minecraft:red_terracotta"},
        {pos: [11, 1, 9], state: "minecraft:red_terracotta"},
        {pos: [11, 1, 10], state: "minecraft:red_terracotta"},
        {pos: [11, 1, 11], state: "minecraft:red_terracotta"},
        {pos: [12, 1, 0], state: "minecraft:red_sand"},
        {pos: [12, 1, 1], state: "minecraft:red_sand"},
        {pos: [12, 1, 2], state: "minecraft:red_sand"},
        {pos: [12, 1, 3], state: "minecraft:red_sand"},
        {pos: [12, 1, 4], state: "minecraft:red_sand"},
        {pos: [12, 1, 5], state: "minecraft:red_sand"},
        {pos: [12, 1, 6], state: "minecraft:red_sandstone_stairs{facing:south,half:top,shape:straight,waterlogged:false}"},
        {pos: [12, 1, 7], state: "minecraft:red_terracotta"},
        {pos: [13, 1, 0], state: "minecraft:red_terracotta"},
        {pos: [13, 1, 1], state: "minecraft:red_sand"},
        {pos: [13, 1, 2], state: "minecraft:red_sand"},
        {pos: [13, 1, 3], state: "minecraft:red_sand"},
        {pos: [13, 1, 4], state: "minecraft:red_sand"},
        {pos: [13, 1, 5], state: "minecraft:red_sand"},
        {pos: [13, 1, 6], state: "minecraft:red_sand"},
        {pos: [13, 1, 7], state: "minecraft:red_terracotta"},
        {pos: [14, 1, 0], state: "minecraft:red_terracotta"},
        {pos: [14, 1, 1], state: "minecraft:red_sand"},
        {pos: [14, 1, 2], state: "minecraft:red_sandstone_stairs{facing:east,half:top,shape:straight,waterlogged:false}"},
        {pos: [14, 1, 3], state: "minecraft:red_sandstone_stairs{facing:east,half:top,shape:straight,waterlogged:false}"},
        {pos: [14, 1, 4], state: "minecraft:red_sandstone_stairs{facing:east,half:top,shape:straight,waterlogged:false}"},
        {pos: [14, 1, 5], state: "minecraft:red_sand"},
        {pos: [14, 1, 6], state: "minecraft:red_sand"},
        {pos: [14, 1, 7], state: "minecraft:red_terracotta"},
        {pos: [15, 1, 0], state: "minecraft:red_terracotta"},
        {pos: [15, 1, 1], state: "minecraft:red_terracotta"},
        {pos: [15, 1, 2], state: "minecraft:red_terracotta"},
        {pos: [15, 1, 3], state: "minecraft:red_terracotta"},
        {pos: [15, 1, 4], state: "minecraft:red_terracotta"},
        {pos: [15, 1, 5], state: "minecraft:red_terracotta"},
        {pos: [15, 1, 6], state: "minecraft:red_terracotta"},
        {pos: [15, 1, 7], state: "minecraft:red_terracotta"},
        {pos: [16, 1, 0], state: "minecraft:red_sandstone_stairs{facing:south,half:top,shape:straight,waterlogged:false}"},
        {pos: [16, 1, 1], state: "minecraft:red_terracotta"},
        {pos: [16, 1, 2], state: "minecraft:red_terracotta"},
        {pos: [16, 1, 3], state: "minecraft:smooth_red_sandstone"},
        {pos: [16, 1, 4], state: "minecraft:smooth_red_sandstone"},
        {pos: [16, 1, 5], state: "minecraft:smooth_red_sandstone"},
        {pos: [16, 1, 6], state: "minecraft:red_terracotta"},
        {pos: [16, 1, 7], state: "minecraft:red_terracotta"},
        {pos: [17, 1, 0], state: "minecraft:red_sandstone_stairs{facing:south,half:top,shape:straight,waterlogged:false}"},
        {pos: [17, 1, 1], state: "minecraft:red_terracotta"},
        {pos: [17, 1, 2], state: "minecraft:red_terracotta"},
        {pos: [17, 1, 3], state: "minecraft:smooth_red_sandstone"},
        {pos: [17, 1, 4], state: "minecraft:smooth_red_sandstone"},
        {pos: [17, 1, 5], state: "minecraft:smooth_red_sandstone"},
        {pos: [17, 1, 6], state: "minecraft:red_terracotta"},
        {pos: [17, 1, 7], state: "minecraft:red_terracotta"},
        {pos: [18, 1, 0], state: "minecraft:red_sandstone_stairs{facing:south,half:top,shape:straight,waterlogged:false}"},
        {pos: [18, 1, 1], state: "minecraft:red_terracotta"},
        {pos: [18, 1, 2], state: "minecraft:red_terracotta"},
        {pos: [18, 1, 3], state: "minecraft:smooth_red_sandstone"},
        {pos: [18, 1, 4], state: "minecraft:smooth_red_sandstone"},
        {pos: [18, 1, 5], state: "minecraft:smooth_red_sandstone"},
        {pos: [18, 1, 6], state: "minecraft:red_terracotta"},
        {pos: [18, 1, 7], state: "minecraft:red_terracotta"},
        {pos: [19, 1, 1], state: "minecraft:red_sandstone_stairs{facing:south,half:bottom,shape:straight,waterlogged:false}"},
        {pos: [19, 1, 2], state: "minecraft:smooth_red_sandstone"},
        {pos: [19, 1, 3], state: "minecraft:smooth_red_sandstone"},
        {pos: [19, 1, 4], state: "minecraft:smooth_red_sandstone"},
        {pos: [19, 1, 5], state: "minecraft:smooth_red_sandstone"},
        {pos: [19, 1, 6], state: "minecraft:red_terracotta"},
        {pos: [19, 1, 7], state: "minecraft:red_terracotta"},
        {pos: [20, 1, 1], state: "minecraft:red_sandstone_stairs{facing:south,half:bottom,shape:straight,waterlogged:false}"},
        {pos: [20, 1, 2], state: "minecraft:smooth_red_sandstone"},
        {pos: [20, 1, 3], state: "minecraft:smooth_red_sandstone"},
        {pos: [20, 1, 4], state: "minecraft:smooth_red_sandstone"},
        {pos: [20, 1, 5], state: "minecraft:smooth_red_sandstone"},
        {pos: [20, 1, 6], state: "minecraft:red_terracotta"},
        {pos: [20, 1, 7], state: "minecraft:red_terracotta"},
        {pos: [21, 1, 1], state: "minecraft:red_sand"},
        {pos: [21, 1, 2], state: "minecraft:smooth_red_sandstone"},
        {pos: [21, 1, 3], state: "minecraft:smooth_red_sandstone"},
        {pos: [21, 1, 4], state: "minecraft:smooth_red_sandstone"},
        {pos: [21, 1, 5], state: "minecraft:smooth_red_sandstone"},
        {pos: [21, 1, 6], state: "minecraft:red_terracotta"},
        {pos: [21, 1, 7], state: "minecraft:red_terracotta"},
        {pos: [0, 2, 4], state: "minecraft:red_sand"},
        {pos: [0, 2, 5], state: "minecraft:red_sandstone_stairs{facing:south,half:bottom,shape:straight,waterlogged:false}"},
        {pos: [0, 2, 6], state: "minecraft:smooth_red_sandstone"},
        {pos: [0, 2, 7], state: "minecraft:smooth_red_sandstone"},
        {pos: [0, 2, 8], state: "minecraft:smooth_red_sandstone"},
        {pos: [0, 2, 9], state: "minecraft:smooth_red_sandstone"},
        {pos: [0, 2, 10], state: "minecraft:smooth_red_sandstone"},
        {pos: [1, 2, 4], state: "minecraft:red_sand"},
        {pos: [1, 2, 5], state: "minecraft:red_sandstone_stairs{facing:south,half:bottom,shape:straight,waterlogged:false}"},
        {pos: [1, 2, 6], state: "minecraft:smooth_red_sandstone"},
        {pos: [1, 2, 7], state: "minecraft:smooth_red_sandstone"},
        {pos: [1, 2, 8], state: "minecraft:smooth_red_sandstone"},
        {pos: [1, 2, 9], state: "minecraft:red_terracotta"},
        {pos: [1, 2, 10], state: "minecraft:smooth_red_sandstone"},
        {pos: [2, 2, 4], state: "minecraft:red_sand"},
        {pos: [2, 2, 5], state: "minecraft:red_sandstone_stairs{facing:south,half:bottom,shape:straight,waterlogged:false}"},
        {pos: [2, 2, 6], state: "minecraft:smooth_red_sandstone"},
        {pos: [2, 2, 7], state: "minecraft:smooth_red_sandstone"},
        {pos: [2, 2, 8], state: "minecraft:smooth_red_sandstone"},
        {pos: [2, 2, 9], state: "minecraft:red_terracotta"},
        {pos: [2, 2, 10], state: "minecraft:red_terracotta"},
        {pos: [3, 2, 3], state: "minecraft:red_sand"},
        {pos: [3, 2, 4], state: "minecraft:red_terracotta"},
        {pos: [3, 2, 5], state: "minecraft:red_terracotta"},
        {pos: [3, 2, 6], state: "minecraft:smooth_red_sandstone"},
        {pos: [3, 2, 7], state: "minecraft:smooth_red_sandstone"},
        {pos: [3, 2, 8], state: "minecraft:smooth_red_sandstone"},
        {pos: [3, 2, 9], state: "minecraft:red_terracotta"},
        {pos: [3, 2, 10], state: "minecraft:red_terracotta"},
        {pos: [4, 2, 3], state: "minecraft:red_sand"},
        {pos: [4, 2, 4], state: "minecraft:red_terracotta"},
        {pos: [4, 2, 5], state: "minecraft:red_terracotta"},
        {pos: [4, 2, 6], state: "minecraft:smooth_red_sandstone"},
        {pos: [4, 2, 7], state: "minecraft:smooth_red_sandstone"},
        {pos: [4, 2, 8], state: "minecraft:smooth_red_sandstone"},
        {pos: [4, 2, 9], state: "minecraft:red_terracotta"},
        {pos: [4, 2, 10], state: "minecraft:red_terracotta"},
        {pos: [4, 2, 11], state: "minecraft:red_terracotta"},
        {pos: [5, 2, 3], state: "minecraft:red_sand"},
        {pos: [5, 2, 4], state: "minecraft:red_terracotta"},
        {pos: [5, 2, 5], state: "minecraft:red_terracotta"},
        {pos: [5, 2, 6], state: "minecraft:smooth_red_sandstone"},
        {pos: [5, 2, 7], state: "minecraft:smooth_red_sandstone"},
        {pos: [5, 2, 8], state: "minecraft:smooth_red_sandstone"},
        {pos: [5, 2, 9], state: "minecraft:red_terracotta"},
        {pos: [5, 2, 10], state: "minecraft:red_terracotta"},
        {pos: [5, 2, 11], state: "minecraft:red_terracotta"},
        {pos: [6, 2, 3], state: "minecraft:red_terracotta"},
        {pos: [6, 2, 4], state: "minecraft:red_terracotta"},
        {pos: [6, 2, 5], state: "minecraft:red_terracotta"},
        {pos: [6, 2, 6], state: "minecraft:red_terracotta"},
        {pos: [6, 2, 7], state: "minecraft:red_terracotta"},
        {pos: [6, 2, 8], state: "minecraft:red_terracotta"},
        {pos: [6, 2, 9], state: "minecraft:red_terracotta"},
        {pos: [6, 2, 10], state: "minecraft:red_terracotta"},
        {pos: [6, 2, 11], state: "minecraft:red_terracotta"},
        {pos: [7, 2, 3], state: "minecraft:red_sand"},
        {pos: [7, 2, 4], state: "minecraft:red_sand"},
        {pos: [7, 2, 5], state: "minecraft:red_sand"},
        {pos: [7, 2, 6], state: "minecraft:red_sand"},
        {pos: [7, 2, 7], state: "minecraft:red_sand"},
        {pos: [7, 2, 8], state: "minecraft:red_sand"},
        {pos: [7, 2, 9], state: "minecraft:red_sand"},
        {pos: [7, 2, 10], state: "minecraft:red_sand"},
        {pos: [7, 2, 11], state: "minecraft:red_terracotta"},
        {pos: [8, 2, 3], state: "minecraft:red_terracotta"},
        {pos: [8, 2, 4], state: "minecraft:red_sand"},
        {pos: [8, 2, 5], state: "minecraft:red_sand"},
        {pos: [8, 2, 6], state: "minecraft:red_sand"},
        {pos: [8, 2, 7], state: "minecraft:red_sand"},
        {pos: [8, 2, 8], state: "minecraft:red_sand"},
        {pos: [8, 2, 9], state: "minecraft:red_sand"},
        {pos: [8, 2, 10], state: "minecraft:red_sand"},
        {pos: [8, 2, 11], state: "minecraft:red_terracotta"},
        {pos: [9, 2, 0], state: "minecraft:red_terracotta"},
        {pos: [9, 2, 1], state: "minecraft:red_sand"},
        {pos: [9, 2, 2], state: "minecraft:red_terracotta"},
        {pos: [9, 2, 3], state: "minecraft:red_terracotta"},
        {pos: [9, 2, 4], state: "minecraft:red_sand"},
        {pos: [9, 2, 5], state: "minecraft:red_sand"},
        {pos: [9, 2, 6], state: "minecraft:red_sand"},
        {pos: [9, 2, 7], state: "minecraft:red_sand"},
        {pos: [9, 2, 8], state: "minecraft:red_sand"},
        {pos: [9, 2, 9], state: "minecraft:red_sand"},
        {pos: [9, 2, 10], state: "minecraft:red_sand"},
        {pos: [9, 2, 11], state: "minecraft:red_terracotta"},
        {pos: [10, 2, 0], state: "minecraft:red_sand"},
        {pos: [10, 2, 1], state: "minecraft:red_sand"},
        {pos: [10, 2, 2], state: "minecraft:red_sand"},
        {pos: [10, 2, 3], state: "minecraft:red_sand"},
        {pos: [10, 2, 4], state: "minecraft:red_sand"},
        {pos: [10, 2, 5], state: "minecraft:red_sand"},
        {pos: [10, 2, 6], state: "minecraft:red_sand"},
        {pos: [10, 2, 7], state: "minecraft:red_terracotta"},
        {pos: [10, 2, 8], state: "minecraft:red_terracotta"},
        {pos: [10, 2, 9], state: "minecraft:red_terracotta"},
        {pos: [10, 2, 10], state: "minecraft:red_terracotta"},
        {pos: [10, 2, 11], state: "minecraft:red_terracotta"},
        {pos: [11, 2, 0], state: "minecraft:red_terracotta"},
        {pos: [11, 2, 1], state: "minecraft:red_sand"},
        {pos: [11, 2, 2], state: "minecraft:red_sand"},
        {pos: [11, 2, 3], state: "minecraft:red_sand"},
        {pos: [11, 2, 4], state: "minecraft:red_sand"},
        {pos: [11, 2, 5], state: "minecraft:red_sand"},
        {pos: [11, 2, 6], state: "minecraft:red_sand"},
        {pos: [11, 2, 7], state: "minecraft:red_terracotta"},
        {pos: [11, 2, 8], state: "minecraft:red_terracotta"},
        {pos: [11, 2, 9], state: "minecraft:red_terracotta"},
        {pos: [11, 2, 10], state: "minecraft:red_terracotta"},
        {pos: [11, 2, 11], state: "minecraft:red_terracotta"},
        {pos: [12, 2, 0], state: "minecraft:red_sand"},
        {pos: [12, 2, 1], state: "minecraft:red_sand"},
        {pos: [12, 2, 2], state: "minecraft:red_sand"},
        {pos: [12, 2, 3], state: "minecraft:red_sand"},
        {pos: [12, 2, 4], state: "minecraft:red_sand"},
        {pos: [12, 2, 5], state: "minecraft:red_sand"},
        {pos: [12, 2, 6], state: "minecraft:red_sand"},
        {pos: [12, 2, 7], state: "minecraft:red_terracotta"},
        {pos: [13, 2, 0], state: "minecraft:red_terracotta"},
        {pos: [13, 2, 1], state: "minecraft:red_sand"},
        {pos: [13, 2, 2], state: "minecraft:red_sand"},
        {pos: [13, 2, 3], state: "minecraft:red_sand"},
        {pos: [13, 2, 4], state: "minecraft:red_sand"},
        {pos: [13, 2, 5], state: "minecraft:red_sand"},
        {pos: [13, 2, 6], state: "minecraft:red_sand"},
        {pos: [13, 2, 7], state: "minecraft:red_terracotta"},
        {pos: [14, 2, 0], state: "minecraft:red_sand"},
        {pos: [14, 2, 1], state: "minecraft:red_sand"},
        {pos: [14, 2, 2], state: "minecraft:red_sand"},
        {pos: [14, 2, 3], state: "minecraft:red_sand"},
        {pos: [14, 2, 4], state: "minecraft:red_sand"},
        {pos: [14, 2, 5], state: "minecraft:red_sand"},
        {pos: [14, 2, 6], state: "minecraft:red_sand"},
        {pos: [14, 2, 7], state: "minecraft:red_terracotta"},
        {pos: [15, 2, 0], state: "minecraft:red_terracotta"},
        {pos: [15, 2, 1], state: "minecraft:red_terracotta"},
        {pos: [15, 2, 2], state: "minecraft:red_terracotta"},
        {pos: [15, 2, 3], state: "minecraft:red_terracotta"},
        {pos: [15, 2, 4], state: "minecraft:red_terracotta"},
        {pos: [15, 2, 5], state: "minecraft:red_terracotta"},
        {pos: [15, 2, 6], state: "minecraft:red_terracotta"},
        {pos: [15, 2, 7], state: "minecraft:red_terracotta"},
        {pos: [16, 2, 0], state: "minecraft:red_sand"},
        {pos: [16, 2, 1], state: "minecraft:red_terracotta"},
        {pos: [16, 2, 2], state: "minecraft:red_terracotta"},
        {pos: [16, 2, 3], state: "minecraft:smooth_red_sandstone"},
        {pos: [16, 2, 4], state: "minecraft:smooth_red_sandstone"},
        {pos: [16, 2, 5], state: "minecraft:smooth_red_sandstone"},
        {pos: [16, 2, 6], state: "minecraft:red_terracotta"},
        {pos: [16, 2, 7], state: "minecraft:red_terracotta"},
        {pos: [17, 2, 0], state: "minecraft:red_sand"},
        {pos: [17, 2, 1], state: "minecraft:red_terracotta"},
        {pos: [17, 2, 2], state: "minecraft:red_terracotta"},
        {pos: [17, 2, 3], state: "minecraft:smooth_red_sandstone"},
        {pos: [17, 2, 4], state: "minecraft:smooth_red_sandstone"},
        {pos: [17, 2, 5], state: "minecraft:smooth_red_sandstone"},
        {pos: [17, 2, 6], state: "minecraft:red_terracotta"},
        {pos: [17, 2, 7], state: "minecraft:red_terracotta"},
        {pos: [18, 2, 0], state: "minecraft:red_sand"},
        {pos: [18, 2, 1], state: "minecraft:red_terracotta"},
        {pos: [18, 2, 2], state: "minecraft:red_terracotta"},
        {pos: [18, 2, 3], state: "minecraft:smooth_red_sandstone"},
        {pos: [18, 2, 4], state: "minecraft:smooth_red_sandstone"},
        {pos: [18, 2, 5], state: "minecraft:smooth_red_sandstone"},
        {pos: [18, 2, 6], state: "minecraft:red_terracotta"},
        {pos: [18, 2, 7], state: "minecraft:red_terracotta"},
        {pos: [19, 2, 1], state: "minecraft:red_sand"},
        {pos: [19, 2, 2], state: "minecraft:red_sandstone_stairs{facing:south,half:bottom,shape:straight,waterlogged:false}"},
        {pos: [19, 2, 3], state: "minecraft:smooth_red_sandstone"},
        {pos: [19, 2, 4], state: "minecraft:smooth_red_sandstone"},
        {pos: [19, 2, 5], state: "minecraft:smooth_red_sandstone"},
        {pos: [19, 2, 6], state: "minecraft:red_terracotta"},
        {pos: [19, 2, 7], state: "minecraft:red_terracotta"},
        {pos: [20, 2, 1], state: "minecraft:red_sand"},
        {pos: [20, 2, 2], state: "minecraft:red_sandstone_stairs{facing:south,half:bottom,shape:straight,waterlogged:false}"},
        {pos: [20, 2, 3], state: "minecraft:smooth_red_sandstone"},
        {pos: [20, 2, 4], state: "minecraft:smooth_red_sandstone"},
        {pos: [20, 2, 5], state: "minecraft:smooth_red_sandstone"},
        {pos: [20, 2, 6], state: "minecraft:red_terracotta"},
        {pos: [20, 2, 7], state: "minecraft:smooth_red_sandstone"},
        {pos: [21, 2, 1], state: "minecraft:red_sand"},
        {pos: [21, 2, 2], state: "minecraft:red_sandstone_stairs{facing:south,half:bottom,shape:straight,waterlogged:false}"},
        {pos: [21, 2, 3], state: "minecraft:smooth_red_sandstone"},
        {pos: [21, 2, 4], state: "minecraft:smooth_red_sandstone"},
        {pos: [21, 2, 5], state: "minecraft:smooth_red_sandstone"},
        {pos: [21, 2, 6], state: "minecraft:smooth_red_sandstone"},
        {pos: [21, 2, 7], state: "minecraft:smooth_red_sandstone"},
        {pos: [0, 3, 4], state: "minecraft:red_sand"},
        {pos: [0, 3, 5], state: "minecraft:red_sand"},
        {pos: [0, 3, 6], state: "minecraft:red_sand"},
        {pos: [0, 3, 7], state: "minecraft:red_sand"},
        {pos: [0, 3, 8], state: "minecraft:red_sand"},
        {pos: [0, 3, 9], state: "minecraft:cut_red_sandstone"},
        {pos: [0, 3, 10], state: "minecraft:cut_red_sandstone"},
        {pos: [1, 3, 4], state: "minecraft:red_sand"},
        {pos: [1, 3, 5], state: "minecraft:red_sand"},
        {pos: [1, 3, 6], state: "minecraft:red_sand"},
        {pos: [1, 3, 7], state: "minecraft:red_sand"},
        {pos: [1, 3, 8], state: "minecraft:red_sand"},
        {pos: [1, 3, 9], state: "minecraft:smooth_red_sandstone"},
        {pos: [1, 3, 10], state: "minecraft:smooth_red_sandstone"},
        {pos: [2, 3, 4], state: "minecraft:red_sand"},
        {pos: [2, 3, 5], state: "minecraft:red_sand"},
        {pos: [2, 3, 6], state: "minecraft:red_sand"},
        {pos: [2, 3, 7], state: "minecraft:red_sand"},
        {pos: [2, 3, 8], state: "minecraft:red_sand"},
        {pos: [2, 3, 9], state: "minecraft:smooth_red_sandstone"},
        {pos: [2, 3, 10], state: "minecraft:smooth_red_sandstone"},
        {pos: [3, 3, 3], state: "minecraft:red_sand"},
        {pos: [3, 3, 4], state: "minecraft:red_terracotta"},
        {pos: [3, 3, 5], state: "minecraft:red_terracotta"},
        {pos: [3, 3, 6], state: "minecraft:red_sand"},
        {pos: [3, 3, 7], state: "minecraft:red_sandstone_stairs{facing:east,half:bottom,shape:straight,waterlogged:false}"},
        {pos: [3, 3, 8], state: "minecraft:red_sandstone_stairs{facing:east,half:bottom,shape:straight,waterlogged:false}"},
        {pos: [3, 3, 9], state: "minecraft:red_terracotta"},
        {pos: [3, 3, 10], state: "minecraft:red_terracotta"},
        {pos: [4, 3, 3], state: "minecraft:red_sand"},
        {pos: [4, 3, 4], state: "minecraft:red_terracotta"},
        {pos: [4, 3, 5], state: "minecraft:red_terracotta"},
        {pos: [4, 3, 6], state: "minecraft:smooth_red_sandstone"},
        {pos: [4, 3, 7], state: "minecraft:smooth_red_sandstone"},
        {pos: [4, 3, 8], state: "minecraft:smooth_red_sandstone"},
        {pos: [4, 3, 9], state: "minecraft:red_terracotta"},
        {pos: [4, 3, 10], state: "minecraft:red_terracotta"},
        {pos: [4, 3, 11], state: "minecraft:red_terracotta"},
        {pos: [5, 3, 3], state: "minecraft:red_sand"},
        {pos: [5, 3, 4], state: "minecraft:red_terracotta"},
        {pos: [5, 3, 5], state: "minecraft:red_terracotta"},
        {pos: [5, 3, 6], state: "minecraft:smooth_red_sandstone"},
        {pos: [5, 3, 7], state: "minecraft:smooth_red_sandstone"},
        {pos: [5, 3, 8], state: "minecraft:smooth_red_sandstone"},
        {pos: [5, 3, 9], state: "minecraft:red_terracotta"},
        {pos: [5, 3, 10], state: "minecraft:red_terracotta"},
        {pos: [5, 3, 11], state: "minecraft:red_terracotta"},
        {pos: [6, 3, 3], state: "minecraft:red_terracotta"},
        {pos: [6, 3, 4], state: "minecraft:red_terracotta"},
        {pos: [6, 3, 5], state: "minecraft:red_terracotta"},
        {pos: [6, 3, 6], state: "minecraft:red_terracotta"},
        {pos: [6, 3, 7], state: "minecraft:red_terracotta"},
        {pos: [6, 3, 8], state: "minecraft:red_terracotta"},
        {pos: [6, 3, 9], state: "minecraft:red_terracotta"},
        {pos: [6, 3, 10], state: "minecraft:red_terracotta"},
        {pos: [6, 3, 11], state: "minecraft:red_terracotta"},
        {pos: [7, 3, 3], state: "minecraft:red_terracotta"},
        {pos: [7, 3, 4], state: "minecraft:red_sand"},
        {pos: [7, 3, 5], state: "minecraft:red_sand"},
        {pos: [7, 3, 6], state: "minecraft:red_sand"},
        {pos: [7, 3, 7], state: "minecraft:red_sand"},
        {pos: [7, 3, 8], state: "minecraft:red_sand"},
        {pos: [7, 3, 9], state: "minecraft:red_sand"},
        {pos: [7, 3, 10], state: "minecraft:red_sand"},
        {pos: [7, 3, 11], state: "minecraft:red_terracotta"},
        {pos: [8, 3, 3], state: "minecraft:red_terracotta"},
        {pos: [8, 3, 4], state: "minecraft:red_sand"},
        {pos: [8, 3, 5], state: "minecraft:red_sand"},
        {pos: [8, 3, 6], state: "minecraft:red_sand"},
        {pos: [8, 3, 7], state: "minecraft:red_sand"},
        {pos: [8, 3, 8], state: "minecraft:red_sand"},
        {pos: [8, 3, 9], state: "minecraft:red_sand"},
        {pos: [8, 3, 10], state: "minecraft:red_sand"},
        {pos: [8, 3, 11], state: "minecraft:red_terracotta"},
        {pos: [9, 3, 0], state: "minecraft:red_terracotta"},
        {pos: [9, 3, 1], state: "minecraft:red_terracotta"},
        {pos: [9, 3, 2], state: "minecraft:red_terracotta"},
        {pos: [9, 3, 3], state: "minecraft:red_terracotta"},
        {pos: [9, 3, 4], state: "minecraft:red_sand"},
        {pos: [9, 3, 5], state: "minecraft:red_sand"},
        {pos: [9, 3, 6], state: "minecraft:red_sand"},
        {pos: [9, 3, 7], state: "minecraft:red_sand"},
        {pos: [9, 3, 8], state: "minecraft:red_sand"},
        {pos: [9, 3, 9], state: "minecraft:red_sand"},
        {pos: [9, 3, 10], state: "minecraft:red_sand"},
        {pos: [9, 3, 11], state: "minecraft:red_terracotta"},
        {pos: [10, 3, 0], state: "minecraft:red_terracotta"},
        {pos: [10, 3, 1], state: "minecraft:red_sand"},
        {pos: [10, 3, 2], state: "minecraft:red_sand"},
        {pos: [10, 3, 3], state: "minecraft:red_sand"},
        {pos: [10, 3, 4], state: "minecraft:red_sand"},
        {pos: [10, 3, 5], state: "minecraft:red_sand"},
        {pos: [10, 3, 6], state: "minecraft:red_sand"},
        {pos: [10, 3, 7], state: "minecraft:red_terracotta"},
        {pos: [10, 3, 8], state: "minecraft:red_terracotta"},
        {pos: [10, 3, 9], state: "minecraft:red_terracotta"},
        {pos: [10, 3, 10], state: "minecraft:red_terracotta"},
        {pos: [10, 3, 11], state: "minecraft:red_terracotta"},
        {pos: [11, 3, 0], state: "minecraft:red_terracotta"},
        {pos: [11, 3, 1], state: "minecraft:red_sand"},
        {pos: [11, 3, 2], state: "minecraft:red_sand"},
        {pos: [11, 3, 3], state: "minecraft:red_sand"},
        {pos: [11, 3, 4], state: "minecraft:red_sand"},
        {pos: [11, 3, 5], state: "minecraft:red_sand"},
        {pos: [11, 3, 6], state: "minecraft:red_sand"},
        {pos: [11, 3, 7], state: "minecraft:red_terracotta"},
        {pos: [11, 3, 8], state: "minecraft:red_terracotta"},
        {pos: [11, 3, 9], state: "minecraft:red_terracotta"},
        {pos: [11, 3, 10], state: "minecraft:red_terracotta"},
        {pos: [11, 3, 11], state: "minecraft:red_terracotta"},
        {pos: [12, 3, 0], state: "minecraft:red_terracotta"},
        {pos: [12, 3, 1], state: "minecraft:red_sand"},
        {pos: [12, 3, 2], state: "minecraft:red_sand"},
        {pos: [12, 3, 3], state: "minecraft:red_sand"},
        {pos: [12, 3, 4], state: "minecraft:red_sand"},
        {pos: [12, 3, 5], state: "minecraft:red_sand"},
        {pos: [12, 3, 6], state: "minecraft:red_sand"},
        {pos: [12, 3, 7], state: "minecraft:red_terracotta"},
        {pos: [13, 3, 0], state: "minecraft:red_terracotta"},
        {pos: [13, 3, 1], state: "minecraft:red_sand"},
        {pos: [13, 3, 2], state: "minecraft:red_sand"},
        {pos: [13, 3, 3], state: "minecraft:red_sand"},
        {pos: [13, 3, 4], state: "minecraft:red_sand"},
        {pos: [13, 3, 5], state: "minecraft:red_sand"},
        {pos: [13, 3, 6], state: "minecraft:red_sand"},
        {pos: [13, 3, 7], state: "minecraft:red_terracotta"},
        {pos: [14, 3, 0], state: "minecraft:red_terracotta"},
        {pos: [14, 3, 1], state: "minecraft:red_sand"},
        {pos: [14, 3, 2], state: "minecraft:red_sand"},
        {pos: [14, 3, 3], state: "minecraft:red_sand"},
        {pos: [14, 3, 4], state: "minecraft:red_sand"},
        {pos: [14, 3, 5], state: "minecraft:red_sand"},
        {pos: [14, 3, 6], state: "minecraft:red_sand"},
        {pos: [14, 3, 7], state: "minecraft:red_terracotta"},
        {pos: [15, 3, 0], state: "minecraft:red_terracotta"},
        {pos: [15, 3, 1], state: "minecraft:red_terracotta"},
        {pos: [15, 3, 2], state: "minecraft:red_terracotta"},
        {pos: [15, 3, 3], state: "minecraft:red_terracotta"},
        {pos: [15, 3, 4], state: "minecraft:red_terracotta"},
        {pos: [15, 3, 5], state: "minecraft:red_terracotta"},
        {pos: [15, 3, 6], state: "minecraft:red_terracotta"},
        {pos: [15, 3, 7], state: "minecraft:red_terracotta"},
        {pos: [16, 3, 0], state: "minecraft:red_sand"},
        {pos: [16, 3, 1], state: "minecraft:red_terracotta"},
        {pos: [16, 3, 2], state: "minecraft:red_terracotta"},
        {pos: [16, 3, 3], state: "minecraft:smooth_red_sandstone"},
        {pos: [16, 3, 4], state: "minecraft:smooth_red_sandstone"},
        {pos: [16, 3, 5], state: "minecraft:smooth_red_sandstone"},
        {pos: [16, 3, 6], state: "minecraft:red_terracotta"},
        {pos: [16, 3, 7], state: "minecraft:red_terracotta"},
        {pos: [17, 3, 0], state: "minecraft:red_sand"},
        {pos: [17, 3, 1], state: "minecraft:red_terracotta"},
        {pos: [17, 3, 2], state: "minecraft:red_terracotta"},
        {pos: [17, 3, 3], state: "minecraft:smooth_red_sandstone"},
        {pos: [17, 3, 4], state: "minecraft:smooth_red_sandstone"},
        {pos: [17, 3, 5], state: "minecraft:smooth_red_sandstone"},
        {pos: [17, 3, 6], state: "minecraft:red_terracotta"},
        {pos: [17, 3, 7], state: "minecraft:red_terracotta"},
        {pos: [18, 3, 0], state: "minecraft:red_sand"},
        {pos: [18, 3, 1], state: "minecraft:red_terracotta"},
        {pos: [18, 3, 2], state: "minecraft:red_terracotta"},
        {pos: [18, 3, 3], state: "minecraft:red_sandstone_stairs{facing:west,half:bottom,shape:straight,waterlogged:false}"},
        {pos: [18, 3, 4], state: "minecraft:red_sandstone_stairs{facing:west,half:bottom,shape:straight,waterlogged:false}"},
        {pos: [18, 3, 5], state: "minecraft:red_sand"},
        {pos: [18, 3, 6], state: "minecraft:red_terracotta"},
        {pos: [18, 3, 7], state: "minecraft:red_terracotta"},
        {pos: [19, 3, 1], state: "minecraft:red_sand"},
        {pos: [19, 3, 2], state: "minecraft:red_sand"},
        {pos: [19, 3, 3], state: "minecraft:red_sand"},
        {pos: [19, 3, 4], state: "minecraft:red_sand"},
        {pos: [19, 3, 5], state: "minecraft:red_sand"},
        {pos: [19, 3, 6], state: "minecraft:smooth_red_sandstone"},
        {pos: [19, 3, 7], state: "minecraft:smooth_red_sandstone"},
        {pos: [20, 3, 1], state: "minecraft:red_sand"},
        {pos: [20, 3, 2], state: "minecraft:red_sand"},
        {pos: [20, 3, 3], state: "minecraft:red_sand"},
        {pos: [20, 3, 4], state: "minecraft:red_sand"},
        {pos: [20, 3, 5], state: "minecraft:red_sand"},
        {pos: [20, 3, 6], state: "minecraft:smooth_red_sandstone"},
        {pos: [20, 3, 7], state: "minecraft:smooth_red_sandstone"},
        {pos: [21, 3, 1], state: "minecraft:red_sand"},
        {pos: [21, 3, 2], state: "minecraft:red_sand"},
        {pos: [21, 3, 3], state: "minecraft:red_sand"},
        {pos: [21, 3, 4], state: "minecraft:red_sand"},
        {pos: [21, 3, 5], state: "minecraft:red_sand"},
        {pos: [21, 3, 6], state: "minecraft:cut_red_sandstone"},
        {pos: [21, 3, 7], state: "minecraft:cut_red_sandstone"},
        {pos: [0, 4, 4], state: "minecraft:red_sand"},
        {pos: [0, 4, 5], state: "minecraft:red_sand"},
        {pos: [0, 4, 6], state: "minecraft:red_sand"},
        {pos: [0, 4, 7], state: "minecraft:red_sand"},
        {pos: [0, 4, 8], state: "minecraft:red_sand"},
        {pos: [0, 4, 9], state: "minecraft:red_sand"},
        {pos: [0, 4, 10], state: "minecraft:red_sand"},
        {pos: [1, 4, 4], state: "minecraft:red_sand"},
        {pos: [1, 4, 5], state: "minecraft:red_sand"},
        {pos: [1, 4, 6], state: "minecraft:red_sand"},
        {pos: [1, 4, 7], state: "minecraft:red_sand"},
        {pos: [1, 4, 8], state: "minecraft:red_sand"},
        {pos: [1, 4, 9], state: "minecraft:cut_red_sandstone"},
        {pos: [1, 4, 10], state: "minecraft:cut_red_sandstone"},
        {pos: [2, 4, 4], state: "minecraft:red_sand"},
        {pos: [2, 4, 5], state: "minecraft:red_sand"},
        {pos: [2, 4, 6], state: "minecraft:red_sand"},
        {pos: [2, 4, 7], state: "minecraft:red_sand"},
        {pos: [2, 4, 8], state: "minecraft:red_sand"},
        {pos: [2, 4, 9], state: "minecraft:smooth_red_sandstone"},
        {pos: [2, 4, 10], state: "minecraft:smooth_red_sandstone"},
        {pos: [3, 4, 3], state: "minecraft:red_sand"},
        {pos: [3, 4, 4], state: "minecraft:smooth_red_sandstone"},
        {pos: [3, 4, 5], state: "minecraft:red_sand"},
        {pos: [3, 4, 6], state: "minecraft:red_sand"},
        {pos: [3, 4, 7], state: "minecraft:red_sand"},
        {pos: [3, 4, 8], state: "minecraft:red_sand"},
        {pos: [3, 4, 9], state: "minecraft:smooth_red_sandstone"},
        {pos: [3, 4, 10], state: "minecraft:smooth_red_sandstone"},
        {pos: [4, 4, 3], state: "minecraft:red_sand"},
        {pos: [4, 4, 4], state: "minecraft:smooth_red_sandstone"},
        {pos: [4, 4, 5], state: "minecraft:smooth_red_sandstone"},
        {pos: [4, 4, 6], state: "minecraft:red_sandstone_stairs{facing:east,half:bottom,shape:straight,waterlogged:false}"},
        {pos: [4, 4, 7], state: "minecraft:red_sandstone_stairs{facing:east,half:bottom,shape:straight,waterlogged:false}"},
        {pos: [4, 4, 8], state: "minecraft:red_sandstone_stairs{facing:east,half:bottom,shape:straight,waterlogged:false}"},
        {pos: [4, 4, 9], state: "minecraft:smooth_red_sandstone"},
        {pos: [4, 4, 10], state: "minecraft:smooth_red_sandstone"},
        {pos: [4, 4, 11], state: "minecraft:smooth_red_sandstone"},
        {pos: [5, 4, 3], state: "minecraft:red_sand"},
        {pos: [5, 4, 4], state: "minecraft:smooth_red_sandstone"},
        {pos: [5, 4, 5], state: "minecraft:smooth_red_sandstone"},
        {pos: [5, 4, 6], state: "minecraft:smooth_red_sandstone"},
        {pos: [5, 4, 7], state: "minecraft:smooth_red_sandstone"},
        {pos: [5, 4, 8], state: "minecraft:smooth_red_sandstone"},
        {pos: [5, 4, 9], state: "minecraft:smooth_red_sandstone"},
        {pos: [5, 4, 10], state: "minecraft:smooth_red_sandstone"},
        {pos: [5, 4, 11], state: "minecraft:smooth_red_sandstone"},
        {pos: [6, 4, 3], state: "minecraft:smooth_red_sandstone"},
        {pos: [6, 4, 4], state: "minecraft:smooth_red_sandstone"},
        {pos: [6, 4, 5], state: "minecraft:smooth_red_sandstone"},
        {pos: [6, 4, 6], state: "minecraft:smooth_red_sandstone"},
        {pos: [6, 4, 7], state: "minecraft:smooth_red_sandstone"},
        {pos: [6, 4, 8], state: "minecraft:smooth_red_sandstone"},
        {pos: [6, 4, 9], state: "minecraft:smooth_red_sandstone"},
        {pos: [6, 4, 10], state: "minecraft:smooth_red_sandstone"},
        {pos: [6, 4, 11], state: "minecraft:smooth_red_sandstone"},
        {pos: [7, 4, 3], state: "minecraft:smooth_red_sandstone"},
        {pos: [7, 4, 4], state: "minecraft:smooth_red_sandstone"},
        {pos: [7, 4, 5], state: "minecraft:smooth_red_sandstone"},
        {pos: [7, 4, 6], state: "minecraft:smooth_red_sandstone"},
        {pos: [7, 4, 7], state: "minecraft:smooth_red_sandstone"},
        {pos: [7, 4, 8], state: "minecraft:smooth_red_sandstone"},
        {pos: [7, 4, 9], state: "minecraft:smooth_red_sandstone"},
        {pos: [7, 4, 10], state: "minecraft:smooth_red_sandstone"},
        {pos: [7, 4, 11], state: "minecraft:smooth_red_sandstone"},
        {pos: [8, 4, 3], state: "minecraft:smooth_red_sandstone"},
        {pos: [8, 4, 4], state: "minecraft:smooth_red_sandstone"},
        {pos: [8, 4, 5], state: "minecraft:smooth_red_sandstone"},
        {pos: [8, 4, 6], state: "minecraft:smooth_red_sandstone"},
        {pos: [8, 4, 7], state: "minecraft:smooth_red_sandstone"},
        {pos: [8, 4, 8], state: "minecraft:smooth_red_sandstone"},
        {pos: [8, 4, 9], state: "minecraft:smooth_red_sandstone"},
        {pos: [8, 4, 10], state: "minecraft:smooth_red_sandstone"},
        {pos: [8, 4, 11], state: "minecraft:smooth_red_sandstone"},
        {pos: [9, 4, 1], state: "minecraft:smooth_red_sandstone"},
        {pos: [9, 4, 2], state: "minecraft:smooth_red_sandstone"},
        {pos: [9, 4, 3], state: "minecraft:smooth_red_sandstone"},
        {pos: [9, 4, 4], state: "minecraft:smooth_red_sandstone"},
        {pos: [9, 4, 5], state: "minecraft:smooth_red_sandstone"},
        {pos: [9, 4, 6], state: "minecraft:smooth_red_sandstone"},
        {pos: [9, 4, 7], state: "minecraft:smooth_red_sandstone"},
        {pos: [9, 4, 8], state: "minecraft:smooth_red_sandstone"},
        {pos: [9, 4, 9], state: "minecraft:smooth_red_sandstone"},
        {pos: [9, 4, 10], state: "minecraft:smooth_red_sandstone"},
        {pos: [9, 4, 11], state: "minecraft:smooth_red_sandstone"},
        {pos: [10, 4, 0], state: "minecraft:smooth_red_sandstone"},
        {pos: [10, 4, 1], state: "minecraft:smooth_red_sandstone"},
        {pos: [10, 4, 2], state: "minecraft:smooth_red_sandstone"},
        {pos: [10, 4, 3], state: "minecraft:smooth_red_sandstone"},
        {pos: [10, 4, 4], state: "minecraft:smooth_red_sandstone"},
        {pos: [10, 4, 5], state: "minecraft:smooth_red_sandstone"},
        {pos: [10, 4, 6], state: "minecraft:smooth_red_sandstone"},
        {pos: [10, 4, 7], state: "minecraft:smooth_red_sandstone"},
        {pos: [10, 4, 8], state: "minecraft:smooth_red_sandstone"},
        {pos: [10, 4, 9], state: "minecraft:smooth_red_sandstone"},
        {pos: [10, 4, 10], state: "minecraft:smooth_red_sandstone"},
        {pos: [10, 4, 11], state: "minecraft:smooth_red_sandstone"},
        {pos: [11, 4, 0], state: "minecraft:smooth_red_sandstone"},
        {pos: [11, 4, 1], state: "minecraft:smooth_red_sandstone"},
        {pos: [11, 4, 2], state: "minecraft:smooth_red_sandstone"},
        {pos: [11, 4, 3], state: "minecraft:smooth_red_sandstone"},
        {pos: [11, 4, 4], state: "minecraft:smooth_red_sandstone"},
        {pos: [11, 4, 5], state: "minecraft:smooth_red_sandstone"},
        {pos: [11, 4, 6], state: "minecraft:smooth_red_sandstone"},
        {pos: [11, 4, 7], state: "minecraft:smooth_red_sandstone"},
        {pos: [11, 4, 8], state: "minecraft:smooth_red_sandstone"},
        {pos: [11, 4, 9], state: "minecraft:smooth_red_sandstone"},
        {pos: [11, 4, 10], state: "minecraft:smooth_red_sandstone"},
        {pos: [12, 4, 0], state: "minecraft:smooth_red_sandstone"},
        {pos: [12, 4, 1], state: "minecraft:smooth_red_sandstone"},
        {pos: [12, 4, 2], state: "minecraft:smooth_red_sandstone"},
        {pos: [12, 4, 3], state: "minecraft:smooth_red_sandstone"},
        {pos: [12, 4, 4], state: "minecraft:smooth_red_sandstone"},
        {pos: [12, 4, 5], state: "minecraft:smooth_red_sandstone"},
        {pos: [12, 4, 6], state: "minecraft:smooth_red_sandstone"},
        {pos: [12, 4, 7], state: "minecraft:smooth_red_sandstone"},
        {pos: [13, 4, 0], state: "minecraft:smooth_red_sandstone"},
        {pos: [13, 4, 1], state: "minecraft:smooth_red_sandstone"},
        {pos: [13, 4, 2], state: "minecraft:smooth_red_sandstone"},
        {pos: [13, 4, 3], state: "minecraft:smooth_red_sandstone"},
        {pos: [13, 4, 4], state: "minecraft:smooth_red_sandstone"},
        {pos: [13, 4, 5], state: "minecraft:smooth_red_sandstone"},
        {pos: [13, 4, 6], state: "minecraft:smooth_red_sandstone"},
        {pos: [13, 4, 7], state: "minecraft:smooth_red_sandstone"},
        {pos: [14, 4, 0], state: "minecraft:smooth_red_sandstone"},
        {pos: [14, 4, 1], state: "minecraft:smooth_red_sandstone"},
        {pos: [14, 4, 2], state: "minecraft:smooth_red_sandstone"},
        {pos: [14, 4, 3], state: "minecraft:smooth_red_sandstone"},
        {pos: [14, 4, 4], state: "minecraft:smooth_red_sandstone"},
        {pos: [14, 4, 5], state: "minecraft:smooth_red_sandstone"},
        {pos: [14, 4, 6], state: "minecraft:smooth_red_sandstone"},
        {pos: [14, 4, 7], state: "minecraft:smooth_red_sandstone"},
        {pos: [15, 4, 0], state: "minecraft:smooth_red_sandstone"},
        {pos: [15, 4, 1], state: "minecraft:smooth_red_sandstone"},
        {pos: [15, 4, 2], state: "minecraft:smooth_red_sandstone"},
        {pos: [15, 4, 3], state: "minecraft:smooth_red_sandstone"},
        {pos: [15, 4, 4], state: "minecraft:smooth_red_sandstone"},
        {pos: [15, 4, 5], state: "minecraft:smooth_red_sandstone"},
        {pos: [15, 4, 6], state: "minecraft:smooth_red_sandstone"},
        {pos: [15, 4, 7], state: "minecraft:smooth_red_sandstone"},
        {pos: [16, 4, 0], state: "minecraft:red_sand"},
        {pos: [16, 4, 1], state: "minecraft:smooth_red_sandstone"},
        {pos: [16, 4, 2], state: "minecraft:smooth_red_sandstone"},
        {pos: [16, 4, 3], state: "minecraft:smooth_red_sandstone"},
        {pos: [16, 4, 4], state: "minecraft:smooth_red_sandstone"},
        {pos: [16, 4, 5], state: "minecraft:smooth_red_sandstone"},
        {pos: [16, 4, 6], state: "minecraft:smooth_red_sandstone"},
        {pos: [17, 4, 0], state: "minecraft:red_sand"},
        {pos: [17, 4, 1], state: "minecraft:smooth_red_sandstone"},
        {pos: [17, 4, 2], state: "minecraft:smooth_red_sandstone"},
        {pos: [17, 4, 3], state: "minecraft:red_sandstone_stairs{facing:west,half:bottom,shape:straight,waterlogged:false}"},
        {pos: [17, 4, 4], state: "minecraft:red_sandstone_stairs{facing:west,half:bottom,shape:straight,waterlogged:false}"},
        {pos: [17, 4, 5], state: "minecraft:red_sandstone_stairs{facing:west,half:bottom,shape:straight,waterlogged:false}"},
        {pos: [17, 4, 6], state: "minecraft:smooth_red_sandstone"},
        {pos: [17, 4, 7], state: "minecraft:smooth_red_sandstone"},
        {pos: [18, 4, 0], state: "minecraft:red_sand"},
        {pos: [18, 4, 1], state: "minecraft:smooth_red_sandstone"},
        {pos: [18, 4, 2], state: "minecraft:smooth_red_sandstone"},
        {pos: [18, 4, 3], state: "minecraft:red_sand"},
        {pos: [18, 4, 4], state: "minecraft:red_sand"},
        {pos: [18, 4, 5], state: "minecraft:red_sand"},
        {pos: [18, 4, 6], state: "minecraft:smooth_red_sandstone"},
        {pos: [18, 4, 7], state: "minecraft:smooth_red_sandstone"},
        {pos: [19, 4, 1], state: "minecraft:red_sand"},
        {pos: [19, 4, 2], state: "minecraft:red_sand"},
        {pos: [19, 4, 3], state: "minecraft:red_sand"},
        {pos: [19, 4, 4], state: "minecraft:red_sand"},
        {pos: [19, 4, 5], state: "minecraft:red_sand"},
        {pos: [19, 4, 6], state: "minecraft:smooth_red_sandstone"},
        {pos: [19, 4, 7], state: "minecraft:smooth_red_sandstone"},
        {pos: [20, 4, 1], state: "minecraft:red_sand"},
        {pos: [20, 4, 2], state: "minecraft:red_sand"},
        {pos: [20, 4, 3], state: "minecraft:red_sand"},
        {pos: [20, 4, 4], state: "minecraft:red_sand"},
        {pos: [20, 4, 5], state: "minecraft:red_sand"},
        {pos: [20, 4, 6], state: "minecraft:cut_red_sandstone"},
        {pos: [20, 4, 7], state: "minecraft:cut_red_sandstone"},
        {pos: [21, 4, 1], state: "minecraft:red_sand"},
        {pos: [21, 4, 2], state: "minecraft:red_sand"},
        {pos: [21, 4, 3], state: "minecraft:red_sand"},
        {pos: [21, 4, 4], state: "minecraft:red_sand"},
        {pos: [21, 4, 5], state: "minecraft:red_sand"},
        {pos: [21, 4, 6], state: "minecraft:red_sand"},
        {pos: [21, 4, 7], state: "minecraft:red_sand"},
        {pos: [0, 5, 5], state: "minecraft:red_sand"},
        {pos: [0, 5, 6], state: "minecraft:red_sand"},
        {pos: [0, 5, 7], state: "minecraft:red_sand"},
        {pos: [0, 5, 8], state: "minecraft:red_sand"},
        {pos: [0, 5, 9], state: "minecraft:red_sand"},
        {pos: [0, 5, 10], state: "minecraft:red_sand"},
        {pos: [1, 5, 4], state: "minecraft:red_sand"},
        {pos: [1, 5, 5], state: "minecraft:red_sand"},
        {pos: [1, 5, 6], state: "minecraft:red_sand"},
        {pos: [1, 5, 7], state: "minecraft:red_sand"},
        {pos: [1, 5, 8], state: "minecraft:red_sand"},
        {pos: [1, 5, 9], state: "minecraft:red_sand"},
        {pos: [1, 5, 10], state: "minecraft:red_sand"},
        {pos: [2, 5, 4], state: "minecraft:red_sand"},
        {pos: [2, 5, 5], state: "minecraft:red_sand"},
        {pos: [2, 5, 6], state: "minecraft:red_sand"},
        {pos: [2, 5, 7], state: "minecraft:red_sand"},
        {pos: [2, 5, 8], state: "minecraft:red_sand"},
        {pos: [2, 5, 9], state: "minecraft:cut_red_sandstone"},
        {pos: [2, 5, 10], state: "minecraft:cut_red_sandstone"},
        {pos: [3, 5, 4], state: "minecraft:cut_red_sandstone"},
        {pos: [3, 5, 5], state: "minecraft:red_sand"},
        {pos: [3, 5, 6], state: "minecraft:red_sand"},
        {pos: [3, 5, 7], state: "minecraft:red_sand"},
        {pos: [3, 5, 8], state: "minecraft:red_sand"},
        {pos: [3, 5, 9], state: "minecraft:cut_red_sandstone"},
        {pos: [3, 5, 10], state: "minecraft:red_sand"},
        {pos: [4, 5, 3], state: "minecraft:red_sand"},
        {pos: [4, 5, 4], state: "minecraft:chiseled_red_sandstone"},
        {pos: [4, 5, 5], state: "minecraft:cut_red_sandstone"},
        {pos: [4, 5, 6], state: "minecraft:red_sand"},
        {pos: [4, 5, 7], state: "minecraft:red_sand"},
        {pos: [4, 5, 8], state: "minecraft:red_sand"},
        {pos: [4, 5, 9], state: "minecraft:cut_red_sandstone"},
        {pos: [4, 5, 10], state: "minecraft:cut_red_sandstone"},
        {pos: [5, 5, 3], state: "minecraft:red_sand"},
        {pos: [5, 5, 4], state: "minecraft:cut_red_sandstone"},
        {pos: [5, 5, 5], state: "minecraft:red_sand"},
        {pos: [5, 5, 6], state: "minecraft:red_sand"},
        {pos: [5, 5, 7], state: "minecraft:red_sand"},
        {pos: [5, 5, 8], state: "minecraft:red_sand"},
        {pos: [5, 5, 9], state: "minecraft:cut_red_sandstone"},
        {pos: [5, 5, 10], state: "minecraft:cut_red_sandstone"},
        {pos: [5, 5, 11], state: "minecraft:red_sand"},
        {pos: [6, 5, 3], state: "minecraft:cut_red_sandstone"},
        {pos: [6, 5, 4], state: "minecraft:cut_red_sandstone"},
        {pos: [6, 5, 5], state: "minecraft:cut_red_sandstone"},
        {pos: [6, 5, 6], state: "minecraft:red_sand"},
        {pos: [6, 5, 7], state: "minecraft:red_sand"},
        {pos: [6, 5, 8], state: "minecraft:red_sand"},
        {pos: [6, 5, 9], state: "minecraft:cut_red_sandstone"},
        {pos: [6, 5, 10], state: "minecraft:cut_red_sandstone"},
        {pos: [6, 5, 11], state: "minecraft:cut_red_sandstone"},
        {pos: [7, 5, 3], state: "minecraft:chiseled_red_sandstone"},
        {pos: [7, 5, 4], state: "minecraft:red_sand"},
        {pos: [7, 5, 5], state: "minecraft:red_sand"},
        {pos: [7, 5, 6], state: "minecraft:red_sand"},
        {pos: [7, 5, 7], state: "minecraft:red_sand"},
        {pos: [7, 5, 8], state: "minecraft:red_sand"},
        {pos: [7, 5, 9], state: "minecraft:red_sand"},
        {pos: [7, 5, 10], state: "minecraft:red_sand"},
        {pos: [7, 5, 11], state: "minecraft:cut_red_sandstone"},
        {pos: [8, 5, 3], state: "minecraft:cut_red_sandstone"},
        {pos: [8, 5, 4], state: "minecraft:red_sand"},
        {pos: [8, 5, 5], state: "minecraft:red_sand"},
        {pos: [8, 5, 6], state: "minecraft:red_sand"},
        {pos: [8, 5, 7], state: "minecraft:red_sand"},
        {pos: [8, 5, 8], state: "minecraft:red_sand"},
        {pos: [8, 5, 9], state: "minecraft:red_sand"},
        {pos: [8, 5, 10], state: "minecraft:red_sand"},
        {pos: [8, 5, 11], state: "minecraft:cut_red_sandstone"},
        {pos: [9, 5, 1], state: "minecraft:chiseled_red_sandstone"},
        {pos: [9, 5, 2], state: "minecraft:cut_red_sandstone"},
        {pos: [9, 5, 3], state: "minecraft:cut_red_sandstone"},
        {pos: [9, 5, 4], state: "minecraft:red_sand"},
        {pos: [9, 5, 5], state: "minecraft:red_sand"},
        {pos: [9, 5, 6], state: "minecraft:red_sand"},
        {pos: [9, 5, 7], state: "minecraft:red_sand"},
        {pos: [9, 5, 8], state: "minecraft:red_sand"},
        {pos: [9, 5, 9], state: "minecraft:red_sand"},
        {pos: [9, 5, 10], state: "minecraft:red_sand"},
        {pos: [9, 5, 11], state: "minecraft:cut_red_sandstone"},
        {pos: [10, 5, 0], state: "minecraft:cut_red_sandstone"},
        {pos: [10, 5, 1], state: "minecraft:red_sand"},
        {pos: [10, 5, 2], state: "minecraft:red_sand"},
        {pos: [10, 5, 3], state: "minecraft:red_sand"},
        {pos: [10, 5, 4], state: "minecraft:red_sand"},
        {pos: [10, 5, 5], state: "minecraft:red_sand"},
        {pos: [10, 5, 6], state: "minecraft:red_sand"},
        {pos: [10, 5, 7], state: "minecraft:red_sand"},
        {pos: [10, 5, 8], state: "minecraft:red_sand"},
        {pos: [10, 5, 9], state: "minecraft:red_sand"},
        {pos: [10, 5, 10], state: "minecraft:red_sand"},
        {pos: [11, 5, 0], state: "minecraft:cut_red_sandstone"},
        {pos: [11, 5, 5], state: "minecraft:red_sand"},
        {pos: [11, 5, 6], state: "minecraft:red_sand"},
        {pos: [11, 5, 7], state: "minecraft:cut_red_sandstone"},
        {pos: [11, 5, 8], state: "minecraft:cut_red_sandstone"},
        {pos: [11, 5, 9], state: "minecraft:cut_red_sandstone"},
        {pos: [11, 5, 10], state: "minecraft:cut_red_sandstone"},
        {pos: [12, 5, 0], state: "minecraft:chiseled_red_sandstone"},
        {pos: [12, 5, 1], state: "minecraft:red_sand"},
        {pos: [12, 5, 6], state: "minecraft:red_sand"},
        {pos: [12, 5, 7], state: "minecraft:cut_red_sandstone"},
        {pos: [13, 5, 0], state: "minecraft:cut_red_sandstone"},
        {pos: [13, 5, 1], state: "minecraft:red_sand"},
        {pos: [13, 5, 2], state: "minecraft:red_sand"},
        {pos: [13, 5, 7], state: "minecraft:cut_red_sandstone"},
        {pos: [14, 5, 0], state: "minecraft:cut_red_sandstone"},
        {pos: [14, 5, 1], state: "minecraft:red_sand"},
        {pos: [14, 5, 2], state: "minecraft:red_sand"},
        {pos: [14, 5, 3], state: "minecraft:red_sand"},
        {pos: [14, 5, 6], state: "minecraft:red_sand"},
        {pos: [14, 5, 7], state: "minecraft:cut_red_sandstone"},
        {pos: [15, 5, 0], state: "minecraft:red_sand"},
        {pos: [15, 5, 1], state: "minecraft:cut_red_sandstone"},
        {pos: [15, 5, 2], state: "minecraft:cut_red_sandstone"},
        {pos: [15, 5, 3], state: "minecraft:red_sand"},
        {pos: [15, 5, 5], state: "minecraft:red_sand"},
        {pos: [15, 5, 6], state: "minecraft:cut_red_sandstone"},
        {pos: [16, 5, 0], state: "minecraft:red_sand"},
        {pos: [16, 5, 1], state: "minecraft:cut_red_sandstone"},
        {pos: [16, 5, 2], state: "minecraft:cut_red_sandstone"},
        {pos: [16, 5, 3], state: "minecraft:red_sand"},
        {pos: [16, 5, 4], state: "minecraft:red_sand"},
        {pos: [16, 5, 6], state: "minecraft:cut_red_sandstone"},
        {pos: [17, 5, 0], state: "minecraft:red_sand"},
        {pos: [17, 5, 1], state: "minecraft:chiseled_red_sandstone"},
        {pos: [17, 5, 2], state: "minecraft:cut_red_sandstone"},
        {pos: [17, 5, 3], state: "minecraft:red_sand"},
        {pos: [17, 5, 4], state: "minecraft:red_sand"},
        {pos: [17, 5, 5], state: "minecraft:red_sand"},
        {pos: [17, 5, 6], state: "minecraft:cut_red_sandstone"},
        {pos: [17, 5, 7], state: "minecraft:cut_red_sandstone"},
        {pos: [18, 5, 0], state: "minecraft:red_sand"},
        {pos: [18, 5, 1], state: "minecraft:cut_red_sandstone"},
        {pos: [18, 5, 2], state: "minecraft:cut_red_sandstone"},
        {pos: [18, 5, 3], state: "minecraft:red_sand"},
        {pos: [18, 5, 4], state: "minecraft:red_sand"},
        {pos: [18, 5, 5], state: "minecraft:red_sand"},
        {pos: [18, 5, 6], state: "minecraft:cut_red_sandstone"},
        {pos: [18, 5, 7], state: "minecraft:cut_red_sandstone"},
        {pos: [19, 5, 1], state: "minecraft:red_sand"},
        {pos: [19, 5, 2], state: "minecraft:red_sand"},
        {pos: [19, 5, 3], state: "minecraft:red_sand"},
        {pos: [19, 5, 4], state: "minecraft:red_sand"},
        {pos: [19, 5, 5], state: "minecraft:red_sand"},
        {pos: [19, 5, 6], state: "minecraft:cut_red_sandstone"},
        {pos: [19, 5, 7], state: "minecraft:red_sand"},
        {pos: [20, 5, 1], state: "minecraft:red_sand"},
        {pos: [20, 5, 2], state: "minecraft:red_sand"},
        {pos: [20, 5, 3], state: "minecraft:red_sand"},
        {pos: [20, 5, 4], state: "minecraft:red_sand"},
        {pos: [20, 5, 5], state: "minecraft:red_sand"},
        {pos: [20, 5, 6], state: "minecraft:red_sand"},
        {pos: [20, 5, 7], state: "minecraft:red_sand"},
        {pos: [21, 5, 2], state: "minecraft:red_sand"},
        {pos: [21, 5, 3], state: "minecraft:red_sand"},
        {pos: [21, 5, 4], state: "minecraft:red_sand"},
        {pos: [21, 5, 5], state: "minecraft:red_sand"},
        {pos: [21, 5, 6], state: "minecraft:red_sand"},
        {pos: [21, 5, 7], state: "minecraft:red_sand"}
    ],
    entities: [],
    palette: [
        "minecraft:red_sandstone",
        "minecraft:yellow_glazed_terracotta{facing:north}",
        "minecraft:yellow_glazed_terracotta{facing:west}",
        "minecraft:yellow_glazed_terracotta{facing:east}",
        "minecraft:yellow_glazed_terracotta{facing:south}",
        "minecraft:red_sand",
        "minecraft:smooth_red_sandstone",
        "minecraft:red_terracotta",
        "minecraft:cut_red_sandstone",
        "minecraft:chiseled_red_sandstone",
        "minecraft:red_sandstone_stairs{facing:south,half:bottom,shape:straight,waterlogged:false}",
        "minecraft:red_sandstone_stairs{facing:south,half:top,shape:straight,waterlogged:false}",
        "minecraft:red_sandstone_stairs{facing:west,half:top,shape:straight,waterlogged:false}",
        "minecraft:red_sandstone_stairs{facing:east,half:top,shape:straight,waterlogged:false}",
        "minecraft:red_sandstone_stairs{facing:east,half:bottom,shape:straight,waterlogged:false}",
        "minecraft:red_sandstone_stairs{facing:west,half:bottom,shape:straight,waterlogged:false}",
        "minecraft:orange_bed{facing:south,occupied:false,part:foot}",
        "minecraft:orange_bed{facing:south,occupied:false,part:head}"
    ],
    trailiertales_DataVersion: 2
}
