{
    DataVersion: 3953,
    size: [15, 6, 20],
    data: [
        {pos: [0, 0, 16], state: "minecraft:cut_red_sandstone"},
        {pos: [0, 0, 17], state: "minecraft:cut_red_sandstone"},
        {pos: [0, 0, 18], state: "minecraft:cut_red_sandstone"},
        {pos: [0, 0, 19], state: "minecraft:cut_red_sandstone"},
        {pos: [1, 0, 15], state: "minecraft:cut_red_sandstone"},
        {pos: [1, 0, 16], state: "minecraft:cut_red_sandstone"},
        {pos: [1, 0, 17], state: "minecraft:cut_red_sandstone"},
        {pos: [1, 0, 18], state: "minecraft:cut_red_sandstone"},
        {pos: [1, 0, 19], state: "minecraft:cut_red_sandstone"},
        {pos: [2, 0, 15], state: "minecraft:cut_red_sandstone"},
        {pos: [2, 0, 16], state: "minecraft:yellow_glazed_terracotta{facing:north}"},
        {pos: [2, 0, 17], state: "minecraft:cut_red_sandstone"},
        {pos: [2, 0, 18], state: "minecraft:cut_red_sandstone"},
        {pos: [2, 0, 19], state: "minecraft:cut_red_sandstone"},
        {pos: [3, 0, 9], state: "minecraft:cut_red_sandstone"},
        {pos: [3, 0, 10], state: "minecraft:cut_red_sandstone"},
        {pos: [3, 0, 11], state: "minecraft:cut_red_sandstone"},
        {pos: [3, 0, 14], state: "minecraft:cut_red_sandstone"},
        {pos: [3, 0, 15], state: "minecraft:cut_red_sandstone"},
        {pos: [3, 0, 16], state: "minecraft:yellow_glazed_terracotta{facing:east}"},
        {pos: [3, 0, 17], state: "minecraft:yellow_glazed_terracotta{facing:south}"},
        {pos: [3, 0, 18], state: "minecraft:cut_red_sandstone"},
        {pos: [3, 0, 19], state: "minecraft:cut_red_sandstone"},
        {pos: [4, 0, 9], state: "minecraft:cut_red_sandstone"},
        {pos: [4, 0, 10], state: "minecraft:cut_red_sandstone"},
        {pos: [4, 0, 13], state: "minecraft:cut_red_sandstone"},
        {pos: [4, 0, 14], state: "minecraft:cut_red_sandstone"},
        {pos: [4, 0, 15], state: "minecraft:cut_red_sandstone"},
        {pos: [4, 0, 16], state: "minecraft:cut_red_sandstone"},
        {pos: [4, 0, 17], state: "minecraft:cut_red_sandstone"},
        {pos: [4, 0, 18], state: "minecraft:cut_red_sandstone"},
        {pos: [5, 0, 3], state: "minecraft:cut_red_sandstone"},
        {pos: [5, 0, 4], state: "minecraft:cut_red_sandstone"},
        {pos: [5, 0, 9], state: "minecraft:cut_red_sandstone"},
        {pos: [5, 0, 10], state: "minecraft:cut_red_sandstone"},
        {pos: [5, 0, 12], state: "minecraft:cut_red_sandstone"},
        {pos: [5, 0, 13], state: "minecraft:cut_red_sandstone"},
        {pos: [5, 0, 14], state: "minecraft:cut_red_sandstone"},
        {pos: [5, 0, 15], state: "minecraft:cut_red_sandstone"},
        {pos: [6, 0, 3], state: "minecraft:cut_red_sandstone"},
        {pos: [6, 0, 4], state: "minecraft:cut_red_sandstone"},
        {pos: [6, 0, 5], state: "minecraft:cut_red_sandstone"},
        {pos: [6, 0, 10], state: "minecraft:cut_red_sandstone"},
        {pos: [6, 0, 11], state: "minecraft:cut_red_sandstone"},
        {pos: [6, 0, 12], state: "minecraft:cut_red_sandstone"},
        {pos: [6, 0, 13], state: "minecraft:orange_glazed_terracotta{facing:north}"},
        {pos: [6, 0, 14], state: "minecraft:cut_red_sandstone"},
        {pos: [7, 0, 2], state: "minecraft:cut_red_sandstone"},
        {pos: [7, 0, 3], state: "minecraft:cut_red_sandstone"},
        {pos: [7, 0, 4], state: "minecraft:cut_red_sandstone"},
        {pos: [7, 0, 5], state: "minecraft:cut_red_sandstone"},
        {pos: [7, 0, 7], state: "minecraft:cut_red_sandstone"},
        {pos: [7, 0, 8], state: "minecraft:cut_red_sandstone"},
        {pos: [7, 0, 9], state: "minecraft:cut_red_sandstone"},
        {pos: [7, 0, 10], state: "minecraft:orange_glazed_terracotta{facing:north}"},
        {pos: [7, 0, 11], state: "minecraft:cut_red_sandstone"},
        {pos: [7, 0, 12], state: "minecraft:cut_red_sandstone"},
        {pos: [7, 0, 13], state: "minecraft:cut_red_sandstone"},
        {pos: [8, 0, 2], state: "minecraft:cut_red_sandstone"},
        {pos: [8, 0, 3], state: "minecraft:cut_red_sandstone"},
        {pos: [8, 0, 4], state: "minecraft:cut_red_sandstone"},
        {pos: [8, 0, 5], state: "minecraft:cut_red_sandstone"},
        {pos: [8, 0, 6], state: "minecraft:cut_red_sandstone"},
        {pos: [8, 0, 7], state: "minecraft:cut_red_sandstone"},
        {pos: [8, 0, 8], state: "minecraft:cut_red_sandstone"},
        {pos: [8, 0, 9], state: "minecraft:cut_red_sandstone"},
        {pos: [8, 0, 10], state: "minecraft:orange_glazed_terracotta{facing:east}"},
        {pos: [8, 0, 11], state: "minecraft:orange_glazed_terracotta{facing:south}"},
        {pos: [8, 0, 12], state: "minecraft:cut_red_sandstone"},
        {pos: [8, 0, 13], state: "minecraft:cut_red_sandstone"},
        {pos: [9, 0, 0], state: "minecraft:cut_red_sandstone"},
        {pos: [9, 0, 1], state: "minecraft:cut_red_sandstone"},
        {pos: [9, 0, 2], state: "minecraft:cut_red_sandstone"},
        {pos: [9, 0, 3], state: "minecraft:cut_red_sandstone"},
        {pos: [9, 0, 4], state: "minecraft:cut_red_sandstone"},
        {pos: [9, 0, 5], state: "minecraft:cut_red_sandstone"},
        {pos: [9, 0, 6], state: "minecraft:yellow_glazed_terracotta{facing:north}"},
        {pos: [9, 0, 7], state: "minecraft:cut_red_sandstone"},
        {pos: [9, 0, 8], state: "minecraft:cut_red_sandstone"},
        {pos: [9, 0, 9], state: "minecraft:cut_red_sandstone"},
        {pos: [9, 0, 10], state: "minecraft:cut_red_sandstone"},
        {pos: [9, 0, 11], state: "minecraft:cut_red_sandstone"},
        {pos: [9, 0, 12], state: "minecraft:cut_red_sandstone"},
        {pos: [9, 0, 13], state: "minecraft:cut_red_sandstone"},
        {pos: [9, 0, 14], state: "minecraft:cut_red_sandstone"},
        {pos: [10, 0, 0], state: "minecraft:cut_red_sandstone"},
        {pos: [10, 0, 1], state: "minecraft:cut_red_sandstone"},
        {pos: [10, 0, 2], state: "minecraft:cut_red_sandstone"},
        {pos: [10, 0, 3], state: "minecraft:cut_red_sandstone"},
        {pos: [10, 0, 4], state: "minecraft:cut_red_sandstone"},
        {pos: [10, 0, 5], state: "minecraft:cut_red_sandstone"},
        {pos: [10, 0, 6], state: "minecraft:cut_red_sandstone"},
        {pos: [10, 0, 7], state: "minecraft:cut_red_sandstone"},
        {pos: [10, 0, 8], state: "minecraft:cut_red_sandstone"},
        {pos: [10, 0, 11], state: "minecraft:cut_red_sandstone"},
        {pos: [10, 0, 12], state: "minecraft:cut_red_sandstone"},
        {pos: [10, 0, 13], state: "minecraft:cut_red_sandstone"},
        {pos: [10, 0, 14], state: "minecraft:cut_red_sandstone"},
        {pos: [11, 0, 0], state: "minecraft:cut_red_sandstone"},
        {pos: [11, 0, 1], state: "minecraft:cut_red_sandstone"},
        {pos: [11, 0, 2], state: "minecraft:cut_red_sandstone"},
        {pos: [11, 0, 3], state: "minecraft:cut_red_sandstone"},
        {pos: [11, 0, 4], state: "minecraft:cut_red_sandstone"},
        {pos: [11, 0, 5], state: "minecraft:cut_red_sandstone"},
        {pos: [11, 0, 8], state: "minecraft:cut_red_sandstone"},
        {pos: [11, 0, 9], state: "minecraft:cut_red_sandstone"},
        {pos: [11, 0, 10], state: "minecraft:cut_red_sandstone"},
        {pos: [11, 0, 12], state: "minecraft:cut_red_sandstone"},
        {pos: [11, 0, 13], state: "minecraft:cut_red_sandstone"},
        {pos: [12, 0, 0], state: "minecraft:cut_red_sandstone"},
        {pos: [12, 0, 1], state: "minecraft:cut_red_sandstone"},
        {pos: [12, 0, 2], state: "minecraft:cut_red_sandstone"},
        {pos: [12, 0, 4], state: "minecraft:cut_red_sandstone"},
        {pos: [12, 0, 5], state: "minecraft:cut_red_sandstone"},
        {pos: [12, 0, 8], state: "minecraft:cut_red_sandstone"},
        {pos: [12, 0, 9], state: "minecraft:cut_red_sandstone"},
        {pos: [12, 0, 10], state: "minecraft:cut_red_sandstone"},
        {pos: [13, 0, 1], state: "minecraft:cut_red_sandstone"},
        {pos: [13, 0, 2], state: "minecraft:cut_red_sandstone"},
        {pos: [13, 0, 8], state: "minecraft:cut_red_sandstone"},
        {pos: [13, 0, 9], state: "minecraft:cut_red_sandstone"},
        {pos: [13, 0, 10], state: "minecraft:cut_red_sandstone"},
        {pos: [14, 0, 8], state: "minecraft:cut_red_sandstone"},
        {pos: [14, 0, 9], state: "minecraft:cut_red_sandstone"},
        {pos: [0, 1, 16], state: "minecraft:cut_red_sandstone"},
        {pos: [0, 1, 17], state: "minecraft:cut_red_sandstone"},
        {pos: [0, 1, 18], state: "minecraft:cut_red_sandstone"},
        {pos: [0, 1, 19], state: "minecraft:cut_red_sandstone"},
        {pos: [1, 1, 15], state: "minecraft:cut_red_sandstone"},
        {pos: [1, 1, 16], state: "minecraft:red_sand"},
        {pos: [1, 1, 17], state: "minecraft:red_sand"},
        {pos: [1, 1, 18], state: "minecraft:cut_red_sandstone"},
        {pos: [1, 1, 19], state: "minecraft:cut_red_sandstone"},
        {pos: [2, 1, 15], state: "minecraft:red_sand"},
        {pos: [2, 1, 16], state: "minecraft:red_sand"},
        {pos: [2, 1, 17], state: "minecraft:red_sand"},
        {pos: [2, 1, 18], state: "minecraft:red_sand"},
        {pos: [2, 1, 19], state: "minecraft:cut_red_sandstone"},
        {pos: [3, 1, 9], state: "minecraft:cut_red_sandstone"},
        {pos: [3, 1, 10], state: "minecraft:cut_red_sandstone"},
        {pos: [3, 1, 11], state: "minecraft:red_sand"},
        {pos: [3, 1, 14], state: "minecraft:cut_red_sandstone"},
        {pos: [3, 1, 15], state: "minecraft:red_sand"},
        {pos: [3, 1, 16], state: "minecraft:red_sand"},
        {pos: [3, 1, 17], state: "minecraft:red_sand"},
        {pos: [3, 1, 18], state: "minecraft:red_sand"},
        {pos: [3, 1, 19], state: "minecraft:red_sand"},
        {pos: [4, 1, 9], state: "minecraft:cut_red_sandstone"},
        {pos: [4, 1, 10], state: "minecraft:cut_red_sandstone"},
        {pos: [4, 1, 13], state: "minecraft:red_sand"},
        {pos: [4, 1, 14], state: "minecraft:red_sand"},
        {pos: [4, 1, 15], state: "minecraft:red_sand"},
        {pos: [4, 1, 16], state: "minecraft:cut_red_sandstone"},
        {pos: [4, 1, 17], state: "minecraft:red_sand"},
        {pos: [4, 1, 18], state: "minecraft:red_sand"},
        {pos: [5, 1, 3], state: "minecraft:red_sand"},
        {pos: [5, 1, 4], state: "minecraft:red_sand"},
        {pos: [5, 1, 9], state: "minecraft:red_sand"},
        {pos: [5, 1, 10], state: "minecraft:red_sand"},
        {pos: [5, 1, 12], state: "minecraft:red_sand"},
        {pos: [5, 1, 13], state: "minecraft:red_sand"},
        {pos: [5, 1, 14], state: "minecraft:red_sand"},
        {pos: [5, 1, 15], state: "minecraft:red_sand"},
        {pos: [6, 1, 3], state: "minecraft:cut_red_sandstone"},
        {pos: [6, 1, 4], state: "minecraft:cut_red_sandstone"},
        {pos: [6, 1, 5], state: "minecraft:cut_red_sandstone"},
        {pos: [6, 1, 10], state: "minecraft:red_sand"},
        {pos: [6, 1, 11], state: "minecraft:red_sand"},
        {pos: [6, 1, 12], state: "minecraft:red_sand"},
        {pos: [6, 1, 13], state: "minecraft:red_sand"},
        {pos: [6, 1, 14], state: "minecraft:red_sand"},
        {pos: [7, 1, 2], state: "minecraft:red_sand"},
        {pos: [7, 1, 3], state: "minecraft:cut_red_sandstone"},
        {pos: [7, 1, 4], state: "minecraft:cut_red_sandstone"},
        {pos: [7, 1, 5], state: "minecraft:cut_red_sandstone"},
        {pos: [7, 1, 7], state: "minecraft:red_sand"},
        {pos: [7, 1, 8], state: "minecraft:red_sand"},
        {pos: [7, 1, 9], state: "minecraft:red_sand"},
        {pos: [7, 1, 10], state: "minecraft:red_sand"},
        {pos: [7, 1, 11], state: "minecraft:red_sand"},
        {pos: [7, 1, 12], state: "minecraft:red_sand"},
        {pos: [7, 1, 13], state: "minecraft:red_sand"},
        {pos: [8, 1, 2], state: "minecraft:red_sand"},
        {pos: [8, 1, 3], state: "minecraft:red_sand"},
        {pos: [8, 1, 4], state: "minecraft:red_sand"},
        {pos: [8, 1, 5], state: "minecraft:red_sand"},
        {pos: [8, 1, 6], state: "minecraft:red_sand"},
        {pos: [8, 1, 7], state: "minecraft:red_sand"},
        {pos: [8, 1, 8], state: "minecraft:red_sand"},
        {pos: [8, 1, 9], state: "minecraft:red_sand"},
        {pos: [8, 1, 10], state: "minecraft:red_sand"},
        {pos: [8, 1, 11], state: "minecraft:red_sand"},
        {pos: [8, 1, 12], state: "minecraft:red_sand"},
        {pos: [8, 1, 13], state: "minecraft:red_sand"},
        {pos: [9, 1, 0], state: "minecraft:cut_red_sandstone"},
        {pos: [9, 1, 1], state: "minecraft:cut_red_sandstone"},
        {pos: [9, 1, 2], state: "minecraft:red_sand"},
        {pos: [9, 1, 3], state: "minecraft:red_sand"},
        {pos: [9, 1, 4], state: "minecraft:red_sand"},
        {pos: [9, 1, 5], state: "minecraft:red_sand"},
        {pos: [9, 1, 6], state: "minecraft:red_sand"},
        {pos: [9, 1, 7], state: "minecraft:red_sand"},
        {pos: [9, 1, 8], state: "minecraft:red_sand"},
        {pos: [9, 1, 9], state: "minecraft:red_sand"},
        {pos: [9, 1, 10], state: "minecraft:red_sand"},
        {pos: [9, 1, 11], state: "minecraft:red_sand"},
        {pos: [9, 1, 12], state: "minecraft:red_sandstone_stairs{facing:south,half:top,shape:straight,waterlogged:false}"},
        {pos: [9, 1, 13], state: "minecraft:cut_red_sandstone"},
        {pos: [9, 1, 14], state: "minecraft:cut_red_sandstone"},
        {pos: [10, 1, 0], state: "minecraft:cut_red_sandstone"},
        {pos: [10, 1, 1], state: "minecraft:red_sand"},
        {pos: [10, 1, 2], state: "minecraft:red_sand"},
        {pos: [10, 1, 3], state: "minecraft:red_sand"},
        {pos: [10, 1, 4], state: "minecraft:red_sand"},
        {pos: [10, 1, 5], state: "minecraft:red_sand"},
        {pos: [10, 1, 6], state: "minecraft:red_sand"},
        {pos: [10, 1, 7], state: "minecraft:red_sand"},
        {pos: [10, 1, 8], state: "minecraft:red_sand"},
        {pos: [10, 1, 11], state: "minecraft:red_sand"},
        {pos: [10, 1, 12], state: "minecraft:red_sandstone_stairs{facing:south,half:top,shape:straight,waterlogged:false}"},
        {pos: [10, 1, 13], state: "minecraft:cut_red_sandstone"},
        {pos: [10, 1, 14], state: "minecraft:cut_red_sandstone"},
        {pos: [11, 1, 0], state: "minecraft:cut_red_sandstone"},
        {pos: [11, 1, 1], state: "minecraft:red_sand"},
        {pos: [11, 1, 2], state: "minecraft:red_sand"},
        {pos: [11, 1, 3], state: "minecraft:red_sand"},
        {pos: [11, 1, 4], state: "minecraft:cut_red_sandstone"},
        {pos: [11, 1, 5], state: "minecraft:cut_red_sandstone"},
        {pos: [11, 1, 8], state: "minecraft:cut_red_sandstone"},
        {pos: [11, 1, 9], state: "minecraft:cut_red_sandstone"},
        {pos: [11, 1, 10], state: "minecraft:red_sand"},
        {pos: [11, 1, 12], state: "minecraft:red_sand"},
        {pos: [11, 1, 13], state: "minecraft:red_sand"},
        {pos: [12, 1, 0], state: "minecraft:red_sand"},
        {pos: [12, 1, 1], state: "minecraft:red_sand"},
        {pos: [12, 1, 2], state: "minecraft:red_sand"},
        {pos: [12, 1, 4], state: "minecraft:cut_red_sandstone"},
        {pos: [12, 1, 5], state: "minecraft:cut_red_sandstone"},
        {pos: [12, 1, 8], state: "minecraft:cut_red_sandstone"},
        {pos: [12, 1, 9], state: "minecraft:cut_red_sandstone"},
        {pos: [12, 1, 10], state: "minecraft:cut_red_sandstone"},
        {pos: [13, 1, 1], state: "minecraft:cut_red_sandstone"},
        {pos: [13, 1, 2], state: "minecraft:cut_red_sandstone"},
        {pos: [13, 1, 8], state: "minecraft:red_sand"},
        {pos: [13, 1, 9], state: "minecraft:cut_red_sandstone"},
        {pos: [13, 1, 10], state: "minecraft:cut_red_sandstone"},
        {pos: [14, 1, 8], state: "minecraft:red_sand"},
        {pos: [14, 1, 9], state: "minecraft:red_sand"},
        {pos: [0, 2, 16], state: "minecraft:red_sand"},
        {pos: [0, 2, 17], state: "minecraft:red_sand"},
        {pos: [0, 2, 18], state: "minecraft:cut_red_sandstone"},
        {pos: [0, 2, 19], state: "minecraft:cut_red_sandstone"},
        {pos: [1, 2, 15], state: "minecraft:red_sand"},
        {pos: [1, 2, 16], state: "minecraft:red_sand"},
        {pos: [1, 2, 17], state: "minecraft:red_sand"},
        {pos: [1, 2, 18], state: "minecraft:red_sand"},
        {pos: [1, 2, 19], state: "minecraft:cut_red_sandstone"},
        {pos: [2, 2, 15], state: "minecraft:red_sand"},
        {pos: [2, 2, 16], state: "minecraft:red_sand"},
        {pos: [2, 2, 17], state: "minecraft:red_sand"},
        {pos: [2, 2, 18], state: "minecraft:red_sand"},
        {pos: [2, 2, 19], state: "minecraft:cut_red_sandstone"},
        {pos: [3, 2, 9], state: "minecraft:cut_red_sandstone"},
        {pos: [3, 2, 10], state: "minecraft:cut_red_sandstone"},
        {pos: [3, 2, 11], state: "minecraft:red_sand"},
        {pos: [3, 2, 14], state: "minecraft:cut_red_sandstone"},
        {pos: [3, 2, 15], state: "minecraft:red_sand"},
        {pos: [3, 2, 16], state: "minecraft:red_sand"},
        {pos: [3, 2, 17], state: "minecraft:red_sand"},
        {pos: [3, 2, 18], state: "minecraft:red_sand"},
        {pos: [3, 2, 19], state: "minecraft:red_sand"},
        {pos: [4, 2, 9], state: "minecraft:cut_red_sandstone"},
        {pos: [4, 2, 10], state: "minecraft:chiseled_red_sandstone"},
        {pos: [4, 2, 13], state: "minecraft:red_sand"},
        {pos: [4, 2, 14], state: "minecraft:red_sand"},
        {pos: [4, 2, 15], state: "minecraft:red_sand"},
        {pos: [4, 2, 16], state: "minecraft:cut_red_sandstone"},
        {pos: [4, 2, 17], state: "minecraft:red_sand"},
        {pos: [4, 2, 18], state: "minecraft:red_sand"},
        {pos: [5, 2, 3], state: "minecraft:red_sand"},
        {pos: [5, 2, 4], state: "minecraft:red_sand"},
        {pos: [5, 2, 9], state: "minecraft:red_sand"},
        {pos: [5, 2, 10], state: "minecraft:red_sand"},
        {pos: [5, 2, 12], state: "minecraft:red_sand"},
        {pos: [5, 2, 13], state: "minecraft:red_sand"},
        {pos: [5, 2, 14], state: "minecraft:red_sand"},
        {pos: [5, 2, 15], state: "minecraft:red_sand"},
        {pos: [6, 2, 3], state: "minecraft:red_sand"},
        {pos: [6, 2, 4], state: "minecraft:cut_red_sandstone"},
        {pos: [6, 2, 5], state: "minecraft:cut_red_sandstone"},
        {pos: [6, 2, 10], state: "minecraft:red_sand"},
        {pos: [6, 2, 11], state: "minecraft:red_sand"},
        {pos: [6, 2, 12], state: "minecraft:red_sand"},
        {pos: [6, 2, 13], state: "minecraft:red_sand"},
        {pos: [6, 2, 14], state: "minecraft:red_sand"},
        {pos: [7, 2, 2], state: "minecraft:red_sand"},
        {pos: [7, 2, 3], state: "minecraft:red_sand"},
        {pos: [7, 2, 4], state: "minecraft:cut_red_sandstone"},
        {pos: [7, 2, 5], state: "minecraft:chiseled_red_sandstone"},
        {pos: [7, 2, 7], state: "minecraft:red_sand"},
        {pos: [7, 2, 8], state: "minecraft:red_sand"},
        {pos: [7, 2, 9], state: "minecraft:red_sand"},
        {pos: [7, 2, 10], state: "minecraft:red_sand"},
        {pos: [7, 2, 11], state: "minecraft:red_sand"},
        {pos: [7, 2, 12], state: "minecraft:red_sand"},
        {pos: [7, 2, 13], state: "minecraft:red_sand"},
        {pos: [8, 2, 2], state: "minecraft:red_sand"},
        {pos: [8, 2, 3], state: "minecraft:red_sand"},
        {pos: [8, 2, 4], state: "minecraft:red_sand"},
        {pos: [8, 2, 5], state: "minecraft:red_sand"},
        {pos: [8, 2, 6], state: "minecraft:red_sand"},
        {pos: [8, 2, 7], state: "minecraft:red_sand"},
        {pos: [8, 2, 8], state: "minecraft:red_sand"},
        {pos: [8, 2, 9], state: "minecraft:red_sand"},
        {pos: [8, 2, 10], state: "minecraft:red_sand"},
        {pos: [8, 2, 11], state: "minecraft:red_sand"},
        {pos: [8, 2, 12], state: "minecraft:red_sand"},
        {pos: [8, 2, 13], state: "minecraft:red_sand"},
        {pos: [9, 2, 0], state: "minecraft:cut_red_sandstone"},
        {pos: [9, 2, 1], state: "minecraft:cut_red_sandstone"},
        {pos: [9, 2, 2], state: "minecraft:red_sand"},
        {pos: [9, 2, 3], state: "minecraft:red_sand"},
        {pos: [9, 2, 4], state: "minecraft:red_sand"},
        {pos: [9, 2, 5], state: "minecraft:red_sand"},
        {pos: [9, 2, 6], state: "minecraft:red_sand"},
        {pos: [9, 2, 7], state: "minecraft:red_sand"},
        {pos: [9, 2, 8], state: "minecraft:red_sand"},
        {pos: [9, 2, 9], state: "minecraft:red_sand"},
        {pos: [9, 2, 10], state: "minecraft:red_sand"},
        {pos: [9, 2, 11], state: "minecraft:red_sand"},
        {pos: [9, 2, 12], state: "minecraft:red_sand"},
        {pos: [9, 2, 13], state: "minecraft:cut_red_sandstone"},
        {pos: [9, 2, 14], state: "minecraft:cut_red_sandstone"},
        {pos: [10, 2, 0], state: "minecraft:cut_red_sandstone"},
        {pos: [10, 2, 1], state: "minecraft:red_sand"},
        {pos: [10, 2, 2], state: "minecraft:red_sand"},
        {pos: [10, 2, 3], state: "minecraft:red_sand"},
        {pos: [10, 2, 4], state: "minecraft:red_sand"},
        {pos: [10, 2, 5], state: "minecraft:red_sand"},
        {pos: [10, 2, 6], state: "minecraft:red_sand"},
        {pos: [10, 2, 7], state: "minecraft:red_sand"},
        {pos: [10, 2, 8], state: "minecraft:red_sand"},
        {pos: [10, 2, 11], state: "minecraft:red_sand"},
        {pos: [10, 2, 12], state: "minecraft:red_sand"},
        {pos: [10, 2, 13], state: "minecraft:cut_red_sandstone"},
        {pos: [10, 2, 14], state: "minecraft:cut_red_sandstone"},
        {pos: [11, 2, 0], state: "minecraft:cut_red_sandstone"},
        {pos: [11, 2, 1], state: "minecraft:red_sand"},
        {pos: [11, 2, 2], state: "minecraft:red_sand"},
        {pos: [11, 2, 3], state: "minecraft:red_sand"},
        {pos: [11, 2, 4], state: "minecraft:red_sand"},
        {pos: [11, 2, 5], state: "minecraft:cut_red_sandstone"},
        {pos: [11, 2, 8], state: "minecraft:cut_red_sandstone"},
        {pos: [11, 2, 9], state: "minecraft:cut_red_sandstone"},
        {pos: [11, 2, 10], state: "minecraft:red_sand"},
        {pos: [11, 2, 12], state: "minecraft:red_sand"},
        {pos: [11, 2, 13], state: "minecraft:red_sand"},
        {pos: [12, 2, 0], state: "minecraft:red_sand"},
        {pos: [12, 2, 1], state: "minecraft:red_sand"},
        {pos: [12, 2, 2], state: "minecraft:red_sand"},
        {pos: [12, 2, 4], state: "minecraft:red_sand"},
        {pos: [12, 2, 5], state: "minecraft:cut_red_sandstone"},
        {pos: [12, 2, 8], state: "minecraft:cut_red_sandstone"},
        {pos: [12, 2, 9], state: "minecraft:cut_red_sandstone"},
        {pos: [12, 2, 10], state: "minecraft:red_sand"},
        {pos: [13, 2, 1], state: "minecraft:cut_red_sandstone"},
        {pos: [13, 2, 2], state: "minecraft:cut_red_sandstone"},
        {pos: [13, 2, 8], state: "minecraft:red_sand"},
        {pos: [13, 2, 9], state: "minecraft:red_sand"},
        {pos: [13, 2, 10], state: "minecraft:red_sand"},
        {pos: [14, 2, 8], state: "minecraft:red_sand"},
        {pos: [14, 2, 9], state: "minecraft:red_sand"},
        {pos: [0, 3, 16], state: "minecraft:red_sand"},
        {pos: [0, 3, 17], state: "minecraft:red_sand"},
        {pos: [0, 3, 18], state: "minecraft:red_sand"},
        {pos: [0, 3, 19], state: "minecraft:cut_red_sandstone"},
        {pos: [1, 3, 15], state: "minecraft:red_sand"},
        {pos: [1, 3, 16], state: "minecraft:red_sand"},
        {pos: [1, 3, 17], state: "minecraft:red_sand"},
        {pos: [1, 3, 18], state: "minecraft:red_sand"},
        {pos: [1, 3, 19], state: "minecraft:cut_red_sandstone"},
        {pos: [2, 3, 15], state: "minecraft:red_sand"},
        {pos: [2, 3, 16], state: "minecraft:red_sand"},
        {pos: [2, 3, 17], state: "minecraft:red_sand"},
        {pos: [2, 3, 18], state: "minecraft:red_sand"},
        {pos: [2, 3, 19], state: "minecraft:red_sand"},
        {pos: [3, 3, 9], state: "minecraft:cut_red_sandstone"},
        {pos: [3, 3, 10], state: "minecraft:cut_red_sandstone"},
        {pos: [3, 3, 11], state: "minecraft:red_sand"},
        {pos: [3, 3, 14], state: "minecraft:cut_red_sandstone"},
        {pos: [3, 3, 15], state: "minecraft:cut_red_sandstone"},
        {pos: [3, 3, 16], state: "minecraft:red_sand"},
        {pos: [3, 3, 17], state: "minecraft:red_sand"},
        {pos: [3, 3, 18], state: "minecraft:red_sand"},
        {pos: [3, 3, 19], state: "minecraft:red_sand"},
        {pos: [4, 3, 9], state: "minecraft:cut_red_sandstone"},
        {pos: [4, 3, 10], state: "minecraft:cut_red_sandstone"},
        {pos: [4, 3, 13], state: "minecraft:red_sand"},
        {pos: [4, 3, 14], state: "minecraft:red_sand"},
        {pos: [4, 3, 15], state: "minecraft:cut_red_sandstone"},
        {pos: [4, 3, 16], state: "minecraft:cut_red_sandstone"},
        {pos: [4, 3, 17], state: "minecraft:red_sand"},
        {pos: [4, 3, 18], state: "minecraft:red_sand"},
        {pos: [5, 3, 3], state: "minecraft:red_sand"},
        {pos: [5, 3, 4], state: "minecraft:red_sand"},
        {pos: [5, 3, 9], state: "minecraft:red_sand"},
        {pos: [5, 3, 10], state: "minecraft:red_sand"},
        {pos: [5, 3, 12], state: "minecraft:red_sand"},
        {pos: [5, 3, 13], state: "minecraft:red_sand"},
        {pos: [5, 3, 14], state: "minecraft:red_sand"},
        {pos: [5, 3, 15], state: "minecraft:red_sand"},
        {pos: [6, 3, 3], state: "minecraft:red_sand"},
        {pos: [6, 3, 4], state: "minecraft:cut_red_sandstone"},
        {pos: [6, 3, 5], state: "minecraft:cut_red_sandstone"},
        {pos: [6, 3, 10], state: "minecraft:red_sand"},
        {pos: [6, 3, 11], state: "minecraft:red_sand"},
        {pos: [6, 3, 12], state: "minecraft:red_sand"},
        {pos: [6, 3, 13], state: "minecraft:red_sand"},
        {pos: [6, 3, 14], state: "minecraft:red_sand"},
        {pos: [7, 3, 2], state: "minecraft:red_sand"},
        {pos: [7, 3, 3], state: "minecraft:red_sand"},
        {pos: [7, 3, 4], state: "minecraft:cut_red_sandstone"},
        {pos: [7, 3, 5], state: "minecraft:cut_red_sandstone"},
        {pos: [7, 3, 6], state: "minecraft:cut_red_sandstone"},
        {pos: [7, 3, 7], state: "minecraft:red_sand"},
        {pos: [7, 3, 8], state: "minecraft:red_sand"},
        {pos: [7, 3, 9], state: "minecraft:red_sand"},
        {pos: [7, 3, 10], state: "minecraft:red_sand"},
        {pos: [7, 3, 11], state: "minecraft:red_sand"},
        {pos: [7, 3, 12], state: "minecraft:red_sand"},
        {pos: [7, 3, 13], state: "minecraft:red_sand"},
        {pos: [8, 3, 2], state: "minecraft:red_sand"},
        {pos: [8, 3, 3], state: "minecraft:red_sand"},
        {pos: [8, 3, 4], state: "minecraft:red_sand"},
        {pos: [8, 3, 5], state: "minecraft:cut_red_sandstone"},
        {pos: [8, 3, 6], state: "minecraft:cut_red_sandstone"},
        {pos: [8, 3, 7], state: "minecraft:red_sand"},
        {pos: [8, 3, 8], state: "minecraft:red_sand"},
        {pos: [8, 3, 9], state: "minecraft:red_sand"},
        {pos: [8, 3, 10], state: "minecraft:red_sand"},
        {pos: [8, 3, 11], state: "minecraft:red_sand"},
        {pos: [8, 3, 12], state: "minecraft:red_sand"},
        {pos: [8, 3, 13], state: "minecraft:red_sand"},
        {pos: [9, 3, 0], state: "minecraft:cut_red_sandstone"},
        {pos: [9, 3, 1], state: "minecraft:cut_red_sandstone"},
        {pos: [9, 3, 2], state: "minecraft:red_sand"},
        {pos: [9, 3, 3], state: "minecraft:red_sand"},
        {pos: [9, 3, 4], state: "minecraft:red_sand"},
        {pos: [9, 3, 5], state: "minecraft:red_sand"},
        {pos: [9, 3, 6], state: "minecraft:red_sand"},
        {pos: [9, 3, 7], state: "minecraft:red_sand"},
        {pos: [9, 3, 8], state: "minecraft:red_sand"},
        {pos: [9, 3, 9], state: "minecraft:red_sand"},
        {pos: [9, 3, 10], state: "minecraft:red_sand"},
        {pos: [9, 3, 11], state: "minecraft:red_sand"},
        {pos: [9, 3, 12], state: "minecraft:red_sand"},
        {pos: [9, 3, 13], state: "minecraft:cut_red_sandstone"},
        {pos: [9, 3, 14], state: "minecraft:chiseled_red_sandstone"},
        {pos: [10, 3, 0], state: "minecraft:cut_red_sandstone"},
        {pos: [10, 3, 1], state: "minecraft:red_sand"},
        {pos: [10, 3, 2], state: "minecraft:red_sand"},
        {pos: [10, 3, 3], state: "minecraft:red_sand"},
        {pos: [10, 3, 4], state: "minecraft:red_sand"},
        {pos: [10, 3, 5], state: "minecraft:red_sand"},
        {pos: [10, 3, 6], state: "minecraft:red_sand"},
        {pos: [10, 3, 7], state: "minecraft:red_sand"},
        {pos: [10, 3, 8], state: "minecraft:red_sand"},
        {pos: [10, 3, 11], state: "minecraft:red_sand"},
        {pos: [10, 3, 12], state: "minecraft:red_sand"},
        {pos: [10, 3, 13], state: "minecraft:cut_red_sandstone"},
        {pos: [10, 3, 14], state: "minecraft:cut_red_sandstone"},
        {pos: [11, 3, 0], state: "minecraft:red_sand"},
        {pos: [11, 3, 1], state: "minecraft:red_sand"},
        {pos: [11, 3, 2], state: "minecraft:red_sand"},
        {pos: [11, 3, 3], state: "minecraft:red_sand"},
        {pos: [11, 3, 4], state: "minecraft:red_sand"},
        {pos: [11, 3, 5], state: "minecraft:red_sand"},
        {pos: [11, 3, 8], state: "minecraft:cut_red_sandstone"},
        {pos: [11, 3, 9], state: "minecraft:cut_red_sandstone"},
        {pos: [11, 3, 10], state: "minecraft:red_sand"},
        {pos: [11, 3, 12], state: "minecraft:red_sand"},
        {pos: [11, 3, 13], state: "minecraft:red_sand"},
        {pos: [12, 3, 0], state: "minecraft:red_sand"},
        {pos: [12, 3, 1], state: "minecraft:red_sand"},
        {pos: [12, 3, 2], state: "minecraft:red_sand"},
        {pos: [12, 3, 5], state: "minecraft:red_sand"},
        {pos: [12, 3, 8], state: "minecraft:chiseled_red_sandstone"},
        {pos: [12, 3, 9], state: "minecraft:cut_red_sandstone"},
        {pos: [12, 3, 10], state: "minecraft:red_sand"},
        {pos: [13, 3, 1], state: "minecraft:red_sand"},
        {pos: [13, 3, 2], state: "minecraft:cut_red_sandstone"},
        {pos: [13, 3, 8], state: "minecraft:red_sand"},
        {pos: [13, 3, 9], state: "minecraft:red_sand"},
        {pos: [13, 3, 10], state: "minecraft:red_sand"},
        {pos: [14, 3, 8], state: "minecraft:red_sand"},
        {pos: [14, 3, 9], state: "minecraft:red_sand"},
        {pos: [1, 4, 16], state: "minecraft:red_sand"},
        {pos: [1, 4, 17], state: "minecraft:red_sand"},
        {pos: [2, 4, 15], state: "minecraft:red_sand"},
        {pos: [2, 4, 16], state: "minecraft:red_sand"},
        {pos: [2, 4, 17], state: "minecraft:red_sand"},
        {pos: [3, 4, 9], state: "minecraft:cut_red_sandstone"},
        {pos: [3, 4, 10], state: "minecraft:cut_red_sandstone"},
        {pos: [3, 4, 15], state: "minecraft:red_sand"},
        {pos: [3, 4, 16], state: "minecraft:red_sand"},
        {pos: [3, 4, 17], state: "minecraft:red_sand"},
        {pos: [4, 4, 9], state: "minecraft:cut_red_sandstone"},
        {pos: [4, 4, 10], state: "minecraft:cut_red_sandstone"},
        {pos: [4, 4, 14], state: "minecraft:red_sand"},
        {pos: [4, 4, 15], state: "minecraft:cut_red_sandstone"},
        {pos: [4, 4, 16], state: "minecraft:cut_red_sandstone"},
        {pos: [4, 4, 17], state: "minecraft:red_sand"},
        {pos: [5, 4, 10], state: "minecraft:red_sand"},
        {pos: [5, 4, 15], state: "minecraft:red_sand"},
        {pos: [7, 4, 5], state: "minecraft:cut_red_sandstone"},
        {pos: [7, 4, 6], state: "minecraft:cut_red_sandstone"},
        {pos: [7, 4, 10], state: "minecraft:red_sand"},
        {pos: [7, 4, 11], state: "minecraft:red_sand"},
        {pos: [7, 4, 12], state: "minecraft:red_sand"},
        {pos: [7, 4, 13], state: "minecraft:red_sand"},
        {pos: [8, 4, 5], state: "minecraft:cut_red_sandstone"},
        {pos: [8, 4, 6], state: "minecraft:cut_red_sandstone"},
        {pos: [8, 4, 7], state: "minecraft:cut_red_sandstone"},
        {pos: [8, 4, 10], state: "minecraft:red_sand"},
        {pos: [8, 4, 11], state: "minecraft:red_sand"},
        {pos: [8, 4, 12], state: "minecraft:red_sand"},
        {pos: [8, 4, 13], state: "minecraft:red_sand"},
        {pos: [9, 4, 6], state: "minecraft:cut_red_sandstone"},
        {pos: [9, 4, 7], state: "minecraft:cut_red_sandstone"},
        {pos: [9, 4, 11], state: "minecraft:red_sand"},
        {pos: [9, 4, 12], state: "minecraft:red_sand"},
        {pos: [9, 4, 13], state: "minecraft:cut_red_sandstone"},
        {pos: [9, 4, 14], state: "minecraft:red_sand"},
        {pos: [10, 4, 12], state: "minecraft:red_sand"},
        {pos: [10, 4, 13], state: "minecraft:cut_red_sandstone"},
        {pos: [10, 4, 14], state: "minecraft:cut_red_sandstone"},
        {pos: [11, 4, 8], state: "minecraft:cut_red_sandstone"},
        {pos: [11, 4, 9], state: "minecraft:cut_red_sandstone"},
        {pos: [11, 4, 10], state: "minecraft:red_sand"},
        {pos: [12, 4, 5], state: "minecraft:red_sand"},
        {pos: [12, 4, 8], state: "minecraft:cut_red_sandstone"},
        {pos: [12, 4, 9], state: "minecraft:cut_red_sandstone"},
        {pos: [12, 4, 10], state: "minecraft:red_sand"},
        {pos: [13, 4, 8], state: "minecraft:red_sand"},
        {pos: [13, 4, 9], state: "minecraft:red_sand"},
        {pos: [14, 4, 8], state: "minecraft:red_sand"},
        {pos: [14, 4, 9], state: "minecraft:red_sand"},
        {pos: [8, 5, 6], state: "minecraft:cut_red_sandstone"},
        {pos: [8, 5, 7], state: "minecraft:cut_red_sandstone"},
        {pos: [9, 5, 7], state: "minecraft:cut_red_sandstone"},
        {pos: [11, 5, 8], state: "minecraft:cut_red_sandstone"}
    ],
    entities: [],
    palette: [
        "minecraft:cut_red_sandstone",
        "minecraft:yellow_glazed_terracotta{facing:north}",
        "minecraft:yellow_glazed_terracotta{facing:east}",
        "minecraft:yellow_glazed_terracotta{facing:south}",
        "minecraft:orange_glazed_terracotta{facing:north}",
        "minecraft:orange_glazed_terracotta{facing:east}",
        "minecraft:orange_glazed_terracotta{facing:south}",
        "minecraft:red_sand",
        "minecraft:chiseled_red_sandstone",
        "minecraft:red_sandstone_stairs{facing:south,half:top,shape:straight,waterlogged:false}"
    ],
    trailiertales_DataVersion: 2
}
