{
    DataVersion: 3953,
    size: [15, 5, 18],
    data: [
        {pos: [0, 0, 6], state: "minecraft:cut_red_sandstone"},
        {pos: [0, 0, 7], state: "minecraft:cut_red_sandstone"},
        {pos: [0, 0, 8], state: "minecraft:cut_red_sandstone"},
        {pos: [1, 0, 5], state: "minecraft:cut_red_sandstone"},
        {pos: [1, 0, 6], state: "minecraft:cut_red_sandstone"},
        {pos: [1, 0, 7], state: "minecraft:cut_red_sandstone"},
        {pos: [1, 0, 8], state: "minecraft:cut_red_sandstone"},
        {pos: [2, 0, 5], state: "minecraft:cut_red_sandstone"},
        {pos: [2, 0, 6], state: "minecraft:cut_red_sandstone"},
        {pos: [2, 0, 7], state: "minecraft:cut_red_sandstone"},
        {pos: [2, 0, 8], state: "minecraft:cut_red_sandstone"},
        {pos: [3, 0, 4], state: "minecraft:cut_red_sandstone"},
        {pos: [3, 0, 5], state: "minecraft:cut_red_sandstone"},
        {pos: [3, 0, 6], state: "minecraft:yellow_glazed_terracotta{facing:north}"},
        {pos: [3, 0, 7], state: "minecraft:yellow_glazed_terracotta{facing:west}"},
        {pos: [3, 0, 8], state: "minecraft:cut_red_sandstone"},
        {pos: [3, 0, 9], state: "minecraft:cut_red_sandstone"},
        {pos: [4, 0, 2], state: "minecraft:cut_red_sandstone"},
        {pos: [4, 0, 3], state: "minecraft:cut_red_sandstone"},
        {pos: [4, 0, 4], state: "minecraft:cut_red_sandstone"},
        {pos: [4, 0, 5], state: "minecraft:cut_red_sandstone"},
        {pos: [4, 0, 6], state: "minecraft:yellow_glazed_terracotta{facing:east}"},
        {pos: [4, 0, 7], state: "minecraft:yellow_glazed_terracotta{facing:south}"},
        {pos: [4, 0, 8], state: "minecraft:cut_red_sandstone"},
        {pos: [4, 0, 9], state: "minecraft:cut_red_sandstone"},
        {pos: [4, 0, 10], state: "minecraft:cut_red_sandstone"},
        {pos: [4, 0, 13], state: "minecraft:cut_red_sandstone"},
        {pos: [4, 0, 14], state: "minecraft:cut_red_sandstone"},
        {pos: [4, 0, 15], state: "minecraft:cut_red_sandstone"},
        {pos: [4, 0, 16], state: "minecraft:cut_red_sandstone"},
        {pos: [4, 0, 17], state: "minecraft:cut_red_sandstone"},
        {pos: [5, 0, 1], state: "minecraft:cut_red_sandstone"},
        {pos: [5, 0, 2], state: "minecraft:cut_red_sandstone"},
        {pos: [5, 0, 3], state: "minecraft:cut_red_sandstone"},
        {pos: [5, 0, 4], state: "minecraft:cut_red_sandstone"},
        {pos: [5, 0, 5], state: "minecraft:cut_red_sandstone"},
        {pos: [5, 0, 6], state: "minecraft:cut_red_sandstone"},
        {pos: [5, 0, 7], state: "minecraft:cut_red_sandstone"},
        {pos: [5, 0, 8], state: "minecraft:cut_red_sandstone"},
        {pos: [5, 0, 9], state: "minecraft:cut_red_sandstone"},
        {pos: [5, 0, 10], state: "minecraft:cut_red_sandstone"},
        {pos: [5, 0, 11], state: "minecraft:cut_red_sandstone"},
        {pos: [5, 0, 12], state: "minecraft:cut_red_sandstone"},
        {pos: [5, 0, 13], state: "minecraft:cut_red_sandstone"},
        {pos: [5, 0, 14], state: "minecraft:cut_red_sandstone"},
        {pos: [5, 0, 15], state: "minecraft:cut_red_sandstone"},
        {pos: [5, 0, 16], state: "minecraft:cut_red_sandstone"},
        {pos: [5, 0, 17], state: "minecraft:cut_red_sandstone"},
        {pos: [6, 0, 1], state: "minecraft:cut_red_sandstone"},
        {pos: [6, 0, 2], state: "minecraft:cut_red_sandstone"},
        {pos: [6, 0, 3], state: "minecraft:cut_red_sandstone"},
        {pos: [6, 0, 4], state: "minecraft:cut_red_sandstone"},
        {pos: [6, 0, 5], state: "minecraft:cut_red_sandstone"},
        {pos: [6, 0, 10], state: "minecraft:cut_red_sandstone"},
        {pos: [6, 0, 11], state: "minecraft:cut_red_sandstone"},
        {pos: [6, 0, 12], state: "minecraft:cut_red_sandstone"},
        {pos: [6, 0, 13], state: "minecraft:cut_red_sandstone"},
        {pos: [6, 0, 14], state: "minecraft:cut_red_sandstone"},
        {pos: [6, 0, 15], state: "minecraft:cut_red_sandstone"},
        {pos: [6, 0, 16], state: "minecraft:cut_red_sandstone"},
        {pos: [6, 0, 17], state: "minecraft:cut_red_sandstone"},
        {pos: [7, 0, 0], state: "minecraft:cut_red_sandstone"},
        {pos: [7, 0, 1], state: "minecraft:cut_red_sandstone"},
        {pos: [7, 0, 2], state: "minecraft:cut_red_sandstone"},
        {pos: [7, 0, 3], state: "minecraft:orange_glazed_terracotta{facing:west}"},
        {pos: [7, 0, 4], state: "minecraft:cut_red_sandstone"},
        {pos: [7, 0, 7], state: "minecraft:cut_red_sandstone"},
        {pos: [7, 0, 8], state: "minecraft:cut_red_sandstone"},
        {pos: [7, 0, 13], state: "minecraft:cut_red_sandstone"},
        {pos: [7, 0, 14], state: "minecraft:cut_red_sandstone"},
        {pos: [7, 0, 15], state: "minecraft:cut_red_sandstone"},
        {pos: [7, 0, 16], state: "minecraft:cut_red_sandstone"},
        {pos: [8, 0, 0], state: "minecraft:cut_red_sandstone"},
        {pos: [8, 0, 1], state: "minecraft:cut_red_sandstone"},
        {pos: [8, 0, 2], state: "minecraft:cut_red_sandstone"},
        {pos: [8, 0, 3], state: "minecraft:orange_glazed_terracotta{facing:south}"},
        {pos: [8, 0, 4], state: "minecraft:cut_red_sandstone"},
        {pos: [8, 0, 5], state: "minecraft:cut_red_sandstone"},
        {pos: [8, 0, 6], state: "minecraft:cut_red_sandstone"},
        {pos: [8, 0, 7], state: "minecraft:orange_glazed_terracotta{facing:north}"},
        {pos: [8, 0, 8], state: "minecraft:orange_glazed_terracotta{facing:west}"},
        {pos: [8, 0, 9], state: "minecraft:cut_red_sandstone"},
        {pos: [8, 0, 12], state: "minecraft:cut_red_sandstone"},
        {pos: [8, 0, 13], state: "minecraft:cut_red_sandstone"},
        {pos: [8, 0, 14], state: "minecraft:cut_red_sandstone"},
        {pos: [8, 0, 15], state: "minecraft:cut_red_sandstone"},
        {pos: [8, 0, 16], state: "minecraft:cut_red_sandstone"},
        {pos: [9, 0, 0], state: "minecraft:cut_red_sandstone"},
        {pos: [9, 0, 1], state: "minecraft:cut_red_sandstone"},
        {pos: [9, 0, 2], state: "minecraft:cut_red_sandstone"},
        {pos: [9, 0, 3], state: "minecraft:cut_red_sandstone"},
        {pos: [9, 0, 4], state: "minecraft:cut_red_sandstone"},
        {pos: [9, 0, 5], state: "minecraft:cut_red_sandstone"},
        {pos: [9, 0, 6], state: "minecraft:cut_red_sandstone"},
        {pos: [9, 0, 7], state: "minecraft:orange_glazed_terracotta{facing:east}"},
        {pos: [9, 0, 8], state: "minecraft:cut_red_sandstone"},
        {pos: [9, 0, 9], state: "minecraft:cut_red_sandstone"},
        {pos: [9, 0, 11], state: "minecraft:cut_red_sandstone"},
        {pos: [9, 0, 12], state: "minecraft:cut_red_sandstone"},
        {pos: [9, 0, 13], state: "minecraft:cut_red_sandstone"},
        {pos: [9, 0, 14], state: "minecraft:cut_red_sandstone"},
        {pos: [9, 0, 15], state: "minecraft:cut_red_sandstone"},
        {pos: [10, 0, 1], state: "minecraft:cut_red_sandstone"},
        {pos: [10, 0, 2], state: "minecraft:cut_red_sandstone"},
        {pos: [10, 0, 3], state: "minecraft:cut_red_sandstone"},
        {pos: [10, 0, 4], state: "minecraft:cut_red_sandstone"},
        {pos: [10, 0, 5], state: "minecraft:cut_red_sandstone"},
        {pos: [10, 0, 6], state: "minecraft:cut_red_sandstone"},
        {pos: [10, 0, 7], state: "minecraft:cut_red_sandstone"},
        {pos: [10, 0, 8], state: "minecraft:cut_red_sandstone"},
        {pos: [10, 0, 9], state: "minecraft:cut_red_sandstone"},
        {pos: [10, 0, 10], state: "minecraft:cut_red_sandstone"},
        {pos: [10, 0, 11], state: "minecraft:cut_red_sandstone"},
        {pos: [10, 0, 12], state: "minecraft:cut_red_sandstone"},
        {pos: [11, 0, 6], state: "minecraft:cut_red_sandstone"},
        {pos: [11, 0, 7], state: "minecraft:cut_red_sandstone"},
        {pos: [11, 0, 8], state: "minecraft:cut_red_sandstone"},
        {pos: [11, 0, 9], state: "minecraft:cut_red_sandstone"},
        {pos: [11, 0, 10], state: "minecraft:cut_red_sandstone"},
        {pos: [11, 0, 11], state: "minecraft:cut_red_sandstone"},
        {pos: [11, 0, 12], state: "minecraft:cut_red_sandstone"},
        {pos: [12, 0, 6], state: "minecraft:cut_red_sandstone"},
        {pos: [12, 0, 7], state: "minecraft:cut_red_sandstone"},
        {pos: [12, 0, 8], state: "minecraft:cut_red_sandstone"},
        {pos: [12, 0, 9], state: "minecraft:cut_red_sandstone"},
        {pos: [12, 0, 10], state: "minecraft:cut_red_sandstone"},
        {pos: [12, 0, 11], state: "minecraft:cut_red_sandstone"},
        {pos: [12, 0, 12], state: "minecraft:cut_red_sandstone"},
        {pos: [13, 0, 6], state: "minecraft:cut_red_sandstone"},
        {pos: [13, 0, 7], state: "minecraft:cut_red_sandstone"},
        {pos: [13, 0, 8], state: "minecraft:cut_red_sandstone"},
        {pos: [13, 0, 9], state: "minecraft:cut_red_sandstone"},
        {pos: [13, 0, 10], state: "minecraft:cut_red_sandstone"},
        {pos: [13, 0, 11], state: "minecraft:cut_red_sandstone"},
        {pos: [13, 0, 12], state: "minecraft:cut_red_sandstone"},
        {pos: [14, 0, 7], state: "minecraft:cut_red_sandstone"},
        {pos: [14, 0, 8], state: "minecraft:cut_red_sandstone"},
        {pos: [14, 0, 9], state: "minecraft:cut_red_sandstone"},
        {pos: [14, 0, 10], state: "minecraft:cut_red_sandstone"},
        {pos: [14, 0, 11], state: "minecraft:cut_red_sandstone"},
        {pos: [0, 1, 6], state: "minecraft:cut_red_sandstone"},
        {pos: [0, 1, 7], state: "minecraft:cut_red_sandstone"},
        {pos: [0, 1, 8], state: "minecraft:cut_red_sandstone"},
        {pos: [1, 1, 5], state: "minecraft:red_sand"},
        {pos: [1, 1, 6], state: "minecraft:cut_red_sandstone"},
        {pos: [1, 1, 7], state: "minecraft:red_sand"},
        {pos: [1, 1, 8], state: "minecraft:cut_red_sandstone"},
        {pos: [2, 1, 5], state: "minecraft:red_sand"},
        {pos: [2, 1, 6], state: "minecraft:cut_red_sandstone"},
        {pos: [2, 1, 7], state: "minecraft:red_sand"},
        {pos: [2, 1, 8], state: "minecraft:cut_red_sandstone"},
        {pos: [3, 1, 4], state: "minecraft:red_sand"},
        {pos: [3, 1, 5], state: "minecraft:red_sand"},
        {pos: [3, 1, 6], state: "minecraft:red_sand"},
        {pos: [3, 1, 7], state: "minecraft:red_sand"},
        {pos: [3, 1, 8], state: "minecraft:red_sand"},
        {pos: [3, 1, 9], state: "minecraft:red_sand"},
        {pos: [4, 1, 2], state: "minecraft:red_sand"},
        {pos: [4, 1, 3], state: "minecraft:red_sand"},
        {pos: [4, 1, 4], state: "minecraft:red_sand"},
        {pos: [4, 1, 5], state: "minecraft:red_sand"},
        {pos: [4, 1, 6], state: "minecraft:red_sand"},
        {pos: [4, 1, 7], state: "minecraft:red_sand"},
        {pos: [4, 1, 8], state: "minecraft:red_sand"},
        {pos: [4, 1, 9], state: "minecraft:cut_red_sandstone"},
        {pos: [4, 1, 10], state: "minecraft:red_sand"},
        {pos: [4, 1, 13], state: "minecraft:red_sand"},
        {pos: [4, 1, 14], state: "minecraft:red_sand"},
        {pos: [4, 1, 15], state: "minecraft:red_sand"},
        {pos: [4, 1, 16], state: "minecraft:red_sand"},
        {pos: [4, 1, 17], state: "minecraft:red_sand"},
        {pos: [5, 1, 1], state: "minecraft:red_sand"},
        {pos: [5, 1, 2], state: "minecraft:cut_red_sandstone"},
        {pos: [5, 1, 3], state: "minecraft:red_sand"},
        {pos: [5, 1, 4], state: "minecraft:red_sand"},
        {pos: [5, 1, 5], state: "minecraft:red_sand"},
        {pos: [5, 1, 6], state: "minecraft:cut_red_sandstone"},
        {pos: [5, 1, 7], state: "minecraft:red_sand"},
        {pos: [5, 1, 8], state: "minecraft:red_sand"},
        {pos: [5, 1, 9], state: "minecraft:red_sand"},
        {pos: [5, 1, 10], state: "minecraft:red_sand"},
        {pos: [5, 1, 11], state: "minecraft:red_sand"},
        {pos: [5, 1, 12], state: "minecraft:red_sand"},
        {pos: [5, 1, 13], state: "minecraft:red_sand"},
        {pos: [5, 1, 14], state: "minecraft:cut_red_sandstone"},
        {pos: [5, 1, 15], state: "minecraft:cut_red_sandstone"},
        {pos: [5, 1, 16], state: "minecraft:cut_red_sandstone"},
        {pos: [5, 1, 17], state: "minecraft:red_sand"},
        {pos: [6, 1, 1], state: "minecraft:red_sand"},
        {pos: [6, 1, 2], state: "minecraft:cut_red_sandstone"},
        {pos: [6, 1, 3], state: "minecraft:red_sand"},
        {pos: [6, 1, 4], state: "minecraft:red_sand"},
        {pos: [6, 1, 5], state: "minecraft:red_sand"},
        {pos: [6, 1, 10], state: "minecraft:red_sand"},
        {pos: [6, 1, 11], state: "minecraft:red_sand"},
        {pos: [6, 1, 12], state: "minecraft:red_sand"},
        {pos: [6, 1, 13], state: "minecraft:red_sand"},
        {pos: [6, 1, 14], state: "minecraft:red_sand"},
        {pos: [6, 1, 15], state: "minecraft:red_sand"},
        {pos: [6, 1, 16], state: "minecraft:cut_red_sandstone"},
        {pos: [6, 1, 17], state: "minecraft:red_sand"},
        {pos: [7, 1, 0], state: "minecraft:red_sand"},
        {pos: [7, 1, 1], state: "minecraft:red_sand"},
        {pos: [7, 1, 2], state: "minecraft:chiseled_red_sandstone"},
        {pos: [7, 1, 3], state: "minecraft:red_sand"},
        {pos: [7, 1, 4], state: "minecraft:red_sand"},
        {pos: [7, 1, 7], state: "minecraft:red_sand"},
        {pos: [7, 1, 8], state: "minecraft:red_sand"},
        {pos: [7, 1, 13], state: "minecraft:red_sand"},
        {pos: [7, 1, 14], state: "minecraft:cut_red_sandstone"},
        {pos: [7, 1, 15], state: "minecraft:red_sand"},
        {pos: [7, 1, 16], state: "minecraft:cut_red_sandstone"},
        {pos: [8, 1, 0], state: "minecraft:red_sand"},
        {pos: [8, 1, 1], state: "minecraft:red_sand"},
        {pos: [8, 1, 2], state: "minecraft:cut_red_sandstone"},
        {pos: [8, 1, 3], state: "minecraft:red_sand"},
        {pos: [8, 1, 4], state: "minecraft:red_sand"},
        {pos: [8, 1, 5], state: "minecraft:red_sand"},
        {pos: [8, 1, 6], state: "minecraft:red_sand"},
        {pos: [8, 1, 7], state: "minecraft:red_sand"},
        {pos: [8, 1, 8], state: "minecraft:red_sand"},
        {pos: [8, 1, 9], state: "minecraft:red_sand"},
        {pos: [8, 1, 12], state: "minecraft:red_sand"},
        {pos: [8, 1, 13], state: "minecraft:red_sand"},
        {pos: [8, 1, 14], state: "minecraft:red_sand"},
        {pos: [8, 1, 15], state: "minecraft:cut_red_sandstone"},
        {pos: [8, 1, 16], state: "minecraft:red_sand"},
        {pos: [9, 1, 0], state: "minecraft:red_sand"},
        {pos: [9, 1, 1], state: "minecraft:red_sand"},
        {pos: [9, 1, 2], state: "minecraft:cut_red_sandstone"},
        {pos: [9, 1, 3], state: "minecraft:red_sand"},
        {pos: [9, 1, 4], state: "minecraft:red_sand"},
        {pos: [9, 1, 5], state: "minecraft:red_sand"},
        {pos: [9, 1, 6], state: "minecraft:cut_red_sandstone"},
        {pos: [9, 1, 7], state: "minecraft:red_sand"},
        {pos: [9, 1, 8], state: "minecraft:red_sand"},
        {pos: [9, 1, 9], state: "minecraft:cut_red_sandstone"},
        {pos: [9, 1, 11], state: "minecraft:red_sand"},
        {pos: [9, 1, 12], state: "minecraft:red_sand"},
        {pos: [9, 1, 13], state: "minecraft:red_sand"},
        {pos: [9, 1, 14], state: "minecraft:red_sand"},
        {pos: [9, 1, 15], state: "minecraft:red_sand"},
        {pos: [10, 1, 1], state: "minecraft:red_sand"},
        {pos: [10, 1, 2], state: "minecraft:red_sand"},
        {pos: [10, 1, 3], state: "minecraft:red_sand"},
        {pos: [10, 1, 4], state: "minecraft:red_sand"},
        {pos: [10, 1, 5], state: "minecraft:red_sand"},
        {pos: [10, 1, 6], state: "minecraft:red_sand"},
        {pos: [10, 1, 7], state: "minecraft:red_sand"},
        {pos: [10, 1, 8], state: "minecraft:red_sand"},
        {pos: [10, 1, 9], state: "minecraft:red_sand"},
        {pos: [10, 1, 10], state: "minecraft:red_sand"},
        {pos: [10, 1, 11], state: "minecraft:red_sand"},
        {pos: [10, 1, 12], state: "minecraft:red_sand"},
        {pos: [11, 1, 6], state: "minecraft:cut_red_sandstone"},
        {pos: [11, 1, 7], state: "minecraft:cut_red_sandstone"},
        {pos: [11, 1, 8], state: "minecraft:cut_red_sandstone"},
        {pos: [11, 1, 9], state: "minecraft:red_sand"},
        {pos: [11, 1, 10], state: "minecraft:cut_red_sandstone"},
        {pos: [11, 1, 11], state: "minecraft:cut_red_sandstone"},
        {pos: [11, 1, 12], state: "minecraft:cut_red_sandstone"},
        {pos: [12, 1, 6], state: "minecraft:cut_red_sandstone"},
        {pos: [12, 1, 7], state: "minecraft:cut_red_sandstone"},
        {pos: [12, 1, 8], state: "minecraft:red_sand"},
        {pos: [12, 1, 9], state: "minecraft:red_sand"},
        {pos: [12, 1, 10], state: "minecraft:red_sand"},
        {pos: [12, 1, 11], state: "minecraft:red_sand"},
        {pos: [12, 1, 12], state: "minecraft:red_sand"},
        {pos: [13, 1, 6], state: "minecraft:cut_red_sandstone"},
        {pos: [13, 1, 7], state: "minecraft:cut_red_sandstone"},
        {pos: [13, 1, 8], state: "minecraft:red_sand"},
        {pos: [13, 1, 9], state: "minecraft:red_sand"},
        {pos: [13, 1, 10], state: "minecraft:red_sand"},
        {pos: [13, 1, 11], state: "minecraft:red_sand"},
        {pos: [13, 1, 12], state: "minecraft:red_sand"},
        {pos: [14, 1, 7], state: "minecraft:cut_red_sandstone"},
        {pos: [14, 1, 8], state: "minecraft:cut_red_sandstone"},
        {pos: [14, 1, 9], state: "minecraft:cut_red_sandstone"},
        {pos: [14, 1, 10], state: "minecraft:cut_red_sandstone"},
        {pos: [14, 1, 11], state: "minecraft:red_sand"},
        {pos: [0, 2, 6], state: "minecraft:red_sand"},
        {pos: [0, 2, 7], state: "minecraft:cut_red_sandstone"},
        {pos: [0, 2, 8], state: "minecraft:cut_red_sandstone"},
        {pos: [1, 2, 5], state: "minecraft:red_sand"},
        {pos: [1, 2, 6], state: "minecraft:cut_red_sandstone"},
        {pos: [1, 2, 7], state: "minecraft:red_sand"},
        {pos: [1, 2, 8], state: "minecraft:cut_red_sandstone"},
        {pos: [2, 2, 5], state: "minecraft:red_sand"},
        {pos: [2, 2, 6], state: "minecraft:cut_red_sandstone"},
        {pos: [2, 2, 7], state: "minecraft:red_sand"},
        {pos: [2, 2, 8], state: "minecraft:cut_red_sandstone"},
        {pos: [3, 2, 4], state: "minecraft:red_sand"},
        {pos: [3, 2, 5], state: "minecraft:red_sand"},
        {pos: [3, 2, 6], state: "minecraft:red_sand"},
        {pos: [3, 2, 7], state: "minecraft:red_sand"},
        {pos: [3, 2, 8], state: "minecraft:red_sand"},
        {pos: [3, 2, 9], state: "minecraft:red_sand"},
        {pos: [4, 2, 2], state: "minecraft:red_sand"},
        {pos: [4, 2, 3], state: "minecraft:red_sand"},
        {pos: [4, 2, 4], state: "minecraft:red_sand"},
        {pos: [4, 2, 5], state: "minecraft:red_sand"},
        {pos: [4, 2, 6], state: "minecraft:red_sand"},
        {pos: [4, 2, 7], state: "minecraft:red_sand"},
        {pos: [4, 2, 8], state: "minecraft:red_sand"},
        {pos: [4, 2, 9], state: "minecraft:cut_red_sandstone"},
        {pos: [4, 2, 10], state: "minecraft:red_sand"},
        {pos: [4, 2, 13], state: "minecraft:red_sand"},
        {pos: [4, 2, 14], state: "minecraft:red_sand"},
        {pos: [4, 2, 15], state: "minecraft:red_sand"},
        {pos: [4, 2, 16], state: "minecraft:red_sand"},
        {pos: [4, 2, 17], state: "minecraft:red_sand"},
        {pos: [5, 2, 1], state: "minecraft:red_sand"},
        {pos: [5, 2, 2], state: "minecraft:cut_red_sandstone"},
        {pos: [5, 2, 3], state: "minecraft:red_sand"},
        {pos: [5, 2, 4], state: "minecraft:red_sand"},
        {pos: [5, 2, 5], state: "minecraft:red_sand"},
        {pos: [5, 2, 6], state: "minecraft:cut_red_sandstone"},
        {pos: [5, 2, 7], state: "minecraft:red_sand"},
        {pos: [5, 2, 8], state: "minecraft:red_sand"},
        {pos: [5, 2, 9], state: "minecraft:red_sand"},
        {pos: [5, 2, 10], state: "minecraft:red_sand"},
        {pos: [5, 2, 11], state: "minecraft:red_sand"},
        {pos: [5, 2, 12], state: "minecraft:red_sand"},
        {pos: [5, 2, 13], state: "minecraft:red_sand"},
        {pos: [5, 2, 14], state: "minecraft:cut_red_sandstone"},
        {pos: [5, 2, 15], state: "minecraft:cut_red_sandstone"},
        {pos: [5, 2, 16], state: "minecraft:cut_red_sandstone"},
        {pos: [5, 2, 17], state: "minecraft:red_sand"},
        {pos: [6, 2, 1], state: "minecraft:red_sand"},
        {pos: [6, 2, 2], state: "minecraft:red_sand"},
        {pos: [6, 2, 3], state: "minecraft:red_sand"},
        {pos: [6, 2, 4], state: "minecraft:red_sand"},
        {pos: [6, 2, 5], state: "minecraft:red_sand"},
        {pos: [6, 2, 10], state: "minecraft:red_sand"},
        {pos: [6, 2, 11], state: "minecraft:red_sand"},
        {pos: [6, 2, 12], state: "minecraft:red_sand"},
        {pos: [6, 2, 13], state: "minecraft:red_sand"},
        {pos: [6, 2, 14], state: "minecraft:red_sand"},
        {pos: [6, 2, 15], state: "minecraft:red_sand"},
        {pos: [6, 2, 16], state: "minecraft:cut_red_sandstone"},
        {pos: [6, 2, 17], state: "minecraft:red_sand"},
        {pos: [7, 2, 0], state: "minecraft:red_sand"},
        {pos: [7, 2, 1], state: "minecraft:red_sand"},
        {pos: [7, 2, 2], state: "minecraft:red_sand"},
        {pos: [7, 2, 3], state: "minecraft:red_sand"},
        {pos: [7, 2, 4], state: "minecraft:red_sand"},
        {pos: [7, 2, 7], state: "minecraft:red_sand"},
        {pos: [7, 2, 8], state: "minecraft:red_sand"},
        {pos: [7, 2, 13], state: "minecraft:red_sand"},
        {pos: [7, 2, 14], state: "minecraft:cut_red_sandstone"},
        {pos: [7, 2, 15], state: "minecraft:red_sand"},
        {pos: [7, 2, 16], state: "minecraft:cut_red_sandstone"},
        {pos: [8, 2, 0], state: "minecraft:red_sand"},
        {pos: [8, 2, 1], state: "minecraft:red_sand"},
        {pos: [8, 2, 2], state: "minecraft:red_sand"},
        {pos: [8, 2, 3], state: "minecraft:red_sand"},
        {pos: [8, 2, 4], state: "minecraft:red_sand"},
        {pos: [8, 2, 5], state: "minecraft:red_sand"},
        {pos: [8, 2, 6], state: "minecraft:red_sand"},
        {pos: [8, 2, 7], state: "minecraft:red_sand"},
        {pos: [8, 2, 8], state: "minecraft:red_sand"},
        {pos: [8, 2, 9], state: "minecraft:red_sand"},
        {pos: [8, 2, 12], state: "minecraft:red_sand"},
        {pos: [8, 2, 13], state: "minecraft:red_sand"},
        {pos: [8, 2, 14], state: "minecraft:red_sand"},
        {pos: [8, 2, 15], state: "minecraft:cut_red_sandstone"},
        {pos: [8, 2, 16], state: "minecraft:red_sand"},
        {pos: [9, 2, 0], state: "minecraft:red_sand"},
        {pos: [9, 2, 1], state: "minecraft:red_sand"},
        {pos: [9, 2, 2], state: "minecraft:cut_red_sandstone"},
        {pos: [9, 2, 3], state: "minecraft:red_sand"},
        {pos: [9, 2, 4], state: "minecraft:red_sand"},
        {pos: [9, 2, 5], state: "minecraft:red_sand"},
        {pos: [9, 2, 6], state: "minecraft:cut_red_sandstone"},
        {pos: [9, 2, 7], state: "minecraft:red_sand"},
        {pos: [9, 2, 8], state: "minecraft:red_sand"},
        {pos: [9, 2, 9], state: "minecraft:cut_red_sandstone"},
        {pos: [9, 2, 11], state: "minecraft:red_sand"},
        {pos: [9, 2, 12], state: "minecraft:red_sand"},
        {pos: [9, 2, 13], state: "minecraft:red_sand"},
        {pos: [9, 2, 14], state: "minecraft:red_sand"},
        {pos: [9, 2, 15], state: "minecraft:red_sand"},
        {pos: [10, 2, 1], state: "minecraft:red_sand"},
        {pos: [10, 2, 2], state: "minecraft:red_sand"},
        {pos: [10, 2, 3], state: "minecraft:red_sand"},
        {pos: [10, 2, 4], state: "minecraft:red_sand"},
        {pos: [10, 2, 5], state: "minecraft:red_sand"},
        {pos: [10, 2, 6], state: "minecraft:red_sand"},
        {pos: [10, 2, 7], state: "minecraft:red_sand"},
        {pos: [10, 2, 8], state: "minecraft:red_sand"},
        {pos: [10, 2, 9], state: "minecraft:red_sand"},
        {pos: [10, 2, 10], state: "minecraft:red_sand"},
        {pos: [10, 2, 11], state: "minecraft:red_sand"},
        {pos: [10, 2, 12], state: "minecraft:red_sand"},
        {pos: [11, 2, 6], state: "minecraft:cut_red_sandstone"},
        {pos: [11, 2, 7], state: "minecraft:cut_red_sandstone"},
        {pos: [11, 2, 8], state: "minecraft:cut_red_sandstone"},
        {pos: [11, 2, 9], state: "minecraft:red_sand"},
        {pos: [11, 2, 10], state: "minecraft:cut_red_sandstone"},
        {pos: [11, 2, 11], state: "minecraft:cut_red_sandstone"},
        {pos: [11, 2, 12], state: "minecraft:red_sand"},
        {pos: [12, 2, 6], state: "minecraft:red_sand"},
        {pos: [12, 2, 7], state: "minecraft:cut_red_sandstone"},
        {pos: [12, 2, 8], state: "minecraft:red_sand"},
        {pos: [12, 2, 9], state: "minecraft:red_sand"},
        {pos: [12, 2, 10], state: "minecraft:red_sand"},
        {pos: [12, 2, 11], state: "minecraft:red_sand"},
        {pos: [12, 2, 12], state: "minecraft:red_sand"},
        {pos: [13, 2, 7], state: "minecraft:cut_red_sandstone"},
        {pos: [13, 2, 8], state: "minecraft:red_sand"},
        {pos: [13, 2, 9], state: "minecraft:red_sand"},
        {pos: [13, 2, 10], state: "minecraft:red_sand"},
        {pos: [13, 2, 11], state: "minecraft:red_sand"},
        {pos: [13, 2, 12], state: "minecraft:red_sand"},
        {pos: [14, 2, 7], state: "minecraft:cut_red_sandstone"},
        {pos: [14, 2, 8], state: "minecraft:cut_red_sandstone"},
        {pos: [14, 2, 9], state: "minecraft:cut_red_sandstone"},
        {pos: [14, 2, 10], state: "minecraft:red_sand"},
        {pos: [14, 2, 11], state: "minecraft:red_sand"},
        {pos: [0, 3, 6], state: "minecraft:red_sand"},
        {pos: [0, 3, 7], state: "minecraft:red_sand"},
        {pos: [0, 3, 8], state: "minecraft:red_sand"},
        {pos: [1, 3, 5], state: "minecraft:red_sand"},
        {pos: [1, 3, 6], state: "minecraft:red_sand"},
        {pos: [1, 3, 7], state: "minecraft:cut_red_sandstone"},
        {pos: [1, 3, 8], state: "minecraft:cut_red_sandstone"},
        {pos: [2, 3, 5], state: "minecraft:red_sand"},
        {pos: [2, 3, 6], state: "minecraft:cut_red_sandstone"},
        {pos: [2, 3, 7], state: "minecraft:cut_red_sandstone"},
        {pos: [2, 3, 8], state: "minecraft:red_sand"},
        {pos: [3, 3, 4], state: "minecraft:red_sand"},
        {pos: [3, 3, 5], state: "minecraft:red_sand"},
        {pos: [3, 3, 6], state: "minecraft:red_sand"},
        {pos: [3, 3, 7], state: "minecraft:red_sand"},
        {pos: [3, 3, 8], state: "minecraft:red_sand"},
        {pos: [3, 3, 9], state: "minecraft:red_sand"},
        {pos: [4, 3, 2], state: "minecraft:red_sand"},
        {pos: [4, 3, 3], state: "minecraft:red_sand"},
        {pos: [4, 3, 4], state: "minecraft:red_sand"},
        {pos: [4, 3, 5], state: "minecraft:red_sand"},
        {pos: [4, 3, 6], state: "minecraft:red_sand"},
        {pos: [4, 3, 7], state: "minecraft:red_sand"},
        {pos: [4, 3, 8], state: "minecraft:red_sand"},
        {pos: [4, 3, 9], state: "minecraft:red_sand"},
        {pos: [4, 3, 10], state: "minecraft:red_sand"},
        {pos: [4, 3, 13], state: "minecraft:red_sand"},
        {pos: [4, 3, 14], state: "minecraft:red_sand"},
        {pos: [4, 3, 15], state: "minecraft:red_sand"},
        {pos: [4, 3, 16], state: "minecraft:red_sand"},
        {pos: [4, 3, 17], state: "minecraft:red_sand"},
        {pos: [5, 3, 1], state: "minecraft:red_sand"},
        {pos: [5, 3, 2], state: "minecraft:red_sandstone_wall{east:tall,north:tall,south:tall,up:false,waterlogged:false,west:tall}"},
        {pos: [5, 3, 3], state: "minecraft:red_sand"},
        {pos: [5, 3, 4], state: "minecraft:red_sand"},
        {pos: [5, 3, 5], state: "minecraft:red_sand"},
        {pos: [5, 3, 6], state: "minecraft:red_sand"},
        {pos: [5, 3, 7], state: "minecraft:red_sand"},
        {pos: [5, 3, 8], state: "minecraft:red_sand"},
        {pos: [5, 3, 9], state: "minecraft:red_sand"},
        {pos: [5, 3, 10], state: "minecraft:red_sand"},
        {pos: [5, 3, 11], state: "minecraft:red_sand"},
        {pos: [5, 3, 12], state: "minecraft:red_sand"},
        {pos: [5, 3, 13], state: "minecraft:red_sand"},
        {pos: [5, 3, 14], state: "minecraft:cut_red_sandstone"},
        {pos: [5, 3, 15], state: "minecraft:cut_red_sandstone"},
        {pos: [5, 3, 16], state: "minecraft:red_sand"},
        {pos: [5, 3, 17], state: "minecraft:red_sand"},
        {pos: [6, 3, 1], state: "minecraft:red_sand"},
        {pos: [6, 3, 2], state: "minecraft:red_sand"},
        {pos: [6, 3, 3], state: "minecraft:red_sand"},
        {pos: [6, 3, 4], state: "minecraft:red_sand"},
        {pos: [6, 3, 5], state: "minecraft:red_sand"},
        {pos: [6, 3, 10], state: "minecraft:red_sand"},
        {pos: [6, 3, 11], state: "minecraft:red_sand"},
        {pos: [6, 3, 12], state: "minecraft:red_sand"},
        {pos: [6, 3, 13], state: "minecraft:red_sand"},
        {pos: [6, 3, 14], state: "minecraft:cut_red_sandstone"},
        {pos: [6, 3, 15], state: "minecraft:cut_red_sandstone"},
        {pos: [6, 3, 16], state: "minecraft:cut_red_sandstone"},
        {pos: [7, 3, 0], state: "minecraft:red_sand"},
        {pos: [7, 3, 1], state: "minecraft:red_sand"},
        {pos: [7, 3, 2], state: "minecraft:red_sand"},
        {pos: [7, 3, 3], state: "minecraft:red_sand"},
        {pos: [7, 3, 4], state: "minecraft:red_sand"},
        {pos: [7, 3, 13], state: "minecraft:red_sand"},
        {pos: [7, 3, 14], state: "minecraft:cut_red_sandstone"},
        {pos: [7, 3, 15], state: "minecraft:cut_red_sandstone"},
        {pos: [7, 3, 16], state: "minecraft:red_sand"},
        {pos: [8, 3, 0], state: "minecraft:red_sand"},
        {pos: [8, 3, 1], state: "minecraft:red_sand"},
        {pos: [8, 3, 2], state: "minecraft:red_sand"},
        {pos: [8, 3, 3], state: "minecraft:red_sand"},
        {pos: [8, 3, 4], state: "minecraft:red_sand"},
        {pos: [8, 3, 5], state: "minecraft:red_sand"},
        {pos: [8, 3, 6], state: "minecraft:red_sand"},
        {pos: [8, 3, 7], state: "minecraft:red_sand"},
        {pos: [8, 3, 8], state: "minecraft:red_sand"},
        {pos: [8, 3, 12], state: "minecraft:red_sand"},
        {pos: [8, 3, 13], state: "minecraft:red_sand"},
        {pos: [8, 3, 14], state: "minecraft:red_sand"},
        {pos: [8, 3, 15], state: "minecraft:red_sand"},
        {pos: [8, 3, 16], state: "minecraft:red_sand"},
        {pos: [9, 3, 0], state: "minecraft:red_sand"},
        {pos: [9, 3, 1], state: "minecraft:red_sand"},
        {pos: [9, 3, 2], state: "minecraft:cut_red_sandstone"},
        {pos: [9, 3, 3], state: "minecraft:red_sand"},
        {pos: [9, 3, 4], state: "minecraft:red_sand"},
        {pos: [9, 3, 5], state: "minecraft:red_sand"},
        {pos: [9, 3, 6], state: "minecraft:red_sand"},
        {pos: [9, 3, 7], state: "minecraft:red_sand"},
        {pos: [9, 3, 8], state: "minecraft:red_sand"},
        {pos: [9, 3, 9], state: "minecraft:red_sand"},
        {pos: [9, 3, 11], state: "minecraft:red_sand"},
        {pos: [9, 3, 12], state: "minecraft:red_sand"},
        {pos: [9, 3, 13], state: "minecraft:red_sand"},
        {pos: [9, 3, 14], state: "minecraft:red_sand"},
        {pos: [9, 3, 15], state: "minecraft:red_sand"},
        {pos: [10, 3, 1], state: "minecraft:red_sand"},
        {pos: [10, 3, 2], state: "minecraft:red_sand"},
        {pos: [10, 3, 3], state: "minecraft:red_sand"},
        {pos: [10, 3, 4], state: "minecraft:red_sand"},
        {pos: [10, 3, 5], state: "minecraft:red_sand"},
        {pos: [10, 3, 6], state: "minecraft:red_sand"},
        {pos: [10, 3, 7], state: "minecraft:red_sand"},
        {pos: [10, 3, 8], state: "minecraft:red_sand"},
        {pos: [10, 3, 9], state: "minecraft:red_sand"},
        {pos: [10, 3, 10], state: "minecraft:red_sand"},
        {pos: [10, 3, 11], state: "minecraft:red_sand"},
        {pos: [11, 3, 6], state: "minecraft:red_sand"},
        {pos: [11, 3, 7], state: "minecraft:cut_red_sandstone"},
        {pos: [11, 3, 8], state: "minecraft:cut_red_sandstone"},
        {pos: [11, 3, 9], state: "minecraft:cut_red_sandstone"},
        {pos: [11, 3, 10], state: "minecraft:cut_red_sandstone"},
        {pos: [11, 3, 11], state: "minecraft:red_sand"},
        {pos: [12, 3, 6], state: "minecraft:red_sand"},
        {pos: [12, 3, 7], state: "minecraft:cut_red_sandstone"},
        {pos: [12, 3, 8], state: "minecraft:cut_red_sandstone"},
        {pos: [12, 3, 9], state: "minecraft:cut_red_sandstone"},
        {pos: [12, 3, 10], state: "minecraft:red_sand"},
        {pos: [12, 3, 11], state: "minecraft:red_sand"},
        {pos: [13, 3, 7], state: "minecraft:cut_red_sandstone"},
        {pos: [13, 3, 8], state: "minecraft:cut_red_sandstone"},
        {pos: [13, 3, 9], state: "minecraft:red_sand"},
        {pos: [13, 3, 10], state: "minecraft:red_sand"},
        {pos: [14, 3, 8], state: "minecraft:red_sand"},
        {pos: [14, 3, 9], state: "minecraft:red_sand"},
        {pos: [0, 4, 6], state: "minecraft:red_sand"},
        {pos: [0, 4, 7], state: "minecraft:red_sand"},
        {pos: [1, 4, 5], state: "minecraft:red_sand"},
        {pos: [1, 4, 6], state: "minecraft:red_sand"},
        {pos: [1, 4, 7], state: "minecraft:red_sand"},
        {pos: [1, 4, 8], state: "minecraft:red_sand"},
        {pos: [2, 4, 5], state: "minecraft:red_sand"},
        {pos: [2, 4, 6], state: "minecraft:red_sand"},
        {pos: [2, 4, 7], state: "minecraft:red_sand"},
        {pos: [2, 4, 8], state: "minecraft:red_sand"},
        {pos: [3, 4, 6], state: "minecraft:red_sand"},
        {pos: [3, 4, 7], state: "minecraft:red_sand"},
        {pos: [4, 4, 2], state: "minecraft:red_sand"},
        {pos: [4, 4, 6], state: "minecraft:red_sand"},
        {pos: [4, 4, 14], state: "minecraft:red_sand"},
        {pos: [4, 4, 15], state: "minecraft:red_sand"},
        {pos: [5, 4, 1], state: "minecraft:red_sand"},
        {pos: [5, 4, 2], state: "minecraft:red_sand"},
        {pos: [5, 4, 3], state: "minecraft:red_sand"},
        {pos: [5, 4, 13], state: "minecraft:red_sand"},
        {pos: [5, 4, 14], state: "minecraft:red_sand"},
        {pos: [5, 4, 15], state: "minecraft:red_sand"},
        {pos: [5, 4, 16], state: "minecraft:red_sand"},
        {pos: [6, 4, 1], state: "minecraft:red_sand"},
        {pos: [6, 4, 2], state: "minecraft:red_sand"},
        {pos: [6, 4, 3], state: "minecraft:red_sand"},
        {pos: [6, 4, 12], state: "minecraft:red_sand"},
        {pos: [6, 4, 13], state: "minecraft:red_sand"},
        {pos: [6, 4, 14], state: "minecraft:red_sand"},
        {pos: [6, 4, 15], state: "minecraft:red_sand"},
        {pos: [6, 4, 16], state: "minecraft:red_sand"},
        {pos: [7, 4, 1], state: "minecraft:red_sand"},
        {pos: [7, 4, 13], state: "minecraft:red_sand"},
        {pos: [7, 4, 14], state: "minecraft:red_sand"},
        {pos: [7, 4, 15], state: "minecraft:red_sand"},
        {pos: [7, 4, 16], state: "minecraft:red_sand"},
        {pos: [8, 4, 13], state: "minecraft:red_sand"},
        {pos: [8, 4, 14], state: "minecraft:red_sand"},
        {pos: [8, 4, 15], state: "minecraft:red_sand"},
        {pos: [8, 4, 16], state: "minecraft:red_sand"},
        {pos: [9, 4, 2], state: "minecraft:air"},
        {pos: [10, 4, 8], state: "minecraft:red_sand"},
        {pos: [10, 4, 9], state: "minecraft:red_sand"},
        {pos: [10, 4, 10], state: "minecraft:red_sand"},
        {pos: [11, 4, 7], state: "minecraft:red_sand"},
        {pos: [11, 4, 8], state: "minecraft:red_sand"},
        {pos: [11, 4, 9], state: "minecraft:red_sand"},
        {pos: [11, 4, 10], state: "minecraft:red_sand"},
        {pos: [12, 4, 7], state: "minecraft:red_sand"},
        {pos: [12, 4, 8], state: "minecraft:red_sand"},
        {pos: [12, 4, 9], state: "minecraft:red_sand"},
        {pos: [12, 4, 10], state: "minecraft:red_sand"},
        {pos: [13, 4, 8], state: "minecraft:red_sand"}
    ],
    entities: [],
    palette: [
        "minecraft:cut_red_sandstone",
        "minecraft:yellow_glazed_terracotta{facing:north}",
        "minecraft:yellow_glazed_terracotta{facing:west}",
        "minecraft:yellow_glazed_terracotta{facing:east}",
        "minecraft:yellow_glazed_terracotta{facing:south}",
        "minecraft:orange_glazed_terracotta{facing:west}",
        "minecraft:orange_glazed_terracotta{facing:south}",
        "minecraft:orange_glazed_terracotta{facing:north}",
        "minecraft:orange_glazed_terracotta{facing:east}",
        "minecraft:red_sand",
        "minecraft:chiseled_red_sandstone",
        "minecraft:red_sandstone_wall{east:tall,north:tall,south:tall,up:false,waterlogged:false,west:tall}",
        "minecraft:air"
    ],
    trailiertales_DataVersion: 2
}
