{
    DataVersion: 3953,
    size: [22, 8, 9],
    data: [
        {pos: [0, 0, 4], state: "minecraft:stone_bricks"},
        {pos: [0, 0, 5], state: "minecraft:stone_bricks"},
        {pos: [1, 0, 3], state: "minecraft:stone_bricks"},
        {pos: [1, 0, 4], state: "minecraft:polished_andesite"},
        {pos: [1, 0, 5], state: "minecraft:stone_bricks"},
        {pos: [1, 0, 6], state: "minecraft:stone_bricks"},
        {pos: [2, 0, 2], state: "minecraft:stone_bricks"},
        {pos: [2, 0, 3], state: "minecraft:stone_bricks"},
        {pos: [2, 0, 4], state: "minecraft:stone_bricks"},
        {pos: [2, 0, 5], state: "minecraft:chiseled_stone_bricks"},
        {pos: [2, 0, 6], state: "minecraft:stone_bricks"},
        {pos: [3, 0, 1], state: "minecraft:stone_bricks"},
        {pos: [3, 0, 2], state: "minecraft:stone_bricks"},
        {pos: [3, 0, 3], state: "minecraft:stone_bricks"},
        {pos: [3, 0, 4], state: "minecraft:stone_bricks"},
        {pos: [3, 0, 5], state: "minecraft:stone_bricks"},
        {pos: [3, 0, 6], state: "minecraft:stone_bricks"},
        {pos: [3, 0, 7], state: "minecraft:stone_bricks"},
        {pos: [4, 0, 2], state: "minecraft:stone_bricks"},
        {pos: [4, 0, 3], state: "minecraft:polished_andesite"},
        {pos: [4, 0, 4], state: "minecraft:stone_bricks"},
        {pos: [4, 0, 5], state: "minecraft:stone_bricks"},
        {pos: [4, 0, 6], state: "minecraft:stone_bricks"},
        {pos: [4, 0, 7], state: "minecraft:stone_bricks"},
        {pos: [5, 0, 1], state: "minecraft:stone_bricks"},
        {pos: [5, 0, 2], state: "minecraft:stone_bricks"},
        {pos: [5, 0, 3], state: "minecraft:stone_bricks"},
        {pos: [5, 0, 4], state: "minecraft:stone_bricks"},
        {pos: [5, 0, 5], state: "minecraft:stone_bricks"},
        {pos: [5, 0, 6], state: "minecraft:stone_bricks"},
        {pos: [5, 0, 7], state: "minecraft:stone_bricks"},
        {pos: [6, 0, 2], state: "minecraft:stone_bricks"},
        {pos: [6, 0, 3], state: "minecraft:stone_bricks"},
        {pos: [6, 0, 4], state: "minecraft:stone_bricks"},
        {pos: [6, 0, 5], state: "minecraft:stone_bricks"},
        {pos: [6, 0, 6], state: "minecraft:stone_bricks"},
        {pos: [6, 0, 7], state: "minecraft:stone_bricks"},
        {pos: [7, 0, 3], state: "minecraft:stone_bricks"},
        {pos: [7, 0, 4], state: "minecraft:stone_bricks"},
        {pos: [7, 0, 5], state: "minecraft:stone_bricks"},
        {pos: [7, 0, 6], state: "minecraft:stone_bricks"},
        {pos: [7, 0, 7], state: "minecraft:stone_bricks"},
        {pos: [8, 0, 4], state: "minecraft:stone_bricks"},
        {pos: [8, 0, 5], state: "minecraft:stone_bricks"},
        {pos: [8, 0, 6], state: "minecraft:stone_bricks"},
        {pos: [9, 0, 5], state: "minecraft:stone_bricks"},
        {pos: [9, 0, 6], state: "minecraft:stone_bricks"},
        {pos: [9, 0, 7], state: "minecraft:stone_bricks"},
        {pos: [10, 0, 5], state: "minecraft:stone_bricks"},
        {pos: [10, 0, 6], state: "minecraft:stone_bricks"},
        {pos: [10, 0, 7], state: "minecraft:stone_bricks"},
        {pos: [10, 0, 8], state: "minecraft:stone_bricks"},
        {pos: [11, 0, 5], state: "minecraft:stone_bricks"},
        {pos: [11, 0, 6], state: "minecraft:stone_bricks"},
        {pos: [11, 0, 7], state: "minecraft:stone_bricks"},
        {pos: [11, 0, 8], state: "minecraft:stone_bricks"},
        {pos: [12, 0, 5], state: "minecraft:stone_bricks"},
        {pos: [12, 0, 6], state: "minecraft:stone_bricks"},
        {pos: [12, 0, 7], state: "minecraft:stone_bricks"},
        {pos: [13, 0, 5], state: "minecraft:stone_bricks"},
        {pos: [13, 0, 6], state: "minecraft:stone_bricks"},
        {pos: [14, 0, 3], state: "minecraft:stone_bricks"},
        {pos: [14, 0, 4], state: "minecraft:stone_bricks"},
        {pos: [14, 0, 5], state: "minecraft:stone_bricks"},
        {pos: [15, 0, 2], state: "minecraft:stone_bricks"},
        {pos: [15, 0, 3], state: "minecraft:stone_bricks"},
        {pos: [15, 0, 4], state: "minecraft:stone_bricks"},
        {pos: [15, 0, 5], state: "minecraft:stone_bricks"},
        {pos: [15, 0, 6], state: "minecraft:stone_bricks"},
        {pos: [15, 0, 7], state: "minecraft:stone_bricks"},
        {pos: [16, 0, 1], state: "minecraft:polished_andesite"},
        {pos: [16, 0, 2], state: "minecraft:stone_bricks"},
        {pos: [16, 0, 3], state: "minecraft:stone_bricks"},
        {pos: [16, 0, 4], state: "minecraft:stone_bricks"},
        {pos: [16, 0, 5], state: "minecraft:stone_bricks"},
        {pos: [16, 0, 6], state: "minecraft:stone_bricks"},
        {pos: [16, 0, 7], state: "minecraft:stone_bricks"},
        {pos: [16, 0, 8], state: "minecraft:polished_andesite"},
        {pos: [17, 0, 0], state: "minecraft:stone_bricks"},
        {pos: [17, 0, 1], state: "minecraft:stone_bricks"},
        {pos: [17, 0, 2], state: "minecraft:stone_bricks"},
        {pos: [17, 0, 3], state: "minecraft:stone_bricks"},
        {pos: [17, 0, 4], state: "minecraft:stone_bricks"},
        {pos: [17, 0, 5], state: "minecraft:stone_bricks"},
        {pos: [17, 0, 6], state: "minecraft:stone_bricks"},
        {pos: [17, 0, 7], state: "minecraft:stone_bricks"},
        {pos: [17, 0, 8], state: "minecraft:stone_bricks"},
        {pos: [18, 0, 0], state: "minecraft:stone_bricks"},
        {pos: [18, 0, 1], state: "minecraft:polished_andesite"},
        {pos: [18, 0, 2], state: "minecraft:stone_bricks"},
        {pos: [18, 0, 3], state: "minecraft:stone_bricks"},
        {pos: [18, 0, 4], state: "minecraft:stone_bricks"},
        {pos: [18, 0, 5], state: "minecraft:stone_bricks"},
        {pos: [18, 0, 6], state: "minecraft:stone_bricks"},
        {pos: [18, 0, 7], state: "minecraft:chiseled_stone_bricks"},
        {pos: [19, 0, 0], state: "minecraft:stone_bricks"},
        {pos: [19, 0, 1], state: "minecraft:stone_bricks"},
        {pos: [19, 0, 2], state: "minecraft:stone_bricks"},
        {pos: [19, 0, 3], state: "minecraft:stone_bricks"},
        {pos: [19, 0, 4], state: "minecraft:stone_bricks"},
        {pos: [19, 0, 5], state: "minecraft:stone_bricks"},
        {pos: [19, 0, 6], state: "minecraft:stone_bricks"},
        {pos: [19, 0, 7], state: "minecraft:stone_bricks"},
        {pos: [20, 0, 1], state: "minecraft:stone_bricks"},
        {pos: [20, 0, 2], state: "minecraft:stone_bricks"},
        {pos: [20, 0, 3], state: "minecraft:stone_bricks"},
        {pos: [20, 0, 4], state: "minecraft:stone_bricks"},
        {pos: [20, 0, 5], state: "minecraft:stone_bricks"},
        {pos: [20, 0, 6], state: "minecraft:stone_bricks"},
        {pos: [21, 0, 2], state: "minecraft:stone_bricks"},
        {pos: [21, 0, 3], state: "minecraft:stone_bricks"},
        {pos: [21, 0, 4], state: "minecraft:stone_bricks"},
        {pos: [21, 0, 5], state: "minecraft:stone_bricks"},
        {pos: [0, 1, 4], state: "minecraft:gravel"},
        {pos: [0, 1, 5], state: "minecraft:gravel"},
        {pos: [1, 1, 3], state: "minecraft:gravel"},
        {pos: [1, 1, 4], state: "minecraft:gravel"},
        {pos: [1, 1, 5], state: "minecraft:gravel"},
        {pos: [1, 1, 6], state: "minecraft:gravel"},
        {pos: [2, 1, 2], state: "minecraft:gravel"},
        {pos: [2, 1, 3], state: "minecraft:stone_bricks"},
        {pos: [2, 1, 4], state: "minecraft:stone_bricks"},
        {pos: [2, 1, 5], state: "minecraft:stone_bricks"},
        {pos: [2, 1, 6], state: "minecraft:gravel"},
        {pos: [3, 1, 1], state: "minecraft:gravel"},
        {pos: [3, 1, 2], state: "minecraft:stone_bricks"},
        {pos: [3, 1, 3], state: "minecraft:gravel"},
        {pos: [3, 1, 4], state: "minecraft:gravel"},
        {pos: [3, 1, 5], state: "minecraft:gravel"},
        {pos: [3, 1, 6], state: "minecraft:stone_bricks"},
        {pos: [3, 1, 7], state: "minecraft:gravel"},
        {pos: [4, 1, 2], state: "minecraft:gravel"},
        {pos: [4, 1, 3], state: "minecraft:gravel"},
        {pos: [4, 1, 4], state: "minecraft:gravel"},
        {pos: [4, 1, 5], state: "minecraft:gravel"},
        {pos: [4, 1, 6], state: "minecraft:stone_bricks"},
        {pos: [4, 1, 7], state: "minecraft:stone_bricks"},
        {pos: [5, 1, 1], state: "minecraft:gravel"},
        {pos: [5, 1, 2], state: "minecraft:stone_bricks"},
        {pos: [5, 1, 3], state: "minecraft:gravel"},
        {pos: [5, 1, 4], state: "minecraft:gravel"},
        {pos: [5, 1, 5], state: "minecraft:gravel"},
        {pos: [5, 1, 6], state: "minecraft:stone_bricks"},
        {pos: [5, 1, 7], state: "minecraft:stone_bricks"},
        {pos: [6, 1, 2], state: "minecraft:gravel"},
        {pos: [6, 1, 3], state: "minecraft:stone_bricks"},
        {pos: [6, 1, 4], state: "minecraft:stone_bricks"},
        {pos: [6, 1, 5], state: "minecraft:stone_bricks"},
        {pos: [6, 1, 6], state: "minecraft:gravel"},
        {pos: [6, 1, 7], state: "minecraft:gravel"},
        {pos: [7, 1, 3], state: "minecraft:gravel"},
        {pos: [7, 1, 4], state: "minecraft:gravel"},
        {pos: [7, 1, 5], state: "minecraft:gravel"},
        {pos: [7, 1, 6], state: "minecraft:gravel"},
        {pos: [7, 1, 7], state: "minecraft:gravel"},
        {pos: [8, 1, 4], state: "minecraft:gravel"},
        {pos: [8, 1, 5], state: "minecraft:gravel"},
        {pos: [8, 1, 6], state: "minecraft:gravel"},
        {pos: [9, 1, 5], state: "minecraft:gravel"},
        {pos: [9, 1, 6], state: "minecraft:gravel"},
        {pos: [9, 1, 7], state: "minecraft:gravel"},
        {pos: [10, 1, 5], state: "minecraft:stone_bricks"},
        {pos: [10, 1, 6], state: "minecraft:gravel"},
        {pos: [10, 1, 7], state: "minecraft:stone_bricks"},
        {pos: [10, 1, 8], state: "minecraft:gravel"},
        {pos: [11, 1, 5], state: "minecraft:gravel"},
        {pos: [11, 1, 6], state: "minecraft:stone_bricks"},
        {pos: [11, 1, 7], state: "minecraft:stone_bricks"},
        {pos: [11, 1, 8], state: "minecraft:gravel"},
        {pos: [12, 1, 5], state: "minecraft:gravel"},
        {pos: [12, 1, 6], state: "minecraft:gravel"},
        {pos: [12, 1, 7], state: "minecraft:gravel"},
        {pos: [13, 1, 5], state: "minecraft:gravel"},
        {pos: [13, 1, 6], state: "minecraft:gravel"},
        {pos: [14, 1, 3], state: "minecraft:gravel"},
        {pos: [14, 1, 4], state: "minecraft:gravel"},
        {pos: [14, 1, 5], state: "minecraft:gravel"},
        {pos: [15, 1, 2], state: "minecraft:gravel"},
        {pos: [15, 1, 3], state: "minecraft:gravel"},
        {pos: [15, 1, 4], state: "minecraft:gravel"},
        {pos: [15, 1, 5], state: "minecraft:gravel"},
        {pos: [15, 1, 6], state: "minecraft:gravel"},
        {pos: [15, 1, 7], state: "minecraft:gravel"},
        {pos: [16, 1, 1], state: "minecraft:gravel"},
        {pos: [16, 1, 2], state: "minecraft:gravel"},
        {pos: [16, 1, 3], state: "minecraft:stone_bricks"},
        {pos: [16, 1, 4], state: "minecraft:stone_bricks"},
        {pos: [16, 1, 5], state: "minecraft:stone_bricks"},
        {pos: [16, 1, 6], state: "minecraft:stone_bricks"},
        {pos: [16, 1, 7], state: "minecraft:gravel"},
        {pos: [16, 1, 8], state: "minecraft:gravel"},
        {pos: [17, 1, 0], state: "minecraft:stone_bricks"},
        {pos: [17, 1, 1], state: "minecraft:stone_bricks"},
        {pos: [17, 1, 2], state: "minecraft:stone_bricks"},
        {pos: [17, 1, 3], state: "minecraft:gravel"},
        {pos: [17, 1, 4], state: "minecraft:gravel"},
        {pos: [17, 1, 5], state: "minecraft:gravel"},
        {pos: [17, 1, 6], state: "minecraft:chiseled_stone_bricks"},
        {pos: [17, 1, 7], state: "minecraft:gravel"},
        {pos: [17, 1, 8], state: "minecraft:gravel"},
        {pos: [18, 1, 0], state: "minecraft:stone_bricks"},
        {pos: [18, 1, 1], state: "minecraft:stone_bricks"},
        {pos: [18, 1, 2], state: "minecraft:gravel"},
        {pos: [18, 1, 3], state: "minecraft:gravel"},
        {pos: [18, 1, 4], state: "minecraft:gravel"},
        {pos: [18, 1, 5], state: "minecraft:gravel"},
        {pos: [18, 1, 6], state: "minecraft:stone_bricks"},
        {pos: [18, 1, 7], state: "minecraft:gravel"},
        {pos: [19, 1, 0], state: "minecraft:chiseled_stone_bricks"},
        {pos: [19, 1, 1], state: "minecraft:stone_bricks"},
        {pos: [19, 1, 2], state: "minecraft:polished_andesite"},
        {pos: [19, 1, 3], state: "minecraft:stone_bricks"},
        {pos: [19, 1, 4], state: "minecraft:stone_bricks"},
        {pos: [19, 1, 5], state: "minecraft:stone_bricks"},
        {pos: [19, 1, 6], state: "minecraft:gravel"},
        {pos: [19, 1, 7], state: "minecraft:gravel"},
        {pos: [20, 1, 1], state: "minecraft:gravel"},
        {pos: [20, 1, 2], state: "minecraft:stone_bricks"},
        {pos: [20, 1, 3], state: "minecraft:stone_bricks"},
        {pos: [20, 1, 4], state: "minecraft:stone_bricks"},
        {pos: [20, 1, 5], state: "minecraft:gravel"},
        {pos: [20, 1, 6], state: "minecraft:gravel"},
        {pos: [21, 1, 2], state: "minecraft:gravel"},
        {pos: [21, 1, 3], state: "minecraft:gravel"},
        {pos: [21, 1, 4], state: "minecraft:gravel"},
        {pos: [21, 1, 5], state: "minecraft:gravel"},
        {pos: [0, 2, 4], state: "minecraft:gravel"},
        {pos: [0, 2, 5], state: "minecraft:gravel"},
        {pos: [1, 2, 3], state: "minecraft:gravel"},
        {pos: [1, 2, 4], state: "minecraft:gravel"},
        {pos: [1, 2, 5], state: "minecraft:gravel"},
        {pos: [1, 2, 6], state: "minecraft:gravel"},
        {pos: [2, 2, 2], state: "minecraft:gravel"},
        {pos: [2, 2, 3], state: "minecraft:stone_bricks"},
        {pos: [2, 2, 4], state: "minecraft:stone_bricks"},
        {pos: [2, 2, 5], state: "minecraft:stone_bricks"},
        {pos: [2, 2, 6], state: "minecraft:gravel"},
        {pos: [3, 2, 1], state: "minecraft:gravel"},
        {pos: [3, 2, 2], state: "minecraft:stone_bricks"},
        {pos: [3, 2, 3], state: "minecraft:gravel"},
        {pos: [3, 2, 4], state: "minecraft:gravel"},
        {pos: [3, 2, 5], state: "minecraft:gravel"},
        {pos: [3, 2, 6], state: "minecraft:stone_bricks"},
        {pos: [3, 2, 7], state: "minecraft:gravel"},
        {pos: [4, 2, 2], state: "minecraft:gravel"},
        {pos: [4, 2, 3], state: "minecraft:gravel"},
        {pos: [4, 2, 4], state: "minecraft:gravel"},
        {pos: [4, 2, 5], state: "minecraft:gravel"},
        {pos: [4, 2, 6], state: "minecraft:gravel"},
        {pos: [4, 2, 7], state: "minecraft:gravel"},
        {pos: [5, 2, 1], state: "minecraft:gravel"},
        {pos: [5, 2, 2], state: "minecraft:stone_bricks"},
        {pos: [5, 2, 3], state: "minecraft:gravel"},
        {pos: [5, 2, 4], state: "minecraft:gravel"},
        {pos: [5, 2, 5], state: "minecraft:gravel"},
        {pos: [5, 2, 6], state: "minecraft:stone_bricks"},
        {pos: [5, 2, 7], state: "minecraft:gravel"},
        {pos: [6, 2, 2], state: "minecraft:gravel"},
        {pos: [6, 2, 3], state: "minecraft:stone_bricks"},
        {pos: [6, 2, 4], state: "minecraft:gravel"},
        {pos: [6, 2, 5], state: "minecraft:stone_bricks"},
        {pos: [6, 2, 6], state: "minecraft:gravel"},
        {pos: [6, 2, 7], state: "minecraft:gravel"},
        {pos: [7, 2, 3], state: "minecraft:gravel"},
        {pos: [7, 2, 4], state: "minecraft:gravel"},
        {pos: [7, 2, 5], state: "minecraft:gravel"},
        {pos: [7, 2, 6], state: "minecraft:gravel"},
        {pos: [7, 2, 7], state: "minecraft:gravel"},
        {pos: [8, 2, 4], state: "minecraft:gravel"},
        {pos: [8, 2, 5], state: "minecraft:gravel"},
        {pos: [8, 2, 6], state: "minecraft:gravel"},
        {pos: [9, 2, 5], state: "minecraft:gravel"},
        {pos: [9, 2, 6], state: "minecraft:gravel"},
        {pos: [9, 2, 7], state: "minecraft:gravel"},
        {pos: [10, 2, 5], state: "minecraft:stone_bricks"},
        {pos: [10, 2, 6], state: "minecraft:gravel"},
        {pos: [10, 2, 7], state: "minecraft:stone_bricks"},
        {pos: [10, 2, 8], state: "minecraft:gravel"},
        {pos: [11, 2, 5], state: "minecraft:stone_bricks"},
        {pos: [11, 2, 6], state: "minecraft:polished_andesite"},
        {pos: [11, 2, 7], state: "minecraft:stone_bricks"},
        {pos: [11, 2, 8], state: "minecraft:gravel"},
        {pos: [12, 2, 5], state: "minecraft:gravel"},
        {pos: [12, 2, 6], state: "minecraft:gravel"},
        {pos: [12, 2, 7], state: "minecraft:gravel"},
        {pos: [13, 2, 5], state: "minecraft:gravel"},
        {pos: [13, 2, 6], state: "minecraft:gravel"},
        {pos: [14, 2, 3], state: "minecraft:gravel"},
        {pos: [14, 2, 4], state: "minecraft:gravel"},
        {pos: [14, 2, 5], state: "minecraft:gravel"},
        {pos: [15, 2, 2], state: "minecraft:gravel"},
        {pos: [15, 2, 3], state: "minecraft:gravel"},
        {pos: [15, 2, 4], state: "minecraft:gravel"},
        {pos: [15, 2, 5], state: "minecraft:gravel"},
        {pos: [15, 2, 6], state: "minecraft:gravel"},
        {pos: [15, 2, 7], state: "minecraft:gravel"},
        {pos: [16, 2, 1], state: "minecraft:gravel"},
        {pos: [16, 2, 2], state: "minecraft:stone_bricks"},
        {pos: [16, 2, 3], state: "minecraft:stone_bricks"},
        {pos: [16, 2, 4], state: "minecraft:stone_bricks"},
        {pos: [16, 2, 5], state: "minecraft:stone_bricks"},
        {pos: [16, 2, 6], state: "minecraft:stone_bricks"},
        {pos: [16, 2, 7], state: "minecraft:gravel"},
        {pos: [16, 2, 8], state: "minecraft:gravel"},
        {pos: [17, 2, 0], state: "minecraft:gravel"},
        {pos: [17, 2, 1], state: "minecraft:stone_bricks"},
        {pos: [17, 2, 2], state: "minecraft:gravel"},
        {pos: [17, 2, 3], state: "minecraft:gravel"},
        {pos: [17, 2, 4], state: "minecraft:gravel"},
        {pos: [17, 2, 5], state: "minecraft:gravel"},
        {pos: [17, 2, 6], state: "minecraft:stone_bricks"},
        {pos: [17, 2, 7], state: "minecraft:gravel"},
        {pos: [17, 2, 8], state: "minecraft:gravel"},
        {pos: [18, 2, 0], state: "minecraft:stone_bricks"},
        {pos: [18, 2, 1], state: "minecraft:polished_andesite"},
        {pos: [18, 2, 2], state: "minecraft:gravel"},
        {pos: [18, 2, 3], state: "minecraft:gravel"},
        {pos: [18, 2, 4], state: "minecraft:gravel"},
        {pos: [18, 2, 5], state: "minecraft:gravel"},
        {pos: [18, 2, 6], state: "minecraft:stone_bricks"},
        {pos: [18, 2, 7], state: "minecraft:gravel"},
        {pos: [19, 2, 0], state: "minecraft:gravel"},
        {pos: [19, 2, 1], state: "minecraft:stone_bricks"},
        {pos: [19, 2, 2], state: "minecraft:stone_bricks"},
        {pos: [19, 2, 3], state: "minecraft:stone_bricks"},
        {pos: [19, 2, 4], state: "minecraft:stone_bricks"},
        {pos: [19, 2, 5], state: "minecraft:stone_bricks"},
        {pos: [19, 2, 6], state: "minecraft:gravel"},
        {pos: [19, 2, 7], state: "minecraft:gravel"},
        {pos: [20, 2, 1], state: "minecraft:gravel"},
        {pos: [20, 2, 2], state: "minecraft:gravel"},
        {pos: [20, 2, 3], state: "minecraft:gravel"},
        {pos: [20, 2, 4], state: "minecraft:gravel"},
        {pos: [20, 2, 5], state: "minecraft:gravel"},
        {pos: [20, 2, 6], state: "minecraft:gravel"},
        {pos: [21, 2, 2], state: "minecraft:gravel"},
        {pos: [21, 2, 3], state: "minecraft:gravel"},
        {pos: [21, 2, 4], state: "minecraft:gravel"},
        {pos: [21, 2, 5], state: "minecraft:gravel"},
        {pos: [0, 3, 4], state: "minecraft:gravel"},
        {pos: [0, 3, 5], state: "minecraft:gravel"},
        {pos: [1, 3, 3], state: "minecraft:gravel"},
        {pos: [1, 3, 4], state: "minecraft:gravel"},
        {pos: [1, 3, 5], state: "minecraft:gravel"},
        {pos: [1, 3, 6], state: "minecraft:gravel"},
        {pos: [2, 3, 2], state: "minecraft:gravel"},
        {pos: [2, 3, 3], state: "minecraft:stone_bricks"},
        {pos: [2, 3, 4], state: "minecraft:stone_bricks"},
        {pos: [2, 3, 5], state: "minecraft:stone_bricks"},
        {pos: [2, 3, 6], state: "minecraft:gravel"},
        {pos: [3, 3, 1], state: "minecraft:gravel"},
        {pos: [3, 3, 2], state: "minecraft:stone_bricks"},
        {pos: [3, 3, 3], state: "minecraft:gravel"},
        {pos: [3, 3, 4], state: "minecraft:gravel"},
        {pos: [3, 3, 5], state: "minecraft:gravel"},
        {pos: [3, 3, 6], state: "minecraft:stone_bricks"},
        {pos: [3, 3, 7], state: "minecraft:gravel"},
        {pos: [4, 3, 2], state: "minecraft:stone_bricks"},
        {pos: [4, 3, 3], state: "minecraft:gravel"},
        {pos: [4, 3, 4], state: "minecraft:gravel"},
        {pos: [4, 3, 5], state: "minecraft:gravel"},
        {pos: [4, 3, 6], state: "minecraft:stone_bricks"},
        {pos: [4, 3, 7], state: "minecraft:gravel"},
        {pos: [5, 3, 1], state: "minecraft:gravel"},
        {pos: [5, 3, 2], state: "minecraft:chiseled_stone_bricks"},
        {pos: [5, 3, 3], state: "minecraft:gravel"},
        {pos: [5, 3, 4], state: "minecraft:gravel"},
        {pos: [5, 3, 5], state: "minecraft:gravel"},
        {pos: [5, 3, 6], state: "minecraft:stone_bricks"},
        {pos: [5, 3, 7], state: "minecraft:gravel"},
        {pos: [6, 3, 2], state: "minecraft:gravel"},
        {pos: [6, 3, 3], state: "minecraft:stone_bricks"},
        {pos: [6, 3, 4], state: "minecraft:stone_bricks"},
        {pos: [6, 3, 5], state: "minecraft:stone_bricks"},
        {pos: [6, 3, 6], state: "minecraft:gravel"},
        {pos: [6, 3, 7], state: "minecraft:gravel"},
        {pos: [7, 3, 3], state: "minecraft:gravel"},
        {pos: [7, 3, 4], state: "minecraft:gravel"},
        {pos: [7, 3, 5], state: "minecraft:gravel"},
        {pos: [7, 3, 6], state: "minecraft:gravel"},
        {pos: [7, 3, 7], state: "minecraft:gravel"},
        {pos: [8, 3, 4], state: "minecraft:gravel"},
        {pos: [8, 3, 5], state: "minecraft:gravel"},
        {pos: [8, 3, 6], state: "minecraft:gravel"},
        {pos: [9, 3, 5], state: "minecraft:gravel"},
        {pos: [9, 3, 6], state: "minecraft:gravel"},
        {pos: [9, 3, 7], state: "minecraft:gravel"},
        {pos: [10, 3, 5], state: "minecraft:stone_bricks"},
        {pos: [10, 3, 6], state: "minecraft:stone_bricks"},
        {pos: [10, 3, 7], state: "minecraft:stone_bricks"},
        {pos: [10, 3, 8], state: "minecraft:gravel"},
        {pos: [11, 3, 5], state: "minecraft:stone_bricks"},
        {pos: [11, 3, 6], state: "minecraft:stone_bricks"},
        {pos: [11, 3, 7], state: "minecraft:stone_bricks"},
        {pos: [11, 3, 8], state: "minecraft:gravel"},
        {pos: [12, 3, 5], state: "minecraft:gravel"},
        {pos: [12, 3, 6], state: "minecraft:stone_bricks"},
        {pos: [12, 3, 7], state: "minecraft:gravel"},
        {pos: [13, 3, 5], state: "minecraft:gravel"},
        {pos: [13, 3, 6], state: "minecraft:gravel"},
        {pos: [14, 3, 3], state: "minecraft:gravel"},
        {pos: [14, 3, 4], state: "minecraft:gravel"},
        {pos: [14, 3, 5], state: "minecraft:gravel"},
        {pos: [15, 3, 2], state: "minecraft:gravel"},
        {pos: [15, 3, 3], state: "minecraft:gravel"},
        {pos: [15, 3, 4], state: "minecraft:gravel"},
        {pos: [15, 3, 5], state: "minecraft:gravel"},
        {pos: [15, 3, 6], state: "minecraft:gravel"},
        {pos: [15, 3, 7], state: "minecraft:gravel"},
        {pos: [16, 3, 1], state: "minecraft:gravel"},
        {pos: [16, 3, 2], state: "minecraft:gravel"},
        {pos: [16, 3, 3], state: "minecraft:stone_bricks"},
        {pos: [16, 3, 4], state: "minecraft:stone_bricks"},
        {pos: [16, 3, 5], state: "minecraft:stone_bricks"},
        {pos: [16, 3, 6], state: "minecraft:gravel"},
        {pos: [16, 3, 7], state: "minecraft:gravel"},
        {pos: [16, 3, 8], state: "minecraft:gravel"},
        {pos: [17, 3, 0], state: "minecraft:gravel"},
        {pos: [17, 3, 1], state: "minecraft:stone_bricks"},
        {pos: [17, 3, 2], state: "minecraft:stone_bricks"},
        {pos: [17, 3, 3], state: "minecraft:stone_bricks"},
        {pos: [17, 3, 4], state: "minecraft:gravel"},
        {pos: [17, 3, 5], state: "minecraft:gravel"},
        {pos: [17, 3, 6], state: "minecraft:stone_bricks"},
        {pos: [17, 3, 7], state: "minecraft:gravel"},
        {pos: [17, 3, 8], state: "minecraft:gravel"},
        {pos: [18, 3, 0], state: "minecraft:gravel"},
        {pos: [18, 3, 1], state: "minecraft:stone_bricks"},
        {pos: [18, 3, 2], state: "minecraft:gravel"},
        {pos: [18, 3, 3], state: "minecraft:gravel"},
        {pos: [18, 3, 4], state: "minecraft:gravel"},
        {pos: [18, 3, 5], state: "minecraft:gravel"},
        {pos: [18, 3, 6], state: "minecraft:polished_andesite"},
        {pos: [18, 3, 7], state: "minecraft:gravel"},
        {pos: [19, 3, 0], state: "minecraft:gravel"},
        {pos: [19, 3, 1], state: "minecraft:stone_bricks"},
        {pos: [19, 3, 2], state: "minecraft:stone_bricks"},
        {pos: [19, 3, 3], state: "minecraft:stone_bricks"},
        {pos: [19, 3, 4], state: "minecraft:stone_bricks"},
        {pos: [19, 3, 5], state: "minecraft:stone_bricks"},
        {pos: [19, 3, 6], state: "minecraft:gravel"},
        {pos: [19, 3, 7], state: "minecraft:gravel"},
        {pos: [20, 3, 1], state: "minecraft:gravel"},
        {pos: [20, 3, 2], state: "minecraft:gravel"},
        {pos: [20, 3, 3], state: "minecraft:gravel"},
        {pos: [20, 3, 4], state: "minecraft:gravel"},
        {pos: [20, 3, 5], state: "minecraft:gravel"},
        {pos: [20, 3, 6], state: "minecraft:gravel"},
        {pos: [21, 3, 2], state: "minecraft:gravel"},
        {pos: [21, 3, 3], state: "minecraft:gravel"},
        {pos: [21, 3, 4], state: "minecraft:gravel"},
        {pos: [21, 3, 5], state: "minecraft:gravel"},
        {pos: [2, 4, 3], state: "minecraft:chiseled_stone_bricks"},
        {pos: [2, 4, 4], state: "minecraft:stone_bricks"},
        {pos: [2, 4, 5], state: "minecraft:stone_bricks"},
        {pos: [3, 4, 2], state: "minecraft:stone_bricks"},
        {pos: [3, 4, 3], state: "minecraft:gravel"},
        {pos: [3, 4, 4], state: "minecraft:gravel"},
        {pos: [3, 4, 5], state: "minecraft:stone_bricks"},
        {pos: [3, 4, 6], state: "minecraft:stone_bricks"},
        {pos: [3, 4, 7], state: "minecraft:gravel"},
        {pos: [4, 4, 2], state: "minecraft:stone_bricks"},
        {pos: [4, 4, 3], state: "minecraft:gravel"},
        {pos: [4, 4, 4], state: "minecraft:gravel"},
        {pos: [4, 4, 5], state: "minecraft:stone_bricks"},
        {pos: [4, 4, 6], state: "minecraft:stone_bricks"},
        {pos: [4, 4, 7], state: "minecraft:stone_bricks"},
        {pos: [5, 4, 2], state: "minecraft:stone_bricks"},
        {pos: [5, 4, 3], state: "minecraft:gravel"},
        {pos: [5, 4, 4], state: "minecraft:stone_bricks"},
        {pos: [5, 4, 5], state: "minecraft:stone_bricks"},
        {pos: [5, 4, 6], state: "minecraft:stone_bricks"},
        {pos: [5, 4, 7], state: "minecraft:stone_bricks"},
        {pos: [6, 4, 3], state: "minecraft:stone_bricks"},
        {pos: [6, 4, 4], state: "minecraft:stone_bricks"},
        {pos: [6, 4, 5], state: "minecraft:stone_bricks"},
        {pos: [6, 4, 6], state: "minecraft:stone_bricks"},
        {pos: [6, 4, 7], state: "minecraft:gravel"},
        {pos: [7, 4, 3], state: "minecraft:gravel"},
        {pos: [7, 4, 4], state: "minecraft:gravel"},
        {pos: [7, 4, 5], state: "minecraft:stone_bricks"},
        {pos: [7, 4, 6], state: "minecraft:gravel"},
        {pos: [7, 4, 7], state: "minecraft:gravel"},
        {pos: [8, 4, 4], state: "minecraft:gravel"},
        {pos: [8, 4, 5], state: "minecraft:gravel"},
        {pos: [8, 4, 6], state: "minecraft:gravel"},
        {pos: [9, 4, 5], state: "minecraft:stone_bricks"},
        {pos: [9, 4, 6], state: "minecraft:stone_bricks"},
        {pos: [9, 4, 7], state: "minecraft:stone_bricks"},
        {pos: [10, 4, 5], state: "minecraft:stone_bricks"},
        {pos: [10, 4, 6], state: "minecraft:stone_bricks"},
        {pos: [10, 4, 7], state: "minecraft:gravel"},
        {pos: [10, 4, 8], state: "minecraft:stone_bricks"},
        {pos: [11, 4, 5], state: "minecraft:stone_bricks"},
        {pos: [11, 4, 6], state: "minecraft:stone_bricks"},
        {pos: [11, 4, 7], state: "minecraft:stone_bricks"},
        {pos: [11, 4, 8], state: "minecraft:stone_bricks"},
        {pos: [12, 4, 5], state: "minecraft:stone_bricks"},
        {pos: [12, 4, 6], state: "minecraft:stone_bricks"},
        {pos: [12, 4, 7], state: "minecraft:stone_bricks"},
        {pos: [12, 4, 8], state: "minecraft:stone_bricks"},
        {pos: [13, 4, 5], state: "minecraft:gravel"},
        {pos: [13, 4, 6], state: "minecraft:gravel"},
        {pos: [13, 4, 7], state: "minecraft:stone_bricks"},
        {pos: [14, 4, 3], state: "minecraft:gravel"},
        {pos: [14, 4, 4], state: "minecraft:gravel"},
        {pos: [14, 4, 5], state: "minecraft:gravel"},
        {pos: [15, 4, 2], state: "minecraft:gravel"},
        {pos: [15, 4, 3], state: "minecraft:gravel"},
        {pos: [15, 4, 4], state: "minecraft:gravel"},
        {pos: [15, 4, 5], state: "minecraft:gravel"},
        {pos: [15, 4, 6], state: "minecraft:gravel"},
        {pos: [15, 4, 7], state: "minecraft:gravel"},
        {pos: [16, 4, 1], state: "minecraft:gravel"},
        {pos: [16, 4, 2], state: "minecraft:gravel"},
        {pos: [16, 4, 3], state: "minecraft:stone_bricks"},
        {pos: [16, 4, 4], state: "minecraft:stone_bricks"},
        {pos: [16, 4, 5], state: "minecraft:gravel"},
        {pos: [16, 4, 6], state: "minecraft:gravel"},
        {pos: [16, 4, 7], state: "minecraft:gravel"},
        {pos: [16, 4, 8], state: "minecraft:gravel"},
        {pos: [17, 4, 0], state: "minecraft:gravel"},
        {pos: [17, 4, 1], state: "minecraft:stone_bricks"},
        {pos: [17, 4, 2], state: "minecraft:polished_andesite"},
        {pos: [17, 4, 3], state: "minecraft:stone_bricks"},
        {pos: [17, 4, 4], state: "minecraft:stone_bricks"},
        {pos: [17, 4, 5], state: "minecraft:stone_bricks"},
        {pos: [17, 4, 6], state: "minecraft:gravel"},
        {pos: [17, 4, 7], state: "minecraft:gravel"},
        {pos: [17, 4, 8], state: "minecraft:gravel"},
        {pos: [18, 4, 0], state: "minecraft:gravel"},
        {pos: [18, 4, 1], state: "minecraft:stone_bricks"},
        {pos: [18, 4, 2], state: "minecraft:stone_bricks"},
        {pos: [18, 4, 3], state: "minecraft:stone_bricks"},
        {pos: [18, 4, 4], state: "minecraft:stone_bricks"},
        {pos: [18, 4, 5], state: "minecraft:stone_bricks"},
        {pos: [18, 4, 6], state: "minecraft:gravel"},
        {pos: [18, 4, 7], state: "minecraft:gravel"},
        {pos: [19, 4, 0], state: "minecraft:gravel"},
        {pos: [19, 4, 1], state: "minecraft:stone_bricks"},
        {pos: [19, 4, 2], state: "minecraft:stone_bricks"},
        {pos: [19, 4, 3], state: "minecraft:stone_bricks"},
        {pos: [19, 4, 4], state: "minecraft:gravel"},
        {pos: [19, 4, 5], state: "minecraft:gravel"},
        {pos: [19, 4, 6], state: "minecraft:gravel"},
        {pos: [19, 4, 7], state: "minecraft:gravel"},
        {pos: [20, 4, 1], state: "minecraft:gravel"},
        {pos: [20, 4, 2], state: "minecraft:gravel"},
        {pos: [20, 4, 3], state: "minecraft:gravel"},
        {pos: [20, 4, 4], state: "minecraft:gravel"},
        {pos: [20, 4, 5], state: "minecraft:gravel"},
        {pos: [20, 4, 6], state: "minecraft:gravel"},
        {pos: [21, 4, 2], state: "minecraft:gravel"},
        {pos: [21, 4, 3], state: "minecraft:gravel"},
        {pos: [21, 4, 4], state: "minecraft:gravel"},
        {pos: [21, 4, 5], state: "minecraft:gravel"},
        {pos: [2, 5, 3], state: "minecraft:stone_bricks"},
        {pos: [2, 5, 4], state: "minecraft:stone_bricks"},
        {pos: [2, 5, 5], state: "minecraft:stone_bricks"},
        {pos: [3, 5, 2], state: "minecraft:stone_bricks"},
        {pos: [3, 5, 3], state: "minecraft:stone_bricks"},
        {pos: [3, 5, 4], state: "minecraft:stone_bricks"},
        {pos: [3, 5, 5], state: "minecraft:stone_bricks"},
        {pos: [3, 5, 6], state: "minecraft:stone_bricks"},
        {pos: [3, 5, 7], state: "minecraft:gravel"},
        {pos: [4, 5, 2], state: "minecraft:stone_bricks"},
        {pos: [4, 5, 3], state: "minecraft:stone_bricks"},
        {pos: [4, 5, 4], state: "minecraft:gravel"},
        {pos: [4, 5, 5], state: "minecraft:gravel"},
        {pos: [4, 5, 6], state: "minecraft:stone_bricks"},
        {pos: [4, 5, 7], state: "minecraft:stone_bricks"},
        {pos: [4, 5, 8], state: "minecraft:stone_bricks"},
        {pos: [5, 5, 2], state: "minecraft:stone_bricks"},
        {pos: [5, 5, 3], state: "minecraft:stone_bricks"},
        {pos: [5, 5, 4], state: "minecraft:stone_bricks"},
        {pos: [5, 5, 5], state: "minecraft:stone_bricks"},
        {pos: [5, 5, 6], state: "minecraft:chiseled_stone_bricks"},
        {pos: [5, 5, 7], state: "minecraft:stone_bricks"},
        {pos: [5, 5, 8], state: "minecraft:stone_bricks"},
        {pos: [6, 5, 3], state: "minecraft:stone_bricks"},
        {pos: [6, 5, 4], state: "minecraft:stone_bricks"},
        {pos: [6, 5, 5], state: "minecraft:stone_bricks"},
        {pos: [6, 5, 6], state: "minecraft:stone_bricks"},
        {pos: [6, 5, 7], state: "minecraft:stone_bricks"},
        {pos: [6, 5, 8], state: "minecraft:stone_bricks"},
        {pos: [7, 5, 5], state: "minecraft:stone_bricks"},
        {pos: [7, 5, 6], state: "minecraft:stone_bricks"},
        {pos: [7, 5, 7], state: "minecraft:stone_bricks"},
        {pos: [7, 5, 8], state: "minecraft:chiseled_stone_bricks"},
        {pos: [8, 5, 5], state: "minecraft:stone_bricks"},
        {pos: [8, 5, 6], state: "minecraft:stone_bricks"},
        {pos: [8, 5, 7], state: "minecraft:stone_bricks"},
        {pos: [8, 5, 8], state: "minecraft:stone_bricks"},
        {pos: [9, 5, 5], state: "minecraft:stone_bricks"},
        {pos: [9, 5, 6], state: "minecraft:stone_bricks"},
        {pos: [9, 5, 7], state: "minecraft:stone_bricks"},
        {pos: [9, 5, 8], state: "minecraft:stone_bricks"},
        {pos: [10, 5, 5], state: "minecraft:stone_bricks"},
        {pos: [10, 5, 6], state: "minecraft:stone_bricks"},
        {pos: [10, 5, 7], state: "minecraft:gravel"},
        {pos: [10, 5, 8], state: "minecraft:stone_bricks"},
        {pos: [11, 5, 5], state: "minecraft:stone_bricks"},
        {pos: [11, 5, 6], state: "minecraft:stone_bricks"},
        {pos: [11, 5, 7], state: "minecraft:stone_bricks"},
        {pos: [11, 5, 8], state: "minecraft:stone_bricks"},
        {pos: [12, 5, 5], state: "minecraft:stone_bricks"},
        {pos: [12, 5, 6], state: "minecraft:stone_bricks"},
        {pos: [12, 5, 7], state: "minecraft:stone_bricks"},
        {pos: [12, 5, 8], state: "minecraft:stone_bricks"},
        {pos: [13, 5, 5], state: "minecraft:stone_bricks"},
        {pos: [13, 5, 6], state: "minecraft:stone_bricks"},
        {pos: [13, 5, 7], state: "minecraft:stone_bricks"},
        {pos: [13, 5, 8], state: "minecraft:stone_bricks"},
        {pos: [14, 5, 4], state: "minecraft:gravel"},
        {pos: [14, 5, 5], state: "minecraft:stone_bricks"},
        {pos: [14, 5, 6], state: "minecraft:stone_bricks"},
        {pos: [14, 5, 7], state: "minecraft:stone_bricks"},
        {pos: [14, 5, 8], state: "minecraft:stone_bricks"},
        {pos: [15, 5, 4], state: "minecraft:gravel"},
        {pos: [15, 5, 5], state: "minecraft:chiseled_stone_bricks"},
        {pos: [15, 5, 6], state: "minecraft:stone_bricks"},
        {pos: [15, 5, 7], state: "minecraft:stone_bricks"},
        {pos: [15, 5, 8], state: "minecraft:stone_bricks"},
        {pos: [16, 5, 3], state: "minecraft:gravel"},
        {pos: [16, 5, 4], state: "minecraft:gravel"},
        {pos: [16, 5, 5], state: "minecraft:stone_bricks"},
        {pos: [16, 5, 6], state: "minecraft:stone_bricks"},
        {pos: [16, 5, 7], state: "minecraft:stone_bricks"},
        {pos: [16, 5, 8], state: "minecraft:stone_bricks"},
        {pos: [17, 5, 1], state: "minecraft:gravel"},
        {pos: [17, 5, 2], state: "minecraft:gravel"},
        {pos: [17, 5, 3], state: "minecraft:gravel"},
        {pos: [17, 5, 4], state: "minecraft:stone_bricks"},
        {pos: [17, 5, 5], state: "minecraft:stone_bricks"},
        {pos: [17, 5, 6], state: "minecraft:stone_bricks"},
        {pos: [17, 5, 7], state: "minecraft:stone_bricks"},
        {pos: [17, 5, 8], state: "minecraft:stone_bricks"},
        {pos: [18, 5, 1], state: "minecraft:gravel"},
        {pos: [18, 5, 2], state: "minecraft:gravel"},
        {pos: [18, 5, 3], state: "minecraft:stone_bricks"},
        {pos: [18, 5, 4], state: "minecraft:stone_bricks"},
        {pos: [18, 5, 5], state: "minecraft:stone_bricks"},
        {pos: [18, 5, 6], state: "minecraft:stone_bricks"},
        {pos: [18, 5, 7], state: "minecraft:stone_bricks"},
        {pos: [18, 5, 8], state: "minecraft:stone_bricks"},
        {pos: [19, 5, 1], state: "minecraft:gravel"},
        {pos: [19, 5, 2], state: "minecraft:gravel"},
        {pos: [19, 5, 3], state: "minecraft:stone_bricks"},
        {pos: [19, 5, 4], state: "minecraft:stone_bricks"},
        {pos: [19, 5, 5], state: "minecraft:stone_bricks"},
        {pos: [19, 5, 6], state: "minecraft:stone_bricks"},
        {pos: [19, 5, 7], state: "minecraft:stone_bricks"},
        {pos: [19, 5, 8], state: "minecraft:stone_bricks"},
        {pos: [20, 5, 2], state: "minecraft:stone_bricks"},
        {pos: [20, 5, 3], state: "minecraft:stone_bricks"},
        {pos: [20, 5, 4], state: "minecraft:stone_bricks"},
        {pos: [20, 5, 5], state: "minecraft:stone_bricks"},
        {pos: [20, 5, 6], state: "minecraft:stone_bricks"},
        {pos: [20, 5, 7], state: "minecraft:stone_bricks"},
        {pos: [20, 5, 8], state: "minecraft:stone_bricks"},
        {pos: [21, 5, 3], state: "minecraft:gravel"},
        {pos: [21, 5, 4], state: "minecraft:gravel"},
        {pos: [21, 5, 5], state: "minecraft:gravel"},
        {pos: [2, 6, 3], state: "minecraft:gravel"},
        {pos: [2, 6, 4], state: "minecraft:stone_bricks"},
        {pos: [2, 6, 5], state: "minecraft:stone_bricks"},
        {pos: [3, 6, 2], state: "minecraft:gravel"},
        {pos: [3, 6, 3], state: "minecraft:gravel"},
        {pos: [3, 6, 4], state: "minecraft:stone_bricks"},
        {pos: [3, 6, 5], state: "minecraft:stone_bricks"},
        {pos: [3, 6, 6], state: "minecraft:stone_bricks"},
        {pos: [4, 6, 2], state: "minecraft:gravel"},
        {pos: [4, 6, 3], state: "minecraft:stone_bricks"},
        {pos: [4, 6, 4], state: "minecraft:polished_andesite"},
        {pos: [4, 6, 5], state: "minecraft:gravel"},
        {pos: [4, 6, 6], state: "minecraft:stone_bricks"},
        {pos: [4, 6, 7], state: "minecraft:stone_bricks"},
        {pos: [4, 6, 8], state: "minecraft:stone_bricks"},
        {pos: [5, 6, 2], state: "minecraft:stone_bricks"},
        {pos: [5, 6, 3], state: "minecraft:stone_bricks"},
        {pos: [5, 6, 4], state: "minecraft:stone_bricks"},
        {pos: [5, 6, 5], state: "minecraft:stone_bricks"},
        {pos: [5, 6, 6], state: "minecraft:stone_bricks"},
        {pos: [5, 6, 7], state: "minecraft:gravel"},
        {pos: [5, 6, 8], state: "minecraft:stone_bricks"},
        {pos: [6, 6, 3], state: "minecraft:stone_bricks"},
        {pos: [6, 6, 4], state: "minecraft:stone_bricks"},
        {pos: [6, 6, 5], state: "minecraft:stone_bricks"},
        {pos: [6, 6, 6], state: "minecraft:gravel"},
        {pos: [6, 6, 7], state: "minecraft:gravel"},
        {pos: [6, 6, 8], state: "minecraft:gravel"},
        {pos: [7, 6, 5], state: "minecraft:stone_bricks"},
        {pos: [7, 6, 6], state: "minecraft:gravel"},
        {pos: [7, 6, 7], state: "minecraft:gravel"},
        {pos: [7, 6, 8], state: "minecraft:gravel"},
        {pos: [8, 6, 5], state: "minecraft:polished_andesite"},
        {pos: [8, 6, 6], state: "minecraft:gravel"},
        {pos: [8, 6, 7], state: "minecraft:gravel"},
        {pos: [8, 6, 8], state: "minecraft:stone_bricks"},
        {pos: [9, 6, 5], state: "minecraft:gravel"},
        {pos: [9, 6, 6], state: "minecraft:gravel"},
        {pos: [9, 6, 7], state: "minecraft:gravel"},
        {pos: [9, 6, 8], state: "minecraft:stone_bricks"},
        {pos: [10, 6, 5], state: "minecraft:gravel"},
        {pos: [10, 6, 6], state: "minecraft:gravel"},
        {pos: [11, 6, 5], state: "minecraft:gravel"},
        {pos: [11, 6, 6], state: "minecraft:gravel"},
        {pos: [11, 6, 7], state: "minecraft:gravel"},
        {pos: [11, 6, 8], state: "minecraft:gravel"},
        {pos: [12, 6, 5], state: "minecraft:polished_andesite"},
        {pos: [12, 6, 7], state: "minecraft:gravel"},
        {pos: [12, 6, 8], state: "minecraft:gravel"},
        {pos: [13, 6, 6], state: "minecraft:gravel"},
        {pos: [13, 6, 7], state: "minecraft:gravel"},
        {pos: [13, 6, 8], state: "minecraft:polished_andesite"},
        {pos: [14, 6, 5], state: "minecraft:stone_bricks"},
        {pos: [14, 6, 6], state: "minecraft:gravel"},
        {pos: [14, 6, 7], state: "minecraft:gravel"},
        {pos: [14, 6, 8], state: "minecraft:stone_bricks"},
        {pos: [15, 6, 5], state: "minecraft:gravel"},
        {pos: [15, 6, 6], state: "minecraft:gravel"},
        {pos: [15, 6, 7], state: "minecraft:gravel"},
        {pos: [15, 6, 8], state: "minecraft:gravel"},
        {pos: [16, 6, 5], state: "minecraft:stone_bricks"},
        {pos: [16, 6, 6], state: "minecraft:gravel"},
        {pos: [16, 6, 7], state: "minecraft:gravel"},
        {pos: [16, 6, 8], state: "minecraft:stone_bricks"},
        {pos: [17, 6, 4], state: "minecraft:gravel"},
        {pos: [17, 6, 5], state: "minecraft:stone_bricks"},
        {pos: [17, 6, 6], state: "minecraft:gravel"},
        {pos: [17, 6, 7], state: "minecraft:gravel"},
        {pos: [18, 6, 3], state: "minecraft:gravel"},
        {pos: [18, 6, 4], state: "minecraft:gravel"},
        {pos: [18, 6, 5], state: "minecraft:gravel"},
        {pos: [18, 6, 6], state: "minecraft:gravel"},
        {pos: [18, 6, 7], state: "minecraft:gravel"},
        {pos: [19, 6, 3], state: "minecraft:gravel"},
        {pos: [19, 6, 4], state: "minecraft:gravel"},
        {pos: [19, 6, 5], state: "minecraft:gravel"},
        {pos: [19, 6, 6], state: "minecraft:gravel"},
        {pos: [19, 6, 7], state: "minecraft:gravel"},
        {pos: [19, 6, 8], state: "minecraft:stone_bricks"},
        {pos: [20, 6, 2], state: "minecraft:stone_bricks"},
        {pos: [20, 6, 3], state: "minecraft:stone_bricks"},
        {pos: [20, 6, 4], state: "minecraft:stone_bricks"},
        {pos: [20, 6, 5], state: "minecraft:stone_bricks"},
        {pos: [20, 6, 6], state: "minecraft:gravel"},
        {pos: [20, 6, 7], state: "minecraft:stone_bricks"},
        {pos: [20, 6, 8], state: "minecraft:chiseled_stone_bricks"},
        {pos: [21, 6, 4], state: "minecraft:gravel"},
        {pos: [21, 6, 5], state: "minecraft:gravel"},
        {pos: [3, 7, 4], state: "minecraft:gravel"},
        {pos: [3, 7, 5], state: "minecraft:gravel"},
        {pos: [4, 7, 3], state: "minecraft:gravel"},
        {pos: [4, 7, 4], state: "minecraft:gravel"},
        {pos: [4, 7, 5], state: "minecraft:gravel"},
        {pos: [4, 7, 6], state: "minecraft:gravel"},
        {pos: [5, 7, 3], state: "minecraft:gravel"},
        {pos: [5, 7, 4], state: "minecraft:gravel"},
        {pos: [5, 7, 5], state: "minecraft:gravel"},
        {pos: [5, 7, 6], state: "minecraft:gravel"},
        {pos: [5, 7, 7], state: "minecraft:gravel"},
        {pos: [6, 7, 4], state: "minecraft:gravel"},
        {pos: [6, 7, 5], state: "minecraft:gravel"},
        {pos: [6, 7, 6], state: "minecraft:gravel"},
        {pos: [6, 7, 7], state: "minecraft:gravel"},
        {pos: [7, 7, 6], state: "minecraft:gravel"},
        {pos: [7, 7, 7], state: "minecraft:gravel"},
        {pos: [8, 7, 6], state: "minecraft:gravel"},
        {pos: [14, 7, 7], state: "minecraft:gravel"},
        {pos: [14, 7, 8], state: "minecraft:gravel"},
        {pos: [15, 7, 6], state: "minecraft:gravel"},
        {pos: [15, 7, 7], state: "minecraft:gravel"},
        {pos: [15, 7, 8], state: "minecraft:gravel"},
        {pos: [16, 7, 6], state: "minecraft:gravel"},
        {pos: [16, 7, 7], state: "minecraft:gravel"},
        {pos: [17, 7, 5], state: "minecraft:gravel"},
        {pos: [18, 7, 4], state: "minecraft:gravel"},
        {pos: [18, 7, 5], state: "minecraft:gravel"},
        {pos: [19, 7, 4], state: "minecraft:gravel"},
        {pos: [19, 7, 5], state: "minecraft:gravel"},
        {pos: [19, 7, 6], state: "minecraft:gravel"},
        {pos: [20, 7, 4], state: "minecraft:gravel"},
        {pos: [20, 7, 5], state: "minecraft:gravel"}
    ],
    entities: [],
    palette: [
        "minecraft:stone_bricks",
        "minecraft:polished_andesite",
        "minecraft:chiseled_stone_bricks",
        "minecraft:gravel"
    ],
    trailiertales_DataVersion: 2
}
