{
    DataVersion: 3953,
    size: [14, 9, 20],
    data: [
        {pos: [0, 0, 4], state: "minecraft:stone_bricks"},
        {pos: [0, 0, 5], state: "minecraft:stone_bricks"},
        {pos: [1, 0, 3], state: "minecraft:stone_bricks"},
        {pos: [1, 0, 4], state: "minecraft:stone_bricks"},
        {pos: [1, 0, 5], state: "minecraft:stone_bricks"},
        {pos: [1, 0, 6], state: "minecraft:stone_bricks"},
        {pos: [1, 0, 7], state: "minecraft:stone_bricks"},
        {pos: [1, 0, 8], state: "minecraft:stone_bricks"},
        {pos: [2, 0, 2], state: "minecraft:stone_bricks"},
        {pos: [2, 0, 3], state: "minecraft:stone_bricks"},
        {pos: [2, 0, 4], state: "minecraft:stone_bricks"},
        {pos: [2, 0, 5], state: "minecraft:stone_bricks"},
        {pos: [2, 0, 6], state: "minecraft:stone_bricks"},
        {pos: [2, 0, 7], state: "minecraft:stone_bricks"},
        {pos: [2, 0, 15], state: "minecraft:stone_bricks"},
        {pos: [2, 0, 16], state: "minecraft:stone_bricks"},
        {pos: [3, 0, 2], state: "minecraft:stone_bricks"},
        {pos: [3, 0, 3], state: "minecraft:stone_bricks"},
        {pos: [3, 0, 4], state: "minecraft:stone_bricks"},
        {pos: [3, 0, 5], state: "minecraft:stone_bricks"},
        {pos: [3, 0, 12], state: "minecraft:stone_bricks"},
        {pos: [3, 0, 13], state: "minecraft:stone_bricks"},
        {pos: [3, 0, 14], state: "minecraft:gravel"},
        {pos: [3, 0, 15], state: "minecraft:stone_bricks"},
        {pos: [3, 0, 16], state: "minecraft:stone_bricks"},
        {pos: [4, 0, 2], state: "minecraft:stone_bricks"},
        {pos: [4, 0, 3], state: "minecraft:stone_bricks"},
        {pos: [4, 0, 4], state: "minecraft:stone_bricks"},
        {pos: [4, 0, 10], state: "minecraft:stone_bricks"},
        {pos: [4, 0, 11], state: "minecraft:stone_bricks"},
        {pos: [4, 0, 12], state: "minecraft:stone_bricks"},
        {pos: [4, 0, 13], state: "minecraft:stone_bricks"},
        {pos: [4, 0, 14], state: "minecraft:gravel"},
        {pos: [4, 0, 15], state: "minecraft:stone_bricks"},
        {pos: [4, 0, 16], state: "minecraft:stone_bricks"},
        {pos: [4, 0, 17], state: "minecraft:stone_bricks"},
        {pos: [5, 0, 2], state: "minecraft:stone_bricks"},
        {pos: [5, 0, 3], state: "minecraft:stone_bricks"},
        {pos: [5, 0, 9], state: "minecraft:polished_andesite"},
        {pos: [5, 0, 10], state: "minecraft:stone_bricks"},
        {pos: [5, 0, 11], state: "minecraft:stone_bricks"},
        {pos: [5, 0, 12], state: "minecraft:stone_bricks"},
        {pos: [5, 0, 13], state: "minecraft:stone_bricks"},
        {pos: [5, 0, 14], state: "minecraft:polished_andesite"},
        {pos: [5, 0, 15], state: "minecraft:stone_bricks"},
        {pos: [5, 0, 16], state: "minecraft:stone_bricks"},
        {pos: [5, 0, 17], state: "minecraft:stone_bricks"},
        {pos: [5, 0, 18], state: "minecraft:stone_bricks"},
        {pos: [6, 0, 2], state: "minecraft:stone_bricks"},
        {pos: [6, 0, 3], state: "minecraft:polished_andesite"},
        {pos: [6, 0, 10], state: "minecraft:stone_bricks"},
        {pos: [6, 0, 11], state: "minecraft:stone_bricks"},
        {pos: [6, 0, 12], state: "minecraft:stone_bricks"},
        {pos: [6, 0, 13], state: "minecraft:stone_bricks"},
        {pos: [6, 0, 14], state: "minecraft:stone_bricks"},
        {pos: [6, 0, 15], state: "minecraft:stone_bricks"},
        {pos: [6, 0, 16], state: "minecraft:stone_bricks"},
        {pos: [6, 0, 17], state: "minecraft:stone_bricks"},
        {pos: [6, 0, 18], state: "minecraft:stone_bricks"},
        {pos: [7, 0, 13], state: "minecraft:stone_bricks"},
        {pos: [7, 0, 14], state: "minecraft:stone_bricks"},
        {pos: [7, 0, 15], state: "minecraft:stone_bricks"},
        {pos: [7, 0, 16], state: "minecraft:polished_andesite"},
        {pos: [7, 0, 17], state: "minecraft:stone_bricks"},
        {pos: [7, 0, 18], state: "minecraft:stone_bricks"},
        {pos: [7, 0, 19], state: "minecraft:stone_bricks"},
        {pos: [8, 0, 0], state: "minecraft:polished_andesite"},
        {pos: [8, 0, 1], state: "minecraft:stone_bricks"},
        {pos: [8, 0, 2], state: "minecraft:polished_andesite"},
        {pos: [8, 0, 13], state: "minecraft:stone_bricks"},
        {pos: [8, 0, 15], state: "minecraft:stone_bricks"},
        {pos: [8, 0, 16], state: "minecraft:stone_bricks"},
        {pos: [8, 0, 17], state: "minecraft:stone_bricks"},
        {pos: [8, 0, 18], state: "minecraft:stone_bricks"},
        {pos: [8, 0, 19], state: "minecraft:stone_bricks"},
        {pos: [9, 0, 0], state: "minecraft:polished_andesite"},
        {pos: [9, 0, 1], state: "minecraft:chiseled_stone_bricks"},
        {pos: [9, 0, 2], state: "minecraft:stone_bricks"},
        {pos: [9, 0, 6], state: "minecraft:stone_bricks"},
        {pos: [9, 0, 9], state: "minecraft:chiseled_stone_bricks"},
        {pos: [9, 0, 16], state: "minecraft:stone_bricks"},
        {pos: [9, 0, 17], state: "minecraft:stone_bricks"},
        {pos: [9, 0, 18], state: "minecraft:stone_bricks"},
        {pos: [10, 0, 1], state: "minecraft:stone_bricks"},
        {pos: [10, 0, 2], state: "minecraft:stone_bricks"},
        {pos: [10, 0, 3], state: "minecraft:stone_bricks"},
        {pos: [10, 0, 5], state: "minecraft:stone_bricks"},
        {pos: [10, 0, 6], state: "minecraft:chiseled_stone_bricks"},
        {pos: [10, 0, 9], state: "minecraft:stone_bricks"},
        {pos: [10, 0, 10], state: "minecraft:stone_bricks"},
        {pos: [10, 0, 11], state: "minecraft:stone_bricks"},
        {pos: [10, 0, 17], state: "minecraft:stone_bricks"},
        {pos: [11, 0, 2], state: "minecraft:stone_bricks"},
        {pos: [11, 0, 3], state: "minecraft:stone_bricks"},
        {pos: [11, 0, 4], state: "minecraft:chiseled_stone_bricks"},
        {pos: [11, 0, 5], state: "minecraft:stone_bricks"},
        {pos: [11, 0, 6], state: "minecraft:stone_bricks"},
        {pos: [11, 0, 9], state: "minecraft:stone_bricks"},
        {pos: [11, 0, 10], state: "minecraft:stone_bricks"},
        {pos: [11, 0, 11], state: "minecraft:stone_bricks"},
        {pos: [12, 0, 3], state: "minecraft:stone_bricks"},
        {pos: [12, 0, 4], state: "minecraft:stone_bricks"},
        {pos: [12, 0, 5], state: "minecraft:stone_bricks"},
        {pos: [12, 0, 6], state: "minecraft:stone_bricks"},
        {pos: [13, 0, 5], state: "minecraft:stone_bricks"},
        {pos: [0, 1, 4], state: "minecraft:stone_bricks"},
        {pos: [0, 1, 5], state: "minecraft:gravel"},
        {pos: [1, 1, 3], state: "minecraft:polished_andesite"},
        {pos: [1, 1, 4], state: "minecraft:stone_bricks"},
        {pos: [1, 1, 5], state: "minecraft:stone_bricks"},
        {pos: [1, 1, 6], state: "minecraft:gravel"},
        {pos: [1, 1, 7], state: "minecraft:gravel"},
        {pos: [1, 1, 8], state: "minecraft:gravel"},
        {pos: [2, 1, 2], state: "minecraft:gravel"},
        {pos: [2, 1, 3], state: "minecraft:stone_bricks"},
        {pos: [2, 1, 4], state: "minecraft:stone_bricks"},
        {pos: [2, 1, 5], state: "minecraft:stone_bricks"},
        {pos: [2, 1, 6], state: "minecraft:gravel"},
        {pos: [2, 1, 7], state: "minecraft:gravel"},
        {pos: [2, 1, 15], state: "minecraft:gravel"},
        {pos: [2, 1, 16], state: "minecraft:gravel"},
        {pos: [3, 1, 2], state: "minecraft:stone_bricks"},
        {pos: [3, 1, 3], state: "minecraft:stone_bricks"},
        {pos: [3, 1, 4], state: "minecraft:stone_bricks"},
        {pos: [3, 1, 5], state: "minecraft:gravel"},
        {pos: [3, 1, 12], state: "minecraft:gravel"},
        {pos: [3, 1, 13], state: "minecraft:stone_bricks"},
        {pos: [3, 1, 14], state: "minecraft:gravel"},
        {pos: [3, 1, 15], state: "minecraft:gravel"},
        {pos: [3, 1, 16], state: "minecraft:stone_bricks"},
        {pos: [4, 1, 2], state: "minecraft:stone_bricks"},
        {pos: [4, 1, 3], state: "minecraft:stone_bricks"},
        {pos: [4, 1, 4], state: "minecraft:gravel"},
        {pos: [4, 1, 10], state: "minecraft:gravel"},
        {pos: [4, 1, 11], state: "minecraft:stone_bricks"},
        {pos: [4, 1, 12], state: "minecraft:stone_bricks"},
        {pos: [4, 1, 13], state: "minecraft:stone_bricks"},
        {pos: [4, 1, 14], state: "minecraft:gravel"},
        {pos: [4, 1, 15], state: "minecraft:gravel"},
        {pos: [4, 1, 16], state: "minecraft:stone_bricks"},
        {pos: [4, 1, 17], state: "minecraft:gravel"},
        {pos: [5, 1, 2], state: "minecraft:gravel"},
        {pos: [5, 1, 3], state: "minecraft:gravel"},
        {pos: [5, 1, 9], state: "minecraft:gravel"},
        {pos: [5, 1, 10], state: "minecraft:gravel"},
        {pos: [5, 1, 11], state: "minecraft:stone_bricks"},
        {pos: [5, 1, 12], state: "minecraft:stone_bricks"},
        {pos: [5, 1, 13], state: "minecraft:stone_bricks"},
        {pos: [5, 1, 14], state: "minecraft:stone_bricks"},
        {pos: [5, 1, 15], state: "minecraft:stone_bricks"},
        {pos: [5, 1, 16], state: "minecraft:stone_bricks"},
        {pos: [5, 1, 17], state: "minecraft:gravel"},
        {pos: [5, 1, 18], state: "minecraft:gravel"},
        {pos: [6, 1, 2], state: "minecraft:gravel"},
        {pos: [6, 1, 3], state: "minecraft:gravel"},
        {pos: [6, 1, 10], state: "minecraft:gravel"},
        {pos: [6, 1, 11], state: "minecraft:stone_bricks"},
        {pos: [6, 1, 12], state: "minecraft:stone_bricks"},
        {pos: [6, 1, 13], state: "minecraft:stone_bricks"},
        {pos: [6, 1, 14], state: "minecraft:stone_bricks"},
        {pos: [6, 1, 15], state: "minecraft:stone_bricks"},
        {pos: [6, 1, 16], state: "minecraft:stone_bricks"},
        {pos: [6, 1, 17], state: "minecraft:gravel"},
        {pos: [6, 1, 18], state: "minecraft:gravel"},
        {pos: [7, 1, 13], state: "minecraft:stone_bricks"},
        {pos: [7, 1, 14], state: "minecraft:stone_bricks"},
        {pos: [7, 1, 15], state: "minecraft:stone_bricks"},
        {pos: [7, 1, 16], state: "minecraft:stone_bricks"},
        {pos: [7, 1, 17], state: "minecraft:gravel"},
        {pos: [7, 1, 18], state: "minecraft:gravel"},
        {pos: [7, 1, 19], state: "minecraft:gravel"},
        {pos: [8, 1, 0], state: "minecraft:gravel"},
        {pos: [8, 1, 1], state: "minecraft:gravel"},
        {pos: [8, 1, 2], state: "minecraft:gravel"},
        {pos: [8, 1, 13], state: "minecraft:gravel"},
        {pos: [8, 1, 15], state: "minecraft:gravel"},
        {pos: [8, 1, 16], state: "minecraft:stone_bricks"},
        {pos: [8, 1, 17], state: "minecraft:stone_bricks"},
        {pos: [8, 1, 18], state: "minecraft:stone_bricks"},
        {pos: [8, 1, 19], state: "minecraft:gravel"},
        {pos: [9, 1, 0], state: "minecraft:gravel"},
        {pos: [9, 1, 1], state: "minecraft:stone_bricks"},
        {pos: [9, 1, 2], state: "minecraft:stone_bricks"},
        {pos: [9, 1, 6], state: "minecraft:gravel"},
        {pos: [9, 1, 9], state: "minecraft:stone_bricks"},
        {pos: [9, 1, 10], state: "minecraft:stone_bricks"},
        {pos: [9, 1, 16], state: "minecraft:gravel"},
        {pos: [9, 1, 17], state: "minecraft:gravel"},
        {pos: [9, 1, 18], state: "minecraft:gravel"},
        {pos: [10, 1, 1], state: "minecraft:stone_bricks"},
        {pos: [10, 1, 2], state: "minecraft:polished_andesite"},
        {pos: [10, 1, 3], state: "minecraft:gravel"},
        {pos: [10, 1, 5], state: "minecraft:stone_bricks"},
        {pos: [10, 1, 6], state: "minecraft:stone_bricks"},
        {pos: [10, 1, 9], state: "minecraft:stone_bricks"},
        {pos: [10, 1, 10], state: "minecraft:stone_bricks"},
        {pos: [10, 1, 11], state: "minecraft:gravel"},
        {pos: [10, 1, 17], state: "minecraft:gravel"},
        {pos: [11, 1, 2], state: "minecraft:cobblestone_stairs{facing:west,half:top,shape:straight,waterlogged:false}"},
        {pos: [11, 1, 3], state: "minecraft:gravel"},
        {pos: [11, 1, 4], state: "minecraft:gravel"},
        {pos: [11, 1, 5], state: "minecraft:stone_bricks"},
        {pos: [11, 1, 6], state: "minecraft:stone_bricks"},
        {pos: [11, 1, 9], state: "minecraft:gravel"},
        {pos: [11, 1, 10], state: "minecraft:stone_bricks"},
        {pos: [11, 1, 11], state: "minecraft:stone_bricks"},
        {pos: [12, 1, 3], state: "minecraft:gravel"},
        {pos: [12, 1, 4], state: "minecraft:gravel"},
        {pos: [12, 1, 5], state: "minecraft:gravel"},
        {pos: [12, 1, 6], state: "minecraft:gravel"},
        {pos: [13, 1, 5], state: "minecraft:gravel"},
        {pos: [0, 2, 4], state: "minecraft:gravel"},
        {pos: [0, 2, 5], state: "minecraft:gravel"},
        {pos: [1, 2, 3], state: "minecraft:gravel"},
        {pos: [1, 2, 4], state: "minecraft:stone_bricks"},
        {pos: [1, 2, 5], state: "minecraft:stone_bricks"},
        {pos: [1, 2, 6], state: "minecraft:gravel"},
        {pos: [1, 2, 7], state: "minecraft:gravel"},
        {pos: [1, 2, 8], state: "minecraft:gravel"},
        {pos: [2, 2, 2], state: "minecraft:gravel"},
        {pos: [2, 2, 3], state: "minecraft:stone_bricks"},
        {pos: [2, 2, 4], state: "minecraft:stone_bricks"},
        {pos: [2, 2, 5], state: "minecraft:gravel"},
        {pos: [2, 2, 6], state: "minecraft:gravel"},
        {pos: [2, 2, 7], state: "minecraft:gravel"},
        {pos: [2, 2, 15], state: "minecraft:gravel"},
        {pos: [2, 2, 16], state: "minecraft:gravel"},
        {pos: [3, 2, 2], state: "minecraft:stone_bricks"},
        {pos: [3, 2, 3], state: "minecraft:stone_bricks"},
        {pos: [3, 2, 4], state: "minecraft:stone_bricks"},
        {pos: [3, 2, 5], state: "minecraft:gravel"},
        {pos: [3, 2, 12], state: "minecraft:gravel"},
        {pos: [3, 2, 13], state: "minecraft:stone_bricks"},
        {pos: [3, 2, 14], state: "minecraft:stone_bricks"},
        {pos: [3, 2, 15], state: "minecraft:stone_bricks"},
        {pos: [3, 2, 16], state: "minecraft:stone_bricks"},
        {pos: [4, 2, 2], state: "minecraft:gravel"},
        {pos: [4, 2, 3], state: "minecraft:gravel"},
        {pos: [4, 2, 4], state: "minecraft:gravel"},
        {pos: [4, 2, 10], state: "minecraft:gravel"},
        {pos: [4, 2, 11], state: "minecraft:gravel"},
        {pos: [4, 2, 12], state: "minecraft:gravel"},
        {pos: [4, 2, 13], state: "minecraft:chiseled_stone_bricks"},
        {pos: [4, 2, 14], state: "minecraft:stone_bricks"},
        {pos: [4, 2, 15], state: "minecraft:stone_bricks"},
        {pos: [4, 2, 16], state: "minecraft:stone_bricks"},
        {pos: [4, 2, 17], state: "minecraft:gravel"},
        {pos: [5, 2, 2], state: "minecraft:gravel"},
        {pos: [5, 2, 3], state: "minecraft:gravel"},
        {pos: [5, 2, 9], state: "minecraft:gravel"},
        {pos: [5, 2, 10], state: "minecraft:gravel"},
        {pos: [5, 2, 11], state: "minecraft:gravel"},
        {pos: [5, 2, 12], state: "minecraft:stone_bricks"},
        {pos: [5, 2, 13], state: "minecraft:stone_bricks"},
        {pos: [5, 2, 14], state: "minecraft:stone_bricks"},
        {pos: [5, 2, 15], state: "minecraft:stone_bricks"},
        {pos: [5, 2, 16], state: "minecraft:polished_andesite"},
        {pos: [5, 2, 17], state: "minecraft:gravel"},
        {pos: [5, 2, 18], state: "minecraft:gravel"},
        {pos: [6, 2, 2], state: "minecraft:gravel"},
        {pos: [6, 2, 3], state: "minecraft:gravel"},
        {pos: [6, 2, 10], state: "minecraft:gravel"},
        {pos: [6, 2, 11], state: "minecraft:gravel"},
        {pos: [6, 2, 12], state: "minecraft:polished_andesite"},
        {pos: [6, 2, 13], state: "minecraft:stone_bricks"},
        {pos: [6, 2, 14], state: "minecraft:stone_bricks"},
        {pos: [6, 2, 15], state: "minecraft:stone_bricks"},
        {pos: [6, 2, 16], state: "minecraft:stone_bricks"},
        {pos: [6, 2, 17], state: "minecraft:gravel"},
        {pos: [6, 2, 18], state: "minecraft:gravel"},
        {pos: [7, 2, 13], state: "minecraft:gravel"},
        {pos: [7, 2, 14], state: "minecraft:stone_bricks"},
        {pos: [7, 2, 15], state: "minecraft:stone_bricks"},
        {pos: [7, 2, 16], state: "minecraft:stone_bricks"},
        {pos: [7, 2, 17], state: "minecraft:gravel"},
        {pos: [7, 2, 18], state: "minecraft:gravel"},
        {pos: [7, 2, 19], state: "minecraft:gravel"},
        {pos: [8, 2, 0], state: "minecraft:gravel"},
        {pos: [8, 2, 1], state: "minecraft:gravel"},
        {pos: [8, 2, 2], state: "minecraft:gravel"},
        {pos: [8, 2, 13], state: "minecraft:gravel"},
        {pos: [8, 2, 15], state: "minecraft:gravel"},
        {pos: [8, 2, 16], state: "minecraft:gravel"},
        {pos: [8, 2, 17], state: "minecraft:stone_bricks"},
        {pos: [8, 2, 18], state: "minecraft:polished_andesite"},
        {pos: [8, 2, 19], state: "minecraft:gravel"},
        {pos: [9, 2, 0], state: "minecraft:gravel"},
        {pos: [9, 2, 1], state: "minecraft:stone_bricks"},
        {pos: [9, 2, 2], state: "minecraft:polished_andesite"},
        {pos: [9, 2, 6], state: "minecraft:gravel"},
        {pos: [9, 2, 9], state: "minecraft:stone_bricks"},
        {pos: [9, 2, 10], state: "minecraft:polished_andesite"},
        {pos: [9, 2, 16], state: "minecraft:gravel"},
        {pos: [9, 2, 17], state: "minecraft:gravel"},
        {pos: [9, 2, 18], state: "minecraft:gravel"},
        {pos: [10, 2, 1], state: "minecraft:stone_bricks"},
        {pos: [10, 2, 2], state: "minecraft:stone_bricks"},
        {pos: [10, 2, 3], state: "minecraft:gravel"},
        {pos: [10, 2, 5], state: "minecraft:stone_bricks"},
        {pos: [10, 2, 6], state: "minecraft:stone_bricks"},
        {pos: [10, 2, 9], state: "minecraft:polished_andesite"},
        {pos: [10, 2, 10], state: "minecraft:polished_andesite"},
        {pos: [10, 2, 11], state: "minecraft:gravel"},
        {pos: [10, 2, 17], state: "minecraft:gravel"},
        {pos: [11, 2, 2], state: "minecraft:gravel"},
        {pos: [11, 2, 3], state: "minecraft:gravel"},
        {pos: [11, 2, 4], state: "minecraft:gravel"},
        {pos: [11, 2, 5], state: "minecraft:polished_andesite"},
        {pos: [11, 2, 6], state: "minecraft:polished_andesite"},
        {pos: [11, 2, 9], state: "minecraft:gravel"},
        {pos: [11, 2, 10], state: "minecraft:stone_bricks"},
        {pos: [11, 2, 11], state: "minecraft:gravel"},
        {pos: [12, 2, 3], state: "minecraft:gravel"},
        {pos: [12, 2, 4], state: "minecraft:gravel"},
        {pos: [12, 2, 5], state: "minecraft:gravel"},
        {pos: [12, 2, 6], state: "minecraft:gravel"},
        {pos: [13, 2, 5], state: "minecraft:gravel"},
        {pos: [0, 3, 4], state: "minecraft:gravel"},
        {pos: [0, 3, 5], state: "minecraft:gravel"},
        {pos: [1, 3, 3], state: "minecraft:gravel"},
        {pos: [1, 3, 4], state: "minecraft:gravel"},
        {pos: [1, 3, 5], state: "minecraft:gravel"},
        {pos: [1, 3, 6], state: "minecraft:gravel"},
        {pos: [1, 3, 7], state: "minecraft:gravel"},
        {pos: [1, 3, 8], state: "minecraft:gravel"},
        {pos: [2, 3, 2], state: "minecraft:gravel"},
        {pos: [2, 3, 3], state: "minecraft:stone_bricks"},
        {pos: [2, 3, 4], state: "minecraft:stone_bricks"},
        {pos: [2, 3, 5], state: "minecraft:gravel"},
        {pos: [2, 3, 6], state: "minecraft:gravel"},
        {pos: [2, 3, 7], state: "minecraft:gravel"},
        {pos: [3, 3, 2], state: "minecraft:gravel"},
        {pos: [3, 3, 3], state: "minecraft:stone_bricks"},
        {pos: [3, 3, 4], state: "minecraft:stone_bricks"},
        {pos: [3, 3, 5], state: "minecraft:gravel"},
        {pos: [3, 3, 13], state: "minecraft:gravel"},
        {pos: [3, 3, 14], state: "minecraft:gravel"},
        {pos: [3, 3, 15], state: "minecraft:gravel"},
        {pos: [3, 3, 16], state: "minecraft:gravel"},
        {pos: [4, 3, 2], state: "minecraft:gravel"},
        {pos: [4, 3, 3], state: "minecraft:gravel"},
        {pos: [4, 3, 4], state: "minecraft:gravel"},
        {pos: [4, 3, 12], state: "minecraft:gravel"},
        {pos: [4, 3, 13], state: "minecraft:gravel"},
        {pos: [4, 3, 14], state: "minecraft:stone_bricks"},
        {pos: [4, 3, 15], state: "minecraft:chiseled_stone_bricks"},
        {pos: [4, 3, 16], state: "minecraft:stone_bricks"},
        {pos: [4, 3, 17], state: "minecraft:gravel"},
        {pos: [5, 3, 2], state: "minecraft:gravel"},
        {pos: [5, 3, 3], state: "minecraft:gravel"},
        {pos: [5, 3, 10], state: "minecraft:gravel"},
        {pos: [5, 3, 11], state: "minecraft:gravel"},
        {pos: [5, 3, 12], state: "minecraft:gravel"},
        {pos: [5, 3, 13], state: "minecraft:stone_bricks"},
        {pos: [5, 3, 14], state: "minecraft:stone_bricks"},
        {pos: [5, 3, 15], state: "minecraft:stone_bricks"},
        {pos: [5, 3, 16], state: "minecraft:stone_bricks"},
        {pos: [5, 3, 17], state: "minecraft:gravel"},
        {pos: [5, 3, 18], state: "minecraft:gravel"},
        {pos: [6, 3, 2], state: "minecraft:gravel"},
        {pos: [6, 3, 3], state: "minecraft:gravel"},
        {pos: [6, 3, 10], state: "minecraft:gravel"},
        {pos: [6, 3, 11], state: "minecraft:gravel"},
        {pos: [6, 3, 12], state: "minecraft:stone_bricks"},
        {pos: [6, 3, 13], state: "minecraft:stone_bricks"},
        {pos: [6, 3, 14], state: "minecraft:stone_bricks"},
        {pos: [6, 3, 15], state: "minecraft:stone_bricks"},
        {pos: [6, 3, 16], state: "minecraft:stone_bricks"},
        {pos: [6, 3, 17], state: "minecraft:gravel"},
        {pos: [6, 3, 18], state: "minecraft:gravel"},
        {pos: [7, 3, 13], state: "minecraft:stone_bricks"},
        {pos: [7, 3, 14], state: "minecraft:stone_bricks"},
        {pos: [7, 3, 15], state: "minecraft:stone_bricks"},
        {pos: [7, 3, 16], state: "minecraft:stone_bricks"},
        {pos: [7, 3, 17], state: "minecraft:stone_bricks"},
        {pos: [7, 3, 18], state: "minecraft:stone_bricks"},
        {pos: [7, 3, 19], state: "minecraft:gravel"},
        {pos: [8, 3, 0], state: "minecraft:gravel"},
        {pos: [8, 3, 1], state: "minecraft:stone_bricks"},
        {pos: [8, 3, 2], state: "minecraft:stone_bricks"},
        {pos: [8, 3, 6], state: "minecraft:stone_bricks"},
        {pos: [8, 3, 13], state: "minecraft:gravel"},
        {pos: [8, 3, 15], state: "minecraft:gravel"},
        {pos: [8, 3, 16], state: "minecraft:gravel"},
        {pos: [8, 3, 17], state: "minecraft:stone_bricks"},
        {pos: [8, 3, 18], state: "minecraft:stone_bricks"},
        {pos: [8, 3, 19], state: "minecraft:gravel"},
        {pos: [9, 3, 0], state: "minecraft:gravel"},
        {pos: [9, 3, 1], state: "minecraft:stone_bricks"},
        {pos: [9, 3, 2], state: "minecraft:stone_bricks"},
        {pos: [9, 3, 5], state: "minecraft:stone_bricks"},
        {pos: [9, 3, 6], state: "minecraft:stone_bricks"},
        {pos: [9, 3, 9], state: "minecraft:stone_bricks"},
        {pos: [9, 3, 10], state: "minecraft:stone_bricks"},
        {pos: [9, 3, 16], state: "minecraft:gravel"},
        {pos: [9, 3, 17], state: "minecraft:gravel"},
        {pos: [9, 3, 18], state: "minecraft:gravel"},
        {pos: [10, 3, 1], state: "minecraft:stone_bricks"},
        {pos: [10, 3, 2], state: "minecraft:gravel"},
        {pos: [10, 3, 3], state: "minecraft:gravel"},
        {pos: [10, 3, 5], state: "minecraft:stone_bricks"},
        {pos: [10, 3, 6], state: "minecraft:stone_bricks"},
        {pos: [10, 3, 9], state: "minecraft:stone_bricks"},
        {pos: [10, 3, 10], state: "minecraft:stone_bricks"},
        {pos: [10, 3, 11], state: "minecraft:gravel"},
        {pos: [10, 3, 17], state: "minecraft:gravel"},
        {pos: [11, 3, 2], state: "minecraft:gravel"},
        {pos: [11, 3, 3], state: "minecraft:gravel"},
        {pos: [11, 3, 4], state: "minecraft:gravel"},
        {pos: [11, 3, 5], state: "minecraft:stone_bricks"},
        {pos: [11, 3, 6], state: "minecraft:polished_andesite"},
        {pos: [11, 3, 9], state: "minecraft:gravel"},
        {pos: [11, 3, 10], state: "minecraft:gravel"},
        {pos: [11, 3, 11], state: "minecraft:gravel"},
        {pos: [12, 3, 3], state: "minecraft:gravel"},
        {pos: [12, 3, 4], state: "minecraft:gravel"},
        {pos: [12, 3, 5], state: "minecraft:gravel"},
        {pos: [12, 3, 6], state: "minecraft:gravel"},
        {pos: [13, 3, 5], state: "minecraft:gravel"},
        {pos: [0, 4, 4], state: "minecraft:gravel"},
        {pos: [0, 4, 5], state: "minecraft:gravel"},
        {pos: [1, 4, 3], state: "minecraft:gravel"},
        {pos: [1, 4, 4], state: "minecraft:gravel"},
        {pos: [1, 4, 5], state: "minecraft:gravel"},
        {pos: [1, 4, 6], state: "minecraft:gravel"},
        {pos: [1, 4, 7], state: "minecraft:gravel"},
        {pos: [1, 4, 8], state: "minecraft:gravel"},
        {pos: [2, 4, 2], state: "minecraft:gravel"},
        {pos: [2, 4, 3], state: "minecraft:chiseled_stone_bricks"},
        {pos: [2, 4, 4], state: "minecraft:stone_bricks"},
        {pos: [2, 4, 5], state: "minecraft:gravel"},
        {pos: [2, 4, 6], state: "minecraft:gravel"},
        {pos: [2, 4, 7], state: "minecraft:gravel"},
        {pos: [3, 4, 2], state: "minecraft:gravel"},
        {pos: [3, 4, 3], state: "minecraft:stone_bricks"},
        {pos: [3, 4, 4], state: "minecraft:stone_bricks"},
        {pos: [3, 4, 5], state: "minecraft:gravel"},
        {pos: [4, 4, 2], state: "minecraft:gravel"},
        {pos: [4, 4, 3], state: "minecraft:gravel"},
        {pos: [4, 4, 4], state: "minecraft:gravel"},
        {pos: [4, 4, 14], state: "minecraft:gravel"},
        {pos: [4, 4, 15], state: "minecraft:gravel"},
        {pos: [4, 4, 16], state: "minecraft:gravel"},
        {pos: [4, 4, 17], state: "minecraft:gravel"},
        {pos: [5, 4, 2], state: "minecraft:gravel"},
        {pos: [5, 4, 3], state: "minecraft:gravel"},
        {pos: [5, 4, 12], state: "minecraft:gravel"},
        {pos: [5, 4, 13], state: "minecraft:gravel"},
        {pos: [5, 4, 14], state: "minecraft:stone_bricks"},
        {pos: [5, 4, 15], state: "minecraft:stone_bricks"},
        {pos: [5, 4, 16], state: "minecraft:gravel"},
        {pos: [5, 4, 17], state: "minecraft:gravel"},
        {pos: [5, 4, 18], state: "minecraft:gravel"},
        {pos: [6, 4, 2], state: "minecraft:gravel"},
        {pos: [6, 4, 3], state: "minecraft:gravel"},
        {pos: [6, 4, 10], state: "minecraft:gravel"},
        {pos: [6, 4, 11], state: "minecraft:gravel"},
        {pos: [6, 4, 12], state: "minecraft:gravel"},
        {pos: [6, 4, 13], state: "minecraft:gravel"},
        {pos: [6, 4, 14], state: "minecraft:stone_bricks"},
        {pos: [6, 4, 15], state: "minecraft:stone_bricks"},
        {pos: [6, 4, 16], state: "minecraft:stone_bricks"},
        {pos: [6, 4, 17], state: "minecraft:gravel"},
        {pos: [6, 4, 18], state: "minecraft:gravel"},
        {pos: [7, 4, 1], state: "minecraft:stone_bricks"},
        {pos: [7, 4, 8], state: "minecraft:stone_bricks"},
        {pos: [7, 4, 9], state: "minecraft:polished_andesite"},
        {pos: [7, 4, 10], state: "minecraft:stone_bricks"},
        {pos: [7, 4, 11], state: "minecraft:stone_bricks"},
        {pos: [7, 4, 12], state: "minecraft:stone_bricks"},
        {pos: [7, 4, 13], state: "minecraft:stone_bricks"},
        {pos: [7, 4, 14], state: "minecraft:polished_andesite"},
        {pos: [7, 4, 15], state: "minecraft:stone_bricks"},
        {pos: [7, 4, 16], state: "minecraft:stone_bricks"},
        {pos: [7, 4, 17], state: "minecraft:stone_bricks"},
        {pos: [7, 4, 18], state: "minecraft:stone_bricks"},
        {pos: [7, 4, 19], state: "minecraft:gravel"},
        {pos: [8, 4, 0], state: "minecraft:gravel"},
        {pos: [8, 4, 1], state: "minecraft:stone_bricks"},
        {pos: [8, 4, 2], state: "minecraft:stone_bricks"},
        {pos: [8, 4, 3], state: "minecraft:stone_bricks"},
        {pos: [8, 4, 4], state: "minecraft:stone_bricks"},
        {pos: [8, 4, 5], state: "minecraft:stone_bricks"},
        {pos: [8, 4, 6], state: "minecraft:stone_bricks"},
        {pos: [8, 4, 7], state: "minecraft:stone_bricks"},
        {pos: [8, 4, 8], state: "minecraft:stone_bricks"},
        {pos: [8, 4, 9], state: "minecraft:polished_andesite"},
        {pos: [8, 4, 10], state: "minecraft:stone_bricks"},
        {pos: [8, 4, 11], state: "minecraft:stone_bricks"},
        {pos: [8, 4, 12], state: "minecraft:stone_bricks"},
        {pos: [8, 4, 13], state: "minecraft:stone_bricks"},
        {pos: [8, 4, 14], state: "minecraft:stone_bricks"},
        {pos: [8, 4, 15], state: "minecraft:stone_bricks"},
        {pos: [8, 4, 16], state: "minecraft:stone_bricks"},
        {pos: [8, 4, 17], state: "minecraft:stone_bricks"},
        {pos: [8, 4, 18], state: "minecraft:stone_bricks"},
        {pos: [8, 4, 19], state: "minecraft:gravel"},
        {pos: [9, 4, 0], state: "minecraft:gravel"},
        {pos: [9, 4, 1], state: "minecraft:stone_bricks"},
        {pos: [9, 4, 2], state: "minecraft:stone_bricks"},
        {pos: [9, 4, 3], state: "minecraft:stone_bricks"},
        {pos: [9, 4, 4], state: "minecraft:stone_bricks"},
        {pos: [9, 4, 5], state: "minecraft:stone_bricks"},
        {pos: [9, 4, 6], state: "minecraft:stone_bricks"},
        {pos: [9, 4, 7], state: "minecraft:stone_bricks"},
        {pos: [9, 4, 8], state: "minecraft:polished_andesite"},
        {pos: [9, 4, 9], state: "minecraft:stone_bricks"},
        {pos: [9, 4, 10], state: "minecraft:stone_bricks"},
        {pos: [9, 4, 11], state: "minecraft:stone_bricks"},
        {pos: [9, 4, 12], state: "minecraft:stone_bricks"},
        {pos: [9, 4, 13], state: "minecraft:stone_bricks"},
        {pos: [9, 4, 14], state: "minecraft:stone_bricks"},
        {pos: [9, 4, 15], state: "minecraft:stone_bricks"},
        {pos: [9, 4, 16], state: "minecraft:gravel"},
        {pos: [9, 4, 17], state: "minecraft:gravel"},
        {pos: [9, 4, 18], state: "minecraft:gravel"},
        {pos: [10, 4, 1], state: "minecraft:gravel"},
        {pos: [10, 4, 2], state: "minecraft:gravel"},
        {pos: [10, 4, 3], state: "minecraft:gravel"},
        {pos: [10, 4, 5], state: "minecraft:stone_bricks"},
        {pos: [10, 4, 6], state: "minecraft:stone_bricks"},
        {pos: [10, 4, 9], state: "minecraft:stone_bricks"},
        {pos: [10, 4, 10], state: "minecraft:stone_bricks"},
        {pos: [10, 4, 11], state: "minecraft:stone_bricks"},
        {pos: [10, 4, 12], state: "minecraft:stone_bricks"},
        {pos: [10, 4, 13], state: "minecraft:stone_bricks"},
        {pos: [10, 4, 17], state: "minecraft:gravel"},
        {pos: [11, 4, 2], state: "minecraft:gravel"},
        {pos: [11, 4, 3], state: "minecraft:gravel"},
        {pos: [11, 4, 4], state: "minecraft:gravel"},
        {pos: [11, 4, 5], state: "minecraft:gravel"},
        {pos: [11, 4, 6], state: "minecraft:gravel"},
        {pos: [11, 4, 9], state: "minecraft:gravel"},
        {pos: [11, 4, 10], state: "minecraft:gravel"},
        {pos: [11, 4, 11], state: "minecraft:gravel"},
        {pos: [12, 4, 3], state: "minecraft:gravel"},
        {pos: [12, 4, 4], state: "minecraft:gravel"},
        {pos: [12, 4, 5], state: "minecraft:gravel"},
        {pos: [12, 4, 6], state: "minecraft:gravel"},
        {pos: [13, 4, 5], state: "minecraft:gravel"},
        {pos: [0, 5, 4], state: "minecraft:gravel"},
        {pos: [0, 5, 5], state: "minecraft:gravel"},
        {pos: [1, 5, 3], state: "minecraft:gravel"},
        {pos: [1, 5, 4], state: "minecraft:gravel"},
        {pos: [1, 5, 5], state: "minecraft:gravel"},
        {pos: [1, 5, 6], state: "minecraft:gravel"},
        {pos: [1, 5, 7], state: "minecraft:gravel"},
        {pos: [1, 5, 8], state: "minecraft:gravel"},
        {pos: [2, 5, 2], state: "minecraft:gravel"},
        {pos: [2, 5, 3], state: "minecraft:stone_bricks"},
        {pos: [2, 5, 4], state: "minecraft:stone_bricks"},
        {pos: [2, 5, 5], state: "minecraft:gravel"},
        {pos: [2, 5, 6], state: "minecraft:gravel"},
        {pos: [2, 5, 7], state: "minecraft:gravel"},
        {pos: [3, 5, 2], state: "minecraft:gravel"},
        {pos: [3, 5, 3], state: "minecraft:stone_bricks"},
        {pos: [3, 5, 4], state: "minecraft:stone_bricks"},
        {pos: [3, 5, 5], state: "minecraft:gravel"},
        {pos: [4, 5, 2], state: "minecraft:gravel"},
        {pos: [4, 5, 3], state: "minecraft:gravel"},
        {pos: [4, 5, 4], state: "minecraft:gravel"},
        {pos: [4, 5, 15], state: "minecraft:gravel"},
        {pos: [4, 5, 16], state: "minecraft:gravel"},
        {pos: [5, 5, 2], state: "minecraft:gravel"},
        {pos: [5, 5, 3], state: "minecraft:gravel"},
        {pos: [5, 5, 14], state: "minecraft:gravel"},
        {pos: [5, 5, 15], state: "minecraft:gravel"},
        {pos: [5, 5, 16], state: "minecraft:gravel"},
        {pos: [5, 5, 17], state: "minecraft:gravel"},
        {pos: [6, 5, 2], state: "minecraft:gravel"},
        {pos: [6, 5, 3], state: "minecraft:gravel"},
        {pos: [6, 5, 12], state: "minecraft:gravel"},
        {pos: [6, 5, 13], state: "minecraft:gravel"},
        {pos: [6, 5, 14], state: "minecraft:gravel"},
        {pos: [6, 5, 15], state: "minecraft:gravel"},
        {pos: [6, 5, 16], state: "minecraft:gravel"},
        {pos: [6, 5, 17], state: "minecraft:gravel"},
        {pos: [6, 5, 18], state: "minecraft:gravel"},
        {pos: [7, 5, 1], state: "minecraft:stone_bricks"},
        {pos: [7, 5, 2], state: "minecraft:stone_bricks"},
        {pos: [7, 5, 8], state: "minecraft:gravel"},
        {pos: [7, 5, 9], state: "minecraft:gravel"},
        {pos: [7, 5, 10], state: "minecraft:gravel"},
        {pos: [7, 5, 11], state: "minecraft:gravel"},
        {pos: [7, 5, 12], state: "minecraft:gravel"},
        {pos: [7, 5, 13], state: "minecraft:gravel"},
        {pos: [7, 5, 14], state: "minecraft:gravel"},
        {pos: [7, 5, 15], state: "minecraft:gravel"},
        {pos: [7, 5, 16], state: "minecraft:gravel"},
        {pos: [7, 5, 17], state: "minecraft:gravel"},
        {pos: [7, 5, 18], state: "minecraft:stone_bricks"},
        {pos: [7, 5, 19], state: "minecraft:gravel"},
        {pos: [8, 5, 0], state: "minecraft:gravel"},
        {pos: [8, 5, 1], state: "minecraft:stone_bricks"},
        {pos: [8, 5, 2], state: "minecraft:stone_bricks"},
        {pos: [8, 5, 3], state: "minecraft:stone_brick_stairs{facing:west,half:top,shape:straight,waterlogged:false}"},
        {pos: [8, 5, 4], state: "minecraft:cobblestone_stairs{facing:west,half:top,shape:straight,waterlogged:false}"},
        {pos: [8, 5, 5], state: "minecraft:gravel"},
        {pos: [8, 5, 6], state: "minecraft:gravel"},
        {pos: [8, 5, 7], state: "minecraft:gravel"},
        {pos: [8, 5, 8], state: "minecraft:gravel"},
        {pos: [8, 5, 9], state: "minecraft:gravel"},
        {pos: [8, 5, 10], state: "minecraft:gravel"},
        {pos: [8, 5, 11], state: "minecraft:gravel"},
        {pos: [8, 5, 12], state: "minecraft:gravel"},
        {pos: [8, 5, 13], state: "minecraft:gravel"},
        {pos: [8, 5, 14], state: "minecraft:gravel"},
        {pos: [8, 5, 15], state: "minecraft:gravel"},
        {pos: [8, 5, 16], state: "minecraft:gravel"},
        {pos: [8, 5, 17], state: "minecraft:stone_bricks"},
        {pos: [8, 5, 18], state: "minecraft:stone_bricks"},
        {pos: [8, 5, 19], state: "minecraft:gravel"},
        {pos: [9, 5, 1], state: "minecraft:gravel"},
        {pos: [9, 5, 2], state: "minecraft:gravel"},
        {pos: [9, 5, 3], state: "minecraft:gravel"},
        {pos: [9, 5, 4], state: "minecraft:gravel"},
        {pos: [9, 5, 5], state: "minecraft:gravel"},
        {pos: [9, 5, 6], state: "minecraft:gravel"},
        {pos: [9, 5, 7], state: "minecraft:gravel"},
        {pos: [9, 5, 8], state: "minecraft:gravel"},
        {pos: [9, 5, 9], state: "minecraft:stone_bricks"},
        {pos: [9, 5, 10], state: "minecraft:stone_bricks"},
        {pos: [9, 5, 11], state: "minecraft:gravel"},
        {pos: [9, 5, 12], state: "minecraft:gravel"},
        {pos: [9, 5, 13], state: "minecraft:gravel"},
        {pos: [9, 5, 14], state: "minecraft:gravel"},
        {pos: [9, 5, 15], state: "minecraft:gravel"},
        {pos: [9, 5, 16], state: "minecraft:gravel"},
        {pos: [9, 5, 17], state: "minecraft:gravel"},
        {pos: [9, 5, 18], state: "minecraft:gravel"},
        {pos: [10, 5, 2], state: "minecraft:gravel"},
        {pos: [10, 5, 3], state: "minecraft:gravel"},
        {pos: [10, 5, 5], state: "minecraft:gravel"},
        {pos: [10, 5, 6], state: "minecraft:gravel"},
        {pos: [10, 5, 9], state: "minecraft:stone_bricks"},
        {pos: [10, 5, 10], state: "minecraft:stone_bricks"},
        {pos: [10, 5, 11], state: "minecraft:gravel"},
        {pos: [10, 5, 12], state: "minecraft:gravel"},
        {pos: [10, 5, 13], state: "minecraft:gravel"},
        {pos: [10, 5, 17], state: "minecraft:gravel"},
        {pos: [11, 5, 2], state: "minecraft:gravel"},
        {pos: [11, 5, 3], state: "minecraft:gravel"},
        {pos: [11, 5, 4], state: "minecraft:gravel"},
        {pos: [11, 5, 5], state: "minecraft:gravel"},
        {pos: [11, 5, 6], state: "minecraft:gravel"},
        {pos: [11, 5, 9], state: "minecraft:gravel"},
        {pos: [11, 5, 10], state: "minecraft:gravel"},
        {pos: [11, 5, 11], state: "minecraft:gravel"},
        {pos: [12, 5, 5], state: "minecraft:gravel"},
        {pos: [12, 5, 6], state: "minecraft:gravel"},
        {pos: [1, 6, 4], state: "minecraft:gravel"},
        {pos: [1, 6, 5], state: "minecraft:gravel"},
        {pos: [2, 6, 3], state: "minecraft:stone_bricks"},
        {pos: [2, 6, 4], state: "minecraft:stone_bricks"},
        {pos: [2, 6, 5], state: "minecraft:gravel"},
        {pos: [2, 6, 6], state: "minecraft:gravel"},
        {pos: [3, 6, 3], state: "minecraft:stone_bricks"},
        {pos: [3, 6, 4], state: "minecraft:stone_bricks"},
        {pos: [3, 6, 5], state: "minecraft:gravel"},
        {pos: [5, 6, 15], state: "minecraft:gravel"},
        {pos: [5, 6, 16], state: "minecraft:gravel"},
        {pos: [6, 6, 14], state: "minecraft:gravel"},
        {pos: [6, 6, 15], state: "minecraft:gravel"},
        {pos: [6, 6, 16], state: "minecraft:gravel"},
        {pos: [6, 6, 17], state: "minecraft:gravel"},
        {pos: [6, 6, 18], state: "minecraft:gravel"},
        {pos: [7, 6, 1], state: "minecraft:gravel"},
        {pos: [7, 6, 2], state: "minecraft:gravel"},
        {pos: [7, 6, 14], state: "minecraft:gravel"},
        {pos: [7, 6, 15], state: "minecraft:gravel"},
        {pos: [7, 6, 16], state: "minecraft:gravel"},
        {pos: [7, 6, 17], state: "minecraft:stone_bricks"},
        {pos: [7, 6, 18], state: "minecraft:stone_bricks"},
        {pos: [7, 6, 19], state: "minecraft:gravel"},
        {pos: [8, 6, 2], state: "minecraft:gravel"},
        {pos: [8, 6, 3], state: "minecraft:gravel"},
        {pos: [8, 6, 4], state: "minecraft:gravel"},
        {pos: [8, 6, 5], state: "minecraft:gravel"},
        {pos: [8, 6, 6], state: "minecraft:gravel"},
        {pos: [8, 6, 7], state: "minecraft:gravel"},
        {pos: [8, 6, 8], state: "minecraft:gravel"},
        {pos: [8, 6, 9], state: "minecraft:gravel"},
        {pos: [8, 6, 15], state: "minecraft:gravel"},
        {pos: [8, 6, 16], state: "minecraft:gravel"},
        {pos: [8, 6, 17], state: "minecraft:stone_bricks"},
        {pos: [8, 6, 18], state: "minecraft:stone_bricks"},
        {pos: [8, 6, 19], state: "minecraft:gravel"},
        {pos: [9, 6, 4], state: "minecraft:gravel"},
        {pos: [9, 6, 5], state: "minecraft:gravel"},
        {pos: [9, 6, 6], state: "minecraft:gravel"},
        {pos: [9, 6, 7], state: "minecraft:gravel"},
        {pos: [9, 6, 8], state: "minecraft:gravel"},
        {pos: [9, 6, 9], state: "minecraft:stone_bricks"},
        {pos: [9, 6, 10], state: "minecraft:gravel"},
        {pos: [9, 6, 11], state: "minecraft:gravel"},
        {pos: [9, 6, 16], state: "minecraft:gravel"},
        {pos: [9, 6, 17], state: "minecraft:gravel"},
        {pos: [9, 6, 18], state: "minecraft:gravel"},
        {pos: [10, 6, 5], state: "minecraft:gravel"},
        {pos: [10, 6, 6], state: "minecraft:gravel"},
        {pos: [10, 6, 9], state: "minecraft:stone_bricks"},
        {pos: [10, 6, 10], state: "minecraft:stone_bricks"},
        {pos: [10, 6, 11], state: "minecraft:gravel"},
        {pos: [10, 6, 12], state: "minecraft:gravel"},
        {pos: [11, 6, 6], state: "minecraft:gravel"},
        {pos: [11, 6, 9], state: "minecraft:gravel"},
        {pos: [11, 6, 10], state: "minecraft:gravel"},
        {pos: [2, 7, 3], state: "minecraft:stone_bricks"},
        {pos: [2, 7, 4], state: "minecraft:stone_bricks"},
        {pos: [3, 7, 4], state: "minecraft:stone_bricks"},
        {pos: [7, 7, 17], state: "minecraft:stone_bricks"},
        {pos: [7, 7, 18], state: "minecraft:stone_bricks"},
        {pos: [8, 7, 17], state: "minecraft:stone_bricks"},
        {pos: [8, 7, 18], state: "minecraft:stone_bricks"},
        {pos: [9, 7, 9], state: "minecraft:stone_bricks"},
        {pos: [10, 7, 9], state: "minecraft:stone_bricks"},
        {pos: [10, 7, 10], state: "minecraft:stone_bricks"},
        {pos: [7, 8, 17], state: "minecraft:stone_bricks"},
        {pos: [7, 8, 18], state: "minecraft:gravel"},
        {pos: [8, 8, 18], state: "minecraft:stone_bricks"},
        {pos: [9, 8, 9], state: "minecraft:gravel"}
    ],
    entities: [],
    palette: [
        "minecraft:stone_bricks",
        "minecraft:gravel",
        "minecraft:polished_andesite",
        "minecraft:chiseled_stone_bricks",
        "minecraft:cobblestone_stairs{facing:west,half:top,shape:straight,waterlogged:false}",
        "minecraft:stone_brick_stairs{facing:west,half:top,shape:straight,waterlogged:false}"
    ],
    trailiertales_DataVersion: 2
}
