{
    DataVersion: 3953,
    size: [13, 11, 11],
    data: [
        {pos: [0, 0, 7], state: "minecraft:stone_bricks"},
        {pos: [0, 0, 8], state: "minecraft:stone_bricks"},
        {pos: [0, 0, 9], state: "minecraft:stone_bricks"},
        {pos: [0, 0, 10], state: "minecraft:stone_bricks"},
        {pos: [1, 0, 7], state: "minecraft:stone_bricks"},
        {pos: [1, 0, 8], state: "minecraft:stone_bricks"},
        {pos: [1, 0, 9], state: "minecraft:stone_bricks"},
        {pos: [1, 0, 10], state: "minecraft:polished_andesite"},
        {pos: [2, 0, 7], state: "minecraft:stone_bricks"},
        {pos: [2, 0, 8], state: "minecraft:stone_bricks"},
        {pos: [2, 0, 9], state: "minecraft:stone_bricks"},
        {pos: [2, 0, 10], state: "minecraft:stone_bricks"},
        {pos: [3, 0, 7], state: "minecraft:stone_bricks"},
        {pos: [3, 0, 8], state: "minecraft:stone_bricks"},
        {pos: [3, 0, 9], state: "minecraft:stone_bricks"},
        {pos: [3, 0, 10], state: "minecraft:stone_bricks"},
        {pos: [4, 0, 8], state: "minecraft:stone_bricks"},
        {pos: [4, 0, 9], state: "minecraft:stone_bricks"},
        {pos: [5, 0, 3], state: "minecraft:stone_bricks"},
        {pos: [5, 0, 4], state: "minecraft:stone_bricks"},
        {pos: [5, 0, 5], state: "minecraft:stone_bricks"},
        {pos: [5, 0, 9], state: "minecraft:stone_bricks"},
        {pos: [6, 0, 2], state: "minecraft:chiseled_stone_bricks"},
        {pos: [6, 0, 3], state: "minecraft:stone_bricks"},
        {pos: [6, 0, 4], state: "minecraft:stone_bricks"},
        {pos: [6, 0, 5], state: "minecraft:stone_bricks"},
        {pos: [6, 0, 6], state: "minecraft:stone_bricks"},
        {pos: [6, 0, 7], state: "minecraft:stone_bricks"},
        {pos: [6, 0, 8], state: "minecraft:stone_bricks"},
        {pos: [7, 0, 2], state: "minecraft:stone_bricks"},
        {pos: [7, 0, 3], state: "minecraft:stone_bricks"},
        {pos: [7, 0, 5], state: "minecraft:stone_bricks"},
        {pos: [7, 0, 6], state: "minecraft:stone_bricks"},
        {pos: [7, 0, 7], state: "minecraft:stone_bricks"},
        {pos: [7, 0, 8], state: "minecraft:chiseled_stone_bricks"},
        {pos: [7, 0, 9], state: "minecraft:stone_bricks"},
        {pos: [8, 0, 0], state: "minecraft:polished_andesite"},
        {pos: [8, 0, 1], state: "minecraft:stone_bricks"},
        {pos: [8, 0, 2], state: "minecraft:stone_bricks"},
        {pos: [8, 0, 3], state: "minecraft:stone_bricks"},
        {pos: [8, 0, 8], state: "minecraft:stone_bricks"},
        {pos: [8, 0, 9], state: "minecraft:stone_bricks"},
        {pos: [9, 0, 0], state: "minecraft:stone_bricks"},
        {pos: [9, 0, 1], state: "minecraft:stone_bricks"},
        {pos: [9, 0, 2], state: "minecraft:stone_bricks"},
        {pos: [9, 0, 3], state: "minecraft:stone_bricks"},
        {pos: [9, 0, 8], state: "minecraft:stone_bricks"},
        {pos: [9, 0, 9], state: "minecraft:stone_bricks"},
        {pos: [9, 0, 10], state: "minecraft:stone_bricks"},
        {pos: [10, 0, 0], state: "minecraft:stone_bricks"},
        {pos: [10, 0, 1], state: "minecraft:stone_bricks"},
        {pos: [10, 0, 2], state: "minecraft:stone_bricks"},
        {pos: [10, 0, 3], state: "minecraft:stone_bricks"},
        {pos: [10, 0, 7], state: "minecraft:stone_bricks"},
        {pos: [10, 0, 8], state: "minecraft:stone_bricks"},
        {pos: [10, 0, 9], state: "minecraft:stone_bricks"},
        {pos: [10, 0, 10], state: "minecraft:stone_bricks"},
        {pos: [11, 0, 0], state: "minecraft:stone_bricks"},
        {pos: [11, 0, 1], state: "minecraft:stone_bricks"},
        {pos: [11, 0, 2], state: "minecraft:stone_bricks"},
        {pos: [11, 0, 3], state: "minecraft:polished_andesite"},
        {pos: [11, 0, 4], state: "minecraft:stone_bricks"},
        {pos: [11, 0, 7], state: "minecraft:stone_bricks"},
        {pos: [11, 0, 8], state: "minecraft:stone_bricks"},
        {pos: [11, 0, 9], state: "minecraft:stone_bricks"},
        {pos: [11, 0, 10], state: "minecraft:chiseled_stone_bricks"},
        {pos: [12, 0, 1], state: "minecraft:stone_bricks"},
        {pos: [12, 0, 2], state: "minecraft:stone_bricks"},
        {pos: [12, 0, 3], state: "minecraft:polished_andesite"},
        {pos: [12, 0, 4], state: "minecraft:stone_bricks"},
        {pos: [12, 0, 7], state: "minecraft:polished_andesite"},
        {pos: [12, 0, 8], state: "minecraft:stone_bricks"},
        {pos: [12, 0, 9], state: "minecraft:stone_bricks"},
        {pos: [0, 1, 7], state: "minecraft:stone_bricks"},
        {pos: [0, 1, 8], state: "minecraft:stone_bricks"},
        {pos: [0, 1, 9], state: "minecraft:polished_andesite"},
        {pos: [0, 1, 10], state: "minecraft:stone_bricks"},
        {pos: [1, 1, 7], state: "minecraft:stone_bricks"},
        {pos: [1, 1, 8], state: "minecraft:gravel"},
        {pos: [1, 1, 9], state: "minecraft:gravel"},
        {pos: [1, 1, 10], state: "minecraft:stone_bricks"},
        {pos: [2, 1, 7], state: "minecraft:stone_bricks"},
        {pos: [2, 1, 8], state: "minecraft:gravel"},
        {pos: [2, 1, 9], state: "minecraft:gravel"},
        {pos: [2, 1, 10], state: "minecraft:gravel"},
        {pos: [3, 1, 7], state: "minecraft:stone_bricks"},
        {pos: [3, 1, 8], state: "minecraft:gravel"},
        {pos: [3, 1, 9], state: "minecraft:gravel"},
        {pos: [3, 1, 10], state: "minecraft:stone_bricks"},
        {pos: [4, 1, 8], state: "minecraft:gravel"},
        {pos: [4, 1, 9], state: "minecraft:gravel"},
        {pos: [5, 1, 3], state: "minecraft:gravel"},
        {pos: [5, 1, 4], state: "minecraft:gravel"},
        {pos: [5, 1, 5], state: "minecraft:gravel"},
        {pos: [5, 1, 9], state: "minecraft:gravel"},
        {pos: [6, 1, 2], state: "minecraft:gravel"},
        {pos: [6, 1, 3], state: "minecraft:gravel"},
        {pos: [6, 1, 4], state: "minecraft:gravel"},
        {pos: [6, 1, 5], state: "minecraft:gravel"},
        {pos: [6, 1, 6], state: "minecraft:gravel"},
        {pos: [6, 1, 7], state: "minecraft:gravel"},
        {pos: [6, 1, 8], state: "minecraft:gravel"},
        {pos: [7, 1, 2], state: "minecraft:gravel"},
        {pos: [7, 1, 3], state: "minecraft:gravel"},
        {pos: [7, 1, 5], state: "minecraft:gravel"},
        {pos: [7, 1, 6], state: "minecraft:gravel"},
        {pos: [7, 1, 7], state: "minecraft:gravel"},
        {pos: [7, 1, 8], state: "minecraft:gravel"},
        {pos: [7, 1, 9], state: "minecraft:gravel"},
        {pos: [8, 1, 0], state: "minecraft:stone_bricks"},
        {pos: [8, 1, 1], state: "minecraft:stone_bricks"},
        {pos: [8, 1, 2], state: "minecraft:gravel"},
        {pos: [8, 1, 3], state: "minecraft:gravel"},
        {pos: [8, 1, 8], state: "minecraft:gravel"},
        {pos: [8, 1, 9], state: "minecraft:gravel"},
        {pos: [9, 1, 0], state: "minecraft:stone_bricks"},
        {pos: [9, 1, 1], state: "minecraft:gravel"},
        {pos: [9, 1, 2], state: "minecraft:gravel"},
        {pos: [9, 1, 3], state: "minecraft:gravel"},
        {pos: [9, 1, 8], state: "minecraft:gravel"},
        {pos: [9, 1, 9], state: "minecraft:gravel"},
        {pos: [9, 1, 10], state: "minecraft:stone_bricks"},
        {pos: [10, 1, 0], state: "minecraft:stone_bricks"},
        {pos: [10, 1, 1], state: "minecraft:stone_bricks"},
        {pos: [10, 1, 2], state: "minecraft:gravel"},
        {pos: [10, 1, 3], state: "minecraft:gravel"},
        {pos: [10, 1, 7], state: "minecraft:stone_bricks"},
        {pos: [10, 1, 8], state: "minecraft:gravel"},
        {pos: [10, 1, 9], state: "minecraft:gravel"},
        {pos: [10, 1, 10], state: "minecraft:gravel"},
        {pos: [11, 1, 0], state: "minecraft:stone_bricks"},
        {pos: [11, 1, 1], state: "minecraft:stone_bricks"},
        {pos: [11, 1, 2], state: "minecraft:stone_bricks"},
        {pos: [11, 1, 3], state: "minecraft:stone_bricks"},
        {pos: [11, 1, 4], state: "minecraft:gravel"},
        {pos: [11, 1, 7], state: "minecraft:stone_bricks"},
        {pos: [11, 1, 8], state: "minecraft:gravel"},
        {pos: [11, 1, 9], state: "minecraft:gravel"},
        {pos: [11, 1, 10], state: "minecraft:stone_bricks"},
        {pos: [12, 1, 1], state: "minecraft:gravel"},
        {pos: [12, 1, 2], state: "minecraft:stone_bricks"},
        {pos: [12, 1, 3], state: "minecraft:stone_bricks"},
        {pos: [12, 1, 4], state: "minecraft:gravel"},
        {pos: [12, 1, 7], state: "minecraft:gravel"},
        {pos: [12, 1, 8], state: "minecraft:stone_bricks"},
        {pos: [12, 1, 9], state: "minecraft:chiseled_stone_bricks"},
        {pos: [0, 2, 7], state: "minecraft:stone_bricks"},
        {pos: [0, 2, 8], state: "minecraft:stone_bricks"},
        {pos: [0, 2, 9], state: "minecraft:gravel"},
        {pos: [0, 2, 10], state: "minecraft:stone_bricks"},
        {pos: [1, 2, 7], state: "minecraft:stone_bricks"},
        {pos: [1, 2, 8], state: "minecraft:gravel"},
        {pos: [1, 2, 9], state: "minecraft:gravel"},
        {pos: [1, 2, 10], state: "minecraft:gravel"},
        {pos: [2, 2, 7], state: "minecraft:gravel"},
        {pos: [2, 2, 8], state: "minecraft:gravel"},
        {pos: [2, 2, 9], state: "minecraft:gravel"},
        {pos: [2, 2, 10], state: "minecraft:gravel"},
        {pos: [3, 2, 7], state: "minecraft:stone_bricks"},
        {pos: [3, 2, 8], state: "minecraft:gravel"},
        {pos: [3, 2, 9], state: "minecraft:gravel"},
        {pos: [3, 2, 10], state: "minecraft:stone_bricks"},
        {pos: [4, 2, 8], state: "minecraft:gravel"},
        {pos: [4, 2, 9], state: "minecraft:gravel"},
        {pos: [5, 2, 3], state: "minecraft:gravel"},
        {pos: [5, 2, 4], state: "minecraft:gravel"},
        {pos: [5, 2, 5], state: "minecraft:gravel"},
        {pos: [5, 2, 9], state: "minecraft:gravel"},
        {pos: [6, 2, 2], state: "minecraft:gravel"},
        {pos: [6, 2, 3], state: "minecraft:gravel"},
        {pos: [6, 2, 4], state: "minecraft:gravel"},
        {pos: [6, 2, 5], state: "minecraft:gravel"},
        {pos: [6, 2, 6], state: "minecraft:gravel"},
        {pos: [6, 2, 7], state: "minecraft:gravel"},
        {pos: [6, 2, 8], state: "minecraft:gravel"},
        {pos: [7, 2, 2], state: "minecraft:gravel"},
        {pos: [7, 2, 3], state: "minecraft:gravel"},
        {pos: [7, 2, 5], state: "minecraft:gravel"},
        {pos: [7, 2, 6], state: "minecraft:gravel"},
        {pos: [7, 2, 7], state: "minecraft:gravel"},
        {pos: [7, 2, 8], state: "minecraft:gravel"},
        {pos: [7, 2, 9], state: "minecraft:gravel"},
        {pos: [8, 2, 0], state: "minecraft:stone_bricks"},
        {pos: [8, 2, 1], state: "minecraft:polished_andesite"},
        {pos: [8, 2, 2], state: "minecraft:gravel"},
        {pos: [8, 2, 3], state: "minecraft:gravel"},
        {pos: [8, 2, 8], state: "minecraft:gravel"},
        {pos: [8, 2, 9], state: "minecraft:gravel"},
        {pos: [9, 2, 0], state: "minecraft:gravel"},
        {pos: [9, 2, 1], state: "minecraft:gravel"},
        {pos: [9, 2, 2], state: "minecraft:gravel"},
        {pos: [9, 2, 3], state: "minecraft:gravel"},
        {pos: [9, 2, 8], state: "minecraft:gravel"},
        {pos: [9, 2, 10], state: "minecraft:stone_bricks"},
        {pos: [10, 2, 0], state: "minecraft:gravel"},
        {pos: [10, 2, 1], state: "minecraft:stone_bricks"},
        {pos: [10, 2, 2], state: "minecraft:gravel"},
        {pos: [10, 2, 3], state: "minecraft:gravel"},
        {pos: [10, 2, 7], state: "minecraft:stone_bricks"},
        {pos: [10, 2, 8], state: "minecraft:gravel"},
        {pos: [10, 2, 9], state: "minecraft:gravel"},
        {pos: [10, 2, 10], state: "minecraft:gravel"},
        {pos: [11, 2, 0], state: "minecraft:stone_bricks"},
        {pos: [11, 2, 1], state: "minecraft:stone_bricks"},
        {pos: [11, 2, 2], state: "minecraft:chiseled_stone_bricks"},
        {pos: [11, 2, 3], state: "minecraft:stone_bricks"},
        {pos: [11, 2, 4], state: "minecraft:gravel"},
        {pos: [11, 2, 7], state: "minecraft:gravel"},
        {pos: [11, 2, 8], state: "minecraft:gravel"},
        {pos: [11, 2, 9], state: "minecraft:gravel"},
        {pos: [11, 2, 10], state: "minecraft:stone_bricks"},
        {pos: [12, 2, 1], state: "minecraft:gravel"},
        {pos: [12, 2, 2], state: "minecraft:gravel"},
        {pos: [12, 2, 3], state: "minecraft:stone_bricks"},
        {pos: [12, 2, 4], state: "minecraft:gravel"},
        {pos: [12, 2, 7], state: "minecraft:gravel"},
        {pos: [12, 2, 8], state: "minecraft:gravel"},
        {pos: [12, 2, 9], state: "minecraft:stone_bricks"},
        {pos: [0, 3, 7], state: "minecraft:stone_bricks"},
        {pos: [0, 3, 8], state: "minecraft:gravel"},
        {pos: [0, 3, 9], state: "minecraft:gravel"},
        {pos: [0, 3, 10], state: "minecraft:gravel"},
        {pos: [1, 3, 7], state: "minecraft:gravel"},
        {pos: [1, 3, 8], state: "minecraft:gravel"},
        {pos: [1, 3, 9], state: "minecraft:gravel"},
        {pos: [1, 3, 10], state: "minecraft:gravel"},
        {pos: [2, 3, 7], state: "minecraft:gravel"},
        {pos: [2, 3, 8], state: "minecraft:gravel"},
        {pos: [2, 3, 9], state: "minecraft:gravel"},
        {pos: [2, 3, 10], state: "minecraft:gravel"},
        {pos: [3, 3, 7], state: "minecraft:gravel"},
        {pos: [3, 3, 8], state: "minecraft:gravel"},
        {pos: [3, 3, 9], state: "minecraft:stone_bricks"},
        {pos: [3, 3, 10], state: "minecraft:stone_bricks"},
        {pos: [4, 3, 8], state: "minecraft:gravel"},
        {pos: [4, 3, 9], state: "minecraft:gravel"},
        {pos: [5, 3, 9], state: "minecraft:gravel"},
        {pos: [6, 3, 5], state: "minecraft:gravel"},
        {pos: [6, 3, 6], state: "minecraft:gravel"},
        {pos: [6, 3, 7], state: "minecraft:gravel"},
        {pos: [6, 3, 8], state: "minecraft:gravel"},
        {pos: [7, 3, 2], state: "minecraft:gravel"},
        {pos: [7, 3, 3], state: "minecraft:gravel"},
        {pos: [7, 3, 6], state: "minecraft:gravel"},
        {pos: [7, 3, 8], state: "minecraft:gravel"},
        {pos: [7, 3, 9], state: "minecraft:gravel"},
        {pos: [8, 3, 0], state: "minecraft:stone_bricks"},
        {pos: [8, 3, 1], state: "minecraft:stone_bricks"},
        {pos: [8, 3, 2], state: "minecraft:stone_bricks"},
        {pos: [8, 3, 3], state: "minecraft:gravel"},
        {pos: [8, 3, 8], state: "minecraft:gravel"},
        {pos: [8, 3, 9], state: "minecraft:gravel"},
        {pos: [9, 3, 0], state: "minecraft:gravel"},
        {pos: [9, 3, 1], state: "minecraft:gravel"},
        {pos: [9, 3, 2], state: "minecraft:gravel"},
        {pos: [9, 3, 3], state: "minecraft:gravel"},
        {pos: [9, 3, 8], state: "minecraft:gravel"},
        {pos: [9, 3, 9], state: "minecraft:stone_bricks"},
        {pos: [9, 3, 10], state: "minecraft:stone_bricks"},
        {pos: [10, 3, 0], state: "minecraft:gravel"},
        {pos: [10, 3, 1], state: "minecraft:stone_bricks"},
        {pos: [10, 3, 2], state: "minecraft:gravel"},
        {pos: [10, 3, 3], state: "minecraft:gravel"},
        {pos: [10, 3, 7], state: "minecraft:gravel"},
        {pos: [10, 3, 8], state: "minecraft:gravel"},
        {pos: [10, 3, 9], state: "minecraft:gravel"},
        {pos: [10, 3, 10], state: "minecraft:gravel"},
        {pos: [11, 3, 0], state: "minecraft:gravel"},
        {pos: [11, 3, 1], state: "minecraft:stone_bricks"},
        {pos: [11, 3, 2], state: "minecraft:gravel"},
        {pos: [11, 3, 3], state: "minecraft:stone_bricks"},
        {pos: [11, 3, 4], state: "minecraft:gravel"},
        {pos: [11, 3, 7], state: "minecraft:gravel"},
        {pos: [11, 3, 8], state: "minecraft:gravel"},
        {pos: [11, 3, 9], state: "minecraft:gravel"},
        {pos: [11, 3, 10], state: "minecraft:stone_bricks"},
        {pos: [12, 3, 1], state: "minecraft:gravel"},
        {pos: [12, 3, 2], state: "minecraft:gravel"},
        {pos: [12, 3, 3], state: "minecraft:gravel"},
        {pos: [12, 3, 4], state: "minecraft:gravel"},
        {pos: [12, 3, 7], state: "minecraft:gravel"},
        {pos: [12, 3, 9], state: "minecraft:stone_bricks"},
        {pos: [0, 4, 7], state: "minecraft:gravel"},
        {pos: [0, 4, 8], state: "minecraft:gravel"},
        {pos: [0, 4, 9], state: "minecraft:gravel"},
        {pos: [1, 4, 7], state: "minecraft:gravel"},
        {pos: [1, 4, 8], state: "minecraft:gravel"},
        {pos: [1, 4, 9], state: "minecraft:gravel"},
        {pos: [1, 4, 10], state: "minecraft:gravel"},
        {pos: [2, 4, 7], state: "minecraft:gravel"},
        {pos: [2, 4, 8], state: "minecraft:gravel"},
        {pos: [2, 4, 9], state: "minecraft:gravel"},
        {pos: [2, 4, 10], state: "minecraft:gravel"},
        {pos: [3, 4, 8], state: "minecraft:gravel"},
        {pos: [3, 4, 9], state: "minecraft:gravel"},
        {pos: [3, 4, 10], state: "minecraft:gravel"},
        {pos: [4, 4, 8], state: "minecraft:gravel"},
        {pos: [4, 4, 9], state: "minecraft:gravel"},
        {pos: [5, 4, 9], state: "minecraft:gravel"},
        {pos: [7, 4, 2], state: "minecraft:gravel"},
        {pos: [7, 4, 3], state: "minecraft:gravel"},
        {pos: [8, 4, 0], state: "minecraft:stone_bricks"},
        {pos: [8, 4, 1], state: "minecraft:stone_bricks"},
        {pos: [8, 4, 2], state: "minecraft:gravel"},
        {pos: [8, 4, 3], state: "minecraft:stone_bricks"},
        {pos: [9, 4, 0], state: "minecraft:gravel"},
        {pos: [9, 4, 1], state: "minecraft:gravel"},
        {pos: [9, 4, 2], state: "minecraft:gravel"},
        {pos: [9, 4, 3], state: "minecraft:stone_bricks"},
        {pos: [10, 4, 0], state: "minecraft:gravel"},
        {pos: [10, 4, 1], state: "minecraft:gravel"},
        {pos: [10, 4, 2], state: "minecraft:gravel"},
        {pos: [10, 4, 3], state: "minecraft:polished_andesite"},
        {pos: [10, 4, 7], state: "minecraft:gravel"},
        {pos: [11, 4, 0], state: "minecraft:gravel"},
        {pos: [11, 4, 1], state: "minecraft:stone_bricks"},
        {pos: [11, 4, 2], state: "minecraft:gravel"},
        {pos: [11, 4, 3], state: "minecraft:stone_bricks"},
        {pos: [11, 4, 4], state: "minecraft:gravel"},
        {pos: [11, 4, 7], state: "minecraft:gravel"},
        {pos: [11, 4, 9], state: "minecraft:gravel"},
        {pos: [11, 4, 10], state: "minecraft:gravel"},
        {pos: [12, 4, 1], state: "minecraft:gravel"},
        {pos: [12, 4, 2], state: "minecraft:gravel"},
        {pos: [12, 4, 3], state: "minecraft:gravel"},
        {pos: [12, 4, 4], state: "minecraft:gravel"},
        {pos: [12, 4, 7], state: "minecraft:gravel"},
        {pos: [2, 5, 9], state: "minecraft:gravel"},
        {pos: [2, 5, 10], state: "minecraft:gravel"},
        {pos: [3, 5, 8], state: "minecraft:gravel"},
        {pos: [3, 5, 9], state: "minecraft:gravel"},
        {pos: [3, 5, 10], state: "minecraft:gravel"},
        {pos: [7, 5, 2], state: "minecraft:gravel"},
        {pos: [7, 5, 3], state: "minecraft:gravel"},
        {pos: [8, 5, 0], state: "minecraft:gravel"},
        {pos: [8, 5, 1], state: "minecraft:stone_bricks"},
        {pos: [8, 5, 2], state: "minecraft:gravel"},
        {pos: [8, 5, 3], state: "minecraft:gravel"},
        {pos: [9, 5, 0], state: "minecraft:gravel"},
        {pos: [9, 5, 1], state: "minecraft:gravel"},
        {pos: [9, 5, 2], state: "minecraft:gravel"},
        {pos: [9, 5, 3], state: "minecraft:stone_bricks"},
        {pos: [10, 5, 0], state: "minecraft:gravel"},
        {pos: [10, 5, 1], state: "minecraft:gravel"},
        {pos: [10, 5, 2], state: "minecraft:gravel"},
        {pos: [10, 5, 3], state: "minecraft:stone_bricks"},
        {pos: [11, 5, 0], state: "minecraft:gravel"},
        {pos: [11, 5, 1], state: "minecraft:stone_bricks"},
        {pos: [11, 5, 2], state: "minecraft:stone_bricks"},
        {pos: [11, 5, 3], state: "minecraft:polished_andesite"},
        {pos: [11, 5, 4], state: "minecraft:gravel"},
        {pos: [12, 5, 1], state: "minecraft:gravel"},
        {pos: [12, 5, 2], state: "minecraft:gravel"},
        {pos: [12, 5, 3], state: "minecraft:gravel"},
        {pos: [12, 5, 4], state: "minecraft:gravel"},
        {pos: [7, 6, 2], state: "minecraft:gravel"},
        {pos: [8, 6, 0], state: "minecraft:gravel"},
        {pos: [8, 6, 1], state: "minecraft:polished_andesite"},
        {pos: [8, 6, 2], state: "minecraft:gravel"},
        {pos: [8, 6, 3], state: "minecraft:gravel"},
        {pos: [9, 6, 0], state: "minecraft:gravel"},
        {pos: [9, 6, 1], state: "minecraft:stone_bricks"},
        {pos: [9, 6, 2], state: "minecraft:gravel"},
        {pos: [9, 6, 3], state: "minecraft:gravel"},
        {pos: [10, 6, 0], state: "minecraft:gravel"},
        {pos: [10, 6, 1], state: "minecraft:gravel"},
        {pos: [10, 6, 2], state: "minecraft:gravel"},
        {pos: [10, 6, 3], state: "minecraft:stone_bricks"},
        {pos: [11, 6, 0], state: "minecraft:gravel"},
        {pos: [11, 6, 1], state: "minecraft:stone_bricks"},
        {pos: [11, 6, 2], state: "minecraft:stone_bricks"},
        {pos: [11, 6, 3], state: "minecraft:polished_andesite"},
        {pos: [11, 6, 4], state: "minecraft:gravel"},
        {pos: [12, 6, 1], state: "minecraft:gravel"},
        {pos: [12, 6, 2], state: "minecraft:gravel"},
        {pos: [12, 6, 3], state: "minecraft:gravel"},
        {pos: [12, 6, 4], state: "minecraft:gravel"},
        {pos: [8, 7, 0], state: "minecraft:gravel"},
        {pos: [8, 7, 1], state: "minecraft:stone_bricks"},
        {pos: [8, 7, 2], state: "minecraft:stone_bricks"},
        {pos: [8, 7, 3], state: "minecraft:stone_bricks"},
        {pos: [9, 7, 0], state: "minecraft:gravel"},
        {pos: [9, 7, 1], state: "minecraft:stone_bricks"},
        {pos: [9, 7, 2], state: "minecraft:gravel"},
        {pos: [9, 7, 3], state: "minecraft:stone_bricks"},
        {pos: [10, 7, 0], state: "minecraft:gravel"},
        {pos: [10, 7, 1], state: "minecraft:polished_andesite"},
        {pos: [10, 7, 2], state: "minecraft:gravel"},
        {pos: [10, 7, 3], state: "minecraft:stone_bricks"},
        {pos: [11, 7, 0], state: "minecraft:gravel"},
        {pos: [11, 7, 1], state: "minecraft:stone_bricks"},
        {pos: [11, 7, 2], state: "minecraft:stone_bricks"},
        {pos: [11, 7, 3], state: "minecraft:stone_bricks"},
        {pos: [11, 7, 4], state: "minecraft:gravel"},
        {pos: [12, 7, 1], state: "minecraft:gravel"},
        {pos: [12, 7, 2], state: "minecraft:gravel"},
        {pos: [12, 7, 3], state: "minecraft:gravel"},
        {pos: [12, 7, 4], state: "minecraft:gravel"},
        {pos: [8, 8, 1], state: "minecraft:gravel"},
        {pos: [8, 8, 2], state: "minecraft:gravel"},
        {pos: [8, 8, 3], state: "minecraft:gravel"},
        {pos: [9, 8, 1], state: "minecraft:gravel"},
        {pos: [9, 8, 2], state: "minecraft:gravel"},
        {pos: [9, 8, 3], state: "minecraft:gravel"},
        {pos: [10, 8, 0], state: "minecraft:gravel"},
        {pos: [10, 8, 1], state: "minecraft:stone_bricks"},
        {pos: [10, 8, 2], state: "minecraft:gravel"},
        {pos: [10, 8, 3], state: "minecraft:gravel"},
        {pos: [11, 8, 1], state: "minecraft:stone_bricks"},
        {pos: [11, 8, 2], state: "minecraft:stone_bricks"},
        {pos: [11, 8, 3], state: "minecraft:stone_bricks"},
        {pos: [11, 8, 4], state: "minecraft:gravel"},
        {pos: [12, 8, 3], state: "minecraft:gravel"},
        {pos: [10, 9, 1], state: "minecraft:gravel"},
        {pos: [10, 9, 2], state: "minecraft:gravel"},
        {pos: [11, 9, 1], state: "minecraft:stone_bricks"},
        {pos: [11, 9, 2], state: "minecraft:stone_bricks"},
        {pos: [11, 10, 1], state: "minecraft:stone_bricks"},
        {pos: [11, 10, 2], state: "minecraft:stone_bricks"}
    ],
    entities: [],
    palette: [
        "minecraft:stone_bricks",
        "minecraft:polished_andesite",
        "minecraft:chiseled_stone_bricks",
        "minecraft:gravel"
    ],
    trailiertales_DataVersion: 2
}
