{
    DataVersion: 3953,
    size: [12, 10, 10],
    data: [
        {pos: [0, 0, 3], state: "minecraft:stone_bricks"},
        {pos: [1, 0, 2], state: "minecraft:stone_bricks"},
        {pos: [1, 0, 3], state: "minecraft:stone_bricks"},
        {pos: [1, 0, 4], state: "minecraft:stone_bricks"},
        {pos: [2, 0, 1], state: "minecraft:stone_bricks"},
        {pos: [2, 0, 2], state: "minecraft:stone_bricks"},
        {pos: [2, 0, 3], state: "minecraft:stone_bricks"},
        {pos: [2, 0, 4], state: "minecraft:stone_bricks"},
        {pos: [2, 0, 5], state: "minecraft:stone_bricks"},
        {pos: [2, 0, 7], state: "minecraft:stone_bricks"},
        {pos: [2, 0, 8], state: "minecraft:stone_bricks"},
        {pos: [2, 0, 9], state: "minecraft:stone_bricks"},
        {pos: [3, 0, 0], state: "minecraft:stone_bricks"},
        {pos: [3, 0, 1], state: "minecraft:stone_bricks"},
        {pos: [3, 0, 2], state: "minecraft:stone_bricks"},
        {pos: [3, 0, 3], state: "minecraft:stone_bricks"},
        {pos: [3, 0, 4], state: "minecraft:stone_bricks"},
        {pos: [3, 0, 7], state: "minecraft:stone_bricks"},
        {pos: [3, 0, 8], state: "minecraft:stone_bricks"},
        {pos: [3, 0, 9], state: "minecraft:stone_bricks"},
        {pos: [4, 0, 0], state: "minecraft:stone_bricks"},
        {pos: [4, 0, 1], state: "minecraft:chiseled_stone_bricks"},
        {pos: [4, 0, 2], state: "minecraft:polished_andesite"},
        {pos: [4, 0, 3], state: "minecraft:stone_bricks"},
        {pos: [4, 0, 4], state: "minecraft:stone_bricks"},
        {pos: [4, 0, 7], state: "minecraft:stone_bricks"},
        {pos: [4, 0, 8], state: "minecraft:stone_bricks"},
        {pos: [4, 0, 9], state: "minecraft:stone_bricks"},
        {pos: [5, 0, 3], state: "minecraft:stone_bricks"},
        {pos: [5, 0, 4], state: "minecraft:stone_bricks"},
        {pos: [5, 0, 6], state: "minecraft:stone_bricks"},
        {pos: [5, 0, 7], state: "minecraft:stone_bricks"},
        {pos: [6, 0, 4], state: "minecraft:stone_bricks"},
        {pos: [6, 0, 5], state: "minecraft:stone_bricks"},
        {pos: [7, 0, 4], state: "minecraft:stone_bricks"},
        {pos: [7, 0, 5], state: "minecraft:stone_bricks"},
        {pos: [7, 0, 6], state: "minecraft:stone_bricks"},
        {pos: [8, 0, 3], state: "minecraft:stone_bricks"},
        {pos: [8, 0, 4], state: "minecraft:stone_bricks"},
        {pos: [8, 0, 5], state: "minecraft:stone_bricks"},
        {pos: [8, 0, 6], state: "minecraft:stone_bricks"},
        {pos: [8, 0, 7], state: "minecraft:stone_bricks"},
        {pos: [8, 0, 8], state: "minecraft:stone_bricks"},
        {pos: [9, 0, 3], state: "minecraft:stone_bricks"},
        {pos: [9, 0, 4], state: "minecraft:stone_bricks"},
        {pos: [9, 0, 5], state: "minecraft:stone_bricks"},
        {pos: [9, 0, 6], state: "minecraft:stone_bricks"},
        {pos: [9, 0, 7], state: "minecraft:stone_bricks"},
        {pos: [9, 0, 8], state: "minecraft:stone_bricks"},
        {pos: [10, 0, 3], state: "minecraft:stone_bricks"},
        {pos: [10, 0, 4], state: "minecraft:stone_bricks"},
        {pos: [10, 0, 5], state: "minecraft:stone_bricks"},
        {pos: [10, 0, 6], state: "minecraft:stone_bricks"},
        {pos: [10, 0, 7], state: "minecraft:stone_bricks"},
        {pos: [10, 0, 8], state: "minecraft:stone_bricks"},
        {pos: [11, 0, 4], state: "minecraft:stone_bricks"},
        {pos: [11, 0, 5], state: "minecraft:stone_bricks"},
        {pos: [11, 0, 6], state: "minecraft:stone_bricks"},
        {pos: [0, 1, 3], state: "minecraft:gravel"},
        {pos: [1, 1, 2], state: "minecraft:stone_bricks"},
        {pos: [1, 1, 3], state: "minecraft:stone_bricks"},
        {pos: [1, 1, 4], state: "minecraft:gravel"},
        {pos: [2, 1, 1], state: "minecraft:gravel"},
        {pos: [2, 1, 2], state: "minecraft:stone_bricks"},
        {pos: [2, 1, 3], state: "minecraft:stone_bricks"},
        {pos: [2, 1, 4], state: "minecraft:stone_bricks"},
        {pos: [2, 1, 5], state: "minecraft:gravel"},
        {pos: [2, 1, 7], state: "minecraft:gravel"},
        {pos: [2, 1, 8], state: "minecraft:stone_bricks"},
        {pos: [2, 1, 9], state: "minecraft:stone_bricks"},
        {pos: [3, 1, 0], state: "minecraft:gravel"},
        {pos: [3, 1, 1], state: "minecraft:stone_bricks"},
        {pos: [3, 1, 2], state: "minecraft:gravel"},
        {pos: [3, 1, 3], state: "minecraft:gravel"},
        {pos: [3, 1, 4], state: "minecraft:gravel"},
        {pos: [3, 1, 7], state: "minecraft:gravel"},
        {pos: [3, 1, 8], state: "minecraft:gravel"},
        {pos: [3, 1, 9], state: "minecraft:polished_andesite"},
        {pos: [4, 1, 0], state: "minecraft:gravel"},
        {pos: [4, 1, 1], state: "minecraft:stone_bricks"},
        {pos: [4, 1, 2], state: "minecraft:gravel"},
        {pos: [4, 1, 3], state: "minecraft:gravel"},
        {pos: [4, 1, 4], state: "minecraft:gravel"},
        {pos: [4, 1, 7], state: "minecraft:gravel"},
        {pos: [4, 1, 8], state: "minecraft:gravel"},
        {pos: [4, 1, 9], state: "minecraft:gravel"},
        {pos: [5, 1, 3], state: "minecraft:gravel"},
        {pos: [5, 1, 4], state: "minecraft:gravel"},
        {pos: [5, 1, 6], state: "minecraft:gravel"},
        {pos: [5, 1, 7], state: "minecraft:gravel"},
        {pos: [6, 1, 4], state: "minecraft:gravel"},
        {pos: [6, 1, 5], state: "minecraft:gravel"},
        {pos: [7, 1, 4], state: "minecraft:stone_bricks"},
        {pos: [7, 1, 5], state: "minecraft:gravel"},
        {pos: [7, 1, 6], state: "minecraft:gravel"},
        {pos: [8, 1, 3], state: "minecraft:stone_bricks"},
        {pos: [8, 1, 4], state: "minecraft:water_cauldron{level:3}"},
        {pos: [8, 1, 5], state: "minecraft:gravel"},
        {pos: [8, 1, 6], state: "minecraft:gravel"},
        {pos: [8, 1, 7], state: "minecraft:stone_bricks"},
        {pos: [8, 1, 8], state: "minecraft:stone_bricks"},
        {pos: [9, 1, 3], state: "minecraft:stone_bricks"},
        {pos: [9, 1, 4], state: "minecraft:gravel"},
        {pos: [9, 1, 5], state: "minecraft:gravel"},
        {pos: [9, 1, 6], state: "minecraft:gravel"},
        {pos: [9, 1, 7], state: "minecraft:gravel"},
        {pos: [9, 1, 8], state: "minecraft:stone_bricks"},
        {pos: [10, 1, 3], state: "minecraft:stone_bricks"},
        {pos: [10, 1, 4], state: "minecraft:gravel"},
        {pos: [10, 1, 5], state: "minecraft:gravel"},
        {pos: [10, 1, 6], state: "minecraft:stone_bricks"},
        {pos: [10, 1, 7], state: "minecraft:chiseled_stone_bricks"},
        {pos: [10, 1, 8], state: "minecraft:stone_bricks"},
        {pos: [11, 1, 4], state: "minecraft:stone_bricks"},
        {pos: [11, 1, 5], state: "minecraft:stone_bricks"},
        {pos: [11, 1, 6], state: "minecraft:stone_bricks"},
        {pos: [0, 2, 3], state: "minecraft:gravel"},
        {pos: [1, 2, 2], state: "minecraft:gravel"},
        {pos: [1, 2, 3], state: "minecraft:gravel"},
        {pos: [1, 2, 4], state: "minecraft:gravel"},
        {pos: [2, 2, 1], state: "minecraft:gravel"},
        {pos: [2, 2, 2], state: "minecraft:stone_bricks"},
        {pos: [2, 2, 3], state: "minecraft:stone_bricks"},
        {pos: [2, 2, 4], state: "minecraft:gravel"},
        {pos: [2, 2, 5], state: "minecraft:gravel"},
        {pos: [2, 2, 7], state: "minecraft:gravel"},
        {pos: [2, 2, 8], state: "minecraft:gravel"},
        {pos: [2, 2, 9], state: "minecraft:polished_andesite"},
        {pos: [3, 2, 0], state: "minecraft:gravel"},
        {pos: [3, 2, 1], state: "minecraft:stone_bricks"},
        {pos: [3, 2, 2], state: "minecraft:gravel"},
        {pos: [3, 2, 3], state: "minecraft:gravel"},
        {pos: [3, 2, 4], state: "minecraft:gravel"},
        {pos: [3, 2, 7], state: "minecraft:gravel"},
        {pos: [3, 2, 8], state: "minecraft:gravel"},
        {pos: [3, 2, 9], state: "minecraft:gravel"},
        {pos: [4, 2, 0], state: "minecraft:gravel"},
        {pos: [4, 2, 1], state: "minecraft:gravel"},
        {pos: [4, 2, 2], state: "minecraft:gravel"},
        {pos: [4, 2, 3], state: "minecraft:gravel"},
        {pos: [4, 2, 4], state: "minecraft:gravel"},
        {pos: [4, 2, 7], state: "minecraft:gravel"},
        {pos: [4, 2, 8], state: "minecraft:gravel"},
        {pos: [4, 2, 9], state: "minecraft:gravel"},
        {pos: [5, 2, 3], state: "minecraft:gravel"},
        {pos: [5, 2, 4], state: "minecraft:gravel"},
        {pos: [5, 2, 6], state: "minecraft:gravel"},
        {pos: [5, 2, 7], state: "minecraft:gravel"},
        {pos: [6, 2, 5], state: "minecraft:gravel"},
        {pos: [7, 2, 4], state: "minecraft:stone_bricks"},
        {pos: [7, 2, 5], state: "minecraft:gravel"},
        {pos: [7, 2, 6], state: "minecraft:gravel"},
        {pos: [8, 2, 3], state: "minecraft:stone_bricks"},
        {pos: [8, 2, 4], state: "minecraft:gravel"},
        {pos: [8, 2, 5], state: "minecraft:gravel"},
        {pos: [8, 2, 6], state: "minecraft:gravel"},
        {pos: [8, 2, 7], state: "minecraft:stone_bricks"},
        {pos: [8, 2, 8], state: "minecraft:stone_bricks"},
        {pos: [9, 2, 3], state: "minecraft:stone_bricks"},
        {pos: [9, 2, 4], state: "minecraft:gravel"},
        {pos: [9, 2, 5], state: "minecraft:gravel"},
        {pos: [9, 2, 6], state: "minecraft:gravel"},
        {pos: [9, 2, 7], state: "minecraft:gravel"},
        {pos: [9, 2, 8], state: "minecraft:gravel"},
        {pos: [10, 2, 3], state: "minecraft:stone_bricks"},
        {pos: [10, 2, 4], state: "minecraft:gravel"},
        {pos: [10, 2, 5], state: "minecraft:gravel"},
        {pos: [10, 2, 6], state: "minecraft:gravel"},
        {pos: [10, 2, 7], state: "minecraft:stone_bricks"},
        {pos: [10, 2, 8], state: "minecraft:stone_bricks"},
        {pos: [11, 2, 4], state: "minecraft:stone_bricks"},
        {pos: [11, 2, 5], state: "minecraft:gravel"},
        {pos: [11, 2, 6], state: "minecraft:stone_bricks"},
        {pos: [0, 3, 3], state: "minecraft:gravel"},
        {pos: [1, 3, 2], state: "minecraft:gravel"},
        {pos: [1, 3, 3], state: "minecraft:gravel"},
        {pos: [1, 3, 4], state: "minecraft:gravel"},
        {pos: [2, 3, 1], state: "minecraft:gravel"},
        {pos: [2, 3, 2], state: "minecraft:stone_bricks"},
        {pos: [2, 3, 3], state: "minecraft:gravel"},
        {pos: [2, 3, 4], state: "minecraft:gravel"},
        {pos: [2, 3, 5], state: "minecraft:gravel"},
        {pos: [2, 3, 7], state: "minecraft:gravel"},
        {pos: [2, 3, 8], state: "minecraft:gravel"},
        {pos: [2, 3, 9], state: "minecraft:gravel"},
        {pos: [3, 3, 0], state: "minecraft:gravel"},
        {pos: [3, 3, 1], state: "minecraft:gravel"},
        {pos: [3, 3, 2], state: "minecraft:gravel"},
        {pos: [3, 3, 3], state: "minecraft:gravel"},
        {pos: [3, 3, 4], state: "minecraft:gravel"},
        {pos: [3, 3, 7], state: "minecraft:gravel"},
        {pos: [3, 3, 8], state: "minecraft:gravel"},
        {pos: [3, 3, 9], state: "minecraft:gravel"},
        {pos: [4, 3, 0], state: "minecraft:gravel"},
        {pos: [4, 3, 1], state: "minecraft:gravel"},
        {pos: [4, 3, 2], state: "minecraft:gravel"},
        {pos: [4, 3, 3], state: "minecraft:gravel"},
        {pos: [4, 3, 4], state: "minecraft:gravel"},
        {pos: [4, 3, 7], state: "minecraft:gravel"},
        {pos: [4, 3, 8], state: "minecraft:gravel"},
        {pos: [4, 3, 9], state: "minecraft:gravel"},
        {pos: [5, 3, 3], state: "minecraft:gravel"},
        {pos: [7, 3, 4], state: "minecraft:stone_bricks"},
        {pos: [7, 3, 5], state: "minecraft:gravel"},
        {pos: [7, 3, 6], state: "minecraft:gravel"},
        {pos: [8, 3, 3], state: "minecraft:stone_bricks"},
        {pos: [8, 3, 4], state: "minecraft:gravel"},
        {pos: [8, 3, 5], state: "minecraft:gravel"},
        {pos: [8, 3, 6], state: "minecraft:gravel"},
        {pos: [8, 3, 7], state: "minecraft:stone_bricks"},
        {pos: [8, 3, 8], state: "minecraft:gravel"},
        {pos: [9, 3, 3], state: "minecraft:stone_bricks"},
        {pos: [9, 3, 4], state: "minecraft:gravel"},
        {pos: [9, 3, 5], state: "minecraft:gravel"},
        {pos: [9, 3, 6], state: "minecraft:stone_bricks"},
        {pos: [9, 3, 7], state: "minecraft:gravel"},
        {pos: [9, 3, 8], state: "minecraft:gravel"},
        {pos: [10, 3, 3], state: "minecraft:gravel"},
        {pos: [10, 3, 4], state: "minecraft:gravel"},
        {pos: [10, 3, 5], state: "minecraft:gravel"},
        {pos: [10, 3, 6], state: "minecraft:stone_bricks"},
        {pos: [10, 3, 7], state: "minecraft:polished_andesite"},
        {pos: [10, 3, 8], state: "minecraft:gravel"},
        {pos: [11, 3, 4], state: "minecraft:stone_bricks"},
        {pos: [11, 3, 5], state: "minecraft:stone_bricks"},
        {pos: [11, 3, 6], state: "minecraft:stone_bricks"},
        {pos: [1, 4, 2], state: "minecraft:gravel"},
        {pos: [2, 4, 1], state: "minecraft:gravel"},
        {pos: [2, 4, 2], state: "minecraft:stone_bricks"},
        {pos: [2, 4, 3], state: "minecraft:gravel"},
        {pos: [3, 4, 1], state: "minecraft:gravel"},
        {pos: [3, 4, 2], state: "minecraft:stone_bricks"},
        {pos: [3, 4, 3], state: "minecraft:gravel"},
        {pos: [3, 4, 8], state: "minecraft:gravel"},
        {pos: [4, 4, 2], state: "minecraft:gravel"},
        {pos: [7, 4, 4], state: "minecraft:stone_bricks"},
        {pos: [7, 4, 5], state: "minecraft:stone_bricks"},
        {pos: [7, 4, 6], state: "minecraft:stone_bricks"},
        {pos: [8, 4, 3], state: "minecraft:stone_bricks"},
        {pos: [8, 4, 4], state: "minecraft:gravel"},
        {pos: [8, 4, 5], state: "minecraft:gravel"},
        {pos: [8, 4, 6], state: "minecraft:stone_bricks"},
        {pos: [8, 4, 7], state: "minecraft:stone_bricks"},
        {pos: [8, 4, 8], state: "minecraft:gravel"},
        {pos: [9, 4, 3], state: "minecraft:gravel"},
        {pos: [9, 4, 4], state: "minecraft:gravel"},
        {pos: [9, 4, 5], state: "minecraft:gravel"},
        {pos: [9, 4, 6], state: "minecraft:gravel"},
        {pos: [9, 4, 7], state: "minecraft:stone_bricks"},
        {pos: [9, 4, 8], state: "minecraft:gravel"},
        {pos: [10, 4, 3], state: "minecraft:gravel"},
        {pos: [10, 4, 4], state: "minecraft:gravel"},
        {pos: [10, 4, 5], state: "minecraft:gravel"},
        {pos: [10, 4, 6], state: "minecraft:stone_bricks"},
        {pos: [10, 4, 7], state: "minecraft:gravel"},
        {pos: [10, 4, 8], state: "minecraft:gravel"},
        {pos: [11, 4, 4], state: "minecraft:stone_bricks"},
        {pos: [11, 4, 5], state: "minecraft:stone_bricks"},
        {pos: [11, 4, 6], state: "minecraft:gravel"},
        {pos: [2, 5, 2], state: "minecraft:gravel"},
        {pos: [3, 5, 2], state: "minecraft:gravel"},
        {pos: [7, 5, 4], state: "minecraft:gravel"},
        {pos: [7, 5, 5], state: "minecraft:stone_bricks"},
        {pos: [7, 5, 6], state: "minecraft:gravel"},
        {pos: [8, 5, 3], state: "minecraft:gravel"},
        {pos: [8, 5, 4], state: "minecraft:stone_bricks"},
        {pos: [8, 5, 5], state: "minecraft:gravel"},
        {pos: [8, 5, 6], state: "minecraft:stone_bricks"},
        {pos: [8, 5, 7], state: "minecraft:gravel"},
        {pos: [9, 5, 3], state: "minecraft:gravel"},
        {pos: [9, 5, 4], state: "minecraft:chiseled_stone_bricks"},
        {pos: [9, 5, 5], state: "minecraft:gravel"},
        {pos: [9, 5, 6], state: "minecraft:gravel"},
        {pos: [9, 5, 7], state: "minecraft:gravel"},
        {pos: [9, 5, 8], state: "minecraft:gravel"},
        {pos: [10, 5, 4], state: "minecraft:gravel"},
        {pos: [10, 5, 5], state: "minecraft:stone_bricks"},
        {pos: [10, 5, 6], state: "minecraft:gravel"},
        {pos: [10, 5, 7], state: "minecraft:gravel"},
        {pos: [11, 5, 4], state: "minecraft:gravel"},
        {pos: [11, 5, 5], state: "minecraft:gravel"},
        {pos: [11, 5, 6], state: "minecraft:gravel"},
        {pos: [7, 6, 4], state: "minecraft:gravel"},
        {pos: [7, 6, 5], state: "minecraft:stone_bricks"},
        {pos: [7, 6, 6], state: "minecraft:gravel"},
        {pos: [8, 6, 3], state: "minecraft:gravel"},
        {pos: [8, 6, 4], state: "minecraft:stone_bricks"},
        {pos: [8, 6, 5], state: "minecraft:gravel"},
        {pos: [8, 6, 6], state: "minecraft:stone_bricks"},
        {pos: [8, 6, 7], state: "minecraft:gravel"},
        {pos: [9, 6, 4], state: "minecraft:gravel"},
        {pos: [9, 6, 5], state: "minecraft:gravel"},
        {pos: [9, 6, 6], state: "minecraft:stone_bricks"},
        {pos: [9, 6, 7], state: "minecraft:gravel"},
        {pos: [10, 6, 4], state: "minecraft:gravel"},
        {pos: [10, 6, 5], state: "minecraft:gravel"},
        {pos: [10, 6, 6], state: "minecraft:gravel"},
        {pos: [7, 7, 4], state: "minecraft:gravel"},
        {pos: [7, 7, 5], state: "minecraft:stone_bricks"},
        {pos: [7, 7, 6], state: "minecraft:gravel"},
        {pos: [8, 7, 4], state: "minecraft:stone_bricks"},
        {pos: [8, 7, 5], state: "minecraft:gravel"},
        {pos: [8, 7, 6], state: "minecraft:stone_bricks"},
        {pos: [8, 7, 7], state: "minecraft:gravel"},
        {pos: [9, 7, 4], state: "minecraft:gravel"},
        {pos: [9, 7, 5], state: "minecraft:gravel"},
        {pos: [9, 7, 6], state: "minecraft:gravel"},
        {pos: [7, 8, 5], state: "minecraft:stone_bricks"},
        {pos: [8, 8, 5], state: "minecraft:gravel"},
        {pos: [8, 8, 6], state: "minecraft:stone_bricks"},
        {pos: [8, 9, 6], state: "minecraft:stone_bricks"}
    ],
    entities: [],
    palette: [
        "minecraft:stone_bricks",
        "minecraft:chiseled_stone_bricks",
        "minecraft:polished_andesite",
        "minecraft:gravel",
        "minecraft:water_cauldron{level:3}"
    ],
    trailiertales_DataVersion: 2
}
