{
    DataVersion: 3953,
    size: [10, 7, 7],
    data: [
        {pos: [0, 0, 3], state: "minecraft:stone_bricks"},
        {pos: [0, 0, 4], state: "minecraft:stone_bricks"},
        {pos: [1, 0, 2], state: "minecraft:stone_bricks"},
        {pos: [1, 0, 3], state: "minecraft:stone_bricks"},
        {pos: [1, 0, 4], state: "minecraft:stone_bricks"},
        {pos: [1, 0, 5], state: "minecraft:stone_bricks"},
        {pos: [2, 0, 0], state: "minecraft:stone_bricks"},
        {pos: [2, 0, 1], state: "minecraft:polished_andesite"},
        {pos: [2, 0, 2], state: "minecraft:stone_bricks"},
        {pos: [2, 0, 3], state: "minecraft:stone_bricks"},
        {pos: [2, 0, 4], state: "minecraft:stone_bricks"},
        {pos: [2, 0, 5], state: "minecraft:stone_bricks"},
        {pos: [2, 0, 6], state: "minecraft:stone_bricks"},
        {pos: [3, 0, 0], state: "minecraft:stone_bricks"},
        {pos: [3, 0, 1], state: "minecraft:stone_bricks"},
        {pos: [3, 0, 2], state: "minecraft:stone_bricks"},
        {pos: [3, 0, 3], state: "minecraft:stone_bricks"},
        {pos: [3, 0, 4], state: "minecraft:stone_bricks"},
        {pos: [3, 0, 5], state: "minecraft:stone_bricks"},
        {pos: [3, 0, 6], state: "minecraft:stone_bricks"},
        {pos: [4, 0, 1], state: "minecraft:stone_bricks"},
        {pos: [4, 0, 2], state: "minecraft:stone_bricks"},
        {pos: [4, 0, 3], state: "minecraft:stone_bricks"},
        {pos: [4, 0, 4], state: "minecraft:stone_bricks"},
        {pos: [4, 0, 5], state: "minecraft:stone_bricks"},
        {pos: [4, 0, 6], state: "minecraft:stone_bricks"},
        {pos: [5, 0, 0], state: "minecraft:stone_bricks"},
        {pos: [5, 0, 1], state: "minecraft:stone_bricks"},
        {pos: [5, 0, 2], state: "minecraft:stone_bricks"},
        {pos: [5, 0, 3], state: "minecraft:stone_bricks"},
        {pos: [5, 0, 4], state: "minecraft:stone_bricks"},
        {pos: [5, 0, 5], state: "minecraft:stone_bricks"},
        {pos: [5, 0, 6], state: "minecraft:stone_bricks"},
        {pos: [6, 0, 0], state: "minecraft:stone_bricks"},
        {pos: [6, 0, 1], state: "minecraft:stone_bricks"},
        {pos: [6, 0, 2], state: "minecraft:stone_bricks"},
        {pos: [6, 0, 3], state: "minecraft:stone_bricks"},
        {pos: [6, 0, 4], state: "minecraft:stone_bricks"},
        {pos: [6, 0, 5], state: "minecraft:stone_bricks"},
        {pos: [7, 0, 0], state: "minecraft:stone_bricks"},
        {pos: [7, 0, 1], state: "minecraft:stone_bricks"},
        {pos: [7, 0, 2], state: "minecraft:polished_andesite"},
        {pos: [7, 0, 3], state: "minecraft:stone_bricks"},
        {pos: [7, 0, 4], state: "minecraft:stone_bricks"},
        {pos: [7, 0, 5], state: "minecraft:stone_bricks"},
        {pos: [8, 0, 1], state: "minecraft:stone_bricks"},
        {pos: [8, 0, 2], state: "minecraft:stone_bricks"},
        {pos: [8, 0, 3], state: "minecraft:stone_bricks"},
        {pos: [8, 0, 4], state: "minecraft:polished_andesite"},
        {pos: [8, 0, 5], state: "minecraft:stone_bricks"},
        {pos: [9, 0, 2], state: "minecraft:stone_bricks"},
        {pos: [9, 0, 3], state: "minecraft:stone_bricks"},
        {pos: [9, 0, 4], state: "minecraft:stone_bricks"},
        {pos: [0, 1, 3], state: "minecraft:gravel"},
        {pos: [0, 1, 4], state: "minecraft:gravel"},
        {pos: [1, 1, 2], state: "minecraft:gravel"},
        {pos: [1, 1, 3], state: "minecraft:gravel"},
        {pos: [1, 1, 4], state: "minecraft:gravel"},
        {pos: [1, 1, 5], state: "minecraft:gravel"},
        {pos: [2, 1, 0], state: "minecraft:gravel"},
        {pos: [2, 1, 1], state: "minecraft:gravel"},
        {pos: [2, 1, 2], state: "minecraft:polished_andesite"},
        {pos: [2, 1, 3], state: "minecraft:stone_bricks"},
        {pos: [2, 1, 4], state: "minecraft:stone_bricks"},
        {pos: [2, 1, 5], state: "minecraft:cobblestone_stairs{facing:north,half:top,shape:straight,waterlogged:false}"},
        {pos: [2, 1, 6], state: "minecraft:gravel"},
        {pos: [3, 1, 0], state: "minecraft:gravel"},
        {pos: [3, 1, 1], state: "minecraft:gravel"},
        {pos: [3, 1, 2], state: "minecraft:stone_bricks"},
        {pos: [3, 1, 3], state: "minecraft:stone_bricks"},
        {pos: [3, 1, 4], state: "minecraft:stone_bricks"},
        {pos: [3, 1, 5], state: "minecraft:cobblestone_stairs{facing:north,half:top,shape:straight,waterlogged:false}"},
        {pos: [3, 1, 6], state: "minecraft:gravel"},
        {pos: [4, 1, 1], state: "minecraft:gravel"},
        {pos: [4, 1, 2], state: "minecraft:stone_bricks"},
        {pos: [4, 1, 3], state: "minecraft:polished_andesite"},
        {pos: [4, 1, 4], state: "minecraft:stone_bricks"},
        {pos: [4, 1, 5], state: "minecraft:gravel"},
        {pos: [4, 1, 6], state: "minecraft:gravel"},
        {pos: [5, 1, 0], state: "minecraft:gravel"},
        {pos: [5, 1, 1], state: "minecraft:gravel"},
        {pos: [5, 1, 2], state: "minecraft:stone_bricks"},
        {pos: [5, 1, 3], state: "minecraft:stone_bricks"},
        {pos: [5, 1, 4], state: "minecraft:stone_bricks"},
        {pos: [5, 1, 5], state: "minecraft:gravel"},
        {pos: [5, 1, 6], state: "minecraft:gravel"},
        {pos: [6, 1, 0], state: "minecraft:gravel"},
        {pos: [6, 1, 1], state: "minecraft:gravel"},
        {pos: [6, 1, 2], state: "minecraft:stone_bricks"},
        {pos: [6, 1, 3], state: "minecraft:stone_bricks"},
        {pos: [6, 1, 4], state: "minecraft:stone_bricks"},
        {pos: [6, 1, 5], state: "minecraft:gravel"},
        {pos: [7, 1, 0], state: "minecraft:gravel"},
        {pos: [7, 1, 1], state: "minecraft:gravel"},
        {pos: [7, 1, 2], state: "minecraft:stone_bricks"},
        {pos: [7, 1, 3], state: "minecraft:stone_bricks"},
        {pos: [7, 1, 4], state: "minecraft:stone_bricks"},
        {pos: [7, 1, 5], state: "minecraft:gravel"},
        {pos: [8, 1, 1], state: "minecraft:gravel"},
        {pos: [8, 1, 2], state: "minecraft:gravel"},
        {pos: [8, 1, 3], state: "minecraft:gravel"},
        {pos: [8, 1, 4], state: "minecraft:gravel"},
        {pos: [8, 1, 5], state: "minecraft:gravel"},
        {pos: [9, 1, 2], state: "minecraft:gravel"},
        {pos: [9, 1, 3], state: "minecraft:gravel"},
        {pos: [9, 1, 4], state: "minecraft:gravel"},
        {pos: [0, 2, 3], state: "minecraft:gravel"},
        {pos: [0, 2, 4], state: "minecraft:gravel"},
        {pos: [1, 2, 3], state: "minecraft:gravel"},
        {pos: [1, 2, 4], state: "minecraft:gravel"},
        {pos: [1, 2, 5], state: "minecraft:gravel"},
        {pos: [2, 2, 1], state: "minecraft:gravel"},
        {pos: [2, 2, 2], state: "minecraft:gravel"},
        {pos: [2, 2, 3], state: "minecraft:gravel"},
        {pos: [2, 2, 4], state: "minecraft:gravel"},
        {pos: [2, 2, 5], state: "minecraft:gravel"},
        {pos: [2, 2, 6], state: "minecraft:gravel"},
        {pos: [3, 2, 0], state: "minecraft:gravel"},
        {pos: [3, 2, 1], state: "minecraft:gravel"},
        {pos: [3, 2, 2], state: "minecraft:gravel"},
        {pos: [3, 2, 3], state: "minecraft:obsidian"},
        {pos: [3, 2, 4], state: "minecraft:gravel"},
        {pos: [3, 2, 5], state: "minecraft:gravel"},
        {pos: [3, 2, 6], state: "minecraft:gravel"},
        {pos: [4, 2, 1], state: "minecraft:gravel"},
        {pos: [4, 2, 2], state: "minecraft:gravel"},
        {pos: [4, 2, 3], state: "minecraft:obsidian"},
        {pos: [4, 2, 4], state: "minecraft:gravel"},
        {pos: [4, 2, 5], state: "minecraft:gravel"},
        {pos: [4, 2, 6], state: "minecraft:gravel"},
        {pos: [5, 2, 1], state: "minecraft:gravel"},
        {pos: [5, 2, 2], state: "minecraft:gravel"},
        {pos: [5, 2, 3], state: "minecraft:obsidian"},
        {pos: [5, 2, 4], state: "minecraft:gravel"},
        {pos: [5, 2, 5], state: "minecraft:gravel"},
        {pos: [5, 2, 6], state: "minecraft:gravel"},
        {pos: [6, 2, 0], state: "minecraft:gravel"},
        {pos: [6, 2, 1], state: "minecraft:gravel"},
        {pos: [6, 2, 2], state: "minecraft:gravel"},
        {pos: [6, 2, 3], state: "minecraft:obsidian"},
        {pos: [6, 2, 4], state: "minecraft:gravel"},
        {pos: [6, 2, 5], state: "minecraft:gravel"},
        {pos: [7, 2, 0], state: "minecraft:gravel"},
        {pos: [7, 2, 1], state: "minecraft:gravel"},
        {pos: [7, 2, 2], state: "minecraft:gravel"},
        {pos: [7, 2, 3], state: "minecraft:gravel"},
        {pos: [7, 2, 4], state: "minecraft:gravel"},
        {pos: [7, 2, 5], state: "minecraft:gravel"},
        {pos: [8, 2, 1], state: "minecraft:gravel"},
        {pos: [8, 2, 2], state: "minecraft:gravel"},
        {pos: [8, 2, 3], state: "minecraft:gravel"},
        {pos: [8, 2, 4], state: "minecraft:gravel"},
        {pos: [8, 2, 5], state: "minecraft:gravel"},
        {pos: [9, 2, 3], state: "minecraft:gravel"},
        {pos: [9, 2, 4], state: "minecraft:gravel"},
        {pos: [1, 3, 4], state: "minecraft:gravel"},
        {pos: [2, 3, 3], state: "minecraft:gravel"},
        {pos: [2, 3, 4], state: "minecraft:gravel"},
        {pos: [2, 3, 5], state: "minecraft:gravel"},
        {pos: [3, 3, 2], state: "minecraft:gravel"},
        {pos: [3, 3, 3], state: "minecraft:obsidian"},
        {pos: [3, 3, 4], state: "minecraft:gravel"},
        {pos: [3, 3, 5], state: "minecraft:gravel"},
        {pos: [3, 3, 6], state: "minecraft:gravel"},
        {pos: [4, 3, 1], state: "minecraft:gravel"},
        {pos: [4, 3, 2], state: "minecraft:gravel"},
        {pos: [4, 3, 3], state: "minecraft:gravel"},
        {pos: [4, 3, 4], state: "minecraft:gravel"},
        {pos: [4, 3, 5], state: "minecraft:gravel"},
        {pos: [4, 3, 6], state: "minecraft:gravel"},
        {pos: [5, 3, 1], state: "minecraft:gravel"},
        {pos: [5, 3, 2], state: "minecraft:gravel"},
        {pos: [5, 3, 3], state: "minecraft:gravel"},
        {pos: [5, 3, 4], state: "minecraft:gravel"},
        {pos: [5, 3, 5], state: "minecraft:gravel"},
        {pos: [6, 3, 0], state: "minecraft:gravel"},
        {pos: [6, 3, 1], state: "minecraft:gravel"},
        {pos: [6, 3, 2], state: "minecraft:gravel"},
        {pos: [6, 3, 3], state: "minecraft:obsidian"},
        {pos: [6, 3, 4], state: "minecraft:gravel"},
        {pos: [6, 3, 5], state: "minecraft:gravel"},
        {pos: [7, 3, 1], state: "minecraft:gravel"},
        {pos: [7, 3, 2], state: "minecraft:gravel"},
        {pos: [7, 3, 3], state: "minecraft:gravel"},
        {pos: [7, 3, 4], state: "minecraft:gravel"},
        {pos: [8, 3, 2], state: "minecraft:gravel"},
        {pos: [8, 3, 3], state: "minecraft:gravel"},
        {pos: [8, 3, 4], state: "minecraft:gravel"},
        {pos: [2, 4, 3], state: "minecraft:gravel"},
        {pos: [3, 4, 2], state: "minecraft:gravel"},
        {pos: [3, 4, 3], state: "minecraft:obsidian"},
        {pos: [3, 4, 4], state: "minecraft:gravel"},
        {pos: [4, 4, 2], state: "minecraft:gravel"},
        {pos: [4, 4, 3], state: "minecraft:gravel"},
        {pos: [4, 4, 4], state: "minecraft:gravel"},
        {pos: [5, 4, 2], state: "minecraft:gravel"},
        {pos: [5, 4, 3], state: "minecraft:gravel"},
        {pos: [5, 4, 4], state: "minecraft:gravel"},
        {pos: [6, 4, 2], state: "minecraft:gravel"},
        {pos: [6, 4, 3], state: "minecraft:gravel"},
        {pos: [6, 4, 4], state: "minecraft:gravel"},
        {pos: [2, 5, 3], state: "minecraft:gravel"},
        {pos: [3, 5, 2], state: "minecraft:gravel"},
        {pos: [3, 5, 3], state: "minecraft:crying_obsidian"},
        {pos: [3, 5, 4], state: "minecraft:gravel"},
        {pos: [4, 5, 2], state: "minecraft:gravel"},
        {pos: [4, 5, 3], state: "minecraft:gravel"},
        {pos: [4, 5, 4], state: "minecraft:gravel"},
        {pos: [3, 6, 3], state: "minecraft:gravel"}
    ],
    entities: [],
    palette: [
        "minecraft:stone_bricks",
        "minecraft:polished_andesite",
        "minecraft:gravel",
        "minecraft:obsidian",
        "minecraft:crying_obsidian",
        "minecraft:cobblestone_stairs{facing:north,half:top,shape:straight,waterlogged:false}"
    ],
    trailiertales_DataVersion: 2
}
