{
    DataVersion: 3953,
    size: [16, 7, 8],
    data: [
        {pos: [0, 0, 4], state: "minecraft:stone_bricks"},
        {pos: [1, 0, 3], state: "minecraft:stone_bricks"},
        {pos: [1, 0, 4], state: "minecraft:stone_bricks"},
        {pos: [1, 0, 5], state: "minecraft:stone_bricks"},
        {pos: [2, 0, 3], state: "minecraft:stone_bricks"},
        {pos: [2, 0, 4], state: "minecraft:stone_bricks"},
        {pos: [2, 0, 5], state: "minecraft:stone_bricks"},
        {pos: [2, 0, 6], state: "minecraft:stone_bricks"},
        {pos: [3, 0, 1], state: "minecraft:stone_bricks"},
        {pos: [3, 0, 2], state: "minecraft:stone_bricks"},
        {pos: [3, 0, 3], state: "minecraft:stone_bricks"},
        {pos: [3, 0, 4], state: "minecraft:stone_bricks"},
        {pos: [3, 0, 5], state: "minecraft:stone_bricks"},
        {pos: [3, 0, 6], state: "minecraft:stone_bricks"},
        {pos: [3, 0, 7], state: "minecraft:polished_andesite"},
        {pos: [4, 0, 2], state: "minecraft:stone_bricks"},
        {pos: [4, 0, 3], state: "minecraft:polished_andesite"},
        {pos: [4, 0, 4], state: "minecraft:stone_bricks"},
        {pos: [4, 0, 5], state: "minecraft:stone_bricks"},
        {pos: [4, 0, 6], state: "minecraft:stone_bricks"},
        {pos: [4, 0, 7], state: "minecraft:stone_bricks"},
        {pos: [5, 0, 3], state: "minecraft:stone_bricks"},
        {pos: [5, 0, 4], state: "minecraft:polished_andesite"},
        {pos: [5, 0, 5], state: "minecraft:stone_bricks"},
        {pos: [5, 0, 6], state: "minecraft:stone_bricks"},
        {pos: [6, 0, 4], state: "minecraft:polished_andesite"},
        {pos: [6, 0, 5], state: "minecraft:stone_bricks"},
        {pos: [6, 0, 6], state: "minecraft:stone_bricks"},
        {pos: [7, 0, 3], state: "minecraft:stone_bricks"},
        {pos: [7, 0, 4], state: "minecraft:stone_bricks"},
        {pos: [7, 0, 5], state: "minecraft:stone_bricks"},
        {pos: [8, 0, 2], state: "minecraft:polished_andesite"},
        {pos: [8, 0, 3], state: "minecraft:stone_bricks"},
        {pos: [8, 0, 4], state: "minecraft:stone_bricks"},
        {pos: [8, 0, 5], state: "minecraft:stone_bricks"},
        {pos: [8, 0, 6], state: "minecraft:stone_bricks"},
        {pos: [9, 0, 2], state: "minecraft:stone_bricks"},
        {pos: [9, 0, 3], state: "minecraft:stone_bricks"},
        {pos: [9, 0, 4], state: "minecraft:stone_bricks"},
        {pos: [9, 0, 5], state: "minecraft:stone_bricks"},
        {pos: [9, 0, 6], state: "minecraft:stone_bricks"},
        {pos: [9, 0, 7], state: "minecraft:stone_bricks"},
        {pos: [10, 0, 3], state: "minecraft:stone_bricks"},
        {pos: [10, 0, 4], state: "minecraft:stone_bricks"},
        {pos: [10, 0, 5], state: "minecraft:stone_bricks"},
        {pos: [10, 0, 6], state: "minecraft:polished_andesite"},
        {pos: [10, 0, 7], state: "minecraft:stone_bricks"},
        {pos: [11, 0, 0], state: "minecraft:stone_bricks"},
        {pos: [11, 0, 1], state: "minecraft:stone_bricks"},
        {pos: [11, 0, 2], state: "minecraft:stone_bricks"},
        {pos: [11, 0, 3], state: "minecraft:stone_bricks"},
        {pos: [11, 0, 4], state: "minecraft:polished_andesite"},
        {pos: [11, 0, 5], state: "minecraft:polished_andesite"},
        {pos: [11, 0, 6], state: "minecraft:stone_bricks"},
        {pos: [11, 0, 7], state: "minecraft:stone_bricks"},
        {pos: [12, 0, 0], state: "minecraft:stone_bricks"},
        {pos: [12, 0, 1], state: "minecraft:stone_bricks"},
        {pos: [12, 0, 2], state: "minecraft:stone_bricks"},
        {pos: [12, 0, 3], state: "minecraft:stone_bricks"},
        {pos: [12, 0, 4], state: "minecraft:chiseled_stone_bricks"},
        {pos: [12, 0, 5], state: "minecraft:stone_bricks"},
        {pos: [12, 0, 6], state: "minecraft:stone_bricks"},
        {pos: [13, 0, 2], state: "minecraft:stone_bricks"},
        {pos: [13, 0, 3], state: "minecraft:stone_bricks"},
        {pos: [13, 0, 4], state: "minecraft:stone_bricks"},
        {pos: [13, 0, 5], state: "minecraft:stone_bricks"},
        {pos: [13, 0, 6], state: "minecraft:stone_bricks"},
        {pos: [14, 0, 3], state: "minecraft:stone_bricks"},
        {pos: [14, 0, 4], state: "minecraft:stone_bricks"},
        {pos: [14, 0, 5], state: "minecraft:stone_bricks"},
        {pos: [15, 0, 4], state: "minecraft:stone_bricks"},
        {pos: [15, 0, 5], state: "minecraft:polished_andesite"},
        {pos: [0, 1, 4], state: "minecraft:gravel"},
        {pos: [1, 1, 3], state: "minecraft:gravel"},
        {pos: [1, 1, 4], state: "minecraft:gravel"},
        {pos: [1, 1, 5], state: "minecraft:gravel"},
        {pos: [2, 1, 3], state: "minecraft:gravel"},
        {pos: [2, 1, 4], state: "minecraft:gravel"},
        {pos: [2, 1, 5], state: "minecraft:gravel"},
        {pos: [2, 1, 6], state: "minecraft:gravel"},
        {pos: [3, 1, 1], state: "minecraft:gravel"},
        {pos: [3, 1, 2], state: "minecraft:gravel"},
        {pos: [3, 1, 3], state: "minecraft:gravel"},
        {pos: [3, 1, 4], state: "minecraft:stone_bricks"},
        {pos: [3, 1, 5], state: "minecraft:stone_bricks"},
        {pos: [3, 1, 6], state: "minecraft:gravel"},
        {pos: [3, 1, 7], state: "minecraft:gravel"},
        {pos: [4, 1, 2], state: "minecraft:gravel"},
        {pos: [4, 1, 3], state: "minecraft:gravel"},
        {pos: [4, 1, 4], state: "minecraft:stone_bricks"},
        {pos: [4, 1, 5], state: "minecraft:stone_bricks"},
        {pos: [4, 1, 6], state: "minecraft:gravel"},
        {pos: [4, 1, 7], state: "minecraft:gravel"},
        {pos: [5, 1, 3], state: "minecraft:gravel"},
        {pos: [5, 1, 4], state: "minecraft:gravel"},
        {pos: [5, 1, 5], state: "minecraft:stone_bricks"},
        {pos: [5, 1, 6], state: "minecraft:gravel"},
        {pos: [6, 1, 4], state: "minecraft:gravel"},
        {pos: [6, 1, 5], state: "minecraft:gravel"},
        {pos: [6, 1, 6], state: "minecraft:gravel"},
        {pos: [7, 1, 3], state: "minecraft:gravel"},
        {pos: [7, 1, 4], state: "minecraft:gravel"},
        {pos: [7, 1, 5], state: "minecraft:stone_bricks"},
        {pos: [8, 1, 2], state: "minecraft:gravel"},
        {pos: [8, 1, 3], state: "minecraft:gravel"},
        {pos: [8, 1, 4], state: "minecraft:stone_bricks"},
        {pos: [8, 1, 5], state: "minecraft:stone_bricks"},
        {pos: [8, 1, 6], state: "minecraft:gravel"},
        {pos: [9, 1, 2], state: "minecraft:gravel"},
        {pos: [9, 1, 3], state: "minecraft:gravel"},
        {pos: [9, 1, 4], state: "minecraft:stone_bricks"},
        {pos: [9, 1, 5], state: "minecraft:stone_bricks"},
        {pos: [9, 1, 6], state: "minecraft:gravel"},
        {pos: [9, 1, 7], state: "minecraft:gravel"},
        {pos: [10, 1, 3], state: "minecraft:gravel"},
        {pos: [10, 1, 4], state: "minecraft:gravel"},
        {pos: [10, 1, 5], state: "minecraft:stone_bricks"},
        {pos: [10, 1, 6], state: "minecraft:gravel"},
        {pos: [10, 1, 7], state: "minecraft:gravel"},
        {pos: [11, 1, 0], state: "minecraft:gravel"},
        {pos: [11, 1, 1], state: "minecraft:gravel"},
        {pos: [11, 1, 2], state: "minecraft:gravel"},
        {pos: [11, 1, 3], state: "minecraft:gravel"},
        {pos: [11, 1, 4], state: "minecraft:gravel"},
        {pos: [11, 1, 5], state: "minecraft:stone_bricks"},
        {pos: [11, 1, 6], state: "minecraft:gravel"},
        {pos: [11, 1, 7], state: "minecraft:gravel"},
        {pos: [12, 1, 0], state: "minecraft:gravel"},
        {pos: [12, 1, 1], state: "minecraft:gravel"},
        {pos: [12, 1, 2], state: "minecraft:gravel"},
        {pos: [12, 1, 3], state: "minecraft:gravel"},
        {pos: [12, 1, 4], state: "minecraft:stone_bricks"},
        {pos: [12, 1, 5], state: "minecraft:stone_bricks"},
        {pos: [12, 1, 6], state: "minecraft:gravel"},
        {pos: [13, 1, 2], state: "minecraft:gravel"},
        {pos: [13, 1, 3], state: "minecraft:gravel"},
        {pos: [13, 1, 4], state: "minecraft:stone_bricks"},
        {pos: [13, 1, 5], state: "minecraft:stone_bricks"},
        {pos: [13, 1, 6], state: "minecraft:gravel"},
        {pos: [14, 1, 3], state: "minecraft:gravel"},
        {pos: [14, 1, 4], state: "minecraft:gravel"},
        {pos: [14, 1, 5], state: "minecraft:stone_bricks"},
        {pos: [15, 1, 4], state: "minecraft:gravel"},
        {pos: [15, 1, 5], state: "minecraft:stone_bricks"},
        {pos: [0, 2, 4], state: "minecraft:gravel"},
        {pos: [1, 2, 3], state: "minecraft:gravel"},
        {pos: [1, 2, 4], state: "minecraft:gravel"},
        {pos: [1, 2, 5], state: "minecraft:gravel"},
        {pos: [2, 2, 3], state: "minecraft:gravel"},
        {pos: [2, 2, 4], state: "minecraft:gravel"},
        {pos: [2, 2, 5], state: "minecraft:gravel"},
        {pos: [2, 2, 6], state: "minecraft:gravel"},
        {pos: [3, 2, 1], state: "minecraft:gravel"},
        {pos: [3, 2, 2], state: "minecraft:gravel"},
        {pos: [3, 2, 3], state: "minecraft:gravel"},
        {pos: [3, 2, 4], state: "minecraft:stone_bricks"},
        {pos: [3, 2, 5], state: "minecraft:stone_bricks"},
        {pos: [3, 2, 6], state: "minecraft:gravel"},
        {pos: [3, 2, 7], state: "minecraft:gravel"},
        {pos: [4, 2, 2], state: "minecraft:gravel"},
        {pos: [4, 2, 3], state: "minecraft:gravel"},
        {pos: [4, 2, 4], state: "minecraft:stone_bricks"},
        {pos: [4, 2, 5], state: "minecraft:stone_bricks"},
        {pos: [4, 2, 6], state: "minecraft:gravel"},
        {pos: [4, 2, 7], state: "minecraft:gravel"},
        {pos: [5, 2, 3], state: "minecraft:gravel"},
        {pos: [5, 2, 4], state: "minecraft:gravel"},
        {pos: [5, 2, 5], state: "minecraft:cobblestone_stairs{facing:west,half:bottom,shape:straight,waterlogged:false}"},
        {pos: [5, 2, 6], state: "minecraft:gravel"},
        {pos: [6, 2, 4], state: "minecraft:gravel"},
        {pos: [6, 2, 5], state: "minecraft:gravel"},
        {pos: [6, 2, 6], state: "minecraft:gravel"},
        {pos: [7, 2, 3], state: "minecraft:gravel"},
        {pos: [7, 2, 4], state: "minecraft:gravel"},
        {pos: [7, 2, 5], state: "minecraft:gravel"},
        {pos: [8, 2, 2], state: "minecraft:gravel"},
        {pos: [8, 2, 3], state: "minecraft:gravel"},
        {pos: [8, 2, 4], state: "minecraft:stone_bricks"},
        {pos: [8, 2, 5], state: "minecraft:stone_bricks"},
        {pos: [8, 2, 6], state: "minecraft:gravel"},
        {pos: [9, 2, 2], state: "minecraft:gravel"},
        {pos: [9, 2, 3], state: "minecraft:gravel"},
        {pos: [9, 2, 4], state: "minecraft:polished_andesite"},
        {pos: [9, 2, 5], state: "minecraft:stone_bricks"},
        {pos: [9, 2, 6], state: "minecraft:gravel"},
        {pos: [9, 2, 7], state: "minecraft:gravel"},
        {pos: [10, 2, 3], state: "minecraft:gravel"},
        {pos: [10, 2, 4], state: "minecraft:gravel"},
        {pos: [10, 2, 5], state: "minecraft:stone_bricks"},
        {pos: [10, 2, 6], state: "minecraft:gravel"},
        {pos: [10, 2, 7], state: "minecraft:gravel"},
        {pos: [11, 2, 0], state: "minecraft:gravel"},
        {pos: [11, 2, 1], state: "minecraft:gravel"},
        {pos: [11, 2, 2], state: "minecraft:gravel"},
        {pos: [11, 2, 3], state: "minecraft:gravel"},
        {pos: [11, 2, 4], state: "minecraft:gravel"},
        {pos: [11, 2, 5], state: "minecraft:gravel"},
        {pos: [11, 2, 6], state: "minecraft:gravel"},
        {pos: [11, 2, 7], state: "minecraft:gravel"},
        {pos: [12, 2, 0], state: "minecraft:gravel"},
        {pos: [12, 2, 1], state: "minecraft:gravel"},
        {pos: [12, 2, 2], state: "minecraft:gravel"},
        {pos: [12, 2, 3], state: "minecraft:gravel"},
        {pos: [12, 2, 4], state: "minecraft:stone_bricks"},
        {pos: [12, 2, 5], state: "minecraft:stone_bricks"},
        {pos: [12, 2, 6], state: "minecraft:gravel"},
        {pos: [13, 2, 2], state: "minecraft:gravel"},
        {pos: [13, 2, 3], state: "minecraft:gravel"},
        {pos: [13, 2, 4], state: "minecraft:stone_bricks"},
        {pos: [13, 2, 5], state: "minecraft:stone_bricks"},
        {pos: [13, 2, 6], state: "minecraft:gravel"},
        {pos: [14, 2, 3], state: "minecraft:gravel"},
        {pos: [14, 2, 4], state: "minecraft:gravel"},
        {pos: [14, 2, 5], state: "minecraft:cobblestone_stairs{facing:west,half:bottom,shape:straight,waterlogged:false}"},
        {pos: [15, 2, 4], state: "minecraft:gravel"},
        {pos: [15, 2, 5], state: "minecraft:cobblestone_stairs{facing:east,half:bottom,shape:straight,waterlogged:false}"},
        {pos: [0, 3, 4], state: "minecraft:gravel"},
        {pos: [1, 3, 3], state: "minecraft:gravel"},
        {pos: [1, 3, 4], state: "minecraft:gravel"},
        {pos: [1, 3, 5], state: "minecraft:gravel"},
        {pos: [2, 3, 3], state: "minecraft:gravel"},
        {pos: [2, 3, 4], state: "minecraft:gravel"},
        {pos: [2, 3, 5], state: "minecraft:gravel"},
        {pos: [2, 3, 6], state: "minecraft:gravel"},
        {pos: [3, 3, 1], state: "minecraft:gravel"},
        {pos: [3, 3, 2], state: "minecraft:gravel"},
        {pos: [3, 3, 3], state: "minecraft:gravel"},
        {pos: [3, 3, 4], state: "minecraft:stone_bricks"},
        {pos: [3, 3, 5], state: "minecraft:stone_bricks"},
        {pos: [3, 3, 6], state: "minecraft:gravel"},
        {pos: [3, 3, 7], state: "minecraft:gravel"},
        {pos: [4, 3, 2], state: "minecraft:gravel"},
        {pos: [4, 3, 3], state: "minecraft:gravel"},
        {pos: [4, 3, 4], state: "minecraft:stone_bricks"},
        {pos: [4, 3, 5], state: "minecraft:stone_bricks"},
        {pos: [4, 3, 6], state: "minecraft:gravel"},
        {pos: [4, 3, 7], state: "minecraft:gravel"},
        {pos: [5, 3, 3], state: "minecraft:gravel"},
        {pos: [5, 3, 4], state: "minecraft:gravel"},
        {pos: [5, 3, 5], state: "minecraft:gravel"},
        {pos: [5, 3, 6], state: "minecraft:gravel"},
        {pos: [6, 3, 4], state: "minecraft:gravel"},
        {pos: [6, 3, 5], state: "minecraft:gravel"},
        {pos: [6, 3, 6], state: "minecraft:gravel"},
        {pos: [7, 3, 3], state: "minecraft:gravel"},
        {pos: [7, 3, 4], state: "minecraft:gravel"},
        {pos: [7, 3, 5], state: "minecraft:gravel"},
        {pos: [8, 3, 2], state: "minecraft:gravel"},
        {pos: [8, 3, 3], state: "minecraft:gravel"},
        {pos: [8, 3, 4], state: "minecraft:stone_bricks"},
        {pos: [8, 3, 5], state: "minecraft:stone_bricks"},
        {pos: [8, 3, 6], state: "minecraft:gravel"},
        {pos: [9, 3, 2], state: "minecraft:gravel"},
        {pos: [9, 3, 3], state: "minecraft:gravel"},
        {pos: [9, 3, 4], state: "minecraft:polished_andesite"},
        {pos: [9, 3, 5], state: "minecraft:stone_bricks"},
        {pos: [9, 3, 6], state: "minecraft:gravel"},
        {pos: [9, 3, 7], state: "minecraft:gravel"},
        {pos: [10, 3, 3], state: "minecraft:gravel"},
        {pos: [10, 3, 4], state: "minecraft:gravel"},
        {pos: [10, 3, 5], state: "minecraft:gravel"},
        {pos: [10, 3, 6], state: "minecraft:gravel"},
        {pos: [10, 3, 7], state: "minecraft:gravel"},
        {pos: [11, 3, 0], state: "minecraft:gravel"},
        {pos: [11, 3, 1], state: "minecraft:gravel"},
        {pos: [11, 3, 2], state: "minecraft:gravel"},
        {pos: [11, 3, 3], state: "minecraft:gravel"},
        {pos: [11, 3, 4], state: "minecraft:gravel"},
        {pos: [11, 3, 5], state: "minecraft:gravel"},
        {pos: [11, 3, 6], state: "minecraft:gravel"},
        {pos: [11, 3, 7], state: "minecraft:gravel"},
        {pos: [12, 3, 0], state: "minecraft:gravel"},
        {pos: [12, 3, 1], state: "minecraft:gravel"},
        {pos: [12, 3, 2], state: "minecraft:gravel"},
        {pos: [12, 3, 3], state: "minecraft:gravel"},
        {pos: [12, 3, 4], state: "minecraft:stone_bricks"},
        {pos: [12, 3, 5], state: "minecraft:stone_bricks"},
        {pos: [12, 3, 6], state: "minecraft:gravel"},
        {pos: [13, 3, 2], state: "minecraft:gravel"},
        {pos: [13, 3, 3], state: "minecraft:gravel"},
        {pos: [13, 3, 4], state: "minecraft:stone_bricks"},
        {pos: [13, 3, 5], state: "minecraft:stone_bricks"},
        {pos: [13, 3, 6], state: "minecraft:gravel"},
        {pos: [14, 3, 3], state: "minecraft:gravel"},
        {pos: [14, 3, 4], state: "minecraft:gravel"},
        {pos: [14, 3, 5], state: "minecraft:gravel"},
        {pos: [15, 3, 4], state: "minecraft:gravel"},
        {pos: [15, 3, 5], state: "minecraft:gravel"},
        {pos: [1, 4, 4], state: "minecraft:gravel"},
        {pos: [2, 4, 3], state: "minecraft:gravel"},
        {pos: [2, 4, 4], state: "minecraft:gravel"},
        {pos: [2, 4, 5], state: "minecraft:gravel"},
        {pos: [2, 4, 6], state: "minecraft:gravel"},
        {pos: [3, 4, 2], state: "minecraft:gravel"},
        {pos: [3, 4, 3], state: "minecraft:gravel"},
        {pos: [3, 4, 4], state: "minecraft:stone_bricks"},
        {pos: [3, 4, 5], state: "minecraft:stone_bricks"},
        {pos: [3, 4, 6], state: "minecraft:gravel"},
        {pos: [3, 4, 7], state: "minecraft:gravel"},
        {pos: [4, 4, 3], state: "minecraft:gravel"},
        {pos: [4, 4, 4], state: "minecraft:stone_bricks"},
        {pos: [4, 4, 5], state: "minecraft:stone_bricks"},
        {pos: [4, 4, 6], state: "minecraft:gravel"},
        {pos: [5, 4, 4], state: "minecraft:gravel"},
        {pos: [5, 4, 5], state: "minecraft:gravel"},
        {pos: [7, 4, 5], state: "minecraft:gravel"},
        {pos: [8, 4, 3], state: "minecraft:gravel"},
        {pos: [8, 4, 4], state: "minecraft:gravel"},
        {pos: [8, 4, 5], state: "minecraft:stone_bricks"},
        {pos: [8, 4, 6], state: "minecraft:gravel"},
        {pos: [9, 4, 3], state: "minecraft:gravel"},
        {pos: [9, 4, 4], state: "minecraft:gravel"},
        {pos: [9, 4, 5], state: "minecraft:stone_bricks"},
        {pos: [9, 4, 6], state: "minecraft:gravel"},
        {pos: [10, 4, 4], state: "minecraft:gravel"},
        {pos: [10, 4, 5], state: "minecraft:gravel"},
        {pos: [11, 4, 4], state: "minecraft:gravel"},
        {pos: [11, 4, 5], state: "minecraft:gravel"},
        {pos: [11, 4, 6], state: "minecraft:gravel"},
        {pos: [12, 4, 3], state: "minecraft:gravel"},
        {pos: [12, 4, 4], state: "minecraft:stone_bricks"},
        {pos: [12, 4, 5], state: "minecraft:polished_andesite"},
        {pos: [12, 4, 6], state: "minecraft:gravel"},
        {pos: [13, 4, 3], state: "minecraft:gravel"},
        {pos: [13, 4, 4], state: "minecraft:gravel"},
        {pos: [13, 4, 5], state: "minecraft:stone_bricks"},
        {pos: [13, 4, 6], state: "minecraft:gravel"},
        {pos: [14, 4, 4], state: "minecraft:gravel"},
        {pos: [14, 4, 5], state: "minecraft:gravel"},
        {pos: [2, 5, 4], state: "minecraft:gravel"},
        {pos: [2, 5, 5], state: "minecraft:gravel"},
        {pos: [3, 5, 3], state: "minecraft:gravel"},
        {pos: [3, 5, 4], state: "minecraft:stone_bricks"},
        {pos: [3, 5, 5], state: "minecraft:polished_andesite"},
        {pos: [3, 5, 6], state: "minecraft:gravel"},
        {pos: [4, 5, 4], state: "minecraft:stone_bricks"},
        {pos: [4, 5, 5], state: "minecraft:stone_bricks"},
        {pos: [4, 5, 6], state: "minecraft:gravel"},
        {pos: [8, 5, 4], state: "minecraft:gravel"},
        {pos: [8, 5, 5], state: "minecraft:gravel"},
        {pos: [9, 5, 5], state: "minecraft:gravel"},
        {pos: [11, 5, 5], state: "minecraft:gravel"},
        {pos: [12, 5, 4], state: "minecraft:gravel"},
        {pos: [12, 5, 5], state: "minecraft:gravel"},
        {pos: [13, 5, 4], state: "minecraft:gravel"},
        {pos: [13, 5, 5], state: "minecraft:gravel"},
        {pos: [3, 6, 4], state: "minecraft:stone_bricks"},
        {pos: [3, 6, 5], state: "minecraft:stone_bricks"},
        {pos: [4, 6, 5], state: "minecraft:stone_bricks"}
    ],
    entities: [],
    palette: [
        "minecraft:stone_bricks",
        "minecraft:polished_andesite",
        "minecraft:chiseled_stone_bricks",
        "minecraft:gravel",
        "minecraft:cobblestone_stairs{facing:west,half:bottom,shape:straight,waterlogged:false}",
        "minecraft:cobblestone_stairs{facing:east,half:bottom,shape:straight,waterlogged:false}"
    ],
    trailiertales_DataVersion: 2
}
