{
    DataVersion: 3953,
    size: [11, 10, 12],
    data: [
        {pos: [0, 0, 4], state: "minecraft:stone_bricks"},
        {pos: [0, 0, 5], state: "minecraft:stone_bricks"},
        {pos: [0, 0, 6], state: "minecraft:stone_bricks"},
        {pos: [0, 0, 7], state: "minecraft:stone_bricks"},
        {pos: [1, 0, 3], state: "minecraft:stone_bricks"},
        {pos: [1, 0, 4], state: "minecraft:stone_bricks"},
        {pos: [1, 0, 5], state: "minecraft:stone_bricks"},
        {pos: [1, 0, 6], state: "minecraft:stone_bricks"},
        {pos: [1, 0, 7], state: "minecraft:stone_bricks"},
        {pos: [1, 0, 8], state: "minecraft:stone_bricks"},
        {pos: [2, 0, 2], state: "minecraft:stone_bricks"},
        {pos: [2, 0, 3], state: "minecraft:stone_bricks"},
        {pos: [2, 0, 4], state: "minecraft:stone_bricks"},
        {pos: [2, 0, 5], state: "minecraft:stone_bricks"},
        {pos: [2, 0, 6], state: "minecraft:polished_andesite"},
        {pos: [2, 0, 7], state: "minecraft:stone_bricks"},
        {pos: [2, 0, 8], state: "minecraft:stone_bricks"},
        {pos: [3, 0, 1], state: "minecraft:stone_bricks"},
        {pos: [3, 0, 2], state: "minecraft:stone_bricks"},
        {pos: [3, 0, 3], state: "minecraft:stone_bricks"},
        {pos: [3, 0, 4], state: "minecraft:stone_bricks"},
        {pos: [3, 0, 5], state: "minecraft:chiseled_stone_bricks"},
        {pos: [3, 0, 6], state: "minecraft:stone_bricks"},
        {pos: [3, 0, 7], state: "minecraft:polished_andesite"},
        {pos: [3, 0, 8], state: "minecraft:stone_bricks"},
        {pos: [3, 0, 9], state: "minecraft:stone_bricks"},
        {pos: [3, 0, 10], state: "minecraft:stone_bricks"},
        {pos: [4, 0, 0], state: "minecraft:polished_andesite"},
        {pos: [4, 0, 1], state: "minecraft:stone_bricks"},
        {pos: [4, 0, 2], state: "minecraft:stone_bricks"},
        {pos: [4, 0, 3], state: "minecraft:stone_bricks"},
        {pos: [4, 0, 4], state: "minecraft:stone_bricks"},
        {pos: [4, 0, 5], state: "minecraft:stone_bricks"},
        {pos: [4, 0, 6], state: "minecraft:stone_bricks"},
        {pos: [4, 0, 7], state: "minecraft:stone_bricks"},
        {pos: [4, 0, 8], state: "minecraft:stone_bricks"},
        {pos: [4, 0, 9], state: "minecraft:stone_bricks"},
        {pos: [4, 0, 10], state: "minecraft:stone_bricks"},
        {pos: [5, 0, 0], state: "minecraft:stone_bricks"},
        {pos: [5, 0, 1], state: "minecraft:stone_bricks"},
        {pos: [5, 0, 2], state: "minecraft:stone_bricks"},
        {pos: [5, 0, 3], state: "minecraft:stone_bricks"},
        {pos: [5, 0, 4], state: "minecraft:polished_andesite"},
        {pos: [5, 0, 5], state: "minecraft:stone_bricks"},
        {pos: [5, 0, 6], state: "minecraft:stone_bricks"},
        {pos: [5, 0, 7], state: "minecraft:stone_bricks"},
        {pos: [5, 0, 8], state: "minecraft:stone_bricks"},
        {pos: [5, 0, 9], state: "minecraft:stone_bricks"},
        {pos: [5, 0, 10], state: "minecraft:stone_bricks"},
        {pos: [5, 0, 11], state: "minecraft:stone_bricks"},
        {pos: [6, 0, 1], state: "minecraft:stone_bricks"},
        {pos: [6, 0, 2], state: "minecraft:polished_andesite"},
        {pos: [6, 0, 3], state: "minecraft:stone_bricks"},
        {pos: [6, 0, 4], state: "minecraft:stone_bricks"},
        {pos: [6, 0, 5], state: "minecraft:stone_bricks"},
        {pos: [6, 0, 6], state: "minecraft:stone_bricks"},
        {pos: [6, 0, 7], state: "minecraft:stone_bricks"},
        {pos: [6, 0, 8], state: "minecraft:stone_bricks"},
        {pos: [6, 0, 9], state: "minecraft:stone_bricks"},
        {pos: [6, 0, 10], state: "minecraft:stone_bricks"},
        {pos: [6, 0, 11], state: "minecraft:stone_bricks"},
        {pos: [7, 0, 1], state: "minecraft:stone_bricks"},
        {pos: [7, 0, 2], state: "minecraft:stone_bricks"},
        {pos: [7, 0, 3], state: "minecraft:stone_bricks"},
        {pos: [7, 0, 4], state: "minecraft:stone_bricks"},
        {pos: [7, 0, 5], state: "minecraft:chiseled_stone_bricks"},
        {pos: [7, 0, 6], state: "minecraft:stone_bricks"},
        {pos: [7, 0, 7], state: "minecraft:stone_bricks"},
        {pos: [7, 0, 8], state: "minecraft:stone_bricks"},
        {pos: [7, 0, 9], state: "minecraft:stone_bricks"},
        {pos: [7, 0, 10], state: "minecraft:stone_bricks"},
        {pos: [8, 0, 2], state: "minecraft:stone_bricks"},
        {pos: [8, 0, 3], state: "minecraft:stone_bricks"},
        {pos: [8, 0, 4], state: "minecraft:stone_bricks"},
        {pos: [8, 0, 5], state: "minecraft:stone_bricks"},
        {pos: [8, 0, 6], state: "minecraft:stone_bricks"},
        {pos: [8, 0, 7], state: "minecraft:stone_bricks"},
        {pos: [8, 0, 8], state: "minecraft:chiseled_stone_bricks"},
        {pos: [8, 0, 9], state: "minecraft:stone_bricks"},
        {pos: [9, 0, 3], state: "minecraft:stone_bricks"},
        {pos: [9, 0, 4], state: "minecraft:stone_bricks"},
        {pos: [9, 0, 5], state: "minecraft:polished_andesite"},
        {pos: [9, 0, 6], state: "minecraft:stone_bricks"},
        {pos: [9, 0, 7], state: "minecraft:stone_bricks"},
        {pos: [9, 0, 8], state: "minecraft:stone_bricks"},
        {pos: [9, 0, 9], state: "minecraft:stone_bricks"},
        {pos: [10, 0, 3], state: "minecraft:stone_bricks"},
        {pos: [10, 0, 4], state: "minecraft:stone_bricks"},
        {pos: [10, 0, 5], state: "minecraft:stone_bricks"},
        {pos: [10, 0, 6], state: "minecraft:stone_bricks"},
        {pos: [10, 0, 7], state: "minecraft:stone_bricks"},
        {pos: [10, 0, 8], state: "minecraft:stone_bricks"},
        {pos: [0, 1, 4], state: "minecraft:gravel"},
        {pos: [0, 1, 5], state: "minecraft:gravel"},
        {pos: [0, 1, 6], state: "minecraft:gravel"},
        {pos: [0, 1, 7], state: "minecraft:gravel"},
        {pos: [1, 1, 3], state: "minecraft:gravel"},
        {pos: [1, 1, 4], state: "minecraft:stone_bricks"},
        {pos: [1, 1, 5], state: "minecraft:stone_bricks"},
        {pos: [1, 1, 6], state: "minecraft:stone_bricks"},
        {pos: [1, 1, 7], state: "minecraft:cauldron"},
        {pos: [1, 1, 8], state: "minecraft:gravel"},
        {pos: [2, 1, 2], state: "minecraft:stone_bricks"},
        {pos: [2, 1, 3], state: "minecraft:gravel"},
        {pos: [2, 1, 4], state: "minecraft:gravel"},
        {pos: [2, 1, 5], state: "minecraft:polished_andesite"},
        {pos: [2, 1, 6], state: "minecraft:stone_bricks"},
        {pos: [2, 1, 7], state: "minecraft:stone_bricks"},
        {pos: [2, 1, 8], state: "minecraft:stone_bricks"},
        {pos: [2, 1, 9], state: "minecraft:stone_bricks"},
        {pos: [3, 1, 1], state: "minecraft:gravel"},
        {pos: [3, 1, 2], state: "minecraft:polished_andesite"},
        {pos: [3, 1, 3], state: "minecraft:gravel"},
        {pos: [3, 1, 4], state: "minecraft:gravel"},
        {pos: [3, 1, 5], state: "minecraft:gravel"},
        {pos: [3, 1, 6], state: "minecraft:gravel"},
        {pos: [3, 1, 7], state: "minecraft:gravel"},
        {pos: [3, 1, 8], state: "minecraft:gravel"},
        {pos: [3, 1, 9], state: "minecraft:stone_bricks"},
        {pos: [3, 1, 10], state: "minecraft:gravel"},
        {pos: [4, 1, 0], state: "minecraft:gravel"},
        {pos: [4, 1, 1], state: "minecraft:stone_bricks"},
        {pos: [4, 1, 2], state: "minecraft:stone_bricks"},
        {pos: [4, 1, 3], state: "minecraft:gravel"},
        {pos: [4, 1, 4], state: "minecraft:gravel"},
        {pos: [4, 1, 5], state: "minecraft:stone_bricks"},
        {pos: [4, 1, 6], state: "minecraft:stone_bricks"},
        {pos: [4, 1, 7], state: "minecraft:stone_bricks"},
        {pos: [4, 1, 8], state: "minecraft:gravel"},
        {pos: [4, 1, 9], state: "minecraft:stone_bricks"},
        {pos: [4, 1, 10], state: "minecraft:stone_bricks"},
        {pos: [5, 1, 0], state: "minecraft:gravel"},
        {pos: [5, 1, 1], state: "minecraft:stone_bricks"},
        {pos: [5, 1, 2], state: "minecraft:stone_bricks"},
        {pos: [5, 1, 3], state: "minecraft:gravel"},
        {pos: [5, 1, 4], state: "minecraft:gravel"},
        {pos: [5, 1, 5], state: "minecraft:gravel"},
        {pos: [5, 1, 6], state: "minecraft:stone_bricks"},
        {pos: [5, 1, 7], state: "minecraft:stone_bricks"},
        {pos: [5, 1, 8], state: "minecraft:stone_bricks"},
        {pos: [5, 1, 9], state: "minecraft:stone_bricks"},
        {pos: [5, 1, 10], state: "minecraft:stone_bricks"},
        {pos: [5, 1, 11], state: "minecraft:gravel"},
        {pos: [6, 1, 1], state: "minecraft:gravel"},
        {pos: [6, 1, 2], state: "minecraft:stone_bricks"},
        {pos: [6, 1, 3], state: "minecraft:gravel"},
        {pos: [6, 1, 4], state: "minecraft:gravel"},
        {pos: [6, 1, 5], state: "minecraft:gravel"},
        {pos: [6, 1, 6], state: "minecraft:stone_bricks"},
        {pos: [6, 1, 7], state: "minecraft:stone_bricks"},
        {pos: [6, 1, 8], state: "minecraft:gravel"},
        {pos: [6, 1, 9], state: "minecraft:polished_andesite"},
        {pos: [6, 1, 10], state: "minecraft:stone_bricks"},
        {pos: [6, 1, 11], state: "minecraft:gravel"},
        {pos: [7, 1, 1], state: "minecraft:gravel"},
        {pos: [7, 1, 2], state: "minecraft:stone_bricks"},
        {pos: [7, 1, 3], state: "minecraft:gravel"},
        {pos: [7, 1, 4], state: "minecraft:gravel"},
        {pos: [7, 1, 5], state: "minecraft:gravel"},
        {pos: [7, 1, 6], state: "minecraft:gravel"},
        {pos: [7, 1, 7], state: "minecraft:gravel"},
        {pos: [7, 1, 8], state: "minecraft:gravel"},
        {pos: [7, 1, 9], state: "minecraft:stone_bricks"},
        {pos: [7, 1, 10], state: "minecraft:gravel"},
        {pos: [8, 1, 2], state: "minecraft:gravel"},
        {pos: [8, 1, 3], state: "minecraft:gravel"},
        {pos: [8, 1, 4], state: "minecraft:gravel"},
        {pos: [8, 1, 5], state: "minecraft:stone_bricks"},
        {pos: [8, 1, 6], state: "minecraft:stone_bricks"},
        {pos: [8, 1, 7], state: "minecraft:stone_bricks"},
        {pos: [8, 1, 8], state: "minecraft:stone_bricks"},
        {pos: [8, 1, 9], state: "minecraft:chiseled_stone_bricks"},
        {pos: [9, 1, 3], state: "minecraft:gravel"},
        {pos: [9, 1, 4], state: "minecraft:stone_bricks"},
        {pos: [9, 1, 5], state: "minecraft:stone_bricks"},
        {pos: [9, 1, 6], state: "minecraft:stone_bricks"},
        {pos: [9, 1, 7], state: "minecraft:stone_bricks"},
        {pos: [9, 1, 8], state: "minecraft:polished_andesite"},
        {pos: [9, 1, 9], state: "minecraft:gravel"},
        {pos: [10, 1, 3], state: "minecraft:gravel"},
        {pos: [10, 1, 4], state: "minecraft:gravel"},
        {pos: [10, 1, 5], state: "minecraft:stone_bricks"},
        {pos: [10, 1, 6], state: "minecraft:stone_bricks"},
        {pos: [10, 1, 7], state: "minecraft:gravel"},
        {pos: [10, 1, 8], state: "minecraft:gravel"},
        {pos: [0, 2, 5], state: "minecraft:gravel"},
        {pos: [0, 2, 6], state: "minecraft:gravel"},
        {pos: [0, 2, 7], state: "minecraft:gravel"},
        {pos: [1, 2, 3], state: "minecraft:gravel"},
        {pos: [1, 2, 4], state: "minecraft:gravel"},
        {pos: [1, 2, 5], state: "minecraft:stone_bricks"},
        {pos: [1, 2, 6], state: "minecraft:gravel"},
        {pos: [1, 2, 7], state: "minecraft:gravel"},
        {pos: [1, 2, 8], state: "minecraft:gravel"},
        {pos: [2, 2, 2], state: "minecraft:gravel"},
        {pos: [2, 2, 3], state: "minecraft:gravel"},
        {pos: [2, 2, 4], state: "minecraft:gravel"},
        {pos: [2, 2, 5], state: "minecraft:stone_bricks"},
        {pos: [2, 2, 6], state: "minecraft:stone_bricks"},
        {pos: [2, 2, 7], state: "minecraft:stone_bricks"},
        {pos: [2, 2, 8], state: "minecraft:stone_bricks"},
        {pos: [2, 2, 9], state: "minecraft:stone_bricks"},
        {pos: [3, 2, 1], state: "minecraft:gravel"},
        {pos: [3, 2, 2], state: "minecraft:stone_bricks"},
        {pos: [3, 2, 3], state: "minecraft:gravel"},
        {pos: [3, 2, 4], state: "minecraft:gravel"},
        {pos: [3, 2, 5], state: "minecraft:gravel"},
        {pos: [3, 2, 6], state: "minecraft:gravel"},
        {pos: [3, 2, 7], state: "minecraft:gravel"},
        {pos: [3, 2, 8], state: "minecraft:gravel"},
        {pos: [3, 2, 9], state: "minecraft:stone_bricks"},
        {pos: [3, 2, 10], state: "minecraft:gravel"},
        {pos: [4, 2, 0], state: "minecraft:gravel"},
        {pos: [4, 2, 1], state: "minecraft:gravel"},
        {pos: [4, 2, 2], state: "minecraft:stone_bricks"},
        {pos: [4, 2, 3], state: "minecraft:gravel"},
        {pos: [4, 2, 4], state: "minecraft:gravel"},
        {pos: [4, 2, 5], state: "minecraft:gravel"},
        {pos: [4, 2, 6], state: "minecraft:stone_bricks"},
        {pos: [4, 2, 7], state: "minecraft:polished_andesite"},
        {pos: [4, 2, 8], state: "minecraft:gravel"},
        {pos: [4, 2, 9], state: "minecraft:stone_bricks"},
        {pos: [4, 2, 10], state: "minecraft:gravel"},
        {pos: [5, 2, 0], state: "minecraft:gravel"},
        {pos: [5, 2, 1], state: "minecraft:stone_bricks"},
        {pos: [5, 2, 2], state: "minecraft:stone_bricks"},
        {pos: [5, 2, 3], state: "minecraft:gravel"},
        {pos: [5, 2, 4], state: "minecraft:gravel"},
        {pos: [5, 2, 5], state: "minecraft:gravel"},
        {pos: [5, 2, 6], state: "minecraft:stone_bricks"},
        {pos: [5, 2, 7], state: "minecraft:stone_bricks"},
        {pos: [5, 2, 8], state: "minecraft:stone_bricks"},
        {pos: [5, 2, 9], state: "minecraft:stone_bricks"},
        {pos: [5, 2, 10], state: "minecraft:gravel"},
        {pos: [5, 2, 11], state: "minecraft:gravel"},
        {pos: [6, 2, 1], state: "minecraft:gravel"},
        {pos: [6, 2, 2], state: "minecraft:stone_bricks"},
        {pos: [6, 2, 3], state: "minecraft:gravel"},
        {pos: [6, 2, 4], state: "minecraft:gravel"},
        {pos: [6, 2, 5], state: "minecraft:gravel"},
        {pos: [6, 2, 6], state: "minecraft:stone_bricks"},
        {pos: [6, 2, 7], state: "minecraft:stone_bricks"},
        {pos: [6, 2, 8], state: "minecraft:gravel"},
        {pos: [6, 2, 9], state: "minecraft:stone_bricks"},
        {pos: [6, 2, 10], state: "minecraft:gravel"},
        {pos: [6, 2, 11], state: "minecraft:gravel"},
        {pos: [7, 2, 1], state: "minecraft:gravel"},
        {pos: [7, 2, 2], state: "minecraft:gravel"},
        {pos: [7, 2, 3], state: "minecraft:gravel"},
        {pos: [7, 2, 4], state: "minecraft:gravel"},
        {pos: [7, 2, 5], state: "minecraft:gravel"},
        {pos: [7, 2, 6], state: "minecraft:gravel"},
        {pos: [7, 2, 7], state: "minecraft:gravel"},
        {pos: [7, 2, 8], state: "minecraft:gravel"},
        {pos: [7, 2, 9], state: "minecraft:stone_bricks"},
        {pos: [7, 2, 10], state: "minecraft:gravel"},
        {pos: [8, 2, 2], state: "minecraft:gravel"},
        {pos: [8, 2, 3], state: "minecraft:gravel"},
        {pos: [8, 2, 4], state: "minecraft:gravel"},
        {pos: [8, 2, 5], state: "minecraft:gravel"},
        {pos: [8, 2, 6], state: "minecraft:stone_bricks"},
        {pos: [8, 2, 7], state: "minecraft:stone_bricks"},
        {pos: [8, 2, 8], state: "minecraft:stone_bricks"},
        {pos: [8, 2, 9], state: "minecraft:chiseled_stone_bricks"},
        {pos: [9, 2, 3], state: "minecraft:gravel"},
        {pos: [9, 2, 4], state: "minecraft:gravel"},
        {pos: [9, 2, 5], state: "minecraft:gravel"},
        {pos: [9, 2, 6], state: "minecraft:gravel"},
        {pos: [9, 2, 7], state: "minecraft:gravel"},
        {pos: [9, 2, 8], state: "minecraft:gravel"},
        {pos: [9, 2, 9], state: "minecraft:gravel"},
        {pos: [10, 2, 3], state: "minecraft:gravel"},
        {pos: [10, 2, 4], state: "minecraft:gravel"},
        {pos: [10, 2, 5], state: "minecraft:gravel"},
        {pos: [10, 2, 6], state: "minecraft:gravel"},
        {pos: [10, 2, 7], state: "minecraft:gravel"},
        {pos: [10, 2, 8], state: "minecraft:gravel"},
        {pos: [1, 3, 4], state: "minecraft:gravel"},
        {pos: [1, 3, 5], state: "minecraft:gravel"},
        {pos: [1, 3, 6], state: "minecraft:gravel"},
        {pos: [1, 3, 7], state: "minecraft:gravel"},
        {pos: [2, 3, 4], state: "minecraft:gravel"},
        {pos: [2, 3, 5], state: "minecraft:gravel"},
        {pos: [2, 3, 6], state: "minecraft:gravel"},
        {pos: [2, 3, 7], state: "minecraft:stone_bricks"},
        {pos: [2, 3, 8], state: "minecraft:stone_bricks"},
        {pos: [2, 3, 9], state: "minecraft:gravel"},
        {pos: [3, 3, 2], state: "minecraft:gravel"},
        {pos: [3, 3, 3], state: "minecraft:gravel"},
        {pos: [3, 3, 4], state: "minecraft:gravel"},
        {pos: [3, 3, 5], state: "minecraft:gravel"},
        {pos: [3, 3, 6], state: "minecraft:polished_andesite"},
        {pos: [3, 3, 7], state: "minecraft:stone_bricks"},
        {pos: [3, 3, 8], state: "minecraft:stone_bricks"},
        {pos: [3, 3, 9], state: "minecraft:stone_bricks"},
        {pos: [3, 3, 10], state: "minecraft:gravel"},
        {pos: [4, 3, 1], state: "minecraft:gravel"},
        {pos: [4, 3, 2], state: "minecraft:gravel"},
        {pos: [4, 3, 3], state: "minecraft:gravel"},
        {pos: [4, 3, 4], state: "minecraft:stone_bricks"},
        {pos: [4, 3, 5], state: "minecraft:stone_bricks"},
        {pos: [4, 3, 6], state: "minecraft:stone_bricks"},
        {pos: [4, 3, 7], state: "minecraft:stone_bricks"},
        {pos: [4, 3, 8], state: "minecraft:stone_bricks"},
        {pos: [4, 3, 9], state: "minecraft:stone_bricks"},
        {pos: [4, 3, 10], state: "minecraft:gravel"},
        {pos: [5, 3, 0], state: "minecraft:gravel"},
        {pos: [5, 3, 1], state: "minecraft:gravel"},
        {pos: [5, 3, 2], state: "minecraft:stone_bricks"},
        {pos: [5, 3, 3], state: "minecraft:stone_bricks"},
        {pos: [5, 3, 4], state: "minecraft:stone_bricks"},
        {pos: [5, 3, 5], state: "minecraft:stone_bricks"},
        {pos: [5, 3, 6], state: "minecraft:stone_bricks"},
        {pos: [5, 3, 7], state: "minecraft:stone_bricks"},
        {pos: [5, 3, 8], state: "minecraft:stone_bricks"},
        {pos: [5, 3, 9], state: "minecraft:stone_bricks"},
        {pos: [5, 3, 10], state: "minecraft:gravel"},
        {pos: [6, 3, 1], state: "minecraft:gravel"},
        {pos: [6, 3, 2], state: "minecraft:gravel"},
        {pos: [6, 3, 3], state: "minecraft:gravel"},
        {pos: [6, 3, 4], state: "minecraft:gravel"},
        {pos: [6, 3, 5], state: "minecraft:stone_bricks"},
        {pos: [6, 3, 6], state: "minecraft:stone_bricks"},
        {pos: [6, 3, 7], state: "minecraft:stone_bricks"},
        {pos: [6, 3, 8], state: "minecraft:stone_bricks"},
        {pos: [6, 3, 9], state: "minecraft:stone_bricks"},
        {pos: [6, 3, 10], state: "minecraft:gravel"},
        {pos: [7, 3, 2], state: "minecraft:gravel"},
        {pos: [7, 3, 3], state: "minecraft:gravel"},
        {pos: [7, 3, 4], state: "minecraft:gravel"},
        {pos: [7, 3, 5], state: "minecraft:gravel"},
        {pos: [7, 3, 6], state: "minecraft:stone_bricks"},
        {pos: [7, 3, 7], state: "minecraft:stone_bricks"},
        {pos: [7, 3, 8], state: "minecraft:stone_bricks"},
        {pos: [7, 3, 9], state: "minecraft:stone_bricks"},
        {pos: [7, 3, 10], state: "minecraft:gravel"},
        {pos: [8, 3, 2], state: "minecraft:gravel"},
        {pos: [8, 3, 3], state: "minecraft:gravel"},
        {pos: [8, 3, 4], state: "minecraft:gravel"},
        {pos: [8, 3, 5], state: "minecraft:gravel"},
        {pos: [8, 3, 6], state: "minecraft:gravel"},
        {pos: [8, 3, 7], state: "minecraft:stone_bricks"},
        {pos: [8, 3, 8], state: "minecraft:stone_bricks"},
        {pos: [8, 3, 9], state: "minecraft:stone_bricks"},
        {pos: [9, 3, 3], state: "minecraft:gravel"},
        {pos: [9, 3, 4], state: "minecraft:gravel"},
        {pos: [9, 3, 5], state: "minecraft:gravel"},
        {pos: [9, 3, 6], state: "minecraft:gravel"},
        {pos: [9, 3, 7], state: "minecraft:gravel"},
        {pos: [9, 3, 8], state: "minecraft:gravel"},
        {pos: [9, 3, 9], state: "minecraft:gravel"},
        {pos: [10, 3, 5], state: "minecraft:gravel"},
        {pos: [10, 3, 6], state: "minecraft:gravel"},
        {pos: [10, 3, 7], state: "minecraft:gravel"},
        {pos: [1, 4, 6], state: "minecraft:gravel"},
        {pos: [1, 4, 7], state: "minecraft:gravel"},
        {pos: [2, 4, 5], state: "minecraft:gravel"},
        {pos: [2, 4, 6], state: "minecraft:gravel"},
        {pos: [2, 4, 7], state: "minecraft:polished_andesite"},
        {pos: [2, 4, 8], state: "minecraft:gravel"},
        {pos: [3, 4, 4], state: "minecraft:gravel"},
        {pos: [3, 4, 5], state: "minecraft:gravel"},
        {pos: [3, 4, 6], state: "minecraft:stone_bricks"},
        {pos: [3, 4, 7], state: "minecraft:stone_bricks"},
        {pos: [3, 4, 8], state: "minecraft:gravel"},
        {pos: [3, 4, 9], state: "minecraft:stone_bricks"},
        {pos: [3, 4, 10], state: "minecraft:gravel"},
        {pos: [4, 4, 3], state: "minecraft:gravel"},
        {pos: [4, 4, 4], state: "minecraft:stone_bricks"},
        {pos: [4, 4, 5], state: "minecraft:stone_bricks"},
        {pos: [4, 4, 6], state: "minecraft:stone_bricks"},
        {pos: [4, 4, 7], state: "minecraft:gravel"},
        {pos: [4, 4, 8], state: "minecraft:gravel"},
        {pos: [4, 4, 9], state: "minecraft:stone_bricks"},
        {pos: [4, 4, 10], state: "minecraft:gravel"},
        {pos: [5, 4, 1], state: "minecraft:gravel"},
        {pos: [5, 4, 2], state: "minecraft:gravel"},
        {pos: [5, 4, 3], state: "minecraft:gravel"},
        {pos: [5, 4, 4], state: "minecraft:gravel"},
        {pos: [5, 4, 5], state: "minecraft:gravel"},
        {pos: [5, 4, 6], state: "minecraft:gravel"},
        {pos: [5, 4, 7], state: "minecraft:gravel"},
        {pos: [5, 4, 8], state: "minecraft:gravel"},
        {pos: [5, 4, 9], state: "minecraft:gravel"},
        {pos: [5, 4, 10], state: "minecraft:gravel"},
        {pos: [6, 4, 2], state: "minecraft:gravel"},
        {pos: [6, 4, 3], state: "minecraft:gravel"},
        {pos: [6, 4, 4], state: "minecraft:gravel"},
        {pos: [6, 4, 5], state: "minecraft:gravel"},
        {pos: [6, 4, 6], state: "minecraft:gravel"},
        {pos: [6, 4, 7], state: "minecraft:gravel"},
        {pos: [6, 4, 8], state: "minecraft:gravel"},
        {pos: [6, 4, 9], state: "minecraft:stone_bricks"},
        {pos: [6, 4, 10], state: "minecraft:gravel"},
        {pos: [7, 4, 5], state: "minecraft:gravel"},
        {pos: [7, 4, 6], state: "minecraft:gravel"},
        {pos: [7, 4, 7], state: "minecraft:gravel"},
        {pos: [7, 4, 8], state: "minecraft:gravel"},
        {pos: [7, 4, 9], state: "minecraft:polished_andesite"},
        {pos: [7, 4, 10], state: "minecraft:gravel"},
        {pos: [8, 4, 6], state: "minecraft:gravel"},
        {pos: [8, 4, 7], state: "minecraft:stone_bricks"},
        {pos: [8, 4, 8], state: "minecraft:stone_bricks"},
        {pos: [8, 4, 9], state: "minecraft:stone_bricks"},
        {pos: [9, 4, 7], state: "minecraft:gravel"},
        {pos: [9, 4, 8], state: "minecraft:gravel"},
        {pos: [9, 4, 9], state: "minecraft:gravel"},
        {pos: [1, 5, 6], state: "minecraft:gravel"},
        {pos: [1, 5, 7], state: "minecraft:gravel"},
        {pos: [2, 5, 5], state: "minecraft:gravel"},
        {pos: [2, 5, 6], state: "minecraft:gravel"},
        {pos: [2, 5, 7], state: "minecraft:stone_bricks"},
        {pos: [2, 5, 8], state: "minecraft:gravel"},
        {pos: [3, 5, 4], state: "minecraft:gravel"},
        {pos: [3, 5, 5], state: "minecraft:gravel"},
        {pos: [3, 5, 6], state: "minecraft:stone_bricks"},
        {pos: [3, 5, 7], state: "minecraft:gravel"},
        {pos: [3, 5, 8], state: "minecraft:gravel"},
        {pos: [3, 5, 9], state: "minecraft:gravel"},
        {pos: [4, 5, 3], state: "minecraft:gravel"},
        {pos: [4, 5, 4], state: "minecraft:stone_bricks"},
        {pos: [4, 5, 5], state: "minecraft:stone_bricks"},
        {pos: [4, 5, 6], state: "minecraft:gravel"},
        {pos: [4, 5, 7], state: "minecraft:gravel"},
        {pos: [4, 5, 8], state: "minecraft:gravel"},
        {pos: [4, 5, 9], state: "minecraft:stone_bricks"},
        {pos: [4, 5, 10], state: "minecraft:gravel"},
        {pos: [5, 5, 1], state: "minecraft:gravel"},
        {pos: [5, 5, 2], state: "minecraft:gravel"},
        {pos: [5, 5, 3], state: "minecraft:gravel"},
        {pos: [5, 5, 4], state: "minecraft:gravel"},
        {pos: [5, 5, 5], state: "minecraft:gravel"},
        {pos: [5, 5, 6], state: "minecraft:gravel"},
        {pos: [5, 5, 7], state: "minecraft:gravel"},
        {pos: [5, 5, 8], state: "minecraft:gravel"},
        {pos: [5, 5, 9], state: "minecraft:gravel"},
        {pos: [5, 5, 10], state: "minecraft:gravel"},
        {pos: [6, 5, 3], state: "minecraft:gravel"},
        {pos: [6, 5, 4], state: "minecraft:gravel"},
        {pos: [6, 5, 5], state: "minecraft:gravel"},
        {pos: [6, 5, 6], state: "minecraft:gravel"},
        {pos: [6, 5, 7], state: "minecraft:gravel"},
        {pos: [6, 5, 8], state: "minecraft:gravel"},
        {pos: [6, 5, 9], state: "minecraft:gravel"},
        {pos: [6, 5, 10], state: "minecraft:gravel"},
        {pos: [7, 5, 5], state: "minecraft:gravel"},
        {pos: [7, 5, 6], state: "minecraft:gravel"},
        {pos: [7, 5, 7], state: "minecraft:gravel"},
        {pos: [7, 5, 8], state: "minecraft:gravel"},
        {pos: [7, 5, 9], state: "minecraft:stone_bricks"},
        {pos: [7, 5, 10], state: "minecraft:gravel"},
        {pos: [8, 5, 6], state: "minecraft:gravel"},
        {pos: [8, 5, 7], state: "minecraft:gravel"},
        {pos: [8, 5, 8], state: "minecraft:stone_bricks"},
        {pos: [8, 5, 9], state: "minecraft:stone_bricks"},
        {pos: [9, 5, 8], state: "minecraft:gravel"},
        {pos: [9, 5, 9], state: "minecraft:gravel"},
        {pos: [1, 6, 7], state: "minecraft:gravel"},
        {pos: [2, 6, 6], state: "minecraft:gravel"},
        {pos: [2, 6, 7], state: "minecraft:stone_bricks"},
        {pos: [2, 6, 8], state: "minecraft:gravel"},
        {pos: [3, 6, 4], state: "minecraft:gravel"},
        {pos: [3, 6, 5], state: "minecraft:gravel"},
        {pos: [3, 6, 6], state: "minecraft:stone_bricks"},
        {pos: [3, 6, 7], state: "minecraft:gravel"},
        {pos: [3, 6, 8], state: "minecraft:gravel"},
        {pos: [3, 6, 9], state: "minecraft:gravel"},
        {pos: [4, 6, 3], state: "minecraft:gravel"},
        {pos: [4, 6, 4], state: "minecraft:stone_bricks"},
        {pos: [4, 6, 5], state: "minecraft:gravel"},
        {pos: [4, 6, 6], state: "minecraft:gravel"},
        {pos: [4, 6, 7], state: "minecraft:gravel"},
        {pos: [4, 6, 8], state: "minecraft:gravel"},
        {pos: [4, 6, 9], state: "minecraft:gravel"},
        {pos: [5, 6, 2], state: "minecraft:gravel"},
        {pos: [5, 6, 3], state: "minecraft:gravel"},
        {pos: [5, 6, 4], state: "minecraft:gravel"},
        {pos: [5, 6, 5], state: "minecraft:gravel"},
        {pos: [5, 6, 6], state: "minecraft:gravel"},
        {pos: [5, 6, 7], state: "minecraft:gravel"},
        {pos: [5, 6, 8], state: "minecraft:gravel"},
        {pos: [5, 6, 9], state: "minecraft:gravel"},
        {pos: [6, 6, 5], state: "minecraft:gravel"},
        {pos: [6, 6, 6], state: "minecraft:gravel"},
        {pos: [6, 6, 7], state: "minecraft:gravel"},
        {pos: [6, 6, 8], state: "minecraft:gravel"},
        {pos: [6, 6, 9], state: "minecraft:gravel"},
        {pos: [6, 6, 10], state: "minecraft:gravel"},
        {pos: [7, 6, 6], state: "minecraft:gravel"},
        {pos: [7, 6, 7], state: "minecraft:gravel"},
        {pos: [7, 6, 8], state: "minecraft:gravel"},
        {pos: [7, 6, 9], state: "minecraft:stone_bricks"},
        {pos: [7, 6, 10], state: "minecraft:gravel"},
        {pos: [8, 6, 7], state: "minecraft:gravel"},
        {pos: [8, 6, 8], state: "minecraft:stone_bricks"},
        {pos: [8, 6, 9], state: "minecraft:stone_bricks"},
        {pos: [9, 6, 8], state: "minecraft:gravel"},
        {pos: [9, 6, 9], state: "minecraft:gravel"},
        {pos: [1, 7, 7], state: "minecraft:gravel"},
        {pos: [2, 7, 7], state: "minecraft:stone_bricks"},
        {pos: [3, 7, 6], state: "minecraft:stone_bricks"},
        {pos: [3, 7, 7], state: "minecraft:gravel"},
        {pos: [4, 7, 4], state: "minecraft:gravel"},
        {pos: [4, 7, 5], state: "minecraft:gravel"},
        {pos: [4, 7, 6], state: "minecraft:gravel"},
        {pos: [7, 7, 9], state: "minecraft:gravel"},
        {pos: [8, 7, 9], state: "minecraft:stone_bricks"},
        {pos: [3, 8, 6], state: "minecraft:stone_bricks"},
        {pos: [8, 8, 9], state: "minecraft:stone_bricks"},
        {pos: [3, 9, 6], state: "minecraft:stone_bricks"}
    ],
    entities: [],
    palette: [
        "minecraft:stone_bricks",
        "minecraft:polished_andesite",
        "minecraft:chiseled_stone_bricks",
        "minecraft:gravel",
        "minecraft:cauldron"
    ],
    trailiertales_DataVersion: 2
}
