{
    DataVersion: 3953,
    size: [25, 10, 18],
    data: [
        {pos: [0, 0, 11], state: "minecraft:stone_bricks"},
        {pos: [1, 0, 10], state: "minecraft:stone_bricks"},
        {pos: [1, 0, 11], state: "minecraft:stone_bricks"},
        {pos: [1, 0, 12], state: "minecraft:polished_andesite"},
        {pos: [1, 0, 15], state: "minecraft:stone_bricks"},
        {pos: [2, 0, 10], state: "minecraft:stone_bricks"},
        {pos: [2, 0, 11], state: "minecraft:stone_bricks"},
        {pos: [2, 0, 12], state: "minecraft:stone_bricks"},
        {pos: [2, 0, 13], state: "minecraft:stone_bricks"},
        {pos: [2, 0, 14], state: "minecraft:polished_andesite"},
        {pos: [2, 0, 15], state: "minecraft:stone_bricks"},
        {pos: [2, 0, 16], state: "minecraft:stone_bricks"},
        {pos: [3, 0, 10], state: "minecraft:stone_bricks"},
        {pos: [3, 0, 11], state: "minecraft:stone_bricks"},
        {pos: [3, 0, 12], state: "minecraft:stone_bricks"},
        {pos: [3, 0, 13], state: "minecraft:stone_bricks"},
        {pos: [3, 0, 14], state: "minecraft:stone_bricks"},
        {pos: [3, 0, 15], state: "minecraft:stone_bricks"},
        {pos: [3, 0, 16], state: "minecraft:stone_bricks"},
        {pos: [4, 0, 11], state: "minecraft:stone_bricks"},
        {pos: [4, 0, 12], state: "minecraft:stone_bricks"},
        {pos: [4, 0, 13], state: "minecraft:stone_bricks"},
        {pos: [4, 0, 14], state: "minecraft:stone_bricks"},
        {pos: [4, 0, 15], state: "minecraft:stone_bricks"},
        {pos: [4, 0, 16], state: "minecraft:stone_bricks"},
        {pos: [4, 0, 17], state: "minecraft:stone_bricks"},
        {pos: [5, 0, 10], state: "minecraft:stone_bricks"},
        {pos: [5, 0, 11], state: "minecraft:stone_bricks"},
        {pos: [5, 0, 12], state: "minecraft:stone_bricks"},
        {pos: [5, 0, 13], state: "minecraft:stone_bricks"},
        {pos: [5, 0, 14], state: "minecraft:stone_bricks"},
        {pos: [5, 0, 15], state: "minecraft:gravel"},
        {pos: [5, 0, 16], state: "minecraft:stone_bricks"},
        {pos: [5, 0, 17], state: "minecraft:stone_bricks"},
        {pos: [6, 0, 9], state: "minecraft:stone_bricks"},
        {pos: [6, 0, 10], state: "minecraft:stone_bricks"},
        {pos: [6, 0, 11], state: "minecraft:stone_bricks"},
        {pos: [6, 0, 12], state: "minecraft:stone_bricks"},
        {pos: [6, 0, 13], state: "minecraft:stone_bricks"},
        {pos: [6, 0, 14], state: "minecraft:stone_bricks"},
        {pos: [6, 0, 15], state: "minecraft:stone_bricks"},
        {pos: [6, 0, 16], state: "minecraft:stone_bricks"},
        {pos: [6, 0, 17], state: "minecraft:stone_bricks"},
        {pos: [7, 0, 8], state: "minecraft:stone_bricks"},
        {pos: [7, 0, 9], state: "minecraft:stone_bricks"},
        {pos: [7, 0, 10], state: "minecraft:stone_bricks"},
        {pos: [7, 0, 11], state: "minecraft:stone_bricks"},
        {pos: [7, 0, 12], state: "minecraft:stone_bricks"},
        {pos: [7, 0, 13], state: "minecraft:stone_bricks"},
        {pos: [7, 0, 14], state: "minecraft:stone_bricks"},
        {pos: [7, 0, 15], state: "minecraft:stone_bricks"},
        {pos: [7, 0, 16], state: "minecraft:stone_bricks"},
        {pos: [7, 0, 17], state: "minecraft:stone_bricks"},
        {pos: [8, 0, 7], state: "minecraft:stone_bricks"},
        {pos: [8, 0, 8], state: "minecraft:stone_bricks"},
        {pos: [8, 0, 9], state: "minecraft:stone_bricks"},
        {pos: [8, 0, 10], state: "minecraft:stone_bricks"},
        {pos: [8, 0, 11], state: "minecraft:stone_bricks"},
        {pos: [8, 0, 12], state: "minecraft:stone_bricks"},
        {pos: [8, 0, 13], state: "minecraft:stone_bricks"},
        {pos: [8, 0, 14], state: "minecraft:stone_bricks"},
        {pos: [8, 0, 15], state: "minecraft:stone_bricks"},
        {pos: [8, 0, 16], state: "minecraft:stone_bricks"},
        {pos: [8, 0, 17], state: "minecraft:stone_bricks"},
        {pos: [9, 0, 6], state: "minecraft:stone_bricks"},
        {pos: [9, 0, 7], state: "minecraft:stone_bricks"},
        {pos: [9, 0, 8], state: "minecraft:stone_bricks"},
        {pos: [9, 0, 9], state: "minecraft:stone_bricks"},
        {pos: [9, 0, 13], state: "minecraft:stone_bricks"},
        {pos: [9, 0, 14], state: "minecraft:stone_bricks"},
        {pos: [9, 0, 15], state: "minecraft:stone_bricks"},
        {pos: [9, 0, 16], state: "minecraft:stone_bricks"},
        {pos: [10, 0, 1], state: "minecraft:stone_bricks"},
        {pos: [10, 0, 2], state: "minecraft:stone_bricks"},
        {pos: [10, 0, 5], state: "minecraft:stone_bricks"},
        {pos: [10, 0, 6], state: "minecraft:polished_andesite"},
        {pos: [10, 0, 7], state: "minecraft:stone_bricks"},
        {pos: [10, 0, 8], state: "minecraft:stone_bricks"},
        {pos: [10, 0, 9], state: "minecraft:stone_bricks"},
        {pos: [10, 0, 14], state: "minecraft:stone_bricks"},
        {pos: [10, 0, 15], state: "minecraft:stone_bricks"},
        {pos: [11, 0, 0], state: "minecraft:stone_bricks"},
        {pos: [11, 0, 1], state: "minecraft:stone_bricks"},
        {pos: [11, 0, 2], state: "minecraft:stone_bricks"},
        {pos: [11, 0, 3], state: "minecraft:stone_bricks"},
        {pos: [11, 0, 14], state: "minecraft:stone_bricks"},
        {pos: [11, 0, 15], state: "minecraft:stone_bricks"},
        {pos: [12, 0, 0], state: "minecraft:stone_bricks"},
        {pos: [12, 0, 1], state: "minecraft:stone_bricks"},
        {pos: [12, 0, 2], state: "minecraft:stone_bricks"},
        {pos: [12, 0, 3], state: "minecraft:stone_bricks"},
        {pos: [12, 0, 4], state: "minecraft:stone_bricks"},
        {pos: [12, 0, 10], state: "minecraft:stone_bricks"},
        {pos: [12, 0, 11], state: "minecraft:stone_bricks"},
        {pos: [12, 0, 14], state: "minecraft:stone_bricks"},
        {pos: [12, 0, 15], state: "minecraft:stone_bricks"},
        {pos: [12, 0, 16], state: "minecraft:stone_bricks"},
        {pos: [13, 0, 0], state: "minecraft:stone_bricks"},
        {pos: [13, 0, 1], state: "minecraft:stone_bricks"},
        {pos: [13, 0, 2], state: "minecraft:polished_andesite"},
        {pos: [13, 0, 3], state: "minecraft:stone_bricks"},
        {pos: [13, 0, 4], state: "minecraft:stone_bricks"},
        {pos: [13, 0, 11], state: "minecraft:stone_bricks"},
        {pos: [13, 0, 15], state: "minecraft:stone_bricks"},
        {pos: [13, 0, 16], state: "minecraft:stone_bricks"},
        {pos: [14, 0, 1], state: "minecraft:stone_bricks"},
        {pos: [14, 0, 2], state: "minecraft:stone_bricks"},
        {pos: [14, 0, 3], state: "minecraft:stone_bricks"},
        {pos: [14, 0, 4], state: "minecraft:stone_bricks"},
        {pos: [14, 0, 6], state: "minecraft:stone_bricks"},
        {pos: [14, 0, 7], state: "minecraft:stone_bricks"},
        {pos: [14, 0, 8], state: "minecraft:stone_bricks"},
        {pos: [14, 0, 9], state: "minecraft:stone_bricks"},
        {pos: [14, 0, 13], state: "minecraft:stone_bricks"},
        {pos: [14, 0, 15], state: "minecraft:stone_bricks"},
        {pos: [14, 0, 16], state: "minecraft:stone_bricks"},
        {pos: [15, 0, 2], state: "minecraft:stone_bricks"},
        {pos: [15, 0, 3], state: "minecraft:stone_bricks"},
        {pos: [15, 0, 7], state: "minecraft:stone_bricks"},
        {pos: [15, 0, 8], state: "minecraft:stone_bricks"},
        {pos: [15, 0, 9], state: "minecraft:stone_bricks"},
        {pos: [15, 0, 10], state: "minecraft:stone_bricks"},
        {pos: [15, 0, 12], state: "minecraft:stone_bricks"},
        {pos: [15, 0, 13], state: "minecraft:stone_bricks"},
        {pos: [15, 0, 15], state: "minecraft:stone_bricks"},
        {pos: [15, 0, 16], state: "minecraft:stone_bricks"},
        {pos: [15, 0, 17], state: "minecraft:stone_bricks"},
        {pos: [16, 0, 7], state: "minecraft:stone_bricks"},
        {pos: [16, 0, 8], state: "minecraft:stone_bricks"},
        {pos: [16, 0, 9], state: "minecraft:stone_bricks"},
        {pos: [16, 0, 10], state: "minecraft:stone_bricks"},
        {pos: [16, 0, 11], state: "minecraft:stone_bricks"},
        {pos: [16, 0, 12], state: "minecraft:stone_bricks"},
        {pos: [16, 0, 13], state: "minecraft:stone_bricks"},
        {pos: [16, 0, 14], state: "minecraft:stone_bricks"},
        {pos: [16, 0, 15], state: "minecraft:stone_bricks"},
        {pos: [16, 0, 16], state: "minecraft:stone_bricks"},
        {pos: [16, 0, 17], state: "minecraft:stone_bricks"},
        {pos: [17, 0, 9], state: "minecraft:stone_bricks"},
        {pos: [17, 0, 10], state: "minecraft:stone_bricks"},
        {pos: [17, 0, 11], state: "minecraft:stone_bricks"},
        {pos: [17, 0, 12], state: "minecraft:polished_andesite"},
        {pos: [17, 0, 13], state: "minecraft:stone_bricks"},
        {pos: [17, 0, 14], state: "minecraft:stone_bricks"},
        {pos: [17, 0, 15], state: "minecraft:stone_bricks"},
        {pos: [17, 0, 16], state: "minecraft:stone_bricks"},
        {pos: [17, 0, 17], state: "minecraft:stone_bricks"},
        {pos: [18, 0, 10], state: "minecraft:stone_bricks"},
        {pos: [18, 0, 11], state: "minecraft:stone_bricks"},
        {pos: [18, 0, 12], state: "minecraft:stone_bricks"},
        {pos: [18, 0, 13], state: "minecraft:stone_bricks"},
        {pos: [18, 0, 14], state: "minecraft:stone_bricks"},
        {pos: [18, 0, 15], state: "minecraft:stone_bricks"},
        {pos: [18, 0, 16], state: "minecraft:stone_bricks"},
        {pos: [19, 0, 11], state: "minecraft:polished_andesite"},
        {pos: [19, 0, 12], state: "minecraft:stone_bricks"},
        {pos: [19, 0, 13], state: "minecraft:polished_andesite"},
        {pos: [19, 0, 14], state: "minecraft:stone_bricks"},
        {pos: [19, 0, 15], state: "minecraft:stone_bricks"},
        {pos: [20, 0, 10], state: "minecraft:chiseled_stone_bricks"},
        {pos: [20, 0, 11], state: "minecraft:stone_bricks"},
        {pos: [20, 0, 12], state: "minecraft:stone_bricks"},
        {pos: [20, 0, 13], state: "minecraft:stone_bricks"},
        {pos: [20, 0, 14], state: "minecraft:stone_bricks"},
        {pos: [20, 0, 15], state: "minecraft:stone_bricks"},
        {pos: [21, 0, 9], state: "minecraft:stone_bricks"},
        {pos: [21, 0, 10], state: "minecraft:stone_bricks"},
        {pos: [21, 0, 11], state: "minecraft:stone_bricks"},
        {pos: [21, 0, 12], state: "minecraft:stone_bricks"},
        {pos: [21, 0, 13], state: "minecraft:stone_bricks"},
        {pos: [21, 0, 14], state: "minecraft:stone_bricks"},
        {pos: [21, 0, 15], state: "minecraft:stone_bricks"},
        {pos: [21, 0, 16], state: "minecraft:stone_bricks"},
        {pos: [22, 0, 9], state: "minecraft:stone_bricks"},
        {pos: [22, 0, 10], state: "minecraft:stone_bricks"},
        {pos: [22, 0, 11], state: "minecraft:stone_bricks"},
        {pos: [22, 0, 12], state: "minecraft:stone_bricks"},
        {pos: [22, 0, 13], state: "minecraft:stone_bricks"},
        {pos: [22, 0, 14], state: "minecraft:stone_bricks"},
        {pos: [22, 0, 15], state: "minecraft:stone_bricks"},
        {pos: [22, 0, 16], state: "minecraft:stone_bricks"},
        {pos: [22, 0, 17], state: "minecraft:stone_bricks"},
        {pos: [23, 0, 10], state: "minecraft:stone_bricks"},
        {pos: [23, 0, 11], state: "minecraft:stone_bricks"},
        {pos: [23, 0, 14], state: "minecraft:chiseled_stone_bricks"},
        {pos: [23, 0, 15], state: "minecraft:stone_bricks"},
        {pos: [23, 0, 16], state: "minecraft:stone_bricks"},
        {pos: [23, 0, 17], state: "minecraft:stone_bricks"},
        {pos: [24, 0, 15], state: "minecraft:stone_bricks"},
        {pos: [24, 0, 16], state: "minecraft:polished_andesite"},
        {pos: [0, 1, 11], state: "minecraft:gravel"},
        {pos: [1, 1, 10], state: "minecraft:gravel"},
        {pos: [1, 1, 11], state: "minecraft:gravel"},
        {pos: [1, 1, 12], state: "minecraft:gravel"},
        {pos: [1, 1, 15], state: "minecraft:gravel"},
        {pos: [2, 1, 10], state: "minecraft:gravel"},
        {pos: [2, 1, 11], state: "minecraft:stone_bricks"},
        {pos: [2, 1, 12], state: "minecraft:stone_bricks"},
        {pos: [2, 1, 13], state: "minecraft:gravel"},
        {pos: [2, 1, 14], state: "minecraft:stone_bricks"},
        {pos: [2, 1, 15], state: "minecraft:stone_bricks"},
        {pos: [2, 1, 16], state: "minecraft:gravel"},
        {pos: [3, 1, 10], state: "minecraft:gravel"},
        {pos: [3, 1, 11], state: "minecraft:stone_bricks"},
        {pos: [3, 1, 12], state: "minecraft:cauldron"},
        {pos: [3, 1, 13], state: "minecraft:gravel"},
        {pos: [3, 1, 14], state: "minecraft:gravel"},
        {pos: [3, 1, 15], state: "minecraft:gravel"},
        {pos: [3, 1, 16], state: "minecraft:gravel"},
        {pos: [4, 1, 11], state: "minecraft:stone_bricks"},
        {pos: [4, 1, 12], state: "minecraft:gravel"},
        {pos: [4, 1, 13], state: "minecraft:gravel"},
        {pos: [4, 1, 14], state: "minecraft:gravel"},
        {pos: [4, 1, 15], state: "minecraft:gravel"},
        {pos: [4, 1, 16], state: "minecraft:stone_bricks"},
        {pos: [4, 1, 17], state: "minecraft:gravel"},
        {pos: [5, 1, 10], state: "minecraft:gravel"},
        {pos: [5, 1, 11], state: "minecraft:stone_bricks"},
        {pos: [5, 1, 12], state: "minecraft:gravel"},
        {pos: [5, 1, 13], state: "minecraft:gravel"},
        {pos: [5, 1, 14], state: "minecraft:gravel"},
        {pos: [5, 1, 15], state: "minecraft:gravel"},
        {pos: [5, 1, 16], state: "minecraft:stone_bricks"},
        {pos: [5, 1, 17], state: "minecraft:gravel"},
        {pos: [6, 1, 9], state: "minecraft:gravel"},
        {pos: [6, 1, 10], state: "minecraft:gravel"},
        {pos: [6, 1, 11], state: "minecraft:stone_bricks"},
        {pos: [6, 1, 12], state: "minecraft:gravel"},
        {pos: [6, 1, 13], state: "minecraft:gravel"},
        {pos: [6, 1, 14], state: "minecraft:polished_andesite"},
        {pos: [6, 1, 15], state: "minecraft:stone_bricks"},
        {pos: [6, 1, 16], state: "minecraft:polished_andesite"},
        {pos: [6, 1, 17], state: "minecraft:gravel"},
        {pos: [7, 1, 8], state: "minecraft:gravel"},
        {pos: [7, 1, 9], state: "minecraft:gravel"},
        {pos: [7, 1, 10], state: "minecraft:gravel"},
        {pos: [7, 1, 11], state: "minecraft:gravel"},
        {pos: [7, 1, 12], state: "minecraft:gravel"},
        {pos: [7, 1, 13], state: "minecraft:gravel"},
        {pos: [7, 1, 14], state: "minecraft:gravel"},
        {pos: [7, 1, 15], state: "minecraft:stone_bricks"},
        {pos: [7, 1, 16], state: "minecraft:gravel"},
        {pos: [7, 1, 17], state: "minecraft:gravel"},
        {pos: [8, 1, 7], state: "minecraft:stone_bricks"},
        {pos: [8, 1, 8], state: "minecraft:gravel"},
        {pos: [8, 1, 9], state: "minecraft:gravel"},
        {pos: [8, 1, 10], state: "minecraft:gravel"},
        {pos: [8, 1, 11], state: "minecraft:gravel"},
        {pos: [8, 1, 12], state: "minecraft:gravel"},
        {pos: [8, 1, 13], state: "minecraft:gravel"},
        {pos: [8, 1, 14], state: "minecraft:gravel"},
        {pos: [8, 1, 15], state: "minecraft:stone_bricks"},
        {pos: [8, 1, 16], state: "minecraft:gravel"},
        {pos: [8, 1, 17], state: "minecraft:gravel"},
        {pos: [9, 1, 6], state: "minecraft:gravel"},
        {pos: [9, 1, 7], state: "minecraft:stone_bricks"},
        {pos: [9, 1, 8], state: "minecraft:gravel"},
        {pos: [9, 1, 9], state: "minecraft:gravel"},
        {pos: [9, 1, 13], state: "minecraft:gravel"},
        {pos: [9, 1, 14], state: "minecraft:gravel"},
        {pos: [9, 1, 15], state: "minecraft:stone_bricks"},
        {pos: [9, 1, 16], state: "minecraft:gravel"},
        {pos: [10, 1, 1], state: "minecraft:gravel"},
        {pos: [10, 1, 2], state: "minecraft:gravel"},
        {pos: [10, 1, 5], state: "minecraft:gravel"},
        {pos: [10, 1, 6], state: "minecraft:gravel"},
        {pos: [10, 1, 7], state: "minecraft:gravel"},
        {pos: [10, 1, 8], state: "minecraft:gravel"},
        {pos: [10, 1, 9], state: "minecraft:gravel"},
        {pos: [10, 1, 14], state: "minecraft:gravel"},
        {pos: [10, 1, 15], state: "minecraft:stone_bricks"},
        {pos: [11, 1, 0], state: "minecraft:gravel"},
        {pos: [11, 1, 1], state: "minecraft:gravel"},
        {pos: [11, 1, 2], state: "minecraft:cauldron"},
        {pos: [11, 1, 3], state: "minecraft:gravel"},
        {pos: [11, 1, 14], state: "minecraft:gravel"},
        {pos: [11, 1, 15], state: "minecraft:stone_bricks"},
        {pos: [12, 1, 0], state: "minecraft:gravel"},
        {pos: [12, 1, 1], state: "minecraft:gravel"},
        {pos: [12, 1, 2], state: "minecraft:stone_bricks"},
        {pos: [12, 1, 3], state: "minecraft:stone_bricks"},
        {pos: [12, 1, 4], state: "minecraft:gravel"},
        {pos: [12, 1, 10], state: "minecraft:stone_bricks"},
        {pos: [12, 1, 11], state: "minecraft:stone_bricks"},
        {pos: [12, 1, 14], state: "minecraft:gravel"},
        {pos: [12, 1, 15], state: "minecraft:gravel"},
        {pos: [12, 1, 16], state: "minecraft:gravel"},
        {pos: [13, 1, 0], state: "minecraft:gravel"},
        {pos: [13, 1, 1], state: "minecraft:gravel"},
        {pos: [13, 1, 2], state: "minecraft:polished_andesite"},
        {pos: [13, 1, 3], state: "minecraft:stone_bricks"},
        {pos: [13, 1, 4], state: "minecraft:gravel"},
        {pos: [13, 1, 11], state: "minecraft:stone_bricks"},
        {pos: [13, 1, 15], state: "minecraft:stone_bricks"},
        {pos: [13, 1, 16], state: "minecraft:gravel"},
        {pos: [14, 1, 1], state: "minecraft:gravel"},
        {pos: [14, 1, 2], state: "minecraft:gravel"},
        {pos: [14, 1, 3], state: "minecraft:gravel"},
        {pos: [14, 1, 4], state: "minecraft:gravel"},
        {pos: [14, 1, 6], state: "minecraft:gravel"},
        {pos: [14, 1, 7], state: "minecraft:gravel"},
        {pos: [14, 1, 8], state: "minecraft:gravel"},
        {pos: [14, 1, 9], state: "minecraft:gravel"},
        {pos: [14, 1, 13], state: "minecraft:gravel"},
        {pos: [14, 1, 15], state: "minecraft:stone_bricks"},
        {pos: [14, 1, 16], state: "minecraft:gravel"},
        {pos: [15, 1, 2], state: "minecraft:gravel"},
        {pos: [15, 1, 3], state: "minecraft:gravel"},
        {pos: [15, 1, 7], state: "minecraft:gravel"},
        {pos: [15, 1, 8], state: "minecraft:gravel"},
        {pos: [15, 1, 9], state: "minecraft:gravel"},
        {pos: [15, 1, 10], state: "minecraft:gravel"},
        {pos: [15, 1, 12], state: "minecraft:gravel"},
        {pos: [15, 1, 13], state: "minecraft:gravel"},
        {pos: [15, 1, 15], state: "minecraft:stone_bricks"},
        {pos: [15, 1, 16], state: "minecraft:gravel"},
        {pos: [15, 1, 17], state: "minecraft:gravel"},
        {pos: [16, 1, 7], state: "minecraft:gravel"},
        {pos: [16, 1, 8], state: "minecraft:gravel"},
        {pos: [16, 1, 9], state: "minecraft:gravel"},
        {pos: [16, 1, 10], state: "minecraft:gravel"},
        {pos: [16, 1, 11], state: "minecraft:gravel"},
        {pos: [16, 1, 12], state: "minecraft:gravel"},
        {pos: [16, 1, 13], state: "minecraft:gravel"},
        {pos: [16, 1, 14], state: "minecraft:gravel"},
        {pos: [16, 1, 15], state: "minecraft:stone_bricks"},
        {pos: [16, 1, 16], state: "minecraft:gravel"},
        {pos: [16, 1, 17], state: "minecraft:gravel"},
        {pos: [17, 1, 9], state: "minecraft:gravel"},
        {pos: [17, 1, 10], state: "minecraft:gravel"},
        {pos: [17, 1, 11], state: "minecraft:gravel"},
        {pos: [17, 1, 12], state: "minecraft:gravel"},
        {pos: [17, 1, 13], state: "minecraft:gravel"},
        {pos: [17, 1, 14], state: "minecraft:gravel"},
        {pos: [17, 1, 15], state: "minecraft:stone_bricks"},
        {pos: [17, 1, 16], state: "minecraft:gravel"},
        {pos: [17, 1, 17], state: "minecraft:gravel"},
        {pos: [18, 1, 10], state: "minecraft:gravel"},
        {pos: [18, 1, 11], state: "minecraft:gravel"},
        {pos: [18, 1, 12], state: "minecraft:gravel"},
        {pos: [18, 1, 13], state: "minecraft:gravel"},
        {pos: [18, 1, 14], state: "minecraft:gravel"},
        {pos: [18, 1, 15], state: "minecraft:polished_andesite"},
        {pos: [18, 1, 16], state: "minecraft:gravel"},
        {pos: [19, 1, 11], state: "minecraft:stone_bricks"},
        {pos: [19, 1, 12], state: "minecraft:gravel"},
        {pos: [19, 1, 13], state: "minecraft:gravel"},
        {pos: [19, 1, 14], state: "minecraft:stone_bricks"},
        {pos: [19, 1, 15], state: "minecraft:stone_bricks"},
        {pos: [20, 1, 10], state: "minecraft:gravel"},
        {pos: [20, 1, 11], state: "minecraft:stone_bricks"},
        {pos: [20, 1, 12], state: "minecraft:gravel"},
        {pos: [20, 1, 13], state: "minecraft:gravel"},
        {pos: [20, 1, 14], state: "minecraft:gravel"},
        {pos: [20, 1, 15], state: "minecraft:stone_bricks"},
        {pos: [21, 1, 9], state: "minecraft:gravel"},
        {pos: [21, 1, 10], state: "minecraft:gravel"},
        {pos: [21, 1, 11], state: "minecraft:stone_bricks"},
        {pos: [21, 1, 12], state: "minecraft:gravel"},
        {pos: [21, 1, 13], state: "minecraft:gravel"},
        {pos: [21, 1, 14], state: "minecraft:gravel"},
        {pos: [21, 1, 15], state: "minecraft:stone_bricks"},
        {pos: [21, 1, 16], state: "minecraft:gravel"},
        {pos: [22, 1, 9], state: "minecraft:gravel"},
        {pos: [22, 1, 10], state: "minecraft:gravel"},
        {pos: [22, 1, 11], state: "minecraft:gravel"},
        {pos: [22, 1, 12], state: "minecraft:gravel"},
        {pos: [22, 1, 13], state: "minecraft:stone_bricks"},
        {pos: [22, 1, 14], state: "minecraft:stone_bricks"},
        {pos: [22, 1, 15], state: "minecraft:stone_bricks"},
        {pos: [22, 1, 16], state: "minecraft:stone_bricks"},
        {pos: [22, 1, 17], state: "minecraft:gravel"},
        {pos: [23, 1, 10], state: "minecraft:gravel"},
        {pos: [23, 1, 11], state: "minecraft:gravel"},
        {pos: [23, 1, 14], state: "minecraft:gravel"},
        {pos: [23, 1, 15], state: "minecraft:stone_bricks"},
        {pos: [23, 1, 16], state: "minecraft:stone_bricks"},
        {pos: [23, 1, 17], state: "minecraft:gravel"},
        {pos: [24, 1, 15], state: "minecraft:gravel"},
        {pos: [24, 1, 16], state: "minecraft:gravel"},
        {pos: [0, 2, 11], state: "minecraft:gravel"},
        {pos: [1, 2, 10], state: "minecraft:gravel"},
        {pos: [1, 2, 11], state: "minecraft:gravel"},
        {pos: [1, 2, 12], state: "minecraft:gravel"},
        {pos: [1, 2, 15], state: "minecraft:gravel"},
        {pos: [2, 2, 10], state: "minecraft:gravel"},
        {pos: [2, 2, 11], state: "minecraft:stone_bricks"},
        {pos: [2, 2, 12], state: "minecraft:gravel"},
        {pos: [2, 2, 13], state: "minecraft:gravel"},
        {pos: [2, 2, 14], state: "minecraft:gravel"},
        {pos: [2, 2, 15], state: "minecraft:polished_andesite"},
        {pos: [2, 2, 16], state: "minecraft:gravel"},
        {pos: [3, 2, 10], state: "minecraft:gravel"},
        {pos: [3, 2, 11], state: "minecraft:stone_bricks"},
        {pos: [3, 2, 12], state: "minecraft:gravel"},
        {pos: [3, 2, 13], state: "minecraft:gravel"},
        {pos: [3, 2, 14], state: "minecraft:gravel"},
        {pos: [3, 2, 15], state: "minecraft:gravel"},
        {pos: [3, 2, 16], state: "minecraft:gravel"},
        {pos: [4, 2, 11], state: "minecraft:gravel"},
        {pos: [4, 2, 12], state: "minecraft:gravel"},
        {pos: [4, 2, 13], state: "minecraft:gravel"},
        {pos: [4, 2, 14], state: "minecraft:gravel"},
        {pos: [4, 2, 15], state: "minecraft:gravel"},
        {pos: [4, 2, 16], state: "minecraft:gravel"},
        {pos: [4, 2, 17], state: "minecraft:gravel"},
        {pos: [5, 2, 10], state: "minecraft:gravel"},
        {pos: [5, 2, 11], state: "minecraft:stone_bricks"},
        {pos: [5, 2, 12], state: "minecraft:gravel"},
        {pos: [5, 2, 13], state: "minecraft:gravel"},
        {pos: [5, 2, 14], state: "minecraft:gravel"},
        {pos: [5, 2, 15], state: "minecraft:gravel"},
        {pos: [5, 2, 16], state: "minecraft:stone_bricks"},
        {pos: [5, 2, 17], state: "minecraft:gravel"},
        {pos: [6, 2, 9], state: "minecraft:gravel"},
        {pos: [6, 2, 10], state: "minecraft:gravel"},
        {pos: [6, 2, 11], state: "minecraft:stone_bricks"},
        {pos: [6, 2, 12], state: "minecraft:gravel"},
        {pos: [6, 2, 13], state: "minecraft:gravel"},
        {pos: [6, 2, 14], state: "minecraft:gravel"},
        {pos: [6, 2, 15], state: "minecraft:stone_bricks"},
        {pos: [6, 2, 16], state: "minecraft:stone_bricks"},
        {pos: [6, 2, 17], state: "minecraft:gravel"},
        {pos: [7, 2, 8], state: "minecraft:gravel"},
        {pos: [7, 2, 9], state: "minecraft:gravel"},
        {pos: [7, 2, 10], state: "minecraft:gravel"},
        {pos: [7, 2, 11], state: "minecraft:gravel"},
        {pos: [7, 2, 12], state: "minecraft:gravel"},
        {pos: [7, 2, 13], state: "minecraft:gravel"},
        {pos: [7, 2, 14], state: "minecraft:gravel"},
        {pos: [7, 2, 15], state: "minecraft:gravel"},
        {pos: [7, 2, 16], state: "minecraft:gravel"},
        {pos: [7, 2, 17], state: "minecraft:gravel"},
        {pos: [8, 2, 7], state: "minecraft:chiseled_stone_bricks"},
        {pos: [8, 2, 8], state: "minecraft:gravel"},
        {pos: [8, 2, 9], state: "minecraft:gravel"},
        {pos: [8, 2, 10], state: "minecraft:gravel"},
        {pos: [8, 2, 11], state: "minecraft:gravel"},
        {pos: [8, 2, 12], state: "minecraft:gravel"},
        {pos: [8, 2, 13], state: "minecraft:gravel"},
        {pos: [8, 2, 14], state: "minecraft:gravel"},
        {pos: [8, 2, 15], state: "minecraft:stone_bricks"},
        {pos: [8, 2, 16], state: "minecraft:gravel"},
        {pos: [9, 2, 6], state: "minecraft:gravel"},
        {pos: [9, 2, 7], state: "minecraft:gravel"},
        {pos: [9, 2, 8], state: "minecraft:gravel"},
        {pos: [9, 2, 9], state: "minecraft:gravel"},
        {pos: [9, 2, 13], state: "minecraft:gravel"},
        {pos: [9, 2, 14], state: "minecraft:gravel"},
        {pos: [9, 2, 15], state: "minecraft:stone_bricks"},
        {pos: [9, 2, 16], state: "minecraft:gravel"},
        {pos: [10, 2, 1], state: "minecraft:gravel"},
        {pos: [10, 2, 2], state: "minecraft:gravel"},
        {pos: [10, 2, 5], state: "minecraft:gravel"},
        {pos: [10, 2, 6], state: "minecraft:gravel"},
        {pos: [10, 2, 7], state: "minecraft:gravel"},
        {pos: [10, 2, 8], state: "minecraft:gravel"},
        {pos: [10, 2, 9], state: "minecraft:gravel"},
        {pos: [10, 2, 14], state: "minecraft:gravel"},
        {pos: [10, 2, 15], state: "minecraft:stone_bricks"},
        {pos: [11, 2, 0], state: "minecraft:gravel"},
        {pos: [11, 2, 1], state: "minecraft:gravel"},
        {pos: [11, 2, 2], state: "minecraft:gravel"},
        {pos: [11, 2, 3], state: "minecraft:gravel"},
        {pos: [11, 2, 14], state: "minecraft:gravel"},
        {pos: [11, 2, 15], state: "minecraft:stone_bricks"},
        {pos: [12, 2, 0], state: "minecraft:gravel"},
        {pos: [12, 2, 1], state: "minecraft:gravel"},
        {pos: [12, 2, 2], state: "minecraft:stone_bricks"},
        {pos: [12, 2, 3], state: "minecraft:stone_bricks"},
        {pos: [12, 2, 4], state: "minecraft:gravel"},
        {pos: [12, 2, 10], state: "minecraft:stone_bricks"},
        {pos: [12, 2, 11], state: "minecraft:gravel"},
        {pos: [12, 2, 14], state: "minecraft:gravel"},
        {pos: [12, 2, 15], state: "minecraft:gravel"},
        {pos: [12, 2, 16], state: "minecraft:gravel"},
        {pos: [13, 2, 0], state: "minecraft:gravel"},
        {pos: [13, 2, 1], state: "minecraft:gravel"},
        {pos: [13, 2, 2], state: "minecraft:stone_bricks"},
        {pos: [13, 2, 3], state: "minecraft:stone_bricks"},
        {pos: [13, 2, 4], state: "minecraft:gravel"},
        {pos: [13, 2, 11], state: "minecraft:gravel"},
        {pos: [13, 2, 15], state: "minecraft:gravel"},
        {pos: [13, 2, 16], state: "minecraft:gravel"},
        {pos: [14, 2, 1], state: "minecraft:gravel"},
        {pos: [14, 2, 2], state: "minecraft:gravel"},
        {pos: [14, 2, 3], state: "minecraft:gravel"},
        {pos: [14, 2, 4], state: "minecraft:gravel"},
        {pos: [14, 2, 6], state: "minecraft:gravel"},
        {pos: [14, 2, 7], state: "minecraft:gravel"},
        {pos: [14, 2, 8], state: "minecraft:gravel"},
        {pos: [14, 2, 9], state: "minecraft:gravel"},
        {pos: [14, 2, 13], state: "minecraft:gravel"},
        {pos: [14, 2, 15], state: "minecraft:stone_bricks"},
        {pos: [14, 2, 16], state: "minecraft:gravel"},
        {pos: [15, 2, 2], state: "minecraft:gravel"},
        {pos: [15, 2, 3], state: "minecraft:gravel"},
        {pos: [15, 2, 7], state: "minecraft:gravel"},
        {pos: [15, 2, 8], state: "minecraft:gravel"},
        {pos: [15, 2, 9], state: "minecraft:gravel"},
        {pos: [15, 2, 10], state: "minecraft:gravel"},
        {pos: [15, 2, 12], state: "minecraft:gravel"},
        {pos: [15, 2, 13], state: "minecraft:gravel"},
        {pos: [15, 2, 15], state: "minecraft:chiseled_stone_bricks"},
        {pos: [15, 2, 16], state: "minecraft:gravel"},
        {pos: [15, 2, 17], state: "minecraft:gravel"},
        {pos: [16, 2, 7], state: "minecraft:gravel"},
        {pos: [16, 2, 8], state: "minecraft:gravel"},
        {pos: [16, 2, 9], state: "minecraft:gravel"},
        {pos: [16, 2, 10], state: "minecraft:gravel"},
        {pos: [16, 2, 11], state: "minecraft:gravel"},
        {pos: [16, 2, 12], state: "minecraft:gravel"},
        {pos: [16, 2, 13], state: "minecraft:gravel"},
        {pos: [16, 2, 14], state: "minecraft:gravel"},
        {pos: [16, 2, 15], state: "minecraft:stone_bricks"},
        {pos: [16, 2, 16], state: "minecraft:gravel"},
        {pos: [16, 2, 17], state: "minecraft:gravel"},
        {pos: [17, 2, 9], state: "minecraft:gravel"},
        {pos: [17, 2, 10], state: "minecraft:gravel"},
        {pos: [17, 2, 11], state: "minecraft:gravel"},
        {pos: [17, 2, 12], state: "minecraft:gravel"},
        {pos: [17, 2, 13], state: "minecraft:gravel"},
        {pos: [17, 2, 14], state: "minecraft:gravel"},
        {pos: [17, 2, 15], state: "minecraft:stone_bricks"},
        {pos: [17, 2, 16], state: "minecraft:gravel"},
        {pos: [17, 2, 17], state: "minecraft:gravel"},
        {pos: [18, 2, 10], state: "minecraft:gravel"},
        {pos: [18, 2, 11], state: "minecraft:gravel"},
        {pos: [18, 2, 12], state: "minecraft:gravel"},
        {pos: [18, 2, 13], state: "minecraft:gravel"},
        {pos: [18, 2, 14], state: "minecraft:gravel"},
        {pos: [18, 2, 15], state: "minecraft:gravel"},
        {pos: [18, 2, 16], state: "minecraft:gravel"},
        {pos: [19, 2, 11], state: "minecraft:stone_bricks"},
        {pos: [19, 2, 12], state: "minecraft:gravel"},
        {pos: [19, 2, 13], state: "minecraft:gravel"},
        {pos: [19, 2, 14], state: "minecraft:stone_bricks"},
        {pos: [19, 2, 15], state: "minecraft:gravel"},
        {pos: [20, 2, 10], state: "minecraft:gravel"},
        {pos: [20, 2, 11], state: "minecraft:stone_bricks"},
        {pos: [20, 2, 12], state: "minecraft:gravel"},
        {pos: [20, 2, 13], state: "minecraft:gravel"},
        {pos: [20, 2, 14], state: "minecraft:gravel"},
        {pos: [20, 2, 15], state: "minecraft:stone_bricks"},
        {pos: [21, 2, 9], state: "minecraft:gravel"},
        {pos: [21, 2, 10], state: "minecraft:gravel"},
        {pos: [21, 2, 11], state: "minecraft:chiseled_stone_bricks"},
        {pos: [21, 2, 12], state: "minecraft:gravel"},
        {pos: [21, 2, 13], state: "minecraft:gravel"},
        {pos: [21, 2, 14], state: "minecraft:gravel"},
        {pos: [21, 2, 15], state: "minecraft:stone_bricks"},
        {pos: [21, 2, 16], state: "minecraft:gravel"},
        {pos: [22, 2, 9], state: "minecraft:gravel"},
        {pos: [22, 2, 10], state: "minecraft:gravel"},
        {pos: [22, 2, 11], state: "minecraft:gravel"},
        {pos: [22, 2, 12], state: "minecraft:gravel"},
        {pos: [22, 2, 13], state: "minecraft:stone_bricks"},
        {pos: [22, 2, 14], state: "minecraft:gravel"},
        {pos: [22, 2, 15], state: "minecraft:stone_bricks"},
        {pos: [22, 2, 16], state: "minecraft:stone_bricks"},
        {pos: [22, 2, 17], state: "minecraft:gravel"},
        {pos: [23, 2, 10], state: "minecraft:gravel"},
        {pos: [23, 2, 11], state: "minecraft:gravel"},
        {pos: [23, 2, 14], state: "minecraft:gravel"},
        {pos: [23, 2, 15], state: "minecraft:gravel"},
        {pos: [23, 2, 16], state: "minecraft:stone_bricks"},
        {pos: [23, 2, 17], state: "minecraft:gravel"},
        {pos: [24, 2, 15], state: "minecraft:gravel"},
        {pos: [24, 2, 16], state: "minecraft:gravel"},
        {pos: [0, 3, 11], state: "minecraft:gravel"},
        {pos: [1, 3, 10], state: "minecraft:gravel"},
        {pos: [1, 3, 11], state: "minecraft:gravel"},
        {pos: [1, 3, 12], state: "minecraft:gravel"},
        {pos: [1, 3, 15], state: "minecraft:gravel"},
        {pos: [2, 3, 10], state: "minecraft:gravel"},
        {pos: [2, 3, 11], state: "minecraft:chiseled_stone_bricks"},
        {pos: [2, 3, 12], state: "minecraft:gravel"},
        {pos: [2, 3, 13], state: "minecraft:gravel"},
        {pos: [2, 3, 14], state: "minecraft:gravel"},
        {pos: [2, 3, 15], state: "minecraft:gravel"},
        {pos: [2, 3, 16], state: "minecraft:gravel"},
        {pos: [3, 3, 10], state: "minecraft:gravel"},
        {pos: [3, 3, 11], state: "minecraft:gravel"},
        {pos: [3, 3, 12], state: "minecraft:gravel"},
        {pos: [3, 3, 13], state: "minecraft:gravel"},
        {pos: [3, 3, 14], state: "minecraft:gravel"},
        {pos: [3, 3, 15], state: "minecraft:gravel"},
        {pos: [3, 3, 16], state: "minecraft:gravel"},
        {pos: [4, 3, 11], state: "minecraft:gravel"},
        {pos: [4, 3, 12], state: "minecraft:gravel"},
        {pos: [4, 3, 13], state: "minecraft:gravel"},
        {pos: [4, 3, 14], state: "minecraft:gravel"},
        {pos: [4, 3, 15], state: "minecraft:gravel"},
        {pos: [4, 3, 16], state: "minecraft:gravel"},
        {pos: [4, 3, 17], state: "minecraft:gravel"},
        {pos: [5, 3, 10], state: "minecraft:gravel"},
        {pos: [5, 3, 11], state: "minecraft:gravel"},
        {pos: [5, 3, 12], state: "minecraft:gravel"},
        {pos: [5, 3, 13], state: "minecraft:gravel"},
        {pos: [5, 3, 14], state: "minecraft:gravel"},
        {pos: [5, 3, 15], state: "minecraft:gravel"},
        {pos: [5, 3, 16], state: "minecraft:stone_bricks"},
        {pos: [5, 3, 17], state: "minecraft:gravel"},
        {pos: [6, 3, 10], state: "minecraft:gravel"},
        {pos: [6, 3, 11], state: "minecraft:stone_bricks"},
        {pos: [6, 3, 12], state: "minecraft:gravel"},
        {pos: [6, 3, 13], state: "minecraft:gravel"},
        {pos: [6, 3, 14], state: "minecraft:gravel"},
        {pos: [6, 3, 15], state: "minecraft:stone_bricks"},
        {pos: [6, 3, 16], state: "minecraft:stone_bricks"},
        {pos: [6, 3, 17], state: "minecraft:gravel"},
        {pos: [7, 3, 8], state: "minecraft:gravel"},
        {pos: [7, 3, 9], state: "minecraft:gravel"},
        {pos: [7, 3, 10], state: "minecraft:gravel"},
        {pos: [7, 3, 11], state: "minecraft:gravel"},
        {pos: [7, 3, 12], state: "minecraft:gravel"},
        {pos: [7, 3, 13], state: "minecraft:gravel"},
        {pos: [7, 3, 14], state: "minecraft:gravel"},
        {pos: [7, 3, 15], state: "minecraft:gravel"},
        {pos: [7, 3, 16], state: "minecraft:gravel"},
        {pos: [7, 3, 17], state: "minecraft:gravel"},
        {pos: [8, 3, 7], state: "minecraft:stone_bricks"},
        {pos: [8, 3, 8], state: "minecraft:gravel"},
        {pos: [8, 3, 9], state: "minecraft:gravel"},
        {pos: [8, 3, 10], state: "minecraft:gravel"},
        {pos: [8, 3, 11], state: "minecraft:gravel"},
        {pos: [8, 3, 12], state: "minecraft:gravel"},
        {pos: [8, 3, 13], state: "minecraft:gravel"},
        {pos: [8, 3, 14], state: "minecraft:gravel"},
        {pos: [8, 3, 15], state: "minecraft:gravel"},
        {pos: [9, 3, 6], state: "minecraft:gravel"},
        {pos: [9, 3, 7], state: "minecraft:gravel"},
        {pos: [9, 3, 8], state: "minecraft:gravel"},
        {pos: [9, 3, 9], state: "minecraft:gravel"},
        {pos: [9, 3, 13], state: "minecraft:gravel"},
        {pos: [9, 3, 14], state: "minecraft:gravel"},
        {pos: [9, 3, 15], state: "minecraft:gravel"},
        {pos: [10, 3, 1], state: "minecraft:gravel"},
        {pos: [10, 3, 2], state: "minecraft:gravel"},
        {pos: [10, 3, 5], state: "minecraft:gravel"},
        {pos: [10, 3, 6], state: "minecraft:gravel"},
        {pos: [10, 3, 7], state: "minecraft:gravel"},
        {pos: [10, 3, 8], state: "minecraft:gravel"},
        {pos: [10, 3, 9], state: "minecraft:gravel"},
        {pos: [10, 3, 14], state: "minecraft:gravel"},
        {pos: [10, 3, 15], state: "minecraft:stone_bricks"},
        {pos: [11, 3, 0], state: "minecraft:gravel"},
        {pos: [11, 3, 1], state: "minecraft:gravel"},
        {pos: [11, 3, 2], state: "minecraft:gravel"},
        {pos: [11, 3, 3], state: "minecraft:gravel"},
        {pos: [11, 3, 14], state: "minecraft:gravel"},
        {pos: [11, 3, 15], state: "minecraft:stone_bricks"},
        {pos: [12, 3, 0], state: "minecraft:gravel"},
        {pos: [12, 3, 1], state: "minecraft:gravel"},
        {pos: [12, 3, 2], state: "minecraft:stone_bricks"},
        {pos: [12, 3, 3], state: "minecraft:gravel"},
        {pos: [12, 3, 4], state: "minecraft:gravel"},
        {pos: [12, 3, 9], state: "minecraft:stone_bricks"},
        {pos: [12, 3, 10], state: "minecraft:stone_bricks"},
        {pos: [12, 3, 11], state: "minecraft:gravel"},
        {pos: [12, 3, 14], state: "minecraft:gravel"},
        {pos: [12, 3, 15], state: "minecraft:gravel"},
        {pos: [12, 3, 16], state: "minecraft:gravel"},
        {pos: [13, 3, 0], state: "minecraft:gravel"},
        {pos: [13, 3, 1], state: "minecraft:gravel"},
        {pos: [13, 3, 2], state: "minecraft:gravel"},
        {pos: [13, 3, 3], state: "minecraft:gravel"},
        {pos: [13, 3, 4], state: "minecraft:gravel"},
        {pos: [13, 3, 11], state: "minecraft:gravel"},
        {pos: [13, 3, 15], state: "minecraft:gravel"},
        {pos: [13, 3, 16], state: "minecraft:gravel"},
        {pos: [14, 3, 1], state: "minecraft:gravel"},
        {pos: [14, 3, 2], state: "minecraft:gravel"},
        {pos: [14, 3, 3], state: "minecraft:gravel"},
        {pos: [14, 3, 4], state: "minecraft:gravel"},
        {pos: [14, 3, 6], state: "minecraft:gravel"},
        {pos: [14, 3, 7], state: "minecraft:gravel"},
        {pos: [14, 3, 8], state: "minecraft:gravel"},
        {pos: [14, 3, 9], state: "minecraft:gravel"},
        {pos: [14, 3, 13], state: "minecraft:gravel"},
        {pos: [14, 3, 15], state: "minecraft:chiseled_stone_bricks"},
        {pos: [14, 3, 16], state: "minecraft:gravel"},
        {pos: [15, 3, 2], state: "minecraft:gravel"},
        {pos: [15, 3, 3], state: "minecraft:gravel"},
        {pos: [15, 3, 7], state: "minecraft:gravel"},
        {pos: [15, 3, 8], state: "minecraft:gravel"},
        {pos: [15, 3, 9], state: "minecraft:gravel"},
        {pos: [15, 3, 10], state: "minecraft:gravel"},
        {pos: [15, 3, 12], state: "minecraft:gravel"},
        {pos: [15, 3, 13], state: "minecraft:gravel"},
        {pos: [15, 3, 15], state: "minecraft:stone_bricks"},
        {pos: [15, 3, 16], state: "minecraft:gravel"},
        {pos: [15, 3, 17], state: "minecraft:gravel"},
        {pos: [16, 3, 7], state: "minecraft:gravel"},
        {pos: [16, 3, 8], state: "minecraft:gravel"},
        {pos: [16, 3, 9], state: "minecraft:gravel"},
        {pos: [16, 3, 10], state: "minecraft:gravel"},
        {pos: [16, 3, 11], state: "minecraft:gravel"},
        {pos: [16, 3, 12], state: "minecraft:gravel"},
        {pos: [16, 3, 13], state: "minecraft:gravel"},
        {pos: [16, 3, 14], state: "minecraft:gravel"},
        {pos: [16, 3, 15], state: "minecraft:gravel"},
        {pos: [16, 3, 16], state: "minecraft:gravel"},
        {pos: [16, 3, 17], state: "minecraft:gravel"},
        {pos: [17, 3, 9], state: "minecraft:gravel"},
        {pos: [17, 3, 10], state: "minecraft:gravel"},
        {pos: [17, 3, 11], state: "minecraft:gravel"},
        {pos: [17, 3, 12], state: "minecraft:gravel"},
        {pos: [17, 3, 13], state: "minecraft:gravel"},
        {pos: [17, 3, 14], state: "minecraft:gravel"},
        {pos: [17, 3, 15], state: "minecraft:gravel"},
        {pos: [17, 3, 16], state: "minecraft:gravel"},
        {pos: [17, 3, 17], state: "minecraft:gravel"},
        {pos: [18, 3, 10], state: "minecraft:gravel"},
        {pos: [18, 3, 11], state: "minecraft:gravel"},
        {pos: [18, 3, 12], state: "minecraft:gravel"},
        {pos: [18, 3, 13], state: "minecraft:gravel"},
        {pos: [18, 3, 14], state: "minecraft:gravel"},
        {pos: [18, 3, 15], state: "minecraft:gravel"},
        {pos: [18, 3, 16], state: "minecraft:gravel"},
        {pos: [19, 3, 11], state: "minecraft:stone_bricks"},
        {pos: [19, 3, 12], state: "minecraft:stone_bricks"},
        {pos: [19, 3, 13], state: "minecraft:stone_bricks"},
        {pos: [19, 3, 14], state: "minecraft:stone_bricks"},
        {pos: [19, 3, 15], state: "minecraft:gravel"},
        {pos: [20, 3, 10], state: "minecraft:gravel"},
        {pos: [20, 3, 11], state: "minecraft:stone_bricks"},
        {pos: [20, 3, 12], state: "minecraft:gravel"},
        {pos: [20, 3, 13], state: "minecraft:gravel"},
        {pos: [20, 3, 14], state: "minecraft:gravel"},
        {pos: [20, 3, 15], state: "minecraft:chiseled_stone_bricks"},
        {pos: [21, 3, 9], state: "minecraft:gravel"},
        {pos: [21, 3, 10], state: "minecraft:gravel"},
        {pos: [21, 3, 11], state: "minecraft:stone_bricks"},
        {pos: [21, 3, 12], state: "minecraft:gravel"},
        {pos: [21, 3, 13], state: "minecraft:gravel"},
        {pos: [21, 3, 14], state: "minecraft:gravel"},
        {pos: [21, 3, 15], state: "minecraft:stone_bricks"},
        {pos: [21, 3, 16], state: "minecraft:gravel"},
        {pos: [22, 3, 9], state: "minecraft:gravel"},
        {pos: [22, 3, 10], state: "minecraft:gravel"},
        {pos: [22, 3, 11], state: "minecraft:stone_bricks"},
        {pos: [22, 3, 12], state: "minecraft:gravel"},
        {pos: [22, 3, 13], state: "minecraft:gravel"},
        {pos: [22, 3, 14], state: "minecraft:stone_bricks"},
        {pos: [22, 3, 15], state: "minecraft:stone_bricks"},
        {pos: [22, 3, 16], state: "minecraft:polished_andesite"},
        {pos: [22, 3, 17], state: "minecraft:gravel"},
        {pos: [23, 3, 10], state: "minecraft:gravel"},
        {pos: [23, 3, 11], state: "minecraft:gravel"},
        {pos: [23, 3, 14], state: "minecraft:gravel"},
        {pos: [23, 3, 15], state: "minecraft:gravel"},
        {pos: [23, 3, 16], state: "minecraft:gravel"},
        {pos: [23, 3, 17], state: "minecraft:gravel"},
        {pos: [24, 3, 16], state: "minecraft:gravel"},
        {pos: [1, 4, 11], state: "minecraft:gravel"},
        {pos: [1, 4, 12], state: "minecraft:gravel"},
        {pos: [2, 4, 10], state: "minecraft:gravel"},
        {pos: [2, 4, 11], state: "minecraft:stone_bricks"},
        {pos: [2, 4, 12], state: "minecraft:stone_bricks"},
        {pos: [2, 4, 13], state: "minecraft:gravel"},
        {pos: [2, 4, 15], state: "minecraft:gravel"},
        {pos: [3, 4, 10], state: "minecraft:gravel"},
        {pos: [3, 4, 11], state: "minecraft:gravel"},
        {pos: [3, 4, 12], state: "minecraft:gravel"},
        {pos: [3, 4, 13], state: "minecraft:gravel"},
        {pos: [3, 4, 14], state: "minecraft:gravel"},
        {pos: [3, 4, 15], state: "minecraft:gravel"},
        {pos: [3, 4, 16], state: "minecraft:gravel"},
        {pos: [4, 4, 11], state: "minecraft:gravel"},
        {pos: [4, 4, 12], state: "minecraft:gravel"},
        {pos: [4, 4, 13], state: "minecraft:gravel"},
        {pos: [4, 4, 14], state: "minecraft:gravel"},
        {pos: [4, 4, 15], state: "minecraft:gravel"},
        {pos: [4, 4, 16], state: "minecraft:gravel"},
        {pos: [5, 4, 11], state: "minecraft:gravel"},
        {pos: [5, 4, 12], state: "minecraft:gravel"},
        {pos: [5, 4, 13], state: "minecraft:gravel"},
        {pos: [5, 4, 14], state: "minecraft:gravel"},
        {pos: [5, 4, 15], state: "minecraft:gravel"},
        {pos: [5, 4, 16], state: "minecraft:stone_bricks"},
        {pos: [5, 4, 17], state: "minecraft:gravel"},
        {pos: [6, 4, 10], state: "minecraft:gravel"},
        {pos: [6, 4, 11], state: "minecraft:gravel"},
        {pos: [6, 4, 12], state: "minecraft:gravel"},
        {pos: [6, 4, 13], state: "minecraft:gravel"},
        {pos: [6, 4, 14], state: "minecraft:gravel"},
        {pos: [6, 4, 15], state: "minecraft:stone_bricks"},
        {pos: [6, 4, 16], state: "minecraft:stone_bricks"},
        {pos: [6, 4, 17], state: "minecraft:gravel"},
        {pos: [7, 4, 8], state: "minecraft:gravel"},
        {pos: [7, 4, 9], state: "minecraft:gravel"},
        {pos: [7, 4, 10], state: "minecraft:gravel"},
        {pos: [7, 4, 11], state: "minecraft:gravel"},
        {pos: [7, 4, 14], state: "minecraft:gravel"},
        {pos: [7, 4, 15], state: "minecraft:gravel"},
        {pos: [7, 4, 16], state: "minecraft:gravel"},
        {pos: [8, 4, 7], state: "minecraft:stone_bricks"},
        {pos: [8, 4, 8], state: "minecraft:polished_andesite"},
        {pos: [8, 4, 9], state: "minecraft:gravel"},
        {pos: [9, 4, 6], state: "minecraft:gravel"},
        {pos: [9, 4, 7], state: "minecraft:stone_bricks"},
        {pos: [9, 4, 9], state: "minecraft:gravel"},
        {pos: [9, 4, 15], state: "minecraft:gravel"},
        {pos: [10, 4, 7], state: "minecraft:gravel"},
        {pos: [10, 4, 8], state: "minecraft:gravel"},
        {pos: [10, 4, 14], state: "minecraft:gravel"},
        {pos: [10, 4, 15], state: "minecraft:stone_bricks"},
        {pos: [11, 4, 1], state: "minecraft:gravel"},
        {pos: [11, 4, 2], state: "minecraft:gravel"},
        {pos: [11, 4, 3], state: "minecraft:gravel"},
        {pos: [11, 4, 14], state: "minecraft:gravel"},
        {pos: [11, 4, 15], state: "minecraft:stone_bricks"},
        {pos: [12, 4, 0], state: "minecraft:gravel"},
        {pos: [12, 4, 1], state: "minecraft:gravel"},
        {pos: [12, 4, 2], state: "minecraft:gravel"},
        {pos: [12, 4, 3], state: "minecraft:gravel"},
        {pos: [12, 4, 9], state: "minecraft:gravel"},
        {pos: [12, 4, 10], state: "minecraft:gravel"},
        {pos: [12, 4, 11], state: "minecraft:gravel"},
        {pos: [12, 4, 14], state: "minecraft:gravel"},
        {pos: [12, 4, 15], state: "minecraft:gravel"},
        {pos: [13, 4, 2], state: "minecraft:gravel"},
        {pos: [13, 4, 3], state: "minecraft:gravel"},
        {pos: [13, 4, 11], state: "minecraft:gravel"},
        {pos: [14, 4, 15], state: "minecraft:gravel"},
        {pos: [15, 4, 8], state: "minecraft:gravel"},
        {pos: [15, 4, 9], state: "minecraft:gravel"},
        {pos: [15, 4, 10], state: "minecraft:gravel"},
        {pos: [15, 4, 15], state: "minecraft:gravel"},
        {pos: [15, 4, 16], state: "minecraft:gravel"},
        {pos: [16, 4, 9], state: "minecraft:gravel"},
        {pos: [16, 4, 10], state: "minecraft:gravel"},
        {pos: [16, 4, 11], state: "minecraft:gravel"},
        {pos: [16, 4, 12], state: "minecraft:gravel"},
        {pos: [16, 4, 13], state: "minecraft:gravel"},
        {pos: [16, 4, 14], state: "minecraft:gravel"},
        {pos: [16, 4, 15], state: "minecraft:gravel"},
        {pos: [16, 4, 16], state: "minecraft:gravel"},
        {pos: [17, 4, 10], state: "minecraft:gravel"},
        {pos: [17, 4, 11], state: "minecraft:gravel"},
        {pos: [17, 4, 12], state: "minecraft:gravel"},
        {pos: [17, 4, 13], state: "minecraft:gravel"},
        {pos: [17, 4, 14], state: "minecraft:gravel"},
        {pos: [17, 4, 15], state: "minecraft:gravel"},
        {pos: [18, 4, 10], state: "minecraft:gravel"},
        {pos: [18, 4, 11], state: "minecraft:gravel"},
        {pos: [18, 4, 12], state: "minecraft:gravel"},
        {pos: [18, 4, 13], state: "minecraft:gravel"},
        {pos: [18, 4, 14], state: "minecraft:gravel"},
        {pos: [18, 4, 15], state: "minecraft:gravel"},
        {pos: [19, 4, 11], state: "minecraft:stone_bricks"},
        {pos: [19, 4, 12], state: "minecraft:stone_bricks"},
        {pos: [19, 4, 13], state: "minecraft:stone_bricks"},
        {pos: [19, 4, 14], state: "minecraft:gravel"},
        {pos: [19, 4, 15], state: "minecraft:gravel"},
        {pos: [20, 4, 10], state: "minecraft:gravel"},
        {pos: [20, 4, 11], state: "minecraft:stone_bricks"},
        {pos: [20, 4, 12], state: "minecraft:gravel"},
        {pos: [20, 4, 13], state: "minecraft:gravel"},
        {pos: [20, 4, 14], state: "minecraft:gravel"},
        {pos: [20, 4, 15], state: "minecraft:gravel"},
        {pos: [21, 4, 9], state: "minecraft:gravel"},
        {pos: [21, 4, 10], state: "minecraft:gravel"},
        {pos: [21, 4, 11], state: "minecraft:polished_andesite"},
        {pos: [21, 4, 12], state: "minecraft:gravel"},
        {pos: [21, 4, 13], state: "minecraft:gravel"},
        {pos: [21, 4, 14], state: "minecraft:gravel"},
        {pos: [21, 4, 15], state: "minecraft:stone_bricks"},
        {pos: [22, 4, 10], state: "minecraft:gravel"},
        {pos: [22, 4, 11], state: "minecraft:stone_bricks"},
        {pos: [22, 4, 12], state: "minecraft:stone_bricks"},
        {pos: [22, 4, 13], state: "minecraft:gravel"},
        {pos: [22, 4, 14], state: "minecraft:stone_bricks"},
        {pos: [22, 4, 15], state: "minecraft:stone_bricks"},
        {pos: [22, 4, 16], state: "minecraft:gravel"},
        {pos: [22, 4, 17], state: "minecraft:gravel"},
        {pos: [23, 4, 10], state: "minecraft:gravel"},
        {pos: [23, 4, 11], state: "minecraft:gravel"},
        {pos: [23, 4, 14], state: "minecraft:gravel"},
        {pos: [23, 4, 15], state: "minecraft:gravel"},
        {pos: [23, 4, 16], state: "minecraft:gravel"},
        {pos: [1, 5, 11], state: "minecraft:gravel"},
        {pos: [1, 5, 12], state: "minecraft:gravel"},
        {pos: [2, 5, 10], state: "minecraft:gravel"},
        {pos: [2, 5, 11], state: "minecraft:stone_bricks"},
        {pos: [2, 5, 12], state: "minecraft:stone_bricks"},
        {pos: [2, 5, 13], state: "minecraft:stone_bricks"},
        {pos: [3, 5, 10], state: "minecraft:gravel"},
        {pos: [3, 5, 11], state: "minecraft:stone_bricks"},
        {pos: [3, 5, 12], state: "minecraft:gravel"},
        {pos: [3, 5, 13], state: "minecraft:gravel"},
        {pos: [4, 5, 11], state: "minecraft:gravel"},
        {pos: [4, 5, 12], state: "minecraft:gravel"},
        {pos: [4, 5, 16], state: "minecraft:gravel"},
        {pos: [5, 5, 11], state: "minecraft:gravel"},
        {pos: [5, 5, 12], state: "minecraft:gravel"},
        {pos: [5, 5, 14], state: "minecraft:gravel"},
        {pos: [5, 5, 15], state: "minecraft:gravel"},
        {pos: [5, 5, 16], state: "minecraft:stone_bricks"},
        {pos: [5, 5, 17], state: "minecraft:gravel"},
        {pos: [6, 5, 11], state: "minecraft:gravel"},
        {pos: [6, 5, 14], state: "minecraft:gravel"},
        {pos: [6, 5, 15], state: "minecraft:gravel"},
        {pos: [6, 5, 16], state: "minecraft:stone_bricks"},
        {pos: [6, 5, 17], state: "minecraft:gravel"},
        {pos: [7, 5, 8], state: "minecraft:gravel"},
        {pos: [7, 5, 9], state: "minecraft:gravel"},
        {pos: [7, 5, 15], state: "minecraft:gravel"},
        {pos: [7, 5, 16], state: "minecraft:gravel"},
        {pos: [8, 5, 7], state: "minecraft:stone_bricks"},
        {pos: [8, 5, 8], state: "minecraft:stone_bricks"},
        {pos: [8, 5, 9], state: "minecraft:gravel"},
        {pos: [9, 5, 6], state: "minecraft:gravel"},
        {pos: [9, 5, 7], state: "minecraft:gravel"},
        {pos: [9, 5, 8], state: "minecraft:polished_andesite"},
        {pos: [9, 5, 9], state: "minecraft:gravel"},
        {pos: [10, 5, 7], state: "minecraft:gravel"},
        {pos: [10, 5, 8], state: "minecraft:gravel"},
        {pos: [10, 5, 14], state: "minecraft:gravel"},
        {pos: [10, 5, 15], state: "minecraft:gravel"},
        {pos: [11, 5, 14], state: "minecraft:gravel"},
        {pos: [11, 5, 15], state: "minecraft:polished_andesite"},
        {pos: [12, 5, 2], state: "minecraft:gravel"},
        {pos: [12, 5, 3], state: "minecraft:gravel"},
        {pos: [12, 5, 10], state: "minecraft:gravel"},
        {pos: [12, 5, 11], state: "minecraft:gravel"},
        {pos: [12, 5, 15], state: "minecraft:gravel"},
        {pos: [15, 5, 15], state: "minecraft:gravel"},
        {pos: [16, 5, 14], state: "minecraft:gravel"},
        {pos: [16, 5, 15], state: "minecraft:gravel"},
        {pos: [17, 5, 12], state: "minecraft:gravel"},
        {pos: [17, 5, 13], state: "minecraft:gravel"},
        {pos: [17, 5, 14], state: "minecraft:gravel"},
        {pos: [17, 5, 15], state: "minecraft:gravel"},
        {pos: [18, 5, 11], state: "minecraft:gravel"},
        {pos: [18, 5, 12], state: "minecraft:gravel"},
        {pos: [18, 5, 13], state: "minecraft:gravel"},
        {pos: [18, 5, 14], state: "minecraft:gravel"},
        {pos: [18, 5, 15], state: "minecraft:gravel"},
        {pos: [19, 5, 11], state: "minecraft:stone_bricks"},
        {pos: [19, 5, 12], state: "minecraft:stone_bricks"},
        {pos: [19, 5, 13], state: "minecraft:gravel"},
        {pos: [19, 5, 14], state: "minecraft:gravel"},
        {pos: [19, 5, 15], state: "minecraft:gravel"},
        {pos: [20, 5, 10], state: "minecraft:gravel"},
        {pos: [20, 5, 11], state: "minecraft:stone_bricks"},
        {pos: [20, 5, 12], state: "minecraft:gravel"},
        {pos: [20, 5, 13], state: "minecraft:gravel"},
        {pos: [20, 5, 14], state: "minecraft:gravel"},
        {pos: [20, 5, 15], state: "minecraft:gravel"},
        {pos: [21, 5, 9], state: "minecraft:gravel"},
        {pos: [21, 5, 10], state: "minecraft:gravel"},
        {pos: [21, 5, 11], state: "minecraft:stone_bricks"},
        {pos: [21, 5, 12], state: "minecraft:gravel"},
        {pos: [21, 5, 13], state: "minecraft:gravel"},
        {pos: [21, 5, 14], state: "minecraft:gravel"},
        {pos: [21, 5, 15], state: "minecraft:stone_bricks"},
        {pos: [22, 5, 10], state: "minecraft:gravel"},
        {pos: [22, 5, 11], state: "minecraft:chiseled_stone_bricks"},
        {pos: [22, 5, 12], state: "minecraft:stone_bricks"},
        {pos: [22, 5, 13], state: "minecraft:stone_bricks"},
        {pos: [22, 5, 14], state: "minecraft:gravel"},
        {pos: [22, 5, 15], state: "minecraft:stone_bricks"},
        {pos: [23, 5, 10], state: "minecraft:gravel"},
        {pos: [23, 5, 11], state: "minecraft:gravel"},
        {pos: [1, 6, 11], state: "minecraft:gravel"},
        {pos: [1, 6, 12], state: "minecraft:gravel"},
        {pos: [2, 6, 10], state: "minecraft:gravel"},
        {pos: [2, 6, 11], state: "minecraft:stone_bricks"},
        {pos: [2, 6, 12], state: "minecraft:stone_bricks"},
        {pos: [2, 6, 13], state: "minecraft:gravel"},
        {pos: [3, 6, 11], state: "minecraft:gravel"},
        {pos: [3, 6, 12], state: "minecraft:gravel"},
        {pos: [5, 6, 16], state: "minecraft:gravel"},
        {pos: [6, 6, 15], state: "minecraft:gravel"},
        {pos: [6, 6, 16], state: "minecraft:stone_bricks"},
        {pos: [6, 6, 17], state: "minecraft:gravel"},
        {pos: [7, 6, 8], state: "minecraft:gravel"},
        {pos: [7, 6, 15], state: "minecraft:gravel"},
        {pos: [7, 6, 16], state: "minecraft:gravel"},
        {pos: [8, 6, 7], state: "minecraft:gravel"},
        {pos: [8, 6, 8], state: "minecraft:gravel"},
        {pos: [8, 6, 9], state: "minecraft:gravel"},
        {pos: [9, 6, 7], state: "minecraft:gravel"},
        {pos: [9, 6, 8], state: "minecraft:gravel"},
        {pos: [9, 6, 9], state: "minecraft:gravel"},
        {pos: [10, 6, 7], state: "minecraft:gravel"},
        {pos: [11, 6, 15], state: "minecraft:gravel"},
        {pos: [18, 6, 11], state: "minecraft:gravel"},
        {pos: [18, 6, 12], state: "minecraft:gravel"},
        {pos: [19, 6, 11], state: "minecraft:stone_bricks"},
        {pos: [19, 6, 12], state: "minecraft:polished_andesite"},
        {pos: [19, 6, 13], state: "minecraft:gravel"},
        {pos: [19, 6, 14], state: "minecraft:gravel"},
        {pos: [20, 6, 10], state: "minecraft:gravel"},
        {pos: [20, 6, 11], state: "minecraft:stone_bricks"},
        {pos: [20, 6, 12], state: "minecraft:gravel"},
        {pos: [20, 6, 13], state: "minecraft:gravel"},
        {pos: [20, 6, 14], state: "minecraft:gravel"},
        {pos: [20, 6, 15], state: "minecraft:gravel"},
        {pos: [21, 6, 10], state: "minecraft:gravel"},
        {pos: [21, 6, 11], state: "minecraft:stone_bricks"},
        {pos: [21, 6, 12], state: "minecraft:gravel"},
        {pos: [21, 6, 13], state: "minecraft:gravel"},
        {pos: [21, 6, 14], state: "minecraft:gravel"},
        {pos: [21, 6, 15], state: "minecraft:stone_bricks"},
        {pos: [22, 6, 10], state: "minecraft:gravel"},
        {pos: [22, 6, 11], state: "minecraft:stone_bricks"},
        {pos: [22, 6, 12], state: "minecraft:stone_bricks"},
        {pos: [22, 6, 13], state: "minecraft:gravel"},
        {pos: [22, 6, 14], state: "minecraft:gravel"},
        {pos: [22, 6, 15], state: "minecraft:stone_bricks"},
        {pos: [23, 6, 11], state: "minecraft:gravel"},
        {pos: [2, 7, 11], state: "minecraft:gravel"},
        {pos: [2, 7, 12], state: "minecraft:gravel"},
        {pos: [3, 7, 11], state: "minecraft:gravel"},
        {pos: [6, 7, 16], state: "minecraft:gravel"},
        {pos: [7, 7, 8], state: "minecraft:gravel"},
        {pos: [8, 7, 8], state: "minecraft:gravel"},
        {pos: [9, 7, 8], state: "minecraft:gravel"},
        {pos: [18, 7, 11], state: "minecraft:gravel"},
        {pos: [18, 7, 12], state: "minecraft:gravel"},
        {pos: [19, 7, 11], state: "minecraft:stone_bricks"},
        {pos: [19, 7, 12], state: "minecraft:stone_bricks"},
        {pos: [19, 7, 13], state: "minecraft:gravel"},
        {pos: [20, 7, 11], state: "minecraft:stone_bricks"},
        {pos: [20, 7, 12], state: "minecraft:gravel"},
        {pos: [20, 7, 13], state: "minecraft:gravel"},
        {pos: [20, 7, 14], state: "minecraft:gravel"},
        {pos: [20, 7, 15], state: "minecraft:gravel"},
        {pos: [21, 7, 11], state: "minecraft:stone_bricks"},
        {pos: [21, 7, 12], state: "minecraft:gravel"},
        {pos: [21, 7, 13], state: "minecraft:gravel"},
        {pos: [21, 7, 14], state: "minecraft:gravel"},
        {pos: [21, 7, 15], state: "minecraft:stone_bricks"},
        {pos: [22, 7, 11], state: "minecraft:gravel"},
        {pos: [22, 7, 12], state: "minecraft:gravel"},
        {pos: [22, 7, 13], state: "minecraft:gravel"},
        {pos: [22, 7, 14], state: "minecraft:gravel"},
        {pos: [22, 7, 15], state: "minecraft:stone_bricks"},
        {pos: [19, 8, 11], state: "minecraft:stone_bricks"},
        {pos: [19, 8, 12], state: "minecraft:stone_bricks"},
        {pos: [20, 8, 11], state: "minecraft:stone_bricks"},
        {pos: [21, 8, 14], state: "minecraft:gravel"},
        {pos: [21, 8, 15], state: "minecraft:stone_bricks"},
        {pos: [22, 8, 13], state: "minecraft:gravel"},
        {pos: [22, 8, 14], state: "minecraft:gravel"},
        {pos: [22, 8, 15], state: "minecraft:stone_bricks"},
        {pos: [19, 9, 11], state: "minecraft:stone_bricks"},
        {pos: [21, 9, 15], state: "minecraft:polished_andesite"},
        {pos: [22, 9, 15], state: "minecraft:stone_bricks"}
    ],
    entities: [],
    palette: [
        "minecraft:stone_bricks",
        "minecraft:polished_andesite",
        "minecraft:gravel",
        "minecraft:chiseled_stone_bricks",
        "minecraft:cauldron"
    ],
    trailiertales_DataVersion: 2
}
