{
    DataVersion: 3953,
    size: [15, 8, 21],
    data: [
        {pos: [0, 0, 8], state: "minecraft:stone_bricks"},
        {pos: [0, 0, 9], state: "minecraft:stone_bricks"},
        {pos: [1, 0, 6], state: "minecraft:stone_bricks"},
        {pos: [1, 0, 7], state: "minecraft:stone_bricks"},
        {pos: [1, 0, 8], state: "minecraft:stone_bricks"},
        {pos: [1, 0, 9], state: "minecraft:stone_bricks"},
        {pos: [1, 0, 10], state: "minecraft:stone_bricks"},
        {pos: [1, 0, 15], state: "minecraft:stone_bricks"},
        {pos: [1, 0, 16], state: "minecraft:stone_bricks"},
        {pos: [2, 0, 5], state: "minecraft:stone_bricks"},
        {pos: [2, 0, 6], state: "minecraft:stone_bricks"},
        {pos: [2, 0, 7], state: "minecraft:stone_bricks"},
        {pos: [2, 0, 8], state: "minecraft:stone_bricks"},
        {pos: [2, 0, 9], state: "minecraft:stone_bricks"},
        {pos: [2, 0, 10], state: "minecraft:stone_bricks"},
        {pos: [2, 0, 11], state: "minecraft:stone_bricks"},
        {pos: [2, 0, 15], state: "minecraft:polished_andesite"},
        {pos: [2, 0, 16], state: "minecraft:stone_bricks"},
        {pos: [2, 0, 17], state: "minecraft:stone_bricks"},
        {pos: [2, 0, 18], state: "minecraft:stone_bricks"},
        {pos: [3, 0, 4], state: "minecraft:stone_bricks"},
        {pos: [3, 0, 5], state: "minecraft:stone_bricks"},
        {pos: [3, 0, 6], state: "minecraft:stone_bricks"},
        {pos: [3, 0, 7], state: "minecraft:stone_bricks"},
        {pos: [3, 0, 8], state: "minecraft:stone_bricks"},
        {pos: [3, 0, 9], state: "minecraft:stone_bricks"},
        {pos: [3, 0, 10], state: "minecraft:stone_bricks"},
        {pos: [3, 0, 11], state: "minecraft:stone_bricks"},
        {pos: [3, 0, 13], state: "minecraft:stone_bricks"},
        {pos: [3, 0, 14], state: "minecraft:stone_bricks"},
        {pos: [3, 0, 15], state: "minecraft:stone_bricks"},
        {pos: [3, 0, 16], state: "minecraft:stone_bricks"},
        {pos: [3, 0, 17], state: "minecraft:stone_bricks"},
        {pos: [3, 0, 18], state: "minecraft:stone_bricks"},
        {pos: [3, 0, 19], state: "minecraft:stone_bricks"},
        {pos: [4, 0, 4], state: "minecraft:stone_bricks"},
        {pos: [4, 0, 5], state: "minecraft:stone_bricks"},
        {pos: [4, 0, 6], state: "minecraft:stone_bricks"},
        {pos: [4, 0, 7], state: "minecraft:polished_andesite"},
        {pos: [4, 0, 8], state: "minecraft:stone_bricks"},
        {pos: [4, 0, 9], state: "minecraft:stone_bricks"},
        {pos: [4, 0, 10], state: "minecraft:chiseled_stone_bricks"},
        {pos: [4, 0, 11], state: "minecraft:stone_bricks"},
        {pos: [4, 0, 13], state: "minecraft:stone_bricks"},
        {pos: [4, 0, 14], state: "minecraft:stone_bricks"},
        {pos: [4, 0, 15], state: "minecraft:stone_bricks"},
        {pos: [4, 0, 16], state: "minecraft:stone_bricks"},
        {pos: [4, 0, 17], state: "minecraft:stone_bricks"},
        {pos: [4, 0, 18], state: "minecraft:stone_bricks"},
        {pos: [4, 0, 19], state: "minecraft:stone_bricks"},
        {pos: [4, 0, 20], state: "minecraft:stone_bricks"},
        {pos: [5, 0, 5], state: "minecraft:stone_bricks"},
        {pos: [5, 0, 6], state: "minecraft:stone_bricks"},
        {pos: [5, 0, 7], state: "minecraft:stone_bricks"},
        {pos: [5, 0, 8], state: "minecraft:stone_bricks"},
        {pos: [5, 0, 9], state: "minecraft:stone_bricks"},
        {pos: [5, 0, 10], state: "minecraft:stone_bricks"},
        {pos: [5, 0, 11], state: "minecraft:polished_andesite"},
        {pos: [5, 0, 12], state: "minecraft:polished_andesite"},
        {pos: [5, 0, 13], state: "minecraft:stone_bricks"},
        {pos: [5, 0, 14], state: "minecraft:stone_bricks"},
        {pos: [5, 0, 15], state: "minecraft:stone_bricks"},
        {pos: [5, 0, 16], state: "minecraft:stone_bricks"},
        {pos: [5, 0, 17], state: "minecraft:stone_bricks"},
        {pos: [5, 0, 18], state: "minecraft:stone_bricks"},
        {pos: [5, 0, 19], state: "minecraft:stone_bricks"},
        {pos: [5, 0, 20], state: "minecraft:polished_andesite"},
        {pos: [6, 0, 8], state: "minecraft:stone_bricks"},
        {pos: [6, 0, 9], state: "minecraft:stone_bricks"},
        {pos: [6, 0, 10], state: "minecraft:stone_bricks"},
        {pos: [6, 0, 11], state: "minecraft:stone_bricks"},
        {pos: [6, 0, 12], state: "minecraft:stone_bricks"},
        {pos: [6, 0, 13], state: "minecraft:stone_bricks"},
        {pos: [6, 0, 14], state: "minecraft:stone_bricks"},
        {pos: [6, 0, 15], state: "minecraft:polished_andesite"},
        {pos: [6, 0, 16], state: "minecraft:stone_bricks"},
        {pos: [6, 0, 17], state: "minecraft:stone_bricks"},
        {pos: [6, 0, 18], state: "minecraft:stone_bricks"},
        {pos: [6, 0, 19], state: "minecraft:stone_bricks"},
        {pos: [6, 0, 20], state: "minecraft:stone_bricks"},
        {pos: [7, 0, 7], state: "minecraft:stone_bricks"},
        {pos: [7, 0, 8], state: "minecraft:stone_bricks"},
        {pos: [7, 0, 10], state: "minecraft:polished_andesite"},
        {pos: [7, 0, 11], state: "minecraft:stone_bricks"},
        {pos: [7, 0, 12], state: "minecraft:stone_bricks"},
        {pos: [7, 0, 13], state: "minecraft:stone_bricks"},
        {pos: [7, 0, 14], state: "minecraft:stone_bricks"},
        {pos: [7, 0, 15], state: "minecraft:stone_bricks"},
        {pos: [7, 0, 16], state: "minecraft:stone_bricks"},
        {pos: [7, 0, 17], state: "minecraft:stone_bricks"},
        {pos: [7, 0, 18], state: "minecraft:stone_bricks"},
        {pos: [7, 0, 19], state: "minecraft:stone_bricks"},
        {pos: [7, 0, 20], state: "minecraft:stone_bricks"},
        {pos: [8, 0, 5], state: "minecraft:stone_bricks"},
        {pos: [8, 0, 6], state: "minecraft:stone_bricks"},
        {pos: [8, 0, 7], state: "minecraft:stone_bricks"},
        {pos: [8, 0, 8], state: "minecraft:stone_bricks"},
        {pos: [8, 0, 9], state: "minecraft:stone_bricks"},
        {pos: [8, 0, 10], state: "minecraft:stone_bricks"},
        {pos: [8, 0, 12], state: "minecraft:stone_bricks"},
        {pos: [8, 0, 13], state: "minecraft:stone_bricks"},
        {pos: [8, 0, 14], state: "minecraft:gravel"},
        {pos: [8, 0, 15], state: "minecraft:stone_bricks"},
        {pos: [8, 0, 16], state: "minecraft:stone_bricks"},
        {pos: [8, 0, 17], state: "minecraft:stone_bricks"},
        {pos: [8, 0, 18], state: "minecraft:stone_bricks"},
        {pos: [8, 0, 19], state: "minecraft:stone_bricks"},
        {pos: [8, 0, 20], state: "minecraft:polished_andesite"},
        {pos: [9, 0, 2], state: "minecraft:stone_bricks"},
        {pos: [9, 0, 3], state: "minecraft:stone_bricks"},
        {pos: [9, 0, 5], state: "minecraft:stone_bricks"},
        {pos: [9, 0, 6], state: "minecraft:stone_bricks"},
        {pos: [9, 0, 8], state: "minecraft:stone_bricks"},
        {pos: [9, 0, 9], state: "minecraft:stone_bricks"},
        {pos: [9, 0, 10], state: "minecraft:stone_bricks"},
        {pos: [9, 0, 13], state: "minecraft:stone_bricks"},
        {pos: [9, 0, 14], state: "minecraft:stone_bricks"},
        {pos: [9, 0, 15], state: "minecraft:stone_bricks"},
        {pos: [9, 0, 16], state: "minecraft:stone_bricks"},
        {pos: [9, 0, 17], state: "minecraft:stone_bricks"},
        {pos: [9, 0, 18], state: "minecraft:stone_bricks"},
        {pos: [9, 0, 19], state: "minecraft:stone_bricks"},
        {pos: [10, 0, 1], state: "minecraft:stone_bricks"},
        {pos: [10, 0, 2], state: "minecraft:stone_bricks"},
        {pos: [10, 0, 3], state: "minecraft:stone_bricks"},
        {pos: [10, 0, 4], state: "minecraft:stone_bricks"},
        {pos: [10, 0, 5], state: "minecraft:stone_bricks"},
        {pos: [10, 0, 6], state: "minecraft:stone_bricks"},
        {pos: [10, 0, 7], state: "minecraft:stone_bricks"},
        {pos: [10, 0, 8], state: "minecraft:stone_bricks"},
        {pos: [10, 0, 9], state: "minecraft:stone_bricks"},
        {pos: [10, 0, 10], state: "minecraft:stone_bricks"},
        {pos: [10, 0, 11], state: "minecraft:stone_bricks"},
        {pos: [10, 0, 12], state: "minecraft:stone_bricks"},
        {pos: [10, 0, 13], state: "minecraft:stone_bricks"},
        {pos: [10, 0, 14], state: "minecraft:stone_bricks"},
        {pos: [10, 0, 15], state: "minecraft:polished_andesite"},
        {pos: [10, 0, 16], state: "minecraft:stone_bricks"},
        {pos: [10, 0, 17], state: "minecraft:stone_bricks"},
        {pos: [10, 0, 18], state: "minecraft:stone_bricks"},
        {pos: [11, 0, 0], state: "minecraft:stone_bricks"},
        {pos: [11, 0, 1], state: "minecraft:stone_bricks"},
        {pos: [11, 0, 2], state: "minecraft:stone_bricks"},
        {pos: [11, 0, 3], state: "minecraft:stone_bricks"},
        {pos: [11, 0, 4], state: "minecraft:stone_bricks"},
        {pos: [11, 0, 5], state: "minecraft:stone_bricks"},
        {pos: [11, 0, 6], state: "minecraft:stone_bricks"},
        {pos: [11, 0, 7], state: "minecraft:stone_bricks"},
        {pos: [11, 0, 8], state: "minecraft:stone_bricks"},
        {pos: [11, 0, 9], state: "minecraft:stone_bricks"},
        {pos: [11, 0, 10], state: "minecraft:stone_bricks"},
        {pos: [11, 0, 11], state: "minecraft:stone_bricks"},
        {pos: [11, 0, 12], state: "minecraft:stone_bricks"},
        {pos: [11, 0, 13], state: "minecraft:stone_bricks"},
        {pos: [11, 0, 15], state: "minecraft:stone_bricks"},
        {pos: [11, 0, 16], state: "minecraft:stone_bricks"},
        {pos: [12, 0, 1], state: "minecraft:stone_bricks"},
        {pos: [12, 0, 2], state: "minecraft:chiseled_stone_bricks"},
        {pos: [12, 0, 3], state: "minecraft:stone_bricks"},
        {pos: [12, 0, 4], state: "minecraft:stone_bricks"},
        {pos: [12, 0, 5], state: "minecraft:stone_bricks"},
        {pos: [12, 0, 6], state: "minecraft:stone_bricks"},
        {pos: [12, 0, 7], state: "minecraft:gravel"},
        {pos: [12, 0, 8], state: "minecraft:stone_bricks"},
        {pos: [12, 0, 10], state: "minecraft:stone_bricks"},
        {pos: [12, 0, 11], state: "minecraft:stone_bricks"},
        {pos: [12, 0, 12], state: "minecraft:stone_bricks"},
        {pos: [13, 0, 3], state: "minecraft:stone_bricks"},
        {pos: [13, 0, 4], state: "minecraft:stone_bricks"},
        {pos: [13, 0, 5], state: "minecraft:stone_bricks"},
        {pos: [13, 0, 6], state: "minecraft:stone_bricks"},
        {pos: [13, 0, 7], state: "minecraft:stone_bricks"},
        {pos: [13, 0, 10], state: "minecraft:stone_bricks"},
        {pos: [13, 0, 11], state: "minecraft:stone_bricks"},
        {pos: [14, 0, 4], state: "minecraft:stone_bricks"},
        {pos: [14, 0, 6], state: "minecraft:stone_bricks"},
        {pos: [0, 1, 8], state: "minecraft:gravel"},
        {pos: [0, 1, 9], state: "minecraft:gravel"},
        {pos: [1, 1, 6], state: "minecraft:gravel"},
        {pos: [1, 1, 7], state: "minecraft:gravel"},
        {pos: [1, 1, 8], state: "minecraft:gravel"},
        {pos: [1, 1, 9], state: "minecraft:gravel"},
        {pos: [1, 1, 10], state: "minecraft:gravel"},
        {pos: [1, 1, 15], state: "minecraft:gravel"},
        {pos: [1, 1, 16], state: "minecraft:gravel"},
        {pos: [2, 1, 5], state: "minecraft:gravel"},
        {pos: [2, 1, 6], state: "minecraft:gravel"},
        {pos: [2, 1, 7], state: "minecraft:stone_bricks"},
        {pos: [2, 1, 8], state: "minecraft:gravel"},
        {pos: [2, 1, 9], state: "minecraft:chiseled_stone_bricks"},
        {pos: [2, 1, 10], state: "minecraft:stone_bricks"},
        {pos: [2, 1, 11], state: "minecraft:gravel"},
        {pos: [2, 1, 15], state: "minecraft:gravel"},
        {pos: [2, 1, 16], state: "minecraft:stone_bricks"},
        {pos: [2, 1, 17], state: "minecraft:gravel"},
        {pos: [2, 1, 18], state: "minecraft:gravel"},
        {pos: [3, 1, 4], state: "minecraft:gravel"},
        {pos: [3, 1, 5], state: "minecraft:gravel"},
        {pos: [3, 1, 6], state: "minecraft:stone_bricks"},
        {pos: [3, 1, 7], state: "minecraft:stone_bricks"},
        {pos: [3, 1, 8], state: "minecraft:gravel"},
        {pos: [3, 1, 9], state: "minecraft:stone_bricks"},
        {pos: [3, 1, 10], state: "minecraft:stone_bricks"},
        {pos: [3, 1, 11], state: "minecraft:gravel"},
        {pos: [3, 1, 13], state: "minecraft:gravel"},
        {pos: [3, 1, 14], state: "minecraft:gravel"},
        {pos: [3, 1, 15], state: "minecraft:stone_bricks"},
        {pos: [3, 1, 16], state: "minecraft:stone_bricks"},
        {pos: [3, 1, 17], state: "minecraft:stone_bricks"},
        {pos: [3, 1, 18], state: "minecraft:stone_bricks"},
        {pos: [3, 1, 19], state: "minecraft:gravel"},
        {pos: [4, 1, 4], state: "minecraft:gravel"},
        {pos: [4, 1, 5], state: "minecraft:gravel"},
        {pos: [4, 1, 6], state: "minecraft:gravel"},
        {pos: [4, 1, 7], state: "minecraft:gravel"},
        {pos: [4, 1, 8], state: "minecraft:gravel"},
        {pos: [4, 1, 9], state: "minecraft:gravel"},
        {pos: [4, 1, 10], state: "minecraft:gravel"},
        {pos: [4, 1, 11], state: "minecraft:gravel"},
        {pos: [4, 1, 13], state: "minecraft:gravel"},
        {pos: [4, 1, 14], state: "minecraft:stone_bricks"},
        {pos: [4, 1, 15], state: "minecraft:gravel"},
        {pos: [4, 1, 16], state: "minecraft:cobblestone_stairs{facing:west,half:top,shape:straight,waterlogged:false}"},
        {pos: [4, 1, 17], state: "minecraft:cobblestone_stairs{facing:west,half:top,shape:straight,waterlogged:false}"},
        {pos: [4, 1, 18], state: "minecraft:chiseled_stone_bricks"},
        {pos: [4, 1, 19], state: "minecraft:gravel"},
        {pos: [4, 1, 20], state: "minecraft:gravel"},
        {pos: [5, 1, 5], state: "minecraft:gravel"},
        {pos: [5, 1, 6], state: "minecraft:gravel"},
        {pos: [5, 1, 7], state: "minecraft:gravel"},
        {pos: [5, 1, 8], state: "minecraft:gravel"},
        {pos: [5, 1, 9], state: "minecraft:gravel"},
        {pos: [5, 1, 10], state: "minecraft:gravel"},
        {pos: [5, 1, 11], state: "minecraft:gravel"},
        {pos: [5, 1, 12], state: "minecraft:gravel"},
        {pos: [5, 1, 13], state: "minecraft:stone_bricks"},
        {pos: [5, 1, 14], state: "minecraft:gravel"},
        {pos: [5, 1, 15], state: "minecraft:gravel"},
        {pos: [5, 1, 16], state: "minecraft:gravel"},
        {pos: [5, 1, 17], state: "minecraft:gravel"},
        {pos: [5, 1, 18], state: "minecraft:gravel"},
        {pos: [5, 1, 19], state: "minecraft:stone_bricks"},
        {pos: [5, 1, 20], state: "minecraft:gravel"},
        {pos: [6, 1, 8], state: "minecraft:gravel"},
        {pos: [6, 1, 9], state: "minecraft:gravel"},
        {pos: [6, 1, 10], state: "minecraft:gravel"},
        {pos: [6, 1, 11], state: "minecraft:gravel"},
        {pos: [6, 1, 12], state: "minecraft:gravel"},
        {pos: [6, 1, 13], state: "minecraft:gravel"},
        {pos: [6, 1, 14], state: "minecraft:gravel"},
        {pos: [6, 1, 15], state: "minecraft:gravel"},
        {pos: [6, 1, 16], state: "minecraft:gravel"},
        {pos: [6, 1, 17], state: "minecraft:gravel"},
        {pos: [6, 1, 18], state: "minecraft:gravel"},
        {pos: [6, 1, 19], state: "minecraft:stone_bricks"},
        {pos: [6, 1, 20], state: "minecraft:stone_bricks"},
        {pos: [7, 1, 7], state: "minecraft:gravel"},
        {pos: [7, 1, 8], state: "minecraft:gravel"},
        {pos: [7, 1, 10], state: "minecraft:gravel"},
        {pos: [7, 1, 11], state: "minecraft:gravel"},
        {pos: [7, 1, 12], state: "minecraft:gravel"},
        {pos: [7, 1, 13], state: "minecraft:gravel"},
        {pos: [7, 1, 14], state: "minecraft:gravel"},
        {pos: [7, 1, 15], state: "minecraft:gravel"},
        {pos: [7, 1, 16], state: "minecraft:gravel"},
        {pos: [7, 1, 17], state: "minecraft:gravel"},
        {pos: [7, 1, 18], state: "minecraft:gravel"},
        {pos: [7, 1, 19], state: "minecraft:stone_bricks"},
        {pos: [7, 1, 20], state: "minecraft:gravel"},
        {pos: [8, 1, 5], state: "minecraft:gravel"},
        {pos: [8, 1, 6], state: "minecraft:gravel"},
        {pos: [8, 1, 7], state: "minecraft:gravel"},
        {pos: [8, 1, 8], state: "minecraft:gravel"},
        {pos: [8, 1, 9], state: "minecraft:gravel"},
        {pos: [8, 1, 10], state: "minecraft:gravel"},
        {pos: [8, 1, 12], state: "minecraft:gravel"},
        {pos: [8, 1, 13], state: "minecraft:stone_bricks"},
        {pos: [8, 1, 14], state: "minecraft:gravel"},
        {pos: [8, 1, 15], state: "minecraft:gravel"},
        {pos: [8, 1, 16], state: "minecraft:gravel"},
        {pos: [8, 1, 17], state: "minecraft:gravel"},
        {pos: [8, 1, 18], state: "minecraft:stone_bricks"},
        {pos: [8, 1, 19], state: "minecraft:gravel"},
        {pos: [8, 1, 20], state: "minecraft:gravel"},
        {pos: [9, 1, 2], state: "minecraft:gravel"},
        {pos: [9, 1, 3], state: "minecraft:gravel"},
        {pos: [9, 1, 5], state: "minecraft:gravel"},
        {pos: [9, 1, 6], state: "minecraft:gravel"},
        {pos: [9, 1, 8], state: "minecraft:gravel"},
        {pos: [9, 1, 9], state: "minecraft:gravel"},
        {pos: [9, 1, 10], state: "minecraft:gravel"},
        {pos: [9, 1, 13], state: "minecraft:gravel"},
        {pos: [9, 1, 14], state: "minecraft:stone_bricks"},
        {pos: [9, 1, 15], state: "minecraft:stone_bricks"},
        {pos: [9, 1, 16], state: "minecraft:stone_bricks"},
        {pos: [9, 1, 17], state: "minecraft:stone_bricks"},
        {pos: [9, 1, 18], state: "minecraft:gravel"},
        {pos: [9, 1, 19], state: "minecraft:gravel"},
        {pos: [10, 1, 1], state: "minecraft:gravel"},
        {pos: [10, 1, 2], state: "minecraft:gravel"},
        {pos: [10, 1, 3], state: "minecraft:gravel"},
        {pos: [10, 1, 4], state: "minecraft:gravel"},
        {pos: [10, 1, 5], state: "minecraft:gravel"},
        {pos: [10, 1, 6], state: "minecraft:gravel"},
        {pos: [10, 1, 7], state: "minecraft:gravel"},
        {pos: [10, 1, 8], state: "minecraft:gravel"},
        {pos: [10, 1, 9], state: "minecraft:gravel"},
        {pos: [10, 1, 10], state: "minecraft:gravel"},
        {pos: [10, 1, 11], state: "minecraft:gravel"},
        {pos: [10, 1, 12], state: "minecraft:gravel"},
        {pos: [10, 1, 13], state: "minecraft:gravel"},
        {pos: [10, 1, 14], state: "minecraft:gravel"},
        {pos: [10, 1, 15], state: "minecraft:gravel"},
        {pos: [10, 1, 16], state: "minecraft:gravel"},
        {pos: [10, 1, 17], state: "minecraft:gravel"},
        {pos: [10, 1, 18], state: "minecraft:gravel"},
        {pos: [11, 1, 0], state: "minecraft:gravel"},
        {pos: [11, 1, 1], state: "minecraft:gravel"},
        {pos: [11, 1, 2], state: "minecraft:stone_bricks"},
        {pos: [11, 1, 3], state: "minecraft:stone_bricks"},
        {pos: [11, 1, 4], state: "minecraft:gravel"},
        {pos: [11, 1, 5], state: "minecraft:gravel"},
        {pos: [11, 1, 6], state: "minecraft:stone_bricks"},
        {pos: [11, 1, 7], state: "minecraft:stone_bricks"},
        {pos: [11, 1, 8], state: "minecraft:gravel"},
        {pos: [11, 1, 9], state: "minecraft:gravel"},
        {pos: [11, 1, 10], state: "minecraft:stone_bricks"},
        {pos: [11, 1, 11], state: "minecraft:stone_bricks"},
        {pos: [11, 1, 12], state: "minecraft:gravel"},
        {pos: [11, 1, 13], state: "minecraft:gravel"},
        {pos: [11, 1, 15], state: "minecraft:gravel"},
        {pos: [11, 1, 16], state: "minecraft:gravel"},
        {pos: [12, 1, 1], state: "minecraft:gravel"},
        {pos: [12, 1, 2], state: "minecraft:stone_bricks"},
        {pos: [12, 1, 3], state: "minecraft:stone_bricks"},
        {pos: [12, 1, 4], state: "minecraft:gravel"},
        {pos: [12, 1, 5], state: "minecraft:gravel"},
        {pos: [12, 1, 6], state: "minecraft:stone_bricks"},
        {pos: [12, 1, 7], state: "minecraft:gravel"},
        {pos: [12, 1, 8], state: "minecraft:gravel"},
        {pos: [12, 1, 10], state: "minecraft:stone_bricks"},
        {pos: [12, 1, 11], state: "minecraft:stone_bricks"},
        {pos: [12, 1, 12], state: "minecraft:gravel"},
        {pos: [13, 1, 3], state: "minecraft:gravel"},
        {pos: [13, 1, 4], state: "minecraft:gravel"},
        {pos: [13, 1, 5], state: "minecraft:gravel"},
        {pos: [13, 1, 6], state: "minecraft:gravel"},
        {pos: [13, 1, 7], state: "minecraft:gravel"},
        {pos: [13, 1, 10], state: "minecraft:gravel"},
        {pos: [13, 1, 11], state: "minecraft:gravel"},
        {pos: [14, 1, 4], state: "minecraft:gravel"},
        {pos: [14, 1, 6], state: "minecraft:gravel"},
        {pos: [0, 2, 8], state: "minecraft:gravel"},
        {pos: [0, 2, 9], state: "minecraft:gravel"},
        {pos: [1, 2, 6], state: "minecraft:gravel"},
        {pos: [1, 2, 7], state: "minecraft:gravel"},
        {pos: [1, 2, 8], state: "minecraft:gravel"},
        {pos: [1, 2, 9], state: "minecraft:gravel"},
        {pos: [1, 2, 10], state: "minecraft:gravel"},
        {pos: [1, 2, 15], state: "minecraft:gravel"},
        {pos: [1, 2, 16], state: "minecraft:gravel"},
        {pos: [2, 2, 5], state: "minecraft:gravel"},
        {pos: [2, 2, 6], state: "minecraft:stone_bricks"},
        {pos: [2, 2, 7], state: "minecraft:stone_bricks"},
        {pos: [2, 2, 8], state: "minecraft:gravel"},
        {pos: [2, 2, 9], state: "minecraft:stone_bricks"},
        {pos: [2, 2, 10], state: "minecraft:chiseled_stone_bricks"},
        {pos: [2, 2, 11], state: "minecraft:gravel"},
        {pos: [2, 2, 15], state: "minecraft:gravel"},
        {pos: [2, 2, 16], state: "minecraft:gravel"},
        {pos: [2, 2, 17], state: "minecraft:gravel"},
        {pos: [2, 2, 18], state: "minecraft:gravel"},
        {pos: [3, 2, 4], state: "minecraft:gravel"},
        {pos: [3, 2, 5], state: "minecraft:gravel"},
        {pos: [3, 2, 6], state: "minecraft:stone_bricks"},
        {pos: [3, 2, 7], state: "minecraft:stone_bricks"},
        {pos: [3, 2, 8], state: "minecraft:gravel"},
        {pos: [3, 2, 9], state: "minecraft:chiseled_stone_bricks"},
        {pos: [3, 2, 10], state: "minecraft:stone_bricks"},
        {pos: [3, 2, 11], state: "minecraft:gravel"},
        {pos: [3, 2, 13], state: "minecraft:gravel"},
        {pos: [3, 2, 14], state: "minecraft:gravel"},
        {pos: [3, 2, 15], state: "minecraft:stone_bricks"},
        {pos: [3, 2, 16], state: "minecraft:stone_bricks"},
        {pos: [3, 2, 17], state: "minecraft:stone_bricks"},
        {pos: [3, 2, 18], state: "minecraft:gravel"},
        {pos: [3, 2, 19], state: "minecraft:gravel"},
        {pos: [4, 2, 4], state: "minecraft:gravel"},
        {pos: [4, 2, 5], state: "minecraft:gravel"},
        {pos: [4, 2, 6], state: "minecraft:gravel"},
        {pos: [4, 2, 7], state: "minecraft:gravel"},
        {pos: [4, 2, 8], state: "minecraft:gravel"},
        {pos: [4, 2, 9], state: "minecraft:gravel"},
        {pos: [4, 2, 10], state: "minecraft:gravel"},
        {pos: [4, 2, 11], state: "minecraft:gravel"},
        {pos: [4, 2, 13], state: "minecraft:gravel"},
        {pos: [4, 2, 14], state: "minecraft:stone_bricks"},
        {pos: [4, 2, 15], state: "minecraft:gravel"},
        {pos: [4, 2, 16], state: "minecraft:gravel"},
        {pos: [4, 2, 17], state: "minecraft:gravel"},
        {pos: [4, 2, 18], state: "minecraft:stone_bricks"},
        {pos: [4, 2, 19], state: "minecraft:gravel"},
        {pos: [4, 2, 20], state: "minecraft:gravel"},
        {pos: [5, 2, 5], state: "minecraft:gravel"},
        {pos: [5, 2, 6], state: "minecraft:gravel"},
        {pos: [5, 2, 7], state: "minecraft:gravel"},
        {pos: [5, 2, 8], state: "minecraft:gravel"},
        {pos: [5, 2, 9], state: "minecraft:gravel"},
        {pos: [5, 2, 10], state: "minecraft:gravel"},
        {pos: [5, 2, 11], state: "minecraft:gravel"},
        {pos: [5, 2, 12], state: "minecraft:gravel"},
        {pos: [5, 2, 13], state: "minecraft:stone_bricks"},
        {pos: [5, 2, 14], state: "minecraft:gravel"},
        {pos: [5, 2, 15], state: "minecraft:gravel"},
        {pos: [5, 2, 16], state: "minecraft:gravel"},
        {pos: [5, 2, 17], state: "minecraft:gravel"},
        {pos: [5, 2, 18], state: "minecraft:gravel"},
        {pos: [5, 2, 19], state: "minecraft:gravel"},
        {pos: [5, 2, 20], state: "minecraft:gravel"},
        {pos: [6, 2, 8], state: "minecraft:gravel"},
        {pos: [6, 2, 9], state: "minecraft:gravel"},
        {pos: [6, 2, 10], state: "minecraft:gravel"},
        {pos: [6, 2, 11], state: "minecraft:gravel"},
        {pos: [6, 2, 12], state: "minecraft:gravel"},
        {pos: [6, 2, 13], state: "minecraft:gravel"},
        {pos: [6, 2, 14], state: "minecraft:gravel"},
        {pos: [6, 2, 15], state: "minecraft:gravel"},
        {pos: [6, 2, 16], state: "minecraft:gravel"},
        {pos: [6, 2, 17], state: "minecraft:gravel"},
        {pos: [6, 2, 18], state: "minecraft:gravel"},
        {pos: [6, 2, 19], state: "minecraft:stone_bricks"},
        {pos: [6, 2, 20], state: "minecraft:gravel"},
        {pos: [7, 2, 7], state: "minecraft:gravel"},
        {pos: [7, 2, 8], state: "minecraft:gravel"},
        {pos: [7, 2, 10], state: "minecraft:gravel"},
        {pos: [7, 2, 11], state: "minecraft:gravel"},
        {pos: [7, 2, 12], state: "minecraft:gravel"},
        {pos: [7, 2, 13], state: "minecraft:gravel"},
        {pos: [7, 2, 14], state: "minecraft:gravel"},
        {pos: [7, 2, 15], state: "minecraft:gravel"},
        {pos: [7, 2, 16], state: "minecraft:gravel"},
        {pos: [7, 2, 17], state: "minecraft:gravel"},
        {pos: [7, 2, 18], state: "minecraft:gravel"},
        {pos: [7, 2, 19], state: "minecraft:gravel"},
        {pos: [7, 2, 20], state: "minecraft:gravel"},
        {pos: [8, 2, 5], state: "minecraft:gravel"},
        {pos: [8, 2, 6], state: "minecraft:gravel"},
        {pos: [8, 2, 7], state: "minecraft:gravel"},
        {pos: [8, 2, 8], state: "minecraft:gravel"},
        {pos: [8, 2, 9], state: "minecraft:gravel"},
        {pos: [8, 2, 10], state: "minecraft:gravel"},
        {pos: [8, 2, 12], state: "minecraft:gravel"},
        {pos: [8, 2, 13], state: "minecraft:stone_bricks"},
        {pos: [8, 2, 14], state: "minecraft:gravel"},
        {pos: [8, 2, 15], state: "minecraft:gravel"},
        {pos: [8, 2, 16], state: "minecraft:gravel"},
        {pos: [8, 2, 17], state: "minecraft:stone_bricks"},
        {pos: [8, 2, 18], state: "minecraft:stone_bricks"},
        {pos: [8, 2, 19], state: "minecraft:gravel"},
        {pos: [8, 2, 20], state: "minecraft:gravel"},
        {pos: [9, 2, 2], state: "minecraft:gravel"},
        {pos: [9, 2, 3], state: "minecraft:gravel"},
        {pos: [9, 2, 5], state: "minecraft:gravel"},
        {pos: [9, 2, 6], state: "minecraft:gravel"},
        {pos: [9, 2, 8], state: "minecraft:gravel"},
        {pos: [9, 2, 9], state: "minecraft:gravel"},
        {pos: [9, 2, 10], state: "minecraft:gravel"},
        {pos: [9, 2, 13], state: "minecraft:gravel"},
        {pos: [9, 2, 14], state: "minecraft:stone_bricks"},
        {pos: [9, 2, 15], state: "minecraft:stone_bricks"},
        {pos: [9, 2, 16], state: "minecraft:stone_bricks"},
        {pos: [9, 2, 17], state: "minecraft:stone_bricks"},
        {pos: [9, 2, 18], state: "minecraft:gravel"},
        {pos: [9, 2, 19], state: "minecraft:gravel"},
        {pos: [10, 2, 1], state: "minecraft:gravel"},
        {pos: [10, 2, 2], state: "minecraft:gravel"},
        {pos: [10, 2, 3], state: "minecraft:gravel"},
        {pos: [10, 2, 4], state: "minecraft:gravel"},
        {pos: [10, 2, 5], state: "minecraft:gravel"},
        {pos: [10, 2, 6], state: "minecraft:gravel"},
        {pos: [10, 2, 7], state: "minecraft:gravel"},
        {pos: [10, 2, 8], state: "minecraft:gravel"},
        {pos: [10, 2, 9], state: "minecraft:gravel"},
        {pos: [10, 2, 10], state: "minecraft:gravel"},
        {pos: [10, 2, 11], state: "minecraft:gravel"},
        {pos: [10, 2, 12], state: "minecraft:gravel"},
        {pos: [10, 2, 13], state: "minecraft:gravel"},
        {pos: [10, 2, 14], state: "minecraft:gravel"},
        {pos: [10, 2, 15], state: "minecraft:gravel"},
        {pos: [10, 2, 16], state: "minecraft:gravel"},
        {pos: [10, 2, 17], state: "minecraft:gravel"},
        {pos: [10, 2, 18], state: "minecraft:gravel"},
        {pos: [11, 2, 0], state: "minecraft:gravel"},
        {pos: [11, 2, 1], state: "minecraft:gravel"},
        {pos: [11, 2, 2], state: "minecraft:stone_bricks"},
        {pos: [11, 2, 3], state: "minecraft:stone_bricks"},
        {pos: [11, 2, 4], state: "minecraft:gravel"},
        {pos: [11, 2, 5], state: "minecraft:gravel"},
        {pos: [11, 2, 6], state: "minecraft:stone_bricks"},
        {pos: [11, 2, 7], state: "minecraft:stone_bricks"},
        {pos: [11, 2, 8], state: "minecraft:gravel"},
        {pos: [11, 2, 9], state: "minecraft:gravel"},
        {pos: [11, 2, 10], state: "minecraft:stone_bricks"},
        {pos: [11, 2, 11], state: "minecraft:stone_bricks"},
        {pos: [11, 2, 12], state: "minecraft:gravel"},
        {pos: [11, 2, 13], state: "minecraft:gravel"},
        {pos: [11, 2, 15], state: "minecraft:gravel"},
        {pos: [11, 2, 16], state: "minecraft:gravel"},
        {pos: [12, 2, 1], state: "minecraft:gravel"},
        {pos: [12, 2, 2], state: "minecraft:stone_bricks"},
        {pos: [12, 2, 3], state: "minecraft:stone_bricks"},
        {pos: [12, 2, 4], state: "minecraft:gravel"},
        {pos: [12, 2, 5], state: "minecraft:gravel"},
        {pos: [12, 2, 6], state: "minecraft:stone_bricks"},
        {pos: [12, 2, 7], state: "minecraft:stone_bricks"},
        {pos: [12, 2, 8], state: "minecraft:gravel"},
        {pos: [12, 2, 10], state: "minecraft:stone_bricks"},
        {pos: [12, 2, 11], state: "minecraft:stone_bricks"},
        {pos: [12, 2, 12], state: "minecraft:gravel"},
        {pos: [13, 2, 3], state: "minecraft:gravel"},
        {pos: [13, 2, 4], state: "minecraft:gravel"},
        {pos: [13, 2, 5], state: "minecraft:gravel"},
        {pos: [13, 2, 6], state: "minecraft:gravel"},
        {pos: [13, 2, 7], state: "minecraft:gravel"},
        {pos: [13, 2, 10], state: "minecraft:gravel"},
        {pos: [13, 2, 11], state: "minecraft:gravel"},
        {pos: [14, 2, 4], state: "minecraft:gravel"},
        {pos: [14, 2, 6], state: "minecraft:gravel"},
        {pos: [0, 3, 8], state: "minecraft:gravel"},
        {pos: [0, 3, 9], state: "minecraft:gravel"},
        {pos: [1, 3, 6], state: "minecraft:gravel"},
        {pos: [1, 3, 7], state: "minecraft:gravel"},
        {pos: [1, 3, 8], state: "minecraft:gravel"},
        {pos: [1, 3, 9], state: "minecraft:gravel"},
        {pos: [1, 3, 10], state: "minecraft:gravel"},
        {pos: [1, 3, 15], state: "minecraft:gravel"},
        {pos: [1, 3, 16], state: "minecraft:gravel"},
        {pos: [2, 3, 5], state: "minecraft:gravel"},
        {pos: [2, 3, 6], state: "minecraft:stone_bricks"},
        {pos: [2, 3, 7], state: "minecraft:stone_bricks"},
        {pos: [2, 3, 8], state: "minecraft:gravel"},
        {pos: [2, 3, 9], state: "minecraft:stone_bricks"},
        {pos: [2, 3, 10], state: "minecraft:stone_bricks"},
        {pos: [2, 3, 11], state: "minecraft:gravel"},
        {pos: [2, 3, 15], state: "minecraft:gravel"},
        {pos: [2, 3, 16], state: "minecraft:gravel"},
        {pos: [2, 3, 17], state: "minecraft:gravel"},
        {pos: [2, 3, 18], state: "minecraft:gravel"},
        {pos: [3, 3, 4], state: "minecraft:gravel"},
        {pos: [3, 3, 5], state: "minecraft:gravel"},
        {pos: [3, 3, 6], state: "minecraft:stone_bricks"},
        {pos: [3, 3, 7], state: "minecraft:stone_bricks"},
        {pos: [3, 3, 8], state: "minecraft:gravel"},
        {pos: [3, 3, 9], state: "minecraft:stone_bricks"},
        {pos: [3, 3, 10], state: "minecraft:stone_bricks"},
        {pos: [3, 3, 11], state: "minecraft:gravel"},
        {pos: [3, 3, 13], state: "minecraft:gravel"},
        {pos: [3, 3, 14], state: "minecraft:gravel"},
        {pos: [3, 3, 15], state: "minecraft:stone_bricks"},
        {pos: [3, 3, 16], state: "minecraft:gravel"},
        {pos: [3, 3, 17], state: "minecraft:stone_bricks"},
        {pos: [3, 3, 18], state: "minecraft:gravel"},
        {pos: [3, 3, 19], state: "minecraft:gravel"},
        {pos: [4, 3, 4], state: "minecraft:gravel"},
        {pos: [4, 3, 5], state: "minecraft:gravel"},
        {pos: [4, 3, 6], state: "minecraft:gravel"},
        {pos: [4, 3, 7], state: "minecraft:gravel"},
        {pos: [4, 3, 8], state: "minecraft:gravel"},
        {pos: [4, 3, 9], state: "minecraft:gravel"},
        {pos: [4, 3, 10], state: "minecraft:gravel"},
        {pos: [4, 3, 11], state: "minecraft:gravel"},
        {pos: [4, 3, 13], state: "minecraft:gravel"},
        {pos: [4, 3, 14], state: "minecraft:stone_bricks"},
        {pos: [4, 3, 15], state: "minecraft:gravel"},
        {pos: [4, 3, 16], state: "minecraft:gravel"},
        {pos: [4, 3, 17], state: "minecraft:gravel"},
        {pos: [4, 3, 18], state: "minecraft:stone_bricks"},
        {pos: [4, 3, 19], state: "minecraft:gravel"},
        {pos: [4, 3, 20], state: "minecraft:gravel"},
        {pos: [5, 3, 5], state: "minecraft:gravel"},
        {pos: [5, 3, 6], state: "minecraft:gravel"},
        {pos: [5, 3, 7], state: "minecraft:gravel"},
        {pos: [5, 3, 8], state: "minecraft:gravel"},
        {pos: [5, 3, 9], state: "minecraft:gravel"},
        {pos: [5, 3, 10], state: "minecraft:gravel"},
        {pos: [5, 3, 11], state: "minecraft:gravel"},
        {pos: [5, 3, 12], state: "minecraft:gravel"},
        {pos: [5, 3, 13], state: "minecraft:gravel"},
        {pos: [5, 3, 14], state: "minecraft:gravel"},
        {pos: [5, 3, 15], state: "minecraft:gravel"},
        {pos: [5, 3, 16], state: "minecraft:gravel"},
        {pos: [5, 3, 17], state: "minecraft:gravel"},
        {pos: [5, 3, 18], state: "minecraft:gravel"},
        {pos: [5, 3, 19], state: "minecraft:gravel"},
        {pos: [5, 3, 20], state: "minecraft:gravel"},
        {pos: [6, 3, 8], state: "minecraft:gravel"},
        {pos: [6, 3, 9], state: "minecraft:gravel"},
        {pos: [6, 3, 10], state: "minecraft:gravel"},
        {pos: [6, 3, 11], state: "minecraft:gravel"},
        {pos: [6, 3, 12], state: "minecraft:gravel"},
        {pos: [6, 3, 13], state: "minecraft:gravel"},
        {pos: [6, 3, 14], state: "minecraft:gravel"},
        {pos: [6, 3, 15], state: "minecraft:gravel"},
        {pos: [6, 3, 16], state: "minecraft:gravel"},
        {pos: [6, 3, 17], state: "minecraft:gravel"},
        {pos: [6, 3, 18], state: "minecraft:stone_bricks"},
        {pos: [6, 3, 19], state: "minecraft:stone_bricks"},
        {pos: [6, 3, 20], state: "minecraft:gravel"},
        {pos: [7, 3, 7], state: "minecraft:gravel"},
        {pos: [7, 3, 8], state: "minecraft:gravel"},
        {pos: [7, 3, 10], state: "minecraft:gravel"},
        {pos: [7, 3, 11], state: "minecraft:gravel"},
        {pos: [7, 3, 12], state: "minecraft:gravel"},
        {pos: [7, 3, 13], state: "minecraft:stone_bricks"},
        {pos: [7, 3, 14], state: "minecraft:gravel"},
        {pos: [7, 3, 15], state: "minecraft:gravel"},
        {pos: [7, 3, 16], state: "minecraft:gravel"},
        {pos: [7, 3, 17], state: "minecraft:stone_bricks"},
        {pos: [7, 3, 18], state: "minecraft:stone_bricks"},
        {pos: [7, 3, 19], state: "minecraft:stone_bricks"},
        {pos: [7, 3, 20], state: "minecraft:gravel"},
        {pos: [8, 3, 5], state: "minecraft:gravel"},
        {pos: [8, 3, 6], state: "minecraft:gravel"},
        {pos: [8, 3, 7], state: "minecraft:gravel"},
        {pos: [8, 3, 8], state: "minecraft:gravel"},
        {pos: [8, 3, 9], state: "minecraft:gravel"},
        {pos: [8, 3, 10], state: "minecraft:gravel"},
        {pos: [8, 3, 12], state: "minecraft:gravel"},
        {pos: [8, 3, 13], state: "minecraft:stone_bricks"},
        {pos: [8, 3, 14], state: "minecraft:gravel"},
        {pos: [8, 3, 15], state: "minecraft:gravel"},
        {pos: [8, 3, 16], state: "minecraft:gravel"},
        {pos: [8, 3, 17], state: "minecraft:gravel"},
        {pos: [8, 3, 18], state: "minecraft:stone_bricks"},
        {pos: [8, 3, 19], state: "minecraft:gravel"},
        {pos: [8, 3, 20], state: "minecraft:gravel"},
        {pos: [9, 3, 2], state: "minecraft:gravel"},
        {pos: [9, 3, 3], state: "minecraft:gravel"},
        {pos: [9, 3, 5], state: "minecraft:gravel"},
        {pos: [9, 3, 6], state: "minecraft:gravel"},
        {pos: [9, 3, 8], state: "minecraft:gravel"},
        {pos: [9, 3, 9], state: "minecraft:gravel"},
        {pos: [9, 3, 10], state: "minecraft:gravel"},
        {pos: [9, 3, 13], state: "minecraft:gravel"},
        {pos: [9, 3, 14], state: "minecraft:stone_bricks"},
        {pos: [9, 3, 15], state: "minecraft:stone_bricks"},
        {pos: [9, 3, 16], state: "minecraft:gravel"},
        {pos: [9, 3, 17], state: "minecraft:stone_bricks"},
        {pos: [9, 3, 18], state: "minecraft:gravel"},
        {pos: [9, 3, 19], state: "minecraft:gravel"},
        {pos: [10, 3, 1], state: "minecraft:gravel"},
        {pos: [10, 3, 2], state: "minecraft:gravel"},
        {pos: [10, 3, 3], state: "minecraft:gravel"},
        {pos: [10, 3, 4], state: "minecraft:gravel"},
        {pos: [10, 3, 5], state: "minecraft:gravel"},
        {pos: [10, 3, 6], state: "minecraft:gravel"},
        {pos: [10, 3, 7], state: "minecraft:gravel"},
        {pos: [10, 3, 8], state: "minecraft:gravel"},
        {pos: [10, 3, 9], state: "minecraft:gravel"},
        {pos: [10, 3, 10], state: "minecraft:gravel"},
        {pos: [10, 3, 11], state: "minecraft:gravel"},
        {pos: [10, 3, 12], state: "minecraft:gravel"},
        {pos: [10, 3, 13], state: "minecraft:gravel"},
        {pos: [10, 3, 14], state: "minecraft:gravel"},
        {pos: [10, 3, 15], state: "minecraft:gravel"},
        {pos: [10, 3, 16], state: "minecraft:gravel"},
        {pos: [10, 3, 17], state: "minecraft:gravel"},
        {pos: [10, 3, 18], state: "minecraft:gravel"},
        {pos: [11, 3, 0], state: "minecraft:gravel"},
        {pos: [11, 3, 1], state: "minecraft:gravel"},
        {pos: [11, 3, 2], state: "minecraft:stone_bricks"},
        {pos: [11, 3, 3], state: "minecraft:polished_andesite"},
        {pos: [11, 3, 4], state: "minecraft:gravel"},
        {pos: [11, 3, 5], state: "minecraft:gravel"},
        {pos: [11, 3, 6], state: "minecraft:stone_bricks"},
        {pos: [11, 3, 7], state: "minecraft:stone_bricks"},
        {pos: [11, 3, 8], state: "minecraft:gravel"},
        {pos: [11, 3, 9], state: "minecraft:gravel"},
        {pos: [11, 3, 10], state: "minecraft:stone_bricks"},
        {pos: [11, 3, 11], state: "minecraft:polished_andesite"},
        {pos: [11, 3, 12], state: "minecraft:gravel"},
        {pos: [11, 3, 13], state: "minecraft:gravel"},
        {pos: [11, 3, 15], state: "minecraft:gravel"},
        {pos: [11, 3, 16], state: "minecraft:gravel"},
        {pos: [12, 3, 1], state: "minecraft:gravel"},
        {pos: [12, 3, 2], state: "minecraft:stone_bricks"},
        {pos: [12, 3, 3], state: "minecraft:polished_andesite"},
        {pos: [12, 3, 4], state: "minecraft:gravel"},
        {pos: [12, 3, 5], state: "minecraft:gravel"},
        {pos: [12, 3, 6], state: "minecraft:stone_bricks"},
        {pos: [12, 3, 7], state: "minecraft:stone_bricks"},
        {pos: [12, 3, 8], state: "minecraft:gravel"},
        {pos: [12, 3, 10], state: "minecraft:stone_bricks"},
        {pos: [12, 3, 11], state: "minecraft:stone_bricks"},
        {pos: [12, 3, 12], state: "minecraft:gravel"},
        {pos: [13, 3, 3], state: "minecraft:gravel"},
        {pos: [13, 3, 4], state: "minecraft:gravel"},
        {pos: [13, 3, 5], state: "minecraft:gravel"},
        {pos: [13, 3, 6], state: "minecraft:gravel"},
        {pos: [13, 3, 7], state: "minecraft:gravel"},
        {pos: [13, 3, 10], state: "minecraft:gravel"},
        {pos: [13, 3, 11], state: "minecraft:gravel"},
        {pos: [14, 3, 4], state: "minecraft:gravel"},
        {pos: [14, 3, 6], state: "minecraft:gravel"},
        {pos: [1, 4, 6], state: "minecraft:gravel"},
        {pos: [1, 4, 7], state: "minecraft:gravel"},
        {pos: [1, 4, 8], state: "minecraft:gravel"},
        {pos: [1, 4, 9], state: "minecraft:gravel"},
        {pos: [1, 4, 10], state: "minecraft:gravel"},
        {pos: [2, 4, 5], state: "minecraft:gravel"},
        {pos: [2, 4, 6], state: "minecraft:stone_bricks"},
        {pos: [2, 4, 7], state: "minecraft:polished_andesite"},
        {pos: [2, 4, 8], state: "minecraft:gravel"},
        {pos: [2, 4, 9], state: "minecraft:stone_bricks"},
        {pos: [2, 4, 10], state: "minecraft:stone_bricks"},
        {pos: [2, 4, 11], state: "minecraft:gravel"},
        {pos: [2, 4, 15], state: "minecraft:gravel"},
        {pos: [2, 4, 16], state: "minecraft:gravel"},
        {pos: [2, 4, 17], state: "minecraft:gravel"},
        {pos: [3, 4, 5], state: "minecraft:gravel"},
        {pos: [3, 4, 6], state: "minecraft:stone_bricks"},
        {pos: [3, 4, 7], state: "minecraft:stone_bricks"},
        {pos: [3, 4, 8], state: "minecraft:gravel"},
        {pos: [3, 4, 9], state: "minecraft:stone_bricks"},
        {pos: [3, 4, 10], state: "minecraft:stone_bricks"},
        {pos: [3, 4, 11], state: "minecraft:gravel"},
        {pos: [3, 4, 14], state: "minecraft:gravel"},
        {pos: [3, 4, 15], state: "minecraft:chiseled_stone_bricks"},
        {pos: [3, 4, 16], state: "minecraft:stone_bricks"},
        {pos: [3, 4, 17], state: "minecraft:gravel"},
        {pos: [3, 4, 18], state: "minecraft:gravel"},
        {pos: [4, 4, 6], state: "minecraft:gravel"},
        {pos: [4, 4, 7], state: "minecraft:gravel"},
        {pos: [4, 4, 8], state: "minecraft:gravel"},
        {pos: [4, 4, 9], state: "minecraft:gravel"},
        {pos: [4, 4, 10], state: "minecraft:gravel"},
        {pos: [4, 4, 13], state: "minecraft:gravel"},
        {pos: [4, 4, 14], state: "minecraft:stone_bricks"},
        {pos: [4, 4, 15], state: "minecraft:gravel"},
        {pos: [4, 4, 16], state: "minecraft:gravel"},
        {pos: [4, 4, 17], state: "minecraft:gravel"},
        {pos: [4, 4, 18], state: "minecraft:stone_bricks"},
        {pos: [4, 4, 19], state: "minecraft:gravel"},
        {pos: [5, 4, 10], state: "minecraft:gravel"},
        {pos: [5, 4, 11], state: "minecraft:gravel"},
        {pos: [5, 4, 12], state: "minecraft:gravel"},
        {pos: [5, 4, 13], state: "minecraft:stone_bricks"},
        {pos: [5, 4, 14], state: "minecraft:gravel"},
        {pos: [5, 4, 15], state: "minecraft:gravel"},
        {pos: [5, 4, 16], state: "minecraft:gravel"},
        {pos: [5, 4, 17], state: "minecraft:gravel"},
        {pos: [5, 4, 18], state: "minecraft:gravel"},
        {pos: [5, 4, 19], state: "minecraft:stone_bricks"},
        {pos: [5, 4, 20], state: "minecraft:gravel"},
        {pos: [6, 4, 11], state: "minecraft:gravel"},
        {pos: [6, 4, 12], state: "minecraft:gravel"},
        {pos: [6, 4, 13], state: "minecraft:stone_bricks"},
        {pos: [6, 4, 14], state: "minecraft:gravel"},
        {pos: [6, 4, 15], state: "minecraft:gravel"},
        {pos: [6, 4, 16], state: "minecraft:gravel"},
        {pos: [6, 4, 17], state: "minecraft:gravel"},
        {pos: [6, 4, 18], state: "minecraft:gravel"},
        {pos: [6, 4, 19], state: "minecraft:polished_andesite"},
        {pos: [6, 4, 20], state: "minecraft:gravel"},
        {pos: [7, 4, 12], state: "minecraft:gravel"},
        {pos: [7, 4, 13], state: "minecraft:stone_bricks"},
        {pos: [7, 4, 14], state: "minecraft:gravel"},
        {pos: [7, 4, 15], state: "minecraft:gravel"},
        {pos: [7, 4, 16], state: "minecraft:gravel"},
        {pos: [7, 4, 17], state: "minecraft:gravel"},
        {pos: [7, 4, 18], state: "minecraft:gravel"},
        {pos: [7, 4, 19], state: "minecraft:stone_bricks"},
        {pos: [7, 4, 20], state: "minecraft:gravel"},
        {pos: [8, 4, 9], state: "minecraft:gravel"},
        {pos: [8, 4, 12], state: "minecraft:gravel"},
        {pos: [8, 4, 13], state: "minecraft:chiseled_stone_bricks"},
        {pos: [8, 4, 14], state: "minecraft:gravel"},
        {pos: [8, 4, 15], state: "minecraft:gravel"},
        {pos: [8, 4, 16], state: "minecraft:gravel"},
        {pos: [8, 4, 17], state: "minecraft:gravel"},
        {pos: [8, 4, 18], state: "minecraft:polished_andesite"},
        {pos: [8, 4, 19], state: "minecraft:gravel"},
        {pos: [9, 4, 8], state: "minecraft:gravel"},
        {pos: [9, 4, 9], state: "minecraft:gravel"},
        {pos: [9, 4, 10], state: "minecraft:gravel"},
        {pos: [9, 4, 13], state: "minecraft:gravel"},
        {pos: [9, 4, 14], state: "minecraft:stone_bricks"},
        {pos: [9, 4, 15], state: "minecraft:stone_bricks"},
        {pos: [9, 4, 16], state: "minecraft:gravel"},
        {pos: [9, 4, 17], state: "minecraft:gravel"},
        {pos: [9, 4, 18], state: "minecraft:gravel"},
        {pos: [10, 4, 2], state: "minecraft:gravel"},
        {pos: [10, 4, 3], state: "minecraft:gravel"},
        {pos: [10, 4, 4], state: "minecraft:gravel"},
        {pos: [10, 4, 5], state: "minecraft:gravel"},
        {pos: [10, 4, 6], state: "minecraft:gravel"},
        {pos: [10, 4, 7], state: "minecraft:gravel"},
        {pos: [10, 4, 8], state: "minecraft:gravel"},
        {pos: [10, 4, 9], state: "minecraft:gravel"},
        {pos: [10, 4, 10], state: "minecraft:gravel"},
        {pos: [10, 4, 11], state: "minecraft:gravel"},
        {pos: [10, 4, 13], state: "minecraft:gravel"},
        {pos: [10, 4, 14], state: "minecraft:gravel"},
        {pos: [10, 4, 15], state: "minecraft:gravel"},
        {pos: [11, 4, 1], state: "minecraft:gravel"},
        {pos: [11, 4, 2], state: "minecraft:stone_bricks"},
        {pos: [11, 4, 3], state: "minecraft:stone_bricks"},
        {pos: [11, 4, 4], state: "minecraft:gravel"},
        {pos: [11, 4, 5], state: "minecraft:gravel"},
        {pos: [11, 4, 6], state: "minecraft:stone_bricks"},
        {pos: [11, 4, 7], state: "minecraft:stone_bricks"},
        {pos: [11, 4, 8], state: "minecraft:gravel"},
        {pos: [11, 4, 9], state: "minecraft:gravel"},
        {pos: [11, 4, 10], state: "minecraft:stone_bricks"},
        {pos: [11, 4, 11], state: "minecraft:gravel"},
        {pos: [11, 4, 12], state: "minecraft:gravel"},
        {pos: [12, 4, 1], state: "minecraft:gravel"},
        {pos: [12, 4, 2], state: "minecraft:gravel"},
        {pos: [12, 4, 3], state: "minecraft:stone_bricks"},
        {pos: [12, 4, 4], state: "minecraft:gravel"},
        {pos: [12, 4, 5], state: "minecraft:gravel"},
        {pos: [12, 4, 6], state: "minecraft:stone_bricks"},
        {pos: [12, 4, 7], state: "minecraft:stone_bricks"},
        {pos: [12, 4, 8], state: "minecraft:gravel"},
        {pos: [12, 4, 10], state: "minecraft:gravel"},
        {pos: [12, 4, 11], state: "minecraft:stone_bricks"},
        {pos: [12, 4, 12], state: "minecraft:gravel"},
        {pos: [13, 4, 3], state: "minecraft:gravel"},
        {pos: [13, 4, 4], state: "minecraft:gravel"},
        {pos: [13, 4, 5], state: "minecraft:gravel"},
        {pos: [13, 4, 6], state: "minecraft:gravel"},
        {pos: [13, 4, 7], state: "minecraft:gravel"},
        {pos: [13, 4, 10], state: "minecraft:gravel"},
        {pos: [1, 5, 6], state: "minecraft:gravel"},
        {pos: [1, 5, 7], state: "minecraft:gravel"},
        {pos: [1, 5, 8], state: "minecraft:gravel"},
        {pos: [2, 5, 5], state: "minecraft:gravel"},
        {pos: [2, 5, 6], state: "minecraft:stone_bricks"},
        {pos: [2, 5, 7], state: "minecraft:stone_bricks"},
        {pos: [2, 5, 8], state: "minecraft:gravel"},
        {pos: [2, 5, 9], state: "minecraft:gravel"},
        {pos: [2, 5, 10], state: "minecraft:stone_bricks"},
        {pos: [2, 5, 11], state: "minecraft:gravel"},
        {pos: [3, 5, 6], state: "minecraft:gravel"},
        {pos: [3, 5, 7], state: "minecraft:gravel"},
        {pos: [3, 5, 8], state: "minecraft:gravel"},
        {pos: [3, 5, 9], state: "minecraft:gravel"},
        {pos: [3, 5, 10], state: "minecraft:stone_bricks"},
        {pos: [3, 5, 15], state: "minecraft:gravel"},
        {pos: [3, 5, 16], state: "minecraft:gravel"},
        {pos: [3, 5, 17], state: "minecraft:gravel"},
        {pos: [3, 5, 18], state: "minecraft:gravel"},
        {pos: [4, 5, 7], state: "minecraft:gravel"},
        {pos: [4, 5, 8], state: "minecraft:gravel"},
        {pos: [4, 5, 14], state: "minecraft:gravel"},
        {pos: [4, 5, 15], state: "minecraft:gravel"},
        {pos: [4, 5, 16], state: "minecraft:gravel"},
        {pos: [4, 5, 17], state: "minecraft:gravel"},
        {pos: [4, 5, 18], state: "minecraft:stone_bricks"},
        {pos: [4, 5, 19], state: "minecraft:gravel"},
        {pos: [5, 5, 13], state: "minecraft:gravel"},
        {pos: [5, 5, 14], state: "minecraft:gravel"},
        {pos: [5, 5, 15], state: "minecraft:gravel"},
        {pos: [5, 5, 16], state: "minecraft:gravel"},
        {pos: [5, 5, 17], state: "minecraft:gravel"},
        {pos: [5, 5, 18], state: "minecraft:gravel"},
        {pos: [5, 5, 19], state: "minecraft:stone_bricks"},
        {pos: [5, 5, 20], state: "minecraft:gravel"},
        {pos: [6, 5, 13], state: "minecraft:gravel"},
        {pos: [6, 5, 14], state: "minecraft:gravel"},
        {pos: [6, 5, 15], state: "minecraft:gravel"},
        {pos: [6, 5, 16], state: "minecraft:gravel"},
        {pos: [6, 5, 17], state: "minecraft:gravel"},
        {pos: [6, 5, 18], state: "minecraft:gravel"},
        {pos: [6, 5, 19], state: "minecraft:gravel"},
        {pos: [6, 5, 20], state: "minecraft:gravel"},
        {pos: [7, 5, 12], state: "minecraft:gravel"},
        {pos: [7, 5, 13], state: "minecraft:stone_bricks"},
        {pos: [7, 5, 14], state: "minecraft:gravel"},
        {pos: [7, 5, 15], state: "minecraft:gravel"},
        {pos: [7, 5, 16], state: "minecraft:gravel"},
        {pos: [7, 5, 17], state: "minecraft:gravel"},
        {pos: [7, 5, 18], state: "minecraft:gravel"},
        {pos: [7, 5, 19], state: "minecraft:gravel"},
        {pos: [7, 5, 20], state: "minecraft:gravel"},
        {pos: [8, 5, 12], state: "minecraft:gravel"},
        {pos: [8, 5, 13], state: "minecraft:stone_bricks"},
        {pos: [8, 5, 14], state: "minecraft:gravel"},
        {pos: [8, 5, 15], state: "minecraft:gravel"},
        {pos: [8, 5, 17], state: "minecraft:gravel"},
        {pos: [8, 5, 18], state: "minecraft:stone_bricks"},
        {pos: [8, 5, 19], state: "minecraft:gravel"},
        {pos: [9, 5, 15], state: "minecraft:gravel"},
        {pos: [9, 5, 18], state: "minecraft:gravel"},
        {pos: [10, 5, 3], state: "minecraft:gravel"},
        {pos: [10, 5, 4], state: "minecraft:gravel"},
        {pos: [11, 5, 2], state: "minecraft:gravel"},
        {pos: [11, 5, 3], state: "minecraft:gravel"},
        {pos: [11, 5, 4], state: "minecraft:gravel"},
        {pos: [11, 5, 6], state: "minecraft:gravel"},
        {pos: [11, 5, 7], state: "minecraft:gravel"},
        {pos: [11, 5, 10], state: "minecraft:gravel"},
        {pos: [11, 5, 11], state: "minecraft:gravel"},
        {pos: [12, 5, 3], state: "minecraft:gravel"},
        {pos: [12, 5, 5], state: "minecraft:gravel"},
        {pos: [12, 5, 6], state: "minecraft:stone_bricks"},
        {pos: [12, 5, 7], state: "minecraft:stone_bricks"},
        {pos: [12, 5, 8], state: "minecraft:gravel"},
        {pos: [12, 5, 10], state: "minecraft:gravel"},
        {pos: [12, 5, 11], state: "minecraft:gravel"},
        {pos: [13, 5, 6], state: "minecraft:gravel"},
        {pos: [13, 5, 7], state: "minecraft:gravel"},
        {pos: [1, 6, 6], state: "minecraft:gravel"},
        {pos: [1, 6, 7], state: "minecraft:gravel"},
        {pos: [2, 6, 5], state: "minecraft:gravel"},
        {pos: [2, 6, 6], state: "minecraft:stone_bricks"},
        {pos: [2, 6, 7], state: "minecraft:stone_bricks"},
        {pos: [2, 6, 8], state: "minecraft:gravel"},
        {pos: [2, 6, 9], state: "minecraft:gravel"},
        {pos: [2, 6, 10], state: "minecraft:stone_bricks"},
        {pos: [3, 6, 6], state: "minecraft:gravel"},
        {pos: [3, 6, 7], state: "minecraft:polished_andesite"},
        {pos: [3, 6, 8], state: "minecraft:gravel"},
        {pos: [4, 6, 7], state: "minecraft:gravel"},
        {pos: [4, 6, 17], state: "minecraft:gravel"},
        {pos: [4, 6, 18], state: "minecraft:gravel"},
        {pos: [5, 6, 16], state: "minecraft:gravel"},
        {pos: [5, 6, 17], state: "minecraft:gravel"},
        {pos: [6, 6, 16], state: "minecraft:gravel"},
        {pos: [6, 6, 17], state: "minecraft:gravel"},
        {pos: [6, 6, 18], state: "minecraft:gravel"},
        {pos: [6, 6, 19], state: "minecraft:gravel"},
        {pos: [7, 6, 17], state: "minecraft:gravel"},
        {pos: [7, 6, 18], state: "minecraft:gravel"},
        {pos: [7, 6, 19], state: "minecraft:gravel"},
        {pos: [8, 6, 18], state: "minecraft:gravel"},
        {pos: [11, 6, 3], state: "minecraft:gravel"},
        {pos: [12, 6, 6], state: "minecraft:gravel"},
        {pos: [12, 6, 7], state: "minecraft:gravel"},
        {pos: [13, 6, 7], state: "minecraft:gravel"},
        {pos: [2, 7, 6], state: "minecraft:stone_bricks"},
        {pos: [3, 7, 7], state: "minecraft:stone_bricks"}
    ],
    entities: [],
    palette: [
        "minecraft:stone_bricks",
        "minecraft:polished_andesite",
        "minecraft:chiseled_stone_bricks",
        "minecraft:gravel",
        "minecraft:cobblestone_stairs{facing:west,half:top,shape:straight,waterlogged:false}"
    ],
    trailiertales_DataVersion: 2
}
