{
    DataVersion: 3953,
    size: [5, 10, 13],
    data: [
        {pos: [0, 0, 2], state: "minecraft:stone_bricks"},
        {pos: [0, 0, 3], state: "minecraft:stone_bricks"},
        {pos: [0, 0, 10], state: "minecraft:chiseled_stone_bricks"},
        {pos: [1, 0, 1], state: "minecraft:stone_bricks"},
        {pos: [1, 0, 2], state: "minecraft:chiseled_stone_bricks"},
        {pos: [1, 0, 3], state: "minecraft:stone_bricks"},
        {pos: [1, 0, 4], state: "minecraft:stone_bricks"},
        {pos: [1, 0, 7], state: "minecraft:stone_bricks"},
        {pos: [1, 0, 8], state: "minecraft:stone_bricks"},
        {pos: [1, 0, 9], state: "minecraft:stone_bricks"},
        {pos: [1, 0, 10], state: "minecraft:stone_bricks"},
        {pos: [1, 0, 11], state: "minecraft:stone_bricks"},
        {pos: [1, 0, 12], state: "minecraft:stone_bricks"},
        {pos: [2, 0, 1], state: "minecraft:stone_bricks"},
        {pos: [2, 0, 2], state: "minecraft:stone_bricks"},
        {pos: [2, 0, 3], state: "minecraft:stone_bricks"},
        {pos: [2, 0, 4], state: "minecraft:stone_bricks"},
        {pos: [2, 0, 7], state: "minecraft:stone_bricks"},
        {pos: [2, 0, 8], state: "minecraft:stone_bricks"},
        {pos: [2, 0, 9], state: "minecraft:polished_andesite"},
        {pos: [2, 0, 10], state: "minecraft:stone_bricks"},
        {pos: [2, 0, 11], state: "minecraft:stone_bricks"},
        {pos: [2, 0, 12], state: "minecraft:stone_bricks"},
        {pos: [3, 0, 0], state: "minecraft:stone_bricks"},
        {pos: [3, 0, 1], state: "minecraft:polished_andesite"},
        {pos: [3, 0, 2], state: "minecraft:stone_bricks"},
        {pos: [3, 0, 3], state: "minecraft:stone_bricks"},
        {pos: [3, 0, 4], state: "minecraft:stone_bricks"},
        {pos: [3, 0, 8], state: "minecraft:stone_bricks"},
        {pos: [3, 0, 9], state: "minecraft:stone_bricks"},
        {pos: [3, 0, 10], state: "minecraft:stone_bricks"},
        {pos: [3, 0, 11], state: "minecraft:stone_bricks"},
        {pos: [3, 0, 12], state: "minecraft:stone_bricks"},
        {pos: [4, 0, 1], state: "minecraft:stone_bricks"},
        {pos: [4, 0, 2], state: "minecraft:stone_bricks"},
        {pos: [4, 0, 3], state: "minecraft:stone_bricks"},
        {pos: [4, 0, 9], state: "minecraft:stone_bricks"},
        {pos: [4, 0, 10], state: "minecraft:stone_bricks"},
        {pos: [0, 1, 2], state: "minecraft:gravel"},
        {pos: [0, 1, 3], state: "minecraft:gravel"},
        {pos: [0, 1, 10], state: "minecraft:gravel"},
        {pos: [1, 1, 1], state: "minecraft:gravel"},
        {pos: [1, 1, 2], state: "minecraft:chiseled_stone_bricks"},
        {pos: [1, 1, 3], state: "minecraft:stone_bricks"},
        {pos: [1, 1, 4], state: "minecraft:gravel"},
        {pos: [1, 1, 7], state: "minecraft:gravel"},
        {pos: [1, 1, 8], state: "minecraft:stone_bricks"},
        {pos: [1, 1, 9], state: "minecraft:stone_bricks"},
        {pos: [1, 1, 10], state: "minecraft:stone_bricks"},
        {pos: [1, 1, 11], state: "minecraft:gravel"},
        {pos: [1, 1, 12], state: "minecraft:gravel"},
        {pos: [2, 1, 1], state: "minecraft:gravel"},
        {pos: [2, 1, 2], state: "minecraft:stone_bricks"},
        {pos: [2, 1, 3], state: "minecraft:gravel"},
        {pos: [2, 1, 4], state: "minecraft:gravel"},
        {pos: [2, 1, 7], state: "minecraft:gravel"},
        {pos: [2, 1, 8], state: "minecraft:gravel"},
        {pos: [2, 1, 9], state: "minecraft:gravel"},
        {pos: [2, 1, 10], state: "minecraft:stone_bricks"},
        {pos: [2, 1, 11], state: "minecraft:stone_bricks"},
        {pos: [2, 1, 12], state: "minecraft:gravel"},
        {pos: [3, 1, 0], state: "minecraft:gravel"},
        {pos: [3, 1, 1], state: "minecraft:gravel"},
        {pos: [3, 1, 2], state: "minecraft:stone_bricks"},
        {pos: [3, 1, 3], state: "minecraft:stone_bricks"},
        {pos: [3, 1, 4], state: "minecraft:stone_bricks"},
        {pos: [3, 1, 8], state: "minecraft:stone_bricks"},
        {pos: [3, 1, 9], state: "minecraft:stone_bricks"},
        {pos: [3, 1, 10], state: "minecraft:stone_bricks"},
        {pos: [3, 1, 11], state: "minecraft:gravel"},
        {pos: [3, 1, 12], state: "minecraft:gravel"},
        {pos: [4, 1, 1], state: "minecraft:gravel"},
        {pos: [4, 1, 2], state: "minecraft:gravel"},
        {pos: [4, 1, 3], state: "minecraft:gravel"},
        {pos: [4, 1, 9], state: "minecraft:gravel"},
        {pos: [4, 1, 10], state: "minecraft:gravel"},
        {pos: [0, 2, 2], state: "minecraft:gravel"},
        {pos: [0, 2, 3], state: "minecraft:gravel"},
        {pos: [0, 2, 10], state: "minecraft:gravel"},
        {pos: [1, 2, 1], state: "minecraft:gravel"},
        {pos: [1, 2, 2], state: "minecraft:stone_bricks"},
        {pos: [1, 2, 3], state: "minecraft:stone_bricks"},
        {pos: [1, 2, 4], state: "minecraft:gravel"},
        {pos: [1, 2, 7], state: "minecraft:gravel"},
        {pos: [1, 2, 8], state: "minecraft:stone_bricks"},
        {pos: [1, 2, 9], state: "minecraft:stone_bricks"},
        {pos: [1, 2, 10], state: "minecraft:stone_bricks"},
        {pos: [1, 2, 11], state: "minecraft:gravel"},
        {pos: [1, 2, 12], state: "minecraft:gravel"},
        {pos: [2, 2, 1], state: "minecraft:gravel"},
        {pos: [2, 2, 2], state: "minecraft:stone_bricks"},
        {pos: [2, 2, 3], state: "minecraft:gravel"},
        {pos: [2, 2, 4], state: "minecraft:gravel"},
        {pos: [2, 2, 7], state: "minecraft:gravel"},
        {pos: [2, 2, 8], state: "minecraft:gravel"},
        {pos: [2, 2, 9], state: "minecraft:gravel"},
        {pos: [2, 2, 10], state: "minecraft:stone_bricks"},
        {pos: [2, 2, 11], state: "minecraft:gravel"},
        {pos: [2, 2, 12], state: "minecraft:gravel"},
        {pos: [3, 2, 0], state: "minecraft:gravel"},
        {pos: [3, 2, 1], state: "minecraft:gravel"},
        {pos: [3, 2, 2], state: "minecraft:stone_bricks"},
        {pos: [3, 2, 3], state: "minecraft:gravel"},
        {pos: [3, 2, 4], state: "minecraft:stone_bricks"},
        {pos: [3, 2, 8], state: "minecraft:stone_bricks"},
        {pos: [3, 2, 9], state: "minecraft:polished_andesite"},
        {pos: [3, 2, 10], state: "minecraft:stone_bricks"},
        {pos: [3, 2, 11], state: "minecraft:gravel"},
        {pos: [3, 2, 12], state: "minecraft:gravel"},
        {pos: [4, 2, 1], state: "minecraft:gravel"},
        {pos: [4, 2, 2], state: "minecraft:gravel"},
        {pos: [4, 2, 3], state: "minecraft:gravel"},
        {pos: [4, 2, 9], state: "minecraft:gravel"},
        {pos: [4, 2, 10], state: "minecraft:gravel"},
        {pos: [0, 3, 2], state: "minecraft:gravel"},
        {pos: [0, 3, 3], state: "minecraft:gravel"},
        {pos: [0, 3, 10], state: "minecraft:gravel"},
        {pos: [1, 3, 1], state: "minecraft:gravel"},
        {pos: [1, 3, 2], state: "minecraft:stone_bricks"},
        {pos: [1, 3, 3], state: "minecraft:stone_bricks"},
        {pos: [1, 3, 4], state: "minecraft:gravel"},
        {pos: [1, 3, 7], state: "minecraft:gravel"},
        {pos: [1, 3, 8], state: "minecraft:stone_bricks"},
        {pos: [1, 3, 9], state: "minecraft:polished_andesite"},
        {pos: [1, 3, 10], state: "minecraft:stone_bricks"},
        {pos: [1, 3, 11], state: "minecraft:gravel"},
        {pos: [2, 3, 1], state: "minecraft:gravel"},
        {pos: [2, 3, 2], state: "minecraft:stone_bricks"},
        {pos: [2, 3, 3], state: "minecraft:gravel"},
        {pos: [2, 3, 4], state: "minecraft:gravel"},
        {pos: [2, 3, 7], state: "minecraft:gravel"},
        {pos: [2, 3, 8], state: "minecraft:gravel"},
        {pos: [2, 3, 9], state: "minecraft:gravel"},
        {pos: [2, 3, 10], state: "minecraft:stone_bricks"},
        {pos: [2, 3, 11], state: "minecraft:gravel"},
        {pos: [2, 3, 12], state: "minecraft:gravel"},
        {pos: [3, 3, 0], state: "minecraft:gravel"},
        {pos: [3, 3, 1], state: "minecraft:gravel"},
        {pos: [3, 3, 2], state: "minecraft:stone_bricks"},
        {pos: [3, 3, 3], state: "minecraft:stone_bricks"},
        {pos: [3, 3, 4], state: "minecraft:stone_bricks"},
        {pos: [3, 3, 8], state: "minecraft:stone_bricks"},
        {pos: [3, 3, 9], state: "minecraft:stone_bricks"},
        {pos: [3, 3, 10], state: "minecraft:stone_bricks"},
        {pos: [3, 3, 11], state: "minecraft:gravel"},
        {pos: [3, 3, 12], state: "minecraft:gravel"},
        {pos: [4, 3, 1], state: "minecraft:gravel"},
        {pos: [4, 3, 2], state: "minecraft:gravel"},
        {pos: [4, 3, 3], state: "minecraft:gravel"},
        {pos: [4, 3, 9], state: "minecraft:gravel"},
        {pos: [4, 3, 10], state: "minecraft:gravel"},
        {pos: [0, 4, 2], state: "minecraft:gravel"},
        {pos: [1, 4, 1], state: "minecraft:gravel"},
        {pos: [1, 4, 2], state: "minecraft:stone_bricks"},
        {pos: [1, 4, 3], state: "minecraft:gravel"},
        {pos: [1, 4, 4], state: "minecraft:gravel"},
        {pos: [1, 4, 7], state: "minecraft:gravel"},
        {pos: [1, 4, 8], state: "minecraft:stone_bricks"},
        {pos: [1, 4, 9], state: "minecraft:stone_bricks"},
        {pos: [1, 4, 10], state: "minecraft:polished_andesite"},
        {pos: [1, 4, 11], state: "minecraft:gravel"},
        {pos: [2, 4, 1], state: "minecraft:gravel"},
        {pos: [2, 4, 2], state: "minecraft:stone_bricks"},
        {pos: [2, 4, 3], state: "minecraft:gravel"},
        {pos: [2, 4, 4], state: "minecraft:gravel"},
        {pos: [2, 4, 7], state: "minecraft:gravel"},
        {pos: [2, 4, 8], state: "minecraft:gravel"},
        {pos: [2, 4, 9], state: "minecraft:gravel"},
        {pos: [2, 4, 10], state: "minecraft:polished_andesite"},
        {pos: [2, 4, 11], state: "minecraft:gravel"},
        {pos: [3, 4, 0], state: "minecraft:gravel"},
        {pos: [3, 4, 1], state: "minecraft:gravel"},
        {pos: [3, 4, 2], state: "minecraft:stone_bricks"},
        {pos: [3, 4, 3], state: "minecraft:stone_bricks"},
        {pos: [3, 4, 4], state: "minecraft:gravel"},
        {pos: [3, 4, 8], state: "minecraft:stone_bricks"},
        {pos: [3, 4, 9], state: "minecraft:stone_bricks"},
        {pos: [3, 4, 10], state: "minecraft:stone_bricks"},
        {pos: [3, 4, 11], state: "minecraft:gravel"},
        {pos: [3, 4, 12], state: "minecraft:gravel"},
        {pos: [4, 4, 1], state: "minecraft:gravel"},
        {pos: [4, 4, 2], state: "minecraft:gravel"},
        {pos: [4, 4, 3], state: "minecraft:gravel"},
        {pos: [4, 4, 9], state: "minecraft:gravel"},
        {pos: [4, 4, 10], state: "minecraft:gravel"},
        {pos: [1, 5, 2], state: "minecraft:gravel"},
        {pos: [1, 5, 3], state: "minecraft:gravel"},
        {pos: [1, 5, 8], state: "minecraft:gravel"},
        {pos: [1, 5, 9], state: "minecraft:stone_bricks"},
        {pos: [1, 5, 10], state: "minecraft:stone_bricks"},
        {pos: [1, 5, 11], state: "minecraft:gravel"},
        {pos: [2, 5, 1], state: "minecraft:gravel"},
        {pos: [2, 5, 2], state: "minecraft:stone_bricks"},
        {pos: [2, 5, 3], state: "minecraft:gravel"},
        {pos: [2, 5, 4], state: "minecraft:gravel"},
        {pos: [2, 5, 7], state: "minecraft:gravel"},
        {pos: [2, 5, 8], state: "minecraft:stone_bricks"},
        {pos: [2, 5, 9], state: "minecraft:gravel"},
        {pos: [2, 5, 10], state: "minecraft:stone_bricks"},
        {pos: [2, 5, 11], state: "minecraft:gravel"},
        {pos: [3, 5, 1], state: "minecraft:gravel"},
        {pos: [3, 5, 2], state: "minecraft:stone_bricks"},
        {pos: [3, 5, 3], state: "minecraft:stone_bricks"},
        {pos: [3, 5, 4], state: "minecraft:gravel"},
        {pos: [3, 5, 8], state: "minecraft:stone_bricks"},
        {pos: [3, 5, 9], state: "minecraft:stone_bricks"},
        {pos: [3, 5, 10], state: "minecraft:stone_bricks"},
        {pos: [3, 5, 11], state: "minecraft:gravel"},
        {pos: [4, 5, 1], state: "minecraft:gravel"},
        {pos: [4, 5, 2], state: "minecraft:gravel"},
        {pos: [4, 5, 3], state: "minecraft:gravel"},
        {pos: [4, 5, 10], state: "minecraft:gravel"},
        {pos: [1, 6, 2], state: "minecraft:gravel"},
        {pos: [1, 6, 9], state: "minecraft:gravel"},
        {pos: [1, 6, 10], state: "minecraft:stone_bricks"},
        {pos: [1, 6, 11], state: "minecraft:gravel"},
        {pos: [2, 6, 1], state: "minecraft:gravel"},
        {pos: [2, 6, 2], state: "minecraft:stone_bricks"},
        {pos: [2, 6, 3], state: "minecraft:gravel"},
        {pos: [2, 6, 8], state: "minecraft:gravel"},
        {pos: [2, 6, 9], state: "minecraft:gravel"},
        {pos: [2, 6, 10], state: "minecraft:stone_bricks"},
        {pos: [2, 6, 11], state: "minecraft:gravel"},
        {pos: [3, 6, 1], state: "minecraft:gravel"},
        {pos: [3, 6, 2], state: "minecraft:stone_bricks"},
        {pos: [3, 6, 3], state: "minecraft:stone_bricks"},
        {pos: [3, 6, 4], state: "minecraft:gravel"},
        {pos: [3, 6, 8], state: "minecraft:stone_bricks"},
        {pos: [3, 6, 9], state: "minecraft:stone_bricks"},
        {pos: [3, 6, 10], state: "minecraft:stone_bricks"},
        {pos: [4, 6, 2], state: "minecraft:gravel"},
        {pos: [4, 6, 3], state: "minecraft:gravel"},
        {pos: [1, 7, 10], state: "minecraft:gravel"},
        {pos: [2, 7, 2], state: "minecraft:gravel"},
        {pos: [2, 7, 9], state: "minecraft:gravel"},
        {pos: [2, 7, 10], state: "minecraft:stone_bricks"},
        {pos: [3, 7, 1], state: "minecraft:gravel"},
        {pos: [3, 7, 2], state: "minecraft:stone_bricks"},
        {pos: [3, 7, 3], state: "minecraft:gravel"},
        {pos: [3, 7, 8], state: "minecraft:stone_bricks"},
        {pos: [3, 7, 9], state: "minecraft:stone_bricks"},
        {pos: [3, 7, 10], state: "minecraft:stone_bricks"},
        {pos: [4, 7, 2], state: "minecraft:gravel"},
        {pos: [2, 8, 10], state: "minecraft:stone_bricks"},
        {pos: [3, 8, 2], state: "minecraft:gravel"},
        {pos: [3, 8, 9], state: "minecraft:stone_bricks"},
        {pos: [3, 8, 10], state: "minecraft:stone_bricks"},
        {pos: [3, 9, 10], state: "minecraft:stone_bricks"}
    ],
    entities: [],
    palette: [
        "minecraft:stone_bricks",
        "minecraft:chiseled_stone_bricks",
        "minecraft:polished_andesite",
        "minecraft:gravel"
    ],
    trailiertales_DataVersion: 2
}
