{
    DataVersion: 3953,
    size: [12, 8, 15],
    data: [
        {pos: [0, 0, 10], state: "minecraft:stone_bricks"},
        {pos: [0, 0, 11], state: "minecraft:stone_bricks"},
        {pos: [0, 0, 12], state: "minecraft:stone_bricks"},
        {pos: [1, 0, 8], state: "minecraft:stone_bricks"},
        {pos: [1, 0, 9], state: "minecraft:stone_bricks"},
        {pos: [1, 0, 10], state: "minecraft:stone_bricks"},
        {pos: [1, 0, 11], state: "minecraft:stone_bricks"},
        {pos: [1, 0, 12], state: "minecraft:stone_bricks"},
        {pos: [1, 0, 13], state: "minecraft:stone_bricks"},
        {pos: [1, 0, 14], state: "minecraft:stone_bricks"},
        {pos: [2, 0, 7], state: "minecraft:stone_bricks"},
        {pos: [2, 0, 8], state: "minecraft:stone_bricks"},
        {pos: [2, 0, 9], state: "minecraft:stone_bricks"},
        {pos: [2, 0, 10], state: "minecraft:stone_bricks"},
        {pos: [2, 0, 11], state: "minecraft:stone_bricks"},
        {pos: [2, 0, 12], state: "minecraft:stone_bricks"},
        {pos: [2, 0, 13], state: "minecraft:stone_bricks"},
        {pos: [2, 0, 14], state: "minecraft:stone_bricks"},
        {pos: [3, 0, 8], state: "minecraft:stone_bricks"},
        {pos: [3, 0, 9], state: "minecraft:stone_bricks"},
        {pos: [3, 0, 10], state: "minecraft:stone_bricks"},
        {pos: [3, 0, 11], state: "minecraft:stone_bricks"},
        {pos: [3, 0, 12], state: "minecraft:stone_bricks"},
        {pos: [3, 0, 13], state: "minecraft:stone_bricks"},
        {pos: [3, 0, 14], state: "minecraft:stone_bricks"},
        {pos: [4, 0, 8], state: "minecraft:stone_bricks"},
        {pos: [4, 0, 9], state: "minecraft:stone_bricks"},
        {pos: [4, 0, 10], state: "minecraft:stone_bricks"},
        {pos: [4, 0, 11], state: "minecraft:stone_bricks"},
        {pos: [4, 0, 12], state: "minecraft:stone_bricks"},
        {pos: [4, 0, 13], state: "minecraft:stone_bricks"},
        {pos: [4, 0, 14], state: "minecraft:stone_bricks"},
        {pos: [5, 0, 1], state: "minecraft:stone_bricks"},
        {pos: [5, 0, 2], state: "minecraft:stone_bricks"},
        {pos: [5, 0, 3], state: "minecraft:stone_bricks"},
        {pos: [5, 0, 4], state: "minecraft:stone_bricks"},
        {pos: [5, 0, 7], state: "minecraft:stone_bricks"},
        {pos: [5, 0, 8], state: "minecraft:stone_bricks"},
        {pos: [5, 0, 9], state: "minecraft:stone_bricks"},
        {pos: [5, 0, 10], state: "minecraft:stone_bricks"},
        {pos: [5, 0, 11], state: "minecraft:stone_bricks"},
        {pos: [5, 0, 12], state: "minecraft:stone_bricks"},
        {pos: [5, 0, 13], state: "minecraft:stone_bricks"},
        {pos: [6, 0, 0], state: "minecraft:stone_bricks"},
        {pos: [6, 0, 1], state: "minecraft:polished_andesite"},
        {pos: [6, 0, 2], state: "minecraft:stone_bricks"},
        {pos: [6, 0, 3], state: "minecraft:stone_bricks"},
        {pos: [6, 0, 4], state: "minecraft:stone_bricks"},
        {pos: [6, 0, 5], state: "minecraft:stone_bricks"},
        {pos: [6, 0, 6], state: "minecraft:stone_bricks"},
        {pos: [6, 0, 7], state: "minecraft:stone_bricks"},
        {pos: [6, 0, 8], state: "minecraft:stone_bricks"},
        {pos: [6, 0, 9], state: "minecraft:stone_bricks"},
        {pos: [6, 0, 10], state: "minecraft:stone_bricks"},
        {pos: [6, 0, 11], state: "minecraft:stone_bricks"},
        {pos: [6, 0, 12], state: "minecraft:stone_bricks"},
        {pos: [7, 0, 0], state: "minecraft:stone_bricks"},
        {pos: [7, 0, 1], state: "minecraft:polished_andesite"},
        {pos: [7, 0, 2], state: "minecraft:stone_bricks"},
        {pos: [7, 0, 3], state: "minecraft:stone_bricks"},
        {pos: [7, 0, 4], state: "minecraft:stone_bricks"},
        {pos: [7, 0, 5], state: "minecraft:stone_bricks"},
        {pos: [7, 0, 6], state: "minecraft:stone_bricks"},
        {pos: [7, 0, 7], state: "minecraft:stone_bricks"},
        {pos: [7, 0, 8], state: "minecraft:stone_bricks"},
        {pos: [8, 0, 0], state: "minecraft:stone_bricks"},
        {pos: [8, 0, 1], state: "minecraft:stone_bricks"},
        {pos: [8, 0, 2], state: "minecraft:stone_bricks"},
        {pos: [8, 0, 3], state: "minecraft:stone_bricks"},
        {pos: [8, 0, 4], state: "minecraft:stone_bricks"},
        {pos: [8, 0, 5], state: "minecraft:stone_bricks"},
        {pos: [8, 0, 6], state: "minecraft:stone_bricks"},
        {pos: [9, 0, 0], state: "minecraft:stone_bricks"},
        {pos: [9, 0, 1], state: "minecraft:stone_bricks"},
        {pos: [9, 0, 2], state: "minecraft:stone_bricks"},
        {pos: [9, 0, 3], state: "minecraft:stone_bricks"},
        {pos: [9, 0, 4], state: "minecraft:stone_bricks"},
        {pos: [9, 0, 5], state: "minecraft:stone_bricks"},
        {pos: [9, 0, 6], state: "minecraft:stone_bricks"},
        {pos: [10, 0, 1], state: "minecraft:stone_bricks"},
        {pos: [10, 0, 2], state: "minecraft:stone_bricks"},
        {pos: [10, 0, 3], state: "minecraft:stone_bricks"},
        {pos: [10, 0, 4], state: "minecraft:stone_bricks"},
        {pos: [10, 0, 5], state: "minecraft:stone_bricks"},
        {pos: [11, 0, 2], state: "minecraft:chiseled_stone_bricks"},
        {pos: [11, 0, 3], state: "minecraft:stone_bricks"},
        {pos: [0, 1, 10], state: "minecraft:stone_bricks"},
        {pos: [0, 1, 11], state: "minecraft:stone_bricks"},
        {pos: [0, 1, 12], state: "minecraft:stone_bricks"},
        {pos: [1, 1, 8], state: "minecraft:stone_bricks"},
        {pos: [1, 1, 9], state: "minecraft:stone_bricks"},
        {pos: [1, 1, 13], state: "minecraft:stone_bricks"},
        {pos: [1, 1, 14], state: "minecraft:stone_bricks"},
        {pos: [2, 1, 7], state: "minecraft:polished_andesite"},
        {pos: [2, 1, 8], state: "minecraft:stone_bricks"},
        {pos: [2, 1, 9], state: "minecraft:gravel"},
        {pos: [2, 1, 10], state: "minecraft:gravel"},
        {pos: [2, 1, 11], state: "minecraft:gravel"},
        {pos: [2, 1, 12], state: "minecraft:gravel"},
        {pos: [2, 1, 13], state: "minecraft:gravel"},
        {pos: [2, 1, 14], state: "minecraft:chiseled_stone_bricks"},
        {pos: [3, 1, 8], state: "minecraft:gravel"},
        {pos: [3, 1, 9], state: "minecraft:gravel"},
        {pos: [3, 1, 10], state: "minecraft:gravel"},
        {pos: [3, 1, 11], state: "minecraft:gravel"},
        {pos: [3, 1, 12], state: "minecraft:gravel"},
        {pos: [3, 1, 13], state: "minecraft:gravel"},
        {pos: [3, 1, 14], state: "minecraft:polished_andesite"},
        {pos: [4, 1, 8], state: "minecraft:gravel"},
        {pos: [4, 1, 9], state: "minecraft:gravel"},
        {pos: [4, 1, 10], state: "minecraft:gravel"},
        {pos: [4, 1, 11], state: "minecraft:gravel"},
        {pos: [4, 1, 12], state: "minecraft:gravel"},
        {pos: [4, 1, 13], state: "minecraft:gravel"},
        {pos: [4, 1, 14], state: "minecraft:stone_bricks"},
        {pos: [5, 1, 1], state: "minecraft:stone_bricks"},
        {pos: [5, 1, 2], state: "minecraft:stone_bricks"},
        {pos: [5, 1, 3], state: "minecraft:stone_bricks"},
        {pos: [5, 1, 4], state: "minecraft:gravel"},
        {pos: [5, 1, 7], state: "minecraft:gravel"},
        {pos: [5, 1, 8], state: "minecraft:gravel"},
        {pos: [5, 1, 9], state: "minecraft:gravel"},
        {pos: [5, 1, 10], state: "minecraft:gravel"},
        {pos: [5, 1, 11], state: "minecraft:gravel"},
        {pos: [5, 1, 12], state: "minecraft:stone_bricks"},
        {pos: [5, 1, 13], state: "minecraft:stone_bricks"},
        {pos: [6, 1, 0], state: "minecraft:stone_bricks"},
        {pos: [6, 1, 1], state: "minecraft:stone_bricks"},
        {pos: [6, 1, 2], state: "minecraft:stone_bricks"},
        {pos: [6, 1, 3], state: "minecraft:gravel"},
        {pos: [6, 1, 4], state: "minecraft:gravel"},
        {pos: [6, 1, 5], state: "minecraft:gravel"},
        {pos: [6, 1, 6], state: "minecraft:gravel"},
        {pos: [6, 1, 7], state: "minecraft:gravel"},
        {pos: [6, 1, 8], state: "minecraft:gravel"},
        {pos: [6, 1, 9], state: "minecraft:gravel"},
        {pos: [6, 1, 10], state: "minecraft:gravel"},
        {pos: [6, 1, 11], state: "minecraft:gravel"},
        {pos: [6, 1, 12], state: "minecraft:gravel"},
        {pos: [7, 1, 0], state: "minecraft:stone_bricks"},
        {pos: [7, 1, 1], state: "minecraft:stone_bricks"},
        {pos: [7, 1, 2], state: "minecraft:gravel"},
        {pos: [7, 1, 3], state: "minecraft:gravel"},
        {pos: [7, 1, 4], state: "minecraft:gravel"},
        {pos: [7, 1, 5], state: "minecraft:gravel"},
        {pos: [7, 1, 6], state: "minecraft:gravel"},
        {pos: [7, 1, 7], state: "minecraft:gravel"},
        {pos: [7, 1, 8], state: "minecraft:gravel"},
        {pos: [8, 1, 0], state: "minecraft:stone_bricks"},
        {pos: [8, 1, 1], state: "minecraft:gravel"},
        {pos: [8, 1, 2], state: "minecraft:gravel"},
        {pos: [8, 1, 3], state: "minecraft:gravel"},
        {pos: [8, 1, 4], state: "minecraft:gravel"},
        {pos: [8, 1, 5], state: "minecraft:stone_bricks"},
        {pos: [8, 1, 6], state: "minecraft:gravel"},
        {pos: [9, 1, 0], state: "minecraft:stone_bricks"},
        {pos: [9, 1, 1], state: "minecraft:gravel"},
        {pos: [9, 1, 2], state: "minecraft:gravel"},
        {pos: [9, 1, 3], state: "minecraft:gravel"},
        {pos: [9, 1, 4], state: "minecraft:gravel"},
        {pos: [9, 1, 5], state: "minecraft:stone_bricks"},
        {pos: [9, 1, 6], state: "minecraft:gravel"},
        {pos: [10, 1, 1], state: "minecraft:polished_andesite"},
        {pos: [10, 1, 2], state: "minecraft:gravel"},
        {pos: [10, 1, 3], state: "minecraft:stone_bricks"},
        {pos: [10, 1, 4], state: "minecraft:gravel"},
        {pos: [10, 1, 5], state: "minecraft:gravel"},
        {pos: [11, 1, 2], state: "minecraft:stone_bricks"},
        {pos: [11, 1, 3], state: "minecraft:polished_andesite"},
        {pos: [0, 2, 10], state: "minecraft:polished_andesite"},
        {pos: [0, 2, 12], state: "minecraft:stone_bricks"},
        {pos: [1, 2, 8], state: "minecraft:stone_bricks"},
        {pos: [1, 2, 9], state: "minecraft:stone_bricks"},
        {pos: [1, 2, 13], state: "minecraft:polished_andesite"},
        {pos: [1, 2, 14], state: "minecraft:stone_bricks"},
        {pos: [2, 2, 7], state: "minecraft:gravel"},
        {pos: [2, 2, 8], state: "minecraft:stone_bricks"},
        {pos: [2, 2, 9], state: "minecraft:gravel"},
        {pos: [2, 2, 10], state: "minecraft:gravel"},
        {pos: [2, 2, 11], state: "minecraft:gravel"},
        {pos: [2, 2, 12], state: "minecraft:gravel"},
        {pos: [2, 2, 13], state: "minecraft:gravel"},
        {pos: [2, 2, 14], state: "minecraft:chiseled_stone_bricks"},
        {pos: [3, 2, 8], state: "minecraft:gravel"},
        {pos: [3, 2, 9], state: "minecraft:gravel"},
        {pos: [3, 2, 10], state: "minecraft:gravel"},
        {pos: [3, 2, 11], state: "minecraft:gravel"},
        {pos: [3, 2, 12], state: "minecraft:gravel"},
        {pos: [3, 2, 13], state: "minecraft:gravel"},
        {pos: [3, 2, 14], state: "minecraft:stone_bricks"},
        {pos: [4, 2, 8], state: "minecraft:gravel"},
        {pos: [4, 2, 9], state: "minecraft:gravel"},
        {pos: [4, 2, 10], state: "minecraft:gravel"},
        {pos: [4, 2, 11], state: "minecraft:gravel"},
        {pos: [4, 2, 12], state: "minecraft:gravel"},
        {pos: [4, 2, 13], state: "minecraft:gravel"},
        {pos: [4, 2, 14], state: "minecraft:polished_andesite"},
        {pos: [5, 2, 1], state: "minecraft:stone_bricks"},
        {pos: [5, 2, 2], state: "minecraft:polished_andesite"},
        {pos: [5, 2, 3], state: "minecraft:stone_bricks"},
        {pos: [5, 2, 4], state: "minecraft:gravel"},
        {pos: [5, 2, 7], state: "minecraft:gravel"},
        {pos: [5, 2, 8], state: "minecraft:gravel"},
        {pos: [5, 2, 9], state: "minecraft:gravel"},
        {pos: [5, 2, 10], state: "minecraft:gravel"},
        {pos: [5, 2, 11], state: "minecraft:gravel"},
        {pos: [5, 2, 12], state: "minecraft:stone_bricks"},
        {pos: [5, 2, 13], state: "minecraft:stone_bricks"},
        {pos: [6, 2, 0], state: "minecraft:stone_bricks"},
        {pos: [6, 2, 1], state: "minecraft:gravel"},
        {pos: [6, 2, 2], state: "minecraft:gravel"},
        {pos: [6, 2, 3], state: "minecraft:gravel"},
        {pos: [6, 2, 4], state: "minecraft:gravel"},
        {pos: [6, 2, 5], state: "minecraft:gravel"},
        {pos: [6, 2, 6], state: "minecraft:gravel"},
        {pos: [6, 2, 7], state: "minecraft:gravel"},
        {pos: [6, 2, 8], state: "minecraft:gravel"},
        {pos: [6, 2, 9], state: "minecraft:gravel"},
        {pos: [6, 2, 10], state: "minecraft:gravel"},
        {pos: [6, 2, 11], state: "minecraft:gravel"},
        {pos: [6, 2, 12], state: "minecraft:gravel"},
        {pos: [7, 2, 0], state: "minecraft:stone_bricks"},
        {pos: [7, 2, 1], state: "minecraft:gravel"},
        {pos: [7, 2, 2], state: "minecraft:gravel"},
        {pos: [7, 2, 3], state: "minecraft:gravel"},
        {pos: [7, 2, 4], state: "minecraft:gravel"},
        {pos: [7, 2, 5], state: "minecraft:gravel"},
        {pos: [7, 2, 6], state: "minecraft:gravel"},
        {pos: [7, 2, 7], state: "minecraft:gravel"},
        {pos: [7, 2, 8], state: "minecraft:gravel"},
        {pos: [8, 2, 0], state: "minecraft:stone_bricks"},
        {pos: [8, 2, 1], state: "minecraft:gravel"},
        {pos: [8, 2, 2], state: "minecraft:gravel"},
        {pos: [8, 2, 3], state: "minecraft:gravel"},
        {pos: [8, 2, 4], state: "minecraft:gravel"},
        {pos: [8, 2, 5], state: "minecraft:stone_bricks"},
        {pos: [8, 2, 6], state: "minecraft:gravel"},
        {pos: [9, 2, 0], state: "minecraft:stone_bricks"},
        {pos: [9, 2, 1], state: "minecraft:gravel"},
        {pos: [9, 2, 2], state: "minecraft:gravel"},
        {pos: [9, 2, 3], state: "minecraft:gravel"},
        {pos: [9, 2, 4], state: "minecraft:gravel"},
        {pos: [9, 2, 5], state: "minecraft:stone_bricks"},
        {pos: [9, 2, 6], state: "minecraft:gravel"},
        {pos: [10, 2, 1], state: "minecraft:polished_andesite"},
        {pos: [10, 2, 2], state: "minecraft:gravel"},
        {pos: [10, 2, 3], state: "minecraft:gravel"},
        {pos: [10, 2, 4], state: "minecraft:gravel"},
        {pos: [10, 2, 5], state: "minecraft:gravel"},
        {pos: [11, 2, 2], state: "minecraft:stone_bricks"},
        {pos: [11, 2, 3], state: "minecraft:stone_bricks"},
        {pos: [0, 3, 10], state: "minecraft:stone_bricks"},
        {pos: [0, 3, 11], state: "minecraft:stone_bricks"},
        {pos: [0, 3, 12], state: "minecraft:stone_bricks"},
        {pos: [1, 3, 8], state: "minecraft:gravel"},
        {pos: [1, 3, 9], state: "minecraft:stone_bricks"},
        {pos: [1, 3, 13], state: "minecraft:stone_bricks"},
        {pos: [1, 3, 14], state: "minecraft:gravel"},
        {pos: [2, 3, 8], state: "minecraft:stone_bricks"},
        {pos: [2, 3, 9], state: "minecraft:gravel"},
        {pos: [2, 3, 10], state: "minecraft:gravel"},
        {pos: [2, 3, 11], state: "minecraft:gravel"},
        {pos: [2, 3, 12], state: "minecraft:gravel"},
        {pos: [2, 3, 13], state: "minecraft:gravel"},
        {pos: [2, 3, 14], state: "minecraft:stone_bricks"},
        {pos: [3, 3, 8], state: "minecraft:gravel"},
        {pos: [3, 3, 9], state: "minecraft:gravel"},
        {pos: [3, 3, 10], state: "minecraft:gravel"},
        {pos: [3, 3, 11], state: "minecraft:gravel"},
        {pos: [3, 3, 12], state: "minecraft:gravel"},
        {pos: [3, 3, 13], state: "minecraft:gravel"},
        {pos: [3, 3, 14], state: "minecraft:stone_bricks"},
        {pos: [4, 3, 8], state: "minecraft:gravel"},
        {pos: [4, 3, 9], state: "minecraft:gravel"},
        {pos: [4, 3, 10], state: "minecraft:gravel"},
        {pos: [4, 3, 11], state: "minecraft:gravel"},
        {pos: [4, 3, 12], state: "minecraft:stone_bricks"},
        {pos: [4, 3, 13], state: "minecraft:gravel"},
        {pos: [4, 3, 14], state: "minecraft:gravel"},
        {pos: [5, 3, 1], state: "minecraft:stone_bricks"},
        {pos: [5, 3, 2], state: "minecraft:stone_bricks"},
        {pos: [5, 3, 3], state: "minecraft:polished_andesite"},
        {pos: [5, 3, 4], state: "minecraft:gravel"},
        {pos: [5, 3, 7], state: "minecraft:gravel"},
        {pos: [5, 3, 8], state: "minecraft:gravel"},
        {pos: [5, 3, 9], state: "minecraft:gravel"},
        {pos: [5, 3, 10], state: "minecraft:gravel"},
        {pos: [5, 3, 11], state: "minecraft:stone_bricks"},
        {pos: [5, 3, 12], state: "minecraft:stone_bricks"},
        {pos: [5, 3, 13], state: "minecraft:gravel"},
        {pos: [6, 3, 0], state: "minecraft:stone_bricks"},
        {pos: [6, 3, 1], state: "minecraft:gravel"},
        {pos: [6, 3, 2], state: "minecraft:gravel"},
        {pos: [6, 3, 3], state: "minecraft:gravel"},
        {pos: [6, 3, 4], state: "minecraft:gravel"},
        {pos: [6, 3, 5], state: "minecraft:gravel"},
        {pos: [6, 3, 6], state: "minecraft:gravel"},
        {pos: [6, 3, 7], state: "minecraft:gravel"},
        {pos: [6, 3, 8], state: "minecraft:gravel"},
        {pos: [6, 3, 9], state: "minecraft:gravel"},
        {pos: [6, 3, 10], state: "minecraft:gravel"},
        {pos: [6, 3, 11], state: "minecraft:gravel"},
        {pos: [6, 3, 12], state: "minecraft:gravel"},
        {pos: [7, 3, 0], state: "minecraft:stone_bricks"},
        {pos: [7, 3, 1], state: "minecraft:gravel"},
        {pos: [7, 3, 2], state: "minecraft:gravel"},
        {pos: [7, 3, 3], state: "minecraft:gravel"},
        {pos: [7, 3, 4], state: "minecraft:gravel"},
        {pos: [7, 3, 5], state: "minecraft:gravel"},
        {pos: [7, 3, 6], state: "minecraft:gravel"},
        {pos: [7, 3, 7], state: "minecraft:gravel"},
        {pos: [7, 3, 8], state: "minecraft:gravel"},
        {pos: [8, 3, 0], state: "minecraft:stone_bricks"},
        {pos: [8, 3, 1], state: "minecraft:gravel"},
        {pos: [8, 3, 2], state: "minecraft:gravel"},
        {pos: [8, 3, 3], state: "minecraft:gravel"},
        {pos: [8, 3, 4], state: "minecraft:gravel"},
        {pos: [8, 3, 5], state: "minecraft:stone_bricks"},
        {pos: [8, 3, 6], state: "minecraft:gravel"},
        {pos: [9, 3, 0], state: "minecraft:stone_bricks"},
        {pos: [9, 3, 1], state: "minecraft:gravel"},
        {pos: [9, 3, 2], state: "minecraft:gravel"},
        {pos: [9, 3, 3], state: "minecraft:gravel"},
        {pos: [9, 3, 4], state: "minecraft:gravel"},
        {pos: [9, 3, 5], state: "minecraft:gravel"},
        {pos: [9, 3, 6], state: "minecraft:gravel"},
        {pos: [10, 3, 1], state: "minecraft:polished_andesite"},
        {pos: [10, 3, 2], state: "minecraft:gravel"},
        {pos: [10, 3, 3], state: "minecraft:gravel"},
        {pos: [10, 3, 4], state: "minecraft:stone_bricks"},
        {pos: [10, 3, 5], state: "minecraft:gravel"},
        {pos: [11, 3, 2], state: "minecraft:stone_bricks"},
        {pos: [11, 3, 3], state: "minecraft:stone_bricks"},
        {pos: [0, 4, 10], state: "minecraft:gravel"},
        {pos: [0, 4, 11], state: "minecraft:gravel"},
        {pos: [0, 4, 12], state: "minecraft:stone_bricks"},
        {pos: [1, 4, 8], state: "minecraft:gravel"},
        {pos: [1, 4, 9], state: "minecraft:gravel"},
        {pos: [1, 4, 10], state: "minecraft:stone_bricks"},
        {pos: [1, 4, 11], state: "minecraft:stone_bricks"},
        {pos: [1, 4, 12], state: "minecraft:chiseled_stone_bricks"},
        {pos: [1, 4, 13], state: "minecraft:stone_bricks"},
        {pos: [1, 4, 14], state: "minecraft:gravel"},
        {pos: [2, 4, 8], state: "minecraft:stone_bricks"},
        {pos: [2, 4, 9], state: "minecraft:stone_bricks"},
        {pos: [2, 4, 10], state: "minecraft:stone_bricks"},
        {pos: [2, 4, 11], state: "minecraft:stone_bricks"},
        {pos: [2, 4, 12], state: "minecraft:stone_bricks"},
        {pos: [2, 4, 13], state: "minecraft:gravel"},
        {pos: [2, 4, 14], state: "minecraft:gravel"},
        {pos: [3, 4, 8], state: "minecraft:gravel"},
        {pos: [3, 4, 9], state: "minecraft:stone_bricks"},
        {pos: [3, 4, 10], state: "minecraft:polished_andesite"},
        {pos: [3, 4, 11], state: "minecraft:stone_bricks"},
        {pos: [3, 4, 12], state: "minecraft:stone_bricks"},
        {pos: [3, 4, 13], state: "minecraft:polished_andesite"},
        {pos: [3, 4, 14], state: "minecraft:gravel"},
        {pos: [4, 4, 8], state: "minecraft:gravel"},
        {pos: [4, 4, 9], state: "minecraft:stone_bricks"},
        {pos: [4, 4, 10], state: "minecraft:stone_bricks"},
        {pos: [4, 4, 11], state: "minecraft:stone_bricks"},
        {pos: [4, 4, 12], state: "minecraft:gravel"},
        {pos: [4, 4, 13], state: "minecraft:gravel"},
        {pos: [4, 4, 14], state: "minecraft:gravel"},
        {pos: [5, 4, 1], state: "minecraft:stone_bricks"},
        {pos: [5, 4, 2], state: "minecraft:stone_bricks"},
        {pos: [5, 4, 3], state: "minecraft:stone_bricks"},
        {pos: [5, 4, 4], state: "minecraft:gravel"},
        {pos: [5, 4, 9], state: "minecraft:gravel"},
        {pos: [5, 4, 10], state: "minecraft:stone_bricks"},
        {pos: [5, 4, 11], state: "minecraft:gravel"},
        {pos: [5, 4, 12], state: "minecraft:gravel"},
        {pos: [5, 4, 13], state: "minecraft:gravel"},
        {pos: [6, 4, 0], state: "minecraft:stone_bricks"},
        {pos: [6, 4, 1], state: "minecraft:gravel"},
        {pos: [6, 4, 2], state: "minecraft:gravel"},
        {pos: [6, 4, 3], state: "minecraft:polished_andesite"},
        {pos: [6, 4, 4], state: "minecraft:stone_bricks"},
        {pos: [6, 4, 5], state: "minecraft:gravel"},
        {pos: [6, 4, 6], state: "minecraft:gravel"},
        {pos: [6, 4, 10], state: "minecraft:gravel"},
        {pos: [6, 4, 11], state: "minecraft:gravel"},
        {pos: [7, 4, 0], state: "minecraft:stone_bricks"},
        {pos: [7, 4, 1], state: "minecraft:gravel"},
        {pos: [7, 4, 2], state: "minecraft:gravel"},
        {pos: [7, 4, 3], state: "minecraft:gravel"},
        {pos: [7, 4, 4], state: "minecraft:stone_bricks"},
        {pos: [7, 4, 5], state: "minecraft:chiseled_stone_bricks"},
        {pos: [7, 4, 6], state: "minecraft:gravel"},
        {pos: [7, 4, 7], state: "minecraft:gravel"},
        {pos: [8, 4, 0], state: "minecraft:stone_bricks"},
        {pos: [8, 4, 1], state: "minecraft:gravel"},
        {pos: [8, 4, 2], state: "minecraft:gravel"},
        {pos: [8, 4, 3], state: "minecraft:gravel"},
        {pos: [8, 4, 4], state: "minecraft:gravel"},
        {pos: [8, 4, 5], state: "minecraft:chiseled_stone_bricks"},
        {pos: [8, 4, 6], state: "minecraft:gravel"},
        {pos: [9, 4, 0], state: "minecraft:stone_bricks"},
        {pos: [9, 4, 1], state: "minecraft:gravel"},
        {pos: [9, 4, 2], state: "minecraft:gravel"},
        {pos: [9, 4, 3], state: "minecraft:gravel"},
        {pos: [9, 4, 4], state: "minecraft:gravel"},
        {pos: [9, 4, 5], state: "minecraft:gravel"},
        {pos: [9, 4, 6], state: "minecraft:gravel"},
        {pos: [10, 4, 1], state: "minecraft:polished_andesite"},
        {pos: [10, 4, 2], state: "minecraft:gravel"},
        {pos: [10, 4, 3], state: "minecraft:gravel"},
        {pos: [10, 4, 4], state: "minecraft:stone_bricks"},
        {pos: [10, 4, 5], state: "minecraft:gravel"},
        {pos: [11, 4, 2], state: "minecraft:stone_bricks"},
        {pos: [11, 4, 3], state: "minecraft:stone_bricks"},
        {pos: [0, 5, 11], state: "minecraft:gravel"},
        {pos: [0, 5, 12], state: "minecraft:gravel"},
        {pos: [1, 5, 10], state: "minecraft:gravel"},
        {pos: [1, 5, 11], state: "minecraft:gravel"},
        {pos: [1, 5, 12], state: "minecraft:gravel"},
        {pos: [1, 5, 13], state: "minecraft:gravel"},
        {pos: [1, 5, 14], state: "minecraft:gravel"},
        {pos: [2, 5, 8], state: "minecraft:gravel"},
        {pos: [2, 5, 9], state: "minecraft:gravel"},
        {pos: [2, 5, 10], state: "minecraft:gravel"},
        {pos: [2, 5, 11], state: "minecraft:gravel"},
        {pos: [2, 5, 12], state: "minecraft:gravel"},
        {pos: [2, 5, 13], state: "minecraft:gravel"},
        {pos: [2, 5, 14], state: "minecraft:gravel"},
        {pos: [3, 5, 9], state: "minecraft:gravel"},
        {pos: [3, 5, 10], state: "minecraft:gravel"},
        {pos: [3, 5, 11], state: "minecraft:gravel"},
        {pos: [3, 5, 12], state: "minecraft:gravel"},
        {pos: [3, 5, 13], state: "minecraft:gravel"},
        {pos: [4, 5, 9], state: "minecraft:gravel"},
        {pos: [4, 5, 10], state: "minecraft:gravel"},
        {pos: [4, 5, 11], state: "minecraft:gravel"},
        {pos: [4, 5, 12], state: "minecraft:gravel"},
        {pos: [5, 5, 1], state: "minecraft:stone_bricks"},
        {pos: [5, 5, 2], state: "minecraft:stone_bricks"},
        {pos: [5, 5, 3], state: "minecraft:stone_bricks"},
        {pos: [5, 5, 4], state: "minecraft:gravel"},
        {pos: [5, 5, 10], state: "minecraft:gravel"},
        {pos: [5, 5, 11], state: "minecraft:gravel"},
        {pos: [5, 5, 12], state: "minecraft:gravel"},
        {pos: [6, 5, 0], state: "minecraft:stone_bricks"},
        {pos: [6, 5, 1], state: "minecraft:gravel"},
        {pos: [6, 5, 2], state: "minecraft:gravel"},
        {pos: [6, 5, 3], state: "minecraft:gravel"},
        {pos: [6, 5, 4], state: "minecraft:stone_bricks"},
        {pos: [6, 5, 5], state: "minecraft:gravel"},
        {pos: [7, 5, 0], state: "minecraft:stone_bricks"},
        {pos: [7, 5, 1], state: "minecraft:gravel"},
        {pos: [7, 5, 2], state: "minecraft:gravel"},
        {pos: [7, 5, 3], state: "minecraft:gravel"},
        {pos: [7, 5, 4], state: "minecraft:gravel"},
        {pos: [7, 5, 5], state: "minecraft:stone_bricks"},
        {pos: [8, 5, 0], state: "minecraft:stone_bricks"},
        {pos: [8, 5, 1], state: "minecraft:gravel"},
        {pos: [8, 5, 2], state: "minecraft:gravel"},
        {pos: [8, 5, 3], state: "minecraft:gravel"},
        {pos: [8, 5, 4], state: "minecraft:gravel"},
        {pos: [8, 5, 5], state: "minecraft:stone_bricks"},
        {pos: [8, 5, 6], state: "minecraft:gravel"},
        {pos: [9, 5, 0], state: "minecraft:stone_bricks"},
        {pos: [9, 5, 1], state: "minecraft:gravel"},
        {pos: [9, 5, 2], state: "minecraft:gravel"},
        {pos: [9, 5, 3], state: "minecraft:gravel"},
        {pos: [9, 5, 4], state: "minecraft:gravel"},
        {pos: [9, 5, 5], state: "minecraft:gravel"},
        {pos: [10, 5, 1], state: "minecraft:stone_bricks"},
        {pos: [10, 5, 2], state: "minecraft:gravel"},
        {pos: [10, 5, 3], state: "minecraft:gravel"},
        {pos: [10, 5, 4], state: "minecraft:gravel"},
        {pos: [10, 5, 5], state: "minecraft:gravel"},
        {pos: [11, 5, 2], state: "minecraft:stone_bricks"},
        {pos: [11, 5, 3], state: "minecraft:stone_bricks"},
        {pos: [0, 6, 11], state: "minecraft:gravel"},
        {pos: [0, 6, 12], state: "minecraft:gravel"},
        {pos: [1, 6, 11], state: "minecraft:gravel"},
        {pos: [1, 6, 12], state: "minecraft:gravel"},
        {pos: [2, 6, 11], state: "minecraft:gravel"},
        {pos: [2, 6, 12], state: "minecraft:gravel"},
        {pos: [2, 6, 13], state: "minecraft:gravel"},
        {pos: [3, 6, 9], state: "minecraft:gravel"},
        {pos: [3, 6, 12], state: "minecraft:gravel"},
        {pos: [4, 6, 9], state: "minecraft:gravel"},
        {pos: [4, 6, 10], state: "minecraft:gravel"},
        {pos: [5, 6, 1], state: "minecraft:gravel"},
        {pos: [5, 6, 2], state: "minecraft:gravel"},
        {pos: [5, 6, 3], state: "minecraft:stone_bricks"},
        {pos: [5, 6, 4], state: "minecraft:gravel"},
        {pos: [5, 6, 10], state: "minecraft:gravel"},
        {pos: [6, 6, 0], state: "minecraft:gravel"},
        {pos: [6, 6, 1], state: "minecraft:gravel"},
        {pos: [6, 6, 2], state: "minecraft:gravel"},
        {pos: [6, 6, 3], state: "minecraft:gravel"},
        {pos: [6, 6, 4], state: "minecraft:stone_bricks"},
        {pos: [7, 6, 0], state: "minecraft:gravel"},
        {pos: [7, 6, 1], state: "minecraft:gravel"},
        {pos: [7, 6, 2], state: "minecraft:gravel"},
        {pos: [7, 6, 3], state: "minecraft:gravel"},
        {pos: [7, 6, 4], state: "minecraft:gravel"},
        {pos: [7, 6, 5], state: "minecraft:stone_bricks"},
        {pos: [8, 6, 0], state: "minecraft:stone_bricks"},
        {pos: [8, 6, 1], state: "minecraft:stone_bricks"},
        {pos: [8, 6, 2], state: "minecraft:stone_bricks"},
        {pos: [8, 6, 3], state: "minecraft:gravel"},
        {pos: [8, 6, 4], state: "minecraft:gravel"},
        {pos: [8, 6, 5], state: "minecraft:gravel"},
        {pos: [9, 6, 0], state: "minecraft:stone_bricks"},
        {pos: [9, 6, 1], state: "minecraft:stone_bricks"},
        {pos: [9, 6, 2], state: "minecraft:stone_bricks"},
        {pos: [9, 6, 3], state: "minecraft:stone_bricks"},
        {pos: [9, 6, 4], state: "minecraft:gravel"},
        {pos: [9, 6, 5], state: "minecraft:gravel"},
        {pos: [10, 6, 1], state: "minecraft:stone_bricks"},
        {pos: [10, 6, 2], state: "minecraft:stone_bricks"},
        {pos: [10, 6, 3], state: "minecraft:stone_bricks"},
        {pos: [10, 6, 4], state: "minecraft:gravel"},
        {pos: [11, 6, 2], state: "minecraft:stone_bricks"},
        {pos: [11, 6, 3], state: "minecraft:gravel"},
        {pos: [5, 7, 2], state: "minecraft:gravel"},
        {pos: [5, 7, 3], state: "minecraft:stone_bricks"},
        {pos: [6, 7, 2], state: "minecraft:gravel"},
        {pos: [6, 7, 3], state: "minecraft:gravel"},
        {pos: [6, 7, 4], state: "minecraft:stone_bricks"},
        {pos: [7, 7, 3], state: "minecraft:gravel"},
        {pos: [7, 7, 4], state: "minecraft:gravel"},
        {pos: [8, 7, 0], state: "minecraft:gravel"},
        {pos: [8, 7, 4], state: "minecraft:gravel"},
        {pos: [9, 7, 0], state: "minecraft:stone_bricks"},
        {pos: [10, 7, 1], state: "minecraft:stone_bricks"},
        {pos: [11, 7, 2], state: "minecraft:stone_bricks"}
    ],
    entities: [],
    palette: [
        "minecraft:stone_bricks",
        "minecraft:polished_andesite",
        "minecraft:chiseled_stone_bricks",
        "minecraft:gravel"
    ],
    trailiertales_DataVersion: 2
}
