{
    DataVersion: 3953,
    size: [18, 19, 23],
    data: [
        {pos: [2, 0, 3], state: "minecraft:stone_bricks"},
        {pos: [2, 0, 4], state: "minecraft:stone_bricks"},
        {pos: [2, 0, 5], state: "minecraft:stone_bricks"},
        {pos: [2, 0, 11], state: "minecraft:stone_bricks"},
        {pos: [2, 0, 12], state: "minecraft:stone_bricks"},
        {pos: [2, 0, 13], state: "minecraft:stone_bricks"},
        {pos: [2, 0, 14], state: "minecraft:stone_bricks"},
        {pos: [2, 0, 15], state: "minecraft:stone_bricks"},
        {pos: [2, 0, 16], state: "minecraft:stone_bricks"},
        {pos: [2, 0, 17], state: "minecraft:stone_bricks"},
        {pos: [2, 0, 18], state: "minecraft:stone_bricks"},
        {pos: [2, 0, 19], state: "minecraft:stone_bricks"},
        {pos: [2, 0, 20], state: "minecraft:stone_bricks"},
        {pos: [2, 0, 21], state: "minecraft:stone_bricks"},
        {pos: [2, 0, 22], state: "minecraft:stone_bricks"},
        {pos: [3, 0, 1], state: "minecraft:stone_bricks"},
        {pos: [3, 0, 2], state: "minecraft:stone_bricks"},
        {pos: [3, 0, 3], state: "minecraft:stone_bricks"},
        {pos: [3, 0, 4], state: "minecraft:stone_bricks"},
        {pos: [3, 0, 5], state: "minecraft:stone_bricks"},
        {pos: [3, 0, 6], state: "minecraft:stone_bricks"},
        {pos: [3, 0, 7], state: "minecraft:stone_bricks"},
        {pos: [3, 0, 8], state: "minecraft:stone_bricks"},
        {pos: [3, 0, 9], state: "minecraft:stone_bricks"},
        {pos: [3, 0, 10], state: "minecraft:stone_bricks"},
        {pos: [3, 0, 11], state: "minecraft:stone_bricks"},
        {pos: [3, 0, 12], state: "minecraft:stone_bricks"},
        {pos: [3, 0, 13], state: "minecraft:stone_bricks"},
        {pos: [3, 0, 14], state: "minecraft:stone_bricks"},
        {pos: [3, 0, 15], state: "minecraft:stone_bricks"},
        {pos: [3, 0, 16], state: "minecraft:stone_bricks"},
        {pos: [3, 0, 17], state: "minecraft:stone_bricks"},
        {pos: [3, 0, 18], state: "minecraft:stone_bricks"},
        {pos: [3, 0, 19], state: "minecraft:stone_bricks"},
        {pos: [3, 0, 20], state: "minecraft:stone_bricks"},
        {pos: [3, 0, 21], state: "minecraft:stone_bricks"},
        {pos: [3, 0, 22], state: "minecraft:stone_bricks"},
        {pos: [4, 0, 0], state: "minecraft:stone_bricks"},
        {pos: [4, 0, 1], state: "minecraft:stone_bricks"},
        {pos: [4, 0, 2], state: "minecraft:stone_bricks"},
        {pos: [4, 0, 3], state: "minecraft:stone_bricks"},
        {pos: [4, 0, 4], state: "minecraft:stone_bricks"},
        {pos: [4, 0, 5], state: "minecraft:stone_bricks"},
        {pos: [4, 0, 6], state: "minecraft:stone_bricks"},
        {pos: [4, 0, 7], state: "minecraft:stone_bricks"},
        {pos: [4, 0, 8], state: "minecraft:stone_bricks"},
        {pos: [4, 0, 9], state: "minecraft:stone_bricks"},
        {pos: [4, 0, 10], state: "minecraft:stone_bricks"},
        {pos: [4, 0, 11], state: "minecraft:stone_bricks"},
        {pos: [4, 0, 12], state: "minecraft:stone_bricks"},
        {pos: [4, 0, 13], state: "minecraft:stone_bricks"},
        {pos: [4, 0, 14], state: "minecraft:stone_bricks"},
        {pos: [4, 0, 15], state: "minecraft:stone_bricks"},
        {pos: [4, 0, 16], state: "minecraft:stone_bricks"},
        {pos: [4, 0, 17], state: "minecraft:stone_bricks"},
        {pos: [4, 0, 18], state: "minecraft:stone_bricks"},
        {pos: [4, 0, 19], state: "minecraft:stone_bricks"},
        {pos: [4, 0, 20], state: "minecraft:stone_bricks"},
        {pos: [4, 0, 21], state: "minecraft:stone_bricks"},
        {pos: [4, 0, 22], state: "minecraft:stone_bricks"},
        {pos: [5, 0, 0], state: "minecraft:stone_bricks"},
        {pos: [5, 0, 1], state: "minecraft:stone_bricks"},
        {pos: [5, 0, 2], state: "minecraft:stone_bricks"},
        {pos: [5, 0, 3], state: "minecraft:stone_bricks"},
        {pos: [5, 0, 4], state: "minecraft:stone_bricks"},
        {pos: [5, 0, 5], state: "minecraft:stone_bricks"},
        {pos: [5, 0, 6], state: "minecraft:stone_bricks"},
        {pos: [5, 0, 7], state: "minecraft:stone_bricks"},
        {pos: [5, 0, 8], state: "minecraft:stone_bricks"},
        {pos: [5, 0, 9], state: "minecraft:stone_bricks"},
        {pos: [5, 0, 10], state: "minecraft:stone_bricks"},
        {pos: [5, 0, 11], state: "minecraft:stone_bricks"},
        {pos: [5, 0, 12], state: "minecraft:stone_bricks"},
        {pos: [5, 0, 13], state: "minecraft:stone_bricks"},
        {pos: [5, 0, 14], state: "minecraft:stone_bricks"},
        {pos: [5, 0, 15], state: "minecraft:stone_bricks"},
        {pos: [5, 0, 16], state: "minecraft:stone_bricks"},
        {pos: [5, 0, 17], state: "minecraft:stone_bricks"},
        {pos: [5, 0, 18], state: "minecraft:stone_bricks"},
        {pos: [5, 0, 19], state: "minecraft:stone_bricks"},
        {pos: [5, 0, 20], state: "minecraft:stone_bricks"},
        {pos: [5, 0, 21], state: "minecraft:stone_bricks"},
        {pos: [6, 0, 1], state: "minecraft:stone_bricks"},
        {pos: [6, 0, 2], state: "minecraft:stone_bricks"},
        {pos: [6, 0, 3], state: "minecraft:stone_bricks"},
        {pos: [6, 0, 4], state: "minecraft:stone_bricks"},
        {pos: [6, 0, 5], state: "minecraft:stone_bricks"},
        {pos: [6, 0, 6], state: "minecraft:stone_bricks"},
        {pos: [6, 0, 11], state: "minecraft:stone_bricks"},
        {pos: [6, 0, 12], state: "minecraft:stone_bricks"},
        {pos: [6, 0, 13], state: "minecraft:stone_bricks"},
        {pos: [6, 0, 14], state: "minecraft:stone_bricks"},
        {pos: [6, 0, 15], state: "minecraft:stone_bricks"},
        {pos: [6, 0, 16], state: "minecraft:stone_bricks"},
        {pos: [6, 0, 17], state: "minecraft:stone_bricks"},
        {pos: [6, 0, 18], state: "minecraft:stone_bricks"},
        {pos: [6, 0, 19], state: "minecraft:stone_bricks"},
        {pos: [6, 0, 20], state: "minecraft:stone_bricks"},
        {pos: [7, 0, 2], state: "minecraft:stone_bricks"},
        {pos: [7, 0, 3], state: "minecraft:stone_bricks"},
        {pos: [7, 0, 4], state: "minecraft:stone_bricks"},
        {pos: [7, 0, 5], state: "minecraft:stone_bricks"},
        {pos: [7, 0, 12], state: "minecraft:stone_bricks"},
        {pos: [7, 0, 13], state: "minecraft:stone_bricks"},
        {pos: [7, 0, 14], state: "minecraft:stone_bricks"},
        {pos: [8, 0, 2], state: "minecraft:stone_bricks"},
        {pos: [8, 0, 3], state: "minecraft:stone_bricks"},
        {pos: [8, 0, 4], state: "minecraft:stone_bricks"},
        {pos: [8, 0, 12], state: "minecraft:stone_bricks"},
        {pos: [8, 0, 13], state: "minecraft:stone_bricks"},
        {pos: [8, 0, 14], state: "minecraft:stone_bricks"},
        {pos: [9, 0, 3], state: "minecraft:stone_bricks"},
        {pos: [9, 0, 12], state: "minecraft:stone_bricks"},
        {pos: [9, 0, 13], state: "minecraft:stone_bricks"},
        {pos: [9, 0, 14], state: "minecraft:stone_bricks"},
        {pos: [10, 0, 12], state: "minecraft:stone_bricks"},
        {pos: [10, 0, 13], state: "minecraft:stone_bricks"},
        {pos: [10, 0, 14], state: "minecraft:stone_bricks"},
        {pos: [11, 0, 12], state: "minecraft:stone_bricks"},
        {pos: [11, 0, 13], state: "minecraft:stone_bricks"},
        {pos: [11, 0, 14], state: "minecraft:stone_bricks"},
        {pos: [12, 0, 11], state: "minecraft:stone_bricks"},
        {pos: [12, 0, 12], state: "minecraft:stone_bricks"},
        {pos: [12, 0, 13], state: "minecraft:stone_bricks"},
        {pos: [12, 0, 14], state: "minecraft:stone_bricks"},
        {pos: [12, 0, 15], state: "minecraft:stone_bricks"},
        {pos: [13, 0, 11], state: "minecraft:stone_bricks"},
        {pos: [13, 0, 12], state: "minecraft:stone_bricks"},
        {pos: [13, 0, 13], state: "minecraft:stone_bricks"},
        {pos: [13, 0, 14], state: "minecraft:stone_bricks"},
        {pos: [13, 0, 15], state: "minecraft:stone_bricks"},
        {pos: [14, 0, 9], state: "minecraft:stone_bricks"},
        {pos: [14, 0, 10], state: "minecraft:stone_bricks"},
        {pos: [14, 0, 11], state: "minecraft:stone_bricks"},
        {pos: [14, 0, 12], state: "minecraft:stone_bricks"},
        {pos: [14, 0, 13], state: "minecraft:stone_bricks"},
        {pos: [14, 0, 14], state: "minecraft:stone_bricks"},
        {pos: [14, 0, 15], state: "minecraft:stone_bricks"},
        {pos: [15, 0, 8], state: "minecraft:stone_bricks"},
        {pos: [15, 0, 9], state: "minecraft:stone_bricks"},
        {pos: [15, 0, 10], state: "minecraft:stone_bricks"},
        {pos: [15, 0, 11], state: "minecraft:stone_bricks"},
        {pos: [15, 0, 12], state: "minecraft:stone_bricks"},
        {pos: [15, 0, 13], state: "minecraft:stone_bricks"},
        {pos: [15, 0, 14], state: "minecraft:stone_bricks"},
        {pos: [15, 0, 15], state: "minecraft:stone_bricks"},
        {pos: [16, 0, 9], state: "minecraft:stone_bricks"},
        {pos: [16, 0, 10], state: "minecraft:stone_bricks"},
        {pos: [16, 0, 11], state: "minecraft:stone_bricks"},
        {pos: [16, 0, 12], state: "minecraft:stone_bricks"},
        {pos: [16, 0, 13], state: "minecraft:stone_bricks"},
        {pos: [16, 0, 14], state: "minecraft:stone_bricks"},
        {pos: [17, 0, 10], state: "minecraft:stone_bricks"},
        {pos: [17, 0, 11], state: "minecraft:stone_bricks"},
        {pos: [17, 0, 12], state: "minecraft:stone_bricks"},
        {pos: [17, 0, 13], state: "minecraft:stone_bricks"},
        {pos: [2, 1, 3], state: "minecraft:stone_bricks"},
        {pos: [2, 1, 4], state: "minecraft:stone_bricks"},
        {pos: [2, 1, 5], state: "minecraft:stone_bricks"},
        {pos: [2, 1, 11], state: "minecraft:stone_bricks"},
        {pos: [2, 1, 12], state: "minecraft:stone_bricks"},
        {pos: [2, 1, 13], state: "minecraft:stone_bricks"},
        {pos: [2, 1, 14], state: "minecraft:stone_bricks"},
        {pos: [2, 1, 15], state: "minecraft:stone_bricks"},
        {pos: [2, 1, 16], state: "minecraft:stone_bricks"},
        {pos: [2, 1, 17], state: "minecraft:stone_bricks"},
        {pos: [2, 1, 18], state: "minecraft:stone_bricks"},
        {pos: [2, 1, 19], state: "minecraft:stone_bricks"},
        {pos: [2, 1, 20], state: "minecraft:stone_bricks"},
        {pos: [2, 1, 21], state: "minecraft:stone_bricks"},
        {pos: [2, 1, 22], state: "minecraft:stone_bricks"},
        {pos: [3, 1, 1], state: "minecraft:stone_bricks"},
        {pos: [3, 1, 2], state: "minecraft:stone_bricks"},
        {pos: [3, 1, 3], state: "minecraft:water{level:0}"},
        {pos: [3, 1, 4], state: "minecraft:stone_bricks"},
        {pos: [3, 1, 5], state: "minecraft:stone_bricks"},
        {pos: [3, 1, 6], state: "minecraft:stone_bricks"},
        {pos: [3, 1, 7], state: "minecraft:stone_bricks"},
        {pos: [3, 1, 8], state: "minecraft:stone_bricks"},
        {pos: [3, 1, 9], state: "minecraft:stone_bricks"},
        {pos: [3, 1, 10], state: "minecraft:stone_bricks"},
        {pos: [3, 1, 11], state: "minecraft:stone_bricks"},
        {pos: [3, 1, 12], state: "minecraft:water{level:0}"},
        {pos: [3, 1, 13], state: "minecraft:gravel"},
        {pos: [3, 1, 14], state: "minecraft:gravel"},
        {pos: [3, 1, 15], state: "minecraft:gravel"},
        {pos: [3, 1, 16], state: "minecraft:gravel"},
        {pos: [3, 1, 17], state: "minecraft:gravel"},
        {pos: [3, 1, 18], state: "minecraft:gravel"},
        {pos: [3, 1, 19], state: "minecraft:gravel"},
        {pos: [3, 1, 20], state: "minecraft:gravel"},
        {pos: [3, 1, 21], state: "minecraft:water{level:8}"},
        {pos: [3, 1, 22], state: "minecraft:stone_bricks"},
        {pos: [4, 1, 0], state: "minecraft:stone_bricks"},
        {pos: [4, 1, 1], state: "minecraft:stone_bricks"},
        {pos: [4, 1, 2], state: "minecraft:water{level:0}"},
        {pos: [4, 1, 3], state: "minecraft:water{level:0}"},
        {pos: [4, 1, 4], state: "minecraft:decorated_pot{cracked:false,facing:north,waterlogged:true}", nbt: {id: "minecraft:decorated_pot"}},
        {pos: [4, 1, 5], state: "minecraft:water{level:0}"},
        {pos: [4, 1, 6], state: "minecraft:gravel"},
        {pos: [4, 1, 7], state: "minecraft:gravel"},
        {pos: [4, 1, 8], state: "minecraft:water{level:0}"},
        {pos: [4, 1, 9], state: "minecraft:water{level:0}"},
        {pos: [4, 1, 10], state: "minecraft:water{level:0}"},
        {pos: [4, 1, 11], state: "minecraft:water{level:0}"},
        {pos: [4, 1, 12], state: "minecraft:water{level:0}"},
        {pos: [4, 1, 13], state: "minecraft:water{level:0}"},
        {pos: [4, 1, 14], state: "minecraft:gravel"},
        {pos: [4, 1, 15], state: "minecraft:gravel"},
        {pos: [4, 1, 16], state: "minecraft:gravel"},
        {pos: [4, 1, 17], state: "minecraft:gravel"},
        {pos: [4, 1, 18], state: "minecraft:gravel"},
        {pos: [4, 1, 19], state: "minecraft:gravel"},
        {pos: [4, 1, 20], state: "minecraft:water{level:8}"},
        {pos: [4, 1, 21], state: "minecraft:water{level:8}"},
        {pos: [4, 1, 22], state: "minecraft:stone_bricks"},
        {pos: [5, 1, 0], state: "minecraft:stone_bricks"},
        {pos: [5, 1, 1], state: "minecraft:decorated_pot{cracked:false,facing:north,waterlogged:true}", nbt: {id: "minecraft:decorated_pot"}},
        {pos: [5, 1, 2], state: "minecraft:water{level:0}"},
        {pos: [5, 1, 3], state: "minecraft:water{level:0}"},
        {pos: [5, 1, 4], state: "minecraft:water{level:0}"},
        {pos: [5, 1, 5], state: "minecraft:water{level:0}"},
        {pos: [5, 1, 6], state: "minecraft:stone_bricks"},
        {pos: [5, 1, 7], state: "minecraft:stone_bricks"},
        {pos: [5, 1, 8], state: "minecraft:stone_bricks"},
        {pos: [5, 1, 9], state: "minecraft:stone_bricks"},
        {pos: [5, 1, 10], state: "minecraft:stone_bricks"},
        {pos: [5, 1, 11], state: "minecraft:stone_bricks"},
        {pos: [5, 1, 12], state: "minecraft:gravel"},
        {pos: [5, 1, 13], state: "minecraft:water{level:0}"},
        {pos: [5, 1, 14], state: "minecraft:water{level:0}"},
        {pos: [5, 1, 15], state: "minecraft:stone_bricks"},
        {pos: [5, 1, 16], state: "minecraft:gravel"},
        {pos: [5, 1, 17], state: "minecraft:gravel"},
        {pos: [5, 1, 18], state: "minecraft:gravel"},
        {pos: [5, 1, 19], state: "minecraft:gravel"},
        {pos: [5, 1, 20], state: "minecraft:water{level:8}"},
        {pos: [5, 1, 21], state: "minecraft:stone_bricks"},
        {pos: [6, 1, 1], state: "minecraft:stone_bricks"},
        {pos: [6, 1, 2], state: "minecraft:decorated_pot{cracked:false,facing:north,waterlogged:true}", nbt: {id: "minecraft:decorated_pot"}},
        {pos: [6, 1, 3], state: "minecraft:water{level:0}"},
        {pos: [6, 1, 4], state: "minecraft:stone_bricks"},
        {pos: [6, 1, 5], state: "minecraft:stone_bricks"},
        {pos: [6, 1, 6], state: "minecraft:stone_bricks"},
        {pos: [6, 1, 11], state: "minecraft:stone_bricks"},
        {pos: [6, 1, 12], state: "minecraft:stone_bricks"},
        {pos: [6, 1, 13], state: "minecraft:water{level:0}"},
        {pos: [6, 1, 14], state: "minecraft:stone_bricks"},
        {pos: [6, 1, 15], state: "minecraft:stone_bricks"},
        {pos: [6, 1, 16], state: "minecraft:stone_bricks"},
        {pos: [6, 1, 17], state: "minecraft:stone_bricks"},
        {pos: [6, 1, 18], state: "minecraft:stone_bricks"},
        {pos: [6, 1, 19], state: "minecraft:stone_bricks"},
        {pos: [6, 1, 20], state: "minecraft:stone_bricks"},
        {pos: [7, 1, 2], state: "minecraft:stone_bricks"},
        {pos: [7, 1, 3], state: "minecraft:stone_bricks"},
        {pos: [7, 1, 4], state: "minecraft:stone_bricks"},
        {pos: [7, 1, 5], state: "minecraft:stone_bricks"},
        {pos: [7, 1, 12], state: "minecraft:stone_bricks"},
        {pos: [7, 1, 13], state: "minecraft:water{level:0}"},
        {pos: [7, 1, 14], state: "minecraft:stone_bricks"},
        {pos: [8, 1, 2], state: "minecraft:stone_bricks"},
        {pos: [8, 1, 3], state: "minecraft:stone_bricks"},
        {pos: [8, 1, 4], state: "minecraft:stone_bricks"},
        {pos: [8, 1, 12], state: "minecraft:stone_bricks"},
        {pos: [8, 1, 13], state: "minecraft:water{level:0}"},
        {pos: [8, 1, 14], state: "minecraft:stone_bricks"},
        {pos: [9, 1, 2], state: "minecraft:stone_bricks"},
        {pos: [9, 1, 3], state: "minecraft:stone_bricks"},
        {pos: [9, 1, 4], state: "minecraft:stone_bricks"},
        {pos: [9, 1, 12], state: "minecraft:stone_bricks"},
        {pos: [9, 1, 13], state: "minecraft:gravel"},
        {pos: [9, 1, 14], state: "minecraft:stone_bricks"},
        {pos: [10, 1, 12], state: "minecraft:stone_bricks"},
        {pos: [10, 1, 13], state: "minecraft:gravel"},
        {pos: [10, 1, 14], state: "minecraft:stone_bricks"},
        {pos: [11, 1, 12], state: "minecraft:stone_bricks"},
        {pos: [11, 1, 13], state: "minecraft:gravel"},
        {pos: [11, 1, 14], state: "minecraft:stone_bricks"},
        {pos: [12, 1, 11], state: "minecraft:stone_bricks"},
        {pos: [12, 1, 12], state: "minecraft:water_cauldron{level:3}"},
        {pos: [12, 1, 13], state: "minecraft:gravel"},
        {pos: [12, 1, 14], state: "minecraft:stone_bricks"},
        {pos: [12, 1, 15], state: "minecraft:stone_bricks"},
        {pos: [13, 1, 11], state: "minecraft:stone_bricks"},
        {pos: [13, 1, 12], state: "minecraft:water{level:0}"},
        {pos: [13, 1, 13], state: "minecraft:water{level:0}"},
        {pos: [13, 1, 14], state: "minecraft:decorated_pot{cracked:false,facing:north,waterlogged:true}", nbt: {id: "minecraft:decorated_pot"}},
        {pos: [13, 1, 15], state: "minecraft:stone_bricks"},
        {pos: [14, 1, 9], state: "minecraft:stone_bricks"},
        {pos: [14, 1, 10], state: "minecraft:stone_bricks"},
        {pos: [14, 1, 11], state: "minecraft:gravel"},
        {pos: [14, 1, 12], state: "minecraft:water{level:0}"},
        {pos: [14, 1, 13], state: "minecraft:water{level:0}"},
        {pos: [14, 1, 14], state: "minecraft:water_cauldron{level:3}"},
        {pos: [14, 1, 15], state: "minecraft:stone_bricks"},
        {pos: [15, 1, 8], state: "minecraft:stone_bricks"},
        {pos: [15, 1, 9], state: "minecraft:gravel"},
        {pos: [15, 1, 10], state: "minecraft:gravel"},
        {pos: [15, 1, 11], state: "minecraft:gravel"},
        {pos: [15, 1, 12], state: "minecraft:decorated_pot{cracked:false,facing:north,waterlogged:true}", nbt: {id: "minecraft:decorated_pot"}},
        {pos: [15, 1, 13], state: "minecraft:gravel"},
        {pos: [15, 1, 14], state: "minecraft:stone_bricks"},
        {pos: [15, 1, 15], state: "minecraft:stone_bricks"},
        {pos: [16, 1, 8], state: "minecraft:stone_bricks"},
        {pos: [16, 1, 9], state: "minecraft:stone_bricks"},
        {pos: [16, 1, 10], state: "minecraft:stone_bricks"},
        {pos: [16, 1, 11], state: "minecraft:stone_bricks"},
        {pos: [16, 1, 12], state: "minecraft:water{level:0}"},
        {pos: [16, 1, 13], state: "minecraft:stone_bricks"},
        {pos: [16, 1, 14], state: "minecraft:stone_bricks"},
        {pos: [17, 1, 10], state: "minecraft:stone_bricks"},
        {pos: [17, 1, 11], state: "minecraft:stone_bricks"},
        {pos: [17, 1, 12], state: "minecraft:stone_bricks"},
        {pos: [17, 1, 13], state: "minecraft:stone_bricks"},
        {pos: [2, 2, 3], state: "minecraft:stone_bricks"},
        {pos: [2, 2, 4], state: "minecraft:stone_bricks"},
        {pos: [2, 2, 5], state: "minecraft:stone_bricks"},
        {pos: [2, 2, 11], state: "minecraft:stone_bricks"},
        {pos: [2, 2, 12], state: "minecraft:stone_bricks"},
        {pos: [2, 2, 13], state: "minecraft:stone_bricks"},
        {pos: [2, 2, 14], state: "minecraft:stone_bricks"},
        {pos: [2, 2, 15], state: "minecraft:stone_bricks"},
        {pos: [2, 2, 16], state: "minecraft:stone_bricks"},
        {pos: [2, 2, 17], state: "minecraft:stone_bricks"},
        {pos: [2, 2, 18], state: "minecraft:stone_bricks"},
        {pos: [2, 2, 19], state: "minecraft:stone_bricks"},
        {pos: [2, 2, 20], state: "minecraft:stone_bricks"},
        {pos: [2, 2, 21], state: "minecraft:stone_bricks"},
        {pos: [2, 2, 22], state: "minecraft:stone_bricks"},
        {pos: [3, 2, 1], state: "minecraft:stone_bricks"},
        {pos: [3, 2, 2], state: "minecraft:stone_bricks"},
        {pos: [3, 2, 3], state: "minecraft:cave_air"},
        {pos: [3, 2, 4], state: "minecraft:candle{candles:4,lit:false,waterlogged:false}"},
        {pos: [3, 2, 5], state: "minecraft:stone_bricks"},
        {pos: [3, 2, 6], state: "minecraft:stone_bricks"},
        {pos: [3, 2, 7], state: "minecraft:stone_bricks"},
        {pos: [3, 2, 8], state: "minecraft:stone_bricks"},
        {pos: [3, 2, 9], state: "minecraft:stone_bricks"},
        {pos: [3, 2, 10], state: "minecraft:stone_bricks"},
        {pos: [3, 2, 11], state: "minecraft:stone_bricks"},
        {pos: [3, 2, 12], state: "minecraft:cave_air"},
        {pos: [3, 2, 13], state: "minecraft:cave_air"},
        {pos: [3, 2, 14], state: "minecraft:decorated_pot{cracked:false,facing:north,waterlogged:false}", nbt: {id: "minecraft:decorated_pot", sherds: ["minecraft:brick", "minecraft:brick", "minecraft:brick", "minecraft:burn_pottery_sherd"]}},
        {pos: [3, 2, 15], state: "minecraft:stone_bricks"},
        {pos: [3, 2, 16], state: "minecraft:gravel"},
        {pos: [3, 2, 17], state: "minecraft:gravel"},
        {pos: [3, 2, 18], state: "minecraft:gravel"},
        {pos: [3, 2, 19], state: "minecraft:water{level:0}"},
        {pos: [3, 2, 20], state: "minecraft:water{level:8}"},
        {pos: [3, 2, 21], state: "minecraft:water{level:8}"},
        {pos: [3, 2, 22], state: "minecraft:stone_bricks"},
        {pos: [4, 2, 0], state: "minecraft:stone_bricks"},
        {pos: [4, 2, 1], state: "minecraft:candle{candles:4,lit:false,waterlogged:false}"},
        {pos: [4, 2, 2], state: "minecraft:cave_air"},
        {pos: [4, 2, 3], state: "minecraft:cave_air"},
        {pos: [4, 2, 4], state: "minecraft:cave_air"},
        {pos: [4, 2, 5], state: "minecraft:cave_air"},
        {pos: [4, 2, 6], state: "minecraft:gravel"},
        {pos: [4, 2, 7], state: "minecraft:gravel"},
        {pos: [4, 2, 8], state: "minecraft:cave_air"},
        {pos: [4, 2, 9], state: "minecraft:cave_air"},
        {pos: [4, 2, 10], state: "minecraft:cave_air"},
        {pos: [4, 2, 11], state: "minecraft:cave_air"},
        {pos: [4, 2, 12], state: "minecraft:cave_air"},
        {pos: [4, 2, 13], state: "minecraft:cave_air"},
        {pos: [4, 2, 14], state: "minecraft:cave_air"},
        {pos: [4, 2, 15], state: "minecraft:gravel"},
        {pos: [4, 2, 16], state: "minecraft:gravel"},
        {pos: [4, 2, 17], state: "minecraft:gravel"},
        {pos: [4, 2, 18], state: "minecraft:gravel"},
        {pos: [4, 2, 19], state: "minecraft:water{level:8}"},
        {pos: [4, 2, 20], state: "minecraft:water{level:8}"},
        {pos: [4, 2, 21], state: "minecraft:water{level:8}"},
        {pos: [4, 2, 22], state: "minecraft:stone_bricks"},
        {pos: [5, 2, 0], state: "minecraft:stone_bricks"},
        {pos: [5, 2, 1], state: "minecraft:cave_air"},
        {pos: [5, 2, 2], state: "minecraft:cave_air"},
        {pos: [5, 2, 3], state: "minecraft:cave_air"},
        {pos: [5, 2, 4], state: "minecraft:cave_air"},
        {pos: [5, 2, 5], state: "minecraft:cave_air"},
        {pos: [5, 2, 6], state: "minecraft:stone_bricks"},
        {pos: [5, 2, 7], state: "minecraft:stone_bricks"},
        {pos: [5, 2, 8], state: "minecraft:stone_bricks"},
        {pos: [5, 2, 9], state: "minecraft:stone_bricks"},
        {pos: [5, 2, 10], state: "minecraft:stone_bricks"},
        {pos: [5, 2, 11], state: "minecraft:stone_bricks"},
        {pos: [5, 2, 12], state: "minecraft:cave_air"},
        {pos: [5, 2, 13], state: "minecraft:cave_air"},
        {pos: [5, 2, 14], state: "minecraft:cave_air"},
        {pos: [5, 2, 15], state: "minecraft:stone_bricks"},
        {pos: [5, 2, 16], state: "minecraft:gravel"},
        {pos: [5, 2, 17], state: "minecraft:gravel"},
        {pos: [5, 2, 18], state: "minecraft:gravel"},
        {pos: [5, 2, 19], state: "minecraft:gravel"},
        {pos: [5, 2, 20], state: "minecraft:water{level:8}"},
        {pos: [5, 2, 21], state: "minecraft:stone_bricks"},
        {pos: [6, 2, 1], state: "minecraft:stone_bricks"},
        {pos: [6, 2, 2], state: "minecraft:cave_air"},
        {pos: [6, 2, 3], state: "minecraft:cave_air"},
        {pos: [6, 2, 4], state: "minecraft:candle{candles:4,lit:false,waterlogged:false}"},
        {pos: [6, 2, 5], state: "minecraft:stone_bricks"},
        {pos: [6, 2, 6], state: "minecraft:stone_bricks"},
        {pos: [6, 2, 11], state: "minecraft:stone_bricks"},
        {pos: [6, 2, 12], state: "minecraft:stone_bricks"},
        {pos: [6, 2, 13], state: "minecraft:cave_air"},
        {pos: [6, 2, 14], state: "minecraft:stone_bricks"},
        {pos: [6, 2, 15], state: "minecraft:stone_bricks"},
        {pos: [6, 2, 16], state: "minecraft:stone_bricks"},
        {pos: [6, 2, 17], state: "minecraft:stone_bricks"},
        {pos: [6, 2, 18], state: "minecraft:stone_bricks"},
        {pos: [6, 2, 19], state: "minecraft:stone_bricks"},
        {pos: [6, 2, 20], state: "minecraft:stone_bricks"},
        {pos: [7, 2, 2], state: "minecraft:stone_bricks"},
        {pos: [7, 2, 3], state: "minecraft:gravel"},
        {pos: [7, 2, 4], state: "minecraft:stone_bricks"},
        {pos: [7, 2, 5], state: "minecraft:stone_bricks"},
        {pos: [7, 2, 12], state: "minecraft:stone_bricks"},
        {pos: [7, 2, 13], state: "minecraft:cave_air"},
        {pos: [7, 2, 14], state: "minecraft:stone_bricks"},
        {pos: [8, 2, 2], state: "minecraft:stone_bricks"},
        {pos: [8, 2, 3], state: "minecraft:gravel"},
        {pos: [8, 2, 4], state: "minecraft:stone_bricks"},
        {pos: [8, 2, 12], state: "minecraft:stone_bricks"},
        {pos: [8, 2, 13], state: "minecraft:cave_air"},
        {pos: [8, 2, 14], state: "minecraft:stone_bricks"},
        {pos: [9, 2, 2], state: "minecraft:stone_bricks"},
        {pos: [9, 2, 3], state: "minecraft:stone_bricks"},
        {pos: [9, 2, 4], state: "minecraft:stone_bricks"},
        {pos: [9, 2, 12], state: "minecraft:stone_bricks"},
        {pos: [9, 2, 13], state: "minecraft:cave_air"},
        {pos: [9, 2, 14], state: "minecraft:stone_bricks"},
        {pos: [10, 2, 12], state: "minecraft:stone_bricks"},
        {pos: [10, 2, 13], state: "minecraft:gravel"},
        {pos: [10, 2, 14], state: "minecraft:stone_bricks"},
        {pos: [11, 2, 12], state: "minecraft:stone_bricks"},
        {pos: [11, 2, 13], state: "minecraft:gravel"},
        {pos: [11, 2, 14], state: "minecraft:stone_bricks"},
        {pos: [12, 2, 11], state: "minecraft:stone_bricks"},
        {pos: [12, 2, 12], state: "minecraft:cave_air"},
        {pos: [12, 2, 13], state: "minecraft:cave_air"},
        {pos: [12, 2, 14], state: "minecraft:candle{candles:4,lit:false,waterlogged:false}"},
        {pos: [12, 2, 15], state: "minecraft:stone_bricks"},
        {pos: [13, 2, 11], state: "minecraft:stone_bricks"},
        {pos: [13, 2, 12], state: "minecraft:cave_air"},
        {pos: [13, 2, 13], state: "minecraft:cave_air"},
        {pos: [13, 2, 14], state: "minecraft:cave_air"},
        {pos: [13, 2, 15], state: "minecraft:stone_bricks"},
        {pos: [14, 2, 8], state: "minecraft:stone_bricks"},
        {pos: [14, 2, 9], state: "minecraft:stone_bricks"},
        {pos: [14, 2, 10], state: "minecraft:stone_bricks"},
        {pos: [14, 2, 11], state: "minecraft:cave_air"},
        {pos: [14, 2, 12], state: "minecraft:cave_air"},
        {pos: [14, 2, 13], state: "minecraft:cave_air"},
        {pos: [14, 2, 14], state: "minecraft:cave_air"},
        {pos: [14, 2, 15], state: "minecraft:stone_bricks"},
        {pos: [15, 2, 8], state: "minecraft:stone_bricks"},
        {pos: [15, 2, 9], state: "minecraft:stone_bricks"},
        {pos: [15, 2, 10], state: "minecraft:gravel"},
        {pos: [15, 2, 11], state: "minecraft:cave_air"},
        {pos: [15, 2, 12], state: "minecraft:cave_air"},
        {pos: [15, 2, 13], state: "minecraft:cave_air"},
        {pos: [15, 2, 14], state: "minecraft:gravel"},
        {pos: [15, 2, 15], state: "minecraft:stone_bricks"},
        {pos: [16, 2, 8], state: "minecraft:stone_bricks"},
        {pos: [16, 2, 9], state: "minecraft:stone_bricks"},
        {pos: [16, 2, 10], state: "minecraft:stone_bricks"},
        {pos: [16, 2, 11], state: "minecraft:candle{candles:4,lit:false,waterlogged:false}"},
        {pos: [16, 2, 12], state: "minecraft:cave_air"},
        {pos: [16, 2, 13], state: "minecraft:gravel"},
        {pos: [16, 2, 14], state: "minecraft:stone_bricks"},
        {pos: [17, 2, 10], state: "minecraft:stone_bricks"},
        {pos: [17, 2, 11], state: "minecraft:stone_bricks"},
        {pos: [17, 2, 12], state: "minecraft:stone_bricks"},
        {pos: [17, 2, 13], state: "minecraft:stone_bricks"},
        {pos: [2, 3, 3], state: "minecraft:stone_bricks"},
        {pos: [2, 3, 4], state: "minecraft:stone_bricks"},
        {pos: [2, 3, 5], state: "minecraft:stone_bricks"},
        {pos: [2, 3, 11], state: "minecraft:stone_bricks"},
        {pos: [2, 3, 12], state: "minecraft:stone_bricks"},
        {pos: [2, 3, 13], state: "minecraft:stone_bricks"},
        {pos: [2, 3, 14], state: "minecraft:stone_bricks"},
        {pos: [2, 3, 15], state: "minecraft:stone_bricks"},
        {pos: [2, 3, 16], state: "minecraft:gravel"},
        {pos: [2, 3, 17], state: "minecraft:gravel"},
        {pos: [2, 3, 18], state: "minecraft:gravel"},
        {pos: [2, 3, 19], state: "minecraft:stone_bricks"},
        {pos: [2, 3, 20], state: "minecraft:stone_bricks"},
        {pos: [2, 3, 21], state: "minecraft:stone_bricks"},
        {pos: [2, 3, 22], state: "minecraft:stone_bricks"},
        {pos: [3, 3, 1], state: "minecraft:stone_bricks"},
        {pos: [3, 3, 2], state: "minecraft:stone_bricks"},
        {pos: [3, 3, 3], state: "minecraft:cave_air"},
        {pos: [3, 3, 4], state: "minecraft:cave_air"},
        {pos: [3, 3, 5], state: "minecraft:decorated_pot{cracked:false,facing:north,waterlogged:false}", nbt: {id: "minecraft:decorated_pot"}},
        {pos: [3, 3, 6], state: "minecraft:stone_bricks"},
        {pos: [3, 3, 7], state: "minecraft:stone_bricks"},
        {pos: [3, 3, 8], state: "minecraft:gravel"},
        {pos: [3, 3, 9], state: "minecraft:gravel"},
        {pos: [3, 3, 10], state: "minecraft:stone_bricks"},
        {pos: [3, 3, 11], state: "minecraft:stone_bricks"},
        {pos: [3, 3, 12], state: "minecraft:cave_air"},
        {pos: [3, 3, 13], state: "minecraft:cave_air"},
        {pos: [3, 3, 14], state: "minecraft:cave_air"},
        {pos: [3, 3, 15], state: "minecraft:stone_bricks"},
        {pos: [3, 3, 16], state: "minecraft:stone_bricks"},
        {pos: [3, 3, 17], state: "minecraft:stone_bricks"},
        {pos: [3, 3, 18], state: "minecraft:stone_bricks"},
        {pos: [3, 3, 19], state: "minecraft:water{level:0}"},
        {pos: [3, 3, 20], state: "minecraft:water{level:0}"},
        {pos: [3, 3, 21], state: "minecraft:water{level:8}"},
        {pos: [3, 3, 22], state: "minecraft:stone_bricks"},
        {pos: [4, 3, 0], state: "minecraft:stone_bricks"},
        {pos: [4, 3, 1], state: "minecraft:cave_air"},
        {pos: [4, 3, 2], state: "minecraft:cave_air"},
        {pos: [4, 3, 3], state: "minecraft:cave_air"},
        {pos: [4, 3, 4], state: "minecraft:cave_air"},
        {pos: [4, 3, 5], state: "minecraft:cave_air"},
        {pos: [4, 3, 6], state: "minecraft:stone_bricks"},
        {pos: [4, 3, 7], state: "minecraft:stone_bricks"},
        {pos: [4, 3, 8], state: "minecraft:stone_bricks"},
        {pos: [4, 3, 9], state: "minecraft:stone_bricks"},
        {pos: [4, 3, 10], state: "minecraft:stone_bricks"},
        {pos: [4, 3, 11], state: "minecraft:stone_bricks"},
        {pos: [4, 3, 12], state: "minecraft:cave_air"},
        {pos: [4, 3, 13], state: "minecraft:cave_air"},
        {pos: [4, 3, 14], state: "minecraft:cave_air"},
        {pos: [4, 3, 15], state: "minecraft:stone_bricks"},
        {pos: [4, 3, 16], state: "minecraft:stone_bricks"},
        {pos: [4, 3, 17], state: "minecraft:stone_bricks"},
        {pos: [4, 3, 18], state: "minecraft:stone_bricks"},
        {pos: [4, 3, 19], state: "minecraft:water{level:8}"},
        {pos: [4, 3, 20], state: "minecraft:water{level:8}"},
        {pos: [4, 3, 21], state: "minecraft:water{level:8}"},
        {pos: [4, 3, 22], state: "minecraft:stone_bricks"},
        {pos: [5, 3, 0], state: "minecraft:stone_bricks"},
        {pos: [5, 3, 1], state: "minecraft:cave_air"},
        {pos: [5, 3, 2], state: "minecraft:cave_air"},
        {pos: [5, 3, 3], state: "minecraft:cave_air"},
        {pos: [5, 3, 4], state: "minecraft:cave_air"},
        {pos: [5, 3, 5], state: "minecraft:cave_air"},
        {pos: [5, 3, 6], state: "minecraft:stone_bricks"},
        {pos: [5, 3, 7], state: "minecraft:stone_bricks"},
        {pos: [5, 3, 8], state: "minecraft:stone_bricks"},
        {pos: [5, 3, 9], state: "minecraft:stone_bricks"},
        {pos: [5, 3, 10], state: "minecraft:stone_bricks"},
        {pos: [5, 3, 11], state: "minecraft:stone_bricks"},
        {pos: [5, 3, 12], state: "minecraft:cave_air"},
        {pos: [5, 3, 13], state: "minecraft:cave_air"},
        {pos: [5, 3, 14], state: "minecraft:cave_air"},
        {pos: [5, 3, 15], state: "minecraft:stone_bricks"},
        {pos: [5, 3, 16], state: "minecraft:stone_bricks"},
        {pos: [5, 3, 17], state: "minecraft:stone_bricks"},
        {pos: [5, 3, 18], state: "minecraft:stone_bricks"},
        {pos: [5, 3, 19], state: "minecraft:water{level:8}"},
        {pos: [5, 3, 20], state: "minecraft:water{level:8}"},
        {pos: [5, 3, 21], state: "minecraft:stone_bricks"},
        {pos: [6, 3, 1], state: "minecraft:stone_bricks"},
        {pos: [6, 3, 2], state: "minecraft:cave_air"},
        {pos: [6, 3, 3], state: "minecraft:cave_air"},
        {pos: [6, 3, 4], state: "minecraft:cave_air"},
        {pos: [6, 3, 5], state: "minecraft:candle{candles:4,lit:false,waterlogged:false}"},
        {pos: [6, 3, 6], state: "minecraft:stone_bricks"},
        {pos: [6, 3, 11], state: "minecraft:stone_bricks"},
        {pos: [6, 3, 12], state: "minecraft:stone_bricks"},
        {pos: [6, 3, 13], state: "minecraft:stone_bricks"},
        {pos: [6, 3, 14], state: "minecraft:stone_bricks"},
        {pos: [6, 3, 15], state: "minecraft:stone_bricks"},
        {pos: [6, 3, 16], state: "minecraft:gravel"},
        {pos: [6, 3, 17], state: "minecraft:gravel"},
        {pos: [6, 3, 18], state: "minecraft:gravel"},
        {pos: [6, 3, 19], state: "minecraft:stone_bricks"},
        {pos: [6, 3, 20], state: "minecraft:stone_bricks"},
        {pos: [7, 3, 2], state: "minecraft:stone_bricks"},
        {pos: [7, 3, 3], state: "minecraft:gravel"},
        {pos: [7, 3, 4], state: "minecraft:stone_bricks"},
        {pos: [7, 3, 5], state: "minecraft:stone_bricks"},
        {pos: [7, 3, 12], state: "minecraft:stone_bricks"},
        {pos: [7, 3, 13], state: "minecraft:stone_bricks"},
        {pos: [7, 3, 14], state: "minecraft:stone_bricks"},
        {pos: [8, 3, 2], state: "minecraft:stone_bricks"},
        {pos: [8, 3, 3], state: "minecraft:gravel"},
        {pos: [8, 3, 4], state: "minecraft:stone_bricks"},
        {pos: [8, 3, 12], state: "minecraft:stone_bricks"},
        {pos: [8, 3, 13], state: "minecraft:stone_bricks"},
        {pos: [8, 3, 14], state: "minecraft:stone_bricks"},
        {pos: [9, 3, 2], state: "minecraft:gravel"},
        {pos: [9, 3, 3], state: "minecraft:stone_bricks"},
        {pos: [9, 3, 4], state: "minecraft:stone_bricks"},
        {pos: [9, 3, 12], state: "minecraft:gravel"},
        {pos: [9, 3, 13], state: "minecraft:stone_bricks"},
        {pos: [9, 3, 14], state: "minecraft:gravel"},
        {pos: [10, 3, 12], state: "minecraft:gravel"},
        {pos: [10, 3, 13], state: "minecraft:stone_bricks"},
        {pos: [10, 3, 14], state: "minecraft:gravel"},
        {pos: [11, 3, 12], state: "minecraft:stone_bricks"},
        {pos: [11, 3, 13], state: "minecraft:stone_bricks"},
        {pos: [11, 3, 14], state: "minecraft:stone_bricks"},
        {pos: [12, 3, 11], state: "minecraft:stone_bricks"},
        {pos: [12, 3, 12], state: "minecraft:cave_air"},
        {pos: [12, 3, 13], state: "minecraft:cave_air"},
        {pos: [12, 3, 14], state: "minecraft:cave_air"},
        {pos: [12, 3, 15], state: "minecraft:stone_bricks"},
        {pos: [13, 3, 11], state: "minecraft:stone_bricks"},
        {pos: [13, 3, 12], state: "minecraft:cave_air"},
        {pos: [13, 3, 13], state: "minecraft:cave_air"},
        {pos: [13, 3, 14], state: "minecraft:cave_air"},
        {pos: [13, 3, 15], state: "minecraft:stone_bricks"},
        {pos: [14, 3, 10], state: "minecraft:stone_bricks"},
        {pos: [14, 3, 11], state: "minecraft:cave_air"},
        {pos: [14, 3, 12], state: "minecraft:cave_air"},
        {pos: [14, 3, 13], state: "minecraft:cave_air"},
        {pos: [14, 3, 14], state: "minecraft:cave_air"},
        {pos: [14, 3, 15], state: "minecraft:stone_bricks"},
        {pos: [15, 3, 10], state: "minecraft:stone_bricks"},
        {pos: [15, 3, 11], state: "minecraft:cave_air"},
        {pos: [15, 3, 12], state: "minecraft:cave_air"},
        {pos: [15, 3, 13], state: "minecraft:cave_air"},
        {pos: [15, 3, 14], state: "minecraft:gravel"},
        {pos: [15, 3, 15], state: "minecraft:stone_bricks"},
        {pos: [16, 3, 10], state: "minecraft:stone_bricks"},
        {pos: [16, 3, 11], state: "minecraft:cave_air"},
        {pos: [16, 3, 12], state: "minecraft:cave_air"},
        {pos: [16, 3, 13], state: "minecraft:air"},
        {pos: [16, 3, 14], state: "minecraft:stone_bricks"},
        {pos: [17, 3, 10], state: "minecraft:stone_bricks"},
        {pos: [17, 3, 11], state: "minecraft:stone_bricks"},
        {pos: [17, 3, 12], state: "minecraft:stone_bricks"},
        {pos: [17, 3, 13], state: "minecraft:stone_bricks"},
        {pos: [0, 4, 13], state: "minecraft:stone_bricks"},
        {pos: [1, 4, 12], state: "minecraft:stone_bricks"},
        {pos: [1, 4, 13], state: "minecraft:stone_bricks"},
        {pos: [1, 4, 14], state: "minecraft:stone_bricks"},
        {pos: [2, 4, 3], state: "minecraft:stone_bricks"},
        {pos: [2, 4, 4], state: "minecraft:stone_bricks"},
        {pos: [2, 4, 5], state: "minecraft:stone_bricks"},
        {pos: [2, 4, 11], state: "minecraft:gravel"},
        {pos: [2, 4, 12], state: "minecraft:stone_bricks"},
        {pos: [2, 4, 13], state: "minecraft:stone_bricks"},
        {pos: [2, 4, 14], state: "minecraft:stone_bricks"},
        {pos: [2, 4, 15], state: "minecraft:stone_bricks"},
        {pos: [2, 4, 16], state: "minecraft:gravel"},
        {pos: [2, 4, 17], state: "minecraft:gravel"},
        {pos: [2, 4, 18], state: "minecraft:gravel"},
        {pos: [2, 4, 19], state: "minecraft:stone_bricks"},
        {pos: [2, 4, 20], state: "minecraft:stone_bricks"},
        {pos: [2, 4, 21], state: "minecraft:stone_bricks"},
        {pos: [2, 4, 22], state: "minecraft:gravel"},
        {pos: [3, 4, 1], state: "minecraft:stone_bricks"},
        {pos: [3, 4, 2], state: "minecraft:stone_bricks"},
        {pos: [3, 4, 3], state: "minecraft:stone_bricks"},
        {pos: [3, 4, 4], state: "minecraft:cave_air"},
        {pos: [3, 4, 5], state: "minecraft:cave_air"},
        {pos: [3, 4, 6], state: "minecraft:stone_bricks"},
        {pos: [3, 4, 7], state: "minecraft:stone_bricks"},
        {pos: [3, 4, 8], state: "minecraft:gravel"},
        {pos: [3, 4, 9], state: "minecraft:gravel"},
        {pos: [3, 4, 10], state: "minecraft:gravel"},
        {pos: [3, 4, 11], state: "minecraft:stone_bricks"},
        {pos: [3, 4, 12], state: "minecraft:cave_air"},
        {pos: [3, 4, 13], state: "minecraft:cave_air"},
        {pos: [3, 4, 14], state: "minecraft:cave_air"},
        {pos: [3, 4, 15], state: "minecraft:stone_bricks"},
        {pos: [3, 4, 16], state: "minecraft:stone_bricks"},
        {pos: [3, 4, 17], state: "minecraft:gravel"},
        {pos: [3, 4, 18], state: "minecraft:stone_bricks"},
        {pos: [3, 4, 19], state: "minecraft:stone_bricks"},
        {pos: [3, 4, 20], state: "minecraft:stone_bricks"},
        {pos: [3, 4, 21], state: "minecraft:water{level:0}"},
        {pos: [3, 4, 22], state: "minecraft:stone_bricks"},
        {pos: [4, 4, 0], state: "minecraft:stone_bricks"},
        {pos: [4, 4, 1], state: "minecraft:cave_air"},
        {pos: [4, 4, 2], state: "minecraft:cave_air"},
        {pos: [4, 4, 3], state: "minecraft:cave_air"},
        {pos: [4, 4, 4], state: "minecraft:cave_air"},
        {pos: [4, 4, 5], state: "minecraft:cave_air"},
        {pos: [4, 4, 6], state: "minecraft:stone_bricks"},
        {pos: [4, 4, 7], state: "minecraft:stone_bricks"},
        {pos: [4, 4, 8], state: "minecraft:stone_bricks"},
        {pos: [4, 4, 9], state: "minecraft:gravel"},
        {pos: [4, 4, 10], state: "minecraft:gravel"},
        {pos: [4, 4, 11], state: "minecraft:stone_bricks"},
        {pos: [4, 4, 12], state: "minecraft:cave_air"},
        {pos: [4, 4, 13], state: "minecraft:cave_air"},
        {pos: [4, 4, 14], state: "minecraft:cave_air"},
        {pos: [4, 4, 15], state: "minecraft:stone_bricks"},
        {pos: [4, 4, 16], state: "minecraft:stone_bricks"},
        {pos: [4, 4, 17], state: "minecraft:stone_bricks"},
        {pos: [4, 4, 18], state: "minecraft:stone_bricks"},
        {pos: [4, 4, 19], state: "minecraft:water{level:8}"},
        {pos: [4, 4, 20], state: "minecraft:water{level:0}"},
        {pos: [4, 4, 21], state: "minecraft:water{level:8}"},
        {pos: [4, 4, 22], state: "minecraft:stone_bricks"},
        {pos: [5, 4, 0], state: "minecraft:stone_bricks"},
        {pos: [5, 4, 1], state: "minecraft:stone_bricks"},
        {pos: [5, 4, 2], state: "minecraft:cave_air"},
        {pos: [5, 4, 3], state: "minecraft:cave_air"},
        {pos: [5, 4, 4], state: "minecraft:cave_air"},
        {pos: [5, 4, 5], state: "minecraft:stone_bricks"},
        {pos: [5, 4, 6], state: "minecraft:stone_bricks"},
        {pos: [5, 4, 7], state: "minecraft:stone_bricks"},
        {pos: [5, 4, 8], state: "minecraft:gravel"},
        {pos: [5, 4, 9], state: "minecraft:gravel"},
        {pos: [5, 4, 10], state: "minecraft:gravel"},
        {pos: [5, 4, 11], state: "minecraft:stone_bricks"},
        {pos: [5, 4, 12], state: "minecraft:cave_air"},
        {pos: [5, 4, 13], state: "minecraft:cave_air"},
        {pos: [5, 4, 14], state: "minecraft:cave_air"},
        {pos: [5, 4, 15], state: "minecraft:stone_bricks"},
        {pos: [5, 4, 16], state: "minecraft:stone_bricks"},
        {pos: [5, 4, 17], state: "minecraft:stone_bricks"},
        {pos: [5, 4, 18], state: "minecraft:stone_bricks"},
        {pos: [5, 4, 19], state: "minecraft:water{level:8}"},
        {pos: [5, 4, 20], state: "minecraft:water{level:8}"},
        {pos: [5, 4, 21], state: "minecraft:stone_bricks"},
        {pos: [6, 4, 1], state: "minecraft:stone_bricks"},
        {pos: [6, 4, 2], state: "minecraft:cave_air"},
        {pos: [6, 4, 3], state: "minecraft:cave_air"},
        {pos: [6, 4, 4], state: "minecraft:stone_bricks"},
        {pos: [6, 4, 5], state: "minecraft:stone_bricks"},
        {pos: [6, 4, 6], state: "minecraft:stone_bricks"},
        {pos: [6, 4, 11], state: "minecraft:gravel"},
        {pos: [6, 4, 12], state: "minecraft:stone_bricks"},
        {pos: [6, 4, 13], state: "minecraft:stone_bricks"},
        {pos: [6, 4, 14], state: "minecraft:stone_bricks"},
        {pos: [6, 4, 15], state: "minecraft:stone_bricks"},
        {pos: [6, 4, 16], state: "minecraft:gravel"},
        {pos: [6, 4, 17], state: "minecraft:gravel"},
        {pos: [6, 4, 18], state: "minecraft:gravel"},
        {pos: [6, 4, 19], state: "minecraft:stone_bricks"},
        {pos: [6, 4, 20], state: "minecraft:stone_bricks"},
        {pos: [7, 4, 2], state: "minecraft:stone_bricks"},
        {pos: [7, 4, 3], state: "minecraft:stone_bricks"},
        {pos: [7, 4, 4], state: "minecraft:stone_bricks"},
        {pos: [7, 4, 5], state: "minecraft:stone_bricks"},
        {pos: [7, 4, 12], state: "minecraft:gravel"},
        {pos: [7, 4, 13], state: "minecraft:gravel"},
        {pos: [7, 4, 14], state: "minecraft:gravel"},
        {pos: [8, 4, 2], state: "minecraft:gravel"},
        {pos: [8, 4, 3], state: "minecraft:stone_bricks"},
        {pos: [8, 4, 4], state: "minecraft:stone_bricks"},
        {pos: [8, 4, 12], state: "minecraft:gravel"},
        {pos: [8, 4, 13], state: "minecraft:gravel"},
        {pos: [8, 4, 14], state: "minecraft:gravel"},
        {pos: [9, 4, 2], state: "minecraft:gravel"},
        {pos: [9, 4, 3], state: "minecraft:gravel"},
        {pos: [9, 4, 4], state: "minecraft:gravel"},
        {pos: [9, 4, 13], state: "minecraft:gravel"},
        {pos: [9, 4, 14], state: "minecraft:gravel"},
        {pos: [10, 4, 13], state: "minecraft:gravel"},
        {pos: [11, 4, 12], state: "minecraft:gravel"},
        {pos: [11, 4, 13], state: "minecraft:gravel"},
        {pos: [11, 4, 14], state: "minecraft:gravel"},
        {pos: [12, 4, 11], state: "minecraft:gravel"},
        {pos: [12, 4, 12], state: "minecraft:stone_bricks"},
        {pos: [12, 4, 13], state: "minecraft:stone_bricks"},
        {pos: [12, 4, 14], state: "minecraft:stone_bricks"},
        {pos: [12, 4, 15], state: "minecraft:stone_bricks"},
        {pos: [13, 4, 11], state: "minecraft:stone_bricks"},
        {pos: [13, 4, 12], state: "minecraft:cave_air"},
        {pos: [13, 4, 13], state: "minecraft:cave_air"},
        {pos: [13, 4, 14], state: "minecraft:stone_bricks"},
        {pos: [13, 4, 15], state: "minecraft:stone_bricks"},
        {pos: [14, 4, 10], state: "minecraft:stone_bricks"},
        {pos: [14, 4, 11], state: "minecraft:cave_air"},
        {pos: [14, 4, 12], state: "minecraft:cave_air"},
        {pos: [14, 4, 13], state: "minecraft:cave_air"},
        {pos: [14, 4, 14], state: "minecraft:cave_air"},
        {pos: [14, 4, 15], state: "minecraft:stone_bricks"},
        {pos: [15, 4, 10], state: "minecraft:stone_bricks"},
        {pos: [15, 4, 11], state: "minecraft:stone_bricks"},
        {pos: [15, 4, 12], state: "minecraft:cave_air"},
        {pos: [15, 4, 13], state: "minecraft:cave_air"},
        {pos: [15, 4, 14], state: "minecraft:stone_bricks"},
        {pos: [15, 4, 15], state: "minecraft:stone_bricks"},
        {pos: [16, 4, 10], state: "minecraft:stone_bricks"},
        {pos: [16, 4, 11], state: "minecraft:stone_bricks"},
        {pos: [16, 4, 12], state: "minecraft:stone_bricks"},
        {pos: [16, 4, 13], state: "minecraft:stone_bricks"},
        {pos: [16, 4, 14], state: "minecraft:stone_bricks"},
        {pos: [17, 4, 10], state: "minecraft:stone_bricks"},
        {pos: [17, 4, 11], state: "minecraft:stone_bricks"},
        {pos: [17, 4, 12], state: "minecraft:stone_bricks"},
        {pos: [17, 4, 13], state: "minecraft:stone_bricks"},
        {pos: [0, 5, 13], state: "minecraft:stone_bricks"},
        {pos: [0, 5, 14], state: "minecraft:stone_bricks"},
        {pos: [1, 5, 12], state: "minecraft:stone_bricks"},
        {pos: [1, 5, 13], state: "minecraft:gravel"},
        {pos: [1, 5, 14], state: "minecraft:stone_bricks"},
        {pos: [2, 5, 3], state: "minecraft:stone_bricks"},
        {pos: [2, 5, 4], state: "minecraft:stone_bricks"},
        {pos: [2, 5, 5], state: "minecraft:stone_bricks"},
        {pos: [2, 5, 11], state: "minecraft:gravel"},
        {pos: [2, 5, 12], state: "minecraft:stone_bricks"},
        {pos: [2, 5, 13], state: "minecraft:gravel"},
        {pos: [2, 5, 14], state: "minecraft:stone_bricks"},
        {pos: [2, 5, 15], state: "minecraft:gravel"},
        {pos: [2, 5, 17], state: "minecraft:gravel"},
        {pos: [2, 5, 18], state: "minecraft:gravel"},
        {pos: [2, 5, 19], state: "minecraft:stone_bricks"},
        {pos: [2, 5, 20], state: "minecraft:stone_bricks"},
        {pos: [2, 5, 21], state: "minecraft:stone_bricks"},
        {pos: [2, 5, 22], state: "minecraft:gravel"},
        {pos: [3, 5, 1], state: "minecraft:stone_bricks"},
        {pos: [3, 5, 2], state: "minecraft:stone_bricks"},
        {pos: [3, 5, 3], state: "minecraft:stone_bricks"},
        {pos: [3, 5, 4], state: "minecraft:cave_air"},
        {pos: [3, 5, 5], state: "minecraft:cave_air"},
        {pos: [3, 5, 6], state: "minecraft:stone_bricks"},
        {pos: [3, 5, 7], state: "minecraft:gravel"},
        {pos: [3, 5, 10], state: "minecraft:gravel"},
        {pos: [3, 5, 11], state: "minecraft:stone_bricks"},
        {pos: [3, 5, 12], state: "minecraft:cave_air"},
        {pos: [3, 5, 13], state: "minecraft:cave_air"},
        {pos: [3, 5, 14], state: "minecraft:cave_air"},
        {pos: [3, 5, 15], state: "minecraft:stone_bricks"},
        {pos: [3, 5, 16], state: "minecraft:gravel"},
        {pos: [3, 5, 17], state: "minecraft:gravel"},
        {pos: [3, 5, 18], state: "minecraft:stone_bricks"},
        {pos: [3, 5, 19], state: "minecraft:stone_bricks"},
        {pos: [3, 5, 20], state: "minecraft:stone_bricks"},
        {pos: [3, 5, 21], state: "minecraft:stone_bricks"},
        {pos: [3, 5, 22], state: "minecraft:stone_bricks"},
        {pos: [4, 5, 0], state: "minecraft:stone_bricks"},
        {pos: [4, 5, 1], state: "minecraft:stone_bricks"},
        {pos: [4, 5, 2], state: "minecraft:cave_air"},
        {pos: [4, 5, 3], state: "minecraft:cave_air"},
        {pos: [4, 5, 4], state: "minecraft:cave_air"},
        {pos: [4, 5, 5], state: "minecraft:cave_air"},
        {pos: [4, 5, 6], state: "minecraft:stone_bricks"},
        {pos: [4, 5, 7], state: "minecraft:stone_bricks"},
        {pos: [4, 5, 8], state: "minecraft:gravel"},
        {pos: [4, 5, 10], state: "minecraft:gravel"},
        {pos: [4, 5, 11], state: "minecraft:stone_bricks"},
        {pos: [4, 5, 12], state: "minecraft:cave_air"},
        {pos: [4, 5, 13], state: "minecraft:cave_air"},
        {pos: [4, 5, 14], state: "minecraft:cave_air"},
        {pos: [4, 5, 15], state: "minecraft:stone_bricks"},
        {pos: [4, 5, 16], state: "minecraft:stone_bricks"},
        {pos: [4, 5, 17], state: "minecraft:gravel"},
        {pos: [4, 5, 18], state: "minecraft:stone_bricks"},
        {pos: [4, 5, 19], state: "minecraft:water{level:0}"},
        {pos: [4, 5, 20], state: "minecraft:water{level:0}"},
        {pos: [4, 5, 21], state: "minecraft:water{level:0}"},
        {pos: [4, 5, 22], state: "minecraft:stone_bricks"},
        {pos: [5, 5, 0], state: "minecraft:stone_bricks"},
        {pos: [5, 5, 1], state: "minecraft:stone_bricks"},
        {pos: [5, 5, 2], state: "minecraft:cave_air"},
        {pos: [5, 5, 3], state: "minecraft:cave_air"},
        {pos: [5, 5, 4], state: "minecraft:air"},
        {pos: [5, 5, 5], state: "minecraft:cave_air"},
        {pos: [5, 5, 6], state: "minecraft:stone_bricks"},
        {pos: [5, 5, 7], state: "minecraft:gravel"},
        {pos: [5, 5, 9], state: "minecraft:gravel"},
        {pos: [5, 5, 10], state: "minecraft:gravel"},
        {pos: [5, 5, 11], state: "minecraft:stone_bricks"},
        {pos: [5, 5, 12], state: "minecraft:cave_air"},
        {pos: [5, 5, 13], state: "minecraft:cave_air"},
        {pos: [5, 5, 14], state: "minecraft:cave_air"},
        {pos: [5, 5, 15], state: "minecraft:stone_bricks"},
        {pos: [5, 5, 16], state: "minecraft:gravel"},
        {pos: [5, 5, 17], state: "minecraft:gravel"},
        {pos: [5, 5, 18], state: "minecraft:stone_bricks"},
        {pos: [5, 5, 19], state: "minecraft:water{level:0}"},
        {pos: [5, 5, 20], state: "minecraft:water{level:0}"},
        {pos: [5, 5, 21], state: "minecraft:stone_bricks"},
        {pos: [6, 5, 1], state: "minecraft:stone_bricks"},
        {pos: [6, 5, 2], state: "minecraft:stone_bricks"},
        {pos: [6, 5, 3], state: "minecraft:cave_air"},
        {pos: [6, 5, 4], state: "minecraft:cave_air"},
        {pos: [6, 5, 5], state: "minecraft:decorated_pot{cracked:false,facing:north,waterlogged:false}", nbt: {id: "minecraft:decorated_pot", sherds: ["minecraft:brick", "minecraft:brick", "minecraft:brick", "minecraft:burn_pottery_sherd"]}},
        {pos: [6, 5, 6], state: "minecraft:stone_bricks"},
        {pos: [6, 5, 11], state: "minecraft:gravel"},
        {pos: [6, 5, 12], state: "minecraft:stone_bricks"},
        {pos: [6, 5, 13], state: "minecraft:stone_bricks"},
        {pos: [6, 5, 14], state: "minecraft:stone_bricks"},
        {pos: [6, 5, 15], state: "minecraft:stone_bricks"},
        {pos: [6, 5, 16], state: "minecraft:gravel"},
        {pos: [6, 5, 17], state: "minecraft:gravel"},
        {pos: [6, 5, 18], state: "minecraft:gravel"},
        {pos: [6, 5, 19], state: "minecraft:stone_bricks"},
        {pos: [6, 5, 20], state: "minecraft:stone_bricks"},
        {pos: [7, 5, 2], state: "minecraft:stone_bricks"},
        {pos: [7, 5, 3], state: "minecraft:stone_bricks"},
        {pos: [7, 5, 4], state: "minecraft:stone_bricks"},
        {pos: [7, 5, 5], state: "minecraft:stone_bricks"},
        {pos: [7, 5, 12], state: "minecraft:gravel"},
        {pos: [7, 5, 13], state: "minecraft:gravel"},
        {pos: [7, 5, 14], state: "minecraft:gravel"},
        {pos: [8, 5, 2], state: "minecraft:gravel"},
        {pos: [8, 5, 3], state: "minecraft:gravel"},
        {pos: [8, 5, 4], state: "minecraft:gravel"},
        {pos: [8, 5, 12], state: "minecraft:gravel"},
        {pos: [8, 5, 13], state: "minecraft:gravel"},
        {pos: [8, 5, 14], state: "minecraft:gravel"},
        {pos: [9, 5, 2], state: "minecraft:gravel"},
        {pos: [9, 5, 3], state: "minecraft:gravel"},
        {pos: [9, 5, 4], state: "minecraft:gravel"},
        {pos: [9, 5, 13], state: "minecraft:gravel"},
        {pos: [11, 5, 12], state: "minecraft:gravel"},
        {pos: [11, 5, 13], state: "minecraft:gravel"},
        {pos: [11, 5, 14], state: "minecraft:gravel"},
        {pos: [12, 5, 11], state: "minecraft:gravel"},
        {pos: [12, 5, 12], state: "minecraft:gravel"},
        {pos: [12, 5, 13], state: "minecraft:gravel"},
        {pos: [12, 5, 14], state: "minecraft:gravel"},
        {pos: [12, 5, 15], state: "minecraft:gravel"},
        {pos: [13, 5, 11], state: "minecraft:gravel"},
        {pos: [13, 5, 12], state: "minecraft:stone_bricks"},
        {pos: [13, 5, 13], state: "minecraft:stone_bricks"},
        {pos: [13, 5, 14], state: "minecraft:gravel"},
        {pos: [13, 5, 15], state: "minecraft:gravel"},
        {pos: [14, 5, 10], state: "minecraft:gravel"},
        {pos: [14, 5, 11], state: "minecraft:stone_bricks"},
        {pos: [14, 5, 12], state: "minecraft:stone_bricks"},
        {pos: [14, 5, 13], state: "minecraft:stone_bricks"},
        {pos: [14, 5, 14], state: "minecraft:stone_bricks"},
        {pos: [14, 5, 15], state: "minecraft:gravel"},
        {pos: [15, 5, 10], state: "minecraft:gravel"},
        {pos: [15, 5, 11], state: "minecraft:stone_bricks"},
        {pos: [15, 5, 12], state: "minecraft:stone_bricks"},
        {pos: [15, 5, 13], state: "minecraft:stone_bricks"},
        {pos: [15, 5, 14], state: "minecraft:stone_bricks"},
        {pos: [15, 5, 15], state: "minecraft:gravel"},
        {pos: [16, 5, 10], state: "minecraft:gravel"},
        {pos: [16, 5, 11], state: "minecraft:stone_bricks"},
        {pos: [16, 5, 12], state: "minecraft:stone_bricks"},
        {pos: [16, 5, 13], state: "minecraft:stone_bricks"},
        {pos: [16, 5, 14], state: "minecraft:gravel"},
        {pos: [17, 5, 10], state: "minecraft:gravel"},
        {pos: [17, 5, 11], state: "minecraft:gravel"},
        {pos: [17, 5, 12], state: "minecraft:gravel"},
        {pos: [17, 5, 13], state: "minecraft:gravel"},
        {pos: [0, 6, 13], state: "minecraft:stone_bricks"},
        {pos: [0, 6, 14], state: "minecraft:stone_bricks"},
        {pos: [1, 6, 12], state: "minecraft:stone_bricks"},
        {pos: [1, 6, 13], state: "minecraft:gravel"},
        {pos: [1, 6, 14], state: "minecraft:stone_bricks"},
        {pos: [2, 6, 3], state: "minecraft:stone_bricks"},
        {pos: [2, 6, 4], state: "minecraft:stone_bricks"},
        {pos: [2, 6, 5], state: "minecraft:stone_bricks"},
        {pos: [2, 6, 11], state: "minecraft:gravel"},
        {pos: [2, 6, 12], state: "minecraft:stone_bricks"},
        {pos: [2, 6, 13], state: "minecraft:gravel"},
        {pos: [2, 6, 14], state: "minecraft:stone_bricks"},
        {pos: [2, 6, 15], state: "minecraft:gravel"},
        {pos: [2, 6, 19], state: "minecraft:gravel"},
        {pos: [2, 6, 20], state: "minecraft:gravel"},
        {pos: [2, 6, 21], state: "minecraft:gravel"},
        {pos: [3, 6, 1], state: "minecraft:stone_bricks"},
        {pos: [3, 6, 2], state: "minecraft:stone_bricks"},
        {pos: [3, 6, 3], state: "minecraft:stone_bricks"},
        {pos: [3, 6, 4], state: "minecraft:cave_air"},
        {pos: [3, 6, 5], state: "minecraft:cave_air"},
        {pos: [3, 6, 6], state: "minecraft:stone_bricks"},
        {pos: [3, 6, 7], state: "minecraft:gravel"},
        {pos: [3, 6, 10], state: "minecraft:gravel"},
        {pos: [3, 6, 11], state: "minecraft:stone_bricks"},
        {pos: [3, 6, 12], state: "minecraft:cave_air"},
        {pos: [3, 6, 13], state: "minecraft:cave_air"},
        {pos: [3, 6, 14], state: "minecraft:cave_air"},
        {pos: [3, 6, 15], state: "minecraft:stone_bricks"},
        {pos: [3, 6, 16], state: "minecraft:gravel"},
        {pos: [3, 6, 17], state: "minecraft:gravel"},
        {pos: [3, 6, 18], state: "minecraft:gravel"},
        {pos: [3, 6, 19], state: "minecraft:stone_bricks"},
        {pos: [3, 6, 20], state: "minecraft:stone_bricks"},
        {pos: [3, 6, 21], state: "minecraft:stone_bricks"},
        {pos: [3, 6, 22], state: "minecraft:gravel"},
        {pos: [4, 6, 0], state: "minecraft:stone_bricks"},
        {pos: [4, 6, 1], state: "minecraft:stone_bricks"},
        {pos: [4, 6, 2], state: "minecraft:stone_bricks"},
        {pos: [4, 6, 3], state: "minecraft:stone_bricks"},
        {pos: [4, 6, 4], state: "minecraft:cave_air"},
        {pos: [4, 6, 5], state: "minecraft:cave_air"},
        {pos: [4, 6, 6], state: "minecraft:stone_bricks"},
        {pos: [4, 6, 7], state: "minecraft:gravel"},
        {pos: [4, 6, 8], state: "minecraft:gravel"},
        {pos: [4, 6, 10], state: "minecraft:gravel"},
        {pos: [4, 6, 11], state: "minecraft:stone_bricks"},
        {pos: [4, 6, 12], state: "minecraft:cave_air"},
        {pos: [4, 6, 13], state: "minecraft:cave_air"},
        {pos: [4, 6, 14], state: "minecraft:cave_air"},
        {pos: [4, 6, 15], state: "minecraft:stone_bricks"},
        {pos: [4, 6, 16], state: "minecraft:gravel"},
        {pos: [4, 6, 17], state: "minecraft:gravel"},
        {pos: [4, 6, 18], state: "minecraft:stone_bricks"},
        {pos: [4, 6, 19], state: "minecraft:stone_bricks"},
        {pos: [4, 6, 20], state: "minecraft:water{level:0}"},
        {pos: [4, 6, 21], state: "minecraft:stone_bricks"},
        {pos: [4, 6, 22], state: "minecraft:gravel"},
        {pos: [5, 6, 0], state: "minecraft:stone_bricks"},
        {pos: [5, 6, 1], state: "minecraft:stone_bricks"},
        {pos: [5, 6, 2], state: "minecraft:stone_bricks"},
        {pos: [5, 6, 3], state: "minecraft:cave_air"},
        {pos: [5, 6, 4], state: "minecraft:cave_air"},
        {pos: [5, 6, 5], state: "minecraft:cave_air"},
        {pos: [5, 6, 6], state: "minecraft:stone_bricks"},
        {pos: [5, 6, 7], state: "minecraft:gravel"},
        {pos: [5, 6, 10], state: "minecraft:gravel"},
        {pos: [5, 6, 11], state: "minecraft:stone_bricks"},
        {pos: [5, 6, 12], state: "minecraft:cave_air"},
        {pos: [5, 6, 13], state: "minecraft:cave_air"},
        {pos: [5, 6, 14], state: "minecraft:cave_air"},
        {pos: [5, 6, 15], state: "minecraft:stone_bricks"},
        {pos: [5, 6, 16], state: "minecraft:gravel"},
        {pos: [5, 6, 17], state: "minecraft:gravel"},
        {pos: [5, 6, 18], state: "minecraft:gravel"},
        {pos: [5, 6, 19], state: "minecraft:stone_bricks"},
        {pos: [5, 6, 20], state: "minecraft:stone_bricks"},
        {pos: [5, 6, 21], state: "minecraft:gravel"},
        {pos: [6, 6, 1], state: "minecraft:stone_bricks"},
        {pos: [6, 6, 2], state: "minecraft:stone_bricks"},
        {pos: [6, 6, 3], state: "minecraft:cave_air"},
        {pos: [6, 6, 4], state: "minecraft:cave_air"},
        {pos: [6, 6, 5], state: "minecraft:cave_air"},
        {pos: [6, 6, 6], state: "minecraft:stone_bricks"},
        {pos: [6, 6, 11], state: "minecraft:gravel"},
        {pos: [6, 6, 12], state: "minecraft:stone_bricks"},
        {pos: [6, 6, 13], state: "minecraft:stone_bricks"},
        {pos: [6, 6, 14], state: "minecraft:stone_bricks"},
        {pos: [6, 6, 15], state: "minecraft:gravel"},
        {pos: [6, 6, 18], state: "minecraft:gravel"},
        {pos: [6, 6, 19], state: "minecraft:gravel"},
        {pos: [6, 6, 20], state: "minecraft:gravel"},
        {pos: [7, 6, 2], state: "minecraft:stone_bricks"},
        {pos: [7, 6, 3], state: "minecraft:stone_bricks"},
        {pos: [7, 6, 4], state: "minecraft:stone_bricks"},
        {pos: [7, 6, 5], state: "minecraft:stone_bricks"},
        {pos: [7, 6, 12], state: "minecraft:gravel"},
        {pos: [7, 6, 13], state: "minecraft:gravel"},
        {pos: [7, 6, 14], state: "minecraft:gravel"},
        {pos: [8, 6, 2], state: "minecraft:gravel"},
        {pos: [8, 6, 3], state: "minecraft:gravel"},
        {pos: [8, 6, 4], state: "minecraft:gravel"},
        {pos: [8, 6, 13], state: "minecraft:gravel"},
        {pos: [9, 6, 3], state: "minecraft:gravel"},
        {pos: [9, 6, 4], state: "minecraft:gravel"},
        {pos: [11, 6, 13], state: "minecraft:gravel"},
        {pos: [12, 6, 11], state: "minecraft:gravel"},
        {pos: [12, 6, 12], state: "minecraft:gravel"},
        {pos: [12, 6, 13], state: "minecraft:gravel"},
        {pos: [12, 6, 14], state: "minecraft:gravel"},
        {pos: [12, 6, 15], state: "minecraft:gravel"},
        {pos: [13, 6, 11], state: "minecraft:gravel"},
        {pos: [13, 6, 12], state: "minecraft:gravel"},
        {pos: [13, 6, 13], state: "minecraft:gravel"},
        {pos: [13, 6, 14], state: "minecraft:gravel"},
        {pos: [13, 6, 15], state: "minecraft:gravel"},
        {pos: [14, 6, 10], state: "minecraft:gravel"},
        {pos: [14, 6, 11], state: "minecraft:gravel"},
        {pos: [14, 6, 12], state: "minecraft:gravel"},
        {pos: [14, 6, 13], state: "minecraft:gravel"},
        {pos: [14, 6, 14], state: "minecraft:gravel"},
        {pos: [14, 6, 15], state: "minecraft:gravel"},
        {pos: [15, 6, 10], state: "minecraft:gravel"},
        {pos: [15, 6, 11], state: "minecraft:gravel"},
        {pos: [15, 6, 12], state: "minecraft:gravel"},
        {pos: [15, 6, 13], state: "minecraft:gravel"},
        {pos: [15, 6, 14], state: "minecraft:gravel"},
        {pos: [15, 6, 15], state: "minecraft:gravel"},
        {pos: [16, 6, 10], state: "minecraft:gravel"},
        {pos: [16, 6, 11], state: "minecraft:gravel"},
        {pos: [16, 6, 12], state: "minecraft:gravel"},
        {pos: [16, 6, 13], state: "minecraft:gravel"},
        {pos: [16, 6, 14], state: "minecraft:gravel"},
        {pos: [17, 6, 10], state: "minecraft:gravel"},
        {pos: [17, 6, 11], state: "minecraft:gravel"},
        {pos: [17, 6, 12], state: "minecraft:gravel"},
        {pos: [17, 6, 13], state: "minecraft:gravel"},
        {pos: [0, 7, 13], state: "minecraft:gravel"},
        {pos: [0, 7, 14], state: "minecraft:gravel"},
        {pos: [1, 7, 12], state: "minecraft:gravel"},
        {pos: [1, 7, 13], state: "minecraft:gravel"},
        {pos: [1, 7, 14], state: "minecraft:gravel"},
        {pos: [2, 7, 3], state: "minecraft:gravel"},
        {pos: [2, 7, 4], state: "minecraft:stone_bricks"},
        {pos: [2, 7, 5], state: "minecraft:stone_bricks"},
        {pos: [2, 7, 12], state: "minecraft:stone_bricks"},
        {pos: [2, 7, 13], state: "minecraft:stone_bricks"},
        {pos: [2, 7, 14], state: "minecraft:stone_bricks"},
        {pos: [2, 7, 19], state: "minecraft:gravel"},
        {pos: [2, 7, 20], state: "minecraft:gravel"},
        {pos: [2, 7, 21], state: "minecraft:gravel"},
        {pos: [3, 7, 1], state: "minecraft:gravel"},
        {pos: [3, 7, 2], state: "minecraft:gravel"},
        {pos: [3, 7, 3], state: "minecraft:stone_bricks"},
        {pos: [3, 7, 4], state: "minecraft:stone_bricks"},
        {pos: [3, 7, 5], state: "minecraft:stone_bricks"},
        {pos: [3, 7, 6], state: "minecraft:gravel"},
        {pos: [3, 7, 11], state: "minecraft:stone_bricks"},
        {pos: [3, 7, 12], state: "minecraft:stone_bricks"},
        {pos: [3, 7, 13], state: "minecraft:cave_air"},
        {pos: [3, 7, 14], state: "minecraft:cave_air"},
        {pos: [3, 7, 15], state: "minecraft:stone_bricks"},
        {pos: [3, 7, 16], state: "minecraft:gravel"},
        {pos: [3, 7, 17], state: "minecraft:gravel"},
        {pos: [3, 7, 18], state: "minecraft:gravel"},
        {pos: [3, 7, 19], state: "minecraft:stone_bricks"},
        {pos: [3, 7, 20], state: "minecraft:stone_bricks"},
        {pos: [3, 7, 21], state: "minecraft:gravel"},
        {pos: [3, 7, 22], state: "minecraft:gravel"},
        {pos: [4, 7, 0], state: "minecraft:gravel"},
        {pos: [4, 7, 1], state: "minecraft:gravel"},
        {pos: [4, 7, 2], state: "minecraft:gravel"},
        {pos: [4, 7, 3], state: "minecraft:stone_bricks"},
        {pos: [4, 7, 4], state: "minecraft:stone_bricks"},
        {pos: [4, 7, 5], state: "minecraft:stone_bricks"},
        {pos: [4, 7, 6], state: "minecraft:gravel"},
        {pos: [4, 7, 7], state: "minecraft:gravel"},
        {pos: [4, 7, 10], state: "minecraft:gravel"},
        {pos: [4, 7, 11], state: "minecraft:stone_bricks"},
        {pos: [4, 7, 12], state: "minecraft:stone_bricks"},
        {pos: [4, 7, 13], state: "minecraft:cave_air"},
        {pos: [4, 7, 14], state: "minecraft:cave_air"},
        {pos: [4, 7, 15], state: "minecraft:stone_bricks"},
        {pos: [4, 7, 16], state: "minecraft:stone_bricks"},
        {pos: [4, 7, 17], state: "minecraft:stone_bricks"},
        {pos: [4, 7, 18], state: "minecraft:stone_bricks"},
        {pos: [4, 7, 19], state: "minecraft:stone_bricks"},
        {pos: [4, 7, 20], state: "minecraft:water{level:0}"},
        {pos: [4, 7, 21], state: "minecraft:stone_bricks"},
        {pos: [4, 7, 22], state: "minecraft:gravel"},
        {pos: [5, 7, 0], state: "minecraft:gravel"},
        {pos: [5, 7, 1], state: "minecraft:gravel"},
        {pos: [5, 7, 2], state: "minecraft:stone_bricks"},
        {pos: [5, 7, 3], state: "minecraft:stone_bricks"},
        {pos: [5, 7, 4], state: "minecraft:cave_air"},
        {pos: [5, 7, 5], state: "minecraft:cave_air"},
        {pos: [5, 7, 6], state: "minecraft:stone_bricks"},
        {pos: [5, 7, 7], state: "minecraft:gravel"},
        {pos: [5, 7, 11], state: "minecraft:stone_bricks"},
        {pos: [5, 7, 12], state: "minecraft:cave_air"},
        {pos: [5, 7, 13], state: "minecraft:cave_air"},
        {pos: [5, 7, 14], state: "minecraft:cave_air"},
        {pos: [5, 7, 15], state: "minecraft:stone_bricks"},
        {pos: [5, 7, 16], state: "minecraft:stone_bricks"},
        {pos: [5, 7, 17], state: "minecraft:stone_bricks"},
        {pos: [5, 7, 18], state: "minecraft:gravel"},
        {pos: [5, 7, 19], state: "minecraft:stone_bricks"},
        {pos: [5, 7, 20], state: "minecraft:stone_bricks"},
        {pos: [5, 7, 21], state: "minecraft:gravel"},
        {pos: [6, 7, 1], state: "minecraft:gravel"},
        {pos: [6, 7, 2], state: "minecraft:stone_bricks"},
        {pos: [6, 7, 3], state: "minecraft:cave_air"},
        {pos: [6, 7, 4], state: "minecraft:cave_air"},
        {pos: [6, 7, 5], state: "minecraft:cave_air"},
        {pos: [6, 7, 6], state: "minecraft:stone_bricks"},
        {pos: [6, 7, 11], state: "minecraft:gravel"},
        {pos: [6, 7, 12], state: "minecraft:stone_bricks"},
        {pos: [6, 7, 13], state: "minecraft:stone_bricks"},
        {pos: [6, 7, 14], state: "minecraft:stone_bricks"},
        {pos: [6, 7, 15], state: "minecraft:gravel"},
        {pos: [6, 7, 19], state: "minecraft:gravel"},
        {pos: [6, 7, 20], state: "minecraft:gravel"},
        {pos: [7, 7, 2], state: "minecraft:gravel"},
        {pos: [7, 7, 3], state: "minecraft:stone_bricks"},
        {pos: [7, 7, 4], state: "minecraft:stone_bricks"},
        {pos: [7, 7, 5], state: "minecraft:stone_bricks"},
        {pos: [7, 7, 12], state: "minecraft:gravel"},
        {pos: [7, 7, 13], state: "minecraft:gravel"},
        {pos: [8, 7, 3], state: "minecraft:gravel"},
        {pos: [8, 7, 4], state: "minecraft:gravel"},
        {pos: [12, 7, 12], state: "minecraft:gravel"},
        {pos: [12, 7, 13], state: "minecraft:gravel"},
        {pos: [12, 7, 14], state: "minecraft:gravel"},
        {pos: [12, 7, 15], state: "minecraft:gravel"},
        {pos: [13, 7, 11], state: "minecraft:gravel"},
        {pos: [13, 7, 12], state: "minecraft:gravel"},
        {pos: [13, 7, 13], state: "minecraft:gravel"},
        {pos: [13, 7, 14], state: "minecraft:gravel"},
        {pos: [13, 7, 15], state: "minecraft:gravel"},
        {pos: [14, 7, 10], state: "minecraft:gravel"},
        {pos: [14, 7, 11], state: "minecraft:gravel"},
        {pos: [14, 7, 12], state: "minecraft:gravel"},
        {pos: [14, 7, 13], state: "minecraft:gravel"},
        {pos: [14, 7, 14], state: "minecraft:gravel"},
        {pos: [14, 7, 15], state: "minecraft:gravel"},
        {pos: [15, 7, 10], state: "minecraft:gravel"},
        {pos: [15, 7, 11], state: "minecraft:gravel"},
        {pos: [15, 7, 12], state: "minecraft:gravel"},
        {pos: [15, 7, 13], state: "minecraft:gravel"},
        {pos: [15, 7, 14], state: "minecraft:gravel"},
        {pos: [15, 7, 15], state: "minecraft:gravel"},
        {pos: [16, 7, 10], state: "minecraft:gravel"},
        {pos: [16, 7, 11], state: "minecraft:gravel"},
        {pos: [16, 7, 12], state: "minecraft:gravel"},
        {pos: [16, 7, 13], state: "minecraft:gravel"},
        {pos: [16, 7, 14], state: "minecraft:gravel"},
        {pos: [17, 7, 10], state: "minecraft:gravel"},
        {pos: [17, 7, 11], state: "minecraft:gravel"},
        {pos: [17, 7, 12], state: "minecraft:gravel"},
        {pos: [17, 7, 13], state: "minecraft:gravel"},
        {pos: [0, 8, 13], state: "minecraft:gravel"},
        {pos: [0, 8, 14], state: "minecraft:gravel"},
        {pos: [1, 8, 12], state: "minecraft:gravel"},
        {pos: [1, 8, 13], state: "minecraft:gravel"},
        {pos: [1, 8, 14], state: "minecraft:gravel"},
        {pos: [2, 8, 4], state: "minecraft:gravel"},
        {pos: [2, 8, 5], state: "minecraft:gravel"},
        {pos: [2, 8, 12], state: "minecraft:stone_bricks"},
        {pos: [2, 8, 13], state: "minecraft:stone_bricks"},
        {pos: [2, 8, 14], state: "minecraft:stone_bricks"},
        {pos: [2, 8, 19], state: "minecraft:gravel"},
        {pos: [2, 8, 20], state: "minecraft:gravel"},
        {pos: [3, 8, 3], state: "minecraft:gravel"},
        {pos: [3, 8, 4], state: "minecraft:gravel"},
        {pos: [3, 8, 5], state: "minecraft:gravel"},
        {pos: [3, 8, 11], state: "minecraft:stone_bricks"},
        {pos: [3, 8, 12], state: "minecraft:stone_bricks"},
        {pos: [3, 8, 13], state: "minecraft:stone_bricks"},
        {pos: [3, 8, 14], state: "minecraft:cave_air"},
        {pos: [3, 8, 15], state: "minecraft:stone_bricks"},
        {pos: [3, 8, 16], state: "minecraft:stone_bricks"},
        {pos: [3, 8, 17], state: "minecraft:stone_bricks"},
        {pos: [3, 8, 18], state: "minecraft:stone_bricks"},
        {pos: [3, 8, 19], state: "minecraft:stone_bricks"},
        {pos: [3, 8, 20], state: "minecraft:stone_bricks"},
        {pos: [3, 8, 21], state: "minecraft:gravel"},
        {pos: [3, 8, 22], state: "minecraft:gravel"},
        {pos: [4, 8, 2], state: "minecraft:gravel"},
        {pos: [4, 8, 3], state: "minecraft:stone_bricks"},
        {pos: [4, 8, 4], state: "minecraft:stone_bricks"},
        {pos: [4, 8, 5], state: "minecraft:stone_bricks"},
        {pos: [4, 8, 6], state: "minecraft:gravel"},
        {pos: [4, 8, 7], state: "minecraft:gravel"},
        {pos: [4, 8, 11], state: "minecraft:stone_bricks"},
        {pos: [4, 8, 12], state: "minecraft:stone_bricks"},
        {pos: [4, 8, 13], state: "minecraft:cave_air"},
        {pos: [4, 8, 14], state: "minecraft:cave_air"},
        {pos: [4, 8, 15], state: "minecraft:stone_bricks"},
        {pos: [4, 8, 16], state: "minecraft:gravel"},
        {pos: [4, 8, 17], state: "minecraft:gravel"},
        {pos: [4, 8, 18], state: "minecraft:stone_bricks"},
        {pos: [4, 8, 19], state: "minecraft:gravel"},
        {pos: [4, 8, 20], state: "minecraft:water{level:8}"},
        {pos: [4, 8, 21], state: "minecraft:stone_bricks"},
        {pos: [4, 8, 22], state: "minecraft:gravel"},
        {pos: [5, 8, 2], state: "minecraft:gravel"},
        {pos: [5, 8, 3], state: "minecraft:stone_bricks"},
        {pos: [5, 8, 4], state: "minecraft:cave_air"},
        {pos: [5, 8, 5], state: "minecraft:cave_air"},
        {pos: [5, 8, 6], state: "minecraft:stone_bricks"},
        {pos: [5, 8, 7], state: "minecraft:gravel"},
        {pos: [5, 8, 11], state: "minecraft:stone_bricks"},
        {pos: [5, 8, 12], state: "minecraft:cave_air"},
        {pos: [5, 8, 13], state: "minecraft:cave_air"},
        {pos: [5, 8, 14], state: "minecraft:cave_air"},
        {pos: [5, 8, 15], state: "minecraft:stone_bricks"},
        {pos: [5, 8, 16], state: "minecraft:stone_bricks"},
        {pos: [5, 8, 17], state: "minecraft:stone_bricks"},
        {pos: [5, 8, 18], state: "minecraft:gravel"},
        {pos: [5, 8, 19], state: "minecraft:stone_bricks"},
        {pos: [5, 8, 20], state: "minecraft:stone_bricks"},
        {pos: [5, 8, 21], state: "minecraft:gravel"},
        {pos: [6, 8, 1], state: "minecraft:gravel"},
        {pos: [6, 8, 2], state: "minecraft:stone_bricks"},
        {pos: [6, 8, 3], state: "minecraft:cave_air"},
        {pos: [6, 8, 4], state: "minecraft:cave_air"},
        {pos: [6, 8, 5], state: "minecraft:stone_bricks"},
        {pos: [6, 8, 6], state: "minecraft:stone_bricks"},
        {pos: [6, 8, 12], state: "minecraft:stone_bricks"},
        {pos: [6, 8, 13], state: "minecraft:stone_bricks"},
        {pos: [6, 8, 14], state: "minecraft:stone_bricks"},
        {pos: [6, 8, 19], state: "minecraft:gravel"},
        {pos: [7, 8, 2], state: "minecraft:gravel"},
        {pos: [7, 8, 3], state: "minecraft:stone_bricks"},
        {pos: [7, 8, 4], state: "minecraft:stone_bricks"},
        {pos: [7, 8, 5], state: "minecraft:stone_bricks"},
        {pos: [7, 8, 12], state: "minecraft:gravel"},
        {pos: [8, 8, 3], state: "minecraft:gravel"},
        {pos: [8, 8, 4], state: "minecraft:gravel"},
        {pos: [13, 8, 12], state: "minecraft:gravel"},
        {pos: [13, 8, 13], state: "minecraft:gravel"},
        {pos: [14, 8, 11], state: "minecraft:gravel"},
        {pos: [14, 8, 12], state: "minecraft:gravel"},
        {pos: [14, 8, 13], state: "minecraft:gravel"},
        {pos: [14, 8, 14], state: "minecraft:gravel"},
        {pos: [15, 8, 11], state: "minecraft:gravel"},
        {pos: [15, 8, 12], state: "minecraft:gravel"},
        {pos: [15, 8, 13], state: "minecraft:gravel"},
        {pos: [15, 8, 14], state: "minecraft:gravel"},
        {pos: [16, 8, 11], state: "minecraft:gravel"},
        {pos: [16, 8, 12], state: "minecraft:gravel"},
        {pos: [16, 8, 13], state: "minecraft:gravel"},
        {pos: [1, 9, 12], state: "minecraft:gravel"},
        {pos: [1, 9, 13], state: "minecraft:gravel"},
        {pos: [1, 9, 14], state: "minecraft:gravel"},
        {pos: [2, 9, 12], state: "minecraft:stone_bricks"},
        {pos: [2, 9, 13], state: "minecraft:stone_bricks"},
        {pos: [2, 9, 14], state: "minecraft:stone_bricks"},
        {pos: [2, 9, 19], state: "minecraft:gravel"},
        {pos: [2, 9, 20], state: "minecraft:gravel"},
        {pos: [3, 9, 3], state: "minecraft:gravel"},
        {pos: [3, 9, 4], state: "minecraft:gravel"},
        {pos: [3, 9, 5], state: "minecraft:gravel"},
        {pos: [3, 9, 11], state: "minecraft:stone_bricks"},
        {pos: [3, 9, 12], state: "minecraft:decorated_pot{cracked:false,facing:north,waterlogged:false}", nbt: {id: "minecraft:decorated_pot"}},
        {pos: [3, 9, 13], state: "minecraft:cave_air"},
        {pos: [3, 9, 14], state: "minecraft:cave_air"},
        {pos: [3, 9, 15], state: "minecraft:stone_bricks"},
        {pos: [3, 9, 16], state: "minecraft:stone_bricks"},
        {pos: [3, 9, 17], state: "minecraft:stone_bricks"},
        {pos: [3, 9, 18], state: "minecraft:stone_bricks"},
        {pos: [3, 9, 19], state: "minecraft:stone_bricks"},
        {pos: [3, 9, 20], state: "minecraft:stone_bricks"},
        {pos: [3, 9, 21], state: "minecraft:gravel"},
        {pos: [4, 9, 3], state: "minecraft:gravel"},
        {pos: [4, 9, 4], state: "minecraft:gravel"},
        {pos: [4, 9, 5], state: "minecraft:gravel"},
        {pos: [4, 9, 6], state: "minecraft:gravel"},
        {pos: [4, 9, 11], state: "minecraft:stone_bricks"},
        {pos: [4, 9, 12], state: "minecraft:air"},
        {pos: [4, 9, 13], state: "minecraft:cave_air"},
        {pos: [4, 9, 14], state: "minecraft:cave_air"},
        {pos: [4, 9, 15], state: "minecraft:stone_bricks"},
        {pos: [4, 9, 16], state: "minecraft:gravel"},
        {pos: [4, 9, 17], state: "minecraft:water{level:0}"},
        {pos: [4, 9, 18], state: "minecraft:water{level:0}"},
        {pos: [4, 9, 19], state: "minecraft:water{level:0}"},
        {pos: [4, 9, 20], state: "minecraft:water{level:0}"},
        {pos: [4, 9, 21], state: "minecraft:stone_bricks"},
        {pos: [4, 9, 22], state: "minecraft:gravel"},
        {pos: [5, 9, 2], state: "minecraft:gravel"},
        {pos: [5, 9, 3], state: "minecraft:stone_bricks"},
        {pos: [5, 9, 4], state: "minecraft:stone_bricks"},
        {pos: [5, 9, 5], state: "minecraft:stone_bricks"},
        {pos: [5, 9, 6], state: "minecraft:stone_bricks"},
        {pos: [5, 9, 7], state: "minecraft:gravel"},
        {pos: [5, 9, 11], state: "minecraft:stone_bricks"},
        {pos: [5, 9, 12], state: "minecraft:cave_air"},
        {pos: [5, 9, 13], state: "minecraft:cave_air"},
        {pos: [5, 9, 14], state: "minecraft:cave_air"},
        {pos: [5, 9, 15], state: "minecraft:stone_bricks"},
        {pos: [5, 9, 16], state: "minecraft:stone_bricks"},
        {pos: [5, 9, 17], state: "minecraft:stone_bricks"},
        {pos: [5, 9, 18], state: "minecraft:stone_bricks"},
        {pos: [5, 9, 19], state: "minecraft:stone_bricks"},
        {pos: [5, 9, 20], state: "minecraft:stone_bricks"},
        {pos: [5, 9, 21], state: "minecraft:gravel"},
        {pos: [6, 9, 2], state: "minecraft:gravel"},
        {pos: [6, 9, 3], state: "minecraft:stone_bricks"},
        {pos: [6, 9, 4], state: "minecraft:stone_bricks"},
        {pos: [6, 9, 5], state: "minecraft:gravel"},
        {pos: [6, 9, 6], state: "minecraft:gravel"},
        {pos: [6, 9, 12], state: "minecraft:stone_bricks"},
        {pos: [6, 9, 13], state: "minecraft:stone_bricks"},
        {pos: [6, 9, 14], state: "minecraft:stone_bricks"},
        {pos: [7, 9, 3], state: "minecraft:gravel"},
        {pos: [7, 9, 4], state: "minecraft:gravel"},
        {pos: [7, 9, 5], state: "minecraft:gravel"},
        {pos: [2, 10, 12], state: "minecraft:stone_bricks"},
        {pos: [2, 10, 13], state: "minecraft:stone_bricks"},
        {pos: [2, 10, 14], state: "minecraft:stone_bricks"},
        {pos: [2, 10, 20], state: "minecraft:gravel"},
        {pos: [3, 10, 4], state: "minecraft:gravel"},
        {pos: [3, 10, 5], state: "minecraft:gravel"},
        {pos: [3, 10, 11], state: "minecraft:stone_bricks"},
        {pos: [3, 10, 12], state: "minecraft:air"},
        {pos: [3, 10, 13], state: "minecraft:cave_air"},
        {pos: [3, 10, 14], state: "minecraft:cave_air"},
        {pos: [3, 10, 15], state: "minecraft:stone_bricks"},
        {pos: [3, 10, 16], state: "minecraft:gravel"},
        {pos: [3, 10, 17], state: "minecraft:gravel"},
        {pos: [3, 10, 18], state: "minecraft:gravel"},
        {pos: [3, 10, 19], state: "minecraft:stone_bricks"},
        {pos: [3, 10, 20], state: "minecraft:stone_bricks"},
        {pos: [3, 10, 21], state: "minecraft:gravel"},
        {pos: [4, 10, 3], state: "minecraft:gravel"},
        {pos: [4, 10, 4], state: "minecraft:gravel"},
        {pos: [4, 10, 5], state: "minecraft:gravel"},
        {pos: [4, 10, 11], state: "minecraft:stone_bricks"},
        {pos: [4, 10, 12], state: "minecraft:air"},
        {pos: [4, 10, 13], state: "minecraft:air"},
        {pos: [4, 10, 14], state: "minecraft:cave_air"},
        {pos: [4, 10, 15], state: "minecraft:stone_bricks"},
        {pos: [4, 10, 16], state: "minecraft:stone_bricks"},
        {pos: [4, 10, 17], state: "minecraft:stone_bricks"},
        {pos: [4, 10, 18], state: "minecraft:stone_bricks"},
        {pos: [4, 10, 19], state: "minecraft:stone_bricks"},
        {pos: [4, 10, 20], state: "minecraft:stone_bricks"},
        {pos: [4, 10, 21], state: "minecraft:gravel"},
        {pos: [5, 10, 2], state: "minecraft:gravel"},
        {pos: [5, 10, 3], state: "minecraft:gravel"},
        {pos: [5, 10, 4], state: "minecraft:gravel"},
        {pos: [5, 10, 5], state: "minecraft:gravel"},
        {pos: [5, 10, 6], state: "minecraft:gravel"},
        {pos: [5, 10, 11], state: "minecraft:stone_bricks"},
        {pos: [5, 10, 12], state: "minecraft:air"},
        {pos: [5, 10, 13], state: "minecraft:cave_air"},
        {pos: [5, 10, 14], state: "minecraft:cave_air"},
        {pos: [5, 10, 15], state: "minecraft:stone_bricks"},
        {pos: [5, 10, 16], state: "minecraft:gravel"},
        {pos: [5, 10, 17], state: "minecraft:gravel"},
        {pos: [5, 10, 18], state: "minecraft:gravel"},
        {pos: [5, 10, 19], state: "minecraft:gravel"},
        {pos: [5, 10, 20], state: "minecraft:gravel"},
        {pos: [6, 10, 2], state: "minecraft:gravel"},
        {pos: [6, 10, 3], state: "minecraft:gravel"},
        {pos: [6, 10, 4], state: "minecraft:gravel"},
        {pos: [6, 10, 5], state: "minecraft:gravel"},
        {pos: [6, 10, 6], state: "minecraft:gravel"},
        {pos: [6, 10, 12], state: "minecraft:stone_bricks"},
        {pos: [6, 10, 13], state: "minecraft:stone_bricks"},
        {pos: [6, 10, 14], state: "minecraft:stone_bricks"},
        {pos: [7, 10, 4], state: "minecraft:gravel"},
        {pos: [7, 10, 5], state: "minecraft:gravel"},
        {pos: [2, 11, 12], state: "minecraft:stone_bricks"},
        {pos: [2, 11, 13], state: "minecraft:stone_bricks"},
        {pos: [2, 11, 14], state: "minecraft:stone_bricks"},
        {pos: [3, 11, 11], state: "minecraft:stone_bricks"},
        {pos: [3, 11, 12], state: "minecraft:stone_bricks"},
        {pos: [3, 11, 13], state: "minecraft:cave_air"},
        {pos: [3, 11, 14], state: "minecraft:cave_air"},
        {pos: [3, 11, 15], state: "minecraft:stone_bricks"},
        {pos: [3, 11, 16], state: "minecraft:gravel"},
        {pos: [3, 11, 17], state: "minecraft:gravel"},
        {pos: [3, 11, 19], state: "minecraft:gravel"},
        {pos: [3, 11, 20], state: "minecraft:gravel"},
        {pos: [4, 11, 3], state: "minecraft:gravel"},
        {pos: [4, 11, 4], state: "minecraft:gravel"},
        {pos: [4, 11, 5], state: "minecraft:gravel"},
        {pos: [4, 11, 11], state: "minecraft:stone_bricks"},
        {pos: [4, 11, 12], state: "minecraft:air"},
        {pos: [4, 11, 13], state: "minecraft:air"},
        {pos: [4, 11, 14], state: "minecraft:stone_bricks"},
        {pos: [4, 11, 15], state: "minecraft:stone_bricks"},
        {pos: [4, 11, 16], state: "minecraft:gravel"},
        {pos: [4, 11, 17], state: "minecraft:gravel"},
        {pos: [4, 11, 18], state: "minecraft:gravel"},
        {pos: [4, 11, 19], state: "minecraft:gravel"},
        {pos: [4, 11, 20], state: "minecraft:gravel"},
        {pos: [4, 11, 21], state: "minecraft:gravel"},
        {pos: [5, 11, 3], state: "minecraft:gravel"},
        {pos: [5, 11, 4], state: "minecraft:gravel"},
        {pos: [5, 11, 5], state: "minecraft:gravel"},
        {pos: [5, 11, 6], state: "minecraft:gravel"},
        {pos: [5, 11, 11], state: "minecraft:stone_bricks"},
        {pos: [5, 11, 12], state: "minecraft:air"},
        {pos: [5, 11, 13], state: "minecraft:stone_bricks"},
        {pos: [5, 11, 14], state: "minecraft:stone_bricks"},
        {pos: [5, 11, 15], state: "minecraft:stone_bricks"},
        {pos: [5, 11, 16], state: "minecraft:gravel"},
        {pos: [5, 11, 17], state: "minecraft:gravel"},
        {pos: [6, 11, 3], state: "minecraft:gravel"},
        {pos: [6, 11, 4], state: "minecraft:gravel"},
        {pos: [6, 11, 5], state: "minecraft:gravel"},
        {pos: [6, 11, 6], state: "minecraft:gravel"},
        {pos: [6, 11, 12], state: "minecraft:stone_bricks"},
        {pos: [6, 11, 13], state: "minecraft:stone_bricks"},
        {pos: [6, 11, 14], state: "minecraft:stone_bricks"},
        {pos: [7, 11, 5], state: "minecraft:gravel"},
        {pos: [1, 12, 13], state: "minecraft:stone_bricks"},
        {pos: [1, 12, 14], state: "minecraft:stone_bricks"},
        {pos: [1, 12, 15], state: "minecraft:stone_bricks"},
        {pos: [2, 12, 12], state: "minecraft:stone_bricks"},
        {pos: [2, 12, 13], state: "minecraft:stone_bricks"},
        {pos: [2, 12, 14], state: "minecraft:stone_bricks"},
        {pos: [2, 12, 15], state: "minecraft:stone_bricks"},
        {pos: [2, 12, 16], state: "minecraft:stone_bricks"},
        {pos: [3, 12, 11], state: "minecraft:stone_bricks"},
        {pos: [3, 12, 12], state: "minecraft:stone_bricks"},
        {pos: [3, 12, 13], state: "minecraft:stone_bricks"},
        {pos: [3, 12, 14], state: "minecraft:stone_bricks"},
        {pos: [3, 12, 15], state: "minecraft:gravel"},
        {pos: [3, 12, 16], state: "minecraft:stone_bricks"},
        {pos: [4, 12, 11], state: "minecraft:stone_bricks"},
        {pos: [4, 12, 12], state: "minecraft:stone_bricks"},
        {pos: [4, 12, 13], state: "minecraft:oak_trapdoor{facing:east,half:top,open:false,powered:false,waterlogged:false}"},
        {pos: [4, 12, 14], state: "minecraft:stone_bricks"},
        {pos: [4, 12, 15], state: "minecraft:stone_bricks"},
        {pos: [4, 12, 16], state: "minecraft:stone_bricks"},
        {pos: [5, 12, 11], state: "minecraft:stone_bricks"},
        {pos: [5, 12, 12], state: "minecraft:stone_bricks"},
        {pos: [5, 12, 13], state: "minecraft:stone_bricks"},
        {pos: [5, 12, 14], state: "minecraft:stone_bricks"},
        {pos: [5, 12, 15], state: "minecraft:stone_bricks"},
        {pos: [5, 12, 16], state: "minecraft:gravel"},
        {pos: [6, 12, 11], state: "minecraft:stone_bricks"},
        {pos: [6, 12, 12], state: "minecraft:stone_bricks"},
        {pos: [6, 12, 13], state: "minecraft:stone_bricks"},
        {pos: [6, 12, 14], state: "minecraft:stone_bricks"},
        {pos: [7, 12, 11], state: "minecraft:stone_bricks"},
        {pos: [7, 12, 12], state: "minecraft:stone_bricks"},
        {pos: [7, 12, 13], state: "minecraft:stone_bricks"},
        {pos: [1, 13, 13], state: "minecraft:gravel"},
        {pos: [1, 13, 14], state: "minecraft:gravel"},
        {pos: [1, 13, 15], state: "minecraft:gravel"},
        {pos: [2, 13, 11], state: "minecraft:stone_bricks"},
        {pos: [2, 13, 12], state: "minecraft:stone_bricks"},
        {pos: [2, 13, 13], state: "minecraft:stone_bricks"},
        {pos: [2, 13, 14], state: "minecraft:stone_bricks"},
        {pos: [2, 13, 15], state: "minecraft:stone_bricks"},
        {pos: [2, 13, 16], state: "minecraft:gravel"},
        {pos: [3, 13, 11], state: "minecraft:stone_bricks"},
        {pos: [3, 13, 12], state: "minecraft:gravel"},
        {pos: [3, 13, 13], state: "minecraft:gravel"},
        {pos: [3, 13, 14], state: "minecraft:gravel"},
        {pos: [3, 13, 15], state: "minecraft:gravel"},
        {pos: [3, 13, 16], state: "minecraft:gravel"},
        {pos: [4, 13, 11], state: "minecraft:stone_bricks"},
        {pos: [4, 13, 12], state: "minecraft:gravel"},
        {pos: [4, 13, 13], state: "minecraft:gravel"},
        {pos: [4, 13, 14], state: "minecraft:gravel"},
        {pos: [4, 13, 15], state: "minecraft:stone_bricks"},
        {pos: [4, 13, 16], state: "minecraft:gravel"},
        {pos: [5, 13, 11], state: "minecraft:stone_bricks"},
        {pos: [5, 13, 12], state: "minecraft:gravel"},
        {pos: [5, 13, 13], state: "minecraft:gravel"},
        {pos: [5, 13, 14], state: "minecraft:gravel"},
        {pos: [5, 13, 15], state: "minecraft:stone_bricks"},
        {pos: [6, 13, 11], state: "minecraft:stone_bricks"},
        {pos: [6, 13, 12], state: "minecraft:stone_bricks"},
        {pos: [6, 13, 13], state: "minecraft:stone_bricks"},
        {pos: [6, 13, 14], state: "minecraft:stone_bricks"},
        {pos: [6, 13, 15], state: "minecraft:stone_bricks"},
        {pos: [7, 13, 11], state: "minecraft:gravel"},
        {pos: [7, 13, 12], state: "minecraft:gravel"},
        {pos: [2, 14, 11], state: "minecraft:stone_bricks"},
        {pos: [2, 14, 12], state: "minecraft:stone_bricks"},
        {pos: [2, 14, 13], state: "minecraft:stone_bricks"},
        {pos: [2, 14, 14], state: "minecraft:stone_bricks"},
        {pos: [2, 14, 15], state: "minecraft:stone_bricks"},
        {pos: [3, 14, 11], state: "minecraft:stone_bricks"},
        {pos: [3, 14, 12], state: "minecraft:stone_bricks"},
        {pos: [3, 14, 13], state: "minecraft:air"},
        {pos: [3, 14, 14], state: "minecraft:stone_bricks"},
        {pos: [3, 14, 15], state: "minecraft:stone_bricks"},
        {pos: [4, 14, 11], state: "minecraft:stone_bricks"},
        {pos: [4, 14, 12], state: "minecraft:gravel"},
        {pos: [4, 14, 13], state: "minecraft:air"},
        {pos: [4, 14, 14], state: "minecraft:gravel"},
        {pos: [4, 14, 15], state: "minecraft:stone_bricks"},
        {pos: [5, 14, 11], state: "minecraft:stone_bricks"},
        {pos: [5, 14, 12], state: "minecraft:stone_bricks"},
        {pos: [5, 14, 13], state: "minecraft:gravel"},
        {pos: [5, 14, 14], state: "minecraft:stone_bricks"},
        {pos: [5, 14, 15], state: "minecraft:stone_bricks"},
        {pos: [6, 14, 11], state: "minecraft:stone_bricks"},
        {pos: [6, 14, 12], state: "minecraft:stone_bricks"},
        {pos: [6, 14, 13], state: "minecraft:stone_bricks"},
        {pos: [6, 14, 14], state: "minecraft:stone_bricks"},
        {pos: [6, 14, 15], state: "minecraft:stone_bricks"},
        {pos: [3, 15, 12], state: "minecraft:stone_bricks"},
        {pos: [3, 15, 13], state: "minecraft:air"},
        {pos: [3, 15, 14], state: "minecraft:stone_bricks"},
        {pos: [4, 15, 12], state: "minecraft:air"},
        {pos: [4, 15, 13], state: "minecraft:chain{axis:y,waterlogged:false}"},
        {pos: [4, 15, 14], state: "minecraft:air"},
        {pos: [5, 15, 12], state: "minecraft:stone_bricks"},
        {pos: [5, 15, 13], state: "minecraft:air"},
        {pos: [5, 15, 14], state: "minecraft:stone_bricks"},
        {pos: [3, 16, 12], state: "minecraft:stone_bricks"},
        {pos: [3, 16, 13], state: "minecraft:air"},
        {pos: [3, 16, 14], state: "minecraft:stone_bricks"},
        {pos: [4, 16, 12], state: "minecraft:air"},
        {pos: [4, 16, 13], state: "minecraft:chain{axis:y,waterlogged:false}"},
        {pos: [4, 16, 14], state: "minecraft:air"},
        {pos: [5, 16, 12], state: "minecraft:stone_bricks"},
        {pos: [5, 16, 13], state: "minecraft:air"},
        {pos: [5, 16, 14], state: "minecraft:stone_bricks"},
        {pos: [3, 17, 12], state: "minecraft:stone_bricks"},
        {pos: [3, 17, 13], state: "minecraft:stone_bricks"},
        {pos: [3, 17, 14], state: "minecraft:stone_bricks"},
        {pos: [4, 17, 12], state: "minecraft:stone_bricks"},
        {pos: [4, 17, 13], state: "minecraft:stone_bricks"},
        {pos: [4, 17, 14], state: "minecraft:stone_bricks"},
        {pos: [5, 17, 12], state: "minecraft:stone_bricks"},
        {pos: [5, 17, 13], state: "minecraft:stone_bricks"},
        {pos: [5, 17, 14], state: "minecraft:stone_bricks"},
        {pos: [4, 18, 13], state: "minecraft:stone_bricks"}
    ],
    entities: [],
    palette: [
        "minecraft:stone_bricks",
        "minecraft:gravel",
        "minecraft:water{level:0}",
        "minecraft:water{level:8}",
        "minecraft:water_cauldron{level:3}",
        "minecraft:cave_air",
        "minecraft:candle{candles:4,lit:false,waterlogged:false}",
        "minecraft:air",
        "minecraft:oak_trapdoor{facing:east,half:top,open:false,powered:false,waterlogged:false}",
        "minecraft:chain{axis:y,waterlogged:false}",
        "minecraft:decorated_pot{cracked:false,facing:north,waterlogged:true}",
        "minecraft:decorated_pot{cracked:false,facing:north,waterlogged:false}"
    ],
    trailiertales_DataVersion: 2
}
