{
    DataVersion: 3953,
    size: [7, 6, 7],
    data: [
        {pos: [0, 0, 1], state: "minecraft:gravel"},
        {pos: [0, 0, 2], state: "minecraft:jungle_log{axis:y}"},
        {pos: [0, 0, 3], state: "minecraft:jungle_log{axis:y}"},
        {pos: [0, 0, 4], state: "minecraft:jungle_log{axis:y}"},
        {pos: [0, 0, 5], state: "minecraft:gravel"},
        {pos: [0, 0, 6], state: "minecraft:gravel"},
        {pos: [1, 0, 0], state: "minecraft:gravel"},
        {pos: [1, 0, 1], state: "minecraft:jungle_log{axis:y}"},
        {pos: [1, 0, 2], state: "minecraft:jungle_log{axis:y}"},
        {pos: [1, 0, 3], state: "minecraft:jungle_log{axis:y}"},
        {pos: [1, 0, 4], state: "minecraft:jungle_log{axis:y}"},
        {pos: [1, 0, 5], state: "minecraft:jungle_log{axis:y}"},
        {pos: [1, 0, 6], state: "minecraft:gravel"},
        {pos: [2, 0, 0], state: "minecraft:jungle_log{axis:y}"},
        {pos: [2, 0, 1], state: "minecraft:jungle_log{axis:y}"},
        {pos: [2, 0, 2], state: "minecraft:jungle_log{axis:y}"},
        {pos: [2, 0, 3], state: "minecraft:jungle_log{axis:y}"},
        {pos: [2, 0, 4], state: "minecraft:jungle_log{axis:y}"},
        {pos: [2, 0, 5], state: "minecraft:jungle_log{axis:y}"},
        {pos: [2, 0, 6], state: "minecraft:jungle_log{axis:y}"},
        {pos: [3, 0, 0], state: "minecraft:gravel"},
        {pos: [3, 0, 1], state: "minecraft:jungle_log{axis:y}"},
        {pos: [3, 0, 2], state: "minecraft:jungle_log{axis:y}"},
        {pos: [3, 0, 3], state: "minecraft:jungle_log{axis:y}"},
        {pos: [3, 0, 4], state: "minecraft:jungle_log{axis:y}"},
        {pos: [3, 0, 5], state: "minecraft:jungle_log{axis:y}"},
        {pos: [3, 0, 6], state: "minecraft:jungle_log{axis:y}"},
        {pos: [4, 0, 0], state: "minecraft:jungle_log{axis:y}"},
        {pos: [4, 0, 1], state: "minecraft:jungle_log{axis:y}"},
        {pos: [4, 0, 2], state: "minecraft:jungle_log{axis:y}"},
        {pos: [4, 0, 3], state: "minecraft:jungle_log{axis:y}"},
        {pos: [4, 0, 4], state: "minecraft:jungle_log{axis:y}"},
        {pos: [4, 0, 5], state: "minecraft:jungle_log{axis:y}"},
        {pos: [4, 0, 6], state: "minecraft:jungle_log{axis:y}"},
        {pos: [5, 0, 0], state: "minecraft:gravel"},
        {pos: [5, 0, 1], state: "minecraft:jungle_log{axis:y}"},
        {pos: [5, 0, 2], state: "minecraft:jungle_log{axis:y}"},
        {pos: [5, 0, 3], state: "minecraft:jungle_log{axis:y}"},
        {pos: [5, 0, 4], state: "minecraft:jungle_log{axis:y}"},
        {pos: [5, 0, 5], state: "minecraft:jungle_log{axis:y}"},
        {pos: [6, 0, 1], state: "minecraft:gravel"},
        {pos: [6, 0, 2], state: "minecraft:jungle_log{axis:y}"},
        {pos: [6, 0, 3], state: "minecraft:jungle_log{axis:y}"},
        {pos: [6, 0, 4], state: "minecraft:jungle_log{axis:y}"},
        {pos: [0, 1, 2], state: "minecraft:jungle_log{axis:y}"},
        {pos: [0, 1, 3], state: "minecraft:jungle_log{axis:y}"},
        {pos: [0, 1, 4], state: "minecraft:jungle_log{axis:y}"},
        {pos: [1, 1, 1], state: "minecraft:jungle_log{axis:y}"},
        {pos: [1, 1, 2], state: "minecraft:gravel"},
        {pos: [1, 1, 3], state: "minecraft:gravel"},
        {pos: [1, 1, 4], state: "minecraft:gravel"},
        {pos: [1, 1, 5], state: "minecraft:jungle_log{axis:y}"},
        {pos: [1, 1, 6], state: "minecraft:gravel"},
        {pos: [2, 1, 0], state: "minecraft:jungle_log{axis:y}"},
        {pos: [2, 1, 1], state: "minecraft:gravel"},
        {pos: [2, 1, 2], state: "minecraft:gravel"},
        {pos: [2, 1, 3], state: "minecraft:gravel"},
        {pos: [2, 1, 4], state: "minecraft:gravel"},
        {pos: [2, 1, 5], state: "minecraft:gravel"},
        {pos: [2, 1, 6], state: "minecraft:jungle_log{axis:y}"},
        {pos: [3, 1, 0], state: "minecraft:gravel"},
        {pos: [3, 1, 1], state: "minecraft:gravel"},
        {pos: [3, 1, 2], state: "minecraft:gravel"},
        {pos: [3, 1, 3], state: "minecraft:gravel"},
        {pos: [3, 1, 4], state: "minecraft:gravel"},
        {pos: [3, 1, 5], state: "minecraft:gravel"},
        {pos: [3, 1, 6], state: "minecraft:jungle_log{axis:y}"},
        {pos: [4, 1, 0], state: "minecraft:jungle_log{axis:y}"},
        {pos: [4, 1, 1], state: "minecraft:gravel"},
        {pos: [4, 1, 2], state: "minecraft:gravel"},
        {pos: [4, 1, 3], state: "minecraft:gravel"},
        {pos: [4, 1, 4], state: "minecraft:jungle_log{axis:y}"},
        {pos: [4, 1, 5], state: "minecraft:jungle_log{axis:y}"},
        {pos: [5, 1, 1], state: "minecraft:jungle_log{axis:y}"},
        {pos: [5, 1, 2], state: "minecraft:gravel"},
        {pos: [5, 1, 3], state: "minecraft:gravel"},
        {pos: [5, 1, 4], state: "minecraft:jungle_log{axis:y}"},
        {pos: [6, 1, 2], state: "minecraft:jungle_log{axis:y}"},
        {pos: [6, 1, 3], state: "minecraft:jungle_log{axis:y}"},
        {pos: [6, 1, 4], state: "minecraft:jungle_log{axis:y}"},
        {pos: [0, 2, 2], state: "minecraft:jungle_log{axis:y}"},
        {pos: [0, 2, 3], state: "minecraft:jungle_log{axis:y}"},
        {pos: [0, 2, 4], state: "minecraft:jungle_log{axis:y}"},
        {pos: [1, 2, 1], state: "minecraft:jungle_log{axis:y}"},
        {pos: [1, 2, 2], state: "minecraft:gravel"},
        {pos: [1, 2, 3], state: "minecraft:gravel"},
        {pos: [1, 2, 4], state: "minecraft:gravel"},
        {pos: [1, 2, 5], state: "minecraft:jungle_log{axis:y}"},
        {pos: [2, 2, 0], state: "minecraft:jungle_log{axis:y}"},
        {pos: [2, 2, 3], state: "minecraft:gravel"},
        {pos: [2, 2, 4], state: "minecraft:gravel"},
        {pos: [2, 2, 5], state: "minecraft:gravel"},
        {pos: [2, 2, 6], state: "minecraft:jungle_log{axis:y}"},
        {pos: [3, 2, 4], state: "minecraft:gravel"},
        {pos: [3, 2, 5], state: "minecraft:gravel"},
        {pos: [3, 2, 6], state: "minecraft:jungle_log{axis:y}"},
        {pos: [4, 2, 0], state: "minecraft:jungle_log{axis:y}"},
        {pos: [4, 2, 1], state: "minecraft:gravel"},
        {pos: [4, 2, 2], state: "minecraft:gravel"},
        {pos: [4, 2, 3], state: "minecraft:gravel"},
        {pos: [4, 2, 4], state: "minecraft:jungle_log{axis:y}"},
        {pos: [4, 2, 5], state: "minecraft:jungle_log{axis:y}"},
        {pos: [5, 2, 1], state: "minecraft:jungle_log{axis:y}"},
        {pos: [5, 2, 2], state: "minecraft:gravel"},
        {pos: [5, 2, 3], state: "minecraft:gravel"},
        {pos: [5, 2, 4], state: "minecraft:jungle_log{axis:y}"},
        {pos: [6, 2, 2], state: "minecraft:jungle_log{axis:y}"},
        {pos: [6, 2, 3], state: "minecraft:jungle_log{axis:y}"},
        {pos: [0, 3, 2], state: "minecraft:jungle_log{axis:y}"},
        {pos: [0, 3, 3], state: "minecraft:jungle_log{axis:y}"},
        {pos: [0, 3, 4], state: "minecraft:jungle_log{axis:y}"},
        {pos: [1, 3, 1], state: "minecraft:jungle_log{axis:y}"},
        {pos: [1, 3, 4], state: "minecraft:gravel"},
        {pos: [1, 3, 5], state: "minecraft:jungle_log{axis:y}"},
        {pos: [2, 3, 0], state: "minecraft:jungle_log{axis:y}"},
        {pos: [2, 3, 6], state: "minecraft:jungle_log{axis:y}"},
        {pos: [3, 3, 0], state: "minecraft:jungle_log{axis:y}"},
        {pos: [3, 3, 6], state: "minecraft:jungle_log{axis:y}"},
        {pos: [4, 3, 0], state: "minecraft:jungle_log{axis:y}"},
        {pos: [4, 3, 4], state: "minecraft:jungle_log{axis:y}"},
        {pos: [4, 3, 5], state: "minecraft:jungle_log{axis:y}"},
        {pos: [5, 3, 1], state: "minecraft:jungle_log{axis:y}"},
        {pos: [5, 3, 3], state: "minecraft:gravel"},
        {pos: [5, 3, 4], state: "minecraft:jungle_log{axis:y}"},
        {pos: [6, 3, 2], state: "minecraft:jungle_log{axis:y}"},
        {pos: [6, 3, 3], state: "minecraft:jungle_log{axis:y}"},
        {pos: [0, 4, 3], state: "minecraft:jungle_log{axis:y}"},
        {pos: [0, 4, 4], state: "minecraft:jungle_log{axis:y}"},
        {pos: [1, 4, 5], state: "minecraft:jungle_log{axis:y}"},
        {pos: [2, 4, 0], state: "minecraft:jungle_log{axis:y}"},
        {pos: [2, 4, 6], state: "minecraft:jungle_log{axis:y}"},
        {pos: [3, 4, 0], state: "minecraft:jungle_log{axis:y}"},
        {pos: [3, 4, 6], state: "minecraft:jungle_log{axis:y}"},
        {pos: [4, 4, 0], state: "minecraft:jungle_log{axis:y}"},
        {pos: [4, 4, 4], state: "minecraft:jungle_log{axis:y}"},
        {pos: [5, 4, 4], state: "minecraft:jungle_log{axis:y}"},
        {pos: [6, 4, 2], state: "minecraft:jungle_log{axis:y}"},
        {pos: [6, 4, 3], state: "minecraft:jungle_log{axis:y}"},
        {pos: [0, 5, 4], state: "minecraft:jungle_log{axis:y}"},
        {pos: [1, 5, 5], state: "minecraft:jungle_log{axis:y}"},
        {pos: [2, 5, 0], state: "minecraft:jungle_log{axis:y}"},
        {pos: [2, 5, 6], state: "minecraft:jungle_log{axis:y}"},
        {pos: [3, 5, 0], state: "minecraft:jungle_log{axis:y}"},
        {pos: [5, 5, 4], state: "minecraft:jungle_log{axis:y}"},
        {pos: [6, 5, 3], state: "minecraft:jungle_log{axis:y}"}
    ],
    entities: [],
    palette: [
        "minecraft:gravel",
        "minecraft:jungle_log{axis:y}"
    ],
    trailiertales_DataVersion: 2
}
