{
    DataVersion: 3953,
    size: [5, 9, 4],
    data: [
        {pos: [0, 0, 1], state: "minecraft:gravel"},
        {pos: [0, 0, 2], state: "minecraft:cobblestone"},
        {pos: [0, 0, 3], state: "minecraft:cobblestone"},
        {pos: [1, 0, 0], state: "minecraft:gravel"},
        {pos: [1, 0, 1], state: "minecraft:cobblestone"},
        {pos: [1, 0, 2], state: "minecraft:cobblestone"},
        {pos: [1, 0, 3], state: "minecraft:cobblestone"},
        {pos: [2, 0, 0], state: "minecraft:cobblestone"},
        {pos: [2, 0, 1], state: "minecraft:cobblestone"},
        {pos: [2, 0, 2], state: "minecraft:cobblestone"},
        {pos: [2, 0, 3], state: "minecraft:cobblestone"},
        {pos: [3, 0, 0], state: "minecraft:cobblestone"},
        {pos: [3, 0, 1], state: "minecraft:cobblestone"},
        {pos: [3, 0, 2], state: "minecraft:cobblestone"},
        {pos: [3, 0, 3], state: "minecraft:cobblestone"},
        {pos: [4, 0, 0], state: "minecraft:gravel"},
        {pos: [4, 0, 1], state: "minecraft:cobblestone"},
        {pos: [4, 0, 2], state: "minecraft:cobblestone"},
        {pos: [4, 0, 3], state: "minecraft:gravel"},
        {pos: [0, 1, 1], state: "minecraft:gravel"},
        {pos: [0, 1, 2], state: "minecraft:gravel"},
        {pos: [0, 1, 3], state: "minecraft:gravel"},
        {pos: [1, 1, 0], state: "minecraft:gravel"},
        {pos: [1, 1, 1], state: "minecraft:gravel"},
        {pos: [1, 1, 2], state: "minecraft:cobblestone"},
        {pos: [1, 1, 3], state: "minecraft:cobblestone"},
        {pos: [2, 1, 0], state: "minecraft:gravel"},
        {pos: [2, 1, 1], state: "minecraft:gravel"},
        {pos: [2, 1, 2], state: "minecraft:gravel"},
        {pos: [2, 1, 3], state: "minecraft:cobblestone"},
        {pos: [3, 1, 0], state: "minecraft:gravel"},
        {pos: [3, 1, 1], state: "minecraft:gravel"},
        {pos: [3, 1, 2], state: "minecraft:gravel"},
        {pos: [3, 1, 3], state: "minecraft:gravel"},
        {pos: [4, 1, 2], state: "minecraft:gravel"},
        {pos: [0, 2, 2], state: "minecraft:gravel"},
        {pos: [1, 2, 1], state: "minecraft:gravel"},
        {pos: [1, 2, 2], state: "minecraft:cobblestone"},
        {pos: [1, 2, 3], state: "minecraft:cobblestone"},
        {pos: [2, 2, 1], state: "minecraft:gravel"},
        {pos: [2, 2, 2], state: "minecraft:gravel"},
        {pos: [2, 2, 3], state: "minecraft:cobblestone"},
        {pos: [1, 3, 2], state: "minecraft:cobblestone"},
        {pos: [1, 3, 3], state: "minecraft:cobblestone"},
        {pos: [2, 3, 2], state: "minecraft:cobblestone"},
        {pos: [2, 3, 3], state: "minecraft:cobblestone"},
        {pos: [1, 4, 2], state: "minecraft:cobblestone"},
        {pos: [1, 4, 3], state: "minecraft:cobblestone"},
        {pos: [2, 4, 2], state: "minecraft:cobblestone"},
        {pos: [2, 4, 3], state: "minecraft:cobblestone"},
        {pos: [1, 5, 2], state: "minecraft:gravel"},
        {pos: [1, 5, 3], state: "minecraft:cobblestone"},
        {pos: [2, 5, 2], state: "minecraft:cobblestone"},
        {pos: [2, 5, 3], state: "minecraft:cobblestone"},
        {pos: [1, 6, 2], state: "minecraft:gray_glazed_terracotta{facing:north}"},
        {pos: [1, 6, 3], state: "minecraft:gray_glazed_terracotta{facing:west}"},
        {pos: [2, 6, 2], state: "minecraft:gray_glazed_terracotta{facing:east}"},
        {pos: [2, 6, 3], state: "minecraft:gray_glazed_terracotta{facing:south}"},
        {pos: [1, 7, 2], state: "minecraft:cobblestone"},
        {pos: [2, 7, 2], state: "minecraft:cobblestone"},
        {pos: [2, 7, 3], state: "minecraft:cobblestone"},
        {pos: [2, 8, 3], state: "minecraft:cobblestone"}
    ],
    entities: [],
    palette: [
        "minecraft:gravel",
        "minecraft:cobblestone",
        "minecraft:gray_glazed_terracotta{facing:north}",
        "minecraft:gray_glazed_terracotta{facing:west}",
        "minecraft:gray_glazed_terracotta{facing:east}",
        "minecraft:gray_glazed_terracotta{facing:south}"
    ],
    trailiertales_DataVersion: 2
}
