{
    DataVersion: 3953,
    size: [15, 8, 15],
    data: [
        {pos: [0, 0, 1], state: "minecraft:cobblestone"},
        {pos: [0, 0, 2], state: "minecraft:cobblestone"},
        {pos: [0, 0, 3], state: "minecraft:cobblestone"},
        {pos: [0, 0, 4], state: "minecraft:cobblestone"},
        {pos: [0, 0, 5], state: "minecraft:gravel"},
        {pos: [0, 0, 6], state: "minecraft:gravel"},
        {pos: [0, 0, 9], state: "minecraft:cobblestone"},
        {pos: [0, 0, 10], state: "minecraft:cobblestone"},
        {pos: [0, 0, 11], state: "minecraft:cobblestone"},
        {pos: [1, 0, 0], state: "minecraft:gravel"},
        {pos: [1, 0, 1], state: "minecraft:cobblestone"},
        {pos: [1, 0, 2], state: "minecraft:cobblestone"},
        {pos: [1, 0, 3], state: "minecraft:cobblestone"},
        {pos: [1, 0, 4], state: "minecraft:cobblestone"},
        {pos: [1, 0, 5], state: "minecraft:gravel"},
        {pos: [1, 0, 6], state: "minecraft:gravel"},
        {pos: [1, 0, 7], state: "minecraft:gravel"},
        {pos: [1, 0, 8], state: "minecraft:gravel"},
        {pos: [1, 0, 9], state: "minecraft:cobblestone"},
        {pos: [1, 0, 10], state: "minecraft:cobblestone"},
        {pos: [1, 0, 11], state: "minecraft:cobblestone"},
        {pos: [1, 0, 12], state: "minecraft:cobblestone"},
        {pos: [2, 0, 0], state: "minecraft:gravel"},
        {pos: [2, 0, 1], state: "minecraft:gravel"},
        {pos: [2, 0, 2], state: "minecraft:cobblestone"},
        {pos: [2, 0, 3], state: "minecraft:cobblestone"},
        {pos: [2, 0, 4], state: "minecraft:cobblestone"},
        {pos: [2, 0, 5], state: "minecraft:cobblestone"},
        {pos: [2, 0, 6], state: "minecraft:gravel"},
        {pos: [2, 0, 7], state: "minecraft:cobblestone"},
        {pos: [2, 0, 8], state: "minecraft:gravel"},
        {pos: [2, 0, 9], state: "minecraft:cobblestone"},
        {pos: [2, 0, 10], state: "minecraft:cobblestone"},
        {pos: [2, 0, 11], state: "minecraft:cobblestone"},
        {pos: [2, 0, 12], state: "minecraft:cobblestone"},
        {pos: [3, 0, 0], state: "minecraft:gravel"},
        {pos: [3, 0, 1], state: "minecraft:cobblestone"},
        {pos: [3, 0, 2], state: "minecraft:cobblestone"},
        {pos: [3, 0, 3], state: "minecraft:gravel"},
        {pos: [3, 0, 4], state: "minecraft:cobblestone_stairs{facing:west,half:bottom,shape:inner_right,waterlogged:true}"},
        {pos: [3, 0, 5], state: "minecraft:cobblestone_stairs{facing:west,half:bottom,shape:straight,waterlogged:true}"},
        {pos: [3, 0, 6], state: "minecraft:cobblestone_stairs{facing:west,half:bottom,shape:straight,waterlogged:true}"},
        {pos: [3, 0, 7], state: "minecraft:cobblestone_stairs{facing:west,half:bottom,shape:straight,waterlogged:true}"},
        {pos: [3, 0, 8], state: "minecraft:cobblestone_stairs{facing:west,half:bottom,shape:straight,waterlogged:true}"},
        {pos: [3, 0, 9], state: "minecraft:cobblestone_stairs{facing:west,half:bottom,shape:straight,waterlogged:true}"},
        {pos: [3, 0, 10], state: "minecraft:cobblestone_stairs{facing:south,half:bottom,shape:inner_right,waterlogged:true}"},
        {pos: [3, 0, 11], state: "minecraft:gravel"},
        {pos: [3, 0, 12], state: "minecraft:gravel"},
        {pos: [3, 0, 13], state: "minecraft:cobblestone"},
        {pos: [4, 0, 0], state: "minecraft:gravel"},
        {pos: [4, 0, 1], state: "minecraft:cobblestone"},
        {pos: [4, 0, 2], state: "minecraft:cobblestone"},
        {pos: [4, 0, 3], state: "minecraft:gravel"},
        {pos: [4, 0, 4], state: "minecraft:cobblestone_stairs{facing:north,half:bottom,shape:straight,waterlogged:true}"},
        {pos: [4, 0, 5], state: "minecraft:cobblestone"},
        {pos: [4, 0, 6], state: "minecraft:cobblestone"},
        {pos: [4, 0, 7], state: "minecraft:cobblestone"},
        {pos: [4, 0, 8], state: "minecraft:cobblestone"},
        {pos: [4, 0, 9], state: "minecraft:gravel"},
        {pos: [4, 0, 10], state: "minecraft:cobblestone_stairs{facing:south,half:bottom,shape:straight,waterlogged:true}"},
        {pos: [4, 0, 11], state: "minecraft:gravel"},
        {pos: [4, 0, 12], state: "minecraft:gravel"},
        {pos: [4, 0, 13], state: "minecraft:cobblestone"},
        {pos: [4, 0, 14], state: "minecraft:cobblestone"},
        {pos: [5, 0, 0], state: "minecraft:gravel"},
        {pos: [5, 0, 1], state: "minecraft:cobblestone"},
        {pos: [5, 0, 2], state: "minecraft:cobblestone"},
        {pos: [5, 0, 3], state: "minecraft:cobblestone"},
        {pos: [5, 0, 4], state: "minecraft:cobblestone_stairs{facing:north,half:bottom,shape:straight,waterlogged:true}"},
        {pos: [5, 0, 5], state: "minecraft:cobblestone"},
        {pos: [5, 0, 6], state: "minecraft:gravel"},
        {pos: [5, 0, 7], state: "minecraft:gravel"},
        {pos: [5, 0, 8], state: "minecraft:gravel"},
        {pos: [5, 0, 9], state: "minecraft:cobblestone"},
        {pos: [5, 0, 10], state: "minecraft:cobblestone_stairs{facing:south,half:bottom,shape:straight,waterlogged:true}"},
        {pos: [5, 0, 11], state: "minecraft:gravel"},
        {pos: [5, 0, 12], state: "minecraft:cobblestone"},
        {pos: [5, 0, 13], state: "minecraft:cobblestone"},
        {pos: [6, 0, 0], state: "minecraft:gravel"},
        {pos: [6, 0, 1], state: "minecraft:cobblestone"},
        {pos: [6, 0, 2], state: "minecraft:cobblestone"},
        {pos: [6, 0, 3], state: "minecraft:gravel"},
        {pos: [6, 0, 4], state: "minecraft:cobblestone_stairs{facing:north,half:bottom,shape:straight,waterlogged:true}"},
        {pos: [6, 0, 5], state: "minecraft:cobblestone"},
        {pos: [6, 0, 6], state: "minecraft:gravel"},
        {pos: [6, 0, 7], state: "minecraft:gravel"},
        {pos: [6, 0, 8], state: "minecraft:gravel"},
        {pos: [6, 0, 9], state: "minecraft:cobblestone"},
        {pos: [6, 0, 10], state: "minecraft:cobblestone_stairs{facing:south,half:bottom,shape:straight,waterlogged:true}"},
        {pos: [6, 0, 11], state: "minecraft:cobblestone"},
        {pos: [6, 0, 12], state: "minecraft:cobblestone"},
        {pos: [6, 0, 13], state: "minecraft:cobblestone"},
        {pos: [6, 0, 14], state: "minecraft:cobblestone"},
        {pos: [7, 0, 1], state: "minecraft:gravel"},
        {pos: [7, 0, 2], state: "minecraft:cobblestone"},
        {pos: [7, 0, 3], state: "minecraft:gravel"},
        {pos: [7, 0, 4], state: "minecraft:cobblestone_stairs{facing:north,half:bottom,shape:straight,waterlogged:true}"},
        {pos: [7, 0, 5], state: "minecraft:gravel"},
        {pos: [7, 0, 6], state: "minecraft:gravel"},
        {pos: [7, 0, 7], state: "minecraft:gravel"},
        {pos: [7, 0, 8], state: "minecraft:gravel"},
        {pos: [7, 0, 9], state: "minecraft:cobblestone"},
        {pos: [7, 0, 10], state: "minecraft:cobblestone_stairs{facing:south,half:bottom,shape:straight,waterlogged:true}"},
        {pos: [7, 0, 11], state: "minecraft:cobblestone"},
        {pos: [7, 0, 12], state: "minecraft:cobblestone"},
        {pos: [7, 0, 13], state: "minecraft:cobblestone"},
        {pos: [7, 0, 14], state: "minecraft:cobblestone"},
        {pos: [8, 0, 1], state: "minecraft:gravel"},
        {pos: [8, 0, 2], state: "minecraft:gravel"},
        {pos: [8, 0, 3], state: "minecraft:gravel"},
        {pos: [8, 0, 4], state: "minecraft:cobblestone_stairs{facing:north,half:bottom,shape:straight,waterlogged:true}"},
        {pos: [8, 0, 5], state: "minecraft:gravel"},
        {pos: [8, 0, 6], state: "minecraft:gravel"},
        {pos: [8, 0, 7], state: "minecraft:cobblestone"},
        {pos: [8, 0, 8], state: "minecraft:cobblestone"},
        {pos: [8, 0, 9], state: "minecraft:cobblestone"},
        {pos: [8, 0, 10], state: "minecraft:cobblestone_stairs{facing:south,half:bottom,shape:straight,waterlogged:true}"},
        {pos: [8, 0, 11], state: "minecraft:gravel"},
        {pos: [8, 0, 12], state: "minecraft:cobblestone"},
        {pos: [8, 0, 13], state: "minecraft:cobblestone"},
        {pos: [8, 0, 14], state: "minecraft:cobblestone"},
        {pos: [9, 0, 1], state: "minecraft:cobblestone"},
        {pos: [9, 0, 2], state: "minecraft:gravel"},
        {pos: [9, 0, 3], state: "minecraft:gravel"},
        {pos: [9, 0, 4], state: "minecraft:cobblestone_stairs{facing:north,half:bottom,shape:inner_right,waterlogged:true}"},
        {pos: [9, 0, 5], state: "minecraft:cobblestone_stairs{facing:east,half:bottom,shape:straight,waterlogged:true}"},
        {pos: [9, 0, 6], state: "minecraft:cobblestone_stairs{facing:east,half:bottom,shape:straight,waterlogged:true}"},
        {pos: [9, 0, 7], state: "minecraft:cobblestone_stairs{facing:east,half:bottom,shape:straight,waterlogged:true}"},
        {pos: [9, 0, 8], state: "minecraft:cobblestone_stairs{facing:east,half:bottom,shape:straight,waterlogged:true}"},
        {pos: [9, 0, 9], state: "minecraft:cobblestone_stairs{facing:east,half:bottom,shape:straight,waterlogged:true}"},
        {pos: [9, 0, 10], state: "minecraft:cobblestone_stairs{facing:east,half:bottom,shape:inner_right,waterlogged:true}"},
        {pos: [9, 0, 11], state: "minecraft:gravel"},
        {pos: [9, 0, 12], state: "minecraft:gravel"},
        {pos: [9, 0, 13], state: "minecraft:cobblestone"},
        {pos: [9, 0, 14], state: "minecraft:gravel"},
        {pos: [10, 0, 1], state: "minecraft:cobblestone"},
        {pos: [10, 0, 2], state: "minecraft:cobblestone"},
        {pos: [10, 0, 3], state: "minecraft:cobblestone"},
        {pos: [10, 0, 4], state: "minecraft:cobblestone"},
        {pos: [10, 0, 5], state: "minecraft:cobblestone"},
        {pos: [10, 0, 6], state: "minecraft:cobblestone"},
        {pos: [10, 0, 7], state: "minecraft:gravel"},
        {pos: [10, 0, 8], state: "minecraft:gravel"},
        {pos: [10, 0, 9], state: "minecraft:gravel"},
        {pos: [10, 0, 10], state: "minecraft:gravel"},
        {pos: [10, 0, 11], state: "minecraft:cobblestone"},
        {pos: [10, 0, 12], state: "minecraft:cobblestone"},
        {pos: [10, 0, 13], state: "minecraft:cobblestone"},
        {pos: [11, 0, 1], state: "minecraft:gravel"},
        {pos: [11, 0, 2], state: "minecraft:cobblestone"},
        {pos: [11, 0, 3], state: "minecraft:cobblestone"},
        {pos: [11, 0, 4], state: "minecraft:cobblestone"},
        {pos: [11, 0, 5], state: "minecraft:cobblestone"},
        {pos: [11, 0, 6], state: "minecraft:cobblestone"},
        {pos: [11, 0, 7], state: "minecraft:gravel"},
        {pos: [11, 0, 8], state: "minecraft:gravel"},
        {pos: [11, 0, 9], state: "minecraft:gravel"},
        {pos: [11, 0, 10], state: "minecraft:gravel"},
        {pos: [11, 0, 11], state: "minecraft:cobblestone"},
        {pos: [11, 0, 12], state: "minecraft:cobblestone"},
        {pos: [11, 0, 13], state: "minecraft:gravel"},
        {pos: [12, 0, 1], state: "minecraft:gravel"},
        {pos: [12, 0, 2], state: "minecraft:cobblestone"},
        {pos: [12, 0, 3], state: "minecraft:cobblestone"},
        {pos: [12, 0, 4], state: "minecraft:cobblestone"},
        {pos: [12, 0, 5], state: "minecraft:cobblestone"},
        {pos: [12, 0, 6], state: "minecraft:cobblestone"},
        {pos: [12, 0, 7], state: "minecraft:cobblestone"},
        {pos: [12, 0, 8], state: "minecraft:cobblestone"},
        {pos: [12, 0, 9], state: "minecraft:gravel"},
        {pos: [12, 0, 10], state: "minecraft:cobblestone"},
        {pos: [12, 0, 11], state: "minecraft:cobblestone"},
        {pos: [12, 0, 12], state: "minecraft:gravel"},
        {pos: [12, 0, 13], state: "minecraft:gravel"},
        {pos: [13, 0, 1], state: "minecraft:gravel"},
        {pos: [13, 0, 2], state: "minecraft:gravel"},
        {pos: [13, 0, 3], state: "minecraft:gravel"},
        {pos: [13, 0, 4], state: "minecraft:cobblestone"},
        {pos: [13, 0, 5], state: "minecraft:cobblestone"},
        {pos: [13, 0, 6], state: "minecraft:cobblestone"},
        {pos: [13, 0, 7], state: "minecraft:cobblestone"},
        {pos: [14, 0, 2], state: "minecraft:gravel"},
        {pos: [14, 0, 3], state: "minecraft:gravel"},
        {pos: [14, 0, 4], state: "minecraft:gravel"},
        {pos: [14, 0, 5], state: "minecraft:gravel"},
        {pos: [0, 1, 1], state: "minecraft:cobblestone"},
        {pos: [0, 1, 2], state: "minecraft:gravel"},
        {pos: [1, 1, 1], state: "minecraft:cobblestone"},
        {pos: [1, 1, 2], state: "minecraft:gravel"},
        {pos: [1, 1, 3], state: "minecraft:cobblestone"},
        {pos: [1, 1, 4], state: "minecraft:gravel"},
        {pos: [1, 1, 7], state: "minecraft:gravel"},
        {pos: [1, 1, 10], state: "minecraft:cobblestone"},
        {pos: [1, 1, 11], state: "minecraft:cobblestone"},
        {pos: [1, 1, 12], state: "minecraft:cobblestone"},
        {pos: [2, 1, 2], state: "minecraft:cobblestone"},
        {pos: [2, 1, 3], state: "minecraft:cobblestone"},
        {pos: [2, 1, 4], state: "minecraft:cobblestone"},
        {pos: [2, 1, 10], state: "minecraft:cobblestone"},
        {pos: [2, 1, 11], state: "minecraft:cobblestone"},
        {pos: [2, 1, 12], state: "minecraft:cobblestone"},
        {pos: [3, 1, 2], state: "minecraft:gravel"},
        {pos: [3, 1, 3], state: "minecraft:gravel"},
        {pos: [5, 1, 9], state: "minecraft:gravel"},
        {pos: [6, 1, 9], state: "minecraft:gravel"},
        {pos: [7, 1, 5], state: "minecraft:gravel"},
        {pos: [8, 1, 7], state: "minecraft:gravel"},
        {pos: [9, 1, 2], state: "minecraft:gravel"},
        {pos: [9, 1, 3], state: "minecraft:gravel"},
        {pos: [9, 1, 11], state: "minecraft:gravel"},
        {pos: [9, 1, 12], state: "minecraft:gravel"},
        {pos: [10, 1, 2], state: "minecraft:cobblestone"},
        {pos: [10, 1, 3], state: "minecraft:cobblestone"},
        {pos: [10, 1, 4], state: "minecraft:gravel"},
        {pos: [10, 1, 5], state: "minecraft:gravel"},
        {pos: [10, 1, 11], state: "minecraft:cobblestone"},
        {pos: [10, 1, 12], state: "minecraft:cobblestone"},
        {pos: [11, 1, 2], state: "minecraft:cobblestone"},
        {pos: [11, 1, 3], state: "minecraft:cobblestone"},
        {pos: [11, 1, 11], state: "minecraft:cobblestone"},
        {pos: [11, 1, 12], state: "minecraft:cobblestone"},
        {pos: [1, 2, 2], state: "minecraft:gravel"},
        {pos: [1, 2, 3], state: "minecraft:cobblestone"},
        {pos: [1, 2, 11], state: "minecraft:cobblestone"},
        {pos: [1, 2, 12], state: "minecraft:cobblestone"},
        {pos: [2, 2, 2], state: "minecraft:cobblestone"},
        {pos: [2, 2, 3], state: "minecraft:cobblestone"},
        {pos: [2, 2, 4], state: "minecraft:gravel"},
        {pos: [2, 2, 11], state: "minecraft:cobblestone"},
        {pos: [2, 2, 12], state: "minecraft:cobblestone"},
        {pos: [3, 2, 3], state: "minecraft:gravel"},
        {pos: [9, 2, 11], state: "minecraft:gravel"},
        {pos: [10, 2, 2], state: "minecraft:cobblestone"},
        {pos: [10, 2, 3], state: "minecraft:cobblestone"},
        {pos: [10, 2, 11], state: "minecraft:cobblestone"},
        {pos: [10, 2, 12], state: "minecraft:cobblestone"},
        {pos: [11, 2, 2], state: "minecraft:cobblestone"},
        {pos: [11, 2, 3], state: "minecraft:cobblestone"},
        {pos: [11, 2, 11], state: "minecraft:cobblestone"},
        {pos: [11, 2, 12], state: "minecraft:cobblestone"},
        {pos: [1, 3, 2], state: "minecraft:cobblestone"},
        {pos: [1, 3, 3], state: "minecraft:cobblestone"},
        {pos: [1, 3, 11], state: "minecraft:cobblestone"},
        {pos: [1, 3, 12], state: "minecraft:cobblestone"},
        {pos: [2, 3, 2], state: "minecraft:cobblestone"},
        {pos: [2, 3, 3], state: "minecraft:cobblestone"},
        {pos: [2, 3, 11], state: "minecraft:cobblestone"},
        {pos: [2, 3, 12], state: "minecraft:cobblestone"},
        {pos: [10, 3, 2], state: "minecraft:cobblestone"},
        {pos: [10, 3, 3], state: "minecraft:cobblestone"},
        {pos: [10, 3, 11], state: "minecraft:cobblestone"},
        {pos: [10, 3, 12], state: "minecraft:cobblestone"},
        {pos: [11, 3, 2], state: "minecraft:cobblestone"},
        {pos: [11, 3, 3], state: "minecraft:cobblestone"},
        {pos: [11, 3, 11], state: "minecraft:cobblestone"},
        {pos: [11, 3, 12], state: "minecraft:cobblestone"},
        {pos: [1, 4, 2], state: "minecraft:cobblestone"},
        {pos: [1, 4, 3], state: "minecraft:cobblestone"},
        {pos: [1, 4, 11], state: "minecraft:cobblestone"},
        {pos: [2, 4, 3], state: "minecraft:cobblestone"},
        {pos: [2, 4, 12], state: "minecraft:cobblestone"},
        {pos: [10, 4, 2], state: "minecraft:cobblestone"},
        {pos: [10, 4, 3], state: "minecraft:cobblestone"},
        {pos: [10, 4, 11], state: "minecraft:cobblestone"},
        {pos: [10, 4, 12], state: "minecraft:cobblestone"},
        {pos: [11, 4, 3], state: "minecraft:cobblestone"},
        {pos: [11, 4, 11], state: "minecraft:cobblestone"},
        {pos: [11, 4, 12], state: "minecraft:cobblestone"},
        {pos: [1, 5, 2], state: "minecraft:cobblestone"},
        {pos: [2, 5, 12], state: "minecraft:cobblestone"},
        {pos: [9, 5, 10], state: "minecraft:cobblestone"},
        {pos: [10, 5, 2], state: "minecraft:cobblestone"},
        {pos: [10, 5, 3], state: "minecraft:cobblestone"},
        {pos: [10, 5, 10], state: "minecraft:cobblestone"},
        {pos: [10, 5, 11], state: "minecraft:cobblestone"},
        {pos: [10, 5, 12], state: "minecraft:cobblestone"},
        {pos: [11, 5, 3], state: "minecraft:cobblestone"},
        {pos: [11, 5, 11], state: "minecraft:cobblestone"},
        {pos: [9, 6, 6], state: "minecraft:cobblestone"},
        {pos: [9, 6, 7], state: "minecraft:cobblestone"},
        {pos: [9, 6, 8], state: "minecraft:cobblestone"},
        {pos: [9, 6, 9], state: "minecraft:cobblestone"},
        {pos: [9, 6, 10], state: "minecraft:cobblestone"},
        {pos: [9, 6, 11], state: "minecraft:cobblestone"},
        {pos: [10, 6, 3], state: "minecraft:cobblestone"},
        {pos: [10, 6, 8], state: "minecraft:cobblestone"},
        {pos: [10, 6, 9], state: "minecraft:cobblestone"},
        {pos: [10, 6, 10], state: "minecraft:cobblestone"},
        {pos: [10, 6, 11], state: "minecraft:cobblestone"},
        {pos: [10, 6, 12], state: "minecraft:cobblestone"},
        {pos: [11, 6, 3], state: "minecraft:cobblestone"},
        {pos: [11, 6, 10], state: "minecraft:cobblestone"},
        {pos: [11, 6, 11], state: "minecraft:cobblestone"},
        {pos: [9, 7, 7], state: "minecraft:cobblestone"},
        {pos: [9, 7, 8], state: "minecraft:cobblestone"},
        {pos: [9, 7, 9], state: "minecraft:cobblestone"},
        {pos: [9, 7, 10], state: "minecraft:cobblestone"},
        {pos: [9, 7, 11], state: "minecraft:cobblestone"},
        {pos: [10, 7, 6], state: "minecraft:cobblestone"},
        {pos: [10, 7, 7], state: "minecraft:cobblestone"},
        {pos: [10, 7, 8], state: "minecraft:cobblestone"},
        {pos: [10, 7, 9], state: "minecraft:cobblestone"},
        {pos: [10, 7, 10], state: "minecraft:cobblestone"}
    ],
    entities: [],
    palette: [
        "minecraft:cobblestone",
        "minecraft:gravel",
        "minecraft:cobblestone_stairs{facing:west,half:bottom,shape:inner_right,waterlogged:true}",
        "minecraft:cobblestone_stairs{facing:west,half:bottom,shape:straight,waterlogged:true}",
        "minecraft:cobblestone_stairs{facing:south,half:bottom,shape:inner_right,waterlogged:true}",
        "minecraft:cobblestone_stairs{facing:north,half:bottom,shape:straight,waterlogged:true}",
        "minecraft:cobblestone_stairs{facing:south,half:bottom,shape:straight,waterlogged:true}",
        "minecraft:cobblestone_stairs{facing:north,half:bottom,shape:inner_right,waterlogged:true}",
        "minecraft:cobblestone_stairs{facing:east,half:bottom,shape:straight,waterlogged:true}",
        "minecraft:cobblestone_stairs{facing:east,half:bottom,shape:inner_right,waterlogged:true}"
    ],
    trailiertales_DataVersion: 2
}
