{
    DataVersion: 3953,
    size: [9, 8, 9],
    data: [
        {pos: [0, 0, 6], state: "minecraft:cobblestone"},
        {pos: [0, 0, 7], state: "minecraft:cobblestone"},
        {pos: [1, 0, 3], state: "minecraft:gravel"},
        {pos: [1, 0, 4], state: "minecraft:gravel"},
        {pos: [1, 0, 5], state: "minecraft:gravel"},
        {pos: [1, 0, 6], state: "minecraft:cobblestone"},
        {pos: [1, 0, 7], state: "minecraft:cobblestone"},
        {pos: [2, 0, 1], state: "minecraft:gravel"},
        {pos: [2, 0, 2], state: "minecraft:gravel"},
        {pos: [2, 0, 3], state: "minecraft:gravel"},
        {pos: [2, 0, 4], state: "minecraft:gravel"},
        {pos: [2, 0, 5], state: "minecraft:gravel"},
        {pos: [2, 0, 6], state: "minecraft:gravel"},
        {pos: [2, 0, 7], state: "minecraft:gravel"},
        {pos: [2, 0, 8], state: "minecraft:gravel"},
        {pos: [3, 0, 0], state: "minecraft:cobblestone"},
        {pos: [3, 0, 1], state: "minecraft:cobblestone"},
        {pos: [3, 0, 2], state: "minecraft:gravel"},
        {pos: [3, 0, 3], state: "minecraft:gravel"},
        {pos: [3, 0, 4], state: "minecraft:gravel"},
        {pos: [3, 0, 5], state: "minecraft:gravel"},
        {pos: [3, 0, 6], state: "minecraft:gravel"},
        {pos: [3, 0, 7], state: "minecraft:gravel"},
        {pos: [3, 0, 8], state: "minecraft:gravel"},
        {pos: [4, 0, 0], state: "minecraft:cobblestone"},
        {pos: [4, 0, 1], state: "minecraft:cobblestone"},
        {pos: [4, 0, 2], state: "minecraft:gravel"},
        {pos: [4, 0, 3], state: "minecraft:gravel"},
        {pos: [4, 0, 4], state: "minecraft:gravel"},
        {pos: [4, 0, 5], state: "minecraft:gravel"},
        {pos: [4, 0, 6], state: "minecraft:gravel"},
        {pos: [4, 0, 7], state: "minecraft:gravel"},
        {pos: [4, 0, 8], state: "minecraft:gravel"},
        {pos: [5, 0, 1], state: "minecraft:gravel"},
        {pos: [5, 0, 2], state: "minecraft:gravel"},
        {pos: [5, 0, 3], state: "minecraft:gravel"},
        {pos: [5, 0, 4], state: "minecraft:gravel"},
        {pos: [5, 0, 5], state: "minecraft:gravel"},
        {pos: [5, 0, 6], state: "minecraft:gravel"},
        {pos: [5, 0, 7], state: "minecraft:gravel"},
        {pos: [5, 0, 8], state: "minecraft:gravel"},
        {pos: [6, 0, 2], state: "minecraft:gravel"},
        {pos: [6, 0, 3], state: "minecraft:gravel"},
        {pos: [6, 0, 4], state: "minecraft:gravel"},
        {pos: [6, 0, 5], state: "minecraft:gravel"},
        {pos: [6, 0, 6], state: "minecraft:gravel"},
        {pos: [6, 0, 7], state: "minecraft:gravel"},
        {pos: [6, 0, 8], state: "minecraft:gravel"},
        {pos: [7, 0, 2], state: "minecraft:gravel"},
        {pos: [7, 0, 3], state: "minecraft:gravel"},
        {pos: [7, 0, 4], state: "minecraft:gravel"},
        {pos: [7, 0, 5], state: "minecraft:cobblestone"},
        {pos: [7, 0, 6], state: "minecraft:cobblestone"},
        {pos: [7, 0, 7], state: "minecraft:gravel"},
        {pos: [8, 0, 5], state: "minecraft:cobblestone"},
        {pos: [8, 0, 6], state: "minecraft:cobblestone"},
        {pos: [0, 1, 6], state: "minecraft:cobblestone"},
        {pos: [0, 1, 7], state: "minecraft:cobblestone"},
        {pos: [1, 1, 6], state: "minecraft:cobblestone"},
        {pos: [1, 1, 7], state: "minecraft:cobblestone"},
        {pos: [2, 1, 2], state: "minecraft:gravel"},
        {pos: [2, 1, 3], state: "minecraft:gravel"},
        {pos: [2, 1, 4], state: "minecraft:gravel"},
        {pos: [2, 1, 5], state: "minecraft:gravel"},
        {pos: [2, 1, 6], state: "minecraft:gravel"},
        {pos: [2, 1, 7], state: "minecraft:gravel"},
        {pos: [3, 1, 0], state: "minecraft:cobblestone"},
        {pos: [3, 1, 1], state: "minecraft:cobblestone"},
        {pos: [3, 1, 2], state: "minecraft:gravel"},
        {pos: [3, 1, 3], state: "minecraft:gravel"},
        {pos: [3, 1, 4], state: "minecraft:gravel"},
        {pos: [3, 1, 5], state: "minecraft:gravel"},
        {pos: [3, 1, 6], state: "minecraft:gravel"},
        {pos: [3, 1, 7], state: "minecraft:gravel"},
        {pos: [4, 1, 0], state: "minecraft:cobblestone"},
        {pos: [4, 1, 1], state: "minecraft:cobblestone"},
        {pos: [4, 1, 2], state: "minecraft:gravel"},
        {pos: [4, 1, 3], state: "minecraft:gravel"},
        {pos: [4, 1, 4], state: "minecraft:gravel"},
        {pos: [4, 1, 5], state: "minecraft:gravel"},
        {pos: [4, 1, 6], state: "minecraft:gravel"},
        {pos: [4, 1, 7], state: "minecraft:gravel"},
        {pos: [5, 1, 2], state: "minecraft:gravel"},
        {pos: [5, 1, 3], state: "minecraft:gravel"},
        {pos: [5, 1, 4], state: "minecraft:gravel"},
        {pos: [5, 1, 5], state: "minecraft:gravel"},
        {pos: [5, 1, 6], state: "minecraft:gravel"},
        {pos: [5, 1, 7], state: "minecraft:gravel"},
        {pos: [6, 1, 3], state: "minecraft:gravel"},
        {pos: [6, 1, 4], state: "minecraft:gravel"},
        {pos: [6, 1, 5], state: "minecraft:gravel"},
        {pos: [6, 1, 6], state: "minecraft:gravel"},
        {pos: [6, 1, 7], state: "minecraft:gravel"},
        {pos: [7, 1, 5], state: "minecraft:cobblestone"},
        {pos: [7, 1, 6], state: "minecraft:cobblestone"},
        {pos: [8, 1, 5], state: "minecraft:cobblestone"},
        {pos: [8, 1, 6], state: "minecraft:cobblestone"},
        {pos: [0, 2, 6], state: "minecraft:cobblestone"},
        {pos: [0, 2, 7], state: "minecraft:cobblestone"},
        {pos: [1, 2, 6], state: "minecraft:cobblestone"},
        {pos: [1, 2, 7], state: "minecraft:cobblestone"},
        {pos: [2, 2, 3], state: "minecraft:gravel"},
        {pos: [3, 2, 0], state: "minecraft:cobblestone"},
        {pos: [3, 2, 1], state: "minecraft:cobblestone"},
        {pos: [4, 2, 1], state: "minecraft:cobblestone"},
        {pos: [5, 2, 5], state: "minecraft:gravel"},
        {pos: [6, 2, 5], state: "minecraft:gravel"},
        {pos: [7, 2, 5], state: "minecraft:cobblestone"},
        {pos: [7, 2, 6], state: "minecraft:cobblestone"},
        {pos: [8, 2, 5], state: "minecraft:cobblestone"},
        {pos: [8, 2, 6], state: "minecraft:cobblestone"},
        {pos: [0, 3, 7], state: "minecraft:cobblestone"},
        {pos: [1, 3, 6], state: "minecraft:cobblestone"},
        {pos: [1, 3, 7], state: "minecraft:cobblestone"},
        {pos: [3, 3, 1], state: "minecraft:cobblestone"},
        {pos: [4, 3, 1], state: "minecraft:cobblestone"},
        {pos: [6, 3, 5], state: "minecraft:gravel"},
        {pos: [7, 3, 5], state: "minecraft:cobblestone"},
        {pos: [7, 3, 6], state: "minecraft:cobblestone"},
        {pos: [8, 3, 5], state: "minecraft:cobblestone"},
        {pos: [8, 3, 6], state: "minecraft:cobblestone"},
        {pos: [0, 4, 7], state: "minecraft:cobblestone"},
        {pos: [1, 4, 7], state: "minecraft:cobblestone"},
        {pos: [7, 4, 5], state: "minecraft:cobblestone"},
        {pos: [7, 4, 6], state: "minecraft:cobblestone"},
        {pos: [8, 4, 5], state: "minecraft:cobblestone"},
        {pos: [8, 4, 6], state: "minecraft:cobblestone"},
        {pos: [7, 5, 5], state: "minecraft:cobblestone"},
        {pos: [7, 5, 6], state: "minecraft:cobblestone"},
        {pos: [8, 5, 6], state: "minecraft:cobblestone"},
        {pos: [7, 6, 6], state: "minecraft:cobblestone"},
        {pos: [8, 6, 6], state: "minecraft:cobblestone"},
        {pos: [7, 7, 6], state: "minecraft:gravel"}
    ],
    entities: [],
    palette: [
        "minecraft:cobblestone",
        "minecraft:gravel"
    ],
    trailiertales_DataVersion: 2
}
