{
    DataVersion: 3953,
    size: [7, 7, 7],
    data: [
        {pos: [0, 0, 2], state: "minecraft:gravel"},
        {pos: [0, 0, 3], state: "minecraft:gravel"},
        {pos: [0, 0, 4], state: "minecraft:gravel"},
        {pos: [1, 0, 1], state: "minecraft:gravel"},
        {pos: [1, 0, 2], state: "minecraft:cobblestone"},
        {pos: [1, 0, 3], state: "minecraft:cobblestone"},
        {pos: [1, 0, 4], state: "minecraft:cobblestone"},
        {pos: [1, 0, 5], state: "minecraft:gravel"},
        {pos: [2, 0, 1], state: "minecraft:cobblestone"},
        {pos: [2, 0, 2], state: "minecraft:cobblestone"},
        {pos: [2, 0, 3], state: "minecraft:cobblestone"},
        {pos: [2, 0, 4], state: "minecraft:cobblestone"},
        {pos: [2, 0, 5], state: "minecraft:cobblestone"},
        {pos: [2, 0, 6], state: "minecraft:gravel"},
        {pos: [3, 0, 1], state: "minecraft:cobblestone"},
        {pos: [3, 0, 2], state: "minecraft:cobblestone"},
        {pos: [3, 0, 3], state: "minecraft:cobblestone"},
        {pos: [3, 0, 4], state: "minecraft:cobblestone"},
        {pos: [3, 0, 5], state: "minecraft:cobblestone"},
        {pos: [3, 0, 6], state: "minecraft:gravel"},
        {pos: [4, 0, 0], state: "minecraft:gravel"},
        {pos: [4, 0, 1], state: "minecraft:cobblestone"},
        {pos: [4, 0, 2], state: "minecraft:cobblestone"},
        {pos: [4, 0, 3], state: "minecraft:cobblestone"},
        {pos: [4, 0, 4], state: "minecraft:cobblestone"},
        {pos: [4, 0, 5], state: "minecraft:cobblestone"},
        {pos: [4, 0, 6], state: "minecraft:gravel"},
        {pos: [5, 0, 0], state: "minecraft:gravel"},
        {pos: [5, 0, 1], state: "minecraft:cobblestone"},
        {pos: [5, 0, 2], state: "minecraft:cobblestone"},
        {pos: [5, 0, 3], state: "minecraft:cobblestone"},
        {pos: [5, 0, 4], state: "minecraft:cobblestone"},
        {pos: [5, 0, 5], state: "minecraft:gravel"},
        {pos: [6, 0, 2], state: "minecraft:gravel"},
        {pos: [6, 0, 3], state: "minecraft:gravel"},
        {pos: [6, 0, 4], state: "minecraft:gravel"},
        {pos: [0, 1, 2], state: "minecraft:gravel"},
        {pos: [0, 1, 3], state: "minecraft:gravel"},
        {pos: [0, 1, 4], state: "minecraft:gravel"},
        {pos: [1, 1, 2], state: "minecraft:cobblestone"},
        {pos: [1, 1, 3], state: "minecraft:cobblestone"},
        {pos: [1, 1, 4], state: "minecraft:cobblestone"},
        {pos: [1, 1, 5], state: "minecraft:gravel"},
        {pos: [2, 1, 1], state: "minecraft:cobblestone"},
        {pos: [2, 1, 2], state: "minecraft:gravel"},
        {pos: [2, 1, 3], state: "minecraft:gravel"},
        {pos: [2, 1, 4], state: "minecraft:gravel"},
        {pos: [2, 1, 5], state: "minecraft:cobblestone"},
        {pos: [2, 1, 6], state: "minecraft:gravel"},
        {pos: [3, 1, 1], state: "minecraft:gravel"},
        {pos: [3, 1, 2], state: "minecraft:gravel"},
        {pos: [3, 1, 3], state: "minecraft:gravel"},
        {pos: [3, 1, 4], state: "minecraft:cobblestone_stairs{facing:south,half:top,shape:straight,waterlogged:false}"},
        {pos: [3, 1, 5], state: "minecraft:cobblestone"},
        {pos: [3, 1, 6], state: "minecraft:gravel"},
        {pos: [4, 1, 1], state: "minecraft:cobblestone"},
        {pos: [4, 1, 2], state: "minecraft:cobblestone"},
        {pos: [4, 1, 3], state: "minecraft:gravel"},
        {pos: [4, 1, 4], state: "minecraft:cobblestone_stairs{facing:south,half:top,shape:straight,waterlogged:false}"},
        {pos: [4, 1, 5], state: "minecraft:cobblestone"},
        {pos: [5, 1, 1], state: "minecraft:cobblestone"},
        {pos: [5, 1, 2], state: "minecraft:cobblestone"},
        {pos: [5, 1, 3], state: "minecraft:cobblestone"},
        {pos: [5, 1, 4], state: "minecraft:cobblestone"},
        {pos: [5, 1, 5], state: "minecraft:gravel"},
        {pos: [6, 1, 2], state: "minecraft:gravel"},
        {pos: [6, 1, 3], state: "minecraft:gravel"},
        {pos: [6, 1, 4], state: "minecraft:gravel"},
        {pos: [1, 2, 2], state: "minecraft:cobblestone"},
        {pos: [1, 2, 3], state: "minecraft:cobblestone"},
        {pos: [1, 2, 4], state: "minecraft:cobblestone"},
        {pos: [2, 2, 1], state: "minecraft:cobblestone"},
        {pos: [2, 2, 2], state: "minecraft:gravel"},
        {pos: [2, 2, 3], state: "minecraft:gravel"},
        {pos: [2, 2, 4], state: "minecraft:gravel"},
        {pos: [2, 2, 5], state: "minecraft:cobblestone"},
        {pos: [3, 2, 1], state: "minecraft:gravel"},
        {pos: [3, 2, 2], state: "minecraft:gravel"},
        {pos: [3, 2, 3], state: "minecraft:gravel"},
        {pos: [3, 2, 4], state: "minecraft:gravel"},
        {pos: [3, 2, 5], state: "minecraft:cobblestone"},
        {pos: [4, 2, 1], state: "minecraft:cobblestone"},
        {pos: [4, 2, 2], state: "minecraft:gravel"},
        {pos: [4, 2, 3], state: "minecraft:gravel"},
        {pos: [4, 2, 4], state: "minecraft:gravel"},
        {pos: [4, 2, 5], state: "minecraft:cobblestone"},
        {pos: [5, 2, 2], state: "minecraft:cobblestone"},
        {pos: [5, 2, 3], state: "minecraft:cobblestone"},
        {pos: [5, 2, 4], state: "minecraft:cobblestone"},
        {pos: [5, 2, 5], state: "minecraft:gravel"},
        {pos: [1, 3, 2], state: "minecraft:cobblestone"},
        {pos: [1, 3, 3], state: "minecraft:cobblestone"},
        {pos: [1, 3, 4], state: "minecraft:cobblestone"},
        {pos: [2, 3, 1], state: "minecraft:cobblestone"},
        {pos: [2, 3, 2], state: "minecraft:gravel"},
        {pos: [2, 3, 3], state: "minecraft:gravel"},
        {pos: [2, 3, 4], state: "minecraft:gravel"},
        {pos: [2, 3, 5], state: "minecraft:cobblestone"},
        {pos: [3, 3, 0], state: "minecraft:cobblestone_wall{east:none,north:none,south:low,up:true,waterlogged:false,west:none}"},
        {pos: [3, 3, 1], state: "minecraft:cobblestone"},
        {pos: [3, 3, 2], state: "minecraft:gravel"},
        {pos: [3, 3, 3], state: "minecraft:gravel"},
        {pos: [3, 3, 4], state: "minecraft:gravel"},
        {pos: [3, 3, 5], state: "minecraft:cobblestone"},
        {pos: [4, 3, 1], state: "minecraft:cobblestone"},
        {pos: [4, 3, 2], state: "minecraft:gravel"},
        {pos: [4, 3, 3], state: "minecraft:gravel"},
        {pos: [4, 3, 4], state: "minecraft:gravel"},
        {pos: [4, 3, 5], state: "minecraft:cobblestone"},
        {pos: [5, 3, 2], state: "minecraft:cobblestone"},
        {pos: [5, 3, 3], state: "minecraft:cobblestone"},
        {pos: [5, 3, 4], state: "minecraft:cobblestone"},
        {pos: [1, 4, 2], state: "minecraft:cobblestone"},
        {pos: [1, 4, 3], state: "minecraft:cobblestone"},
        {pos: [1, 4, 4], state: "minecraft:cobblestone"},
        {pos: [2, 4, 1], state: "minecraft:cobblestone_stairs{facing:south,half:top,shape:straight,waterlogged:false}"},
        {pos: [2, 4, 2], state: "minecraft:gravel"},
        {pos: [2, 4, 3], state: "minecraft:gravel"},
        {pos: [2, 4, 4], state: "minecraft:cobblestone"},
        {pos: [2, 4, 5], state: "minecraft:cobblestone"},
        {pos: [3, 4, 1], state: "minecraft:cobblestone"},
        {pos: [3, 4, 2], state: "minecraft:gravel"},
        {pos: [3, 4, 3], state: "minecraft:gravel"},
        {pos: [3, 4, 4], state: "minecraft:gravel"},
        {pos: [3, 4, 5], state: "minecraft:cobblestone"},
        {pos: [4, 4, 1], state: "minecraft:cobblestone_stairs{facing:south,half:top,shape:straight,waterlogged:false}"},
        {pos: [4, 4, 2], state: "minecraft:cobblestone"},
        {pos: [4, 4, 3], state: "minecraft:gravel"},
        {pos: [4, 4, 4], state: "minecraft:gravel"},
        {pos: [4, 4, 5], state: "minecraft:cobblestone"},
        {pos: [5, 4, 2], state: "minecraft:cobblestone"},
        {pos: [5, 4, 3], state: "minecraft:cobblestone"},
        {pos: [5, 4, 4], state: "minecraft:cobblestone"},
        {pos: [1, 5, 2], state: "minecraft:cobblestone"},
        {pos: [1, 5, 3], state: "minecraft:cobblestone"},
        {pos: [1, 5, 4], state: "minecraft:cobblestone"},
        {pos: [2, 5, 1], state: "minecraft:cobblestone"},
        {pos: [2, 5, 3], state: "minecraft:gravel"},
        {pos: [2, 5, 4], state: "minecraft:cobblestone"},
        {pos: [3, 5, 1], state: "minecraft:cobblestone"},
        {pos: [3, 5, 2], state: "minecraft:cobblestone"},
        {pos: [3, 5, 3], state: "minecraft:gravel"},
        {pos: [3, 5, 4], state: "minecraft:gravel"},
        {pos: [3, 5, 5], state: "minecraft:cobblestone"},
        {pos: [4, 5, 1], state: "minecraft:cobblestone"},
        {pos: [4, 5, 2], state: "minecraft:cobblestone"},
        {pos: [4, 5, 3], state: "minecraft:cobblestone"},
        {pos: [4, 5, 4], state: "minecraft:gravel"},
        {pos: [4, 5, 5], state: "minecraft:cobblestone"},
        {pos: [5, 5, 2], state: "minecraft:cobblestone"},
        {pos: [5, 5, 3], state: "minecraft:cobblestone"},
        {pos: [5, 5, 4], state: "minecraft:cobblestone"},
        {pos: [2, 6, 3], state: "minecraft:cobblestone"},
        {pos: [2, 6, 4], state: "minecraft:cobblestone"},
        {pos: [3, 6, 3], state: "minecraft:cobblestone"},
        {pos: [3, 6, 4], state: "minecraft:cobblestone"},
        {pos: [4, 6, 2], state: "minecraft:cobblestone"},
        {pos: [4, 6, 3], state: "minecraft:cobblestone"}
    ],
    entities: [],
    palette: [
        "minecraft:gravel",
        "minecraft:cobblestone",
        "minecraft:cobblestone_stairs{facing:south,half:top,shape:straight,waterlogged:false}",
        "minecraft:cobblestone_wall{east:none,north:none,south:low,up:true,waterlogged:false,west:none}"
    ],
    trailiertales_DataVersion: 2
}
