{
    DataVersion: 3953,
    size: [10, 12, 10],
    data: [
        {pos: [0, 0, 3], state: "minecraft:sandstone"},
        {pos: [0, 0, 4], state: "minecraft:sandstone"},
        {pos: [0, 0, 5], state: "minecraft:sandstone"},
        {pos: [0, 0, 6], state: "minecraft:sandstone"},
        {pos: [0, 0, 7], state: "minecraft:sandstone"},
        {pos: [0, 0, 8], state: "minecraft:sandstone"},
        {pos: [0, 0, 9], state: "minecraft:sandstone"},
        {pos: [1, 0, 3], state: "minecraft:sandstone"},
        {pos: [1, 0, 4], state: "minecraft:sandstone"},
        {pos: [1, 0, 5], state: "minecraft:sandstone"},
        {pos: [1, 0, 6], state: "minecraft:sandstone"},
        {pos: [1, 0, 7], state: "minecraft:sandstone"},
        {pos: [1, 0, 8], state: "minecraft:sandstone"},
        {pos: [1, 0, 9], state: "minecraft:sandstone"},
        {pos: [2, 0, 3], state: "minecraft:sandstone"},
        {pos: [2, 0, 4], state: "minecraft:sandstone"},
        {pos: [2, 0, 5], state: "minecraft:sandstone"},
        {pos: [2, 0, 6], state: "minecraft:sandstone"},
        {pos: [2, 0, 7], state: "minecraft:sandstone"},
        {pos: [2, 0, 8], state: "minecraft:sandstone"},
        {pos: [2, 0, 9], state: "minecraft:sand"},
        {pos: [3, 0, 3], state: "minecraft:sandstone"},
        {pos: [3, 0, 4], state: "minecraft:sandstone"},
        {pos: [3, 0, 5], state: "minecraft:sandstone"},
        {pos: [3, 0, 6], state: "minecraft:sandstone"},
        {pos: [3, 0, 7], state: "minecraft:sandstone"},
        {pos: [3, 0, 8], state: "minecraft:sandstone"},
        {pos: [3, 0, 9], state: "minecraft:sandstone"},
        {pos: [4, 0, 3], state: "minecraft:sandstone"},
        {pos: [4, 0, 4], state: "minecraft:sandstone"},
        {pos: [4, 0, 5], state: "minecraft:sandstone"},
        {pos: [4, 0, 6], state: "minecraft:sandstone"},
        {pos: [4, 0, 7], state: "minecraft:sandstone"},
        {pos: [4, 0, 8], state: "minecraft:sandstone"},
        {pos: [4, 0, 9], state: "minecraft:sandstone"},
        {pos: [5, 0, 4], state: "minecraft:sandstone"},
        {pos: [5, 0, 5], state: "minecraft:sandstone"},
        {pos: [5, 0, 6], state: "minecraft:sandstone"},
        {pos: [5, 0, 7], state: "minecraft:sandstone"},
        {pos: [5, 0, 8], state: "minecraft:sandstone"},
        {pos: [5, 0, 9], state: "minecraft:sandstone"},
        {pos: [6, 0, 4], state: "minecraft:sandstone"},
        {pos: [6, 0, 5], state: "minecraft:sandstone"},
        {pos: [6, 0, 6], state: "minecraft:sandstone"},
        {pos: [6, 0, 7], state: "minecraft:sandstone"},
        {pos: [8, 0, 0], state: "minecraft:sandstone"},
        {pos: [8, 0, 1], state: "minecraft:sandstone"},
        {pos: [9, 0, 0], state: "minecraft:sandstone"},
        {pos: [9, 0, 1], state: "minecraft:sandstone"},
        {pos: [0, 1, 4], state: "minecraft:sandstone"},
        {pos: [0, 1, 5], state: "minecraft:sandstone"},
        {pos: [0, 1, 6], state: "minecraft:sandstone"},
        {pos: [0, 1, 7], state: "minecraft:sand"},
        {pos: [0, 1, 8], state: "minecraft:sand"},
        {pos: [0, 1, 9], state: "minecraft:sandstone"},
        {pos: [1, 1, 3], state: "minecraft:chiseled_sandstone"},
        {pos: [1, 1, 4], state: "minecraft:sand"},
        {pos: [1, 1, 5], state: "minecraft:sand"},
        {pos: [1, 1, 6], state: "minecraft:sand"},
        {pos: [1, 1, 7], state: "minecraft:sand"},
        {pos: [1, 1, 8], state: "minecraft:sand"},
        {pos: [1, 1, 9], state: "minecraft:sandstone"},
        {pos: [2, 1, 3], state: "minecraft:sandstone"},
        {pos: [2, 1, 4], state: "minecraft:sand"},
        {pos: [2, 1, 5], state: "minecraft:sand"},
        {pos: [2, 1, 6], state: "minecraft:sand"},
        {pos: [2, 1, 7], state: "minecraft:sand"},
        {pos: [2, 1, 8], state: "minecraft:sand"},
        {pos: [2, 1, 9], state: "minecraft:sand"},
        {pos: [3, 1, 3], state: "minecraft:sand"},
        {pos: [3, 1, 4], state: "minecraft:sand"},
        {pos: [3, 1, 5], state: "minecraft:sand"},
        {pos: [3, 1, 6], state: "minecraft:sand"},
        {pos: [3, 1, 7], state: "minecraft:sand"},
        {pos: [3, 1, 8], state: "minecraft:sand"},
        {pos: [3, 1, 9], state: "minecraft:sand"},
        {pos: [4, 1, 3], state: "minecraft:sandstone"},
        {pos: [4, 1, 4], state: "minecraft:sand"},
        {pos: [4, 1, 5], state: "minecraft:sand"},
        {pos: [4, 1, 6], state: "minecraft:sand"},
        {pos: [4, 1, 7], state: "minecraft:sand"},
        {pos: [4, 1, 8], state: "minecraft:sand"},
        {pos: [4, 1, 9], state: "minecraft:sandstone"},
        {pos: [5, 1, 3], state: "minecraft:chiseled_sandstone"},
        {pos: [5, 1, 4], state: "minecraft:sand"},
        {pos: [5, 1, 5], state: "minecraft:sandstone_stairs{facing:east,half:top,shape:straight,waterlogged:false}"},
        {pos: [5, 1, 6], state: "minecraft:sandstone_stairs{facing:east,half:top,shape:straight,waterlogged:false}"},
        {pos: [5, 1, 7], state: "minecraft:sandstone_stairs{facing:east,half:top,shape:straight,waterlogged:false}"},
        {pos: [5, 1, 8], state: "minecraft:sand"},
        {pos: [5, 1, 9], state: "minecraft:sandstone"},
        {pos: [6, 1, 3], state: "minecraft:sandstone"},
        {pos: [6, 1, 4], state: "minecraft:sandstone"},
        {pos: [6, 1, 5], state: "minecraft:sandstone"},
        {pos: [6, 1, 6], state: "minecraft:smooth_sandstone"},
        {pos: [6, 1, 7], state: "minecraft:sandstone"},
        {pos: [6, 1, 8], state: "minecraft:sandstone"},
        {pos: [8, 1, 0], state: "minecraft:sandstone"},
        {pos: [8, 1, 1], state: "minecraft:sandstone"},
        {pos: [9, 1, 0], state: "minecraft:sandstone"},
        {pos: [9, 1, 1], state: "minecraft:sand"},
        {pos: [0, 2, 3], state: "minecraft:sandstone"},
        {pos: [0, 2, 4], state: "minecraft:sandstone"},
        {pos: [0, 2, 5], state: "minecraft:sandstone"},
        {pos: [0, 2, 6], state: "minecraft:smooth_sandstone"},
        {pos: [0, 2, 7], state: "minecraft:sand"},
        {pos: [0, 2, 8], state: "minecraft:sand"},
        {pos: [0, 2, 9], state: "minecraft:sand"},
        {pos: [1, 2, 3], state: "minecraft:sand"},
        {pos: [1, 2, 4], state: "minecraft:sand"},
        {pos: [1, 2, 5], state: "minecraft:sand"},
        {pos: [1, 2, 6], state: "minecraft:sand"},
        {pos: [1, 2, 7], state: "minecraft:sand"},
        {pos: [1, 2, 8], state: "minecraft:sand"},
        {pos: [1, 2, 9], state: "minecraft:smooth_sandstone"},
        {pos: [2, 2, 3], state: "minecraft:smooth_sandstone"},
        {pos: [2, 2, 4], state: "minecraft:sand"},
        {pos: [2, 2, 5], state: "minecraft:sand"},
        {pos: [2, 2, 6], state: "minecraft:sand"},
        {pos: [2, 2, 7], state: "minecraft:sand"},
        {pos: [2, 2, 8], state: "minecraft:sand"},
        {pos: [2, 2, 9], state: "minecraft:smooth_sandstone"},
        {pos: [3, 2, 3], state: "minecraft:sand"},
        {pos: [3, 2, 4], state: "minecraft:sand"},
        {pos: [3, 2, 5], state: "minecraft:sand"},
        {pos: [3, 2, 6], state: "minecraft:sand"},
        {pos: [3, 2, 7], state: "minecraft:sand"},
        {pos: [3, 2, 8], state: "minecraft:sand"},
        {pos: [3, 2, 9], state: "minecraft:sand"},
        {pos: [4, 2, 3], state: "minecraft:smooth_sandstone"},
        {pos: [4, 2, 4], state: "minecraft:sand"},
        {pos: [4, 2, 5], state: "minecraft:sand"},
        {pos: [4, 2, 6], state: "minecraft:sand"},
        {pos: [4, 2, 7], state: "minecraft:sand"},
        {pos: [4, 2, 8], state: "minecraft:sand"},
        {pos: [4, 2, 9], state: "minecraft:smooth_sandstone"},
        {pos: [5, 2, 3], state: "minecraft:sand"},
        {pos: [5, 2, 4], state: "minecraft:sand"},
        {pos: [5, 2, 5], state: "minecraft:sand"},
        {pos: [5, 2, 6], state: "minecraft:sand"},
        {pos: [5, 2, 7], state: "minecraft:sand"},
        {pos: [5, 2, 8], state: "minecraft:sand"},
        {pos: [5, 2, 9], state: "minecraft:smooth_sandstone"},
        {pos: [6, 2, 3], state: "minecraft:sandstone"},
        {pos: [6, 2, 4], state: "minecraft:sandstone"},
        {pos: [6, 2, 5], state: "minecraft:smooth_sandstone"},
        {pos: [6, 2, 6], state: "minecraft:smooth_sandstone"},
        {pos: [6, 2, 7], state: "minecraft:smooth_sandstone"},
        {pos: [6, 2, 8], state: "minecraft:smooth_sandstone"},
        {pos: [6, 2, 9], state: "minecraft:smooth_sandstone"},
        {pos: [8, 2, 0], state: "minecraft:sand"},
        {pos: [8, 2, 1], state: "minecraft:smooth_sandstone"},
        {pos: [9, 2, 0], state: "minecraft:sandstone"},
        {pos: [9, 2, 1], state: "minecraft:sandstone"},
        {pos: [0, 3, 3], state: "minecraft:smooth_sandstone"},
        {pos: [0, 3, 4], state: "minecraft:smooth_sandstone"},
        {pos: [0, 3, 5], state: "minecraft:smooth_sandstone"},
        {pos: [0, 3, 6], state: "minecraft:smooth_sandstone"},
        {pos: [0, 3, 7], state: "minecraft:smooth_sandstone"},
        {pos: [0, 3, 8], state: "minecraft:sand"},
        {pos: [1, 3, 3], state: "minecraft:smooth_sandstone"},
        {pos: [1, 3, 4], state: "minecraft:sand"},
        {pos: [1, 3, 5], state: "minecraft:sand"},
        {pos: [1, 3, 6], state: "minecraft:sand"},
        {pos: [1, 3, 7], state: "minecraft:sand"},
        {pos: [1, 3, 8], state: "minecraft:sand"},
        {pos: [1, 3, 9], state: "minecraft:smooth_sandstone"},
        {pos: [2, 3, 3], state: "minecraft:smooth_sandstone"},
        {pos: [2, 3, 4], state: "minecraft:sand"},
        {pos: [2, 3, 5], state: "minecraft:sand"},
        {pos: [2, 3, 6], state: "minecraft:sand"},
        {pos: [2, 3, 7], state: "minecraft:sand"},
        {pos: [2, 3, 8], state: "minecraft:sand"},
        {pos: [2, 3, 9], state: "minecraft:smooth_sandstone"},
        {pos: [3, 3, 3], state: "minecraft:smooth_sandstone"},
        {pos: [3, 3, 4], state: "minecraft:sand"},
        {pos: [3, 3, 5], state: "minecraft:sand"},
        {pos: [3, 3, 6], state: "minecraft:sand"},
        {pos: [3, 3, 7], state: "minecraft:sand"},
        {pos: [3, 3, 8], state: "minecraft:sand"},
        {pos: [3, 3, 9], state: "minecraft:smooth_sandstone"},
        {pos: [4, 3, 3], state: "minecraft:smooth_sandstone"},
        {pos: [4, 3, 4], state: "minecraft:sand"},
        {pos: [4, 3, 5], state: "minecraft:sand"},
        {pos: [4, 3, 6], state: "minecraft:sand"},
        {pos: [4, 3, 7], state: "minecraft:sand"},
        {pos: [4, 3, 8], state: "minecraft:sand"},
        {pos: [4, 3, 9], state: "minecraft:smooth_sandstone"},
        {pos: [5, 3, 3], state: "minecraft:smooth_sandstone"},
        {pos: [5, 3, 4], state: "minecraft:sand"},
        {pos: [5, 3, 5], state: "minecraft:sand"},
        {pos: [5, 3, 6], state: "minecraft:sand"},
        {pos: [5, 3, 7], state: "minecraft:sand"},
        {pos: [5, 3, 8], state: "minecraft:sand"},
        {pos: [5, 3, 9], state: "minecraft:smooth_sandstone"},
        {pos: [6, 3, 3], state: "minecraft:smooth_sandstone"},
        {pos: [6, 3, 4], state: "minecraft:smooth_sandstone"},
        {pos: [6, 3, 5], state: "minecraft:smooth_sandstone"},
        {pos: [6, 3, 6], state: "minecraft:smooth_sandstone"},
        {pos: [6, 3, 7], state: "minecraft:smooth_sandstone"},
        {pos: [6, 3, 8], state: "minecraft:smooth_sandstone"},
        {pos: [6, 3, 9], state: "minecraft:smooth_sandstone"},
        {pos: [8, 3, 1], state: "minecraft:smooth_sandstone"},
        {pos: [9, 3, 0], state: "minecraft:sandstone"},
        {pos: [9, 3, 1], state: "minecraft:smooth_sandstone"},
        {pos: [0, 4, 3], state: "minecraft:yellow_terracotta"},
        {pos: [0, 4, 4], state: "minecraft:yellow_terracotta"},
        {pos: [0, 4, 5], state: "minecraft:yellow_terracotta"},
        {pos: [0, 4, 6], state: "minecraft:yellow_terracotta"},
        {pos: [0, 4, 7], state: "minecraft:yellow_terracotta"},
        {pos: [0, 4, 8], state: "minecraft:yellow_terracotta"},
        {pos: [0, 4, 9], state: "minecraft:yellow_terracotta"},
        {pos: [1, 4, 3], state: "minecraft:yellow_terracotta"},
        {pos: [1, 4, 4], state: "minecraft:sand"},
        {pos: [1, 4, 5], state: "minecraft:sand"},
        {pos: [1, 4, 6], state: "minecraft:sand"},
        {pos: [1, 4, 8], state: "minecraft:sand"},
        {pos: [1, 4, 9], state: "minecraft:yellow_terracotta"},
        {pos: [2, 4, 3], state: "minecraft:sand"},
        {pos: [2, 4, 4], state: "minecraft:sand"},
        {pos: [2, 4, 5], state: "minecraft:sand"},
        {pos: [2, 4, 8], state: "minecraft:sand"},
        {pos: [2, 4, 9], state: "minecraft:yellow_terracotta"},
        {pos: [3, 4, 3], state: "minecraft:yellow_terracotta"},
        {pos: [3, 4, 4], state: "minecraft:sand"},
        {pos: [3, 4, 7], state: "minecraft:sand"},
        {pos: [3, 4, 8], state: "minecraft:sand"},
        {pos: [3, 4, 9], state: "minecraft:yellow_terracotta"},
        {pos: [4, 4, 3], state: "minecraft:yellow_terracotta"},
        {pos: [4, 4, 4], state: "minecraft:sand"},
        {pos: [4, 4, 6], state: "minecraft:sand"},
        {pos: [4, 4, 7], state: "minecraft:sand"},
        {pos: [4, 4, 8], state: "minecraft:sand"},
        {pos: [4, 4, 9], state: "minecraft:yellow_terracotta"},
        {pos: [5, 4, 3], state: "minecraft:yellow_terracotta"},
        {pos: [5, 4, 4], state: "minecraft:sand"},
        {pos: [5, 4, 6], state: "minecraft:sand"},
        {pos: [5, 4, 7], state: "minecraft:sand"},
        {pos: [5, 4, 8], state: "minecraft:sand"},
        {pos: [5, 4, 9], state: "minecraft:yellow_terracotta"},
        {pos: [6, 4, 3], state: "minecraft:yellow_terracotta"},
        {pos: [6, 4, 4], state: "minecraft:yellow_terracotta"},
        {pos: [6, 4, 5], state: "minecraft:yellow_terracotta"},
        {pos: [6, 4, 6], state: "minecraft:yellow_terracotta"},
        {pos: [6, 4, 7], state: "minecraft:yellow_terracotta"},
        {pos: [6, 4, 8], state: "minecraft:yellow_terracotta"},
        {pos: [6, 4, 9], state: "minecraft:sand"},
        {pos: [8, 4, 0], state: "minecraft:smooth_sandstone"},
        {pos: [8, 4, 1], state: "minecraft:smooth_sandstone"},
        {pos: [9, 4, 0], state: "minecraft:smooth_sandstone"},
        {pos: [9, 4, 1], state: "minecraft:smooth_sandstone"},
        {pos: [0, 5, 4], state: "minecraft:cut_sandstone"},
        {pos: [0, 5, 5], state: "minecraft:cut_sandstone"},
        {pos: [0, 5, 6], state: "minecraft:cut_sandstone"},
        {pos: [0, 5, 7], state: "minecraft:cut_sandstone"},
        {pos: [0, 5, 8], state: "minecraft:cut_sandstone"},
        {pos: [1, 5, 3], state: "minecraft:cut_sandstone"},
        {pos: [1, 5, 4], state: "minecraft:sand"},
        {pos: [1, 5, 5], state: "minecraft:sand"},
        {pos: [1, 5, 9], state: "minecraft:cut_sandstone"},
        {pos: [2, 5, 9], state: "minecraft:cut_sandstone"},
        {pos: [3, 5, 8], state: "minecraft:sand"},
        {pos: [3, 5, 9], state: "minecraft:cut_sandstone"},
        {pos: [4, 5, 3], state: "minecraft:cut_sandstone"},
        {pos: [4, 5, 7], state: "minecraft:sand"},
        {pos: [4, 5, 8], state: "minecraft:sand"},
        {pos: [4, 5, 9], state: "minecraft:cut_sandstone"},
        {pos: [5, 5, 3], state: "minecraft:cut_sandstone"},
        {pos: [5, 5, 7], state: "minecraft:sand"},
        {pos: [5, 5, 8], state: "minecraft:sand"},
        {pos: [5, 5, 9], state: "minecraft:cut_sandstone"},
        {pos: [6, 5, 4], state: "minecraft:cut_sandstone"},
        {pos: [6, 5, 5], state: "minecraft:cut_sandstone"},
        {pos: [6, 5, 6], state: "minecraft:cut_sandstone"},
        {pos: [6, 5, 7], state: "minecraft:cut_sandstone"},
        {pos: [6, 5, 8], state: "minecraft:cut_sandstone"},
        {pos: [8, 5, 0], state: "minecraft:smooth_sandstone"},
        {pos: [8, 5, 1], state: "minecraft:smooth_sandstone"},
        {pos: [9, 5, 0], state: "minecraft:smooth_sandstone"},
        {pos: [9, 5, 1], state: "minecraft:smooth_sandstone"},
        {pos: [8, 6, 0], state: "minecraft:blue_terracotta"},
        {pos: [8, 6, 1], state: "minecraft:blue_terracotta"},
        {pos: [9, 6, 0], state: "minecraft:blue_terracotta"},
        {pos: [9, 6, 1], state: "minecraft:blue_terracotta"},
        {pos: [8, 7, 0], state: "minecraft:chiseled_sandstone"},
        {pos: [8, 7, 1], state: "minecraft:chiseled_sandstone"},
        {pos: [9, 7, 0], state: "minecraft:chiseled_sandstone"},
        {pos: [9, 7, 1], state: "minecraft:chiseled_sandstone"},
        {pos: [8, 8, 0], state: "minecraft:yellow_terracotta"},
        {pos: [8, 8, 1], state: "minecraft:yellow_terracotta"},
        {pos: [9, 8, 0], state: "minecraft:yellow_terracotta"},
        {pos: [9, 8, 1], state: "minecraft:yellow_terracotta"},
        {pos: [8, 9, 0], state: "minecraft:smooth_sandstone"},
        {pos: [8, 9, 1], state: "minecraft:smooth_sandstone"},
        {pos: [9, 9, 0], state: "minecraft:smooth_sandstone"},
        {pos: [9, 9, 1], state: "minecraft:smooth_sandstone"},
        {pos: [8, 10, 0], state: "minecraft:smooth_sandstone"},
        {pos: [8, 10, 1], state: "minecraft:smooth_sandstone"},
        {pos: [9, 10, 0], state: "minecraft:smooth_sandstone"},
        {pos: [9, 10, 1], state: "minecraft:smooth_sandstone"},
        {pos: [8, 11, 0], state: "minecraft:cut_sandstone"},
        {pos: [8, 11, 1], state: "minecraft:cut_sandstone"},
        {pos: [9, 11, 0], state: "minecraft:cut_sandstone"},
        {pos: [9, 11, 1], state: "minecraft:cut_sandstone"}
    ],
    entities: [],
    palette: [
        "minecraft:sandstone",
        "minecraft:sand",
        "minecraft:chiseled_sandstone",
        "minecraft:smooth_sandstone",
        "minecraft:yellow_terracotta",
        "minecraft:cut_sandstone",
        "minecraft:blue_terracotta",
        "minecraft:sandstone_stairs{facing:east,half:top,shape:straight,waterlogged:false}"
    ],
    trailiertales_DataVersion: 2
}
