{
    DataVersion: 3953,
    size: [9, 11, 9],
    data: [
        {pos: [2, 0, 3], state: "minecraft:sandstone"},
        {pos: [2, 0, 4], state: "minecraft:sandstone"},
        {pos: [3, 0, 2], state: "minecraft:sandstone"},
        {pos: [3, 0, 3], state: "minecraft:sandstone"},
        {pos: [3, 0, 4], state: "minecraft:sandstone"},
        {pos: [3, 0, 5], state: "minecraft:sandstone"},
        {pos: [4, 0, 2], state: "minecraft:sandstone"},
        {pos: [4, 0, 3], state: "minecraft:sandstone"},
        {pos: [4, 0, 4], state: "minecraft:sandstone"},
        {pos: [4, 0, 5], state: "minecraft:sandstone"},
        {pos: [4, 0, 6], state: "minecraft:sandstone"},
        {pos: [5, 0, 2], state: "minecraft:sandstone"},
        {pos: [5, 0, 3], state: "minecraft:sandstone"},
        {pos: [5, 0, 4], state: "minecraft:sandstone"},
        {pos: [5, 0, 5], state: "minecraft:sandstone"},
        {pos: [6, 0, 4], state: "minecraft:sandstone"},
        {pos: [6, 0, 5], state: "minecraft:sandstone"},
        {pos: [2, 1, 2], state: "minecraft:sandstone"},
        {pos: [2, 1, 3], state: "minecraft:sandstone"},
        {pos: [2, 1, 4], state: "minecraft:sandstone"},
        {pos: [2, 1, 5], state: "minecraft:sandstone"},
        {pos: [3, 1, 2], state: "minecraft:sandstone"},
        {pos: [3, 1, 3], state: "minecraft:sand"},
        {pos: [3, 1, 4], state: "minecraft:sand"},
        {pos: [3, 1, 5], state: "minecraft:sand"},
        {pos: [3, 1, 6], state: "minecraft:sandstone"},
        {pos: [4, 1, 2], state: "minecraft:sandstone"},
        {pos: [4, 1, 3], state: "minecraft:sand"},
        {pos: [4, 1, 4], state: "minecraft:sand"},
        {pos: [4, 1, 5], state: "minecraft:sand"},
        {pos: [4, 1, 6], state: "minecraft:sandstone"},
        {pos: [5, 1, 2], state: "minecraft:sandstone"},
        {pos: [5, 1, 3], state: "minecraft:sand"},
        {pos: [5, 1, 4], state: "minecraft:sand"},
        {pos: [5, 1, 5], state: "minecraft:sand"},
        {pos: [5, 1, 6], state: "minecraft:sandstone"},
        {pos: [6, 1, 3], state: "minecraft:sandstone"},
        {pos: [6, 1, 4], state: "minecraft:sandstone"},
        {pos: [6, 1, 5], state: "minecraft:sandstone"},
        {pos: [1, 2, 4], state: "minecraft:sandstone"},
        {pos: [2, 2, 2], state: "minecraft:sandstone"},
        {pos: [2, 2, 3], state: "minecraft:sandstone"},
        {pos: [2, 2, 4], state: "minecraft:sandstone"},
        {pos: [2, 2, 5], state: "minecraft:sandstone"},
        {pos: [3, 2, 1], state: "minecraft:sandstone"},
        {pos: [3, 2, 2], state: "minecraft:sandstone"},
        {pos: [3, 2, 3], state: "minecraft:sand"},
        {pos: [3, 2, 4], state: "minecraft:sand"},
        {pos: [3, 2, 5], state: "minecraft:sand"},
        {pos: [3, 2, 6], state: "minecraft:sandstone"},
        {pos: [4, 2, 1], state: "minecraft:sandstone"},
        {pos: [4, 2, 2], state: "minecraft:sandstone"},
        {pos: [4, 2, 3], state: "minecraft:sand"},
        {pos: [4, 2, 4], state: "minecraft:sand"},
        {pos: [4, 2, 5], state: "minecraft:sand"},
        {pos: [4, 2, 6], state: "minecraft:sandstone"},
        {pos: [5, 2, 2], state: "minecraft:sandstone"},
        {pos: [5, 2, 3], state: "minecraft:sand"},
        {pos: [5, 2, 4], state: "minecraft:sand"},
        {pos: [5, 2, 5], state: "minecraft:sand"},
        {pos: [5, 2, 6], state: "minecraft:sandstone"},
        {pos: [6, 2, 2], state: "minecraft:sandstone"},
        {pos: [6, 2, 3], state: "minecraft:sandstone"},
        {pos: [6, 2, 4], state: "minecraft:sandstone"},
        {pos: [6, 2, 5], state: "minecraft:sandstone"},
        {pos: [6, 2, 6], state: "minecraft:sandstone"},
        {pos: [7, 2, 3], state: "minecraft:sandstone"},
        {pos: [7, 2, 4], state: "minecraft:sandstone"},
        {pos: [0, 3, 4], state: "minecraft:sandstone"},
        {pos: [0, 3, 5], state: "minecraft:sandstone"},
        {pos: [1, 3, 3], state: "minecraft:sandstone"},
        {pos: [1, 3, 4], state: "minecraft:sandstone"},
        {pos: [1, 3, 5], state: "minecraft:sandstone"},
        {pos: [2, 3, 2], state: "minecraft:sandstone"},
        {pos: [2, 3, 3], state: "minecraft:sandstone"},
        {pos: [2, 3, 4], state: "minecraft:sandstone"},
        {pos: [2, 3, 5], state: "minecraft:sandstone"},
        {pos: [2, 3, 6], state: "minecraft:sandstone"},
        {pos: [3, 3, 0], state: "minecraft:sandstone"},
        {pos: [3, 3, 1], state: "minecraft:sandstone"},
        {pos: [3, 3, 2], state: "minecraft:sandstone"},
        {pos: [3, 3, 3], state: "minecraft:sand"},
        {pos: [3, 3, 4], state: "minecraft:decorated_pot{cracked:false,facing:south,waterlogged:false}", nbt: {id: "minecraft:decorated_pot", sherds: ["minecraft:brick", "minecraft:arms_up_pottery_sherd", "minecraft:brewer_pottery_sherd", "minecraft:brick"]}},
        {pos: [3, 3, 5], state: "minecraft:sand"},
        {pos: [3, 3, 6], state: "minecraft:sandstone"},
        {pos: [3, 3, 7], state: "minecraft:sandstone"},
        {pos: [4, 3, 1], state: "minecraft:sandstone"},
        {pos: [4, 3, 2], state: "minecraft:sandstone"},
        {pos: [4, 3, 3], state: "minecraft:sand"},
        {pos: [4, 3, 4], state: "minecraft:sand"},
        {pos: [4, 3, 5], state: "minecraft:sand"},
        {pos: [4, 3, 6], state: "minecraft:sandstone"},
        {pos: [4, 3, 7], state: "minecraft:sandstone"},
        {pos: [5, 3, 1], state: "minecraft:sandstone"},
        {pos: [5, 3, 2], state: "minecraft:sandstone"},
        {pos: [5, 3, 3], state: "minecraft:sand"},
        {pos: [5, 3, 4], state: "minecraft:sand"},
        {pos: [5, 3, 5], state: "minecraft:sand"},
        {pos: [5, 3, 6], state: "minecraft:sandstone"},
        {pos: [6, 3, 2], state: "minecraft:sandstone"},
        {pos: [6, 3, 3], state: "minecraft:sandstone"},
        {pos: [6, 3, 4], state: "minecraft:sandstone"},
        {pos: [6, 3, 5], state: "minecraft:sandstone"},
        {pos: [6, 3, 6], state: "minecraft:sandstone"},
        {pos: [7, 3, 2], state: "minecraft:sandstone"},
        {pos: [7, 3, 3], state: "minecraft:sandstone"},
        {pos: [7, 3, 4], state: "minecraft:sandstone"},
        {pos: [7, 3, 5], state: "minecraft:sandstone"},
        {pos: [8, 3, 3], state: "minecraft:sandstone"},
        {pos: [8, 3, 4], state: "minecraft:sandstone"},
        {pos: [0, 4, 3], state: "minecraft:sandstone"},
        {pos: [0, 4, 4], state: "minecraft:sandstone"},
        {pos: [0, 4, 5], state: "minecraft:sandstone"},
        {pos: [0, 4, 6], state: "minecraft:sandstone"},
        {pos: [1, 4, 2], state: "minecraft:sandstone"},
        {pos: [1, 4, 3], state: "minecraft:sandstone"},
        {pos: [1, 4, 4], state: "minecraft:sandstone"},
        {pos: [1, 4, 5], state: "minecraft:sandstone"},
        {pos: [1, 4, 6], state: "minecraft:sandstone"},
        {pos: [1, 4, 7], state: "minecraft:sandstone"},
        {pos: [2, 4, 1], state: "minecraft:sandstone"},
        {pos: [2, 4, 2], state: "minecraft:sandstone"},
        {pos: [2, 4, 3], state: "minecraft:sandstone"},
        {pos: [2, 4, 4], state: "minecraft:sandstone"},
        {pos: [2, 4, 5], state: "minecraft:sandstone"},
        {pos: [2, 4, 6], state: "minecraft:sandstone"},
        {pos: [2, 4, 7], state: "minecraft:sandstone"},
        {pos: [2, 4, 8], state: "minecraft:sandstone"},
        {pos: [3, 4, 0], state: "minecraft:sandstone"},
        {pos: [3, 4, 1], state: "minecraft:sandstone"},
        {pos: [3, 4, 2], state: "minecraft:sandstone"},
        {pos: [3, 4, 3], state: "minecraft:sand"},
        {pos: [3, 4, 4], state: "minecraft:sand"},
        {pos: [3, 4, 5], state: "minecraft:sand"},
        {pos: [3, 4, 6], state: "minecraft:sandstone"},
        {pos: [3, 4, 7], state: "minecraft:sandstone"},
        {pos: [3, 4, 8], state: "minecraft:sandstone"},
        {pos: [4, 4, 0], state: "minecraft:sandstone"},
        {pos: [4, 4, 1], state: "minecraft:sandstone"},
        {pos: [4, 4, 2], state: "minecraft:sandstone"},
        {pos: [4, 4, 3], state: "minecraft:air"},
        {pos: [4, 4, 4], state: "minecraft:air"},
        {pos: [4, 4, 5], state: "minecraft:sand"},
        {pos: [4, 4, 6], state: "minecraft:sandstone"},
        {pos: [4, 4, 7], state: "minecraft:sandstone"},
        {pos: [5, 4, 0], state: "minecraft:sandstone"},
        {pos: [5, 4, 1], state: "minecraft:sandstone"},
        {pos: [5, 4, 2], state: "minecraft:sandstone"},
        {pos: [5, 4, 3], state: "minecraft:sand"},
        {pos: [5, 4, 4], state: "minecraft:air"},
        {pos: [5, 4, 5], state: "minecraft:air"},
        {pos: [5, 4, 6], state: "minecraft:sandstone"},
        {pos: [5, 4, 7], state: "minecraft:sandstone"},
        {pos: [6, 4, 1], state: "minecraft:sandstone"},
        {pos: [6, 4, 2], state: "minecraft:sandstone"},
        {pos: [6, 4, 3], state: "minecraft:sandstone"},
        {pos: [6, 4, 4], state: "minecraft:sandstone"},
        {pos: [6, 4, 5], state: "minecraft:sandstone"},
        {pos: [6, 4, 6], state: "minecraft:sandstone"},
        {pos: [7, 4, 2], state: "minecraft:sandstone"},
        {pos: [7, 4, 3], state: "minecraft:sandstone"},
        {pos: [7, 4, 4], state: "minecraft:sandstone"},
        {pos: [7, 4, 5], state: "minecraft:sandstone"},
        {pos: [7, 4, 6], state: "minecraft:sandstone"},
        {pos: [8, 4, 2], state: "minecraft:sandstone"},
        {pos: [8, 4, 3], state: "minecraft:sandstone"},
        {pos: [8, 4, 4], state: "minecraft:sandstone"},
        {pos: [8, 4, 5], state: "minecraft:sandstone"},
        {pos: [0, 5, 3], state: "minecraft:sand"},
        {pos: [0, 5, 4], state: "minecraft:sand"},
        {pos: [0, 5, 5], state: "minecraft:sand"},
        {pos: [0, 5, 6], state: "minecraft:sand"},
        {pos: [1, 5, 2], state: "minecraft:sand"},
        {pos: [1, 5, 3], state: "minecraft:sand"},
        {pos: [1, 5, 4], state: "minecraft:sand"},
        {pos: [1, 5, 5], state: "minecraft:sand"},
        {pos: [1, 5, 6], state: "minecraft:sand"},
        {pos: [1, 5, 7], state: "minecraft:sand"},
        {pos: [2, 5, 1], state: "minecraft:sand"},
        {pos: [2, 5, 2], state: "minecraft:sandstone"},
        {pos: [2, 5, 3], state: "minecraft:sandstone"},
        {pos: [2, 5, 4], state: "minecraft:sandstone"},
        {pos: [2, 5, 5], state: "minecraft:sandstone"},
        {pos: [2, 5, 6], state: "minecraft:sandstone"},
        {pos: [2, 5, 7], state: "minecraft:sand"},
        {pos: [2, 5, 8], state: "minecraft:sand"},
        {pos: [3, 5, 0], state: "minecraft:sand"},
        {pos: [3, 5, 1], state: "minecraft:sand"},
        {pos: [3, 5, 2], state: "minecraft:sandstone"},
        {pos: [3, 5, 3], state: "minecraft:air"},
        {pos: [3, 5, 4], state: "minecraft:air"},
        {pos: [3, 5, 5], state: "minecraft:air"},
        {pos: [3, 5, 6], state: "minecraft:sandstone"},
        {pos: [3, 5, 7], state: "minecraft:sand"},
        {pos: [3, 5, 8], state: "minecraft:sand"},
        {pos: [4, 5, 0], state: "minecraft:sand"},
        {pos: [4, 5, 1], state: "minecraft:sand"},
        {pos: [4, 5, 2], state: "minecraft:sandstone"},
        {pos: [4, 5, 3], state: "minecraft:air"},
        {pos: [4, 5, 4], state: "minecraft:air"},
        {pos: [4, 5, 5], state: "minecraft:air"},
        {pos: [4, 5, 6], state: "minecraft:sandstone"},
        {pos: [4, 5, 7], state: "minecraft:sand"},
        {pos: [5, 5, 0], state: "minecraft:sand"},
        {pos: [5, 5, 1], state: "minecraft:sand"},
        {pos: [5, 5, 2], state: "minecraft:sandstone"},
        {pos: [5, 5, 3], state: "minecraft:air"},
        {pos: [5, 5, 4], state: "minecraft:air"},
        {pos: [5, 5, 5], state: "minecraft:air"},
        {pos: [5, 5, 6], state: "minecraft:sandstone"},
        {pos: [5, 5, 7], state: "minecraft:sand"},
        {pos: [6, 5, 1], state: "minecraft:sand"},
        {pos: [6, 5, 2], state: "minecraft:sandstone"},
        {pos: [6, 5, 3], state: "minecraft:sandstone"},
        {pos: [6, 5, 4], state: "minecraft:sandstone"},
        {pos: [6, 5, 5], state: "minecraft:sandstone"},
        {pos: [6, 5, 6], state: "minecraft:sandstone"},
        {pos: [7, 5, 2], state: "minecraft:sand"},
        {pos: [7, 5, 3], state: "minecraft:sand"},
        {pos: [7, 5, 4], state: "minecraft:sand"},
        {pos: [7, 5, 5], state: "minecraft:sand"},
        {pos: [7, 5, 6], state: "minecraft:sand"},
        {pos: [8, 5, 2], state: "minecraft:sand"},
        {pos: [8, 5, 3], state: "minecraft:sand"},
        {pos: [8, 5, 4], state: "minecraft:sand"},
        {pos: [8, 5, 5], state: "minecraft:sand"},
        {pos: [2, 6, 2], state: "minecraft:sandstone"},
        {pos: [2, 6, 6], state: "minecraft:sandstone"},
        {pos: [3, 6, 4], state: "minecraft:air"},
        {pos: [4, 6, 3], state: "minecraft:air"},
        {pos: [4, 6, 4], state: "minecraft:chain{axis:y,waterlogged:false}"},
        {pos: [4, 6, 5], state: "minecraft:air"},
        {pos: [5, 6, 4], state: "minecraft:air"},
        {pos: [6, 6, 2], state: "minecraft:sandstone"},
        {pos: [6, 6, 6], state: "minecraft:sandstone"},
        {pos: [2, 7, 2], state: "minecraft:sandstone"},
        {pos: [2, 7, 6], state: "minecraft:sandstone"},
        {pos: [4, 7, 4], state: "minecraft:chain{axis:y,waterlogged:false}"},
        {pos: [6, 7, 6], state: "minecraft:smooth_sandstone"},
        {pos: [2, 8, 2], state: "minecraft:smooth_sandstone"},
        {pos: [2, 8, 6], state: "minecraft:smooth_sandstone"},
        {pos: [4, 8, 4], state: "minecraft:sandstone_wall{east:none,north:none,south:none,up:true,waterlogged:false,west:none}"},
        {pos: [6, 8, 6], state: "minecraft:sandstone"},
        {pos: [2, 9, 2], state: "minecraft:cut_sandstone"},
        {pos: [2, 9, 3], state: "minecraft:cut_sandstone"},
        {pos: [2, 9, 4], state: "minecraft:cut_sandstone"},
        {pos: [2, 9, 5], state: "minecraft:cut_sandstone"},
        {pos: [2, 9, 6], state: "minecraft:cut_sandstone"},
        {pos: [3, 9, 2], state: "minecraft:cut_sandstone"},
        {pos: [3, 9, 3], state: "minecraft:smooth_sandstone"},
        {pos: [3, 9, 4], state: "minecraft:smooth_sandstone"},
        {pos: [3, 9, 5], state: "minecraft:smooth_sandstone"},
        {pos: [3, 9, 6], state: "minecraft:cut_sandstone"},
        {pos: [4, 9, 2], state: "minecraft:cut_sandstone"},
        {pos: [4, 9, 3], state: "minecraft:smooth_sandstone"},
        {pos: [4, 9, 4], state: "minecraft:smooth_sandstone"},
        {pos: [4, 9, 5], state: "minecraft:smooth_sandstone"},
        {pos: [4, 9, 6], state: "minecraft:cut_sandstone"},
        {pos: [5, 9, 3], state: "minecraft:smooth_sandstone"},
        {pos: [5, 9, 4], state: "minecraft:smooth_sandstone"},
        {pos: [5, 9, 5], state: "minecraft:smooth_sandstone"},
        {pos: [5, 9, 6], state: "minecraft:cut_sandstone"},
        {pos: [6, 9, 4], state: "minecraft:cut_sandstone"},
        {pos: [6, 9, 5], state: "minecraft:cut_sandstone"},
        {pos: [6, 9, 6], state: "minecraft:cut_sandstone"},
        {pos: [3, 10, 3], state: "minecraft:sandstone_stairs{facing:east,half:bottom,shape:outer_right,waterlogged:false}"},
        {pos: [3, 10, 4], state: "minecraft:sandstone_stairs{facing:east,half:bottom,shape:straight,waterlogged:false}"},
        {pos: [3, 10, 5], state: "minecraft:sandstone_stairs{facing:north,half:bottom,shape:outer_right,waterlogged:false}"},
        {pos: [4, 10, 3], state: "minecraft:sandstone_stairs{facing:south,half:bottom,shape:straight,waterlogged:false}"},
        {pos: [4, 10, 4], state: "minecraft:smooth_sandstone"},
        {pos: [4, 10, 5], state: "minecraft:sandstone_stairs{facing:north,half:bottom,shape:straight,waterlogged:false}"},
        {pos: [5, 10, 3], state: "minecraft:sandstone_stairs{facing:south,half:bottom,shape:outer_right,waterlogged:false}"},
        {pos: [5, 10, 4], state: "minecraft:sandstone_stairs{facing:west,half:bottom,shape:straight,waterlogged:false}"},
        {pos: [5, 10, 5], state: "minecraft:sandstone_stairs{facing:west,half:bottom,shape:outer_right,waterlogged:false}"}
    ],
    entities: [],
    palette: [
        "minecraft:sandstone",
        "minecraft:sand",
        "minecraft:smooth_sandstone",
        "minecraft:cut_sandstone",
        "minecraft:air",
        "minecraft:chain{axis:y,waterlogged:false}",
        "minecraft:sandstone_wall{east:none,north:none,south:none,up:true,waterlogged:false,west:none}",
        "minecraft:sandstone_stairs{facing:east,half:bottom,shape:outer_right,waterlogged:false}",
        "minecraft:sandstone_stairs{facing:east,half:bottom,shape:straight,waterlogged:false}",
        "minecraft:sandstone_stairs{facing:north,half:bottom,shape:outer_right,waterlogged:false}",
        "minecraft:sandstone_stairs{facing:south,half:bottom,shape:straight,waterlogged:false}",
        "minecraft:sandstone_stairs{facing:north,half:bottom,shape:straight,waterlogged:false}",
        "minecraft:sandstone_stairs{facing:south,half:bottom,shape:outer_right,waterlogged:false}",
        "minecraft:sandstone_stairs{facing:west,half:bottom,shape:straight,waterlogged:false}",
        "minecraft:sandstone_stairs{facing:west,half:bottom,shape:outer_right,waterlogged:false}",
        "minecraft:decorated_pot{cracked:false,facing:south,waterlogged:false}"
    ],
    trailiertales_DataVersion: 2
}
