{
    DataVersion: 3953,
    size: [11, 17, 11],
    data: [
        {pos: [0, 0, 4], state: "minecraft:sandstone"},
        {pos: [0, 0, 5], state: "minecraft:sandstone"},
        {pos: [0, 0, 6], state: "minecraft:sandstone"},
        {pos: [1, 0, 1], state: "minecraft:sandstone"},
        {pos: [1, 0, 2], state: "minecraft:sandstone"},
        {pos: [1, 0, 3], state: "minecraft:sandstone"},
        {pos: [1, 0, 4], state: "minecraft:sandstone"},
        {pos: [1, 0, 5], state: "minecraft:sandstone"},
        {pos: [1, 0, 6], state: "minecraft:sandstone"},
        {pos: [1, 0, 7], state: "minecraft:sandstone"},
        {pos: [1, 0, 8], state: "minecraft:sandstone"},
        {pos: [1, 0, 9], state: "minecraft:sandstone"},
        {pos: [2, 0, 1], state: "minecraft:sandstone"},
        {pos: [2, 0, 2], state: "minecraft:sandstone"},
        {pos: [2, 0, 3], state: "minecraft:sandstone"},
        {pos: [2, 0, 4], state: "minecraft:sandstone"},
        {pos: [2, 0, 5], state: "minecraft:sandstone"},
        {pos: [2, 0, 6], state: "minecraft:sandstone"},
        {pos: [2, 0, 7], state: "minecraft:sandstone"},
        {pos: [2, 0, 8], state: "minecraft:sandstone"},
        {pos: [2, 0, 9], state: "minecraft:sandstone"},
        {pos: [2, 0, 10], state: "minecraft:sandstone"},
        {pos: [3, 0, 0], state: "minecraft:sandstone"},
        {pos: [3, 0, 1], state: "minecraft:sandstone"},
        {pos: [3, 0, 2], state: "minecraft:sandstone"},
        {pos: [3, 0, 3], state: "minecraft:sandstone"},
        {pos: [3, 0, 4], state: "minecraft:sandstone"},
        {pos: [3, 0, 5], state: "minecraft:sandstone"},
        {pos: [3, 0, 6], state: "minecraft:sandstone"},
        {pos: [3, 0, 7], state: "minecraft:sandstone"},
        {pos: [3, 0, 8], state: "minecraft:sandstone"},
        {pos: [3, 0, 9], state: "minecraft:sandstone"},
        {pos: [3, 0, 10], state: "minecraft:sandstone"},
        {pos: [4, 0, 0], state: "minecraft:sandstone"},
        {pos: [4, 0, 1], state: "minecraft:sandstone"},
        {pos: [4, 0, 2], state: "minecraft:sandstone"},
        {pos: [4, 0, 3], state: "minecraft:sandstone"},
        {pos: [4, 0, 4], state: "minecraft:sandstone"},
        {pos: [4, 0, 5], state: "minecraft:sandstone"},
        {pos: [4, 0, 6], state: "minecraft:sandstone"},
        {pos: [4, 0, 7], state: "minecraft:sandstone"},
        {pos: [4, 0, 8], state: "minecraft:sandstone"},
        {pos: [4, 0, 9], state: "minecraft:sandstone"},
        {pos: [4, 0, 10], state: "minecraft:sandstone"},
        {pos: [5, 0, 0], state: "minecraft:sandstone"},
        {pos: [5, 0, 1], state: "minecraft:sandstone"},
        {pos: [5, 0, 2], state: "minecraft:sandstone"},
        {pos: [5, 0, 3], state: "minecraft:sandstone"},
        {pos: [5, 0, 4], state: "minecraft:sandstone"},
        {pos: [5, 0, 5], state: "minecraft:sandstone"},
        {pos: [5, 0, 6], state: "minecraft:sandstone"},
        {pos: [5, 0, 7], state: "minecraft:sandstone"},
        {pos: [5, 0, 8], state: "minecraft:sandstone"},
        {pos: [5, 0, 9], state: "minecraft:sandstone"},
        {pos: [6, 0, 0], state: "minecraft:sandstone"},
        {pos: [6, 0, 1], state: "minecraft:sandstone"},
        {pos: [6, 0, 2], state: "minecraft:sandstone"},
        {pos: [6, 0, 3], state: "minecraft:sandstone"},
        {pos: [6, 0, 4], state: "minecraft:sandstone"},
        {pos: [6, 0, 5], state: "minecraft:sandstone"},
        {pos: [6, 0, 6], state: "minecraft:sandstone"},
        {pos: [6, 0, 7], state: "minecraft:sandstone"},
        {pos: [6, 0, 8], state: "minecraft:sandstone"},
        {pos: [6, 0, 9], state: "minecraft:sandstone"},
        {pos: [7, 0, 1], state: "minecraft:sandstone"},
        {pos: [7, 0, 2], state: "minecraft:sandstone"},
        {pos: [7, 0, 3], state: "minecraft:sandstone"},
        {pos: [7, 0, 4], state: "minecraft:sandstone"},
        {pos: [7, 0, 5], state: "minecraft:sandstone"},
        {pos: [7, 0, 6], state: "minecraft:sandstone"},
        {pos: [7, 0, 7], state: "minecraft:sandstone"},
        {pos: [7, 0, 8], state: "minecraft:sandstone"},
        {pos: [8, 0, 1], state: "minecraft:sandstone"},
        {pos: [8, 0, 2], state: "minecraft:sandstone"},
        {pos: [8, 0, 3], state: "minecraft:sandstone"},
        {pos: [8, 0, 4], state: "minecraft:sandstone"},
        {pos: [8, 0, 5], state: "minecraft:sandstone"},
        {pos: [8, 0, 6], state: "minecraft:sandstone"},
        {pos: [8, 0, 7], state: "minecraft:sandstone"},
        {pos: [8, 0, 8], state: "minecraft:sandstone"},
        {pos: [8, 0, 9], state: "minecraft:sandstone"},
        {pos: [9, 0, 1], state: "minecraft:sandstone"},
        {pos: [9, 0, 2], state: "minecraft:sandstone"},
        {pos: [9, 0, 3], state: "minecraft:sandstone"},
        {pos: [9, 0, 4], state: "minecraft:sandstone"},
        {pos: [9, 0, 5], state: "minecraft:sandstone"},
        {pos: [9, 0, 6], state: "minecraft:sandstone"},
        {pos: [9, 0, 7], state: "minecraft:sandstone"},
        {pos: [9, 0, 8], state: "minecraft:sandstone"},
        {pos: [9, 0, 9], state: "minecraft:sandstone"},
        {pos: [10, 0, 5], state: "minecraft:sandstone"},
        {pos: [10, 0, 6], state: "minecraft:sandstone"},
        {pos: [0, 1, 2], state: "minecraft:sandstone"},
        {pos: [0, 1, 3], state: "minecraft:sandstone"},
        {pos: [0, 1, 4], state: "minecraft:sandstone"},
        {pos: [0, 1, 5], state: "minecraft:sandstone"},
        {pos: [0, 1, 6], state: "minecraft:sandstone"},
        {pos: [0, 1, 7], state: "minecraft:sandstone"},
        {pos: [0, 1, 8], state: "minecraft:sandstone"},
        {pos: [0, 1, 9], state: "minecraft:sandstone"},
        {pos: [1, 1, 0], state: "minecraft:sandstone"},
        {pos: [1, 1, 1], state: "minecraft:sandstone"},
        {pos: [1, 1, 2], state: "minecraft:sandstone"},
        {pos: [1, 1, 3], state: "minecraft:sandstone"},
        {pos: [1, 1, 4], state: "minecraft:decorated_pot{cracked:false,facing:west,waterlogged:true}", nbt: {id: "minecraft:decorated_pot", sherds: ["minecraft:brick", "minecraft:brick", "minecraft:brick", "minecraft:arms_up_pottery_sherd"]}},
        {pos: [1, 1, 5], state: "minecraft:clay"},
        {pos: [1, 1, 6], state: "minecraft:sandstone"},
        {pos: [1, 1, 7], state: "minecraft:sandstone"},
        {pos: [1, 1, 8], state: "minecraft:sandstone"},
        {pos: [1, 1, 9], state: "minecraft:sandstone"},
        {pos: [1, 1, 10], state: "minecraft:sandstone"},
        {pos: [2, 1, 0], state: "minecraft:sandstone"},
        {pos: [2, 1, 1], state: "minecraft:sandstone"},
        {pos: [2, 1, 2], state: "minecraft:sandstone"},
        {pos: [2, 1, 3], state: "minecraft:sand"},
        {pos: [2, 1, 4], state: "minecraft:water{level:8}"},
        {pos: [2, 1, 5], state: "minecraft:clay"},
        {pos: [2, 1, 6], state: "minecraft:clay"},
        {pos: [2, 1, 7], state: "minecraft:sand"},
        {pos: [2, 1, 8], state: "minecraft:sandstone"},
        {pos: [2, 1, 9], state: "minecraft:sandstone"},
        {pos: [2, 1, 10], state: "minecraft:sandstone"},
        {pos: [3, 1, 0], state: "minecraft:sandstone"},
        {pos: [3, 1, 1], state: "minecraft:sandstone"},
        {pos: [3, 1, 2], state: "minecraft:sand"},
        {pos: [3, 1, 3], state: "minecraft:water{level:8}"},
        {pos: [3, 1, 4], state: "minecraft:water{level:8}"},
        {pos: [3, 1, 5], state: "minecraft:water{level:8}"},
        {pos: [3, 1, 6], state: "minecraft:sand"},
        {pos: [3, 1, 7], state: "minecraft:sand"},
        {pos: [3, 1, 8], state: "minecraft:sand"},
        {pos: [3, 1, 9], state: "minecraft:sandstone"},
        {pos: [3, 1, 10], state: "minecraft:sandstone"},
        {pos: [4, 1, 0], state: "minecraft:sandstone"},
        {pos: [4, 1, 1], state: "minecraft:sandstone"},
        {pos: [4, 1, 2], state: "minecraft:water{level:8}"},
        {pos: [4, 1, 3], state: "minecraft:water{level:8}"},
        {pos: [4, 1, 4], state: "minecraft:brick_slab{type:bottom,waterlogged:true}"},
        {pos: [4, 1, 5], state: "minecraft:sand"},
        {pos: [4, 1, 6], state: "minecraft:sand"},
        {pos: [4, 1, 7], state: "minecraft:sandstone_stairs{facing:south,half:top,shape:straight,waterlogged:true}"},
        {pos: [4, 1, 8], state: "minecraft:sand"},
        {pos: [4, 1, 9], state: "minecraft:sandstone"},
        {pos: [4, 1, 10], state: "minecraft:sandstone"},
        {pos: [5, 1, 0], state: "minecraft:sandstone"},
        {pos: [5, 1, 1], state: "minecraft:sandstone_stairs{facing:north,half:top,shape:straight,waterlogged:true}"},
        {pos: [5, 1, 2], state: "minecraft:water{level:8}"},
        {pos: [5, 1, 3], state: "minecraft:water{level:8}"},
        {pos: [5, 1, 4], state: "minecraft:sand"},
        {pos: [5, 1, 5], state: "minecraft:sand"},
        {pos: [5, 1, 6], state: "minecraft:water{level:8}"},
        {pos: [5, 1, 7], state: "minecraft:sandstone_stairs{facing:south,half:top,shape:straight,waterlogged:true}"},
        {pos: [5, 1, 8], state: "minecraft:sand"},
        {pos: [5, 1, 9], state: "minecraft:sand"},
        {pos: [5, 1, 10], state: "minecraft:sandstone"},
        {pos: [6, 1, 0], state: "minecraft:sandstone"},
        {pos: [6, 1, 1], state: "minecraft:sandstone_stairs{facing:north,half:top,shape:straight,waterlogged:true}"},
        {pos: [6, 1, 2], state: "minecraft:water{level:8}"},
        {pos: [6, 1, 3], state: "minecraft:bricks"},
        {pos: [6, 1, 4], state: "minecraft:sand"},
        {pos: [6, 1, 5], state: "minecraft:water{level:8}"},
        {pos: [6, 1, 6], state: "minecraft:water{level:8}"},
        {pos: [6, 1, 7], state: "minecraft:sandstone_stairs{facing:south,half:top,shape:straight,waterlogged:true}"},
        {pos: [6, 1, 8], state: "minecraft:sand"},
        {pos: [6, 1, 9], state: "minecraft:sandstone"},
        {pos: [6, 1, 10], state: "minecraft:sandstone"},
        {pos: [7, 1, 0], state: "minecraft:sandstone"},
        {pos: [7, 1, 1], state: "minecraft:clay"},
        {pos: [7, 1, 2], state: "minecraft:clay"},
        {pos: [7, 1, 3], state: "minecraft:water{level:8}"},
        {pos: [7, 1, 4], state: "minecraft:water{level:8}"},
        {pos: [7, 1, 5], state: "minecraft:stonecutter{facing:west}"},
        {pos: [7, 1, 6], state: "minecraft:water{level:8}"},
        {pos: [7, 1, 7], state: "minecraft:sandstone_stairs{facing:south,half:top,shape:straight,waterlogged:true}"},
        {pos: [7, 1, 8], state: "minecraft:sand"},
        {pos: [7, 1, 9], state: "minecraft:sandstone"},
        {pos: [7, 1, 10], state: "minecraft:sandstone"},
        {pos: [8, 1, 0], state: "minecraft:sandstone"},
        {pos: [8, 1, 1], state: "minecraft:sandstone"},
        {pos: [8, 1, 2], state: "minecraft:sand"},
        {pos: [8, 1, 3], state: "minecraft:sand"},
        {pos: [8, 1, 4], state: "minecraft:sandstone_stairs{facing:east,half:top,shape:straight,waterlogged:true}"},
        {pos: [8, 1, 5], state: "minecraft:sandstone_stairs{facing:east,half:top,shape:straight,waterlogged:true}"},
        {pos: [8, 1, 6], state: "minecraft:sand"},
        {pos: [8, 1, 7], state: "minecraft:sand"},
        {pos: [8, 1, 8], state: "minecraft:sand"},
        {pos: [8, 1, 9], state: "minecraft:sandstone"},
        {pos: [8, 1, 10], state: "minecraft:sandstone"},
        {pos: [9, 1, 1], state: "minecraft:sandstone"},
        {pos: [9, 1, 2], state: "minecraft:sandstone"},
        {pos: [9, 1, 3], state: "minecraft:sandstone"},
        {pos: [9, 1, 4], state: "minecraft:sandstone"},
        {pos: [9, 1, 5], state: "minecraft:sandstone"},
        {pos: [9, 1, 6], state: "minecraft:sand"},
        {pos: [9, 1, 7], state: "minecraft:sandstone"},
        {pos: [9, 1, 8], state: "minecraft:sandstone"},
        {pos: [9, 1, 9], state: "minecraft:sandstone"},
        {pos: [10, 1, 2], state: "minecraft:sandstone"},
        {pos: [10, 1, 3], state: "minecraft:sandstone"},
        {pos: [10, 1, 4], state: "minecraft:sandstone"},
        {pos: [10, 1, 5], state: "minecraft:sandstone"},
        {pos: [10, 1, 6], state: "minecraft:sandstone"},
        {pos: [10, 1, 7], state: "minecraft:sandstone"},
        {pos: [10, 1, 8], state: "minecraft:sandstone"},
        {pos: [10, 1, 9], state: "minecraft:sandstone"},
        {pos: [0, 2, 1], state: "minecraft:sandstone"},
        {pos: [0, 2, 2], state: "minecraft:sandstone"},
        {pos: [0, 2, 3], state: "minecraft:sandstone"},
        {pos: [0, 2, 4], state: "minecraft:sandstone"},
        {pos: [0, 2, 5], state: "minecraft:sandstone"},
        {pos: [0, 2, 6], state: "minecraft:sandstone"},
        {pos: [0, 2, 7], state: "minecraft:sandstone"},
        {pos: [0, 2, 8], state: "minecraft:sandstone"},
        {pos: [0, 2, 9], state: "minecraft:sandstone"},
        {pos: [0, 2, 10], state: "minecraft:sandstone"},
        {pos: [1, 2, 0], state: "minecraft:sandstone"},
        {pos: [1, 2, 1], state: "minecraft:sandstone"},
        {pos: [1, 2, 2], state: "minecraft:sandstone"},
        {pos: [1, 2, 3], state: "minecraft:decorated_pot{cracked:false,facing:west,waterlogged:true}", nbt: {id: "minecraft:decorated_pot"}},
        {pos: [1, 2, 4], state: "minecraft:water{level:8}"},
        {pos: [1, 2, 5], state: "minecraft:water{level:1}"},
        {pos: [1, 2, 6], state: "minecraft:sand"},
        {pos: [1, 2, 7], state: "minecraft:sandstone"},
        {pos: [1, 2, 8], state: "minecraft:sandstone"},
        {pos: [1, 2, 9], state: "minecraft:sandstone"},
        {pos: [1, 2, 10], state: "minecraft:sandstone"},
        {pos: [2, 2, 0], state: "minecraft:sandstone"},
        {pos: [2, 2, 1], state: "minecraft:sandstone"},
        {pos: [2, 2, 2], state: "minecraft:sand"},
        {pos: [2, 2, 3], state: "minecraft:bricks"},
        {pos: [2, 2, 4], state: "minecraft:water{level:8}"},
        {pos: [2, 2, 5], state: "minecraft:water{level:8}"},
        {pos: [2, 2, 6], state: "minecraft:water{level:8}"},
        {pos: [2, 2, 7], state: "minecraft:sand"},
        {pos: [2, 2, 8], state: "minecraft:sand"},
        {pos: [2, 2, 9], state: "minecraft:sandstone"},
        {pos: [2, 2, 10], state: "minecraft:sandstone"},
        {pos: [3, 2, 0], state: "minecraft:sandstone"},
        {pos: [3, 2, 1], state: "minecraft:sandstone"},
        {pos: [3, 2, 2], state: "minecraft:water{level:0}"},
        {pos: [3, 2, 3], state: "minecraft:water{level:0}"},
        {pos: [3, 2, 4], state: "minecraft:water{level:8}"},
        {pos: [3, 2, 5], state: "minecraft:water{level:8}"},
        {pos: [3, 2, 6], state: "minecraft:chain{axis:y,waterlogged:true}"},
        {pos: [3, 2, 7], state: "minecraft:sand"},
        {pos: [3, 2, 8], state: "minecraft:sand"},
        {pos: [3, 2, 9], state: "minecraft:sandstone"},
        {pos: [3, 2, 10], state: "minecraft:sandstone"},
        {pos: [4, 2, 0], state: "minecraft:sandstone"},
        {pos: [4, 2, 1], state: "minecraft:clay"},
        {pos: [4, 2, 2], state: "minecraft:water{level:0}"},
        {pos: [4, 2, 3], state: "minecraft:water{level:8}"},
        {pos: [4, 2, 4], state: "minecraft:water{level:0}"},
        {pos: [4, 2, 5], state: "minecraft:water{level:0}"},
        {pos: [4, 2, 6], state: "minecraft:bricks"},
        {pos: [4, 2, 7], state: "minecraft:water{level:0}"},
        {pos: [4, 2, 8], state: "minecraft:sandstone_stairs{facing:south,half:top,shape:straight,waterlogged:true}"},
        {pos: [4, 2, 9], state: "minecraft:water{level:0}"},
        {pos: [4, 2, 10], state: "minecraft:sandstone"},
        {pos: [5, 2, 0], state: "minecraft:sandstone"},
        {pos: [5, 2, 1], state: "minecraft:water{level:0}"},
        {pos: [5, 2, 2], state: "minecraft:water{level:0}"},
        {pos: [5, 2, 3], state: "minecraft:water{level:0}"},
        {pos: [5, 2, 4], state: "minecraft:water{level:0}"},
        {pos: [5, 2, 5], state: "minecraft:decorated_pot{cracked:false,facing:west,waterlogged:true}", nbt: {id: "minecraft:decorated_pot"}},
        {pos: [5, 2, 6], state: "minecraft:water{level:0}"},
        {pos: [5, 2, 7], state: "minecraft:water{level:0}"},
        {pos: [5, 2, 8], state: "minecraft:sandstone_stairs{facing:south,half:top,shape:straight,waterlogged:true}"},
        {pos: [5, 2, 9], state: "minecraft:water{level:0}"},
        {pos: [5, 2, 10], state: "minecraft:sandstone"},
        {pos: [6, 2, 0], state: "minecraft:sandstone"},
        {pos: [6, 2, 1], state: "minecraft:decorated_pot{cracked:false,facing:north,waterlogged:true}", nbt: {id: "minecraft:decorated_pot"}},
        {pos: [6, 2, 2], state: "minecraft:water{level:8}"},
        {pos: [6, 2, 3], state: "minecraft:water{level:0}"},
        {pos: [6, 2, 4], state: "minecraft:decorated_pot{cracked:false,facing:north,waterlogged:true}", nbt: {id: "minecraft:decorated_pot", sherds: ["minecraft:brick", "minecraft:brick", "minecraft:brick", "minecraft:brewer_pottery_sherd"]}},
        {pos: [6, 2, 5], state: "minecraft:water{level:0}"},
        {pos: [6, 2, 6], state: "minecraft:water{level:8}"},
        {pos: [6, 2, 7], state: "minecraft:water{level:0}"},
        {pos: [6, 2, 8], state: "minecraft:sandstone_stairs{facing:south,half:top,shape:straight,waterlogged:true}"},
        {pos: [6, 2, 9], state: "minecraft:water{level:0}"},
        {pos: [6, 2, 10], state: "minecraft:sandstone"},
        {pos: [7, 2, 0], state: "minecraft:sandstone"},
        {pos: [7, 2, 1], state: "minecraft:sand"},
        {pos: [7, 2, 2], state: "minecraft:water{level:0}"},
        {pos: [7, 2, 3], state: "minecraft:water{level:0}"},
        {pos: [7, 2, 4], state: "minecraft:chain{axis:y,waterlogged:true}"},
        {pos: [7, 2, 5], state: "minecraft:water{level:0}"},
        {pos: [7, 2, 6], state: "minecraft:water{level:8}"},
        {pos: [7, 2, 7], state: "minecraft:decorated_pot{cracked:false,facing:south,waterlogged:true}", nbt: {id: "minecraft:decorated_pot"}},
        {pos: [7, 2, 8], state: "minecraft:sandstone_stairs{facing:south,half:top,shape:straight,waterlogged:true}"},
        {pos: [7, 2, 9], state: "minecraft:water{level:0}"},
        {pos: [7, 2, 10], state: "minecraft:sandstone"},
        {pos: [8, 2, 0], state: "minecraft:sandstone"},
        {pos: [8, 2, 1], state: "minecraft:sandstone"},
        {pos: [8, 2, 2], state: "minecraft:sand"},
        {pos: [8, 2, 3], state: "minecraft:water{level:0}"},
        {pos: [8, 2, 4], state: "minecraft:water{level:0}"},
        {pos: [8, 2, 5], state: "minecraft:decorated_pot{cracked:false,facing:east,waterlogged:true}", nbt: {id: "minecraft:decorated_pot"}},
        {pos: [8, 2, 6], state: "minecraft:water{level:8}"},
        {pos: [8, 2, 7], state: "minecraft:sand"},
        {pos: [8, 2, 8], state: "minecraft:sand"},
        {pos: [8, 2, 9], state: "minecraft:sandstone"},
        {pos: [8, 2, 10], state: "minecraft:sandstone"},
        {pos: [9, 2, 0], state: "minecraft:sandstone"},
        {pos: [9, 2, 1], state: "minecraft:sandstone"},
        {pos: [9, 2, 2], state: "minecraft:sandstone"},
        {pos: [9, 2, 3], state: "minecraft:sandstone"},
        {pos: [9, 2, 4], state: "minecraft:decorated_pot{cracked:false,facing:east,waterlogged:true}", nbt: {id: "minecraft:decorated_pot"}},
        {pos: [9, 2, 5], state: "minecraft:clay"},
        {pos: [9, 2, 6], state: "minecraft:clay"},
        {pos: [9, 2, 7], state: "minecraft:sand"},
        {pos: [9, 2, 8], state: "minecraft:sandstone"},
        {pos: [9, 2, 9], state: "minecraft:sandstone"},
        {pos: [9, 2, 10], state: "minecraft:sandstone"},
        {pos: [10, 2, 1], state: "minecraft:sandstone"},
        {pos: [10, 2, 2], state: "minecraft:sandstone"},
        {pos: [10, 2, 3], state: "minecraft:sandstone"},
        {pos: [10, 2, 4], state: "minecraft:sandstone"},
        {pos: [10, 2, 5], state: "minecraft:sandstone"},
        {pos: [10, 2, 6], state: "minecraft:sandstone"},
        {pos: [10, 2, 7], state: "minecraft:sandstone"},
        {pos: [10, 2, 8], state: "minecraft:sandstone"},
        {pos: [10, 2, 9], state: "minecraft:sandstone"},
        {pos: [0, 3, 3], state: "minecraft:sandstone"},
        {pos: [0, 3, 4], state: "minecraft:sandstone"},
        {pos: [0, 3, 5], state: "minecraft:sandstone"},
        {pos: [0, 3, 6], state: "minecraft:sandstone"},
        {pos: [0, 3, 7], state: "minecraft:sandstone"},
        {pos: [0, 3, 8], state: "minecraft:sandstone"},
        {pos: [0, 3, 9], state: "minecraft:sandstone"},
        {pos: [1, 3, 1], state: "minecraft:sandstone"},
        {pos: [1, 3, 2], state: "minecraft:sandstone"},
        {pos: [1, 3, 3], state: "minecraft:water{level:0}"},
        {pos: [1, 3, 4], state: "minecraft:water{level:0}"},
        {pos: [1, 3, 5], state: "minecraft:sandstone"},
        {pos: [1, 3, 6], state: "minecraft:sandstone"},
        {pos: [1, 3, 7], state: "minecraft:sandstone"},
        {pos: [1, 3, 8], state: "minecraft:sandstone"},
        {pos: [1, 3, 9], state: "minecraft:sandstone"},
        {pos: [1, 3, 10], state: "minecraft:sandstone"},
        {pos: [2, 3, 1], state: "minecraft:sandstone"},
        {pos: [2, 3, 2], state: "minecraft:sandstone"},
        {pos: [2, 3, 3], state: "minecraft:water{level:0}"},
        {pos: [2, 3, 4], state: "minecraft:water{level:0}"},
        {pos: [2, 3, 5], state: "minecraft:water{level:0}"},
        {pos: [2, 3, 6], state: "minecraft:water{level:0}"},
        {pos: [2, 3, 7], state: "minecraft:sandstone"},
        {pos: [2, 3, 8], state: "minecraft:sandstone"},
        {pos: [2, 3, 9], state: "minecraft:sandstone"},
        {pos: [2, 3, 10], state: "minecraft:sandstone"},
        {pos: [3, 3, 0], state: "minecraft:sandstone"},
        {pos: [3, 3, 1], state: "minecraft:sandstone"},
        {pos: [3, 3, 2], state: "minecraft:water{level:0}"},
        {pos: [3, 3, 3], state: "minecraft:water{level:0}"},
        {pos: [3, 3, 4], state: "minecraft:water{level:0}"},
        {pos: [3, 3, 5], state: "minecraft:water{level:0}"},
        {pos: [3, 3, 6], state: "minecraft:chain{axis:y,waterlogged:true}"},
        {pos: [3, 3, 7], state: "minecraft:water{level:0}"},
        {pos: [3, 3, 8], state: "minecraft:sandstone"},
        {pos: [3, 3, 9], state: "minecraft:sandstone"},
        {pos: [3, 3, 10], state: "minecraft:sandstone"},
        {pos: [4, 3, 0], state: "minecraft:sandstone"},
        {pos: [4, 3, 1], state: "minecraft:sandstone"},
        {pos: [4, 3, 2], state: "minecraft:chain{axis:y,waterlogged:true}"},
        {pos: [4, 3, 3], state: "minecraft:water{level:0}"},
        {pos: [4, 3, 4], state: "minecraft:water{level:0}"},
        {pos: [4, 3, 5], state: "minecraft:water{level:0}"},
        {pos: [4, 3, 6], state: "minecraft:water{level:0}"},
        {pos: [4, 3, 7], state: "minecraft:water{level:0}"},
        {pos: [4, 3, 8], state: "minecraft:decorated_pot{cracked:false,facing:south,waterlogged:true}", nbt: {id: "minecraft:decorated_pot"}},
        {pos: [4, 3, 9], state: "minecraft:sandstone"},
        {pos: [4, 3, 10], state: "minecraft:sandstone"},
        {pos: [5, 3, 0], state: "minecraft:sandstone"},
        {pos: [5, 3, 1], state: "minecraft:sandstone"},
        {pos: [5, 3, 2], state: "minecraft:water{level:0}"},
        {pos: [5, 3, 3], state: "minecraft:water{level:0}"},
        {pos: [5, 3, 4], state: "minecraft:water{level:0}"},
        {pos: [5, 3, 5], state: "minecraft:water{level:0}"},
        {pos: [5, 3, 6], state: "minecraft:water{level:0}"},
        {pos: [5, 3, 7], state: "minecraft:water{level:0}"},
        {pos: [5, 3, 8], state: "minecraft:decorated_pot{cracked:false,facing:south,waterlogged:true}", nbt: {id: "minecraft:decorated_pot"}},
        {pos: [5, 3, 9], state: "minecraft:water{level:1}"},
        {pos: [5, 3, 10], state: "minecraft:sandstone"},
        {pos: [6, 3, 0], state: "minecraft:sandstone"},
        {pos: [6, 3, 1], state: "minecraft:water{level:0}"},
        {pos: [6, 3, 2], state: "minecraft:water{level:0}"},
        {pos: [6, 3, 3], state: "minecraft:water{level:0}"},
        {pos: [6, 3, 4], state: "minecraft:water{level:0}"},
        {pos: [6, 3, 5], state: "minecraft:water{level:0}"},
        {pos: [6, 3, 6], state: "minecraft:water{level:0}"},
        {pos: [6, 3, 7], state: "minecraft:water{level:0}"},
        {pos: [6, 3, 8], state: "minecraft:sand"},
        {pos: [6, 3, 9], state: "minecraft:sandstone"},
        {pos: [6, 3, 10], state: "minecraft:sandstone"},
        {pos: [7, 3, 0], state: "minecraft:sandstone"},
        {pos: [7, 3, 1], state: "minecraft:sandstone"},
        {pos: [7, 3, 2], state: "minecraft:water{level:0}"},
        {pos: [7, 3, 3], state: "minecraft:water{level:0}"},
        {pos: [7, 3, 4], state: "minecraft:chain{axis:y,waterlogged:true}"},
        {pos: [7, 3, 5], state: "minecraft:water{level:0}"},
        {pos: [7, 3, 6], state: "minecraft:chain{axis:y,waterlogged:true}"},
        {pos: [7, 3, 7], state: "minecraft:water{level:0}"},
        {pos: [7, 3, 8], state: "minecraft:sand"},
        {pos: [7, 3, 9], state: "minecraft:sandstone"},
        {pos: [7, 3, 10], state: "minecraft:sandstone"},
        {pos: [8, 3, 0], state: "minecraft:sandstone"},
        {pos: [8, 3, 1], state: "minecraft:sandstone"},
        {pos: [8, 3, 2], state: "minecraft:sandstone"},
        {pos: [8, 3, 3], state: "minecraft:sandstone"},
        {pos: [8, 3, 4], state: "minecraft:water{level:0}"},
        {pos: [8, 3, 5], state: "minecraft:water{level:0}"},
        {pos: [8, 3, 6], state: "minecraft:water{level:0}"},
        {pos: [8, 3, 7], state: "minecraft:water{level:0}"},
        {pos: [8, 3, 8], state: "minecraft:sand"},
        {pos: [8, 3, 9], state: "minecraft:sandstone"},
        {pos: [9, 3, 0], state: "minecraft:sandstone"},
        {pos: [9, 3, 1], state: "minecraft:sandstone"},
        {pos: [9, 3, 2], state: "minecraft:sandstone"},
        {pos: [9, 3, 3], state: "minecraft:sandstone"},
        {pos: [9, 3, 4], state: "minecraft:sandstone"},
        {pos: [9, 3, 5], state: "minecraft:water{level:0}"},
        {pos: [9, 3, 6], state: "minecraft:clay"},
        {pos: [9, 3, 7], state: "minecraft:sandstone"},
        {pos: [9, 3, 8], state: "minecraft:sandstone"},
        {pos: [9, 3, 9], state: "minecraft:sandstone"},
        {pos: [10, 3, 2], state: "minecraft:sandstone"},
        {pos: [10, 3, 3], state: "minecraft:sandstone"},
        {pos: [10, 3, 4], state: "minecraft:sandstone"},
        {pos: [10, 3, 5], state: "minecraft:sandstone"},
        {pos: [10, 3, 6], state: "minecraft:sandstone"},
        {pos: [10, 3, 7], state: "minecraft:sandstone"},
        {pos: [10, 3, 8], state: "minecraft:sandstone"},
        {pos: [0, 4, 6], state: "minecraft:sandstone"},
        {pos: [0, 4, 7], state: "minecraft:sandstone"},
        {pos: [1, 4, 2], state: "minecraft:sandstone"},
        {pos: [1, 4, 3], state: "minecraft:sandstone"},
        {pos: [1, 4, 4], state: "minecraft:sandstone"},
        {pos: [1, 4, 5], state: "minecraft:sandstone"},
        {pos: [1, 4, 6], state: "minecraft:sandstone"},
        {pos: [1, 4, 7], state: "minecraft:sandstone"},
        {pos: [1, 4, 8], state: "minecraft:sandstone"},
        {pos: [1, 4, 9], state: "minecraft:sandstone"},
        {pos: [2, 4, 1], state: "minecraft:sandstone"},
        {pos: [2, 4, 2], state: "minecraft:sandstone"},
        {pos: [2, 4, 3], state: "minecraft:sandstone"},
        {pos: [2, 4, 4], state: "minecraft:sandstone"},
        {pos: [2, 4, 5], state: "minecraft:sandstone"},
        {pos: [2, 4, 6], state: "minecraft:sandstone"},
        {pos: [2, 4, 7], state: "minecraft:sandstone"},
        {pos: [2, 4, 8], state: "minecraft:sandstone"},
        {pos: [2, 4, 9], state: "minecraft:sandstone"},
        {pos: [3, 4, 1], state: "minecraft:sandstone"},
        {pos: [3, 4, 2], state: "minecraft:sandstone"},
        {pos: [3, 4, 3], state: "minecraft:sandstone"},
        {pos: [3, 4, 4], state: "minecraft:sandstone"},
        {pos: [3, 4, 5], state: "minecraft:sandstone"},
        {pos: [3, 4, 6], state: "minecraft:sandstone"},
        {pos: [3, 4, 7], state: "minecraft:sandstone"},
        {pos: [3, 4, 8], state: "minecraft:sandstone"},
        {pos: [3, 4, 9], state: "minecraft:sandstone"},
        {pos: [4, 4, 0], state: "minecraft:sandstone"},
        {pos: [4, 4, 1], state: "minecraft:sandstone"},
        {pos: [4, 4, 2], state: "minecraft:sandstone"},
        {pos: [4, 4, 3], state: "minecraft:sandstone"},
        {pos: [4, 4, 4], state: "minecraft:sandstone"},
        {pos: [4, 4, 5], state: "minecraft:sandstone"},
        {pos: [4, 4, 6], state: "minecraft:sandstone"},
        {pos: [4, 4, 7], state: "minecraft:sandstone"},
        {pos: [4, 4, 8], state: "minecraft:sandstone"},
        {pos: [4, 4, 9], state: "minecraft:sandstone"},
        {pos: [4, 4, 10], state: "minecraft:sandstone"},
        {pos: [5, 4, 0], state: "minecraft:sandstone"},
        {pos: [5, 4, 1], state: "minecraft:sandstone"},
        {pos: [5, 4, 2], state: "minecraft:sandstone"},
        {pos: [5, 4, 3], state: "minecraft:sandstone"},
        {pos: [5, 4, 4], state: "minecraft:sandstone"},
        {pos: [5, 4, 5], state: "minecraft:water{level:0}"},
        {pos: [5, 4, 6], state: "minecraft:sandstone"},
        {pos: [5, 4, 7], state: "minecraft:sandstone"},
        {pos: [5, 4, 8], state: "minecraft:sandstone"},
        {pos: [5, 4, 9], state: "minecraft:sandstone"},
        {pos: [5, 4, 10], state: "minecraft:sandstone"},
        {pos: [6, 4, 0], state: "minecraft:sandstone"},
        {pos: [6, 4, 1], state: "minecraft:sandstone"},
        {pos: [6, 4, 2], state: "minecraft:sandstone"},
        {pos: [6, 4, 3], state: "minecraft:sandstone"},
        {pos: [6, 4, 4], state: "minecraft:sandstone"},
        {pos: [6, 4, 5], state: "minecraft:sandstone"},
        {pos: [6, 4, 6], state: "minecraft:sandstone"},
        {pos: [6, 4, 7], state: "minecraft:sandstone"},
        {pos: [6, 4, 8], state: "minecraft:sandstone"},
        {pos: [6, 4, 9], state: "minecraft:sandstone"},
        {pos: [6, 4, 10], state: "minecraft:sandstone"},
        {pos: [7, 4, 1], state: "minecraft:sandstone"},
        {pos: [7, 4, 2], state: "minecraft:sandstone"},
        {pos: [7, 4, 3], state: "minecraft:sandstone"},
        {pos: [7, 4, 4], state: "minecraft:sandstone"},
        {pos: [7, 4, 5], state: "minecraft:sandstone"},
        {pos: [7, 4, 6], state: "minecraft:sandstone"},
        {pos: [7, 4, 7], state: "minecraft:sandstone"},
        {pos: [7, 4, 8], state: "minecraft:sandstone"},
        {pos: [7, 4, 9], state: "minecraft:sandstone"},
        {pos: [8, 4, 1], state: "minecraft:sandstone"},
        {pos: [8, 4, 2], state: "minecraft:sandstone"},
        {pos: [8, 4, 3], state: "minecraft:sandstone"},
        {pos: [8, 4, 4], state: "minecraft:sandstone"},
        {pos: [8, 4, 5], state: "minecraft:sandstone"},
        {pos: [8, 4, 6], state: "minecraft:sandstone"},
        {pos: [8, 4, 7], state: "minecraft:sandstone"},
        {pos: [8, 4, 8], state: "minecraft:sandstone"},
        {pos: [8, 4, 9], state: "minecraft:sandstone"},
        {pos: [9, 4, 2], state: "minecraft:sandstone"},
        {pos: [9, 4, 3], state: "minecraft:sandstone"},
        {pos: [9, 4, 4], state: "minecraft:sandstone"},
        {pos: [9, 4, 5], state: "minecraft:sandstone"},
        {pos: [9, 4, 6], state: "minecraft:sandstone"},
        {pos: [9, 4, 7], state: "minecraft:sandstone"},
        {pos: [9, 4, 8], state: "minecraft:sandstone"},
        {pos: [10, 4, 4], state: "minecraft:sandstone"},
        {pos: [10, 4, 5], state: "minecraft:sandstone"},
        {pos: [10, 4, 6], state: "minecraft:sandstone"},
        {pos: [2, 5, 6], state: "minecraft:sandstone"},
        {pos: [2, 5, 7], state: "minecraft:sandstone"},
        {pos: [3, 5, 4], state: "minecraft:sandstone"},
        {pos: [3, 5, 5], state: "minecraft:sandstone"},
        {pos: [3, 5, 6], state: "minecraft:sandstone"},
        {pos: [3, 5, 7], state: "minecraft:sandstone"},
        {pos: [4, 5, 3], state: "minecraft:sandstone"},
        {pos: [4, 5, 4], state: "minecraft:sandstone"},
        {pos: [4, 5, 5], state: "minecraft:sandstone"},
        {pos: [4, 5, 6], state: "minecraft:sandstone"},
        {pos: [4, 5, 7], state: "minecraft:sandstone"},
        {pos: [5, 5, 2], state: "minecraft:sandstone"},
        {pos: [5, 5, 3], state: "minecraft:sandstone"},
        {pos: [5, 5, 4], state: "minecraft:sandstone"},
        {pos: [5, 5, 5], state: "minecraft:water{level:0}"},
        {pos: [5, 5, 6], state: "minecraft:sandstone"},
        {pos: [5, 5, 7], state: "minecraft:sandstone"},
        {pos: [5, 5, 8], state: "minecraft:sandstone"},
        {pos: [6, 5, 3], state: "minecraft:sandstone"},
        {pos: [6, 5, 4], state: "minecraft:sandstone"},
        {pos: [6, 5, 5], state: "minecraft:sandstone"},
        {pos: [6, 5, 6], state: "minecraft:sandstone"},
        {pos: [6, 5, 7], state: "minecraft:sandstone"},
        {pos: [6, 5, 8], state: "minecraft:sandstone"},
        {pos: [7, 5, 4], state: "minecraft:sandstone"},
        {pos: [7, 5, 5], state: "minecraft:sandstone"},
        {pos: [7, 5, 6], state: "minecraft:sandstone"},
        {pos: [7, 5, 7], state: "minecraft:sandstone"},
        {pos: [8, 5, 5], state: "minecraft:sandstone"},
        {pos: [8, 5, 6], state: "minecraft:sandstone"},
        {pos: [3, 6, 4], state: "minecraft:sandstone"},
        {pos: [3, 6, 5], state: "minecraft:sandstone"},
        {pos: [3, 6, 6], state: "minecraft:sandstone"},
        {pos: [4, 6, 4], state: "minecraft:sandstone"},
        {pos: [4, 6, 5], state: "minecraft:sandstone"},
        {pos: [4, 6, 6], state: "minecraft:sandstone"},
        {pos: [4, 6, 7], state: "minecraft:sandstone"},
        {pos: [5, 6, 3], state: "minecraft:sandstone"},
        {pos: [5, 6, 4], state: "minecraft:sandstone"},
        {pos: [5, 6, 5], state: "minecraft:water{level:0}"},
        {pos: [5, 6, 6], state: "minecraft:sandstone"},
        {pos: [5, 6, 7], state: "minecraft:sandstone"},
        {pos: [6, 6, 4], state: "minecraft:sandstone"},
        {pos: [6, 6, 5], state: "minecraft:sandstone"},
        {pos: [6, 6, 6], state: "minecraft:sandstone"},
        {pos: [7, 6, 5], state: "minecraft:sandstone"},
        {pos: [3, 7, 5], state: "minecraft:sandstone"},
        {pos: [3, 7, 6], state: "minecraft:sandstone"},
        {pos: [4, 7, 4], state: "minecraft:sandstone"},
        {pos: [4, 7, 5], state: "minecraft:sandstone"},
        {pos: [4, 7, 6], state: "minecraft:sandstone"},
        {pos: [5, 7, 4], state: "minecraft:sandstone"},
        {pos: [5, 7, 5], state: "minecraft:water{level:0}"},
        {pos: [5, 7, 6], state: "minecraft:sandstone"},
        {pos: [6, 7, 4], state: "minecraft:sandstone"},
        {pos: [6, 7, 5], state: "minecraft:sandstone"},
        {pos: [6, 7, 6], state: "minecraft:sandstone"},
        {pos: [4, 8, 4], state: "minecraft:sandstone"},
        {pos: [4, 8, 5], state: "minecraft:sandstone"},
        {pos: [4, 8, 6], state: "minecraft:sandstone"},
        {pos: [5, 8, 3], state: "minecraft:sandstone"},
        {pos: [5, 8, 4], state: "minecraft:sandstone"},
        {pos: [5, 8, 5], state: "minecraft:water{level:0}"},
        {pos: [5, 8, 6], state: "minecraft:sandstone"},
        {pos: [5, 8, 7], state: "minecraft:sandstone"},
        {pos: [6, 8, 3], state: "minecraft:sandstone"},
        {pos: [6, 8, 4], state: "minecraft:sandstone"},
        {pos: [6, 8, 5], state: "minecraft:sandstone"},
        {pos: [6, 8, 6], state: "minecraft:sandstone"},
        {pos: [7, 8, 4], state: "minecraft:sandstone"},
        {pos: [7, 8, 5], state: "minecraft:sandstone"},
        {pos: [3, 9, 3], state: "minecraft:sandstone"},
        {pos: [3, 9, 4], state: "minecraft:sandstone"},
        {pos: [3, 9, 5], state: "minecraft:sandstone"},
        {pos: [3, 9, 6], state: "minecraft:sandstone"},
        {pos: [3, 9, 7], state: "minecraft:sandstone"},
        {pos: [4, 9, 3], state: "minecraft:sandstone"},
        {pos: [4, 9, 4], state: "minecraft:sandstone"},
        {pos: [4, 9, 5], state: "minecraft:sandstone"},
        {pos: [4, 9, 6], state: "minecraft:sandstone"},
        {pos: [4, 9, 7], state: "minecraft:sandstone"},
        {pos: [5, 9, 3], state: "minecraft:sandstone"},
        {pos: [5, 9, 4], state: "minecraft:sandstone"},
        {pos: [5, 9, 5], state: "minecraft:water{level:0}"},
        {pos: [5, 9, 6], state: "minecraft:sandstone"},
        {pos: [5, 9, 7], state: "minecraft:sandstone"},
        {pos: [6, 9, 3], state: "minecraft:sandstone"},
        {pos: [6, 9, 4], state: "minecraft:sandstone"},
        {pos: [6, 9, 5], state: "minecraft:sandstone"},
        {pos: [6, 9, 6], state: "minecraft:sandstone"},
        {pos: [6, 9, 7], state: "minecraft:sandstone"},
        {pos: [7, 9, 3], state: "minecraft:sandstone"},
        {pos: [7, 9, 4], state: "minecraft:sandstone"},
        {pos: [7, 9, 5], state: "minecraft:sandstone"},
        {pos: [7, 9, 6], state: "minecraft:sandstone"},
        {pos: [7, 9, 7], state: "minecraft:sandstone"},
        {pos: [3, 10, 3], state: "minecraft:sandstone"},
        {pos: [3, 10, 4], state: "minecraft:sandstone"},
        {pos: [3, 10, 5], state: "minecraft:sandstone"},
        {pos: [3, 10, 6], state: "minecraft:sandstone"},
        {pos: [3, 10, 7], state: "minecraft:sandstone"},
        {pos: [4, 10, 3], state: "minecraft:sandstone"},
        {pos: [4, 10, 4], state: "minecraft:sandstone"},
        {pos: [4, 10, 5], state: "minecraft:sandstone"},
        {pos: [4, 10, 6], state: "minecraft:sandstone"},
        {pos: [4, 10, 7], state: "minecraft:sandstone"},
        {pos: [5, 10, 3], state: "minecraft:sandstone"},
        {pos: [5, 10, 4], state: "minecraft:water{level:0}"},
        {pos: [5, 10, 5], state: "minecraft:water{level:0}"},
        {pos: [5, 10, 6], state: "minecraft:sandstone"},
        {pos: [5, 10, 7], state: "minecraft:sandstone"},
        {pos: [6, 10, 3], state: "minecraft:sandstone"},
        {pos: [6, 10, 4], state: "minecraft:sandstone"},
        {pos: [6, 10, 5], state: "minecraft:water{level:0}"},
        {pos: [6, 10, 6], state: "minecraft:sandstone"},
        {pos: [6, 10, 7], state: "minecraft:sandstone"},
        {pos: [7, 10, 3], state: "minecraft:sandstone"},
        {pos: [7, 10, 4], state: "minecraft:sandstone"},
        {pos: [7, 10, 5], state: "minecraft:sandstone"},
        {pos: [7, 10, 6], state: "minecraft:sandstone"},
        {pos: [7, 10, 7], state: "minecraft:sandstone"},
        {pos: [3, 11, 3], state: "minecraft:sandstone"},
        {pos: [3, 11, 4], state: "minecraft:sandstone"},
        {pos: [3, 11, 5], state: "minecraft:sandstone"},
        {pos: [3, 11, 6], state: "minecraft:sandstone"},
        {pos: [3, 11, 7], state: "minecraft:sandstone"},
        {pos: [4, 11, 3], state: "minecraft:sandstone"},
        {pos: [4, 11, 4], state: "minecraft:sandstone"},
        {pos: [4, 11, 5], state: "minecraft:water{level:0}"},
        {pos: [4, 11, 6], state: "minecraft:sandstone"},
        {pos: [4, 11, 7], state: "minecraft:sandstone"},
        {pos: [5, 11, 3], state: "minecraft:sandstone"},
        {pos: [5, 11, 4], state: "minecraft:water{level:0}"},
        {pos: [5, 11, 5], state: "minecraft:water{level:0}"},
        {pos: [5, 11, 6], state: "minecraft:water{level:0}"},
        {pos: [5, 11, 7], state: "minecraft:sandstone"},
        {pos: [6, 11, 3], state: "minecraft:sandstone"},
        {pos: [6, 11, 4], state: "minecraft:sandstone"},
        {pos: [6, 11, 5], state: "minecraft:water{level:0}"},
        {pos: [6, 11, 6], state: "minecraft:sandstone"},
        {pos: [6, 11, 7], state: "minecraft:sandstone"},
        {pos: [7, 11, 3], state: "minecraft:sandstone"},
        {pos: [7, 11, 4], state: "minecraft:sandstone"},
        {pos: [7, 11, 5], state: "minecraft:sandstone"},
        {pos: [7, 11, 6], state: "minecraft:sandstone"},
        {pos: [7, 11, 7], state: "minecraft:sandstone"},
        {pos: [3, 12, 3], state: "minecraft:sandstone"},
        {pos: [3, 12, 4], state: "minecraft:sandstone"},
        {pos: [3, 12, 5], state: "minecraft:sandstone"},
        {pos: [3, 12, 6], state: "minecraft:sandstone"},
        {pos: [3, 12, 7], state: "minecraft:sandstone"},
        {pos: [4, 12, 3], state: "minecraft:sandstone"},
        {pos: [4, 12, 4], state: "minecraft:sandstone"},
        {pos: [4, 12, 5], state: "minecraft:water{level:0}"},
        {pos: [4, 12, 6], state: "minecraft:sandstone"},
        {pos: [4, 12, 7], state: "minecraft:sandstone"},
        {pos: [5, 12, 3], state: "minecraft:sandstone"},
        {pos: [5, 12, 4], state: "minecraft:water{level:0}"},
        {pos: [5, 12, 5], state: "minecraft:water{level:0}"},
        {pos: [5, 12, 6], state: "minecraft:water{level:0}"},
        {pos: [5, 12, 7], state: "minecraft:sandstone"},
        {pos: [6, 12, 3], state: "minecraft:sandstone"},
        {pos: [6, 12, 4], state: "minecraft:sandstone"},
        {pos: [6, 12, 5], state: "minecraft:water{level:0}"},
        {pos: [6, 12, 6], state: "minecraft:sandstone"},
        {pos: [6, 12, 7], state: "minecraft:sandstone"},
        {pos: [7, 12, 3], state: "minecraft:sandstone"},
        {pos: [7, 12, 4], state: "minecraft:sandstone"},
        {pos: [7, 12, 5], state: "minecraft:sandstone"},
        {pos: [7, 12, 6], state: "minecraft:sandstone"},
        {pos: [7, 12, 7], state: "minecraft:sandstone"},
        {pos: [3, 13, 3], state: "minecraft:sandstone"},
        {pos: [3, 13, 4], state: "minecraft:sandstone"},
        {pos: [3, 13, 5], state: "minecraft:sandstone_slab{type:bottom,waterlogged:false}"},
        {pos: [3, 13, 6], state: "minecraft:sandstone"},
        {pos: [3, 13, 7], state: "minecraft:cut_sandstone"},
        {pos: [4, 13, 3], state: "minecraft:sandstone"},
        {pos: [4, 13, 4], state: "minecraft:sandstone"},
        {pos: [4, 13, 5], state: "minecraft:air"},
        {pos: [4, 13, 6], state: "minecraft:sandstone"},
        {pos: [4, 13, 7], state: "minecraft:sandstone"},
        {pos: [5, 13, 3], state: "minecraft:sandstone_slab{type:bottom,waterlogged:false}"},
        {pos: [5, 13, 4], state: "minecraft:air"},
        {pos: [5, 13, 5], state: "minecraft:air"},
        {pos: [5, 13, 6], state: "minecraft:air"},
        {pos: [5, 13, 7], state: "minecraft:sandstone_slab{type:bottom,waterlogged:false}"},
        {pos: [6, 13, 3], state: "minecraft:sandstone"},
        {pos: [6, 13, 4], state: "minecraft:sandstone"},
        {pos: [6, 13, 5], state: "minecraft:air"},
        {pos: [6, 13, 6], state: "minecraft:sandstone"},
        {pos: [6, 13, 7], state: "minecraft:sandstone"},
        {pos: [7, 13, 3], state: "minecraft:sandstone"},
        {pos: [7, 13, 4], state: "minecraft:sandstone"},
        {pos: [7, 13, 5], state: "minecraft:sandstone_slab{type:bottom,waterlogged:false}"},
        {pos: [7, 13, 6], state: "minecraft:sandstone"},
        {pos: [7, 13, 7], state: "minecraft:sandstone"},
        {pos: [4, 14, 4], state: "minecraft:sandstone"},
        {pos: [4, 14, 6], state: "minecraft:sandstone"},
        {pos: [5, 14, 5], state: "minecraft:air"},
        {pos: [6, 14, 4], state: "minecraft:sandstone"},
        {pos: [6, 14, 6], state: "minecraft:sandstone"},
        {pos: [4, 15, 4], state: "minecraft:sandstone"},
        {pos: [4, 15, 6], state: "minecraft:sandstone"},
        {pos: [6, 15, 4], state: "minecraft:sandstone"},
        {pos: [6, 15, 6], state: "minecraft:sandstone"},
        {pos: [4, 16, 4], state: "minecraft:sandstone_slab{type:bottom,waterlogged:false}"},
        {pos: [4, 16, 5], state: "minecraft:sandstone_slab{type:bottom,waterlogged:false}"},
        {pos: [4, 16, 6], state: "minecraft:sandstone_slab{type:bottom,waterlogged:false}"},
        {pos: [5, 16, 4], state: "minecraft:sandstone_slab{type:bottom,waterlogged:false}"},
        {pos: [5, 16, 5], state: "minecraft:sandstone"},
        {pos: [5, 16, 6], state: "minecraft:sandstone_slab{type:bottom,waterlogged:false}"},
        {pos: [6, 16, 4], state: "minecraft:sandstone_slab{type:bottom,waterlogged:false}"},
        {pos: [6, 16, 5], state: "minecraft:sandstone_slab{type:bottom,waterlogged:false}"},
        {pos: [6, 16, 6], state: "minecraft:sandstone_slab{type:bottom,waterlogged:false}"}
    ],
    entities: [],
    palette: [
        "minecraft:sandstone",
        "minecraft:clay",
        "minecraft:sand",
        "minecraft:bricks",
        "minecraft:cut_sandstone",
        "minecraft:water{level:8}",
        "minecraft:brick_slab{type:bottom,waterlogged:true}",
        "minecraft:sandstone_stairs{facing:south,half:top,shape:straight,waterlogged:true}",
        "minecraft:sandstone_stairs{facing:north,half:top,shape:straight,waterlogged:true}",
        "minecraft:stonecutter{facing:west}",
        "minecraft:sandstone_stairs{facing:east,half:top,shape:straight,waterlogged:true}",
        "minecraft:water{level:1}",
        "minecraft:water{level:0}",
        "minecraft:chain{axis:y,waterlogged:true}",
        "minecraft:sandstone_slab{type:bottom,waterlogged:false}",
        "minecraft:air",
        "minecraft:decorated_pot{cracked:false,facing:west,waterlogged:true}",
        "minecraft:decorated_pot{cracked:false,facing:north,waterlogged:true}",
        "minecraft:decorated_pot{cracked:false,facing:south,waterlogged:true}",
        "minecraft:decorated_pot{cracked:false,facing:east,waterlogged:true}"
    ],
    trailiertales_DataVersion: 2
}
