{
    DataVersion: 3953,
    size: [27, 13, 37],
    data: [
        {pos: [5, 0, 0], state: "minecraft:deepslate_bricks"},
        {pos: [5, 0, 1], state: "minecraft:deepslate_bricks"},
        {pos: [5, 0, 2], state: "minecraft:deepslate_bricks"},
        {pos: [5, 0, 3], state: "minecraft:deepslate_bricks"},
        {pos: [5, 0, 4], state: "minecraft:deepslate_bricks"},
        {pos: [5, 0, 5], state: "minecraft:deepslate_bricks"},
        {pos: [5, 0, 6], state: "minecraft:deepslate_bricks"},
        {pos: [5, 0, 7], state: "minecraft:deepslate_bricks"},
        {pos: [5, 0, 8], state: "minecraft:deepslate_bricks"},
        {pos: [5, 0, 28], state: "minecraft:deepslate_bricks"},
        {pos: [5, 0, 29], state: "minecraft:deepslate_bricks"},
        {pos: [5, 0, 30], state: "minecraft:deepslate_bricks"},
        {pos: [5, 0, 31], state: "minecraft:deepslate_bricks"},
        {pos: [5, 0, 32], state: "minecraft:deepslate_bricks"},
        {pos: [5, 0, 33], state: "minecraft:deepslate_bricks"},
        {pos: [5, 0, 34], state: "minecraft:deepslate_bricks"},
        {pos: [5, 0, 35], state: "minecraft:deepslate_bricks"},
        {pos: [5, 0, 36], state: "minecraft:deepslate_bricks"},
        {pos: [6, 0, 0], state: "minecraft:deepslate_bricks"},
        {pos: [6, 0, 1], state: "minecraft:deepslate_bricks"},
        {pos: [6, 0, 2], state: "minecraft:deepslate_bricks"},
        {pos: [6, 0, 3], state: "minecraft:deepslate_bricks"},
        {pos: [6, 0, 4], state: "minecraft:deepslate_bricks"},
        {pos: [6, 0, 5], state: "minecraft:deepslate_bricks"},
        {pos: [6, 0, 6], state: "minecraft:deepslate_bricks"},
        {pos: [6, 0, 7], state: "minecraft:deepslate_bricks"},
        {pos: [6, 0, 8], state: "minecraft:deepslate_bricks"},
        {pos: [6, 0, 28], state: "minecraft:deepslate_bricks"},
        {pos: [6, 0, 29], state: "minecraft:deepslate_bricks"},
        {pos: [6, 0, 30], state: "minecraft:deepslate_bricks"},
        {pos: [6, 0, 31], state: "minecraft:deepslate_bricks"},
        {pos: [6, 0, 32], state: "minecraft:deepslate_bricks"},
        {pos: [6, 0, 33], state: "minecraft:deepslate_bricks"},
        {pos: [6, 0, 34], state: "minecraft:deepslate_bricks"},
        {pos: [6, 0, 35], state: "minecraft:deepslate_bricks"},
        {pos: [6, 0, 36], state: "minecraft:deepslate_bricks"},
        {pos: [7, 0, 0], state: "minecraft:deepslate_bricks"},
        {pos: [7, 0, 1], state: "minecraft:deepslate_bricks"},
        {pos: [7, 0, 2], state: "minecraft:deepslate_bricks"},
        {pos: [7, 0, 3], state: "minecraft:deepslate_bricks"},
        {pos: [7, 0, 4], state: "minecraft:deepslate_bricks"},
        {pos: [7, 0, 5], state: "minecraft:deepslate_bricks"},
        {pos: [7, 0, 6], state: "minecraft:deepslate_bricks"},
        {pos: [7, 0, 7], state: "minecraft:deepslate_bricks"},
        {pos: [7, 0, 8], state: "minecraft:deepslate_bricks"},
        {pos: [7, 0, 28], state: "minecraft:deepslate_bricks"},
        {pos: [7, 0, 29], state: "minecraft:deepslate_bricks"},
        {pos: [7, 0, 30], state: "minecraft:deepslate_bricks"},
        {pos: [7, 0, 31], state: "minecraft:deepslate_bricks"},
        {pos: [7, 0, 32], state: "minecraft:deepslate_bricks"},
        {pos: [7, 0, 33], state: "minecraft:deepslate_bricks"},
        {pos: [7, 0, 34], state: "minecraft:deepslate_bricks"},
        {pos: [7, 0, 35], state: "minecraft:deepslate_bricks"},
        {pos: [7, 0, 36], state: "minecraft:deepslate_bricks"},
        {pos: [8, 0, 0], state: "minecraft:deepslate_bricks"},
        {pos: [8, 0, 1], state: "minecraft:deepslate_bricks"},
        {pos: [8, 0, 2], state: "minecraft:deepslate_bricks"},
        {pos: [8, 0, 3], state: "minecraft:deepslate_bricks"},
        {pos: [8, 0, 4], state: "minecraft:deepslate_bricks"},
        {pos: [8, 0, 5], state: "minecraft:deepslate_bricks"},
        {pos: [8, 0, 6], state: "minecraft:deepslate_bricks"},
        {pos: [8, 0, 7], state: "minecraft:deepslate_bricks"},
        {pos: [8, 0, 8], state: "minecraft:deepslate_bricks"},
        {pos: [8, 0, 28], state: "minecraft:deepslate_bricks"},
        {pos: [8, 0, 29], state: "minecraft:deepslate_bricks"},
        {pos: [8, 0, 30], state: "minecraft:deepslate_bricks"},
        {pos: [8, 0, 31], state: "minecraft:deepslate_bricks"},
        {pos: [8, 0, 32], state: "minecraft:deepslate_bricks"},
        {pos: [8, 0, 33], state: "minecraft:deepslate_bricks"},
        {pos: [8, 0, 34], state: "minecraft:deepslate_bricks"},
        {pos: [8, 0, 35], state: "minecraft:deepslate_bricks"},
        {pos: [8, 0, 36], state: "minecraft:deepslate_bricks"},
        {pos: [9, 0, 0], state: "minecraft:deepslate_bricks"},
        {pos: [9, 0, 1], state: "minecraft:deepslate_bricks"},
        {pos: [9, 0, 2], state: "minecraft:deepslate_bricks"},
        {pos: [9, 0, 3], state: "minecraft:deepslate_bricks"},
        {pos: [9, 0, 4], state: "minecraft:deepslate_bricks"},
        {pos: [9, 0, 5], state: "minecraft:deepslate_bricks"},
        {pos: [9, 0, 6], state: "minecraft:deepslate_bricks"},
        {pos: [9, 0, 7], state: "minecraft:deepslate_bricks"},
        {pos: [9, 0, 8], state: "minecraft:deepslate_bricks"},
        {pos: [9, 0, 28], state: "minecraft:deepslate_bricks"},
        {pos: [9, 0, 29], state: "minecraft:deepslate_bricks"},
        {pos: [9, 0, 30], state: "minecraft:deepslate_bricks"},
        {pos: [9, 0, 31], state: "minecraft:deepslate_bricks"},
        {pos: [9, 0, 32], state: "minecraft:deepslate_bricks"},
        {pos: [9, 0, 33], state: "minecraft:deepslate_bricks"},
        {pos: [9, 0, 34], state: "minecraft:deepslate_bricks"},
        {pos: [9, 0, 35], state: "minecraft:deepslate_bricks"},
        {pos: [9, 0, 36], state: "minecraft:deepslate_bricks"},
        {pos: [10, 0, 0], state: "minecraft:deepslate_bricks"},
        {pos: [10, 0, 1], state: "minecraft:deepslate_bricks"},
        {pos: [10, 0, 2], state: "minecraft:deepslate_bricks"},
        {pos: [10, 0, 3], state: "minecraft:deepslate_bricks"},
        {pos: [10, 0, 4], state: "minecraft:deepslate_bricks"},
        {pos: [10, 0, 5], state: "minecraft:deepslate_bricks"},
        {pos: [10, 0, 6], state: "minecraft:deepslate_bricks"},
        {pos: [10, 0, 7], state: "minecraft:deepslate_bricks"},
        {pos: [10, 0, 8], state: "minecraft:deepslate_bricks"},
        {pos: [10, 0, 28], state: "minecraft:deepslate_bricks"},
        {pos: [10, 0, 29], state: "minecraft:deepslate_bricks"},
        {pos: [10, 0, 30], state: "minecraft:deepslate_bricks"},
        {pos: [10, 0, 31], state: "minecraft:deepslate_bricks"},
        {pos: [10, 0, 32], state: "minecraft:deepslate_bricks"},
        {pos: [10, 0, 33], state: "minecraft:deepslate_bricks"},
        {pos: [10, 0, 34], state: "minecraft:deepslate_bricks"},
        {pos: [10, 0, 35], state: "minecraft:deepslate_bricks"},
        {pos: [10, 0, 36], state: "minecraft:deepslate_bricks"},
        {pos: [11, 0, 0], state: "minecraft:deepslate_bricks"},
        {pos: [11, 0, 1], state: "minecraft:deepslate_bricks"},
        {pos: [11, 0, 2], state: "minecraft:deepslate_bricks"},
        {pos: [11, 0, 3], state: "minecraft:deepslate_bricks"},
        {pos: [11, 0, 4], state: "minecraft:deepslate_bricks"},
        {pos: [11, 0, 5], state: "minecraft:deepslate_bricks"},
        {pos: [11, 0, 6], state: "minecraft:deepslate_bricks"},
        {pos: [11, 0, 7], state: "minecraft:deepslate_bricks"},
        {pos: [11, 0, 8], state: "minecraft:deepslate_bricks"},
        {pos: [11, 0, 9], state: "minecraft:deepslate_bricks"},
        {pos: [11, 0, 10], state: "minecraft:deepslate_bricks"},
        {pos: [11, 0, 11], state: "minecraft:deepslate_bricks"},
        {pos: [11, 0, 12], state: "minecraft:deepslate_bricks"},
        {pos: [11, 0, 13], state: "minecraft:deepslate_bricks"},
        {pos: [11, 0, 23], state: "minecraft:deepslate_bricks"},
        {pos: [11, 0, 24], state: "minecraft:deepslate_bricks"},
        {pos: [11, 0, 25], state: "minecraft:deepslate_bricks"},
        {pos: [11, 0, 26], state: "minecraft:deepslate_bricks"},
        {pos: [11, 0, 27], state: "minecraft:deepslate_bricks"},
        {pos: [11, 0, 28], state: "minecraft:deepslate_bricks"},
        {pos: [11, 0, 29], state: "minecraft:deepslate_bricks"},
        {pos: [11, 0, 30], state: "minecraft:deepslate_bricks"},
        {pos: [11, 0, 31], state: "minecraft:deepslate_bricks"},
        {pos: [11, 0, 32], state: "minecraft:deepslate_bricks"},
        {pos: [11, 0, 33], state: "minecraft:deepslate_bricks"},
        {pos: [11, 0, 34], state: "minecraft:deepslate_bricks"},
        {pos: [11, 0, 35], state: "minecraft:deepslate_bricks"},
        {pos: [11, 0, 36], state: "minecraft:deepslate_bricks"},
        {pos: [12, 0, 0], state: "minecraft:deepslate_bricks"},
        {pos: [12, 0, 1], state: "minecraft:deepslate_bricks"},
        {pos: [12, 0, 2], state: "minecraft:deepslate_bricks"},
        {pos: [12, 0, 3], state: "minecraft:deepslate_bricks"},
        {pos: [12, 0, 4], state: "minecraft:deepslate_bricks"},
        {pos: [12, 0, 5], state: "minecraft:deepslate_bricks"},
        {pos: [12, 0, 6], state: "minecraft:deepslate_bricks"},
        {pos: [12, 0, 7], state: "minecraft:deepslate_bricks"},
        {pos: [12, 0, 8], state: "minecraft:deepslate_bricks"},
        {pos: [12, 0, 9], state: "minecraft:deepslate_bricks"},
        {pos: [12, 0, 10], state: "minecraft:deepslate_bricks"},
        {pos: [12, 0, 11], state: "minecraft:deepslate_bricks"},
        {pos: [12, 0, 12], state: "minecraft:deepslate_bricks"},
        {pos: [12, 0, 13], state: "minecraft:deepslate_bricks"},
        {pos: [12, 0, 23], state: "minecraft:deepslate_bricks"},
        {pos: [12, 0, 24], state: "minecraft:deepslate_bricks"},
        {pos: [12, 0, 25], state: "minecraft:deepslate_bricks"},
        {pos: [12, 0, 26], state: "minecraft:deepslate_bricks"},
        {pos: [12, 0, 27], state: "minecraft:deepslate_bricks"},
        {pos: [12, 0, 28], state: "minecraft:deepslate_bricks"},
        {pos: [12, 0, 29], state: "minecraft:deepslate_bricks"},
        {pos: [12, 0, 30], state: "minecraft:deepslate_bricks"},
        {pos: [12, 0, 31], state: "minecraft:deepslate_bricks"},
        {pos: [12, 0, 32], state: "minecraft:deepslate_bricks"},
        {pos: [12, 0, 33], state: "minecraft:deepslate_bricks"},
        {pos: [12, 0, 34], state: "minecraft:deepslate_bricks"},
        {pos: [12, 0, 35], state: "minecraft:deepslate_bricks"},
        {pos: [12, 0, 36], state: "minecraft:deepslate_bricks"},
        {pos: [13, 0, 0], state: "minecraft:deepslate_bricks"},
        {pos: [13, 0, 1], state: "minecraft:deepslate_bricks"},
        {pos: [13, 0, 2], state: "minecraft:deepslate_bricks"},
        {pos: [13, 0, 3], state: "minecraft:deepslate_bricks"},
        {pos: [13, 0, 4], state: "minecraft:deepslate_bricks"},
        {pos: [13, 0, 5], state: "minecraft:deepslate_bricks"},
        {pos: [13, 0, 6], state: "minecraft:deepslate_bricks"},
        {pos: [13, 0, 7], state: "minecraft:deepslate_bricks"},
        {pos: [13, 0, 8], state: "minecraft:deepslate_bricks"},
        {pos: [13, 0, 9], state: "minecraft:deepslate_bricks"},
        {pos: [13, 0, 10], state: "minecraft:deepslate_bricks"},
        {pos: [13, 0, 11], state: "minecraft:deepslate_bricks"},
        {pos: [13, 0, 12], state: "minecraft:deepslate_bricks"},
        {pos: [13, 0, 13], state: "minecraft:deepslate_bricks"},
        {pos: [13, 0, 23], state: "minecraft:deepslate_bricks"},
        {pos: [13, 0, 24], state: "minecraft:deepslate_bricks"},
        {pos: [13, 0, 25], state: "minecraft:deepslate_bricks"},
        {pos: [13, 0, 26], state: "minecraft:deepslate_bricks"},
        {pos: [13, 0, 27], state: "minecraft:deepslate_bricks"},
        {pos: [13, 0, 28], state: "minecraft:deepslate_bricks"},
        {pos: [13, 0, 29], state: "minecraft:deepslate_bricks"},
        {pos: [13, 0, 30], state: "minecraft:deepslate_bricks"},
        {pos: [13, 0, 31], state: "minecraft:deepslate_bricks"},
        {pos: [13, 0, 32], state: "minecraft:deepslate_bricks"},
        {pos: [13, 0, 33], state: "minecraft:deepslate_bricks"},
        {pos: [13, 0, 34], state: "minecraft:deepslate_bricks"},
        {pos: [13, 0, 35], state: "minecraft:deepslate_bricks"},
        {pos: [13, 0, 36], state: "minecraft:deepslate_bricks"},
        {pos: [14, 0, 0], state: "minecraft:deepslate_bricks"},
        {pos: [14, 0, 1], state: "minecraft:deepslate_bricks"},
        {pos: [14, 0, 2], state: "minecraft:deepslate_bricks"},
        {pos: [14, 0, 3], state: "minecraft:deepslate_bricks"},
        {pos: [14, 0, 4], state: "minecraft:deepslate_bricks"},
        {pos: [14, 0, 5], state: "minecraft:deepslate_bricks"},
        {pos: [14, 0, 6], state: "minecraft:deepslate_bricks"},
        {pos: [14, 0, 7], state: "minecraft:deepslate_bricks"},
        {pos: [14, 0, 8], state: "minecraft:deepslate_bricks"},
        {pos: [14, 0, 9], state: "minecraft:deepslate_bricks"},
        {pos: [14, 0, 10], state: "minecraft:deepslate_bricks"},
        {pos: [14, 0, 11], state: "minecraft:deepslate_bricks"},
        {pos: [14, 0, 12], state: "minecraft:deepslate_bricks"},
        {pos: [14, 0, 13], state: "minecraft:deepslate_bricks"},
        {pos: [14, 0, 23], state: "minecraft:deepslate_bricks"},
        {pos: [14, 0, 24], state: "minecraft:deepslate_bricks"},
        {pos: [14, 0, 25], state: "minecraft:deepslate_bricks"},
        {pos: [14, 0, 26], state: "minecraft:deepslate_bricks"},
        {pos: [14, 0, 27], state: "minecraft:deepslate_bricks"},
        {pos: [14, 0, 28], state: "minecraft:deepslate_bricks"},
        {pos: [14, 0, 29], state: "minecraft:deepslate_bricks"},
        {pos: [14, 0, 30], state: "minecraft:deepslate_bricks"},
        {pos: [14, 0, 31], state: "minecraft:deepslate_bricks"},
        {pos: [14, 0, 32], state: "minecraft:deepslate_bricks"},
        {pos: [14, 0, 33], state: "minecraft:deepslate_bricks"},
        {pos: [14, 0, 34], state: "minecraft:deepslate_bricks"},
        {pos: [14, 0, 35], state: "minecraft:deepslate_bricks"},
        {pos: [14, 0, 36], state: "minecraft:deepslate_bricks"},
        {pos: [15, 0, 0], state: "minecraft:deepslate_bricks"},
        {pos: [15, 0, 1], state: "minecraft:deepslate_bricks"},
        {pos: [15, 0, 2], state: "minecraft:deepslate_bricks"},
        {pos: [15, 0, 3], state: "minecraft:deepslate_bricks"},
        {pos: [15, 0, 4], state: "minecraft:deepslate_bricks"},
        {pos: [15, 0, 5], state: "minecraft:deepslate_bricks"},
        {pos: [15, 0, 6], state: "minecraft:deepslate_bricks"},
        {pos: [15, 0, 7], state: "minecraft:deepslate_bricks"},
        {pos: [15, 0, 8], state: "minecraft:deepslate_bricks"},
        {pos: [15, 0, 9], state: "minecraft:deepslate_bricks"},
        {pos: [15, 0, 10], state: "minecraft:deepslate_bricks"},
        {pos: [15, 0, 11], state: "minecraft:deepslate_bricks"},
        {pos: [15, 0, 12], state: "minecraft:deepslate_bricks"},
        {pos: [15, 0, 13], state: "minecraft:deepslate_bricks"},
        {pos: [15, 0, 23], state: "minecraft:deepslate_bricks"},
        {pos: [15, 0, 24], state: "minecraft:deepslate_bricks"},
        {pos: [15, 0, 25], state: "minecraft:deepslate_bricks"},
        {pos: [15, 0, 26], state: "minecraft:deepslate_bricks"},
        {pos: [15, 0, 27], state: "minecraft:deepslate_bricks"},
        {pos: [15, 0, 28], state: "minecraft:deepslate_bricks"},
        {pos: [15, 0, 29], state: "minecraft:deepslate_bricks"},
        {pos: [15, 0, 30], state: "minecraft:deepslate_bricks"},
        {pos: [15, 0, 31], state: "minecraft:deepslate_bricks"},
        {pos: [15, 0, 32], state: "minecraft:deepslate_bricks"},
        {pos: [15, 0, 33], state: "minecraft:deepslate_bricks"},
        {pos: [15, 0, 34], state: "minecraft:deepslate_bricks"},
        {pos: [15, 0, 35], state: "minecraft:deepslate_bricks"},
        {pos: [15, 0, 36], state: "minecraft:deepslate_bricks"},
        {pos: [16, 0, 0], state: "minecraft:deepslate_bricks"},
        {pos: [16, 0, 1], state: "minecraft:deepslate_bricks"},
        {pos: [16, 0, 2], state: "minecraft:deepslate_bricks"},
        {pos: [16, 0, 3], state: "minecraft:deepslate_bricks"},
        {pos: [16, 0, 4], state: "minecraft:deepslate_bricks"},
        {pos: [16, 0, 5], state: "minecraft:deepslate_bricks"},
        {pos: [16, 0, 6], state: "minecraft:deepslate_bricks"},
        {pos: [16, 0, 7], state: "minecraft:deepslate_bricks"},
        {pos: [16, 0, 8], state: "minecraft:deepslate_bricks"},
        {pos: [16, 0, 28], state: "minecraft:deepslate_bricks"},
        {pos: [16, 0, 29], state: "minecraft:deepslate_bricks"},
        {pos: [16, 0, 30], state: "minecraft:deepslate_bricks"},
        {pos: [16, 0, 31], state: "minecraft:deepslate_bricks"},
        {pos: [16, 0, 32], state: "minecraft:deepslate_bricks"},
        {pos: [16, 0, 33], state: "minecraft:deepslate_bricks"},
        {pos: [16, 0, 34], state: "minecraft:deepslate_bricks"},
        {pos: [16, 0, 35], state: "minecraft:deepslate_bricks"},
        {pos: [16, 0, 36], state: "minecraft:deepslate_bricks"},
        {pos: [17, 0, 0], state: "minecraft:deepslate_bricks"},
        {pos: [17, 0, 1], state: "minecraft:deepslate_bricks"},
        {pos: [17, 0, 2], state: "minecraft:deepslate_bricks"},
        {pos: [17, 0, 3], state: "minecraft:deepslate_bricks"},
        {pos: [17, 0, 4], state: "minecraft:deepslate_bricks"},
        {pos: [17, 0, 5], state: "minecraft:deepslate_bricks"},
        {pos: [17, 0, 6], state: "minecraft:deepslate_bricks"},
        {pos: [17, 0, 7], state: "minecraft:deepslate_bricks"},
        {pos: [17, 0, 8], state: "minecraft:deepslate_bricks"},
        {pos: [17, 0, 28], state: "minecraft:deepslate_bricks"},
        {pos: [17, 0, 29], state: "minecraft:deepslate_bricks"},
        {pos: [17, 0, 30], state: "minecraft:deepslate_bricks"},
        {pos: [17, 0, 31], state: "minecraft:deepslate_bricks"},
        {pos: [17, 0, 32], state: "minecraft:deepslate_bricks"},
        {pos: [17, 0, 33], state: "minecraft:deepslate_bricks"},
        {pos: [17, 0, 34], state: "minecraft:deepslate_bricks"},
        {pos: [17, 0, 35], state: "minecraft:deepslate_bricks"},
        {pos: [17, 0, 36], state: "minecraft:deepslate_bricks"},
        {pos: [18, 0, 0], state: "minecraft:deepslate_bricks"},
        {pos: [18, 0, 1], state: "minecraft:deepslate_bricks"},
        {pos: [18, 0, 2], state: "minecraft:deepslate_bricks"},
        {pos: [18, 0, 3], state: "minecraft:deepslate_bricks"},
        {pos: [18, 0, 4], state: "minecraft:deepslate_bricks"},
        {pos: [18, 0, 5], state: "minecraft:deepslate_bricks"},
        {pos: [18, 0, 6], state: "minecraft:deepslate_bricks"},
        {pos: [18, 0, 7], state: "minecraft:deepslate_bricks"},
        {pos: [18, 0, 8], state: "minecraft:deepslate_bricks"},
        {pos: [18, 0, 28], state: "minecraft:deepslate_bricks"},
        {pos: [18, 0, 29], state: "minecraft:deepslate_bricks"},
        {pos: [18, 0, 30], state: "minecraft:deepslate_bricks"},
        {pos: [18, 0, 31], state: "minecraft:deepslate_bricks"},
        {pos: [18, 0, 32], state: "minecraft:deepslate_bricks"},
        {pos: [18, 0, 33], state: "minecraft:deepslate_bricks"},
        {pos: [18, 0, 34], state: "minecraft:deepslate_bricks"},
        {pos: [18, 0, 35], state: "minecraft:deepslate_bricks"},
        {pos: [18, 0, 36], state: "minecraft:deepslate_bricks"},
        {pos: [19, 0, 0], state: "minecraft:deepslate_bricks"},
        {pos: [19, 0, 1], state: "minecraft:deepslate_bricks"},
        {pos: [19, 0, 2], state: "minecraft:deepslate_bricks"},
        {pos: [19, 0, 3], state: "minecraft:deepslate_bricks"},
        {pos: [19, 0, 4], state: "minecraft:deepslate_bricks"},
        {pos: [19, 0, 5], state: "minecraft:deepslate_bricks"},
        {pos: [19, 0, 6], state: "minecraft:deepslate_bricks"},
        {pos: [19, 0, 7], state: "minecraft:deepslate_bricks"},
        {pos: [19, 0, 8], state: "minecraft:deepslate_bricks"},
        {pos: [19, 0, 28], state: "minecraft:deepslate_bricks"},
        {pos: [19, 0, 29], state: "minecraft:deepslate_bricks"},
        {pos: [19, 0, 30], state: "minecraft:deepslate_bricks"},
        {pos: [19, 0, 31], state: "minecraft:deepslate_bricks"},
        {pos: [19, 0, 32], state: "minecraft:deepslate_bricks"},
        {pos: [19, 0, 33], state: "minecraft:deepslate_bricks"},
        {pos: [19, 0, 34], state: "minecraft:deepslate_bricks"},
        {pos: [19, 0, 35], state: "minecraft:deepslate_bricks"},
        {pos: [19, 0, 36], state: "minecraft:deepslate_bricks"},
        {pos: [20, 0, 0], state: "minecraft:deepslate_bricks"},
        {pos: [20, 0, 1], state: "minecraft:deepslate_bricks"},
        {pos: [20, 0, 2], state: "minecraft:deepslate_bricks"},
        {pos: [20, 0, 3], state: "minecraft:deepslate_bricks"},
        {pos: [20, 0, 4], state: "minecraft:deepslate_bricks"},
        {pos: [20, 0, 5], state: "minecraft:deepslate_bricks"},
        {pos: [20, 0, 6], state: "minecraft:deepslate_bricks"},
        {pos: [20, 0, 7], state: "minecraft:deepslate_bricks"},
        {pos: [20, 0, 8], state: "minecraft:deepslate_bricks"},
        {pos: [20, 0, 28], state: "minecraft:deepslate_bricks"},
        {pos: [20, 0, 29], state: "minecraft:deepslate_bricks"},
        {pos: [20, 0, 30], state: "minecraft:deepslate_bricks"},
        {pos: [20, 0, 31], state: "minecraft:deepslate_bricks"},
        {pos: [20, 0, 32], state: "minecraft:deepslate_bricks"},
        {pos: [20, 0, 33], state: "minecraft:deepslate_bricks"},
        {pos: [20, 0, 34], state: "minecraft:deepslate_bricks"},
        {pos: [20, 0, 35], state: "minecraft:deepslate_bricks"},
        {pos: [20, 0, 36], state: "minecraft:deepslate_bricks"},
        {pos: [21, 0, 0], state: "minecraft:deepslate_bricks"},
        {pos: [21, 0, 1], state: "minecraft:deepslate_bricks"},
        {pos: [21, 0, 2], state: "minecraft:deepslate_bricks"},
        {pos: [21, 0, 3], state: "minecraft:deepslate_bricks"},
        {pos: [21, 0, 4], state: "minecraft:deepslate_bricks"},
        {pos: [21, 0, 5], state: "minecraft:deepslate_bricks"},
        {pos: [21, 0, 6], state: "minecraft:deepslate_bricks"},
        {pos: [21, 0, 7], state: "minecraft:deepslate_bricks"},
        {pos: [21, 0, 8], state: "minecraft:deepslate_bricks"},
        {pos: [21, 0, 28], state: "minecraft:deepslate_bricks"},
        {pos: [21, 0, 29], state: "minecraft:deepslate_bricks"},
        {pos: [21, 0, 30], state: "minecraft:deepslate_bricks"},
        {pos: [21, 0, 31], state: "minecraft:deepslate_bricks"},
        {pos: [21, 0, 32], state: "minecraft:deepslate_bricks"},
        {pos: [21, 0, 33], state: "minecraft:deepslate_bricks"},
        {pos: [21, 0, 34], state: "minecraft:deepslate_bricks"},
        {pos: [21, 0, 35], state: "minecraft:deepslate_bricks"},
        {pos: [21, 0, 36], state: "minecraft:deepslate_bricks"},
        {pos: [5, 1, 0], state: "minecraft:deepslate_bricks"},
        {pos: [5, 1, 1], state: "minecraft:deepslate_bricks"},
        {pos: [5, 1, 2], state: "minecraft:deepslate_bricks"},
        {pos: [5, 1, 3], state: "minecraft:deepslate_bricks"},
        {pos: [5, 1, 4], state: "minecraft:deepslate_bricks"},
        {pos: [5, 1, 5], state: "minecraft:deepslate_bricks"},
        {pos: [5, 1, 6], state: "minecraft:deepslate_bricks"},
        {pos: [5, 1, 7], state: "minecraft:deepslate_bricks"},
        {pos: [5, 1, 8], state: "minecraft:deepslate_bricks"},
        {pos: [5, 1, 28], state: "minecraft:deepslate_bricks"},
        {pos: [5, 1, 29], state: "minecraft:deepslate_bricks"},
        {pos: [5, 1, 30], state: "minecraft:deepslate_bricks"},
        {pos: [5, 1, 31], state: "minecraft:deepslate_bricks"},
        {pos: [5, 1, 32], state: "minecraft:deepslate_bricks"},
        {pos: [5, 1, 33], state: "minecraft:deepslate_bricks"},
        {pos: [5, 1, 34], state: "minecraft:deepslate_bricks"},
        {pos: [5, 1, 35], state: "minecraft:deepslate_bricks"},
        {pos: [5, 1, 36], state: "minecraft:deepslate_bricks"},
        {pos: [6, 1, 0], state: "minecraft:deepslate_bricks"},
        {pos: [6, 1, 1], state: "minecraft:gravel"},
        {pos: [6, 1, 2], state: "minecraft:gravel"},
        {pos: [6, 1, 3], state: "minecraft:gravel"},
        {pos: [6, 1, 4], state: "minecraft:deepslate_bricks"},
        {pos: [6, 1, 5], state: "minecraft:deepslate_bricks"},
        {pos: [6, 1, 6], state: "minecraft:gravel"},
        {pos: [6, 1, 7], state: "minecraft:gravel"},
        {pos: [6, 1, 8], state: "minecraft:deepslate_bricks"},
        {pos: [6, 1, 28], state: "minecraft:deepslate_bricks"},
        {pos: [6, 1, 29], state: "minecraft:gravel"},
        {pos: [6, 1, 30], state: "minecraft:gravel"},
        {pos: [6, 1, 31], state: "minecraft:gravel"},
        {pos: [6, 1, 32], state: "minecraft:deepslate_bricks"},
        {pos: [6, 1, 33], state: "minecraft:deepslate_bricks"},
        {pos: [6, 1, 34], state: "minecraft:deepslate_bricks"},
        {pos: [6, 1, 35], state: "minecraft:deepslate_bricks"},
        {pos: [6, 1, 36], state: "minecraft:deepslate_bricks"},
        {pos: [7, 1, 0], state: "minecraft:deepslate_bricks"},
        {pos: [7, 1, 1], state: "minecraft:gravel"},
        {pos: [7, 1, 2], state: "minecraft:deepslate_bricks"},
        {pos: [7, 1, 3], state: "minecraft:deepslate_bricks"},
        {pos: [7, 1, 4], state: "minecraft:deepslate_bricks"},
        {pos: [7, 1, 5], state: "minecraft:deepslate_bricks"},
        {pos: [7, 1, 6], state: "minecraft:deepslate_bricks"},
        {pos: [7, 1, 7], state: "minecraft:gravel"},
        {pos: [7, 1, 8], state: "minecraft:deepslate_bricks"},
        {pos: [7, 1, 28], state: "minecraft:deepslate_bricks"},
        {pos: [7, 1, 29], state: "minecraft:gravel"},
        {pos: [7, 1, 30], state: "minecraft:deepslate_bricks"},
        {pos: [7, 1, 31], state: "minecraft:deepslate_bricks"},
        {pos: [7, 1, 32], state: "minecraft:deepslate_bricks"},
        {pos: [7, 1, 33], state: "minecraft:deepslate_bricks"},
        {pos: [7, 1, 34], state: "minecraft:deepslate_bricks"},
        {pos: [7, 1, 35], state: "minecraft:deepslate_bricks"},
        {pos: [7, 1, 36], state: "minecraft:deepslate_bricks"},
        {pos: [8, 1, 0], state: "minecraft:deepslate_bricks"},
        {pos: [8, 1, 1], state: "minecraft:gravel"},
        {pos: [8, 1, 2], state: "minecraft:deepslate_bricks"},
        {pos: [8, 1, 3], state: "minecraft:deepslate_bricks"},
        {pos: [8, 1, 4], state: "minecraft:deepslate_bricks"},
        {pos: [8, 1, 5], state: "minecraft:deepslate_bricks"},
        {pos: [8, 1, 6], state: "minecraft:deepslate_bricks"},
        {pos: [8, 1, 7], state: "minecraft:gravel"},
        {pos: [8, 1, 8], state: "minecraft:deepslate_bricks"},
        {pos: [8, 1, 28], state: "minecraft:deepslate_bricks"},
        {pos: [8, 1, 29], state: "minecraft:deepslate_bricks"},
        {pos: [8, 1, 30], state: "minecraft:deepslate_bricks"},
        {pos: [8, 1, 31], state: "minecraft:deepslate_bricks"},
        {pos: [8, 1, 32], state: "minecraft:deepslate_bricks"},
        {pos: [8, 1, 33], state: "minecraft:deepslate_bricks"},
        {pos: [8, 1, 34], state: "minecraft:deepslate_bricks"},
        {pos: [8, 1, 35], state: "minecraft:deepslate_bricks"},
        {pos: [8, 1, 36], state: "minecraft:deepslate_bricks"},
        {pos: [9, 1, 0], state: "minecraft:deepslate_bricks"},
        {pos: [9, 1, 1], state: "minecraft:deepslate_bricks"},
        {pos: [9, 1, 2], state: "minecraft:deepslate_bricks"},
        {pos: [9, 1, 3], state: "minecraft:deepslate_bricks"},
        {pos: [9, 1, 4], state: "minecraft:deepslate_bricks"},
        {pos: [9, 1, 5], state: "minecraft:deepslate_bricks"},
        {pos: [9, 1, 6], state: "minecraft:deepslate_bricks"},
        {pos: [9, 1, 7], state: "minecraft:deepslate_bricks"},
        {pos: [9, 1, 8], state: "minecraft:deepslate_bricks"},
        {pos: [9, 1, 28], state: "minecraft:deepslate_bricks"},
        {pos: [9, 1, 29], state: "minecraft:deepslate_bricks"},
        {pos: [9, 1, 30], state: "minecraft:deepslate_bricks"},
        {pos: [9, 1, 31], state: "minecraft:deepslate_bricks"},
        {pos: [9, 1, 32], state: "minecraft:deepslate_bricks"},
        {pos: [9, 1, 33], state: "minecraft:deepslate_bricks"},
        {pos: [9, 1, 34], state: "minecraft:deepslate_bricks"},
        {pos: [9, 1, 35], state: "minecraft:deepslate_bricks"},
        {pos: [9, 1, 36], state: "minecraft:deepslate_bricks"},
        {pos: [10, 1, 0], state: "minecraft:deepslate_bricks"},
        {pos: [10, 1, 1], state: "minecraft:gravel"},
        {pos: [10, 1, 2], state: "minecraft:deepslate_bricks"},
        {pos: [10, 1, 3], state: "minecraft:deepslate_bricks"},
        {pos: [10, 1, 4], state: "minecraft:deepslate_bricks"},
        {pos: [10, 1, 5], state: "minecraft:deepslate_bricks"},
        {pos: [10, 1, 6], state: "minecraft:deepslate_bricks"},
        {pos: [10, 1, 7], state: "minecraft:deepslate_bricks"},
        {pos: [10, 1, 8], state: "minecraft:deepslate_bricks"},
        {pos: [10, 1, 28], state: "minecraft:deepslate_bricks"},
        {pos: [10, 1, 29], state: "minecraft:gravel"},
        {pos: [10, 1, 30], state: "minecraft:deepslate_bricks"},
        {pos: [10, 1, 31], state: "minecraft:deepslate_bricks"},
        {pos: [10, 1, 32], state: "minecraft:deepslate_bricks"},
        {pos: [10, 1, 33], state: "minecraft:deepslate_bricks"},
        {pos: [10, 1, 34], state: "minecraft:deepslate_bricks"},
        {pos: [10, 1, 35], state: "minecraft:deepslate_bricks"},
        {pos: [10, 1, 36], state: "minecraft:deepslate_bricks"},
        {pos: [11, 1, 0], state: "minecraft:deepslate_bricks"},
        {pos: [11, 1, 1], state: "minecraft:gravel"},
        {pos: [11, 1, 2], state: "minecraft:deepslate_bricks"},
        {pos: [11, 1, 3], state: "minecraft:deepslate_bricks"},
        {pos: [11, 1, 4], state: "minecraft:deepslate_bricks"},
        {pos: [11, 1, 5], state: "minecraft:deepslate_bricks"},
        {pos: [11, 1, 6], state: "minecraft:deepslate_bricks"},
        {pos: [11, 1, 7], state: "minecraft:deepslate_bricks"},
        {pos: [11, 1, 8], state: "minecraft:deepslate_bricks"},
        {pos: [11, 1, 9], state: "minecraft:deepslate_bricks"},
        {pos: [11, 1, 10], state: "minecraft:deepslate_bricks"},
        {pos: [11, 1, 11], state: "minecraft:deepslate_bricks"},
        {pos: [11, 1, 12], state: "minecraft:deepslate_bricks"},
        {pos: [11, 1, 13], state: "minecraft:deepslate_bricks"},
        {pos: [11, 1, 23], state: "minecraft:deepslate_bricks"},
        {pos: [11, 1, 24], state: "minecraft:deepslate_bricks"},
        {pos: [11, 1, 25], state: "minecraft:deepslate_bricks"},
        {pos: [11, 1, 26], state: "minecraft:deepslate_bricks"},
        {pos: [11, 1, 27], state: "minecraft:deepslate_bricks"},
        {pos: [11, 1, 28], state: "minecraft:deepslate_bricks"},
        {pos: [11, 1, 29], state: "minecraft:gravel"},
        {pos: [11, 1, 30], state: "minecraft:deepslate_bricks"},
        {pos: [11, 1, 31], state: "minecraft:deepslate_bricks"},
        {pos: [11, 1, 32], state: "minecraft:deepslate_bricks"},
        {pos: [11, 1, 33], state: "minecraft:deepslate_bricks"},
        {pos: [11, 1, 34], state: "minecraft:deepslate_bricks"},
        {pos: [11, 1, 35], state: "minecraft:gravel"},
        {pos: [11, 1, 36], state: "minecraft:deepslate_bricks"},
        {pos: [12, 1, 0], state: "minecraft:deepslate_bricks"},
        {pos: [12, 1, 1], state: "minecraft:gravel"},
        {pos: [12, 1, 2], state: "minecraft:deepslate_bricks"},
        {pos: [12, 1, 3], state: "minecraft:deepslate_bricks"},
        {pos: [12, 1, 4], state: "minecraft:deepslate_bricks"},
        {pos: [12, 1, 5], state: "minecraft:deepslate_bricks"},
        {pos: [12, 1, 6], state: "minecraft:gravel"},
        {pos: [12, 1, 7], state: "minecraft:gravel"},
        {pos: [12, 1, 8], state: "minecraft:gravel"},
        {pos: [12, 1, 9], state: "minecraft:deepslate_bricks"},
        {pos: [12, 1, 10], state: "minecraft:deepslate_bricks"},
        {pos: [12, 1, 11], state: "minecraft:deepslate_bricks"},
        {pos: [12, 1, 12], state: "minecraft:deepslate_bricks"},
        {pos: [12, 1, 13], state: "minecraft:deepslate_bricks"},
        {pos: [12, 1, 23], state: "minecraft:deepslate_bricks"},
        {pos: [12, 1, 24], state: "minecraft:deepslate_bricks"},
        {pos: [12, 1, 25], state: "minecraft:deepslate_bricks"},
        {pos: [12, 1, 26], state: "minecraft:deepslate_bricks"},
        {pos: [12, 1, 27], state: "minecraft:gravel"},
        {pos: [12, 1, 28], state: "minecraft:gravel"},
        {pos: [12, 1, 29], state: "minecraft:gravel"},
        {pos: [12, 1, 30], state: "minecraft:gravel"},
        {pos: [12, 1, 31], state: "minecraft:gravel"},
        {pos: [12, 1, 32], state: "minecraft:gravel"},
        {pos: [12, 1, 33], state: "minecraft:deepslate_bricks"},
        {pos: [12, 1, 34], state: "minecraft:gravel"},
        {pos: [12, 1, 35], state: "minecraft:gravel"},
        {pos: [12, 1, 36], state: "minecraft:deepslate_bricks"},
        {pos: [13, 1, 0], state: "minecraft:deepslate_bricks"},
        {pos: [13, 1, 1], state: "minecraft:gravel"},
        {pos: [13, 1, 2], state: "minecraft:gravel"},
        {pos: [13, 1, 3], state: "minecraft:deepslate_bricks"},
        {pos: [13, 1, 4], state: "minecraft:deepslate_bricks"},
        {pos: [13, 1, 5], state: "minecraft:deepslate_bricks"},
        {pos: [13, 1, 6], state: "minecraft:gravel"},
        {pos: [13, 1, 7], state: "minecraft:gravel"},
        {pos: [13, 1, 8], state: "minecraft:gravel"},
        {pos: [13, 1, 9], state: "minecraft:deepslate_bricks"},
        {pos: [13, 1, 10], state: "minecraft:deepslate_bricks"},
        {pos: [13, 1, 11], state: "minecraft:deepslate_bricks"},
        {pos: [13, 1, 12], state: "minecraft:deepslate_bricks"},
        {pos: [13, 1, 13], state: "minecraft:deepslate_bricks"},
        {pos: [13, 1, 23], state: "minecraft:deepslate_bricks"},
        {pos: [13, 1, 24], state: "minecraft:deepslate_bricks"},
        {pos: [13, 1, 25], state: "minecraft:deepslate_bricks"},
        {pos: [13, 1, 26], state: "minecraft:deepslate_bricks"},
        {pos: [13, 1, 27], state: "minecraft:deepslate_bricks"},
        {pos: [13, 1, 28], state: "minecraft:gravel"},
        {pos: [13, 1, 29], state: "minecraft:gravel"},
        {pos: [13, 1, 30], state: "minecraft:gravel"},
        {pos: [13, 1, 31], state: "minecraft:deepslate_bricks"},
        {pos: [13, 1, 32], state: "minecraft:deepslate_bricks"},
        {pos: [13, 1, 33], state: "minecraft:deepslate_bricks"},
        {pos: [13, 1, 34], state: "minecraft:gravel"},
        {pos: [13, 1, 35], state: "minecraft:gravel"},
        {pos: [13, 1, 36], state: "minecraft:deepslate_bricks"},
        {pos: [14, 1, 0], state: "minecraft:deepslate_bricks"},
        {pos: [14, 1, 1], state: "minecraft:gravel"},
        {pos: [14, 1, 2], state: "minecraft:gravel"},
        {pos: [14, 1, 3], state: "minecraft:deepslate_bricks"},
        {pos: [14, 1, 4], state: "minecraft:gravel"},
        {pos: [14, 1, 5], state: "minecraft:gravel"},
        {pos: [14, 1, 6], state: "minecraft:gravel"},
        {pos: [14, 1, 7], state: "minecraft:gravel"},
        {pos: [14, 1, 8], state: "minecraft:gravel"},
        {pos: [14, 1, 9], state: "minecraft:gravel"},
        {pos: [14, 1, 10], state: "minecraft:deepslate_bricks"},
        {pos: [14, 1, 11], state: "minecraft:deepslate_bricks"},
        {pos: [14, 1, 12], state: "minecraft:deepslate_bricks"},
        {pos: [14, 1, 13], state: "minecraft:deepslate_bricks"},
        {pos: [14, 1, 23], state: "minecraft:deepslate_bricks"},
        {pos: [14, 1, 24], state: "minecraft:deepslate_bricks"},
        {pos: [14, 1, 25], state: "minecraft:deepslate_bricks"},
        {pos: [14, 1, 26], state: "minecraft:deepslate_bricks"},
        {pos: [14, 1, 27], state: "minecraft:deepslate_bricks"},
        {pos: [14, 1, 28], state: "minecraft:gravel"},
        {pos: [14, 1, 29], state: "minecraft:gravel"},
        {pos: [14, 1, 30], state: "minecraft:gravel"},
        {pos: [14, 1, 31], state: "minecraft:deepslate_bricks"},
        {pos: [14, 1, 32], state: "minecraft:deepslate_bricks"},
        {pos: [14, 1, 33], state: "minecraft:deepslate_bricks"},
        {pos: [14, 1, 34], state: "minecraft:deepslate_bricks"},
        {pos: [14, 1, 35], state: "minecraft:gravel"},
        {pos: [14, 1, 36], state: "minecraft:deepslate_bricks"},
        {pos: [15, 1, 0], state: "minecraft:deepslate_bricks"},
        {pos: [15, 1, 1], state: "minecraft:gravel"},
        {pos: [15, 1, 2], state: "minecraft:deepslate_bricks"},
        {pos: [15, 1, 3], state: "minecraft:deepslate_bricks"},
        {pos: [15, 1, 4], state: "minecraft:deepslate_bricks"},
        {pos: [15, 1, 5], state: "minecraft:deepslate_bricks"},
        {pos: [15, 1, 6], state: "minecraft:deepslate_bricks"},
        {pos: [15, 1, 7], state: "minecraft:gravel"},
        {pos: [15, 1, 8], state: "minecraft:deepslate_bricks"},
        {pos: [15, 1, 9], state: "minecraft:deepslate_bricks"},
        {pos: [15, 1, 10], state: "minecraft:deepslate_bricks"},
        {pos: [15, 1, 11], state: "minecraft:deepslate_bricks"},
        {pos: [15, 1, 12], state: "minecraft:deepslate_bricks"},
        {pos: [15, 1, 13], state: "minecraft:deepslate_bricks"},
        {pos: [15, 1, 23], state: "minecraft:deepslate_bricks"},
        {pos: [15, 1, 24], state: "minecraft:deepslate_bricks"},
        {pos: [15, 1, 25], state: "minecraft:deepslate_bricks"},
        {pos: [15, 1, 26], state: "minecraft:deepslate_bricks"},
        {pos: [15, 1, 27], state: "minecraft:deepslate_bricks"},
        {pos: [15, 1, 28], state: "minecraft:deepslate_bricks"},
        {pos: [15, 1, 29], state: "minecraft:deepslate_bricks"},
        {pos: [15, 1, 30], state: "minecraft:deepslate_bricks"},
        {pos: [15, 1, 31], state: "minecraft:deepslate_bricks"},
        {pos: [15, 1, 32], state: "minecraft:deepslate_bricks"},
        {pos: [15, 1, 33], state: "minecraft:deepslate_bricks"},
        {pos: [15, 1, 34], state: "minecraft:deepslate_bricks"},
        {pos: [15, 1, 35], state: "minecraft:gravel"},
        {pos: [15, 1, 36], state: "minecraft:deepslate_bricks"},
        {pos: [16, 1, 0], state: "minecraft:deepslate_bricks"},
        {pos: [16, 1, 1], state: "minecraft:deepslate_bricks"},
        {pos: [16, 1, 2], state: "minecraft:deepslate_bricks"},
        {pos: [16, 1, 3], state: "minecraft:deepslate_bricks"},
        {pos: [16, 1, 4], state: "minecraft:deepslate_bricks"},
        {pos: [16, 1, 5], state: "minecraft:deepslate_bricks"},
        {pos: [16, 1, 6], state: "minecraft:deepslate_bricks"},
        {pos: [16, 1, 7], state: "minecraft:gravel"},
        {pos: [16, 1, 8], state: "minecraft:deepslate_bricks"},
        {pos: [16, 1, 28], state: "minecraft:deepslate_bricks"},
        {pos: [16, 1, 29], state: "minecraft:deepslate_bricks"},
        {pos: [16, 1, 30], state: "minecraft:deepslate_bricks"},
        {pos: [16, 1, 31], state: "minecraft:deepslate_bricks"},
        {pos: [16, 1, 32], state: "minecraft:deepslate_bricks"},
        {pos: [16, 1, 33], state: "minecraft:deepslate_bricks"},
        {pos: [16, 1, 34], state: "minecraft:deepslate_bricks"},
        {pos: [16, 1, 35], state: "minecraft:gravel"},
        {pos: [16, 1, 36], state: "minecraft:deepslate_bricks"},
        {pos: [17, 1, 0], state: "minecraft:deepslate_bricks"},
        {pos: [17, 1, 1], state: "minecraft:deepslate_bricks"},
        {pos: [17, 1, 2], state: "minecraft:deepslate_bricks"},
        {pos: [17, 1, 3], state: "minecraft:deepslate_bricks"},
        {pos: [17, 1, 4], state: "minecraft:deepslate_bricks"},
        {pos: [17, 1, 5], state: "minecraft:deepslate_bricks"},
        {pos: [17, 1, 6], state: "minecraft:deepslate_bricks"},
        {pos: [17, 1, 7], state: "minecraft:deepslate_bricks"},
        {pos: [17, 1, 8], state: "minecraft:deepslate_bricks"},
        {pos: [17, 1, 28], state: "minecraft:deepslate_bricks"},
        {pos: [17, 1, 29], state: "minecraft:deepslate_bricks"},
        {pos: [17, 1, 30], state: "minecraft:deepslate_bricks"},
        {pos: [17, 1, 31], state: "minecraft:deepslate_bricks"},
        {pos: [17, 1, 32], state: "minecraft:deepslate_bricks"},
        {pos: [17, 1, 33], state: "minecraft:deepslate_bricks"},
        {pos: [17, 1, 34], state: "minecraft:deepslate_bricks"},
        {pos: [17, 1, 35], state: "minecraft:deepslate_bricks"},
        {pos: [17, 1, 36], state: "minecraft:deepslate_bricks"},
        {pos: [18, 1, 0], state: "minecraft:deepslate_bricks"},
        {pos: [18, 1, 1], state: "minecraft:deepslate_bricks"},
        {pos: [18, 1, 2], state: "minecraft:deepslate_bricks"},
        {pos: [18, 1, 3], state: "minecraft:deepslate_bricks"},
        {pos: [18, 1, 4], state: "minecraft:deepslate_bricks"},
        {pos: [18, 1, 5], state: "minecraft:deepslate_bricks"},
        {pos: [18, 1, 6], state: "minecraft:deepslate_bricks"},
        {pos: [18, 1, 7], state: "minecraft:deepslate_bricks"},
        {pos: [18, 1, 8], state: "minecraft:deepslate_bricks"},
        {pos: [18, 1, 28], state: "minecraft:deepslate_bricks"},
        {pos: [18, 1, 29], state: "minecraft:gravel"},
        {pos: [18, 1, 30], state: "minecraft:deepslate_bricks"},
        {pos: [18, 1, 31], state: "minecraft:deepslate_bricks"},
        {pos: [18, 1, 32], state: "minecraft:deepslate_bricks"},
        {pos: [18, 1, 33], state: "minecraft:deepslate_bricks"},
        {pos: [18, 1, 34], state: "minecraft:deepslate_bricks"},
        {pos: [18, 1, 35], state: "minecraft:gravel"},
        {pos: [18, 1, 36], state: "minecraft:deepslate_bricks"},
        {pos: [19, 1, 0], state: "minecraft:deepslate_bricks"},
        {pos: [19, 1, 1], state: "minecraft:deepslate_bricks"},
        {pos: [19, 1, 2], state: "minecraft:deepslate_bricks"},
        {pos: [19, 1, 3], state: "minecraft:deepslate_bricks"},
        {pos: [19, 1, 4], state: "minecraft:deepslate_bricks"},
        {pos: [19, 1, 5], state: "minecraft:deepslate_bricks"},
        {pos: [19, 1, 6], state: "minecraft:deepslate_bricks"},
        {pos: [19, 1, 7], state: "minecraft:gravel"},
        {pos: [19, 1, 8], state: "minecraft:deepslate_bricks"},
        {pos: [19, 1, 28], state: "minecraft:deepslate_bricks"},
        {pos: [19, 1, 29], state: "minecraft:gravel"},
        {pos: [19, 1, 30], state: "minecraft:deepslate_bricks"},
        {pos: [19, 1, 31], state: "minecraft:deepslate_bricks"},
        {pos: [19, 1, 32], state: "minecraft:deepslate_bricks"},
        {pos: [19, 1, 33], state: "minecraft:deepslate_bricks"},
        {pos: [19, 1, 34], state: "minecraft:deepslate_bricks"},
        {pos: [19, 1, 35], state: "minecraft:gravel"},
        {pos: [19, 1, 36], state: "minecraft:deepslate_bricks"},
        {pos: [20, 1, 0], state: "minecraft:deepslate_bricks"},
        {pos: [20, 1, 1], state: "minecraft:deepslate_bricks"},
        {pos: [20, 1, 2], state: "minecraft:deepslate_bricks"},
        {pos: [20, 1, 3], state: "minecraft:deepslate_bricks"},
        {pos: [20, 1, 4], state: "minecraft:deepslate_bricks"},
        {pos: [20, 1, 5], state: "minecraft:gravel"},
        {pos: [20, 1, 6], state: "minecraft:gravel"},
        {pos: [20, 1, 7], state: "minecraft:gravel"},
        {pos: [20, 1, 8], state: "minecraft:deepslate_bricks"},
        {pos: [20, 1, 28], state: "minecraft:deepslate_bricks"},
        {pos: [20, 1, 29], state: "minecraft:gravel"},
        {pos: [20, 1, 30], state: "minecraft:gravel"},
        {pos: [20, 1, 31], state: "minecraft:deepslate_bricks"},
        {pos: [20, 1, 32], state: "minecraft:deepslate_bricks"},
        {pos: [20, 1, 33], state: "minecraft:gravel"},
        {pos: [20, 1, 34], state: "minecraft:gravel"},
        {pos: [20, 1, 35], state: "minecraft:gravel"},
        {pos: [20, 1, 36], state: "minecraft:deepslate_bricks"},
        {pos: [21, 1, 0], state: "minecraft:deepslate_bricks"},
        {pos: [21, 1, 1], state: "minecraft:deepslate_bricks"},
        {pos: [21, 1, 2], state: "minecraft:deepslate_bricks"},
        {pos: [21, 1, 3], state: "minecraft:deepslate_bricks"},
        {pos: [21, 1, 4], state: "minecraft:deepslate_bricks"},
        {pos: [21, 1, 5], state: "minecraft:deepslate_bricks"},
        {pos: [21, 1, 6], state: "minecraft:deepslate_bricks"},
        {pos: [21, 1, 7], state: "minecraft:deepslate_bricks"},
        {pos: [21, 1, 8], state: "minecraft:deepslate_bricks"},
        {pos: [21, 1, 28], state: "minecraft:deepslate_bricks"},
        {pos: [21, 1, 29], state: "minecraft:deepslate_bricks"},
        {pos: [21, 1, 30], state: "minecraft:deepslate_bricks"},
        {pos: [21, 1, 31], state: "minecraft:deepslate_bricks"},
        {pos: [21, 1, 32], state: "minecraft:deepslate_bricks"},
        {pos: [21, 1, 33], state: "minecraft:deepslate_bricks"},
        {pos: [21, 1, 34], state: "minecraft:deepslate_bricks"},
        {pos: [21, 1, 35], state: "minecraft:deepslate_bricks"},
        {pos: [21, 1, 36], state: "minecraft:deepslate_bricks"},
        {pos: [5, 2, 0], state: "minecraft:deepslate_bricks"},
        {pos: [5, 2, 1], state: "minecraft:deepslate_bricks"},
        {pos: [5, 2, 2], state: "minecraft:deepslate_bricks"},
        {pos: [5, 2, 3], state: "minecraft:deepslate_bricks"},
        {pos: [5, 2, 4], state: "minecraft:deepslate_bricks"},
        {pos: [5, 2, 5], state: "minecraft:deepslate_bricks"},
        {pos: [5, 2, 6], state: "minecraft:deepslate_bricks"},
        {pos: [5, 2, 7], state: "minecraft:deepslate_bricks"},
        {pos: [5, 2, 8], state: "minecraft:deepslate_bricks"},
        {pos: [5, 2, 28], state: "minecraft:deepslate_bricks"},
        {pos: [5, 2, 29], state: "minecraft:deepslate_bricks"},
        {pos: [5, 2, 30], state: "minecraft:deepslate_bricks"},
        {pos: [5, 2, 31], state: "minecraft:deepslate_bricks"},
        {pos: [5, 2, 32], state: "minecraft:deepslate_bricks"},
        {pos: [5, 2, 33], state: "minecraft:deepslate_bricks"},
        {pos: [5, 2, 34], state: "minecraft:deepslate_bricks"},
        {pos: [5, 2, 35], state: "minecraft:deepslate_bricks"},
        {pos: [5, 2, 36], state: "minecraft:deepslate_bricks"},
        {pos: [6, 2, 0], state: "minecraft:deepslate_bricks"},
        {pos: [6, 2, 1], state: "minecraft:candle{candles:4,lit:false,waterlogged:false}"},
        {pos: [6, 2, 2], state: "minecraft:candle{candles:4,lit:false,waterlogged:false}"},
        {pos: [6, 2, 3], state: "minecraft:candle{candles:4,lit:false,waterlogged:false}"},
        {pos: [6, 2, 4], state: "minecraft:candle{candles:4,lit:false,waterlogged:false}"},
        {pos: [6, 2, 5], state: "minecraft:candle{candles:4,lit:false,waterlogged:false}"},
        {pos: [6, 2, 6], state: "minecraft:skeleton_skull{powered:false,rotation:4}", nbt: {id: "minecraft:skull"}},
        {pos: [6, 2, 7], state: "minecraft:decorated_pot{cracked:false,facing:west,waterlogged:false}", nbt: {id: "minecraft:decorated_pot"}},
        {pos: [6, 2, 8], state: "minecraft:deepslate_bricks"},
        {pos: [6, 2, 28], state: "minecraft:deepslate_bricks"},
        {pos: [6, 2, 29], state: "minecraft:decorated_pot{cracked:false,facing:north,waterlogged:false}", nbt: {id: "minecraft:decorated_pot"}},
        {pos: [6, 2, 30], state: "minecraft:candle{candles:4,lit:false,waterlogged:false}"},
        {pos: [6, 2, 31], state: "minecraft:candle{candles:4,lit:false,waterlogged:false}"},
        {pos: [6, 2, 32], state: "minecraft:candle{candles:4,lit:false,waterlogged:false}"},
        {pos: [6, 2, 33], state: "minecraft:candle{candles:4,lit:false,waterlogged:false}"},
        {pos: [6, 2, 34], state: "minecraft:candle{candles:4,lit:false,waterlogged:false}"},
        {pos: [6, 2, 35], state: "minecraft:candle{candles:4,lit:false,waterlogged:false}"},
        {pos: [6, 2, 36], state: "minecraft:deepslate_bricks"},
        {pos: [7, 2, 0], state: "minecraft:deepslate_bricks"},
        {pos: [7, 2, 1], state: "minecraft:skeleton_skull{powered:false,rotation:4}", nbt: {id: "minecraft:skull"}},
        {pos: [7, 2, 2], state: "minecraft:deepslate_bricks"},
        {pos: [7, 2, 3], state: "minecraft:deepslate_bricks"},
        {pos: [7, 2, 4], state: "minecraft:deepslate_bricks"},
        {pos: [7, 2, 5], state: "minecraft:deepslate_bricks"},
        {pos: [7, 2, 6], state: "minecraft:deepslate_bricks"},
        {pos: [7, 2, 7], state: "minecraft:candle{candles:4,lit:false,waterlogged:false}"},
        {pos: [7, 2, 8], state: "minecraft:deepslate_bricks"},
        {pos: [7, 2, 28], state: "minecraft:deepslate_bricks"},
        {pos: [7, 2, 29], state: "minecraft:candle{candles:4,lit:false,waterlogged:false}"},
        {pos: [7, 2, 30], state: "minecraft:deepslate_bricks"},
        {pos: [7, 2, 31], state: "minecraft:deepslate_bricks"},
        {pos: [7, 2, 32], state: "minecraft:deepslate_bricks"},
        {pos: [7, 2, 33], state: "minecraft:deepslate_bricks"},
        {pos: [7, 2, 34], state: "minecraft:deepslate_bricks"},
        {pos: [7, 2, 35], state: "minecraft:candle{candles:4,lit:false,waterlogged:false}"},
        {pos: [7, 2, 36], state: "minecraft:deepslate_bricks"},
        {pos: [8, 2, 0], state: "minecraft:deepslate_bricks"},
        {pos: [8, 2, 1], state: "minecraft:candle{candles:4,lit:false,waterlogged:false}"},
        {pos: [8, 2, 2], state: "minecraft:deepslate_bricks"},
        {pos: [8, 2, 3], state: "minecraft:gravel"},
        {pos: [8, 2, 4], state: "minecraft:gravel"},
        {pos: [8, 2, 5], state: "minecraft:gravel"},
        {pos: [8, 2, 6], state: "minecraft:deepslate_bricks"},
        {pos: [8, 2, 7], state: "minecraft:candle{candles:4,lit:false,waterlogged:false}"},
        {pos: [8, 2, 8], state: "minecraft:deepslate_bricks"},
        {pos: [8, 2, 28], state: "minecraft:deepslate_bricks"},
        {pos: [8, 2, 29], state: "minecraft:candle{candles:4,lit:false,waterlogged:false}"},
        {pos: [8, 2, 30], state: "minecraft:deepslate_bricks"},
        {pos: [8, 2, 31], state: "minecraft:gravel"},
        {pos: [8, 2, 32], state: "minecraft:gravel"},
        {pos: [8, 2, 33], state: "minecraft:gravel"},
        {pos: [8, 2, 34], state: "minecraft:deepslate_bricks"},
        {pos: [8, 2, 35], state: "minecraft:candle{candles:4,lit:false,waterlogged:false}"},
        {pos: [8, 2, 36], state: "minecraft:deepslate_bricks"},
        {pos: [9, 2, 0], state: "minecraft:deepslate_bricks"},
        {pos: [9, 2, 1], state: "minecraft:candle{candles:4,lit:false,waterlogged:false}"},
        {pos: [9, 2, 2], state: "minecraft:deepslate_bricks"},
        {pos: [9, 2, 3], state: "minecraft:gravel"},
        {pos: [9, 2, 4], state: "minecraft:gravel"},
        {pos: [9, 2, 5], state: "minecraft:gravel"},
        {pos: [9, 2, 6], state: "minecraft:deepslate_bricks"},
        {pos: [9, 2, 7], state: "minecraft:candle{candles:4,lit:false,waterlogged:false}"},
        {pos: [9, 2, 8], state: "minecraft:deepslate_bricks"},
        {pos: [9, 2, 28], state: "minecraft:deepslate_bricks"},
        {pos: [9, 2, 29], state: "minecraft:candle{candles:4,lit:false,waterlogged:false}"},
        {pos: [9, 2, 30], state: "minecraft:deepslate_bricks"},
        {pos: [9, 2, 31], state: "minecraft:gravel"},
        {pos: [9, 2, 32], state: "minecraft:gravel"},
        {pos: [9, 2, 33], state: "minecraft:gravel"},
        {pos: [9, 2, 34], state: "minecraft:deepslate_bricks"},
        {pos: [9, 2, 35], state: "minecraft:skeleton_skull{powered:false,rotation:4}", nbt: {id: "minecraft:skull"}},
        {pos: [9, 2, 36], state: "minecraft:deepslate_bricks"},
        {pos: [10, 2, 0], state: "minecraft:deepslate_bricks"},
        {pos: [10, 2, 1], state: "minecraft:candle{candles:4,lit:false,waterlogged:false}"},
        {pos: [10, 2, 2], state: "minecraft:deepslate_bricks"},
        {pos: [10, 2, 3], state: "minecraft:gravel"},
        {pos: [10, 2, 4], state: "minecraft:gravel"},
        {pos: [10, 2, 5], state: "minecraft:gravel"},
        {pos: [10, 2, 6], state: "minecraft:deepslate_bricks"},
        {pos: [10, 2, 7], state: "minecraft:candle{candles:4,lit:false,waterlogged:false}"},
        {pos: [10, 2, 8], state: "minecraft:deepslate_bricks"},
        {pos: [10, 2, 28], state: "minecraft:deepslate_bricks"},
        {pos: [10, 2, 29], state: "minecraft:skeleton_skull{powered:false,rotation:4}", nbt: {id: "minecraft:skull"}},
        {pos: [10, 2, 30], state: "minecraft:deepslate_bricks"},
        {pos: [10, 2, 31], state: "minecraft:gravel"},
        {pos: [10, 2, 32], state: "minecraft:gravel"},
        {pos: [10, 2, 33], state: "minecraft:gravel"},
        {pos: [10, 2, 34], state: "minecraft:deepslate_bricks"},
        {pos: [10, 2, 35], state: "minecraft:candle{candles:4,lit:false,waterlogged:false}"},
        {pos: [10, 2, 36], state: "minecraft:deepslate_bricks"},
        {pos: [11, 2, 0], state: "minecraft:deepslate_bricks"},
        {pos: [11, 2, 1], state: "minecraft:candle{candles:4,lit:false,waterlogged:false}"},
        {pos: [11, 2, 2], state: "minecraft:deepslate_bricks"},
        {pos: [11, 2, 3], state: "minecraft:deepslate_bricks"},
        {pos: [11, 2, 4], state: "minecraft:deepslate_bricks"},
        {pos: [11, 2, 5], state: "minecraft:deepslate_bricks"},
        {pos: [11, 2, 6], state: "minecraft:deepslate_bricks"},
        {pos: [11, 2, 7], state: "minecraft:candle{candles:4,lit:false,waterlogged:false}"},
        {pos: [11, 2, 8], state: "minecraft:deepslate_bricks"},
        {pos: [11, 2, 9], state: "minecraft:deepslate_bricks"},
        {pos: [11, 2, 10], state: "minecraft:deepslate_bricks"},
        {pos: [11, 2, 11], state: "minecraft:deepslate_bricks"},
        {pos: [11, 2, 12], state: "minecraft:deepslate_bricks"},
        {pos: [11, 2, 13], state: "minecraft:deepslate_bricks"},
        {pos: [11, 2, 23], state: "minecraft:deepslate_bricks"},
        {pos: [11, 2, 24], state: "minecraft:deepslate_bricks"},
        {pos: [11, 2, 25], state: "minecraft:deepslate_bricks"},
        {pos: [11, 2, 26], state: "minecraft:deepslate_bricks"},
        {pos: [11, 2, 27], state: "minecraft:deepslate_bricks"},
        {pos: [11, 2, 28], state: "minecraft:deepslate_bricks"},
        {pos: [11, 2, 29], state: "minecraft:candle{candles:4,lit:false,waterlogged:false}"},
        {pos: [11, 2, 30], state: "minecraft:deepslate_bricks"},
        {pos: [11, 2, 31], state: "minecraft:deepslate_bricks"},
        {pos: [11, 2, 32], state: "minecraft:deepslate_bricks"},
        {pos: [11, 2, 33], state: "minecraft:deepslate_bricks"},
        {pos: [11, 2, 34], state: "minecraft:deepslate_bricks"},
        {pos: [11, 2, 35], state: "minecraft:candle{candles:4,lit:false,waterlogged:false}"},
        {pos: [11, 2, 36], state: "minecraft:deepslate_bricks"},
        {pos: [12, 2, 0], state: "minecraft:deepslate_bricks"},
        {pos: [12, 2, 1], state: "minecraft:candle{candles:4,lit:false,waterlogged:false}"},
        {pos: [12, 2, 2], state: "minecraft:decorated_pot{cracked:false,facing:west,waterlogged:false}", nbt: {id: "minecraft:decorated_pot"}},
        {pos: [12, 2, 3], state: "minecraft:cave_air"},
        {pos: [12, 2, 4], state: "minecraft:cave_air"},
        {pos: [12, 2, 5], state: "minecraft:cave_air"},
        {pos: [12, 2, 6], state: "minecraft:cave_air"},
        {pos: [12, 2, 7], state: "minecraft:cave_air"},
        {pos: [12, 2, 8], state: "minecraft:skeleton_skull{powered:false,rotation:4}", nbt: {id: "minecraft:skull"}},
        {pos: [12, 2, 9], state: "minecraft:candle{candles:4,lit:false,waterlogged:false}"},
        {pos: [12, 2, 10], state: "minecraft:candle{candles:4,lit:false,waterlogged:false}"},
        {pos: [12, 2, 11], state: "minecraft:deepslate_brick_stairs{facing:south,half:bottom,shape:straight,waterlogged:false}"},
        {pos: [12, 2, 12], state: "minecraft:deepslate_bricks"},
        {pos: [12, 2, 13], state: "minecraft:deepslate_bricks"},
        {pos: [12, 2, 23], state: "minecraft:deepslate_bricks"},
        {pos: [12, 2, 24], state: "minecraft:deepslate_bricks"},
        {pos: [12, 2, 25], state: "minecraft:deepslate_brick_stairs{facing:north,half:bottom,shape:straight,waterlogged:false}"},
        {pos: [12, 2, 26], state: "minecraft:skeleton_skull{powered:false,rotation:4}", nbt: {id: "minecraft:skull"}},
        {pos: [12, 2, 27], state: "minecraft:candle{candles:4,lit:false,waterlogged:false}"},
        {pos: [12, 2, 28], state: "minecraft:candle{candles:4,lit:false,waterlogged:false}"},
        {pos: [12, 2, 29], state: "minecraft:cave_air"},
        {pos: [12, 2, 30], state: "minecraft:candle{candles:4,lit:false,waterlogged:false}"},
        {pos: [12, 2, 31], state: "minecraft:candle{candles:4,lit:false,waterlogged:false}"},
        {pos: [12, 2, 32], state: "minecraft:candle{candles:4,lit:false,waterlogged:false}"},
        {pos: [12, 2, 33], state: "minecraft:candle{candles:4,lit:false,waterlogged:false}"},
        {pos: [12, 2, 34], state: "minecraft:candle{candles:4,lit:false,waterlogged:false}"},
        {pos: [12, 2, 35], state: "minecraft:candle{candles:4,lit:false,waterlogged:false}"},
        {pos: [12, 2, 36], state: "minecraft:deepslate_bricks"},
        {pos: [13, 2, 0], state: "minecraft:deepslate_bricks"},
        {pos: [13, 2, 1], state: "minecraft:candle{candles:4,lit:false,waterlogged:false}"},
        {pos: [13, 2, 2], state: "minecraft:cave_air"},
        {pos: [13, 2, 3], state: "minecraft:cave_air"},
        {pos: [13, 2, 4], state: "minecraft:cave_air"},
        {pos: [13, 2, 5], state: "minecraft:cave_air"},
        {pos: [13, 2, 6], state: "minecraft:cave_air"},
        {pos: [13, 2, 7], state: "minecraft:cave_air"},
        {pos: [13, 2, 8], state: "minecraft:cave_air"},
        {pos: [13, 2, 9], state: "minecraft:cave_air"},
        {pos: [13, 2, 10], state: "minecraft:cave_air"},
        {pos: [13, 2, 11], state: "minecraft:deepslate_brick_stairs{facing:south,half:bottom,shape:straight,waterlogged:false}"},
        {pos: [13, 2, 12], state: "minecraft:deepslate_bricks"},
        {pos: [13, 2, 13], state: "minecraft:deepslate_bricks"},
        {pos: [13, 2, 23], state: "minecraft:deepslate_bricks"},
        {pos: [13, 2, 24], state: "minecraft:deepslate_bricks"},
        {pos: [13, 2, 25], state: "minecraft:deepslate_brick_stairs{facing:north,half:bottom,shape:straight,waterlogged:false}"},
        {pos: [13, 2, 26], state: "minecraft:cave_air"},
        {pos: [13, 2, 27], state: "minecraft:cave_air"},
        {pos: [13, 2, 28], state: "minecraft:cave_air"},
        {pos: [13, 2, 29], state: "minecraft:cave_air"},
        {pos: [13, 2, 30], state: "minecraft:cave_air"},
        {pos: [13, 2, 31], state: "minecraft:cave_air"},
        {pos: [13, 2, 32], state: "minecraft:cave_air"},
        {pos: [13, 2, 33], state: "minecraft:cave_air"},
        {pos: [13, 2, 34], state: "minecraft:cave_air"},
        {pos: [13, 2, 35], state: "minecraft:candle{candles:4,lit:false,waterlogged:false}"},
        {pos: [13, 2, 36], state: "minecraft:deepslate_bricks"},
        {pos: [14, 2, 0], state: "minecraft:deepslate_bricks"},
        {pos: [14, 2, 1], state: "minecraft:candle{candles:4,lit:false,waterlogged:false}"},
        {pos: [14, 2, 2], state: "minecraft:candle{candles:4,lit:false,waterlogged:false}"},
        {pos: [14, 2, 3], state: "minecraft:candle{candles:4,lit:false,waterlogged:false}"},
        {pos: [14, 2, 4], state: "minecraft:candle{candles:4,lit:false,waterlogged:false}"},
        {pos: [14, 2, 5], state: "minecraft:skeleton_skull{powered:false,rotation:12}", nbt: {id: "minecraft:skull"}},
        {pos: [14, 2, 6], state: "minecraft:candle{candles:4,lit:false,waterlogged:false}"},
        {pos: [14, 2, 7], state: "minecraft:cave_air"},
        {pos: [14, 2, 8], state: "minecraft:candle{candles:4,lit:false,waterlogged:false}"},
        {pos: [14, 2, 9], state: "minecraft:candle{candles:4,lit:false,waterlogged:false}"},
        {pos: [14, 2, 10], state: "minecraft:candle{candles:4,lit:false,waterlogged:false}"},
        {pos: [14, 2, 11], state: "minecraft:deepslate_brick_stairs{facing:south,half:bottom,shape:straight,waterlogged:false}"},
        {pos: [14, 2, 12], state: "minecraft:deepslate_bricks"},
        {pos: [14, 2, 13], state: "minecraft:deepslate_bricks"},
        {pos: [14, 2, 23], state: "minecraft:deepslate_bricks"},
        {pos: [14, 2, 24], state: "minecraft:deepslate_bricks"},
        {pos: [14, 2, 25], state: "minecraft:deepslate_brick_stairs{facing:north,half:bottom,shape:straight,waterlogged:false}"},
        {pos: [14, 2, 26], state: "minecraft:candle{candles:4,lit:false,waterlogged:false}"},
        {pos: [14, 2, 27], state: "minecraft:candle{candles:4,lit:false,waterlogged:false}"},
        {pos: [14, 2, 28], state: "minecraft:candle{candles:4,lit:false,waterlogged:false}"},
        {pos: [14, 2, 29], state: "minecraft:cave_air"},
        {pos: [14, 2, 30], state: "minecraft:candle{candles:4,lit:false,waterlogged:false}"},
        {pos: [14, 2, 31], state: "minecraft:candle{candles:4,lit:false,waterlogged:false}"},
        {pos: [14, 2, 32], state: "minecraft:candle{candles:4,lit:false,waterlogged:false}"},
        {pos: [14, 2, 33], state: "minecraft:candle{candles:4,lit:false,waterlogged:false}"},
        {pos: [14, 2, 34], state: "minecraft:decorated_pot{cracked:false,facing:east,waterlogged:false}", nbt: {id: "minecraft:decorated_pot"}},
        {pos: [14, 2, 35], state: "minecraft:candle{candles:4,lit:false,waterlogged:false}"},
        {pos: [14, 2, 36], state: "minecraft:deepslate_bricks"},
        {pos: [15, 2, 0], state: "minecraft:deepslate_bricks"},
        {pos: [15, 2, 1], state: "minecraft:skeleton_skull{powered:false,rotation:8}", nbt: {id: "minecraft:skull"}},
        {pos: [15, 2, 2], state: "minecraft:deepslate_bricks"},
        {pos: [15, 2, 3], state: "minecraft:deepslate_bricks"},
        {pos: [15, 2, 4], state: "minecraft:deepslate_bricks"},
        {pos: [15, 2, 5], state: "minecraft:deepslate_bricks"},
        {pos: [15, 2, 6], state: "minecraft:deepslate_bricks"},
        {pos: [15, 2, 7], state: "minecraft:candle{candles:4,lit:false,waterlogged:false}"},
        {pos: [15, 2, 8], state: "minecraft:deepslate_bricks"},
        {pos: [15, 2, 9], state: "minecraft:deepslate_bricks"},
        {pos: [15, 2, 10], state: "minecraft:deepslate_bricks"},
        {pos: [15, 2, 11], state: "minecraft:deepslate_bricks"},
        {pos: [15, 2, 12], state: "minecraft:deepslate_bricks"},
        {pos: [15, 2, 13], state: "minecraft:deepslate_bricks"},
        {pos: [15, 2, 23], state: "minecraft:deepslate_bricks"},
        {pos: [15, 2, 24], state: "minecraft:deepslate_bricks"},
        {pos: [15, 2, 25], state: "minecraft:deepslate_bricks"},
        {pos: [15, 2, 26], state: "minecraft:deepslate_bricks"},
        {pos: [15, 2, 27], state: "minecraft:deepslate_bricks"},
        {pos: [15, 2, 28], state: "minecraft:deepslate_bricks"},
        {pos: [15, 2, 29], state: "minecraft:candle{candles:4,lit:false,waterlogged:false}"},
        {pos: [15, 2, 30], state: "minecraft:deepslate_bricks"},
        {pos: [15, 2, 31], state: "minecraft:deepslate_bricks"},
        {pos: [15, 2, 32], state: "minecraft:deepslate_bricks"},
        {pos: [15, 2, 33], state: "minecraft:deepslate_bricks"},
        {pos: [15, 2, 34], state: "minecraft:deepslate_bricks"},
        {pos: [15, 2, 35], state: "minecraft:candle{candles:4,lit:false,waterlogged:false}"},
        {pos: [15, 2, 36], state: "minecraft:deepslate_bricks"},
        {pos: [16, 2, 0], state: "minecraft:deepslate_bricks"},
        {pos: [16, 2, 1], state: "minecraft:candle{candles:4,lit:false,waterlogged:false}"},
        {pos: [16, 2, 2], state: "minecraft:deepslate_bricks"},
        {pos: [16, 2, 3], state: "minecraft:gravel"},
        {pos: [16, 2, 4], state: "minecraft:gravel"},
        {pos: [16, 2, 5], state: "minecraft:gravel"},
        {pos: [16, 2, 6], state: "minecraft:deepslate_bricks"},
        {pos: [16, 2, 7], state: "minecraft:candle{candles:4,lit:false,waterlogged:false}"},
        {pos: [16, 2, 8], state: "minecraft:deepslate_bricks"},
        {pos: [16, 2, 28], state: "minecraft:deepslate_bricks"},
        {pos: [16, 2, 29], state: "minecraft:candle{candles:4,lit:false,waterlogged:false}"},
        {pos: [16, 2, 30], state: "minecraft:deepslate_bricks"},
        {pos: [16, 2, 31], state: "minecraft:gravel"},
        {pos: [16, 2, 32], state: "minecraft:gravel"},
        {pos: [16, 2, 33], state: "minecraft:gravel"},
        {pos: [16, 2, 34], state: "minecraft:deepslate_bricks"},
        {pos: [16, 2, 35], state: "minecraft:candle{candles:4,lit:false,waterlogged:false}"},
        {pos: [16, 2, 36], state: "minecraft:deepslate_bricks"},
        {pos: [17, 2, 0], state: "minecraft:deepslate_bricks"},
        {pos: [17, 2, 1], state: "minecraft:candle{candles:4,lit:false,waterlogged:false}"},
        {pos: [17, 2, 2], state: "minecraft:deepslate_bricks"},
        {pos: [17, 2, 3], state: "minecraft:gravel"},
        {pos: [17, 2, 4], state: "minecraft:gravel"},
        {pos: [17, 2, 5], state: "minecraft:gravel"},
        {pos: [17, 2, 6], state: "minecraft:deepslate_bricks"},
        {pos: [17, 2, 7], state: "minecraft:candle{candles:4,lit:false,waterlogged:false}"},
        {pos: [17, 2, 8], state: "minecraft:deepslate_bricks"},
        {pos: [17, 2, 28], state: "minecraft:deepslate_bricks"},
        {pos: [17, 2, 29], state: "minecraft:candle{candles:4,lit:false,waterlogged:false}"},
        {pos: [17, 2, 30], state: "minecraft:deepslate_bricks"},
        {pos: [17, 2, 31], state: "minecraft:gravel"},
        {pos: [17, 2, 32], state: "minecraft:gravel"},
        {pos: [17, 2, 33], state: "minecraft:gravel"},
        {pos: [17, 2, 34], state: "minecraft:deepslate_bricks"},
        {pos: [17, 2, 35], state: "minecraft:candle{candles:4,lit:false,waterlogged:false}"},
        {pos: [17, 2, 36], state: "minecraft:deepslate_bricks"},
        {pos: [18, 2, 0], state: "minecraft:deepslate_bricks"},
        {pos: [18, 2, 1], state: "minecraft:candle{candles:4,lit:false,waterlogged:false}"},
        {pos: [18, 2, 2], state: "minecraft:deepslate_bricks"},
        {pos: [18, 2, 3], state: "minecraft:gravel"},
        {pos: [18, 2, 4], state: "minecraft:gravel"},
        {pos: [18, 2, 5], state: "minecraft:gravel"},
        {pos: [18, 2, 6], state: "minecraft:deepslate_bricks"},
        {pos: [18, 2, 7], state: "minecraft:candle{candles:4,lit:false,waterlogged:false}"},
        {pos: [18, 2, 8], state: "minecraft:deepslate_bricks"},
        {pos: [18, 2, 28], state: "minecraft:deepslate_bricks"},
        {pos: [18, 2, 29], state: "minecraft:candle{candles:4,lit:false,waterlogged:false}"},
        {pos: [18, 2, 30], state: "minecraft:deepslate_bricks"},
        {pos: [18, 2, 31], state: "minecraft:gravel"},
        {pos: [18, 2, 32], state: "minecraft:gravel"},
        {pos: [18, 2, 33], state: "minecraft:gravel"},
        {pos: [18, 2, 34], state: "minecraft:deepslate_bricks"},
        {pos: [18, 2, 35], state: "minecraft:candle{candles:4,lit:false,waterlogged:false}"},
        {pos: [18, 2, 36], state: "minecraft:deepslate_bricks"},
        {pos: [19, 2, 0], state: "minecraft:deepslate_bricks"},
        {pos: [19, 2, 1], state: "minecraft:candle{candles:4,lit:false,waterlogged:false}"},
        {pos: [19, 2, 2], state: "minecraft:deepslate_bricks"},
        {pos: [19, 2, 3], state: "minecraft:deepslate_bricks"},
        {pos: [19, 2, 4], state: "minecraft:deepslate_bricks"},
        {pos: [19, 2, 5], state: "minecraft:deepslate_bricks"},
        {pos: [19, 2, 6], state: "minecraft:deepslate_bricks"},
        {pos: [19, 2, 7], state: "minecraft:candle{candles:4,lit:false,waterlogged:false}"},
        {pos: [19, 2, 8], state: "minecraft:deepslate_bricks"},
        {pos: [19, 2, 28], state: "minecraft:deepslate_bricks"},
        {pos: [19, 2, 29], state: "minecraft:candle{candles:4,lit:false,waterlogged:false}"},
        {pos: [19, 2, 30], state: "minecraft:deepslate_bricks"},
        {pos: [19, 2, 31], state: "minecraft:deepslate_bricks"},
        {pos: [19, 2, 32], state: "minecraft:deepslate_bricks"},
        {pos: [19, 2, 33], state: "minecraft:deepslate_bricks"},
        {pos: [19, 2, 34], state: "minecraft:deepslate_bricks"},
        {pos: [19, 2, 35], state: "minecraft:skeleton_skull{powered:false,rotation:12}", nbt: {id: "minecraft:skull"}},
        {pos: [19, 2, 36], state: "minecraft:deepslate_bricks"},
        {pos: [20, 2, 0], state: "minecraft:deepslate_bricks"},
        {pos: [20, 2, 1], state: "minecraft:candle{candles:4,lit:false,waterlogged:false}"},
        {pos: [20, 2, 2], state: "minecraft:candle{candles:4,lit:false,waterlogged:false}"},
        {pos: [20, 2, 3], state: "minecraft:candle{candles:4,lit:false,waterlogged:false}"},
        {pos: [20, 2, 4], state: "minecraft:candle{candles:4,lit:false,waterlogged:false}"},
        {pos: [20, 2, 5], state: "minecraft:candle{candles:4,lit:false,waterlogged:false}"},
        {pos: [20, 2, 6], state: "minecraft:candle{candles:4,lit:false,waterlogged:false}"},
        {pos: [20, 2, 7], state: "minecraft:decorated_pot{cracked:false,facing:south,waterlogged:false}", nbt: {id: "minecraft:decorated_pot"}},
        {pos: [20, 2, 8], state: "minecraft:deepslate_bricks"},
        {pos: [20, 2, 28], state: "minecraft:deepslate_bricks"},
        {pos: [20, 2, 29], state: "minecraft:decorated_pot{cracked:false,facing:east,waterlogged:false}", nbt: {id: "minecraft:decorated_pot"}},
        {pos: [20, 2, 30], state: "minecraft:candle{candles:4,lit:false,waterlogged:false}"},
        {pos: [20, 2, 31], state: "minecraft:candle{candles:4,lit:false,waterlogged:false}"},
        {pos: [20, 2, 32], state: "minecraft:candle{candles:4,lit:false,waterlogged:false}"},
        {pos: [20, 2, 33], state: "minecraft:candle{candles:4,lit:false,waterlogged:false}"},
        {pos: [20, 2, 34], state: "minecraft:candle{candles:4,lit:false,waterlogged:false}"},
        {pos: [20, 2, 35], state: "minecraft:candle{candles:4,lit:false,waterlogged:false}"},
        {pos: [20, 2, 36], state: "minecraft:deepslate_bricks"},
        {pos: [21, 2, 0], state: "minecraft:deepslate_bricks"},
        {pos: [21, 2, 1], state: "minecraft:deepslate_bricks"},
        {pos: [21, 2, 2], state: "minecraft:deepslate_bricks"},
        {pos: [21, 2, 3], state: "minecraft:deepslate_bricks"},
        {pos: [21, 2, 4], state: "minecraft:deepslate_bricks"},
        {pos: [21, 2, 5], state: "minecraft:deepslate_bricks"},
        {pos: [21, 2, 6], state: "minecraft:deepslate_bricks"},
        {pos: [21, 2, 7], state: "minecraft:deepslate_bricks"},
        {pos: [21, 2, 8], state: "minecraft:deepslate_bricks"},
        {pos: [21, 2, 28], state: "minecraft:deepslate_bricks"},
        {pos: [21, 2, 29], state: "minecraft:deepslate_bricks"},
        {pos: [21, 2, 30], state: "minecraft:deepslate_bricks"},
        {pos: [21, 2, 31], state: "minecraft:deepslate_bricks"},
        {pos: [21, 2, 32], state: "minecraft:deepslate_bricks"},
        {pos: [21, 2, 33], state: "minecraft:deepslate_bricks"},
        {pos: [21, 2, 34], state: "minecraft:deepslate_bricks"},
        {pos: [21, 2, 35], state: "minecraft:deepslate_bricks"},
        {pos: [21, 2, 36], state: "minecraft:deepslate_bricks"},
        {pos: [0, 3, 13], state: "minecraft:deepslate{axis:y}"},
        {pos: [0, 3, 14], state: "minecraft:deepslate{axis:y}"},
        {pos: [0, 3, 15], state: "minecraft:deepslate{axis:y}"},
        {pos: [0, 3, 16], state: "minecraft:deepslate{axis:y}"},
        {pos: [0, 3, 17], state: "minecraft:deepslate{axis:y}"},
        {pos: [0, 3, 18], state: "minecraft:deepslate{axis:y}"},
        {pos: [0, 3, 19], state: "minecraft:deepslate{axis:y}"},
        {pos: [0, 3, 20], state: "minecraft:deepslate{axis:y}"},
        {pos: [0, 3, 21], state: "minecraft:deepslate{axis:y}"},
        {pos: [0, 3, 22], state: "minecraft:deepslate{axis:y}"},
        {pos: [0, 3, 23], state: "minecraft:deepslate{axis:y}"},
        {pos: [0, 3, 24], state: "minecraft:deepslate{axis:y}"},
        {pos: [0, 3, 25], state: "minecraft:deepslate{axis:y}"},
        {pos: [1, 3, 13], state: "minecraft:deepslate{axis:y}"},
        {pos: [1, 3, 14], state: "minecraft:deepslate{axis:y}"},
        {pos: [1, 3, 15], state: "minecraft:deepslate{axis:y}"},
        {pos: [1, 3, 16], state: "minecraft:deepslate{axis:y}"},
        {pos: [1, 3, 17], state: "minecraft:deepslate{axis:y}"},
        {pos: [1, 3, 18], state: "minecraft:deepslate{axis:y}"},
        {pos: [1, 3, 19], state: "minecraft:deepslate{axis:y}"},
        {pos: [1, 3, 20], state: "minecraft:deepslate{axis:y}"},
        {pos: [1, 3, 21], state: "minecraft:deepslate{axis:y}"},
        {pos: [1, 3, 22], state: "minecraft:deepslate{axis:y}"},
        {pos: [1, 3, 23], state: "minecraft:deepslate{axis:y}"},
        {pos: [1, 3, 24], state: "minecraft:deepslate{axis:y}"},
        {pos: [1, 3, 25], state: "minecraft:deepslate{axis:y}"},
        {pos: [2, 3, 11], state: "minecraft:deepslate{axis:y}"},
        {pos: [2, 3, 12], state: "minecraft:deepslate{axis:y}"},
        {pos: [2, 3, 13], state: "minecraft:deepslate{axis:y}"},
        {pos: [2, 3, 14], state: "minecraft:deepslate{axis:y}"},
        {pos: [2, 3, 15], state: "minecraft:deepslate{axis:y}"},
        {pos: [2, 3, 16], state: "minecraft:deepslate{axis:y}"},
        {pos: [2, 3, 17], state: "minecraft:deepslate{axis:y}"},
        {pos: [2, 3, 18], state: "minecraft:deepslate{axis:y}"},
        {pos: [2, 3, 19], state: "minecraft:deepslate{axis:y}"},
        {pos: [2, 3, 20], state: "minecraft:deepslate{axis:y}"},
        {pos: [2, 3, 21], state: "minecraft:deepslate{axis:y}"},
        {pos: [2, 3, 22], state: "minecraft:deepslate{axis:y}"},
        {pos: [2, 3, 23], state: "minecraft:deepslate{axis:y}"},
        {pos: [2, 3, 24], state: "minecraft:deepslate{axis:y}"},
        {pos: [2, 3, 25], state: "minecraft:deepslate{axis:y}"},
        {pos: [3, 3, 9], state: "minecraft:deepslate{axis:y}"},
        {pos: [3, 3, 10], state: "minecraft:deepslate{axis:y}"},
        {pos: [3, 3, 11], state: "minecraft:deepslate{axis:y}"},
        {pos: [3, 3, 12], state: "minecraft:deepslate{axis:y}"},
        {pos: [3, 3, 13], state: "minecraft:deepslate{axis:y}"},
        {pos: [3, 3, 14], state: "minecraft:deepslate{axis:y}"},
        {pos: [3, 3, 15], state: "minecraft:deepslate{axis:y}"},
        {pos: [3, 3, 16], state: "minecraft:deepslate{axis:y}"},
        {pos: [3, 3, 17], state: "minecraft:deepslate{axis:y}"},
        {pos: [3, 3, 18], state: "minecraft:deepslate{axis:y}"},
        {pos: [3, 3, 19], state: "minecraft:deepslate{axis:y}"},
        {pos: [3, 3, 20], state: "minecraft:deepslate{axis:y}"},
        {pos: [3, 3, 21], state: "minecraft:deepslate{axis:y}"},
        {pos: [3, 3, 22], state: "minecraft:deepslate{axis:y}"},
        {pos: [3, 3, 23], state: "minecraft:deepslate{axis:y}"},
        {pos: [3, 3, 24], state: "minecraft:deepslate{axis:y}"},
        {pos: [3, 3, 25], state: "minecraft:deepslate{axis:y}"},
        {pos: [4, 3, 9], state: "minecraft:deepslate{axis:y}"},
        {pos: [4, 3, 10], state: "minecraft:deepslate{axis:y}"},
        {pos: [4, 3, 11], state: "minecraft:deepslate{axis:y}"},
        {pos: [4, 3, 12], state: "minecraft:deepslate{axis:y}"},
        {pos: [4, 3, 13], state: "minecraft:deepslate{axis:y}"},
        {pos: [4, 3, 14], state: "minecraft:deepslate{axis:y}"},
        {pos: [4, 3, 15], state: "minecraft:deepslate{axis:y}"},
        {pos: [4, 3, 16], state: "minecraft:deepslate{axis:y}"},
        {pos: [4, 3, 17], state: "minecraft:deepslate{axis:y}"},
        {pos: [4, 3, 18], state: "minecraft:deepslate{axis:y}"},
        {pos: [4, 3, 19], state: "minecraft:deepslate{axis:y}"},
        {pos: [4, 3, 20], state: "minecraft:deepslate{axis:y}"},
        {pos: [4, 3, 21], state: "minecraft:deepslate{axis:y}"},
        {pos: [4, 3, 22], state: "minecraft:deepslate{axis:y}"},
        {pos: [4, 3, 23], state: "minecraft:deepslate{axis:y}"},
        {pos: [4, 3, 24], state: "minecraft:deepslate{axis:y}"},
        {pos: [4, 3, 25], state: "minecraft:deepslate{axis:y}"},
        {pos: [5, 3, 0], state: "minecraft:deepslate_bricks"},
        {pos: [5, 3, 1], state: "minecraft:deepslate_bricks"},
        {pos: [5, 3, 2], state: "minecraft:deepslate_bricks"},
        {pos: [5, 3, 3], state: "minecraft:deepslate_bricks"},
        {pos: [5, 3, 4], state: "minecraft:deepslate_bricks"},
        {pos: [5, 3, 5], state: "minecraft:deepslate_bricks"},
        {pos: [5, 3, 6], state: "minecraft:deepslate_bricks"},
        {pos: [5, 3, 7], state: "minecraft:deepslate_bricks"},
        {pos: [5, 3, 8], state: "minecraft:deepslate_bricks"},
        {pos: [5, 3, 9], state: "minecraft:deepslate{axis:y}"},
        {pos: [5, 3, 10], state: "minecraft:deepslate{axis:y}"},
        {pos: [5, 3, 11], state: "minecraft:deepslate{axis:y}"},
        {pos: [5, 3, 12], state: "minecraft:deepslate{axis:y}"},
        {pos: [5, 3, 13], state: "minecraft:deepslate{axis:y}"},
        {pos: [5, 3, 14], state: "minecraft:deepslate{axis:y}"},
        {pos: [5, 3, 15], state: "minecraft:deepslate{axis:y}"},
        {pos: [5, 3, 16], state: "minecraft:deepslate{axis:y}"},
        {pos: [5, 3, 17], state: "minecraft:deepslate{axis:y}"},
        {pos: [5, 3, 18], state: "minecraft:deepslate{axis:y}"},
        {pos: [5, 3, 19], state: "minecraft:deepslate{axis:y}"},
        {pos: [5, 3, 20], state: "minecraft:deepslate{axis:y}"},
        {pos: [5, 3, 21], state: "minecraft:deepslate{axis:y}"},
        {pos: [5, 3, 22], state: "minecraft:deepslate{axis:y}"},
        {pos: [5, 3, 23], state: "minecraft:deepslate{axis:y}"},
        {pos: [5, 3, 24], state: "minecraft:deepslate{axis:y}"},
        {pos: [5, 3, 25], state: "minecraft:deepslate{axis:y}"},
        {pos: [5, 3, 26], state: "minecraft:deepslate{axis:y}"},
        {pos: [5, 3, 27], state: "minecraft:deepslate{axis:y}"},
        {pos: [5, 3, 28], state: "minecraft:deepslate_bricks"},
        {pos: [5, 3, 29], state: "minecraft:deepslate_bricks"},
        {pos: [5, 3, 30], state: "minecraft:deepslate_bricks"},
        {pos: [5, 3, 31], state: "minecraft:deepslate_bricks"},
        {pos: [5, 3, 32], state: "minecraft:deepslate_bricks"},
        {pos: [5, 3, 33], state: "minecraft:deepslate_bricks"},
        {pos: [5, 3, 34], state: "minecraft:deepslate_bricks"},
        {pos: [5, 3, 35], state: "minecraft:deepslate_bricks"},
        {pos: [5, 3, 36], state: "minecraft:deepslate_bricks"},
        {pos: [6, 3, 0], state: "minecraft:deepslate_bricks"},
        {pos: [6, 3, 1], state: "minecraft:cave_air"},
        {pos: [6, 3, 2], state: "minecraft:cave_air"},
        {pos: [6, 3, 3], state: "minecraft:cave_air"},
        {pos: [6, 3, 4], state: "minecraft:cave_air"},
        {pos: [6, 3, 5], state: "minecraft:cave_air"},
        {pos: [6, 3, 6], state: "minecraft:cave_air"},
        {pos: [6, 3, 7], state: "minecraft:cave_air"},
        {pos: [6, 3, 8], state: "minecraft:deepslate_bricks"},
        {pos: [6, 3, 9], state: "minecraft:deepslate{axis:y}"},
        {pos: [6, 3, 10], state: "minecraft:deepslate{axis:y}"},
        {pos: [6, 3, 11], state: "minecraft:deepslate{axis:y}"},
        {pos: [6, 3, 12], state: "minecraft:deepslate{axis:y}"},
        {pos: [6, 3, 13], state: "minecraft:deepslate{axis:y}"},
        {pos: [6, 3, 14], state: "minecraft:deepslate{axis:y}"},
        {pos: [6, 3, 15], state: "minecraft:deepslate{axis:y}"},
        {pos: [6, 3, 16], state: "minecraft:deepslate{axis:y}"},
        {pos: [6, 3, 17], state: "minecraft:deepslate{axis:y}"},
        {pos: [6, 3, 18], state: "minecraft:deepslate{axis:y}"},
        {pos: [6, 3, 19], state: "minecraft:deepslate{axis:y}"},
        {pos: [6, 3, 20], state: "minecraft:deepslate{axis:y}"},
        {pos: [6, 3, 21], state: "minecraft:deepslate{axis:y}"},
        {pos: [6, 3, 22], state: "minecraft:deepslate{axis:y}"},
        {pos: [6, 3, 23], state: "minecraft:deepslate{axis:y}"},
        {pos: [6, 3, 24], state: "minecraft:deepslate{axis:y}"},
        {pos: [6, 3, 25], state: "minecraft:deepslate{axis:y}"},
        {pos: [6, 3, 26], state: "minecraft:deepslate{axis:y}"},
        {pos: [6, 3, 27], state: "minecraft:deepslate{axis:y}"},
        {pos: [6, 3, 28], state: "minecraft:deepslate_bricks"},
        {pos: [6, 3, 29], state: "minecraft:cave_air"},
        {pos: [6, 3, 30], state: "minecraft:cave_air"},
        {pos: [6, 3, 31], state: "minecraft:cave_air"},
        {pos: [6, 3, 32], state: "minecraft:cave_air"},
        {pos: [6, 3, 33], state: "minecraft:cave_air"},
        {pos: [6, 3, 34], state: "minecraft:cave_air"},
        {pos: [6, 3, 35], state: "minecraft:cobweb"},
        {pos: [6, 3, 36], state: "minecraft:deepslate_bricks"},
        {pos: [7, 3, 0], state: "minecraft:deepslate_bricks"},
        {pos: [7, 3, 1], state: "minecraft:cave_air"},
        {pos: [7, 3, 2], state: "minecraft:candle{candles:4,lit:false,waterlogged:false}"},
        {pos: [7, 3, 3], state: "minecraft:candle{candles:4,lit:false,waterlogged:false}"},
        {pos: [7, 3, 4], state: "minecraft:candle{candles:4,lit:false,waterlogged:false}"},
        {pos: [7, 3, 5], state: "minecraft:candle{candles:4,lit:false,waterlogged:false}"},
        {pos: [7, 3, 6], state: "minecraft:candle{candles:4,lit:false,waterlogged:false}"},
        {pos: [7, 3, 7], state: "minecraft:cave_air"},
        {pos: [7, 3, 8], state: "minecraft:deepslate_bricks"},
        {pos: [7, 3, 9], state: "minecraft:deepslate{axis:y}"},
        {pos: [7, 3, 10], state: "minecraft:deepslate{axis:y}"},
        {pos: [7, 3, 11], state: "minecraft:deepslate{axis:y}"},
        {pos: [7, 3, 12], state: "minecraft:deepslate{axis:y}"},
        {pos: [7, 3, 13], state: "minecraft:deepslate{axis:y}"},
        {pos: [7, 3, 14], state: "minecraft:deepslate{axis:y}"},
        {pos: [7, 3, 15], state: "minecraft:deepslate{axis:y}"},
        {pos: [7, 3, 16], state: "minecraft:deepslate{axis:y}"},
        {pos: [7, 3, 17], state: "minecraft:deepslate{axis:y}"},
        {pos: [7, 3, 18], state: "minecraft:deepslate{axis:y}"},
        {pos: [7, 3, 19], state: "minecraft:deepslate{axis:y}"},
        {pos: [7, 3, 20], state: "minecraft:deepslate{axis:y}"},
        {pos: [7, 3, 21], state: "minecraft:deepslate{axis:y}"},
        {pos: [7, 3, 22], state: "minecraft:deepslate{axis:y}"},
        {pos: [7, 3, 23], state: "minecraft:deepslate{axis:y}"},
        {pos: [7, 3, 24], state: "minecraft:deepslate{axis:y}"},
        {pos: [7, 3, 25], state: "minecraft:deepslate{axis:y}"},
        {pos: [7, 3, 26], state: "minecraft:deepslate{axis:y}"},
        {pos: [7, 3, 27], state: "minecraft:deepslate{axis:y}"},
        {pos: [7, 3, 28], state: "minecraft:deepslate_bricks"},
        {pos: [7, 3, 29], state: "minecraft:cave_air"},
        {pos: [7, 3, 30], state: "minecraft:candle{candles:4,lit:false,waterlogged:false}"},
        {pos: [7, 3, 31], state: "minecraft:candle{candles:4,lit:false,waterlogged:false}"},
        {pos: [7, 3, 32], state: "minecraft:candle{candles:4,lit:false,waterlogged:false}"},
        {pos: [7, 3, 33], state: "minecraft:candle{candles:4,lit:false,waterlogged:false}"},
        {pos: [7, 3, 34], state: "minecraft:candle{candles:4,lit:false,waterlogged:false}"},
        {pos: [7, 3, 35], state: "minecraft:cave_air"},
        {pos: [7, 3, 36], state: "minecraft:deepslate_bricks"},
        {pos: [8, 3, 0], state: "minecraft:deepslate_bricks"},
        {pos: [8, 3, 1], state: "minecraft:cave_air"},
        {pos: [8, 3, 2], state: "minecraft:candle{candles:4,lit:false,waterlogged:false}"},
        {pos: [8, 3, 3], state: "minecraft:candle{candles:4,lit:false,waterlogged:false}"},
        {pos: [8, 3, 4], state: "minecraft:candle{candles:4,lit:false,waterlogged:false}"},
        {pos: [8, 3, 5], state: "minecraft:skeleton_skull{powered:false,rotation:4}", nbt: {id: "minecraft:skull"}},
        {pos: [8, 3, 6], state: "minecraft:candle{candles:4,lit:false,waterlogged:false}"},
        {pos: [8, 3, 7], state: "minecraft:cave_air"},
        {pos: [8, 3, 8], state: "minecraft:deepslate_bricks"},
        {pos: [8, 3, 9], state: "minecraft:deepslate{axis:y}"},
        {pos: [8, 3, 10], state: "minecraft:deepslate{axis:y}"},
        {pos: [8, 3, 11], state: "minecraft:deepslate{axis:y}"},
        {pos: [8, 3, 12], state: "minecraft:deepslate{axis:y}"},
        {pos: [8, 3, 13], state: "minecraft:deepslate{axis:y}"},
        {pos: [8, 3, 14], state: "minecraft:deepslate{axis:y}"},
        {pos: [8, 3, 15], state: "minecraft:deepslate{axis:y}"},
        {pos: [8, 3, 16], state: "minecraft:deepslate{axis:y}"},
        {pos: [8, 3, 17], state: "minecraft:deepslate{axis:y}"},
        {pos: [8, 3, 18], state: "minecraft:deepslate{axis:y}"},
        {pos: [8, 3, 19], state: "minecraft:deepslate{axis:y}"},
        {pos: [8, 3, 20], state: "minecraft:deepslate{axis:y}"},
        {pos: [8, 3, 21], state: "minecraft:deepslate{axis:y}"},
        {pos: [8, 3, 22], state: "minecraft:deepslate{axis:y}"},
        {pos: [8, 3, 23], state: "minecraft:deepslate{axis:y}"},
        {pos: [8, 3, 24], state: "minecraft:deepslate{axis:y}"},
        {pos: [8, 3, 25], state: "minecraft:deepslate{axis:y}"},
        {pos: [8, 3, 26], state: "minecraft:deepslate{axis:y}"},
        {pos: [8, 3, 27], state: "minecraft:deepslate{axis:y}"},
        {pos: [8, 3, 28], state: "minecraft:deepslate_bricks"},
        {pos: [8, 3, 29], state: "minecraft:cave_air"},
        {pos: [8, 3, 30], state: "minecraft:candle{candles:4,lit:false,waterlogged:false}"},
        {pos: [8, 3, 31], state: "minecraft:candle{candles:4,lit:false,waterlogged:false}"},
        {pos: [8, 3, 32], state: "minecraft:skeleton_skull{powered:false,rotation:4}", nbt: {id: "minecraft:skull"}},
        {pos: [8, 3, 33], state: "minecraft:candle{candles:4,lit:false,waterlogged:false}"},
        {pos: [8, 3, 34], state: "minecraft:candle{candles:4,lit:false,waterlogged:false}"},
        {pos: [8, 3, 35], state: "minecraft:cave_air"},
        {pos: [8, 3, 36], state: "minecraft:deepslate_bricks"},
        {pos: [9, 3, 0], state: "minecraft:deepslate_bricks"},
        {pos: [9, 3, 1], state: "minecraft:cave_air"},
        {pos: [9, 3, 2], state: "minecraft:candle{candles:4,lit:false,waterlogged:false}"},
        {pos: [9, 3, 3], state: "minecraft:candle{candles:4,lit:false,waterlogged:false}"},
        {pos: [9, 3, 4], state: "minecraft:candle{candles:4,lit:false,waterlogged:false}"},
        {pos: [9, 3, 5], state: "minecraft:candle{candles:4,lit:false,waterlogged:false}"},
        {pos: [9, 3, 6], state: "minecraft:candle{candles:4,lit:false,waterlogged:false}"},
        {pos: [9, 3, 7], state: "minecraft:cave_air"},
        {pos: [9, 3, 8], state: "minecraft:deepslate_bricks"},
        {pos: [9, 3, 9], state: "minecraft:deepslate_bricks"},
        {pos: [9, 3, 10], state: "minecraft:deepslate_bricks"},
        {pos: [9, 3, 11], state: "minecraft:deepslate_bricks"},
        {pos: [9, 3, 12], state: "minecraft:deepslate_bricks"},
        {pos: [9, 3, 13], state: "minecraft:deepslate{axis:y}"},
        {pos: [9, 3, 14], state: "minecraft:deepslate{axis:y}"},
        {pos: [9, 3, 15], state: "minecraft:deepslate{axis:y}"},
        {pos: [9, 3, 16], state: "minecraft:deepslate{axis:y}"},
        {pos: [9, 3, 17], state: "minecraft:deepslate{axis:y}"},
        {pos: [9, 3, 18], state: "minecraft:deepslate{axis:y}"},
        {pos: [9, 3, 19], state: "minecraft:deepslate{axis:y}"},
        {pos: [9, 3, 20], state: "minecraft:deepslate{axis:y}"},
        {pos: [9, 3, 21], state: "minecraft:deepslate{axis:y}"},
        {pos: [9, 3, 22], state: "minecraft:deepslate{axis:y}"},
        {pos: [9, 3, 23], state: "minecraft:deepslate{axis:y}"},
        {pos: [9, 3, 24], state: "minecraft:deepslate{axis:y}"},
        {pos: [9, 3, 25], state: "minecraft:deepslate{axis:y}"},
        {pos: [9, 3, 26], state: "minecraft:deepslate{axis:y}"},
        {pos: [9, 3, 27], state: "minecraft:deepslate{axis:y}"},
        {pos: [9, 3, 28], state: "minecraft:deepslate_bricks"},
        {pos: [9, 3, 29], state: "minecraft:cave_air"},
        {pos: [9, 3, 30], state: "minecraft:candle{candles:4,lit:false,waterlogged:false}"},
        {pos: [9, 3, 31], state: "minecraft:skeleton_skull{powered:false,rotation:4}", nbt: {id: "minecraft:skull"}},
        {pos: [9, 3, 32], state: "minecraft:candle{candles:4,lit:false,waterlogged:false}"},
        {pos: [9, 3, 33], state: "minecraft:skeleton_skull{powered:false,rotation:4}", nbt: {id: "minecraft:skull"}},
        {pos: [9, 3, 34], state: "minecraft:candle{candles:4,lit:false,waterlogged:false}"},
        {pos: [9, 3, 35], state: "minecraft:cave_air"},
        {pos: [9, 3, 36], state: "minecraft:deepslate_bricks"},
        {pos: [10, 3, 0], state: "minecraft:deepslate_bricks"},
        {pos: [10, 3, 1], state: "minecraft:cave_air"},
        {pos: [10, 3, 2], state: "minecraft:candle{candles:4,lit:false,waterlogged:false}"},
        {pos: [10, 3, 3], state: "minecraft:skeleton_skull{powered:false,rotation:8}", nbt: {id: "minecraft:skull"}},
        {pos: [10, 3, 4], state: "minecraft:candle{candles:4,lit:false,waterlogged:false}"},
        {pos: [10, 3, 5], state: "minecraft:candle{candles:4,lit:false,waterlogged:false}"},
        {pos: [10, 3, 6], state: "minecraft:candle{candles:4,lit:false,waterlogged:false}"},
        {pos: [10, 3, 7], state: "minecraft:cave_air"},
        {pos: [10, 3, 8], state: "minecraft:deepslate_bricks"},
        {pos: [10, 3, 9], state: "minecraft:deepslate{axis:y}"},
        {pos: [10, 3, 10], state: "minecraft:deepslate{axis:y}"},
        {pos: [10, 3, 11], state: "minecraft:deepslate{axis:y}"},
        {pos: [10, 3, 12], state: "minecraft:deepslate{axis:y}"},
        {pos: [10, 3, 13], state: "minecraft:deepslate{axis:y}"},
        {pos: [10, 3, 14], state: "minecraft:deepslate{axis:y}"},
        {pos: [10, 3, 15], state: "minecraft:deepslate{axis:y}"},
        {pos: [10, 3, 16], state: "minecraft:deepslate{axis:y}"},
        {pos: [10, 3, 17], state: "minecraft:deepslate{axis:y}"},
        {pos: [10, 3, 18], state: "minecraft:deepslate{axis:y}"},
        {pos: [10, 3, 19], state: "minecraft:deepslate{axis:y}"},
        {pos: [10, 3, 20], state: "minecraft:deepslate{axis:y}"},
        {pos: [10, 3, 21], state: "minecraft:deepslate{axis:y}"},
        {pos: [10, 3, 22], state: "minecraft:deepslate{axis:y}"},
        {pos: [10, 3, 23], state: "minecraft:deepslate{axis:y}"},
        {pos: [10, 3, 24], state: "minecraft:deepslate{axis:y}"},
        {pos: [10, 3, 25], state: "minecraft:deepslate{axis:y}"},
        {pos: [10, 3, 26], state: "minecraft:deepslate{axis:y}"},
        {pos: [10, 3, 27], state: "minecraft:deepslate{axis:y}"},
        {pos: [10, 3, 28], state: "minecraft:deepslate_bricks"},
        {pos: [10, 3, 29], state: "minecraft:cave_air"},
        {pos: [10, 3, 30], state: "minecraft:candle{candles:4,lit:false,waterlogged:false}"},
        {pos: [10, 3, 31], state: "minecraft:skeleton_skull{powered:false,rotation:4}", nbt: {id: "minecraft:skull"}},
        {pos: [10, 3, 32], state: "minecraft:candle{candles:4,lit:false,waterlogged:false}"},
        {pos: [10, 3, 33], state: "minecraft:candle{candles:4,lit:false,waterlogged:false}"},
        {pos: [10, 3, 34], state: "minecraft:candle{candles:4,lit:false,waterlogged:false}"},
        {pos: [10, 3, 35], state: "minecraft:cave_air"},
        {pos: [10, 3, 36], state: "minecraft:deepslate_bricks"},
        {pos: [11, 3, 0], state: "minecraft:deepslate_bricks"},
        {pos: [11, 3, 1], state: "minecraft:cave_air"},
        {pos: [11, 3, 2], state: "minecraft:candle{candles:4,lit:false,waterlogged:false}"},
        {pos: [11, 3, 3], state: "minecraft:candle{candles:4,lit:false,waterlogged:false}"},
        {pos: [11, 3, 4], state: "minecraft:candle{candles:4,lit:false,waterlogged:false}"},
        {pos: [11, 3, 5], state: "minecraft:candle{candles:4,lit:false,waterlogged:false}"},
        {pos: [11, 3, 6], state: "minecraft:candle{candles:4,lit:false,waterlogged:false}"},
        {pos: [11, 3, 7], state: "minecraft:cave_air"},
        {pos: [11, 3, 8], state: "minecraft:deepslate_bricks"},
        {pos: [11, 3, 9], state: "minecraft:deepslate_bricks"},
        {pos: [11, 3, 10], state: "minecraft:deepslate_bricks"},
        {pos: [11, 3, 11], state: "minecraft:deepslate_bricks"},
        {pos: [11, 3, 12], state: "minecraft:deepslate_bricks"},
        {pos: [11, 3, 13], state: "minecraft:deepslate_bricks"},
        {pos: [11, 3, 14], state: "minecraft:deepslate{axis:y}"},
        {pos: [11, 3, 15], state: "minecraft:deepslate{axis:y}"},
        {pos: [11, 3, 16], state: "minecraft:deepslate{axis:y}"},
        {pos: [11, 3, 17], state: "minecraft:deepslate{axis:y}"},
        {pos: [11, 3, 18], state: "minecraft:deepslate{axis:y}"},
        {pos: [11, 3, 19], state: "minecraft:deepslate{axis:y}"},
        {pos: [11, 3, 20], state: "minecraft:deepslate{axis:y}"},
        {pos: [11, 3, 21], state: "minecraft:deepslate{axis:y}"},
        {pos: [11, 3, 22], state: "minecraft:deepslate{axis:y}"},
        {pos: [11, 3, 23], state: "minecraft:deepslate_bricks"},
        {pos: [11, 3, 24], state: "minecraft:deepslate_bricks"},
        {pos: [11, 3, 25], state: "minecraft:deepslate_bricks"},
        {pos: [11, 3, 26], state: "minecraft:deepslate_bricks"},
        {pos: [11, 3, 27], state: "minecraft:deepslate_bricks"},
        {pos: [11, 3, 28], state: "minecraft:deepslate_bricks"},
        {pos: [11, 3, 29], state: "minecraft:cave_air"},
        {pos: [11, 3, 30], state: "minecraft:candle{candles:4,lit:false,waterlogged:false}"},
        {pos: [11, 3, 31], state: "minecraft:candle{candles:4,lit:false,waterlogged:false}"},
        {pos: [11, 3, 32], state: "minecraft:candle{candles:4,lit:false,waterlogged:false}"},
        {pos: [11, 3, 33], state: "minecraft:candle{candles:4,lit:false,waterlogged:false}"},
        {pos: [11, 3, 34], state: "minecraft:candle{candles:4,lit:false,waterlogged:false}"},
        {pos: [11, 3, 35], state: "minecraft:cave_air"},
        {pos: [11, 3, 36], state: "minecraft:deepslate_bricks"},
        {pos: [12, 3, 0], state: "minecraft:deepslate_bricks"},
        {pos: [12, 3, 1], state: "minecraft:cave_air"},
        {pos: [12, 3, 2], state: "minecraft:cave_air"},
        {pos: [12, 3, 3], state: "minecraft:cave_air"},
        {pos: [12, 3, 4], state: "minecraft:cave_air"},
        {pos: [12, 3, 5], state: "minecraft:cave_air"},
        {pos: [12, 3, 6], state: "minecraft:cave_air"},
        {pos: [12, 3, 7], state: "minecraft:cave_air"},
        {pos: [12, 3, 8], state: "minecraft:cave_air"},
        {pos: [12, 3, 9], state: "minecraft:cave_air"},
        {pos: [12, 3, 10], state: "minecraft:cave_air"},
        {pos: [12, 3, 11], state: "minecraft:cave_air"},
        {pos: [12, 3, 12], state: "minecraft:deepslate_brick_stairs{facing:south,half:bottom,shape:straight,waterlogged:false}"},
        {pos: [12, 3, 13], state: "minecraft:deepslate{axis:y}"},
        {pos: [12, 3, 14], state: "minecraft:deepslate{axis:y}"},
        {pos: [12, 3, 15], state: "minecraft:deepslate{axis:y}"},
        {pos: [12, 3, 16], state: "minecraft:deepslate{axis:y}"},
        {pos: [12, 3, 17], state: "minecraft:deepslate{axis:y}"},
        {pos: [12, 3, 18], state: "minecraft:deepslate{axis:y}"},
        {pos: [12, 3, 19], state: "minecraft:deepslate{axis:y}"},
        {pos: [12, 3, 20], state: "minecraft:deepslate{axis:y}"},
        {pos: [12, 3, 21], state: "minecraft:deepslate{axis:y}"},
        {pos: [12, 3, 22], state: "minecraft:deepslate{axis:y}"},
        {pos: [12, 3, 23], state: "minecraft:deepslate{axis:y}"},
        {pos: [12, 3, 24], state: "minecraft:deepslate_brick_stairs{facing:north,half:bottom,shape:straight,waterlogged:false}"},
        {pos: [12, 3, 25], state: "minecraft:cave_air"},
        {pos: [12, 3, 26], state: "minecraft:cave_air"},
        {pos: [12, 3, 27], state: "minecraft:cave_air"},
        {pos: [12, 3, 28], state: "minecraft:cave_air"},
        {pos: [12, 3, 29], state: "minecraft:cave_air"},
        {pos: [12, 3, 30], state: "minecraft:cave_air"},
        {pos: [12, 3, 31], state: "minecraft:cave_air"},
        {pos: [12, 3, 32], state: "minecraft:cave_air"},
        {pos: [12, 3, 33], state: "minecraft:cave_air"},
        {pos: [12, 3, 34], state: "minecraft:cave_air"},
        {pos: [12, 3, 35], state: "minecraft:cave_air"},
        {pos: [12, 3, 36], state: "minecraft:deepslate_bricks"},
        {pos: [13, 3, 0], state: "minecraft:deepslate_bricks"},
        {pos: [13, 3, 1], state: "minecraft:cave_air"},
        {pos: [13, 3, 2], state: "minecraft:cave_air"},
        {pos: [13, 3, 3], state: "minecraft:cave_air"},
        {pos: [13, 3, 4], state: "minecraft:cave_air"},
        {pos: [13, 3, 5], state: "minecraft:cave_air"},
        {pos: [13, 3, 6], state: "minecraft:cave_air"},
        {pos: [13, 3, 7], state: "minecraft:cave_air"},
        {pos: [13, 3, 8], state: "minecraft:cave_air"},
        {pos: [13, 3, 9], state: "minecraft:cave_air"},
        {pos: [13, 3, 10], state: "minecraft:cave_air"},
        {pos: [13, 3, 11], state: "minecraft:cave_air"},
        {pos: [13, 3, 12], state: "minecraft:deepslate_brick_stairs{facing:south,half:bottom,shape:straight,waterlogged:false}"},
        {pos: [13, 3, 13], state: "minecraft:deepslate{axis:y}"},
        {pos: [13, 3, 14], state: "minecraft:deepslate{axis:y}"},
        {pos: [13, 3, 15], state: "minecraft:deepslate{axis:y}"},
        {pos: [13, 3, 16], state: "minecraft:deepslate{axis:y}"},
        {pos: [13, 3, 17], state: "minecraft:deepslate{axis:y}"},
        {pos: [13, 3, 18], state: "minecraft:deepslate{axis:y}"},
        {pos: [13, 3, 19], state: "minecraft:deepslate{axis:y}"},
        {pos: [13, 3, 20], state: "minecraft:deepslate{axis:y}"},
        {pos: [13, 3, 21], state: "minecraft:deepslate{axis:y}"},
        {pos: [13, 3, 22], state: "minecraft:deepslate{axis:y}"},
        {pos: [13, 3, 23], state: "minecraft:deepslate{axis:y}"},
        {pos: [13, 3, 24], state: "minecraft:deepslate_brick_stairs{facing:north,half:bottom,shape:straight,waterlogged:false}"},
        {pos: [13, 3, 25], state: "minecraft:cave_air"},
        {pos: [13, 3, 26], state: "minecraft:cave_air"},
        {pos: [13, 3, 27], state: "minecraft:cave_air"},
        {pos: [13, 3, 28], state: "minecraft:cave_air"},
        {pos: [13, 3, 29], state: "minecraft:cave_air"},
        {pos: [13, 3, 30], state: "minecraft:cave_air"},
        {pos: [13, 3, 31], state: "minecraft:cave_air"},
        {pos: [13, 3, 32], state: "minecraft:cave_air"},
        {pos: [13, 3, 33], state: "minecraft:cave_air"},
        {pos: [13, 3, 34], state: "minecraft:cave_air"},
        {pos: [13, 3, 35], state: "minecraft:cave_air"},
        {pos: [13, 3, 36], state: "minecraft:deepslate_bricks"},
        {pos: [14, 3, 0], state: "minecraft:deepslate_bricks"},
        {pos: [14, 3, 1], state: "minecraft:cave_air"},
        {pos: [14, 3, 2], state: "minecraft:cave_air"},
        {pos: [14, 3, 3], state: "minecraft:cave_air"},
        {pos: [14, 3, 4], state: "minecraft:cave_air"},
        {pos: [14, 3, 5], state: "minecraft:cave_air"},
        {pos: [14, 3, 6], state: "minecraft:cave_air"},
        {pos: [14, 3, 7], state: "minecraft:cave_air"},
        {pos: [14, 3, 8], state: "minecraft:cave_air"},
        {pos: [14, 3, 9], state: "minecraft:cave_air"},
        {pos: [14, 3, 10], state: "minecraft:cave_air"},
        {pos: [14, 3, 11], state: "minecraft:cave_air"},
        {pos: [14, 3, 12], state: "minecraft:deepslate_brick_stairs{facing:south,half:bottom,shape:straight,waterlogged:false}"},
        {pos: [14, 3, 13], state: "minecraft:deepslate{axis:y}"},
        {pos: [14, 3, 14], state: "minecraft:deepslate{axis:y}"},
        {pos: [14, 3, 15], state: "minecraft:deepslate{axis:y}"},
