{
    DataVersion: 3955,
    size: [27, 11, 21],
    data: [
        {pos: [8, 0, 9], state: "minecraft:deepslate_bricks"},
        {pos: [8, 0, 10], state: "minecraft:deepslate_bricks"},
        {pos: [9, 0, 8], state: "minecraft:deepslate_bricks"},
        {pos: [9, 0, 9], state: "minecraft:deepslate_bricks"},
        {pos: [9, 0, 10], state: "minecraft:deepslate_bricks"},
        {pos: [9, 0, 11], state: "minecraft:deepslate_bricks"},
        {pos: [10, 0, 8], state: "minecraft:deepslate_bricks"},
        {pos: [10, 0, 9], state: "minecraft:deepslate_bricks"},
        {pos: [10, 0, 10], state: "minecraft:deepslate_bricks"},
        {pos: [11, 0, 3], state: "minecraft:deepslate_bricks"},
        {pos: [11, 0, 4], state: "minecraft:deepslate_bricks"},
        {pos: [11, 0, 8], state: "minecraft:deepslate_bricks"},
        {pos: [11, 0, 9], state: "minecraft:deepslate_bricks"},
        {pos: [11, 0, 10], state: "minecraft:deepslate_bricks"},
        {pos: [11, 0, 11], state: "minecraft:deepslate_bricks"},
        {pos: [11, 0, 12], state: "minecraft:deepslate_bricks"},
        {pos: [11, 0, 14], state: "minecraft:deepslate_bricks"},
        {pos: [11, 0, 15], state: "minecraft:deepslate_bricks"},
        {pos: [11, 0, 16], state: "minecraft:deepslate_bricks"},
        {pos: [11, 0, 17], state: "minecraft:deepslate_bricks"},
        {pos: [12, 0, 2], state: "minecraft:deepslate_bricks"},
        {pos: [12, 0, 3], state: "minecraft:deepslate_bricks"},
        {pos: [12, 0, 4], state: "minecraft:deepslate_bricks"},
        {pos: [12, 0, 5], state: "minecraft:deepslate_bricks"},
        {pos: [12, 0, 6], state: "minecraft:deepslate_bricks"},
        {pos: [12, 0, 7], state: "minecraft:deepslate_bricks"},
        {pos: [12, 0, 8], state: "minecraft:deepslate_bricks"},
        {pos: [12, 0, 9], state: "minecraft:deepslate_bricks"},
        {pos: [12, 0, 10], state: "minecraft:deepslate_bricks"},
        {pos: [12, 0, 11], state: "minecraft:deepslate_bricks"},
        {pos: [12, 0, 12], state: "minecraft:deepslate_bricks"},
        {pos: [12, 0, 13], state: "minecraft:deepslate_bricks"},
        {pos: [12, 0, 14], state: "minecraft:deepslate_bricks"},
        {pos: [12, 0, 15], state: "minecraft:deepslate_bricks"},
        {pos: [12, 0, 16], state: "minecraft:deepslate_bricks"},
        {pos: [12, 0, 17], state: "minecraft:deepslate_bricks"},
        {pos: [12, 0, 18], state: "minecraft:deepslate_bricks"},
        {pos: [13, 0, 3], state: "minecraft:deepslate_bricks"},
        {pos: [13, 0, 4], state: "minecraft:deepslate_bricks"},
        {pos: [13, 0, 5], state: "minecraft:deepslate_bricks"},
        {pos: [13, 0, 6], state: "minecraft:deepslate_bricks"},
        {pos: [13, 0, 7], state: "minecraft:deepslate_bricks"},
        {pos: [13, 0, 8], state: "minecraft:deepslate_bricks"},
        {pos: [13, 0, 9], state: "minecraft:deepslate_bricks"},
        {pos: [13, 0, 10], state: "minecraft:deepslate_bricks"},
        {pos: [13, 0, 11], state: "minecraft:deepslate_bricks"},
        {pos: [13, 0, 12], state: "minecraft:deepslate_bricks"},
        {pos: [13, 0, 14], state: "minecraft:deepslate_bricks"},
        {pos: [13, 0, 15], state: "minecraft:deepslate_bricks"},
        {pos: [13, 0, 16], state: "minecraft:deepslate_bricks"},
        {pos: [13, 0, 17], state: "minecraft:deepslate_bricks"},
        {pos: [13, 0, 18], state: "minecraft:deepslate_bricks"},
        {pos: [14, 0, 3], state: "minecraft:deepslate_bricks"},
        {pos: [14, 0, 4], state: "minecraft:deepslate_bricks"},
        {pos: [14, 0, 5], state: "minecraft:deepslate_bricks"},
        {pos: [14, 0, 6], state: "minecraft:deepslate_bricks"},
        {pos: [14, 0, 7], state: "minecraft:deepslate_bricks"},
        {pos: [14, 0, 8], state: "minecraft:deepslate_bricks"},
        {pos: [14, 0, 9], state: "minecraft:deepslate_bricks"},
        {pos: [14, 0, 10], state: "minecraft:deepslate_bricks"},
        {pos: [14, 0, 11], state: "minecraft:deepslate_bricks"},
        {pos: [14, 0, 12], state: "minecraft:deepslate_bricks"},
        {pos: [14, 0, 15], state: "minecraft:deepslate_bricks"},
        {pos: [14, 0, 16], state: "minecraft:deepslate_bricks"},
        {pos: [14, 0, 17], state: "minecraft:deepslate_bricks"},
        {pos: [15, 0, 4], state: "minecraft:deepslate_bricks"},
        {pos: [15, 0, 5], state: "minecraft:deepslate_bricks"},
        {pos: [15, 0, 6], state: "minecraft:deepslate_bricks"},
        {pos: [15, 0, 7], state: "minecraft:deepslate_bricks"},
        {pos: [15, 0, 8], state: "minecraft:deepslate_bricks"},
        {pos: [15, 0, 9], state: "minecraft:deepslate_bricks"},
        {pos: [15, 0, 10], state: "minecraft:deepslate_bricks"},
        {pos: [15, 0, 11], state: "minecraft:deepslate_bricks"},
        {pos: [15, 0, 12], state: "minecraft:deepslate_bricks"},
        {pos: [15, 0, 16], state: "minecraft:deepslate_bricks"},
        {pos: [16, 0, 8], state: "minecraft:deepslate_bricks"},
        {pos: [16, 0, 9], state: "minecraft:deepslate_bricks"},
        {pos: [16, 0, 10], state: "minecraft:deepslate_bricks"},
        {pos: [17, 0, 8], state: "minecraft:deepslate_bricks"},
        {pos: [17, 0, 9], state: "minecraft:deepslate_bricks"},
        {pos: [17, 0, 10], state: "minecraft:deepslate_bricks"},
        {pos: [17, 0, 11], state: "minecraft:deepslate_bricks"},
        {pos: [18, 0, 9], state: "minecraft:deepslate_bricks"},
        {pos: [18, 0, 10], state: "minecraft:deepslate_bricks"},
        {pos: [18, 0, 11], state: "minecraft:deepslate_bricks"},
        {pos: [18, 0, 12], state: "minecraft:deepslate_bricks"},
        {pos: [19, 0, 9], state: "minecraft:deepslate_bricks"},
        {pos: [19, 0, 10], state: "minecraft:deepslate_bricks"},
        {pos: [19, 0, 11], state: "minecraft:deepslate_bricks"},
        {pos: [19, 0, 12], state: "minecraft:deepslate_bricks"},
        {pos: [20, 0, 8], state: "minecraft:deepslate_bricks"},
        {pos: [20, 0, 9], state: "minecraft:deepslate_bricks"},
        {pos: [20, 0, 10], state: "minecraft:deepslate_bricks"},
        {pos: [20, 0, 11], state: "minecraft:deepslate_bricks"},
        {pos: [21, 0, 9], state: "minecraft:deepslate_bricks"},
        {pos: [8, 1, 9], state: "minecraft:deepslate_bricks"},
        {pos: [8, 1, 10], state: "minecraft:deepslate_bricks"},
        {pos: [9, 1, 8], state: "minecraft:deepslate_bricks"},
        {pos: [9, 1, 9], state: "minecraft:pointed_dripstone{thickness:frustum,vertical_direction:up,waterlogged:false}"},
        {pos: [9, 1, 10], state: "minecraft:pointed_dripstone{thickness:frustum,vertical_direction:up,waterlogged:false}"},
        {pos: [9, 1, 11], state: "minecraft:deepslate_bricks"},
        {pos: [10, 1, 8], state: "minecraft:deepslate_bricks"},
        {pos: [10, 1, 9], state: "minecraft:pointed_dripstone{thickness:frustum,vertical_direction:up,waterlogged:false}"},
        {pos: [10, 1, 10], state: "minecraft:deepslate_bricks"},
        {pos: [11, 1, 3], state: "minecraft:deepslate_bricks"},
        {pos: [11, 1, 4], state: "minecraft:deepslate_bricks"},
        {pos: [11, 1, 8], state: "minecraft:deepslate_bricks"},
        {pos: [11, 1, 9], state: "minecraft:deepslate_bricks"},
        {pos: [11, 1, 10], state: "minecraft:deepslate_bricks"},
        {pos: [11, 1, 11], state: "minecraft:deepslate_bricks"},
        {pos: [11, 1, 12], state: "minecraft:deepslate_bricks"},
        {pos: [11, 1, 14], state: "minecraft:deepslate_bricks"},
        {pos: [11, 1, 15], state: "minecraft:deepslate_bricks"},
        {pos: [11, 1, 16], state: "minecraft:deepslate_bricks"},
        {pos: [11, 1, 17], state: "minecraft:deepslate_bricks"},
        {pos: [12, 1, 2], state: "minecraft:deepslate_bricks"},
        {pos: [12, 1, 3], state: "minecraft:pointed_dripstone{thickness:frustum,vertical_direction:up,waterlogged:false}"},
        {pos: [12, 1, 4], state: "minecraft:pointed_dripstone{thickness:frustum,vertical_direction:up,waterlogged:false}"},
        {pos: [12, 1, 5], state: "minecraft:deepslate_bricks"},
        {pos: [12, 1, 6], state: "minecraft:deepslate_bricks"},
        {pos: [12, 1, 7], state: "minecraft:deepslate_bricks"},
        {pos: [12, 1, 8], state: "minecraft:deepslate_bricks"},
        {pos: [12, 1, 9], state: "minecraft:pointed_dripstone{thickness:frustum,vertical_direction:up,waterlogged:false}"},
        {pos: [12, 1, 10], state: "minecraft:pointed_dripstone{thickness:frustum,vertical_direction:up,waterlogged:false}"},
        {pos: [12, 1, 11], state: "minecraft:pointed_dripstone{thickness:frustum,vertical_direction:up,waterlogged:false}"},
        {pos: [12, 1, 12], state: "minecraft:deepslate_bricks"},
        {pos: [12, 1, 13], state: "minecraft:deepslate_bricks"},
        {pos: [12, 1, 14], state: "minecraft:pointed_dripstone{thickness:frustum,vertical_direction:up,waterlogged:false}"},
        {pos: [12, 1, 15], state: "minecraft:pointed_dripstone{thickness:frustum,vertical_direction:up,waterlogged:false}"},
        {pos: [12, 1, 16], state: "minecraft:pointed_dripstone{thickness:frustum,vertical_direction:up,waterlogged:false}"},
        {pos: [12, 1, 17], state: "minecraft:pointed_dripstone{thickness:frustum,vertical_direction:up,waterlogged:false}"},
        {pos: [12, 1, 18], state: "minecraft:deepslate_bricks"},
        {pos: [13, 1, 3], state: "minecraft:deepslate_bricks"},
        {pos: [13, 1, 4], state: "minecraft:deepslate_bricks"},
        {pos: [13, 1, 5], state: "minecraft:pointed_dripstone{thickness:frustum,vertical_direction:up,waterlogged:false}"},
        {pos: [13, 1, 6], state: "minecraft:pointed_dripstone{thickness:frustum,vertical_direction:up,waterlogged:false}"},
        {pos: [13, 1, 7], state: "minecraft:deepslate_bricks"},
        {pos: [13, 1, 8], state: "minecraft:deepslate_bricks"},
        {pos: [13, 1, 9], state: "minecraft:pointed_dripstone{thickness:frustum,vertical_direction:up,waterlogged:false}"},
        {pos: [13, 1, 10], state: "minecraft:pointed_dripstone{thickness:frustum,vertical_direction:up,waterlogged:false}"},
        {pos: [13, 1, 11], state: "minecraft:pointed_dripstone{thickness:frustum,vertical_direction:up,waterlogged:false}"},
        {pos: [13, 1, 12], state: "minecraft:deepslate_bricks"},
        {pos: [13, 1, 14], state: "minecraft:deepslate_bricks"},
        {pos: [13, 1, 15], state: "minecraft:pointed_dripstone{thickness:frustum,vertical_direction:up,waterlogged:false}"},
        {pos: [13, 1, 16], state: "minecraft:pointed_dripstone{thickness:frustum,vertical_direction:up,waterlogged:false}"},
        {pos: [13, 1, 17], state: "minecraft:pointed_dripstone{thickness:frustum,vertical_direction:up,waterlogged:false}"},
        {pos: [13, 1, 18], state: "minecraft:deepslate_bricks"},
        {pos: [14, 1, 3], state: "minecraft:deepslate_bricks"},
        {pos: [14, 1, 4], state: "minecraft:pointed_dripstone{thickness:frustum,vertical_direction:up,waterlogged:false}"},
        {pos: [14, 1, 5], state: "minecraft:pointed_dripstone{thickness:frustum,vertical_direction:up,waterlogged:false}"},
        {pos: [14, 1, 6], state: "minecraft:pointed_dripstone{thickness:frustum,vertical_direction:up,waterlogged:false}"},
        {pos: [14, 1, 7], state: "minecraft:pointed_dripstone{thickness:frustum,vertical_direction:up,waterlogged:false}"},
        {pos: [14, 1, 8], state: "minecraft:deepslate_bricks"},
        {pos: [14, 1, 9], state: "minecraft:pointed_dripstone{thickness:frustum,vertical_direction:up,waterlogged:false}"},
        {pos: [14, 1, 10], state: "minecraft:pointed_dripstone{thickness:frustum,vertical_direction:up,waterlogged:false}"},
        {pos: [14, 1, 11], state: "minecraft:pointed_dripstone{thickness:frustum,vertical_direction:up,waterlogged:false}"},
        {pos: [14, 1, 12], state: "minecraft:deepslate_bricks"},
        {pos: [14, 1, 15], state: "minecraft:deepslate_bricks"},
        {pos: [14, 1, 16], state: "minecraft:pointed_dripstone{thickness:frustum,vertical_direction:up,waterlogged:false}"},
        {pos: [14, 1, 17], state: "minecraft:deepslate_bricks"},
        {pos: [15, 1, 4], state: "minecraft:deepslate_bricks"},
        {pos: [15, 1, 5], state: "minecraft:deepslate_bricks"},
        {pos: [15, 1, 6], state: "minecraft:deepslate_bricks"},
        {pos: [15, 1, 7], state: "minecraft:deepslate_bricks"},
        {pos: [15, 1, 8], state: "minecraft:deepslate_bricks"},
        {pos: [15, 1, 9], state: "minecraft:deepslate_bricks"},
        {pos: [15, 1, 10], state: "minecraft:deepslate_bricks"},
        {pos: [15, 1, 11], state: "minecraft:deepslate_bricks"},
        {pos: [15, 1, 12], state: "minecraft:deepslate_bricks"},
        {pos: [15, 1, 16], state: "minecraft:deepslate_bricks"},
        {pos: [16, 1, 8], state: "minecraft:deepslate_bricks"},
        {pos: [16, 1, 9], state: "minecraft:pointed_dripstone{thickness:frustum,vertical_direction:up,waterlogged:false}"},
        {pos: [16, 1, 10], state: "minecraft:deepslate_bricks"},
        {pos: [17, 1, 8], state: "minecraft:deepslate_bricks"},
        {pos: [17, 1, 9], state: "minecraft:pointed_dripstone{thickness:frustum,vertical_direction:up,waterlogged:false}"},
        {pos: [17, 1, 10], state: "minecraft:pointed_dripstone{thickness:frustum,vertical_direction:up,waterlogged:false}"},
        {pos: [17, 1, 11], state: "minecraft:deepslate_bricks"},
        {pos: [18, 1, 9], state: "minecraft:deepslate_bricks"},
        {pos: [18, 1, 10], state: "minecraft:pointed_dripstone{thickness:frustum,vertical_direction:up,waterlogged:false}"},
        {pos: [18, 1, 11], state: "minecraft:pointed_dripstone{thickness:frustum,vertical_direction:up,waterlogged:false}"},
        {pos: [18, 1, 12], state: "minecraft:deepslate_bricks"},
        {pos: [19, 1, 9], state: "minecraft:deepslate_bricks"},
        {pos: [19, 1, 10], state: "minecraft:pointed_dripstone{thickness:frustum,vertical_direction:up,waterlogged:false}"},
        {pos: [19, 1, 11], state: "minecraft:pointed_dripstone{thickness:frustum,vertical_direction:up,waterlogged:false}"},
        {pos: [19, 1, 12], state: "minecraft:deepslate_bricks"},
        {pos: [20, 1, 8], state: "minecraft:deepslate_bricks"},
        {pos: [20, 1, 9], state: "minecraft:pointed_dripstone{thickness:frustum,vertical_direction:up,waterlogged:false}"},
        {pos: [20, 1, 10], state: "minecraft:deepslate_bricks"},
        {pos: [20, 1, 11], state: "minecraft:deepslate_bricks"},
        {pos: [21, 1, 9], state: "minecraft:deepslate_bricks"},
        {pos: [8, 2, 9], state: "minecraft:deepslate_bricks"},
        {pos: [8, 2, 10], state: "minecraft:deepslate_bricks"},
        {pos: [9, 2, 8], state: "minecraft:deepslate_bricks"},
        {pos: [9, 2, 9], state: "minecraft:pointed_dripstone{thickness:tip,vertical_direction:up,waterlogged:false}"},
        {pos: [9, 2, 10], state: "minecraft:pointed_dripstone{thickness:tip,vertical_direction:up,waterlogged:false}"},
        {pos: [9, 2, 11], state: "minecraft:deepslate_bricks"},
        {pos: [10, 2, 8], state: "minecraft:deepslate_bricks"},
        {pos: [10, 2, 9], state: "minecraft:pointed_dripstone{thickness:tip,vertical_direction:up,waterlogged:false}"},
        {pos: [10, 2, 10], state: "minecraft:deepslate_bricks"},
        {pos: [11, 2, 3], state: "minecraft:deepslate_bricks"},
        {pos: [11, 2, 4], state: "minecraft:deepslate_bricks"},
        {pos: [11, 2, 8], state: "minecraft:deepslate_bricks"},
        {pos: [11, 2, 9], state: "minecraft:deepslate_bricks"},
        {pos: [11, 2, 10], state: "minecraft:deepslate_bricks"},
        {pos: [11, 2, 11], state: "minecraft:deepslate_bricks"},
        {pos: [11, 2, 12], state: "minecraft:deepslate_bricks"},
        {pos: [11, 2, 14], state: "minecraft:deepslate_bricks"},
        {pos: [11, 2, 15], state: "minecraft:deepslate_bricks"},
        {pos: [11, 2, 16], state: "minecraft:deepslate_bricks"},
        {pos: [11, 2, 17], state: "minecraft:deepslate_bricks"},
        {pos: [12, 2, 2], state: "minecraft:deepslate_bricks"},
        {pos: [12, 2, 3], state: "minecraft:pointed_dripstone{thickness:tip,vertical_direction:up,waterlogged:false}"},
        {pos: [12, 2, 4], state: "minecraft:pointed_dripstone{thickness:tip,vertical_direction:up,waterlogged:false}"},
        {pos: [12, 2, 5], state: "minecraft:deepslate_bricks"},
        {pos: [12, 2, 6], state: "minecraft:deepslate_bricks"},
        {pos: [12, 2, 7], state: "minecraft:deepslate_bricks"},
        {pos: [12, 2, 8], state: "minecraft:deepslate_bricks"},
        {pos: [12, 2, 9], state: "minecraft:pointed_dripstone{thickness:tip,vertical_direction:up,waterlogged:false}"},
        {pos: [12, 2, 10], state: "minecraft:pointed_dripstone{thickness:tip,vertical_direction:up,waterlogged:false}"},
        {pos: [12, 2, 11], state: "minecraft:pointed_dripstone{thickness:tip,vertical_direction:up,waterlogged:false}"},
        {pos: [12, 2, 12], state: "minecraft:deepslate_bricks"},
        {pos: [12, 2, 13], state: "minecraft:deepslate_bricks"},
        {pos: [12, 2, 14], state: "minecraft:pointed_dripstone{thickness:tip,vertical_direction:up,waterlogged:false}"},
        {pos: [12, 2, 15], state: "minecraft:pointed_dripstone{thickness:tip,vertical_direction:up,waterlogged:false}"},
        {pos: [12, 2, 16], state: "minecraft:pointed_dripstone{thickness:tip,vertical_direction:up,waterlogged:false}"},
        {pos: [12, 2, 17], state: "minecraft:pointed_dripstone{thickness:tip,vertical_direction:up,waterlogged:false}"},
        {pos: [12, 2, 18], state: "minecraft:deepslate_bricks"},
        {pos: [13, 2, 3], state: "minecraft:deepslate_bricks"},
        {pos: [13, 2, 4], state: "minecraft:deepslate_bricks"},
        {pos: [13, 2, 5], state: "minecraft:pointed_dripstone{thickness:tip,vertical_direction:up,waterlogged:false}"},
        {pos: [13, 2, 6], state: "minecraft:pointed_dripstone{thickness:tip,vertical_direction:up,waterlogged:false}"},
        {pos: [13, 2, 7], state: "minecraft:deepslate_bricks"},
        {pos: [13, 2, 8], state: "minecraft:deepslate_bricks"},
        {pos: [13, 2, 9], state: "minecraft:pointed_dripstone{thickness:tip,vertical_direction:up,waterlogged:false}"},
        {pos: [13, 2, 10], state: "minecraft:pointed_dripstone{thickness:tip,vertical_direction:up,waterlogged:false}"},
        {pos: [13, 2, 11], state: "minecraft:pointed_dripstone{thickness:tip,vertical_direction:up,waterlogged:false}"},
        {pos: [13, 2, 12], state: "minecraft:deepslate_bricks"},
        {pos: [13, 2, 14], state: "minecraft:deepslate_bricks"},
        {pos: [13, 2, 15], state: "minecraft:pointed_dripstone{thickness:tip,vertical_direction:up,waterlogged:false}"},
        {pos: [13, 2, 16], state: "minecraft:pointed_dripstone{thickness:tip,vertical_direction:up,waterlogged:false}"},
        {pos: [13, 2, 17], state: "minecraft:pointed_dripstone{thickness:tip,vertical_direction:up,waterlogged:false}"},
        {pos: [13, 2, 18], state: "minecraft:deepslate_bricks"},
        {pos: [14, 2, 3], state: "minecraft:deepslate_bricks"},
        {pos: [14, 2, 4], state: "minecraft:pointed_dripstone{thickness:tip,vertical_direction:up,waterlogged:false}"},
        {pos: [14, 2, 5], state: "minecraft:pointed_dripstone{thickness:tip,vertical_direction:up,waterlogged:false}"},
        {pos: [14, 2, 6], state: "minecraft:pointed_dripstone{thickness:tip,vertical_direction:up,waterlogged:false}"},
        {pos: [14, 2, 7], state: "minecraft:pointed_dripstone{thickness:tip,vertical_direction:up,waterlogged:false}"},
        {pos: [14, 2, 8], state: "minecraft:deepslate_bricks"},
        {pos: [14, 2, 9], state: "minecraft:pointed_dripstone{thickness:tip,vertical_direction:up,waterlogged:false}"},
        {pos: [14, 2, 10], state: "minecraft:pointed_dripstone{thickness:tip,vertical_direction:up,waterlogged:false}"},
        {pos: [14, 2, 11], state: "minecraft:pointed_dripstone{thickness:tip,vertical_direction:up,waterlogged:false}"},
        {pos: [14, 2, 12], state: "minecraft:deepslate_bricks"},
        {pos: [14, 2, 15], state: "minecraft:deepslate_bricks"},
        {pos: [14, 2, 16], state: "minecraft:pointed_dripstone{thickness:tip,vertical_direction:up,waterlogged:false}"},
        {pos: [14, 2, 17], state: "minecraft:deepslate_bricks"},
        {pos: [15, 2, 4], state: "minecraft:deepslate_bricks"},
        {pos: [15, 2, 5], state: "minecraft:deepslate_bricks"},
        {pos: [15, 2, 6], state: "minecraft:deepslate_bricks"},
        {pos: [15, 2, 7], state: "minecraft:deepslate_bricks"},
        {pos: [15, 2, 8], state: "minecraft:deepslate_bricks"},
        {pos: [15, 2, 9], state: "minecraft:deepslate_bricks"},
        {pos: [15, 2, 10], state: "minecraft:deepslate_bricks"},
        {pos: [15, 2, 11], state: "minecraft:deepslate_bricks"},
        {pos: [15, 2, 12], state: "minecraft:deepslate_bricks"},
        {pos: [15, 2, 16], state: "minecraft:deepslate_bricks"},
        {pos: [16, 2, 8], state: "minecraft:deepslate_bricks"},
        {pos: [16, 2, 9], state: "minecraft:pointed_dripstone{thickness:tip,vertical_direction:up,waterlogged:false}"},
        {pos: [16, 2, 10], state: "minecraft:deepslate_bricks"},
        {pos: [17, 2, 8], state: "minecraft:deepslate_bricks"},
        {pos: [17, 2, 9], state: "minecraft:pointed_dripstone{thickness:tip,vertical_direction:up,waterlogged:false}"},
        {pos: [17, 2, 10], state: "minecraft:pointed_dripstone{thickness:tip,vertical_direction:up,waterlogged:false}"},
        {pos: [17, 2, 11], state: "minecraft:deepslate_bricks"},
        {pos: [18, 2, 9], state: "minecraft:deepslate_bricks"},
        {pos: [18, 2, 10], state: "minecraft:pointed_dripstone{thickness:tip,vertical_direction:up,waterlogged:false}"},
        {pos: [18, 2, 11], state: "minecraft:pointed_dripstone{thickness:tip,vertical_direction:up,waterlogged:false}"},
        {pos: [18, 2, 12], state: "minecraft:deepslate_bricks"},
        {pos: [19, 2, 9], state: "minecraft:deepslate_bricks"},
        {pos: [19, 2, 10], state: "minecraft:pointed_dripstone{thickness:tip,vertical_direction:up,waterlogged:false}"},
        {pos: [19, 2, 11], state: "minecraft:pointed_dripstone{thickness:tip,vertical_direction:up,waterlogged:false}"},
        {pos: [19, 2, 12], state: "minecraft:deepslate_bricks"},
        {pos: [20, 2, 8], state: "minecraft:deepslate_bricks"},
        {pos: [20, 2, 9], state: "minecraft:pointed_dripstone{thickness:tip,vertical_direction:up,waterlogged:false}"},
        {pos: [20, 2, 10], state: "minecraft:deepslate_bricks"},
        {pos: [20, 2, 11], state: "minecraft:deepslate_bricks"},
        {pos: [21, 2, 9], state: "minecraft:deepslate_bricks"},
        {pos: [8, 3, 9], state: "minecraft:deepslate_bricks"},
        {pos: [8, 3, 10], state: "minecraft:deepslate_bricks"},
        {pos: [9, 3, 8], state: "minecraft:deepslate_bricks"},
        {pos: [9, 3, 9], state: "minecraft:cave_air"},
        {pos: [9, 3, 10], state: "minecraft:cave_air"},
        {pos: [9, 3, 11], state: "minecraft:deepslate_bricks"},
        {pos: [10, 3, 8], state: "minecraft:deepslate_bricks"},
        {pos: [10, 3, 9], state: "minecraft:cave_air"},
        {pos: [10, 3, 10], state: "minecraft:deepslate_bricks"},
        {pos: [11, 3, 3], state: "minecraft:deepslate_bricks"},
        {pos: [11, 3, 4], state: "minecraft:deepslate_bricks"},
        {pos: [11, 3, 8], state: "minecraft:deepslate_bricks"},
        {pos: [11, 3, 9], state: "minecraft:deepslate_bricks"},
        {pos: [11, 3, 10], state: "minecraft:deepslate_bricks"},
        {pos: [11, 3, 11], state: "minecraft:deepslate_bricks"},
        {pos: [11, 3, 12], state: "minecraft:deepslate_bricks"},
        {pos: [11, 3, 14], state: "minecraft:deepslate_bricks"},
        {pos: [11, 3, 15], state: "minecraft:deepslate_bricks"},
        {pos: [11, 3, 16], state: "minecraft:deepslate_bricks"},
        {pos: [11, 3, 17], state: "minecraft:deepslate_bricks"},
        {pos: [12, 3, 2], state: "minecraft:deepslate_bricks"},
        {pos: [12, 3, 3], state: "minecraft:cave_air"},
        {pos: [12, 3, 4], state: "minecraft:cave_air"},
        {pos: [12, 3, 5], state: "minecraft:deepslate_bricks"},
        {pos: [12, 3, 6], state: "minecraft:deepslate_bricks"},
        {pos: [12, 3, 7], state: "minecraft:deepslate_bricks"},
        {pos: [12, 3, 8], state: "minecraft:deepslate_bricks"},
        {pos: [12, 3, 9], state: "minecraft:cave_air"},
        {pos: [12, 3, 10], state: "minecraft:cave_air"},
        {pos: [12, 3, 11], state: "minecraft:cave_air"},
        {pos: [12, 3, 12], state: "minecraft:deepslate_bricks"},
        {pos: [12, 3, 13], state: "minecraft:deepslate_bricks"},
        {pos: [12, 3, 14], state: "minecraft:cave_air"},
        {pos: [12, 3, 15], state: "minecraft:cave_air"},
        {pos: [12, 3, 16], state: "minecraft:cave_air"},
        {pos: [12, 3, 17], state: "minecraft:cave_air"},
        {pos: [12, 3, 18], state: "minecraft:deepslate_bricks"},
        {pos: [13, 3, 3], state: "minecraft:deepslate_bricks"},
        {pos: [13, 3, 4], state: "minecraft:deepslate_bricks"},
        {pos: [13, 3, 5], state: "minecraft:cave_air"},
        {pos: [13, 3, 6], state: "minecraft:cave_air"},
        {pos: [13, 3, 7], state: "minecraft:deepslate_bricks"},
        {pos: [13, 3, 8], state: "minecraft:deepslate_bricks"},
        {pos: [13, 3, 9], state: "minecraft:cave_air"},
        {pos: [13, 3, 10], state: "minecraft:cave_air"},
        {pos: [13, 3, 11], state: "minecraft:cave_air"},
        {pos: [13, 3, 12], state: "minecraft:deepslate_bricks"},
        {pos: [13, 3, 14], state: "minecraft:deepslate_bricks"},
        {pos: [13, 3, 15], state: "minecraft:cave_air"},
        {pos: [13, 3, 16], state: "minecraft:cave_air"},
        {pos: [13, 3, 17], state: "minecraft:cave_air"},
        {pos: [13, 3, 18], state: "minecraft:deepslate_bricks"},
        {pos: [14, 3, 3], state: "minecraft:deepslate_bricks"},
        {pos: [14, 3, 4], state: "minecraft:cave_air"},
        {pos: [14, 3, 5], state: "minecraft:cave_air"},
        {pos: [14, 3, 6], state: "minecraft:cave_air"},
        {pos: [14, 3, 7], state: "minecraft:cave_air"},
        {pos: [14, 3, 8], state: "minecraft:deepslate_bricks"},
        {pos: [14, 3, 9], state: "minecraft:cave_air"},
        {pos: [14, 3, 10], state: "minecraft:cave_air"},
        {pos: [14, 3, 11], state: "minecraft:cave_air"},
        {pos: [14, 3, 12], state: "minecraft:deepslate_bricks"},
        {pos: [14, 3, 15], state: "minecraft:deepslate_bricks"},
        {pos: [14, 3, 16], state: "minecraft:cave_air"},
        {pos: [14, 3, 17], state: "minecraft:deepslate_bricks"},
        {pos: [15, 3, 4], state: "minecraft:deepslate_bricks"},
        {pos: [15, 3, 5], state: "minecraft:deepslate_bricks"},
        {pos: [15, 3, 6], state: "minecraft:deepslate_bricks"},
        {pos: [15, 3, 7], state: "minecraft:deepslate_bricks"},
        {pos: [15, 3, 8], state: "minecraft:deepslate_bricks"},
        {pos: [15, 3, 9], state: "minecraft:deepslate_bricks"},
        {pos: [15, 3, 10], state: "minecraft:deepslate_bricks"},
        {pos: [15, 3, 11], state: "minecraft:deepslate_bricks"},
        {pos: [15, 3, 12], state: "minecraft:deepslate_bricks"},
        {pos: [15, 3, 16], state: "minecraft:deepslate_bricks"},
        {pos: [16, 3, 8], state: "minecraft:deepslate_bricks"},
        {pos: [16, 3, 9], state: "minecraft:cave_air"},
        {pos: [16, 3, 10], state: "minecraft:deepslate_bricks"},
        {pos: [17, 3, 8], state: "minecraft:deepslate_bricks"},
        {pos: [17, 3, 9], state: "minecraft:cave_air"},
        {pos: [17, 3, 10], state: "minecraft:cave_air"},
        {pos: [17, 3, 11], state: "minecraft:deepslate_bricks"},
        {pos: [18, 3, 9], state: "minecraft:deepslate_bricks"},
        {pos: [18, 3, 10], state: "minecraft:cave_air"},
        {pos: [18, 3, 11], state: "minecraft:cave_air"},
        {pos: [18, 3, 12], state: "minecraft:deepslate_bricks"},
        {pos: [19, 3, 9], state: "minecraft:deepslate_bricks"},
        {pos: [19, 3, 10], state: "minecraft:cave_air"},
        {pos: [19, 3, 11], state: "minecraft:cave_air"},
        {pos: [19, 3, 12], state: "minecraft:deepslate_bricks"},
        {pos: [20, 3, 8], state: "minecraft:deepslate_bricks"},
        {pos: [20, 3, 9], state: "minecraft:cave_air"},
        {pos: [20, 3, 10], state: "minecraft:deepslate_bricks"},
        {pos: [20, 3, 11], state: "minecraft:deepslate_bricks"},
        {pos: [21, 3, 9], state: "minecraft:deepslate_bricks"},
        {pos: [0, 4, 8], state: "minecraft:deepslate{axis:y}"},
        {pos: [0, 4, 9], state: "minecraft:deepslate{axis:y}"},
        {pos: [0, 4, 10], state: "minecraft:deepslate{axis:y}"},
        {pos: [0, 4, 11], state: "minecraft:deepslate{axis:y}"},
        {pos: [0, 4, 12], state: "minecraft:deepslate{axis:y}"},
        {pos: [1, 4, 8], state: "minecraft:deepslate{axis:y}"},
        {pos: [1, 4, 9], state: "minecraft:deepslate{axis:y}"},
        {pos: [1, 4, 10], state: "minecraft:deepslate{axis:y}"},
        {pos: [1, 4, 11], state: "minecraft:deepslate{axis:y}"},
        {pos: [1, 4, 12], state: "minecraft:deepslate{axis:y}"},
        {pos: [2, 4, 7], state: "minecraft:deepslate{axis:y}"},
        {pos: [2, 4, 8], state: "minecraft:deepslate{axis:y}"},
        {pos: [2, 4, 9], state: "minecraft:deepslate{axis:y}"},
        {pos: [2, 4, 10], state: "minecraft:deepslate{axis:y}"},
        {pos: [2, 4, 11], state: "minecraft:deepslate{axis:y}"},
        {pos: [2, 4, 12], state: "minecraft:deepslate{axis:y}"},
        {pos: [2, 4, 13], state: "minecraft:deepslate{axis:y}"},
        {pos: [3, 4, 7], state: "minecraft:deepslate{axis:y}"},
        {pos: [3, 4, 8], state: "minecraft:deepslate{axis:y}"},
        {pos: [3, 4, 9], state: "minecraft:deepslate{axis:y}"},
        {pos: [3, 4, 10], state: "minecraft:deepslate{axis:y}"},
        {pos: [3, 4, 11], state: "minecraft:deepslate{axis:y}"},
        {pos: [3, 4, 12], state: "minecraft:deepslate{axis:y}"},
        {pos: [3, 4, 13], state: "minecraft:deepslate{axis:y}"},
        {pos: [4, 4, 0], state: "minecraft:deepslate{axis:y}"},
        {pos: [4, 4, 1], state: "minecraft:deepslate{axis:y}"},
        {pos: [4, 4, 2], state: "minecraft:deepslate{axis:y}"},
        {pos: [4, 4, 3], state: "minecraft:deepslate{axis:y}"},
        {pos: [4, 4, 4], state: "minecraft:deepslate{axis:y}"},
        {pos: [4, 4, 5], state: "minecraft:deepslate{axis:y}"},
        {pos: [4, 4, 6], state: "minecraft:deepslate{axis:y}"},
        {pos: [4, 4, 7], state: "minecraft:deepslate{axis:y}"},
        {pos: [4, 4, 8], state: "minecraft:deepslate{axis:y}"},
        {pos: [4, 4, 9], state: "minecraft:deepslate{axis:y}"},
        {pos: [4, 4, 10], state: "minecraft:deepslate{axis:y}"},
        {pos: [4, 4, 11], state: "minecraft:deepslate{axis:y}"},
        {pos: [4, 4, 12], state: "minecraft:deepslate{axis:y}"},
        {pos: [4, 4, 13], state: "minecraft:deepslate{axis:y}"},
        {pos: [4, 4, 14], state: "minecraft:deepslate{axis:y}"},
        {pos: [4, 4, 15], state: "minecraft:deepslate{axis:y}"},
        {pos: [4, 4, 16], state: "minecraft:deepslate{axis:y}"},
        {pos: [4, 4, 17], state: "minecraft:deepslate{axis:y}"},
        {pos: [4, 4, 18], state: "minecraft:deepslate{axis:y}"},
        {pos: [4, 4, 19], state: "minecraft:deepslate{axis:y}"},
        {pos: [4, 4, 20], state: "minecraft:deepslate{axis:y}"},
        {pos: [5, 4, 0], state: "minecraft:deepslate{axis:y}"},
        {pos: [5, 4, 1], state: "minecraft:deepslate{axis:y}"},
        {pos: [5, 4, 2], state: "minecraft:deepslate{axis:y}"},
        {pos: [5, 4, 3], state: "minecraft:deepslate{axis:y}"},
        {pos: [5, 4, 4], state: "minecraft:deepslate{axis:y}"},
        {pos: [5, 4, 5], state: "minecraft:deepslate{axis:y}"},
        {pos: [5, 4, 6], state: "minecraft:deepslate{axis:y}"},
        {pos: [5, 4, 7], state: "minecraft:deepslate{axis:y}"},
        {pos: [5, 4, 8], state: "minecraft:deepslate{axis:y}"},
        {pos: [5, 4, 9], state: "minecraft:deepslate{axis:y}"},
        {pos: [5, 4, 10], state: "minecraft:deepslate{axis:y}"},
        {pos: [5, 4, 11], state: "minecraft:deepslate{axis:y}"},
        {pos: [5, 4, 12], state: "minecraft:deepslate{axis:y}"},
        {pos: [5, 4, 13], state: "minecraft:deepslate{axis:y}"},
        {pos: [5, 4, 14], state: "minecraft:deepslate{axis:y}"},
        {pos: [5, 4, 15], state: "minecraft:deepslate{axis:y}"},
        {pos: [5, 4, 16], state: "minecraft:deepslate{axis:y}"},
        {pos: [5, 4, 17], state: "minecraft:deepslate{axis:y}"},
        {pos: [5, 4, 18], state: "minecraft:deepslate{axis:y}"},
        {pos: [5, 4, 19], state: "minecraft:deepslate{axis:y}"},
        {pos: [5, 4, 20], state: "minecraft:deepslate{axis:y}"},
        {pos: [6, 4, 0], state: "minecraft:deepslate{axis:y}"},
        {pos: [6, 4, 1], state: "minecraft:deepslate{axis:y}"},
        {pos: [6, 4, 2], state: "minecraft:deepslate{axis:y}"},
        {pos: [6, 4, 3], state: "minecraft:deepslate{axis:y}"},
        {pos: [6, 4, 4], state: "minecraft:deepslate{axis:y}"},
        {pos: [6, 4, 5], state: "minecraft:deepslate{axis:y}"},
        {pos: [6, 4, 6], state: "minecraft:deepslate{axis:y}"},
        {pos: [6, 4, 7], state: "minecraft:deepslate{axis:y}"},
        {pos: [6, 4, 8], state: "minecraft:deepslate{axis:y}"},
        {pos: [6, 4, 9], state: "minecraft:deepslate{axis:y}"},
        {pos: [6, 4, 10], state: "minecraft:deepslate{axis:y}"},
        {pos: [6, 4, 11], state: "minecraft:deepslate{axis:y}"},
        {pos: [6, 4, 12], state: "minecraft:deepslate{axis:y}"},
        {pos: [6, 4, 13], state: "minecraft:deepslate{axis:y}"},
        {pos: [6, 4, 14], state: "minecraft:deepslate{axis:y}"},
        {pos: [6, 4, 15], state: "minecraft:deepslate{axis:y}"},
        {pos: [6, 4, 16], state: "minecraft:deepslate{axis:y}"},
        {pos: [6, 4, 17], state: "minecraft:deepslate{axis:y}"},
        {pos: [6, 4, 18], state: "minecraft:deepslate{axis:y}"},
        {pos: [6, 4, 19], state: "minecraft:deepslate{axis:y}"},
        {pos: [6, 4, 20], state: "minecraft:deepslate{axis:y}"},
        {pos: [7, 4, 0], state: "minecraft:deepslate{axis:y}"},
        {pos: [7, 4, 1], state: "minecraft:deepslate{axis:y}"},
        {pos: [7, 4, 2], state: "minecraft:deepslate{axis:y}"},
        {pos: [7, 4, 3], state: "minecraft:deepslate{axis:y}"},
        {pos: [7, 4, 4], state: "minecraft:deepslate{axis:y}"},
        {pos: [7, 4, 5], state: "minecraft:deepslate{axis:y}"},
        {pos: [7, 4, 6], state: "minecraft:deepslate{axis:y}"},
        {pos: [7, 4, 7], state: "minecraft:deepslate{axis:y}"},
        {pos: [7, 4, 8], state: "minecraft:deepslate{axis:y}"},
        {pos: [7, 4, 9], state: "minecraft:deepslate{axis:y}"},
        {pos: [7, 4, 10], state: "minecraft:deepslate{axis:y}"},
        {pos: [7, 4, 11], state: "minecraft:deepslate{axis:y}"},
        {pos: [7, 4, 12], state: "minecraft:deepslate{axis:y}"},
        {pos: [7, 4, 13], state: "minecraft:deepslate{axis:y}"},
        {pos: [7, 4, 14], state: "minecraft:deepslate{axis:y}"},
        {pos: [7, 4, 15], state: "minecraft:deepslate{axis:y}"},
        {pos: [7, 4, 16], state: "minecraft:deepslate{axis:y}"},
        {pos: [7, 4, 17], state: "minecraft:deepslate{axis:y}"},
        {pos: [7, 4, 18], state: "minecraft:deepslate{axis:y}"},
        {pos: [7, 4, 19], state: "minecraft:deepslate{axis:y}"},
        {pos: [7, 4, 20], state: "minecraft:deepslate{axis:y}"},
        {pos: [8, 4, 0], state: "minecraft:deepslate{axis:y}"},
        {pos: [8, 4, 1], state: "minecraft:deepslate{axis:y}"},
        {pos: [8, 4, 2], state: "minecraft:deepslate{axis:y}"},
        {pos: [8, 4, 3], state: "minecraft:deepslate{axis:y}"},
        {pos: [8, 4, 4], state: "minecraft:deepslate{axis:y}"},
        {pos: [8, 4, 5], state: "minecraft:deepslate{axis:y}"},
        {pos: [8, 4, 6], state: "minecraft:deepslate{axis:y}"},
        {pos: [8, 4, 7], state: "minecraft:deepslate{axis:y}"},
        {pos: [8, 4, 8], state: "minecraft:deepslate{axis:y}"},
        {pos: [8, 4, 9], state: "minecraft:deepslate_bricks"},
        {pos: [8, 4, 10], state: "minecraft:deepslate_bricks"},
        {pos: [8, 4, 11], state: "minecraft:deepslate{axis:y}"},
        {pos: [8, 4, 12], state: "minecraft:deepslate{axis:y}"},
        {pos: [8, 4, 13], state: "minecraft:deepslate{axis:y}"},
        {pos: [8, 4, 14], state: "minecraft:deepslate{axis:y}"},
        {pos: [8, 4, 15], state: "minecraft:deepslate{axis:y}"},
        {pos: [8, 4, 16], state: "minecraft:deepslate{axis:y}"},
        {pos: [8, 4, 17], state: "minecraft:deepslate{axis:y}"},
        {pos: [8, 4, 18], state: "minecraft:deepslate{axis:y}"},
        {pos: [8, 4, 19], state: "minecraft:deepslate{axis:y}"},
        {pos: [8, 4, 20], state: "minecraft:deepslate{axis:y}"},
        {pos: [9, 4, 0], state: "minecraft:deepslate{axis:y}"},
        {pos: [9, 4, 1], state: "minecraft:deepslate{axis:y}"},
        {pos: [9, 4, 2], state: "minecraft:deepslate{axis:y}"},
        {pos: [9, 4, 3], state: "minecraft:deepslate{axis:y}"},
        {pos: [9, 4, 4], state: "minecraft:deepslate{axis:y}"},
        {pos: [9, 4, 5], state: "minecraft:deepslate{axis:y}"},
        {pos: [9, 4, 6], state: "minecraft:deepslate{axis:y}"},
        {pos: [9, 4, 7], state: "minecraft:deepslate{axis:y}"},
        {pos: [9, 4, 8], state: "minecraft:deepslate_bricks"},
        {pos: [9, 4, 9], state: "minecraft:cave_air"},
        {pos: [9, 4, 10], state: "minecraft:cave_air"},
        {pos: [9, 4, 11], state: "minecraft:deepslate_bricks"},
        {pos: [9, 4, 12], state: "minecraft:deepslate{axis:y}"},
        {pos: [9, 4, 13], state: "minecraft:deepslate{axis:y}"},
        {pos: [9, 4, 14], state: "minecraft:deepslate{axis:y}"},
        {pos: [9, 4, 15], state: "minecraft:deepslate{axis:y}"},
        {pos: [9, 4, 16], state: "minecraft:deepslate{axis:y}"},
        {pos: [9, 4, 17], state: "minecraft:deepslate{axis:y}"},
        {pos: [9, 4, 18], state: "minecraft:deepslate{axis:y}"},
        {pos: [9, 4, 19], state: "minecraft:deepslate{axis:y}"},
        {pos: [9, 4, 20], state: "minecraft:deepslate{axis:y}"},
        {pos: [10, 4, 0], state: "minecraft:deepslate{axis:y}"},
        {pos: [10, 4, 1], state: "minecraft:deepslate{axis:y}"},
        {pos: [10, 4, 2], state: "minecraft:deepslate{axis:y}"},
        {pos: [10, 4, 3], state: "minecraft:deepslate{axis:y}"},
        {pos: [10, 4, 4], state: "minecraft:deepslate{axis:y}"},
        {pos: [10, 4, 5], state: "minecraft:deepslate{axis:y}"},
        {pos: [10, 4, 6], state: "minecraft:deepslate{axis:y}"},
        {pos: [10, 4, 7], state: "minecraft:deepslate{axis:y}"},
        {pos: [10, 4, 8], state: "minecraft:deepslate_bricks"},
        {pos: [10, 4, 9], state: "minecraft:cave_air"},
        {pos: [10, 4, 10], state: "minecraft:deepslate_bricks"},
        {pos: [10, 4, 11], state: "minecraft:deepslate{axis:y}"},
        {pos: [10, 4, 12], state: "minecraft:deepslate{axis:y}"},
        {pos: [10, 4, 13], state: "minecraft:deepslate{axis:y}"},
        {pos: [10, 4, 14], state: "minecraft:deepslate{axis:y}"},
        {pos: [10, 4, 15], state: "minecraft:deepslate{axis:y}"},
        {pos: [10, 4, 16], state: "minecraft:deepslate{axis:y}"},
        {pos: [10, 4, 17], state: "minecraft:deepslate{axis:y}"},
        {pos: [10, 4, 18], state: "minecraft:deepslate{axis:y}"},
        {pos: [10, 4, 19], state: "minecraft:deepslate{axis:y}"},
        {pos: [10, 4, 20], state: "minecraft:deepslate{axis:y}"},
        {pos: [11, 4, 0], state: "minecraft:deepslate{axis:y}"},
        {pos: [11, 4, 1], state: "minecraft:deepslate{axis:y}"},
        {pos: [11, 4, 2], state: "minecraft:deepslate{axis:y}"},
        {pos: [11, 4, 3], state: "minecraft:deepslate_bricks"},
        {pos: [11, 4, 4], state: "minecraft:deepslate_bricks"},
        {pos: [11, 4, 5], state: "minecraft:deepslate{axis:y}"},
        {pos: [11, 4, 6], state: "minecraft:deepslate{axis:y}"},
        {pos: [11, 4, 7], state: "minecraft:deepslate{axis:y}"},
        {pos: [11, 4, 8], state: "minecraft:deepslate{axis:y}"},
        {pos: [11, 4, 9], state: "minecraft:deepslate_bricks"},
        {pos: [11, 4, 10], state: "minecraft:deepslate_bricks"},
        {pos: [11, 4, 11], state: "minecraft:deepslate_bricks"},
        {pos: [11, 4, 12], state: "minecraft:deepslate{axis:y}"},
        {pos: [11, 4, 13], state: "minecraft:deepslate{axis:y}"},
        {pos: [11, 4, 14], state: "minecraft:deepslate_bricks"},
        {pos: [11, 4, 15], state: "minecraft:deepslate_bricks"},
        {pos: [11, 4, 16], state: "minecraft:deepslate_bricks"},
        {pos: [11, 4, 17], state: "minecraft:deepslate_bricks"},
        {pos: [11, 4, 18], state: "minecraft:deepslate{axis:y}"},
        {pos: [11, 4, 19], state: "minecraft:deepslate{axis:y}"},
        {pos: [11, 4, 20], state: "minecraft:deepslate{axis:y}"},
        {pos: [12, 4, 0], state: "minecraft:deepslate{axis:y}"},
        {pos: [12, 4, 1], state: "minecraft:deepslate{axis:y}"},
        {pos: [12, 4, 2], state: "minecraft:deepslate_bricks"},
        {pos: [12, 4, 3], state: "minecraft:cave_air"},
        {pos: [12, 4, 4], state: "minecraft:cave_air"},
        {pos: [12, 4, 5], state: "minecraft:deepslate_bricks"},
        {pos: [12, 4, 6], state: "minecraft:deepslate_bricks"},
        {pos: [12, 4, 7], state: "minecraft:deepslate{axis:y}"},
        {pos: [12, 4, 8], state: "minecraft:deepslate_bricks"},
        {pos: [12, 4, 9], state: "minecraft:cave_air"},
        {pos: [12, 4, 10], state: "minecraft:cave_air"},
        {pos: [12, 4, 11], state: "minecraft:cave_air"},
        {pos: [12, 4, 12], state: "minecraft:deepslate_bricks"},
        {pos: [12, 4, 13], state: "minecraft:deepslate_bricks"},
        {pos: [12, 4, 14], state: "minecraft:cave_air"},
        {pos: [12, 4, 15], state: "minecraft:cave_air"},
        {pos: [12, 4, 16], state: "minecraft:cave_air"},
        {pos: [12, 4, 17], state: "minecraft:cave_air"},
        {pos: [12, 4, 18], state: "minecraft:deepslate_bricks"},
        {pos: [12, 4, 19], state: "minecraft:deepslate{axis:y}"},
        {pos: [12, 4, 20], state: "minecraft:deepslate{axis:y}"},
        {pos: [13, 4, 0], state: "minecraft:deepslate{axis:y}"},
        {pos: [13, 4, 1], state: "minecraft:deepslate{axis:y}"},
        {pos: [13, 4, 2], state: "minecraft:deepslate{axis:y}"},
        {pos: [13, 4, 3], state: "minecraft:deepslate_bricks"},
        {pos: [13, 4, 4], state: "minecraft:deepslate_bricks"},
        {pos: [13, 4, 5], state: "minecraft:cave_air"},
        {pos: [13, 4, 6], state: "minecraft:cave_air"},
        {pos: [13, 4, 7], state: "minecraft:deepslate_bricks"},
        {pos: [13, 4, 8], state: "minecraft:deepslate_bricks"},
        {pos: [13, 4, 9], state: "minecraft:cave_air"},
        {pos: [13, 4, 10], state: "minecraft:cave_air"},
        {pos: [13, 4, 11], state: "minecraft:cave_air"},
        {pos: [13, 4, 12], state: "minecraft:deepslate_bricks"},
        {pos: [13, 4, 13], state: "minecraft:deepslate{axis:y}"},
        {pos: [13, 4, 14], state: "minecraft:deepslate_bricks"},
        {pos: [13, 4, 15], state: "minecraft:cave_air"},
        {pos: [13, 4, 16], state: "minecraft:cave_air"},
        {pos: [13, 4, 17], state: "minecraft:cave_air"},
        {pos: [13, 4, 18], state: "minecraft:deepslate_bricks"},
        {pos: [13, 4, 19], state: "minecraft:deepslate{axis:y}"},
        {pos: [13, 4, 20], state: "minecraft:deepslate{axis:y}"},
        {pos: [14, 4, 0], state: "minecraft:deepslate{axis:y}"},
        {pos: [14, 4, 1], state: "minecraft:deepslate{axis:y}"},
        {pos: [14, 4, 2], state: "minecraft:deepslate{axis:y}"},
        {pos: [14, 4, 3], state: "minecraft:deepslate_bricks"},
        {pos: [14, 4, 4], state: "minecraft:cave_air"},
        {pos: [14, 4, 5], state: "minecraft:cave_air"},
        {pos: [14, 4, 6], state: "minecraft:cave_air"},
        {pos: [14, 4, 7], state: "minecraft:cave_air"},
        {pos: [14, 4, 8], state: "minecraft:deepslate_bricks"},
        {pos: [14, 4, 9], state: "minecraft:cave_air"},
        {pos: [14, 4, 10], state: "minecraft:cave_air"},
        {pos: [14, 4, 11], state: "minecraft:cave_air"},
        {pos: [14, 4, 12], state: "minecraft:deepslate_bricks"},
        {pos: [14, 4, 13], state: "minecraft:deepslate{axis:y}"},
        {pos: [14, 4, 14], state: "minecraft:deepslate{axis:y}"},
        {pos: [14, 4, 15], state: "minecraft:deepslate_bricks"},
        {pos: [14, 4, 16], state: "minecraft:cave_air"},
        {pos: [14, 4, 17], state: "minecraft:deepslate_bricks"},
        {pos: [14, 4, 18], state: "minecraft:deepslate{axis:y}"},
        {pos: [14, 4, 19], state: "minecraft:deepslate{axis:y}"},
        {pos: [14, 4, 20], state: "minecraft:deepslate{axis:y}"},
        {pos: [15, 4, 0], state: "minecraft:deepslate{axis:y}"},
        {pos: [15, 4, 1], state: "minecraft:deepslate{axis:y}"},
        {pos: [15, 4, 2], state: "minecraft:deepslate{axis:y}"},
        {pos: [15, 4, 3], state: "minecraft:deepslate_bricks"},
        {pos: [15, 4, 4], state: "minecraft:deepslate_bricks"},
        {pos: [15, 4, 5], state: "minecraft:deepslate_bricks"},
        {pos: [15, 4, 6], state: "minecraft:deepslate_bricks"},
        {pos: [15, 4, 7], state: "minecraft:deepslate_bricks"},
        {pos: [15, 4, 8], state: "minecraft:deepslate{axis:y}"},
        {pos: [15, 4, 9], state: "minecraft:deepslate_bricks"},
        {pos: [15, 4, 10], state: "minecraft:deepslate_bricks"},
        {pos: [15, 4, 11], state: "minecraft:deepslate_bricks"},
        {pos: [15, 4, 12], state: "minecraft:deepslate{axis:y}"},
        {pos: [15, 4, 13], state: "minecraft:deepslate{axis:y}"},
        {pos: [15, 4, 14], state: "minecraft:deepslate{axis:y}"},
        {pos: [15, 4, 15], state: "minecraft:deepslate{axis:y}"},
        {pos: [15, 4, 16], state: "minecraft:deepslate_bricks"},
        {pos: [15, 4, 17], state: "minecraft:deepslate{axis:y}"},
        {pos: [15, 4, 18], state: "minecraft:deepslate{axis:y}"},
        {pos: [15, 4, 19], state: "minecraft:deepslate{axis:y}"},
        {pos: [15, 4, 20], state: "minecraft:deepslate{axis:y}"},
        {pos: [16, 4, 0], state: "minecraft:deepslate{axis:y}"},
        {pos: [16, 4, 1], state: "minecraft:deepslate{axis:y}"},
        {pos: [16, 4, 2], state: "minecraft:deepslate{axis:y}"},
        {pos: [16, 4, 3], state: "minecraft:deepslate{axis:y}"},
        {pos: [16, 4, 4], state: "minecraft:deepslate{axis:y}"},
        {pos: [16, 4, 5], state: "minecraft:deepslate{axis:y}"},
        {pos: [16, 4, 6], state: "minecraft:deepslate{axis:y}"},
        {pos: [16, 4, 7], state: "minecraft:deepslate{axis:y}"},
        {pos: [16, 4, 8], state: "minecraft:deepslate_bricks"},
        {pos: [16, 4, 9], state: "minecraft:cave_air"},
        {pos: [16, 4, 10], state: "minecraft:deepslate_bricks"},
        {pos: [16, 4, 11], state: "minecraft:deepslate{axis:y}"},
        {pos: [16, 4, 12], state: "minecraft:deepslate{axis:y}"},
        {pos: [16, 4, 13], state: "minecraft:deepslate{axis:y}"},
        {pos: [16, 4, 14], state: "minecraft:deepslate{axis:y}"},
        {pos: [16, 4, 15], state: "minecraft:deepslate{axis:y}"},
        {pos: [16, 4, 16], state: "minecraft:deepslate{axis:y}"},
        {pos: [16, 4, 17], state: "minecraft:deepslate{axis:y}"},
        {pos: [16, 4, 18], state: "minecraft:deepslate{axis:y}"},
        {pos: [16, 4, 19], state: "minecraft:deepslate{axis:y}"},
        {pos: [16, 4, 20], state: "minecraft:deepslate{axis:y}"},
        {pos: [17, 4, 0], state: "minecraft:deepslate{axis:y}"},
        {pos: [17, 4, 1], state: "minecraft:deepslate{axis:y}"},
        {pos: [17, 4, 2], state: "minecraft:deepslate{axis:y}"},
        {pos: [17, 4, 3], state: "minecraft:deepslate{axis:y}"},
        {pos: [17, 4, 4], state: "minecraft:deepslate{axis:y}"},
        {pos: [17, 4, 5], state: "minecraft:deepslate{axis:y}"},
        {pos: [17, 4, 6], state: "minecraft:deepslate{axis:y}"},
        {pos: [17, 4, 7], state: "minecraft:deepslate{axis:y}"},
        {pos: [17, 4, 8], state: "minecraft:deepslate_bricks"},
        {pos: [17, 4, 9], state: "minecraft:cave_air"},
        {pos: [17, 4, 10], state: "minecraft:cave_air"},
        {pos: [17, 4, 11], state: "minecraft:deepslate_bricks"},
        {pos: [17, 4, 12], state: "minecraft:deepslate{axis:y}"},
        {pos: [17, 4, 13], state: "minecraft:deepslate{axis:y}"},
        {pos: [17, 4, 14], state: "minecraft:deepslate{axis:y}"},
        {pos: [17, 4, 15], state: "minecraft:deepslate{axis:y}"},
        {pos: [17, 4, 16], state: "minecraft:deepslate{axis:y}"},
        {pos: [17, 4, 17], state: "minecraft:deepslate{axis:y}"},
        {pos: [17, 4, 18], state: "minecraft:deepslate{axis:y}"},
        {pos: [17, 4, 19], state: "minecraft:deepslate{axis:y}"},
        {pos: [17, 4, 20], state: "minecraft:deepslate{axis:y}"},
        {pos: [18, 4, 0], state: "minecraft:deepslate{axis:y}"},
        {pos: [18, 4, 1], state: "minecraft:deepslate{axis:y}"},
        {pos: [18, 4, 2], state: "minecraft:deepslate{axis:y}"},
        {pos: [18, 4, 3], state: "minecraft:deepslate{axis:y}"},
        {pos: [18, 4, 4], state: "minecraft:deepslate{axis:y}"},
        {pos: [18, 4, 5], state: "minecraft:deepslate{axis:y}"},
        {pos: [18, 4, 6], state: "minecraft:deepslate{axis:y}"},
        {pos: [18, 4, 7], state: "minecraft:deepslate{axis:y}"},
        {pos: [18, 4, 8], state: "minecraft:deepslate{axis:y}"},
        {pos: [18, 4, 9], state: "minecraft:deepslate_bricks"},
        {pos: [18, 4, 10], state: "minecraft:cave_air"},
        {pos: [18, 4, 11], state: "minecraft:cave_air"},
        {pos: [18, 4, 12], state: "minecraft:deepslate_bricks"},
        {pos: [18, 4, 13], state: "minecraft:deepslate{axis:y}"},
        {pos: [18, 4, 14], state: "minecraft:deepslate{axis:y}"},
        {pos: [18, 4, 15], state: "minecraft:deepslate{axis:y}"},
        {pos: [18, 4, 16], state: "minecraft:deepslate{axis:y}"},
        {pos: [18, 4, 17], state: "minecraft:deepslate{axis:y}"},
        {pos: [18, 4, 18], state: "minecraft:deepslate{axis:y}"},
        {pos: [18, 4, 19], state: "minecraft:deepslate{axis:y}"},
        {pos: [18, 4, 20], state: "minecraft:deepslate{axis:y}"},
        {pos: [19, 4, 0], state: "minecraft:deepslate{axis:y}"},
        {pos: [19, 4, 1], state: "minecraft:deepslate{axis:y}"},
        {pos: [19, 4, 2], state: "minecraft:deepslate{axis:y}"},
        {pos: [19, 4, 3], state: "minecraft:deepslate{axis:y}"},
        {pos: [19, 4, 4], state: "minecraft:deepslate{axis:y}"},
        {pos: [19, 4, 5], state: "minecraft:deepslate{axis:y}"},
        {pos: [19, 4, 6], state: "minecraft:deepslate{axis:y}"},
        {pos: [19, 4, 7], state: "minecraft:deepslate{axis:y}"},
        {pos: [19, 4, 8], state: "minecraft:deepslate{axis:y}"},
        {pos: [19, 4, 9], state: "minecraft:deepslate_bricks"},
        {pos: [19, 4, 10], state: "minecraft:cave_air"},
        {pos: [19, 4, 11], state: "minecraft:cave_air"},
        {pos: [19, 4, 12], state: "minecraft:deepslate_bricks"},
        {pos: [19, 4, 13], state: "minecraft:deepslate{axis:y}"},
        {pos: [19, 4, 14], state: "minecraft:deepslate{axis:y}"},
        {pos: [19, 4, 15], state: "minecraft:deepslate{axis:y}"},
        {pos: [19, 4, 16], state: "minecraft:deepslate{axis:y}"},
        {pos: [19, 4, 17], state: "minecraft:deepslate{axis:y}"},
        {pos: [19, 4, 18], state: "minecraft:deepslate{axis:y}"},
        {pos: [19, 4, 19], state: "minecraft:deepslate{axis:y}"},
        {pos: [19, 4, 20], state: "minecraft:deepslate{axis:y}"},
        {pos: [20, 4, 0], state: "minecraft:deepslate{axis:y}"},
        {pos: [20, 4, 1], state: "minecraft:deepslate{axis:y}"},
        {pos: [20, 4, 2], state: "minecraft:deepslate{axis:y}"},
        {pos: [20, 4, 3], state: "minecraft:deepslate{axis:y}"},
        {pos: [20, 4, 4], state: "minecraft:deepslate{axis:y}"},
        {pos: [20, 4, 5], state: "minecraft:deepslate{axis:y}"},
        {pos: [20, 4, 6], state: "minecraft:deepslate{axis:y}"},
        {pos: [20, 4, 7], state: "minecraft:deepslate{axis:y}"},
        {pos: [20, 4, 8], state: "minecraft:deepslate_bricks"},
        {pos: [20, 4, 9], state: "minecraft:cave_air"},
        {pos: [20, 4, 10], state: "minecraft:deepslate_bricks"},
        {pos: [20, 4, 11], state: "minecraft:deepslate_bricks"},
        {pos: [20, 4, 12], state: "minecraft:deepslate{axis:y}"},
        {pos: [20, 4, 13], state: "minecraft:deepslate{axis:y}"},
        {pos: [20, 4, 14], state: "minecraft:deepslate{axis:y}"},
        {pos: [20, 4, 15], state: "minecraft:deepslate{axis:y}"},
        {pos: [20, 4, 16], state: "minecraft:deepslate{axis:y}"},
        {pos: [20, 4, 17], state: "minecraft:deepslate{axis:y}"},
        {pos: [20, 4, 18], state: "minecraft:deepslate{axis:y}"},
        {pos: [20, 4, 19], state: "minecraft:deepslate{axis:y}"},
        {pos: [20, 4, 20], state: "minecraft:deepslate{axis:y}"},
        {pos: [21, 4, 0], state: "minecraft:deepslate{axis:y}"},
        {pos: [21, 4, 1], state: "minecraft:deepslate{axis:y}"},
        {pos: [21, 4, 2], state: "minecraft:deepslate{axis:y}"},
        {pos: [21, 4, 3], state: "minecraft:deepslate{axis:y}"},
        {pos: [21, 4, 4], state: "minecraft:deepslate{axis:y}"},
        {pos: [21, 4, 5], state: "minecraft:deepslate{axis:y}"},
        {pos: [21, 4, 6], state: "minecraft:deepslate{axis:y}"},
        {pos: [21, 4, 7], state: "minecraft:deepslate{axis:y}"},
        {pos: [21, 4, 8], state: "minecraft:deepslate{axis:y}"},
        {pos: [21, 4, 9], state: "minecraft:deepslate_bricks"},
        {pos: [21, 4, 10], state: "minecraft:deepslate{axis:y}"},
        {pos: [21, 4, 11], state: "minecraft:deepslate{axis:y}"},
        {pos: [21, 4, 12], state: "minecraft:deepslate{axis:y}"},
        {pos: [21, 4, 13], state: "minecraft:deepslate{axis:y}"},
        {pos: [21, 4, 14], state: "minecraft:deepslate{axis:y}"},
        {pos: [21, 4, 15], state: "minecraft:deepslate{axis:y}"},
        {pos: [21, 4, 16], state: "minecraft:deepslate{axis:y}"},
        {pos: [21, 4, 17], state: "minecraft:deepslate{axis:y}"},
        {pos: [21, 4, 18], state: "minecraft:deepslate{axis:y}"},
        {pos: [21, 4, 19], state: "minecraft:deepslate{axis:y}"},
        {pos: [21, 4, 20], state: "minecraft:deepslate{axis:y}"},
        {pos: [22, 4, 0], state: "minecraft:deepslate{axis:y}"},
        {pos: [22, 4, 1], state: "minecraft:deepslate{axis:y}"},
        {pos: [22, 4, 2], state: "minecraft:deepslate{axis:y}"},
        {pos: [22, 4, 3], state: "minecraft:deepslate{axis:y}"},
        {pos: [22, 4, 4], state: "minecraft:deepslate{axis:y}"},
        {pos: [22, 4, 5], state: "minecraft:deepslate{axis:y}"},
        {pos: [22, 4, 6], state: "minecraft:deepslate{axis:y}"},
        {pos: [22, 4, 7], state: "minecraft:deepslate{axis:y}"},
        {pos: [22, 4, 8], state: "minecraft:deepslate{axis:y}"},
        {pos: [22, 4, 9], state: "minecraft:deepslate{axis:y}"},
        {pos: [22, 4, 10], state: "minecraft:deepslate{axis:y}"},
        {pos: [22, 4, 11], state: "minecraft:deepslate{axis:y}"},
        {pos: [22, 4, 12], state: "minecraft:deepslate{axis:y}"},
        {pos: [22, 4, 13], state: "minecraft:deepslate{axis:y}"},
        {pos: [22, 4, 14], state: "minecraft:deepslate{axis:y}"},
        {pos: [22, 4, 15], state: "minecraft:deepslate{axis:y}"},
        {pos: [22, 4, 16], state: "minecraft:deepslate{axis:y}"},
        {pos: [22, 4, 17], state: "minecraft:deepslate{axis:y}"},
        {pos: [22, 4, 18], state: "minecraft:deepslate{axis:y}"},
        {pos: [22, 4, 19], state: "minecraft:deepslate{axis:y}"},
        {pos: [22, 4, 20], state: "minecraft:deepslate{axis:y}"},
        {pos: [23, 4, 7], state: "minecraft:deepslate{axis:y}"},
        {pos: [23, 4, 8], state: "minecraft:deepslate{axis:y}"},
        {pos: [23, 4, 9], state: "minecraft:deepslate{axis:y}"},
        {pos: [23, 4, 10], state: "minecraft:deepslate{axis:y}"},
        {pos: [23, 4, 11], state: "minecraft:deepslate{axis:y}"},
        {pos: [23, 4, 12], state: "minecraft:deepslate{axis:y}"},
        {pos: [23, 4, 13], state: "minecraft:deepslate{axis:y}"},
        {pos: [24, 4, 7], state: "minecraft:deepslate{axis:y}"},
        {pos: [24, 4, 8], state: "minecraft:deepslate{axis:y}"},
        {pos: [24, 4, 9], state: "minecraft:deepslate{axis:y}"},
        {pos: [24, 4, 10], state: "minecraft:deepslate{axis:y}"},
        {pos: [24, 4, 11], state: "minecraft:deepslate{axis:y}"},
        {pos: [24, 4, 12], state: "minecraft:deepslate{axis:y}"},
        {pos: [24, 4, 13], state: "minecraft:deepslate{axis:y}"},
        {pos: [25, 4, 8], state: "minecraft:deepslate{axis:y}"},
        {pos: [25, 4, 9], state: "minecraft:deepslate{axis:y}"},
        {pos: [25, 4, 10], state: "minecraft:deepslate{axis:y}"},
        {pos: [25, 4, 11], state: "minecraft:deepslate{axis:y}"},
        {pos: [25, 4, 12], state: "minecraft:deepslate{axis:y}"},
        {pos: [26, 4, 8], state: "minecraft:deepslate{axis:y}"},
        {pos: [26, 4, 9], state: "minecraft:deepslate{axis:y}"},
        {pos: [26, 4, 10], state: "minecraft:deepslate{axis:y}"},
        {pos: [26, 4, 11], state: "minecraft:deepslate{axis:y}"},
        {pos: [26, 4, 12], state: "minecraft:deepslate{axis:y}"},
        {pos: [0, 5, 8], state: "minecraft:deepslate_bricks"},
        {pos: [0, 5, 9], state: "minecraft:gravel"},
        {pos: [0, 5, 10], state: "minecraft:gravel"},
        {pos: [0, 5, 11], state: "minecraft:gravel"},
        {pos: [0, 5, 12], state: "minecraft:deepslate_bricks"},
        {pos: [1, 5, 8], state: "minecraft:deepslate_bricks"},
        {pos: [1, 5, 9], state: "minecraft:gravel"},
        {pos: [1, 5, 10], state: "minecraft:gravel"},
        {pos: [1, 5, 11], state: "minecraft:gravel"},
        {pos: [1, 5, 12], state: "minecraft:deepslate_bricks"},
        {pos: [2, 5, 7], state: "minecraft:deepslate_bricks"},
        {pos: [2, 5, 8], state: "minecraft:deepslate_bricks"},
        {pos: [2, 5, 9], state: "minecraft:gravel"},
        {pos: [2, 5, 10], state: "minecraft:gravel"},
        {pos: [2, 5, 11], state: "minecraft:gravel"},
        {pos: [2, 5, 12], state: "minecraft:deepslate_bricks"},
        {pos: [2, 5, 13], state: "minecraft:deepslate_bricks"},
        {pos: [3, 5, 7], state: "minecraft:deepslate_bricks"},
        {pos: [3, 5, 8], state: "minecraft:gravel"},
        {pos: [3, 5, 9], state: "minecraft:gravel"},
        {pos: [3, 5, 10], state: "minecraft:gravel"},
        {pos: [3, 5, 11], state: "minecraft:gravel"},
        {pos: [3, 5, 12], state: "minecraft:gravel"},
        {pos: [3, 5, 13], state: "minecraft:deepslate_bricks"},
        {pos: [4, 5, 0], state: "minecraft:deepslate_bricks"},
        {pos: [4, 5, 1], state: "minecraft:deepslate_bricks"},
        {pos: [4, 5, 2], state: "minecraft:deepslate_bricks"},
        {pos: [4, 5, 3], state: "minecraft:deepslate_bricks"},
        {pos: [4, 5, 4], state: "minecraft:deepslate_bricks"},
        {pos: [4, 5, 5], state: "minecraft:deepslate_bricks"},
        {pos: [4, 5, 6], state: "minecraft:deepslate_bricks"},
        {pos: [4, 5, 7], state: "minecraft:gravel"},
        {pos: [4, 5, 8], state: "minecraft:gravel"},
        {pos: [4, 5, 9], state: "minecraft:gravel"},
        {pos: [4, 5, 10], state: "minecraft:gravel"},
        {pos: [4, 5, 11], state: "minecraft:gravel"},
        {pos: [4, 5, 12], state: "minecraft:gravel"},
        {pos: [4, 5, 13], state: "minecraft:gravel"},
        {pos: [4, 5, 14], state: "minecraft:deepslate_bricks"},
        {pos: [4, 5, 15], state: "minecraft:deepslate_bricks"},
        {pos: [4, 5, 16], state: "minecraft:deepslate_bricks"},
        {pos: [4, 5, 17], state: "minecraft:deepslate_bricks"},
        {pos: [4, 5, 18], state: "minecraft:deepslate_bricks"},
        {pos: [4, 5, 19], state: "minecraft:deepslate_bricks"},
        {pos: [4, 5, 20], state: "minecraft:deepslate_bricks"},
        {pos: [5, 5, 0], state: "minecraft:deepslate_bricks"},
        {pos: [5, 5, 1], state: "minecraft:gravel"},
        {pos: [5, 5, 2], state: "minecraft:gravel"},
        {pos: [5, 5, 3], state: "minecraft:gravel"},
        {pos: [5, 5, 4], state: "minecraft:gravel"},
        {pos: [5, 5, 5], state: "minecraft:gravel"},
        {pos: [5, 5, 6], state: "minecraft:gravel"},
        {pos: [5, 5, 7], state: "minecraft:gravel"},
        {pos: [5, 5, 8], state: "minecraft:gravel"},
        {pos: [5, 5, 9], state: "minecraft:gravel"},
        {pos: [5, 5, 10], state: "minecraft:gravel"},
        {pos: [5, 5, 11], state: "minecraft:gravel"},
        {pos: [5, 5, 12], state: "minecraft:gravel"},
        {pos: [5, 5, 13], state: "minecraft:gravel"},
        {pos: [5, 5, 14], state: "minecraft:gravel"},
        {pos: [5, 5, 15], state: "minecraft:gravel"},
        {pos: [5, 5, 16], state: "minecraft:gravel"},
        {pos: [5, 5, 17], state: "minecraft:gravel"},
        {pos: [5, 5, 18], state: "minecraft:gravel"},
        {pos: [5, 5, 19], state: "minecraft:gravel"},
        {pos: [5, 5, 20], state: "minecraft:deepslate_bricks"},
        {pos: [6, 5, 0], state: "minecraft:deepslate_bricks"},
        {pos: [6, 5, 1], state: "minecraft:gravel"},
        {pos: [6, 5, 2], state: "minecraft:gravel"},
        {pos: [6, 5, 3], state: "minecraft:gravel"},
        {pos: [6, 5, 4], state: "minecraft:gravel"},
        {pos: [6, 5, 5], state: "minecraft:gravel"},
        {pos: [6, 5, 6], state: "minecraft:gravel"},
        {pos: [6, 5, 7], state: "minecraft:gravel"},
        {pos: [6, 5, 8], state: "minecraft:gravel"},
        {pos: [6, 5, 9], state: "minecraft:gravel"},
        {pos: [6, 5, 10], state: "minecraft:gravel"},
        {pos: [6, 5, 11], state: "minecraft:gravel"},
        {pos: [6, 5, 12], state: "minecraft:gravel"},
        {pos: [6, 5, 13], state: "minecraft:gravel"},
        {pos: [6, 5, 14], state: "minecraft:gravel"},
        {pos: [6, 5, 15], state: "minecraft:gravel"},
        {pos: [6, 5, 16], state: "minecraft:gravel"},
        {pos: [6, 5, 17], state: "minecraft:gravel"},
        {pos: [6, 5, 18], state: "minecraft:gravel"},
        {pos: [6, 5, 19], state: "minecraft:gravel"},
        {pos: [6, 5, 20], state: "minecraft:deepslate_bricks"},
        {pos: [7, 5, 0], state: "minecraft:deepslate_bricks"},
        {pos: [7, 5, 1], state: "minecraft:gravel"},
        {pos: [7, 5, 2], state: "minecraft:gravel"},
        {pos: [7, 5, 3], state: "minecraft:gravel"},
        {pos: [7, 5, 4], state: "minecraft:gravel"},
        {pos: [7, 5, 5], state: "minecraft:gravel"},
        {pos: [7, 5, 6], state: "minecraft:gravel"},
        {pos: [7, 5, 7], state: "minecraft:gravel"},
        {pos: [7, 5, 8], state: "minecraft:gravel"},
        {pos: [7, 5, 9], state: "minecraft:gravel"},
        {pos: [7, 5, 10], state: "minecraft:gravel"},
        {pos: [7, 5, 11], state: "minecraft:gravel"},
        {pos: [7, 5, 12], state: "minecraft:gravel"},
        {pos: [7, 5, 13], state: "minecraft:gravel"},
        {pos: [7, 5, 14], state: "minecraft:gravel"},
        {pos: [7, 5, 15], state: "minecraft:gravel"},
        {pos: [7, 5, 16], state: "minecraft:gravel"},
        {pos: [7, 5, 17], state: "minecraft:gravel"},
        {pos: [7, 5, 18], state: "minecraft:gravel"},
        {pos: [7, 5, 19], state: "minecraft:gravel"},
        {pos: [7, 5, 20], state: "minecraft:deepslate_bricks"},
        {pos: [8, 5, 0], state: "minecraft:deepslate_bricks"},
        {pos: [8, 5, 1], state: "minecraft:gravel"},
        {pos: [8, 5, 2], state: "minecraft:gravel"},
        {pos: [8, 5, 3], state: "minecraft:gravel"},
        {pos: [8, 5, 4], state: "minecraft:gravel"},
        {pos: [8, 5, 5], state: "minecraft:gravel"},
        {pos: [8, 5, 6], state: "minecraft:gravel"},
        {pos: [8, 5, 7], state: "minecraft:gravel"},
        {pos: [8, 5, 8], state: "minecraft:gravel"},
        {pos: [8, 5, 9], state: "minecraft:gravel"},
        {pos: [8, 5, 10], state: "minecraft:gravel"},
        {pos: [8, 5, 11], state: "minecraft:gravel"},
        {pos: [8, 5, 12], state: "minecraft:gravel"},
        {pos: [8, 5, 13], state: "minecraft:gravel"},
        {pos: [8, 5, 14], state: "minecraft:gravel"},
        {pos: [8, 5, 15], state: "minecraft:gravel"},
        {pos: [8, 5, 16], state: "minecraft:gravel"},
        {pos: [8, 5, 17], state: "minecraft:gravel"},
        {pos: [8, 5, 18], state: "minecraft:gravel"},
        {pos: [8, 5, 19], state: "minecraft:gravel"},
        {pos: [8, 5, 20], state: "minecraft:deepslate_bricks"},
        {pos: [9, 5, 0], state: "minecraft:deepslate_bricks"},
        {pos: [9, 5, 1], state: "minecraft:gravel"},
        {pos: [9, 5, 2], state: "minecraft:gravel"},
        {pos: [9, 5, 3], state: "minecraft:gravel"},
        {pos: [9, 5, 4], state: "minecraft:gravel"},
        {pos: [9, 5, 5], state: "minecraft:gravel"},
        {pos: [9, 5, 6], state: "minecraft:gravel"},
        {pos: [9, 5, 7], state: "minecraft:gravel"},
        {pos: [9, 5, 8], state: "minecraft:gravel"},
        {pos: [9, 5, 9], state: "minecraft:cave_air"},
        {pos: [9, 5, 10], state: "minecraft:cave_air"},
        {pos: [9, 5, 11], state: "minecraft:gravel"},
        {pos: [9, 5, 12], state: "minecraft:gravel"},
        {pos: [9, 5, 13], state: "minecraft:gravel"},
        {pos: [9, 5, 14], state: "minecraft:gravel"},
        {pos: [9, 5, 15], state: "minecraft:gravel"},
        {pos: [9, 5, 16], state: "minecraft:gravel"},
        {pos: [9, 5, 17], state: "minecraft:gravel"},
        {pos: [9, 5, 18], state: "minecraft:gravel"},
        {pos: [9, 5, 19], state: "minecraft:gravel"},
        {pos: [9, 5, 20], state: "minecraft:deepslate_bricks"},
        {pos: [10, 5, 0], state: "minecraft:deepslate_bricks"},
        {pos: [10, 5, 1], state: "minecraft:gravel"},
        {pos: [10, 5, 2], state: "minecraft:gravel"},
        {pos: [10, 5, 3], state: "minecraft:gravel"},
        {pos: [10, 5, 4], state: "minecraft:gravel"},
        {pos: [10, 5, 5], state: "minecraft:gravel"},
        {pos: [10, 5, 6], state: "minecraft:gravel"},
        {pos: [10, 5, 7], state: "minecraft:gravel"},
        {pos: [10, 5, 8], state: "minecraft:gravel"},
        {pos: [10, 5, 9], state: "minecraft:cave_air"},
        {pos: [10, 5, 10], state: "minecraft:gravel"},
        {pos: [10, 5, 11], state: "minecraft:gravel"},
        {pos: [10, 5, 12], state: "minecraft:gravel"},
        {pos: [10, 5, 13], state: "minecraft:gravel"},
        {pos: [10, 5, 14], state: "minecraft:gravel"},
        {pos: [10, 5, 15], state: "minecraft:gravel"},
        {pos: [10, 5, 16], state: "minecraft:gravel"},
        {pos: [10, 5, 17], state: "minecraft:gravel"},
        {pos: [10, 5, 18], state: "minecraft:gravel"},
        {pos: [10, 5, 19], state: "minecraft:gravel"},
        {pos: [10, 5, 20], state: "minecraft:deepslate_bricks"},
        {pos: [11, 5, 0], state: "minecraft:deepslate_bricks"},
        {pos: [11, 5, 1], state: "minecraft:gravel"},
        {pos: [11, 5, 2], state: "minecraft:gravel"},
        {pos: [11, 5, 3], state: "minecraft:gravel"},
        {pos: [11, 5, 4], state: "minecraft:gravel"},
        {pos: [11, 5, 5], state: "minecraft:gravel"},
        {pos: [11, 5, 6], state: "minecraft:gravel"},
        {pos: [11, 5, 7], state: "minecraft:gravel"},
        {pos: [11, 5, 8], state: "minecraft:gravel"},
        {pos: [11, 5, 9], state: "minecraft:gravel"},
        {pos: [11, 5, 10], state: "minecraft:gravel"},
        {pos: [11, 5, 11], state: "minecraft:gravel"},
        {pos: [11, 5, 12], state: "minecraft:gravel"},
        {pos: [11, 5, 13], state: "minecraft:gravel"},
        {pos: [11, 5, 14], state: "minecraft:gravel"},
        {pos: [11, 5, 15], state: "minecraft:gravel"},
        {pos: [11, 5, 16], state: "minecraft:gravel"},
        {pos: [11, 5, 17], state: "minecraft:gravel"},
        {pos: [11, 5, 18], state: "minecraft:gravel"},
        {pos: [11, 5, 19], state: "minecraft:gravel"},
        {pos: [11, 5, 20], state: "minecraft:deepslate_bricks"},
        {pos: [12, 5, 0], state: "minecraft:deepslate_bricks"},
        {pos: [12, 5, 1], state: "minecraft:gravel"},
        {pos: [12, 5, 2], state: "minecraft:gravel"},
        {pos: [12, 5, 3], state: "minecraft:cave_air"},
        {pos: [12, 5, 4], state: "minecraft:cave_air"},
        {pos: [12, 5, 5], state: "minecraft:gravel"},
        {pos: [12, 5, 6], state: "minecraft:gravel"},
        {pos: [12, 5, 7], state: "minecraft:gravel"},
        {pos: [12, 5, 8], state: "minecraft:gravel"},
        {pos: [12, 5, 9], state: "minecraft:cave_air"},
        {pos: [12, 5, 10], state: "minecraft:cave_air"},
        {pos: [12, 5, 11], state: "minecraft:cave_air"},
        {pos: [12, 5, 12], state: "minecraft:gravel"},
        {pos: [12, 5, 13], state: "minecraft:gravel"},
        {pos: [12, 5, 14], state: "minecraft:cave_air"},
        {pos: [12, 5, 15], state: "minecraft:cave_air"},
        {pos: [12, 5, 16], state: "minecraft:cave_air"},
        {pos: [12, 5, 17], state: "minecraft:cave_air"},
        {pos: [12, 5, 18], state: "minecraft:gravel"},
        {pos: [12, 5, 19], state: "minecraft:gravel"},
        {pos: [12, 5, 20], state: "minecraft:deepslate_bricks"},
        {pos: [13, 5, 0], state: "minecraft:deepslate_bricks"},
        {pos: [13, 5, 1], state: "minecraft:gravel"},
        {pos: [13, 5, 2], state: "minecraft:gravel"},
        {pos: [13, 5, 3], state: "minecraft:gravel"},
        {pos: [13, 5, 4], state: "minecraft:gravel"},
        {pos: [13, 5, 5], state: "minecraft:cave_air"},
        {pos: [13, 5, 6], state: "minecraft:cave_air"},
        {pos: [13, 5, 7], state: "minecraft:gravel"},
        {pos: [13, 5, 8], state: "minecraft:gravel"},
        {pos: [13, 5, 9], state: "minecraft:cave_air"},
        {pos: [13, 5, 10], state: "minecraft:cave_air"},
        {pos: [13, 5, 11], state: "minecraft:cave_air"},
        {pos: [13, 5, 12], state: "minecraft:gravel"},
        {pos: [13, 5, 13], state: "minecraft:gravel"},
        {pos: [13, 5, 14], state: "minecraft:gravel"},
        {pos: [13, 5, 15], state: "minecraft:cave_air"},
        {pos: [13, 5, 16], state: "minecraft:cave_air"},
        {pos: [13, 5, 17], state: "minecraft:cave_air"},
        {pos: [13, 5, 18], state: "minecraft:gravel"},
        {pos: [13, 5, 19], state: "minecraft:gravel"},
        {pos: [13, 5, 20], state: "minecraft:deepslate_bricks"},
        {pos: [14, 5, 0], state: "minecraft:deepslate_bricks"},
        {pos: [14, 5, 1], state: "minecraft:gravel"},
        {pos: [14, 5, 2], state: "minecraft:gravel"},
        {pos: [14, 5, 3], state: "minecraft:gravel"},
        {pos: [14, 5, 4], state: "minecraft:cave_air"},
        {pos: [14, 5, 5], state: "minecraft:cave_air"},
        {pos: [14, 5, 6], state: "minecraft:cave_air"},
        {pos: [14, 5, 7], state: "minecraft:cave_air"},
        {pos: [14, 5, 8], state: "minecraft:gravel"},
        {pos: [14, 5, 9], state: "minecraft:cave_air"},
        {pos: [14, 5, 10], state: "minecraft:cave_air"},
        {pos: [14, 5, 11], state: "minecraft:cave_air"},
        {pos: [14, 5, 12], state: "minecraft:gravel"},
        {pos: [14, 5, 13], state: "minecraft:gravel"},
        {pos: [14, 5, 14], state: "minecraft:gravel"},
        {pos: [14, 5, 15], state: "minecraft:gravel"},
        {pos: [14, 5, 16], state: "minecraft:cave_air"},
        {pos: [14, 5, 17], state: "minecraft:gravel"},
        {pos: [14, 5, 18], state: "minecraft:gravel"},
        {pos: [14, 5, 19], state: "minecraft:gravel"},
        {pos: [14, 5, 20], state: "minecraft:deepslate_bricks"},
        {pos: [15, 5, 0], state: "minecraft:deepslate_bricks"},
        {pos: [15, 5, 1], state: "minecraft:gravel"},
        {pos: [15, 5, 2], state: "minecraft:gravel"},
        {pos: [15, 5, 3], state: "minecraft:gravel"},
        {pos: [15, 5, 4], state: "minecraft:gravel"},
        {pos: [15, 5, 5], state: "minecraft:gravel"},
        {pos: [15, 5, 6], state: "minecraft:gravel"},
        {pos: [15, 5, 7], state: "minecraft:gravel"},
        {pos: [15, 5, 8], state: "minecraft:gravel"},
        {pos: [15, 5, 9], state: "minecraft:gravel"},
        {pos: [15, 5, 10], state: "minecraft:gravel"},
        {pos: [15, 5, 11], state: "minecraft:gravel"},
        {pos: [15, 5, 12], state: "minecraft:gravel"},
        {pos: [15, 5, 13], state: "minecraft:gravel"},
        {pos: [15, 5, 14], state: "minecraft:gravel"},
        {pos: [15, 5, 15], state: "minecraft:gravel"},
        {pos: [15, 5, 16], state: "minecraft:gravel"},
        {pos: [15, 5, 17], state: "minecraft:gravel"},
        {pos: [15, 5, 18], state: "minecraft:gravel"},
        {pos: [15, 5, 19], state: "minecraft:gravel"},
        {pos: [15, 5, 20], state: "minecraft:deepslate_bricks"},
        {pos: [16, 5, 0], state: "minecraft:deepslate_bricks"},
        {pos: [16, 5, 1], state: "minecraft:gravel"},
        {pos: [16, 5, 2], state: "minecraft:gravel"},
        {pos: [16, 5, 3], state: "minecraft:gravel"},
        {pos: [16, 5, 4], state: "minecraft:gravel"},
        {pos: [16, 5, 5], state: "minecraft:gravel"},
        {pos: [16, 5, 6], state: "minecraft:gravel"},
        {pos: [16, 5, 7], state: "minecraft:gravel"},
        {pos: [16, 5, 8], state: "minecraft:gravel"},
        {pos: [16, 5, 9], state: "minecraft:cave_air"},
        {pos: [16, 5, 10], state: "minecraft:gravel"},
        {pos: [16, 5, 11], state: "minecraft:gravel"},
        {pos: [16, 5, 12], state: "minecraft:gravel"},
        {pos: [16, 5, 13], state: "minecraft:gravel"},
        {pos: [16, 5, 14], state: "minecraft:gravel"},
        {pos: [16, 5, 15], state: "minecraft:gravel"},
        {pos: [16, 5, 16], state: "minecraft:gravel"},
        {pos: [16, 5, 17], state: "minecraft:gravel"},
        {pos: [16, 5, 18], state: "minecraft:gravel"},
        {pos: [16, 5, 19], state: "minecraft:gravel"},
        {pos: [16, 5, 20], state: "minecraft:deepslate_bricks"},
        {pos: [17, 5, 0], state: "minecraft:deepslate_bricks"},
        {pos: [17, 5, 1], state: "minecraft:gravel"},
        {pos: [17, 5, 2], state: "minecraft:gravel"},
        {pos: [17, 5, 3], state: "minecraft:gravel"},
        {pos: [17, 5, 4], state: "minecraft:gravel"},
        {pos: [17, 5, 5], state: "minecraft:gravel"},
        {pos: [17, 5, 6], state: "minecraft:gravel"},
        {pos: [17, 5, 7], state: "minecraft:gravel"},
        {pos: [17, 5, 8], state: "minecraft:gravel"},
        {pos: [17, 5, 9], state: "minecraft:cave_air"},
        {pos: [17, 5, 10], state: "minecraft:cave_air"},
        {pos: [17, 5, 11], state: "minecraft:gravel"},
        {pos: [17, 5, 12], state: "minecraft:gravel"},
        {pos: [17, 5, 13], state: "minecraft:gravel"},
        {pos: [17, 5, 14], state: "minecraft:gravel"},
        {pos: [17, 5, 15], state: "minecraft:gravel"},
        {pos: [17, 5, 16], state: "minecraft:gravel"},
        {pos: [17, 5, 17], state: "minecraft:gravel"},
        {pos: [17, 5, 18], state: "minecraft:gravel"},
        {pos: [17, 5, 19], state: "minecraft:gravel"},
        {pos: [17, 5, 20], state: "minecraft:deepslate_bricks"},
        {pos: [18, 5, 0], state: "minecraft:deepslate_bricks"},
        {pos: [18, 5, 1], state: "minecraft:gravel"},
        {pos: [18, 5, 2], state: "minecraft:gravel"},
        {pos: [18, 5, 3], state: "minecraft:gravel"},
        {pos: [18, 5, 4], state: "minecraft:gravel"},
        {pos: [18, 5, 5], state: "minecraft:gravel"},
        {pos: [18, 5, 6], state: "minecraft:gravel"},
        {pos: [18, 5, 7], state: "minecraft:gravel"},
        {pos: [18, 5, 8], state: "minecraft:gravel"},
        {pos: [18, 5, 9], state: "minecraft:gravel"},
        {pos: [18, 5, 10], state: "minecraft:cave_air"},
        {pos: [18, 5, 11], state: "minecraft:cave_air"},
        {pos: [18, 5, 12], state: "minecraft:gravel"},
        {pos: [18, 5, 13], state: "minecraft:gravel"},
        {pos: [18, 5, 14], state: "minecraft:gravel"},
        {pos: [18, 5, 15], state: "minecraft:gravel"},
        {pos: [18, 5, 16], state: "minecraft:gravel"},
        {pos: [18, 5, 17], state: "minecraft:gravel"},
        {pos: [18, 5, 18], state: "minecraft:gravel"},
        {pos: [18, 5, 19], state: "minecraft:deepslate_bricks"},
        {pos: [18, 5, 20], state: "minecraft:deepslate_bricks"},
        {pos: [19, 5, 0], state: "minecraft:deepslate_bricks"},
        {pos: [19, 5, 1], state: "minecraft:gravel"},
        {pos: [19, 5, 2], state: "minecraft:gravel"},
        {pos: [19, 5, 3], state: "minecraft:gravel"},
        {pos: [19, 5, 4], state: "minecraft:gravel"},
        {pos: [19, 5, 5], state: "minecraft:gravel"},
        {pos: [19, 5, 6], state: "minecraft:gravel"},
        {pos: [19, 5, 7], state: "minecraft:gravel"},
        {pos: [19, 5, 8], state: "minecraft:gravel"},
        {pos: [19, 5, 9], state: "minecraft:gravel"},
        {pos: [19, 5, 10], state: "minecraft:cave_air"},
        {pos: [19, 5, 11], state: "minecraft:cave_air"},
        {pos: [19, 5, 12], state: "minecraft:gravel"},
        {pos: [19, 5, 13], state: "minecraft:gravel"},
        {pos: [19, 5, 14], state: "minecraft:gravel"},
        {pos: [19, 5, 15], state: "minecraft:gravel"},
        {pos: [19, 5, 16], state: "minecraft:gravel"},
        {pos: [19, 5, 17], state: "minecraft:gravel"},
        {pos: [19, 5, 18], state: "minecraft:gravel"},
        {pos: [19, 5, 19], state: "minecraft:gravel"},
        {pos: [19, 5, 20], state: "minecraft:deepslate_bricks"},
        {pos: [20, 5, 0], state: "minecraft:deepslate_bricks"},
        {pos: [20, 5, 1], state: "minecraft:gravel"},
        {pos: [20, 5, 2], state: "minecraft:gravel"},
        {pos: [20, 5, 3], state: "minecraft:gravel"},
        {pos: [20, 5, 4], state: "minecraft:gravel"},
        {pos: [20, 5, 5], state: "minecraft:gravel"},
        {pos: [20, 5, 6], state: "minecraft:gravel"},
        {pos: [20, 5, 7], state: "minecraft:gravel"},
        {pos: [20, 5, 8], state: "minecraft:gravel"},
        {pos: [20, 5, 9], state: "minecraft:cave_air"},
        {pos: [20, 5, 10], state: "minecraft:gravel"},
        {pos: [20, 5, 11], state: "minecraft:gravel"},
        {pos: [20, 5, 12], state: "minecraft:gravel"},
        {pos: [20, 5, 13], state: "minecraft:gravel"},
        {pos: [20, 5, 14], state: "minecraft:gravel"},
        {pos: [20, 5, 15], state: "minecraft:gravel"},
        {pos: [20, 5, 16], state: "minecraft:gravel"},
        {pos: [20, 5, 17], state: "minecraft:gravel"},
        {pos: [20, 5, 18], state: "minecraft:gravel"},
        {pos: [20, 5, 19], state: "minecraft:gravel"},
        {pos: [20, 5, 20], state: "minecraft:deepslate_bricks"},
        {pos: [21, 5, 0], state: "minecraft:deepslate_bricks"},
        {pos: [21, 5, 1], state: "minecraft:gravel"},
        {pos: [21, 5, 2], state: "minecraft:gravel"},
        {pos: [21, 5, 3], state: "minecraft:gravel"},
        {pos: [21, 5, 4], state: "minecraft:gravel"},
        {pos: [21, 5, 5], state: "minecraft:gravel"},
        {pos: [21, 5, 6], state: "minecraft:gravel"},
        {pos: [21, 5, 7], state: "minecraft:gravel"},
        {pos: [21, 5, 8], state: "minecraft:gravel"},
        {pos: [21, 5, 9], state: "minecraft:gravel"},
        {pos: [21, 5, 10], state: "minecraft:gravel"},
        {pos: [21, 5, 11], state: "minecraft:gravel"},
        {pos: [21, 5, 12], state: "minecraft:gravel"},
        {pos: [21, 5, 13], state: "minecraft:gravel"},
        {pos: [21, 5, 14], state: "minecraft:gravel"},
        {pos: [21, 5, 15], state: "minecraft:gravel"},
        {pos: [21, 5, 16], state: "minecraft:gravel"},
        {pos: [21, 5, 17], state: "minecraft:gravel"},
        {pos: [21, 5, 18], state: "minecraft:gravel"},
        {pos: [21, 5, 19], state: "minecraft:gravel"},
        {pos: [21, 5, 20], state: "minecraft:deepslate_bricks"},
        {pos: [22, 5, 0], state: "minecraft:deepslate_bricks"},
        {pos: [22, 5, 1], state: "minecraft:deepslate_bricks"},
        {pos: [22, 5, 2], state: "minecraft:deepslate_bricks"},
        {pos: [22, 5, 3], state: "minecraft:deepslate_bricks"},
        {pos: [22, 5, 4], state: "minecraft:deepslate_bricks"},
        {pos: [22, 5, 5], state: "minecraft:deepslate_bricks"},
        {pos: [22, 5, 6], state: "minecraft:deepslate_bricks"},
        {pos: [22, 5, 7], state: "minecraft:gravel"},
        {pos: [22, 5, 8], state: "minecraft:gravel"},
        {pos: [22, 5, 9], state: "minecraft:gravel"},
        {pos: [22, 5, 10], state: "minecraft:gravel"},
        {pos: [22, 5, 11], state: "minecraft:gravel"},
        {pos: [22, 5, 12], state: "minecraft:gravel"},
        {pos: [22, 5, 13], state: "minecraft:gravel"},
        {pos: [22, 5, 14], state: "minecraft:deepslate_bricks"},
        {pos: [22, 5, 15], state: "minecraft:deepslate_bricks"},
        {pos: [22, 5, 16], state: "minecraft:deepslate_bricks"},
        {pos: [22, 5, 17], state: "minecraft:deepslate_bricks"},
        {pos: [22, 5, 18], state: "minecraft:deepslate_bricks"},
        {pos: [22, 5, 19], state: "minecraft:deepslate_bricks"},
        {pos: [22, 5, 20], state: "minecraft:deepslate_bricks"},
        {pos: [23, 5, 7], state: "minecraft:deepslate_bricks"},
        {pos: [23, 5, 8], state: "minecraft:gravel"},
        {pos: [23, 5, 9], state: "minecraft:gravel"},
        {pos: [23, 5, 10], state: "minecraft:gravel"},
        {pos: [23, 5, 11], state: "minecraft:gravel"},
        {pos: [23, 5, 12], state: "minecraft:gravel"},
        {pos: [23, 5, 13], state: "minecraft:deepslate_bricks"},
        {pos: [24, 5, 7], state: "minecraft:deepslate_bricks"},
        {pos: [24, 5, 8], state: "minecraft:gravel"},
        {pos: [24, 5, 9], state: "minecraft:gravel"},
        {pos: [24, 5, 10], state: "minecraft:gravel"},
        {pos: [24, 5, 11], state: "minecraft:gravel"},
        {pos: [24, 5, 12], state: "minecraft:gravel"},
        {pos: [24, 5, 13], state: "minecraft:deepslate_bricks"},
        {pos: [25, 5, 8], state: "minecraft:deepslate_bricks"},
        {pos: [25, 5, 9], state: "minecraft:gravel"},
        {pos: [25, 5, 10], state: "minecraft:gravel"},
        {pos: [25, 5, 11], state: "minecraft:gravel"},
        {pos: [25, 5, 12], state: "minecraft:deepslate_bricks"},
        {pos: [26, 5, 8], state: "minecraft:deepslate_bricks"},
        {pos: [26, 5, 9], state: "minecraft:gravel"},
        {pos: [26, 5, 10], state: "minecraft:gravel"},
        {pos: [26, 5, 11], state: "minecraft:gravel"},
        {pos: [26, 5, 12], state: "minecraft:deepslate_bricks"},
        {pos: [0, 6, 8], state: "minecraft:deepslate_bricks"},
        {pos: [0, 6, 9], state: "minecraft:candle{candles:4,lit:false,waterlogged:false}"},
        {pos: [0, 6, 10], state: "minecraft:jigsaw{orientation:west_up}", nbt: {final_state: "minecraft:cave_air", id: "minecraft:jigsaw", joint: "rollable", name: "trailiertales:corridor", placement_priority: 0, pool: "trailiertales:catacombs/corridor_connector", selection_priority: 0, target: "trailiertales:corridor"}},
        {pos: [0, 6, 11], state: "minecraft:candle{candles:4,lit:false,waterlogged:false}"},
        {pos: [0, 6, 12], state: "minecraft:deepslate_bricks"},
        {pos: [1, 6, 8], state: "minecraft:deepslate_bricks"},
        {pos: [1, 6, 9], state: "minecraft:candle{candles:4,lit:false,waterlogged:false}"},
        {pos: [1, 6, 10], state: "minecraft:cave_air"},
        {pos: [1, 6, 11], state: "minecraft:candle{candles:4,lit:false,waterlogged:false}"},
        {pos: [1, 6, 12], state: "minecraft:deepslate_bricks"},
        {pos: [2, 6, 7], state: "minecraft:deepslate_bricks"},
        {pos: [2, 6, 8], state: "minecraft:deepslate_bricks"},
        {pos: [2, 6, 9], state: "minecraft:candle{candles:4,lit:false,waterlogged:false}"},
        {pos: [2, 6, 10], state: "minecraft:cave_air"},
        {pos: [2, 6, 11], state: "minecraft:candle{candles:4,lit:false,waterlogged:false}"},
        {pos: [2, 6, 12], state: "minecraft:deepslate_bricks"},
        {pos: [2, 6, 13], state: "minecraft:deepslate_bricks"},
        {pos: [3, 6, 7], state: "minecraft:deepslate_bricks"},
        {pos: [3, 6, 8], state: "minecraft:candle{candles:4,lit:false,waterlogged:false}"},
        {pos: [3, 6, 9], state: "minecraft:cave_air"},
        {pos: [3, 6, 10], state: "minecraft:cave_air"},
        {pos: [3, 6, 11], state: "minecraft:cave_air"},
        {pos: [3, 6, 12], state: "minecraft:skeleton_skull{powered:false,rotation:0}", nbt: {id: "minecraft:skull"}},
        {pos: [3, 6, 13], state: "minecraft:deepslate_bricks"},
        {pos: [4, 6, 0], state: "minecraft:deepslate_bricks"},
        {pos: [4, 6, 1], state: "minecraft:deepslate_bricks"},
        {pos: [4, 6, 2], state: "minecraft:deepslate_bricks"},
        {pos: [4, 6, 3], state: "minecraft:deepslate_bricks"},
        {pos: [4, 6, 4], state: "minecraft:deepslate_bricks"},
        {pos: [4, 6, 5], state: "minecraft:deepslate_bricks"},
        {pos: [4, 6, 6], state: "minecraft:deepslate_bricks"},
        {pos: [4, 6, 7], state: "minecraft:deepslate_brick_stairs{facing:north,half:top,shape:straight,waterlogged:false}"},
        {pos: [4, 6, 8], state: "minecraft:candle{candles:4,lit:false,waterlogged:false}"},
        {pos: [4, 6, 9], state: "minecraft:cave_air"},
        {pos: [4, 6, 10], state: "minecraft:cave_air"},
        {pos: [4, 6, 11], state: "minecraft:cave_air"},
        {pos: [4, 6, 12], state: "minecraft:candle{candles:4,lit:false,waterlogged:false}"},
        {pos: [4, 6, 13], state: "minecraft:deepslate_brick_stairs{facing:south,half:top,shape:straight,waterlogged:false}"},
        {pos: [4, 6, 14], state: "minecraft:deepslate_bricks"},
        {pos: [4, 6, 15], state: "minecraft:deepslate_bricks"},
        {pos: [4, 6, 16], state: "minecraft:deepslate_bricks"},
        {pos: [4, 6, 17], state: "minecraft:deepslate_bricks"},
        {pos: [4, 6, 18], state: "minecraft:deepslate_bricks"},
        {pos: [4, 6, 19], state: "minecraft:deepslate_bricks"},
        {pos: [4, 6, 20], state: "minecraft:deepslate_bricks"},
        {pos: [5, 6, 0], state: "minecraft:deepslate_bricks"},
        {pos: [5, 6, 1], state: "minecraft:deepslate_bricks"},
        {pos: [5, 6, 2], state: "minecraft:deepslate_brick_stairs{facing:west,half:top,shape:straight,waterlogged:false}"},
        {pos: [5, 6, 3], state: "minecraft:deepslate_bricks"},
        {pos: [5, 6, 4], state: "minecraft:deepslate_brick_stairs{facing:west,half:top,shape:straight,waterlogged:false}"},
        {pos: [5, 6, 5], state: "minecraft:deepslate_bricks"},
        {pos: [5, 6, 6], state: "minecraft:deepslate_brick_stairs{facing:west,half:top,shape:straight,waterlogged:false}"},
        {pos: [5, 6, 7], state: "minecraft:deepslate_bricks"},
        {pos: [5, 6, 8], state: "minecraft:candle{candles:4,lit:false,waterlogged:false}"},
        {pos: [5, 6, 9], state: "minecraft:cave_air"},
        {pos: [5, 6, 10], state: "minecraft:cave_air"},
        {pos: [5, 6, 11], state: "minecraft:cave_air"},
        {pos: [5, 6, 12], state: "minecraft:candle{candles:4,lit:false,waterlogged:false}"},
        {pos: [5, 6, 13], state: "minecraft:deepslate_bricks"},
        {pos: [5, 6, 14], state: "minecraft:deepslate_brick_stairs{facing:west,half:top,shape:straight,waterlogged:false}"},
        {pos: [5, 6, 15], state: "minecraft:deepslate_bricks"},
        {pos: [5, 6, 16], state: "minecraft:deepslate_brick_stairs{facing:west,half:top,shape:straight,waterlogged:false}"},
        {pos: [5, 6, 17], state: "minecraft:deepslate_bricks"},
        {pos: [5, 6, 18], state: "minecraft:deepslate_brick_stairs{facing:west,half:top,shape:straight,waterlogged:false}"},
        {pos: [5, 6, 19], state: "minecraft:deepslate_bricks"},
        {pos: [5, 6, 20], state: "minecraft:deepslate_bricks"},
        {pos: [6, 6, 0], state: "minecraft:deepslate_bricks"},
        {pos: [6, 6, 1], state: "minecraft:deepslate_bricks"},
        {pos: [6, 6, 2], state: "minecraft:candle{candles:4,lit:false,waterlogged:false}"},
        {pos: [6, 6, 3], state: "minecraft:candle{candles:4,lit:false,waterlogged:false}"},
        {pos: [6, 6, 4], state: "minecraft:candle{candles:4,lit:false,waterlogged:false}"},
        {pos: [6, 6, 5], state: "minecraft:candle{candles:4,lit:false,waterlogged:false}"},
        {pos: [6, 6, 6], state: "minecraft:candle{candles:4,lit:false,waterlogged:false}"},
        {pos: [6, 6, 7], state: "minecraft:skeleton_skull{powered:false,rotation:4}", nbt: {id: "minecraft:skull"}},
        {pos: [6, 6, 8], state: "minecraft:cave_air"},
        {pos: [6, 6, 9], state: "minecraft:cave_air"},
        {pos: [6, 6, 10], state: "minecraft:cave_air"},
        {pos: [6, 6, 11], state: "minecraft:cave_air"},
        {pos: [6, 6, 12], state: "minecraft:cave_air"},
        {pos: [6, 6, 13], state: "minecraft:candle{candles:4,lit:false,waterlogged:false}"},
        {pos: [6, 6, 14], state: "minecraft:candle{candles:4,lit:false,waterlogged:false}"},
        {pos: [6, 6, 15], state: "minecraft:candle{candles:4,lit:false,waterlogged:false}"},
        {pos: [6, 6, 16], state: "minecraft:candle{candles:4,lit:false,waterlogged:false}"},
        {pos: [6, 6, 17], state: "minecraft:candle{candles:4,lit:false,waterlogged:false}"},
        {pos: [6, 6, 18], state: "minecraft:decorated_pot{cracked:false,facing:south,waterlogged:false}", nbt: {id: "minecraft:decorated_pot"}},
        {pos: [6, 6, 19], state: "minecraft:deepslate_bricks"},
        {pos: [6, 6, 20], state: "minecraft:deepslate_bricks"},
        {pos: [7, 6, 0], state: "minecraft:deepslate_bricks"},
        {pos: [7, 6, 1], state: "trailiertales:coffin{facing:south,part:foot,state:inactive}", nbt: {id: "trailiertales:coffin", max_active_light_level: 7, uuid: "99b16a58-c23b-4a81-a63c-f00a702ab14d"}},
        {pos: [7, 6, 2], state: "trailiertales:coffin{facing:south,part:head,state:inactive}", nbt: {id: "trailiertales:coffin"}},
        {pos: [7, 6, 3], state: "minecraft:candle{candles:4,lit:false,waterlogged:false}"},
        {pos: [7, 6, 4], state: "minecraft:cave_air"},
        {pos: [7, 6, 5], state: "minecraft:cave_air"},
        {pos: [7, 6, 6], state: "minecraft:cave_air"},
        {pos: [7, 6, 7], state: "minecraft:cave_air"},
        {pos: [7, 6, 8], state: "minecraft:cave_air"},
        {pos: [7, 6, 9], state: "minecraft:cave_air"},
        {pos: [7, 6, 10], state: "minecraft:cave_air"},
        {pos: [7, 6, 11], state: "minecraft:cave_air"},
        {pos: [7, 6, 12], state: "minecraft:cave_air"},
        {pos: [7, 6, 13], state: "minecraft:cave_air"},
        {pos: [7, 6, 14], state: "minecraft:cave_air"},
        {pos: [7, 6, 15], state: "minecraft:cave_air"},
        {pos: [7, 6, 16], state: "minecraft:cave_air"},
        {pos: [7, 6, 17], state: "minecraft:cave_air"},
        {pos: [7, 6, 18], state: "trailiertales:coffin{facing:south,part:foot,state:inactive}", nbt: {id: "trailiertales:coffin", max_active_light_level: 7, uuid: "7943060e-63fb-41ab-ad7f-1b0050907d85"}},
        {pos: [7, 6, 19], state: "trailiertales:coffin{facing:south,part:head,state:inactive}", nbt: {id: "trailiertales:coffin"}},
        {pos: [7, 6, 20], state: "minecraft:deepslate_bricks"},
        {pos: [8, 6, 0], state: "minecraft:deepslate_bricks"},
        {pos: [8, 6, 1], state: "minecraft:deepslate_bricks"},
        {pos: [8, 6, 2], state: "minecraft:candle{candles:4,lit:false,waterlogged:false}"},
        {pos: [8, 6, 3], state: "minecraft:candle{candles:4,lit:false,waterlogged:false}"},
        {pos: [8, 6, 4], state: "minecraft:candle{candles:4,lit:false,waterlogged:false}"},
        {pos: [8, 6, 5], state: "minecraft:candle{candles:4,lit:false,waterlogged:false}"},
        {pos: [8, 6, 6], state: "minecraft:candle{candles:4,lit:false,waterlogged:false}"},
        {pos: [8, 6, 7], state: "minecraft:candle{candles:4,lit:false,waterlogged:false}"},
        {pos: [8, 6, 8], state: "minecraft:cave_air"},
        {pos: [8, 6, 9], state: "minecraft:cave_air"},
        {pos: [8, 6, 10], state: "minecraft:cave_air"},
        {pos: [8, 6, 11], state: "minecraft:cave_air"},
        {pos: [8, 6, 12], state: "minecraft:cave_air"},
        {pos: [8, 6, 13], state: "minecraft:candle{candles:4,lit:false,waterlogged:false}"},
        {pos: [8, 6, 14], state: "minecraft:candle{candles:4,lit:false,waterlogged:false}"},
        {pos: [8, 6, 15], state: "minecraft:candle{candles:4,lit:false,waterlogged:false}"},
        {pos: [8, 6, 16], state: "minecraft:candle{candles:4,lit:false,waterlogged:false}"},
        {pos: [8, 6, 17], state: "minecraft:candle{candles:4,lit:false,waterlogged:false}"},
        {pos: [8, 6, 18], state: "minecraft:candle{candles:4,lit:false,waterlogged:false}"},
        {pos: [8, 6, 19], state: "minecraft:deepslate_bricks"},
        {pos: [8, 6, 20], state: "minecraft:deepslate_bricks"},
        {pos: [9, 6, 0], state: "minecraft:deepslate_bricks"},
        {pos: [9, 6, 1], state: "minecraft:deepslate_bricks"},
        {pos: [9, 6, 2], state: "minecraft:deepslate_brick_stairs{facing:east,half:top,shape:straight,waterlogged:false}"},
        {pos: [9, 6, 3], state: "minecraft:deepslate_bricks"},
        {pos: [9, 6, 4], state: "minecraft:deepslate_brick_stairs{facing:east,half:top,shape:straight,waterlogged:false}"},
        {pos: [9, 6, 5], state: "minecraft:deepslate_bricks"},
        {pos: [9, 6, 6], state: "minecraft:deepslate_brick_stairs{facing:east,half:top,shape:straight,waterlogged:false}"},
        {pos: [9, 6, 7], state: "minecraft:deepslate_bricks"},
        {pos: [9, 6, 8], state: "minecraft:candle{candles:4,lit:false,waterlogged:false}"},
        {pos: [9, 6, 9], state: "minecraft:cave_air"},
        {pos: [9, 6, 10], state: "minecraft:cave_air"},
        {pos: [9, 6, 11], state: "minecraft:cave_air"},
        {pos: [9, 6, 12], state: "minecraft:skeleton_skull{powered:false,rotation:0}", nbt: {id: "minecraft:skull"}},
        {pos: [9, 6, 13], state: "minecraft:deepslate_bricks"},
        {pos: [9, 6, 14], state: "minecraft:deepslate_brick_stairs{facing:east,half:top,shape:straight,waterlogged:false}"},
        {pos: [9, 6, 15], state: "minecraft:deepslate_bricks"},
        {pos: [9, 6, 16], state: "minecraft:deepslate_brick_stairs{facing:east,half:top,shape:straight,waterlogged:false}"},
        {pos: [9, 6, 17], state: "minecraft:deepslate_bricks"},
        {pos: [9, 6, 18], state: "minecraft:deepslate_brick_stairs{facing:east,half:top,shape:straight,waterlogged:false}"},
        {pos: [9, 6, 19], state: "minecraft:deepslate_bricks"},
        {pos: [9, 6, 20], state: "minecraft:deepslate_bricks"},
        {pos: [10, 6, 0], state: "minecraft:deepslate_bricks"},
        {pos: [10, 6, 1], state: "minecraft:deepslate_bricks"},
        {pos: [10, 6, 2], state: "minecraft:deepslate_bricks"},
        {pos: [10, 6, 3], state: "minecraft:deepslate_bricks"},
        {pos: [10, 6, 4], state: "minecraft:deepslate_bricks"},
        {pos: [10, 6, 5], state: "minecraft:deepslate_bricks"},
        {pos: [10, 6, 6], state: "minecraft:deepslate_bricks"},
        {pos: [10, 6, 7], state: "minecraft:deepslate_bricks"},
        {pos: [10, 6, 8], state: "minecraft:candle{candles:4,lit:false,waterlogged:false}"},
        {pos: [10, 6, 9], state: "minecraft:cave_air"},
        {pos: [10, 6, 10], state: "minecraft:cave_air"},
        {pos: [10, 6, 11], state: "minecraft:cave_air"},
        {pos: [10, 6, 12], state: "minecraft:candle{candles:4,lit:false,waterlogged:false}"},
        {pos: [10, 6, 13], state: "minecraft:deepslate_bricks"},
        {pos: [10, 6, 14], state: "minecraft:deepslate_bricks"},
        {pos: [10, 6, 15], state: "minecraft:deepslate_bricks"},
        {pos: [10, 6, 16], state: "minecraft:deepslate_bricks"},
        {pos: [10, 6, 17], state: "minecraft:deepslate_bricks"},
        {pos: [10, 6, 18], state: "minecraft:deepslate_bricks"},
        {pos: [10, 6, 19], state: "minecraft:deepslate_bricks"},
        {pos: [10, 6, 20], state: "minecraft:deepslate_bricks"},
        {pos: [11, 6, 0], state: "minecraft:deepslate_bricks"},
        {pos: [11, 6, 1], state: "minecraft:candle{candles:4,lit:false,waterlogged:false}"},
        {pos: [11, 6, 2], state: "minecraft:candle{candles:4,lit:false,waterlogged:false}"},
        {pos: [11, 6, 3], state: "minecraft:candle{candles:4,lit:false,waterlogged:false}"},
        {pos: [11, 6, 4], state: "minecraft:deepslate_brick_stairs{facing:west,half:top,shape:straight,waterlogged:false}"},
        {pos: [11, 6, 5], state: "minecraft:deepslate_brick_stairs{facing:west,half:top,shape:straight,waterlogged:false}"},
        {pos: [11, 6, 6], state: "minecraft:deepslate_brick_stairs{facing:west,half:top,shape:straight,waterlogged:false}"},
        {pos: [11, 6, 7], state: "minecraft:candle{candles:4,lit:false,waterlogged:false}"},
        {pos: [11, 6, 8], state: "minecraft:cave_air"},
        {pos: [11, 6, 9], state: "minecraft:cave_air"},
        {pos: [11, 6, 10], state: "minecraft:cave_air"},
        {pos: [11, 6, 11], state: "minecraft:cave_air"},
        {pos: [11, 6, 12], state: "minecraft:cave_air"},
        {pos: [11, 6, 13], state: "minecraft:candle{candles:4,lit:false,waterlogged:false}"},
        {pos: [11, 6, 14], state: "minecraft:deepslate_brick_stairs{facing:west,half:top,shape:straight,waterlogged:false}"},
        {pos: [11, 6, 15], state: "minecraft:deepslate_brick_stairs{facing:west,half:top,shape:straight,waterlogged:false}"},
        {pos: [11, 6, 16], state: "minecraft:deepslate_brick_stairs{facing:west,half:top,shape:straight,waterlogged:false}"},
        {pos: [11, 6, 17], state: "minecraft:candle{candles:4,lit:false,waterlogged:false}"},
        {pos: [11, 6, 18], state: "minecraft:candle{candles:4,lit:false,waterlogged:false}"},
        {pos: [11, 6, 19], state: "minecraft:skeleton_skull{powered:false,rotation:0}", nbt: {id: "minecraft:skull"}},
        {pos: [11, 6, 20], state: "minecraft:deepslate_bricks"},
        {pos: [12, 6, 0], state: "minecraft:deepslate_bricks"},
        {pos: [12, 6, 1], state: "minecraft:deepslate_brick_stairs{facing:east,half:bottom,shape:straight,waterlogged:false}"},
        {pos: [12, 6, 2], state: "minecraft:candle{candles:4,lit:false,waterlogged:false}"},
        {pos: [12, 6, 3], state: "minecraft:cave_air"},
        {pos: [12, 6, 4], state: "minecraft:cave_air"},
        {pos: [12, 6, 5], state: "minecraft:cave_air"},
        {pos: [12, 6, 6], state: "minecraft:cave_air"},
        {pos: [12, 6, 7], state: "minecraft:cave_air"},
        {pos: [12, 6, 8], state: "minecraft:cave_air"},
        {pos: [12, 6, 9], state: "minecraft:cave_air"},
        {pos: [12, 6, 10], state: "minecraft:cave_air"},
        {pos: [12, 6, 11], state: "minecraft:cave_air"},
        {pos: [12, 6, 12], state: "minecraft:cave_air"},
        {pos: [12, 6, 13], state: "minecraft:cave_air"},
        {pos: [12, 6, 14], state: "minecraft:cave_air"},
        {pos: [12, 6, 15], state: "minecraft:cave_air"},
        {pos: [12, 6, 16], state: "minecraft:cave_air"},
        {pos: [12, 6, 17], state: "minecraft:cave_air"},
        {pos: [12, 6, 18], state: "minecraft:candle{candles:4,lit:false,waterlogged:false}"},
        {pos: [12, 6, 19], state: "minecraft:deepslate_brick_stairs{facing:east,half:bottom,shape:straight,waterlogged:false}"},
        {pos: [12, 6, 20], state: "minecraft:deepslate_bricks"},
        {pos: [13, 6, 0], state: "minecraft:deepslate_bricks"},
        {pos: [13, 6, 1], state: "minecraft:chest{facing:south,type:single,waterlogged:false}", nbt: {id: "minecraft:chest"}},
        {pos: [13, 6, 2], state: "minecraft:candle{candles:4,lit:false,waterlogged:false}"},
        {pos: [13, 6, 3], state: "minecraft:cave_air"},
        {pos: [13, 6, 4], state: "minecraft:cave_air"},
        {pos: [13, 6, 5], state: "minecraft:cave_air"},
        {pos: [13, 6, 6], state: "minecraft:cave_air"},
        {pos: [13, 6, 7], state: "minecraft:cave_air"},
        {pos: [13, 6, 8], state: "minecraft:cave_air"},
        {pos: [13, 6, 9], state: "minecraft:cave_air"},
        {pos: [13, 6, 10], state: "minecraft:cave_air"},
        {pos: [13, 6, 11], state: "minecraft:cave_air"},
        {pos: [13, 6, 12], state: "minecraft:cave_air"},
        {pos: [13, 6, 13], state: "minecraft:cave_air"},
