{
    DataVersion: 3953,
    size: [30, 15, 27],
    data: [
        {pos: [0, 0, 10], state: "minecraft:deepslate{axis:y}"},
        {pos: [0, 0, 11], state: "minecraft:deepslate{axis:y}"},
        {pos: [0, 0, 12], state: "minecraft:deepslate{axis:y}"},
        {pos: [0, 0, 13], state: "minecraft:deepslate{axis:y}"},
        {pos: [0, 0, 14], state: "minecraft:deepslate{axis:y}"},
        {pos: [0, 0, 15], state: "minecraft:deepslate{axis:y}"},
        {pos: [0, 0, 16], state: "minecraft:deepslate{axis:y}"},
        {pos: [1, 0, 10], state: "minecraft:deepslate{axis:y}"},
        {pos: [1, 0, 11], state: "minecraft:deepslate{axis:y}"},
        {pos: [1, 0, 12], state: "minecraft:deepslate{axis:y}"},
        {pos: [1, 0, 13], state: "minecraft:deepslate{axis:y}"},
        {pos: [1, 0, 14], state: "minecraft:deepslate{axis:y}"},
        {pos: [1, 0, 15], state: "minecraft:deepslate{axis:y}"},
        {pos: [1, 0, 16], state: "minecraft:deepslate{axis:y}"},
        {pos: [2, 0, 10], state: "minecraft:deepslate{axis:y}"},
        {pos: [2, 0, 11], state: "minecraft:deepslate{axis:y}"},
        {pos: [2, 0, 12], state: "minecraft:deepslate{axis:y}"},
        {pos: [2, 0, 13], state: "minecraft:deepslate{axis:y}"},
        {pos: [2, 0, 14], state: "minecraft:deepslate{axis:y}"},
        {pos: [2, 0, 15], state: "minecraft:deepslate{axis:y}"},
        {pos: [2, 0, 16], state: "minecraft:deepslate{axis:y}"},
        {pos: [3, 0, 6], state: "minecraft:deepslate{axis:y}"},
        {pos: [3, 0, 7], state: "minecraft:deepslate{axis:y}"},
        {pos: [3, 0, 8], state: "minecraft:deepslate{axis:y}"},
        {pos: [3, 0, 9], state: "minecraft:deepslate{axis:y}"},
        {pos: [3, 0, 10], state: "minecraft:deepslate{axis:y}"},
        {pos: [3, 0, 11], state: "minecraft:deepslate{axis:y}"},
        {pos: [3, 0, 12], state: "minecraft:deepslate{axis:y}"},
        {pos: [3, 0, 13], state: "minecraft:deepslate{axis:y}"},
        {pos: [3, 0, 14], state: "minecraft:deepslate{axis:y}"},
        {pos: [3, 0, 15], state: "minecraft:deepslate{axis:y}"},
        {pos: [3, 0, 16], state: "minecraft:deepslate{axis:y}"},
        {pos: [3, 0, 17], state: "minecraft:deepslate{axis:y}"},
        {pos: [3, 0, 18], state: "minecraft:deepslate{axis:y}"},
        {pos: [3, 0, 19], state: "minecraft:deepslate{axis:y}"},
        {pos: [3, 0, 20], state: "minecraft:deepslate{axis:y}"},
        {pos: [4, 0, 6], state: "minecraft:deepslate{axis:y}"},
        {pos: [4, 0, 7], state: "minecraft:deepslate{axis:y}"},
        {pos: [4, 0, 8], state: "minecraft:deepslate{axis:y}"},
        {pos: [4, 0, 9], state: "minecraft:deepslate{axis:y}"},
        {pos: [4, 0, 10], state: "minecraft:deepslate{axis:y}"},
        {pos: [4, 0, 11], state: "minecraft:deepslate{axis:y}"},
        {pos: [4, 0, 12], state: "minecraft:deepslate{axis:y}"},
        {pos: [4, 0, 13], state: "minecraft:deepslate{axis:y}"},
        {pos: [4, 0, 14], state: "minecraft:deepslate{axis:y}"},
        {pos: [4, 0, 15], state: "minecraft:deepslate{axis:y}"},
        {pos: [4, 0, 16], state: "minecraft:deepslate{axis:y}"},
        {pos: [4, 0, 17], state: "minecraft:deepslate{axis:y}"},
        {pos: [4, 0, 18], state: "minecraft:deepslate{axis:y}"},
        {pos: [4, 0, 19], state: "minecraft:deepslate{axis:y}"},
        {pos: [4, 0, 20], state: "minecraft:deepslate{axis:y}"},
        {pos: [5, 0, 6], state: "minecraft:deepslate{axis:y}"},
        {pos: [5, 0, 7], state: "minecraft:deepslate{axis:y}"},
        {pos: [5, 0, 8], state: "minecraft:deepslate{axis:y}"},
        {pos: [5, 0, 9], state: "minecraft:deepslate{axis:y}"},
        {pos: [5, 0, 10], state: "minecraft:deepslate{axis:y}"},
        {pos: [5, 0, 11], state: "minecraft:deepslate{axis:y}"},
        {pos: [5, 0, 12], state: "minecraft:deepslate{axis:y}"},
        {pos: [5, 0, 13], state: "minecraft:deepslate{axis:y}"},
        {pos: [5, 0, 14], state: "minecraft:deepslate{axis:y}"},
        {pos: [5, 0, 15], state: "minecraft:deepslate{axis:y}"},
        {pos: [5, 0, 16], state: "minecraft:deepslate{axis:y}"},
        {pos: [5, 0, 17], state: "minecraft:deepslate{axis:y}"},
        {pos: [5, 0, 18], state: "minecraft:deepslate{axis:y}"},
        {pos: [5, 0, 19], state: "minecraft:deepslate{axis:y}"},
        {pos: [5, 0, 20], state: "minecraft:deepslate{axis:y}"},
        {pos: [6, 0, 5], state: "minecraft:deepslate{axis:y}"},
        {pos: [6, 0, 6], state: "minecraft:deepslate{axis:y}"},
        {pos: [6, 0, 7], state: "minecraft:deepslate{axis:y}"},
        {pos: [6, 0, 8], state: "minecraft:deepslate{axis:y}"},
        {pos: [6, 0, 9], state: "minecraft:deepslate{axis:y}"},
        {pos: [6, 0, 10], state: "minecraft:deepslate{axis:y}"},
        {pos: [6, 0, 11], state: "minecraft:deepslate{axis:y}"},
        {pos: [6, 0, 12], state: "minecraft:deepslate{axis:y}"},
        {pos: [6, 0, 13], state: "minecraft:deepslate{axis:y}"},
        {pos: [6, 0, 14], state: "minecraft:deepslate{axis:y}"},
        {pos: [6, 0, 15], state: "minecraft:deepslate{axis:y}"},
        {pos: [6, 0, 16], state: "minecraft:deepslate{axis:y}"},
        {pos: [6, 0, 17], state: "minecraft:deepslate{axis:y}"},
        {pos: [6, 0, 18], state: "minecraft:deepslate{axis:y}"},
        {pos: [6, 0, 19], state: "minecraft:deepslate{axis:y}"},
        {pos: [6, 0, 20], state: "minecraft:deepslate{axis:y}"},
        {pos: [6, 0, 21], state: "minecraft:deepslate{axis:y}"},
        {pos: [7, 0, 5], state: "minecraft:deepslate{axis:y}"},
        {pos: [7, 0, 6], state: "minecraft:deepslate{axis:y}"},
        {pos: [7, 0, 7], state: "minecraft:deepslate{axis:y}"},
        {pos: [7, 0, 8], state: "minecraft:deepslate{axis:y}"},
        {pos: [7, 0, 9], state: "minecraft:deepslate{axis:y}"},
        {pos: [7, 0, 10], state: "minecraft:deepslate{axis:y}"},
        {pos: [7, 0, 11], state: "minecraft:deepslate{axis:y}"},
        {pos: [7, 0, 12], state: "minecraft:deepslate{axis:y}"},
        {pos: [7, 0, 13], state: "minecraft:deepslate{axis:y}"},
        {pos: [7, 0, 14], state: "minecraft:deepslate{axis:y}"},
        {pos: [7, 0, 15], state: "minecraft:deepslate{axis:y}"},
        {pos: [7, 0, 16], state: "minecraft:deepslate{axis:y}"},
        {pos: [7, 0, 17], state: "minecraft:deepslate{axis:y}"},
        {pos: [7, 0, 18], state: "minecraft:deepslate{axis:y}"},
        {pos: [7, 0, 19], state: "minecraft:deepslate{axis:y}"},
        {pos: [7, 0, 20], state: "minecraft:deepslate{axis:y}"},
        {pos: [7, 0, 21], state: "minecraft:deepslate{axis:y}"},
        {pos: [8, 0, 5], state: "minecraft:deepslate{axis:y}"},
        {pos: [8, 0, 6], state: "minecraft:deepslate{axis:y}"},
        {pos: [8, 0, 7], state: "minecraft:deepslate{axis:y}"},
        {pos: [8, 0, 8], state: "minecraft:deepslate{axis:y}"},
        {pos: [8, 0, 9], state: "minecraft:deepslate{axis:y}"},
        {pos: [8, 0, 10], state: "minecraft:deepslate{axis:y}"},
        {pos: [8, 0, 11], state: "minecraft:deepslate{axis:y}"},
        {pos: [8, 0, 12], state: "minecraft:deepslate{axis:y}"},
        {pos: [8, 0, 13], state: "minecraft:deepslate{axis:y}"},
        {pos: [8, 0, 14], state: "minecraft:deepslate{axis:y}"},
        {pos: [8, 0, 15], state: "minecraft:deepslate{axis:y}"},
        {pos: [8, 0, 16], state: "minecraft:deepslate{axis:y}"},
        {pos: [8, 0, 17], state: "minecraft:deepslate{axis:y}"},
        {pos: [8, 0, 18], state: "minecraft:deepslate{axis:y}"},
        {pos: [8, 0, 19], state: "minecraft:deepslate{axis:y}"},
        {pos: [8, 0, 20], state: "minecraft:deepslate{axis:y}"},
        {pos: [8, 0, 21], state: "minecraft:deepslate{axis:y}"},
        {pos: [9, 0, 5], state: "minecraft:deepslate{axis:y}"},
        {pos: [9, 0, 6], state: "minecraft:deepslate{axis:y}"},
        {pos: [9, 0, 7], state: "minecraft:deepslate{axis:y}"},
        {pos: [9, 0, 8], state: "minecraft:deepslate{axis:y}"},
        {pos: [9, 0, 9], state: "minecraft:deepslate{axis:y}"},
        {pos: [9, 0, 10], state: "minecraft:deepslate{axis:y}"},
        {pos: [9, 0, 11], state: "minecraft:deepslate{axis:y}"},
        {pos: [9, 0, 12], state: "minecraft:deepslate{axis:y}"},
        {pos: [9, 0, 13], state: "minecraft:deepslate{axis:y}"},
        {pos: [9, 0, 14], state: "minecraft:deepslate{axis:y}"},
        {pos: [9, 0, 15], state: "minecraft:deepslate{axis:y}"},
        {pos: [9, 0, 16], state: "minecraft:deepslate{axis:y}"},
        {pos: [9, 0, 17], state: "minecraft:deepslate{axis:y}"},
        {pos: [9, 0, 18], state: "minecraft:deepslate{axis:y}"},
        {pos: [9, 0, 19], state: "minecraft:deepslate{axis:y}"},
        {pos: [9, 0, 20], state: "minecraft:deepslate{axis:y}"},
        {pos: [9, 0, 21], state: "minecraft:deepslate{axis:y}"},
        {pos: [10, 0, 5], state: "minecraft:deepslate{axis:y}"},
        {pos: [10, 0, 6], state: "minecraft:deepslate{axis:y}"},
        {pos: [10, 0, 7], state: "minecraft:deepslate{axis:y}"},
        {pos: [10, 0, 8], state: "minecraft:deepslate{axis:y}"},
        {pos: [10, 0, 9], state: "minecraft:deepslate{axis:y}"},
        {pos: [10, 0, 10], state: "minecraft:deepslate{axis:y}"},
        {pos: [10, 0, 11], state: "minecraft:deepslate{axis:y}"},
        {pos: [10, 0, 12], state: "minecraft:deepslate{axis:y}"},
        {pos: [10, 0, 13], state: "minecraft:deepslate{axis:y}"},
        {pos: [10, 0, 14], state: "minecraft:deepslate{axis:y}"},
        {pos: [10, 0, 15], state: "minecraft:deepslate{axis:y}"},
        {pos: [10, 0, 16], state: "minecraft:deepslate{axis:y}"},
        {pos: [10, 0, 17], state: "minecraft:deepslate{axis:y}"},
        {pos: [10, 0, 18], state: "minecraft:deepslate{axis:y}"},
        {pos: [10, 0, 19], state: "minecraft:deepslate{axis:y}"},
        {pos: [10, 0, 20], state: "minecraft:deepslate{axis:y}"},
        {pos: [10, 0, 21], state: "minecraft:deepslate{axis:y}"},
        {pos: [11, 0, 6], state: "minecraft:deepslate{axis:y}"},
        {pos: [11, 0, 7], state: "minecraft:deepslate{axis:y}"},
        {pos: [11, 0, 8], state: "minecraft:deepslate{axis:y}"},
        {pos: [11, 0, 9], state: "minecraft:deepslate{axis:y}"},
        {pos: [11, 0, 10], state: "minecraft:deepslate{axis:y}"},
        {pos: [11, 0, 11], state: "minecraft:deepslate{axis:y}"},
        {pos: [11, 0, 12], state: "minecraft:deepslate{axis:y}"},
        {pos: [11, 0, 13], state: "minecraft:deepslate{axis:y}"},
        {pos: [11, 0, 14], state: "minecraft:deepslate{axis:y}"},
        {pos: [11, 0, 15], state: "minecraft:deepslate{axis:y}"},
        {pos: [11, 0, 16], state: "minecraft:deepslate{axis:y}"},
        {pos: [11, 0, 17], state: "minecraft:deepslate{axis:y}"},
        {pos: [11, 0, 18], state: "minecraft:deepslate{axis:y}"},
        {pos: [11, 0, 19], state: "minecraft:deepslate{axis:y}"},
        {pos: [11, 0, 20], state: "minecraft:deepslate{axis:y}"},
        {pos: [12, 0, 6], state: "minecraft:deepslate{axis:y}"},
        {pos: [12, 0, 7], state: "minecraft:deepslate{axis:y}"},
        {pos: [12, 0, 8], state: "minecraft:deepslate{axis:y}"},
        {pos: [12, 0, 9], state: "minecraft:deepslate{axis:y}"},
        {pos: [12, 0, 10], state: "minecraft:deepslate{axis:y}"},
        {pos: [12, 0, 11], state: "minecraft:deepslate{axis:y}"},
        {pos: [12, 0, 12], state: "minecraft:deepslate{axis:y}"},
        {pos: [12, 0, 13], state: "minecraft:deepslate{axis:y}"},
        {pos: [12, 0, 14], state: "minecraft:deepslate{axis:y}"},
        {pos: [12, 0, 15], state: "minecraft:deepslate{axis:y}"},
        {pos: [12, 0, 16], state: "minecraft:deepslate{axis:y}"},
        {pos: [12, 0, 17], state: "minecraft:deepslate{axis:y}"},
        {pos: [12, 0, 18], state: "minecraft:deepslate{axis:y}"},
        {pos: [12, 0, 19], state: "minecraft:deepslate{axis:y}"},
        {pos: [12, 0, 20], state: "minecraft:deepslate{axis:y}"},
        {pos: [13, 0, 6], state: "minecraft:deepslate{axis:y}"},
        {pos: [13, 0, 7], state: "minecraft:deepslate{axis:y}"},
        {pos: [13, 0, 8], state: "minecraft:deepslate{axis:y}"},
        {pos: [13, 0, 9], state: "minecraft:deepslate{axis:y}"},
        {pos: [13, 0, 10], state: "minecraft:deepslate{axis:y}"},
        {pos: [13, 0, 11], state: "minecraft:deepslate{axis:y}"},
        {pos: [13, 0, 12], state: "minecraft:deepslate{axis:y}"},
        {pos: [13, 0, 13], state: "minecraft:deepslate{axis:y}"},
        {pos: [13, 0, 14], state: "minecraft:deepslate{axis:y}"},
        {pos: [13, 0, 15], state: "minecraft:deepslate{axis:y}"},
        {pos: [13, 0, 16], state: "minecraft:deepslate{axis:y}"},
        {pos: [13, 0, 17], state: "minecraft:deepslate{axis:y}"},
        {pos: [13, 0, 18], state: "minecraft:deepslate{axis:y}"},
        {pos: [13, 0, 19], state: "minecraft:deepslate{axis:y}"},
        {pos: [13, 0, 20], state: "minecraft:deepslate{axis:y}"},
        {pos: [14, 0, 6], state: "minecraft:deepslate{axis:y}"},
        {pos: [14, 0, 7], state: "minecraft:deepslate{axis:y}"},
        {pos: [14, 0, 8], state: "minecraft:deepslate{axis:y}"},
        {pos: [14, 0, 9], state: "minecraft:deepslate{axis:y}"},
        {pos: [14, 0, 10], state: "minecraft:deepslate{axis:y}"},
        {pos: [14, 0, 11], state: "minecraft:deepslate{axis:y}"},
        {pos: [14, 0, 12], state: "minecraft:deepslate{axis:y}"},
        {pos: [14, 0, 13], state: "minecraft:deepslate{axis:y}"},
        {pos: [14, 0, 14], state: "minecraft:deepslate{axis:y}"},
        {pos: [14, 0, 15], state: "minecraft:deepslate{axis:y}"},
        {pos: [14, 0, 16], state: "minecraft:deepslate{axis:y}"},
        {pos: [14, 0, 17], state: "minecraft:deepslate{axis:y}"},
        {pos: [14, 0, 18], state: "minecraft:deepslate{axis:y}"},
        {pos: [14, 0, 19], state: "minecraft:deepslate{axis:y}"},
        {pos: [14, 0, 20], state: "minecraft:deepslate{axis:y}"},
        {pos: [15, 0, 6], state: "minecraft:deepslate{axis:y}"},
        {pos: [15, 0, 7], state: "minecraft:deepslate{axis:y}"},
        {pos: [15, 0, 8], state: "minecraft:deepslate{axis:y}"},
        {pos: [15, 0, 9], state: "minecraft:deepslate{axis:y}"},
        {pos: [15, 0, 10], state: "minecraft:deepslate{axis:y}"},
        {pos: [15, 0, 11], state: "minecraft:deepslate{axis:y}"},
        {pos: [15, 0, 12], state: "minecraft:deepslate{axis:y}"},
        {pos: [15, 0, 13], state: "minecraft:deepslate{axis:y}"},
        {pos: [15, 0, 14], state: "minecraft:deepslate{axis:y}"},
        {pos: [15, 0, 15], state: "minecraft:deepslate{axis:y}"},
        {pos: [15, 0, 16], state: "minecraft:deepslate{axis:y}"},
        {pos: [15, 0, 17], state: "minecraft:deepslate{axis:y}"},
        {pos: [15, 0, 18], state: "minecraft:deepslate{axis:y}"},
        {pos: [15, 0, 19], state: "minecraft:deepslate{axis:y}"},
        {pos: [15, 0, 20], state: "minecraft:deepslate{axis:y}"},
        {pos: [16, 0, 6], state: "minecraft:deepslate{axis:y}"},
        {pos: [16, 0, 7], state: "minecraft:deepslate{axis:y}"},
        {pos: [16, 0, 8], state: "minecraft:deepslate{axis:y}"},
        {pos: [16, 0, 9], state: "minecraft:deepslate{axis:y}"},
        {pos: [16, 0, 10], state: "minecraft:deepslate{axis:y}"},
        {pos: [16, 0, 11], state: "minecraft:deepslate{axis:y}"},
        {pos: [16, 0, 12], state: "minecraft:deepslate{axis:y}"},
        {pos: [16, 0, 13], state: "minecraft:deepslate{axis:y}"},
        {pos: [16, 0, 14], state: "minecraft:deepslate{axis:y}"},
        {pos: [16, 0, 15], state: "minecraft:deepslate{axis:y}"},
        {pos: [16, 0, 16], state: "minecraft:deepslate{axis:y}"},
        {pos: [16, 0, 17], state: "minecraft:deepslate{axis:y}"},
        {pos: [16, 0, 18], state: "minecraft:deepslate{axis:y}"},
        {pos: [16, 0, 19], state: "minecraft:deepslate{axis:y}"},
        {pos: [16, 0, 20], state: "minecraft:deepslate{axis:y}"},
        {pos: [17, 0, 6], state: "minecraft:deepslate{axis:y}"},
        {pos: [17, 0, 7], state: "minecraft:deepslate{axis:y}"},
        {pos: [17, 0, 8], state: "minecraft:deepslate{axis:y}"},
        {pos: [17, 0, 9], state: "minecraft:deepslate{axis:y}"},
        {pos: [17, 0, 10], state: "minecraft:deepslate{axis:y}"},
        {pos: [17, 0, 11], state: "minecraft:deepslate{axis:y}"},
        {pos: [17, 0, 12], state: "minecraft:deepslate{axis:y}"},
        {pos: [17, 0, 13], state: "minecraft:deepslate{axis:y}"},
        {pos: [17, 0, 14], state: "minecraft:deepslate{axis:y}"},
        {pos: [17, 0, 15], state: "minecraft:deepslate{axis:y}"},
        {pos: [17, 0, 16], state: "minecraft:deepslate{axis:y}"},
        {pos: [17, 0, 17], state: "minecraft:deepslate{axis:y}"},
        {pos: [17, 0, 18], state: "minecraft:deepslate{axis:y}"},
        {pos: [17, 0, 19], state: "minecraft:deepslate{axis:y}"},
        {pos: [17, 0, 20], state: "minecraft:deepslate{axis:y}"},
        {pos: [18, 0, 6], state: "minecraft:deepslate{axis:y}"},
        {pos: [18, 0, 7], state: "minecraft:deepslate{axis:y}"},
        {pos: [18, 0, 8], state: "minecraft:deepslate{axis:y}"},
        {pos: [18, 0, 9], state: "minecraft:deepslate{axis:y}"},
        {pos: [18, 0, 10], state: "minecraft:deepslate{axis:y}"},
        {pos: [18, 0, 11], state: "minecraft:deepslate{axis:y}"},
        {pos: [18, 0, 12], state: "minecraft:deepslate{axis:y}"},
        {pos: [18, 0, 13], state: "minecraft:deepslate{axis:y}"},
        {pos: [18, 0, 14], state: "minecraft:deepslate{axis:y}"},
        {pos: [18, 0, 15], state: "minecraft:deepslate{axis:y}"},
        {pos: [18, 0, 16], state: "minecraft:deepslate{axis:y}"},
        {pos: [18, 0, 17], state: "minecraft:deepslate{axis:y}"},
        {pos: [18, 0, 18], state: "minecraft:deepslate{axis:y}"},
        {pos: [18, 0, 19], state: "minecraft:deepslate{axis:y}"},
        {pos: [18, 0, 20], state: "minecraft:deepslate{axis:y}"},
        {pos: [19, 0, 6], state: "minecraft:deepslate{axis:y}"},
        {pos: [19, 0, 7], state: "minecraft:deepslate{axis:y}"},
        {pos: [19, 0, 8], state: "minecraft:deepslate{axis:y}"},
        {pos: [19, 0, 9], state: "minecraft:deepslate{axis:y}"},
        {pos: [19, 0, 10], state: "minecraft:deepslate{axis:y}"},
        {pos: [19, 0, 11], state: "minecraft:deepslate{axis:y}"},
        {pos: [19, 0, 12], state: "minecraft:deepslate{axis:y}"},
        {pos: [19, 0, 13], state: "minecraft:deepslate{axis:y}"},
        {pos: [19, 0, 14], state: "minecraft:deepslate{axis:y}"},
        {pos: [19, 0, 15], state: "minecraft:deepslate{axis:y}"},
        {pos: [19, 0, 16], state: "minecraft:deepslate{axis:y}"},
        {pos: [19, 0, 17], state: "minecraft:deepslate{axis:y}"},
        {pos: [19, 0, 18], state: "minecraft:deepslate{axis:y}"},
        {pos: [19, 0, 19], state: "minecraft:deepslate{axis:y}"},
        {pos: [19, 0, 20], state: "minecraft:deepslate{axis:y}"},
        {pos: [20, 0, 6], state: "minecraft:deepslate{axis:y}"},
        {pos: [20, 0, 7], state: "minecraft:deepslate{axis:y}"},
        {pos: [20, 0, 8], state: "minecraft:deepslate{axis:y}"},
        {pos: [20, 0, 9], state: "minecraft:deepslate{axis:y}"},
        {pos: [20, 0, 10], state: "minecraft:deepslate{axis:y}"},
        {pos: [20, 0, 11], state: "minecraft:deepslate{axis:y}"},
        {pos: [20, 0, 12], state: "minecraft:deepslate{axis:y}"},
        {pos: [20, 0, 13], state: "minecraft:deepslate{axis:y}"},
        {pos: [20, 0, 14], state: "minecraft:deepslate{axis:y}"},
        {pos: [20, 0, 15], state: "minecraft:deepslate{axis:y}"},
        {pos: [20, 0, 16], state: "minecraft:deepslate{axis:y}"},
        {pos: [20, 0, 17], state: "minecraft:deepslate{axis:y}"},
        {pos: [20, 0, 18], state: "minecraft:deepslate{axis:y}"},
        {pos: [20, 0, 19], state: "minecraft:deepslate{axis:y}"},
        {pos: [20, 0, 20], state: "minecraft:deepslate{axis:y}"},
        {pos: [21, 0, 6], state: "minecraft:deepslate{axis:y}"},
        {pos: [21, 0, 7], state: "minecraft:deepslate{axis:y}"},
        {pos: [21, 0, 8], state: "minecraft:deepslate{axis:y}"},
        {pos: [21, 0, 9], state: "minecraft:deepslate{axis:y}"},
        {pos: [21, 0, 10], state: "minecraft:deepslate{axis:y}"},
        {pos: [21, 0, 11], state: "minecraft:deepslate{axis:y}"},
        {pos: [21, 0, 12], state: "minecraft:deepslate{axis:y}"},
        {pos: [21, 0, 13], state: "minecraft:deepslate{axis:y}"},
        {pos: [21, 0, 14], state: "minecraft:deepslate{axis:y}"},
        {pos: [21, 0, 15], state: "minecraft:deepslate{axis:y}"},
        {pos: [21, 0, 16], state: "minecraft:deepslate{axis:y}"},
        {pos: [21, 0, 17], state: "minecraft:deepslate{axis:y}"},
        {pos: [21, 0, 18], state: "minecraft:deepslate{axis:y}"},
        {pos: [21, 0, 19], state: "minecraft:deepslate{axis:y}"},
        {pos: [21, 0, 20], state: "minecraft:deepslate{axis:y}"},
        {pos: [22, 0, 6], state: "minecraft:deepslate{axis:y}"},
        {pos: [22, 0, 7], state: "minecraft:deepslate{axis:y}"},
        {pos: [22, 0, 8], state: "minecraft:deepslate{axis:y}"},
        {pos: [22, 0, 9], state: "minecraft:deepslate{axis:y}"},
        {pos: [22, 0, 10], state: "minecraft:deepslate{axis:y}"},
        {pos: [22, 0, 11], state: "minecraft:deepslate{axis:y}"},
        {pos: [22, 0, 12], state: "minecraft:deepslate{axis:y}"},
        {pos: [22, 0, 13], state: "minecraft:deepslate{axis:y}"},
        {pos: [22, 0, 14], state: "minecraft:deepslate{axis:y}"},
        {pos: [22, 0, 15], state: "minecraft:deepslate{axis:y}"},
        {pos: [22, 0, 16], state: "minecraft:deepslate{axis:y}"},
        {pos: [22, 0, 17], state: "minecraft:deepslate{axis:y}"},
        {pos: [22, 0, 18], state: "minecraft:deepslate{axis:y}"},
        {pos: [22, 0, 19], state: "minecraft:deepslate{axis:y}"},
        {pos: [22, 0, 20], state: "minecraft:deepslate{axis:y}"},
        {pos: [23, 0, 6], state: "minecraft:deepslate{axis:y}"},
        {pos: [23, 0, 7], state: "minecraft:deepslate{axis:y}"},
        {pos: [23, 0, 8], state: "minecraft:deepslate{axis:y}"},
        {pos: [23, 0, 9], state: "minecraft:deepslate{axis:y}"},
        {pos: [23, 0, 10], state: "minecraft:deepslate{axis:y}"},
        {pos: [23, 0, 11], state: "minecraft:deepslate{axis:y}"},
        {pos: [23, 0, 12], state: "minecraft:deepslate{axis:y}"},
        {pos: [23, 0, 13], state: "minecraft:deepslate{axis:y}"},
        {pos: [23, 0, 14], state: "minecraft:deepslate{axis:y}"},
        {pos: [23, 0, 15], state: "minecraft:deepslate{axis:y}"},
        {pos: [23, 0, 16], state: "minecraft:deepslate{axis:y}"},
        {pos: [23, 0, 17], state: "minecraft:deepslate{axis:y}"},
        {pos: [23, 0, 18], state: "minecraft:deepslate{axis:y}"},
        {pos: [23, 0, 19], state: "minecraft:deepslate{axis:y}"},
        {pos: [23, 0, 20], state: "minecraft:deepslate{axis:y}"},
        {pos: [24, 0, 6], state: "minecraft:deepslate{axis:y}"},
        {pos: [24, 0, 7], state: "minecraft:deepslate{axis:y}"},
        {pos: [24, 0, 8], state: "minecraft:deepslate{axis:y}"},
        {pos: [24, 0, 9], state: "minecraft:deepslate{axis:y}"},
        {pos: [24, 0, 10], state: "minecraft:deepslate{axis:y}"},
        {pos: [24, 0, 11], state: "minecraft:deepslate{axis:y}"},
        {pos: [24, 0, 12], state: "minecraft:deepslate{axis:y}"},
        {pos: [24, 0, 13], state: "minecraft:deepslate{axis:y}"},
        {pos: [24, 0, 14], state: "minecraft:deepslate{axis:y}"},
        {pos: [24, 0, 15], state: "minecraft:deepslate{axis:y}"},
        {pos: [24, 0, 16], state: "minecraft:deepslate{axis:y}"},
        {pos: [24, 0, 17], state: "minecraft:deepslate{axis:y}"},
        {pos: [24, 0, 18], state: "minecraft:deepslate{axis:y}"},
        {pos: [24, 0, 19], state: "minecraft:deepslate{axis:y}"},
        {pos: [24, 0, 20], state: "minecraft:deepslate{axis:y}"},
        {pos: [25, 0, 6], state: "minecraft:deepslate{axis:y}"},
        {pos: [25, 0, 7], state: "minecraft:deepslate{axis:y}"},
        {pos: [25, 0, 8], state: "minecraft:deepslate{axis:y}"},
        {pos: [25, 0, 9], state: "minecraft:deepslate{axis:y}"},
        {pos: [25, 0, 10], state: "minecraft:deepslate{axis:y}"},
        {pos: [25, 0, 11], state: "minecraft:deepslate{axis:y}"},
        {pos: [25, 0, 12], state: "minecraft:deepslate{axis:y}"},
        {pos: [25, 0, 13], state: "minecraft:deepslate{axis:y}"},
        {pos: [25, 0, 14], state: "minecraft:deepslate{axis:y}"},
        {pos: [25, 0, 15], state: "minecraft:deepslate{axis:y}"},
        {pos: [25, 0, 16], state: "minecraft:deepslate{axis:y}"},
        {pos: [25, 0, 17], state: "minecraft:deepslate{axis:y}"},
        {pos: [25, 0, 18], state: "minecraft:deepslate{axis:y}"},
        {pos: [25, 0, 19], state: "minecraft:deepslate{axis:y}"},
        {pos: [25, 0, 20], state: "minecraft:deepslate{axis:y}"},
        {pos: [26, 0, 6], state: "minecraft:deepslate{axis:y}"},
        {pos: [26, 0, 7], state: "minecraft:deepslate{axis:y}"},
        {pos: [26, 0, 8], state: "minecraft:deepslate{axis:y}"},
        {pos: [26, 0, 9], state: "minecraft:deepslate{axis:y}"},
        {pos: [26, 0, 10], state: "minecraft:deepslate{axis:y}"},
        {pos: [26, 0, 11], state: "minecraft:deepslate{axis:y}"},
        {pos: [26, 0, 12], state: "minecraft:deepslate{axis:y}"},
        {pos: [26, 0, 13], state: "minecraft:deepslate{axis:y}"},
        {pos: [26, 0, 14], state: "minecraft:deepslate{axis:y}"},
        {pos: [26, 0, 15], state: "minecraft:deepslate{axis:y}"},
        {pos: [26, 0, 16], state: "minecraft:deepslate{axis:y}"},
        {pos: [26, 0, 17], state: "minecraft:deepslate{axis:y}"},
        {pos: [26, 0, 18], state: "minecraft:deepslate{axis:y}"},
        {pos: [26, 0, 19], state: "minecraft:deepslate{axis:y}"},
        {pos: [26, 0, 20], state: "minecraft:deepslate{axis:y}"},
        {pos: [27, 0, 11], state: "minecraft:deepslate{axis:y}"},
        {pos: [27, 0, 12], state: "minecraft:deepslate{axis:y}"},
        {pos: [27, 0, 13], state: "minecraft:deepslate{axis:y}"},
        {pos: [27, 0, 14], state: "minecraft:deepslate{axis:y}"},
        {pos: [27, 0, 15], state: "minecraft:deepslate{axis:y}"},
        {pos: [27, 0, 16], state: "minecraft:deepslate{axis:y}"},
        {pos: [27, 0, 17], state: "minecraft:deepslate{axis:y}"},
        {pos: [27, 0, 18], state: "minecraft:deepslate{axis:y}"},
        {pos: [28, 0, 11], state: "minecraft:deepslate{axis:y}"},
        {pos: [28, 0, 12], state: "minecraft:deepslate{axis:y}"},
        {pos: [28, 0, 13], state: "minecraft:deepslate{axis:y}"},
        {pos: [28, 0, 14], state: "minecraft:deepslate{axis:y}"},
        {pos: [28, 0, 15], state: "minecraft:deepslate{axis:y}"},
        {pos: [28, 0, 16], state: "minecraft:deepslate{axis:y}"},
        {pos: [28, 0, 17], state: "minecraft:deepslate{axis:y}"},
        {pos: [28, 0, 18], state: "minecraft:deepslate{axis:y}"},
        {pos: [29, 0, 11], state: "minecraft:deepslate{axis:y}"},
        {pos: [29, 0, 12], state: "minecraft:deepslate{axis:y}"},
        {pos: [29, 0, 13], state: "minecraft:deepslate{axis:y}"},
        {pos: [29, 0, 14], state: "minecraft:deepslate{axis:y}"},
        {pos: [29, 0, 15], state: "minecraft:deepslate{axis:y}"},
        {pos: [29, 0, 16], state: "minecraft:deepslate{axis:y}"},
        {pos: [29, 0, 17], state: "minecraft:deepslate{axis:y}"},
        {pos: [29, 0, 18], state: "minecraft:deepslate{axis:y}"},
        {pos: [0, 1, 10], state: "minecraft:deepslate_bricks"},
        {pos: [0, 1, 11], state: "minecraft:deepslate_bricks"},
        {pos: [0, 1, 12], state: "minecraft:gravel"},
        {pos: [0, 1, 13], state: "minecraft:gravel"},
        {pos: [0, 1, 14], state: "minecraft:gravel"},
        {pos: [0, 1, 15], state: "minecraft:deepslate_bricks"},
        {pos: [0, 1, 16], state: "minecraft:deepslate_bricks"},
        {pos: [1, 1, 10], state: "minecraft:deepslate_bricks"},
        {pos: [1, 1, 11], state: "minecraft:gravel"},
        {pos: [1, 1, 12], state: "minecraft:gravel"},
        {pos: [1, 1, 13], state: "minecraft:gravel"},
        {pos: [1, 1, 14], state: "minecraft:gravel"},
        {pos: [1, 1, 15], state: "minecraft:gravel"},
        {pos: [1, 1, 16], state: "minecraft:deepslate_bricks"},
        {pos: [2, 1, 10], state: "minecraft:deepslate_bricks"},
        {pos: [2, 1, 11], state: "minecraft:deepslate_bricks"},
        {pos: [2, 1, 12], state: "minecraft:gravel"},
        {pos: [2, 1, 13], state: "minecraft:gravel"},
        {pos: [2, 1, 14], state: "minecraft:gravel"},
        {pos: [2, 1, 15], state: "minecraft:deepslate_bricks"},
        {pos: [2, 1, 16], state: "minecraft:deepslate_bricks"},
        {pos: [3, 1, 6], state: "minecraft:deepslate_bricks"},
        {pos: [3, 1, 7], state: "minecraft:deepslate_bricks"},
        {pos: [3, 1, 8], state: "minecraft:deepslate_bricks"},
        {pos: [3, 1, 9], state: "minecraft:deepslate_bricks"},
        {pos: [3, 1, 10], state: "minecraft:gravel"},
        {pos: [3, 1, 11], state: "minecraft:gravel"},
        {pos: [3, 1, 12], state: "minecraft:gravel"},
        {pos: [3, 1, 13], state: "minecraft:gravel"},
        {pos: [3, 1, 14], state: "minecraft:gravel"},
        {pos: [3, 1, 15], state: "minecraft:gravel"},
        {pos: [3, 1, 16], state: "minecraft:gravel"},
        {pos: [3, 1, 17], state: "minecraft:deepslate_bricks"},
        {pos: [3, 1, 18], state: "minecraft:deepslate_bricks"},
        {pos: [3, 1, 19], state: "minecraft:deepslate_bricks"},
        {pos: [3, 1, 20], state: "minecraft:deepslate_bricks"},
        {pos: [4, 1, 6], state: "minecraft:deepslate_bricks"},
        {pos: [4, 1, 7], state: "minecraft:deepslate_bricks"},
        {pos: [4, 1, 8], state: "minecraft:deepslate_bricks"},
        {pos: [4, 1, 9], state: "minecraft:gravel"},
        {pos: [4, 1, 10], state: "minecraft:gravel"},
        {pos: [4, 1, 11], state: "minecraft:gravel"},
        {pos: [4, 1, 12], state: "minecraft:gravel"},
        {pos: [4, 1, 13], state: "minecraft:gravel"},
        {pos: [4, 1, 14], state: "minecraft:gravel"},
        {pos: [4, 1, 15], state: "minecraft:gravel"},
        {pos: [4, 1, 16], state: "minecraft:gravel"},
        {pos: [4, 1, 17], state: "minecraft:gravel"},
        {pos: [4, 1, 18], state: "minecraft:deepslate_bricks"},
        {pos: [4, 1, 19], state: "minecraft:deepslate_bricks"},
        {pos: [4, 1, 20], state: "minecraft:deepslate_bricks"},
        {pos: [5, 1, 6], state: "minecraft:deepslate_bricks"},
        {pos: [5, 1, 7], state: "minecraft:deepslate_bricks"},
        {pos: [5, 1, 8], state: "minecraft:gravel"},
        {pos: [5, 1, 9], state: "minecraft:deepslate_bricks"},
        {pos: [5, 1, 10], state: "minecraft:gravel"},
        {pos: [5, 1, 11], state: "minecraft:gravel"},
        {pos: [5, 1, 12], state: "minecraft:gravel"},
        {pos: [5, 1, 13], state: "minecraft:gravel"},
        {pos: [5, 1, 14], state: "minecraft:gravel"},
        {pos: [5, 1, 15], state: "minecraft:gravel"},
        {pos: [5, 1, 16], state: "minecraft:gravel"},
        {pos: [5, 1, 17], state: "minecraft:deepslate_bricks"},
        {pos: [5, 1, 18], state: "minecraft:gravel"},
        {pos: [5, 1, 19], state: "minecraft:deepslate_bricks"},
        {pos: [5, 1, 20], state: "minecraft:deepslate_bricks"},
        {pos: [6, 1, 5], state: "minecraft:deepslate_bricks"},
        {pos: [6, 1, 6], state: "minecraft:gravel"},
        {pos: [6, 1, 7], state: "minecraft:gravel"},
        {pos: [6, 1, 8], state: "minecraft:gravel"},
        {pos: [6, 1, 9], state: "minecraft:gravel"},
        {pos: [6, 1, 10], state: "minecraft:gravel"},
        {pos: [6, 1, 11], state: "minecraft:gravel"},
        {pos: [6, 1, 12], state: "minecraft:gravel"},
        {pos: [6, 1, 13], state: "minecraft:gravel"},
        {pos: [6, 1, 14], state: "minecraft:gravel"},
        {pos: [6, 1, 15], state: "minecraft:gravel"},
        {pos: [6, 1, 16], state: "minecraft:gravel"},
        {pos: [6, 1, 17], state: "minecraft:gravel"},
        {pos: [6, 1, 18], state: "minecraft:gravel"},
        {pos: [6, 1, 19], state: "minecraft:gravel"},
        {pos: [6, 1, 20], state: "minecraft:gravel"},
        {pos: [6, 1, 21], state: "minecraft:deepslate_bricks"},
        {pos: [7, 1, 5], state: "minecraft:deepslate_bricks"},
        {pos: [7, 1, 6], state: "minecraft:gravel"},
        {pos: [7, 1, 7], state: "minecraft:gravel"},
        {pos: [7, 1, 8], state: "minecraft:gravel"},
        {pos: [7, 1, 9], state: "minecraft:gravel"},
        {pos: [7, 1, 10], state: "minecraft:gravel"},
        {pos: [7, 1, 11], state: "minecraft:gravel"},
        {pos: [7, 1, 12], state: "minecraft:gravel"},
        {pos: [7, 1, 13], state: "minecraft:gravel"},
        {pos: [7, 1, 14], state: "minecraft:gravel"},
        {pos: [7, 1, 15], state: "minecraft:gravel"},
        {pos: [7, 1, 16], state: "minecraft:gravel"},
        {pos: [7, 1, 17], state: "minecraft:gravel"},
        {pos: [7, 1, 18], state: "minecraft:gravel"},
        {pos: [7, 1, 19], state: "minecraft:gravel"},
        {pos: [7, 1, 20], state: "minecraft:gravel"},
        {pos: [7, 1, 21], state: "minecraft:deepslate_bricks"},
        {pos: [8, 1, 5], state: "minecraft:deepslate_bricks"},
        {pos: [8, 1, 6], state: "minecraft:gravel"},
        {pos: [8, 1, 7], state: "minecraft:gravel"},
        {pos: [8, 1, 8], state: "minecraft:gravel"},
        {pos: [8, 1, 9], state: "minecraft:gravel"},
        {pos: [8, 1, 10], state: "minecraft:gravel"},
        {pos: [8, 1, 11], state: "minecraft:gravel"},
        {pos: [8, 1, 12], state: "minecraft:gravel"},
        {pos: [8, 1, 13], state: "minecraft:gravel"},
        {pos: [8, 1, 14], state: "minecraft:gravel"},
        {pos: [8, 1, 15], state: "minecraft:gravel"},
        {pos: [8, 1, 16], state: "minecraft:gravel"},
        {pos: [8, 1, 17], state: "minecraft:gravel"},
        {pos: [8, 1, 18], state: "minecraft:gravel"},
        {pos: [8, 1, 19], state: "minecraft:gravel"},
        {pos: [8, 1, 20], state: "minecraft:gravel"},
        {pos: [8, 1, 21], state: "minecraft:deepslate_bricks"},
        {pos: [9, 1, 5], state: "minecraft:deepslate_bricks"},
        {pos: [9, 1, 6], state: "minecraft:gravel"},
        {pos: [9, 1, 7], state: "minecraft:gravel"},
        {pos: [9, 1, 8], state: "minecraft:gravel"},
        {pos: [9, 1, 9], state: "minecraft:gravel"},
        {pos: [9, 1, 10], state: "minecraft:gravel"},
        {pos: [9, 1, 11], state: "minecraft:gravel"},
        {pos: [9, 1, 12], state: "minecraft:gravel"},
        {pos: [9, 1, 13], state: "minecraft:gravel"},
        {pos: [9, 1, 14], state: "minecraft:gravel"},
        {pos: [9, 1, 15], state: "minecraft:gravel"},
        {pos: [9, 1, 16], state: "minecraft:gravel"},
        {pos: [9, 1, 17], state: "minecraft:gravel"},
        {pos: [9, 1, 18], state: "minecraft:gravel"},
        {pos: [9, 1, 19], state: "minecraft:gravel"},
        {pos: [9, 1, 20], state: "minecraft:gravel"},
        {pos: [9, 1, 21], state: "minecraft:deepslate_bricks"},
        {pos: [10, 1, 5], state: "minecraft:deepslate_bricks"},
        {pos: [10, 1, 6], state: "minecraft:gravel"},
        {pos: [10, 1, 7], state: "minecraft:gravel"},
        {pos: [10, 1, 8], state: "minecraft:gravel"},
        {pos: [10, 1, 9], state: "minecraft:gravel"},
        {pos: [10, 1, 10], state: "minecraft:gravel"},
        {pos: [10, 1, 11], state: "minecraft:gravel"},
        {pos: [10, 1, 12], state: "minecraft:gravel"},
        {pos: [10, 1, 13], state: "minecraft:gravel"},
        {pos: [10, 1, 14], state: "minecraft:gravel"},
        {pos: [10, 1, 15], state: "minecraft:gravel"},
        {pos: [10, 1, 16], state: "minecraft:gravel"},
        {pos: [10, 1, 17], state: "minecraft:gravel"},
        {pos: [10, 1, 18], state: "minecraft:gravel"},
        {pos: [10, 1, 19], state: "minecraft:gravel"},
        {pos: [10, 1, 20], state: "minecraft:gravel"},
        {pos: [10, 1, 21], state: "minecraft:deepslate_bricks"},
        {pos: [11, 1, 6], state: "minecraft:deepslate_bricks"},
        {pos: [11, 1, 7], state: "minecraft:gravel"},
        {pos: [11, 1, 8], state: "minecraft:gravel"},
        {pos: [11, 1, 9], state: "minecraft:gravel"},
        {pos: [11, 1, 10], state: "minecraft:gravel"},
        {pos: [11, 1, 11], state: "minecraft:gravel"},
        {pos: [11, 1, 12], state: "minecraft:gravel"},
        {pos: [11, 1, 13], state: "minecraft:gravel"},
        {pos: [11, 1, 14], state: "minecraft:gravel"},
        {pos: [11, 1, 15], state: "minecraft:gravel"},
        {pos: [11, 1, 16], state: "minecraft:gravel"},
        {pos: [11, 1, 17], state: "minecraft:gravel"},
        {pos: [11, 1, 18], state: "minecraft:gravel"},
        {pos: [11, 1, 19], state: "minecraft:gravel"},
        {pos: [11, 1, 20], state: "minecraft:deepslate_bricks"},
        {pos: [12, 1, 6], state: "minecraft:deepslate_bricks"},
        {pos: [12, 1, 7], state: "minecraft:gravel"},
        {pos: [12, 1, 8], state: "minecraft:gravel"},
        {pos: [12, 1, 9], state: "minecraft:gravel"},
        {pos: [12, 1, 10], state: "minecraft:gravel"},
        {pos: [12, 1, 11], state: "minecraft:gravel"},
        {pos: [12, 1, 12], state: "minecraft:gravel"},
        {pos: [12, 1, 13], state: "minecraft:gravel"},
        {pos: [12, 1, 14], state: "minecraft:gravel"},
        {pos: [12, 1, 15], state: "minecraft:gravel"},
        {pos: [12, 1, 16], state: "minecraft:gravel"},
        {pos: [12, 1, 17], state: "minecraft:gravel"},
        {pos: [12, 1, 18], state: "minecraft:gravel"},
        {pos: [12, 1, 19], state: "minecraft:gravel"},
        {pos: [12, 1, 20], state: "minecraft:deepslate_bricks"},
        {pos: [13, 1, 6], state: "minecraft:deepslate_bricks"},
        {pos: [13, 1, 7], state: "minecraft:gravel"},
        {pos: [13, 1, 8], state: "minecraft:gravel"},
        {pos: [13, 1, 9], state: "minecraft:gravel"},
        {pos: [13, 1, 10], state: "minecraft:gravel"},
        {pos: [13, 1, 11], state: "minecraft:gravel"},
        {pos: [13, 1, 12], state: "minecraft:gravel"},
        {pos: [13, 1, 13], state: "minecraft:gravel"},
        {pos: [13, 1, 14], state: "minecraft:gravel"},
        {pos: [13, 1, 15], state: "minecraft:gravel"},
        {pos: [13, 1, 16], state: "minecraft:gravel"},
        {pos: [13, 1, 17], state: "minecraft:gravel"},
        {pos: [13, 1, 18], state: "minecraft:gravel"},
        {pos: [13, 1, 19], state: "minecraft:gravel"},
        {pos: [13, 1, 20], state: "minecraft:deepslate_bricks"},
        {pos: [14, 1, 6], state: "minecraft:deepslate_bricks"},
        {pos: [14, 1, 7], state: "minecraft:gravel"},
        {pos: [14, 1, 8], state: "minecraft:gravel"},
        {pos: [14, 1, 9], state: "minecraft:gravel"},
        {pos: [14, 1, 10], state: "minecraft:gravel"},
        {pos: [14, 1, 11], state: "minecraft:gravel"},
        {pos: [14, 1, 12], state: "minecraft:gravel"},
        {pos: [14, 1, 13], state: "minecraft:gravel"},
        {pos: [14, 1, 14], state: "minecraft:gravel"},
        {pos: [14, 1, 15], state: "minecraft:gravel"},
        {pos: [14, 1, 16], state: "minecraft:gravel"},
        {pos: [14, 1, 17], state: "minecraft:gravel"},
        {pos: [14, 1, 18], state: "minecraft:gravel"},
        {pos: [14, 1, 19], state: "minecraft:gravel"},
        {pos: [14, 1, 20], state: "minecraft:deepslate_bricks"},
        {pos: [15, 1, 6], state: "minecraft:deepslate_bricks"},
        {pos: [15, 1, 7], state: "minecraft:gravel"},
        {pos: [15, 1, 8], state: "minecraft:gravel"},
        {pos: [15, 1, 9], state: "minecraft:gravel"},
        {pos: [15, 1, 10], state: "minecraft:gravel"},
        {pos: [15, 1, 11], state: "minecraft:gravel"},
        {pos: [15, 1, 12], state: "minecraft:gravel"},
        {pos: [15, 1, 13], state: "minecraft:gravel"},
        {pos: [15, 1, 14], state: "minecraft:gravel"},
        {pos: [15, 1, 15], state: "minecraft:gravel"},
        {pos: [15, 1, 16], state: "minecraft:gravel"},
        {pos: [15, 1, 17], state: "minecraft:gravel"},
        {pos: [15, 1, 18], state: "minecraft:gravel"},
        {pos: [15, 1, 19], state: "minecraft:gravel"},
        {pos: [15, 1, 20], state: "minecraft:deepslate_bricks"},
        {pos: [16, 1, 6], state: "minecraft:deepslate_bricks"},
        {pos: [16, 1, 7], state: "minecraft:gravel"},
        {pos: [16, 1, 8], state: "minecraft:gravel"},
        {pos: [16, 1, 9], state: "minecraft:gravel"},
        {pos: [16, 1, 10], state: "minecraft:gravel"},
        {pos: [16, 1, 11], state: "minecraft:gravel"},
        {pos: [16, 1, 12], state: "minecraft:gravel"},
        {pos: [16, 1, 13], state: "minecraft:gravel"},
        {pos: [16, 1, 14], state: "minecraft:gravel"},
        {pos: [16, 1, 15], state: "minecraft:gravel"},
        {pos: [16, 1, 16], state: "minecraft:gravel"},
        {pos: [16, 1, 17], state: "minecraft:gravel"},
        {pos: [16, 1, 18], state: "minecraft:gravel"},
        {pos: [16, 1, 19], state: "minecraft:gravel"},
        {pos: [16, 1, 20], state: "minecraft:deepslate_bricks"},
        {pos: [17, 1, 6], state: "minecraft:deepslate_bricks"},
        {pos: [17, 1, 7], state: "minecraft:gravel"},
        {pos: [17, 1, 8], state: "minecraft:gravel"},
        {pos: [17, 1, 9], state: "minecraft:gravel"},
        {pos: [17, 1, 10], state: "minecraft:gravel"},
        {pos: [17, 1, 11], state: "minecraft:gravel"},
        {pos: [17, 1, 12], state: "minecraft:gravel"},
        {pos: [17, 1, 13], state: "minecraft:gravel"},
        {pos: [17, 1, 14], state: "minecraft:gravel"},
        {pos: [17, 1, 15], state: "minecraft:gravel"},
        {pos: [17, 1, 16], state: "minecraft:gravel"},
        {pos: [17, 1, 17], state: "minecraft:gravel"},
        {pos: [17, 1, 18], state: "minecraft:gravel"},
        {pos: [17, 1, 19], state: "minecraft:gravel"},
        {pos: [17, 1, 20], state: "minecraft:deepslate_bricks"},
        {pos: [18, 1, 6], state: "minecraft:deepslate_bricks"},
        {pos: [18, 1, 7], state: "minecraft:gravel"},
        {pos: [18, 1, 8], state: "minecraft:gravel"},
        {pos: [18, 1, 9], state: "minecraft:gravel"},
        {pos: [18, 1, 10], state: "minecraft:gravel"},
        {pos: [18, 1, 11], state: "minecraft:gravel"},
        {pos: [18, 1, 12], state: "minecraft:gravel"},
        {pos: [18, 1, 13], state: "minecraft:gravel"},
        {pos: [18, 1, 14], state: "minecraft:gravel"},
        {pos: [18, 1, 15], state: "minecraft:gravel"},
        {pos: [18, 1, 16], state: "minecraft:gravel"},
        {pos: [18, 1, 17], state: "minecraft:gravel"},
        {pos: [18, 1, 18], state: "minecraft:gravel"},
        {pos: [18, 1, 19], state: "minecraft:gravel"},
        {pos: [18, 1, 20], state: "minecraft:deepslate_bricks"},
        {pos: [19, 1, 6], state: "minecraft:deepslate_bricks"},
        {pos: [19, 1, 7], state: "minecraft:gravel"},
        {pos: [19, 1, 8], state: "minecraft:gravel"},
        {pos: [19, 1, 9], state: "minecraft:gravel"},
        {pos: [19, 1, 10], state: "minecraft:gravel"},
        {pos: [19, 1, 11], state: "minecraft:gravel"},
        {pos: [19, 1, 12], state: "minecraft:gravel"},
        {pos: [19, 1, 13], state: "minecraft:gravel"},
        {pos: [19, 1, 14], state: "minecraft:gravel"},
        {pos: [19, 1, 15], state: "minecraft:gravel"},
        {pos: [19, 1, 16], state: "minecraft:gravel"},
        {pos: [19, 1, 17], state: "minecraft:gravel"},
        {pos: [19, 1, 18], state: "minecraft:gravel"},
        {pos: [19, 1, 19], state: "minecraft:gravel"},
        {pos: [19, 1, 20], state: "minecraft:deepslate_bricks"},
        {pos: [20, 1, 6], state: "minecraft:deepslate_bricks"},
        {pos: [20, 1, 7], state: "minecraft:gravel"},
        {pos: [20, 1, 8], state: "minecraft:gravel"},
        {pos: [20, 1, 9], state: "minecraft:gravel"},
        {pos: [20, 1, 10], state: "minecraft:gravel"},
        {pos: [20, 1, 11], state: "minecraft:gravel"},
        {pos: [20, 1, 12], state: "minecraft:gravel"},
        {pos: [20, 1, 13], state: "minecraft:gravel"},
        {pos: [20, 1, 14], state: "minecraft:gravel"},
        {pos: [20, 1, 15], state: "minecraft:gravel"},
        {pos: [20, 1, 16], state: "minecraft:gravel"},
        {pos: [20, 1, 17], state: "minecraft:gravel"},
        {pos: [20, 1, 18], state: "minecraft:gravel"},
        {pos: [20, 1, 19], state: "minecraft:gravel"},
        {pos: [20, 1, 20], state: "minecraft:deepslate_bricks"},
        {pos: [21, 1, 6], state: "minecraft:deepslate_bricks"},
        {pos: [21, 1, 7], state: "minecraft:deepslate_bricks"},
        {pos: [21, 1, 8], state: "minecraft:deepslate_bricks"},
        {pos: [21, 1, 9], state: "minecraft:deepslate_bricks"},
        {pos: [21, 1, 10], state: "minecraft:deepslate_bricks"},
        {pos: [21, 1, 11], state: "minecraft:deepslate_bricks"},
        {pos: [21, 1, 12], state: "minecraft:gravel"},
        {pos: [21, 1, 13], state: "minecraft:gravel"},
        {pos: [21, 1, 14], state: "minecraft:gravel"},
        {pos: [21, 1, 15], state: "minecraft:deepslate_bricks"},
        {pos: [21, 1, 16], state: "minecraft:deepslate_bricks"},
        {pos: [21, 1, 17], state: "minecraft:deepslate_bricks"},
        {pos: [21, 1, 18], state: "minecraft:deepslate_bricks"},
        {pos: [21, 1, 19], state: "minecraft:deepslate_bricks"},
        {pos: [21, 1, 20], state: "minecraft:deepslate_bricks"},
        {pos: [22, 1, 6], state: "minecraft:deepslate_bricks"},
        {pos: [22, 1, 7], state: "minecraft:deepslate_bricks"},
        {pos: [22, 1, 8], state: "minecraft:deepslate_bricks"},
        {pos: [22, 1, 9], state: "minecraft:deepslate_bricks"},
        {pos: [22, 1, 10], state: "minecraft:deepslate_bricks"},
        {pos: [22, 1, 11], state: "minecraft:deepslate_bricks"},
        {pos: [22, 1, 12], state: "minecraft:gravel"},
        {pos: [22, 1, 13], state: "minecraft:gravel"},
        {pos: [22, 1, 14], state: "minecraft:gravel"},
        {pos: [22, 1, 15], state: "minecraft:deepslate_bricks"},
        {pos: [22, 1, 16], state: "minecraft:deepslate_bricks"},
        {pos: [22, 1, 17], state: "minecraft:deepslate_bricks"},
        {pos: [22, 1, 18], state: "minecraft:deepslate_bricks"},
        {pos: [22, 1, 19], state: "minecraft:deepslate_bricks"},
        {pos: [22, 1, 20], state: "minecraft:deepslate_bricks"},
        {pos: [23, 1, 6], state: "minecraft:deepslate_bricks"},
        {pos: [23, 1, 7], state: "minecraft:gravel"},
        {pos: [23, 1, 8], state: "minecraft:gravel"},
        {pos: [23, 1, 9], state: "minecraft:gravel"},
        {pos: [23, 1, 10], state: "minecraft:gravel"},
        {pos: [23, 1, 11], state: "minecraft:gravel"},
        {pos: [23, 1, 12], state: "minecraft:gravel"},
        {pos: [23, 1, 13], state: "minecraft:gravel"},
        {pos: [23, 1, 14], state: "minecraft:gravel"},
        {pos: [23, 1, 15], state: "minecraft:gravel"},
        {pos: [23, 1, 16], state: "minecraft:gravel"},
        {pos: [23, 1, 17], state: "minecraft:gravel"},
        {pos: [23, 1, 18], state: "minecraft:gravel"},
        {pos: [23, 1, 19], state: "minecraft:gravel"},
        {pos: [23, 1, 20], state: "minecraft:deepslate_bricks"},
        {pos: [24, 1, 6], state: "minecraft:deepslate_bricks"},
        {pos: [24, 1, 7], state: "minecraft:gravel"},
        {pos: [24, 1, 8], state: "minecraft:gravel"},
        {pos: [24, 1, 9], state: "minecraft:gravel"},
        {pos: [24, 1, 10], state: "minecraft:gravel"},
        {pos: [24, 1, 11], state: "minecraft:gravel"},
        {pos: [24, 1, 12], state: "minecraft:gravel"},
        {pos: [24, 1, 13], state: "minecraft:gravel"},
        {pos: [24, 1, 14], state: "minecraft:gravel"},
        {pos: [24, 1, 15], state: "minecraft:gravel"},
        {pos: [24, 1, 16], state: "minecraft:gravel"},
        {pos: [24, 1, 17], state: "minecraft:gravel"},
        {pos: [24, 1, 18], state: "minecraft:gravel"},
        {pos: [24, 1, 19], state: "minecraft:gravel"},
        {pos: [24, 1, 20], state: "minecraft:deepslate_bricks"},
        {pos: [25, 1, 6], state: "minecraft:deepslate_bricks"},
        {pos: [25, 1, 7], state: "minecraft:gravel"},
        {pos: [25, 1, 8], state: "minecraft:gravel"},
        {pos: [25, 1, 9], state: "minecraft:gravel"},
        {pos: [25, 1, 10], state: "minecraft:gravel"},
        {pos: [25, 1, 11], state: "minecraft:gravel"},
        {pos: [25, 1, 12], state: "minecraft:gravel"},
        {pos: [25, 1, 13], state: "minecraft:gravel"},
        {pos: [25, 1, 14], state: "minecraft:gravel"},
        {pos: [25, 1, 15], state: "minecraft:gravel"},
        {pos: [25, 1, 16], state: "minecraft:gravel"},
        {pos: [25, 1, 17], state: "minecraft:gravel"},
        {pos: [25, 1, 18], state: "minecraft:gravel"},
        {pos: [25, 1, 19], state: "minecraft:gravel"},
        {pos: [25, 1, 20], state: "minecraft:deepslate_bricks"},
        {pos: [26, 1, 6], state: "minecraft:deepslate_bricks"},
        {pos: [26, 1, 7], state: "minecraft:deepslate_bricks"},
        {pos: [26, 1, 8], state: "minecraft:deepslate_bricks"},
        {pos: [26, 1, 9], state: "minecraft:deepslate_bricks"},
        {pos: [26, 1, 10], state: "minecraft:deepslate_bricks"},
        {pos: [26, 1, 11], state: "minecraft:deepslate_bricks"},
        {pos: [26, 1, 12], state: "minecraft:gravel"},
        {pos: [26, 1, 13], state: "minecraft:gravel"},
        {pos: [26, 1, 14], state: "minecraft:gravel"},
        {pos: [26, 1, 15], state: "minecraft:deepslate_bricks"},
        {pos: [26, 1, 16], state: "minecraft:deepslate_bricks"},
        {pos: [26, 1, 17], state: "minecraft:deepslate_bricks"},
        {pos: [26, 1, 18], state: "minecraft:deepslate_bricks"},
        {pos: [26, 1, 19], state: "minecraft:deepslate_bricks"},
        {pos: [26, 1, 20], state: "minecraft:deepslate_bricks"},
        {pos: [27, 1, 11], state: "minecraft:deepslate_bricks"},
        {pos: [27, 1, 12], state: "minecraft:gravel"},
        {pos: [27, 1, 13], state: "minecraft:gravel"},
        {pos: [27, 1, 14], state: "minecraft:gravel"},
        {pos: [27, 1, 15], state: "minecraft:deepslate_bricks"},
        {pos: [27, 1, 16], state: "minecraft:gravel"},
        {pos: [27, 1, 17], state: "minecraft:gravel"},
        {pos: [27, 1, 18], state: "minecraft:deepslate_bricks"},
        {pos: [28, 1, 11], state: "minecraft:deepslate_bricks"},
        {pos: [28, 1, 12], state: "minecraft:gravel"},
        {pos: [28, 1, 13], state: "minecraft:gravel"},
        {pos: [28, 1, 14], state: "minecraft:gravel"},
        {pos: [28, 1, 15], state: "minecraft:deepslate_bricks"},
        {pos: [28, 1, 16], state: "minecraft:gravel"},
        {pos: [28, 1, 17], state: "minecraft:gravel"},
        {pos: [28, 1, 18], state: "minecraft:deepslate_bricks"},
        {pos: [29, 1, 11], state: "minecraft:deepslate_bricks"},
        {pos: [29, 1, 12], state: "minecraft:gravel"},
        {pos: [29, 1, 13], state: "minecraft:gravel"},
        {pos: [29, 1, 14], state: "minecraft:gravel"},
        {pos: [29, 1, 15], state: "minecraft:deepslate_bricks"},
        {pos: [29, 1, 16], state: "minecraft:deepslate_bricks"},
        {pos: [29, 1, 17], state: "minecraft:deepslate_bricks"},
        {pos: [29, 1, 18], state: "minecraft:deepslate_bricks"},
        {pos: [0, 2, 10], state: "minecraft:deepslate_bricks"},
        {pos: [0, 2, 11], state: "minecraft:deepslate_bricks"},
        {pos: [0, 2, 12], state: "minecraft:candle{candles:4,lit:false,waterlogged:false}"},
        {pos: [0, 2, 13], state: "minecraft:jigsaw{orientation:west_up}", nbt: {final_state: "minecraft:cave_air", id: "minecraft:jigsaw", joint: "rollable", name: "trailiertales:corridor", placement_priority: 0, pool: "trailiertales:catacombs/corridor_connector", selection_priority: 0, target: "trailiertales:corridor"}},
        {pos: [0, 2, 14], state: "minecraft:candle{candles:4,lit:false,waterlogged:false}"},
        {pos: [0, 2, 15], state: "minecraft:deepslate_bricks"},
        {pos: [0, 2, 16], state: "minecraft:deepslate_bricks"},
        {pos: [1, 2, 10], state: "minecraft:deepslate_bricks"},
        {pos: [1, 2, 11], state: "minecraft:deepslate_brick_stairs{facing:north,half:top,shape:straight,waterlogged:false}"},
        {pos: [1, 2, 12], state: "minecraft:candle{candles:4,lit:false,waterlogged:false}"},
        {pos: [1, 2, 13], state: "minecraft:cave_air"},
        {pos: [1, 2, 14], state: "minecraft:candle{candles:4,lit:false,waterlogged:false}"},
        {pos: [1, 2, 15], state: "minecraft:deepslate_brick_stairs{facing:south,half:top,shape:straight,waterlogged:false}"},
        {pos: [1, 2, 16], state: "minecraft:deepslate_bricks"},
        {pos: [2, 2, 10], state: "minecraft:deepslate_bricks"},
        {pos: [2, 2, 11], state: "minecraft:deepslate_bricks"},
        {pos: [2, 2, 12], state: "minecraft:candle{candles:4,lit:false,waterlogged:false}"},
        {pos: [2, 2, 13], state: "minecraft:cave_air"},
        {pos: [2, 2, 14], state: "minecraft:candle{candles:4,lit:false,waterlogged:false}"},
        {pos: [2, 2, 15], state: "minecraft:deepslate_bricks"},
        {pos: [2, 2, 16], state: "minecraft:deepslate_bricks"},
        {pos: [3, 2, 6], state: "minecraft:deepslate_bricks"},
        {pos: [3, 2, 7], state: "minecraft:deepslate_bricks"},
        {pos: [3, 2, 8], state: "minecraft:deepslate_bricks"},
        {pos: [3, 2, 9], state: "minecraft:deepslate_bricks"},
        {pos: [3, 2, 10], state: "minecraft:gray_glazed_terracotta{facing:east}"},
        {pos: [3, 2, 11], state: "minecraft:gray_glazed_terracotta{facing:south}"},
        {pos: [3, 2, 12], state: "minecraft:cave_air"},
        {pos: [3, 2, 13], state: "minecraft:cave_air"},
        {pos: [3, 2, 14], state: "minecraft:cave_air"},
        {pos: [3, 2, 15], state: "minecraft:candle{candles:4,lit:false,waterlogged:false}"},
        {pos: [3, 2, 16], state: "minecraft:candle{candles:4,lit:false,waterlogged:false}"},
        {pos: [3, 2, 17], state: "minecraft:deepslate_bricks"},
        {pos: [3, 2, 18], state: "minecraft:deepslate_bricks"},
        {pos: [3, 2, 19], state: "minecraft:deepslate_bricks"},
        {pos: [3, 2, 20], state: "minecraft:deepslate_bricks"},
        {pos: [4, 2, 6], state: "minecraft:deepslate_bricks"},
        {pos: [4, 2, 7], state: "minecraft:deepslate_bricks"},
        {pos: [4, 2, 8], state: "minecraft:deepslate_bricks"},
        {pos: [4, 2, 9], state: "minecraft:deepslate_brick_stairs{facing:north,half:top,shape:straight,waterlogged:false}"},
        {pos: [4, 2, 10], state: "minecraft:candle{candles:4,lit:false,waterlogged:false}"},
        {pos: [4, 2, 11], state: "minecraft:cave_air"},
        {pos: [4, 2, 12], state: "minecraft:cave_air"},
        {pos: [4, 2, 13], state: "minecraft:cave_air"},
        {pos: [4, 2, 14], state: "minecraft:cave_air"},
        {pos: [4, 2, 15], state: "minecraft:cave_air"},
        {pos: [4, 2, 16], state: "minecraft:candle{candles:4,lit:false,waterlogged:false}"},
        {pos: [4, 2, 17], state: "minecraft:deepslate_brick_stairs{facing:south,half:top,shape:straight,waterlogged:false}"},
        {pos: [4, 2, 18], state: "minecraft:deepslate_bricks"},
        {pos: [4, 2, 19], state: "minecraft:deepslate_bricks"},
        {pos: [4, 2, 20], state: "minecraft:deepslate_bricks"},
        {pos: [5, 2, 6], state: "minecraft:deepslate_bricks"},
        {pos: [5, 2, 7], state: "minecraft:deepslate_bricks"},
        {pos: [5, 2, 8], state: "minecraft:deepslate_brick_stairs{facing:west,half:top,shape:straight,waterlogged:false}"},
        {pos: [5, 2, 9], state: "minecraft:deepslate_bricks"},
        {pos: [5, 2, 10], state: "minecraft:candle{candles:4,lit:false,waterlogged:false}"},
        {pos: [5, 2, 11], state: "minecraft:cave_air"},
        {pos: [5, 2, 12], state: "minecraft:cave_air"},
        {pos: [5, 2, 13], state: "minecraft:skeleton_skull{powered:false,rotation:8}", nbt: {id: "minecraft:skull"}},
        {pos: [5, 2, 14], state: "minecraft:cave_air"},
        {pos: [5, 2, 15], state: "minecraft:cave_air"},
        {pos: [5, 2, 16], state: "minecraft:skeleton_skull{powered:false,rotation:0}", nbt: {id: "minecraft:skull"}},
        {pos: [5, 2, 17], state: "minecraft:deepslate_bricks"},
        {pos: [5, 2, 18], state: "minecraft:deepslate_brick_stairs{facing:west,half:top,shape:straight,waterlogged:false}"},
        {pos: [5, 2, 19], state: "minecraft:deepslate_bricks"},
        {pos: [5, 2, 20], state: "minecraft:deepslate_bricks"},
        {pos: [6, 2, 5], state: "minecraft:deepslate_bricks"},
        {pos: [6, 2, 6], state: "minecraft:deepslate_bricks"},
        {pos: [6, 2, 7], state: "minecraft:candle{candles:4,lit:false,waterlogged:false}"},
        {pos: [6, 2, 8], state: "minecraft:candle{candles:4,lit:false,waterlogged:false}"},
        {pos: [6, 2, 9], state: "minecraft:candle{candles:4,lit:false,waterlogged:false}"},
        {pos: [6, 2, 10], state: "minecraft:cave_air"},
        {pos: [6, 2, 11], state: "minecraft:cave_air"},
        {pos: [6, 2, 12], state: "minecraft:cave_air"},
        {pos: [6, 2, 13], state: "minecraft:cave_air"},
        {pos: [6, 2, 14], state: "minecraft:cave_air"},
        {pos: [6, 2, 15], state: "minecraft:cave_air"},
        {pos: [6, 2, 16], state: "minecraft:cave_air"},
        {pos: [6, 2, 17], state: "minecraft:cave_air"},
        {pos: [6, 2, 18], state: "minecraft:candle{candles:4,lit:false,waterlogged:false}"},
        {pos: [6, 2, 19], state: "minecraft:decorated_pot{cracked:false,facing:south,waterlogged:false}", nbt: {id: "minecraft:decorated_pot"}},
        {pos: [6, 2, 20], state: "minecraft:deepslate_bricks"},
        {pos: [6, 2, 21], state: "minecraft:deepslate_bricks"},
        {pos: [7, 2, 5], state: "minecraft:deepslate_bricks"},
        {pos: [7, 2, 6], state: "minecraft:deepslate_brick_stairs{facing:north,half:top,shape:straight,waterlogged:false}"},
        {pos: [7, 2, 7], state: "minecraft:skeleton_skull{powered:false,rotation:8}", nbt: {id: "minecraft:skull"}},
        {pos: [7, 2, 8], state: "minecraft:cave_air"},
        {pos: [7, 2, 9], state: "minecraft:deepslate_bricks"},
        {pos: [7, 2, 10], state: "minecraft:cave_air"},
        {pos: [7, 2, 11], state: "minecraft:cave_air"},
        {pos: [7, 2, 12], state: "minecraft:cave_air"},
        {pos: [7, 2, 13], state: "minecraft:cave_air"},
        {pos: [7, 2, 14], state: "minecraft:cave_air"},
        {pos: [7, 2, 15], state: "minecraft:cave_air"},
        {pos: [7, 2, 16], state: "minecraft:cave_air"},
        {pos: [7, 2, 17], state: "minecraft:deepslate_bricks"},
        {pos: [7, 2, 18], state: "minecraft:cave_air"},
        {pos: [7, 2, 19], state: "minecraft:candle{candles:4,lit:false,waterlogged:false}"},
        {pos: [7, 2, 20], state: "minecraft:deepslate_brick_stairs{facing:south,half:top,shape:straight,waterlogged:false}"},
        {pos: [7, 2, 21], state: "minecraft:deepslate_bricks"},
        {pos: [8, 2, 5], state: "minecraft:deepslate_bricks"},
        {pos: [8, 2, 6], state: "minecraft:deepslate_bricks"},
        {pos: [8, 2, 7], state: "minecraft:candle{candles:4,lit:false,waterlogged:false}"},
        {pos: [8, 2, 8], state: "minecraft:decorated_pot{cracked:false,facing:west,waterlogged:false}", nbt: {id: "minecraft:decorated_pot"}},
        {pos: [8, 2, 9], state: "minecraft:deepslate_brick_stairs{facing:north,half:top,shape:straight,waterlogged:false}"},
        {pos: [8, 2, 10], state: "minecraft:cave_air"},
        {pos: [8, 2, 11], state: "minecraft:cave_air"},
        {pos: [8, 2, 12], state: "minecraft:cave_air"},
        {pos: [8, 2, 13], state: "minecraft:cave_air"},
        {pos: [8, 2, 14], state: "minecraft:cave_air"},
        {pos: [8, 2, 15], state: "minecraft:cave_air"},
        {pos: [8, 2, 16], state: "minecraft:cave_air"},
        {pos: [8, 2, 17], state: "minecraft:deepslate_brick_stairs{facing:south,half:top,shape:straight,waterlogged:false}"},
        {pos: [8, 2, 18], state: "minecraft:cave_air"},
        {pos: [8, 2, 19], state: "minecraft:skeleton_skull{powered:false,rotation:0}", nbt: {id: "minecraft:skull"}},
        {pos: [8, 2, 20], state: "minecraft:deepslate_bricks"},
        {pos: [8, 2, 21], state: "minecraft:deepslate_bricks"},
        {pos: [9, 2, 5], state: "minecraft:deepslate_bricks"},
        {pos: [9, 2, 6], state: "minecraft:deepslate_bricks"},
        {pos: [9, 2, 7], state: "minecraft:deepslate_brick_stairs{facing:north,half:top,shape:straight,waterlogged:false}"},
        {pos: [9, 2, 8], state: "minecraft:cave_air"},
        {pos: [9, 2, 9], state: "minecraft:deepslate_brick_stairs{facing:north,half:top,shape:straight,waterlogged:false}"},
        {pos: [9, 2, 10], state: "minecraft:cave_air"},
        {pos: [9, 2, 11], state: "minecraft:cave_air"},
        {pos: [9, 2, 12], state: "minecraft:cave_air"},
        {pos: [9, 2, 13], state: "minecraft:cave_air"},
        {pos: [9, 2, 14], state: "minecraft:cave_air"},
        {pos: [9, 2, 15], state: "minecraft:cave_air"},
        {pos: [9, 2, 16], state: "minecraft:cave_air"},
        {pos: [9, 2, 17], state: "minecraft:deepslate_brick_stairs{facing:south,half:top,shape:straight,waterlogged:false}"},
        {pos: [9, 2, 18], state: "minecraft:decorated_pot{cracked:false,facing:east,waterlogged:false}", nbt: {id: "minecraft:decorated_pot"}},
        {pos: [9, 2, 19], state: "minecraft:deepslate_brick_stairs{facing:south,half:top,shape:straight,waterlogged:false}"},
        {pos: [9, 2, 20], state: "minecraft:deepslate_bricks"},
        {pos: [9, 2, 21], state: "minecraft:deepslate_bricks"},
        {pos: [10, 2, 5], state: "minecraft:deepslate_bricks"},
        {pos: [10, 2, 6], state: "minecraft:deepslate_bricks"},
        {pos: [10, 2, 7], state: "minecraft:deepslate_brick_stairs{facing:north,half:top,shape:straight,waterlogged:false}"},
        {pos: [10, 2, 8], state: "minecraft:cave_air"},
        {pos: [10, 2, 9], state: "minecraft:deepslate_bricks"},
        {pos: [10, 2, 10], state: "minecraft:cave_air"},
        {pos: [10, 2, 11], state: "minecraft:cave_air"},
        {pos: [10, 2, 12], state: "minecraft:skeleton_skull{powered:false,rotation:8}", nbt: {id: "minecraft:skull"}},
        {pos: [10, 2, 13], state: "minecraft:cave_air"},
        {pos: [10, 2, 14], state: "minecraft:cave_air"},
        {pos: [10, 2, 15], state: "minecraft:cave_air"},
        {pos: [10, 2, 16], state: "minecraft:cave_air"},
        {pos: [10, 2, 17], state: "minecraft:deepslate_bricks"},
        {pos: [10, 2, 18], state: "minecraft:cave_air"},
        {pos: [10, 2, 19], state: "minecraft:deepslate_brick_stairs{facing:south,half:top,shape:straight,waterlogged:false}"},
        {pos: [10, 2, 20], state: "minecraft:deepslate_bricks"},
        {pos: [10, 2, 21], state: "minecraft:deepslate_bricks"},
        {pos: [11, 2, 6], state: "minecraft:deepslate_bricks"},
        {pos: [11, 2, 7], state: "minecraft:deepslate_brick_stairs{facing:north,half:top,shape:straight,waterlogged:false}"},
        {pos: [11, 2, 8], state: "minecraft:candle{candles:4,lit:false,waterlogged:false}"},
        {pos: [11, 2, 9], state: "minecraft:candle{candles:4,lit:false,waterlogged:false}"},
        {pos: [11, 2, 10], state: "minecraft:candle{candles:4,lit:false,waterlogged:false}"},
        {pos: [11, 2, 11], state: "minecraft:cave_air"},
        {pos: [11, 2, 12], state: "minecraft:cave_air"},
        {pos: [11, 2, 13], state: "minecraft:cave_air"},
        {pos: [11, 2, 14], state: "minecraft:cave_air"},
        {pos: [11, 2, 15], state: "minecraft:skeleton_skull{powered:false,rotation:0}", nbt: {id: "minecraft:skull"}},
        {pos: [11, 2, 16], state: "minecraft:candle{candles:4,lit:false,waterlogged:false}"},
        {pos: [11, 2, 17], state: "minecraft:candle{candles:4,lit:false,waterlogged:false}"},
        {pos: [11, 2, 18], state: "minecraft:candle{candles:4,lit:false,waterlogged:false}"},
        {pos: [11, 2, 19], state: "minecraft:deepslate_brick_stairs{facing:south,half:top,shape:straight,waterlogged:false}"},
        {pos: [11, 2, 20], state: "minecraft:deepslate_bricks"},
        {pos: [12, 2, 6], state: "minecraft:deepslate_bricks"},
        {pos: [12, 2, 7], state: "minecraft:deepslate_bricks"},
        {pos: [12, 2, 8], state: "minecraft:deepslate_bricks"},
        {pos: [12, 2, 9], state: "minecraft:deepslate_brick_stairs{facing:east,half:bottom,shape:straight,waterlogged:false}"},
        {pos: [12, 2, 10], state: "minecraft:deepslate_brick_stairs{facing:east,half:bottom,shape:straight,waterlogged:false}"},
        {pos: [12, 2, 11], state: "minecraft:candle{candles:4,lit:false,waterlogged:false}"},
        {pos: [12, 2, 12], state: "minecraft:cave_air"},
        {pos: [12, 2, 13], state: "minecraft:cave_air"},
        {pos: [12, 2, 14], state: "minecraft:cave_air"},
        {pos: [12, 2, 15], state: "minecraft:candle{candles:4,lit:false,waterlogged:false}"},
        {pos: [12, 2, 16], state: "minecraft:deepslate_brick_stairs{facing:east,half:bottom,shape:straight,waterlogged:false}"},
        {pos: [12, 2, 17], state: "minecraft:deepslate_brick_stairs{facing:east,half:bottom,shape:straight,waterlogged:false}"},
        {pos: [12, 2, 18], state: "minecraft:deepslate_bricks"},
        {pos: [12, 2, 19], state: "minecraft:deepslate_bricks"},
        {pos: [12, 2, 20], state: "minecraft:deepslate_bricks"},
        {pos: [13, 2, 6], state: "minecraft:deepslate_bricks"},
        {pos: [13, 2, 7], state: "minecraft:deepslate_bricks"},
        {pos: [13, 2, 8], state: "minecraft:deepslate_bricks"},
        {pos: [13, 2, 9], state: "trailiertales:coffin{facing:north,part:head,state:inactive}", nbt: {id: "trailiertales:coffin"}},
        {pos: [13, 2, 10], state: "trailiertales:coffin{facing:north,part:foot,state:inactive}", nbt: {id: "trailiertales:coffin", max_active_light_level: 7, uuid: "02710f60-0a7e-4b4c-8a55-949a3af25839"}},
        {pos: [13, 2, 11], state: "minecraft:candle{candles:4,lit:false,waterlogged:false}"},
        {pos: [13, 2, 12], state: "minecraft:cave_air"},
        {pos: [13, 2, 13], state: "minecraft:cave_air"},
        {pos: [13, 2, 14], state: "minecraft:cave_air"},
        {pos: [13, 2, 15], state: "minecraft:candle{candles:4,lit:false,waterlogged:false}"},
        {pos: [13, 2, 16], state: "trailiertales:coffin{facing:north,part:head,state:inactive}", nbt: {id: "trailiertales:coffin"}},
        {pos: [13, 2, 17], state: "trailiertales:coffin{facing:north,part:foot,state:inactive}", nbt: {id: "trailiertales:coffin", max_active_light_level: 7, uuid: "2ecabc31-3c15-4c3e-82df-1f255bf06150"}},
        {pos: [13, 2, 18], state: "minecraft:deepslate_bricks"},
        {pos: [13, 2, 19], state: "minecraft:deepslate_bricks"},
        {pos: [13, 2, 20], state: "minecraft:deepslate_bricks"},
        {pos: [14, 2, 6], state: "minecraft:deepslate_bricks"},
        {pos: [14, 2, 7], state: "minecraft:deepslate_bricks"},
        {pos: [14, 2, 8], state: "minecraft:deepslate_bricks"},
        {pos: [14, 2, 9], state: "minecraft:deepslate_brick_stairs{facing:west,half:bottom,shape:straight,waterlogged:false}"},
        {pos: [14, 2, 10], state: "minecraft:deepslate_brick_stairs{facing:west,half:bottom,shape:straight,waterlogged:false}"},
        {pos: [14, 2, 11], state: "minecraft:candle{candles:4,lit:false,waterlogged:false}"},
        {pos: [14, 2, 12], state: "minecraft:cave_air"},
        {pos: [14, 2, 13], state: "minecraft:cave_air"},
        {pos: [14, 2, 14], state: "minecraft:cave_air"},
        {pos: [14, 2, 15], state: "minecraft:candle{candles:4,lit:false,waterlogged:false}"},
        {pos: [14, 2, 16], state: "minecraft:deepslate_brick_stairs{facing:west,half:bottom,shape:straight,waterlogged:false}"},
        {pos: [14, 2, 17], state: "minecraft:deepslate_brick_stairs{facing:west,half:bottom,shape:straight,waterlogged:false}"},
        {pos: [14, 2, 18], state: "minecraft:deepslate_bricks"},
        {pos: [14, 2, 19], state: "minecraft:deepslate_bricks"},
        {pos: [14, 2, 20], state: "minecraft:deepslate_bricks"},
        {pos: [15, 2, 6], state: "minecraft:deepslate_bricks"},
        {pos: [15, 2, 7], state: "minecraft:deepslate_bricks"},
        {pos: [15, 2, 8], state: "minecraft:deepslate_bricks"},
        {pos: [15, 2, 9], state: "minecraft:deepslate_bricks"},
        {pos: [15, 2, 10], state: "minecraft:skeleton_skull{powered:false,rotation:8}", nbt: {id: "minecraft:skull"}},
        {pos: [15, 2, 11], state: "minecraft:cave_air"},
        {pos: [15, 2, 12], state: "minecraft:cave_air"},
        {pos: [15, 2, 13], state: "minecraft:cave_air"},
        {pos: [15, 2, 14], state: "minecraft:cave_air"},
        {pos: [15, 2, 15], state: "minecraft:cave_air"},
        {pos: [15, 2, 16], state: "minecraft:candle{candles:4,lit:false,waterlogged:false}"},
        {pos: [15, 2, 17], state: "minecraft:deepslate_bricks"},
        {pos: [15, 2, 18], state: "minecraft:deepslate_bricks"},
        {pos: [15, 2, 19], state: "minecraft:deepslate_bricks"},
        {pos: [15, 2, 20], state: "minecraft:deepslate_bricks"},
        {pos: [16, 2, 6], state: "minecraft:deepslate_bricks"},
        {pos: [16, 2, 7], state: "minecraft:deepslate_bricks"},
        {pos: [16, 2, 8], state: "minecraft:deepslate_bricks"},
        {pos: [16, 2, 9], state: "minecraft:deepslate_brick_stairs{facing:north,half:top,shape:straight,waterlogged:false}"},
        {pos: [16, 2, 10], state: "minecraft:candle{candles:4,lit:false,waterlogged:false}"},
        {pos: [16, 2, 11], state: "minecraft:cave_air"},
        {pos: [16, 2, 12], state: "minecraft:cave_air"},
        {pos: [16, 2, 13], state: "minecraft:cave_air"},
        {pos: [16, 2, 14], state: "minecraft:cave_air"},
        {pos: [16, 2, 15], state: "minecraft:cave_air"},
        {pos: [16, 2, 16], state: "minecraft:candle{candles:4,lit:false,waterlogged:false}"},
        {pos: [16, 2, 17], state: "minecraft:deepslate_brick_stairs{facing:south,half:top,shape:straight,waterlogged:false}"},
        {pos: [16, 2, 18], state: "minecraft:deepslate_bricks"},
        {pos: [16, 2, 19], state: "minecraft:deepslate_bricks"},
        {pos: [16, 2, 20], state: "minecraft:deepslate_bricks"},
        {pos: [17, 2, 6], state: "minecraft:deepslate_bricks"},
        {pos: [17, 2, 7], state: "minecraft:deepslate_bricks"},
        {pos: [17, 2, 8], state: "minecraft:deepslate_bricks"},
        {pos: [17, 2, 9], state: "minecraft:deepslate_bricks"},
        {pos: [17, 2, 10], state: "minecraft:decorated_pot{cracked:false,facing:north,waterlogged:false}", nbt: {id: "minecraft:decorated_pot"}},
        {pos: [17, 2, 11], state: "minecraft:candle{candles:4,lit:false,waterlogged:false}"},
        {pos: [17, 2, 12], state: "minecraft:cave_air"},
        {pos: [17, 2, 13], state: "minecraft:cave_air"},
        {pos: [17, 2, 14], state: "minecraft:cave_air"},
        {pos: [17, 2, 15], state: "minecraft:skeleton_skull{powered:false,rotation:0}", nbt: {id: "minecraft:skull"}},
        {pos: [17, 2, 16], state: "minecraft:gray_glazed_terracotta{facing:west}"},
        {pos: [17, 2, 17], state: "minecraft:deepslate_bricks"},
        {pos: [17, 2, 18], state: "minecraft:deepslate_bricks"},
        {pos: [17, 2, 19], state: "minecraft:deepslate_bricks"},
        {pos: [17, 2, 20], state: "minecraft:deepslate_bricks"},
        {pos: [18, 2, 6], state: "minecraft:deepslate_bricks"},
        {pos: [18, 2, 7], state: "minecraft:deepslate_bricks"},
        {pos: [18, 2, 8], state: "minecraft:deepslate_bricks"},
        {pos: [18, 2, 9], state: "minecraft:deepslate_bricks"},
        {pos: [18, 2, 10], state: "minecraft:deepslate_bricks"},
        {pos: [18, 2, 11], state: "minecraft:deepslate_brick_stairs{facing:north,half:bottom,shape:straight,waterlogged:false}"},
        {pos: [18, 2, 12], state: "minecraft:cave_air"},
        {pos: [18, 2, 13], state: "minecraft:cave_air"},
        {pos: [18, 2, 14], state: "minecraft:cave_air"},
        {pos: [18, 2, 15], state: "minecraft:deepslate_brick_stairs{facing:south,half:bottom,shape:straight,waterlogged:false}"},
        {pos: [18, 2, 16], state: "minecraft:deepslate_bricks"},
        {pos: [18, 2, 17], state: "minecraft:deepslate_bricks"},
        {pos: [18, 2, 18], state: "minecraft:deepslate_bricks"},
        {pos: [18, 2, 19], state: "minecraft:deepslate_bricks"},
        {pos: [18, 2, 20], state: "minecraft:deepslate_bricks"},
        {pos: [19, 2, 6], state: "minecraft:deepslate_bricks"},
        {pos: [19, 2, 7], state: "minecraft:deepslate_bricks"},
        {pos: [19, 2, 8], state: "minecraft:deepslate_bricks"},
        {pos: [19, 2, 9], state: "minecraft:deepslate_bricks"},
        {pos: [19, 2, 10], state: "minecraft:deepslate_bricks"},
        {pos: [19, 2, 11], state: "minecraft:deepslate_brick_stairs{facing:north,half:bottom,shape:straight,waterlogged:false}"},
        {pos: [19, 2, 12], state: "minecraft:cave_air"},
        {pos: [19, 2, 13], state: "minecraft:cave_air"},
        {pos: [19, 2, 14], state: "minecraft:cave_air"},
        {pos: [19, 2, 15], state: "minecraft:deepslate_brick_stairs{facing:south,half:bottom,shape:straight,waterlogged:false}"},
        {pos: [19, 2, 16], state: "minecraft:deepslate_bricks"},
        {pos: [19, 2, 17], state: "minecraft:deepslate_bricks"},
        {pos: [19, 2, 18], state: "minecraft:deepslate_bricks"},
        {pos: [19, 2, 19], state: "minecraft:deepslate_bricks"},
        {pos: [19, 2, 20], state: "minecraft:deepslate_bricks"},
        {pos: [20, 2, 6], state: "minecraft:deepslate_bricks"},
        {pos: [20, 2, 7], state: "minecraft:deepslate_bricks"},
        {pos: [20, 2, 8], state: "minecraft:deepslate_bricks"},
        {pos: [20, 2, 9], state: "minecraft:deepslate_bricks"},
        {pos: [20, 2, 10], state: "minecraft:deepslate_bricks"},
        {pos: [20, 2, 11], state: "minecraft:deepslate_brick_stairs{facing:north,half:bottom,shape:straight,waterlogged:false}"},
        {pos: [20, 2, 12], state: "minecraft:cave_air"},
        {pos: [20, 2, 13], state: "minecraft:cave_air"},
        {pos: [20, 2, 14], state: "minecraft:cave_air"},
        {pos: [20, 2, 15], state: "minecraft:deepslate_brick_stairs{facing:south,half:bottom,shape:straight,waterlogged:false}"},
        {pos: [20, 2, 16], state: "minecraft:deepslate_bricks"},
        {pos: [20, 2, 17], state: "minecraft:deepslate_bricks"},
        {pos: [20, 2, 18], state: "minecraft:deepslate_bricks"},
        {pos: [20, 2, 19], state: "minecraft:deepslate_bricks"},
        {pos: [20, 2, 20], state: "minecraft:deepslate_bricks"},
        {pos: [21, 2, 6], state: "minecraft:deepslate_bricks"},
        {pos: [21, 2, 7], state: "minecraft:deepslate_bricks"},
        {pos: [21, 2, 8], state: "minecraft:deepslate_bricks"},
        {pos: [21, 2, 9], state: "minecraft:deepslate_bricks"},
        {pos: [21, 2, 10], state: "minecraft:deepslate_bricks"},
        {pos: [21, 2, 11], state: "minecraft:deepslate_bricks"},
        {pos: [21, 2, 12], state: "minecraft:candle{candles:4,lit:false,waterlogged:false}"},
        {pos: [21, 2, 13], state: "minecraft:cave_air"},
        {pos: [21, 2, 14], state: "minecraft:candle{candles:4,lit:false,waterlogged:false}"},
        {pos: [21, 2, 15], state: "minecraft:deepslate_bricks"},
        {pos: [21, 2, 16], state: "minecraft:deepslate_bricks"},
        {pos: [21, 2, 17], state: "minecraft:deepslate_bricks"},
        {pos: [21, 2, 18], state: "minecraft:deepslate_bricks"},
        {pos: [21, 2, 19], state: "minecraft:deepslate_bricks"},
        {pos: [21, 2, 20], state: "minecraft:deepslate_bricks"},
        {pos: [22, 2, 6], state: "minecraft:deepslate_bricks"},
        {pos: [22, 2, 7], state: "minecraft:deepslate_bricks"},
        {pos: [22, 2, 8], state: "minecraft:deepslate_bricks"},
        {pos: [22, 2, 9], state: "minecraft:deepslate_bricks"},
        {pos: [22, 2, 10], state: "minecraft:deepslate_bricks"},
        {pos: [22, 2, 11], state: "minecraft:deepslate_bricks"},
        {pos: [22, 2, 12], state: "minecraft:candle{candles:4,lit:false,waterlogged:false}"},
        {pos: [22, 2, 13], state: "minecraft:cave_air"},
        {pos: [22, 2, 14], state: "minecraft:candle{candles:4,lit:false,waterlogged:false}"},
        {pos: [22, 2, 15], state: "minecraft:deepslate_bricks"},
        {pos: [22, 2, 16], state: "minecraft:deepslate_bricks"},
        {pos: [22, 2, 17], state: "minecraft:deepslate_bricks"},
        {pos: [22, 2, 18], state: "minecraft:deepslate_bricks"},
        {pos: [22, 2, 19], state: "minecraft:deepslate_bricks"},
        {pos: [22, 2, 20], state: "minecraft:deepslate_bricks"},
        {pos: [23, 2, 6], state: "minecraft:deepslate_bricks"},
        {pos: [23, 2, 7], state: "minecraft:cave_air"},
        {pos: [23, 2, 8], state: "minecraft:candle{candles:4,lit:false,waterlogged:false}"},
        {pos: [23, 2, 9], state: "minecraft:candle{candles:4,lit:false,waterlogged:false}"},
        {pos: [23, 2, 10], state: "minecraft:candle{candles:4,lit:false,waterlogged:false}"},
        {pos: [23, 2, 11], state: "minecraft:candle{candles:4,lit:false,waterlogged:false}"},
        {pos: [23, 2, 12], state: "minecraft:cave_air"},
        {pos: [23, 2, 13], state: "minecraft:cave_air"},
        {pos: [23, 2, 14], state: "minecraft:cave_air"},
        {pos: [23, 2, 15], state: "minecraft:candle{candles:4,lit:false,waterlogged:false}"},
        {pos: [23, 2, 16], state: "minecraft:candle{candles:4,lit:false,waterlogged:false}"},
        {pos: [23, 2, 17], state: "minecraft:candle{candles:4,lit:false,waterlogged:false}"},
        {pos: [23, 2, 18], state: "minecraft:candle{candles:4,lit:false,waterlogged:false}"},
        {pos: [23, 2, 19], state: "minecraft:cave_air"},
        {pos: [23, 2, 20], state: "minecraft:deepslate_bricks"},
        {pos: [24, 2, 6], state: "minecraft:deepslate_bricks"},
        {pos: [24, 2, 7], state: "minecraft:cave_air"},
        {pos: [24, 2, 8], state: "minecraft:skeleton_skull{powered:false,rotation:8}", nbt: {id: "minecraft:skull"}},
        {pos: [24, 2, 9], state: "minecraft:deepslate_brick_stairs{facing:east,half:bottom,shape:straight,waterlogged:false}"},
        {pos: [24, 2, 10], state: "minecraft:deepslate_brick_stairs{facing:east,half:bottom,shape:straight,waterlogged:false}"},
        {pos: [24, 2, 11], state: "minecraft:skeleton_skull{powered:false,rotation:8}", nbt: {id: "minecraft:skull"}},
        {pos: [24, 2, 12], state: "minecraft:cave_air"},
        {pos: [24, 2, 13], state: "minecraft:cave_air"},
        {pos: [24, 2, 14], state: "minecraft:cave_air"},
        {pos: [24, 2, 15], state: "minecraft:candle{candles:4,lit:false,waterlogged:false}"},
        {pos: [24, 2, 16], state: "minecraft:deepslate_brick_stairs{facing:east,half:bottom,shape:straight,waterlogged:false}"},
        {pos: [24, 2, 17], state: "minecraft:deepslate_brick_stairs{facing:east,half:bottom,shape:straight,waterlogged:false}"},
        {pos: [24, 2, 18], state: "minecraft:candle{candles:4,lit:false,waterlogged:false}"},
        {pos: [24, 2, 19], state: "minecraft:skeleton_skull{powered:false,rotation:0}", nbt: {id: "minecraft:skull"}},
        {pos: [24, 2, 20], state: "minecraft:deepslate_bricks"},
        {pos: [25, 2, 6], state: "minecraft:deepslate_bricks"},
        {pos: [25, 2, 7], state: "minecraft:cave_air"},
        {pos: [25, 2, 8], state: "minecraft:skeleton_skull{powered:false,rotation:8}", nbt: {id: "minecraft:skull"}},
        {pos: [25, 2, 9], state: "trailiertales:coffin{facing:north,part:head,state:inactive}", nbt: {id: "trailiertales:coffin"}},
        {pos: [25, 2, 10], state: "trailiertales:coffin{facing:north,part:foot,state:inactive}", nbt: {id: "trailiertales:coffin", max_active_light_level: 7, uuid: "f373819e-830a-4228-afc8-4ae542d818fb"}},
        {pos: [25, 2, 11], state: "minecraft:decorated_pot{cracked:false,facing:east,waterlogged:false}", nbt: {id: "minecraft:decorated_pot"}},
        {pos: [25, 2, 12], state: "minecraft:cave_air"},
        {pos: [25, 2, 13], state: "minecraft:cave_air"},
        {pos: [25, 2, 14], state: "minecraft:cave_air"},
        {pos: [25, 2, 15], state: "minecraft:candle{candles:4,lit:false,waterlogged:false}"},
        {pos: [25, 2, 16], state: "trailiertales:coffin{facing:north,part:head,state:inactive}", nbt: {id: "trailiertales:coffin"}},
        {pos: [25, 2, 17], state: "trailiertales:coffin{facing:north,part:foot,state:inactive}", nbt: {id: "trailiertales:coffin", max_active_light_level: 7, uuid: "93970237-e08b-4b6d-a07e-3415a058f69d"}},
        {pos: [25, 2, 18], state: "minecraft:skeleton_skull{powered:false,rotation:0}", nbt: {id: "minecraft:skull"}},
        {pos: [25, 2, 19], state: "minecraft:cave_air"},
        {pos: [25, 2, 20], state: "minecraft:deepslate_bricks"},
        {pos: [26, 2, 6], state: "minecraft:deepslate_bricks"},
        {pos: [26, 2, 7], state: "minecraft:deepslate_bricks"},
        {pos: [26, 2, 8], state: "minecraft:deepslate_bricks"},
        {pos: [26, 2, 9], state: "minecraft:deepslate_bricks"},
        {pos: [26, 2, 10], state: "minecraft:deepslate_bricks"},
        {pos: [26, 2, 11], state: "minecraft:deepslate_bricks"},
        {pos: [26, 2, 12], state: "minecraft:candle{candles:4,lit:false,waterlogged:false}"},
        {pos: [26, 2, 13], state: "minecraft:cave_air"},
        {pos: [26, 2, 14], state: "minecraft:candle{candles:4,lit:false,waterlogged:false}"},
        {pos: [26, 2, 15], state: "minecraft:deepslate_bricks"},
        {pos: [26, 2, 16], state: "minecraft:deepslate_bricks"},
        {pos: [26, 2, 17], state: "minecraft:deepslate_bricks"},
        {pos: [26, 2, 18], state: "minecraft:deepslate_bricks"},
        {pos: [26, 2, 19], state: "minecraft:deepslate_bricks"},
        {pos: [26, 2, 20], state: "minecraft:deepslate_bricks"},
        {pos: [27, 2, 11], state: "minecraft:deepslate_bricks"},
        {pos: [27, 2, 12], state: "minecraft:candle{candles:4,lit:false,waterlogged:false}"},
        {pos: [27, 2, 13], state: "minecraft:cave_air"},
        {pos: [27, 2, 14], state: "minecraft:candle{candles:4,lit:false,waterlogged:false}"},
        {pos: [27, 2, 15], state: "minecraft:deepslate_bricks"},
        {pos: [27, 2, 16], state: "minecraft:deepslate_brick_stairs{facing:west,half:top,shape:straight,waterlogged:false}"},
        {pos: [27, 2, 17], state: "minecraft:deepslate_brick_stairs{facing:west,half:top,shape:straight,waterlogged:false}"},
        {pos: [27, 2, 18], state: "minecraft:deepslate_bricks"},
        {pos: [28, 2, 11], state: "minecraft:deepslate_bricks"},
        {pos: [28, 2, 12], state: "minecraft:candle{candles:4,lit:false,waterlogged:false}"},
        {pos: [28, 2, 13], state: "minecraft:cave_air"},
        {pos: [28, 2, 14], state: "minecraft:candle{candles:4,lit:false,waterlogged:false}"},
        {pos: [28, 2, 15], state: "minecraft:deepslate_bricks"},
        {pos: [28, 2, 16], state: "minecraft:skeleton_skull{powered:false,rotation:0}", nbt: {id: "minecraft:skull"}},
        {pos: [28, 2, 17], state: "minecraft:chest{facing:north,type:single,waterlogged:false}", nbt: {Items: [], id: "minecraft:chest"}},
        {pos: [28, 2, 18], state: "minecraft:deepslate_bricks"},
        {pos: [29, 2, 11], state: "minecraft:deepslate_bricks"},
        {pos: [29, 2, 12], state: "minecraft:candle{candles:4,lit:false,waterlogged:false}"},
        {pos: [29, 2, 13], state: "minecraft:jigsaw{orientation:east_up}", nbt: {final_state: "minecraft:cave_air", id: "minecraft:jigsaw", joint: "rollable", name: "trailiertales:corridor", placement_priority: 0, pool: "trailiertales:catacombs/corridor_connector", selection_priority: 0, target: "trailiertales:corridor"}},
        {pos: [29, 2, 14], state: "minecraft:candle{candles:4,lit:false,waterlogged:false}"},
        {pos: [29, 2, 15], state: "minecraft:deepslate_bricks"},
        {pos: [29, 2, 16], state: "minecraft:deepslate_bricks"},
        {pos: [29, 2, 17], state: "minecraft:deepslate_bricks"},
        {pos: [29, 2, 18], state: "minecraft:deepslate_bricks"},
        {pos: [0, 3, 10], state: "minecraft:deepslate_bricks"},
        {pos: [0, 3, 11], state: "minecraft:deepslate_bricks"},
        {pos: [0, 3, 12], state: "minecraft:cave_air"},
        {pos: [0, 3, 13], state: "minecraft:cave_air"},
        {pos: [0, 3, 14], state: "minecraft:cave_air"},
        {pos: [0, 3, 15], state: "minecraft:deepslate_bricks"},
        {pos: [0, 3, 16], state: "minecraft:deepslate_bricks"},
        {pos: [1, 3, 10], state: "minecraft:deepslate_bricks"},
        {pos: [1, 3, 11], state: "minecraft:gray_glazed_terracotta{facing:south}"},
        {pos: [1, 3, 12], state: "minecraft:cave_air"},
        {pos: [1, 3, 13], state: "minecraft:cave_air"},
        {pos: [1, 3, 14], state: "minecraft:cave_air"},
        {pos: [1, 3, 15], state: "minecraft:skeleton_skull{powered:false,rotation:0}", nbt: {id: "minecraft:skull"}},
        {pos: [1, 3, 16], state: "minecraft:deepslate_bricks"},
        {pos: [2, 3, 10], state: "minecraft:deepslate_bricks"},
        {pos: [2, 3, 11], state: "minecraft:deepslate_bricks"},
        {pos: [2, 3, 12], state: "minecraft:cave_air"},
        {pos: [2, 3, 13], state: "minecraft:cave_air"},
        {pos: [2, 3, 14], state: "minecraft:cave_air"},
        {pos: [2, 3, 15], state: "minecraft:deepslate_bricks"},
        {pos: [2, 3, 16], state: "minecraft:deepslate_bricks"},
        {pos: [3, 3, 6], state: "minecraft:deepslate_bricks"},
        {pos: [3, 3, 7], state: "minecraft:deepslate_bricks"},
        {pos: [3, 3, 8], state: "minecraft:deepslate_bricks"},
        {pos: [3, 3, 9], state: "minecraft:deepslate_bricks"},
        {pos: [3, 3, 10], state: "minecraft:cave_air"},
        {pos: [3, 3, 11], state: "minecraft:cave_air"},
        {pos: [3, 3, 12], state: "minecraft:cave_air"},
        {pos: [3, 3, 13], state: "minecraft:cave_air"},
        {pos: [3, 3, 14], state: "minecraft:cave_air"},
        {pos: [3, 3, 15], state: "minecraft:cave_air"},
        {pos: [3, 3, 16], state: "minecraft:cave_air"},
        {pos: [3, 3, 17], state: "minecraft:deepslate_bricks"},
        {pos: [3, 3, 18], state: "minecraft:deepslate_bricks"},
        {pos: [3, 3, 19], state: "minecraft:deepslate_bricks"},
        {pos: [3, 3, 20], state: "minecraft:deepslate_bricks"},
        {pos: [4, 3, 6], state: "minecraft:deepslate_bricks"},
        {pos: [4, 3, 7], state: "minecraft:deepslate_bricks"},
        {pos: [4, 3, 8], state: "minecraft:deepslate_bricks"},
        {pos: [4, 3, 9], state: "minecraft:skeleton_skull{powered:false,rotation:8}", nbt: {id: "minecraft:skull"}},
        {pos: [4, 3, 10], state: "minecraft:cave_air"},
        {pos: [4, 3, 11], state: "minecraft:cave_air"},
        {pos: [4, 3, 12], state: "minecraft:cave_air"},
        {pos: [4, 3, 13], state: "minecraft:cave_air"},
        {pos: [4, 3, 14], state: "minecraft:cave_air"},
        {pos: [4, 3, 15], state: "minecraft:cave_air"},
        {pos: [4, 3, 16], state: "minecraft:cave_air"},
        {pos: [4, 3, 17], state: "minecraft:skeleton_skull{powered:false,rotation:0}", nbt: {id: "minecraft:skull"}},
        {pos: [4, 3, 18], state: "minecraft:deepslate_bricks"},
        {pos: [4, 3, 19], state: "minecraft:deepslate_bricks"},
        {pos: [4, 3, 20], state: "minecraft:deepslate_bricks"},
        {pos: [5, 3, 6], state: "minecraft:deepslate_bricks"},
        {pos: [5, 3, 7], state: "minecraft:deepslate_bricks"},
        {pos: [5, 3, 8], state: "minecraft:skeleton_skull{powered:false,rotation:4}", nbt: {id: "minecraft:skull"}},
        {pos: [5, 3, 9], state: "minecraft:deepslate_bricks"},
        {pos: [5, 3, 10], state: "minecraft:cave_air"},
        {pos: [5, 3, 11], state: "minecraft:cave_air"},
        {pos: [5, 3, 12], state: "minecraft:cave_air"},
        {pos: [5, 3, 13], state: "minecraft:cave_air"},
        {pos: [5, 3, 14], state: "minecraft:cave_air"},
        {pos: [5, 3, 15], state: "minecraft:cave_air"},
        {pos: [5, 3, 16], state: "minecraft:cave_air"},
        {pos: [5, 3, 17], state: "minecraft:deepslate_bricks"},
        {pos: [5, 3, 18], state: "minecraft:gray_glazed_terracotta{facing:east}"},
        {pos: [5, 3, 19], state: "minecraft:deepslate_bricks"},
        {pos: [5, 3, 20], state: "minecraft:deepslate_bricks"},
        {pos: [6, 3, 5], state: "minecraft:deepslate_bricks"},
        {pos: [6, 3, 6], state: "minecraft:deepslate_bricks"},
        {pos: [6, 3, 7], state: "minecraft:cave_air"},
        {pos: [6, 3, 8], state: "minecraft:cave_air"},
        {pos: [6, 3, 9], state: "minecraft:cave_air"},
        {pos: [6, 3, 10], state: "minecraft:cave_air"},
        {pos: [6, 3, 11], state: "minecraft:cave_air"},
        {pos: [6, 3, 12], state: "minecraft:cave_air"},
        {pos: [6, 3, 13], state: "minecraft:cave_air"},
        {pos: [6, 3, 14], state: "minecraft:cave_air"},
        {pos: [6, 3, 15], state: "minecraft:cave_air"},
        {pos: [6, 3, 16], state: "minecraft:cave_air"},
        {pos: [6, 3, 17], state: "minecraft:cave_air"},
        {pos: [6, 3, 18], state: "minecraft:cave_air"},
        {pos: [6, 3, 19], state: "minecraft:cave_air"},
        {pos: [6, 3, 20], state: "minecraft:deepslate_bricks"},
        {pos: [6, 3, 21], state: "minecraft:deepslate_bricks"},
        {pos: [7, 3, 5], state: "minecraft:deepslate_bricks"},
        {pos: [7, 3, 6], state: "minecraft:skeleton_skull{powered:false,rotation:8}", nbt: {id: "minecraft:skull"}},
        {pos: [7, 3, 7], state: "minecraft:cave_air"},
        {pos: [7, 3, 8], state: "minecraft:cave_air"},
        {pos: [7, 3, 9], state: "minecraft:deepslate_bricks"},
        {pos: [7, 3, 10], state: "minecraft:cave_air"},
        {pos: [7, 3, 11], state: "minecraft:cave_air"},
        {pos: [7, 3, 12], state: "minecraft:cave_air"},
        {pos: [7, 3, 13], state: "minecraft:cave_air"},
        {pos: [7, 3, 14], state: "minecraft:cave_air"},
        {pos: [7, 3, 15], state: "minecraft:cave_air"},
        {pos: [7, 3, 16], state: "minecraft:cave_air"},
        {pos: [7, 3, 17], state: "minecraft:candle{candles:4,lit:false,waterlogged:false}"},
        {pos: [7, 3, 18], state: "minecraft:cave_air"},
        {pos: [7, 3, 19], state: "minecraft:cave_air"},
        {pos: [7, 3, 20], state: "minecraft:gray_glazed_terracotta{facing:north}"},
        {pos: [7, 3, 21], state: "minecraft:deepslate_bricks"},
        {pos: [8, 3, 5], state: "minecraft:deepslate_bricks"},
        {pos: [8, 3, 6], state: "minecraft:deepslate_bricks"},
        {pos: [8, 3, 7], state: "minecraft:cave_air"},
        {pos: [8, 3, 8], state: "minecraft:cave_air"},
        {pos: [8, 3, 9], state: "minecraft:gray_glazed_terracotta{facing:east}"},
        {pos: [8, 3, 10], state: "minecraft:cave_air"},
        {pos: [8, 3, 11], state: "minecraft:cave_air"},
        {pos: [8, 3, 12], state: "minecraft:cave_air"},
        {pos: [8, 3, 13], state: "minecraft:cave_air"},
        {pos: [8, 3, 14], state: "minecraft:cave_air"},
        {pos: [8, 3, 15], state: "minecraft:cave_air"},
        {pos: [8, 3, 16], state: "minecraft:cave_air"},
        {pos: [8, 3, 17], state: "minecraft:gray_glazed_terracotta{facing:west}"},
        {pos: [8, 3, 18], state: "minecraft:cave_air"},
        {pos: [8, 3, 19], state: "minecraft:cave_air"},
        {pos: [8, 3, 20], state: "minecraft:deepslate_bricks"},
        {pos: [8, 3, 21], state: "minecraft:deepslate_bricks"},
        {pos: [9, 3, 5], state: "minecraft:deepslate_bricks"},
        {pos: [9, 3, 6], state: "minecraft:deepslate_bricks"},
        {pos: [9, 3, 7], state: "minecraft:skeleton_skull{powered:false,rotation:8}", nbt: {id: "minecraft:skull"}},
        {pos: [9, 3, 8], state: "minecraft:cave_air"},
        {pos: [9, 3, 9], state: "minecraft:cave_air"},
        {pos: [9, 3, 10], state: "minecraft:cave_air"},
        {pos: [9, 3, 11], state: "minecraft:cave_air"},
        {pos: [9, 3, 12], state: "minecraft:cave_air"},
        {pos: [9, 3, 13], state: "minecraft:cave_air"},
        {pos: [9, 3, 14], state: "minecraft:cave_air"},
        {pos: [9, 3, 15], state: "minecraft:cave_air"},
        {pos: [9, 3, 16], state: "minecraft:cave_air"},
        {pos: [9, 3, 17], state: "minecraft:gray_glazed_terracotta{facing:south}"},
        {pos: [9, 3, 18], state: "minecraft:cave_air"},
        {pos: [9, 3, 19], state: "minecraft:candle{candles:4,lit:false,waterlogged:false}"},
        {pos: [9, 3, 20], state: "minecraft:deepslate_bricks"},
        {pos: [9, 3, 21], state: "minecraft:deepslate_bricks"},
        {pos: [10, 3, 5], state: "minecraft:deepslate_bricks"},
        {pos: [10, 3, 6], state: "minecraft:deepslate_bricks"},
        {pos: [10, 3, 7], state: "minecraft:skeleton_skull{powered:false,rotation:8}", nbt: {id: "minecraft:skull"}},
        {pos: [10, 3, 8], state: "minecraft:cave_air"},
        {pos: [10, 3, 9], state: "minecraft:candle{candles:4,lit:false,waterlogged:false}"},
        {pos: [10, 3, 10], state: "minecraft:cave_air"},
        {pos: [10, 3, 11], state: "minecraft:cave_air"},
        {pos: [10, 3, 12], state: "minecraft:cave_air"},
        {pos: [10, 3, 13], state: "minecraft:cave_air"},
        {pos: [10, 3, 14], state: "minecraft:cave_air"},
        {pos: [10, 3, 15], state: "minecraft:cave_air"},
        {pos: [10, 3, 16], state: "minecraft:cave_air"},
        {pos: [10, 3, 17], state: "minecraft:deepslate_bricks"},
        {pos: [10, 3, 18], state: "minecraft:cave_air"},
        {pos: [10, 3, 19], state: "minecraft:skeleton_skull{powered:false,rotation:0}", nbt: {id: "minecraft:skull"}},
        {pos: [10, 3, 20], state: "minecraft:deepslate_bricks"},
        {pos: [10, 3, 21], state: "minecraft:deepslate_bricks"},
        {pos: [11, 3, 6], state: "minecraft:deepslate_bricks"},
        {pos: [11, 3, 7], state: "minecraft:candle{candles:4,lit:false,waterlogged:false}"},
        {pos: [11, 3, 8], state: "minecraft:cave_air"},
        {pos: [11, 3, 9], state: "minecraft:cave_air"},
        {pos: [11, 3, 10], state: "minecraft:cave_air"},
        {pos: [11, 3, 11], state: "minecraft:cave_air"},
        {pos: [11, 3, 12], state: "minecraft:cave_air"},
        {pos: [11, 3, 13], state: "minecraft:cave_air"},
        {pos: [11, 3, 14], state: "minecraft:cave_air"},
        {pos: [11, 3, 15], state: "minecraft:cave_air"},
        {pos: [11, 3, 16], state: "minecraft:cave_air"},
        {pos: [11, 3, 17], state: "minecraft:cave_air"},
        {pos: [11, 3, 18], state: "minecraft:cave_air"},
        {pos: [11, 3, 19], state: "minecraft:skeleton_skull{powered:false,rotation:0}", nbt: {id: "minecraft:skull"}},
        {pos: [11, 3, 20], state: "minecraft:deepslate_bricks"},
        {pos: [12, 3, 6], state: "minecraft:deepslate_bricks"},
        {pos: [12, 3, 7], state: "minecraft:deepslate_bricks"},
        {pos: [12, 3, 8], state: "minecraft:deepslate_bricks"},
        {pos: [12, 3, 9], state: "minecraft:cave_air"},
        {pos: [12, 3, 10], state: "minecraft:cave_air"},
        {pos: [12, 3, 11], state: "minecraft:cave_air"},
        {pos: [12, 3, 12], state: "minecraft:cave_air"},
        {pos: [12, 3, 13], state: "minecraft:cave_air"},
        {pos: [12, 3, 14], state: "minecraft:cave_air"},
        {pos: [12, 3, 15], state: "minecraft:cave_air"},
        {pos: [12, 3, 16], state: "minecraft:cave_air"},
        {pos: [12, 3, 17], state: "minecraft:cave_air"},
        {pos: [12, 3, 18], state: "minecraft:deepslate_bricks"},
        {pos: [12, 3, 19], state: "minecraft:deepslate_bricks"},
        {pos: [12, 3, 20], state: "minecraft:deepslate_bricks"},
        {pos: [13, 3, 6], state: "minecraft:deepslate_bricks"},
        {pos: [13, 3, 7], state: "minecraft:deepslate_bricks"},
        {pos: [13, 3, 8], state: "minecraft:deepslate_bricks"},
        {pos: [13, 3, 9], state: "minecraft:cave_air"},
        {pos: [13, 3, 10], state: "minecraft:cave_air"},
        {pos: [13, 3, 11], state: "minecraft:cave_air"},
        {pos: [13, 3, 12], state: "minecraft:cave_air"},
        {pos: [13, 3, 13], state: "minecraft:cave_air"},
        {pos: [13, 3, 14], state: "minecraft:cave_air"},
        {pos: [13, 3, 15], state: "minecraft:cave_air"},
        {pos: [13, 3, 16], state: "minecraft:cave_air"},
        {pos: [13, 3, 17], state: "minecraft:cave_air"},
        {pos: [13, 3, 18], state: "minecraft:deepslate_bricks"},
        {pos: [13, 3, 19], state: "minecraft:deepslate_bricks"},
        {pos: [13, 3, 20], state: "minecraft:deepslate_bricks"},
        {pos: [14, 3, 6], state: "minecraft:deepslate_bricks"},
        {pos: [14, 3, 7], state: "minecraft:deepslate_bricks"},
        {pos: [14, 3, 8], state: "minecraft:deepslate_bricks"},
        {pos: [14, 3, 9], state: "minecraft:cave_air"},
        {pos: [14, 3, 10], state: "minecraft:cave_air"},
        {pos: [14, 3, 11], state: "minecraft:cave_air"},
        {pos: [14, 3, 12], state: "minecraft:cave_air"},
        {pos: [14, 3, 13], state: "minecraft:cave_air"},
        {pos: [14, 3, 14], state: "minecraft:cave_air"},
        {pos: [14, 3, 15], state: "minecraft:cave_air"},
        {pos: [14, 3, 16], state: "minecraft:cave_air"},
        {pos: [14, 3, 17], state: "minecraft:cave_air"},
        {pos: [14, 3, 18], state: "minecraft:deepslate_bricks"},
        {pos: [14, 3, 19], state: "minecraft:deepslate_bricks"},
        {pos: [14, 3, 20], state: "minecraft:deepslate_bricks"},
        {pos: [15, 3, 6], state: "minecraft:deepslate_bricks"},
        {pos: [15, 3, 7], state: "minecraft:deepslate_bricks"},
        {pos: [15, 3, 8], state: "minecraft:deepslate_bricks"},
        {pos: [15, 3, 9], state: "minecraft:deepslate_bricks"},
        {pos: [15, 3, 10], state: "minecraft:cave_air"},
        {pos: [15, 3, 11], state: "minecraft:cave_air"},
        {pos: [15, 3, 12], state: "minecraft:cave_air"},
        {pos: [15, 3, 13], state: "minecraft:cave_air"},
        {pos: [15, 3, 14], state: "minecraft:cave_air"},
        {pos: [15, 3, 15], state: "minecraft:cave_air"},
        {pos: [15, 3, 16], state: "minecraft:cave_air"},
        {pos: [15, 3, 17], state: "minecraft:deepslate_bricks"},
        {pos: [15, 3, 18], state: "minecraft:deepslate_bricks"},
        {pos: [15, 3, 19], state: "minecraft:deepslate_bricks"},
        {pos: [15, 3, 20], state: "minecraft:deepslate_bricks"},
        {pos: [16, 3, 6], state: "minecraft:deepslate_bricks"},
        {pos: [16, 3, 7], state: "minecraft:deepslate_bricks"},
        {pos: [16, 3, 8], state: "minecraft:deepslate_bricks"},
        {pos: [16, 3, 9], state: "minecraft:skeleton_skull{powered:false,rotation:8}", nbt: {id: "minecraft:skull"}},
        {pos: [16, 3, 10], state: "minecraft:cave_air"},
        {pos: [16, 3, 11], state: "minecraft:cave_air"},
        {pos: [16, 3, 12], state: "minecraft:cave_air"},
        {pos: [16, 3, 13], state: "minecraft:cave_air"},
        {pos: [16, 3, 14], state: "minecraft:cave_air"},
        {pos: [16, 3, 15], state: "minecraft:cave_air"},
        {pos: [16, 3, 16], state: "minecraft:cave_air"},
        {pos: [16, 3, 17], state: "minecraft:skeleton_skull{powered:false,rotation:0}", nbt: {id: "minecraft:skull"}},
        {pos: [16, 3, 18], state: "minecraft:deepslate_bricks"},
        {pos: [16, 3, 19], state: "minecraft:deepslate_bricks"},
        {pos: [16, 3, 20], state: "minecraft:deepslate_bricks"},
        {pos: [17, 3, 6], state: "minecraft:deepslate_bricks"},
        {pos: [17, 3, 7], state: "minecraft:deepslate_bricks"},
        {pos: [17, 3, 8], state: "minecraft:deepslate_bricks"},
        {pos: [17, 3, 9], state: "minecraft:deepslate_bricks"},
        {pos: [17, 3, 10], state: "minecraft:cave_air"},
        {pos: [17, 3, 11], state: "minecraft:cave_air"},
        {pos: [17, 3, 12], state: "minecraft:cave_air"},
        {pos: [17, 3, 13], state: "minecraft:cave_air"},
        {pos: [17, 3, 14], state: "minecraft:cave_air"},
        {pos: [17, 3, 15], state: "minecraft:cave_air"},
        {pos: [17, 3, 16], state: "minecraft:cave_air"},
        {pos: [17, 3, 17], state: "minecraft:deepslate_bricks"},
        {pos: [17, 3, 18], state: "minecraft:deepslate_bricks"},
        {pos: [17, 3, 19], state: "minecraft:deepslate_bricks"},
        {pos: [17, 3, 20], state: "minecraft:deepslate_bricks"},
        {pos: [18, 3, 6], state: "minecraft:deepslate_bricks"},
        {pos: [18, 3, 7], state: "minecraft:deepslate_bricks"},
        {pos: [18, 3, 8], state: "minecraft:deepslate_bricks"},
        {pos: [18, 3, 9], state: "minecraft:deepslate_bricks"},
