{
    DataVersion: 3953,
    size: [15, 11, 14],
    data: [
        {pos: [1, 0, 4], state: "minecraft:deepslate_bricks"},
        {pos: [1, 0, 5], state: "minecraft:deepslate_bricks"},
        {pos: [1, 0, 6], state: "minecraft:deepslate_bricks"},
        {pos: [1, 0, 7], state: "minecraft:deepslate_bricks"},
        {pos: [1, 0, 8], state: "minecraft:deepslate_bricks"},
        {pos: [1, 0, 9], state: "minecraft:deepslate_bricks"},
        {pos: [1, 0, 10], state: "minecraft:deepslate_bricks"},
        {pos: [2, 0, 4], state: "minecraft:deepslate_bricks"},
        {pos: [2, 0, 5], state: "minecraft:deepslate_bricks"},
        {pos: [2, 0, 6], state: "minecraft:deepslate_bricks"},
        {pos: [2, 0, 7], state: "minecraft:deepslate_bricks"},
        {pos: [2, 0, 8], state: "minecraft:deepslate_bricks"},
        {pos: [2, 0, 9], state: "minecraft:deepslate_bricks"},
        {pos: [2, 0, 10], state: "minecraft:deepslate_bricks"},
        {pos: [3, 0, 4], state: "minecraft:deepslate_bricks"},
        {pos: [3, 0, 5], state: "minecraft:deepslate_bricks"},
        {pos: [3, 0, 6], state: "minecraft:deepslate_bricks"},
        {pos: [3, 0, 7], state: "minecraft:deepslate_bricks"},
        {pos: [3, 0, 8], state: "minecraft:deepslate_bricks"},
        {pos: [3, 0, 9], state: "minecraft:deepslate_bricks"},
        {pos: [3, 0, 10], state: "minecraft:deepslate_bricks"},
        {pos: [4, 0, 8], state: "minecraft:deepslate_bricks"},
        {pos: [4, 0, 9], state: "minecraft:deepslate_bricks"},
        {pos: [4, 0, 10], state: "minecraft:deepslate_bricks"},
        {pos: [5, 0, 0], state: "minecraft:deepslate_bricks"},
        {pos: [5, 0, 1], state: "minecraft:deepslate_bricks"},
        {pos: [5, 0, 2], state: "minecraft:deepslate_bricks"},
        {pos: [5, 0, 3], state: "minecraft:deepslate_bricks"},
        {pos: [5, 0, 4], state: "minecraft:deepslate_bricks"},
        {pos: [5, 0, 5], state: "minecraft:deepslate_bricks"},
        {pos: [5, 0, 6], state: "minecraft:deepslate_bricks"},
        {pos: [5, 0, 7], state: "minecraft:deepslate_bricks"},
        {pos: [5, 0, 8], state: "minecraft:deepslate_bricks"},
        {pos: [5, 0, 9], state: "minecraft:deepslate_bricks"},
        {pos: [5, 0, 10], state: "minecraft:deepslate_bricks"},
        {pos: [6, 0, 0], state: "minecraft:deepslate_bricks"},
        {pos: [6, 0, 1], state: "minecraft:deepslate_bricks"},
        {pos: [6, 0, 2], state: "minecraft:deepslate_bricks"},
        {pos: [6, 0, 3], state: "minecraft:deepslate_bricks"},
        {pos: [6, 0, 4], state: "minecraft:deepslate_bricks"},
        {pos: [6, 0, 5], state: "minecraft:deepslate_bricks"},
        {pos: [6, 0, 6], state: "minecraft:deepslate_bricks"},
        {pos: [6, 0, 7], state: "minecraft:deepslate_bricks"},
        {pos: [6, 0, 8], state: "minecraft:deepslate_bricks"},
        {pos: [6, 0, 9], state: "minecraft:deepslate_bricks"},
        {pos: [6, 0, 10], state: "minecraft:deepslate_bricks"},
        {pos: [7, 0, 0], state: "minecraft:deepslate_bricks"},
        {pos: [7, 0, 1], state: "minecraft:deepslate_bricks"},
        {pos: [7, 0, 2], state: "minecraft:deepslate_bricks"},
        {pos: [7, 0, 3], state: "minecraft:deepslate_bricks"},
        {pos: [7, 0, 4], state: "minecraft:deepslate_bricks"},
        {pos: [7, 0, 5], state: "minecraft:deepslate_bricks"},
        {pos: [7, 0, 6], state: "minecraft:deepslate_bricks"},
        {pos: [7, 0, 7], state: "minecraft:deepslate_bricks"},
        {pos: [7, 0, 8], state: "minecraft:deepslate_bricks"},
        {pos: [7, 0, 9], state: "minecraft:deepslate_bricks"},
        {pos: [7, 0, 10], state: "minecraft:deepslate_bricks"},
        {pos: [8, 0, 7], state: "minecraft:deepslate_bricks"},
        {pos: [8, 0, 8], state: "minecraft:deepslate_bricks"},
        {pos: [8, 0, 9], state: "minecraft:deepslate_bricks"},
        {pos: [8, 0, 10], state: "minecraft:deepslate_bricks"},
        {pos: [9, 0, 7], state: "minecraft:deepslate_bricks"},
        {pos: [9, 0, 8], state: "minecraft:deepslate_bricks"},
        {pos: [9, 0, 9], state: "minecraft:deepslate_bricks"},
        {pos: [9, 0, 10], state: "minecraft:deepslate_bricks"},
        {pos: [9, 0, 11], state: "minecraft:deepslate_bricks"},
        {pos: [9, 0, 12], state: "minecraft:deepslate_bricks"},
        {pos: [9, 0, 13], state: "minecraft:deepslate_bricks"},
        {pos: [10, 0, 7], state: "minecraft:deepslate_bricks"},
        {pos: [10, 0, 8], state: "minecraft:deepslate_bricks"},
        {pos: [10, 0, 9], state: "minecraft:deepslate_bricks"},
        {pos: [10, 0, 10], state: "minecraft:deepslate_bricks"},
        {pos: [10, 0, 11], state: "minecraft:deepslate_bricks"},
        {pos: [10, 0, 12], state: "minecraft:deepslate_bricks"},
        {pos: [10, 0, 13], state: "minecraft:deepslate_bricks"},
        {pos: [11, 0, 7], state: "minecraft:deepslate_bricks"},
        {pos: [11, 0, 8], state: "minecraft:deepslate_bricks"},
        {pos: [11, 0, 9], state: "minecraft:deepslate_bricks"},
        {pos: [11, 0, 10], state: "minecraft:deepslate_bricks"},
        {pos: [11, 0, 11], state: "minecraft:deepslate_bricks"},
        {pos: [11, 0, 12], state: "minecraft:deepslate_bricks"},
        {pos: [11, 0, 13], state: "minecraft:deepslate_bricks"},
        {pos: [1, 1, 4], state: "minecraft:deepslate_bricks"},
        {pos: [1, 1, 5], state: "minecraft:deepslate_bricks"},
        {pos: [1, 1, 6], state: "minecraft:deepslate_bricks"},
        {pos: [1, 1, 7], state: "minecraft:deepslate_bricks"},
        {pos: [1, 1, 8], state: "minecraft:deepslate_bricks"},
        {pos: [1, 1, 9], state: "minecraft:deepslate_bricks"},
        {pos: [1, 1, 10], state: "minecraft:deepslate_bricks"},
        {pos: [2, 1, 4], state: "minecraft:deepslate_bricks"},
        {pos: [2, 1, 5], state: "minecraft:redstone_wire{east:none,north:side,power:0,south:side,west:none}"},
        {pos: [2, 1, 6], state: "minecraft:redstone_wire{east:none,north:side,power:0,south:side,west:none}"},
        {pos: [2, 1, 7], state: "minecraft:repeater{delay:1,facing:north,locked:false,powered:false}"},
        {pos: [2, 1, 8], state: "minecraft:redstone_wire{east:none,north:side,power:0,south:side,west:none}"},
        {pos: [2, 1, 9], state: "minecraft:redstone_wire{east:side,north:side,power:0,south:none,west:none}"},
        {pos: [2, 1, 10], state: "minecraft:deepslate_bricks"},
        {pos: [3, 1, 4], state: "minecraft:deepslate_bricks"},
        {pos: [3, 1, 5], state: "minecraft:deepslate_bricks"},
        {pos: [3, 1, 6], state: "minecraft:deepslate_bricks"},
        {pos: [3, 1, 7], state: "minecraft:deepslate_bricks"},
        {pos: [3, 1, 8], state: "minecraft:deepslate_bricks"},
        {pos: [3, 1, 9], state: "minecraft:redstone_wire{east:side,north:none,power:0,south:none,west:side}"},
        {pos: [3, 1, 10], state: "minecraft:deepslate_bricks"},
        {pos: [4, 1, 8], state: "minecraft:deepslate_bricks"},
        {pos: [4, 1, 9], state: "minecraft:repeater{delay:1,facing:west,locked:false,powered:false}"},
        {pos: [4, 1, 10], state: "minecraft:deepslate_bricks"},
        {pos: [5, 1, 0], state: "minecraft:deepslate_bricks"},
        {pos: [5, 1, 1], state: "minecraft:deepslate_bricks"},
        {pos: [5, 1, 2], state: "minecraft:deepslate_bricks"},
        {pos: [5, 1, 3], state: "minecraft:deepslate_bricks"},
        {pos: [5, 1, 4], state: "minecraft:deepslate_bricks"},
        {pos: [5, 1, 5], state: "minecraft:deepslate_bricks"},
        {pos: [5, 1, 6], state: "minecraft:deepslate_bricks"},
        {pos: [5, 1, 7], state: "minecraft:deepslate_bricks"},
        {pos: [5, 1, 8], state: "minecraft:deepslate_bricks"},
        {pos: [5, 1, 9], state: "minecraft:redstone_wire{east:side,north:none,power:0,south:none,west:side}"},
        {pos: [5, 1, 10], state: "minecraft:deepslate_bricks"},
        {pos: [6, 1, 0], state: "minecraft:deepslate_bricks"},
        {pos: [6, 1, 1], state: "minecraft:deepslate_bricks"},
        {pos: [6, 1, 2], state: "minecraft:redstone_wall_torch{facing:north,lit:true}"},
        {pos: [6, 1, 3], state: "minecraft:deepslate_bricks"},
        {pos: [6, 1, 4], state: "minecraft:repeater{delay:1,facing:south,locked:false,powered:false}"},
        {pos: [6, 1, 5], state: "minecraft:redstone_wire{east:none,north:side,power:0,south:side,west:none}"},
        {pos: [6, 1, 6], state: "minecraft:deepslate_bricks"},
        {pos: [6, 1, 7], state: "minecraft:redstone_wire{east:none,north:side,power:0,south:side,west:none}"},
        {pos: [6, 1, 8], state: "minecraft:redstone_wire{east:side,north:side,power:0,south:side,west:none}"},
        {pos: [6, 1, 9], state: "minecraft:redstone_wire{east:none,north:side,power:0,south:none,west:side}"},
        {pos: [6, 1, 10], state: "minecraft:deepslate_bricks"},
        {pos: [7, 1, 0], state: "minecraft:deepslate_bricks"},
        {pos: [7, 1, 1], state: "minecraft:deepslate_bricks"},
        {pos: [7, 1, 2], state: "minecraft:deepslate_bricks"},
        {pos: [7, 1, 3], state: "minecraft:deepslate_bricks"},
        {pos: [7, 1, 4], state: "minecraft:deepslate_bricks"},
        {pos: [7, 1, 5], state: "minecraft:deepslate_bricks"},
        {pos: [7, 1, 6], state: "minecraft:deepslate_bricks"},
        {pos: [7, 1, 7], state: "minecraft:deepslate_bricks"},
        {pos: [7, 1, 8], state: "minecraft:redstone_wire{east:side,north:none,power:0,south:none,west:side}"},
        {pos: [7, 1, 9], state: "minecraft:deepslate_bricks"},
        {pos: [7, 1, 10], state: "minecraft:deepslate_bricks"},
        {pos: [8, 1, 7], state: "minecraft:deepslate_bricks"},
        {pos: [8, 1, 8], state: "minecraft:repeater{delay:1,facing:west,locked:false,powered:false}"},
        {pos: [8, 1, 9], state: "minecraft:deepslate_bricks"},
        {pos: [8, 1, 10], state: "minecraft:deepslate_bricks"},
        {pos: [9, 1, 7], state: "minecraft:deepslate_bricks"},
        {pos: [9, 1, 8], state: "minecraft:redstone_wire{east:side,north:none,power:0,south:none,west:side}"},
        {pos: [9, 1, 9], state: "minecraft:deepslate_bricks"},
        {pos: [9, 1, 10], state: "minecraft:deepslate_bricks"},
        {pos: [9, 1, 11], state: "minecraft:deepslate_bricks"},
        {pos: [9, 1, 12], state: "minecraft:deepslate_bricks"},
        {pos: [9, 1, 13], state: "minecraft:deepslate_bricks"},
        {pos: [10, 1, 7], state: "minecraft:deepslate_bricks"},
        {pos: [10, 1, 8], state: "minecraft:redstone_wire{east:none,north:none,power:0,south:side,west:side}"},
        {pos: [10, 1, 9], state: "minecraft:redstone_wire{east:none,north:side,power:0,south:side,west:none}"},
        {pos: [10, 1, 10], state: "minecraft:redstone_wire{east:none,north:side,power:0,south:up,west:none}"},
        {pos: [10, 1, 11], state: "minecraft:deepslate_bricks"},
        {pos: [10, 1, 12], state: "minecraft:deepslate_bricks"},
        {pos: [10, 1, 13], state: "minecraft:deepslate_bricks"},
        {pos: [11, 1, 7], state: "minecraft:deepslate_bricks"},
        {pos: [11, 1, 8], state: "minecraft:deepslate_bricks"},
        {pos: [11, 1, 9], state: "minecraft:deepslate_bricks"},
        {pos: [11, 1, 10], state: "minecraft:deepslate_bricks"},
        {pos: [11, 1, 11], state: "minecraft:deepslate_bricks"},
        {pos: [11, 1, 12], state: "minecraft:deepslate_bricks"},
        {pos: [11, 1, 13], state: "minecraft:deepslate_bricks"},
        {pos: [1, 2, 4], state: "minecraft:deepslate_bricks"},
        {pos: [1, 2, 5], state: "minecraft:deepslate_bricks"},
        {pos: [1, 2, 6], state: "minecraft:deepslate_bricks"},
        {pos: [1, 2, 7], state: "minecraft:deepslate_bricks"},
        {pos: [1, 2, 8], state: "minecraft:deepslate_bricks"},
        {pos: [1, 2, 9], state: "minecraft:deepslate_bricks"},
        {pos: [1, 2, 10], state: "minecraft:deepslate_bricks"},
        {pos: [2, 2, 4], state: "minecraft:deepslate_bricks"},
        {pos: [2, 2, 5], state: "minecraft:cave_air"},
        {pos: [2, 2, 6], state: "minecraft:deepslate_bricks"},
        {pos: [2, 2, 7], state: "minecraft:deepslate_bricks"},
        {pos: [2, 2, 8], state: "minecraft:deepslate_bricks"},
        {pos: [2, 2, 9], state: "minecraft:cave_air"},
        {pos: [2, 2, 10], state: "minecraft:deepslate_bricks"},
        {pos: [3, 2, 4], state: "minecraft:deepslate_bricks"},
        {pos: [3, 2, 5], state: "minecraft:deepslate_bricks"},
        {pos: [3, 2, 6], state: "minecraft:deepslate_bricks"},
        {pos: [3, 2, 7], state: "minecraft:deepslate_bricks"},
        {pos: [3, 2, 8], state: "minecraft:deepslate_bricks"},
        {pos: [3, 2, 9], state: "minecraft:deepslate_bricks"},
        {pos: [3, 2, 10], state: "minecraft:deepslate_bricks"},
        {pos: [4, 2, 8], state: "minecraft:deepslate_bricks"},
        {pos: [4, 2, 9], state: "minecraft:deepslate_bricks"},
        {pos: [4, 2, 10], state: "minecraft:deepslate_bricks"},
        {pos: [5, 2, 0], state: "minecraft:deepslate_bricks"},
        {pos: [5, 2, 1], state: "minecraft:deepslate_bricks"},
        {pos: [5, 2, 2], state: "minecraft:deepslate_bricks"},
        {pos: [5, 2, 3], state: "minecraft:deepslate_bricks"},
        {pos: [5, 2, 4], state: "minecraft:deepslate_bricks"},
        {pos: [5, 2, 5], state: "minecraft:deepslate_bricks"},
        {pos: [5, 2, 6], state: "minecraft:deepslate_bricks"},
        {pos: [5, 2, 7], state: "minecraft:deepslate_bricks"},
        {pos: [5, 2, 8], state: "minecraft:deepslate_bricks"},
        {pos: [5, 2, 9], state: "minecraft:deepslate_bricks"},
        {pos: [5, 2, 10], state: "minecraft:deepslate_bricks"},
        {pos: [6, 2, 0], state: "minecraft:deepslate_bricks"},
        {pos: [6, 2, 1], state: "minecraft:deepslate_bricks"},
        {pos: [6, 2, 2], state: "minecraft:deepslate_bricks"},
        {pos: [6, 2, 3], state: "minecraft:deepslate_bricks"},
        {pos: [6, 2, 4], state: "minecraft:deepslate_bricks"},
        {pos: [6, 2, 5], state: "minecraft:cave_air"},
        {pos: [6, 2, 6], state: "minecraft:deepslate_bricks"},
        {pos: [6, 2, 7], state: "minecraft:cave_air"},
        {pos: [6, 2, 8], state: "minecraft:deepslate_bricks"},
        {pos: [6, 2, 9], state: "minecraft:cave_air"},
        {pos: [6, 2, 10], state: "minecraft:deepslate_bricks"},
        {pos: [7, 2, 0], state: "minecraft:deepslate_bricks"},
        {pos: [7, 2, 1], state: "minecraft:deepslate_bricks"},
        {pos: [7, 2, 2], state: "minecraft:deepslate_bricks"},
        {pos: [7, 2, 3], state: "minecraft:deepslate_bricks"},
        {pos: [7, 2, 4], state: "minecraft:deepslate_bricks"},
        {pos: [7, 2, 5], state: "minecraft:deepslate_bricks"},
        {pos: [7, 2, 6], state: "minecraft:deepslate_bricks"},
        {pos: [7, 2, 7], state: "minecraft:deepslate_bricks"},
        {pos: [7, 2, 8], state: "minecraft:deepslate_bricks"},
        {pos: [7, 2, 9], state: "minecraft:deepslate_bricks"},
        {pos: [7, 2, 10], state: "minecraft:deepslate_bricks"},
        {pos: [8, 2, 7], state: "minecraft:deepslate_bricks"},
        {pos: [8, 2, 8], state: "minecraft:deepslate_bricks"},
        {pos: [8, 2, 9], state: "minecraft:deepslate_bricks"},
        {pos: [8, 2, 10], state: "minecraft:deepslate_bricks"},
        {pos: [9, 2, 7], state: "minecraft:deepslate_bricks"},
        {pos: [9, 2, 8], state: "minecraft:deepslate_bricks"},
        {pos: [9, 2, 9], state: "minecraft:deepslate_bricks"},
        {pos: [9, 2, 10], state: "minecraft:deepslate_bricks"},
        {pos: [9, 2, 11], state: "minecraft:deepslate_bricks"},
        {pos: [9, 2, 12], state: "minecraft:deepslate_bricks"},
        {pos: [9, 2, 13], state: "minecraft:deepslate_bricks"},
        {pos: [10, 2, 7], state: "minecraft:deepslate_bricks"},
        {pos: [10, 2, 8], state: "minecraft:deepslate_bricks"},
        {pos: [10, 2, 9], state: "minecraft:deepslate_bricks"},
        {pos: [10, 2, 10], state: "minecraft:cave_air"},
        {pos: [10, 2, 11], state: "minecraft:redstone_wire{east:none,north:side,power:0,south:up,west:none}"},
        {pos: [10, 2, 12], state: "minecraft:deepslate_bricks"},
        {pos: [10, 2, 13], state: "minecraft:deepslate_bricks"},
        {pos: [11, 2, 7], state: "minecraft:deepslate_bricks"},
        {pos: [11, 2, 8], state: "minecraft:deepslate_bricks"},
        {pos: [11, 2, 9], state: "minecraft:deepslate_bricks"},
        {pos: [11, 2, 10], state: "minecraft:deepslate_bricks"},
        {pos: [11, 2, 11], state: "minecraft:deepslate_bricks"},
        {pos: [11, 2, 12], state: "minecraft:deepslate_bricks"},
        {pos: [11, 2, 13], state: "minecraft:deepslate_bricks"},
        {pos: [0, 3, 2], state: "minecraft:deepslate{axis:y}"},
        {pos: [0, 3, 3], state: "minecraft:deepslate{axis:y}"},
        {pos: [0, 3, 4], state: "minecraft:deepslate{axis:y}"},
        {pos: [0, 3, 5], state: "minecraft:deepslate{axis:y}"},
        {pos: [0, 3, 6], state: "minecraft:deepslate{axis:y}"},
        {pos: [0, 3, 7], state: "minecraft:deepslate{axis:y}"},
        {pos: [0, 3, 8], state: "minecraft:deepslate{axis:y}"},
        {pos: [0, 3, 9], state: "minecraft:deepslate{axis:y}"},
        {pos: [0, 3, 10], state: "minecraft:deepslate{axis:y}"},
        {pos: [0, 3, 11], state: "minecraft:deepslate{axis:y}"},
        {pos: [1, 3, 2], state: "minecraft:deepslate{axis:y}"},
        {pos: [1, 3, 3], state: "minecraft:deepslate{axis:y}"},
        {pos: [1, 3, 4], state: "minecraft:deepslate{axis:y}"},
        {pos: [1, 3, 5], state: "minecraft:deepslate{axis:y}"},
        {pos: [1, 3, 6], state: "minecraft:deepslate{axis:y}"},
        {pos: [1, 3, 7], state: "minecraft:deepslate{axis:y}"},
        {pos: [1, 3, 8], state: "minecraft:deepslate{axis:y}"},
        {pos: [1, 3, 9], state: "minecraft:deepslate{axis:y}"},
        {pos: [1, 3, 10], state: "minecraft:deepslate{axis:y}"},
        {pos: [1, 3, 11], state: "minecraft:deepslate{axis:y}"},
        {pos: [2, 3, 1], state: "minecraft:deepslate{axis:y}"},
        {pos: [2, 3, 2], state: "minecraft:deepslate{axis:y}"},
        {pos: [2, 3, 3], state: "minecraft:deepslate{axis:y}"},
        {pos: [2, 3, 4], state: "minecraft:deepslate{axis:y}"},
        {pos: [2, 3, 5], state: "minecraft:redstone_block"},
        {pos: [2, 3, 6], state: "minecraft:deepslate_bricks"},
        {pos: [2, 3, 7], state: "minecraft:deepslate{axis:y}"},
        {pos: [2, 3, 8], state: "minecraft:deepslate_bricks"},
        {pos: [2, 3, 9], state: "minecraft:redstone_block"},
        {pos: [2, 3, 10], state: "minecraft:deepslate{axis:y}"},
        {pos: [2, 3, 11], state: "minecraft:deepslate{axis:y}"},
        {pos: [3, 3, 1], state: "minecraft:deepslate{axis:y}"},
        {pos: [3, 3, 2], state: "minecraft:deepslate{axis:y}"},
        {pos: [3, 3, 3], state: "minecraft:deepslate{axis:y}"},
        {pos: [3, 3, 4], state: "minecraft:deepslate{axis:y}"},
        {pos: [3, 3, 5], state: "minecraft:deepslate{axis:y}"},
        {pos: [3, 3, 6], state: "minecraft:deepslate{axis:y}"},
        {pos: [3, 3, 7], state: "minecraft:deepslate{axis:y}"},
        {pos: [3, 3, 8], state: "minecraft:deepslate{axis:y}"},
        {pos: [3, 3, 9], state: "minecraft:deepslate{axis:y}"},
        {pos: [3, 3, 10], state: "minecraft:deepslate{axis:y}"},
        {pos: [3, 3, 11], state: "minecraft:deepslate{axis:y}"},
        {pos: [4, 3, 1], state: "minecraft:deepslate{axis:y}"},
        {pos: [4, 3, 2], state: "minecraft:deepslate{axis:y}"},
        {pos: [4, 3, 3], state: "minecraft:deepslate{axis:y}"},
        {pos: [4, 3, 4], state: "minecraft:deepslate{axis:y}"},
        {pos: [4, 3, 5], state: "minecraft:deepslate{axis:y}"},
        {pos: [4, 3, 6], state: "minecraft:deepslate{axis:y}"},
        {pos: [4, 3, 7], state: "minecraft:deepslate{axis:y}"},
        {pos: [4, 3, 8], state: "minecraft:deepslate{axis:y}"},
        {pos: [4, 3, 9], state: "minecraft:deepslate{axis:y}"},
        {pos: [4, 3, 10], state: "minecraft:deepslate{axis:y}"},
        {pos: [4, 3, 11], state: "minecraft:deepslate{axis:y}"},
        {pos: [5, 3, 0], state: "minecraft:deepslate_bricks"},
        {pos: [5, 3, 1], state: "minecraft:deepslate_bricks"},
        {pos: [5, 3, 2], state: "minecraft:deepslate_bricks"},
        {pos: [5, 3, 3], state: "minecraft:deepslate{axis:y}"},
        {pos: [5, 3, 4], state: "minecraft:deepslate{axis:y}"},
        {pos: [5, 3, 5], state: "minecraft:deepslate{axis:y}"},
        {pos: [5, 3, 6], state: "minecraft:deepslate{axis:y}"},
        {pos: [5, 3, 7], state: "minecraft:deepslate{axis:y}"},
        {pos: [5, 3, 8], state: "minecraft:deepslate{axis:y}"},
        {pos: [5, 3, 9], state: "minecraft:deepslate{axis:y}"},
        {pos: [5, 3, 10], state: "minecraft:deepslate{axis:y}"},
        {pos: [5, 3, 11], state: "minecraft:deepslate{axis:y}"},
        {pos: [6, 3, 0], state: "minecraft:deepslate_bricks"},
        {pos: [6, 3, 1], state: "minecraft:redstone_wire{east:side,north:none,power:14,south:side,west:none}"},
        {pos: [6, 3, 2], state: "minecraft:redstone_wire{east:none,north:side,power:15,south:side,west:none}"},
        {pos: [6, 3, 3], state: "minecraft:deepslate{axis:y}"},
        {pos: [6, 3, 4], state: "minecraft:deepslate{axis:y}"},
        {pos: [6, 3, 5], state: "minecraft:redstone_block"},
        {pos: [6, 3, 6], state: "minecraft:deepslate{axis:y}"},
        {pos: [6, 3, 7], state: "minecraft:deepslate{axis:y}"},
        {pos: [6, 3, 8], state: "minecraft:deepslate{axis:y}"},
        {pos: [6, 3, 9], state: "minecraft:redstone_block"},
        {pos: [6, 3, 10], state: "minecraft:deepslate{axis:y}"},
        {pos: [6, 3, 11], state: "minecraft:deepslate{axis:y}"},
        {pos: [7, 3, 0], state: "minecraft:deepslate_bricks"},
        {pos: [7, 3, 1], state: "minecraft:redstone_wire{east:up,north:none,power:13,south:none,west:side}"},
        {pos: [7, 3, 2], state: "minecraft:deepslate_bricks"},
        {pos: [7, 3, 3], state: "minecraft:deepslate{axis:y}"},
        {pos: [7, 3, 4], state: "minecraft:deepslate{axis:y}"},
        {pos: [7, 3, 5], state: "minecraft:deepslate{axis:y}"},
        {pos: [7, 3, 6], state: "minecraft:deepslate{axis:y}"},
        {pos: [7, 3, 7], state: "minecraft:deepslate{axis:y}"},
        {pos: [7, 3, 8], state: "minecraft:deepslate{axis:y}"},
        {pos: [7, 3, 9], state: "minecraft:deepslate{axis:y}"},
        {pos: [7, 3, 10], state: "minecraft:deepslate{axis:y}"},
        {pos: [7, 3, 11], state: "minecraft:deepslate{axis:y}"},
        {pos: [8, 3, 0], state: "minecraft:deepslate_bricks"},
        {pos: [8, 3, 1], state: "minecraft:deepslate_bricks"},
        {pos: [8, 3, 2], state: "minecraft:deepslate_bricks"},
        {pos: [8, 3, 3], state: "minecraft:deepslate{axis:y}"},
        {pos: [8, 3, 4], state: "minecraft:deepslate{axis:y}"},
        {pos: [8, 3, 5], state: "minecraft:deepslate{axis:y}"},
        {pos: [8, 3, 6], state: "minecraft:deepslate{axis:y}"},
        {pos: [8, 3, 7], state: "minecraft:deepslate{axis:y}"},
        {pos: [8, 3, 8], state: "minecraft:deepslate{axis:y}"},
        {pos: [8, 3, 9], state: "minecraft:deepslate{axis:y}"},
        {pos: [8, 3, 10], state: "minecraft:deepslate{axis:y}"},
        {pos: [8, 3, 11], state: "minecraft:deepslate{axis:y}"},
        {pos: [8, 3, 12], state: "minecraft:deepslate_bricks"},
        {pos: [8, 3, 13], state: "minecraft:deepslate_bricks"},
        {pos: [9, 3, 0], state: "minecraft:deepslate_bricks"},
        {pos: [9, 3, 1], state: "minecraft:deepslate_bricks"},
        {pos: [9, 3, 2], state: "minecraft:deepslate_bricks"},
        {pos: [9, 3, 3], state: "minecraft:deepslate{axis:y}"},
        {pos: [9, 3, 4], state: "minecraft:deepslate{axis:y}"},
        {pos: [9, 3, 5], state: "minecraft:deepslate{axis:y}"},
        {pos: [9, 3, 6], state: "minecraft:deepslate{axis:y}"},
        {pos: [9, 3, 7], state: "minecraft:deepslate{axis:y}"},
        {pos: [9, 3, 8], state: "minecraft:deepslate{axis:y}"},
        {pos: [9, 3, 9], state: "minecraft:deepslate{axis:y}"},
        {pos: [9, 3, 10], state: "minecraft:deepslate{axis:y}"},
        {pos: [9, 3, 11], state: "minecraft:deepslate{axis:y}"},
        {pos: [9, 3, 12], state: "minecraft:deepslate_bricks"},
        {pos: [9, 3, 13], state: "minecraft:deepslate_bricks"},
        {pos: [10, 3, 0], state: "minecraft:deepslate_bricks"},
        {pos: [10, 3, 1], state: "minecraft:deepslate_bricks"},
        {pos: [10, 3, 2], state: "minecraft:deepslate_bricks"},
        {pos: [10, 3, 3], state: "minecraft:deepslate_bricks"},
        {pos: [10, 3, 4], state: "minecraft:deepslate_bricks"},
        {pos: [10, 3, 5], state: "minecraft:deepslate{axis:y}"},
        {pos: [10, 3, 6], state: "minecraft:deepslate{axis:y}"},
        {pos: [10, 3, 7], state: "minecraft:deepslate{axis:y}"},
        {pos: [10, 3, 8], state: "minecraft:deepslate{axis:y}"},
        {pos: [10, 3, 9], state: "minecraft:deepslate{axis:y}"},
        {pos: [10, 3, 10], state: "minecraft:deepslate_bricks"},
        {pos: [10, 3, 11], state: "minecraft:cave_air"},
        {pos: [10, 3, 12], state: "minecraft:redstone_wire{east:none,north:side,power:0,south:none,west:up}"},
        {pos: [10, 3, 13], state: "minecraft:deepslate_bricks"},
        {pos: [11, 3, 5], state: "minecraft:deepslate{axis:y}"},
        {pos: [11, 3, 6], state: "minecraft:deepslate{axis:y}"},
        {pos: [11, 3, 7], state: "minecraft:deepslate{axis:y}"},
        {pos: [11, 3, 8], state: "minecraft:deepslate{axis:y}"},
        {pos: [11, 3, 9], state: "minecraft:deepslate{axis:y}"},
        {pos: [11, 3, 10], state: "minecraft:deepslate_bricks"},
        {pos: [11, 3, 11], state: "minecraft:deepslate_bricks"},
        {pos: [11, 3, 12], state: "minecraft:deepslate_bricks"},
        {pos: [11, 3, 13], state: "minecraft:deepslate_bricks"},
        {pos: [12, 3, 5], state: "minecraft:deepslate{axis:y}"},
        {pos: [12, 3, 6], state: "minecraft:deepslate{axis:y}"},
        {pos: [12, 3, 7], state: "minecraft:deepslate{axis:y}"},
        {pos: [12, 3, 8], state: "minecraft:deepslate{axis:y}"},
        {pos: [12, 3, 9], state: "minecraft:deepslate{axis:y}"},
        {pos: [13, 3, 5], state: "minecraft:deepslate{axis:y}"},
        {pos: [13, 3, 6], state: "minecraft:deepslate{axis:y}"},
        {pos: [13, 3, 7], state: "minecraft:deepslate{axis:y}"},
        {pos: [13, 3, 8], state: "minecraft:deepslate{axis:y}"},
        {pos: [13, 3, 9], state: "minecraft:deepslate{axis:y}"},
        {pos: [14, 3, 5], state: "minecraft:deepslate{axis:y}"},
        {pos: [14, 3, 6], state: "minecraft:deepslate{axis:y}"},
        {pos: [14, 3, 7], state: "minecraft:deepslate{axis:y}"},
        {pos: [14, 3, 8], state: "minecraft:deepslate{axis:y}"},
        {pos: [14, 3, 9], state: "minecraft:deepslate{axis:y}"},
        {pos: [0, 4, 2], state: "minecraft:deepslate_bricks"},
        {pos: [0, 4, 3], state: "minecraft:deepslate_bricks"},
        {pos: [0, 4, 4], state: "minecraft:deepslate_bricks"},
        {pos: [0, 4, 5], state: "minecraft:deepslate_bricks"},
        {pos: [0, 4, 6], state: "minecraft:gravel"},
        {pos: [0, 4, 7], state: "minecraft:gravel"},
        {pos: [0, 4, 8], state: "minecraft:gravel"},
        {pos: [0, 4, 9], state: "minecraft:deepslate_bricks"},
        {pos: [0, 4, 10], state: "minecraft:deepslate_bricks"},
        {pos: [0, 4, 11], state: "minecraft:deepslate_bricks"},
        {pos: [1, 4, 2], state: "minecraft:deepslate_bricks"},
        {pos: [1, 4, 3], state: "minecraft:deepslate_bricks"},
        {pos: [1, 4, 4], state: "minecraft:gravel"},
        {pos: [1, 4, 5], state: "minecraft:gravel"},
        {pos: [1, 4, 6], state: "minecraft:gravel"},
        {pos: [1, 4, 7], state: "minecraft:gravel"},
        {pos: [1, 4, 8], state: "minecraft:gravel"},
        {pos: [1, 4, 9], state: "minecraft:gravel"},
        {pos: [1, 4, 10], state: "minecraft:gravel"},
        {pos: [1, 4, 11], state: "minecraft:deepslate_bricks"},
        {pos: [2, 4, 1], state: "minecraft:deepslate_bricks"},
        {pos: [2, 4, 2], state: "minecraft:deepslate_bricks"},
        {pos: [2, 4, 3], state: "minecraft:deepslate_bricks"},
        {pos: [2, 4, 4], state: "minecraft:gravel"},
        {pos: [2, 4, 5], state: "minecraft:sticky_piston{extended:false,facing:down}"},
        {pos: [2, 4, 6], state: "minecraft:gravel"},
        {pos: [2, 4, 7], state: "minecraft:gravel"},
        {pos: [2, 4, 8], state: "minecraft:gravel"},
        {pos: [2, 4, 9], state: "minecraft:sticky_piston{extended:false,facing:down}"},
        {pos: [2, 4, 10], state: "minecraft:gravel"},
        {pos: [2, 4, 11], state: "minecraft:deepslate_bricks"},
        {pos: [3, 4, 1], state: "minecraft:deepslate_bricks"},
        {pos: [3, 4, 2], state: "minecraft:deepslate_bricks"},
        {pos: [3, 4, 3], state: "minecraft:deepslate_bricks"},
        {pos: [3, 4, 4], state: "minecraft:gravel"},
        {pos: [3, 4, 5], state: "minecraft:gravel"},
        {pos: [3, 4, 6], state: "minecraft:gravel"},
        {pos: [3, 4, 7], state: "minecraft:gravel"},
        {pos: [3, 4, 8], state: "minecraft:gravel"},
        {pos: [3, 4, 9], state: "minecraft:gravel"},
        {pos: [3, 4, 10], state: "minecraft:gravel"},
        {pos: [3, 4, 11], state: "minecraft:deepslate_bricks"},
        {pos: [4, 4, 1], state: "minecraft:deepslate_bricks"},
        {pos: [4, 4, 2], state: "minecraft:deepslate_bricks"},
        {pos: [4, 4, 3], state: "minecraft:deepslate_bricks"},
        {pos: [4, 4, 4], state: "minecraft:gravel"},
        {pos: [4, 4, 5], state: "minecraft:gravel"},
        {pos: [4, 4, 6], state: "minecraft:gravel"},
        {pos: [4, 4, 7], state: "minecraft:gravel"},
        {pos: [4, 4, 8], state: "minecraft:gravel"},
        {pos: [4, 4, 9], state: "minecraft:gravel"},
        {pos: [4, 4, 10], state: "minecraft:gravel"},
        {pos: [4, 4, 11], state: "minecraft:deepslate_bricks"},
        {pos: [5, 4, 0], state: "minecraft:deepslate_bricks"},
        {pos: [5, 4, 1], state: "minecraft:deepslate_bricks"},
        {pos: [5, 4, 2], state: "minecraft:deepslate_bricks"},
        {pos: [5, 4, 3], state: "minecraft:deepslate_bricks"},
        {pos: [5, 4, 4], state: "minecraft:gravel"},
        {pos: [5, 4, 5], state: "minecraft:gravel"},
        {pos: [5, 4, 6], state: "minecraft:gravel"},
        {pos: [5, 4, 7], state: "minecraft:gravel"},
        {pos: [5, 4, 8], state: "minecraft:gravel"},
        {pos: [5, 4, 9], state: "minecraft:gravel"},
        {pos: [5, 4, 10], state: "minecraft:gravel"},
        {pos: [5, 4, 11], state: "minecraft:deepslate_bricks"},
        {pos: [6, 4, 0], state: "minecraft:deepslate_bricks"},
        {pos: [6, 4, 1], state: "minecraft:deepslate_bricks"},
        {pos: [6, 4, 2], state: "minecraft:deepslate_bricks"},
        {pos: [6, 4, 3], state: "minecraft:deepslate_bricks"},
        {pos: [6, 4, 4], state: "minecraft:gravel"},
        {pos: [6, 4, 5], state: "minecraft:sticky_piston{extended:false,facing:down}"},
        {pos: [6, 4, 6], state: "minecraft:gravel"},
        {pos: [6, 4, 7], state: "minecraft:gravel"},
        {pos: [6, 4, 8], state: "minecraft:gravel"},
        {pos: [6, 4, 9], state: "minecraft:sticky_piston{extended:false,facing:down}"},
        {pos: [6, 4, 10], state: "minecraft:gravel"},
        {pos: [6, 4, 11], state: "minecraft:deepslate_bricks"},
        {pos: [7, 4, 0], state: "minecraft:deepslate_bricks"},
        {pos: [7, 4, 1], state: "minecraft:cave_air"},
        {pos: [7, 4, 2], state: "minecraft:deepslate_bricks"},
        {pos: [7, 4, 3], state: "minecraft:deepslate_bricks"},
        {pos: [7, 4, 4], state: "minecraft:gravel"},
        {pos: [7, 4, 5], state: "minecraft:gravel"},
        {pos: [7, 4, 6], state: "minecraft:gravel"},
        {pos: [7, 4, 7], state: "minecraft:gravel"},
        {pos: [7, 4, 8], state: "minecraft:gravel"},
        {pos: [7, 4, 9], state: "minecraft:gravel"},
        {pos: [7, 4, 10], state: "minecraft:gravel"},
        {pos: [7, 4, 11], state: "minecraft:deepslate_bricks"},
        {pos: [7, 4, 12], state: "minecraft:deepslate_bricks"},
        {pos: [7, 4, 13], state: "minecraft:deepslate_bricks"},
        {pos: [8, 4, 0], state: "minecraft:deepslate_bricks"},
        {pos: [8, 4, 1], state: "minecraft:redstone_wire{east:up,north:none,power:12,south:none,west:side}"},
        {pos: [8, 4, 2], state: "minecraft:deepslate_bricks"},
        {pos: [8, 4, 3], state: "minecraft:deepslate_bricks"},
        {pos: [8, 4, 4], state: "minecraft:deepslate_bricks"},
        {pos: [8, 4, 5], state: "minecraft:gravel"},
        {pos: [8, 4, 6], state: "minecraft:deepslate_bricks"},
        {pos: [8, 4, 7], state: "minecraft:gravel"},
        {pos: [8, 4, 8], state: "minecraft:deepslate_bricks"},
        {pos: [8, 4, 9], state: "minecraft:gravel"},
        {pos: [8, 4, 10], state: "minecraft:gravel"},
        {pos: [8, 4, 11], state: "minecraft:deepslate_bricks"},
        {pos: [8, 4, 12], state: "minecraft:deepslate_bricks"},
        {pos: [8, 4, 13], state: "minecraft:deepslate_bricks"},
        {pos: [9, 4, 0], state: "minecraft:deepslate_bricks"},
        {pos: [9, 4, 1], state: "minecraft:deepslate_bricks"},
        {pos: [9, 4, 2], state: "minecraft:deepslate_bricks"},
        {pos: [9, 4, 3], state: "minecraft:deepslate_bricks"},
        {pos: [9, 4, 4], state: "minecraft:deepslate_bricks"},
        {pos: [9, 4, 5], state: "minecraft:deepslate_bricks"},
        {pos: [9, 4, 6], state: "minecraft:deepslate_bricks"},
        {pos: [9, 4, 7], state: "minecraft:gravel"},
        {pos: [9, 4, 8], state: "minecraft:deepslate_bricks"},
        {pos: [9, 4, 9], state: "minecraft:deepslate_bricks"},
        {pos: [9, 4, 10], state: "minecraft:deepslate_bricks"},
        {pos: [9, 4, 11], state: "minecraft:deepslate_bricks"},
        {pos: [9, 4, 12], state: "minecraft:redstone_wire{east:side,north:none,power:0,south:none,west:up}"},
        {pos: [9, 4, 13], state: "minecraft:deepslate_bricks"},
        {pos: [10, 4, 0], state: "minecraft:deepslate_bricks"},
        {pos: [10, 4, 1], state: "minecraft:deepslate_bricks"},
        {pos: [10, 4, 2], state: "minecraft:deepslate_bricks"},
        {pos: [10, 4, 3], state: "minecraft:deepslate_bricks"},
        {pos: [10, 4, 4], state: "minecraft:deepslate_bricks"},
        {pos: [10, 4, 5], state: "minecraft:deepslate_bricks"},
        {pos: [10, 4, 6], state: "minecraft:deepslate_bricks"},
        {pos: [10, 4, 7], state: "minecraft:gravel"},
        {pos: [10, 4, 8], state: "minecraft:deepslate_bricks"},
        {pos: [10, 4, 9], state: "minecraft:deepslate_bricks"},
        {pos: [10, 4, 10], state: "minecraft:deepslate_bricks"},
        {pos: [10, 4, 11], state: "minecraft:deepslate_bricks"},
        {pos: [10, 4, 12], state: "minecraft:cave_air"},
        {pos: [10, 4, 13], state: "minecraft:deepslate_bricks"},
        {pos: [11, 4, 5], state: "minecraft:deepslate_bricks"},
        {pos: [11, 4, 6], state: "minecraft:gravel"},
        {pos: [11, 4, 7], state: "minecraft:gravel"},
        {pos: [11, 4, 8], state: "minecraft:gravel"},
        {pos: [11, 4, 9], state: "minecraft:deepslate_bricks"},
        {pos: [11, 4, 10], state: "minecraft:deepslate_bricks"},
        {pos: [11, 4, 11], state: "minecraft:deepslate_bricks"},
        {pos: [11, 4, 12], state: "minecraft:deepslate_bricks"},
        {pos: [11, 4, 13], state: "minecraft:deepslate_bricks"},
        {pos: [12, 4, 5], state: "minecraft:deepslate_bricks"},
        {pos: [12, 4, 6], state: "minecraft:gravel"},
        {pos: [12, 4, 7], state: "minecraft:gravel"},
        {pos: [12, 4, 8], state: "minecraft:gravel"},
        {pos: [12, 4, 9], state: "minecraft:deepslate_bricks"},
        {pos: [13, 4, 5], state: "minecraft:deepslate_bricks"},
        {pos: [13, 4, 6], state: "minecraft:gravel"},
        {pos: [13, 4, 7], state: "minecraft:gravel"},
        {pos: [13, 4, 8], state: "minecraft:gravel"},
        {pos: [13, 4, 9], state: "minecraft:deepslate_bricks"},
        {pos: [14, 4, 5], state: "minecraft:deepslate_bricks"},
        {pos: [14, 4, 6], state: "minecraft:deepslate_bricks"},
        {pos: [14, 4, 7], state: "minecraft:deepslate_bricks"},
        {pos: [14, 4, 8], state: "minecraft:deepslate_bricks"},
        {pos: [14, 4, 9], state: "minecraft:deepslate_bricks"},
        {pos: [0, 5, 2], state: "minecraft:deepslate_bricks"},
        {pos: [0, 5, 3], state: "minecraft:deepslate_bricks"},
        {pos: [0, 5, 4], state: "minecraft:deepslate_bricks"},
        {pos: [0, 5, 5], state: "minecraft:deepslate_bricks"},
        {pos: [0, 5, 6], state: "minecraft:candle{candles:4,lit:false,waterlogged:false}"},
        {pos: [0, 5, 7], state: "minecraft:jigsaw{orientation:west_up}", nbt: {final_state: "minecraft:cave_air", id: "minecraft:jigsaw", joint: "rollable", name: "trailiertales:corridor", placement_priority: 0, pool: "trailiertales:catacombs/corridor_connector", selection_priority: 0, target: "trailiertales:corridor"}},
        {pos: [0, 5, 8], state: "minecraft:candle{candles:4,lit:false,waterlogged:false}"},
        {pos: [0, 5, 9], state: "minecraft:deepslate_bricks"},
        {pos: [0, 5, 10], state: "minecraft:deepslate_bricks"},
        {pos: [0, 5, 11], state: "minecraft:deepslate_bricks"},
        {pos: [1, 5, 2], state: "minecraft:deepslate_bricks"},
        {pos: [1, 5, 3], state: "minecraft:deepslate_bricks"},
        {pos: [1, 5, 4], state: "minecraft:deepslate_brick_stairs{facing:south,half:bottom,shape:outer_left,waterlogged:false}"},
        {pos: [1, 5, 5], state: "minecraft:deepslate_brick_stairs{facing:east,half:bottom,shape:straight,waterlogged:false}"},
        {pos: [1, 5, 6], state: "minecraft:deepslate_brick_stairs{facing:east,half:bottom,shape:outer_left,waterlogged:false}"},
        {pos: [1, 5, 7], state: "minecraft:cave_air"},
        {pos: [1, 5, 8], state: "minecraft:deepslate_brick_stairs{facing:east,half:bottom,shape:outer_right,waterlogged:false}"},
        {pos: [1, 5, 9], state: "minecraft:deepslate_brick_stairs{facing:east,half:bottom,shape:straight,waterlogged:false}"},
        {pos: [1, 5, 10], state: "minecraft:deepslate_brick_stairs{facing:north,half:bottom,shape:outer_right,waterlogged:false}"},
        {pos: [1, 5, 11], state: "minecraft:deepslate_bricks"},
        {pos: [1, 5, 12], state: "minecraft:deepslate_bricks"},
        {pos: [1, 5, 13], state: "minecraft:deepslate_bricks"},
        {pos: [2, 5, 1], state: "minecraft:deepslate_bricks"},
        {pos: [2, 5, 2], state: "minecraft:deepslate_bricks"},
        {pos: [2, 5, 3], state: "minecraft:deepslate_bricks"},
        {pos: [2, 5, 4], state: "minecraft:deepslate_brick_stairs{facing:south,half:bottom,shape:straight,waterlogged:false}"},
        {pos: [2, 5, 5], state: "minecraft:observer{facing:up,powered:false}"},
        {pos: [2, 5, 6], state: "minecraft:deepslate_brick_stairs{facing:north,half:bottom,shape:straight,waterlogged:false}"},
        {pos: [2, 5, 7], state: "minecraft:cave_air"},
        {pos: [2, 5, 8], state: "minecraft:deepslate_brick_stairs{facing:south,half:bottom,shape:straight,waterlogged:false}"},
        {pos: [2, 5, 9], state: "minecraft:observer{facing:up,powered:false}"},
        {pos: [2, 5, 10], state: "minecraft:deepslate_brick_stairs{facing:north,half:bottom,shape:straight,waterlogged:false}"},
        {pos: [2, 5, 11], state: "minecraft:deepslate_bricks"},
        {pos: [2, 5, 12], state: "minecraft:deepslate_bricks"},
        {pos: [2, 5, 13], state: "minecraft:deepslate_bricks"},
        {pos: [3, 5, 1], state: "minecraft:deepslate_bricks"},
        {pos: [3, 5, 2], state: "minecraft:deepslate_bricks"},
        {pos: [3, 5, 3], state: "minecraft:deepslate_bricks"},
        {pos: [3, 5, 4], state: "minecraft:deepslate_brick_stairs{facing:south,half:bottom,shape:outer_right,waterlogged:false}"},
        {pos: [3, 5, 5], state: "minecraft:deepslate_brick_stairs{facing:west,half:bottom,shape:straight,waterlogged:false}"},
        {pos: [3, 5, 6], state: "minecraft:deepslate_brick_stairs{facing:north,half:bottom,shape:outer_left,waterlogged:false}"},
        {pos: [3, 5, 7], state: "minecraft:cave_air"},
        {pos: [3, 5, 8], state: "minecraft:deepslate_brick_stairs{facing:south,half:bottom,shape:outer_right,waterlogged:false}"},
        {pos: [3, 5, 9], state: "minecraft:deepslate_brick_stairs{facing:west,half:bottom,shape:straight,waterlogged:false}"},
        {pos: [3, 5, 10], state: "minecraft:deepslate_brick_stairs{facing:north,half:bottom,shape:outer_left,waterlogged:false}"},
        {pos: [3, 5, 11], state: "minecraft:deepslate_bricks"},
        {pos: [3, 5, 12], state: "minecraft:deepslate_bricks"},
        {pos: [3, 5, 13], state: "minecraft:deepslate_bricks"},
        {pos: [4, 5, 1], state: "minecraft:deepslate_bricks"},
        {pos: [4, 5, 2], state: "minecraft:deepslate_bricks"},
        {pos: [4, 5, 3], state: "minecraft:deepslate_bricks"},
        {pos: [4, 5, 4], state: "minecraft:candle{candles:4,lit:false,waterlogged:false}"},
        {pos: [4, 5, 5], state: "minecraft:skeleton_skull{powered:false,rotation:8}", nbt: {id: "minecraft:skull"}},
        {pos: [4, 5, 6], state: "minecraft:candle{candles:4,lit:false,waterlogged:false}"},
        {pos: [4, 5, 7], state: "minecraft:cave_air"},
        {pos: [4, 5, 8], state: "minecraft:candle{candles:4,lit:false,waterlogged:false}"},
        {pos: [4, 5, 9], state: "minecraft:skeleton_skull{powered:false,rotation:0}", nbt: {id: "minecraft:skull"}},
        {pos: [4, 5, 10], state: "minecraft:candle{candles:4,lit:false,waterlogged:false}"},
        {pos: [4, 5, 11], state: "minecraft:deepslate_bricks"},
        {pos: [4, 5, 12], state: "minecraft:deepslate_bricks"},
        {pos: [4, 5, 13], state: "minecraft:deepslate_bricks"},
        {pos: [5, 5, 0], state: "minecraft:deepslate_bricks"},
        {pos: [5, 5, 1], state: "minecraft:deepslate_bricks"},
        {pos: [5, 5, 2], state: "minecraft:deepslate_bricks"},
        {pos: [5, 5, 3], state: "minecraft:deepslate_bricks"},
        {pos: [5, 5, 4], state: "minecraft:deepslate_brick_stairs{facing:south,half:bottom,shape:outer_left,waterlogged:false}"},
        {pos: [5, 5, 5], state: "minecraft:deepslate_brick_stairs{facing:east,half:bottom,shape:straight,waterlogged:false}"},
        {pos: [5, 5, 6], state: "minecraft:deepslate_brick_stairs{facing:east,half:bottom,shape:outer_left,waterlogged:false}"},
        {pos: [5, 5, 7], state: "minecraft:cave_air"},
        {pos: [5, 5, 8], state: "minecraft:deepslate_brick_stairs{facing:south,half:bottom,shape:outer_left,waterlogged:false}"},
        {pos: [5, 5, 9], state: "minecraft:deepslate_brick_stairs{facing:east,half:bottom,shape:straight,waterlogged:false}"},
        {pos: [5, 5, 10], state: "minecraft:deepslate_brick_stairs{facing:north,half:bottom,shape:outer_right,waterlogged:false}"},
        {pos: [5, 5, 11], state: "minecraft:deepslate_bricks"},
        {pos: [5, 5, 12], state: "minecraft:deepslate_bricks"},
        {pos: [5, 5, 13], state: "minecraft:deepslate_bricks"},
        {pos: [6, 5, 0], state: "minecraft:deepslate_bricks"},
        {pos: [6, 5, 1], state: "minecraft:deepslate_bricks"},
        {pos: [6, 5, 2], state: "minecraft:deepslate_bricks"},
        {pos: [6, 5, 3], state: "minecraft:deepslate_bricks"},
        {pos: [6, 5, 4], state: "minecraft:deepslate_brick_stairs{facing:south,half:bottom,shape:straight,waterlogged:false}"},
        {pos: [6, 5, 5], state: "minecraft:observer{facing:up,powered:false}"},
        {pos: [6, 5, 6], state: "minecraft:deepslate_brick_stairs{facing:north,half:bottom,shape:straight,waterlogged:false}"},
        {pos: [6, 5, 7], state: "minecraft:skeleton_skull{powered:false,rotation:12}", nbt: {id: "minecraft:skull"}},
        {pos: [6, 5, 8], state: "minecraft:deepslate_brick_stairs{facing:south,half:bottom,shape:straight,waterlogged:false}"},
        {pos: [6, 5, 9], state: "minecraft:observer{facing:up,powered:false}"},
        {pos: [6, 5, 10], state: "minecraft:deepslate_brick_stairs{facing:north,half:bottom,shape:straight,waterlogged:false}"},
        {pos: [6, 5, 11], state: "minecraft:deepslate_bricks"},
        {pos: [6, 5, 12], state: "minecraft:deepslate_bricks"},
        {pos: [6, 5, 13], state: "minecraft:deepslate_bricks"},
        {pos: [7, 5, 0], state: "minecraft:deepslate_bricks"},
        {pos: [7, 5, 1], state: "minecraft:deepslate_bricks"},
        {pos: [7, 5, 2], state: "minecraft:deepslate_bricks"},
        {pos: [7, 5, 3], state: "minecraft:deepslate_bricks"},
        {pos: [7, 5, 4], state: "minecraft:deepslate_brick_stairs{facing:south,half:bottom,shape:outer_right,waterlogged:false}"},
        {pos: [7, 5, 5], state: "minecraft:deepslate_brick_stairs{facing:west,half:bottom,shape:straight,waterlogged:false}"},
        {pos: [7, 5, 6], state: "minecraft:deepslate_brick_stairs{facing:west,half:bottom,shape:outer_right,waterlogged:false}"},
        {pos: [7, 5, 7], state: "minecraft:cave_air"},
        {pos: [7, 5, 8], state: "minecraft:deepslate_brick_stairs{facing:west,half:bottom,shape:outer_left,waterlogged:false}"},
        {pos: [7, 5, 9], state: "minecraft:deepslate_brick_stairs{facing:west,half:bottom,shape:straight,waterlogged:false}"},
        {pos: [7, 5, 10], state: "minecraft:deepslate_brick_stairs{facing:north,half:bottom,shape:outer_left,waterlogged:false}"},
        {pos: [7, 5, 11], state: "minecraft:deepslate_bricks"},
        {pos: [7, 5, 12], state: "minecraft:deepslate_bricks"},
        {pos: [7, 5, 13], state: "minecraft:deepslate_bricks"},
        {pos: [8, 5, 0], state: "minecraft:deepslate_bricks"},
        {pos: [8, 5, 1], state: "minecraft:cave_air"},
        {pos: [8, 5, 2], state: "minecraft:deepslate_bricks"},
        {pos: [8, 5, 3], state: "minecraft:deepslate_bricks"},
        {pos: [8, 5, 4], state: "minecraft:deepslate_bricks"},
        {pos: [8, 5, 5], state: "minecraft:deepslate_bricks"},
        {pos: [8, 5, 6], state: "minecraft:deepslate_bricks"},
        {pos: [8, 5, 7], state: "minecraft:cave_air"},
        {pos: [8, 5, 8], state: "minecraft:deepslate_bricks"},
        {pos: [8, 5, 9], state: "minecraft:deepslate_bricks"},
        {pos: [8, 5, 10], state: "minecraft:deepslate_bricks"},
        {pos: [8, 5, 11], state: "minecraft:deepslate_bricks"},
        {pos: [8, 5, 12], state: "minecraft:redstone_wire{east:side,north:none,power:0,south:none,west:up}"},
        {pos: [8, 5, 13], state: "minecraft:deepslate_bricks"},
        {pos: [9, 5, 0], state: "minecraft:deepslate_bricks"},
        {pos: [9, 5, 1], state: "minecraft:redstone_wire{east:none,north:none,power:11,south:up,west:side}"},
        {pos: [9, 5, 2], state: "minecraft:deepslate_bricks"},
        {pos: [9, 5, 3], state: "minecraft:deepslate_bricks"},
        {pos: [9, 5, 4], state: "minecraft:deepslate_bricks"},
        {pos: [9, 5, 5], state: "minecraft:sticky_piston{extended:true,facing:south}"},
        {pos: [9, 5, 6], state: "minecraft:piston_head{facing:south,short:false,type:sticky}"},
        {pos: [9, 5, 7], state: "minecraft:deepslate_tiles"},
        {pos: [9, 5, 8], state: "minecraft:deepslate_bricks"},
        {pos: [9, 5, 9], state: "minecraft:deepslate_bricks"},
        {pos: [9, 5, 10], state: "minecraft:deepslate_bricks"},
        {pos: [9, 5, 11], state: "minecraft:deepslate_bricks"},
        {pos: [9, 5, 12], state: "minecraft:cave_air"},
        {pos: [9, 5, 13], state: "minecraft:deepslate_bricks"},
        {pos: [10, 5, 0], state: "minecraft:deepslate_bricks"},
        {pos: [10, 5, 1], state: "minecraft:deepslate_bricks"},
        {pos: [10, 5, 2], state: "minecraft:deepslate_bricks"},
        {pos: [10, 5, 3], state: "minecraft:deepslate_bricks"},
        {pos: [10, 5, 4], state: "minecraft:deepslate_bricks"},
        {pos: [10, 5, 5], state: "minecraft:deepslate_bricks"},
        {pos: [10, 5, 6], state: "minecraft:deepslate_bricks"},
        {pos: [10, 5, 7], state: "minecraft:cave_air"},
        {pos: [10, 5, 8], state: "minecraft:deepslate_bricks"},
        {pos: [10, 5, 9], state: "minecraft:deepslate_bricks"},
        {pos: [10, 5, 10], state: "minecraft:deepslate_bricks"},
        {pos: [10, 5, 11], state: "minecraft:deepslate_bricks"},
        {pos: [10, 5, 12], state: "minecraft:deepslate_bricks"},
        {pos: [10, 5, 13], state: "minecraft:deepslate_bricks"},
        {pos: [11, 5, 5], state: "minecraft:deepslate_bricks"},
        {pos: [11, 5, 6], state: "minecraft:decorated_pot{cracked:false,facing:north,waterlogged:false}", nbt: {id: "minecraft:decorated_pot"}},
        {pos: [11, 5, 7], state: "minecraft:cave_air"},
        {pos: [11, 5, 8], state: "minecraft:skeleton_skull{powered:false,rotation:0}", nbt: {id: "minecraft:skull"}},
        {pos: [11, 5, 9], state: "minecraft:deepslate_bricks"},
        {pos: [12, 5, 5], state: "minecraft:deepslate_bricks"},
        {pos: [12, 5, 6], state: "minecraft:skeleton_skull{powered:false,rotation:8}", nbt: {id: "minecraft:skull"}},
        {pos: [12, 5, 7], state: "minecraft:cave_air"},
        {pos: [12, 5, 8], state: "minecraft:candle{candles:4,lit:false,waterlogged:false}"},
        {pos: [12, 5, 9], state: "minecraft:deepslate_bricks"},
        {pos: [13, 5, 5], state: "minecraft:deepslate_bricks"},
        {pos: [13, 5, 6], state: "minecraft:deepslate_brick_stairs{facing:east,half:top,shape:straight,waterlogged:false}"},
        {pos: [13, 5, 7], state: "minecraft:deepslate_brick_stairs{facing:east,half:top,shape:straight,waterlogged:false}"},
        {pos: [13, 5, 8], state: "minecraft:deepslate_brick_stairs{facing:east,half:top,shape:straight,waterlogged:false}"},
        {pos: [13, 5, 9], state: "minecraft:deepslate_bricks"},
        {pos: [14, 5, 5], state: "minecraft:deepslate_bricks"},
        {pos: [14, 5, 6], state: "minecraft:deepslate_bricks"},
        {pos: [14, 5, 7], state: "minecraft:deepslate_bricks"},
        {pos: [14, 5, 8], state: "minecraft:deepslate_bricks"},
        {pos: [14, 5, 9], state: "minecraft:deepslate_bricks"},
        {pos: [0, 6, 2], state: "minecraft:deepslate_bricks"},
        {pos: [0, 6, 3], state: "minecraft:deepslate_bricks"},
        {pos: [0, 6, 4], state: "minecraft:deepslate_bricks"},
        {pos: [0, 6, 5], state: "minecraft:deepslate_bricks"},
        {pos: [0, 6, 6], state: "minecraft:cave_air"},
        {pos: [0, 6, 7], state: "minecraft:cave_air"},
        {pos: [0, 6, 8], state: "minecraft:cave_air"},
        {pos: [0, 6, 9], state: "minecraft:deepslate_bricks"},
        {pos: [0, 6, 10], state: "minecraft:deepslate_bricks"},
        {pos: [0, 6, 11], state: "minecraft:deepslate_bricks"},
        {pos: [1, 6, 2], state: "minecraft:deepslate_bricks"},
        {pos: [1, 6, 3], state: "minecraft:deepslate_bricks"},
        {pos: [1, 6, 4], state: "minecraft:cave_air"},
        {pos: [1, 6, 5], state: "minecraft:cave_air"},
        {pos: [1, 6, 6], state: "minecraft:cave_air"},
        {pos: [1, 6, 7], state: "minecraft:cave_air"},
        {pos: [1, 6, 8], state: "minecraft:cave_air"},
        {pos: [1, 6, 9], state: "minecraft:cave_air"},
        {pos: [1, 6, 10], state: "minecraft:cobweb"},
        {pos: [1, 6, 11], state: "minecraft:deepslate_bricks"},
        {pos: [1, 6, 12], state: "minecraft:deepslate_bricks"},
        {pos: [1, 6, 13], state: "minecraft:deepslate_bricks"},
        {pos: [2, 6, 1], state: "minecraft:deepslate_bricks"},
        {pos: [2, 6, 2], state: "minecraft:dispenser{facing:south,triggered:false}", nbt: {Items: [{Slot: 0b, components: {"minecraft:potion_contents": {potion: "minecraft:long_poison"}}, count: 1, id: "minecraft:tipped_arrow"}, {Slot: 3b, components: {"minecraft:potion_contents": {potion: "minecraft:long_poison"}}, count: 2, id: "minecraft:tipped_arrow"}, {Slot: 4b, components: {"minecraft:potion_contents": {potion: "minecraft:long_poison"}}, count: 8, id: "minecraft:tipped_arrow"}, {Slot: 5b, components: {"minecraft:potion_contents": {potion: "minecraft:long_poison"}}, count: 3, id: "minecraft:tipped_arrow"}, {Slot: 7b, components: {"minecraft:potion_contents": {potion: "minecraft:long_poison"}}, count: 4, id: "minecraft:tipped_arrow"}], id: "minecraft:dispenser"}},
        {pos: [2, 6, 3], state: "minecraft:cave_air"},
        {pos: [2, 6, 4], state: "minecraft:cave_air"},
        {pos: [2, 6, 5], state: "minecraft:barrel{facing:up,open:false}", nbt: {Items: [], id: "minecraft:barrel"}},
        {pos: [2, 6, 6], state: "minecraft:cave_air"},
        {pos: [2, 6, 7], state: "minecraft:cave_air"},
        {pos: [2, 6, 8], state: "minecraft:cave_air"},
        {pos: [2, 6, 9], state: "minecraft:barrel{facing:up,open:false}", nbt: {Items: [], id: "minecraft:barrel"}},
        {pos: [2, 6, 10], state: "minecraft:cave_air"},
        {pos: [2, 6, 11], state: "minecraft:cave_air"},
        {pos: [2, 6, 12], state: "minecraft:dispenser{facing:north,triggered:false}", nbt: {Items: [{Slot: 4b, components: {"minecraft:potion_contents": {potion: "minecraft:long_poison"}}, count: 7, id: "minecraft:tipped_arrow"}, {Slot: 5b, components: {"minecraft:potion_contents": {potion: "minecraft:long_poison"}}, count: 4, id: "minecraft:tipped_arrow"}, {Slot: 7b, components: {"minecraft:potion_contents": {potion: "minecraft:long_poison"}}, count: 4, id: "minecraft:tipped_arrow"}, {Slot: 8b, components: {"minecraft:potion_contents": {potion: "minecraft:long_poison"}}, count: 1, id: "minecraft:tipped_arrow"}], id: "minecraft:dispenser"}},
        {pos: [2, 6, 13], state: "minecraft:deepslate_bricks"},
        {pos: [3, 6, 1], state: "minecraft:deepslate_bricks"},
        {pos: [3, 6, 2], state: "minecraft:deepslate_bricks"},
        {pos: [3, 6, 3], state: "minecraft:deepslate_bricks"},
        {pos: [3, 6, 4], state: "minecraft:cave_air"},
        {pos: [3, 6, 5], state: "minecraft:cave_air"},
        {pos: [3, 6, 6], state: "minecraft:cave_air"},
        {pos: [3, 6, 7], state: "minecraft:cave_air"},
        {pos: [3, 6, 8], state: "minecraft:cave_air"},
        {pos: [3, 6, 9], state: "minecraft:cave_air"},
        {pos: [3, 6, 10], state: "minecraft:cave_air"},
        {pos: [3, 6, 11], state: "minecraft:deepslate_bricks"},
        {pos: [3, 6, 12], state: "minecraft:deepslate_bricks"},
        {pos: [3, 6, 13], state: "minecraft:deepslate_bricks"},
        {pos: [4, 6, 1], state: "minecraft:deepslate_bricks"},
        {pos: [4, 6, 2], state: "minecraft:dispenser{facing:south,triggered:false}", nbt: {Items: [{Slot: 0b, components: {"minecraft:potion_contents": {potion: "minecraft:long_poison"}}, count: 3, id: "minecraft:tipped_arrow"}, {Slot: 4b, components: {"minecraft:potion_contents": {potion: "minecraft:long_poison"}}, count: 8, id: "minecraft:tipped_arrow"}, {Slot: 5b, components: {"minecraft:potion_contents": {potion: "minecraft:long_poison"}}, count: 3, id: "minecraft:tipped_arrow"}, {Slot: 7b, components: {"minecraft:potion_contents": {potion: "minecraft:long_poison"}}, count: 5, id: "minecraft:tipped_arrow"}], id: "minecraft:dispenser"}},
        {pos: [4, 6, 3], state: "minecraft:cave_air"},
        {pos: [4, 6, 4], state: "minecraft:cave_air"},
        {pos: [4, 6, 5], state: "minecraft:cave_air"},
        {pos: [4, 6, 6], state: "minecraft:cave_air"},
        {pos: [4, 6, 7], state: "minecraft:cave_air"},
        {pos: [4, 6, 8], state: "minecraft:cave_air"},
        {pos: [4, 6, 9], state: "minecraft:cave_air"},
        {pos: [4, 6, 10], state: "minecraft:cave_air"},
        {pos: [4, 6, 11], state: "minecraft:cave_air"},
        {pos: [4, 6, 12], state: "minecraft:dispenser{facing:north,triggered:false}", nbt: {Items: [{Slot: 0b, components: {"minecraft:potion_contents": {potion: "minecraft:long_poison"}}, count: 2, id: "minecraft:tipped_arrow"}, {Slot: 3b, components: {"minecraft:potion_contents": {potion: "minecraft:long_poison"}}, count: 1, id: "minecraft:tipped_arrow"}, {Slot: 4b, components: {"minecraft:potion_contents": {potion: "minecraft:long_poison"}}, count: 9, id: "minecraft:tipped_arrow"}, {Slot: 5b, components: {"minecraft:potion_contents": {potion: "minecraft:long_poison"}}, count: 3, id: "minecraft:tipped_arrow"}, {Slot: 7b, components: {"minecraft:potion_contents": {potion: "minecraft:long_poison"}}, count: 2, id: "minecraft:tipped_arrow"}], id: "minecraft:dispenser"}},
        {pos: [4, 6, 13], state: "minecraft:deepslate_bricks"},
        {pos: [5, 6, 0], state: "minecraft:deepslate_bricks"},
        {pos: [5, 6, 1], state: "minecraft:deepslate_bricks"},
        {pos: [5, 6, 2], state: "minecraft:deepslate_bricks"},
        {pos: [5, 6, 3], state: "minecraft:deepslate_bricks"},
        {pos: [5, 6, 4], state: "minecraft:cave_air"},
        {pos: [5, 6, 5], state: "minecraft:cave_air"},
        {pos: [5, 6, 6], state: "minecraft:cave_air"},
        {pos: [5, 6, 7], state: "minecraft:cave_air"},
        {pos: [5, 6, 8], state: "minecraft:cave_air"},
        {pos: [5, 6, 9], state: "minecraft:cave_air"},
        {pos: [5, 6, 10], state: "minecraft:cave_air"},
        {pos: [5, 6, 11], state: "minecraft:deepslate_bricks"},
        {pos: [5, 6, 12], state: "minecraft:deepslate_bricks"},
        {pos: [5, 6, 13], state: "minecraft:deepslate_bricks"},
        {pos: [6, 6, 0], state: "minecraft:deepslate_bricks"},
        {pos: [6, 6, 1], state: "minecraft:deepslate_bricks"},
        {pos: [6, 6, 2], state: "minecraft:dispenser{facing:south,triggered:false}", nbt: {Items: [{Slot: 0b, components: {"minecraft:potion_contents": {potion: "minecraft:long_poison"}}, count: 1, id: "minecraft:tipped_arrow"}, {Slot: 3b, components: {"minecraft:potion_contents": {potion: "minecraft:long_poison"}}, count: 2, id: "minecraft:tipped_arrow"}, {Slot: 4b, components: {"minecraft:potion_contents": {potion: "minecraft:long_poison"}}, count: 7, id: "minecraft:tipped_arrow"}, {Slot: 5b, components: {"minecraft:potion_contents": {potion: "minecraft:long_poison"}}, count: 4, id: "minecraft:tipped_arrow"}, {Slot: 7b, components: {"minecraft:potion_contents": {potion: "minecraft:long_poison"}}, count: 4, id: "minecraft:tipped_arrow"}], id: "minecraft:dispenser"}},
        {pos: [6, 6, 3], state: "minecraft:cave_air"},
        {pos: [6, 6, 4], state: "minecraft:cave_air"},
        {pos: [6, 6, 5], state: "minecraft:barrel{facing:up,open:false}", nbt: {Items: [], id: "minecraft:barrel"}},
        {pos: [6, 6, 6], state: "minecraft:cave_air"},
        {pos: [6, 6, 7], state: "minecraft:cave_air"},
        {pos: [6, 6, 8], state: "minecraft:cave_air"},
        {pos: [6, 6, 9], state: "minecraft:barrel{facing:up,open:false}", nbt: {Items: [], id: "minecraft:barrel"}},
        {pos: [6, 6, 10], state: "minecraft:cave_air"},
        {pos: [6, 6, 11], state: "minecraft:cave_air"},
        {pos: [6, 6, 12], state: "minecraft:dispenser{facing:north,triggered:false}", nbt: {Items: [{Slot: 3b, components: {"minecraft:potion_contents": {potion: "minecraft:long_poison"}}, count: 2, id: "minecraft:tipped_arrow"}, {Slot: 4b, components: {"minecraft:potion_contents": {potion: "minecraft:long_poison"}}, count: 7, id: "minecraft:tipped_arrow"}, {Slot: 5b, components: {"minecraft:potion_contents": {potion: "minecraft:long_poison"}}, count: 5, id: "minecraft:tipped_arrow"}, {Slot: 7b, components: {"minecraft:potion_contents": {potion: "minecraft:long_poison"}}, count: 4, id: "minecraft:tipped_arrow"}], id: "minecraft:dispenser"}},
        {pos: [6, 6, 13], state: "minecraft:deepslate_bricks"},
        {pos: [7, 6, 0], state: "minecraft:deepslate_bricks"},
        {pos: [7, 6, 1], state: "minecraft:deepslate_bricks"},
        {pos: [7, 6, 2], state: "minecraft:deepslate_bricks"},
        {pos: [7, 6, 3], state: "minecraft:deepslate_bricks"},
        {pos: [7, 6, 4], state: "minecraft:cobweb"},
        {pos: [7, 6, 5], state: "minecraft:cave_air"},
        {pos: [7, 6, 6], state: "minecraft:cave_air"},
        {pos: [7, 6, 7], state: "minecraft:cave_air"},
        {pos: [7, 6, 8], state: "minecraft:cave_air"},
        {pos: [7, 6, 9], state: "minecraft:cave_air"},
        {pos: [7, 6, 10], state: "minecraft:cave_air"},
        {pos: [7, 6, 11], state: "minecraft:deepslate_bricks"},
        {pos: [7, 6, 12], state: "minecraft:redstone_wire{east:side,north:none,power:0,south:none,west:up}"},
        {pos: [7, 6, 13], state: "minecraft:deepslate_bricks"},
        {pos: [8, 6, 0], state: "minecraft:deepslate_bricks"},
        {pos: [8, 6, 1], state: "minecraft:deepslate_bricks"},
        {pos: [8, 6, 2], state: "minecraft:deepslate_bricks"},
        {pos: [8, 6, 3], state: "minecraft:deepslate_bricks"},
        {pos: [8, 6, 4], state: "minecraft:deepslate_bricks"},
        {pos: [8, 6, 5], state: "minecraft:deepslate_bricks"},
        {pos: [8, 6, 6], state: "minecraft:deepslate_bricks"},
        {pos: [8, 6, 7], state: "minecraft:cave_air"},
        {pos: [8, 6, 8], state: "minecraft:deepslate_bricks"},
        {pos: [8, 6, 9], state: "minecraft:deepslate_bricks"},
        {pos: [8, 6, 10], state: "minecraft:deepslate_bricks"},
        {pos: [8, 6, 11], state: "minecraft:deepslate_bricks"},
        {pos: [8, 6, 12], state: "minecraft:cave_air"},
        {pos: [8, 6, 13], state: "minecraft:deepslate_bricks"},
        {pos: [9, 6, 0], state: "minecraft:deepslate_bricks"},
        {pos: [9, 6, 1], state: "minecraft:cave_air"},
        {pos: [9, 6, 2], state: "minecraft:redstone_wire{east:none,north:side,power:10,south:side,west:none}"},
        {pos: [9, 6, 3], state: "minecraft:redstone_wire{east:none,north:side,power:9,south:side,west:none}"},
        {pos: [9, 6, 4], state: "minecraft:repeater{delay:1,facing:north,locked:false,powered:true}"},
        {pos: [9, 6, 5], state: "minecraft:sticky_piston{extended:true,facing:south}"},
        {pos: [9, 6, 6], state: "minecraft:piston_head{facing:south,short:false,type:sticky}"},
        {pos: [9, 6, 7], state: "minecraft:deepslate_tiles"},
        {pos: [9, 6, 8], state: "minecraft:deepslate_bricks"},
        {pos: [9, 6, 9], state: "minecraft:deepslate_bricks"},
        {pos: [9, 6, 10], state: "minecraft:deepslate_bricks"},
        {pos: [9, 6, 11], state: "minecraft:deepslate_bricks"},
        {pos: [9, 6, 12], state: "minecraft:deepslate_bricks"},
        {pos: [9, 6, 13], state: "minecraft:deepslate_bricks"},
        {pos: [10, 6, 0], state: "minecraft:deepslate_bricks"},
        {pos: [10, 6, 1], state: "minecraft:deepslate_bricks"},
        {pos: [10, 6, 2], state: "minecraft:deepslate_bricks"},
        {pos: [10, 6, 3], state: "minecraft:deepslate_bricks"},
        {pos: [10, 6, 4], state: "minecraft:deepslate_bricks"},
        {pos: [10, 6, 5], state: "minecraft:deepslate_bricks"},
        {pos: [10, 6, 6], state: "minecraft:deepslate_bricks"},
        {pos: [10, 6, 7], state: "minecraft:cave_air"},
        {pos: [10, 6, 8], state: "minecraft:deepslate_bricks"},
        {pos: [10, 6, 9], state: "minecraft:deepslate_bricks"},
        {pos: [10, 6, 10], state: "minecraft:deepslate_bricks"},
        {pos: [10, 6, 11], state: "minecraft:deepslate_bricks"},
        {pos: [10, 6, 12], state: "minecraft:deepslate_bricks"},
        {pos: [10, 6, 13], state: "minecraft:deepslate_bricks"},
        {pos: [11, 6, 5], state: "minecraft:deepslate_bricks"},
        {pos: [11, 6, 6], state: "minecraft:cave_air"},
        {pos: [11, 6, 7], state: "minecraft:cave_air"},
        {pos: [11, 6, 8], state: "minecraft:cave_air"},
        {pos: [11, 6, 9], state: "minecraft:deepslate_bricks"},
        {pos: [12, 6, 5], state: "minecraft:deepslate_bricks"},
        {pos: [12, 6, 6], state: "minecraft:cave_air"},
        {pos: [12, 6, 7], state: "minecraft:cave_air"},
        {pos: [12, 6, 8], state: "minecraft:cave_air"},
        {pos: [12, 6, 9], state: "minecraft:deepslate_bricks"},
        {pos: [13, 6, 5], state: "minecraft:deepslate_bricks"},
        {pos: [13, 6, 6], state: "minecraft:skeleton_skull{powered:false,rotation:12}", nbt: {id: "minecraft:skull"}},
        {pos: [13, 6, 7], state: "minecraft:chest{facing:west,type:single,waterlogged:false}", nbt: {id: "minecraft:chest"}},
        {pos: [13, 6, 8], state: "minecraft:skeleton_skull{powered:false,rotation:12}", nbt: {id: "minecraft:skull"}},
        {pos: [13, 6, 9], state: "minecraft:deepslate_bricks"},
        {pos: [14, 6, 5], state: "minecraft:deepslate_bricks"},
        {pos: [14, 6, 6], state: "minecraft:deepslate_bricks"},
        {pos: [14, 6, 7], state: "minecraft:deepslate_bricks"},
        {pos: [14, 6, 8], state: "minecraft:deepslate_bricks"},
        {pos: [14, 6, 9], state: "minecraft:deepslate_bricks"},
        {pos: [0, 7, 2], state: "minecraft:deepslate_bricks"},
        {pos: [0, 7, 3], state: "minecraft:deepslate_bricks"},
        {pos: [0, 7, 4], state: "minecraft:deepslate_bricks"},
        {pos: [0, 7, 5], state: "minecraft:deepslate_bricks"},
        {pos: [0, 7, 6], state: "minecraft:cave_air"},
        {pos: [0, 7, 7], state: "minecraft:cave_air"},
        {pos: [0, 7, 8], state: "minecraft:cave_air"},
        {pos: [0, 7, 9], state: "minecraft:deepslate_bricks"},
        {pos: [0, 7, 10], state: "minecraft:deepslate_bricks"},
        {pos: [0, 7, 11], state: "minecraft:deepslate_bricks"},
        {pos: [1, 7, 2], state: "minecraft:deepslate_bricks"},
        {pos: [1, 7, 3], state: "minecraft:deepslate_bricks"},
        {pos: [1, 7, 4], state: "minecraft:cave_air"},
        {pos: [1, 7, 5], state: "minecraft:cave_air"},
        {pos: [1, 7, 6], state: "minecraft:cave_air"},
        {pos: [1, 7, 7], state: "minecraft:cave_air"},
        {pos: [1, 7, 8], state: "minecraft:cave_air"},
        {pos: [1, 7, 9], state: "minecraft:cobweb"},
        {pos: [1, 7, 10], state: "minecraft:cobweb"},
        {pos: [1, 7, 11], state: "minecraft:deepslate_bricks"},
        {pos: [1, 7, 12], state: "minecraft:deepslate_bricks"},
        {pos: [1, 7, 13], state: "minecraft:deepslate_bricks"},
        {pos: [2, 7, 1], state: "minecraft:deepslate_bricks"},
        {pos: [2, 7, 2], state: "minecraft:redstone_wire{east:none,north:side,power:0,south:up,west:none}"},
        {pos: [2, 7, 3], state: "minecraft:deepslate_bricks"},
        {pos: [2, 7, 4], state: "minecraft:cobweb"},
        {pos: [2, 7, 5], state: "minecraft:cave_air"},
        {pos: [2, 7, 6], state: "minecraft:cave_air"},
        {pos: [2, 7, 7], state: "minecraft:cave_air"},
        {pos: [2, 7, 8], state: "minecraft:cave_air"},
        {pos: [2, 7, 9], state: "minecraft:cave_air"},
        {pos: [2, 7, 10], state: "minecraft:cave_air"},
        {pos: [2, 7, 11], state: "minecraft:deepslate_bricks"},
        {pos: [2, 7, 12], state: "minecraft:redstone_wire{east:side,north:up,power:0,south:none,west:none}"},
        {pos: [2, 7, 13], state: "minecraft:deepslate_bricks"},
        {pos: [3, 7, 1], state: "minecraft:deepslate_bricks"},
        {pos: [3, 7, 2], state: "minecraft:deepslate_bricks"},
        {pos: [3, 7, 3], state: "minecraft:deepslate_bricks"},
        {pos: [3, 7, 4], state: "minecraft:cave_air"},
        {pos: [3, 7, 5], state: "minecraft:cave_air"},
        {pos: [3, 7, 6], state: "minecraft:cave_air"},
        {pos: [3, 7, 7], state: "minecraft:cave_air"},
        {pos: [3, 7, 8], state: "minecraft:cave_air"},
        {pos: [3, 7, 9], state: "minecraft:cave_air"},
        {pos: [3, 7, 10], state: "minecraft:cave_air"},
        {pos: [3, 7, 11], state: "minecraft:deepslate_bricks"},
        {pos: [3, 7, 12], state: "minecraft:redstone_wire{east:side,north:none,power:0,south:none,west:side}"},
        {pos: [3, 7, 13], state: "minecraft:deepslate_bricks"},
        {pos: [4, 7, 1], state: "minecraft:deepslate_bricks"},
        {pos: [4, 7, 2], state: "minecraft:redstone_wire{east:none,north:side,power:0,south:up,west:none}"},
        {pos: [4, 7, 3], state: "minecraft:deepslate_bricks"},
        {pos: [4, 7, 4], state: "minecraft:cave_air"},
        {pos: [4, 7, 5], state: "minecraft:cave_air"},
        {pos: [4, 7, 6], state: "minecraft:cave_air"},
        {pos: [4, 7, 7], state: "minecraft:soul_lantern{hanging:true,waterlogged:false}"},
        {pos: [4, 7, 8], state: "minecraft:cave_air"},
        {pos: [4, 7, 9], state: "minecraft:cave_air"},
        {pos: [4, 7, 10], state: "minecraft:cave_air"},
        {pos: [4, 7, 11], state: "minecraft:deepslate_bricks"},
        {pos: [4, 7, 12], state: "minecraft:redstone_wire{east:side,north:up,power:0,south:none,west:side}"},
        {pos: [4, 7, 13], state: "minecraft:deepslate_bricks"},
        {pos: [5, 7, 1], state: "minecraft:deepslate_bricks"},
        {pos: [5, 7, 2], state: "minecraft:deepslate_bricks"},
        {pos: [5, 7, 3], state: "minecraft:deepslate_bricks"},
        {pos: [5, 7, 4], state: "minecraft:cave_air"},
        {pos: [5, 7, 5], state: "minecraft:cave_air"},
        {pos: [5, 7, 6], state: "minecraft:cave_air"},
        {pos: [5, 7, 7], state: "minecraft:cave_air"},
        {pos: [5, 7, 8], state: "minecraft:cave_air"},
        {pos: [5, 7, 9], state: "minecraft:cave_air"},
        {pos: [5, 7, 10], state: "minecraft:cave_air"},
        {pos: [5, 7, 11], state: "minecraft:deepslate_bricks"},
        {pos: [5, 7, 12], state: "minecraft:repeater{delay:1,facing:east,locked:false,powered:false}"},
        {pos: [5, 7, 13], state: "minecraft:deepslate_bricks"},
        {pos: [6, 7, 1], state: "minecraft:deepslate_bricks"},
        {pos: [6, 7, 2], state: "minecraft:redstone_wire{east:none,north:side,power:0,south:up,west:none}"},
        {pos: [6, 7, 3], state: "minecraft:deepslate_bricks"},
        {pos: [6, 7, 4], state: "minecraft:cobweb"},
        {pos: [6, 7, 5], state: "minecraft:cave_air"},
        {pos: [6, 7, 6], state: "minecraft:cave_air"},
        {pos: [6, 7, 7], state: "minecraft:cave_air"},
        {pos: [6, 7, 8], state: "minecraft:cobweb"},
        {pos: [6, 7, 9], state: "minecraft:cave_air"},
        {pos: [6, 7, 10], state: "minecraft:cave_air"},
        {pos: [6, 7, 11], state: "minecraft:deepslate_bricks"},
        {pos: [6, 7, 12], state: "minecraft:redstone_wire{east:side,north:up,power:0,south:none,west:side}"},
        {pos: [6, 7, 13], state: "minecraft:deepslate_bricks"},
        {pos: [7, 7, 1], state: "minecraft:deepslate_bricks"},
        {pos: [7, 7, 2], state: "minecraft:deepslate_bricks"},
        {pos: [7, 7, 3], state: "minecraft:deepslate_bricks"},
        {pos: [7, 7, 4], state: "minecraft:cobweb"},
        {pos: [7, 7, 5], state: "minecraft:cave_air"},
        {pos: [7, 7, 6], state: "minecraft:cave_air"},
        {pos: [7, 7, 7], state: "minecraft:cobweb"},
        {pos: [7, 7, 8], state: "minecraft:cobweb"},
        {pos: [7, 7, 9], state: "minecraft:cobweb"},
        {pos: [7, 7, 10], state: "minecraft:cave_air"},
        {pos: [7, 7, 11], state: "minecraft:deepslate_bricks"},
        {pos: [7, 7, 12], state: "minecraft:cave_air"},
        {pos: [7, 7, 13], state: "minecraft:deepslate_bricks"},
        {pos: [8, 7, 1], state: "minecraft:deepslate_bricks"},
        {pos: [8, 7, 2], state: "minecraft:deepslate_bricks"},
        {pos: [8, 7, 3], state: "minecraft:deepslate_bricks"},
        {pos: [8, 7, 4], state: "minecraft:deepslate_bricks"},
        {pos: [8, 7, 5], state: "minecraft:deepslate_bricks"},
        {pos: [8, 7, 6], state: "minecraft:deepslate_bricks"},
        {pos: [8, 7, 7], state: "minecraft:deepslate_bricks"},
        {pos: [8, 7, 8], state: "minecraft:deepslate_bricks"},
        {pos: [8, 7, 9], state: "minecraft:deepslate_bricks"},
        {pos: [8, 7, 10], state: "minecraft:deepslate_bricks"},
        {pos: [8, 7, 11], state: "minecraft:deepslate_bricks"},
        {pos: [8, 7, 12], state: "minecraft:deepslate_bricks"},
        {pos: [8, 7, 13], state: "minecraft:deepslate_bricks"},
        {pos: [9, 7, 1], state: "minecraft:deepslate_bricks"},
        {pos: [9, 7, 2], state: "minecraft:deepslate_bricks"},
        {pos: [9, 7, 3], state: "minecraft:deepslate_bricks"},
        {pos: [9, 7, 4], state: "minecraft:deepslate_bricks"},
        {pos: [9, 7, 5], state: "minecraft:deepslate_bricks"},
        {pos: [9, 7, 6], state: "minecraft:deepslate_bricks"},
        {pos: [9, 7, 7], state: "minecraft:deepslate_bricks"},
        {pos: [9, 7, 8], state: "minecraft:deepslate_bricks"},
        {pos: [9, 7, 9], state: "minecraft:deepslate_bricks"},
        {pos: [9, 7, 10], state: "minecraft:deepslate_bricks"},
        {pos: [9, 7, 11], state: "minecraft:deepslate_bricks"},
        {pos: [9, 7, 12], state: "minecraft:deepslate_bricks"},
        {pos: [9, 7, 13], state: "minecraft:deepslate_bricks"},
        {pos: [10, 7, 1], state: "minecraft:deepslate_bricks"},
        {pos: [10, 7, 2], state: "minecraft:deepslate_bricks"},
        {pos: [10, 7, 3], state: "minecraft:deepslate_bricks"},
        {pos: [10, 7, 4], state: "minecraft:deepslate_bricks"},
        {pos: [10, 7, 5], state: "minecraft:deepslate_bricks"},
        {pos: [10, 7, 6], state: "minecraft:deepslate_bricks"},
        {pos: [10, 7, 7], state: "minecraft:deepslate_bricks"},
        {pos: [10, 7, 8], state: "minecraft:deepslate_bricks"},
        {pos: [10, 7, 9], state: "minecraft:deepslate_bricks"},
        {pos: [10, 7, 10], state: "minecraft:deepslate_bricks"},
        {pos: [10, 7, 11], state: "minecraft:deepslate_bricks"},
        {pos: [10, 7, 12], state: "minecraft:deepslate_bricks"},
        {pos: [10, 7, 13], state: "minecraft:deepslate_bricks"},
        {pos: [11, 7, 5], state: "minecraft:deepslate_bricks"},
        {pos: [11, 7, 6], state: "minecraft:cave_air"},
        {pos: [11, 7, 7], state: "minecraft:cave_air"},
        {pos: [11, 7, 8], state: "minecraft:cave_air"},
        {pos: [11, 7, 9], state: "minecraft:deepslate_bricks"},
        {pos: [12, 7, 5], state: "minecraft:deepslate_bricks"},
        {pos: [12, 7, 6], state: "minecraft:cave_air"},
        {pos: [12, 7, 7], state: "minecraft:cave_air"},
        {pos: [12, 7, 8], state: "minecraft:cave_air"},
        {pos: [12, 7, 9], state: "minecraft:deepslate_bricks"},
        {pos: [13, 7, 5], state: "minecraft:deepslate_bricks"},
        {pos: [13, 7, 6], state: "minecraft:cobweb"},
        {pos: [13, 7, 7], state: "minecraft:cave_air"},
        {pos: [13, 7, 8], state: "minecraft:cave_air"},
        {pos: [13, 7, 9], state: "minecraft:deepslate_bricks"},
        {pos: [14, 7, 5], state: "minecraft:deepslate_bricks"},
        {pos: [14, 7, 6], state: "minecraft:deepslate_bricks"},
        {pos: [14, 7, 7], state: "minecraft:deepslate_bricks"},
        {pos: [14, 7, 8], state: "minecraft:deepslate_bricks"},
        {pos: [14, 7, 9], state: "minecraft:deepslate_bricks"},
        {pos: [0, 8, 2], state: "minecraft:deepslate_bricks"},
        {pos: [0, 8, 3], state: "minecraft:deepslate_bricks"},
        {pos: [0, 8, 4], state: "minecraft:deepslate_bricks"},
        {pos: [0, 8, 5], state: "minecraft:deepslate_bricks"},
        {pos: [0, 8, 6], state: "minecraft:deepslate_bricks"},
        {pos: [0, 8, 7], state: "minecraft:deepslate_bricks"},
        {pos: [0, 8, 8], state: "minecraft:deepslate_bricks"},
        {pos: [0, 8, 9], state: "minecraft:deepslate_bricks"},
        {pos: [0, 8, 10], state: "minecraft:deepslate_bricks"},
        {pos: [0, 8, 11], state: "minecraft:deepslate_bricks"},
        {pos: [1, 8, 2], state: "minecraft:deepslate_bricks"},
        {pos: [1, 8, 3], state: "minecraft:deepslate_bricks"},
        {pos: [1, 8, 4], state: "minecraft:jigsaw{orientation:down_south}", nbt: {final_state: "minecraft:deepslate_bricks", id: "minecraft:jigsaw", joint: "rollable", name: "trailiertales:chain", placement_priority: 0, pool: "trailiertales:catacombs/decoration/chain_2", selection_priority: 0, target: "trailiertales:chain"}},
        {pos: [1, 8, 5], state: "minecraft:deepslate_bricks"},
        {pos: [1, 8, 6], state: "minecraft:jigsaw{orientation:down_south}", nbt: {final_state: "minecraft:deepslate_bricks", id: "minecraft:jigsaw", joint: "rollable", name: "trailiertales:chain", placement_priority: 0, pool: "trailiertales:catacombs/decoration/chain_2", selection_priority: 0, target: "trailiertales:chain"}},
        {pos: [1, 8, 7], state: "minecraft:deepslate_bricks"},
        {pos: [1, 8, 8], state: "minecraft:jigsaw{orientation:north_up}", nbt: {final_state: "minecraft:deepslate_bricks", id: "minecraft:jigsaw", joint: "rollable", name: "trailiertales:chain", placement_priority: 0, pool: "trailiertales:catacombs/decoration/chain_2", selection_priority: 0, target: "trailiertales:chain"}},
        {pos: [1, 8, 9], state: "minecraft:deepslate_bricks"},
        {pos: [1, 8, 10], state: "minecraft:deepslate_bricks"},
        {pos: [1, 8, 11], state: "minecraft:deepslate_bricks"},
        {pos: [1, 8, 12], state: "minecraft:deepslate_bricks"},
        {pos: [1, 8, 13], state: "minecraft:deepslate_bricks"},
        {pos: [2, 8, 1], state: "minecraft:deepslate_bricks"},
        {pos: [2, 8, 2], state: "minecraft:cave_air"},
        {pos: [2, 8, 3], state: "minecraft:redstone_wire{east:none,north:side,power:0,south:up,west:none}"},
        {pos: [2, 8, 4], state: "minecraft:deepslate_bricks"},
        {pos: [2, 8, 5], state: "minecraft:jigsaw{orientation:down_south}", nbt: {final_state: "minecraft:deepslate_bricks", id: "minecraft:jigsaw", joint: "rollable", name: "trailiertales:chain", placement_priority: 0, pool: "trailiertales:catacombs/decoration/chain_1", selection_priority: 0, target: "trailiertales:chain"}},
        {pos: [2, 8, 6], state: "minecraft:deepslate_bricks"},
        {pos: [2, 8, 7], state: "minecraft:deepslate_bricks"},
        {pos: [2, 8, 8], state: "minecraft:deepslate_bricks"},
        {pos: [2, 8, 9], state: "minecraft:jigsaw{orientation:down_east}", nbt: {final_state: "minecraft:deepslate_bricks", id: "minecraft:jigsaw", joint: "rollable", name: "trailiertales:chain", placement_priority: 0, pool: "trailiertales:catacombs/decoration/chain_1", selection_priority: 0, target: "trailiertales:chain"}},
        {pos: [2, 8, 10], state: "minecraft:deepslate_bricks"},
        {pos: [2, 8, 11], state: "minecraft:redstone_wire{east:none,north:up,power:0,south:side,west:none}"},
        {pos: [2, 8, 12], state: "minecraft:cave_air"},
        {pos: [2, 8, 13], state: "minecraft:deepslate_bricks"},
        {pos: [3, 8, 1], state: "minecraft:deepslate_bricks"},
        {pos: [3, 8, 2], state: "minecraft:deepslate_bricks"},
        {pos: [3, 8, 3], state: "minecraft:deepslate_bricks"},
        {pos: [3, 8, 4], state: "minecraft:jigsaw{orientation:down_south}", nbt: {final_state: "minecraft:deepslate_bricks", id: "minecraft:jigsaw", joint: "rollable", name: "trailiertales:chain", placement_priority: 0, pool: "trailiertales:catacombs/decoration/chain_2", selection_priority: 0, target: "trailiertales:chain"}},
        {pos: [3, 8, 5], state: "minecraft:deepslate_bricks"},
        {pos: [3, 8, 6], state: "minecraft:jigsaw{orientation:down_south}", nbt: {final_state: "minecraft:deepslate_bricks", id: "minecraft:jigsaw", joint: "rollable", name: "trailiertales:chain", placement_priority: 0, pool: "trailiertales:catacombs/decoration/chain_2", selection_priority: 0, target: "trailiertales:chain"}},
        {pos: [3, 8, 7], state: "minecraft:deepslate_bricks"},
        {pos: [3, 8, 8], state: "minecraft:jigsaw{orientation:down_north}", nbt: {final_state: "minecraft:deepslate_bricks", id: "minecraft:jigsaw", joint: "rollable", name: "trailiertales:chain", placement_priority: 0, pool: "trailiertales:catacombs/decoration/chain_2", selection_priority: 0, target: "trailiertales:chain"}},
        {pos: [3, 8, 9], state: "minecraft:deepslate_bricks"},
        {pos: [3, 8, 10], state: "minecraft:jigsaw{orientation:down_north}", nbt: {final_state: "minecraft:deepslate_bricks", id: "minecraft:jigsaw", joint: "rollable", name: "trailiertales:chain", placement_priority: 0, pool: "trailiertales:catacombs/decoration/chain_2", selection_priority: 0, target: "trailiertales:chain"}},
        {pos: [3, 8, 11], state: "minecraft:deepslate_bricks"},
        {pos: [3, 8, 12], state: "minecraft:deepslate_bricks"},
        {pos: [3, 8, 13], state: "minecraft:deepslate_bricks"},
        {pos: [4, 8, 1], state: "minecraft:deepslate_bricks"},
        {pos: [4, 8, 2], state: "minecraft:cave_air"},
        {pos: [4, 8, 3], state: "minecraft:redstone_wire{east:none,north:side,power:0,south:up,west:none}"},
        {pos: [4, 8, 4], state: "minecraft:deepslate_bricks"},
        {pos: [4, 8, 5], state: "minecraft:deepslate_bricks"},
        {pos: [4, 8, 6], state: "minecraft:deepslate_bricks"},
        {pos: [4, 8, 7], state: "minecraft:polished_deepslate"},
        {pos: [4, 8, 8], state: "minecraft:deepslate_bricks"},
        {pos: [4, 8, 9], state: "minecraft:deepslate_bricks"},
        {pos: [4, 8, 10], state: "minecraft:deepslate_bricks"},
        {pos: [4, 8, 11], state: "minecraft:redstone_wire{east:none,north:up,power:0,south:side,west:none}"},
        {pos: [4, 8, 12], state: "minecraft:cave_air"},
        {pos: [4, 8, 13], state: "minecraft:deepslate_bricks"},
        {pos: [5, 8, 1], state: "minecraft:deepslate_bricks"},
        {pos: [5, 8, 2], state: "minecraft:deepslate_bricks"},
        {pos: [5, 8, 3], state: "minecraft:deepslate_bricks"},
        {pos: [5, 8, 4], state: "minecraft:jigsaw{orientation:down_south}", nbt: {final_state: "minecraft:deepslate_bricks", id: "minecraft:jigsaw", joint: "rollable", name: "trailiertales:chain", placement_priority: 0, pool: "trailiertales:catacombs/decoration/chain_2", selection_priority: 0, target: "trailiertales:chain"}},
        {pos: [5, 8, 5], state: "minecraft:deepslate_bricks"},
        {pos: [5, 8, 6], state: "minecraft:jigsaw{orientation:down_south}", nbt: {final_state: "minecraft:deepslate_bricks", id: "minecraft:jigsaw", joint: "rollable", name: "trailiertales:chain", placement_priority: 0, pool: "trailiertales:catacombs/decoration/chain_2", selection_priority: 0, target: "trailiertales:chain"}},
        {pos: [5, 8, 7], state: "minecraft:deepslate_bricks"},
        {pos: [5, 8, 8], state: "minecraft:jigsaw{orientation:down_west}", nbt: {final_state: "minecraft:deepslate_bricks", id: "minecraft:jigsaw", joint: "rollable", name: "trailiertales:chain", placement_priority: 0, pool: "trailiertales:catacombs/decoration/chain_2", selection_priority: 0, target: "trailiertales:chain"}},
        {pos: [5, 8, 9], state: "minecraft:deepslate_bricks"},
        {pos: [5, 8, 10], state: "minecraft:jigsaw{orientation:down_north}", nbt: {final_state: "minecraft:deepslate_bricks", id: "minecraft:jigsaw", joint: "rollable", name: "trailiertales:chain", placement_priority: 0, pool: "trailiertales:catacombs/decoration/chain_2", selection_priority: 0, target: "trailiertales:chain"}},
        {pos: [5, 8, 11], state: "minecraft:deepslate_bricks"},
        {pos: [5, 8, 12], state: "minecraft:deepslate_bricks"},
        {pos: [5, 8, 13], state: "minecraft:deepslate_bricks"},
        {pos: [6, 8, 1], state: "minecraft:deepslate_bricks"},
        {pos: [6, 8, 2], state: "minecraft:cave_air"},
        {pos: [6, 8, 3], state: "minecraft:redstone_wire{east:none,north:side,power:0,south:up,west:none}"},
        {pos: [6, 8, 4], state: "minecraft:deepslate_bricks"},
        {pos: [6, 8, 5], state: "minecraft:jigsaw{orientation:down_west}", nbt: {final_state: "minecraft:deepslate_bricks", id: "minecraft:jigsaw", joint: "rollable", name: "trailiertales:chain", placement_priority: 0, pool: "trailiertales:catacombs/decoration/chain_1", selection_priority: 0, target: "trailiertales:chain"}},
        {pos: [6, 8, 6], state: "minecraft:deepslate_bricks"},
        {pos: [6, 8, 7], state: "minecraft:deepslate_bricks"},
        {pos: [6, 8, 8], state: "minecraft:deepslate_bricks"},
        {pos: [6, 8, 9], state: "minecraft:jigsaw{orientation:down_west}", nbt: {final_state: "minecraft:deepslate_bricks", id: "minecraft:jigsaw", joint: "rollable", name: "trailiertales:chain", placement_priority: 0, pool: "trailiertales:catacombs/decoration/chain_1", selection_priority: 0, target: "trailiertales:chain"}},
        {pos: [6, 8, 10], state: "minecraft:deepslate_bricks"},
        {pos: [6, 8, 11], state: "minecraft:redstone_wire{east:none,north:up,power:0,south:side,west:none}"},
        {pos: [6, 8, 12], state: "minecraft:cave_air"},
        {pos: [6, 8, 13], state: "minecraft:deepslate_bricks"},
        {pos: [7, 8, 1], state: "minecraft:deepslate_bricks"},
        {pos: [7, 8, 2], state: "minecraft:deepslate_bricks"},
        {pos: [7, 8, 3], state: "minecraft:deepslate_bricks"},
        {pos: [7, 8, 4], state: "minecraft:deepslate_bricks"},
        {pos: [7, 8, 5], state: "minecraft:deepslate_bricks"},
        {pos: [7, 8, 6], state: "minecraft:jigsaw{orientation:down_west}", nbt: {final_state: "minecraft:deepslate_bricks", id: "minecraft:jigsaw", joint: "rollable", name: "trailiertales:chain", placement_priority: 0, pool: "trailiertales:catacombs/decoration/chain_2", selection_priority: 0, target: "trailiertales:chain"}},
        {pos: [7, 8, 7], state: "minecraft:deepslate_bricks"},
        {pos: [7, 8, 8], state: "minecraft:deepslate_bricks"},
        {pos: [7, 8, 9], state: "minecraft:deepslate_bricks"},
        {pos: [7, 8, 10], state: "minecraft:jigsaw{orientation:down_west}", nbt: {final_state: "minecraft:deepslate_bricks", id: "minecraft:jigsaw", joint: "rollable", name: "trailiertales:chain", placement_priority: 0, pool: "trailiertales:catacombs/decoration/chain_2", selection_priority: 0, target: "trailiertales:chain"}},
        {pos: [7, 8, 11], state: "minecraft:deepslate_bricks"},
        {pos: [7, 8, 12], state: "minecraft:deepslate_bricks"},
        {pos: [7, 8, 13], state: "minecraft:deepslate_bricks"},
        {pos: [8, 8, 1], state: "minecraft:deepslate_bricks"},
        {pos: [8, 8, 2], state: "minecraft:deepslate_bricks"},
        {pos: [8, 8, 3], state: "minecraft:deepslate_bricks"},
        {pos: [8, 8, 4], state: "minecraft:deepslate_bricks"},
        {pos: [8, 8, 5], state: "minecraft:deepslate_bricks"},
        {pos: [8, 8, 6], state: "minecraft:deepslate_bricks"},
        {pos: [8, 8, 7], state: "minecraft:deepslate_bricks"},
        {pos: [8, 8, 8], state: "minecraft:deepslate_bricks"},
        {pos: [8, 8, 9], state: "minecraft:deepslate_bricks"},
        {pos: [8, 8, 10], state: "minecraft:deepslate_bricks"},
        {pos: [8, 8, 11], state: "minecraft:deepslate_bricks"},
        {pos: [8, 8, 12], state: "minecraft:deepslate_bricks"},
        {pos: [8, 8, 13], state: "minecraft:deepslate_bricks"},
        {pos: [9, 8, 1], state: "minecraft:deepslate_bricks"},
        {pos: [9, 8, 2], state: "minecraft:deepslate_bricks"},
        {pos: [9, 8, 3], state: "minecraft:deepslate_bricks"},
        {pos: [9, 8, 4], state: "minecraft:deepslate_bricks"},
        {pos: [9, 8, 5], state: "minecraft:deepslate_bricks"},
        {pos: [9, 8, 6], state: "minecraft:deepslate_bricks"},
        {pos: [9, 8, 7], state: "minecraft:deepslate_bricks"},
        {pos: [9, 8, 8], state: "minecraft:deepslate_bricks"},
        {pos: [9, 8, 9], state: "minecraft:deepslate_bricks"},
        {pos: [9, 8, 10], state: "minecraft:deepslate_bricks"},
        {pos: [9, 8, 11], state: "minecraft:deepslate_bricks"},
        {pos: [9, 8, 12], state: "minecraft:deepslate_bricks"},
        {pos: [9, 8, 13], state: "minecraft:deepslate_bricks"},
        {pos: [10, 8, 1], state: "minecraft:deepslate_bricks"},
        {pos: [10, 8, 2], state: "minecraft:deepslate_bricks"},
        {pos: [10, 8, 3], state: "minecraft:deepslate_bricks"},
        {pos: [10, 8, 4], state: "minecraft:deepslate_bricks"},
        {pos: [10, 8, 5], state: "minecraft:deepslate_bricks"},
        {pos: [10, 8, 6], state: "minecraft:deepslate_bricks"},
        {pos: [10, 8, 7], state: "minecraft:deepslate_bricks"},
        {pos: [10, 8, 8], state: "minecraft:deepslate_bricks"},
        {pos: [10, 8, 9], state: "minecraft:deepslate_bricks"},
        {pos: [10, 8, 10], state: "minecraft:deepslate_bricks"},
        {pos: [10, 8, 11], state: "minecraft:deepslate_bricks"},
        {pos: [10, 8, 12], state: "minecraft:deepslate_bricks"},
        {pos: [10, 8, 13], state: "minecraft:deepslate_bricks"},
        {pos: [11, 8, 5], state: "minecraft:deepslate_bricks"},
        {pos: [11, 8, 6], state: "minecraft:jigsaw{orientation:down_south}", nbt: {final_state: "minecraft:deepslate_bricks", id: "minecraft:jigsaw", joint: "rollable", name: "trailiertales:chain", placement_priority: 0, pool: "trailiertales:catacombs/decoration/chain_2", selection_priority: 0, target: "trailiertales:chain"}},
        {pos: [11, 8, 7], state: "minecraft:deepslate_bricks"},
        {pos: [11, 8, 8], state: "minecraft:jigsaw{orientation:down_north}", nbt: {final_state: "minecraft:deepslate_bricks", id: "minecraft:jigsaw", joint: "rollable", name: "trailiertales:chain", placement_priority: 0, pool: "trailiertales:catacombs/decoration/chain_2", selection_priority: 0, target: "trailiertales:chain"}},
        {pos: [11, 8, 9], state: "minecraft:deepslate_bricks"},
        {pos: [12, 8, 5], state: "minecraft:deepslate_bricks"},
        {pos: [12, 8, 6], state: "minecraft:jigsaw{orientation:down_south}", nbt: {final_state: "minecraft:deepslate_bricks", id: "minecraft:jigsaw", joint: "rollable", name: "trailiertales:chain", placement_priority: 0, pool: "trailiertales:catacombs/decoration/chain_2", selection_priority: 0, target: "trailiertales:chain"}},
        {pos: [12, 8, 7], state: "minecraft:deepslate_bricks"},
        {pos: [12, 8, 8], state: "minecraft:jigsaw{orientation:down_north}", nbt: {final_state: "minecraft:deepslate_bricks", id: "minecraft:jigsaw", joint: "rollable", name: "trailiertales:chain", placement_priority: 0, pool: "trailiertales:catacombs/decoration/chain_2", selection_priority: 0, target: "trailiertales:chain"}},
        {pos: [12, 8, 9], state: "minecraft:deepslate_bricks"},
        {pos: [13, 8, 5], state: "minecraft:deepslate_bricks"},
        {pos: [13, 8, 6], state: "minecraft:deepslate_bricks"},
        {pos: [13, 8, 7], state: "minecraft:jigsaw{orientation:down_west}", nbt: {final_state: "minecraft:deepslate_bricks", id: "minecraft:jigsaw", joint: "rollable", name: "trailiertales:chain", placement_priority: 0, pool: "trailiertales:catacombs/decoration/chain_1", selection_priority: 0, target: "trailiertales:chain"}},
        {pos: [13, 8, 8], state: "minecraft:jigsaw{orientation:down_west}", nbt: {final_state: "minecraft:deepslate_bricks", id: "minecraft:jigsaw", joint: "rollable", name: "trailiertales:chain", placement_priority: 0, pool: "trailiertales:catacombs/decoration/chain_2", selection_priority: 0, target: "trailiertales:chain"}},
        {pos: [13, 8, 9], state: "minecraft:deepslate_bricks"},
        {pos: [14, 8, 5], state: "minecraft:deepslate_bricks"},
        {pos: [14, 8, 6], state: "minecraft:deepslate_bricks"},
        {pos: [14, 8, 7], state: "minecraft:deepslate_bricks"},
        {pos: [14, 8, 8], state: "minecraft:deepslate_bricks"},
        {pos: [14, 8, 9], state: "minecraft:deepslate_bricks"},
        {pos: [0, 9, 2], state: "minecraft:deepslate_bricks"},
        {pos: [0, 9, 3], state: "minecraft:deepslate_bricks"},
        {pos: [0, 9, 4], state: "minecraft:deepslate_bricks"},
        {pos: [0, 9, 5], state: "minecraft:deepslate_bricks"},
        {pos: [0, 9, 6], state: "minecraft:deepslate_bricks"},
        {pos: [0, 9, 7], state: "minecraft:deepslate_bricks"},
        {pos: [0, 9, 8], state: "minecraft:deepslate_bricks"},
        {pos: [0, 9, 9], state: "minecraft:deepslate_bricks"},
        {pos: [0, 9, 10], state: "minecraft:deepslate_bricks"},
        {pos: [0, 9, 11], state: "minecraft:deepslate_bricks"},
        {pos: [1, 9, 2], state: "minecraft:deepslate_bricks"},
        {pos: [1, 9, 3], state: "minecraft:deepslate_bricks"},
        {pos: [1, 9, 4], state: "minecraft:deepslate_bricks"},
        {pos: [1, 9, 5], state: "minecraft:deepslate_bricks"},
        {pos: [1, 9, 6], state: "minecraft:deepslate_bricks"},
        {pos: [1, 9, 7], state: "minecraft:deepslate_bricks"},
        {pos: [1, 9, 8], state: "minecraft:deepslate_bricks"},
        {pos: [1, 9, 9], state: "minecraft:deepslate_bricks"},
        {pos: [1, 9, 10], state: "minecraft:deepslate_bricks"},
        {pos: [1, 9, 11], state: "minecraft:deepslate_bricks"},
        {pos: [1, 9, 12], state: "minecraft:deepslate_bricks"},
        {pos: [1, 9, 13], state: "minecraft:deepslate_bricks"},
        {pos: [2, 9, 2], state: "minecraft:deepslate_bricks"},
        {pos: [2, 9, 3], state: "minecraft:cave_air"},
        {pos: [2, 9, 4], state: "minecraft:redstone_wire{east:none,north:side,power:0,south:side,west:none}"},
        {pos: [2, 9, 5], state: "minecraft:redstone_wire{east:none,north:side,power:0,south:side,west:none}"},
        {pos: [2, 9, 6], state: "minecraft:redstone_wire{east:none,north:side,power:0,south:side,west:none}"},
        {pos: [2, 9, 7], state: "minecraft:repeater{delay:1,facing:south,locked:false,powered:false}"},
        {pos: [2, 9, 8], state: "minecraft:redstone_wire{east:none,north:side,power:0,south:side,west:none}"},
        {pos: [2, 9, 9], state: "minecraft:redstone_wire{east:none,north:side,power:0,south:side,west:none}"},
        {pos: [2, 9, 10], state: "minecraft:redstone_wire{east:none,north:side,power:0,south:side,west:none}"},
        {pos: [2, 9, 11], state: "minecraft:cave_air"},
        {pos: [2, 9, 12], state: "minecraft:cave_air"},
        {pos: [2, 9, 13], state: "minecraft:deepslate_bricks"},
        {pos: [3, 9, 2], state: "minecraft:deepslate_bricks"},
        {pos: [3, 9, 3], state: "minecraft:deepslate_bricks"},
        {pos: [3, 9, 4], state: "minecraft:deepslate_bricks"},
        {pos: [3, 9, 5], state: "minecraft:deepslate_bricks"},
        {pos: [3, 9, 6], state: "minecraft:deepslate_bricks"},
        {pos: [3, 9, 7], state: "minecraft:deepslate_bricks"},
        {pos: [3, 9, 8], state: "minecraft:deepslate_bricks"},
        {pos: [3, 9, 9], state: "minecraft:deepslate_bricks"},
        {pos: [3, 9, 10], state: "minecraft:deepslate_bricks"},
        {pos: [3, 9, 11], state: "minecraft:deepslate_bricks"},
        {pos: [3, 9, 12], state: "minecraft:deepslate_bricks"},
        {pos: [3, 9, 13], state: "minecraft:deepslate_bricks"},
        {pos: [4, 9, 2], state: "minecraft:deepslate_bricks"},
        {pos: [4, 9, 3], state: "minecraft:cave_air"},
        {pos: [4, 9, 4], state: "minecraft:redstone_wire{east:none,north:side,power:0,south:side,west:none}"},
        {pos: [4, 9, 5], state: "minecraft:redstone_wire{east:none,north:side,power:0,south:side,west:none}"},
        {pos: [4, 9, 6], state: "minecraft:redstone_wire{east:none,north:side,power:0,south:side,west:none}"},
        {pos: [4, 9, 7], state: "minecraft:cave_air"},
        {pos: [4, 9, 8], state: "minecraft:redstone_wire{east:none,north:side,power:0,south:side,west:none}"},
        {pos: [4, 9, 9], state: "minecraft:redstone_wire{east:none,north:side,power:0,south:side,west:none}"},
        {pos: [4, 9, 10], state: "minecraft:redstone_wire{east:none,north:side,power:0,south:side,west:none}"},
        {pos: [4, 9, 11], state: "minecraft:cave_air"},
        {pos: [4, 9, 12], state: "minecraft:deepslate_bricks"},
        {pos: [4, 9, 13], state: "minecraft:deepslate_bricks"},
        {pos: [5, 9, 2], state: "minecraft:deepslate_bricks"},
        {pos: [5, 9, 3], state: "minecraft:deepslate_bricks"},
        {pos: [5, 9, 4], state: "minecraft:deepslate_bricks"},
        {pos: [5, 9, 5], state: "minecraft:deepslate_bricks"},
        {pos: [5, 9, 6], state: "minecraft:deepslate_bricks"},
        {pos: [5, 9, 7], state: "minecraft:deepslate_bricks"},
        {pos: [5, 9, 8], state: "minecraft:deepslate_bricks"},
        {pos: [5, 9, 9], state: "minecraft:deepslate_bricks"},
        {pos: [5, 9, 10], state: "minecraft:deepslate_bricks"},
        {pos: [5, 9, 11], state: "minecraft:deepslate_bricks"},
        {pos: [5, 9, 12], state: "minecraft:deepslate_bricks"},
        {pos: [5, 9, 13], state: "minecraft:deepslate_bricks"},
        {pos: [6, 9, 2], state: "minecraft:deepslate_bricks"},
        {pos: [6, 9, 3], state: "minecraft:cave_air"},
        {pos: [6, 9, 4], state: "minecraft:redstone_wire{east:none,north:side,power:0,south:side,west:none}"},
        {pos: [6, 9, 5], state: "minecraft:redstone_wire{east:none,north:side,power:0,south:side,west:none}"},
        {pos: [6, 9, 6], state: "minecraft:redstone_wire{east:none,north:side,power:0,south:side,west:none}"},
        {pos: [6, 9, 7], state: "minecraft:repeater{delay:1,facing:south,locked:false,powered:false}"},
        {pos: [6, 9, 8], state: "minecraft:redstone_wire{east:none,north:side,power:0,south:side,west:none}"},
        {pos: [6, 9, 9], state: "minecraft:redstone_wire{east:none,north:side,power:0,south:side,west:none}"},
        {pos: [6, 9, 10], state: "minecraft:redstone_wire{east:none,north:side,power:0,south:side,west:none}"},
        {pos: [6, 9, 11], state: "minecraft:cave_air"},
        {pos: [6, 9, 12], state: "minecraft:deepslate_bricks"},
        {pos: [6, 9, 13], state: "minecraft:deepslate_bricks"},
        {pos: [7, 9, 2], state: "minecraft:deepslate_bricks"},
        {pos: [7, 9, 3], state: "minecraft:deepslate_bricks"},
        {pos: [7, 9, 4], state: "minecraft:deepslate_bricks"},
        {pos: [7, 9, 5], state: "minecraft:deepslate_bricks"},
        {pos: [7, 9, 6], state: "minecraft:deepslate_bricks"},
        {pos: [7, 9, 7], state: "minecraft:deepslate_bricks"},
        {pos: [7, 9, 8], state: "minecraft:deepslate_bricks"},
        {pos: [7, 9, 9], state: "minecraft:deepslate_bricks"},
        {pos: [7, 9, 10], state: "minecraft:deepslate_bricks"},
        {pos: [7, 9, 11], state: "minecraft:deepslate_bricks"},
        {pos: [7, 9, 12], state: "minecraft:deepslate_bricks"},
        {pos: [7, 9, 13], state: "minecraft:deepslate_bricks"},
        {pos: [8, 9, 2], state: "minecraft:deepslate_bricks"},
        {pos: [8, 9, 3], state: "minecraft:deepslate_bricks"},
        {pos: [8, 9, 4], state: "minecraft:deepslate_bricks"},
        {pos: [8, 9, 5], state: "minecraft:deepslate_bricks"},
        {pos: [8, 9, 6], state: "minecraft:deepslate_bricks"},
        {pos: [8, 9, 7], state: "minecraft:deepslate_bricks"},
        {pos: [8, 9, 8], state: "minecraft:deepslate_bricks"},
        {pos: [8, 9, 9], state: "minecraft:deepslate_bricks"},
        {pos: [8, 9, 10], state: "minecraft:deepslate_bricks"},
        {pos: [8, 9, 11], state: "minecraft:deepslate_bricks"},
        {pos: [8, 9, 12], state: "minecraft:deepslate_bricks"},
        {pos: [8, 9, 13], state: "minecraft:deepslate_bricks"},
        {pos: [9, 9, 2], state: "minecraft:deepslate_bricks"},
        {pos: [9, 9, 3], state: "minecraft:deepslate_bricks"},
        {pos: [9, 9, 4], state: "minecraft:deepslate_bricks"},
        {pos: [9, 9, 5], state: "minecraft:deepslate_bricks"},
        {pos: [9, 9, 6], state: "minecraft:deepslate_bricks"},
        {pos: [9, 9, 7], state: "minecraft:deepslate_bricks"},
        {pos: [9, 9, 8], state: "minecraft:deepslate_bricks"},
        {pos: [9, 9, 9], state: "minecraft:deepslate_bricks"},
        {pos: [9, 9, 10], state: "minecraft:deepslate_bricks"},
        {pos: [9, 9, 11], state: "minecraft:deepslate_bricks"},
        {pos: [9, 9, 12], state: "minecraft:deepslate_bricks"},
        {pos: [9, 9, 13], state: "minecraft:deepslate_bricks"},
        {pos: [10, 9, 2], state: "minecraft:deepslate_bricks"},
        {pos: [10, 9, 3], state: "minecraft:deepslate_bricks"},
        {pos: [10, 9, 4], state: "minecraft:deepslate_bricks"},
        {pos: [10, 9, 5], state: "minecraft:deepslate_bricks"},
        {pos: [10, 9, 6], state: "minecraft:deepslate_bricks"},
        {pos: [10, 9, 7], state: "minecraft:deepslate_bricks"},
        {pos: [10, 9, 8], state: "minecraft:deepslate_bricks"},
        {pos: [10, 9, 9], state: "minecraft:deepslate_bricks"},
        {pos: [10, 9, 10], state: "minecraft:deepslate_bricks"},
        {pos: [10, 9, 11], state: "minecraft:deepslate_bricks"},
        {pos: [10, 9, 12], state: "minecraft:deepslate_bricks"},
        {pos: [10, 9, 13], state: "minecraft:deepslate_bricks"},
        {pos: [0, 10, 2], state: "minecraft:deepslate_bricks"},
