{
    DataVersion: 3953,
    size: [17, 11, 9],
    data: [
        {pos: [14, 0, 2], state: "minecraft:deepslate_bricks"},
        {pos: [14, 0, 3], state: "minecraft:deepslate_bricks"},
        {pos: [14, 0, 4], state: "minecraft:deepslate_bricks"},
        {pos: [14, 0, 5], state: "minecraft:deepslate_bricks"},
        {pos: [14, 0, 6], state: "minecraft:deepslate_bricks"},
        {pos: [15, 0, 2], state: "minecraft:deepslate_bricks"},
        {pos: [15, 0, 3], state: "minecraft:deepslate_bricks"},
        {pos: [15, 0, 4], state: "minecraft:deepslate_bricks"},
        {pos: [15, 0, 5], state: "minecraft:deepslate_bricks"},
        {pos: [15, 0, 6], state: "minecraft:deepslate_bricks"},
        {pos: [16, 0, 2], state: "minecraft:deepslate_bricks"},
        {pos: [16, 0, 3], state: "minecraft:deepslate_bricks"},
        {pos: [16, 0, 4], state: "minecraft:deepslate_bricks"},
        {pos: [16, 0, 5], state: "minecraft:deepslate_bricks"},
        {pos: [16, 0, 6], state: "minecraft:deepslate_bricks"},
        {pos: [14, 1, 2], state: "minecraft:deepslate_bricks"},
        {pos: [14, 1, 3], state: "minecraft:deepslate_bricks"},
        {pos: [14, 1, 4], state: "minecraft:deepslate_bricks"},
        {pos: [14, 1, 5], state: "minecraft:deepslate_bricks"},
        {pos: [14, 1, 6], state: "minecraft:deepslate_bricks"},
        {pos: [15, 1, 2], state: "minecraft:deepslate_bricks"},
        {pos: [15, 1, 3], state: "minecraft:gravel"},
        {pos: [15, 1, 4], state: "minecraft:deepslate_bricks"},
        {pos: [15, 1, 5], state: "minecraft:deepslate_bricks"},
        {pos: [15, 1, 6], state: "minecraft:deepslate_bricks"},
        {pos: [16, 1, 2], state: "minecraft:deepslate_bricks"},
        {pos: [16, 1, 3], state: "minecraft:gravel"},
        {pos: [16, 1, 4], state: "minecraft:gravel"},
        {pos: [16, 1, 5], state: "minecraft:gravel"},
        {pos: [16, 1, 6], state: "minecraft:deepslate_bricks"},
        {pos: [0, 2, 2], state: "minecraft:deepslate_bricks"},
        {pos: [0, 2, 3], state: "minecraft:deepslate_bricks"},
        {pos: [0, 2, 4], state: "minecraft:deepslate_bricks"},
        {pos: [0, 2, 5], state: "minecraft:deepslate_bricks"},
        {pos: [0, 2, 6], state: "minecraft:deepslate_bricks"},
        {pos: [1, 2, 2], state: "minecraft:deepslate_bricks"},
        {pos: [1, 2, 3], state: "minecraft:deepslate_bricks"},
        {pos: [1, 2, 4], state: "minecraft:deepslate_bricks"},
        {pos: [1, 2, 5], state: "minecraft:deepslate_bricks"},
        {pos: [1, 2, 6], state: "minecraft:deepslate_bricks"},
        {pos: [2, 2, 2], state: "minecraft:deepslate_bricks"},
        {pos: [2, 2, 3], state: "minecraft:deepslate_bricks"},
        {pos: [2, 2, 4], state: "minecraft:deepslate_bricks"},
        {pos: [2, 2, 5], state: "minecraft:deepslate_bricks"},
        {pos: [2, 2, 6], state: "minecraft:deepslate_bricks"},
        {pos: [3, 2, 2], state: "minecraft:deepslate_bricks"},
        {pos: [3, 2, 3], state: "minecraft:deepslate_bricks"},
        {pos: [3, 2, 4], state: "minecraft:deepslate_bricks"},
        {pos: [3, 2, 5], state: "minecraft:deepslate_bricks"},
        {pos: [3, 2, 6], state: "minecraft:deepslate_bricks"},
        {pos: [4, 2, 2], state: "minecraft:deepslate_bricks"},
        {pos: [4, 2, 3], state: "minecraft:deepslate_bricks"},
        {pos: [4, 2, 4], state: "minecraft:deepslate_bricks"},
        {pos: [4, 2, 5], state: "minecraft:deepslate_bricks"},
        {pos: [4, 2, 6], state: "minecraft:deepslate_bricks"},
        {pos: [5, 2, 2], state: "minecraft:deepslate_bricks"},
        {pos: [5, 2, 3], state: "minecraft:deepslate_bricks"},
        {pos: [5, 2, 4], state: "minecraft:deepslate_bricks"},
        {pos: [5, 2, 5], state: "minecraft:deepslate_bricks"},
        {pos: [5, 2, 6], state: "minecraft:deepslate_bricks"},
        {pos: [6, 2, 2], state: "minecraft:deepslate_bricks"},
        {pos: [6, 2, 3], state: "minecraft:deepslate_bricks"},
        {pos: [6, 2, 4], state: "minecraft:deepslate_bricks"},
        {pos: [6, 2, 5], state: "minecraft:deepslate_bricks"},
        {pos: [6, 2, 6], state: "minecraft:deepslate_bricks"},
        {pos: [7, 2, 2], state: "minecraft:deepslate_bricks"},
        {pos: [7, 2, 3], state: "minecraft:deepslate_bricks"},
        {pos: [7, 2, 4], state: "minecraft:deepslate_bricks"},
        {pos: [7, 2, 5], state: "minecraft:deepslate_bricks"},
        {pos: [7, 2, 6], state: "minecraft:deepslate_bricks"},
        {pos: [8, 2, 2], state: "minecraft:deepslate_bricks"},
        {pos: [8, 2, 3], state: "minecraft:deepslate_bricks"},
        {pos: [8, 2, 4], state: "minecraft:deepslate_bricks"},
        {pos: [8, 2, 5], state: "minecraft:deepslate_bricks"},
        {pos: [8, 2, 6], state: "minecraft:deepslate_bricks"},
        {pos: [9, 2, 2], state: "minecraft:deepslate_bricks"},
        {pos: [9, 2, 3], state: "minecraft:deepslate_bricks"},
        {pos: [9, 2, 4], state: "minecraft:deepslate_bricks"},
        {pos: [9, 2, 5], state: "minecraft:deepslate_bricks"},
        {pos: [9, 2, 6], state: "minecraft:deepslate_bricks"},
        {pos: [10, 2, 2], state: "minecraft:deepslate_bricks"},
        {pos: [10, 2, 3], state: "minecraft:deepslate_bricks"},
        {pos: [10, 2, 4], state: "minecraft:deepslate_bricks"},
        {pos: [10, 2, 5], state: "minecraft:deepslate_bricks"},
        {pos: [10, 2, 6], state: "minecraft:deepslate_bricks"},
        {pos: [11, 2, 2], state: "minecraft:deepslate_bricks"},
        {pos: [11, 2, 3], state: "minecraft:deepslate_bricks"},
        {pos: [11, 2, 4], state: "minecraft:deepslate_bricks"},
        {pos: [11, 2, 5], state: "minecraft:deepslate_bricks"},
        {pos: [11, 2, 6], state: "minecraft:deepslate_bricks"},
        {pos: [12, 2, 0], state: "minecraft:deepslate_bricks"},
        {pos: [12, 2, 1], state: "minecraft:deepslate_bricks"},
        {pos: [12, 2, 2], state: "minecraft:deepslate_bricks"},
        {pos: [12, 2, 3], state: "minecraft:deepslate_bricks"},
        {pos: [12, 2, 4], state: "minecraft:deepslate_bricks"},
        {pos: [12, 2, 5], state: "minecraft:deepslate_bricks"},
        {pos: [12, 2, 6], state: "minecraft:deepslate_bricks"},
        {pos: [12, 2, 7], state: "minecraft:deepslate_bricks"},
        {pos: [12, 2, 8], state: "minecraft:deepslate_bricks"},
        {pos: [13, 2, 0], state: "minecraft:deepslate_bricks"},
        {pos: [13, 2, 1], state: "minecraft:deepslate_bricks"},
        {pos: [13, 2, 2], state: "minecraft:deepslate_bricks"},
        {pos: [13, 2, 3], state: "minecraft:deepslate_bricks"},
        {pos: [13, 2, 4], state: "minecraft:deepslate_bricks"},
        {pos: [13, 2, 5], state: "minecraft:deepslate_bricks"},
        {pos: [13, 2, 6], state: "minecraft:deepslate_bricks"},
        {pos: [13, 2, 7], state: "minecraft:deepslate_bricks"},
        {pos: [13, 2, 8], state: "minecraft:deepslate_bricks"},
        {pos: [14, 2, 0], state: "minecraft:deepslate_bricks"},
        {pos: [14, 2, 1], state: "minecraft:deepslate_bricks"},
        {pos: [14, 2, 2], state: "minecraft:deepslate_bricks"},
        {pos: [14, 2, 3], state: "minecraft:deepslate_brick_stairs{facing:west,half:bottom,shape:straight,waterlogged:false}"},
        {pos: [14, 2, 4], state: "minecraft:deepslate_brick_stairs{facing:west,half:bottom,shape:straight,waterlogged:false}"},
        {pos: [14, 2, 5], state: "minecraft:deepslate_brick_stairs{facing:west,half:bottom,shape:straight,waterlogged:false}"},
        {pos: [14, 2, 6], state: "minecraft:deepslate_bricks"},
        {pos: [14, 2, 7], state: "minecraft:deepslate_bricks"},
        {pos: [14, 2, 8], state: "minecraft:deepslate_bricks"},
        {pos: [15, 2, 2], state: "minecraft:deepslate_bricks"},
        {pos: [15, 2, 3], state: "minecraft:decorated_pot{cracked:false,facing:east,waterlogged:false}", nbt: {id: "minecraft:decorated_pot"}},
        {pos: [15, 2, 4], state: "minecraft:cave_air"},
        {pos: [15, 2, 5], state: "minecraft:cave_air"},
        {pos: [15, 2, 6], state: "minecraft:deepslate_bricks"},
        {pos: [16, 2, 2], state: "minecraft:deepslate_bricks"},
        {pos: [16, 2, 3], state: "minecraft:candle{candles:4,lit:false,waterlogged:false}"},
        {pos: [16, 2, 4], state: "minecraft:jigsaw{orientation:east_up}", nbt: {final_state: "minecraft:cave_air", id: "minecraft:jigsaw", joint: "rollable", name: "trailiertales:corridor", placement_priority: 0, pool: "trailiertales:catacombs/corridor_connector", selection_priority: 0, target: "trailiertales:corridor"}},
        {pos: [16, 2, 5], state: "minecraft:candle{candles:4,lit:false,waterlogged:false}"},
        {pos: [16, 2, 6], state: "minecraft:deepslate_bricks"},
        {pos: [0, 3, 2], state: "minecraft:deepslate_bricks"},
        {pos: [0, 3, 3], state: "minecraft:deepslate_bricks"},
        {pos: [0, 3, 4], state: "minecraft:deepslate_bricks"},
        {pos: [0, 3, 5], state: "minecraft:deepslate_bricks"},
        {pos: [0, 3, 6], state: "minecraft:deepslate_bricks"},
        {pos: [1, 3, 2], state: "minecraft:deepslate_bricks"},
        {pos: [1, 3, 3], state: "minecraft:deepslate_bricks"},
        {pos: [1, 3, 4], state: "minecraft:deepslate_bricks"},
        {pos: [1, 3, 5], state: "minecraft:deepslate_bricks"},
        {pos: [1, 3, 6], state: "minecraft:deepslate_bricks"},
        {pos: [2, 3, 2], state: "minecraft:deepslate_bricks"},
        {pos: [2, 3, 3], state: "minecraft:deepslate_bricks"},
        {pos: [2, 3, 4], state: "minecraft:deepslate_bricks"},
        {pos: [2, 3, 5], state: "minecraft:deepslate_bricks"},
        {pos: [2, 3, 6], state: "minecraft:deepslate_bricks"},
        {pos: [3, 3, 2], state: "minecraft:deepslate_bricks"},
        {pos: [3, 3, 3], state: "minecraft:deepslate_bricks"},
        {pos: [3, 3, 4], state: "minecraft:deepslate_bricks"},
        {pos: [3, 3, 5], state: "minecraft:deepslate_bricks"},
        {pos: [3, 3, 6], state: "minecraft:deepslate_bricks"},
        {pos: [4, 3, 2], state: "minecraft:deepslate_bricks"},
        {pos: [4, 3, 3], state: "minecraft:deepslate_bricks"},
        {pos: [4, 3, 4], state: "minecraft:deepslate_bricks"},
        {pos: [4, 3, 5], state: "minecraft:deepslate_bricks"},
        {pos: [4, 3, 6], state: "minecraft:deepslate_bricks"},
        {pos: [5, 3, 2], state: "minecraft:deepslate_bricks"},
        {pos: [5, 3, 3], state: "minecraft:deepslate_bricks"},
        {pos: [5, 3, 4], state: "minecraft:deepslate_bricks"},
        {pos: [5, 3, 5], state: "minecraft:deepslate_bricks"},
        {pos: [5, 3, 6], state: "minecraft:deepslate_bricks"},
        {pos: [6, 3, 2], state: "minecraft:deepslate_bricks"},
        {pos: [6, 3, 3], state: "minecraft:deepslate_bricks"},
        {pos: [6, 3, 4], state: "minecraft:deepslate_bricks"},
        {pos: [6, 3, 5], state: "minecraft:deepslate_bricks"},
        {pos: [6, 3, 6], state: "minecraft:deepslate_bricks"},
        {pos: [7, 3, 2], state: "minecraft:deepslate_bricks"},
        {pos: [7, 3, 3], state: "minecraft:deepslate_bricks"},
        {pos: [7, 3, 4], state: "minecraft:deepslate_bricks"},
        {pos: [7, 3, 5], state: "minecraft:deepslate_bricks"},
        {pos: [7, 3, 6], state: "minecraft:deepslate_bricks"},
        {pos: [8, 3, 2], state: "minecraft:deepslate_bricks"},
        {pos: [8, 3, 3], state: "minecraft:deepslate_bricks"},
        {pos: [8, 3, 4], state: "minecraft:deepslate_bricks"},
        {pos: [8, 3, 5], state: "minecraft:deepslate_bricks"},
        {pos: [8, 3, 6], state: "minecraft:deepslate_bricks"},
        {pos: [9, 3, 0], state: "minecraft:deepslate_bricks"},
        {pos: [9, 3, 1], state: "minecraft:deepslate_bricks"},
        {pos: [9, 3, 2], state: "minecraft:deepslate_bricks"},
        {pos: [9, 3, 3], state: "minecraft:deepslate_bricks"},
        {pos: [9, 3, 4], state: "minecraft:deepslate_bricks"},
        {pos: [9, 3, 5], state: "minecraft:deepslate_bricks"},
        {pos: [9, 3, 6], state: "minecraft:deepslate_bricks"},
        {pos: [9, 3, 7], state: "minecraft:deepslate_bricks"},
        {pos: [9, 3, 8], state: "minecraft:deepslate_bricks"},
        {pos: [10, 3, 0], state: "minecraft:deepslate_bricks"},
        {pos: [10, 3, 1], state: "minecraft:deepslate_bricks"},
        {pos: [10, 3, 2], state: "minecraft:deepslate_bricks"},
        {pos: [10, 3, 3], state: "minecraft:deepslate_bricks"},
        {pos: [10, 3, 4], state: "minecraft:deepslate_bricks"},
        {pos: [10, 3, 5], state: "minecraft:deepslate_bricks"},
        {pos: [10, 3, 6], state: "minecraft:deepslate_bricks"},
        {pos: [10, 3, 7], state: "minecraft:deepslate_bricks"},
        {pos: [10, 3, 8], state: "minecraft:deepslate_bricks"},
        {pos: [11, 3, 0], state: "minecraft:deepslate_bricks"},
        {pos: [11, 3, 1], state: "minecraft:deepslate_bricks"},
        {pos: [11, 3, 2], state: "minecraft:deepslate_bricks"},
        {pos: [11, 3, 3], state: "minecraft:deepslate_brick_stairs{facing:west,half:bottom,shape:straight,waterlogged:false}"},
        {pos: [11, 3, 4], state: "minecraft:deepslate_brick_stairs{facing:west,half:bottom,shape:straight,waterlogged:false}"},
        {pos: [11, 3, 5], state: "minecraft:deepslate_brick_stairs{facing:west,half:bottom,shape:straight,waterlogged:false}"},
        {pos: [11, 3, 6], state: "minecraft:deepslate_bricks"},
        {pos: [11, 3, 7], state: "minecraft:deepslate_bricks"},
        {pos: [11, 3, 8], state: "minecraft:deepslate_bricks"},
        {pos: [12, 3, 0], state: "minecraft:deepslate_bricks"},
        {pos: [12, 3, 1], state: "minecraft:deepslate_bricks"},
        {pos: [12, 3, 2], state: "minecraft:deepslate_bricks"},
        {pos: [12, 3, 3], state: "minecraft:candle{candles:4,lit:false,waterlogged:false}"},
        {pos: [12, 3, 4], state: "minecraft:cave_air"},
        {pos: [12, 3, 5], state: "minecraft:decorated_pot{cracked:false,facing:south,waterlogged:false}", nbt: {id: "minecraft:decorated_pot"}},
        {pos: [12, 3, 6], state: "minecraft:deepslate_bricks"},
        {pos: [12, 3, 7], state: "minecraft:deepslate_bricks"},
        {pos: [12, 3, 8], state: "minecraft:deepslate_bricks"},
        {pos: [13, 3, 0], state: "minecraft:deepslate_bricks"},
        {pos: [13, 3, 1], state: "minecraft:chest{facing:south,type:single,waterlogged:false}", nbt: {Items: [], id: "minecraft:chest"}},
        {pos: [13, 3, 2], state: "minecraft:candle{candles:4,lit:false,waterlogged:false}"},
        {pos: [13, 3, 3], state: "minecraft:candle{candles:4,lit:false,waterlogged:false}"},
        {pos: [13, 3, 4], state: "minecraft:candle{candles:4,lit:false,waterlogged:false}"},
        {pos: [13, 3, 5], state: "trailiertales:coffin{facing:south,part:foot,state:inactive}", nbt: {id: "trailiertales:coffin", max_active_light_level: 7, uuid: "5a9ee916-0f82-4e31-854d-9ae87768943f"}},
        {pos: [13, 3, 6], state: "trailiertales:coffin{facing:south,part:head,state:inactive}", nbt: {id: "trailiertales:coffin"}},
        {pos: [13, 3, 7], state: "minecraft:candle{candles:4,lit:false,waterlogged:false}"},
        {pos: [13, 3, 8], state: "minecraft:deepslate_bricks"},
        {pos: [14, 3, 0], state: "minecraft:deepslate_bricks"},
        {pos: [14, 3, 1], state: "minecraft:deepslate_bricks"},
        {pos: [14, 3, 2], state: "minecraft:deepslate_bricks"},
        {pos: [14, 3, 3], state: "minecraft:cave_air"},
        {pos: [14, 3, 4], state: "minecraft:cave_air"},
        {pos: [14, 3, 5], state: "minecraft:cave_air"},
        {pos: [14, 3, 6], state: "minecraft:deepslate_bricks"},
        {pos: [14, 3, 7], state: "minecraft:deepslate_bricks"},
        {pos: [14, 3, 8], state: "minecraft:deepslate_bricks"},
        {pos: [15, 3, 2], state: "minecraft:deepslate_bricks"},
        {pos: [15, 3, 3], state: "minecraft:cave_air"},
        {pos: [15, 3, 4], state: "minecraft:cave_air"},
        {pos: [15, 3, 5], state: "minecraft:cave_air"},
        {pos: [15, 3, 6], state: "minecraft:deepslate_bricks"},
        {pos: [16, 3, 2], state: "minecraft:deepslate_bricks"},
        {pos: [16, 3, 3], state: "minecraft:cave_air"},
        {pos: [16, 3, 4], state: "minecraft:cave_air"},
        {pos: [16, 3, 5], state: "minecraft:cave_air"},
        {pos: [16, 3, 6], state: "minecraft:deepslate_bricks"},
        {pos: [0, 4, 2], state: "minecraft:deepslate_bricks"},
        {pos: [0, 4, 3], state: "minecraft:deepslate_bricks"},
        {pos: [0, 4, 4], state: "minecraft:deepslate_bricks"},
        {pos: [0, 4, 5], state: "minecraft:deepslate_bricks"},
        {pos: [0, 4, 6], state: "minecraft:deepslate_bricks"},
        {pos: [1, 4, 2], state: "minecraft:deepslate_bricks"},
        {pos: [1, 4, 3], state: "minecraft:deepslate_bricks"},
        {pos: [1, 4, 4], state: "minecraft:deepslate_bricks"},
        {pos: [1, 4, 5], state: "minecraft:deepslate_bricks"},
        {pos: [1, 4, 6], state: "minecraft:deepslate_bricks"},
        {pos: [2, 4, 2], state: "minecraft:deepslate_bricks"},
        {pos: [2, 4, 3], state: "minecraft:deepslate_bricks"},
        {pos: [2, 4, 4], state: "minecraft:deepslate_bricks"},
        {pos: [2, 4, 5], state: "minecraft:deepslate_bricks"},
        {pos: [2, 4, 6], state: "minecraft:deepslate_bricks"},
        {pos: [3, 4, 2], state: "minecraft:deepslate_bricks"},
        {pos: [3, 4, 3], state: "minecraft:deepslate_bricks"},
        {pos: [3, 4, 4], state: "minecraft:deepslate_bricks"},
        {pos: [3, 4, 5], state: "minecraft:deepslate_bricks"},
        {pos: [3, 4, 6], state: "minecraft:deepslate_bricks"},
        {pos: [4, 4, 2], state: "minecraft:deepslate_bricks"},
        {pos: [4, 4, 3], state: "minecraft:deepslate_bricks"},
        {pos: [4, 4, 4], state: "minecraft:deepslate_bricks"},
        {pos: [4, 4, 5], state: "minecraft:deepslate_bricks"},
        {pos: [4, 4, 6], state: "minecraft:deepslate_bricks"},
        {pos: [5, 4, 2], state: "minecraft:deepslate_bricks"},
        {pos: [5, 4, 3], state: "minecraft:deepslate_bricks"},
        {pos: [5, 4, 4], state: "minecraft:deepslate_bricks"},
        {pos: [5, 4, 5], state: "minecraft:deepslate_bricks"},
        {pos: [5, 4, 6], state: "minecraft:deepslate_bricks"},
        {pos: [6, 4, 0], state: "minecraft:deepslate_bricks"},
        {pos: [6, 4, 1], state: "minecraft:deepslate_bricks"},
        {pos: [6, 4, 2], state: "minecraft:deepslate_bricks"},
        {pos: [6, 4, 3], state: "minecraft:deepslate_bricks"},
        {pos: [6, 4, 4], state: "minecraft:deepslate_bricks"},
        {pos: [6, 4, 5], state: "minecraft:deepslate_bricks"},
        {pos: [6, 4, 6], state: "minecraft:deepslate_bricks"},
        {pos: [6, 4, 7], state: "minecraft:deepslate_bricks"},
        {pos: [6, 4, 8], state: "minecraft:deepslate_bricks"},
        {pos: [7, 4, 0], state: "minecraft:deepslate_bricks"},
        {pos: [7, 4, 1], state: "minecraft:deepslate_bricks"},
        {pos: [7, 4, 2], state: "minecraft:deepslate_bricks"},
        {pos: [7, 4, 3], state: "minecraft:deepslate_bricks"},
        {pos: [7, 4, 4], state: "minecraft:deepslate_bricks"},
        {pos: [7, 4, 5], state: "minecraft:deepslate_bricks"},
        {pos: [7, 4, 6], state: "minecraft:deepslate_bricks"},
        {pos: [7, 4, 7], state: "minecraft:deepslate_bricks"},
        {pos: [7, 4, 8], state: "minecraft:deepslate_bricks"},
        {pos: [8, 4, 0], state: "minecraft:deepslate_bricks"},
        {pos: [8, 4, 1], state: "minecraft:deepslate_bricks"},
        {pos: [8, 4, 2], state: "minecraft:deepslate_bricks"},
        {pos: [8, 4, 3], state: "minecraft:deepslate_brick_stairs{facing:west,half:bottom,shape:straight,waterlogged:false}"},
        {pos: [8, 4, 4], state: "minecraft:deepslate_brick_stairs{facing:west,half:bottom,shape:straight,waterlogged:false}"},
        {pos: [8, 4, 5], state: "minecraft:deepslate_brick_stairs{facing:west,half:bottom,shape:straight,waterlogged:false}"},
        {pos: [8, 4, 6], state: "minecraft:deepslate_bricks"},
        {pos: [8, 4, 7], state: "minecraft:deepslate_bricks"},
        {pos: [8, 4, 8], state: "minecraft:deepslate_bricks"},
        {pos: [9, 4, 0], state: "minecraft:deepslate_bricks"},
        {pos: [9, 4, 1], state: "minecraft:deepslate_bricks"},
        {pos: [9, 4, 2], state: "minecraft:deepslate_bricks"},
        {pos: [9, 4, 3], state: "minecraft:skeleton_skull{powered:false,rotation:8}", nbt: {id: "minecraft:skull"}},
        {pos: [9, 4, 4], state: "minecraft:cave_air"},
        {pos: [9, 4, 5], state: "minecraft:candle{candles:4,lit:false,waterlogged:false}"},
        {pos: [9, 4, 6], state: "minecraft:deepslate_bricks"},
        {pos: [9, 4, 7], state: "minecraft:deepslate_bricks"},
        {pos: [9, 4, 8], state: "minecraft:deepslate_bricks"},
        {pos: [10, 4, 0], state: "minecraft:deepslate_bricks"},
        {pos: [10, 4, 1], state: "trailiertales:coffin{facing:north,part:head,state:inactive}", nbt: {id: "trailiertales:coffin"}},
        {pos: [10, 4, 2], state: "trailiertales:coffin{facing:north,part:foot,state:inactive}", nbt: {id: "trailiertales:coffin", max_active_light_level: 7, uuid: "d53cf6f0-9597-48aa-bb42-b7773c08662e"}},
        {pos: [10, 4, 3], state: "minecraft:candle{candles:4,lit:false,waterlogged:false}"},
        {pos: [10, 4, 4], state: "minecraft:cave_air"},
        {pos: [10, 4, 5], state: "minecraft:candle{candles:4,lit:false,waterlogged:false}"},
        {pos: [10, 4, 6], state: "minecraft:candle{candles:4,lit:false,waterlogged:false}"},
        {pos: [10, 4, 7], state: "minecraft:chest{facing:north,type:single,waterlogged:false}", nbt: {Items: [], id: "minecraft:chest"}},
        {pos: [10, 4, 8], state: "minecraft:deepslate_bricks"},
        {pos: [11, 4, 0], state: "minecraft:deepslate_bricks"},
        {pos: [11, 4, 1], state: "minecraft:deepslate_bricks"},
        {pos: [11, 4, 2], state: "minecraft:deepslate_bricks"},
        {pos: [11, 4, 3], state: "minecraft:cave_air"},
        {pos: [11, 4, 4], state: "minecraft:cave_air"},
        {pos: [11, 4, 5], state: "minecraft:cave_air"},
        {pos: [11, 4, 6], state: "minecraft:deepslate_bricks"},
        {pos: [11, 4, 7], state: "minecraft:deepslate_bricks"},
        {pos: [11, 4, 8], state: "minecraft:deepslate_bricks"},
        {pos: [12, 4, 0], state: "minecraft:deepslate_bricks"},
        {pos: [12, 4, 1], state: "minecraft:deepslate_bricks"},
        {pos: [12, 4, 2], state: "minecraft:deepslate_bricks"},
        {pos: [12, 4, 3], state: "minecraft:cave_air"},
        {pos: [12, 4, 4], state: "minecraft:cave_air"},
        {pos: [12, 4, 5], state: "minecraft:cave_air"},
        {pos: [12, 4, 6], state: "minecraft:deepslate_bricks"},
        {pos: [12, 4, 7], state: "minecraft:deepslate_bricks"},
        {pos: [12, 4, 8], state: "minecraft:deepslate_bricks"},
        {pos: [13, 4, 0], state: "minecraft:deepslate_bricks"},
        {pos: [13, 4, 1], state: "minecraft:cave_air"},
        {pos: [13, 4, 2], state: "minecraft:cave_air"},
        {pos: [13, 4, 3], state: "minecraft:cave_air"},
        {pos: [13, 4, 4], state: "minecraft:cave_air"},
        {pos: [13, 4, 5], state: "minecraft:cave_air"},
        {pos: [13, 4, 6], state: "minecraft:cave_air"},
        {pos: [13, 4, 7], state: "minecraft:cave_air"},
        {pos: [13, 4, 8], state: "minecraft:deepslate_bricks"},
        {pos: [14, 4, 0], state: "minecraft:deepslate_bricks"},
        {pos: [14, 4, 1], state: "minecraft:deepslate_bricks"},
        {pos: [14, 4, 2], state: "minecraft:deepslate_bricks"},
        {pos: [14, 4, 3], state: "minecraft:cave_air"},
        {pos: [14, 4, 4], state: "minecraft:cave_air"},
        {pos: [14, 4, 5], state: "minecraft:cave_air"},
        {pos: [14, 4, 6], state: "minecraft:deepslate_bricks"},
        {pos: [14, 4, 7], state: "minecraft:deepslate_bricks"},
        {pos: [14, 4, 8], state: "minecraft:deepslate_bricks"},
        {pos: [15, 4, 2], state: "minecraft:deepslate_bricks"},
        {pos: [15, 4, 3], state: "minecraft:cave_air"},
        {pos: [15, 4, 4], state: "minecraft:cave_air"},
        {pos: [15, 4, 5], state: "minecraft:cave_air"},
        {pos: [15, 4, 6], state: "minecraft:deepslate_bricks"},
        {pos: [16, 4, 2], state: "minecraft:deepslate_bricks"},
        {pos: [16, 4, 3], state: "minecraft:cave_air"},
        {pos: [16, 4, 4], state: "minecraft:cave_air"},
        {pos: [16, 4, 5], state: "minecraft:cave_air"},
        {pos: [16, 4, 6], state: "minecraft:deepslate_bricks"},
        {pos: [0, 5, 2], state: "minecraft:deepslate_bricks"},
        {pos: [0, 5, 3], state: "minecraft:deepslate_bricks"},
        {pos: [0, 5, 4], state: "minecraft:deepslate_bricks"},
        {pos: [0, 5, 5], state: "minecraft:deepslate_bricks"},
        {pos: [0, 5, 6], state: "minecraft:deepslate_bricks"},
        {pos: [1, 5, 2], state: "minecraft:deepslate_bricks"},
        {pos: [1, 5, 3], state: "minecraft:deepslate_bricks"},
        {pos: [1, 5, 4], state: "minecraft:deepslate_bricks"},
        {pos: [1, 5, 5], state: "minecraft:deepslate_bricks"},
        {pos: [1, 5, 6], state: "minecraft:deepslate_bricks"},
        {pos: [2, 5, 2], state: "minecraft:deepslate_bricks"},
        {pos: [2, 5, 3], state: "minecraft:deepslate_bricks"},
        {pos: [2, 5, 4], state: "minecraft:deepslate_bricks"},
        {pos: [2, 5, 5], state: "minecraft:deepslate_bricks"},
        {pos: [2, 5, 6], state: "minecraft:deepslate_bricks"},
        {pos: [3, 5, 0], state: "minecraft:deepslate_bricks"},
        {pos: [3, 5, 1], state: "minecraft:deepslate_bricks"},
        {pos: [3, 5, 2], state: "minecraft:deepslate_bricks"},
        {pos: [3, 5, 3], state: "minecraft:deepslate_bricks"},
        {pos: [3, 5, 4], state: "minecraft:deepslate_bricks"},
        {pos: [3, 5, 5], state: "minecraft:deepslate_bricks"},
        {pos: [3, 5, 6], state: "minecraft:deepslate_bricks"},
        {pos: [3, 5, 7], state: "minecraft:deepslate_bricks"},
        {pos: [3, 5, 8], state: "minecraft:deepslate_bricks"},
        {pos: [4, 5, 0], state: "minecraft:deepslate_bricks"},
        {pos: [4, 5, 1], state: "minecraft:deepslate_bricks"},
        {pos: [4, 5, 2], state: "minecraft:deepslate_bricks"},
        {pos: [4, 5, 3], state: "minecraft:deepslate_bricks"},
        {pos: [4, 5, 4], state: "minecraft:deepslate_bricks"},
        {pos: [4, 5, 5], state: "minecraft:deepslate_bricks"},
        {pos: [4, 5, 6], state: "minecraft:deepslate_bricks"},
        {pos: [4, 5, 7], state: "minecraft:deepslate_bricks"},
        {pos: [4, 5, 8], state: "minecraft:deepslate_bricks"},
        {pos: [5, 5, 0], state: "minecraft:deepslate_bricks"},
        {pos: [5, 5, 1], state: "minecraft:deepslate_bricks"},
        {pos: [5, 5, 2], state: "minecraft:deepslate_bricks"},
        {pos: [5, 5, 3], state: "minecraft:deepslate_brick_stairs{facing:west,half:bottom,shape:straight,waterlogged:false}"},
        {pos: [5, 5, 4], state: "minecraft:deepslate_brick_stairs{facing:west,half:bottom,shape:straight,waterlogged:false}"},
        {pos: [5, 5, 5], state: "minecraft:deepslate_brick_stairs{facing:west,half:bottom,shape:straight,waterlogged:false}"},
        {pos: [5, 5, 6], state: "minecraft:deepslate_bricks"},
        {pos: [5, 5, 7], state: "minecraft:deepslate_bricks"},
        {pos: [5, 5, 8], state: "minecraft:deepslate_bricks"},
        {pos: [6, 5, 0], state: "minecraft:deepslate_bricks"},
        {pos: [6, 5, 1], state: "minecraft:deepslate_bricks"},
        {pos: [6, 5, 2], state: "minecraft:deepslate_bricks"},
        {pos: [6, 5, 3], state: "minecraft:decorated_pot{cracked:false,facing:north,waterlogged:false}", nbt: {id: "minecraft:decorated_pot"}},
        {pos: [6, 5, 4], state: "minecraft:cave_air"},
        {pos: [6, 5, 5], state: "minecraft:candle{candles:4,lit:false,waterlogged:false}"},
        {pos: [6, 5, 6], state: "minecraft:deepslate_bricks"},
        {pos: [6, 5, 7], state: "minecraft:deepslate_bricks"},
        {pos: [6, 5, 8], state: "minecraft:deepslate_bricks"},
        {pos: [7, 5, 0], state: "minecraft:deepslate_bricks"},
        {pos: [7, 5, 1], state: "minecraft:chest{facing:south,type:single,waterlogged:false}", nbt: {Items: [], id: "minecraft:chest"}},
        {pos: [7, 5, 2], state: "minecraft:candle{candles:4,lit:false,waterlogged:false}"},
        {pos: [7, 5, 3], state: "minecraft:cave_air"},
        {pos: [7, 5, 4], state: "minecraft:candle{candles:4,lit:false,waterlogged:false}"},
        {pos: [7, 5, 5], state: "trailiertales:coffin{facing:north,part:head,state:inactive}", nbt: {id: "trailiertales:coffin"}},
        {pos: [7, 5, 6], state: "trailiertales:coffin{facing:north,part:foot,state:inactive}", nbt: {id: "trailiertales:coffin", max_active_light_level: 7, uuid: "d694f4c5-271c-4bfa-84a4-3c889e7cd63a"}},
        {pos: [7, 5, 7], state: "minecraft:cave_air"},
        {pos: [7, 5, 8], state: "minecraft:deepslate_bricks"},
        {pos: [8, 5, 0], state: "minecraft:deepslate_bricks"},
        {pos: [8, 5, 1], state: "minecraft:deepslate_bricks"},
        {pos: [8, 5, 2], state: "minecraft:deepslate_bricks"},
        {pos: [8, 5, 3], state: "minecraft:cave_air"},
        {pos: [8, 5, 4], state: "minecraft:cave_air"},
        {pos: [8, 5, 5], state: "minecraft:cave_air"},
        {pos: [8, 5, 6], state: "minecraft:deepslate_bricks"},
        {pos: [8, 5, 7], state: "minecraft:deepslate_bricks"},
        {pos: [8, 5, 8], state: "minecraft:deepslate_bricks"},
        {pos: [9, 5, 0], state: "minecraft:deepslate_bricks"},
        {pos: [9, 5, 1], state: "minecraft:deepslate_bricks"},
        {pos: [9, 5, 2], state: "minecraft:deepslate_bricks"},
        {pos: [9, 5, 3], state: "minecraft:cave_air"},
        {pos: [9, 5, 4], state: "minecraft:cave_air"},
        {pos: [9, 5, 5], state: "minecraft:cave_air"},
        {pos: [9, 5, 6], state: "minecraft:deepslate_bricks"},
        {pos: [9, 5, 7], state: "minecraft:deepslate_bricks"},
        {pos: [9, 5, 8], state: "minecraft:deepslate_bricks"},
        {pos: [10, 5, 0], state: "minecraft:deepslate_bricks"},
        {pos: [10, 5, 1], state: "minecraft:cave_air"},
        {pos: [10, 5, 2], state: "minecraft:cave_air"},
        {pos: [10, 5, 3], state: "minecraft:cave_air"},
        {pos: [10, 5, 4], state: "minecraft:cave_air"},
        {pos: [10, 5, 5], state: "minecraft:cave_air"},
        {pos: [10, 5, 6], state: "minecraft:cave_air"},
        {pos: [10, 5, 7], state: "minecraft:cave_air"},
        {pos: [10, 5, 8], state: "minecraft:deepslate_bricks"},
        {pos: [11, 5, 0], state: "minecraft:deepslate_bricks"},
        {pos: [11, 5, 1], state: "minecraft:deepslate_bricks"},
        {pos: [11, 5, 2], state: "minecraft:deepslate_bricks"},
        {pos: [11, 5, 3], state: "minecraft:cave_air"},
        {pos: [11, 5, 4], state: "minecraft:cave_air"},
        {pos: [11, 5, 5], state: "minecraft:cave_air"},
        {pos: [11, 5, 6], state: "minecraft:deepslate_bricks"},
        {pos: [11, 5, 7], state: "minecraft:deepslate_bricks"},
        {pos: [11, 5, 8], state: "minecraft:deepslate_bricks"},
        {pos: [12, 5, 0], state: "minecraft:deepslate_bricks"},
        {pos: [12, 5, 1], state: "minecraft:deepslate_bricks"},
        {pos: [12, 5, 2], state: "minecraft:deepslate_bricks"},
        {pos: [12, 5, 3], state: "minecraft:cave_air"},
        {pos: [12, 5, 4], state: "minecraft:cave_air"},
        {pos: [12, 5, 5], state: "minecraft:cave_air"},
        {pos: [12, 5, 6], state: "minecraft:deepslate_bricks"},
        {pos: [12, 5, 7], state: "minecraft:deepslate_bricks"},
        {pos: [12, 5, 8], state: "minecraft:deepslate_bricks"},
        {pos: [13, 5, 0], state: "minecraft:deepslate_bricks"},
        {pos: [13, 5, 1], state: "minecraft:deepslate_bricks"},
        {pos: [13, 5, 2], state: "minecraft:deepslate_bricks"},
        {pos: [13, 5, 3], state: "minecraft:cave_air"},
        {pos: [13, 5, 4], state: "minecraft:cave_air"},
        {pos: [13, 5, 5], state: "minecraft:cobweb"},
        {pos: [13, 5, 6], state: "minecraft:deepslate_bricks"},
        {pos: [13, 5, 7], state: "minecraft:deepslate_bricks"},
        {pos: [13, 5, 8], state: "minecraft:deepslate_bricks"},
        {pos: [14, 5, 0], state: "minecraft:deepslate_bricks"},
        {pos: [14, 5, 1], state: "minecraft:deepslate_bricks"},
        {pos: [14, 5, 2], state: "minecraft:deepslate_bricks"},
        {pos: [14, 5, 3], state: "minecraft:deepslate_brick_stairs{facing:east,half:top,shape:straight,waterlogged:false}"},
        {pos: [14, 5, 4], state: "minecraft:deepslate_brick_stairs{facing:east,half:top,shape:straight,waterlogged:false}"},
        {pos: [14, 5, 5], state: "minecraft:deepslate_brick_stairs{facing:east,half:top,shape:straight,waterlogged:false}"},
        {pos: [14, 5, 6], state: "minecraft:deepslate_bricks"},
        {pos: [14, 5, 7], state: "minecraft:deepslate_bricks"},
        {pos: [14, 5, 8], state: "minecraft:deepslate_bricks"},
        {pos: [15, 5, 2], state: "minecraft:deepslate_bricks"},
        {pos: [15, 5, 3], state: "minecraft:jigsaw{orientation:down_south}", nbt: {final_state: "minecraft:deepslate_bricks", id: "minecraft:jigsaw", joint: "rollable", name: "trailiertales:chain", placement_priority: 0, pool: "trailiertales:catacombs/decoration/chain_3", selection_priority: 0, target: "trailiertales:chain"}},
        {pos: [15, 5, 4], state: "minecraft:deepslate_bricks"},
        {pos: [15, 5, 5], state: "minecraft:jigsaw{orientation:down_north}", nbt: {final_state: "minecraft:deepslate_bricks", id: "minecraft:jigsaw", joint: "rollable", name: "trailiertales:chain", placement_priority: 0, pool: "trailiertales:catacombs/decoration/chain_3", selection_priority: 0, target: "trailiertales:chain"}},
        {pos: [15, 5, 6], state: "minecraft:deepslate_bricks"},
        {pos: [16, 5, 2], state: "minecraft:deepslate_bricks"},
        {pos: [16, 5, 3], state: "minecraft:jigsaw{orientation:down_south}", nbt: {final_state: "minecraft:deepslate_bricks", id: "minecraft:jigsaw", joint: "rollable", name: "trailiertales:chain", placement_priority: 0, pool: "trailiertales:catacombs/decoration/chain_3", selection_priority: 0, target: "trailiertales:chain"}},
        {pos: [16, 5, 4], state: "minecraft:deepslate_bricks"},
        {pos: [16, 5, 5], state: "minecraft:jigsaw{orientation:down_north}", nbt: {final_state: "minecraft:deepslate_bricks", id: "minecraft:jigsaw", joint: "rollable", name: "trailiertales:chain", placement_priority: 0, pool: "trailiertales:catacombs/decoration/chain_3", selection_priority: 0, target: "trailiertales:chain"}},
        {pos: [16, 5, 6], state: "minecraft:deepslate_bricks"},
        {pos: [0, 6, 2], state: "minecraft:deepslate_bricks"},
        {pos: [0, 6, 3], state: "minecraft:gravel"},
        {pos: [0, 6, 4], state: "minecraft:gravel"},
        {pos: [0, 6, 5], state: "minecraft:gravel"},
        {pos: [0, 6, 6], state: "minecraft:deepslate_bricks"},
        {pos: [1, 6, 2], state: "minecraft:deepslate_bricks"},
        {pos: [1, 6, 3], state: "minecraft:gravel"},
        {pos: [1, 6, 4], state: "minecraft:gravel"},
        {pos: [1, 6, 5], state: "minecraft:deepslate_bricks"},
        {pos: [1, 6, 6], state: "minecraft:deepslate_bricks"},
        {pos: [2, 6, 2], state: "minecraft:deepslate_bricks"},
        {pos: [2, 6, 3], state: "minecraft:deepslate_brick_stairs{facing:west,half:bottom,shape:straight,waterlogged:false}"},
        {pos: [2, 6, 4], state: "minecraft:deepslate_brick_stairs{facing:west,half:bottom,shape:straight,waterlogged:false}"},
        {pos: [2, 6, 5], state: "minecraft:deepslate_brick_stairs{facing:west,half:bottom,shape:straight,waterlogged:false}"},
        {pos: [2, 6, 6], state: "minecraft:deepslate_bricks"},
        {pos: [3, 6, 0], state: "minecraft:deepslate_bricks"},
        {pos: [3, 6, 1], state: "minecraft:deepslate_bricks"},
        {pos: [3, 6, 2], state: "minecraft:deepslate_bricks"},
        {pos: [3, 6, 3], state: "minecraft:candle{candles:4,lit:false,waterlogged:false}"},
        {pos: [3, 6, 4], state: "minecraft:cave_air"},
        {pos: [3, 6, 5], state: "minecraft:skeleton_skull{powered:false,rotation:0}", nbt: {id: "minecraft:skull"}},
        {pos: [3, 6, 6], state: "minecraft:deepslate_bricks"},
        {pos: [3, 6, 7], state: "minecraft:deepslate_bricks"},
        {pos: [3, 6, 8], state: "minecraft:deepslate_bricks"},
        {pos: [4, 6, 0], state: "minecraft:deepslate_bricks"},
        {pos: [4, 6, 1], state: "minecraft:candle{candles:4,lit:false,waterlogged:false}"},
        {pos: [4, 6, 2], state: "trailiertales:coffin{facing:north,part:head,state:inactive}", nbt: {id: "trailiertales:coffin"}},
        {pos: [4, 6, 3], state: "trailiertales:coffin{facing:north,part:foot,state:inactive}", nbt: {id: "trailiertales:coffin", max_active_light_level: 7, uuid: "a583c10b-f236-4bc5-aad4-8f6fae14b77e"}},
        {pos: [4, 6, 4], state: "minecraft:candle{candles:4,lit:false,waterlogged:false}"},
        {pos: [4, 6, 5], state: "minecraft:candle{candles:4,lit:false,waterlogged:false}"},
        {pos: [4, 6, 6], state: "minecraft:candle{candles:4,lit:false,waterlogged:false}"},
        {pos: [4, 6, 7], state: "minecraft:decorated_pot{cracked:false,facing:south,waterlogged:false}", nbt: {id: "minecraft:decorated_pot"}},
        {pos: [4, 6, 8], state: "minecraft:deepslate_bricks"},
        {pos: [5, 6, 0], state: "minecraft:deepslate_bricks"},
        {pos: [5, 6, 1], state: "minecraft:deepslate_bricks"},
        {pos: [5, 6, 2], state: "minecraft:deepslate_bricks"},
        {pos: [5, 6, 3], state: "minecraft:cave_air"},
        {pos: [5, 6, 4], state: "minecraft:cave_air"},
        {pos: [5, 6, 5], state: "minecraft:cave_air"},
        {pos: [5, 6, 6], state: "minecraft:deepslate_bricks"},
        {pos: [5, 6, 7], state: "minecraft:deepslate_bricks"},
        {pos: [5, 6, 8], state: "minecraft:deepslate_bricks"},
        {pos: [6, 6, 0], state: "minecraft:deepslate_bricks"},
        {pos: [6, 6, 1], state: "minecraft:deepslate_bricks"},
        {pos: [6, 6, 2], state: "minecraft:deepslate_bricks"},
        {pos: [6, 6, 3], state: "minecraft:cave_air"},
        {pos: [6, 6, 4], state: "minecraft:cave_air"},
        {pos: [6, 6, 5], state: "minecraft:cave_air"},
        {pos: [6, 6, 6], state: "minecraft:deepslate_bricks"},
        {pos: [6, 6, 7], state: "minecraft:deepslate_bricks"},
        {pos: [6, 6, 8], state: "minecraft:deepslate_bricks"},
        {pos: [7, 6, 0], state: "minecraft:deepslate_bricks"},
        {pos: [7, 6, 1], state: "minecraft:cave_air"},
        {pos: [7, 6, 2], state: "minecraft:cave_air"},
        {pos: [7, 6, 3], state: "minecraft:cave_air"},
        {pos: [7, 6, 4], state: "minecraft:cave_air"},
        {pos: [7, 6, 5], state: "minecraft:cave_air"},
        {pos: [7, 6, 6], state: "minecraft:cave_air"},
        {pos: [7, 6, 7], state: "minecraft:cave_air"},
        {pos: [7, 6, 8], state: "minecraft:deepslate_bricks"},
        {pos: [8, 6, 0], state: "minecraft:deepslate_bricks"},
        {pos: [8, 6, 1], state: "minecraft:deepslate_bricks"},
        {pos: [8, 6, 2], state: "minecraft:deepslate_bricks"},
        {pos: [8, 6, 3], state: "minecraft:cave_air"},
        {pos: [8, 6, 4], state: "minecraft:cave_air"},
        {pos: [8, 6, 5], state: "minecraft:cave_air"},
        {pos: [8, 6, 6], state: "minecraft:deepslate_bricks"},
        {pos: [8, 6, 7], state: "minecraft:deepslate_bricks"},
        {pos: [8, 6, 8], state: "minecraft:deepslate_bricks"},
        {pos: [9, 6, 0], state: "minecraft:deepslate_bricks"},
        {pos: [9, 6, 1], state: "minecraft:deepslate_bricks"},
        {pos: [9, 6, 2], state: "minecraft:deepslate_bricks"},
        {pos: [9, 6, 3], state: "minecraft:cave_air"},
        {pos: [9, 6, 4], state: "minecraft:cave_air"},
        {pos: [9, 6, 5], state: "minecraft:cave_air"},
        {pos: [9, 6, 6], state: "minecraft:deepslate_bricks"},
        {pos: [9, 6, 7], state: "minecraft:deepslate_bricks"},
        {pos: [9, 6, 8], state: "minecraft:deepslate_bricks"},
        {pos: [10, 6, 0], state: "minecraft:deepslate_bricks"},
        {pos: [10, 6, 1], state: "minecraft:deepslate_bricks"},
        {pos: [10, 6, 2], state: "minecraft:deepslate_bricks"},
        {pos: [10, 6, 3], state: "minecraft:cave_air"},
        {pos: [10, 6, 4], state: "minecraft:cave_air"},
        {pos: [10, 6, 5], state: "minecraft:cave_air"},
        {pos: [10, 6, 6], state: "minecraft:deepslate_bricks"},
        {pos: [10, 6, 7], state: "minecraft:deepslate_bricks"},
        {pos: [10, 6, 8], state: "minecraft:deepslate_bricks"},
        {pos: [11, 6, 0], state: "minecraft:deepslate_bricks"},
        {pos: [11, 6, 1], state: "minecraft:deepslate_bricks"},
        {pos: [11, 6, 2], state: "minecraft:deepslate_bricks"},
        {pos: [11, 6, 3], state: "minecraft:deepslate_brick_stairs{facing:east,half:top,shape:straight,waterlogged:false}"},
        {pos: [11, 6, 4], state: "minecraft:deepslate_brick_stairs{facing:east,half:top,shape:straight,waterlogged:false}"},
        {pos: [11, 6, 5], state: "minecraft:deepslate_brick_stairs{facing:east,half:top,shape:straight,waterlogged:false}"},
        {pos: [11, 6, 6], state: "minecraft:deepslate_bricks"},
        {pos: [11, 6, 7], state: "minecraft:deepslate_bricks"},
        {pos: [11, 6, 8], state: "minecraft:deepslate_bricks"},
        {pos: [12, 6, 2], state: "minecraft:deepslate_bricks"},
        {pos: [12, 6, 3], state: "minecraft:jigsaw{orientation:down_south}", nbt: {final_state: "minecraft:deepslate_bricks", id: "minecraft:jigsaw", joint: "rollable", name: "trailiertales:chain", placement_priority: 0, pool: "trailiertales:catacombs/decoration/chain_3", selection_priority: 0, target: "trailiertales:chain"}},
        {pos: [12, 6, 4], state: "minecraft:deepslate_bricks"},
        {pos: [12, 6, 5], state: "minecraft:jigsaw{orientation:down_north}", nbt: {final_state: "minecraft:deepslate_bricks", id: "minecraft:jigsaw", joint: "rollable", name: "trailiertales:chain", placement_priority: 0, pool: "trailiertales:catacombs/decoration/chain_3", selection_priority: 0, target: "trailiertales:chain"}},
        {pos: [12, 6, 6], state: "minecraft:deepslate_bricks"},
        {pos: [13, 6, 2], state: "minecraft:deepslate_bricks"},
        {pos: [13, 6, 3], state: "minecraft:jigsaw{orientation:down_south}", nbt: {final_state: "minecraft:deepslate_bricks", id: "minecraft:jigsaw", joint: "rollable", name: "trailiertales:chain", placement_priority: 0, pool: "trailiertales:catacombs/decoration/chain_3", selection_priority: 0, target: "trailiertales:chain"}},
        {pos: [13, 6, 4], state: "minecraft:deepslate_bricks"},
        {pos: [13, 6, 5], state: "minecraft:deepslate_bricks"},
        {pos: [13, 6, 6], state: "minecraft:deepslate_bricks"},
        {pos: [14, 6, 2], state: "minecraft:deepslate_bricks"},
        {pos: [14, 6, 3], state: "minecraft:deepslate_bricks"},
        {pos: [14, 6, 4], state: "minecraft:deepslate_bricks"},
        {pos: [14, 6, 5], state: "minecraft:deepslate_bricks"},
        {pos: [14, 6, 6], state: "minecraft:deepslate_bricks"},
        {pos: [0, 7, 2], state: "minecraft:deepslate_bricks"},
        {pos: [0, 7, 3], state: "minecraft:candle{candles:4,lit:false,waterlogged:false}"},
        {pos: [0, 7, 4], state: "minecraft:jigsaw{orientation:west_up}", nbt: {final_state: "minecraft:cave_air", id: "minecraft:jigsaw", joint: "rollable", name: "trailiertales:corridor", placement_priority: 0, pool: "trailiertales:catacombs/corridor_connector", selection_priority: 0, target: "trailiertales:corridor"}},
        {pos: [0, 7, 5], state: "minecraft:candle{candles:4,lit:false,waterlogged:false}"},
        {pos: [0, 7, 6], state: "minecraft:deepslate_bricks"},
        {pos: [1, 7, 2], state: "minecraft:deepslate_bricks"},
        {pos: [1, 7, 3], state: "minecraft:skeleton_skull{powered:false,rotation:8}", nbt: {id: "minecraft:skull"}},
        {pos: [1, 7, 4], state: "minecraft:cave_air"},
        {pos: [1, 7, 5], state: "minecraft:candle{candles:4,lit:false,waterlogged:false}"},
        {pos: [1, 7, 6], state: "minecraft:deepslate_bricks"},
        {pos: [2, 7, 2], state: "minecraft:deepslate_bricks"},
        {pos: [2, 7, 3], state: "minecraft:cave_air"},
        {pos: [2, 7, 4], state: "minecraft:cave_air"},
        {pos: [2, 7, 5], state: "minecraft:cave_air"},
        {pos: [2, 7, 6], state: "minecraft:deepslate_bricks"},
        {pos: [3, 7, 0], state: "minecraft:deepslate_bricks"},
        {pos: [3, 7, 1], state: "minecraft:deepslate_bricks"},
        {pos: [3, 7, 2], state: "minecraft:deepslate_bricks"},
        {pos: [3, 7, 3], state: "minecraft:cave_air"},
        {pos: [3, 7, 4], state: "minecraft:cave_air"},
        {pos: [3, 7, 5], state: "minecraft:cave_air"},
        {pos: [3, 7, 6], state: "minecraft:deepslate_bricks"},
        {pos: [3, 7, 7], state: "minecraft:deepslate_bricks"},
        {pos: [3, 7, 8], state: "minecraft:deepslate_bricks"},
        {pos: [4, 7, 0], state: "minecraft:deepslate_bricks"},
        {pos: [4, 7, 1], state: "minecraft:cave_air"},
        {pos: [4, 7, 2], state: "minecraft:cave_air"},
        {pos: [4, 7, 3], state: "minecraft:cave_air"},
        {pos: [4, 7, 4], state: "minecraft:cave_air"},
        {pos: [4, 7, 5], state: "minecraft:cave_air"},
        {pos: [4, 7, 6], state: "minecraft:cave_air"},
        {pos: [4, 7, 7], state: "minecraft:cave_air"},
        {pos: [4, 7, 8], state: "minecraft:deepslate_bricks"},
        {pos: [5, 7, 0], state: "minecraft:deepslate_bricks"},
        {pos: [5, 7, 1], state: "minecraft:deepslate_bricks"},
        {pos: [5, 7, 2], state: "minecraft:deepslate_bricks"},
        {pos: [5, 7, 3], state: "minecraft:cave_air"},
        {pos: [5, 7, 4], state: "minecraft:cave_air"},
        {pos: [5, 7, 5], state: "minecraft:cave_air"},
        {pos: [5, 7, 6], state: "minecraft:deepslate_bricks"},
        {pos: [5, 7, 7], state: "minecraft:deepslate_bricks"},
        {pos: [5, 7, 8], state: "minecraft:deepslate_bricks"},
        {pos: [6, 7, 0], state: "minecraft:deepslate_bricks"},
        {pos: [6, 7, 1], state: "minecraft:deepslate_bricks"},
        {pos: [6, 7, 2], state: "minecraft:deepslate_bricks"},
        {pos: [6, 7, 3], state: "minecraft:cave_air"},
        {pos: [6, 7, 4], state: "minecraft:cave_air"},
        {pos: [6, 7, 5], state: "minecraft:cave_air"},
        {pos: [6, 7, 6], state: "minecraft:deepslate_bricks"},
        {pos: [6, 7, 7], state: "minecraft:deepslate_bricks"},
        {pos: [6, 7, 8], state: "minecraft:deepslate_bricks"},
        {pos: [7, 7, 0], state: "minecraft:deepslate_bricks"},
        {pos: [7, 7, 1], state: "minecraft:deepslate_bricks"},
        {pos: [7, 7, 2], state: "minecraft:deepslate_bricks"},
        {pos: [7, 7, 3], state: "minecraft:cave_air"},
        {pos: [7, 7, 4], state: "minecraft:cave_air"},
        {pos: [7, 7, 5], state: "minecraft:cave_air"},
        {pos: [7, 7, 6], state: "minecraft:deepslate_bricks"},
        {pos: [7, 7, 7], state: "minecraft:deepslate_bricks"},
        {pos: [7, 7, 8], state: "minecraft:deepslate_bricks"},
        {pos: [8, 7, 0], state: "minecraft:deepslate_bricks"},
        {pos: [8, 7, 1], state: "minecraft:deepslate_bricks"},
        {pos: [8, 7, 2], state: "minecraft:deepslate_bricks"},
        {pos: [8, 7, 3], state: "minecraft:deepslate_brick_stairs{facing:east,half:top,shape:straight,waterlogged:false}"},
        {pos: [8, 7, 4], state: "minecraft:deepslate_brick_stairs{facing:east,half:top,shape:straight,waterlogged:false}"},
        {pos: [8, 7, 5], state: "minecraft:deepslate_brick_stairs{facing:east,half:top,shape:straight,waterlogged:false}"},
        {pos: [8, 7, 6], state: "minecraft:deepslate_bricks"},
        {pos: [8, 7, 7], state: "minecraft:deepslate_bricks"},
        {pos: [8, 7, 8], state: "minecraft:deepslate_bricks"},
        {pos: [9, 7, 2], state: "minecraft:deepslate_bricks"},
        {pos: [9, 7, 3], state: "minecraft:jigsaw{orientation:down_south}", nbt: {final_state: "minecraft:deepslate_bricks", id: "minecraft:jigsaw", joint: "rollable", name: "trailiertales:chain", placement_priority: 0, pool: "trailiertales:catacombs/decoration/chain_3", selection_priority: 0, target: "trailiertales:chain"}},
        {pos: [9, 7, 4], state: "minecraft:deepslate_bricks"},
        {pos: [9, 7, 5], state: "minecraft:jigsaw{orientation:down_north}", nbt: {final_state: "minecraft:deepslate_bricks", id: "minecraft:jigsaw", joint: "rollable", name: "trailiertales:chain", placement_priority: 0, pool: "trailiertales:catacombs/decoration/chain_3", selection_priority: 0, target: "trailiertales:chain"}},
        {pos: [9, 7, 6], state: "minecraft:deepslate_bricks"},
        {pos: [10, 7, 2], state: "minecraft:deepslate_bricks"},
        {pos: [10, 7, 3], state: "minecraft:jigsaw{orientation:down_south}", nbt: {final_state: "minecraft:deepslate_bricks", id: "minecraft:jigsaw", joint: "rollable", name: "trailiertales:chain", placement_priority: 0, pool: "trailiertales:catacombs/decoration/chain_3", selection_priority: 0, target: "trailiertales:chain"}},
        {pos: [10, 7, 4], state: "minecraft:deepslate_bricks"},
        {pos: [10, 7, 5], state: "minecraft:jigsaw{orientation:down_north}", nbt: {final_state: "minecraft:deepslate_bricks", id: "minecraft:jigsaw", joint: "rollable", name: "trailiertales:chain", placement_priority: 0, pool: "trailiertales:catacombs/decoration/chain_3", selection_priority: 0, target: "trailiertales:chain"}},
        {pos: [10, 7, 6], state: "minecraft:deepslate_bricks"},
        {pos: [11, 7, 2], state: "minecraft:deepslate_bricks"},
        {pos: [11, 7, 3], state: "minecraft:deepslate_bricks"},
        {pos: [11, 7, 4], state: "minecraft:deepslate_bricks"},
        {pos: [11, 7, 5], state: "minecraft:deepslate_bricks"},
        {pos: [11, 7, 6], state: "minecraft:deepslate_bricks"},
        {pos: [0, 8, 2], state: "minecraft:deepslate_bricks"},
        {pos: [0, 8, 3], state: "minecraft:cave_air"},
        {pos: [0, 8, 4], state: "minecraft:cave_air"},
        {pos: [0, 8, 5], state: "minecraft:cave_air"},
        {pos: [0, 8, 6], state: "minecraft:deepslate_bricks"},
        {pos: [1, 8, 2], state: "minecraft:deepslate_bricks"},
        {pos: [1, 8, 3], state: "minecraft:cave_air"},
        {pos: [1, 8, 4], state: "minecraft:cave_air"},
        {pos: [1, 8, 5], state: "minecraft:cave_air"},
        {pos: [1, 8, 6], state: "minecraft:deepslate_bricks"},
        {pos: [2, 8, 2], state: "minecraft:deepslate_bricks"},
        {pos: [2, 8, 3], state: "minecraft:cave_air"},
        {pos: [2, 8, 4], state: "minecraft:cave_air"},
        {pos: [2, 8, 5], state: "minecraft:cave_air"},
        {pos: [2, 8, 6], state: "minecraft:deepslate_bricks"},
        {pos: [3, 8, 0], state: "minecraft:deepslate_bricks"},
        {pos: [3, 8, 1], state: "minecraft:deepslate_bricks"},
        {pos: [3, 8, 2], state: "minecraft:deepslate_bricks"},
        {pos: [3, 8, 3], state: "minecraft:cave_air"},
        {pos: [3, 8, 4], state: "minecraft:cave_air"},
        {pos: [3, 8, 5], state: "minecraft:cave_air"},
        {pos: [3, 8, 6], state: "minecraft:deepslate_bricks"},
        {pos: [3, 8, 7], state: "minecraft:deepslate_bricks"},
        {pos: [3, 8, 8], state: "minecraft:deepslate_bricks"},
        {pos: [4, 8, 0], state: "minecraft:deepslate_bricks"},
        {pos: [4, 8, 1], state: "minecraft:deepslate_bricks"},
        {pos: [4, 8, 2], state: "minecraft:deepslate_bricks"},
        {pos: [4, 8, 3], state: "minecraft:cobweb"},
        {pos: [4, 8, 4], state: "minecraft:cave_air"},
        {pos: [4, 8, 5], state: "minecraft:cave_air"},
        {pos: [4, 8, 6], state: "minecraft:deepslate_bricks"},
        {pos: [4, 8, 7], state: "minecraft:deepslate_bricks"},
        {pos: [4, 8, 8], state: "minecraft:deepslate_bricks"},
        {pos: [5, 8, 0], state: "minecraft:deepslate_bricks"},
        {pos: [5, 8, 1], state: "minecraft:deepslate_bricks"},
        {pos: [5, 8, 2], state: "minecraft:deepslate_bricks"},
        {pos: [5, 8, 3], state: "minecraft:deepslate_brick_stairs{facing:east,half:top,shape:straight,waterlogged:false}"},
        {pos: [5, 8, 4], state: "minecraft:deepslate_brick_stairs{facing:east,half:top,shape:straight,waterlogged:false}"},
        {pos: [5, 8, 5], state: "minecraft:deepslate_brick_stairs{facing:east,half:top,shape:straight,waterlogged:false}"},
        {pos: [5, 8, 6], state: "minecraft:deepslate_bricks"},
        {pos: [5, 8, 7], state: "minecraft:deepslate_bricks"},
        {pos: [5, 8, 8], state: "minecraft:deepslate_bricks"},
        {pos: [6, 8, 2], state: "minecraft:deepslate_bricks"},
        {pos: [6, 8, 3], state: "minecraft:deepslate_bricks"},
        {pos: [6, 8, 4], state: "minecraft:deepslate_bricks"},
        {pos: [6, 8, 5], state: "minecraft:jigsaw{orientation:down_north}", nbt: {final_state: "minecraft:deepslate_bricks", id: "minecraft:jigsaw", joint: "rollable", name: "trailiertales:chain", placement_priority: 0, pool: "trailiertales:catacombs/decoration/chain_3", selection_priority: 0, target: "trailiertales:chain"}},
        {pos: [6, 8, 6], state: "minecraft:deepslate_bricks"},
        {pos: [7, 8, 2], state: "minecraft:deepslate_bricks"},
        {pos: [7, 8, 3], state: "minecraft:jigsaw{orientation:down_south}", nbt: {final_state: "minecraft:deepslate_bricks", id: "minecraft:jigsaw", joint: "rollable", name: "trailiertales:chain", placement_priority: 0, pool: "trailiertales:catacombs/decoration/chain_3", selection_priority: 0, target: "trailiertales:chain"}},
        {pos: [7, 8, 4], state: "minecraft:deepslate_bricks"},
        {pos: [7, 8, 5], state: "minecraft:jigsaw{orientation:down_north}", nbt: {final_state: "minecraft:deepslate_bricks", id: "minecraft:jigsaw", joint: "rollable", name: "trailiertales:chain", placement_priority: 0, pool: "trailiertales:catacombs/decoration/chain_2", selection_priority: 0, target: "trailiertales:chain"}},
        {pos: [7, 8, 6], state: "minecraft:deepslate_bricks"},
        {pos: [8, 8, 2], state: "minecraft:deepslate_bricks"},
        {pos: [8, 8, 3], state: "minecraft:deepslate_bricks"},
        {pos: [8, 8, 4], state: "minecraft:deepslate_bricks"},
        {pos: [8, 8, 5], state: "minecraft:deepslate_bricks"},
        {pos: [8, 8, 6], state: "minecraft:deepslate_bricks"},
        {pos: [0, 9, 2], state: "minecraft:deepslate_bricks"},
        {pos: [0, 9, 3], state: "minecraft:cave_air"},
        {pos: [0, 9, 4], state: "minecraft:cave_air"},
        {pos: [0, 9, 5], state: "minecraft:cave_air"},
        {pos: [0, 9, 6], state: "minecraft:deepslate_bricks"},
        {pos: [1, 9, 2], state: "minecraft:deepslate_bricks"},
        {pos: [1, 9, 3], state: "minecraft:cave_air"},
        {pos: [1, 9, 4], state: "minecraft:cave_air"},
        {pos: [1, 9, 5], state: "minecraft:cobweb"},
        {pos: [1, 9, 6], state: "minecraft:deepslate_bricks"},
        {pos: [2, 9, 2], state: "minecraft:deepslate_bricks"},
        {pos: [2, 9, 3], state: "minecraft:deepslate_brick_stairs{facing:east,half:top,shape:straight,waterlogged:false}"},
        {pos: [2, 9, 4], state: "minecraft:deepslate_brick_stairs{facing:east,half:top,shape:straight,waterlogged:false}"},
        {pos: [2, 9, 5], state: "minecraft:deepslate_brick_stairs{facing:east,half:top,shape:straight,waterlogged:false}"},
        {pos: [2, 9, 6], state: "minecraft:deepslate_bricks"},
        {pos: [3, 9, 2], state: "minecraft:deepslate_bricks"},
        {pos: [3, 9, 3], state: "minecraft:jigsaw{orientation:down_south}", nbt: {final_state: "minecraft:deepslate_bricks", id: "minecraft:jigsaw", joint: "rollable", name: "trailiertales:chain", placement_priority: 0, pool: "trailiertales:catacombs/decoration/chain_3", selection_priority: 0, target: "trailiertales:chain"}},
        {pos: [3, 9, 4], state: "minecraft:deepslate_bricks"},
        {pos: [3, 9, 5], state: "minecraft:deepslate_bricks"},
        {pos: [3, 9, 6], state: "minecraft:deepslate_bricks"},
        {pos: [4, 9, 2], state: "minecraft:deepslate_bricks"},
        {pos: [4, 9, 3], state: "minecraft:deepslate_bricks"},
        {pos: [4, 9, 4], state: "minecraft:deepslate_bricks"},
        {pos: [4, 9, 5], state: "minecraft:jigsaw{orientation:down_west}", nbt: {final_state: "minecraft:deepslate_bricks", id: "minecraft:jigsaw", joint: "rollable", name: "trailiertales:chain", placement_priority: 0, pool: "trailiertales:catacombs/decoration/chain_3", selection_priority: 0, target: "trailiertales:chain"}},
        {pos: [4, 9, 6], state: "minecraft:deepslate_bricks"},
        {pos: [5, 9, 2], state: "minecraft:deepslate_bricks"},
        {pos: [5, 9, 3], state: "minecraft:deepslate_bricks"},
        {pos: [5, 9, 4], state: "minecraft:deepslate_bricks"},
        {pos: [5, 9, 5], state: "minecraft:deepslate_bricks"},
        {pos: [5, 9, 6], state: "minecraft:deepslate_bricks"},
        {pos: [0, 10, 2], state: "minecraft:deepslate_bricks"},
        {pos: [0, 10, 3], state: "minecraft:deepslate_bricks"},
        {pos: [0, 10, 4], state: "minecraft:deepslate_bricks"},
        {pos: [0, 10, 5], state: "minecraft:jigsaw{orientation:down_north}", nbt: {final_state: "minecraft:deepslate_bricks", id: "minecraft:jigsaw", joint: "rollable", name: "trailiertales:chain", placement_priority: 0, pool: "trailiertales:catacombs/decoration/chain_3", selection_priority: 0, target: "trailiertales:chain"}},
        {pos: [0, 10, 6], state: "minecraft:deepslate_bricks"},
        {pos: [1, 10, 2], state: "minecraft:deepslate_bricks"},
        {pos: [1, 10, 3], state: "minecraft:jigsaw{orientation:down_south}", nbt: {final_state: "minecraft:deepslate_bricks", id: "minecraft:jigsaw", joint: "rollable", name: "trailiertales:chain", placement_priority: 0, pool: "trailiertales:catacombs/decoration/chain_3", selection_priority: 0, target: "trailiertales:chain"}},
        {pos: [1, 10, 4], state: "minecraft:deepslate_bricks"},
        {pos: [1, 10, 5], state: "minecraft:deepslate_bricks"},
        {pos: [1, 10, 6], state: "minecraft:deepslate_bricks"},
        {pos: [2, 10, 2], state: "minecraft:deepslate_bricks"},
        {pos: [2, 10, 3], state: "minecraft:deepslate_bricks"},
        {pos: [2, 10, 4], state: "minecraft:deepslate_bricks"},
        {pos: [2, 10, 5], state: "minecraft:deepslate_bricks"},
        {pos: [2, 10, 6], state: "minecraft:deepslate_bricks"}
    ],
    entities: [],
    palette: [
        "minecraft:deepslate_bricks",
        "minecraft:gravel",
        "minecraft:deepslate_brick_stairs{facing:west,half:bottom,shape:straight,waterlogged:false}",
        "minecraft:cave_air",
        "minecraft:candle{candles:4,lit:false,waterlogged:false}",
        "minecraft:cobweb",
        "minecraft:deepslate_brick_stairs{facing:east,half:top,shape:straight,waterlogged:false}",
        "minecraft:decorated_pot{cracked:false,facing:east,waterlogged:false}",
        "minecraft:jigsaw{orientation:east_up}",
        "minecraft:decorated_pot{cracked:false,facing:south,waterlogged:false}",
        "minecraft:chest{facing:south,type:single,waterlogged:false}",
        "trailiertales:coffin{facing:south,part:foot,state:inactive}",
        "trailiertales:coffin{facing:south,part:head,state:inactive}",
        "minecraft:skeleton_skull{powered:false,rotation:8}",
        "trailiertales:coffin{facing:north,part:head,state:inactive}",
        "trailiertales:coffin{facing:north,part:foot,state:inactive}",
        "minecraft:chest{facing:north,type:single,waterlogged:false}",
        "minecraft:decorated_pot{cracked:false,facing:north,waterlogged:false}",
        "minecraft:jigsaw{orientation:down_south}",
        "minecraft:jigsaw{orientation:down_north}",
        "minecraft:skeleton_skull{powered:false,rotation:0}",
        "minecraft:jigsaw{orientation:west_up}",
        "minecraft:jigsaw{orientation:down_west}"
    ],
    trailiertales_DataVersion: 3
}
