{
    DataVersion: 3953,
    size: [25, 11, 18],
    data: [
        {pos: [0, 0, 0], state: "minecraft:deepslate{axis:y}"},
        {pos: [0, 0, 1], state: "minecraft:deepslate{axis:y}"},
        {pos: [0, 0, 2], state: "minecraft:deepslate{axis:y}"},
        {pos: [0, 0, 3], state: "minecraft:deepslate{axis:y}"},
        {pos: [0, 0, 4], state: "minecraft:deepslate{axis:y}"},
        {pos: [0, 0, 5], state: "minecraft:deepslate{axis:y}"},
        {pos: [0, 0, 6], state: "minecraft:deepslate{axis:y}"},
        {pos: [0, 0, 7], state: "minecraft:deepslate{axis:y}"},
        {pos: [0, 0, 8], state: "minecraft:deepslate{axis:y}"},
        {pos: [0, 0, 9], state: "minecraft:deepslate{axis:y}"},
        {pos: [0, 0, 10], state: "minecraft:deepslate{axis:y}"},
        {pos: [0, 0, 11], state: "minecraft:deepslate{axis:y}"},
        {pos: [0, 0, 12], state: "minecraft:deepslate{axis:y}"},
        {pos: [0, 0, 13], state: "minecraft:deepslate{axis:y}"},
        {pos: [0, 0, 14], state: "minecraft:deepslate{axis:y}"},
        {pos: [0, 0, 15], state: "minecraft:deepslate{axis:y}"},
        {pos: [1, 0, 0], state: "minecraft:deepslate{axis:y}"},
        {pos: [1, 0, 1], state: "minecraft:deepslate{axis:y}"},
        {pos: [1, 0, 2], state: "minecraft:deepslate{axis:y}"},
        {pos: [1, 0, 3], state: "minecraft:deepslate{axis:y}"},
        {pos: [1, 0, 4], state: "minecraft:deepslate{axis:y}"},
        {pos: [1, 0, 5], state: "minecraft:deepslate{axis:y}"},
        {pos: [1, 0, 6], state: "minecraft:deepslate{axis:y}"},
        {pos: [1, 0, 7], state: "minecraft:deepslate{axis:y}"},
        {pos: [1, 0, 8], state: "minecraft:deepslate{axis:y}"},
        {pos: [1, 0, 9], state: "minecraft:deepslate{axis:y}"},
        {pos: [1, 0, 10], state: "minecraft:deepslate{axis:y}"},
        {pos: [1, 0, 11], state: "minecraft:deepslate{axis:y}"},
        {pos: [1, 0, 12], state: "minecraft:deepslate{axis:y}"},
        {pos: [1, 0, 13], state: "minecraft:deepslate{axis:y}"},
        {pos: [1, 0, 14], state: "minecraft:deepslate{axis:y}"},
        {pos: [1, 0, 15], state: "minecraft:deepslate{axis:y}"},
        {pos: [2, 0, 0], state: "minecraft:deepslate{axis:y}"},
        {pos: [2, 0, 1], state: "minecraft:deepslate{axis:y}"},
        {pos: [2, 0, 2], state: "minecraft:deepslate{axis:y}"},
        {pos: [2, 0, 3], state: "minecraft:deepslate{axis:y}"},
        {pos: [2, 0, 4], state: "minecraft:deepslate{axis:y}"},
        {pos: [2, 0, 5], state: "minecraft:deepslate{axis:y}"},
        {pos: [2, 0, 6], state: "minecraft:deepslate{axis:y}"},
        {pos: [2, 0, 7], state: "minecraft:deepslate{axis:y}"},
        {pos: [2, 0, 8], state: "minecraft:deepslate{axis:y}"},
        {pos: [2, 0, 9], state: "minecraft:deepslate{axis:y}"},
        {pos: [2, 0, 10], state: "minecraft:deepslate{axis:y}"},
        {pos: [2, 0, 11], state: "minecraft:deepslate{axis:y}"},
        {pos: [2, 0, 12], state: "minecraft:deepslate{axis:y}"},
        {pos: [2, 0, 13], state: "minecraft:deepslate{axis:y}"},
        {pos: [2, 0, 14], state: "minecraft:deepslate{axis:y}"},
        {pos: [2, 0, 15], state: "minecraft:deepslate{axis:y}"},
        {pos: [3, 0, 0], state: "minecraft:deepslate{axis:y}"},
        {pos: [3, 0, 1], state: "minecraft:deepslate{axis:y}"},
        {pos: [3, 0, 2], state: "minecraft:deepslate{axis:y}"},
        {pos: [3, 0, 3], state: "minecraft:deepslate{axis:y}"},
        {pos: [3, 0, 4], state: "minecraft:deepslate{axis:y}"},
        {pos: [3, 0, 5], state: "minecraft:deepslate{axis:y}"},
        {pos: [3, 0, 6], state: "minecraft:deepslate{axis:y}"},
        {pos: [3, 0, 7], state: "minecraft:deepslate{axis:y}"},
        {pos: [3, 0, 8], state: "minecraft:deepslate{axis:y}"},
        {pos: [3, 0, 9], state: "minecraft:deepslate{axis:y}"},
        {pos: [3, 0, 10], state: "minecraft:deepslate{axis:y}"},
        {pos: [3, 0, 11], state: "minecraft:deepslate{axis:y}"},
        {pos: [3, 0, 12], state: "minecraft:deepslate{axis:y}"},
        {pos: [3, 0, 13], state: "minecraft:deepslate{axis:y}"},
        {pos: [3, 0, 14], state: "minecraft:deepslate{axis:y}"},
        {pos: [3, 0, 15], state: "minecraft:deepslate{axis:y}"},
        {pos: [4, 0, 0], state: "minecraft:deepslate{axis:y}"},
        {pos: [4, 0, 1], state: "minecraft:deepslate{axis:y}"},
        {pos: [4, 0, 2], state: "minecraft:deepslate{axis:y}"},
        {pos: [4, 0, 3], state: "minecraft:deepslate{axis:y}"},
        {pos: [4, 0, 4], state: "minecraft:deepslate{axis:y}"},
        {pos: [4, 0, 5], state: "minecraft:deepslate{axis:y}"},
        {pos: [4, 0, 6], state: "minecraft:deepslate{axis:y}"},
        {pos: [4, 0, 7], state: "minecraft:deepslate{axis:y}"},
        {pos: [4, 0, 8], state: "minecraft:deepslate{axis:y}"},
        {pos: [4, 0, 9], state: "minecraft:deepslate{axis:y}"},
        {pos: [4, 0, 10], state: "minecraft:deepslate{axis:y}"},
        {pos: [4, 0, 11], state: "minecraft:deepslate{axis:y}"},
        {pos: [4, 0, 12], state: "minecraft:deepslate{axis:y}"},
        {pos: [4, 0, 13], state: "minecraft:deepslate{axis:y}"},
        {pos: [4, 0, 14], state: "minecraft:deepslate{axis:y}"},
        {pos: [4, 0, 15], state: "minecraft:deepslate{axis:y}"},
        {pos: [5, 0, 0], state: "minecraft:deepslate{axis:y}"},
        {pos: [5, 0, 1], state: "minecraft:deepslate{axis:y}"},
        {pos: [5, 0, 2], state: "minecraft:deepslate{axis:y}"},
        {pos: [5, 0, 3], state: "minecraft:deepslate{axis:y}"},
        {pos: [5, 0, 4], state: "minecraft:deepslate{axis:y}"},
        {pos: [5, 0, 5], state: "minecraft:deepslate{axis:y}"},
        {pos: [5, 0, 6], state: "minecraft:deepslate{axis:y}"},
        {pos: [5, 0, 7], state: "minecraft:deepslate{axis:y}"},
        {pos: [5, 0, 8], state: "minecraft:deepslate{axis:y}"},
        {pos: [5, 0, 9], state: "minecraft:deepslate{axis:y}"},
        {pos: [5, 0, 10], state: "minecraft:deepslate{axis:y}"},
        {pos: [5, 0, 11], state: "minecraft:deepslate{axis:y}"},
        {pos: [5, 0, 12], state: "minecraft:deepslate{axis:y}"},
        {pos: [5, 0, 13], state: "minecraft:deepslate{axis:y}"},
        {pos: [5, 0, 14], state: "minecraft:deepslate{axis:y}"},
        {pos: [5, 0, 15], state: "minecraft:deepslate{axis:y}"},
        {pos: [6, 0, 0], state: "minecraft:deepslate{axis:y}"},
        {pos: [6, 0, 1], state: "minecraft:deepslate{axis:y}"},
        {pos: [6, 0, 2], state: "minecraft:deepslate{axis:y}"},
        {pos: [6, 0, 3], state: "minecraft:deepslate{axis:y}"},
        {pos: [6, 0, 4], state: "minecraft:deepslate{axis:y}"},
        {pos: [6, 0, 5], state: "minecraft:deepslate{axis:y}"},
        {pos: [6, 0, 6], state: "minecraft:deepslate{axis:y}"},
        {pos: [6, 0, 7], state: "minecraft:deepslate{axis:y}"},
        {pos: [6, 0, 8], state: "minecraft:deepslate{axis:y}"},
        {pos: [6, 0, 9], state: "minecraft:deepslate{axis:y}"},
        {pos: [6, 0, 10], state: "minecraft:deepslate{axis:y}"},
        {pos: [6, 0, 11], state: "minecraft:deepslate{axis:y}"},
        {pos: [6, 0, 12], state: "minecraft:deepslate{axis:y}"},
        {pos: [6, 0, 13], state: "minecraft:deepslate{axis:y}"},
        {pos: [6, 0, 14], state: "minecraft:deepslate{axis:y}"},
        {pos: [6, 0, 15], state: "minecraft:deepslate{axis:y}"},
        {pos: [7, 0, 0], state: "minecraft:deepslate{axis:y}"},
        {pos: [7, 0, 1], state: "minecraft:deepslate{axis:y}"},
        {pos: [7, 0, 2], state: "minecraft:deepslate{axis:y}"},
        {pos: [7, 0, 3], state: "minecraft:deepslate{axis:y}"},
        {pos: [7, 0, 4], state: "minecraft:deepslate{axis:y}"},
        {pos: [7, 0, 5], state: "minecraft:deepslate{axis:y}"},
        {pos: [7, 0, 6], state: "minecraft:deepslate{axis:y}"},
        {pos: [7, 0, 7], state: "minecraft:deepslate{axis:y}"},
        {pos: [7, 0, 8], state: "minecraft:deepslate{axis:y}"},
        {pos: [7, 0, 9], state: "minecraft:deepslate{axis:y}"},
        {pos: [7, 0, 10], state: "minecraft:deepslate{axis:y}"},
        {pos: [7, 0, 11], state: "minecraft:deepslate{axis:y}"},
        {pos: [7, 0, 12], state: "minecraft:deepslate{axis:y}"},
        {pos: [7, 0, 13], state: "minecraft:deepslate{axis:y}"},
        {pos: [7, 0, 14], state: "minecraft:deepslate{axis:y}"},
        {pos: [7, 0, 15], state: "minecraft:deepslate{axis:y}"},
        {pos: [8, 0, 0], state: "minecraft:deepslate{axis:y}"},
        {pos: [8, 0, 1], state: "minecraft:deepslate{axis:y}"},
        {pos: [8, 0, 2], state: "minecraft:deepslate{axis:y}"},
        {pos: [8, 0, 3], state: "minecraft:deepslate{axis:y}"},
        {pos: [8, 0, 4], state: "minecraft:deepslate{axis:y}"},
        {pos: [8, 0, 5], state: "minecraft:deepslate{axis:y}"},
        {pos: [8, 0, 6], state: "minecraft:deepslate{axis:y}"},
        {pos: [8, 0, 7], state: "minecraft:deepslate{axis:y}"},
        {pos: [8, 0, 8], state: "minecraft:deepslate{axis:y}"},
        {pos: [8, 0, 9], state: "minecraft:deepslate{axis:y}"},
        {pos: [8, 0, 10], state: "minecraft:deepslate{axis:y}"},
        {pos: [8, 0, 11], state: "minecraft:deepslate{axis:y}"},
        {pos: [8, 0, 12], state: "minecraft:deepslate{axis:y}"},
        {pos: [8, 0, 13], state: "minecraft:deepslate{axis:y}"},
        {pos: [8, 0, 14], state: "minecraft:deepslate{axis:y}"},
        {pos: [8, 0, 15], state: "minecraft:deepslate{axis:y}"},
        {pos: [9, 0, 0], state: "minecraft:deepslate{axis:y}"},
        {pos: [9, 0, 1], state: "minecraft:deepslate{axis:y}"},
        {pos: [9, 0, 2], state: "minecraft:deepslate{axis:y}"},
        {pos: [9, 0, 3], state: "minecraft:deepslate{axis:y}"},
        {pos: [9, 0, 4], state: "minecraft:deepslate{axis:y}"},
        {pos: [9, 0, 5], state: "minecraft:deepslate{axis:y}"},
        {pos: [9, 0, 6], state: "minecraft:deepslate{axis:y}"},
        {pos: [9, 0, 7], state: "minecraft:deepslate{axis:y}"},
        {pos: [9, 0, 8], state: "minecraft:deepslate{axis:y}"},
        {pos: [9, 0, 9], state: "minecraft:deepslate{axis:y}"},
        {pos: [9, 0, 10], state: "minecraft:deepslate{axis:y}"},
        {pos: [9, 0, 11], state: "minecraft:deepslate{axis:y}"},
        {pos: [9, 0, 12], state: "minecraft:deepslate{axis:y}"},
        {pos: [9, 0, 13], state: "minecraft:deepslate{axis:y}"},
        {pos: [9, 0, 14], state: "minecraft:deepslate{axis:y}"},
        {pos: [9, 0, 15], state: "minecraft:deepslate{axis:y}"},
        {pos: [10, 0, 0], state: "minecraft:deepslate{axis:y}"},
        {pos: [10, 0, 1], state: "minecraft:deepslate{axis:y}"},
        {pos: [10, 0, 2], state: "minecraft:deepslate{axis:y}"},
        {pos: [10, 0, 3], state: "minecraft:deepslate{axis:y}"},
        {pos: [10, 0, 4], state: "minecraft:deepslate{axis:y}"},
        {pos: [10, 0, 5], state: "minecraft:deepslate{axis:y}"},
        {pos: [10, 0, 6], state: "minecraft:deepslate{axis:y}"},
        {pos: [10, 0, 7], state: "minecraft:deepslate{axis:y}"},
        {pos: [10, 0, 8], state: "minecraft:deepslate{axis:y}"},
        {pos: [10, 0, 9], state: "minecraft:deepslate{axis:y}"},
        {pos: [10, 0, 10], state: "minecraft:deepslate{axis:y}"},
        {pos: [10, 0, 11], state: "minecraft:deepslate{axis:y}"},
        {pos: [10, 0, 12], state: "minecraft:deepslate{axis:y}"},
        {pos: [10, 0, 13], state: "minecraft:deepslate{axis:y}"},
        {pos: [10, 0, 14], state: "minecraft:deepslate{axis:y}"},
        {pos: [10, 0, 15], state: "minecraft:deepslate{axis:y}"},
        {pos: [10, 0, 16], state: "minecraft:deepslate{axis:y}"},
        {pos: [10, 0, 17], state: "minecraft:deepslate{axis:y}"},
        {pos: [11, 0, 0], state: "minecraft:deepslate{axis:y}"},
        {pos: [11, 0, 1], state: "minecraft:deepslate{axis:y}"},
        {pos: [11, 0, 2], state: "minecraft:deepslate{axis:y}"},
        {pos: [11, 0, 3], state: "minecraft:deepslate{axis:y}"},
        {pos: [11, 0, 4], state: "minecraft:deepslate{axis:y}"},
        {pos: [11, 0, 5], state: "minecraft:deepslate{axis:y}"},
        {pos: [11, 0, 6], state: "minecraft:deepslate{axis:y}"},
        {pos: [11, 0, 7], state: "minecraft:deepslate{axis:y}"},
        {pos: [11, 0, 8], state: "minecraft:deepslate{axis:y}"},
        {pos: [11, 0, 9], state: "minecraft:deepslate{axis:y}"},
        {pos: [11, 0, 10], state: "minecraft:deepslate{axis:y}"},
        {pos: [11, 0, 11], state: "minecraft:deepslate{axis:y}"},
        {pos: [11, 0, 12], state: "minecraft:deepslate{axis:y}"},
        {pos: [11, 0, 13], state: "minecraft:deepslate{axis:y}"},
        {pos: [11, 0, 14], state: "minecraft:deepslate{axis:y}"},
        {pos: [11, 0, 15], state: "minecraft:deepslate{axis:y}"},
        {pos: [11, 0, 16], state: "minecraft:deepslate{axis:y}"},
        {pos: [11, 0, 17], state: "minecraft:deepslate{axis:y}"},
        {pos: [12, 0, 0], state: "minecraft:deepslate{axis:y}"},
        {pos: [12, 0, 1], state: "minecraft:deepslate{axis:y}"},
        {pos: [12, 0, 2], state: "minecraft:deepslate{axis:y}"},
        {pos: [12, 0, 3], state: "minecraft:deepslate{axis:y}"},
        {pos: [12, 0, 4], state: "minecraft:deepslate{axis:y}"},
        {pos: [12, 0, 5], state: "minecraft:deepslate{axis:y}"},
        {pos: [12, 0, 6], state: "minecraft:deepslate{axis:y}"},
        {pos: [12, 0, 7], state: "minecraft:deepslate{axis:y}"},
        {pos: [12, 0, 8], state: "minecraft:deepslate{axis:y}"},
        {pos: [12, 0, 9], state: "minecraft:deepslate{axis:y}"},
        {pos: [12, 0, 10], state: "minecraft:deepslate{axis:y}"},
        {pos: [12, 0, 11], state: "minecraft:deepslate{axis:y}"},
        {pos: [12, 0, 12], state: "minecraft:deepslate{axis:y}"},
        {pos: [12, 0, 13], state: "minecraft:deepslate{axis:y}"},
        {pos: [12, 0, 14], state: "minecraft:deepslate{axis:y}"},
        {pos: [12, 0, 15], state: "minecraft:deepslate{axis:y}"},
        {pos: [12, 0, 16], state: "minecraft:deepslate{axis:y}"},
        {pos: [12, 0, 17], state: "minecraft:deepslate{axis:y}"},
        {pos: [13, 0, 0], state: "minecraft:deepslate{axis:y}"},
        {pos: [13, 0, 1], state: "minecraft:deepslate{axis:y}"},
        {pos: [13, 0, 2], state: "minecraft:deepslate{axis:y}"},
        {pos: [13, 0, 3], state: "minecraft:deepslate{axis:y}"},
        {pos: [13, 0, 4], state: "minecraft:deepslate{axis:y}"},
        {pos: [13, 0, 5], state: "minecraft:deepslate{axis:y}"},
        {pos: [13, 0, 6], state: "minecraft:deepslate{axis:y}"},
        {pos: [13, 0, 7], state: "minecraft:deepslate{axis:y}"},
        {pos: [13, 0, 8], state: "minecraft:deepslate{axis:y}"},
        {pos: [13, 0, 9], state: "minecraft:deepslate{axis:y}"},
        {pos: [13, 0, 10], state: "minecraft:deepslate{axis:y}"},
        {pos: [13, 0, 11], state: "minecraft:deepslate{axis:y}"},
        {pos: [13, 0, 12], state: "minecraft:deepslate{axis:y}"},
        {pos: [13, 0, 13], state: "minecraft:deepslate{axis:y}"},
        {pos: [13, 0, 14], state: "minecraft:deepslate{axis:y}"},
        {pos: [13, 0, 15], state: "minecraft:deepslate{axis:y}"},
        {pos: [13, 0, 16], state: "minecraft:deepslate{axis:y}"},
        {pos: [13, 0, 17], state: "minecraft:deepslate{axis:y}"},
        {pos: [14, 0, 0], state: "minecraft:deepslate{axis:y}"},
        {pos: [14, 0, 1], state: "minecraft:deepslate{axis:y}"},
        {pos: [14, 0, 2], state: "minecraft:deepslate{axis:y}"},
        {pos: [14, 0, 3], state: "minecraft:deepslate{axis:y}"},
        {pos: [14, 0, 4], state: "minecraft:deepslate{axis:y}"},
        {pos: [14, 0, 5], state: "minecraft:deepslate{axis:y}"},
        {pos: [14, 0, 6], state: "minecraft:deepslate{axis:y}"},
        {pos: [14, 0, 7], state: "minecraft:deepslate{axis:y}"},
        {pos: [14, 0, 8], state: "minecraft:deepslate{axis:y}"},
        {pos: [14, 0, 9], state: "minecraft:deepslate{axis:y}"},
        {pos: [14, 0, 10], state: "minecraft:deepslate{axis:y}"},
        {pos: [14, 0, 11], state: "minecraft:deepslate{axis:y}"},
        {pos: [14, 0, 12], state: "minecraft:deepslate{axis:y}"},
        {pos: [14, 0, 13], state: "minecraft:deepslate{axis:y}"},
        {pos: [14, 0, 14], state: "minecraft:deepslate{axis:y}"},
        {pos: [14, 0, 15], state: "minecraft:deepslate{axis:y}"},
        {pos: [14, 0, 16], state: "minecraft:deepslate{axis:y}"},
        {pos: [14, 0, 17], state: "minecraft:deepslate{axis:y}"},
        {pos: [15, 0, 0], state: "minecraft:deepslate{axis:y}"},
        {pos: [15, 0, 1], state: "minecraft:deepslate{axis:y}"},
        {pos: [15, 0, 2], state: "minecraft:deepslate{axis:y}"},
        {pos: [15, 0, 3], state: "minecraft:deepslate{axis:y}"},
        {pos: [15, 0, 4], state: "minecraft:deepslate{axis:y}"},
        {pos: [15, 0, 5], state: "minecraft:deepslate{axis:y}"},
        {pos: [15, 0, 6], state: "minecraft:deepslate{axis:y}"},
        {pos: [15, 0, 7], state: "minecraft:deepslate{axis:y}"},
        {pos: [15, 0, 8], state: "minecraft:deepslate{axis:y}"},
        {pos: [15, 0, 9], state: "minecraft:deepslate{axis:y}"},
        {pos: [15, 0, 10], state: "minecraft:deepslate{axis:y}"},
        {pos: [15, 0, 11], state: "minecraft:deepslate{axis:y}"},
        {pos: [15, 0, 12], state: "minecraft:deepslate{axis:y}"},
        {pos: [15, 0, 13], state: "minecraft:deepslate{axis:y}"},
        {pos: [15, 0, 14], state: "minecraft:deepslate{axis:y}"},
        {pos: [15, 0, 15], state: "minecraft:deepslate{axis:y}"},
        {pos: [15, 0, 16], state: "minecraft:deepslate{axis:y}"},
        {pos: [15, 0, 17], state: "minecraft:deepslate{axis:y}"},
        {pos: [16, 0, 0], state: "minecraft:deepslate{axis:y}"},
        {pos: [16, 0, 1], state: "minecraft:deepslate{axis:y}"},
        {pos: [16, 0, 2], state: "minecraft:deepslate{axis:y}"},
        {pos: [16, 0, 3], state: "minecraft:deepslate{axis:y}"},
        {pos: [16, 0, 4], state: "minecraft:deepslate{axis:y}"},
        {pos: [16, 0, 5], state: "minecraft:deepslate{axis:y}"},
        {pos: [16, 0, 6], state: "minecraft:deepslate{axis:y}"},
        {pos: [16, 0, 7], state: "minecraft:deepslate{axis:y}"},
        {pos: [16, 0, 8], state: "minecraft:deepslate{axis:y}"},
        {pos: [16, 0, 9], state: "minecraft:deepslate{axis:y}"},
        {pos: [16, 0, 10], state: "minecraft:deepslate{axis:y}"},
        {pos: [16, 0, 11], state: "minecraft:deepslate{axis:y}"},
        {pos: [16, 0, 12], state: "minecraft:deepslate{axis:y}"},
        {pos: [16, 0, 13], state: "minecraft:deepslate{axis:y}"},
        {pos: [16, 0, 14], state: "minecraft:deepslate{axis:y}"},
        {pos: [16, 0, 15], state: "minecraft:deepslate{axis:y}"},
        {pos: [16, 0, 16], state: "minecraft:deepslate{axis:y}"},
        {pos: [16, 0, 17], state: "minecraft:deepslate{axis:y}"},
        {pos: [17, 0, 0], state: "minecraft:deepslate{axis:y}"},
        {pos: [17, 0, 1], state: "minecraft:deepslate{axis:y}"},
        {pos: [17, 0, 2], state: "minecraft:deepslate{axis:y}"},
        {pos: [17, 0, 3], state: "minecraft:deepslate{axis:y}"},
        {pos: [17, 0, 4], state: "minecraft:deepslate{axis:y}"},
        {pos: [17, 0, 5], state: "minecraft:deepslate{axis:y}"},
        {pos: [17, 0, 6], state: "minecraft:deepslate{axis:y}"},
        {pos: [17, 0, 7], state: "minecraft:deepslate{axis:y}"},
        {pos: [17, 0, 8], state: "minecraft:deepslate{axis:y}"},
        {pos: [17, 0, 9], state: "minecraft:deepslate{axis:y}"},
        {pos: [17, 0, 10], state: "minecraft:deepslate{axis:y}"},
        {pos: [17, 0, 11], state: "minecraft:deepslate{axis:y}"},
        {pos: [17, 0, 12], state: "minecraft:deepslate{axis:y}"},
        {pos: [17, 0, 13], state: "minecraft:deepslate{axis:y}"},
        {pos: [17, 0, 14], state: "minecraft:deepslate{axis:y}"},
        {pos: [17, 0, 15], state: "minecraft:deepslate{axis:y}"},
        {pos: [17, 0, 16], state: "minecraft:deepslate{axis:y}"},
        {pos: [17, 0, 17], state: "minecraft:deepslate{axis:y}"},
        {pos: [18, 0, 0], state: "minecraft:deepslate{axis:y}"},
        {pos: [18, 0, 1], state: "minecraft:deepslate{axis:y}"},
        {pos: [18, 0, 2], state: "minecraft:deepslate{axis:y}"},
        {pos: [18, 0, 3], state: "minecraft:deepslate{axis:y}"},
        {pos: [18, 0, 4], state: "minecraft:deepslate{axis:y}"},
        {pos: [18, 0, 5], state: "minecraft:deepslate{axis:y}"},
        {pos: [18, 0, 6], state: "minecraft:deepslate{axis:y}"},
        {pos: [18, 0, 7], state: "minecraft:deepslate{axis:y}"},
        {pos: [18, 0, 8], state: "minecraft:deepslate{axis:y}"},
        {pos: [18, 0, 9], state: "minecraft:deepslate{axis:y}"},
        {pos: [18, 0, 10], state: "minecraft:deepslate{axis:y}"},
        {pos: [18, 0, 11], state: "minecraft:deepslate{axis:y}"},
        {pos: [18, 0, 12], state: "minecraft:deepslate{axis:y}"},
        {pos: [18, 0, 13], state: "minecraft:deepslate{axis:y}"},
        {pos: [18, 0, 14], state: "minecraft:deepslate{axis:y}"},
        {pos: [18, 0, 15], state: "minecraft:deepslate{axis:y}"},
        {pos: [18, 0, 16], state: "minecraft:deepslate{axis:y}"},
        {pos: [18, 0, 17], state: "minecraft:deepslate{axis:y}"},
        {pos: [19, 0, 0], state: "minecraft:deepslate{axis:y}"},
        {pos: [19, 0, 1], state: "minecraft:deepslate{axis:y}"},
        {pos: [19, 0, 2], state: "minecraft:deepslate{axis:y}"},
        {pos: [19, 0, 3], state: "minecraft:deepslate{axis:y}"},
        {pos: [19, 0, 4], state: "minecraft:deepslate{axis:y}"},
        {pos: [19, 0, 5], state: "minecraft:deepslate{axis:y}"},
        {pos: [19, 0, 6], state: "minecraft:deepslate{axis:y}"},
        {pos: [19, 0, 7], state: "minecraft:deepslate{axis:y}"},
        {pos: [19, 0, 8], state: "minecraft:deepslate{axis:y}"},
        {pos: [19, 0, 9], state: "minecraft:deepslate{axis:y}"},
        {pos: [19, 0, 10], state: "minecraft:deepslate{axis:y}"},
        {pos: [19, 0, 11], state: "minecraft:deepslate{axis:y}"},
        {pos: [19, 0, 12], state: "minecraft:deepslate{axis:y}"},
        {pos: [19, 0, 13], state: "minecraft:deepslate{axis:y}"},
        {pos: [20, 0, 0], state: "minecraft:deepslate{axis:y}"},
        {pos: [20, 0, 1], state: "minecraft:deepslate{axis:y}"},
        {pos: [20, 0, 2], state: "minecraft:deepslate{axis:y}"},
        {pos: [20, 0, 3], state: "minecraft:deepslate{axis:y}"},
        {pos: [20, 0, 4], state: "minecraft:deepslate{axis:y}"},
        {pos: [20, 0, 5], state: "minecraft:deepslate{axis:y}"},
        {pos: [20, 0, 6], state: "minecraft:deepslate{axis:y}"},
        {pos: [20, 0, 7], state: "minecraft:deepslate{axis:y}"},
        {pos: [20, 0, 8], state: "minecraft:deepslate{axis:y}"},
        {pos: [20, 0, 9], state: "minecraft:deepslate{axis:y}"},
        {pos: [20, 0, 10], state: "minecraft:deepslate{axis:y}"},
        {pos: [20, 0, 11], state: "minecraft:deepslate{axis:y}"},
        {pos: [20, 0, 12], state: "minecraft:deepslate{axis:y}"},
        {pos: [20, 0, 13], state: "minecraft:deepslate{axis:y}"},
        {pos: [21, 0, 0], state: "minecraft:deepslate{axis:y}"},
        {pos: [21, 0, 1], state: "minecraft:deepslate{axis:y}"},
        {pos: [21, 0, 2], state: "minecraft:deepslate{axis:y}"},
        {pos: [21, 0, 3], state: "minecraft:deepslate{axis:y}"},
        {pos: [21, 0, 4], state: "minecraft:deepslate{axis:y}"},
        {pos: [21, 0, 5], state: "minecraft:deepslate{axis:y}"},
        {pos: [21, 0, 6], state: "minecraft:deepslate{axis:y}"},
        {pos: [21, 0, 7], state: "minecraft:deepslate{axis:y}"},
        {pos: [21, 0, 8], state: "minecraft:deepslate{axis:y}"},
        {pos: [21, 0, 9], state: "minecraft:deepslate{axis:y}"},
        {pos: [21, 0, 10], state: "minecraft:deepslate{axis:y}"},
        {pos: [21, 0, 11], state: "minecraft:deepslate{axis:y}"},
        {pos: [21, 0, 12], state: "minecraft:deepslate{axis:y}"},
        {pos: [21, 0, 13], state: "minecraft:deepslate{axis:y}"},
        {pos: [22, 0, 5], state: "minecraft:deepslate{axis:y}"},
        {pos: [22, 0, 6], state: "minecraft:deepslate{axis:y}"},
        {pos: [22, 0, 7], state: "minecraft:deepslate{axis:y}"},
        {pos: [22, 0, 8], state: "minecraft:deepslate{axis:y}"},
        {pos: [22, 0, 9], state: "minecraft:deepslate{axis:y}"},
        {pos: [22, 0, 10], state: "minecraft:deepslate{axis:y}"},
        {pos: [22, 0, 11], state: "minecraft:deepslate{axis:y}"},
        {pos: [23, 0, 5], state: "minecraft:deepslate{axis:y}"},
        {pos: [23, 0, 6], state: "minecraft:deepslate{axis:y}"},
        {pos: [23, 0, 7], state: "minecraft:deepslate{axis:y}"},
        {pos: [23, 0, 8], state: "minecraft:deepslate{axis:y}"},
        {pos: [23, 0, 9], state: "minecraft:deepslate{axis:y}"},
        {pos: [23, 0, 10], state: "minecraft:deepslate{axis:y}"},
        {pos: [23, 0, 11], state: "minecraft:deepslate{axis:y}"},
        {pos: [24, 0, 5], state: "minecraft:deepslate{axis:y}"},
        {pos: [24, 0, 6], state: "minecraft:deepslate{axis:y}"},
        {pos: [24, 0, 7], state: "minecraft:deepslate{axis:y}"},
        {pos: [24, 0, 8], state: "minecraft:deepslate{axis:y}"},
        {pos: [24, 0, 9], state: "minecraft:deepslate{axis:y}"},
        {pos: [24, 0, 10], state: "minecraft:deepslate{axis:y}"},
        {pos: [24, 0, 11], state: "minecraft:deepslate{axis:y}"},
        {pos: [0, 1, 0], state: "minecraft:deepslate_bricks"},
        {pos: [0, 1, 1], state: "minecraft:deepslate_bricks"},
        {pos: [0, 1, 2], state: "minecraft:deepslate_bricks"},
        {pos: [0, 1, 3], state: "minecraft:deepslate_bricks"},
        {pos: [0, 1, 4], state: "minecraft:deepslate_bricks"},
        {pos: [0, 1, 5], state: "minecraft:deepslate_bricks"},
        {pos: [0, 1, 6], state: "minecraft:deepslate_bricks"},
        {pos: [0, 1, 7], state: "minecraft:gravel"},
        {pos: [0, 1, 8], state: "minecraft:gravel"},
        {pos: [0, 1, 9], state: "minecraft:gravel"},
        {pos: [0, 1, 10], state: "minecraft:deepslate_bricks"},
        {pos: [0, 1, 11], state: "minecraft:deepslate_bricks"},
        {pos: [0, 1, 12], state: "minecraft:deepslate_bricks"},
        {pos: [0, 1, 13], state: "minecraft:deepslate_bricks"},
        {pos: [0, 1, 14], state: "minecraft:deepslate_bricks"},
        {pos: [0, 1, 15], state: "minecraft:deepslate_bricks"},
        {pos: [1, 1, 0], state: "minecraft:deepslate_bricks"},
        {pos: [1, 1, 1], state: "minecraft:gravel"},
        {pos: [1, 1, 2], state: "minecraft:gravel"},
        {pos: [1, 1, 3], state: "minecraft:gravel"},
        {pos: [1, 1, 4], state: "minecraft:gravel"},
        {pos: [1, 1, 5], state: "minecraft:gravel"},
        {pos: [1, 1, 6], state: "minecraft:gravel"},
        {pos: [1, 1, 7], state: "minecraft:gravel"},
        {pos: [1, 1, 8], state: "minecraft:gravel"},
        {pos: [1, 1, 9], state: "minecraft:gravel"},
        {pos: [1, 1, 10], state: "minecraft:gravel"},
        {pos: [1, 1, 11], state: "minecraft:gravel"},
        {pos: [1, 1, 12], state: "minecraft:gravel"},
        {pos: [1, 1, 13], state: "minecraft:gravel"},
        {pos: [1, 1, 14], state: "minecraft:gravel"},
        {pos: [1, 1, 15], state: "minecraft:deepslate_bricks"},
        {pos: [2, 1, 0], state: "minecraft:deepslate_bricks"},
        {pos: [2, 1, 1], state: "minecraft:gravel"},
        {pos: [2, 1, 2], state: "minecraft:gravel"},
        {pos: [2, 1, 3], state: "minecraft:gravel"},
        {pos: [2, 1, 4], state: "minecraft:gravel"},
        {pos: [2, 1, 5], state: "minecraft:gravel"},
        {pos: [2, 1, 6], state: "minecraft:gravel"},
        {pos: [2, 1, 7], state: "minecraft:gravel"},
        {pos: [2, 1, 8], state: "minecraft:gravel"},
        {pos: [2, 1, 9], state: "minecraft:gravel"},
        {pos: [2, 1, 10], state: "minecraft:gravel"},
        {pos: [2, 1, 11], state: "minecraft:gravel"},
        {pos: [2, 1, 12], state: "minecraft:gravel"},
        {pos: [2, 1, 13], state: "minecraft:gravel"},
        {pos: [2, 1, 14], state: "minecraft:gravel"},
        {pos: [2, 1, 15], state: "minecraft:deepslate_bricks"},
        {pos: [3, 1, 0], state: "minecraft:deepslate_bricks"},
        {pos: [3, 1, 1], state: "minecraft:gravel"},
        {pos: [3, 1, 2], state: "minecraft:gravel"},
        {pos: [3, 1, 3], state: "minecraft:gravel"},
        {pos: [3, 1, 4], state: "minecraft:gravel"},
        {pos: [3, 1, 5], state: "minecraft:gravel"},
        {pos: [3, 1, 6], state: "minecraft:gravel"},
        {pos: [3, 1, 7], state: "minecraft:gravel"},
        {pos: [3, 1, 8], state: "minecraft:gravel"},
        {pos: [3, 1, 9], state: "minecraft:gravel"},
        {pos: [3, 1, 10], state: "minecraft:gravel"},
        {pos: [3, 1, 11], state: "minecraft:gravel"},
        {pos: [3, 1, 12], state: "minecraft:gravel"},
        {pos: [3, 1, 13], state: "minecraft:gravel"},
        {pos: [3, 1, 14], state: "minecraft:gravel"},
        {pos: [3, 1, 15], state: "minecraft:deepslate_bricks"},
        {pos: [4, 1, 0], state: "minecraft:deepslate_bricks"},
        {pos: [4, 1, 1], state: "minecraft:gravel"},
        {pos: [4, 1, 2], state: "minecraft:gravel"},
        {pos: [4, 1, 3], state: "minecraft:gravel"},
        {pos: [4, 1, 4], state: "minecraft:gravel"},
        {pos: [4, 1, 5], state: "minecraft:gravel"},
        {pos: [4, 1, 6], state: "minecraft:gravel"},
        {pos: [4, 1, 7], state: "minecraft:gravel"},
        {pos: [4, 1, 8], state: "minecraft:gravel"},
        {pos: [4, 1, 9], state: "minecraft:gravel"},
        {pos: [4, 1, 10], state: "minecraft:gravel"},
        {pos: [4, 1, 11], state: "minecraft:gravel"},
        {pos: [4, 1, 12], state: "minecraft:gravel"},
        {pos: [4, 1, 13], state: "minecraft:gravel"},
        {pos: [4, 1, 14], state: "minecraft:gravel"},
        {pos: [4, 1, 15], state: "minecraft:deepslate_bricks"},
        {pos: [5, 1, 0], state: "minecraft:deepslate_bricks"},
        {pos: [5, 1, 1], state: "minecraft:gravel"},
        {pos: [5, 1, 2], state: "minecraft:gravel"},
        {pos: [5, 1, 3], state: "minecraft:gravel"},
        {pos: [5, 1, 4], state: "minecraft:gravel"},
        {pos: [5, 1, 5], state: "minecraft:gravel"},
        {pos: [5, 1, 6], state: "minecraft:gravel"},
        {pos: [5, 1, 7], state: "minecraft:gravel"},
        {pos: [5, 1, 8], state: "minecraft:gravel"},
        {pos: [5, 1, 9], state: "minecraft:gravel"},
        {pos: [5, 1, 10], state: "minecraft:gravel"},
        {pos: [5, 1, 11], state: "minecraft:gravel"},
        {pos: [5, 1, 12], state: "minecraft:gravel"},
        {pos: [5, 1, 13], state: "minecraft:gravel"},
        {pos: [5, 1, 14], state: "minecraft:gravel"},
        {pos: [5, 1, 15], state: "minecraft:deepslate_bricks"},
        {pos: [6, 1, 0], state: "minecraft:deepslate_bricks"},
        {pos: [6, 1, 1], state: "minecraft:gravel"},
        {pos: [6, 1, 2], state: "minecraft:gravel"},
        {pos: [6, 1, 3], state: "minecraft:gravel"},
        {pos: [6, 1, 4], state: "minecraft:gravel"},
        {pos: [6, 1, 5], state: "minecraft:gravel"},
        {pos: [6, 1, 6], state: "minecraft:gravel"},
        {pos: [6, 1, 7], state: "minecraft:gravel"},
        {pos: [6, 1, 8], state: "minecraft:gravel"},
        {pos: [6, 1, 9], state: "minecraft:gravel"},
        {pos: [6, 1, 10], state: "minecraft:gravel"},
        {pos: [6, 1, 11], state: "minecraft:gravel"},
        {pos: [6, 1, 12], state: "minecraft:gravel"},
        {pos: [6, 1, 13], state: "minecraft:gravel"},
        {pos: [6, 1, 14], state: "minecraft:gravel"},
        {pos: [6, 1, 15], state: "minecraft:deepslate_bricks"},
        {pos: [7, 1, 0], state: "minecraft:deepslate_bricks"},
        {pos: [7, 1, 1], state: "minecraft:gravel"},
        {pos: [7, 1, 2], state: "minecraft:gravel"},
        {pos: [7, 1, 3], state: "minecraft:gravel"},
        {pos: [7, 1, 4], state: "minecraft:gravel"},
        {pos: [7, 1, 5], state: "minecraft:gravel"},
        {pos: [7, 1, 6], state: "minecraft:gravel"},
        {pos: [7, 1, 7], state: "minecraft:gravel"},
        {pos: [7, 1, 8], state: "minecraft:gravel"},
        {pos: [7, 1, 9], state: "minecraft:gravel"},
        {pos: [7, 1, 10], state: "minecraft:gravel"},
        {pos: [7, 1, 11], state: "minecraft:gravel"},
        {pos: [7, 1, 12], state: "minecraft:gravel"},
        {pos: [7, 1, 13], state: "minecraft:gravel"},
        {pos: [7, 1, 14], state: "minecraft:gravel"},
        {pos: [7, 1, 15], state: "minecraft:deepslate_bricks"},
        {pos: [8, 1, 0], state: "minecraft:deepslate_bricks"},
        {pos: [8, 1, 1], state: "minecraft:gravel"},
        {pos: [8, 1, 2], state: "minecraft:gravel"},
        {pos: [8, 1, 3], state: "minecraft:gravel"},
        {pos: [8, 1, 4], state: "minecraft:gravel"},
        {pos: [8, 1, 5], state: "minecraft:gravel"},
        {pos: [8, 1, 6], state: "minecraft:gravel"},
        {pos: [8, 1, 7], state: "minecraft:gravel"},
        {pos: [8, 1, 8], state: "minecraft:gravel"},
        {pos: [8, 1, 9], state: "minecraft:gravel"},
        {pos: [8, 1, 10], state: "minecraft:gravel"},
        {pos: [8, 1, 11], state: "minecraft:gravel"},
        {pos: [8, 1, 12], state: "minecraft:gravel"},
        {pos: [8, 1, 13], state: "minecraft:gravel"},
        {pos: [8, 1, 14], state: "minecraft:gravel"},
        {pos: [8, 1, 15], state: "minecraft:deepslate_bricks"},
        {pos: [9, 1, 0], state: "minecraft:deepslate_bricks"},
        {pos: [9, 1, 1], state: "minecraft:gravel"},
        {pos: [9, 1, 2], state: "minecraft:gravel"},
        {pos: [9, 1, 3], state: "minecraft:gravel"},
        {pos: [9, 1, 4], state: "minecraft:gravel"},
        {pos: [9, 1, 5], state: "minecraft:gravel"},
        {pos: [9, 1, 6], state: "minecraft:gravel"},
        {pos: [9, 1, 7], state: "minecraft:gravel"},
        {pos: [9, 1, 8], state: "minecraft:gravel"},
        {pos: [9, 1, 9], state: "minecraft:gravel"},
        {pos: [9, 1, 10], state: "minecraft:gravel"},
        {pos: [9, 1, 11], state: "minecraft:gravel"},
        {pos: [9, 1, 12], state: "minecraft:gravel"},
        {pos: [9, 1, 13], state: "minecraft:gravel"},
        {pos: [9, 1, 14], state: "minecraft:gravel"},
        {pos: [9, 1, 15], state: "minecraft:deepslate_bricks"},
        {pos: [10, 1, 0], state: "minecraft:deepslate_bricks"},
        {pos: [10, 1, 1], state: "minecraft:gravel"},
        {pos: [10, 1, 2], state: "minecraft:gravel"},
        {pos: [10, 1, 3], state: "minecraft:gravel"},
        {pos: [10, 1, 4], state: "minecraft:gravel"},
        {pos: [10, 1, 5], state: "minecraft:gravel"},
        {pos: [10, 1, 6], state: "minecraft:gravel"},
        {pos: [10, 1, 7], state: "minecraft:gravel"},
        {pos: [10, 1, 8], state: "minecraft:gravel"},
        {pos: [10, 1, 9], state: "minecraft:gravel"},
        {pos: [10, 1, 10], state: "minecraft:gravel"},
        {pos: [10, 1, 11], state: "minecraft:gravel"},
        {pos: [10, 1, 12], state: "minecraft:gravel"},
        {pos: [10, 1, 13], state: "minecraft:gravel"},
        {pos: [10, 1, 14], state: "minecraft:gravel"},
        {pos: [10, 1, 15], state: "minecraft:gravel"},
        {pos: [10, 1, 16], state: "minecraft:deepslate_bricks"},
        {pos: [10, 1, 17], state: "minecraft:deepslate_bricks"},
        {pos: [11, 1, 0], state: "minecraft:deepslate_bricks"},
        {pos: [11, 1, 1], state: "minecraft:gravel"},
        {pos: [11, 1, 2], state: "minecraft:gravel"},
        {pos: [11, 1, 3], state: "minecraft:gravel"},
        {pos: [11, 1, 4], state: "minecraft:gravel"},
        {pos: [11, 1, 5], state: "minecraft:gravel"},
        {pos: [11, 1, 6], state: "minecraft:gravel"},
        {pos: [11, 1, 7], state: "minecraft:gravel"},
        {pos: [11, 1, 8], state: "minecraft:gravel"},
        {pos: [11, 1, 9], state: "minecraft:gravel"},
        {pos: [11, 1, 10], state: "minecraft:gravel"},
        {pos: [11, 1, 11], state: "minecraft:gravel"},
        {pos: [11, 1, 12], state: "minecraft:gravel"},
        {pos: [11, 1, 13], state: "minecraft:gravel"},
        {pos: [11, 1, 14], state: "minecraft:gravel"},
        {pos: [11, 1, 15], state: "minecraft:gravel"},
        {pos: [11, 1, 16], state: "minecraft:gravel"},
        {pos: [11, 1, 17], state: "minecraft:deepslate_bricks"},
        {pos: [12, 1, 0], state: "minecraft:deepslate_bricks"},
        {pos: [12, 1, 1], state: "minecraft:gravel"},
        {pos: [12, 1, 2], state: "minecraft:gravel"},
        {pos: [12, 1, 3], state: "minecraft:gravel"},
        {pos: [12, 1, 4], state: "minecraft:gravel"},
        {pos: [12, 1, 5], state: "minecraft:gravel"},
        {pos: [12, 1, 6], state: "minecraft:gravel"},
        {pos: [12, 1, 7], state: "minecraft:gravel"},
        {pos: [12, 1, 8], state: "minecraft:gravel"},
        {pos: [12, 1, 9], state: "minecraft:gravel"},
        {pos: [12, 1, 10], state: "minecraft:gravel"},
        {pos: [12, 1, 11], state: "minecraft:gravel"},
        {pos: [12, 1, 12], state: "minecraft:gravel"},
        {pos: [12, 1, 13], state: "minecraft:gravel"},
        {pos: [12, 1, 14], state: "minecraft:gravel"},
        {pos: [12, 1, 15], state: "minecraft:gravel"},
        {pos: [12, 1, 16], state: "minecraft:gravel"},
        {pos: [12, 1, 17], state: "minecraft:deepslate_bricks"},
        {pos: [13, 1, 0], state: "minecraft:deepslate_bricks"},
        {pos: [13, 1, 1], state: "minecraft:gravel"},
        {pos: [13, 1, 2], state: "minecraft:gravel"},
        {pos: [13, 1, 3], state: "minecraft:gravel"},
        {pos: [13, 1, 4], state: "minecraft:gravel"},
        {pos: [13, 1, 5], state: "minecraft:gravel"},
        {pos: [13, 1, 6], state: "minecraft:gravel"},
        {pos: [13, 1, 7], state: "minecraft:gravel"},
        {pos: [13, 1, 8], state: "minecraft:gravel"},
        {pos: [13, 1, 9], state: "minecraft:gravel"},
        {pos: [13, 1, 10], state: "minecraft:gravel"},
        {pos: [13, 1, 11], state: "minecraft:gravel"},
        {pos: [13, 1, 12], state: "minecraft:gravel"},
        {pos: [13, 1, 13], state: "minecraft:gravel"},
        {pos: [13, 1, 14], state: "minecraft:gravel"},
        {pos: [13, 1, 15], state: "minecraft:gravel"},
        {pos: [13, 1, 16], state: "minecraft:gravel"},
        {pos: [13, 1, 17], state: "minecraft:deepslate_bricks"},
        {pos: [14, 1, 0], state: "minecraft:deepslate_bricks"},
        {pos: [14, 1, 1], state: "minecraft:gravel"},
        {pos: [14, 1, 2], state: "minecraft:gravel"},
        {pos: [14, 1, 3], state: "minecraft:gravel"},
        {pos: [14, 1, 4], state: "minecraft:gravel"},
        {pos: [14, 1, 5], state: "minecraft:gravel"},
        {pos: [14, 1, 6], state: "minecraft:gravel"},
        {pos: [14, 1, 7], state: "minecraft:gravel"},
        {pos: [14, 1, 8], state: "minecraft:gravel"},
        {pos: [14, 1, 9], state: "minecraft:gravel"},
        {pos: [14, 1, 10], state: "minecraft:gravel"},
        {pos: [14, 1, 11], state: "minecraft:gravel"},
        {pos: [14, 1, 12], state: "minecraft:gravel"},
        {pos: [14, 1, 13], state: "minecraft:gravel"},
        {pos: [14, 1, 14], state: "minecraft:gravel"},
        {pos: [14, 1, 15], state: "minecraft:gravel"},
        {pos: [14, 1, 16], state: "minecraft:gravel"},
        {pos: [14, 1, 17], state: "minecraft:deepslate_bricks"},
        {pos: [15, 1, 0], state: "minecraft:deepslate_bricks"},
        {pos: [15, 1, 1], state: "minecraft:gravel"},
        {pos: [15, 1, 2], state: "minecraft:gravel"},
        {pos: [15, 1, 3], state: "minecraft:gravel"},
        {pos: [15, 1, 4], state: "minecraft:gravel"},
        {pos: [15, 1, 5], state: "minecraft:gravel"},
        {pos: [15, 1, 6], state: "minecraft:gravel"},
        {pos: [15, 1, 7], state: "minecraft:gravel"},
        {pos: [15, 1, 8], state: "minecraft:gravel"},
        {pos: [15, 1, 9], state: "minecraft:gravel"},
        {pos: [15, 1, 10], state: "minecraft:gravel"},
        {pos: [15, 1, 11], state: "minecraft:gravel"},
        {pos: [15, 1, 12], state: "minecraft:gravel"},
        {pos: [15, 1, 13], state: "minecraft:gravel"},
        {pos: [15, 1, 14], state: "minecraft:gravel"},
        {pos: [15, 1, 15], state: "minecraft:gravel"},
        {pos: [15, 1, 16], state: "minecraft:gravel"},
        {pos: [15, 1, 17], state: "minecraft:deepslate_bricks"},
        {pos: [16, 1, 0], state: "minecraft:deepslate_bricks"},
        {pos: [16, 1, 1], state: "minecraft:gravel"},
        {pos: [16, 1, 2], state: "minecraft:gravel"},
        {pos: [16, 1, 3], state: "minecraft:gravel"},
        {pos: [16, 1, 4], state: "minecraft:gravel"},
        {pos: [16, 1, 5], state: "minecraft:gravel"},
        {pos: [16, 1, 6], state: "minecraft:gravel"},
        {pos: [16, 1, 7], state: "minecraft:gravel"},
        {pos: [16, 1, 8], state: "minecraft:gravel"},
        {pos: [16, 1, 9], state: "minecraft:gravel"},
        {pos: [16, 1, 10], state: "minecraft:gravel"},
        {pos: [16, 1, 11], state: "minecraft:gravel"},
        {pos: [16, 1, 12], state: "minecraft:gravel"},
        {pos: [16, 1, 13], state: "minecraft:gravel"},
        {pos: [16, 1, 14], state: "minecraft:gravel"},
        {pos: [16, 1, 15], state: "minecraft:gravel"},
        {pos: [16, 1, 16], state: "minecraft:gravel"},
        {pos: [16, 1, 17], state: "minecraft:deepslate_bricks"},
        {pos: [17, 1, 0], state: "minecraft:deepslate_bricks"},
        {pos: [17, 1, 1], state: "minecraft:gravel"},
        {pos: [17, 1, 2], state: "minecraft:gravel"},
        {pos: [17, 1, 3], state: "minecraft:gravel"},
        {pos: [17, 1, 4], state: "minecraft:gravel"},
        {pos: [17, 1, 5], state: "minecraft:gravel"},
        {pos: [17, 1, 6], state: "minecraft:gravel"},
        {pos: [17, 1, 7], state: "minecraft:gravel"},
        {pos: [17, 1, 8], state: "minecraft:gravel"},
        {pos: [17, 1, 9], state: "minecraft:gravel"},
        {pos: [17, 1, 10], state: "minecraft:gravel"},
        {pos: [17, 1, 11], state: "minecraft:gravel"},
        {pos: [17, 1, 12], state: "minecraft:gravel"},
        {pos: [17, 1, 13], state: "minecraft:gravel"},
        {pos: [17, 1, 14], state: "minecraft:gravel"},
        {pos: [17, 1, 15], state: "minecraft:gravel"},
        {pos: [17, 1, 16], state: "minecraft:gravel"},
        {pos: [17, 1, 17], state: "minecraft:deepslate_bricks"},
        {pos: [18, 1, 0], state: "minecraft:deepslate_bricks"},
        {pos: [18, 1, 1], state: "minecraft:gravel"},
        {pos: [18, 1, 2], state: "minecraft:gravel"},
        {pos: [18, 1, 3], state: "minecraft:gravel"},
        {pos: [18, 1, 4], state: "minecraft:gravel"},
        {pos: [18, 1, 5], state: "minecraft:gravel"},
        {pos: [18, 1, 6], state: "minecraft:gravel"},
        {pos: [18, 1, 7], state: "minecraft:gravel"},
        {pos: [18, 1, 8], state: "minecraft:gravel"},
        {pos: [18, 1, 9], state: "minecraft:gravel"},
        {pos: [18, 1, 10], state: "minecraft:gravel"},
        {pos: [18, 1, 11], state: "minecraft:gravel"},
        {pos: [18, 1, 12], state: "minecraft:gravel"},
        {pos: [18, 1, 13], state: "minecraft:gravel"},
        {pos: [18, 1, 14], state: "minecraft:deepslate_bricks"},
        {pos: [18, 1, 15], state: "minecraft:deepslate_bricks"},
        {pos: [18, 1, 16], state: "minecraft:deepslate_bricks"},
        {pos: [18, 1, 17], state: "minecraft:deepslate_bricks"},
        {pos: [19, 1, 0], state: "minecraft:deepslate_bricks"},
        {pos: [19, 1, 1], state: "minecraft:gravel"},
        {pos: [19, 1, 2], state: "minecraft:gravel"},
        {pos: [19, 1, 3], state: "minecraft:gravel"},
        {pos: [19, 1, 4], state: "minecraft:gravel"},
        {pos: [19, 1, 5], state: "minecraft:gravel"},
        {pos: [19, 1, 6], state: "minecraft:gravel"},
        {pos: [19, 1, 7], state: "minecraft:gravel"},
        {pos: [19, 1, 8], state: "minecraft:gravel"},
        {pos: [19, 1, 9], state: "minecraft:gravel"},
        {pos: [19, 1, 10], state: "minecraft:gravel"},
        {pos: [19, 1, 11], state: "minecraft:gravel"},
        {pos: [19, 1, 12], state: "minecraft:gravel"},
        {pos: [19, 1, 13], state: "minecraft:deepslate_bricks"},
        {pos: [20, 1, 0], state: "minecraft:deepslate_bricks"},
        {pos: [20, 1, 1], state: "minecraft:gravel"},
        {pos: [20, 1, 2], state: "minecraft:gravel"},
        {pos: [20, 1, 3], state: "minecraft:gravel"},
        {pos: [20, 1, 4], state: "minecraft:gravel"},
        {pos: [20, 1, 5], state: "minecraft:gravel"},
        {pos: [20, 1, 6], state: "minecraft:gravel"},
        {pos: [20, 1, 7], state: "minecraft:gravel"},
        {pos: [20, 1, 8], state: "minecraft:gravel"},
        {pos: [20, 1, 9], state: "minecraft:gravel"},
        {pos: [20, 1, 10], state: "minecraft:gravel"},
        {pos: [20, 1, 11], state: "minecraft:gravel"},
        {pos: [20, 1, 12], state: "minecraft:gravel"},
        {pos: [20, 1, 13], state: "minecraft:deepslate_bricks"},
        {pos: [21, 1, 0], state: "minecraft:deepslate_bricks"},
        {pos: [21, 1, 1], state: "minecraft:deepslate_bricks"},
        {pos: [21, 1, 2], state: "minecraft:deepslate_bricks"},
        {pos: [21, 1, 3], state: "minecraft:deepslate_bricks"},
        {pos: [21, 1, 4], state: "minecraft:deepslate_bricks"},
        {pos: [21, 1, 5], state: "minecraft:gravel"},
        {pos: [21, 1, 6], state: "minecraft:gravel"},
        {pos: [21, 1, 7], state: "minecraft:gravel"},
        {pos: [21, 1, 8], state: "minecraft:gravel"},
        {pos: [21, 1, 9], state: "minecraft:gravel"},
        {pos: [21, 1, 10], state: "minecraft:gravel"},
        {pos: [21, 1, 11], state: "minecraft:gravel"},
        {pos: [21, 1, 12], state: "minecraft:deepslate_bricks"},
        {pos: [21, 1, 13], state: "minecraft:deepslate_bricks"},
        {pos: [22, 1, 5], state: "minecraft:deepslate_bricks"},
        {pos: [22, 1, 6], state: "minecraft:gravel"},
        {pos: [22, 1, 7], state: "minecraft:gravel"},
        {pos: [22, 1, 8], state: "minecraft:gravel"},
        {pos: [22, 1, 9], state: "minecraft:gravel"},
        {pos: [22, 1, 10], state: "minecraft:gravel"},
        {pos: [22, 1, 11], state: "minecraft:deepslate_bricks"},
        {pos: [23, 1, 5], state: "minecraft:deepslate_bricks"},
        {pos: [23, 1, 6], state: "minecraft:gravel"},
        {pos: [23, 1, 7], state: "minecraft:gravel"},
        {pos: [23, 1, 8], state: "minecraft:gravel"},
        {pos: [23, 1, 9], state: "minecraft:gravel"},
        {pos: [23, 1, 10], state: "minecraft:gravel"},
        {pos: [23, 1, 11], state: "minecraft:deepslate_bricks"},
        {pos: [24, 1, 5], state: "minecraft:deepslate_bricks"},
        {pos: [24, 1, 6], state: "minecraft:deepslate_bricks"},
        {pos: [24, 1, 7], state: "minecraft:gravel"},
        {pos: [24, 1, 8], state: "minecraft:gravel"},
        {pos: [24, 1, 9], state: "minecraft:gravel"},
        {pos: [24, 1, 10], state: "minecraft:deepslate_bricks"},
        {pos: [24, 1, 11], state: "minecraft:deepslate_bricks"},
        {pos: [0, 2, 0], state: "minecraft:deepslate_bricks"},
        {pos: [0, 2, 1], state: "minecraft:deepslate_bricks"},
        {pos: [0, 2, 2], state: "minecraft:deepslate_bricks"},
        {pos: [0, 2, 3], state: "minecraft:deepslate_bricks"},
        {pos: [0, 2, 4], state: "minecraft:deepslate_bricks"},
        {pos: [0, 2, 5], state: "minecraft:deepslate_bricks"},
        {pos: [0, 2, 6], state: "minecraft:deepslate_bricks"},
        {pos: [0, 2, 7], state: "minecraft:candle{candles:4,lit:false,waterlogged:false}"},
        {pos: [0, 2, 8], state: "minecraft:jigsaw{orientation:west_up}", nbt: {final_state: "minecraft:cave_air", id: "minecraft:jigsaw", joint: "rollable", name: "trailiertales:corridor", placement_priority: 0, pool: "trailiertales:catacombs/corridor_connector", selection_priority: 0, target: "trailiertales:corridor"}},
        {pos: [0, 2, 9], state: "minecraft:candle{candles:4,lit:false,waterlogged:false}"},
        {pos: [0, 2, 10], state: "minecraft:deepslate_bricks"},
        {pos: [0, 2, 11], state: "minecraft:deepslate_bricks"},
        {pos: [0, 2, 12], state: "minecraft:deepslate_bricks"},
        {pos: [0, 2, 13], state: "minecraft:deepslate_bricks"},
        {pos: [0, 2, 14], state: "minecraft:deepslate_bricks"},
        {pos: [0, 2, 15], state: "minecraft:deepslate_bricks"},
        {pos: [1, 2, 0], state: "minecraft:deepslate_bricks"},
        {pos: [1, 2, 1], state: "minecraft:deepslate_bricks"},
        {pos: [1, 2, 2], state: "minecraft:deepslate_bricks"},
        {pos: [1, 2, 3], state: "minecraft:deepslate_bricks"},
        {pos: [1, 2, 4], state: "minecraft:deepslate_bricks"},
        {pos: [1, 2, 5], state: "minecraft:deepslate_bricks"},
        {pos: [1, 2, 6], state: "minecraft:deepslate_brick_stairs{facing:north,half:top,shape:straight,waterlogged:false}"},
        {pos: [1, 2, 7], state: "minecraft:candle{candles:4,lit:false,waterlogged:false}"},
        {pos: [1, 2, 8], state: "minecraft:cave_air"},
        {pos: [1, 2, 9], state: "minecraft:candle{candles:4,lit:false,waterlogged:false}"},
        {pos: [1, 2, 10], state: "minecraft:deepslate_brick_stairs{facing:south,half:top,shape:straight,waterlogged:false}"},
        {pos: [1, 2, 11], state: "minecraft:deepslate_bricks"},
        {pos: [1, 2, 12], state: "minecraft:deepslate_bricks"},
        {pos: [1, 2, 13], state: "minecraft:deepslate_bricks"},
        {pos: [1, 2, 14], state: "minecraft:deepslate_bricks"},
        {pos: [1, 2, 15], state: "minecraft:deepslate_bricks"},
        {pos: [2, 2, 0], state: "minecraft:deepslate_bricks"},
        {pos: [2, 2, 1], state: "minecraft:deepslate_bricks"},
        {pos: [2, 2, 2], state: "minecraft:deepslate_bricks"},
        {pos: [2, 2, 3], state: "minecraft:deepslate_brick_stairs{facing:west,half:top,shape:straight,waterlogged:false}"},
        {pos: [2, 2, 4], state: "minecraft:deepslate_bricks"},
        {pos: [2, 2, 5], state: "minecraft:deepslate_brick_stairs{facing:west,half:top,shape:straight,waterlogged:false}"},
        {pos: [2, 2, 6], state: "minecraft:deepslate_bricks"},
        {pos: [2, 2, 7], state: "minecraft:candle{candles:4,lit:false,waterlogged:false}"},
        {pos: [2, 2, 8], state: "minecraft:cave_air"},
        {pos: [2, 2, 9], state: "minecraft:candle{candles:4,lit:false,waterlogged:false}"},
        {pos: [2, 2, 10], state: "minecraft:deepslate_bricks"},
        {pos: [2, 2, 11], state: "minecraft:deepslate_bricks"},
        {pos: [2, 2, 12], state: "minecraft:deepslate_brick_stairs{facing:west,half:top,shape:straight,waterlogged:false}"},
        {pos: [2, 2, 13], state: "minecraft:deepslate_bricks"},
        {pos: [2, 2, 14], state: "minecraft:deepslate_bricks"},
        {pos: [2, 2, 15], state: "minecraft:deepslate_bricks"},
        {pos: [3, 2, 0], state: "minecraft:deepslate_bricks"},
        {pos: [3, 2, 1], state: "minecraft:deepslate_bricks"},
        {pos: [3, 2, 2], state: "minecraft:cobbled_deepslate"},
        {pos: [3, 2, 3], state: "minecraft:candle{candles:4,lit:false,waterlogged:false}"},
        {pos: [3, 2, 4], state: "minecraft:candle{candles:4,lit:false,waterlogged:false}"},
        {pos: [3, 2, 5], state: "minecraft:candle{candles:4,lit:false,waterlogged:false}"},
        {pos: [3, 2, 6], state: "minecraft:candle{candles:4,lit:false,waterlogged:false}"},
        {pos: [3, 2, 7], state: "minecraft:cave_air"},
        {pos: [3, 2, 8], state: "minecraft:cave_air"},
        {pos: [3, 2, 9], state: "minecraft:cave_air"},
        {pos: [3, 2, 10], state: "minecraft:candle{candles:4,lit:false,waterlogged:false}"},
        {pos: [3, 2, 11], state: "minecraft:cobbled_deepslate"},
        {pos: [3, 2, 12], state: "minecraft:cobbled_deepslate"},
        {pos: [3, 2, 13], state: "minecraft:cobbled_deepslate"},
        {pos: [3, 2, 14], state: "minecraft:deepslate_bricks"},
        {pos: [3, 2, 15], state: "minecraft:deepslate_bricks"},
        {pos: [4, 2, 0], state: "minecraft:deepslate_bricks"},
        {pos: [4, 2, 1], state: "minecraft:deepslate_brick_stairs{facing:north,half:top,shape:straight,waterlogged:false}"},
        {pos: [4, 2, 2], state: "minecraft:candle{candles:4,lit:false,waterlogged:false}"},
        {pos: [4, 2, 3], state: "minecraft:skeleton_skull{powered:false,rotation:8}", nbt: {id: "minecraft:skull"}},
        {pos: [4, 2, 4], state: "minecraft:cave_air"},
        {pos: [4, 2, 5], state: "minecraft:cave_air"},
        {pos: [4, 2, 6], state: "minecraft:cave_air"},
        {pos: [4, 2, 7], state: "minecraft:cave_air"},
        {pos: [4, 2, 8], state: "minecraft:skeleton_skull{powered:false,rotation:0}", nbt: {id: "minecraft:skull"}},
        {pos: [4, 2, 9], state: "minecraft:cobbled_deepslate"},
        {pos: [4, 2, 10], state: "minecraft:cobbled_deepslate"},
        {pos: [4, 2, 11], state: "minecraft:deepslate_bricks"},
        {pos: [4, 2, 12], state: "minecraft:deepslate_bricks"},
        {pos: [4, 2, 13], state: "minecraft:cobbled_deepslate"},
        {pos: [4, 2, 14], state: "minecraft:deepslate_brick_stairs{facing:south,half:top,shape:straight,waterlogged:false}"},
        {pos: [4, 2, 15], state: "minecraft:deepslate_bricks"},
        {pos: [5, 2, 0], state: "minecraft:deepslate_bricks"},
        {pos: [5, 2, 1], state: "minecraft:deepslate_bricks"},
        {pos: [5, 2, 2], state: "minecraft:deepslate_bricks"},
        {pos: [5, 2, 3], state: "minecraft:candle{candles:4,lit:false,waterlogged:false}"},
        {pos: [5, 2, 4], state: "minecraft:cave_air"},
        {pos: [5, 2, 5], state: "minecraft:cave_air"},
        {pos: [5, 2, 6], state: "minecraft:cave_air"},
        {pos: [5, 2, 7], state: "minecraft:cave_air"},
        {pos: [5, 2, 8], state: "minecraft:cave_air"},
        {pos: [5, 2, 9], state: "minecraft:cobbled_deepslate"},
        {pos: [5, 2, 10], state: "minecraft:cobbled_deepslate"},
        {pos: [5, 2, 11], state: "minecraft:deepslate_bricks"},
        {pos: [5, 2, 12], state: "minecraft:deepslate_bricks"},
        {pos: [5, 2, 13], state: "minecraft:cobbled_deepslate"},
        {pos: [5, 2, 14], state: "minecraft:deepslate_bricks"},
        {pos: [5, 2, 15], state: "minecraft:deepslate_bricks"},
        {pos: [6, 2, 0], state: "minecraft:deepslate_bricks"},
        {pos: [6, 2, 1], state: "minecraft:deepslate_bricks"},
        {pos: [6, 2, 2], state: "minecraft:deepslate_bricks"},
        {pos: [6, 2, 3], state: "minecraft:cobbled_deepslate"},
        {pos: [6, 2, 4], state: "minecraft:candle{candles:4,lit:false,waterlogged:false}"},
        {pos: [6, 2, 5], state: "minecraft:cave_air"},
        {pos: [6, 2, 6], state: "minecraft:cave_air"},
        {pos: [6, 2, 7], state: "minecraft:cave_air"},
        {pos: [6, 2, 8], state: "minecraft:cave_air"},
        {pos: [6, 2, 9], state: "minecraft:candle{candles:4,lit:false,waterlogged:false}"},
        {pos: [6, 2, 10], state: "minecraft:deepslate_bricks"},
        {pos: [6, 2, 11], state: "minecraft:deepslate_bricks"},
        {pos: [6, 2, 12], state: "minecraft:deepslate_bricks"},
        {pos: [6, 2, 13], state: "minecraft:cave_air"},
        {pos: [6, 2, 14], state: "minecraft:deepslate_brick_stairs{facing:south,half:top,shape:straight,waterlogged:false}"},
        {pos: [6, 2, 15], state: "minecraft:deepslate_bricks"},
        {pos: [7, 2, 0], state: "minecraft:deepslate_bricks"},
        {pos: [7, 2, 1], state: "minecraft:deepslate_bricks"},
        {pos: [7, 2, 2], state: "minecraft:deepslate_bricks"},
        {pos: [7, 2, 3], state: "minecraft:deepslate_bricks"},
        {pos: [7, 2, 4], state: "minecraft:deepslate_bricks"},
        {pos: [7, 2, 5], state: "minecraft:deepslate_bricks"},
        {pos: [7, 2, 6], state: "minecraft:deepslate_brick_stairs{facing:north,half:bottom,shape:straight,waterlogged:false}"},
        {pos: [7, 2, 7], state: "minecraft:cave_air"},
        {pos: [7, 2, 8], state: "minecraft:cave_air"},
        {pos: [7, 2, 9], state: "minecraft:skeleton_skull{powered:false,rotation:12}", nbt: {id: "minecraft:skull"}},
        {pos: [7, 2, 10], state: "minecraft:cave_air"},
        {pos: [7, 2, 11], state: "minecraft:cave_air"},
        {pos: [7, 2, 12], state: "minecraft:cave_air"},
        {pos: [7, 2, 13], state: "minecraft:cave_air"},
        {pos: [7, 2, 14], state: "minecraft:deepslate_bricks"},
        {pos: [7, 2, 15], state: "minecraft:deepslate_bricks"},
        {pos: [8, 2, 0], state: "minecraft:deepslate_bricks"},
        {pos: [8, 2, 1], state: "minecraft:deepslate_bricks"},
        {pos: [8, 2, 2], state: "minecraft:deepslate_bricks"},
        {pos: [8, 2, 3], state: "minecraft:deepslate_bricks"},
        {pos: [8, 2, 4], state: "minecraft:deepslate_bricks"},
        {pos: [8, 2, 5], state: "minecraft:deepslate_bricks"},
        {pos: [8, 2, 6], state: "minecraft:deepslate_bricks"},
        {pos: [8, 2, 7], state: "minecraft:cave_air"},
        {pos: [8, 2, 8], state: "minecraft:candle{candles:4,lit:false,waterlogged:false}"},
        {pos: [8, 2, 9], state: "minecraft:deepslate_bricks"},
        {pos: [8, 2, 10], state: "minecraft:deepslate_bricks"},
        {pos: [8, 2, 11], state: "minecraft:deepslate_bricks"},
        {pos: [8, 2, 12], state: "minecraft:deepslate_bricks"},
        {pos: [8, 2, 13], state: "minecraft:deepslate_bricks"},
        {pos: [8, 2, 14], state: "minecraft:deepslate_bricks"},
        {pos: [8, 2, 15], state: "minecraft:deepslate_bricks"},
        {pos: [9, 2, 0], state: "minecraft:deepslate_bricks"},
        {pos: [9, 2, 1], state: "minecraft:deepslate_bricks"},
        {pos: [9, 2, 2], state: "minecraft:deepslate_bricks"},
        {pos: [9, 2, 3], state: "minecraft:deepslate_bricks"},
        {pos: [9, 2, 4], state: "minecraft:deepslate_bricks"},
        {pos: [9, 2, 5], state: "minecraft:deepslate_bricks"},
        {pos: [9, 2, 6], state: "minecraft:deepslate_brick_stairs{facing:north,half:top,shape:straight,waterlogged:false}"},
        {pos: [9, 2, 7], state: "minecraft:cave_air"},
        {pos: [9, 2, 8], state: "minecraft:cave_air"},
        {pos: [9, 2, 9], state: "minecraft:deepslate_bricks"},
        {pos: [9, 2, 10], state: "minecraft:cave_air"},
        {pos: [9, 2, 11], state: "minecraft:cave_air"},
        {pos: [9, 2, 12], state: "minecraft:cave_air"},
        {pos: [9, 2, 13], state: "minecraft:deepslate_bricks"},
        {pos: [9, 2, 14], state: "minecraft:deepslate_bricks"},
        {pos: [9, 2, 15], state: "minecraft:deepslate_bricks"},
        {pos: [10, 2, 0], state: "minecraft:deepslate_bricks"},
        {pos: [10, 2, 1], state: "minecraft:deepslate_bricks"},
        {pos: [10, 2, 2], state: "minecraft:deepslate_bricks"},
        {pos: [10, 2, 3], state: "minecraft:deepslate_bricks"},
        {pos: [10, 2, 4], state: "minecraft:deepslate_bricks"},
        {pos: [10, 2, 5], state: "minecraft:deepslate_bricks"},
        {pos: [10, 2, 6], state: "minecraft:deepslate_bricks"},
        {pos: [10, 2, 7], state: "minecraft:candle{candles:4,lit:false,waterlogged:false}"},
        {pos: [10, 2, 8], state: "minecraft:cave_air"},
        {pos: [10, 2, 9], state: "minecraft:deepslate_bricks"},
        {pos: [10, 2, 10], state: "minecraft:decorated_pot{cracked:false,facing:east,waterlogged:false}", nbt: {id: "minecraft:decorated_pot"}},
        {pos: [10, 2, 11], state: "minecraft:candle{candles:4,lit:false,waterlogged:false}"},
        {pos: [10, 2, 12], state: "minecraft:gray_bed{facing:east,occupied:false,part:foot}", nbt: {id: "minecraft:bed"}},
        {pos: [10, 2, 13], state: "minecraft:deepslate_bricks"},
        {pos: [10, 2, 14], state: "minecraft:deepslate_bricks"},
        {pos: [10, 2, 15], state: "minecraft:deepslate_bricks"},
        {pos: [10, 2, 16], state: "minecraft:deepslate_bricks"},
        {pos: [10, 2, 17], state: "minecraft:deepslate_bricks"},
        {pos: [11, 2, 0], state: "minecraft:deepslate_bricks"},
        {pos: [11, 2, 1], state: "minecraft:deepslate_bricks"},
        {pos: [11, 2, 2], state: "minecraft:deepslate_bricks"},
        {pos: [11, 2, 3], state: "minecraft:deepslate_bricks"},
        {pos: [11, 2, 4], state: "minecraft:deepslate_bricks"},
        {pos: [11, 2, 5], state: "minecraft:deepslate_bricks"},
        {pos: [11, 2, 6], state: "minecraft:deepslate_brick_stairs{facing:north,half:top,shape:straight,waterlogged:false}"},
        {pos: [11, 2, 7], state: "minecraft:cave_air"},
        {pos: [11, 2, 8], state: "minecraft:cave_air"},
        {pos: [11, 2, 9], state: "minecraft:deepslate_bricks"},
        {pos: [11, 2, 10], state: "minecraft:deepslate_brick_stairs{facing:east,half:top,shape:straight,waterlogged:false}"},
        {pos: [11, 2, 11], state: "minecraft:deepslate_brick_stairs{facing:east,half:top,shape:straight,waterlogged:false}"},
        {pos: [11, 2, 12], state: "minecraft:gray_bed{facing:east,occupied:false,part:head}", nbt: {id: "minecraft:bed"}},
        {pos: [11, 2, 13], state: "minecraft:deepslate_bricks"},
        {pos: [11, 2, 14], state: "minecraft:decorated_pot{cracked:false,facing:west,waterlogged:false}", nbt: {id: "minecraft:decorated_pot"}},
        {pos: [11, 2, 15], state: "minecraft:gray_bed{facing:west,occupied:false,part:head}", nbt: {id: "minecraft:bed"}},
        {pos: [11, 2, 16], state: "minecraft:cobbled_deepslate"},
        {pos: [11, 2, 17], state: "minecraft:deepslate_bricks"},
        {pos: [12, 2, 0], state: "minecraft:deepslate_bricks"},
        {pos: [12, 2, 1], state: "minecraft:deepslate_bricks"},
        {pos: [12, 2, 2], state: "minecraft:deepslate_bricks"},
        {pos: [12, 2, 3], state: "minecraft:deepslate_bricks"},
        {pos: [12, 2, 4], state: "minecraft:deepslate_bricks"},
        {pos: [12, 2, 5], state: "minecraft:deepslate_bricks"},
        {pos: [12, 2, 6], state: "minecraft:deepslate_bricks"},
        {pos: [12, 2, 7], state: "minecraft:cave_air"},
        {pos: [12, 2, 8], state: "minecraft:cave_air"},
        {pos: [12, 2, 9], state: "minecraft:deepslate_bricks"},
        {pos: [12, 2, 10], state: "minecraft:deepslate_bricks"},
        {pos: [12, 2, 11], state: "minecraft:deepslate_bricks"},
        {pos: [12, 2, 12], state: "minecraft:deepslate_bricks"},
        {pos: [12, 2, 13], state: "minecraft:deepslate_bricks"},
        {pos: [12, 2, 14], state: "minecraft:candle{candles:4,lit:false,waterlogged:false}"},
        {pos: [12, 2, 15], state: "minecraft:gray_bed{facing:west,occupied:false,part:foot}", nbt: {id: "minecraft:bed"}},
        {pos: [12, 2, 16], state: "minecraft:cobbled_deepslate"},
        {pos: [12, 2, 17], state: "minecraft:deepslate_bricks"},
        {pos: [13, 2, 0], state: "minecraft:deepslate_bricks"},
        {pos: [13, 2, 1], state: "minecraft:deepslate_bricks"},
        {pos: [13, 2, 2], state: "minecraft:deepslate_brick_stairs{facing:west,half:bottom,shape:straight,waterlogged:false}"},
        {pos: [13, 2, 3], state: "minecraft:cobbled_deepslate"},
        {pos: [13, 2, 4], state: "minecraft:cobbled_deepslate"},
        {pos: [13, 2, 5], state: "minecraft:candle{candles:4,lit:false,waterlogged:false}"},
        {pos: [13, 2, 6], state: "minecraft:candle{candles:4,lit:false,waterlogged:false}"},
        {pos: [13, 2, 7], state: "minecraft:cave_air"},
        {pos: [13, 2, 8], state: "minecraft:cave_air"},
        {pos: [13, 2, 9], state: "minecraft:skeleton_skull{powered:false,rotation:4}", nbt: {id: "minecraft:skull"}},
        {pos: [13, 2, 10], state: "minecraft:deepslate_brick_stairs{facing:west,half:top,shape:straight,waterlogged:false}"},
        {pos: [13, 2, 11], state: "minecraft:deepslate_brick_stairs{facing:west,half:top,shape:straight,waterlogged:false}"},
        {pos: [13, 2, 12], state: "minecraft:deepslate_brick_stairs{facing:west,half:top,shape:straight,waterlogged:false}"},
        {pos: [13, 2, 13], state: "minecraft:candle{candles:4,lit:false,waterlogged:false}"},
        {pos: [13, 2, 14], state: "minecraft:cave_air"},
        {pos: [13, 2, 15], state: "minecraft:cave_air"},
        {pos: [13, 2, 16], state: "minecraft:cobbled_deepslate"},
        {pos: [13, 2, 17], state: "minecraft:deepslate_bricks"},
        {pos: [14, 2, 0], state: "minecraft:deepslate_bricks"},
        {pos: [14, 2, 1], state: "minecraft:deepslate_bricks"},
        {pos: [14, 2, 2], state: "minecraft:decorated_pot{cracked:false,facing:north,waterlogged:false}", nbt: {id: "minecraft:decorated_pot"}},
        {pos: [14, 2, 3], state: "minecraft:cave_air"},
        {pos: [14, 2, 4], state: "minecraft:cave_air"},
        {pos: [14, 2, 5], state: "minecraft:cave_air"},
        {pos: [14, 2, 6], state: "minecraft:cave_air"},
        {pos: [14, 2, 7], state: "minecraft:cave_air"},
        {pos: [14, 2, 8], state: "minecraft:cave_air"},
        {pos: [14, 2, 9], state: "minecraft:cave_air"},
        {pos: [14, 2, 10], state: "minecraft:cave_air"},
        {pos: [14, 2, 11], state: "minecraft:cave_air"},
        {pos: [14, 2, 12], state: "minecraft:cave_air"},
        {pos: [14, 2, 13], state: "minecraft:cave_air"},
        {pos: [14, 2, 14], state: "minecraft:cave_air"},
        {pos: [14, 2, 15], state: "minecraft:cave_air"},
        {pos: [14, 2, 16], state: "minecraft:cobbled_deepslate"},
        {pos: [14, 2, 17], state: "minecraft:deepslate_bricks"},
        {pos: [15, 2, 0], state: "minecraft:deepslate_bricks"},
        {pos: [15, 2, 1], state: "minecraft:deepslate_bricks"},
        {pos: [15, 2, 2], state: "minecraft:candle{candles:4,lit:false,waterlogged:false}"},
        {pos: [15, 2, 3], state: "minecraft:cave_air"},
        {pos: [15, 2, 4], state: "minecraft:cave_air"},
        {pos: [15, 2, 5], state: "minecraft:cave_air"},
        {pos: [15, 2, 6], state: "minecraft:cave_air"},
        {pos: [15, 2, 7], state: "minecraft:cave_air"},
        {pos: [15, 2, 8], state: "minecraft:cave_air"},
        {pos: [15, 2, 9], state: "minecraft:gravel"},
        {pos: [15, 2, 10], state: "minecraft:gravel"},
        {pos: [15, 2, 11], state: "minecraft:gravel"},
        {pos: [15, 2, 12], state: "minecraft:candle{candles:4,lit:false,waterlogged:false}"},
        {pos: [15, 2, 13], state: "minecraft:skeleton_skull{powered:false,rotation:12}", nbt: {id: "minecraft:skull"}},
        {pos: [15, 2, 14], state: "minecraft:decorated_pot{cracked:false,facing:east,waterlogged:false}", nbt: {id: "minecraft:decorated_pot"}},
        {pos: [15, 2, 15], state: "minecraft:cave_air"},
        {pos: [15, 2, 16], state: "minecraft:candle{candles:4,lit:false,waterlogged:false}"},
        {pos: [15, 2, 17], state: "minecraft:deepslate_bricks"},
        {pos: [16, 2, 0], state: "minecraft:deepslate_bricks"},
        {pos: [16, 2, 1], state: "minecraft:deepslate_bricks"},
        {pos: [16, 2, 2], state: "minecraft:skeleton_skull{powered:false,rotation:8}", nbt: {id: "minecraft:skull"}},
        {pos: [16, 2, 3], state: "minecraft:candle{candles:4,lit:false,waterlogged:false}"},
        {pos: [16, 2, 4], state: "minecraft:cave_air"},
        {pos: [16, 2, 5], state: "minecraft:candle{candles:4,lit:false,waterlogged:false}"},
        {pos: [16, 2, 6], state: "minecraft:gravel"},
        {pos: [16, 2, 7], state: "minecraft:gravel"},
        {pos: [16, 2, 8], state: "minecraft:cave_air"},
        {pos: [16, 2, 9], state: "minecraft:cobbled_deepslate"},
        {pos: [16, 2, 10], state: "minecraft:deepslate_bricks"},
        {pos: [16, 2, 11], state: "minecraft:deepslate_bricks"},
        {pos: [16, 2, 12], state: "minecraft:deepslate_bricks"},
        {pos: [16, 2, 13], state: "minecraft:deepslate_bricks"},
        {pos: [16, 2, 14], state: "minecraft:candle{candles:4,lit:false,waterlogged:false}"},
        {pos: [16, 2, 15], state: "minecraft:gray_bed{facing:east,occupied:false,part:foot}", nbt: {id: "minecraft:bed"}},
        {pos: [16, 2, 16], state: "minecraft:deepslate_brick_stairs{facing:south,half:top,shape:straight,waterlogged:false}"},
        {pos: [16, 2, 17], state: "minecraft:deepslate_bricks"},
        {pos: [17, 2, 0], state: "minecraft:deepslate_bricks"},
        {pos: [17, 2, 1], state: "minecraft:deepslate_bricks"},
        {pos: [17, 2, 2], state: "minecraft:deepslate_bricks"},
        {pos: [17, 2, 3], state: "minecraft:deepslate_bricks"},
        {pos: [17, 2, 4], state: "minecraft:cave_air"},
        {pos: [17, 2, 5], state: "minecraft:cobbled_deepslate"},
        {pos: [17, 2, 6], state: "minecraft:cobbled_deepslate"},
        {pos: [17, 2, 7], state: "minecraft:gravel"},
        {pos: [17, 2, 8], state: "minecraft:cave_air"},
        {pos: [17, 2, 9], state: "minecraft:cobbled_deepslate"},
        {pos: [17, 2, 10], state: "minecraft:cobbled_deepslate"},
        {pos: [17, 2, 11], state: "minecraft:deepslate_bricks"},
        {pos: [17, 2, 12], state: "minecraft:deepslate_bricks"},
        {pos: [17, 2, 13], state: "minecraft:deepslate_bricks"},
        {pos: [17, 2, 14], state: "minecraft:cobbled_deepslate"},
        {pos: [17, 2, 15], state: "minecraft:gray_bed{facing:east,occupied:false,part:head}", nbt: {id: "minecraft:bed"}},
        {pos: [17, 2, 16], state: "minecraft:deepslate_brick_stairs{facing:south,half:top,shape:straight,waterlogged:false}"},
        {pos: [17, 2, 17], state: "minecraft:deepslate_bricks"},
        {pos: [18, 2, 0], state: "minecraft:deepslate_bricks"},
        {pos: [18, 2, 1], state: "minecraft:deepslate_bricks"},
        {pos: [18, 2, 2], state: "minecraft:chest{facing:south,type:single,waterlogged:false}", nbt: {Items: [], id: "minecraft:chest"}},
        {pos: [18, 2, 3], state: "minecraft:cave_air"},
        {pos: [18, 2, 4], state: "minecraft:cave_air"},
        {pos: [18, 2, 5], state: "minecraft:cobbled_deepslate"},
        {pos: [18, 2, 6], state: "minecraft:cobbled_deepslate"},
        {pos: [18, 2, 7], state: "minecraft:candle{candles:4,lit:false,waterlogged:false}"},
        {pos: [18, 2, 8], state: "minecraft:cave_air"},
        {pos: [18, 2, 9], state: "minecraft:cobbled_deepslate"},
        {pos: [18, 2, 10], state: "minecraft:cobbled_deepslate"},
        {pos: [18, 2, 11], state: "minecraft:deepslate_bricks"},
        {pos: [18, 2, 12], state: "minecraft:deepslate_bricks"},
        {pos: [18, 2, 13], state: "minecraft:deepslate_bricks"},
        {pos: [18, 2, 14], state: "minecraft:deepslate_bricks"},
        {pos: [18, 2, 15], state: "minecraft:deepslate_bricks"},
        {pos: [18, 2, 16], state: "minecraft:deepslate_bricks"},
        {pos: [18, 2, 17], state: "minecraft:deepslate_bricks"},
        {pos: [19, 2, 0], state: "minecraft:deepslate_bricks"},
        {pos: [19, 2, 1], state: "minecraft:deepslate_bricks"},
        {pos: [19, 2, 2], state: "minecraft:gray_bed{facing:north,occupied:false,part:head}", nbt: {id: "minecraft:bed"}},
        {pos: [19, 2, 3], state: "minecraft:gray_bed{facing:north,occupied:false,part:foot}", nbt: {id: "minecraft:bed"}},
        {pos: [19, 2, 4], state: "minecraft:cave_air"},
        {pos: [19, 2, 5], state: "minecraft:cobweb"},
        {pos: [19, 2, 6], state: "minecraft:cobbled_deepslate"},
        {pos: [19, 2, 7], state: "minecraft:candle{candles:4,lit:false,waterlogged:false}"},
        {pos: [19, 2, 8], state: "minecraft:cave_air"},
        {pos: [19, 2, 9], state: "minecraft:candle{candles:4,lit:false,waterlogged:false}"},
        {pos: [19, 2, 10], state: "minecraft:deepslate_brick_stairs{facing:south,half:top,shape:straight,waterlogged:false}"},
        {pos: [19, 2, 11], state: "minecraft:deepslate_bricks"},
        {pos: [19, 2, 12], state: "minecraft:deepslate_bricks"},
        {pos: [19, 2, 13], state: "minecraft:deepslate_bricks"},
        {pos: [20, 2, 0], state: "minecraft:deepslate_bricks"},
        {pos: [20, 2, 1], state: "minecraft:deepslate_bricks"},
        {pos: [20, 2, 2], state: "minecraft:candle{candles:4,lit:false,waterlogged:false}"},
        {pos: [20, 2, 3], state: "minecraft:decorated_pot{cracked:false,facing:east,waterlogged:false}", nbt: {id: "minecraft:decorated_pot"}},
        {pos: [20, 2, 4], state: "minecraft:deepslate_brick_stairs{facing:east,half:top,shape:straight,waterlogged:false}"},
        {pos: [20, 2, 5], state: "minecraft:deepslate_brick_stairs{facing:east,half:top,shape:straight,waterlogged:false}"},
        {pos: [20, 2, 6], state: "minecraft:deepslate_bricks"},
        {pos: [20, 2, 7], state: "minecraft:candle{candles:4,lit:false,waterlogged:false}"},
        {pos: [20, 2, 8], state: "minecraft:cave_air"},
        {pos: [20, 2, 9], state: "minecraft:candle{candles:4,lit:false,waterlogged:false}"},
        {pos: [20, 2, 10], state: "minecraft:deepslate_bricks"},
        {pos: [20, 2, 11], state: "minecraft:deepslate_bricks"},
        {pos: [20, 2, 12], state: "minecraft:deepslate_bricks"},
        {pos: [20, 2, 13], state: "minecraft:deepslate_bricks"},
        {pos: [21, 2, 0], state: "minecraft:deepslate_bricks"},
        {pos: [21, 2, 1], state: "minecraft:deepslate_bricks"},
        {pos: [21, 2, 2], state: "minecraft:deepslate_bricks"},
        {pos: [21, 2, 3], state: "minecraft:deepslate_bricks"},
        {pos: [21, 2, 4], state: "minecraft:deepslate_bricks"},
        {pos: [21, 2, 5], state: "minecraft:deepslate_bricks"},
        {pos: [21, 2, 6], state: "minecraft:deepslate_bricks"},
        {pos: [21, 2, 7], state: "minecraft:candle{candles:4,lit:false,waterlogged:false}"},
        {pos: [21, 2, 8], state: "minecraft:cave_air"},
        {pos: [21, 2, 9], state: "minecraft:candle{candles:4,lit:false,waterlogged:false}"},
        {pos: [21, 2, 10], state: "minecraft:deepslate_brick_stairs{facing:south,half:top,shape:straight,waterlogged:false}"},
        {pos: [21, 2, 11], state: "minecraft:deepslate_bricks"},
        {pos: [21, 2, 12], state: "minecraft:deepslate_bricks"},
        {pos: [21, 2, 13], state: "minecraft:deepslate_bricks"},
        {pos: [22, 2, 5], state: "minecraft:deepslate_bricks"},
        {pos: [22, 2, 6], state: "minecraft:deepslate_bricks"},
        {pos: [22, 2, 7], state: "minecraft:candle{candles:4,lit:false,waterlogged:false}"},
        {pos: [22, 2, 8], state: "minecraft:cave_air"},
        {pos: [22, 2, 9], state: "minecraft:candle{candles:4,lit:false,waterlogged:false}"},
        {pos: [22, 2, 10], state: "minecraft:deepslate_bricks"},
        {pos: [22, 2, 11], state: "minecraft:deepslate_bricks"},
        {pos: [23, 2, 5], state: "minecraft:deepslate_bricks"},
        {pos: [23, 2, 6], state: "minecraft:deepslate_brick_stairs{facing:north,half:top,shape:straight,waterlogged:false}"},
        {pos: [23, 2, 7], state: "minecraft:candle{candles:4,lit:false,waterlogged:false}"},
        {pos: [23, 2, 8], state: "minecraft:cave_air"},
        {pos: [23, 2, 9], state: "minecraft:candle{candles:4,lit:false,waterlogged:false}"},
        {pos: [23, 2, 10], state: "minecraft:deepslate_brick_stairs{facing:south,half:top,shape:straight,waterlogged:false}"},
        {pos: [23, 2, 11], state: "minecraft:deepslate_bricks"},
        {pos: [24, 2, 5], state: "minecraft:deepslate_bricks"},
        {pos: [24, 2, 6], state: "minecraft:deepslate_bricks"},
        {pos: [24, 2, 7], state: "minecraft:candle{candles:4,lit:false,waterlogged:false}"},
        {pos: [24, 2, 8], state: "minecraft:jigsaw{orientation:east_up}", nbt: {final_state: "minecraft:cave_air", id: "minecraft:jigsaw", joint: "rollable", name: "trailiertales:corridor", placement_priority: 0, pool: "trailiertales:catacombs/corridor_connector", selection_priority: 0, target: "trailiertales:corridor"}},
        {pos: [24, 2, 9], state: "minecraft:candle{candles:4,lit:false,waterlogged:false}"},
        {pos: [24, 2, 10], state: "minecraft:deepslate_bricks"},
        {pos: [24, 2, 11], state: "minecraft:deepslate_bricks"},
        {pos: [0, 3, 0], state: "minecraft:deepslate_bricks"},
        {pos: [0, 3, 1], state: "minecraft:deepslate_bricks"},
        {pos: [0, 3, 2], state: "minecraft:deepslate_bricks"},
        {pos: [0, 3, 3], state: "minecraft:deepslate_bricks"},
        {pos: [0, 3, 4], state: "minecraft:deepslate_bricks"},
        {pos: [0, 3, 5], state: "minecraft:deepslate_bricks"},
        {pos: [0, 3, 6], state: "minecraft:deepslate_bricks"},
        {pos: [0, 3, 7], state: "minecraft:cave_air"},
        {pos: [0, 3, 8], state: "minecraft:cave_air"},
        {pos: [0, 3, 9], state: "minecraft:cave_air"},
        {pos: [0, 3, 10], state: "minecraft:deepslate_bricks"},
        {pos: [0, 3, 11], state: "minecraft:deepslate_bricks"},
        {pos: [0, 3, 12], state: "minecraft:deepslate_bricks"},
        {pos: [0, 3, 13], state: "minecraft:deepslate_bricks"},
        {pos: [0, 3, 14], state: "minecraft:deepslate_bricks"},
        {pos: [0, 3, 15], state: "minecraft:deepslate_bricks"},
        {pos: [1, 3, 0], state: "minecraft:deepslate_bricks"},
        {pos: [1, 3, 1], state: "minecraft:deepslate_bricks"},
        {pos: [1, 3, 2], state: "minecraft:deepslate_bricks"},
        {pos: [1, 3, 3], state: "minecraft:deepslate_bricks"},
        {pos: [1, 3, 4], state: "minecraft:deepslate_bricks"},
        {pos: [1, 3, 5], state: "minecraft:deepslate_bricks"},
        {pos: [1, 3, 6], state: "minecraft:skeleton_skull{powered:false,rotation:8}", nbt: {id: "minecraft:skull"}},
        {pos: [1, 3, 7], state: "minecraft:cave_air"},
        {pos: [1, 3, 8], state: "minecraft:cave_air"},
        {pos: [1, 3, 9], state: "minecraft:cave_air"},
        {pos: [1, 3, 10], state: "minecraft:skeleton_skull{powered:false,rotation:0}", nbt: {id: "minecraft:skull"}},
        {pos: [1, 3, 11], state: "minecraft:deepslate_bricks"},
        {pos: [1, 3, 12], state: "minecraft:deepslate_bricks"},
        {pos: [1, 3, 13], state: "minecraft:deepslate_bricks"},
        {pos: [1, 3, 14], state: "minecraft:deepslate_bricks"},
        {pos: [1, 3, 15], state: "minecraft:deepslate_bricks"},
        {pos: [2, 3, 0], state: "minecraft:deepslate_bricks"},
        {pos: [2, 3, 1], state: "minecraft:deepslate_bricks"},
        {pos: [2, 3, 2], state: "minecraft:deepslate_bricks"},
        {pos: [2, 3, 3], state: "minecraft:skeleton_skull{powered:false,rotation:4}", nbt: {id: "minecraft:skull"}},
        {pos: [2, 3, 4], state: "minecraft:deepslate_bricks"},
        {pos: [2, 3, 5], state: "minecraft:skeleton_skull{powered:false,rotation:4}", nbt: {id: "minecraft:skull"}},
        {pos: [2, 3, 6], state: "minecraft:deepslate_bricks"},
        {pos: [2, 3, 7], state: "minecraft:cave_air"},
        {pos: [2, 3, 8], state: "minecraft:cave_air"},
        {pos: [2, 3, 9], state: "minecraft:cave_air"},
        {pos: [2, 3, 10], state: "minecraft:deepslate_bricks"},
        {pos: [2, 3, 11], state: "minecraft:deepslate_bricks"},
        {pos: [2, 3, 12], state: "minecraft:cave_air"},
        {pos: [2, 3, 13], state: "minecraft:deepslate_bricks"},
        {pos: [2, 3, 14], state: "minecraft:deepslate_bricks"},
        {pos: [2, 3, 15], state: "minecraft:deepslate_bricks"},
        {pos: [3, 3, 0], state: "minecraft:deepslate_bricks"},
        {pos: [3, 3, 1], state: "minecraft:deepslate_bricks"},
        {pos: [3, 3, 2], state: "minecraft:cobbled_deepslate"},
        {pos: [3, 3, 3], state: "minecraft:cave_air"},
        {pos: [3, 3, 4], state: "minecraft:cave_air"},
        {pos: [3, 3, 5], state: "minecraft:cave_air"},
        {pos: [3, 3, 6], state: "minecraft:cave_air"},
        {pos: [3, 3, 7], state: "minecraft:cave_air"},
        {pos: [3, 3, 8], state: "minecraft:cave_air"},
        {pos: [3, 3, 9], state: "minecraft:cave_air"},
        {pos: [3, 3, 10], state: "minecraft:cave_air"},
        {pos: [3, 3, 11], state: "minecraft:cave_air"},
        {pos: [3, 3, 12], state: "minecraft:cobbled_deepslate"},
        {pos: [3, 3, 13], state: "minecraft:cobbled_deepslate"},
        {pos: [3, 3, 14], state: "minecraft:deepslate_bricks"},
        {pos: [3, 3, 15], state: "minecraft:deepslate_bricks"},
        {pos: [4, 3, 0], state: "minecraft:deepslate_bricks"},
        {pos: [4, 3, 1], state: "minecraft:skeleton_skull{powered:false,rotation:8}", nbt: {id: "minecraft:skull"}},
        {pos: [4, 3, 2], state: "minecraft:cave_air"},
        {pos: [4, 3, 3], state: "minecraft:cave_air"},
        {pos: [4, 3, 4], state: "minecraft:cave_air"},
        {pos: [4, 3, 5], state: "minecraft:cave_air"},
        {pos: [4, 3, 6], state: "minecraft:cave_air"},
        {pos: [4, 3, 7], state: "minecraft:cave_air"},
        {pos: [4, 3, 8], state: "minecraft:cave_air"},
        {pos: [4, 3, 9], state: "minecraft:candle{candles:4,lit:false,waterlogged:false}"},
        {pos: [4, 3, 10], state: "minecraft:cobbled_deepslate"},
        {pos: [4, 3, 11], state: "minecraft:deepslate_bricks"},
        {pos: [4, 3, 12], state: "minecraft:deepslate_bricks"},
        {pos: [4, 3, 13], state: "minecraft:cobbled_deepslate"},
        {pos: [4, 3, 14], state: "minecraft:cave_air"},
        {pos: [4, 3, 15], state: "minecraft:deepslate_bricks"},
        {pos: [5, 3, 0], state: "minecraft:deepslate_bricks"},
        {pos: [5, 3, 1], state: "minecraft:deepslate_bricks"},
        {pos: [5, 3, 2], state: "minecraft:decorated_pot{cracked:false,facing:north,waterlogged:false}", nbt: {id: "minecraft:decorated_pot"}},
        {pos: [5, 3, 3], state: "minecraft:cave_air"},
        {pos: [5, 3, 4], state: "minecraft:cave_air"},
        {pos: [5, 3, 5], state: "minecraft:cave_air"},
        {pos: [5, 3, 6], state: "minecraft:cave_air"},
        {pos: [5, 3, 7], state: "minecraft:cave_air"},
        {pos: [5, 3, 8], state: "minecraft:cave_air"},
        {pos: [5, 3, 9], state: "minecraft:candle{candles:4,lit:false,waterlogged:false}"},
        {pos: [5, 3, 10], state: "minecraft:deepslate_bricks"},
        {pos: [5, 3, 11], state: "minecraft:deepslate_bricks"},
        {pos: [5, 3, 12], state: "minecraft:deepslate_bricks"},
        {pos: [5, 3, 13], state: "minecraft:cobbled_deepslate"},
        {pos: [5, 3, 14], state: "minecraft:deepslate_bricks"},
        {pos: [5, 3, 15], state: "minecraft:deepslate_bricks"},
        {pos: [6, 3, 0], state: "minecraft:deepslate_bricks"},
        {pos: [6, 3, 1], state: "minecraft:deepslate_bricks"},
        {pos: [6, 3, 2], state: "minecraft:deepslate_bricks"},
        {pos: [6, 3, 3], state: "minecraft:cave_air"},
        {pos: [6, 3, 4], state: "minecraft:cave_air"},
        {pos: [6, 3, 5], state: "minecraft:cave_air"},
        {pos: [6, 3, 6], state: "minecraft:cave_air"},
        {pos: [6, 3, 7], state: "minecraft:cave_air"},
        {pos: [6, 3, 8], state: "minecraft:cave_air"},
        {pos: [6, 3, 9], state: "minecraft:cave_air"},
        {pos: [6, 3, 10], state: "minecraft:deepslate_bricks"},
        {pos: [6, 3, 11], state: "minecraft:deepslate_bricks"},
        {pos: [6, 3, 12], state: "minecraft:deepslate_bricks"},
        {pos: [6, 3, 13], state: "minecraft:cave_air"},
        {pos: [6, 3, 14], state: "minecraft:decorated_pot{cracked:false,facing:south,waterlogged:false}", nbt: {id: "minecraft:decorated_pot"}},
        {pos: [6, 3, 15], state: "minecraft:deepslate_bricks"},
        {pos: [7, 3, 0], state: "minecraft:deepslate_bricks"},
        {pos: [7, 3, 1], state: "minecraft:deepslate_bricks"},
        {pos: [7, 3, 2], state: "minecraft:deepslate_bricks"},
        {pos: [7, 3, 3], state: "minecraft:deepslate_bricks"},
        {pos: [7, 3, 4], state: "minecraft:deepslate_bricks"},
        {pos: [7, 3, 5], state: "minecraft:deepslate_brick_stairs{facing:north,half:bottom,shape:straight,waterlogged:false}"},
        {pos: [7, 3, 6], state: "minecraft:cave_air"},
        {pos: [7, 3, 7], state: "minecraft:cave_air"},
        {pos: [7, 3, 8], state: "minecraft:cave_air"},
        {pos: [7, 3, 9], state: "minecraft:cave_air"},
        {pos: [7, 3, 10], state: "minecraft:cave_air"},
        {pos: [7, 3, 11], state: "minecraft:cave_air"},
        {pos: [7, 3, 12], state: "minecraft:cave_air"},
        {pos: [7, 3, 13], state: "minecraft:cave_air"},
        {pos: [7, 3, 14], state: "minecraft:deepslate_bricks"},
        {pos: [7, 3, 15], state: "minecraft:deepslate_bricks"},
        {pos: [8, 3, 0], state: "minecraft:deepslate_bricks"},
        {pos: [8, 3, 1], state: "minecraft:deepslate_bricks"},
        {pos: [8, 3, 2], state: "minecraft:deepslate_bricks"},
        {pos: [8, 3, 3], state: "minecraft:deepslate_bricks"},
        {pos: [8, 3, 4], state: "minecraft:deepslate_bricks"},
        {pos: [8, 3, 5], state: "minecraft:deepslate_bricks"},
        {pos: [8, 3, 6], state: "minecraft:deepslate_bricks"},
        {pos: [8, 3, 7], state: "minecraft:cave_air"},
        {pos: [8, 3, 8], state: "minecraft:cave_air"},
        {pos: [8, 3, 9], state: "minecraft:deepslate_bricks"},
        {pos: [8, 3, 10], state: "minecraft:deepslate_brick_stairs{facing:north,half:bottom,shape:straight,waterlogged:false}"},
        {pos: [8, 3, 11], state: "minecraft:cave_air"},
        {pos: [8, 3, 12], state: "minecraft:cave_air"},
        {pos: [8, 3, 13], state: "minecraft:deepslate_bricks"},
        {pos: [8, 3, 14], state: "minecraft:deepslate_bricks"},
        {pos: [8, 3, 15], state: "minecraft:deepslate_bricks"},
        {pos: [9, 3, 0], state: "minecraft:deepslate_bricks"},
        {pos: [9, 3, 1], state: "minecraft:deepslate_bricks"},
        {pos: [9, 3, 2], state: "minecraft:deepslate_bricks"},
        {pos: [9, 3, 3], state: "minecraft:deepslate_bricks"},
        {pos: [9, 3, 4], state: "minecraft:deepslate_bricks"},
        {pos: [9, 3, 5], state: "minecraft:deepslate_bricks"},
        {pos: [9, 3, 6], state: "minecraft:skeleton_skull{powered:false,rotation:8}", nbt: {id: "minecraft:skull"}},
        {pos: [9, 3, 7], state: "minecraft:cave_air"},
        {pos: [9, 3, 8], state: "minecraft:cave_air"},
        {pos: [9, 3, 9], state: "minecraft:deepslate_bricks"},
        {pos: [9, 3, 10], state: "minecraft:cave_air"},
        {pos: [9, 3, 11], state: "minecraft:cave_air"},
        {pos: [9, 3, 12], state: "minecraft:cave_air"},
        {pos: [9, 3, 13], state: "minecraft:deepslate_bricks"},
        {pos: [9, 3, 14], state: "minecraft:deepslate_bricks"},
        {pos: [9, 3, 15], state: "minecraft:deepslate_bricks"},
        {pos: [10, 3, 0], state: "minecraft:deepslate_bricks"},
        {pos: [10, 3, 1], state: "minecraft:deepslate_bricks"},
        {pos: [10, 3, 2], state: "minecraft:deepslate_bricks"},
        {pos: [10, 3, 3], state: "minecraft:deepslate_bricks"},
        {pos: [10, 3, 4], state: "minecraft:deepslate_bricks"},
        {pos: [10, 3, 5], state: "minecraft:deepslate_bricks"},
        {pos: [10, 3, 6], state: "minecraft:deepslate_bricks"},
        {pos: [10, 3, 7], state: "minecraft:cave_air"},
        {pos: [10, 3, 8], state: "minecraft:cave_air"},
        {pos: [10, 3, 9], state: "minecraft:deepslate_bricks"},
        {pos: [10, 3, 10], state: "minecraft:cave_air"},
        {pos: [10, 3, 11], state: "minecraft:cave_air"},
        {pos: [10, 3, 12], state: "minecraft:cave_air"},
        {pos: [10, 3, 13], state: "minecraft:deepslate_bricks"},
        {pos: [10, 3, 14], state: "minecraft:deepslate_bricks"},
        {pos: [10, 3, 15], state: "minecraft:deepslate_bricks"},
        {pos: [10, 3, 16], state: "minecraft:deepslate_bricks"},
        {pos: [10, 3, 17], state: "minecraft:deepslate_bricks"},
        {pos: [11, 3, 0], state: "minecraft:deepslate_bricks"},
        {pos: [11, 3, 1], state: "minecraft:deepslate_bricks"},
        {pos: [11, 3, 2], state: "minecraft:deepslate_bricks"},
        {pos: [11, 3, 3], state: "minecraft:deepslate_bricks"},
        {pos: [11, 3, 4], state: "minecraft:deepslate_bricks"},
        {pos: [11, 3, 5], state: "minecraft:deepslate_bricks"},
        {pos: [11, 3, 6], state: "minecraft:skeleton_skull{powered:false,rotation:8}", nbt: {id: "minecraft:skull"}},
        {pos: [11, 3, 7], state: "minecraft:cave_air"},
        {pos: [11, 3, 8], state: "minecraft:cave_air"},
        {pos: [11, 3, 9], state: "minecraft:deepslate_bricks"},
        {pos: [11, 3, 10], state: "minecraft:skeleton_skull{powered:false,rotation:12}", nbt: {id: "minecraft:skull"}},
        {pos: [11, 3, 11], state: "minecraft:skeleton_skull{powered:false,rotation:12}", nbt: {id: "minecraft:skull"}},
        {pos: [11, 3, 12], state: "minecraft:cave_air"},
        {pos: [11, 3, 13], state: "minecraft:cobbled_deepslate"},
        {pos: [11, 3, 14], state: "minecraft:cave_air"},
        {pos: [11, 3, 15], state: "minecraft:cave_air"},
        {pos: [11, 3, 16], state: "minecraft:cobbled_deepslate"},
        {pos: [11, 3, 17], state: "minecraft:deepslate_bricks"},
        {pos: [12, 3, 0], state: "minecraft:deepslate_bricks"},
        {pos: [12, 3, 1], state: "minecraft:deepslate_bricks"},
        {pos: [12, 3, 2], state: "minecraft:deepslate_brick_stairs{facing:west,half:bottom,shape:straight,waterlogged:false}"},
        {pos: [12, 3, 3], state: "minecraft:deepslate_brick_stairs{facing:west,half:bottom,shape:straight,waterlogged:false}"},
        {pos: [12, 3, 4], state: "minecraft:deepslate_bricks"},
        {pos: [12, 3, 5], state: "minecraft:deepslate_bricks"},
        {pos: [12, 3, 6], state: "minecraft:deepslate_bricks"},
        {pos: [12, 3, 7], state: "minecraft:cave_air"},
        {pos: [12, 3, 8], state: "minecraft:cave_air"},
        {pos: [12, 3, 9], state: "minecraft:deepslate_bricks"},
        {pos: [12, 3, 10], state: "minecraft:deepslate_bricks"},
        {pos: [12, 3, 11], state: "minecraft:cobbled_deepslate"},
        {pos: [12, 3, 12], state: "minecraft:cobbled_deepslate"},
        {pos: [12, 3, 13], state: "minecraft:cobbled_deepslate"},
        {pos: [12, 3, 14], state: "minecraft:cave_air"},
        {pos: [12, 3, 15], state: "minecraft:cave_air"},
        {pos: [12, 3, 16], state: "minecraft:cobbled_deepslate"},
        {pos: [12, 3, 17], state: "minecraft:deepslate_bricks"},
        {pos: [13, 3, 0], state: "minecraft:deepslate_bricks"},
        {pos: [13, 3, 1], state: "minecraft:deepslate_bricks"},
        {pos: [13, 3, 2], state: "minecraft:cave_air"},
        {pos: [13, 3, 3], state: "minecraft:candle{candles:4,lit:false,waterlogged:false}"},
        {pos: [13, 3, 4], state: "minecraft:candle{candles:4,lit:false,waterlogged:false}"},
        {pos: [13, 3, 5], state: "minecraft:cave_air"},
        {pos: [13, 3, 6], state: "minecraft:cave_air"},
        {pos: [13, 3, 7], state: "minecraft:cave_air"},
        {pos: [13, 3, 8], state: "minecraft:cave_air"},
        {pos: [13, 3, 9], state: "minecraft:cave_air"},
        {pos: [13, 3, 10], state: "minecraft:skeleton_skull{powered:false,rotation:4}", nbt: {id: "minecraft:skull"}},
        {pos: [13, 3, 11], state: "minecraft:skeleton_skull{powered:false,rotation:4}", nbt: {id: "minecraft:skull"}},
        {pos: [13, 3, 12], state: "minecraft:skeleton_skull{powered:false,rotation:4}", nbt: {id: "minecraft:skull"}},
        {pos: [13, 3, 13], state: "minecraft:cave_air"},
        {pos: [13, 3, 14], state: "minecraft:cave_air"},
        {pos: [13, 3, 15], state: "minecraft:cave_air"},
        {pos: [13, 3, 16], state: "minecraft:skeleton_skull{powered:false,rotation:0}", nbt: {id: "minecraft:skull"}},
        {pos: [13, 3, 17], state: "minecraft:deepslate_bricks"},
        {pos: [14, 3, 0], state: "minecraft:deepslate_bricks"},
        {pos: [14, 3, 1], state: "minecraft:deepslate_bricks"},
        {pos: [14, 3, 2], state: "minecraft:cave_air"},
        {pos: [14, 3, 3], state: "minecraft:cave_air"},
        {pos: [14, 3, 4], state: "minecraft:cave_air"},
        {pos: [14, 3, 5], state: "minecraft:cave_air"},
        {pos: [14, 3, 6], state: "minecraft:cave_air"},
        {pos: [14, 3, 7], state: "minecraft:cave_air"},
        {pos: [14, 3, 8], state: "minecraft:cave_air"},
        {pos: [14, 3, 9], state: "minecraft:cave_air"},
        {pos: [14, 3, 10], state: "minecraft:cave_air"},
        {pos: [14, 3, 11], state: "minecraft:cave_air"},
        {pos: [14, 3, 12], state: "minecraft:cave_air"},
        {pos: [14, 3, 13], state: "minecraft:cave_air"},
        {pos: [14, 3, 14], state: "minecraft:cave_air"},
        {pos: [14, 3, 15], state: "minecraft:cave_air"},
        {pos: [14, 3, 16], state: "minecraft:candle{candles:4,lit:false,waterlogged:false}"},
        {pos: [14, 3, 17], state: "minecraft:deepslate_bricks"},
        {pos: [15, 3, 0], state: "minecraft:deepslate_bricks"},
        {pos: [15, 3, 1], state: "minecraft:deepslate_bricks"},
        {pos: [15, 3, 2], state: "minecraft:cave_air"},
        {pos: [15, 3, 3], state: "minecraft:cave_air"},
        {pos: [15, 3, 4], state: "minecraft:cave_air"},
        {pos: [15, 3, 5], state: "minecraft:cave_air"},
        {pos: [15, 3, 6], state: "minecraft:cave_air"},
        {pos: [15, 3, 7], state: "minecraft:cave_air"},
        {pos: [15, 3, 8], state: "minecraft:cave_air"},
        {pos: [15, 3, 9], state: "minecraft:candle{candles:4,lit:false,waterlogged:false}"},
        {pos: [15, 3, 10], state: "minecraft:candle{candles:4,lit:false,waterlogged:false}"},
        {pos: [15, 3, 11], state: "minecraft:candle{candles:4,lit:false,waterlogged:false}"},
        {pos: [15, 3, 12], state: "minecraft:cave_air"},
        {pos: [15, 3, 13], state: "minecraft:cave_air"},
        {pos: [15, 3, 14], state: "minecraft:cave_air"},
        {pos: [15, 3, 15], state: "minecraft:cave_air"},
        {pos: [15, 3, 16], state: "minecraft:cobweb"},
        {pos: [15, 3, 17], state: "minecraft:deepslate_bricks"},
        {pos: [16, 3, 0], state: "minecraft:deepslate_bricks"},
        {pos: [16, 3, 1], state: "minecraft:deepslate_bricks"},
        {pos: [16, 3, 2], state: "minecraft:cave_air"},
        {pos: [16, 3, 3], state: "minecraft:cave_air"},
        {pos: [16, 3, 4], state: "minecraft:cave_air"},
        {pos: [16, 3, 5], state: "minecraft:cave_air"},
        {pos: [16, 3, 6], state: "minecraft:candle{candles:4,lit:false,waterlogged:false}"},
        {pos: [16, 3, 7], state: "minecraft:candle{candles:4,lit:false,waterlogged:false}"},
        {pos: [16, 3, 8], state: "minecraft:cave_air"},
        {pos: [16, 3, 9], state: "minecraft:cobbled_deepslate"},
        {pos: [16, 3, 10], state: "minecraft:cobbled_deepslate"},
        {pos: [16, 3, 11], state: "minecraft:cobbled_deepslate"},
        {pos: [16, 3, 12], state: "minecraft:deepslate_bricks"},
        {pos: [16, 3, 13], state: "minecraft:deepslate_bricks"},
        {pos: [16, 3, 14], state: "minecraft:cave_air"},
        {pos: [16, 3, 15], state: "minecraft:cave_air"},
        {pos: [16, 3, 16], state: "minecraft:candle{candles:4,lit:false,waterlogged:false}"},
        {pos: [16, 3, 17], state: "minecraft:deepslate_bricks"},
        {pos: [17, 3, 0], state: "minecraft:deepslate_bricks"},
        {pos: [17, 3, 1], state: "minecraft:deepslate_bricks"},
        {pos: [17, 3, 2], state: "minecraft:deepslate_bricks"},
        {pos: [17, 3, 3], state: "minecraft:deepslate_brick_stairs{facing:north,half:bottom,shape:straight,waterlogged:false}"},
        {pos: [17, 3, 4], state: "minecraft:cave_air"},
        {pos: [17, 3, 5], state: "minecraft:skeleton_skull{powered:false,rotation:12}", nbt: {id: "minecraft:skull"}},
        {pos: [17, 3, 6], state: "minecraft:cobbled_deepslate"},
        {pos: [17, 3, 7], state: "minecraft:candle{candles:4,lit:false,waterlogged:false}"},
        {pos: [17, 3, 8], state: "minecraft:cave_air"},
        {pos: [17, 3, 9], state: "minecraft:candle{candles:4,lit:false,waterlogged:false}"},
        {pos: [17, 3, 10], state: "minecraft:cobbled_deepslate"},
        {pos: [17, 3, 11], state: "minecraft:deepslate_bricks"},
        {pos: [17, 3, 12], state: "minecraft:deepslate_bricks"},
        {pos: [17, 3, 13], state: "minecraft:deepslate_bricks"},
        {pos: [17, 3, 14], state: "minecraft:cave_air"},
        {pos: [17, 3, 15], state: "minecraft:cobweb"},
        {pos: [17, 3, 16], state: "minecraft:candle{candles:4,lit:false,waterlogged:false}"},
        {pos: [17, 3, 17], state: "minecraft:deepslate_bricks"},
        {pos: [18, 3, 0], state: "minecraft:deepslate_bricks"},
        {pos: [18, 3, 1], state: "minecraft:deepslate_bricks"},
        {pos: [18, 3, 2], state: "minecraft:cave_air"},
        {pos: [18, 3, 3], state: "minecraft:cave_air"},
        {pos: [18, 3, 4], state: "minecraft:cave_air"},
        {pos: [18, 3, 5], state: "minecraft:candle{candles:4,lit:false,waterlogged:false}"},
        {pos: [18, 3, 6], state: "minecraft:cave_air"},
        {pos: [18, 3, 7], state: "minecraft:cave_air"},
        {pos: [18, 3, 8], state: "minecraft:cave_air"},
        {pos: [18, 3, 9], state: "minecraft:candle{candles:4,lit:false,waterlogged:false}"},
        {pos: [18, 3, 10], state: "minecraft:deepslate_bricks"},
        {pos: [18, 3, 11], state: "minecraft:deepslate_bricks"},
        {pos: [18, 3, 12], state: "minecraft:deepslate_bricks"},
        {pos: [18, 3, 13], state: "minecraft:deepslate_bricks"},
        {pos: [18, 3, 14], state: "minecraft:deepslate_bricks"},
        {pos: [18, 3, 15], state: "minecraft:deepslate_bricks"},
        {pos: [18, 3, 16], state: "minecraft:deepslate_bricks"},
        {pos: [18, 3, 17], state: "minecraft:deepslate_bricks"},
        {pos: [19, 3, 0], state: "minecraft:deepslate_bricks"},
        {pos: [19, 3, 1], state: "minecraft:deepslate_bricks"},
        {pos: [19, 3, 2], state: "minecraft:cave_air"},
        {pos: [19, 3, 3], state: "minecraft:cave_air"},
        {pos: [19, 3, 4], state: "minecraft:cave_air"},
        {pos: [19, 3, 5], state: "minecraft:cave_air"},
        {pos: [19, 3, 6], state: "minecraft:cave_air"},
        {pos: [19, 3, 7], state: "minecraft:cave_air"},
        {pos: [19, 3, 8], state: "minecraft:cave_air"},
        {pos: [19, 3, 9], state: "minecraft:cave_air"},
        {pos: [19, 3, 10], state: "minecraft:skeleton_skull{powered:false,rotation:0}", nbt: {id: "minecraft:skull"}},
        {pos: [19, 3, 11], state: "minecraft:deepslate_bricks"},
        {pos: [19, 3, 12], state: "minecraft:deepslate_bricks"},
        {pos: [19, 3, 13], state: "minecraft:deepslate_bricks"},
        {pos: [20, 3, 0], state: "minecraft:deepslate_bricks"},
        {pos: [20, 3, 1], state: "minecraft:deepslate_bricks"},
        {pos: [20, 3, 2], state: "minecraft:cobweb"},
        {pos: [20, 3, 3], state: "minecraft:cave_air"},
        {pos: [20, 3, 4], state: "minecraft:skeleton_skull{powered:false,rotation:12}", nbt: {id: "minecraft:skull"}},
        {pos: [20, 3, 5], state: "minecraft:candle{candles:4,lit:false,waterlogged:false}"},
        {pos: [20, 3, 6], state: "minecraft:cave_air"},
        {pos: [20, 3, 7], state: "minecraft:cave_air"},
        {pos: [20, 3, 8], state: "minecraft:cave_air"},
        {pos: [20, 3, 9], state: "minecraft:cave_air"},
        {pos: [20, 3, 10], state: "minecraft:deepslate_bricks"},
        {pos: [20, 3, 11], state: "minecraft:deepslate_bricks"},
        {pos: [20, 3, 12], state: "minecraft:deepslate_bricks"},
        {pos: [20, 3, 13], state: "minecraft:deepslate_bricks"},
        {pos: [21, 3, 0], state: "minecraft:deepslate_bricks"},
        {pos: [21, 3, 1], state: "minecraft:deepslate_bricks"},
        {pos: [21, 3, 2], state: "minecraft:deepslate_bricks"},
        {pos: [21, 3, 3], state: "minecraft:cobbled_deepslate"},
        {pos: [21, 3, 4], state: "minecraft:cobbled_deepslate"},
        {pos: [21, 3, 5], state: "minecraft:cobbled_deepslate"},
        {pos: [21, 3, 6], state: "minecraft:cobbled_deepslate"},
        {pos: [21, 3, 7], state: "minecraft:cave_air"},
        {pos: [21, 3, 8], state: "minecraft:cave_air"},
        {pos: [21, 3, 9], state: "minecraft:cave_air"},
        {pos: [21, 3, 10], state: "minecraft:skeleton_skull{powered:false,rotation:0}", nbt: {id: "minecraft:skull"}},
        {pos: [21, 3, 11], state: "minecraft:deepslate_bricks"},
        {pos: [21, 3, 12], state: "minecraft:deepslate_bricks"},
        {pos: [21, 3, 13], state: "minecraft:deepslate_bricks"},
        {pos: [22, 3, 5], state: "minecraft:deepslate_bricks"},
        {pos: [22, 3, 6], state: "minecraft:deepslate_bricks"},
        {pos: [22, 3, 7], state: "minecraft:cave_air"},
        {pos: [22, 3, 8], state: "minecraft:cave_air"},
        {pos: [22, 3, 9], state: "minecraft:cave_air"},
        {pos: [22, 3, 10], state: "minecraft:deepslate_bricks"},
        {pos: [22, 3, 11], state: "minecraft:deepslate_bricks"},
        {pos: [23, 3, 5], state: "minecraft:deepslate_bricks"},
        {pos: [23, 3, 6], state: "minecraft:skeleton_skull{powered:false,rotation:8}", nbt: {id: "minecraft:skull"}},
        {pos: [23, 3, 7], state: "minecraft:cave_air"},
        {pos: [23, 3, 8], state: "minecraft:cave_air"},
        {pos: [23, 3, 9], state: "minecraft:cave_air"},
