{
    DataVersion: 3955,
    size: [27, 16, 45],
    data: [
        {pos: [0, 0, 16], state: "minecraft:deepslate{axis:y}"},
        {pos: [0, 0, 17], state: "minecraft:deepslate{axis:y}"},
        {pos: [0, 0, 18], state: "minecraft:deepslate{axis:y}"},
        {pos: [0, 0, 19], state: "minecraft:deepslate{axis:y}"},
        {pos: [0, 0, 20], state: "minecraft:deepslate{axis:y}"},
        {pos: [0, 0, 21], state: "minecraft:deepslate{axis:y}"},
        {pos: [0, 0, 22], state: "minecraft:deepslate{axis:y}"},
        {pos: [0, 0, 23], state: "minecraft:deepslate{axis:y}"},
        {pos: [0, 0, 24], state: "minecraft:deepslate{axis:y}"},
        {pos: [0, 0, 25], state: "minecraft:deepslate{axis:y}"},
        {pos: [0, 0, 26], state: "minecraft:deepslate{axis:y}"},
        {pos: [0, 0, 27], state: "minecraft:deepslate{axis:y}"},
        {pos: [0, 0, 28], state: "minecraft:deepslate{axis:y}"},
        {pos: [1, 0, 16], state: "minecraft:deepslate{axis:y}"},
        {pos: [1, 0, 17], state: "minecraft:deepslate{axis:y}"},
        {pos: [1, 0, 18], state: "minecraft:deepslate{axis:y}"},
        {pos: [1, 0, 19], state: "minecraft:deepslate{axis:y}"},
        {pos: [1, 0, 20], state: "minecraft:deepslate{axis:y}"},
        {pos: [1, 0, 21], state: "minecraft:deepslate{axis:y}"},
        {pos: [1, 0, 22], state: "minecraft:deepslate{axis:y}"},
        {pos: [1, 0, 23], state: "minecraft:deepslate{axis:y}"},
        {pos: [1, 0, 24], state: "minecraft:deepslate{axis:y}"},
        {pos: [1, 0, 25], state: "minecraft:deepslate{axis:y}"},
        {pos: [1, 0, 26], state: "minecraft:deepslate{axis:y}"},
        {pos: [1, 0, 27], state: "minecraft:deepslate{axis:y}"},
        {pos: [1, 0, 28], state: "minecraft:deepslate{axis:y}"},
        {pos: [2, 0, 16], state: "minecraft:deepslate{axis:y}"},
        {pos: [2, 0, 17], state: "minecraft:deepslate{axis:y}"},
        {pos: [2, 0, 18], state: "minecraft:deepslate{axis:y}"},
        {pos: [2, 0, 19], state: "minecraft:deepslate{axis:y}"},
        {pos: [2, 0, 20], state: "minecraft:deepslate{axis:y}"},
        {pos: [2, 0, 21], state: "minecraft:deepslate{axis:y}"},
        {pos: [2, 0, 22], state: "minecraft:deepslate{axis:y}"},
        {pos: [2, 0, 23], state: "minecraft:deepslate{axis:y}"},
        {pos: [2, 0, 24], state: "minecraft:deepslate{axis:y}"},
        {pos: [2, 0, 25], state: "minecraft:deepslate{axis:y}"},
        {pos: [2, 0, 26], state: "minecraft:deepslate{axis:y}"},
        {pos: [2, 0, 27], state: "minecraft:deepslate{axis:y}"},
        {pos: [2, 0, 28], state: "minecraft:deepslate{axis:y}"},
        {pos: [3, 0, 16], state: "minecraft:deepslate{axis:y}"},
        {pos: [3, 0, 17], state: "minecraft:deepslate{axis:y}"},
        {pos: [3, 0, 18], state: "minecraft:deepslate{axis:y}"},
        {pos: [3, 0, 19], state: "minecraft:deepslate{axis:y}"},
        {pos: [3, 0, 20], state: "minecraft:deepslate{axis:y}"},
        {pos: [3, 0, 21], state: "minecraft:deepslate{axis:y}"},
        {pos: [3, 0, 22], state: "minecraft:deepslate{axis:y}"},
        {pos: [3, 0, 23], state: "minecraft:deepslate{axis:y}"},
        {pos: [3, 0, 24], state: "minecraft:deepslate{axis:y}"},
        {pos: [3, 0, 25], state: "minecraft:deepslate{axis:y}"},
        {pos: [3, 0, 26], state: "minecraft:deepslate{axis:y}"},
        {pos: [3, 0, 27], state: "minecraft:deepslate{axis:y}"},
        {pos: [3, 0, 28], state: "minecraft:deepslate{axis:y}"},
        {pos: [4, 0, 16], state: "minecraft:deepslate{axis:y}"},
        {pos: [4, 0, 17], state: "minecraft:deepslate{axis:y}"},
        {pos: [4, 0, 18], state: "minecraft:deepslate{axis:y}"},
        {pos: [4, 0, 19], state: "minecraft:deepslate{axis:y}"},
        {pos: [4, 0, 20], state: "minecraft:deepslate{axis:y}"},
        {pos: [4, 0, 21], state: "minecraft:deepslate{axis:y}"},
        {pos: [4, 0, 22], state: "minecraft:deepslate{axis:y}"},
        {pos: [4, 0, 23], state: "minecraft:deepslate{axis:y}"},
        {pos: [4, 0, 24], state: "minecraft:deepslate{axis:y}"},
        {pos: [4, 0, 25], state: "minecraft:deepslate{axis:y}"},
        {pos: [4, 0, 26], state: "minecraft:deepslate{axis:y}"},
        {pos: [4, 0, 27], state: "minecraft:deepslate{axis:y}"},
        {pos: [4, 0, 28], state: "minecraft:deepslate{axis:y}"},
        {pos: [5, 0, 16], state: "minecraft:deepslate{axis:y}"},
        {pos: [5, 0, 17], state: "minecraft:deepslate{axis:y}"},
        {pos: [5, 0, 18], state: "minecraft:deepslate{axis:y}"},
        {pos: [5, 0, 19], state: "minecraft:deepslate{axis:y}"},
        {pos: [5, 0, 20], state: "minecraft:deepslate{axis:y}"},
        {pos: [5, 0, 21], state: "minecraft:deepslate{axis:y}"},
        {pos: [5, 0, 22], state: "minecraft:deepslate{axis:y}"},
        {pos: [5, 0, 23], state: "minecraft:deepslate{axis:y}"},
        {pos: [5, 0, 24], state: "minecraft:deepslate{axis:y}"},
        {pos: [5, 0, 25], state: "minecraft:deepslate{axis:y}"},
        {pos: [5, 0, 26], state: "minecraft:deepslate{axis:y}"},
        {pos: [5, 0, 27], state: "minecraft:deepslate{axis:y}"},
        {pos: [5, 0, 28], state: "minecraft:deepslate{axis:y}"},
        {pos: [6, 0, 16], state: "minecraft:deepslate{axis:y}"},
        {pos: [6, 0, 17], state: "minecraft:deepslate{axis:y}"},
        {pos: [6, 0, 18], state: "minecraft:deepslate{axis:y}"},
        {pos: [6, 0, 19], state: "minecraft:deepslate{axis:y}"},
        {pos: [6, 0, 20], state: "minecraft:deepslate{axis:y}"},
        {pos: [6, 0, 21], state: "minecraft:deepslate{axis:y}"},
        {pos: [6, 0, 22], state: "minecraft:deepslate{axis:y}"},
        {pos: [6, 0, 23], state: "minecraft:deepslate{axis:y}"},
        {pos: [6, 0, 24], state: "minecraft:deepslate{axis:y}"},
        {pos: [6, 0, 25], state: "minecraft:deepslate{axis:y}"},
        {pos: [6, 0, 26], state: "minecraft:deepslate{axis:y}"},
        {pos: [6, 0, 27], state: "minecraft:deepslate{axis:y}"},
        {pos: [6, 0, 28], state: "minecraft:deepslate{axis:y}"},
        {pos: [7, 0, 16], state: "minecraft:deepslate{axis:y}"},
        {pos: [7, 0, 17], state: "minecraft:deepslate{axis:y}"},
        {pos: [7, 0, 18], state: "minecraft:deepslate{axis:y}"},
        {pos: [7, 0, 19], state: "minecraft:deepslate{axis:y}"},
        {pos: [7, 0, 20], state: "minecraft:deepslate{axis:y}"},
        {pos: [7, 0, 21], state: "minecraft:deepslate{axis:y}"},
        {pos: [7, 0, 22], state: "minecraft:deepslate{axis:y}"},
        {pos: [7, 0, 23], state: "minecraft:deepslate{axis:y}"},
        {pos: [7, 0, 24], state: "minecraft:deepslate{axis:y}"},
        {pos: [7, 0, 25], state: "minecraft:deepslate{axis:y}"},
        {pos: [7, 0, 26], state: "minecraft:deepslate{axis:y}"},
        {pos: [7, 0, 27], state: "minecraft:deepslate{axis:y}"},
        {pos: [7, 0, 28], state: "minecraft:deepslate{axis:y}"},
        {pos: [8, 0, 16], state: "minecraft:deepslate{axis:y}"},
        {pos: [8, 0, 17], state: "minecraft:deepslate{axis:y}"},
        {pos: [8, 0, 18], state: "minecraft:deepslate{axis:y}"},
        {pos: [8, 0, 19], state: "minecraft:deepslate{axis:y}"},
        {pos: [8, 0, 20], state: "minecraft:deepslate{axis:y}"},
        {pos: [8, 0, 21], state: "minecraft:deepslate{axis:y}"},
        {pos: [8, 0, 22], state: "minecraft:deepslate{axis:y}"},
        {pos: [8, 0, 23], state: "minecraft:deepslate{axis:y}"},
        {pos: [8, 0, 24], state: "minecraft:deepslate{axis:y}"},
        {pos: [8, 0, 25], state: "minecraft:deepslate{axis:y}"},
        {pos: [8, 0, 26], state: "minecraft:deepslate{axis:y}"},
        {pos: [8, 0, 27], state: "minecraft:deepslate{axis:y}"},
        {pos: [8, 0, 28], state: "minecraft:deepslate{axis:y}"},
        {pos: [9, 0, 16], state: "minecraft:deepslate{axis:y}"},
        {pos: [9, 0, 17], state: "minecraft:deepslate{axis:y}"},
        {pos: [9, 0, 18], state: "minecraft:deepslate{axis:y}"},
        {pos: [9, 0, 19], state: "minecraft:deepslate{axis:y}"},
        {pos: [9, 0, 20], state: "minecraft:deepslate{axis:y}"},
        {pos: [9, 0, 21], state: "minecraft:deepslate{axis:y}"},
        {pos: [9, 0, 22], state: "minecraft:deepslate{axis:y}"},
        {pos: [9, 0, 23], state: "minecraft:deepslate{axis:y}"},
        {pos: [9, 0, 24], state: "minecraft:deepslate{axis:y}"},
        {pos: [9, 0, 25], state: "minecraft:deepslate{axis:y}"},
        {pos: [9, 0, 26], state: "minecraft:deepslate{axis:y}"},
        {pos: [9, 0, 27], state: "minecraft:deepslate{axis:y}"},
        {pos: [9, 0, 28], state: "minecraft:deepslate{axis:y}"},
        {pos: [10, 0, 16], state: "minecraft:deepslate{axis:y}"},
        {pos: [10, 0, 17], state: "minecraft:deepslate{axis:y}"},
        {pos: [10, 0, 18], state: "minecraft:deepslate{axis:y}"},
        {pos: [10, 0, 19], state: "minecraft:deepslate{axis:y}"},
        {pos: [10, 0, 20], state: "minecraft:deepslate{axis:y}"},
        {pos: [10, 0, 21], state: "minecraft:deepslate{axis:y}"},
        {pos: [10, 0, 22], state: "minecraft:deepslate{axis:y}"},
        {pos: [10, 0, 23], state: "minecraft:deepslate{axis:y}"},
        {pos: [10, 0, 24], state: "minecraft:deepslate{axis:y}"},
        {pos: [10, 0, 25], state: "minecraft:deepslate{axis:y}"},
        {pos: [10, 0, 26], state: "minecraft:deepslate{axis:y}"},
        {pos: [10, 0, 27], state: "minecraft:deepslate{axis:y}"},
        {pos: [10, 0, 28], state: "minecraft:deepslate{axis:y}"},
        {pos: [11, 0, 16], state: "minecraft:deepslate{axis:y}"},
        {pos: [11, 0, 17], state: "minecraft:deepslate{axis:y}"},
        {pos: [11, 0, 18], state: "minecraft:deepslate{axis:y}"},
        {pos: [11, 0, 19], state: "minecraft:deepslate{axis:y}"},
        {pos: [11, 0, 20], state: "minecraft:deepslate{axis:y}"},
        {pos: [11, 0, 21], state: "minecraft:deepslate{axis:y}"},
        {pos: [11, 0, 22], state: "minecraft:deepslate{axis:y}"},
        {pos: [11, 0, 23], state: "minecraft:deepslate{axis:y}"},
        {pos: [11, 0, 24], state: "minecraft:deepslate{axis:y}"},
        {pos: [11, 0, 25], state: "minecraft:deepslate{axis:y}"},
        {pos: [11, 0, 26], state: "minecraft:deepslate{axis:y}"},
        {pos: [11, 0, 27], state: "minecraft:deepslate{axis:y}"},
        {pos: [11, 0, 28], state: "minecraft:deepslate{axis:y}"},
        {pos: [12, 0, 16], state: "minecraft:deepslate{axis:y}"},
        {pos: [12, 0, 17], state: "minecraft:deepslate{axis:y}"},
        {pos: [12, 0, 18], state: "minecraft:deepslate{axis:y}"},
        {pos: [12, 0, 19], state: "minecraft:deepslate{axis:y}"},
        {pos: [12, 0, 20], state: "minecraft:deepslate{axis:y}"},
        {pos: [12, 0, 21], state: "minecraft:deepslate{axis:y}"},
        {pos: [12, 0, 22], state: "minecraft:deepslate{axis:y}"},
        {pos: [12, 0, 23], state: "minecraft:deepslate{axis:y}"},
        {pos: [12, 0, 24], state: "minecraft:deepslate{axis:y}"},
        {pos: [12, 0, 25], state: "minecraft:deepslate{axis:y}"},
        {pos: [12, 0, 26], state: "minecraft:deepslate{axis:y}"},
        {pos: [12, 0, 27], state: "minecraft:deepslate{axis:y}"},
        {pos: [12, 0, 28], state: "minecraft:deepslate{axis:y}"},
        {pos: [13, 0, 16], state: "minecraft:deepslate{axis:y}"},
        {pos: [13, 0, 17], state: "minecraft:deepslate{axis:y}"},
        {pos: [13, 0, 18], state: "minecraft:deepslate{axis:y}"},
        {pos: [13, 0, 19], state: "minecraft:deepslate{axis:y}"},
        {pos: [13, 0, 20], state: "minecraft:deepslate{axis:y}"},
        {pos: [13, 0, 21], state: "minecraft:deepslate{axis:y}"},
        {pos: [13, 0, 22], state: "minecraft:deepslate{axis:y}"},
        {pos: [13, 0, 23], state: "minecraft:deepslate{axis:y}"},
        {pos: [13, 0, 24], state: "minecraft:deepslate{axis:y}"},
        {pos: [13, 0, 25], state: "minecraft:deepslate{axis:y}"},
        {pos: [13, 0, 26], state: "minecraft:deepslate{axis:y}"},
        {pos: [13, 0, 27], state: "minecraft:deepslate{axis:y}"},
        {pos: [13, 0, 28], state: "minecraft:deepslate{axis:y}"},
        {pos: [14, 0, 16], state: "minecraft:deepslate{axis:y}"},
        {pos: [14, 0, 17], state: "minecraft:deepslate{axis:y}"},
        {pos: [14, 0, 18], state: "minecraft:deepslate{axis:y}"},
        {pos: [14, 0, 19], state: "minecraft:deepslate{axis:y}"},
        {pos: [14, 0, 20], state: "minecraft:deepslate{axis:y}"},
        {pos: [14, 0, 21], state: "minecraft:deepslate{axis:y}"},
        {pos: [14, 0, 22], state: "minecraft:deepslate{axis:y}"},
        {pos: [14, 0, 23], state: "minecraft:deepslate{axis:y}"},
        {pos: [14, 0, 24], state: "minecraft:deepslate{axis:y}"},
        {pos: [14, 0, 25], state: "minecraft:deepslate{axis:y}"},
        {pos: [14, 0, 26], state: "minecraft:deepslate{axis:y}"},
        {pos: [14, 0, 27], state: "minecraft:deepslate{axis:y}"},
        {pos: [14, 0, 28], state: "minecraft:deepslate{axis:y}"},
        {pos: [15, 0, 16], state: "minecraft:deepslate{axis:y}"},
        {pos: [15, 0, 17], state: "minecraft:deepslate{axis:y}"},
        {pos: [15, 0, 18], state: "minecraft:deepslate{axis:y}"},
        {pos: [15, 0, 19], state: "minecraft:deepslate{axis:y}"},
        {pos: [15, 0, 20], state: "minecraft:deepslate{axis:y}"},
        {pos: [15, 0, 21], state: "minecraft:deepslate{axis:y}"},
        {pos: [15, 0, 22], state: "minecraft:deepslate{axis:y}"},
        {pos: [15, 0, 23], state: "minecraft:deepslate{axis:y}"},
        {pos: [15, 0, 24], state: "minecraft:deepslate{axis:y}"},
        {pos: [15, 0, 25], state: "minecraft:deepslate{axis:y}"},
        {pos: [15, 0, 26], state: "minecraft:deepslate{axis:y}"},
        {pos: [15, 0, 27], state: "minecraft:deepslate{axis:y}"},
        {pos: [15, 0, 28], state: "minecraft:deepslate{axis:y}"},
        {pos: [16, 0, 16], state: "minecraft:deepslate{axis:y}"},
        {pos: [16, 0, 17], state: "minecraft:deepslate{axis:y}"},
        {pos: [16, 0, 18], state: "minecraft:deepslate{axis:y}"},
        {pos: [16, 0, 19], state: "minecraft:deepslate{axis:y}"},
        {pos: [16, 0, 20], state: "minecraft:deepslate{axis:y}"},
        {pos: [16, 0, 21], state: "minecraft:deepslate{axis:y}"},
        {pos: [16, 0, 22], state: "minecraft:deepslate{axis:y}"},
        {pos: [16, 0, 23], state: "minecraft:deepslate{axis:y}"},
        {pos: [16, 0, 24], state: "minecraft:deepslate{axis:y}"},
        {pos: [16, 0, 25], state: "minecraft:deepslate{axis:y}"},
        {pos: [16, 0, 26], state: "minecraft:deepslate{axis:y}"},
        {pos: [16, 0, 27], state: "minecraft:deepslate{axis:y}"},
        {pos: [16, 0, 28], state: "minecraft:deepslate{axis:y}"},
        {pos: [17, 0, 16], state: "minecraft:deepslate{axis:y}"},
        {pos: [17, 0, 17], state: "minecraft:deepslate{axis:y}"},
        {pos: [17, 0, 18], state: "minecraft:deepslate{axis:y}"},
        {pos: [17, 0, 19], state: "minecraft:deepslate{axis:y}"},
        {pos: [17, 0, 20], state: "minecraft:deepslate{axis:y}"},
        {pos: [17, 0, 21], state: "minecraft:deepslate{axis:y}"},
        {pos: [17, 0, 22], state: "minecraft:deepslate{axis:y}"},
        {pos: [17, 0, 23], state: "minecraft:deepslate{axis:y}"},
        {pos: [17, 0, 24], state: "minecraft:deepslate{axis:y}"},
        {pos: [17, 0, 25], state: "minecraft:deepslate{axis:y}"},
        {pos: [17, 0, 26], state: "minecraft:deepslate{axis:y}"},
        {pos: [17, 0, 27], state: "minecraft:deepslate{axis:y}"},
        {pos: [17, 0, 28], state: "minecraft:deepslate{axis:y}"},
        {pos: [18, 0, 16], state: "minecraft:deepslate{axis:y}"},
        {pos: [18, 0, 17], state: "minecraft:deepslate{axis:y}"},
        {pos: [18, 0, 18], state: "minecraft:deepslate{axis:y}"},
        {pos: [18, 0, 19], state: "minecraft:deepslate{axis:y}"},
        {pos: [18, 0, 20], state: "minecraft:deepslate{axis:y}"},
        {pos: [18, 0, 21], state: "minecraft:deepslate{axis:y}"},
        {pos: [18, 0, 22], state: "minecraft:deepslate{axis:y}"},
        {pos: [18, 0, 23], state: "minecraft:deepslate{axis:y}"},
        {pos: [18, 0, 24], state: "minecraft:deepslate{axis:y}"},
        {pos: [18, 0, 25], state: "minecraft:deepslate{axis:y}"},
        {pos: [18, 0, 26], state: "minecraft:deepslate{axis:y}"},
        {pos: [18, 0, 27], state: "minecraft:deepslate{axis:y}"},
        {pos: [18, 0, 28], state: "minecraft:deepslate{axis:y}"},
        {pos: [19, 0, 16], state: "minecraft:deepslate{axis:y}"},
        {pos: [19, 0, 17], state: "minecraft:deepslate{axis:y}"},
        {pos: [19, 0, 18], state: "minecraft:deepslate{axis:y}"},
        {pos: [19, 0, 19], state: "minecraft:deepslate{axis:y}"},
        {pos: [19, 0, 20], state: "minecraft:deepslate{axis:y}"},
        {pos: [19, 0, 21], state: "minecraft:deepslate{axis:y}"},
        {pos: [19, 0, 22], state: "minecraft:deepslate{axis:y}"},
        {pos: [19, 0, 23], state: "minecraft:deepslate{axis:y}"},
        {pos: [19, 0, 24], state: "minecraft:deepslate{axis:y}"},
        {pos: [19, 0, 25], state: "minecraft:deepslate{axis:y}"},
        {pos: [19, 0, 26], state: "minecraft:deepslate{axis:y}"},
        {pos: [19, 0, 27], state: "minecraft:deepslate{axis:y}"},
        {pos: [19, 0, 28], state: "minecraft:deepslate{axis:y}"},
        {pos: [20, 0, 16], state: "minecraft:deepslate{axis:y}"},
        {pos: [20, 0, 17], state: "minecraft:deepslate{axis:y}"},
        {pos: [20, 0, 18], state: "minecraft:deepslate{axis:y}"},
        {pos: [20, 0, 19], state: "minecraft:deepslate{axis:y}"},
        {pos: [20, 0, 20], state: "minecraft:deepslate{axis:y}"},
        {pos: [20, 0, 21], state: "minecraft:deepslate{axis:y}"},
        {pos: [20, 0, 22], state: "minecraft:deepslate{axis:y}"},
        {pos: [20, 0, 23], state: "minecraft:deepslate{axis:y}"},
        {pos: [20, 0, 24], state: "minecraft:deepslate{axis:y}"},
        {pos: [20, 0, 25], state: "minecraft:deepslate{axis:y}"},
        {pos: [20, 0, 26], state: "minecraft:deepslate{axis:y}"},
        {pos: [20, 0, 27], state: "minecraft:deepslate{axis:y}"},
        {pos: [20, 0, 28], state: "minecraft:deepslate{axis:y}"},
        {pos: [21, 0, 16], state: "minecraft:deepslate{axis:y}"},
        {pos: [21, 0, 17], state: "minecraft:deepslate{axis:y}"},
        {pos: [21, 0, 18], state: "minecraft:deepslate{axis:y}"},
        {pos: [21, 0, 19], state: "minecraft:deepslate{axis:y}"},
        {pos: [21, 0, 20], state: "minecraft:deepslate{axis:y}"},
        {pos: [21, 0, 21], state: "minecraft:deepslate{axis:y}"},
        {pos: [21, 0, 22], state: "minecraft:deepslate{axis:y}"},
        {pos: [21, 0, 23], state: "minecraft:deepslate{axis:y}"},
        {pos: [21, 0, 24], state: "minecraft:deepslate{axis:y}"},
        {pos: [21, 0, 25], state: "minecraft:deepslate{axis:y}"},
        {pos: [21, 0, 26], state: "minecraft:deepslate{axis:y}"},
        {pos: [21, 0, 27], state: "minecraft:deepslate{axis:y}"},
        {pos: [21, 0, 28], state: "minecraft:deepslate{axis:y}"},
        {pos: [22, 0, 16], state: "minecraft:deepslate{axis:y}"},
        {pos: [22, 0, 17], state: "minecraft:deepslate{axis:y}"},
        {pos: [22, 0, 18], state: "minecraft:deepslate{axis:y}"},
        {pos: [22, 0, 19], state: "minecraft:deepslate{axis:y}"},
        {pos: [22, 0, 20], state: "minecraft:deepslate{axis:y}"},
        {pos: [22, 0, 21], state: "minecraft:deepslate{axis:y}"},
        {pos: [22, 0, 22], state: "minecraft:deepslate{axis:y}"},
        {pos: [22, 0, 23], state: "minecraft:deepslate{axis:y}"},
        {pos: [22, 0, 24], state: "minecraft:deepslate{axis:y}"},
        {pos: [22, 0, 25], state: "minecraft:deepslate{axis:y}"},
        {pos: [22, 0, 26], state: "minecraft:deepslate{axis:y}"},
        {pos: [22, 0, 27], state: "minecraft:deepslate{axis:y}"},
        {pos: [22, 0, 28], state: "minecraft:deepslate{axis:y}"},
        {pos: [23, 0, 16], state: "minecraft:deepslate{axis:y}"},
        {pos: [23, 0, 17], state: "minecraft:deepslate{axis:y}"},
        {pos: [23, 0, 18], state: "minecraft:deepslate{axis:y}"},
        {pos: [23, 0, 19], state: "minecraft:deepslate{axis:y}"},
        {pos: [23, 0, 20], state: "minecraft:deepslate{axis:y}"},
        {pos: [23, 0, 21], state: "minecraft:deepslate{axis:y}"},
        {pos: [23, 0, 22], state: "minecraft:deepslate{axis:y}"},
        {pos: [23, 0, 23], state: "minecraft:deepslate{axis:y}"},
        {pos: [23, 0, 24], state: "minecraft:deepslate{axis:y}"},
        {pos: [23, 0, 25], state: "minecraft:deepslate{axis:y}"},
        {pos: [23, 0, 26], state: "minecraft:deepslate{axis:y}"},
        {pos: [23, 0, 27], state: "minecraft:deepslate{axis:y}"},
        {pos: [23, 0, 28], state: "minecraft:deepslate{axis:y}"},
        {pos: [24, 0, 16], state: "minecraft:deepslate{axis:y}"},
        {pos: [24, 0, 17], state: "minecraft:deepslate{axis:y}"},
        {pos: [24, 0, 18], state: "minecraft:deepslate{axis:y}"},
        {pos: [24, 0, 19], state: "minecraft:deepslate{axis:y}"},
        {pos: [24, 0, 20], state: "minecraft:deepslate{axis:y}"},
        {pos: [24, 0, 21], state: "minecraft:deepslate{axis:y}"},
        {pos: [24, 0, 22], state: "minecraft:deepslate{axis:y}"},
        {pos: [24, 0, 23], state: "minecraft:deepslate{axis:y}"},
        {pos: [24, 0, 24], state: "minecraft:deepslate{axis:y}"},
        {pos: [24, 0, 25], state: "minecraft:deepslate{axis:y}"},
        {pos: [24, 0, 26], state: "minecraft:deepslate{axis:y}"},
        {pos: [24, 0, 27], state: "minecraft:deepslate{axis:y}"},
        {pos: [24, 0, 28], state: "minecraft:deepslate{axis:y}"},
        {pos: [25, 0, 16], state: "minecraft:deepslate{axis:y}"},
        {pos: [25, 0, 17], state: "minecraft:deepslate{axis:y}"},
        {pos: [25, 0, 18], state: "minecraft:deepslate{axis:y}"},
        {pos: [25, 0, 19], state: "minecraft:deepslate{axis:y}"},
        {pos: [25, 0, 20], state: "minecraft:deepslate{axis:y}"},
        {pos: [25, 0, 21], state: "minecraft:deepslate{axis:y}"},
        {pos: [25, 0, 22], state: "minecraft:deepslate{axis:y}"},
        {pos: [25, 0, 23], state: "minecraft:deepslate{axis:y}"},
        {pos: [25, 0, 24], state: "minecraft:deepslate{axis:y}"},
        {pos: [25, 0, 25], state: "minecraft:deepslate{axis:y}"},
        {pos: [25, 0, 26], state: "minecraft:deepslate{axis:y}"},
        {pos: [25, 0, 27], state: "minecraft:deepslate{axis:y}"},
        {pos: [25, 0, 28], state: "minecraft:deepslate{axis:y}"},
        {pos: [26, 0, 16], state: "minecraft:deepslate{axis:y}"},
        {pos: [26, 0, 17], state: "minecraft:deepslate{axis:y}"},
        {pos: [26, 0, 18], state: "minecraft:deepslate{axis:y}"},
        {pos: [26, 0, 19], state: "minecraft:deepslate{axis:y}"},
        {pos: [26, 0, 20], state: "minecraft:deepslate{axis:y}"},
        {pos: [26, 0, 21], state: "minecraft:deepslate{axis:y}"},
        {pos: [26, 0, 22], state: "minecraft:deepslate{axis:y}"},
        {pos: [26, 0, 23], state: "minecraft:deepslate{axis:y}"},
        {pos: [26, 0, 24], state: "minecraft:deepslate{axis:y}"},
        {pos: [26, 0, 25], state: "minecraft:deepslate{axis:y}"},
        {pos: [26, 0, 26], state: "minecraft:deepslate{axis:y}"},
        {pos: [26, 0, 27], state: "minecraft:deepslate{axis:y}"},
        {pos: [26, 0, 28], state: "minecraft:deepslate{axis:y}"},
        {pos: [0, 1, 16], state: "minecraft:deepslate_bricks"},
        {pos: [0, 1, 17], state: "minecraft:deepslate_bricks"},
        {pos: [0, 1, 18], state: "minecraft:deepslate_bricks"},
        {pos: [0, 1, 19], state: "minecraft:deepslate_bricks"},
        {pos: [0, 1, 20], state: "minecraft:deepslate_bricks"},
        {pos: [0, 1, 21], state: "minecraft:deepslate_bricks"},
        {pos: [0, 1, 22], state: "minecraft:deepslate_bricks"},
        {pos: [0, 1, 23], state: "minecraft:deepslate_bricks"},
        {pos: [0, 1, 24], state: "minecraft:deepslate_bricks"},
        {pos: [0, 1, 25], state: "minecraft:deepslate_bricks"},
        {pos: [0, 1, 26], state: "minecraft:deepslate_bricks"},
        {pos: [0, 1, 27], state: "minecraft:deepslate_bricks"},
        {pos: [0, 1, 28], state: "minecraft:deepslate_bricks"},
        {pos: [1, 1, 16], state: "minecraft:deepslate_bricks"},
        {pos: [1, 1, 17], state: "minecraft:deepslate_bricks"},
        {pos: [1, 1, 18], state: "minecraft:deepslate_bricks"},
        {pos: [1, 1, 19], state: "minecraft:deepslate_bricks"},
        {pos: [1, 1, 20], state: "minecraft:deepslate_bricks"},
        {pos: [1, 1, 21], state: "minecraft:deepslate_bricks"},
        {pos: [1, 1, 22], state: "minecraft:deepslate_bricks"},
        {pos: [1, 1, 23], state: "minecraft:deepslate_bricks"},
        {pos: [1, 1, 24], state: "minecraft:deepslate_bricks"},
        {pos: [1, 1, 25], state: "minecraft:deepslate_bricks"},
        {pos: [1, 1, 26], state: "minecraft:deepslate_bricks"},
        {pos: [1, 1, 27], state: "minecraft:deepslate_bricks"},
        {pos: [1, 1, 28], state: "minecraft:deepslate_bricks"},
        {pos: [2, 1, 16], state: "minecraft:deepslate_bricks"},
        {pos: [2, 1, 17], state: "minecraft:deepslate_bricks"},
        {pos: [2, 1, 18], state: "minecraft:deepslate_bricks"},
        {pos: [2, 1, 19], state: "minecraft:deepslate_bricks"},
        {pos: [2, 1, 20], state: "minecraft:deepslate_bricks"},
        {pos: [2, 1, 21], state: "minecraft:deepslate_bricks"},
        {pos: [2, 1, 22], state: "minecraft:deepslate_bricks"},
        {pos: [2, 1, 23], state: "minecraft:deepslate_bricks"},
        {pos: [2, 1, 24], state: "minecraft:deepslate_bricks"},
        {pos: [2, 1, 25], state: "minecraft:deepslate_bricks"},
        {pos: [2, 1, 26], state: "minecraft:deepslate_bricks"},
        {pos: [2, 1, 27], state: "minecraft:deepslate_bricks"},
        {pos: [2, 1, 28], state: "minecraft:deepslate_bricks"},
        {pos: [3, 1, 16], state: "minecraft:deepslate_bricks"},
        {pos: [3, 1, 17], state: "minecraft:deepslate_bricks"},
        {pos: [3, 1, 18], state: "minecraft:deepslate_bricks"},
        {pos: [3, 1, 19], state: "minecraft:dripstone_block"},
        {pos: [3, 1, 20], state: "minecraft:dripstone_block"},
        {pos: [3, 1, 21], state: "minecraft:deepslate_bricks"},
        {pos: [3, 1, 22], state: "minecraft:deepslate_bricks"},
        {pos: [3, 1, 23], state: "minecraft:deepslate_bricks"},
        {pos: [3, 1, 24], state: "minecraft:dripstone_block"},
        {pos: [3, 1, 25], state: "minecraft:deepslate_bricks"},
        {pos: [3, 1, 26], state: "minecraft:deepslate_bricks"},
        {pos: [3, 1, 27], state: "minecraft:deepslate_bricks"},
        {pos: [3, 1, 28], state: "minecraft:deepslate_bricks"},
        {pos: [4, 1, 16], state: "minecraft:deepslate_bricks"},
        {pos: [4, 1, 17], state: "minecraft:deepslate_bricks"},
        {pos: [4, 1, 18], state: "minecraft:deepslate_bricks"},
        {pos: [4, 1, 19], state: "minecraft:dripstone_block"},
        {pos: [4, 1, 20], state: "minecraft:deepslate_bricks"},
        {pos: [4, 1, 21], state: "minecraft:deepslate_bricks"},
        {pos: [4, 1, 22], state: "minecraft:deepslate_bricks"},
        {pos: [4, 1, 23], state: "minecraft:deepslate_bricks"},
        {pos: [4, 1, 24], state: "minecraft:dripstone_block"},
        {pos: [4, 1, 25], state: "minecraft:dripstone_block"},
        {pos: [4, 1, 26], state: "minecraft:deepslate_bricks"},
        {pos: [4, 1, 27], state: "minecraft:deepslate_bricks"},
        {pos: [4, 1, 28], state: "minecraft:deepslate_bricks"},
        {pos: [5, 1, 16], state: "minecraft:deepslate_bricks"},
        {pos: [5, 1, 17], state: "minecraft:deepslate_bricks"},
        {pos: [5, 1, 18], state: "minecraft:deepslate_bricks"},
        {pos: [5, 1, 19], state: "minecraft:deepslate_bricks"},
        {pos: [5, 1, 20], state: "minecraft:deepslate_bricks"},
        {pos: [5, 1, 21], state: "minecraft:deepslate_bricks"},
        {pos: [5, 1, 22], state: "minecraft:deepslate_bricks"},
        {pos: [5, 1, 23], state: "minecraft:deepslate_bricks"},
        {pos: [5, 1, 24], state: "minecraft:deepslate_bricks"},
        {pos: [5, 1, 25], state: "minecraft:deepslate_bricks"},
        {pos: [5, 1, 26], state: "minecraft:deepslate_bricks"},
        {pos: [5, 1, 27], state: "minecraft:deepslate_bricks"},
        {pos: [5, 1, 28], state: "minecraft:deepslate_bricks"},
        {pos: [6, 1, 16], state: "minecraft:deepslate_bricks"},
        {pos: [6, 1, 17], state: "minecraft:deepslate_bricks"},
        {pos: [6, 1, 18], state: "minecraft:deepslate_bricks"},
        {pos: [6, 1, 19], state: "minecraft:deepslate_bricks"},
        {pos: [6, 1, 20], state: "minecraft:deepslate_bricks"},
        {pos: [6, 1, 21], state: "minecraft:deepslate_bricks"},
        {pos: [6, 1, 22], state: "minecraft:deepslate_bricks"},
        {pos: [6, 1, 23], state: "minecraft:deepslate_bricks"},
        {pos: [6, 1, 24], state: "minecraft:deepslate_bricks"},
        {pos: [6, 1, 25], state: "minecraft:deepslate_bricks"},
        {pos: [6, 1, 26], state: "minecraft:dripstone_block"},
        {pos: [6, 1, 27], state: "minecraft:dripstone_block"},
        {pos: [6, 1, 28], state: "minecraft:deepslate_bricks"},
        {pos: [7, 1, 16], state: "minecraft:deepslate_bricks"},
        {pos: [7, 1, 17], state: "minecraft:deepslate_bricks"},
        {pos: [7, 1, 18], state: "minecraft:deepslate_bricks"},
        {pos: [7, 1, 19], state: "minecraft:dripstone_block"},
        {pos: [7, 1, 20], state: "minecraft:dripstone_block"},
        {pos: [7, 1, 21], state: "minecraft:deepslate_bricks"},
        {pos: [7, 1, 22], state: "minecraft:deepslate_bricks"},
        {pos: [7, 1, 23], state: "minecraft:deepslate_bricks"},
        {pos: [7, 1, 24], state: "minecraft:deepslate_bricks"},
        {pos: [7, 1, 25], state: "minecraft:deepslate_bricks"},
        {pos: [7, 1, 26], state: "minecraft:deepslate_bricks"},
        {pos: [7, 1, 27], state: "minecraft:deepslate_bricks"},
        {pos: [7, 1, 28], state: "minecraft:deepslate_bricks"},
        {pos: [8, 1, 16], state: "minecraft:deepslate_bricks"},
        {pos: [8, 1, 17], state: "minecraft:deepslate_bricks"},
        {pos: [8, 1, 18], state: "minecraft:deepslate_bricks"},
        {pos: [8, 1, 19], state: "minecraft:dripstone_block"},
        {pos: [8, 1, 20], state: "minecraft:dripstone_block"},
        {pos: [8, 1, 21], state: "minecraft:deepslate_bricks"},
        {pos: [8, 1, 22], state: "minecraft:deepslate_bricks"},
        {pos: [8, 1, 23], state: "minecraft:deepslate_bricks"},
        {pos: [8, 1, 24], state: "minecraft:deepslate_bricks"},
        {pos: [8, 1, 25], state: "minecraft:deepslate_bricks"},
        {pos: [8, 1, 26], state: "minecraft:deepslate_bricks"},
        {pos: [8, 1, 27], state: "minecraft:deepslate_bricks"},
        {pos: [8, 1, 28], state: "minecraft:deepslate_bricks"},
        {pos: [9, 1, 16], state: "minecraft:deepslate_bricks"},
        {pos: [9, 1, 17], state: "minecraft:deepslate_bricks"},
        {pos: [9, 1, 18], state: "minecraft:deepslate_bricks"},
        {pos: [9, 1, 19], state: "minecraft:dripstone_block"},
        {pos: [9, 1, 20], state: "minecraft:dripstone_block"},
        {pos: [9, 1, 21], state: "minecraft:deepslate_bricks"},
        {pos: [9, 1, 22], state: "minecraft:deepslate_bricks"},
        {pos: [9, 1, 23], state: "minecraft:deepslate_bricks"},
        {pos: [9, 1, 24], state: "minecraft:deepslate_bricks"},
        {pos: [9, 1, 25], state: "minecraft:deepslate_bricks"},
        {pos: [9, 1, 26], state: "minecraft:deepslate_bricks"},
        {pos: [9, 1, 27], state: "minecraft:deepslate_bricks"},
        {pos: [9, 1, 28], state: "minecraft:deepslate_bricks"},
        {pos: [10, 1, 16], state: "minecraft:deepslate_bricks"},
        {pos: [10, 1, 17], state: "minecraft:deepslate_bricks"},
        {pos: [10, 1, 18], state: "minecraft:deepslate_bricks"},
        {pos: [10, 1, 19], state: "minecraft:deepslate_bricks"},
        {pos: [10, 1, 20], state: "minecraft:dripstone_block"},
        {pos: [10, 1, 21], state: "minecraft:dripstone_block"},
        {pos: [10, 1, 22], state: "minecraft:deepslate_bricks"},
        {pos: [10, 1, 23], state: "minecraft:deepslate_bricks"},
        {pos: [10, 1, 24], state: "minecraft:deepslate_bricks"},
        {pos: [10, 1, 25], state: "minecraft:deepslate_bricks"},
        {pos: [10, 1, 26], state: "minecraft:deepslate_bricks"},
        {pos: [10, 1, 27], state: "minecraft:deepslate_bricks"},
        {pos: [10, 1, 28], state: "minecraft:deepslate_bricks"},
        {pos: [11, 1, 16], state: "minecraft:deepslate_bricks"},
        {pos: [11, 1, 17], state: "minecraft:deepslate_bricks"},
        {pos: [11, 1, 18], state: "minecraft:deepslate_bricks"},
        {pos: [11, 1, 19], state: "minecraft:deepslate_bricks"},
        {pos: [11, 1, 20], state: "minecraft:deepslate_bricks"},
        {pos: [11, 1, 21], state: "minecraft:deepslate_bricks"},
        {pos: [11, 1, 22], state: "minecraft:deepslate_bricks"},
        {pos: [11, 1, 23], state: "minecraft:deepslate_bricks"},
        {pos: [11, 1, 24], state: "minecraft:deepslate_bricks"},
        {pos: [11, 1, 25], state: "minecraft:dripstone_block"},
        {pos: [11, 1, 26], state: "minecraft:dripstone_block"},
        {pos: [11, 1, 27], state: "minecraft:deepslate_bricks"},
        {pos: [11, 1, 28], state: "minecraft:deepslate_bricks"},
        {pos: [12, 1, 16], state: "minecraft:deepslate_bricks"},
        {pos: [12, 1, 17], state: "minecraft:deepslate_bricks"},
        {pos: [12, 1, 18], state: "minecraft:deepslate_bricks"},
        {pos: [12, 1, 19], state: "minecraft:deepslate_bricks"},
        {pos: [12, 1, 20], state: "minecraft:deepslate_bricks"},
        {pos: [12, 1, 21], state: "minecraft:deepslate_bricks"},
        {pos: [12, 1, 22], state: "minecraft:deepslate_bricks"},
        {pos: [12, 1, 23], state: "minecraft:deepslate_bricks"},
        {pos: [12, 1, 24], state: "minecraft:deepslate_bricks"},
        {pos: [12, 1, 25], state: "minecraft:dripstone_block"},
        {pos: [12, 1, 26], state: "minecraft:deepslate_bricks"},
        {pos: [12, 1, 27], state: "minecraft:deepslate_bricks"},
        {pos: [12, 1, 28], state: "minecraft:deepslate_bricks"},
        {pos: [13, 1, 16], state: "minecraft:deepslate_bricks"},
        {pos: [13, 1, 17], state: "minecraft:deepslate_bricks"},
        {pos: [13, 1, 18], state: "minecraft:deepslate_bricks"},
        {pos: [13, 1, 19], state: "minecraft:dripstone_block"},
        {pos: [13, 1, 20], state: "minecraft:deepslate_bricks"},
        {pos: [13, 1, 21], state: "minecraft:dripstone_block"},
        {pos: [13, 1, 22], state: "minecraft:dripstone_block"},
        {pos: [13, 1, 23], state: "minecraft:dripstone_block"},
        {pos: [13, 1, 24], state: "minecraft:deepslate_bricks"},
        {pos: [13, 1, 25], state: "minecraft:dripstone_block"},
        {pos: [13, 1, 26], state: "minecraft:deepslate_bricks"},
        {pos: [13, 1, 27], state: "minecraft:deepslate_bricks"},
        {pos: [13, 1, 28], state: "minecraft:deepslate_bricks"},
        {pos: [14, 1, 16], state: "minecraft:deepslate_bricks"},
        {pos: [14, 1, 17], state: "minecraft:deepslate_bricks"},
        {pos: [14, 1, 18], state: "minecraft:deepslate_bricks"},
        {pos: [14, 1, 19], state: "minecraft:dripstone_block"},
        {pos: [14, 1, 20], state: "minecraft:deepslate_bricks"},
        {pos: [14, 1, 21], state: "minecraft:dripstone_block"},
        {pos: [14, 1, 22], state: "minecraft:dripstone_block"},
        {pos: [14, 1, 23], state: "minecraft:deepslate_bricks"},
        {pos: [14, 1, 24], state: "minecraft:deepslate_bricks"},
        {pos: [14, 1, 25], state: "minecraft:deepslate_bricks"},
        {pos: [14, 1, 26], state: "minecraft:dripstone_block"},
        {pos: [14, 1, 27], state: "minecraft:deepslate_bricks"},
        {pos: [14, 1, 28], state: "minecraft:deepslate_bricks"},
        {pos: [15, 1, 16], state: "minecraft:deepslate_bricks"},
        {pos: [15, 1, 17], state: "minecraft:deepslate_bricks"},
        {pos: [15, 1, 18], state: "minecraft:deepslate_bricks"},
        {pos: [15, 1, 19], state: "minecraft:deepslate_bricks"},
        {pos: [15, 1, 20], state: "minecraft:deepslate_bricks"},
        {pos: [15, 1, 21], state: "minecraft:deepslate_bricks"},
        {pos: [15, 1, 22], state: "minecraft:deepslate_bricks"},
        {pos: [15, 1, 23], state: "minecraft:deepslate_bricks"},
        {pos: [15, 1, 24], state: "minecraft:deepslate_bricks"},
        {pos: [15, 1, 25], state: "minecraft:deepslate_bricks"},
        {pos: [15, 1, 26], state: "minecraft:deepslate_bricks"},
        {pos: [15, 1, 27], state: "minecraft:deepslate_bricks"},
        {pos: [15, 1, 28], state: "minecraft:deepslate_bricks"},
        {pos: [16, 1, 16], state: "minecraft:deepslate_bricks"},
        {pos: [16, 1, 17], state: "minecraft:deepslate_bricks"},
        {pos: [16, 1, 18], state: "minecraft:dripstone_block"},
        {pos: [16, 1, 19], state: "minecraft:dripstone_block"},
        {pos: [16, 1, 20], state: "minecraft:dripstone_block"},
        {pos: [16, 1, 21], state: "minecraft:deepslate_bricks"},
        {pos: [16, 1, 22], state: "minecraft:deepslate_bricks"},
        {pos: [16, 1, 23], state: "minecraft:deepslate_bricks"},
        {pos: [16, 1, 24], state: "minecraft:deepslate_bricks"},
        {pos: [16, 1, 25], state: "minecraft:deepslate_bricks"},
        {pos: [16, 1, 26], state: "minecraft:deepslate_bricks"},
        {pos: [16, 1, 27], state: "minecraft:deepslate_bricks"},
        {pos: [16, 1, 28], state: "minecraft:deepslate_bricks"},
        {pos: [17, 1, 16], state: "minecraft:deepslate_bricks"},
        {pos: [17, 1, 17], state: "minecraft:deepslate_bricks"},
        {pos: [17, 1, 18], state: "minecraft:dripstone_block"},
        {pos: [17, 1, 19], state: "minecraft:dripstone_block"},
        {pos: [17, 1, 20], state: "minecraft:dripstone_block"},
        {pos: [17, 1, 21], state: "minecraft:deepslate_bricks"},
        {pos: [17, 1, 22], state: "minecraft:deepslate_bricks"},
        {pos: [17, 1, 23], state: "minecraft:deepslate_bricks"},
        {pos: [17, 1, 24], state: "minecraft:deepslate_bricks"},
        {pos: [17, 1, 25], state: "minecraft:deepslate_bricks"},
        {pos: [17, 1, 26], state: "minecraft:deepslate_bricks"},
        {pos: [17, 1, 27], state: "minecraft:deepslate_bricks"},
        {pos: [17, 1, 28], state: "minecraft:deepslate_bricks"},
        {pos: [18, 1, 16], state: "minecraft:deepslate_bricks"},
        {pos: [18, 1, 17], state: "minecraft:deepslate_bricks"},
        {pos: [18, 1, 18], state: "minecraft:deepslate_bricks"},
        {pos: [18, 1, 19], state: "minecraft:dripstone_block"},
        {pos: [18, 1, 20], state: "minecraft:deepslate_bricks"},
        {pos: [18, 1, 21], state: "minecraft:deepslate_bricks"},
        {pos: [18, 1, 22], state: "minecraft:deepslate_bricks"},
        {pos: [18, 1, 23], state: "minecraft:deepslate_bricks"},
        {pos: [18, 1, 24], state: "minecraft:dripstone_block"},
        {pos: [18, 1, 25], state: "minecraft:dripstone_block"},
        {pos: [18, 1, 26], state: "minecraft:deepslate_bricks"},
        {pos: [18, 1, 27], state: "minecraft:deepslate_bricks"},
        {pos: [18, 1, 28], state: "minecraft:deepslate_bricks"},
        {pos: [19, 1, 16], state: "minecraft:deepslate_bricks"},
        {pos: [19, 1, 17], state: "minecraft:deepslate_bricks"},
        {pos: [19, 1, 18], state: "minecraft:deepslate_bricks"},
        {pos: [19, 1, 19], state: "minecraft:deepslate_bricks"},
        {pos: [19, 1, 20], state: "minecraft:deepslate_bricks"},
        {pos: [19, 1, 21], state: "minecraft:deepslate_bricks"},
        {pos: [19, 1, 22], state: "minecraft:deepslate_bricks"},
        {pos: [19, 1, 23], state: "minecraft:deepslate_bricks"},
        {pos: [19, 1, 24], state: "minecraft:dripstone_block"},
        {pos: [19, 1, 25], state: "minecraft:dripstone_block"},
        {pos: [19, 1, 26], state: "minecraft:dripstone_block"},
        {pos: [19, 1, 27], state: "minecraft:deepslate_bricks"},
        {pos: [19, 1, 28], state: "minecraft:deepslate_bricks"},
        {pos: [20, 1, 16], state: "minecraft:deepslate_bricks"},
        {pos: [20, 1, 17], state: "minecraft:deepslate_bricks"},
        {pos: [20, 1, 18], state: "minecraft:deepslate_bricks"},
        {pos: [20, 1, 19], state: "minecraft:deepslate_bricks"},
        {pos: [20, 1, 20], state: "minecraft:deepslate_bricks"},
        {pos: [20, 1, 21], state: "minecraft:deepslate_bricks"},
        {pos: [20, 1, 22], state: "minecraft:deepslate_bricks"},
        {pos: [20, 1, 23], state: "minecraft:deepslate_bricks"},
        {pos: [20, 1, 24], state: "minecraft:deepslate_bricks"},
        {pos: [20, 1, 25], state: "minecraft:deepslate_bricks"},
        {pos: [20, 1, 26], state: "minecraft:deepslate_bricks"},
        {pos: [20, 1, 27], state: "minecraft:deepslate_bricks"},
        {pos: [20, 1, 28], state: "minecraft:deepslate_bricks"},
        {pos: [21, 1, 16], state: "minecraft:deepslate_bricks"},
        {pos: [21, 1, 17], state: "minecraft:deepslate_bricks"},
        {pos: [21, 1, 18], state: "minecraft:deepslate_bricks"},
        {pos: [21, 1, 19], state: "minecraft:deepslate_bricks"},
        {pos: [21, 1, 20], state: "minecraft:deepslate_bricks"},
        {pos: [21, 1, 21], state: "minecraft:deepslate_bricks"},
        {pos: [21, 1, 22], state: "minecraft:deepslate_bricks"},
        {pos: [21, 1, 23], state: "minecraft:deepslate_bricks"},
        {pos: [21, 1, 24], state: "minecraft:dripstone_block"},
        {pos: [21, 1, 25], state: "minecraft:deepslate_bricks"},
        {pos: [21, 1, 26], state: "minecraft:deepslate_bricks"},
        {pos: [21, 1, 27], state: "minecraft:deepslate_bricks"},
        {pos: [21, 1, 28], state: "minecraft:deepslate_bricks"},
        {pos: [22, 1, 16], state: "minecraft:deepslate_bricks"},
        {pos: [22, 1, 17], state: "minecraft:deepslate_bricks"},
        {pos: [22, 1, 18], state: "minecraft:dripstone_block"},
        {pos: [22, 1, 19], state: "minecraft:deepslate_bricks"},
        {pos: [22, 1, 20], state: "minecraft:deepslate_bricks"},
        {pos: [22, 1, 21], state: "minecraft:deepslate_bricks"},
        {pos: [22, 1, 22], state: "minecraft:deepslate_bricks"},
        {pos: [22, 1, 23], state: "minecraft:deepslate_bricks"},
        {pos: [22, 1, 24], state: "minecraft:deepslate_bricks"},
        {pos: [22, 1, 25], state: "minecraft:dripstone_block"},
        {pos: [22, 1, 26], state: "minecraft:dripstone_block"},
        {pos: [22, 1, 27], state: "minecraft:deepslate_bricks"},
        {pos: [22, 1, 28], state: "minecraft:deepslate_bricks"},
        {pos: [23, 1, 16], state: "minecraft:deepslate_bricks"},
        {pos: [23, 1, 17], state: "minecraft:deepslate_bricks"},
        {pos: [23, 1, 18], state: "minecraft:dripstone_block"},
        {pos: [23, 1, 19], state: "minecraft:deepslate_bricks"},
        {pos: [23, 1, 20], state: "minecraft:deepslate_bricks"},
        {pos: [23, 1, 21], state: "minecraft:deepslate_bricks"},
        {pos: [23, 1, 22], state: "minecraft:deepslate_bricks"},
        {pos: [23, 1, 23], state: "minecraft:deepslate_bricks"},
        {pos: [23, 1, 24], state: "minecraft:deepslate_bricks"},
        {pos: [23, 1, 25], state: "minecraft:deepslate_bricks"},
        {pos: [23, 1, 26], state: "minecraft:dripstone_block"},
        {pos: [23, 1, 27], state: "minecraft:dripstone_block"},
        {pos: [23, 1, 28], state: "minecraft:deepslate_bricks"},
        {pos: [24, 1, 16], state: "minecraft:deepslate_bricks"},
        {pos: [24, 1, 17], state: "minecraft:deepslate_bricks"},
        {pos: [24, 1, 18], state: "minecraft:deepslate_bricks"},
        {pos: [24, 1, 19], state: "minecraft:deepslate_bricks"},
        {pos: [24, 1, 20], state: "minecraft:deepslate_bricks"},
        {pos: [24, 1, 21], state: "minecraft:deepslate_bricks"},
        {pos: [24, 1, 22], state: "minecraft:deepslate_bricks"},
        {pos: [24, 1, 23], state: "minecraft:deepslate_bricks"},
        {pos: [24, 1, 24], state: "minecraft:deepslate_bricks"},
        {pos: [24, 1, 25], state: "minecraft:deepslate_bricks"},
        {pos: [24, 1, 26], state: "minecraft:deepslate_bricks"},
        {pos: [24, 1, 27], state: "minecraft:deepslate_bricks"},
        {pos: [24, 1, 28], state: "minecraft:deepslate_bricks"},
        {pos: [25, 1, 16], state: "minecraft:deepslate_bricks"},
        {pos: [25, 1, 17], state: "minecraft:deepslate_bricks"},
        {pos: [25, 1, 18], state: "minecraft:deepslate_bricks"},
        {pos: [25, 1, 19], state: "minecraft:deepslate_bricks"},
        {pos: [25, 1, 20], state: "minecraft:deepslate_bricks"},
        {pos: [25, 1, 21], state: "minecraft:deepslate_bricks"},
        {pos: [25, 1, 22], state: "minecraft:deepslate_bricks"},
        {pos: [25, 1, 23], state: "minecraft:deepslate_bricks"},
        {pos: [25, 1, 24], state: "minecraft:deepslate_bricks"},
        {pos: [25, 1, 25], state: "minecraft:deepslate_bricks"},
        {pos: [25, 1, 26], state: "minecraft:deepslate_bricks"},
        {pos: [25, 1, 27], state: "minecraft:deepslate_bricks"},
        {pos: [25, 1, 28], state: "minecraft:deepslate_bricks"},
        {pos: [26, 1, 16], state: "minecraft:deepslate_bricks"},
        {pos: [26, 1, 17], state: "minecraft:deepslate_bricks"},
        {pos: [26, 1, 18], state: "minecraft:deepslate_bricks"},
        {pos: [26, 1, 19], state: "minecraft:deepslate_bricks"},
        {pos: [26, 1, 20], state: "minecraft:deepslate_bricks"},
        {pos: [26, 1, 21], state: "minecraft:deepslate_bricks"},
        {pos: [26, 1, 22], state: "minecraft:deepslate_bricks"},
        {pos: [26, 1, 23], state: "minecraft:deepslate_bricks"},
        {pos: [26, 1, 24], state: "minecraft:deepslate_bricks"},
        {pos: [26, 1, 25], state: "minecraft:deepslate_bricks"},
        {pos: [26, 1, 26], state: "minecraft:deepslate_bricks"},
        {pos: [26, 1, 27], state: "minecraft:deepslate_bricks"},
        {pos: [26, 1, 28], state: "minecraft:deepslate_bricks"},
        {pos: [0, 2, 16], state: "minecraft:deepslate_bricks"},
        {pos: [0, 2, 17], state: "minecraft:deepslate_bricks"},
        {pos: [0, 2, 18], state: "minecraft:deepslate_bricks"},
        {pos: [0, 2, 19], state: "minecraft:deepslate_bricks"},
        {pos: [0, 2, 20], state: "minecraft:deepslate_bricks"},
        {pos: [0, 2, 21], state: "minecraft:deepslate_bricks"},
        {pos: [0, 2, 22], state: "minecraft:deepslate_bricks"},
        {pos: [0, 2, 23], state: "minecraft:deepslate_bricks"},
        {pos: [0, 2, 24], state: "minecraft:deepslate_bricks"},
        {pos: [0, 2, 25], state: "minecraft:deepslate_bricks"},
        {pos: [0, 2, 26], state: "minecraft:deepslate_bricks"},
        {pos: [0, 2, 27], state: "minecraft:deepslate_bricks"},
        {pos: [0, 2, 28], state: "minecraft:deepslate_bricks"},
        {pos: [1, 2, 16], state: "minecraft:deepslate_bricks"},
        {pos: [1, 2, 17], state: "minecraft:deepslate_bricks"},
        {pos: [1, 2, 18], state: "minecraft:deepslate_bricks"},
        {pos: [1, 2, 19], state: "minecraft:deepslate_bricks"},
        {pos: [1, 2, 20], state: "minecraft:deepslate_bricks"},
        {pos: [1, 2, 21], state: "minecraft:deepslate_bricks"},
        {pos: [1, 2, 22], state: "minecraft:deepslate_bricks"},
        {pos: [1, 2, 23], state: "minecraft:deepslate_bricks"},
        {pos: [1, 2, 24], state: "minecraft:deepslate_bricks"},
        {pos: [1, 2, 25], state: "minecraft:deepslate_bricks"},
        {pos: [1, 2, 26], state: "minecraft:deepslate_bricks"},
        {pos: [1, 2, 27], state: "minecraft:deepslate_bricks"},
        {pos: [1, 2, 28], state: "minecraft:deepslate_bricks"},
        {pos: [2, 2, 16], state: "minecraft:deepslate_bricks"},
        {pos: [2, 2, 17], state: "minecraft:deepslate_bricks"},
        {pos: [2, 2, 18], state: "minecraft:deepslate_bricks"},
        {pos: [2, 2, 19], state: "minecraft:deepslate_bricks"},
        {pos: [2, 2, 20], state: "minecraft:deepslate_bricks"},
        {pos: [2, 2, 21], state: "minecraft:deepslate_bricks"},
        {pos: [2, 2, 22], state: "minecraft:deepslate_bricks"},
        {pos: [2, 2, 23], state: "minecraft:deepslate_bricks"},
        {pos: [2, 2, 24], state: "minecraft:deepslate_bricks"},
        {pos: [2, 2, 25], state: "minecraft:deepslate_bricks"},
        {pos: [2, 2, 26], state: "minecraft:deepslate_bricks"},
        {pos: [2, 2, 27], state: "minecraft:deepslate_bricks"},
        {pos: [2, 2, 28], state: "minecraft:deepslate_bricks"},
        {pos: [3, 2, 16], state: "minecraft:deepslate_bricks"},
        {pos: [3, 2, 17], state: "minecraft:dripstone_block"},
        {pos: [3, 2, 18], state: "minecraft:dripstone_block"},
        {pos: [3, 2, 19], state: "minecraft:pointed_dripstone{thickness:frustum,vertical_direction:up,waterlogged:false}"},
        {pos: [3, 2, 20], state: "minecraft:pointed_dripstone{thickness:frustum,vertical_direction:up,waterlogged:false}"},
        {pos: [3, 2, 21], state: "minecraft:deepslate_bricks"},
        {pos: [3, 2, 22], state: "minecraft:deepslate_bricks"},
        {pos: [3, 2, 23], state: "minecraft:deepslate_bricks"},
        {pos: [3, 2, 24], state: "minecraft:pointed_dripstone{thickness:frustum,vertical_direction:up,waterlogged:false}"},
        {pos: [3, 2, 25], state: "minecraft:dripstone_block"},
        {pos: [3, 2, 26], state: "minecraft:dripstone_block"},
        {pos: [3, 2, 27], state: "minecraft:dripstone_block"},
        {pos: [3, 2, 28], state: "minecraft:deepslate_bricks"},
        {pos: [4, 2, 16], state: "minecraft:deepslate_bricks"},
        {pos: [4, 2, 17], state: "minecraft:dripstone_block"},
        {pos: [4, 2, 18], state: "minecraft:dripstone_block"},
        {pos: [4, 2, 19], state: "minecraft:pointed_dripstone{thickness:frustum,vertical_direction:up,waterlogged:false}"},
        {pos: [4, 2, 20], state: "minecraft:pointed_dripstone{thickness:tip,vertical_direction:up,waterlogged:false}"},
        {pos: [4, 2, 21], state: "minecraft:deepslate_bricks"},
        {pos: [4, 2, 22], state: "minecraft:deepslate_bricks"},
        {pos: [4, 2, 23], state: "minecraft:deepslate_bricks"},
        {pos: [4, 2, 24], state: "minecraft:pointed_dripstone{thickness:frustum,vertical_direction:up,waterlogged:false}"},
        {pos: [4, 2, 25], state: "minecraft:pointed_dripstone{thickness:frustum,vertical_direction:up,waterlogged:false}"},
        {pos: [4, 2, 26], state: "minecraft:dripstone_block"},
        {pos: [4, 2, 27], state: "minecraft:dripstone_block"},
        {pos: [4, 2, 28], state: "minecraft:deepslate_bricks"},
        {pos: [5, 2, 16], state: "minecraft:deepslate_bricks"},
        {pos: [5, 2, 17], state: "minecraft:dripstone_block"},
        {pos: [5, 2, 18], state: "minecraft:pointed_dripstone{thickness:tip,vertical_direction:up,waterlogged:false}"},
        {pos: [5, 2, 19], state: "minecraft:pointed_dripstone{thickness:tip,vertical_direction:up,waterlogged:false}"},
        {pos: [5, 2, 20], state: "minecraft:pointed_dripstone{thickness:base,vertical_direction:up,waterlogged:false}"},
        {pos: [5, 2, 21], state: "minecraft:deepslate_bricks"},
        {pos: [5, 2, 22], state: "minecraft:deepslate_bricks"},
        {pos: [5, 2, 23], state: "minecraft:deepslate_bricks"},
        {pos: [5, 2, 24], state: "minecraft:pointed_dripstone{thickness:frustum,vertical_direction:up,waterlogged:false}"},
        {pos: [5, 2, 25], state: "minecraft:pointed_dripstone{thickness:tip,vertical_direction:up,waterlogged:false}"},
        {pos: [5, 2, 26], state: "minecraft:dripstone_block"},
        {pos: [5, 2, 27], state: "minecraft:dripstone_block"},
        {pos: [5, 2, 28], state: "minecraft:deepslate_bricks"},
        {pos: [6, 2, 16], state: "minecraft:deepslate_bricks"},
        {pos: [6, 2, 17], state: "minecraft:pointed_dripstone{thickness:tip,vertical_direction:up,waterlogged:false}"},
        {pos: [6, 2, 18], state: "minecraft:pointed_dripstone{thickness:frustum,vertical_direction:up,waterlogged:false}"},
        {pos: [6, 2, 19], state: "minecraft:pointed_dripstone{thickness:frustum,vertical_direction:up,waterlogged:false}"},
        {pos: [6, 2, 20], state: "minecraft:pointed_dripstone{thickness:tip,vertical_direction:up,waterlogged:false}"},
        {pos: [6, 2, 21], state: "minecraft:pointed_dripstone{thickness:frustum,vertical_direction:up,waterlogged:false}"},
        {pos: [6, 2, 22], state: "minecraft:deepslate_bricks"},
        {pos: [6, 2, 23], state: "minecraft:deepslate_bricks"},
        {pos: [6, 2, 24], state: "minecraft:pointed_dripstone{thickness:base,vertical_direction:up,waterlogged:false}"},
        {pos: [6, 2, 25], state: "minecraft:pointed_dripstone{thickness:tip,vertical_direction:up,waterlogged:false}"},
        {pos: [6, 2, 26], state: "minecraft:pointed_dripstone{thickness:frustum,vertical_direction:up,waterlogged:false}"},
        {pos: [6, 2, 27], state: "minecraft:pointed_dripstone{thickness:frustum,vertical_direction:up,waterlogged:false}"},
        {pos: [6, 2, 28], state: "minecraft:deepslate_bricks"},
        {pos: [7, 2, 16], state: "minecraft:deepslate_bricks"},
        {pos: [7, 2, 17], state: "minecraft:pointed_dripstone{thickness:frustum,vertical_direction:up,waterlogged:false}"},
        {pos: [7, 2, 18], state: "minecraft:pointed_dripstone{thickness:base,vertical_direction:up,waterlogged:false}"},
        {pos: [7, 2, 19], state: "minecraft:pointed_dripstone{thickness:frustum,vertical_direction:up,waterlogged:false}"},
        {pos: [7, 2, 20], state: "minecraft:pointed_dripstone{thickness:frustum,vertical_direction:up,waterlogged:false}"},
        {pos: [7, 2, 21], state: "minecraft:deepslate_bricks"},
        {pos: [7, 2, 22], state: "minecraft:deepslate_bricks"},
        {pos: [7, 2, 23], state: "minecraft:deepslate_bricks"},
        {pos: [7, 2, 24], state: "minecraft:pointed_dripstone{thickness:tip,vertical_direction:up,waterlogged:false}"},
        {pos: [7, 2, 25], state: "minecraft:pointed_dripstone{thickness:frustum,vertical_direction:up,waterlogged:false}"},
        {pos: [7, 2, 26], state: "minecraft:pointed_dripstone{thickness:tip,vertical_direction:up,waterlogged:false}"},
        {pos: [7, 2, 27], state: "minecraft:pointed_dripstone{thickness:frustum,vertical_direction:up,waterlogged:false}"},
        {pos: [7, 2, 28], state: "minecraft:deepslate_bricks"},
        {pos: [8, 2, 16], state: "minecraft:deepslate_bricks"},
        {pos: [8, 2, 17], state: "minecraft:pointed_dripstone{thickness:tip,vertical_direction:up,waterlogged:false}"},
        {pos: [8, 2, 18], state: "minecraft:pointed_dripstone{thickness:frustum,vertical_direction:up,waterlogged:false}"},
        {pos: [8, 2, 19], state: "minecraft:pointed_dripstone{thickness:frustum,vertical_direction:up,waterlogged:false}"},
        {pos: [8, 2, 20], state: "minecraft:dripstone_block"},
        {pos: [8, 2, 21], state: "minecraft:deepslate_bricks"},
        {pos: [8, 2, 22], state: "minecraft:deepslate_bricks"},
        {pos: [8, 2, 23], state: "minecraft:pointed_dripstone{thickness:base,vertical_direction:up,waterlogged:false}"},
        {pos: [8, 2, 24], state: "minecraft:pointed_dripstone{thickness:base,vertical_direction:up,waterlogged:false}"},
        {pos: [8, 2, 25], state: "minecraft:pointed_dripstone{thickness:frustum,vertical_direction:up,waterlogged:false}"},
        {pos: [8, 2, 26], state: "minecraft:pointed_dripstone{thickness:frustum,vertical_direction:up,waterlogged:false}"},
        {pos: [8, 2, 27], state: "minecraft:pointed_dripstone{thickness:frustum,vertical_direction:up,waterlogged:false}"},
        {pos: [8, 2, 28], state: "minecraft:deepslate_bricks"},
        {pos: [9, 2, 16], state: "minecraft:deepslate_bricks"},
        {pos: [9, 2, 17], state: "minecraft:pointed_dripstone{thickness:tip,vertical_direction:up,waterlogged:false}"},
        {pos: [9, 2, 18], state: "minecraft:deepslate_bricks"},
        {pos: [9, 2, 19], state: "minecraft:deepslate_bricks"},
        {pos: [9, 2, 20], state: "minecraft:dripstone_block"},
        {pos: [9, 2, 21], state: "minecraft:deepslate_bricks"},
        {pos: [9, 2, 22], state: "minecraft:deepslate_bricks"},
        {pos: [9, 2, 23], state: "minecraft:pointed_dripstone{thickness:tip,vertical_direction:up,waterlogged:false}"},
        {pos: [9, 2, 24], state: "minecraft:pointed_dripstone{thickness:tip,vertical_direction:up,waterlogged:false}"},
        {pos: [9, 2, 25], state: "minecraft:pointed_dripstone{thickness:tip,vertical_direction:up,waterlogged:false}"},
        {pos: [9, 2, 26], state: "minecraft:pointed_dripstone{thickness:base,vertical_direction:up,waterlogged:false}"},
        {pos: [9, 2, 27], state: "minecraft:pointed_dripstone{thickness:tip,vertical_direction:up,waterlogged:false}"},
        {pos: [9, 2, 28], state: "minecraft:deepslate_bricks"},
        {pos: [10, 2, 16], state: "minecraft:deepslate_bricks"},
        {pos: [10, 2, 17], state: "minecraft:pointed_dripstone{thickness:frustum,vertical_direction:up,waterlogged:false}"},
        {pos: [10, 2, 18], state: "minecraft:deepslate_bricks"},
        {pos: [10, 2, 19], state: "minecraft:deepslate_bricks"},
        {pos: [10, 2, 20], state: "minecraft:pointed_dripstone{thickness:frustum,vertical_direction:up,waterlogged:false}"},
        {pos: [10, 2, 21], state: "minecraft:pointed_dripstone{thickness:frustum,vertical_direction:up,waterlogged:false}"},
        {pos: [10, 2, 22], state: "minecraft:pointed_dripstone{thickness:tip,vertical_direction:up,waterlogged:false}"},
        {pos: [10, 2, 23], state: "minecraft:pointed_dripstone{thickness:tip,vertical_direction:up,waterlogged:false}"},
        {pos: [10, 2, 24], state: "minecraft:pointed_dripstone{thickness:frustum,vertical_direction:up,waterlogged:false}"},
        {pos: [10, 2, 25], state: "minecraft:pointed_dripstone{thickness:tip,vertical_direction:up,waterlogged:false}"},
        {pos: [10, 2, 26], state: "minecraft:pointed_dripstone{thickness:tip,vertical_direction:up,waterlogged:false}"},
        {pos: [10, 2, 27], state: "minecraft:pointed_dripstone{thickness:frustum,vertical_direction:up,waterlogged:false}"},
        {pos: [10, 2, 28], state: "minecraft:deepslate_bricks"},
        {pos: [11, 2, 16], state: "minecraft:deepslate_bricks"},
        {pos: [11, 2, 17], state: "minecraft:pointed_dripstone{thickness:tip,vertical_direction:up,waterlogged:false}"},
        {pos: [11, 2, 18], state: "minecraft:pointed_dripstone{thickness:tip,vertical_direction:up,waterlogged:false}"},
        {pos: [11, 2, 19], state: "minecraft:pointed_dripstone{thickness:frustum,vertical_direction:up,waterlogged:false}"},
        {pos: [11, 2, 20], state: "minecraft:pointed_dripstone{thickness:tip,vertical_direction:up,waterlogged:false}"},
        {pos: [11, 2, 21], state: "minecraft:deepslate_bricks"},
        {pos: [11, 2, 22], state: "minecraft:deepslate_bricks"},
        {pos: [11, 2, 23], state: "minecraft:pointed_dripstone{thickness:frustum,vertical_direction:up,waterlogged:false}"},
        {pos: [11, 2, 24], state: "minecraft:pointed_dripstone{thickness:frustum,vertical_direction:up,waterlogged:false}"},
        {pos: [11, 2, 25], state: "minecraft:pointed_dripstone{thickness:frustum,vertical_direction:up,waterlogged:false}"},
        {pos: [11, 2, 26], state: "minecraft:pointed_dripstone{thickness:frustum,vertical_direction:up,waterlogged:false}"},
        {pos: [11, 2, 27], state: "minecraft:dripstone_block"},
        {pos: [11, 2, 28], state: "minecraft:deepslate_bricks"},
        {pos: [12, 2, 16], state: "minecraft:deepslate_bricks"},
        {pos: [12, 2, 17], state: "minecraft:deepslate_bricks"},
        {pos: [12, 2, 18], state: "minecraft:pointed_dripstone{thickness:base,vertical_direction:up,waterlogged:false}"},
        {pos: [12, 2, 19], state: "minecraft:pointed_dripstone{thickness:tip,vertical_direction:up,waterlogged:false}"},
        {pos: [12, 2, 20], state: "minecraft:pointed_dripstone{thickness:frustum,vertical_direction:up,waterlogged:false}"},
        {pos: [12, 2, 21], state: "minecraft:deepslate_bricks"},
        {pos: [12, 2, 22], state: "minecraft:deepslate_bricks"},
        {pos: [12, 2, 23], state: "minecraft:deepslate_bricks"},
        {pos: [12, 2, 24], state: "minecraft:pointed_dripstone{thickness:tip,vertical_direction:up,waterlogged:false}"},
        {pos: [12, 2, 25], state: "minecraft:pointed_dripstone{thickness:base,vertical_direction:up,waterlogged:false}"},
        {pos: [12, 2, 26], state: "minecraft:dripstone_block"},
        {pos: [12, 2, 27], state: "minecraft:dripstone_block"},
        {pos: [12, 2, 28], state: "minecraft:deepslate_bricks"},
        {pos: [13, 2, 16], state: "minecraft:deepslate_bricks"},
        {pos: [13, 2, 17], state: "minecraft:deepslate_bricks"},
        {pos: [13, 2, 18], state: "minecraft:deepslate_bricks"},
        {pos: [13, 2, 19], state: "minecraft:pointed_dripstone{thickness:frustum,vertical_direction:up,waterlogged:false}"},
        {pos: [13, 2, 20], state: "minecraft:pointed_dripstone{thickness:tip,vertical_direction:up,waterlogged:false}"},
        {pos: [13, 2, 21], state: "minecraft:pointed_dripstone{thickness:frustum,vertical_direction:up,waterlogged:false}"},
        {pos: [13, 2, 22], state: "minecraft:dripstone_block"},
        {pos: [13, 2, 23], state: "minecraft:pointed_dripstone{thickness:frustum,vertical_direction:up,waterlogged:false}"},
        {pos: [13, 2, 24], state: "minecraft:pointed_dripstone{thickness:frustum,vertical_direction:up,waterlogged:false}"},
        {pos: [13, 2, 25], state: "minecraft:pointed_dripstone{thickness:frustum,vertical_direction:up,waterlogged:false}"},
        {pos: [13, 2, 26], state: "minecraft:dripstone_block"},
        {pos: [13, 2, 27], state: "minecraft:deepslate_bricks"},
        {pos: [13, 2, 28], state: "minecraft:deepslate_bricks"},
        {pos: [14, 2, 16], state: "minecraft:deepslate_bricks"},
        {pos: [14, 2, 17], state: "minecraft:deepslate_bricks"},
        {pos: [14, 2, 18], state: "minecraft:dripstone_block"},
        {pos: [14, 2, 19], state: "minecraft:pointed_dripstone{thickness:tip,vertical_direction:up,waterlogged:false}"},
        {pos: [14, 2, 20], state: "minecraft:pointed_dripstone{thickness:frustum,vertical_direction:up,waterlogged:false}"},
        {pos: [14, 2, 21], state: "minecraft:pointed_dripstone{thickness:tip,vertical_direction:up,waterlogged:false}"},
        {pos: [14, 2, 22], state: "minecraft:pointed_dripstone{thickness:frustum,vertical_direction:up,waterlogged:false}"},
        {pos: [14, 2, 23], state: "minecraft:pointed_dripstone{thickness:tip,vertical_direction:up,waterlogged:false}"},
        {pos: [14, 2, 24], state: "minecraft:pointed_dripstone{thickness:tip,vertical_direction:up,waterlogged:false}"},
        {pos: [14, 2, 25], state: "minecraft:pointed_dripstone{thickness:tip,vertical_direction:up,waterlogged:false}"},
        {pos: [14, 2, 26], state: "minecraft:pointed_dripstone{thickness:frustum,vertical_direction:up,waterlogged:false}"},
        {pos: [14, 2, 27], state: "minecraft:deepslate_bricks"},
        {pos: [14, 2, 28], state: "minecraft:deepslate_bricks"},
        {pos: [15, 2, 16], state: "minecraft:deepslate_bricks"},
        {pos: [15, 2, 17], state: "minecraft:pointed_dripstone{thickness:tip,vertical_direction:up,waterlogged:false}"},
        {pos: [15, 2, 18], state: "minecraft:pointed_dripstone{thickness:frustum,vertical_direction:up,waterlogged:false}"},
        {pos: [15, 2, 19], state: "minecraft:pointed_dripstone{thickness:tip,vertical_direction:up,waterlogged:false}"},
        {pos: [15, 2, 20], state: "minecraft:pointed_dripstone{thickness:tip,vertical_direction:up,waterlogged:false}"},
        {pos: [15, 2, 21], state: "minecraft:deepslate_bricks"},
        {pos: [15, 2, 22], state: "minecraft:deepslate_bricks"},
        {pos: [15, 2, 23], state: "minecraft:pointed_dripstone{thickness:tip,vertical_direction:up,waterlogged:false}"},
        {pos: [15, 2, 24], state: "minecraft:pointed_dripstone{thickness:frustum,vertical_direction:up,waterlogged:false}"},
        {pos: [15, 2, 25], state: "minecraft:pointed_dripstone{thickness:base,vertical_direction:up,waterlogged:false}"},
        {pos: [15, 2, 26], state: "minecraft:pointed_dripstone{thickness:tip,vertical_direction:up,waterlogged:false}"},
        {pos: [15, 2, 27], state: "minecraft:dripstone_block"},
        {pos: [15, 2, 28], state: "minecraft:deepslate_bricks"},
        {pos: [16, 2, 16], state: "minecraft:deepslate_bricks"},
        {pos: [16, 2, 17], state: "minecraft:pointed_dripstone{thickness:frustum,vertical_direction:up,waterlogged:false}"},
        {pos: [16, 2, 18], state: "minecraft:pointed_dripstone{thickness:frustum,vertical_direction:up,waterlogged:false}"},
        {pos: [16, 2, 19], state: "minecraft:pointed_dripstone{thickness:frustum,vertical_direction:up,waterlogged:false}"},
        {pos: [16, 2, 20], state: "minecraft:dripstone_block"},
        {pos: [16, 2, 21], state: "minecraft:deepslate_bricks"},
        {pos: [16, 2, 22], state: "minecraft:pointed_dripstone{thickness:base,vertical_direction:up,waterlogged:false}"},
        {pos: [16, 2, 23], state: "minecraft:pointed_dripstone{thickness:frustum,vertical_direction:up,waterlogged:false}"},
        {pos: [16, 2, 24], state: "minecraft:deepslate_bricks"},
        {pos: [16, 2, 25], state: "minecraft:deepslate_bricks"},
        {pos: [16, 2, 26], state: "minecraft:pointed_dripstone{thickness:frustum,vertical_direction:up,waterlogged:false}"},
        {pos: [16, 2, 27], state: "minecraft:pointed_dripstone{thickness:frustum,vertical_direction:up,waterlogged:false}"},
        {pos: [16, 2, 28], state: "minecraft:deepslate_bricks"},
        {pos: [17, 2, 16], state: "minecraft:deepslate_bricks"},
        {pos: [17, 2, 17], state: "minecraft:pointed_dripstone{thickness:tip,vertical_direction:up,waterlogged:false}"},
        {pos: [17, 2, 18], state: "minecraft:pointed_dripstone{thickness:frustum,vertical_direction:up,waterlogged:false}"},
        {pos: [17, 2, 19], state: "minecraft:pointed_dripstone{thickness:frustum,vertical_direction:up,waterlogged:false}"},
        {pos: [17, 2, 20], state: "minecraft:pointed_dripstone{thickness:frustum,vertical_direction:up,waterlogged:false}"},
        {pos: [17, 2, 21], state: "minecraft:pointed_dripstone{thickness:tip,vertical_direction:up,waterlogged:false}"},
        {pos: [17, 2, 22], state: "minecraft:pointed_dripstone{thickness:frustum,vertical_direction:up,waterlogged:false}"},
        {pos: [17, 2, 23], state: "minecraft:pointed_dripstone{thickness:tip,vertical_direction:up,waterlogged:false}"},
        {pos: [17, 2, 24], state: "minecraft:deepslate_bricks"},
        {pos: [17, 2, 25], state: "minecraft:deepslate_bricks"},
        {pos: [17, 2, 26], state: "minecraft:pointed_dripstone{thickness:frustum,vertical_direction:up,waterlogged:false}"},
        {pos: [17, 2, 27], state: "minecraft:pointed_dripstone{thickness:frustum,vertical_direction:up,waterlogged:false}"},
        {pos: [17, 2, 28], state: "minecraft:deepslate_bricks"},
        {pos: [18, 2, 16], state: "minecraft:deepslate_bricks"},
        {pos: [18, 2, 17], state: "minecraft:pointed_dripstone{thickness:frustum,vertical_direction:up,waterlogged:false}"},
        {pos: [18, 2, 18], state: "minecraft:pointed_dripstone{thickness:tip,vertical_direction:up,waterlogged:false}"},
        {pos: [18, 2, 19], state: "minecraft:pointed_dripstone{thickness:frustum,vertical_direction:up,waterlogged:false}"},
        {pos: [18, 2, 20], state: "minecraft:pointed_dripstone{thickness:tip,vertical_direction:up,waterlogged:false}"},
        {pos: [18, 2, 21], state: "minecraft:pointed_dripstone{thickness:base,vertical_direction:up,waterlogged:false}"},
        {pos: [18, 2, 22], state: "minecraft:pointed_dripstone{thickness:tip,vertical_direction:up,waterlogged:false}"},
        {pos: [18, 2, 23], state: "minecraft:pointed_dripstone{thickness:base,vertical_direction:up,waterlogged:false}"},
        {pos: [18, 2, 24], state: "minecraft:pointed_dripstone{thickness:frustum,vertical_direction:up,waterlogged:false}"},
        {pos: [18, 2, 25], state: "minecraft:pointed_dripstone{thickness:frustum,vertical_direction:up,waterlogged:false}"},
        {pos: [18, 2, 26], state: "minecraft:pointed_dripstone{thickness:tip,vertical_direction:up,waterlogged:false}"},
        {pos: [18, 2, 27], state: "minecraft:pointed_dripstone{thickness:base,vertical_direction:up,waterlogged:false}"},
        {pos: [18, 2, 28], state: "minecraft:deepslate_bricks"},
        {pos: [19, 2, 16], state: "minecraft:deepslate_bricks"},
        {pos: [19, 2, 17], state: "minecraft:pointed_dripstone{thickness:tip,vertical_direction:up,waterlogged:false}"},
        {pos: [19, 2, 18], state: "minecraft:pointed_dripstone{thickness:base,vertical_direction:up,waterlogged:false}"},
        {pos: [19, 2, 19], state: "minecraft:pointed_dripstone{thickness:tip,vertical_direction:up,waterlogged:false}"},
        {pos: [19, 2, 20], state: "minecraft:pointed_dripstone{thickness:tip,vertical_direction:up,waterlogged:false}"},
        {pos: [19, 2, 21], state: "minecraft:deepslate_bricks"},
        {pos: [19, 2, 22], state: "minecraft:pointed_dripstone{thickness:frustum,vertical_direction:up,waterlogged:false}"},
        {pos: [19, 2, 23], state: "minecraft:pointed_dripstone{thickness:tip,vertical_direction:up,waterlogged:false}"},
        {pos: [19, 2, 24], state: "minecraft:pointed_dripstone{thickness:frustum,vertical_direction:up,waterlogged:false}"},
        {pos: [19, 2, 25], state: "minecraft:pointed_dripstone{thickness:frustum,vertical_direction:up,waterlogged:false}"},
        {pos: [19, 2, 26], state: "minecraft:pointed_dripstone{thickness:frustum,vertical_direction:up,waterlogged:false}"},
        {pos: [19, 2, 27], state: "minecraft:pointed_dripstone{thickness:tip,vertical_direction:up,waterlogged:false}"},
        {pos: [19, 2, 28], state: "minecraft:deepslate_bricks"},
        {pos: [20, 2, 16], state: "minecraft:deepslate_bricks"},
        {pos: [20, 2, 17], state: "minecraft:pointed_dripstone{thickness:frustum,vertical_direction:up,waterlogged:false}"},
        {pos: [20, 2, 18], state: "minecraft:pointed_dripstone{thickness:tip,vertical_direction:up,waterlogged:false}"},
        {pos: [20, 2, 19], state: "minecraft:pointed_dripstone{thickness:frustum,vertical_direction:up,waterlogged:false}"},
        {pos: [20, 2, 20], state: "minecraft:dripstone_block"},
        {pos: [20, 2, 21], state: "minecraft:deepslate_bricks"},
        {pos: [20, 2, 22], state: "minecraft:deepslate_bricks"},
        {pos: [20, 2, 23], state: "minecraft:pointed_dripstone{thickness:frustum,vertical_direction:up,waterlogged:false}"},
        {pos: [20, 2, 24], state: "minecraft:pointed_dripstone{thickness:tip,vertical_direction:up,waterlogged:false}"},
        {pos: [20, 2, 25], state: "minecraft:pointed_dripstone{thickness:base,vertical_direction:up,waterlogged:false}"},
        {pos: [20, 2, 26], state: "minecraft:pointed_dripstone{thickness:tip,vertical_direction:up,waterlogged:false}"},
        {pos: [20, 2, 27], state: "minecraft:pointed_dripstone{thickness:frustum,vertical_direction:up,waterlogged:false}"},
        {pos: [20, 2, 28], state: "minecraft:deepslate_bricks"},
        {pos: [21, 2, 16], state: "minecraft:deepslate_bricks"},
        {pos: [21, 2, 17], state: "minecraft:pointed_dripstone{thickness:frustum,vertical_direction:up,waterlogged:false}"},
        {pos: [21, 2, 18], state: "minecraft:pointed_dripstone{thickness:tip,vertical_direction:up,waterlogged:false}"},
        {pos: [21, 2, 19], state: "minecraft:dripstone_block"},
        {pos: [21, 2, 20], state: "minecraft:dripstone_block"},
        {pos: [21, 2, 21], state: "minecraft:deepslate_bricks"},
        {pos: [21, 2, 22], state: "minecraft:deepslate_bricks"},
        {pos: [21, 2, 23], state: "minecraft:dripstone_block"},
        {pos: [21, 2, 24], state: "minecraft:pointed_dripstone{thickness:frustum,vertical_direction:up,waterlogged:false}"},
        {pos: [21, 2, 25], state: "minecraft:pointed_dripstone{thickness:tip,vertical_direction:up,waterlogged:false}"},
        {pos: [21, 2, 26], state: "minecraft:pointed_dripstone{thickness:tip,vertical_direction:up,waterlogged:false}"},
        {pos: [21, 2, 27], state: "minecraft:pointed_dripstone{thickness:base,vertical_direction:up,waterlogged:false}"},
        {pos: [21, 2, 28], state: "minecraft:deepslate_bricks"},
        {pos: [22, 2, 16], state: "minecraft:deepslate_bricks"},
        {pos: [22, 2, 17], state: "minecraft:pointed_dripstone{thickness:frustum,vertical_direction:up,waterlogged:false}"},
        {pos: [22, 2, 18], state: "minecraft:pointed_dripstone{thickness:frustum,vertical_direction:up,waterlogged:false}"},
        {pos: [22, 2, 19], state: "minecraft:dripstone_block"},
        {pos: [22, 2, 20], state: "minecraft:deepslate_bricks"},
        {pos: [22, 2, 21], state: "minecraft:deepslate_bricks"},
        {pos: [22, 2, 22], state: "minecraft:deepslate_bricks"},
        {pos: [22, 2, 23], state: "minecraft:dripstone_block"},
        {pos: [22, 2, 24], state: "minecraft:dripstone_block"},
        {pos: [22, 2, 25], state: "minecraft:pointed_dripstone{thickness:frustum,vertical_direction:up,waterlogged:false}"},
        {pos: [22, 2, 26], state: "minecraft:pointed_dripstone{thickness:frustum,vertical_direction:up,waterlogged:false}"},
        {pos: [22, 2, 27], state: "minecraft:pointed_dripstone{thickness:tip,vertical_direction:up,waterlogged:false}"},
        {pos: [22, 2, 28], state: "minecraft:deepslate_bricks"},
        {pos: [23, 2, 16], state: "minecraft:deepslate_bricks"},
        {pos: [23, 2, 17], state: "minecraft:pointed_dripstone{thickness:tip,vertical_direction:up,waterlogged:false}"},
        {pos: [23, 2, 18], state: "minecraft:pointed_dripstone{thickness:frustum,vertical_direction:up,waterlogged:false}"},
        {pos: [23, 2, 19], state: "minecraft:dripstone_block"},
        {pos: [23, 2, 20], state: "minecraft:deepslate_bricks"},
        {pos: [23, 2, 21], state: "minecraft:deepslate_bricks"},
        {pos: [23, 2, 22], state: "minecraft:deepslate_bricks"},
        {pos: [23, 2, 23], state: "minecraft:deepslate_bricks"},
        {pos: [23, 2, 24], state: "minecraft:dripstone_block"},
        {pos: [23, 2, 25], state: "minecraft:dripstone_block"},
        {pos: [23, 2, 26], state: "minecraft:pointed_dripstone{thickness:frustum,vertical_direction:up,waterlogged:false}"},
        {pos: [23, 2, 27], state: "minecraft:pointed_dripstone{thickness:frustum,vertical_direction:up,waterlogged:false}"},
        {pos: [23, 2, 28], state: "minecraft:deepslate_bricks"},
        {pos: [24, 2, 16], state: "minecraft:deepslate_bricks"},
        {pos: [24, 2, 17], state: "minecraft:deepslate_bricks"},
        {pos: [24, 2, 18], state: "minecraft:deepslate_bricks"},
        {pos: [24, 2, 19], state: "minecraft:deepslate_bricks"},
        {pos: [24, 2, 20], state: "minecraft:deepslate_bricks"},
        {pos: [24, 2, 21], state: "minecraft:deepslate_bricks"},
        {pos: [24, 2, 22], state: "minecraft:deepslate_bricks"},
        {pos: [24, 2, 23], state: "minecraft:deepslate_bricks"},
        {pos: [24, 2, 24], state: "minecraft:deepslate_bricks"},
        {pos: [24, 2, 25], state: "minecraft:deepslate_bricks"},
        {pos: [24, 2, 26], state: "minecraft:deepslate_bricks"},
        {pos: [24, 2, 27], state: "minecraft:deepslate_bricks"},
        {pos: [24, 2, 28], state: "minecraft:deepslate_bricks"},
        {pos: [25, 2, 16], state: "minecraft:deepslate_bricks"},
        {pos: [25, 2, 17], state: "minecraft:deepslate_bricks"},
        {pos: [25, 2, 18], state: "minecraft:deepslate_bricks"},
        {pos: [25, 2, 19], state: "minecraft:deepslate_bricks"},
        {pos: [25, 2, 20], state: "minecraft:deepslate_bricks"},
        {pos: [25, 2, 21], state: "minecraft:deepslate_bricks"},
        {pos: [25, 2, 22], state: "minecraft:deepslate_bricks"},
        {pos: [25, 2, 23], state: "minecraft:deepslate_bricks"},
        {pos: [25, 2, 24], state: "minecraft:deepslate_bricks"},
        {pos: [25, 2, 25], state: "minecraft:deepslate_bricks"},
        {pos: [25, 2, 26], state: "minecraft:deepslate_bricks"},
        {pos: [25, 2, 27], state: "minecraft:deepslate_bricks"},
        {pos: [25, 2, 28], state: "minecraft:deepslate_bricks"},
        {pos: [26, 2, 16], state: "minecraft:deepslate_bricks"},
        {pos: [26, 2, 17], state: "minecraft:deepslate_bricks"},
        {pos: [26, 2, 18], state: "minecraft:deepslate_bricks"},
        {pos: [26, 2, 19], state: "minecraft:deepslate_bricks"},
        {pos: [26, 2, 20], state: "minecraft:deepslate_bricks"},
        {pos: [26, 2, 21], state: "minecraft:deepslate_bricks"},
        {pos: [26, 2, 22], state: "minecraft:deepslate_bricks"},
        {pos: [26, 2, 23], state: "minecraft:deepslate_bricks"},
        {pos: [26, 2, 24], state: "minecraft:deepslate_bricks"},
        {pos: [26, 2, 25], state: "minecraft:deepslate_bricks"},
        {pos: [26, 2, 26], state: "minecraft:deepslate_bricks"},
        {pos: [26, 2, 27], state: "minecraft:deepslate_bricks"},
        {pos: [26, 2, 28], state: "minecraft:deepslate_bricks"},
        {pos: [0, 3, 16], state: "minecraft:deepslate_bricks"},
        {pos: [0, 3, 17], state: "minecraft:deepslate_bricks"},
        {pos: [0, 3, 18], state: "minecraft:deepslate_bricks"},
        {pos: [0, 3, 19], state: "minecraft:deepslate_bricks"},
        {pos: [0, 3, 20], state: "minecraft:deepslate_bricks"},
        {pos: [0, 3, 21], state: "minecraft:deepslate_bricks"},
        {pos: [0, 3, 22], state: "minecraft:deepslate_bricks"},
        {pos: [0, 3, 23], state: "minecraft:deepslate_bricks"},
        {pos: [0, 3, 24], state: "minecraft:deepslate_bricks"},
        {pos: [0, 3, 25], state: "minecraft:deepslate_bricks"},
        {pos: [0, 3, 26], state: "minecraft:deepslate_bricks"},
        {pos: [0, 3, 27], state: "minecraft:deepslate_bricks"},
        {pos: [0, 3, 28], state: "minecraft:deepslate_bricks"},
        {pos: [1, 3, 16], state: "minecraft:deepslate_bricks"},
        {pos: [1, 3, 17], state: "minecraft:deepslate_bricks"},
        {pos: [1, 3, 18], state: "minecraft:deepslate_bricks"},
        {pos: [1, 3, 19], state: "minecraft:deepslate_bricks"},
        {pos: [1, 3, 20], state: "minecraft:deepslate_bricks"},
        {pos: [1, 3, 21], state: "minecraft:deepslate_bricks"},
        {pos: [1, 3, 22], state: "minecraft:deepslate_bricks"},
        {pos: [1, 3, 23], state: "minecraft:deepslate_bricks"},
        {pos: [1, 3, 24], state: "minecraft:deepslate_bricks"},
        {pos: [1, 3, 25], state: "minecraft:deepslate_bricks"},
        {pos: [1, 3, 26], state: "minecraft:deepslate_bricks"},
        {pos: [1, 3, 27], state: "minecraft:deepslate_bricks"},
        {pos: [1, 3, 28], state: "minecraft:deepslate_bricks"},
        {pos: [2, 3, 16], state: "minecraft:deepslate_bricks"},
        {pos: [2, 3, 17], state: "minecraft:deepslate_bricks"},
        {pos: [2, 3, 18], state: "minecraft:deepslate_bricks"},
        {pos: [2, 3, 19], state: "minecraft:deepslate_bricks"},
        {pos: [2, 3, 20], state: "minecraft:deepslate_bricks"},
        {pos: [2, 3, 21], state: "minecraft:deepslate_bricks"},
        {pos: [2, 3, 22], state: "minecraft:deepslate_bricks"},
        {pos: [2, 3, 23], state: "minecraft:deepslate_bricks"},
        {pos: [2, 3, 24], state: "minecraft:deepslate_bricks"},
        {pos: [2, 3, 25], state: "minecraft:deepslate_bricks"},
        {pos: [2, 3, 26], state: "minecraft:deepslate_bricks"},
        {pos: [2, 3, 27], state: "minecraft:deepslate_bricks"},
        {pos: [2, 3, 28], state: "minecraft:deepslate_bricks"},
        {pos: [3, 3, 16], state: "minecraft:deepslate_bricks"},
        {pos: [3, 3, 17], state: "minecraft:dripstone_block"},
        {pos: [3, 3, 18], state: "minecraft:pointed_dripstone{thickness:frustum,vertical_direction:up,waterlogged:false}"},
        {pos: [3, 3, 19], state: "minecraft:pointed_dripstone{thickness:tip,vertical_direction:up,waterlogged:false}"},
        {pos: [3, 3, 20], state: "minecraft:pointed_dripstone{thickness:tip,vertical_direction:up,waterlogged:false}"},
        {pos: [3, 3, 21], state: "minecraft:deepslate_bricks"},
        {pos: [3, 3, 22], state: "minecraft:deepslate_bricks"},
        {pos: [3, 3, 23], state: "minecraft:deepslate_bricks"},
        {pos: [3, 3, 24], state: "minecraft:pointed_dripstone{thickness:tip,vertical_direction:up,waterlogged:false}"},
        {pos: [3, 3, 25], state: "minecraft:pointed_dripstone{thickness:frustum,vertical_direction:up,waterlogged:false}"},
        {pos: [3, 3, 26], state: "minecraft:pointed_dripstone{thickness:base,vertical_direction:up,waterlogged:false}"},
        {pos: [3, 3, 27], state: "minecraft:pointed_dripstone{thickness:frustum,vertical_direction:up,waterlogged:false}"},
        {pos: [3, 3, 28], state: "minecraft:deepslate_bricks"},
        {pos: [4, 3, 16], state: "minecraft:deepslate_bricks"},
        {pos: [4, 3, 17], state: "minecraft:pointed_dripstone{thickness:frustum,vertical_direction:up,waterlogged:false}"},
        {pos: [4, 3, 18], state: "minecraft:pointed_dripstone{thickness:frustum,vertical_direction:up,waterlogged:false}"},
        {pos: [4, 3, 19], state: "minecraft:pointed_dripstone{thickness:tip,vertical_direction:up,waterlogged:false}"},
        {pos: [4, 3, 20], state: "minecraft:cave_air"},
        {pos: [4, 3, 21], state: "minecraft:deepslate_bricks"},
        {pos: [4, 3, 22], state: "minecraft:deepslate_bricks"},
        {pos: [4, 3, 23], state: "minecraft:deepslate_bricks"},
        {pos: [4, 3, 24], state: "minecraft:pointed_dripstone{thickness:tip,vertical_direction:up,waterlogged:false}"},
        {pos: [4, 3, 25], state: "minecraft:pointed_dripstone{thickness:tip,vertical_direction:up,waterlogged:false}"},
        {pos: [4, 3, 26], state: "minecraft:pointed_dripstone{thickness:frustum,vertical_direction:up,waterlogged:false}"},
        {pos: [4, 3, 27], state: "minecraft:pointed_dripstone{thickness:frustum,vertical_direction:up,waterlogged:false}"},
        {pos: [4, 3, 28], state: "minecraft:deepslate_bricks"},
        {pos: [5, 3, 16], state: "minecraft:deepslate_bricks"},
        {pos: [5, 3, 17], state: "minecraft:pointed_dripstone{thickness:frustum,vertical_direction:up,waterlogged:false}"},
        {pos: [5, 3, 18], state: "minecraft:cave_air"},
        {pos: [5, 3, 19], state: "minecraft:cave_air"},
        {pos: [5, 3, 20], state: "minecraft:pointed_dripstone{thickness:frustum,vertical_direction:up,waterlogged:false}"},
        {pos: [5, 3, 21], state: "minecraft:deepslate_bricks"},
        {pos: [5, 3, 22], state: "minecraft:deepslate_bricks"},
        {pos: [5, 3, 23], state: "minecraft:deepslate_bricks"},
        {pos: [5, 3, 24], state: "minecraft:pointed_dripstone{thickness:tip,vertical_direction:up,waterlogged:false}"},
        {pos: [5, 3, 25], state: "minecraft:cave_air"},
        {pos: [5, 3, 26], state: "minecraft:pointed_dripstone{thickness:frustum,vertical_direction:up,waterlogged:false}"},
        {pos: [5, 3, 27], state: "minecraft:pointed_dripstone{thickness:base,vertical_direction:up,waterlogged:false}"},
        {pos: [5, 3, 28], state: "minecraft:deepslate_bricks"},
        {pos: [6, 3, 16], state: "minecraft:deepslate_bricks"},
        {pos: [6, 3, 17], state: "minecraft:cave_air"},
        {pos: [6, 3, 18], state: "minecraft:pointed_dripstone{thickness:tip,vertical_direction:up,waterlogged:false}"},
        {pos: [6, 3, 19], state: "minecraft:pointed_dripstone{thickness:tip,vertical_direction:up,waterlogged:false}"},
        {pos: [6, 3, 20], state: "minecraft:cave_air"},
        {pos: [6, 3, 21], state: "minecraft:pointed_dripstone{thickness:tip,vertical_direction:up,waterlogged:false}"},
        {pos: [6, 3, 22], state: "minecraft:deepslate_bricks"},
        {pos: [6, 3, 23], state: "minecraft:deepslate_bricks"},
        {pos: [6, 3, 24], state: "minecraft:pointed_dripstone{thickness:frustum,vertical_direction:up,waterlogged:false}"},
        {pos: [6, 3, 25], state: "minecraft:cave_air"},
        {pos: [6, 3, 26], state: "minecraft:pointed_dripstone{thickness:tip,vertical_direction:up,waterlogged:false}"},
        {pos: [6, 3, 27], state: "minecraft:pointed_dripstone{thickness:tip,vertical_direction:up,waterlogged:false}"},
        {pos: [6, 3, 28], state: "minecraft:deepslate_bricks"},
        {pos: [7, 3, 16], state: "minecraft:deepslate_bricks"},
        {pos: [7, 3, 17], state: "minecraft:pointed_dripstone{thickness:tip,vertical_direction:up,waterlogged:false}"},
        {pos: [7, 3, 18], state: "minecraft:pointed_dripstone{thickness:frustum,vertical_direction:up,waterlogged:false}"},
        {pos: [7, 3, 19], state: "minecraft:pointed_dripstone{thickness:tip,vertical_direction:up,waterlogged:false}"},
        {pos: [7, 3, 20], state: "minecraft:pointed_dripstone{thickness:tip,vertical_direction:up,waterlogged:false}"},
        {pos: [7, 3, 21], state: "minecraft:deepslate_bricks"},
        {pos: [7, 3, 22], state: "minecraft:deepslate_bricks"},
        {pos: [7, 3, 23], state: "minecraft:deepslate_bricks"},
        {pos: [7, 3, 24], state: "minecraft:cave_air"},
        {pos: [7, 3, 25], state: "minecraft:pointed_dripstone{thickness:tip,vertical_direction:up,waterlogged:false}"},
        {pos: [7, 3, 26], state: "minecraft:cave_air"},
        {pos: [7, 3, 27], state: "minecraft:pointed_dripstone{thickness:tip,vertical_direction:up,waterlogged:false}"},
        {pos: [7, 3, 28], state: "minecraft:deepslate_bricks"},
        {pos: [8, 3, 16], state: "minecraft:deepslate_bricks"},
        {pos: [8, 3, 17], state: "minecraft:cave_air"},
        {pos: [8, 3, 18], state: "minecraft:pointed_dripstone{thickness:tip,vertical_direction:up,waterlogged:false}"},
        {pos: [8, 3, 19], state: "minecraft:pointed_dripstone{thickness:tip,vertical_direction:up,waterlogged:false}"},
        {pos: [8, 3, 20], state: "minecraft:pointed_dripstone{thickness:frustum,vertical_direction:up,waterlogged:false}"},
        {pos: [8, 3, 21], state: "minecraft:deepslate_bricks"},
        {pos: [8, 3, 22], state: "minecraft:deepslate_bricks"},
        {pos: [8, 3, 23], state: "minecraft:pointed_dripstone{thickness:frustum,vertical_direction:up,waterlogged:false}"},
        {pos: [8, 3, 24], state: "minecraft:pointed_dripstone{thickness:frustum,vertical_direction:up,waterlogged:false}"},
        {pos: [8, 3, 25], state: "minecraft:pointed_dripstone{thickness:tip,vertical_direction:up,waterlogged:false}"},
        {pos: [8, 3, 26], state: "minecraft:pointed_dripstone{thickness:tip,vertical_direction:up,waterlogged:false}"},
        {pos: [8, 3, 27], state: "minecraft:pointed_dripstone{thickness:tip,vertical_direction:up,waterlogged:false}"},
        {pos: [8, 3, 28], state: "minecraft:deepslate_bricks"},
        {pos: [9, 3, 16], state: "minecraft:deepslate_bricks"},
        {pos: [9, 3, 17], state: "minecraft:cave_air"},
        {pos: [9, 3, 18], state: "minecraft:deepslate_bricks"},
        {pos: [9, 3, 19], state: "minecraft:deepslate_bricks"},
        {pos: [9, 3, 20], state: "minecraft:pointed_dripstone{thickness:frustum,vertical_direction:up,waterlogged:false}"},
        {pos: [9, 3, 21], state: "minecraft:deepslate_bricks"},
        {pos: [9, 3, 22], state: "minecraft:deepslate_bricks"},
        {pos: [9, 3, 23], state: "minecraft:cave_air"},
        {pos: [9, 3, 24], state: "minecraft:cave_air"},
        {pos: [9, 3, 25], state: "minecraft:cave_air"},
        {pos: [9, 3, 26], state: "minecraft:pointed_dripstone{thickness:frustum,vertical_direction:up,waterlogged:false}"},
        {pos: [9, 3, 27], state: "minecraft:cave_air"},
        {pos: [9, 3, 28], state: "minecraft:deepslate_bricks"},
        {pos: [10, 3, 16], state: "minecraft:deepslate_bricks"},
        {pos: [10, 3, 17], state: "minecraft:pointed_dripstone{thickness:tip,vertical_direction:up,waterlogged:false}"},
        {pos: [10, 3, 18], state: "minecraft:deepslate_bricks"},
        {pos: [10, 3, 19], state: "minecraft:deepslate_bricks"},
        {pos: [10, 3, 20], state: "minecraft:pointed_dripstone{thickness:tip,vertical_direction:up,waterlogged:false}"},
        {pos: [10, 3, 21], state: "minecraft:pointed_dripstone{thickness:tip,vertical_direction:up,waterlogged:false}"},
        {pos: [10, 3, 22], state: "minecraft:cave_air"},
        {pos: [10, 3, 23], state: "minecraft:cave_air"},
        {pos: [10, 3, 24], state: "minecraft:pointed_dripstone{thickness:tip,vertical_direction:up,waterlogged:false}"},
        {pos: [10, 3, 25], state: "minecraft:cave_air"},
        {pos: [10, 3, 26], state: "minecraft:cave_air"},
        {pos: [10, 3, 27], state: "minecraft:pointed_dripstone{thickness:tip,vertical_direction:up,waterlogged:false}"},
        {pos: [10, 3, 28], state: "minecraft:deepslate_bricks"},
        {pos: [11, 3, 16], state: "minecraft:deepslate_bricks"},
        {pos: [11, 3, 17], state: "minecraft:cave_air"},
        {pos: [11, 3, 18], state: "minecraft:cave_air"},
        {pos: [11, 3, 19], state: "minecraft:pointed_dripstone{thickness:tip,vertical_direction:up,waterlogged:false}"},
        {pos: [11, 3, 20], state: "minecraft:cave_air"},
        {pos: [11, 3, 21], state: "minecraft:deepslate_bricks"},
        {pos: [11, 3, 22], state: "minecraft:deepslate_bricks"},
        {pos: [11, 3, 23], state: "minecraft:pointed_dripstone{thickness:tip,vertical_direction:up,waterlogged:false}"},
        {pos: [11, 3, 24], state: "minecraft:pointed_dripstone{thickness:tip,vertical_direction:up,waterlogged:false}"},
        {pos: [11, 3, 25], state: "minecraft:pointed_dripstone{thickness:tip,vertical_direction:up,waterlogged:false}"},
        {pos: [11, 3, 26], state: "minecraft:pointed_dripstone{thickness:tip,vertical_direction:up,waterlogged:false}"},
        {pos: [11, 3, 27], state: "minecraft:pointed_dripstone{thickness:frustum,vertical_direction:up,waterlogged:false}"},
        {pos: [11, 3, 28], state: "minecraft:deepslate_bricks"},
        {pos: [12, 3, 16], state: "minecraft:deepslate_bricks"},
        {pos: [12, 3, 17], state: "minecraft:deepslate_bricks"},
        {pos: [12, 3, 18], state: "minecraft:pointed_dripstone{thickness:frustum,vertical_direction:up,waterlogged:false}"},
        {pos: [12, 3, 19], state: "minecraft:cave_air"},
        {pos: [12, 3, 20], state: "minecraft:pointed_dripstone{thickness:tip,vertical_direction:up,waterlogged:false}"},
        {pos: [12, 3, 21], state: "minecraft:deepslate_bricks"},
        {pos: [12, 3, 22], state: "minecraft:deepslate_bricks"},
        {pos: [12, 3, 23], state: "minecraft:deepslate_bricks"},
        {pos: [12, 3, 24], state: "minecraft:cave_air"},
        {pos: [12, 3, 25], state: "minecraft:pointed_dripstone{thickness:frustum,vertical_direction:up,waterlogged:false}"},
        {pos: [12, 3, 26], state: "minecraft:pointed_dripstone{thickness:frustum,vertical_direction:up,waterlogged:false}"},
        {pos: [12, 3, 27], state: "minecraft:pointed_dripstone{thickness:base,vertical_direction:up,waterlogged:false}"},
        {pos: [12, 3, 28], state: "minecraft:deepslate_bricks"},
        {pos: [13, 3, 16], state: "minecraft:deepslate_bricks"},
        {pos: [13, 3, 17], state: "minecraft:deepslate_bricks"},
        {pos: [13, 3, 18], state: "minecraft:deepslate_bricks"},
        {pos: [13, 3, 19], state: "minecraft:pointed_dripstone{thickness:tip,vertical_direction:up,waterlogged:false}"},
        {pos: [13, 3, 20], state: "minecraft:cave_air"},
        {pos: [13, 3, 21], state: "minecraft:pointed_dripstone{thickness:tip,vertical_direction:up,waterlogged:false}"},
        {pos: [13, 3, 22], state: "minecraft:pointed_dripstone{thickness:frustum,vertical_direction:up,waterlogged:false}"},
        {pos: [13, 3, 23], state: "minecraft:pointed_dripstone{thickness:tip,vertical_direction:up,waterlogged:false}"},
        {pos: [13, 3, 24], state: "minecraft:pointed_dripstone{thickness:tip,vertical_direction:up,waterlogged:false}"},
        {pos: [13, 3, 25], state: "minecraft:pointed_dripstone{thickness:tip,vertical_direction:up,waterlogged:false}"},
        {pos: [13, 3, 26], state: "minecraft:pointed_dripstone{thickness:frustum,vertical_direction:up,waterlogged:false}"},
        {pos: [13, 3, 27], state: "minecraft:deepslate_bricks"},
        {pos: [13, 3, 28], state: "minecraft:deepslate_bricks"},
        {pos: [14, 3, 16], state: "minecraft:deepslate_bricks"},
        {pos: [14, 3, 17], state: "minecraft:deepslate_bricks"},
        {pos: [14, 3, 18], state: "minecraft:pointed_dripstone{thickness:frustum,vertical_direction:up,waterlogged:false}"},
        {pos: [14, 3, 19], state: "minecraft:cave_air"},
        {pos: [14, 3, 20], state: "minecraft:pointed_dripstone{thickness:tip,vertical_direction:up,waterlogged:false}"},
        {pos: [14, 3, 21], state: "minecraft:cave_air"},
        {pos: [14, 3, 22], state: "minecraft:pointed_dripstone{thickness:tip,vertical_direction:up,waterlogged:false}"},
        {pos: [14, 3, 23], state: "minecraft:cave_air"},
        {pos: [14, 3, 24], state: "minecraft:cave_air"},
        {pos: [14, 3, 25], state: "minecraft:cave_air"},
        {pos: [14, 3, 26], state: "minecraft:pointed_dripstone{thickness:tip,vertical_direction:up,waterlogged:false}"},
        {pos: [14, 3, 27], state: "minecraft:deepslate_bricks"},
        {pos: [14, 3, 28], state: "minecraft:deepslate_bricks"},
        {pos: [15, 3, 16], state: "minecraft:deepslate_bricks"},
        {pos: [15, 3, 17], state: "minecraft:cave_air"},
        {pos: [15, 3, 18], state: "minecraft:pointed_dripstone{thickness:tip,vertical_direction:up,waterlogged:false}"},
        {pos: [15, 3, 19], state: "minecraft:cave_air"},
        {pos: [15, 3, 20], state: "minecraft:cave_air"},
        {pos: [15, 3, 21], state: "minecraft:deepslate_bricks"},
        {pos: [15, 3, 22], state: "minecraft:deepslate_bricks"},
        {pos: [15, 3, 23], state: "minecraft:cave_air"},
        {pos: [15, 3, 24], state: "minecraft:pointed_dripstone{thickness:tip,vertical_direction:up,waterlogged:false}"},
        {pos: [15, 3, 25], state: "minecraft:pointed_dripstone{thickness:frustum,vertical_direction:up,waterlogged:false}"},
        {pos: [15, 3, 26], state: "minecraft:cave_air"},
        {pos: [15, 3, 27], state: "minecraft:pointed_dripstone{thickness:frustum,vertical_direction:up,waterlogged:false}"},
        {pos: [15, 3, 28], state: "minecraft:deepslate_bricks"},
        {pos: [16, 3, 16], state: "minecraft:deepslate_bricks"},
        {pos: [16, 3, 17], state: "minecraft:pointed_dripstone{thickness:tip,vertical_direction:up,waterlogged:false}"},
        {pos: [16, 3, 18], state: "minecraft:pointed_dripstone{thickness:tip,vertical_direction:up,waterlogged:false}"},
        {pos: [16, 3, 19], state: "minecraft:pointed_dripstone{thickness:tip,vertical_direction:up,waterlogged:false}"},
        {pos: [16, 3, 20], state: "minecraft:pointed_dripstone{thickness:frustum,vertical_direction:up,waterlogged:false}"},
        {pos: [16, 3, 21], state: "minecraft:deepslate_bricks"},
        {pos: [16, 3, 22], state: "minecraft:pointed_dripstone{thickness:frustum,vertical_direction:up,waterlogged:false}"},
        {pos: [16, 3, 23], state: "minecraft:pointed_dripstone{thickness:tip,vertical_direction:up,waterlogged:false}"},
        {pos: [16, 3, 24], state: "minecraft:deepslate_bricks"},
        {pos: [16, 3, 25], state: "minecraft:deepslate_bricks"},
        {pos: [16, 3, 26], state: "minecraft:pointed_dripstone{thickness:tip,vertical_direction:up,waterlogged:false}"},
        {pos: [16, 3, 27], state: "minecraft:pointed_dripstone{thickness:tip,vertical_direction:up,waterlogged:false}"},
        {pos: [16, 3, 28], state: "minecraft:deepslate_bricks"},
        {pos: [17, 3, 16], state: "minecraft:deepslate_bricks"},
        {pos: [17, 3, 17], state: "minecraft:cave_air"},
        {pos: [17, 3, 18], state: "minecraft:pointed_dripstone{thickness:tip,vertical_direction:up,waterlogged:false}"},
        {pos: [17, 3, 19], state: "minecraft:pointed_dripstone{thickness:tip,vertical_direction:up,waterlogged:false}"},
        {pos: [17, 3, 20], state: "minecraft:pointed_dripstone{thickness:tip,vertical_direction:up,waterlogged:false}"},
        {pos: [17, 3, 21], state: "minecraft:cave_air"},
        {pos: [17, 3, 22], state: "minecraft:pointed_dripstone{thickness:tip,vertical_direction:up,waterlogged:false}"},
        {pos: [17, 3, 23], state: "minecraft:cave_air"},
        {pos: [17, 3, 24], state: "minecraft:deepslate_bricks"},
        {pos: [17, 3, 25], state: "minecraft:deepslate_bricks"},
        {pos: [17, 3, 26], state: "minecraft:pointed_dripstone{thickness:tip,vertical_direction:up,waterlogged:false}"},
        {pos: [17, 3, 27], state: "minecraft:pointed_dripstone{thickness:tip,vertical_direction:up,waterlogged:false}"},
        {pos: [17, 3, 28], state: "minecraft:deepslate_bricks"},
        {pos: [18, 3, 16], state: "minecraft:deepslate_bricks"},
        {pos: [18, 3, 17], state: "minecraft:pointed_dripstone{thickness:tip,vertical_direction:up,waterlogged:false}"},
        {pos: [18, 3, 18], state: "minecraft:cave_air"},
        {pos: [18, 3, 19], state: "minecraft:pointed_dripstone{thickness:tip,vertical_direction:up,waterlogged:false}"},
        {pos: [18, 3, 20], state: "minecraft:cave_air"},
        {pos: [18, 3, 21], state: "minecraft:pointed_dripstone{thickness:frustum,vertical_direction:up,waterlogged:false}"},
        {pos: [18, 3, 22], state: "minecraft:cave_air"},
        {pos: [18, 3, 23], state: "minecraft:pointed_dripstone{thickness:frustum,vertical_direction:up,waterlogged:false}"},
        {pos: [18, 3, 24], state: "minecraft:pointed_dripstone{thickness:tip,vertical_direction:up,waterlogged:false}"},
        {pos: [18, 3, 25], state: "minecraft:pointed_dripstone{thickness:tip,vertical_direction:up,waterlogged:false}"},
        {pos: [18, 3, 26], state: "minecraft:cave_air"},
        {pos: [18, 3, 27], state: "minecraft:pointed_dripstone{thickness:frustum,vertical_direction:up,waterlogged:false}"},
        {pos: [18, 3, 28], state: "minecraft:deepslate_bricks"},
        {pos: [19, 3, 16], state: "minecraft:deepslate_bricks"},
        {pos: [19, 3, 17], state: "minecraft:cave_air"},
        {pos: [19, 3, 18], state: "minecraft:pointed_dripstone{thickness:frustum,vertical_direction:up,waterlogged:false}"},
        {pos: [19, 3, 19], state: "minecraft:cave_air"},
        {pos: [19, 3, 20], state: "minecraft:cave_air"},
        {pos: [19, 3, 21], state: "minecraft:deepslate_bricks"},
        {pos: [19, 3, 22], state: "minecraft:pointed_dripstone{thickness:tip,vertical_direction:up,waterlogged:false}"},
        {pos: [19, 3, 23], state: "minecraft:cave_air"},
        {pos: [19, 3, 24], state: "minecraft:pointed_dripstone{thickness:tip,vertical_direction:up,waterlogged:false}"},
        {pos: [19, 3, 25], state: "minecraft:pointed_dripstone{thickness:tip,vertical_direction:up,waterlogged:false}"},
        {pos: [19, 3, 26], state: "minecraft:pointed_dripstone{thickness:tip,vertical_direction:up,waterlogged:false}"},
        {pos: [19, 3, 27], state: "minecraft:cave_air"},
        {pos: [19, 3, 28], state: "minecraft:deepslate_bricks"},
        {pos: [20, 3, 16], state: "minecraft:deepslate_bricks"},
        {pos: [20, 3, 17], state: "minecraft:pointed_dripstone{thickness:tip,vertical_direction:up,waterlogged:false}"},
        {pos: [20, 3, 18], state: "minecraft:cave_air"},
        {pos: [20, 3, 19], state: "minecraft:pointed_dripstone{thickness:tip,vertical_direction:up,waterlogged:false}"},
        {pos: [20, 3, 20], state: "minecraft:pointed_dripstone{thickness:frustum,vertical_direction:up,waterlogged:false}"},
        {pos: [20, 3, 21], state: "minecraft:deepslate_bricks"},
        {pos: [20, 3, 22], state: "minecraft:deepslate_bricks"},
        {pos: [20, 3, 23], state: "minecraft:pointed_dripstone{thickness:tip,vertical_direction:up,waterlogged:false}"},
        {pos: [20, 3, 24], state: "minecraft:cave_air"},
        {pos: [20, 3, 25], state: "minecraft:pointed_dripstone{thickness:frustum,vertical_direction:up,waterlogged:false}"},
        {pos: [20, 3, 26], state: "minecraft:cave_air"},
