{
    DataVersion: 3953,
    size: [21, 8, 36],
    data: [
        {pos: [0, 0, 5], state: "minecraft:deepslate{axis:y}"},
        {pos: [0, 0, 6], state: "minecraft:deepslate{axis:y}"},
        {pos: [0, 0, 7], state: "minecraft:deepslate{axis:y}"},
        {pos: [0, 0, 8], state: "minecraft:deepslate{axis:y}"},
        {pos: [0, 0, 9], state: "minecraft:deepslate{axis:y}"},
        {pos: [0, 0, 10], state: "minecraft:deepslate{axis:y}"},
        {pos: [0, 0, 11], state: "minecraft:deepslate{axis:y}"},
        {pos: [1, 0, 5], state: "minecraft:deepslate{axis:y}"},
        {pos: [1, 0, 6], state: "minecraft:deepslate{axis:y}"},
        {pos: [1, 0, 7], state: "minecraft:deepslate{axis:y}"},
        {pos: [1, 0, 8], state: "minecraft:deepslate{axis:y}"},
        {pos: [1, 0, 9], state: "minecraft:deepslate{axis:y}"},
        {pos: [1, 0, 10], state: "minecraft:deepslate{axis:y}"},
        {pos: [1, 0, 11], state: "minecraft:deepslate{axis:y}"},
        {pos: [2, 0, 5], state: "minecraft:deepslate{axis:y}"},
        {pos: [2, 0, 6], state: "minecraft:deepslate{axis:y}"},
        {pos: [2, 0, 7], state: "minecraft:deepslate{axis:y}"},
        {pos: [2, 0, 8], state: "minecraft:deepslate{axis:y}"},
        {pos: [2, 0, 9], state: "minecraft:deepslate{axis:y}"},
        {pos: [2, 0, 10], state: "minecraft:deepslate{axis:y}"},
        {pos: [2, 0, 11], state: "minecraft:deepslate{axis:y}"},
        {pos: [2, 0, 12], state: "minecraft:deepslate{axis:y}"},
        {pos: [2, 0, 13], state: "minecraft:deepslate{axis:y}"},
        {pos: [2, 0, 14], state: "minecraft:deepslate{axis:y}"},
        {pos: [3, 0, 5], state: "minecraft:deepslate{axis:y}"},
        {pos: [3, 0, 6], state: "minecraft:deepslate{axis:y}"},
        {pos: [3, 0, 7], state: "minecraft:deepslate{axis:y}"},
        {pos: [3, 0, 8], state: "minecraft:deepslate{axis:y}"},
        {pos: [3, 0, 9], state: "minecraft:deepslate{axis:y}"},
        {pos: [3, 0, 10], state: "minecraft:deepslate{axis:y}"},
        {pos: [3, 0, 11], state: "minecraft:deepslate{axis:y}"},
        {pos: [3, 0, 12], state: "minecraft:deepslate{axis:y}"},
        {pos: [3, 0, 13], state: "minecraft:deepslate{axis:y}"},
        {pos: [3, 0, 14], state: "minecraft:deepslate{axis:y}"},
        {pos: [4, 0, 5], state: "minecraft:deepslate{axis:y}"},
        {pos: [4, 0, 6], state: "minecraft:deepslate{axis:y}"},
        {pos: [4, 0, 7], state: "minecraft:deepslate{axis:y}"},
        {pos: [4, 0, 8], state: "minecraft:deepslate{axis:y}"},
        {pos: [4, 0, 9], state: "minecraft:deepslate{axis:y}"},
        {pos: [4, 0, 10], state: "minecraft:deepslate{axis:y}"},
        {pos: [4, 0, 11], state: "minecraft:deepslate{axis:y}"},
        {pos: [4, 0, 12], state: "minecraft:deepslate{axis:y}"},
        {pos: [4, 0, 13], state: "minecraft:deepslate{axis:y}"},
        {pos: [4, 0, 14], state: "minecraft:deepslate{axis:y}"},
        {pos: [5, 0, 5], state: "minecraft:deepslate{axis:y}"},
        {pos: [5, 0, 6], state: "minecraft:deepslate{axis:y}"},
        {pos: [5, 0, 7], state: "minecraft:deepslate{axis:y}"},
        {pos: [5, 0, 8], state: "minecraft:deepslate{axis:y}"},
        {pos: [5, 0, 9], state: "minecraft:deepslate{axis:y}"},
        {pos: [5, 0, 10], state: "minecraft:deepslate{axis:y}"},
        {pos: [5, 0, 11], state: "minecraft:deepslate{axis:y}"},
        {pos: [5, 0, 12], state: "minecraft:deepslate{axis:y}"},
        {pos: [5, 0, 13], state: "minecraft:deepslate{axis:y}"},
        {pos: [5, 0, 14], state: "minecraft:deepslate{axis:y}"},
        {pos: [6, 0, 5], state: "minecraft:deepslate{axis:y}"},
        {pos: [6, 0, 6], state: "minecraft:deepslate{axis:y}"},
        {pos: [6, 0, 7], state: "minecraft:deepslate{axis:y}"},
        {pos: [6, 0, 8], state: "minecraft:deepslate{axis:y}"},
        {pos: [6, 0, 9], state: "minecraft:deepslate{axis:y}"},
        {pos: [6, 0, 10], state: "minecraft:deepslate{axis:y}"},
        {pos: [6, 0, 11], state: "minecraft:deepslate{axis:y}"},
        {pos: [6, 0, 12], state: "minecraft:deepslate{axis:y}"},
        {pos: [6, 0, 13], state: "minecraft:deepslate{axis:y}"},
        {pos: [6, 0, 14], state: "minecraft:deepslate{axis:y}"},
        {pos: [7, 0, 0], state: "minecraft:deepslate{axis:y}"},
        {pos: [7, 0, 1], state: "minecraft:deepslate{axis:y}"},
        {pos: [7, 0, 2], state: "minecraft:deepslate{axis:y}"},
        {pos: [7, 0, 3], state: "minecraft:deepslate{axis:y}"},
        {pos: [7, 0, 4], state: "minecraft:deepslate{axis:y}"},
        {pos: [7, 0, 5], state: "minecraft:deepslate{axis:y}"},
        {pos: [7, 0, 6], state: "minecraft:deepslate{axis:y}"},
        {pos: [7, 0, 7], state: "minecraft:deepslate{axis:y}"},
        {pos: [7, 0, 8], state: "minecraft:deepslate{axis:y}"},
        {pos: [7, 0, 9], state: "minecraft:deepslate{axis:y}"},
        {pos: [7, 0, 10], state: "minecraft:deepslate{axis:y}"},
        {pos: [7, 0, 11], state: "minecraft:deepslate{axis:y}"},
        {pos: [7, 0, 12], state: "minecraft:deepslate{axis:y}"},
        {pos: [7, 0, 13], state: "minecraft:deepslate{axis:y}"},
        {pos: [7, 0, 14], state: "minecraft:deepslate{axis:y}"},
        {pos: [7, 0, 15], state: "minecraft:deepslate{axis:y}"},
        {pos: [7, 0, 16], state: "minecraft:deepslate{axis:y}"},
        {pos: [8, 0, 0], state: "minecraft:deepslate{axis:y}"},
        {pos: [8, 0, 1], state: "minecraft:deepslate{axis:y}"},
        {pos: [8, 0, 2], state: "minecraft:deepslate{axis:y}"},
        {pos: [8, 0, 3], state: "minecraft:deepslate{axis:y}"},
        {pos: [8, 0, 4], state: "minecraft:deepslate{axis:y}"},
        {pos: [8, 0, 5], state: "minecraft:deepslate{axis:y}"},
        {pos: [8, 0, 6], state: "minecraft:deepslate{axis:y}"},
        {pos: [8, 0, 7], state: "minecraft:deepslate{axis:y}"},
        {pos: [8, 0, 8], state: "minecraft:deepslate{axis:y}"},
        {pos: [8, 0, 9], state: "minecraft:deepslate{axis:y}"},
        {pos: [8, 0, 10], state: "minecraft:deepslate{axis:y}"},
        {pos: [8, 0, 11], state: "minecraft:deepslate{axis:y}"},
        {pos: [8, 0, 12], state: "minecraft:deepslate{axis:y}"},
        {pos: [8, 0, 13], state: "minecraft:deepslate{axis:y}"},
        {pos: [8, 0, 14], state: "minecraft:deepslate{axis:y}"},
        {pos: [8, 0, 15], state: "minecraft:deepslate{axis:y}"},
        {pos: [8, 0, 16], state: "minecraft:deepslate{axis:y}"},
        {pos: [8, 0, 17], state: "minecraft:deepslate{axis:y}"},
        {pos: [8, 0, 18], state: "minecraft:deepslate{axis:y}"},
        {pos: [8, 0, 19], state: "minecraft:deepslate{axis:y}"},
        {pos: [8, 0, 20], state: "minecraft:deepslate{axis:y}"},
        {pos: [8, 0, 21], state: "minecraft:deepslate{axis:y}"},
        {pos: [8, 0, 22], state: "minecraft:deepslate{axis:y}"},
        {pos: [8, 0, 23], state: "minecraft:deepslate{axis:y}"},
        {pos: [8, 0, 24], state: "minecraft:deepslate{axis:y}"},
        {pos: [8, 0, 25], state: "minecraft:deepslate{axis:y}"},
        {pos: [8, 0, 26], state: "minecraft:deepslate{axis:y}"},
        {pos: [8, 0, 27], state: "minecraft:deepslate{axis:y}"},
        {pos: [8, 0, 28], state: "minecraft:deepslate{axis:y}"},
        {pos: [8, 0, 29], state: "minecraft:deepslate{axis:y}"},
        {pos: [8, 0, 30], state: "minecraft:deepslate{axis:y}"},
        {pos: [8, 0, 31], state: "minecraft:deepslate{axis:y}"},
        {pos: [8, 0, 32], state: "minecraft:deepslate{axis:y}"},
        {pos: [8, 0, 33], state: "minecraft:deepslate{axis:y}"},
        {pos: [8, 0, 34], state: "minecraft:deepslate{axis:y}"},
        {pos: [8, 0, 35], state: "minecraft:deepslate{axis:y}"},
        {pos: [9, 0, 0], state: "minecraft:deepslate{axis:y}"},
        {pos: [9, 0, 1], state: "minecraft:deepslate{axis:y}"},
        {pos: [9, 0, 2], state: "minecraft:deepslate{axis:y}"},
        {pos: [9, 0, 3], state: "minecraft:deepslate{axis:y}"},
        {pos: [9, 0, 4], state: "minecraft:deepslate{axis:y}"},
        {pos: [9, 0, 5], state: "minecraft:deepslate{axis:y}"},
        {pos: [9, 0, 6], state: "minecraft:deepslate{axis:y}"},
        {pos: [9, 0, 7], state: "minecraft:deepslate{axis:y}"},
        {pos: [9, 0, 8], state: "minecraft:deepslate{axis:y}"},
        {pos: [9, 0, 9], state: "minecraft:deepslate{axis:y}"},
        {pos: [9, 0, 10], state: "minecraft:deepslate{axis:y}"},
        {pos: [9, 0, 11], state: "minecraft:deepslate{axis:y}"},
        {pos: [9, 0, 12], state: "minecraft:deepslate{axis:y}"},
        {pos: [9, 0, 13], state: "minecraft:deepslate{axis:y}"},
        {pos: [9, 0, 14], state: "minecraft:deepslate{axis:y}"},
        {pos: [9, 0, 15], state: "minecraft:deepslate{axis:y}"},
        {pos: [9, 0, 16], state: "minecraft:deepslate{axis:y}"},
        {pos: [9, 0, 17], state: "minecraft:deepslate{axis:y}"},
        {pos: [9, 0, 18], state: "minecraft:deepslate{axis:y}"},
        {pos: [9, 0, 19], state: "minecraft:deepslate{axis:y}"},
        {pos: [9, 0, 20], state: "minecraft:deepslate{axis:y}"},
        {pos: [9, 0, 21], state: "minecraft:deepslate{axis:y}"},
        {pos: [9, 0, 22], state: "minecraft:deepslate{axis:y}"},
        {pos: [9, 0, 23], state: "minecraft:deepslate{axis:y}"},
        {pos: [9, 0, 24], state: "minecraft:deepslate{axis:y}"},
        {pos: [9, 0, 25], state: "minecraft:deepslate{axis:y}"},
        {pos: [9, 0, 26], state: "minecraft:deepslate{axis:y}"},
        {pos: [9, 0, 27], state: "minecraft:deepslate{axis:y}"},
        {pos: [9, 0, 28], state: "minecraft:deepslate{axis:y}"},
        {pos: [9, 0, 29], state: "minecraft:deepslate{axis:y}"},
        {pos: [9, 0, 30], state: "minecraft:deepslate{axis:y}"},
        {pos: [9, 0, 31], state: "minecraft:deepslate{axis:y}"},
        {pos: [9, 0, 32], state: "minecraft:deepslate{axis:y}"},
        {pos: [9, 0, 33], state: "minecraft:deepslate{axis:y}"},
        {pos: [9, 0, 34], state: "minecraft:deepslate{axis:y}"},
        {pos: [9, 0, 35], state: "minecraft:deepslate{axis:y}"},
        {pos: [10, 0, 0], state: "minecraft:deepslate{axis:y}"},
        {pos: [10, 0, 1], state: "minecraft:deepslate{axis:y}"},
        {pos: [10, 0, 2], state: "minecraft:deepslate{axis:y}"},
        {pos: [10, 0, 3], state: "minecraft:deepslate{axis:y}"},
        {pos: [10, 0, 4], state: "minecraft:deepslate{axis:y}"},
        {pos: [10, 0, 5], state: "minecraft:deepslate{axis:y}"},
        {pos: [10, 0, 6], state: "minecraft:deepslate{axis:y}"},
        {pos: [10, 0, 7], state: "minecraft:deepslate{axis:y}"},
        {pos: [10, 0, 8], state: "minecraft:deepslate{axis:y}"},
        {pos: [10, 0, 9], state: "minecraft:deepslate{axis:y}"},
        {pos: [10, 0, 10], state: "minecraft:deepslate{axis:y}"},
        {pos: [10, 0, 11], state: "minecraft:deepslate{axis:y}"},
        {pos: [10, 0, 12], state: "minecraft:deepslate{axis:y}"},
        {pos: [10, 0, 13], state: "minecraft:deepslate{axis:y}"},
        {pos: [10, 0, 14], state: "minecraft:deepslate{axis:y}"},
        {pos: [10, 0, 15], state: "minecraft:deepslate{axis:y}"},
        {pos: [10, 0, 16], state: "minecraft:deepslate{axis:y}"},
        {pos: [10, 0, 17], state: "minecraft:deepslate{axis:y}"},
        {pos: [10, 0, 18], state: "minecraft:deepslate{axis:y}"},
        {pos: [10, 0, 19], state: "minecraft:deepslate{axis:y}"},
        {pos: [10, 0, 20], state: "minecraft:deepslate{axis:y}"},
        {pos: [10, 0, 21], state: "minecraft:deepslate{axis:y}"},
        {pos: [10, 0, 22], state: "minecraft:deepslate{axis:y}"},
        {pos: [10, 0, 23], state: "minecraft:deepslate{axis:y}"},
        {pos: [10, 0, 24], state: "minecraft:deepslate{axis:y}"},
        {pos: [10, 0, 25], state: "minecraft:deepslate{axis:y}"},
        {pos: [10, 0, 26], state: "minecraft:deepslate{axis:y}"},
        {pos: [10, 0, 27], state: "minecraft:deepslate{axis:y}"},
        {pos: [10, 0, 28], state: "minecraft:deepslate{axis:y}"},
        {pos: [10, 0, 29], state: "minecraft:deepslate{axis:y}"},
        {pos: [10, 0, 30], state: "minecraft:deepslate{axis:y}"},
        {pos: [10, 0, 31], state: "minecraft:deepslate{axis:y}"},
        {pos: [10, 0, 32], state: "minecraft:deepslate{axis:y}"},
        {pos: [10, 0, 33], state: "minecraft:deepslate{axis:y}"},
        {pos: [10, 0, 34], state: "minecraft:deepslate{axis:y}"},
        {pos: [10, 0, 35], state: "minecraft:deepslate{axis:y}"},
        {pos: [11, 0, 0], state: "minecraft:deepslate{axis:y}"},
        {pos: [11, 0, 1], state: "minecraft:deepslate{axis:y}"},
        {pos: [11, 0, 2], state: "minecraft:deepslate{axis:y}"},
        {pos: [11, 0, 3], state: "minecraft:deepslate{axis:y}"},
        {pos: [11, 0, 4], state: "minecraft:deepslate{axis:y}"},
        {pos: [11, 0, 5], state: "minecraft:deepslate{axis:y}"},
        {pos: [11, 0, 6], state: "minecraft:deepslate{axis:y}"},
        {pos: [11, 0, 7], state: "minecraft:deepslate{axis:y}"},
        {pos: [11, 0, 8], state: "minecraft:deepslate{axis:y}"},
        {pos: [11, 0, 9], state: "minecraft:deepslate{axis:y}"},
        {pos: [11, 0, 10], state: "minecraft:deepslate{axis:y}"},
        {pos: [11, 0, 11], state: "minecraft:deepslate{axis:y}"},
        {pos: [11, 0, 12], state: "minecraft:deepslate{axis:y}"},
        {pos: [11, 0, 13], state: "minecraft:deepslate{axis:y}"},
        {pos: [11, 0, 14], state: "minecraft:deepslate{axis:y}"},
        {pos: [11, 0, 15], state: "minecraft:deepslate{axis:y}"},
        {pos: [11, 0, 16], state: "minecraft:deepslate{axis:y}"},
        {pos: [11, 0, 17], state: "minecraft:deepslate{axis:y}"},
        {pos: [11, 0, 18], state: "minecraft:deepslate{axis:y}"},
        {pos: [11, 0, 19], state: "minecraft:deepslate{axis:y}"},
        {pos: [11, 0, 20], state: "minecraft:deepslate{axis:y}"},
        {pos: [11, 0, 21], state: "minecraft:deepslate{axis:y}"},
        {pos: [11, 0, 22], state: "minecraft:deepslate{axis:y}"},
        {pos: [11, 0, 23], state: "minecraft:deepslate{axis:y}"},
        {pos: [11, 0, 24], state: "minecraft:deepslate{axis:y}"},
        {pos: [11, 0, 25], state: "minecraft:deepslate{axis:y}"},
        {pos: [11, 0, 26], state: "minecraft:deepslate{axis:y}"},
        {pos: [11, 0, 27], state: "minecraft:deepslate{axis:y}"},
        {pos: [11, 0, 28], state: "minecraft:deepslate{axis:y}"},
        {pos: [11, 0, 29], state: "minecraft:deepslate{axis:y}"},
        {pos: [11, 0, 30], state: "minecraft:deepslate{axis:y}"},
        {pos: [11, 0, 31], state: "minecraft:deepslate{axis:y}"},
        {pos: [11, 0, 32], state: "minecraft:deepslate{axis:y}"},
        {pos: [11, 0, 33], state: "minecraft:deepslate{axis:y}"},
        {pos: [11, 0, 34], state: "minecraft:deepslate{axis:y}"},
        {pos: [11, 0, 35], state: "minecraft:deepslate{axis:y}"},
        {pos: [12, 0, 0], state: "minecraft:deepslate{axis:y}"},
        {pos: [12, 0, 1], state: "minecraft:deepslate{axis:y}"},
        {pos: [12, 0, 2], state: "minecraft:deepslate{axis:y}"},
        {pos: [12, 0, 3], state: "minecraft:deepslate{axis:y}"},
        {pos: [12, 0, 4], state: "minecraft:deepslate{axis:y}"},
        {pos: [12, 0, 5], state: "minecraft:deepslate{axis:y}"},
        {pos: [12, 0, 6], state: "minecraft:deepslate{axis:y}"},
        {pos: [12, 0, 7], state: "minecraft:deepslate{axis:y}"},
        {pos: [12, 0, 8], state: "minecraft:deepslate{axis:y}"},
        {pos: [12, 0, 9], state: "minecraft:deepslate{axis:y}"},
        {pos: [12, 0, 10], state: "minecraft:deepslate{axis:y}"},
        {pos: [12, 0, 11], state: "minecraft:deepslate{axis:y}"},
        {pos: [12, 0, 12], state: "minecraft:deepslate{axis:y}"},
        {pos: [12, 0, 13], state: "minecraft:deepslate{axis:y}"},
        {pos: [12, 0, 14], state: "minecraft:deepslate{axis:y}"},
        {pos: [12, 0, 15], state: "minecraft:deepslate{axis:y}"},
        {pos: [12, 0, 16], state: "minecraft:deepslate{axis:y}"},
        {pos: [12, 0, 17], state: "minecraft:deepslate{axis:y}"},
        {pos: [12, 0, 18], state: "minecraft:deepslate{axis:y}"},
        {pos: [12, 0, 19], state: "minecraft:deepslate{axis:y}"},
        {pos: [12, 0, 20], state: "minecraft:deepslate{axis:y}"},
        {pos: [12, 0, 21], state: "minecraft:deepslate{axis:y}"},
        {pos: [12, 0, 22], state: "minecraft:deepslate{axis:y}"},
        {pos: [12, 0, 23], state: "minecraft:deepslate{axis:y}"},
        {pos: [12, 0, 24], state: "minecraft:deepslate{axis:y}"},
        {pos: [12, 0, 25], state: "minecraft:deepslate{axis:y}"},
        {pos: [12, 0, 26], state: "minecraft:deepslate{axis:y}"},
        {pos: [12, 0, 27], state: "minecraft:deepslate{axis:y}"},
        {pos: [12, 0, 28], state: "minecraft:deepslate{axis:y}"},
        {pos: [12, 0, 29], state: "minecraft:deepslate{axis:y}"},
        {pos: [12, 0, 30], state: "minecraft:deepslate{axis:y}"},
        {pos: [12, 0, 31], state: "minecraft:deepslate{axis:y}"},
        {pos: [12, 0, 32], state: "minecraft:deepslate{axis:y}"},
        {pos: [12, 0, 33], state: "minecraft:deepslate{axis:y}"},
        {pos: [12, 0, 34], state: "minecraft:deepslate{axis:y}"},
        {pos: [12, 0, 35], state: "minecraft:deepslate{axis:y}"},
        {pos: [13, 0, 0], state: "minecraft:deepslate{axis:y}"},
        {pos: [13, 0, 1], state: "minecraft:deepslate{axis:y}"},
        {pos: [13, 0, 2], state: "minecraft:deepslate{axis:y}"},
        {pos: [13, 0, 3], state: "minecraft:deepslate{axis:y}"},
        {pos: [13, 0, 4], state: "minecraft:deepslate{axis:y}"},
        {pos: [13, 0, 5], state: "minecraft:deepslate{axis:y}"},
        {pos: [13, 0, 6], state: "minecraft:deepslate{axis:y}"},
        {pos: [13, 0, 7], state: "minecraft:deepslate{axis:y}"},
        {pos: [13, 0, 8], state: "minecraft:deepslate{axis:y}"},
        {pos: [13, 0, 9], state: "minecraft:deepslate{axis:y}"},
        {pos: [13, 0, 10], state: "minecraft:deepslate{axis:y}"},
        {pos: [13, 0, 11], state: "minecraft:deepslate{axis:y}"},
        {pos: [13, 0, 12], state: "minecraft:deepslate{axis:y}"},
        {pos: [13, 0, 13], state: "minecraft:deepslate{axis:y}"},
        {pos: [13, 0, 14], state: "minecraft:deepslate{axis:y}"},
        {pos: [13, 0, 15], state: "minecraft:deepslate{axis:y}"},
        {pos: [13, 0, 16], state: "minecraft:deepslate{axis:y}"},
        {pos: [13, 0, 17], state: "minecraft:deepslate{axis:y}"},
        {pos: [13, 0, 18], state: "minecraft:deepslate{axis:y}"},
        {pos: [13, 0, 19], state: "minecraft:deepslate{axis:y}"},
        {pos: [13, 0, 20], state: "minecraft:deepslate{axis:y}"},
        {pos: [13, 0, 21], state: "minecraft:deepslate{axis:y}"},
        {pos: [13, 0, 22], state: "minecraft:deepslate{axis:y}"},
        {pos: [13, 0, 23], state: "minecraft:deepslate{axis:y}"},
        {pos: [13, 0, 24], state: "minecraft:deepslate{axis:y}"},
        {pos: [13, 0, 25], state: "minecraft:deepslate{axis:y}"},
        {pos: [13, 0, 26], state: "minecraft:deepslate{axis:y}"},
        {pos: [13, 0, 27], state: "minecraft:deepslate{axis:y}"},
        {pos: [13, 0, 28], state: "minecraft:deepslate{axis:y}"},
        {pos: [13, 0, 29], state: "minecraft:deepslate{axis:y}"},
        {pos: [13, 0, 30], state: "minecraft:deepslate{axis:y}"},
        {pos: [13, 0, 31], state: "minecraft:deepslate{axis:y}"},
        {pos: [13, 0, 32], state: "minecraft:deepslate{axis:y}"},
        {pos: [13, 0, 33], state: "minecraft:deepslate{axis:y}"},
        {pos: [13, 0, 34], state: "minecraft:deepslate{axis:y}"},
        {pos: [13, 0, 35], state: "minecraft:deepslate{axis:y}"},
        {pos: [14, 0, 0], state: "minecraft:deepslate{axis:y}"},
        {pos: [14, 0, 1], state: "minecraft:deepslate{axis:y}"},
        {pos: [14, 0, 2], state: "minecraft:deepslate{axis:y}"},
        {pos: [14, 0, 3], state: "minecraft:deepslate{axis:y}"},
        {pos: [14, 0, 4], state: "minecraft:deepslate{axis:y}"},
        {pos: [14, 0, 5], state: "minecraft:deepslate{axis:y}"},
        {pos: [14, 0, 6], state: "minecraft:deepslate{axis:y}"},
        {pos: [14, 0, 7], state: "minecraft:deepslate{axis:y}"},
        {pos: [14, 0, 8], state: "minecraft:deepslate{axis:y}"},
        {pos: [14, 0, 9], state: "minecraft:deepslate{axis:y}"},
        {pos: [14, 0, 10], state: "minecraft:deepslate{axis:y}"},
        {pos: [14, 0, 11], state: "minecraft:deepslate{axis:y}"},
        {pos: [14, 0, 12], state: "minecraft:deepslate{axis:y}"},
        {pos: [14, 0, 13], state: "minecraft:deepslate{axis:y}"},
        {pos: [14, 0, 14], state: "minecraft:deepslate{axis:y}"},
        {pos: [14, 0, 15], state: "minecraft:deepslate{axis:y}"},
        {pos: [14, 0, 16], state: "minecraft:deepslate{axis:y}"},
        {pos: [14, 0, 17], state: "minecraft:deepslate{axis:y}"},
        {pos: [14, 0, 18], state: "minecraft:deepslate{axis:y}"},
        {pos: [14, 0, 19], state: "minecraft:deepslate{axis:y}"},
        {pos: [14, 0, 20], state: "minecraft:deepslate{axis:y}"},
        {pos: [14, 0, 21], state: "minecraft:deepslate{axis:y}"},
        {pos: [14, 0, 22], state: "minecraft:deepslate{axis:y}"},
        {pos: [14, 0, 23], state: "minecraft:deepslate{axis:y}"},
        {pos: [14, 0, 24], state: "minecraft:deepslate{axis:y}"},
        {pos: [14, 0, 25], state: "minecraft:deepslate{axis:y}"},
        {pos: [14, 0, 26], state: "minecraft:deepslate{axis:y}"},
        {pos: [14, 0, 27], state: "minecraft:deepslate{axis:y}"},
        {pos: [14, 0, 28], state: "minecraft:deepslate{axis:y}"},
        {pos: [14, 0, 29], state: "minecraft:deepslate{axis:y}"},
        {pos: [14, 0, 30], state: "minecraft:deepslate{axis:y}"},
        {pos: [14, 0, 31], state: "minecraft:deepslate{axis:y}"},
        {pos: [14, 0, 32], state: "minecraft:deepslate{axis:y}"},
        {pos: [14, 0, 33], state: "minecraft:deepslate{axis:y}"},
        {pos: [14, 0, 34], state: "minecraft:deepslate{axis:y}"},
        {pos: [14, 0, 35], state: "minecraft:deepslate{axis:y}"},
        {pos: [15, 0, 2], state: "minecraft:deepslate{axis:y}"},
        {pos: [15, 0, 3], state: "minecraft:deepslate{axis:y}"},
        {pos: [15, 0, 4], state: "minecraft:deepslate{axis:y}"},
        {pos: [15, 0, 5], state: "minecraft:deepslate{axis:y}"},
        {pos: [15, 0, 6], state: "minecraft:deepslate{axis:y}"},
        {pos: [15, 0, 7], state: "minecraft:deepslate{axis:y}"},
        {pos: [15, 0, 8], state: "minecraft:deepslate{axis:y}"},
        {pos: [15, 0, 9], state: "minecraft:deepslate{axis:y}"},
        {pos: [15, 0, 10], state: "minecraft:deepslate{axis:y}"},
        {pos: [15, 0, 11], state: "minecraft:deepslate{axis:y}"},
        {pos: [15, 0, 12], state: "minecraft:deepslate{axis:y}"},
        {pos: [15, 0, 13], state: "minecraft:deepslate{axis:y}"},
        {pos: [15, 0, 14], state: "minecraft:deepslate{axis:y}"},
        {pos: [15, 0, 15], state: "minecraft:deepslate{axis:y}"},
        {pos: [15, 0, 16], state: "minecraft:deepslate{axis:y}"},
        {pos: [15, 0, 17], state: "minecraft:deepslate{axis:y}"},
        {pos: [15, 0, 18], state: "minecraft:deepslate{axis:y}"},
        {pos: [15, 0, 19], state: "minecraft:deepslate{axis:y}"},
        {pos: [15, 0, 20], state: "minecraft:deepslate{axis:y}"},
        {pos: [15, 0, 21], state: "minecraft:deepslate{axis:y}"},
        {pos: [15, 0, 22], state: "minecraft:deepslate{axis:y}"},
        {pos: [15, 0, 23], state: "minecraft:deepslate{axis:y}"},
        {pos: [15, 0, 24], state: "minecraft:deepslate{axis:y}"},
        {pos: [15, 0, 25], state: "minecraft:deepslate{axis:y}"},
        {pos: [15, 0, 26], state: "minecraft:deepslate{axis:y}"},
        {pos: [15, 0, 27], state: "minecraft:deepslate{axis:y}"},
        {pos: [15, 0, 28], state: "minecraft:deepslate{axis:y}"},
        {pos: [15, 0, 29], state: "minecraft:deepslate{axis:y}"},
        {pos: [15, 0, 30], state: "minecraft:deepslate{axis:y}"},
        {pos: [15, 0, 31], state: "minecraft:deepslate{axis:y}"},
        {pos: [15, 0, 32], state: "minecraft:deepslate{axis:y}"},
        {pos: [15, 0, 33], state: "minecraft:deepslate{axis:y}"},
        {pos: [15, 0, 34], state: "minecraft:deepslate{axis:y}"},
        {pos: [15, 0, 35], state: "minecraft:deepslate{axis:y}"},
        {pos: [16, 0, 4], state: "minecraft:deepslate{axis:y}"},
        {pos: [16, 0, 5], state: "minecraft:deepslate{axis:y}"},
        {pos: [16, 0, 6], state: "minecraft:deepslate{axis:y}"},
        {pos: [16, 0, 7], state: "minecraft:deepslate{axis:y}"},
        {pos: [16, 0, 8], state: "minecraft:deepslate{axis:y}"},
        {pos: [16, 0, 9], state: "minecraft:deepslate{axis:y}"},
        {pos: [16, 0, 10], state: "minecraft:deepslate{axis:y}"},
        {pos: [16, 0, 11], state: "minecraft:deepslate{axis:y}"},
        {pos: [16, 0, 12], state: "minecraft:deepslate{axis:y}"},
        {pos: [16, 0, 13], state: "minecraft:deepslate{axis:y}"},
        {pos: [16, 0, 14], state: "minecraft:deepslate{axis:y}"},
        {pos: [16, 0, 15], state: "minecraft:deepslate{axis:y}"},
        {pos: [16, 0, 16], state: "minecraft:deepslate{axis:y}"},
        {pos: [16, 0, 17], state: "minecraft:deepslate{axis:y}"},
        {pos: [16, 0, 18], state: "minecraft:deepslate{axis:y}"},
        {pos: [16, 0, 19], state: "minecraft:deepslate{axis:y}"},
        {pos: [16, 0, 20], state: "minecraft:deepslate{axis:y}"},
        {pos: [16, 0, 21], state: "minecraft:deepslate{axis:y}"},
        {pos: [16, 0, 22], state: "minecraft:deepslate{axis:y}"},
        {pos: [16, 0, 23], state: "minecraft:deepslate{axis:y}"},
        {pos: [16, 0, 24], state: "minecraft:deepslate{axis:y}"},
        {pos: [16, 0, 25], state: "minecraft:deepslate{axis:y}"},
        {pos: [16, 0, 26], state: "minecraft:deepslate{axis:y}"},
        {pos: [16, 0, 27], state: "minecraft:deepslate{axis:y}"},
        {pos: [16, 0, 28], state: "minecraft:deepslate{axis:y}"},
        {pos: [16, 0, 29], state: "minecraft:deepslate{axis:y}"},
        {pos: [16, 0, 30], state: "minecraft:deepslate{axis:y}"},
        {pos: [16, 0, 31], state: "minecraft:deepslate{axis:y}"},
        {pos: [16, 0, 32], state: "minecraft:deepslate{axis:y}"},
        {pos: [16, 0, 33], state: "minecraft:deepslate{axis:y}"},
        {pos: [16, 0, 34], state: "minecraft:deepslate{axis:y}"},
        {pos: [16, 0, 35], state: "minecraft:deepslate{axis:y}"},
        {pos: [17, 0, 4], state: "minecraft:deepslate{axis:y}"},
        {pos: [17, 0, 5], state: "minecraft:deepslate{axis:y}"},
        {pos: [17, 0, 6], state: "minecraft:deepslate{axis:y}"},
        {pos: [17, 0, 7], state: "minecraft:deepslate{axis:y}"},
        {pos: [17, 0, 8], state: "minecraft:deepslate{axis:y}"},
        {pos: [17, 0, 9], state: "minecraft:deepslate{axis:y}"},
        {pos: [17, 0, 10], state: "minecraft:deepslate{axis:y}"},
        {pos: [17, 0, 11], state: "minecraft:deepslate{axis:y}"},
        {pos: [17, 0, 12], state: "minecraft:deepslate{axis:y}"},
        {pos: [17, 0, 13], state: "minecraft:deepslate{axis:y}"},
        {pos: [17, 0, 14], state: "minecraft:deepslate{axis:y}"},
        {pos: [17, 0, 17], state: "minecraft:deepslate{axis:y}"},
        {pos: [17, 0, 18], state: "minecraft:deepslate{axis:y}"},
        {pos: [17, 0, 19], state: "minecraft:deepslate{axis:y}"},
        {pos: [17, 0, 20], state: "minecraft:deepslate{axis:y}"},
        {pos: [17, 0, 21], state: "minecraft:deepslate{axis:y}"},
        {pos: [17, 0, 22], state: "minecraft:deepslate{axis:y}"},
        {pos: [17, 0, 23], state: "minecraft:deepslate{axis:y}"},
        {pos: [17, 0, 24], state: "minecraft:deepslate{axis:y}"},
        {pos: [17, 0, 25], state: "minecraft:deepslate{axis:y}"},
        {pos: [17, 0, 26], state: "minecraft:deepslate{axis:y}"},
        {pos: [17, 0, 27], state: "minecraft:deepslate{axis:y}"},
        {pos: [17, 0, 28], state: "minecraft:deepslate{axis:y}"},
        {pos: [17, 0, 29], state: "minecraft:deepslate{axis:y}"},
        {pos: [17, 0, 30], state: "minecraft:deepslate{axis:y}"},
        {pos: [17, 0, 31], state: "minecraft:deepslate{axis:y}"},
        {pos: [17, 0, 32], state: "minecraft:deepslate{axis:y}"},
        {pos: [17, 0, 33], state: "minecraft:deepslate{axis:y}"},
        {pos: [17, 0, 34], state: "minecraft:deepslate{axis:y}"},
        {pos: [17, 0, 35], state: "minecraft:deepslate{axis:y}"},
        {pos: [18, 0, 4], state: "minecraft:deepslate{axis:y}"},
        {pos: [18, 0, 5], state: "minecraft:deepslate{axis:y}"},
        {pos: [18, 0, 6], state: "minecraft:deepslate{axis:y}"},
        {pos: [18, 0, 7], state: "minecraft:deepslate{axis:y}"},
        {pos: [18, 0, 8], state: "minecraft:deepslate{axis:y}"},
        {pos: [18, 0, 9], state: "minecraft:deepslate{axis:y}"},
        {pos: [18, 0, 10], state: "minecraft:deepslate{axis:y}"},
        {pos: [18, 0, 11], state: "minecraft:deepslate{axis:y}"},
        {pos: [18, 0, 12], state: "minecraft:deepslate{axis:y}"},
        {pos: [18, 0, 13], state: "minecraft:deepslate{axis:y}"},
        {pos: [18, 0, 14], state: "minecraft:deepslate{axis:y}"},
        {pos: [18, 0, 17], state: "minecraft:deepslate{axis:y}"},
        {pos: [18, 0, 18], state: "minecraft:deepslate{axis:y}"},
        {pos: [18, 0, 19], state: "minecraft:deepslate{axis:y}"},
        {pos: [18, 0, 20], state: "minecraft:deepslate{axis:y}"},
        {pos: [18, 0, 21], state: "minecraft:deepslate{axis:y}"},
        {pos: [18, 0, 22], state: "minecraft:deepslate{axis:y}"},
        {pos: [18, 0, 23], state: "minecraft:deepslate{axis:y}"},
        {pos: [18, 0, 24], state: "minecraft:deepslate{axis:y}"},
        {pos: [18, 0, 25], state: "minecraft:deepslate{axis:y}"},
        {pos: [18, 0, 26], state: "minecraft:deepslate{axis:y}"},
        {pos: [18, 0, 27], state: "minecraft:deepslate{axis:y}"},
        {pos: [18, 0, 28], state: "minecraft:deepslate{axis:y}"},
        {pos: [18, 0, 29], state: "minecraft:deepslate{axis:y}"},
        {pos: [18, 0, 30], state: "minecraft:deepslate{axis:y}"},
        {pos: [18, 0, 31], state: "minecraft:deepslate{axis:y}"},
        {pos: [18, 0, 32], state: "minecraft:deepslate{axis:y}"},
        {pos: [18, 0, 33], state: "minecraft:deepslate{axis:y}"},
        {pos: [18, 0, 34], state: "minecraft:deepslate{axis:y}"},
        {pos: [18, 0, 35], state: "minecraft:deepslate{axis:y}"},
        {pos: [19, 0, 4], state: "minecraft:deepslate{axis:y}"},
        {pos: [19, 0, 5], state: "minecraft:deepslate{axis:y}"},
        {pos: [19, 0, 6], state: "minecraft:deepslate{axis:y}"},
        {pos: [19, 0, 7], state: "minecraft:deepslate{axis:y}"},
        {pos: [19, 0, 8], state: "minecraft:deepslate{axis:y}"},
        {pos: [19, 0, 9], state: "minecraft:deepslate{axis:y}"},
        {pos: [19, 0, 10], state: "minecraft:deepslate{axis:y}"},
        {pos: [19, 0, 11], state: "minecraft:deepslate{axis:y}"},
        {pos: [19, 0, 12], state: "minecraft:deepslate{axis:y}"},
        {pos: [20, 0, 4], state: "minecraft:deepslate{axis:y}"},
        {pos: [20, 0, 5], state: "minecraft:deepslate{axis:y}"},
        {pos: [20, 0, 6], state: "minecraft:deepslate{axis:y}"},
        {pos: [20, 0, 7], state: "minecraft:deepslate{axis:y}"},
        {pos: [20, 0, 8], state: "minecraft:deepslate{axis:y}"},
        {pos: [20, 0, 9], state: "minecraft:deepslate{axis:y}"},
        {pos: [20, 0, 10], state: "minecraft:deepslate{axis:y}"},
        {pos: [20, 0, 11], state: "minecraft:deepslate{axis:y}"},
        {pos: [20, 0, 12], state: "minecraft:deepslate{axis:y}"},
        {pos: [0, 1, 5], state: "minecraft:deepslate_bricks"},
        {pos: [0, 1, 6], state: "minecraft:deepslate_bricks"},
        {pos: [0, 1, 7], state: "minecraft:gravel"},
        {pos: [0, 1, 8], state: "minecraft:gravel"},
        {pos: [0, 1, 9], state: "minecraft:gravel"},
        {pos: [0, 1, 10], state: "minecraft:deepslate_bricks"},
        {pos: [0, 1, 11], state: "minecraft:deepslate_bricks"},
        {pos: [1, 1, 5], state: "minecraft:deepslate_bricks"},
        {pos: [1, 1, 6], state: "minecraft:gravel"},
        {pos: [1, 1, 7], state: "minecraft:gravel"},
        {pos: [1, 1, 8], state: "minecraft:gravel"},
        {pos: [1, 1, 9], state: "minecraft:gravel"},
        {pos: [1, 1, 10], state: "minecraft:gravel"},
        {pos: [1, 1, 11], state: "minecraft:deepslate_bricks"},
        {pos: [2, 1, 5], state: "minecraft:deepslate_bricks"},
        {pos: [2, 1, 6], state: "minecraft:deepslate_bricks"},
        {pos: [2, 1, 7], state: "minecraft:gravel"},
        {pos: [2, 1, 8], state: "minecraft:gravel"},
        {pos: [2, 1, 9], state: "minecraft:gravel"},
        {pos: [2, 1, 10], state: "minecraft:deepslate_bricks"},
        {pos: [2, 1, 11], state: "minecraft:gravel"},
        {pos: [2, 1, 12], state: "minecraft:deepslate_bricks"},
        {pos: [2, 1, 13], state: "minecraft:deepslate_bricks"},
        {pos: [2, 1, 14], state: "minecraft:deepslate_bricks"},
        {pos: [3, 1, 5], state: "minecraft:deepslate_bricks"},
        {pos: [3, 1, 6], state: "minecraft:gravel"},
        {pos: [3, 1, 7], state: "minecraft:gravel"},
        {pos: [3, 1, 8], state: "minecraft:gravel"},
        {pos: [3, 1, 9], state: "minecraft:gravel"},
        {pos: [3, 1, 10], state: "minecraft:gravel"},
        {pos: [3, 1, 11], state: "minecraft:gravel"},
        {pos: [3, 1, 12], state: "minecraft:gravel"},
        {pos: [3, 1, 13], state: "minecraft:gravel"},
        {pos: [3, 1, 14], state: "minecraft:deepslate_bricks"},
        {pos: [4, 1, 5], state: "minecraft:deepslate_bricks"},
        {pos: [4, 1, 6], state: "minecraft:gravel"},
        {pos: [4, 1, 7], state: "minecraft:gravel"},
        {pos: [4, 1, 8], state: "minecraft:gravel"},
        {pos: [4, 1, 9], state: "minecraft:gravel"},
        {pos: [4, 1, 10], state: "minecraft:gravel"},
        {pos: [4, 1, 11], state: "minecraft:gravel"},
        {pos: [4, 1, 12], state: "minecraft:gravel"},
        {pos: [4, 1, 13], state: "minecraft:gravel"},
        {pos: [4, 1, 14], state: "minecraft:deepslate_bricks"},
        {pos: [5, 1, 5], state: "minecraft:deepslate_bricks"},
        {pos: [5, 1, 6], state: "minecraft:gravel"},
        {pos: [5, 1, 7], state: "minecraft:gravel"},
        {pos: [5, 1, 8], state: "minecraft:gravel"},
        {pos: [5, 1, 9], state: "minecraft:gravel"},
        {pos: [5, 1, 10], state: "minecraft:gravel"},
        {pos: [5, 1, 11], state: "minecraft:gravel"},
        {pos: [5, 1, 12], state: "minecraft:gravel"},
        {pos: [5, 1, 13], state: "minecraft:gravel"},
        {pos: [5, 1, 14], state: "minecraft:deepslate_bricks"},
        {pos: [6, 1, 5], state: "minecraft:deepslate_bricks"},
        {pos: [6, 1, 6], state: "minecraft:gravel"},
        {pos: [6, 1, 7], state: "minecraft:gravel"},
        {pos: [6, 1, 8], state: "minecraft:gravel"},
        {pos: [6, 1, 9], state: "minecraft:gravel"},
        {pos: [6, 1, 10], state: "minecraft:gravel"},
        {pos: [6, 1, 11], state: "minecraft:gravel"},
        {pos: [6, 1, 12], state: "minecraft:gravel"},
        {pos: [6, 1, 13], state: "minecraft:gravel"},
        {pos: [6, 1, 14], state: "minecraft:deepslate_bricks"},
        {pos: [7, 1, 0], state: "minecraft:deepslate_bricks"},
        {pos: [7, 1, 1], state: "minecraft:deepslate_bricks"},
        {pos: [7, 1, 2], state: "minecraft:deepslate_bricks"},
        {pos: [7, 1, 3], state: "minecraft:deepslate_bricks"},
        {pos: [7, 1, 4], state: "minecraft:deepslate_bricks"},
        {pos: [7, 1, 5], state: "minecraft:gravel"},
        {pos: [7, 1, 6], state: "minecraft:gravel"},
        {pos: [7, 1, 7], state: "minecraft:gravel"},
        {pos: [7, 1, 8], state: "minecraft:gravel"},
        {pos: [7, 1, 9], state: "minecraft:gravel"},
        {pos: [7, 1, 10], state: "minecraft:gravel"},
        {pos: [7, 1, 11], state: "minecraft:gravel"},
        {pos: [7, 1, 12], state: "minecraft:gravel"},
        {pos: [7, 1, 13], state: "minecraft:gravel"},
        {pos: [7, 1, 14], state: "minecraft:gravel"},
        {pos: [7, 1, 15], state: "minecraft:deepslate_bricks"},
        {pos: [7, 1, 16], state: "minecraft:deepslate_bricks"},
        {pos: [8, 1, 0], state: "minecraft:deepslate_bricks"},
        {pos: [8, 1, 1], state: "minecraft:gravel"},
        {pos: [8, 1, 2], state: "minecraft:gravel"},
        {pos: [8, 1, 3], state: "minecraft:gravel"},
        {pos: [8, 1, 4], state: "minecraft:gravel"},
        {pos: [8, 1, 5], state: "minecraft:gravel"},
        {pos: [8, 1, 6], state: "minecraft:gravel"},
        {pos: [8, 1, 7], state: "minecraft:gravel"},
        {pos: [8, 1, 8], state: "minecraft:gravel"},
        {pos: [8, 1, 9], state: "minecraft:gravel"},
        {pos: [8, 1, 10], state: "minecraft:gravel"},
        {pos: [8, 1, 11], state: "minecraft:gravel"},
        {pos: [8, 1, 12], state: "minecraft:gravel"},
        {pos: [8, 1, 13], state: "minecraft:gravel"},
        {pos: [8, 1, 14], state: "minecraft:gravel"},
        {pos: [8, 1, 15], state: "minecraft:gravel"},
        {pos: [8, 1, 16], state: "minecraft:gravel"},
        {pos: [8, 1, 17], state: "minecraft:deepslate_bricks"},
        {pos: [8, 1, 18], state: "minecraft:deepslate_bricks"},
        {pos: [8, 1, 19], state: "minecraft:deepslate_bricks"},
        {pos: [8, 1, 20], state: "minecraft:deepslate_bricks"},
        {pos: [8, 1, 21], state: "minecraft:deepslate_bricks"},
        {pos: [8, 1, 22], state: "minecraft:deepslate_bricks"},
        {pos: [8, 1, 23], state: "minecraft:deepslate_bricks"},
        {pos: [8, 1, 24], state: "minecraft:deepslate_bricks"},
        {pos: [8, 1, 25], state: "minecraft:deepslate_bricks"},
        {pos: [8, 1, 26], state: "minecraft:deepslate_bricks"},
        {pos: [8, 1, 27], state: "minecraft:deepslate_bricks"},
        {pos: [8, 1, 28], state: "minecraft:deepslate_bricks"},
        {pos: [8, 1, 29], state: "minecraft:deepslate_bricks"},
        {pos: [8, 1, 30], state: "minecraft:deepslate_bricks"},
        {pos: [8, 1, 31], state: "minecraft:deepslate_bricks"},
        {pos: [8, 1, 32], state: "minecraft:deepslate_bricks"},
        {pos: [8, 1, 33], state: "minecraft:deepslate_bricks"},
        {pos: [8, 1, 34], state: "minecraft:deepslate_bricks"},
        {pos: [8, 1, 35], state: "minecraft:deepslate_bricks"},
        {pos: [9, 1, 0], state: "minecraft:deepslate_bricks"},
        {pos: [9, 1, 1], state: "minecraft:gravel"},
        {pos: [9, 1, 2], state: "minecraft:gravel"},
        {pos: [9, 1, 3], state: "minecraft:gravel"},
        {pos: [9, 1, 4], state: "minecraft:gravel"},
        {pos: [9, 1, 5], state: "minecraft:gravel"},
        {pos: [9, 1, 6], state: "minecraft:gravel"},
        {pos: [9, 1, 7], state: "minecraft:gravel"},
        {pos: [9, 1, 8], state: "minecraft:gravel"},
        {pos: [9, 1, 9], state: "minecraft:gravel"},
        {pos: [9, 1, 10], state: "minecraft:gravel"},
        {pos: [9, 1, 11], state: "minecraft:gravel"},
        {pos: [9, 1, 12], state: "minecraft:gravel"},
        {pos: [9, 1, 13], state: "minecraft:gravel"},
        {pos: [9, 1, 14], state: "minecraft:gravel"},
        {pos: [9, 1, 15], state: "minecraft:gravel"},
        {pos: [9, 1, 16], state: "minecraft:gravel"},
        {pos: [9, 1, 17], state: "minecraft:deepslate_bricks"},
        {pos: [9, 1, 18], state: "minecraft:deepslate_bricks"},
        {pos: [9, 1, 19], state: "minecraft:deepslate_bricks"},
        {pos: [9, 1, 20], state: "minecraft:gravel"},
        {pos: [9, 1, 21], state: "minecraft:gravel"},
        {pos: [9, 1, 22], state: "minecraft:gravel"},
        {pos: [9, 1, 23], state: "minecraft:deepslate_bricks"},
        {pos: [9, 1, 24], state: "minecraft:deepslate_bricks"},
        {pos: [9, 1, 25], state: "minecraft:deepslate_bricks"},
        {pos: [9, 1, 26], state: "minecraft:gravel"},
        {pos: [9, 1, 27], state: "minecraft:gravel"},
        {pos: [9, 1, 28], state: "minecraft:gravel"},
        {pos: [9, 1, 29], state: "minecraft:deepslate_bricks"},
        {pos: [9, 1, 30], state: "minecraft:deepslate_bricks"},
        {pos: [9, 1, 31], state: "minecraft:deepslate_bricks"},
        {pos: [9, 1, 32], state: "minecraft:gravel"},
        {pos: [9, 1, 33], state: "minecraft:gravel"},
        {pos: [9, 1, 34], state: "minecraft:gravel"},
        {pos: [9, 1, 35], state: "minecraft:deepslate_bricks"},
        {pos: [10, 1, 0], state: "minecraft:deepslate_bricks"},
        {pos: [10, 1, 1], state: "minecraft:gravel"},
        {pos: [10, 1, 2], state: "minecraft:gravel"},
        {pos: [10, 1, 3], state: "minecraft:gravel"},
        {pos: [10, 1, 4], state: "minecraft:gravel"},
        {pos: [10, 1, 5], state: "minecraft:gravel"},
        {pos: [10, 1, 6], state: "minecraft:gravel"},
        {pos: [10, 1, 7], state: "minecraft:gravel"},
        {pos: [10, 1, 8], state: "minecraft:gravel"},
        {pos: [10, 1, 9], state: "minecraft:gravel"},
        {pos: [10, 1, 10], state: "minecraft:gravel"},
        {pos: [10, 1, 11], state: "minecraft:gravel"},
        {pos: [10, 1, 12], state: "minecraft:gravel"},
        {pos: [10, 1, 13], state: "minecraft:gravel"},
        {pos: [10, 1, 14], state: "minecraft:gravel"},
        {pos: [10, 1, 15], state: "minecraft:gravel"},
        {pos: [10, 1, 16], state: "minecraft:gravel"},
        {pos: [10, 1, 17], state: "minecraft:deepslate_bricks"},
        {pos: [10, 1, 18], state: "minecraft:deepslate_bricks"},
        {pos: [10, 1, 19], state: "minecraft:deepslate_bricks"},
        {pos: [10, 1, 20], state: "minecraft:gravel"},
        {pos: [10, 1, 21], state: "minecraft:gravel"},
        {pos: [10, 1, 22], state: "minecraft:gravel"},
        {pos: [10, 1, 23], state: "minecraft:deepslate_bricks"},
        {pos: [10, 1, 24], state: "minecraft:deepslate_bricks"},
        {pos: [10, 1, 25], state: "minecraft:deepslate_bricks"},
        {pos: [10, 1, 26], state: "minecraft:gravel"},
        {pos: [10, 1, 27], state: "minecraft:gravel"},
        {pos: [10, 1, 28], state: "minecraft:gravel"},
        {pos: [10, 1, 29], state: "minecraft:deepslate_bricks"},
        {pos: [10, 1, 30], state: "minecraft:deepslate_bricks"},
        {pos: [10, 1, 31], state: "minecraft:deepslate_bricks"},
        {pos: [10, 1, 32], state: "minecraft:gravel"},
        {pos: [10, 1, 33], state: "minecraft:gravel"},
        {pos: [10, 1, 34], state: "minecraft:gravel"},
        {pos: [10, 1, 35], state: "minecraft:deepslate_bricks"},
        {pos: [11, 1, 0], state: "minecraft:deepslate_bricks"},
        {pos: [11, 1, 1], state: "minecraft:gravel"},
        {pos: [11, 1, 2], state: "minecraft:gravel"},
        {pos: [11, 1, 3], state: "minecraft:gravel"},
        {pos: [11, 1, 4], state: "minecraft:gravel"},
        {pos: [11, 1, 5], state: "minecraft:gravel"},
        {pos: [11, 1, 6], state: "minecraft:gravel"},
        {pos: [11, 1, 7], state: "minecraft:gravel"},
        {pos: [11, 1, 8], state: "minecraft:gravel"},
        {pos: [11, 1, 9], state: "minecraft:gravel"},
        {pos: [11, 1, 10], state: "minecraft:gravel"},
        {pos: [11, 1, 11], state: "minecraft:gravel"},
        {pos: [11, 1, 12], state: "minecraft:gravel"},
        {pos: [11, 1, 13], state: "minecraft:gravel"},
        {pos: [11, 1, 14], state: "minecraft:gravel"},
        {pos: [11, 1, 15], state: "minecraft:gravel"},
        {pos: [11, 1, 16], state: "minecraft:gravel"},
        {pos: [11, 1, 17], state: "minecraft:deepslate_bricks"},
        {pos: [11, 1, 18], state: "minecraft:gravel"},
        {pos: [11, 1, 19], state: "minecraft:deepslate_bricks"},
        {pos: [11, 1, 20], state: "minecraft:gravel"},
        {pos: [11, 1, 21], state: "minecraft:gravel"},
        {pos: [11, 1, 22], state: "minecraft:gravel"},
        {pos: [11, 1, 23], state: "minecraft:deepslate_bricks"},
        {pos: [11, 1, 24], state: "minecraft:gravel"},
        {pos: [11, 1, 25], state: "minecraft:deepslate_bricks"},
        {pos: [11, 1, 26], state: "minecraft:gravel"},
        {pos: [11, 1, 27], state: "minecraft:gravel"},
        {pos: [11, 1, 28], state: "minecraft:gravel"},
        {pos: [11, 1, 29], state: "minecraft:deepslate_bricks"},
        {pos: [11, 1, 30], state: "minecraft:gravel"},
        {pos: [11, 1, 31], state: "minecraft:deepslate_bricks"},
        {pos: [11, 1, 32], state: "minecraft:gravel"},
        {pos: [11, 1, 33], state: "minecraft:gravel"},
        {pos: [11, 1, 34], state: "minecraft:gravel"},
        {pos: [11, 1, 35], state: "minecraft:deepslate_bricks"},
        {pos: [12, 1, 0], state: "minecraft:deepslate_bricks"},
        {pos: [12, 1, 1], state: "minecraft:gravel"},
        {pos: [12, 1, 2], state: "minecraft:gravel"},
        {pos: [12, 1, 3], state: "minecraft:gravel"},
        {pos: [12, 1, 4], state: "minecraft:gravel"},
        {pos: [12, 1, 5], state: "minecraft:gravel"},
        {pos: [12, 1, 6], state: "minecraft:gravel"},
        {pos: [12, 1, 7], state: "minecraft:gravel"},
        {pos: [12, 1, 8], state: "minecraft:gravel"},
        {pos: [12, 1, 9], state: "minecraft:gravel"},
        {pos: [12, 1, 10], state: "minecraft:gravel"},
        {pos: [12, 1, 11], state: "minecraft:gravel"},
        {pos: [12, 1, 12], state: "minecraft:gravel"},
        {pos: [12, 1, 13], state: "minecraft:gravel"},
        {pos: [12, 1, 14], state: "minecraft:gravel"},
        {pos: [12, 1, 15], state: "minecraft:gravel"},
        {pos: [12, 1, 16], state: "minecraft:gravel"},
        {pos: [12, 1, 17], state: "minecraft:gravel"},
        {pos: [12, 1, 18], state: "minecraft:gravel"},
        {pos: [12, 1, 19], state: "minecraft:gravel"},
        {pos: [12, 1, 20], state: "minecraft:gravel"},
        {pos: [12, 1, 21], state: "minecraft:gravel"},
        {pos: [12, 1, 22], state: "minecraft:gravel"},
        {pos: [12, 1, 23], state: "minecraft:gravel"},
        {pos: [12, 1, 24], state: "minecraft:gravel"},
        {pos: [12, 1, 25], state: "minecraft:gravel"},
        {pos: [12, 1, 26], state: "minecraft:gravel"},
        {pos: [12, 1, 27], state: "minecraft:gravel"},
        {pos: [12, 1, 28], state: "minecraft:gravel"},
        {pos: [12, 1, 29], state: "minecraft:gravel"},
        {pos: [12, 1, 30], state: "minecraft:gravel"},
        {pos: [12, 1, 31], state: "minecraft:gravel"},
        {pos: [12, 1, 32], state: "minecraft:gravel"},
        {pos: [12, 1, 33], state: "minecraft:gravel"},
        {pos: [12, 1, 34], state: "minecraft:gravel"},
        {pos: [12, 1, 35], state: "minecraft:deepslate_bricks"},
        {pos: [13, 1, 0], state: "minecraft:deepslate_bricks"},
        {pos: [13, 1, 1], state: "minecraft:gravel"},
        {pos: [13, 1, 2], state: "minecraft:gravel"},
        {pos: [13, 1, 3], state: "minecraft:gravel"},
        {pos: [13, 1, 4], state: "minecraft:gravel"},
        {pos: [13, 1, 5], state: "minecraft:gravel"},
        {pos: [13, 1, 6], state: "minecraft:gravel"},
        {pos: [13, 1, 7], state: "minecraft:gravel"},
        {pos: [13, 1, 8], state: "minecraft:gravel"},
        {pos: [13, 1, 9], state: "minecraft:gravel"},
        {pos: [13, 1, 10], state: "minecraft:gravel"},
        {pos: [13, 1, 11], state: "minecraft:gravel"},
        {pos: [13, 1, 12], state: "minecraft:gravel"},
        {pos: [13, 1, 13], state: "minecraft:gravel"},
        {pos: [13, 1, 14], state: "minecraft:gravel"},
        {pos: [13, 1, 15], state: "minecraft:gravel"},
        {pos: [13, 1, 16], state: "minecraft:gravel"},
        {pos: [13, 1, 17], state: "minecraft:gravel"},
        {pos: [13, 1, 18], state: "minecraft:gravel"},
        {pos: [13, 1, 19], state: "minecraft:gravel"},
        {pos: [13, 1, 20], state: "minecraft:gravel"},
        {pos: [13, 1, 21], state: "minecraft:gravel"},
        {pos: [13, 1, 22], state: "minecraft:gravel"},
        {pos: [13, 1, 23], state: "minecraft:gravel"},
        {pos: [13, 1, 24], state: "minecraft:gravel"},
        {pos: [13, 1, 25], state: "minecraft:gravel"},
        {pos: [13, 1, 26], state: "minecraft:gravel"},
        {pos: [13, 1, 27], state: "minecraft:gravel"},
        {pos: [13, 1, 28], state: "minecraft:gravel"},
        {pos: [13, 1, 29], state: "minecraft:gravel"},
        {pos: [13, 1, 30], state: "minecraft:gravel"},
        {pos: [13, 1, 31], state: "minecraft:gravel"},
        {pos: [13, 1, 32], state: "minecraft:gravel"},
        {pos: [13, 1, 33], state: "minecraft:gravel"},
        {pos: [13, 1, 34], state: "minecraft:gravel"},
        {pos: [13, 1, 35], state: "minecraft:deepslate_bricks"},
        {pos: [14, 1, 0], state: "minecraft:deepslate_bricks"},
        {pos: [14, 1, 1], state: "minecraft:deepslate_bricks"},
        {pos: [14, 1, 2], state: "minecraft:gravel"},
        {pos: [14, 1, 3], state: "minecraft:gravel"},
        {pos: [14, 1, 4], state: "minecraft:gravel"},
        {pos: [14, 1, 5], state: "minecraft:gravel"},
        {pos: [14, 1, 6], state: "minecraft:gravel"},
        {pos: [14, 1, 7], state: "minecraft:gravel"},
        {pos: [14, 1, 8], state: "minecraft:gravel"},
        {pos: [14, 1, 9], state: "minecraft:gravel"},
        {pos: [14, 1, 10], state: "minecraft:gravel"},
        {pos: [14, 1, 11], state: "minecraft:gravel"},
        {pos: [14, 1, 12], state: "minecraft:gravel"},
        {pos: [14, 1, 13], state: "minecraft:gravel"},
        {pos: [14, 1, 14], state: "minecraft:gravel"},
        {pos: [14, 1, 15], state: "minecraft:gravel"},
        {pos: [14, 1, 16], state: "minecraft:gravel"},
        {pos: [14, 1, 17], state: "minecraft:gravel"},
        {pos: [14, 1, 18], state: "minecraft:gravel"},
        {pos: [14, 1, 19], state: "minecraft:gravel"},
        {pos: [14, 1, 20], state: "minecraft:gravel"},
        {pos: [14, 1, 21], state: "minecraft:gravel"},
        {pos: [14, 1, 22], state: "minecraft:gravel"},
        {pos: [14, 1, 23], state: "minecraft:gravel"},
        {pos: [14, 1, 24], state: "minecraft:gravel"},
        {pos: [14, 1, 25], state: "minecraft:gravel"},
        {pos: [14, 1, 26], state: "minecraft:gravel"},
        {pos: [14, 1, 27], state: "minecraft:gravel"},
        {pos: [14, 1, 28], state: "minecraft:gravel"},
        {pos: [14, 1, 29], state: "minecraft:gravel"},
        {pos: [14, 1, 30], state: "minecraft:gravel"},
        {pos: [14, 1, 31], state: "minecraft:gravel"},
        {pos: [14, 1, 32], state: "minecraft:gravel"},
        {pos: [14, 1, 33], state: "minecraft:gravel"},
        {pos: [14, 1, 34], state: "minecraft:gravel"},
        {pos: [14, 1, 35], state: "minecraft:deepslate_bricks"},
        {pos: [15, 1, 2], state: "minecraft:deepslate_bricks"},
        {pos: [15, 1, 3], state: "minecraft:deepslate_bricks"},
        {pos: [15, 1, 4], state: "minecraft:gravel"},
        {pos: [15, 1, 5], state: "minecraft:gravel"},
        {pos: [15, 1, 6], state: "minecraft:gravel"},
        {pos: [15, 1, 7], state: "minecraft:gravel"},
        {pos: [15, 1, 8], state: "minecraft:gravel"},
        {pos: [15, 1, 9], state: "minecraft:gravel"},
        {pos: [15, 1, 10], state: "minecraft:gravel"},
        {pos: [15, 1, 11], state: "minecraft:gravel"},
        {pos: [15, 1, 12], state: "minecraft:gravel"},
        {pos: [15, 1, 13], state: "minecraft:gravel"},
        {pos: [15, 1, 14], state: "minecraft:deepslate_bricks"},
        {pos: [15, 1, 15], state: "minecraft:gravel"},
        {pos: [15, 1, 16], state: "minecraft:gravel"},
        {pos: [15, 1, 17], state: "minecraft:deepslate_bricks"},
        {pos: [15, 1, 18], state: "minecraft:gravel"},
        {pos: [15, 1, 19], state: "minecraft:deepslate_bricks"},
        {pos: [15, 1, 20], state: "minecraft:gravel"},
        {pos: [15, 1, 21], state: "minecraft:gravel"},
        {pos: [15, 1, 22], state: "minecraft:gravel"},
        {pos: [15, 1, 23], state: "minecraft:deepslate_bricks"},
        {pos: [15, 1, 24], state: "minecraft:gravel"},
        {pos: [15, 1, 25], state: "minecraft:deepslate_bricks"},
        {pos: [15, 1, 26], state: "minecraft:gravel"},
        {pos: [15, 1, 27], state: "minecraft:gravel"},
        {pos: [15, 1, 28], state: "minecraft:gravel"},
        {pos: [15, 1, 29], state: "minecraft:deepslate_bricks"},
        {pos: [15, 1, 30], state: "minecraft:gravel"},
        {pos: [15, 1, 31], state: "minecraft:deepslate_bricks"},
        {pos: [15, 1, 32], state: "minecraft:gravel"},
        {pos: [15, 1, 33], state: "minecraft:gravel"},
        {pos: [15, 1, 34], state: "minecraft:gravel"},
        {pos: [15, 1, 35], state: "minecraft:deepslate_bricks"},
        {pos: [16, 1, 4], state: "minecraft:deepslate_bricks"},
        {pos: [16, 1, 5], state: "minecraft:gravel"},
        {pos: [16, 1, 6], state: "minecraft:gravel"},
        {pos: [16, 1, 7], state: "minecraft:gravel"},
        {pos: [16, 1, 8], state: "minecraft:gravel"},
        {pos: [16, 1, 9], state: "minecraft:gravel"},
        {pos: [16, 1, 10], state: "minecraft:gravel"},
        {pos: [16, 1, 11], state: "minecraft:gravel"},
        {pos: [16, 1, 12], state: "minecraft:gravel"},
        {pos: [16, 1, 13], state: "minecraft:gravel"},
        {pos: [16, 1, 14], state: "minecraft:gravel"},
        {pos: [16, 1, 15], state: "minecraft:deepslate_bricks"},
        {pos: [16, 1, 16], state: "minecraft:deepslate_bricks"},
        {pos: [16, 1, 17], state: "minecraft:deepslate_bricks"},
        {pos: [16, 1, 18], state: "minecraft:deepslate_bricks"},
        {pos: [16, 1, 19], state: "minecraft:deepslate_bricks"},
        {pos: [16, 1, 20], state: "minecraft:gravel"},
        {pos: [16, 1, 21], state: "minecraft:gravel"},
        {pos: [16, 1, 22], state: "minecraft:gravel"},
        {pos: [16, 1, 23], state: "minecraft:deepslate_bricks"},
        {pos: [16, 1, 24], state: "minecraft:deepslate_bricks"},
        {pos: [16, 1, 25], state: "minecraft:deepslate_bricks"},
        {pos: [16, 1, 26], state: "minecraft:gravel"},
        {pos: [16, 1, 27], state: "minecraft:gravel"},
        {pos: [16, 1, 28], state: "minecraft:gravel"},
        {pos: [16, 1, 29], state: "minecraft:deepslate_bricks"},
        {pos: [16, 1, 30], state: "minecraft:deepslate_bricks"},
        {pos: [16, 1, 31], state: "minecraft:deepslate_bricks"},
        {pos: [16, 1, 32], state: "minecraft:gravel"},
        {pos: [16, 1, 33], state: "minecraft:gravel"},
        {pos: [16, 1, 34], state: "minecraft:gravel"},
        {pos: [16, 1, 35], state: "minecraft:deepslate_bricks"},
        {pos: [17, 1, 4], state: "minecraft:deepslate_bricks"},
        {pos: [17, 1, 5], state: "minecraft:gravel"},
        {pos: [17, 1, 6], state: "minecraft:gravel"},
        {pos: [17, 1, 7], state: "minecraft:gravel"},
        {pos: [17, 1, 8], state: "minecraft:gravel"},
        {pos: [17, 1, 9], state: "minecraft:gravel"},
        {pos: [17, 1, 10], state: "minecraft:gravel"},
        {pos: [17, 1, 11], state: "minecraft:gravel"},
        {pos: [17, 1, 12], state: "minecraft:gravel"},
        {pos: [17, 1, 13], state: "minecraft:gravel"},
        {pos: [17, 1, 14], state: "minecraft:deepslate_bricks"},
        {pos: [17, 1, 17], state: "minecraft:deepslate_bricks"},
        {pos: [17, 1, 18], state: "minecraft:deepslate_bricks"},
        {pos: [17, 1, 19], state: "minecraft:deepslate_bricks"},
        {pos: [17, 1, 20], state: "minecraft:gravel"},
        {pos: [17, 1, 21], state: "minecraft:gravel"},
        {pos: [17, 1, 22], state: "minecraft:gravel"},
        {pos: [17, 1, 23], state: "minecraft:deepslate_bricks"},
        {pos: [17, 1, 24], state: "minecraft:deepslate_bricks"},
        {pos: [17, 1, 25], state: "minecraft:deepslate_bricks"},
        {pos: [17, 1, 26], state: "minecraft:gravel"},
        {pos: [17, 1, 27], state: "minecraft:gravel"},
        {pos: [17, 1, 28], state: "minecraft:gravel"},
        {pos: [17, 1, 29], state: "minecraft:deepslate_bricks"},
        {pos: [17, 1, 30], state: "minecraft:deepslate_bricks"},
        {pos: [17, 1, 31], state: "minecraft:deepslate_bricks"},
        {pos: [17, 1, 32], state: "minecraft:gravel"},
        {pos: [17, 1, 33], state: "minecraft:gravel"},
        {pos: [17, 1, 34], state: "minecraft:gravel"},
        {pos: [17, 1, 35], state: "minecraft:deepslate_bricks"},
        {pos: [18, 1, 4], state: "minecraft:deepslate_bricks"},
        {pos: [18, 1, 5], state: "minecraft:gravel"},
        {pos: [18, 1, 6], state: "minecraft:gravel"},
        {pos: [18, 1, 7], state: "minecraft:gravel"},
        {pos: [18, 1, 8], state: "minecraft:gravel"},
        {pos: [18, 1, 9], state: "minecraft:gravel"},
        {pos: [18, 1, 10], state: "minecraft:gravel"},
        {pos: [18, 1, 11], state: "minecraft:gravel"},
        {pos: [18, 1, 12], state: "minecraft:gravel"},
        {pos: [18, 1, 13], state: "minecraft:deepslate_bricks"},
        {pos: [18, 1, 14], state: "minecraft:deepslate_bricks"},
        {pos: [18, 1, 17], state: "minecraft:deepslate_bricks"},
        {pos: [18, 1, 18], state: "minecraft:deepslate_bricks"},
        {pos: [18, 1, 19], state: "minecraft:deepslate_bricks"},
        {pos: [18, 1, 20], state: "minecraft:deepslate_bricks"},
        {pos: [18, 1, 21], state: "minecraft:deepslate_bricks"},
        {pos: [18, 1, 22], state: "minecraft:deepslate_bricks"},
        {pos: [18, 1, 23], state: "minecraft:deepslate_bricks"},
        {pos: [18, 1, 24], state: "minecraft:deepslate_bricks"},
        {pos: [18, 1, 25], state: "minecraft:deepslate_bricks"},
        {pos: [18, 1, 26], state: "minecraft:deepslate_bricks"},
        {pos: [18, 1, 27], state: "minecraft:deepslate_bricks"},
        {pos: [18, 1, 28], state: "minecraft:deepslate_bricks"},
        {pos: [18, 1, 29], state: "minecraft:deepslate_bricks"},
        {pos: [18, 1, 30], state: "minecraft:deepslate_bricks"},
        {pos: [18, 1, 31], state: "minecraft:deepslate_bricks"},
        {pos: [18, 1, 32], state: "minecraft:deepslate_bricks"},
        {pos: [18, 1, 33], state: "minecraft:deepslate_bricks"},
        {pos: [18, 1, 34], state: "minecraft:deepslate_bricks"},
        {pos: [18, 1, 35], state: "minecraft:deepslate_bricks"},
        {pos: [19, 1, 4], state: "minecraft:deepslate_bricks"},
        {pos: [19, 1, 5], state: "minecraft:gravel"},
        {pos: [19, 1, 6], state: "minecraft:gravel"},
        {pos: [19, 1, 7], state: "minecraft:gravel"},
        {pos: [19, 1, 8], state: "minecraft:gravel"},
        {pos: [19, 1, 9], state: "minecraft:gravel"},
        {pos: [19, 1, 10], state: "minecraft:gravel"},
        {pos: [19, 1, 11], state: "minecraft:gravel"},
        {pos: [19, 1, 12], state: "minecraft:deepslate_bricks"},
        {pos: [20, 1, 4], state: "minecraft:deepslate_bricks"},
        {pos: [20, 1, 5], state: "minecraft:deepslate_bricks"},
        {pos: [20, 1, 6], state: "minecraft:deepslate_bricks"},
        {pos: [20, 1, 7], state: "minecraft:gravel"},
        {pos: [20, 1, 8], state: "minecraft:gravel"},
        {pos: [20, 1, 9], state: "minecraft:gravel"},
        {pos: [20, 1, 10], state: "minecraft:deepslate_bricks"},
        {pos: [20, 1, 11], state: "minecraft:deepslate_bricks"},
        {pos: [20, 1, 12], state: "minecraft:deepslate_bricks"},
        {pos: [0, 2, 5], state: "minecraft:deepslate_bricks"},
        {pos: [0, 2, 6], state: "minecraft:deepslate_bricks"},
        {pos: [0, 2, 7], state: "minecraft:candle{candles:4,lit:false,waterlogged:false}"},
        {pos: [0, 2, 8], state: "minecraft:jigsaw{orientation:west_up}", nbt: {final_state: "minecraft:cave_air", id: "minecraft:jigsaw", joint: "rollable", name: "trailiertales:corridor", placement_priority: 0, pool: "trailiertales:catacombs/corridor_connector", selection_priority: 0, target: "trailiertales:corridor"}},
        {pos: [0, 2, 9], state: "minecraft:candle{candles:4,lit:false,waterlogged:false}"},
        {pos: [0, 2, 10], state: "minecraft:deepslate_bricks"},
        {pos: [0, 2, 11], state: "minecraft:deepslate_bricks"},
        {pos: [1, 2, 5], state: "minecraft:deepslate_bricks"},
        {pos: [1, 2, 6], state: "minecraft:deepslate_brick_stairs{facing:north,half:top,shape:straight,waterlogged:false}"},
        {pos: [1, 2, 7], state: "minecraft:candle{candles:4,lit:false,waterlogged:false}"},
        {pos: [1, 2, 8], state: "minecraft:cave_air"},
        {pos: [1, 2, 9], state: "minecraft:candle{candles:4,lit:false,waterlogged:false}"},
        {pos: [1, 2, 10], state: "minecraft:deepslate_brick_stairs{facing:south,half:top,shape:straight,waterlogged:false}"},
        {pos: [1, 2, 11], state: "minecraft:deepslate_bricks"},
        {pos: [2, 2, 5], state: "minecraft:deepslate_bricks"},
        {pos: [2, 2, 6], state: "minecraft:deepslate_bricks"},
        {pos: [2, 2, 7], state: "minecraft:candle{candles:4,lit:false,waterlogged:false}"},
        {pos: [2, 2, 8], state: "minecraft:cave_air"},
        {pos: [2, 2, 9], state: "minecraft:candle{candles:4,lit:false,waterlogged:false}"},
        {pos: [2, 2, 10], state: "minecraft:deepslate_bricks"},
        {pos: [2, 2, 11], state: "minecraft:deepslate_bricks"},
        {pos: [2, 2, 12], state: "minecraft:deepslate_bricks"},
        {pos: [2, 2, 13], state: "minecraft:deepslate_bricks"},
        {pos: [2, 2, 14], state: "minecraft:deepslate_bricks"},
        {pos: [3, 2, 5], state: "minecraft:deepslate_bricks"},
        {pos: [3, 2, 6], state: "minecraft:deepslate_brick_stairs{facing:north,half:top,shape:straight,waterlogged:false}"},
        {pos: [3, 2, 7], state: "minecraft:candle{candles:4,lit:false,waterlogged:false}"},
        {pos: [3, 2, 8], state: "minecraft:cave_air"},
        {pos: [3, 2, 9], state: "minecraft:cave_air"},
        {pos: [3, 2, 10], state: "minecraft:candle{candles:4,lit:false,waterlogged:false}"},
        {pos: [3, 2, 11], state: "minecraft:deepslate_brick_stairs{facing:east,half:bottom,shape:straight,waterlogged:false}"},
        {pos: [3, 2, 12], state: "minecraft:deepslate_brick_stairs{facing:east,half:bottom,shape:straight,waterlogged:false}"},
        {pos: [3, 2, 13], state: "minecraft:deepslate_bricks"},
        {pos: [3, 2, 14], state: "minecraft:deepslate_bricks"},
        {pos: [4, 2, 5], state: "minecraft:deepslate_bricks"},
        {pos: [4, 2, 6], state: "minecraft:deepslate_bricks"},
        {pos: [4, 2, 7], state: "minecraft:candle{candles:4,lit:false,waterlogged:false}"},
        {pos: [4, 2, 8], state: "minecraft:cave_air"},
        {pos: [4, 2, 9], state: "minecraft:cave_air"},
        {pos: [4, 2, 10], state: "minecraft:candle{candles:4,lit:false,waterlogged:false}"},
        {pos: [4, 2, 11], state: "trailiertales:coffin{facing:south,part:foot,state:inactive}", nbt: {id: "trailiertales:coffin", max_active_light_level: 7, uuid: "dc70c88e-25a1-4c67-998d-1f2b051d8e4e"}},
        {pos: [4, 2, 12], state: "trailiertales:coffin{facing:south,part:head,state:inactive}", nbt: {id: "trailiertales:coffin"}},
        {pos: [4, 2, 13], state: "minecraft:deepslate_bricks"},
        {pos: [4, 2, 14], state: "minecraft:deepslate_bricks"},
        {pos: [5, 2, 5], state: "minecraft:deepslate_bricks"},
        {pos: [5, 2, 6], state: "minecraft:deepslate_brick_stairs{facing:north,half:top,shape:straight,waterlogged:false}"},
        {pos: [5, 2, 7], state: "minecraft:candle{candles:4,lit:false,waterlogged:false}"},
        {pos: [5, 2, 8], state: "minecraft:cave_air"},
        {pos: [5, 2, 9], state: "minecraft:cave_air"},
        {pos: [5, 2, 10], state: "minecraft:decorated_pot{cracked:false,facing:east,waterlogged:false}", nbt: {id: "minecraft:decorated_pot"}},
        {pos: [5, 2, 11], state: "minecraft:deepslate_brick_stairs{facing:west,half:bottom,shape:straight,waterlogged:false}"},
        {pos: [5, 2, 12], state: "minecraft:deepslate_brick_stairs{facing:west,half:bottom,shape:straight,waterlogged:false}"},
        {pos: [5, 2, 13], state: "minecraft:deepslate_bricks"},
        {pos: [5, 2, 14], state: "minecraft:deepslate_bricks"},
        {pos: [6, 2, 5], state: "minecraft:deepslate_bricks"},
        {pos: [6, 2, 6], state: "minecraft:deepslate_bricks"},
        {pos: [6, 2, 7], state: "minecraft:candle{candles:4,lit:false,waterlogged:false}"},
        {pos: [6, 2, 8], state: "minecraft:cave_air"},
        {pos: [6, 2, 9], state: "minecraft:candle{candles:4,lit:false,waterlogged:false}"},
        {pos: [6, 2, 10], state: "minecraft:deepslate_bricks"},
        {pos: [6, 2, 11], state: "minecraft:deepslate_bricks"},
        {pos: [6, 2, 12], state: "minecraft:deepslate_bricks"},
        {pos: [6, 2, 13], state: "minecraft:deepslate_bricks"},
        {pos: [6, 2, 14], state: "minecraft:deepslate_bricks"},
        {pos: [7, 2, 0], state: "minecraft:deepslate_bricks"},
        {pos: [7, 2, 1], state: "minecraft:deepslate_bricks"},
        {pos: [7, 2, 2], state: "minecraft:deepslate_bricks"},
        {pos: [7, 2, 3], state: "minecraft:deepslate_bricks"},
        {pos: [7, 2, 4], state: "minecraft:deepslate_bricks"},
        {pos: [7, 2, 5], state: "minecraft:deepslate_bricks"},
        {pos: [7, 2, 6], state: "minecraft:deepslate_brick_stairs{facing:north,half:top,shape:straight,waterlogged:false}"},
        {pos: [7, 2, 7], state: "minecraft:candle{candles:4,lit:false,waterlogged:false}"},
        {pos: [7, 2, 8], state: "minecraft:cave_air"},
        {pos: [7, 2, 9], state: "minecraft:candle{candles:4,lit:false,waterlogged:false}"},
        {pos: [7, 2, 10], state: "minecraft:deepslate_brick_stairs{facing:south,half:top,shape:straight,waterlogged:false}"},
        {pos: [7, 2, 11], state: "minecraft:deepslate_bricks"},
        {pos: [7, 2, 12], state: "minecraft:deepslate_bricks"},
        {pos: [7, 2, 13], state: "minecraft:deepslate_bricks"},
        {pos: [7, 2, 14], state: "minecraft:deepslate_bricks"},
        {pos: [7, 2, 15], state: "minecraft:deepslate_bricks"},
        {pos: [7, 2, 16], state: "minecraft:deepslate_bricks"},
        {pos: [8, 2, 0], state: "minecraft:deepslate_bricks"},
        {pos: [8, 2, 1], state: "minecraft:deepslate_bricks"},
        {pos: [8, 2, 2], state: "minecraft:deepslate_bricks"},
        {pos: [8, 2, 3], state: "minecraft:deepslate_bricks"},
        {pos: [8, 2, 4], state: "minecraft:deepslate_bricks"},
        {pos: [8, 2, 5], state: "minecraft:deepslate_bricks"},
        {pos: [8, 2, 6], state: "minecraft:deepslate_bricks"},
        {pos: [8, 2, 7], state: "minecraft:skeleton_skull{powered:false,rotation:8}", nbt: {id: "minecraft:skull"}},
        {pos: [8, 2, 8], state: "minecraft:cave_air"},
        {pos: [8, 2, 9], state: "minecraft:candle{candles:4,lit:false,waterlogged:false}"},
        {pos: [8, 2, 10], state: "minecraft:deepslate_bricks"},
        {pos: [8, 2, 11], state: "minecraft:deepslate_bricks"},
        {pos: [8, 2, 12], state: "minecraft:deepslate_bricks"},
        {pos: [8, 2, 13], state: "minecraft:deepslate_bricks"},
        {pos: [8, 2, 14], state: "minecraft:deepslate_bricks"},
        {pos: [8, 2, 15], state: "minecraft:deepslate_bricks"},
        {pos: [8, 2, 16], state: "minecraft:deepslate_bricks"},
        {pos: [8, 2, 17], state: "minecraft:deepslate_bricks"},
        {pos: [8, 2, 18], state: "minecraft:deepslate_bricks"},
        {pos: [8, 2, 19], state: "minecraft:deepslate_bricks"},
        {pos: [8, 2, 20], state: "minecraft:deepslate_bricks"},
        {pos: [8, 2, 21], state: "minecraft:deepslate_bricks"},
        {pos: [8, 2, 22], state: "minecraft:deepslate_bricks"},
        {pos: [8, 2, 23], state: "minecraft:deepslate_bricks"},
        {pos: [8, 2, 24], state: "minecraft:deepslate_bricks"},
        {pos: [8, 2, 25], state: "minecraft:deepslate_bricks"},
        {pos: [8, 2, 26], state: "minecraft:deepslate_bricks"},
        {pos: [8, 2, 27], state: "minecraft:deepslate_bricks"},
        {pos: [8, 2, 28], state: "minecraft:deepslate_bricks"},
        {pos: [8, 2, 29], state: "minecraft:deepslate_bricks"},
        {pos: [8, 2, 30], state: "minecraft:deepslate_bricks"},
        {pos: [8, 2, 31], state: "minecraft:deepslate_bricks"},
        {pos: [8, 2, 32], state: "minecraft:deepslate_bricks"},
        {pos: [8, 2, 33], state: "minecraft:deepslate_bricks"},
        {pos: [8, 2, 34], state: "minecraft:deepslate_bricks"},
        {pos: [8, 2, 35], state: "minecraft:deepslate_bricks"},
        {pos: [9, 2, 0], state: "minecraft:deepslate_bricks"},
        {pos: [9, 2, 1], state: "minecraft:deepslate_bricks"},
        {pos: [9, 2, 2], state: "minecraft:deepslate_bricks"},
        {pos: [9, 2, 3], state: "minecraft:deepslate_bricks"},
        {pos: [9, 2, 4], state: "minecraft:deepslate_bricks"},
        {pos: [9, 2, 5], state: "minecraft:deepslate_bricks"},
        {pos: [9, 2, 6], state: "minecraft:deepslate_brick_stairs{facing:north,half:top,shape:straight,waterlogged:false}"},
        {pos: [9, 2, 7], state: "minecraft:candle{candles:4,lit:false,waterlogged:false}"},
        {pos: [9, 2, 8], state: "minecraft:cave_air"},
        {pos: [9, 2, 9], state: "minecraft:cave_air"},
        {pos: [9, 2, 10], state: "minecraft:candle{candles:4,lit:false,waterlogged:false}"},
        {pos: [9, 2, 11], state: "minecraft:candle{candles:4,lit:false,waterlogged:false}"},
        {pos: [9, 2, 12], state: "minecraft:candle{candles:4,lit:false,waterlogged:false}"},
        {pos: [9, 2, 13], state: "minecraft:deepslate_brick_stairs{facing:south,half:top,shape:straight,waterlogged:false}"},
        {pos: [9, 2, 14], state: "minecraft:deepslate_bricks"},
        {pos: [9, 2, 15], state: "minecraft:deepslate_bricks"},
        {pos: [9, 2, 16], state: "minecraft:deepslate_bricks"},
        {pos: [9, 2, 17], state: "minecraft:deepslate_bricks"},
        {pos: [9, 2, 18], state: "minecraft:deepslate_bricks"},
        {pos: [9, 2, 19], state: "minecraft:deepslate_bricks"},
        {pos: [9, 2, 20], state: "minecraft:deepslate_bricks"},
        {pos: [9, 2, 21], state: "minecraft:deepslate_bricks"},
        {pos: [9, 2, 22], state: "minecraft:deepslate_bricks"},
        {pos: [9, 2, 23], state: "minecraft:deepslate_bricks"},
        {pos: [9, 2, 24], state: "minecraft:deepslate_bricks"},
        {pos: [9, 2, 25], state: "minecraft:deepslate_bricks"},
        {pos: [9, 2, 26], state: "minecraft:deepslate_bricks"},
        {pos: [9, 2, 27], state: "minecraft:deepslate_bricks"},
        {pos: [9, 2, 28], state: "minecraft:deepslate_bricks"},
        {pos: [9, 2, 29], state: "minecraft:deepslate_bricks"},
        {pos: [9, 2, 30], state: "minecraft:deepslate_bricks"},
        {pos: [9, 2, 31], state: "minecraft:deepslate_bricks"},
        {pos: [9, 2, 32], state: "minecraft:deepslate_brick_stairs{facing:south,half:bottom,shape:straight,waterlogged:false}"},
        {pos: [9, 2, 33], state: "minecraft:chest{facing:east,type:single,waterlogged:false}", nbt: {Items: [], id: "minecraft:chest"}},
        {pos: [9, 2, 34], state: "minecraft:deepslate_brick_stairs{facing:north,half:bottom,shape:straight,waterlogged:false}"},
        {pos: [9, 2, 35], state: "minecraft:deepslate_bricks"},
        {pos: [10, 2, 0], state: "minecraft:deepslate_bricks"},
        {pos: [10, 2, 1], state: "minecraft:deepslate_bricks"},
        {pos: [10, 2, 2], state: "minecraft:deepslate_bricks"},
        {pos: [10, 2, 3], state: "minecraft:deepslate_bricks"},
        {pos: [10, 2, 4], state: "minecraft:deepslate_bricks"},
        {pos: [10, 2, 5], state: "minecraft:deepslate_bricks"},
        {pos: [10, 2, 6], state: "minecraft:deepslate_bricks"},
        {pos: [10, 2, 7], state: "minecraft:candle{candles:4,lit:false,waterlogged:false}"},
        {pos: [10, 2, 8], state: "minecraft:candle{candles:4,lit:false,waterlogged:false}"},
        {pos: [10, 2, 9], state: "minecraft:cave_air"},
        {pos: [10, 2, 10], state: "minecraft:cave_air"},
        {pos: [10, 2, 11], state: "minecraft:cave_air"},
        {pos: [10, 2, 12], state: "minecraft:cave_air"},
        {pos: [10, 2, 13], state: "minecraft:deepslate_brick_stairs{facing:south,half:top,shape:straight,waterlogged:false}"},
        {pos: [10, 2, 14], state: "minecraft:deepslate_bricks"},
        {pos: [10, 2, 15], state: "minecraft:deepslate_bricks"},
        {pos: [10, 2, 16], state: "minecraft:deepslate_bricks"},
        {pos: [10, 2, 17], state: "minecraft:deepslate_bricks"},
        {pos: [10, 2, 18], state: "minecraft:deepslate_bricks"},
        {pos: [10, 2, 19], state: "minecraft:deepslate_bricks"},
        {pos: [10, 2, 20], state: "minecraft:deepslate_brick_stairs{facing:south,half:bottom,shape:straight,waterlogged:false}"},
        {pos: [10, 2, 21], state: "trailiertales:coffin{facing:west,part:head,state:inactive}", nbt: {id: "trailiertales:coffin"}},
        {pos: [10, 2, 22], state: "minecraft:deepslate_brick_stairs{facing:north,half:bottom,shape:straight,waterlogged:false}"},
        {pos: [10, 2, 23], state: "minecraft:deepslate_bricks"},
        {pos: [10, 2, 24], state: "minecraft:deepslate_bricks"},
        {pos: [10, 2, 25], state: "minecraft:deepslate_bricks"},
        {pos: [10, 2, 26], state: "minecraft:deepslate_brick_stairs{facing:south,half:bottom,shape:straight,waterlogged:false}"},
        {pos: [10, 2, 27], state: "trailiertales:coffin{facing:west,part:head,state:inactive}", nbt: {id: "trailiertales:coffin"}},
        {pos: [10, 2, 28], state: "minecraft:deepslate_brick_stairs{facing:north,half:bottom,shape:straight,waterlogged:false}"},
        {pos: [10, 2, 29], state: "minecraft:deepslate_bricks"},
        {pos: [10, 2, 30], state: "minecraft:deepslate_bricks"},
        {pos: [10, 2, 31], state: "minecraft:deepslate_bricks"},
        {pos: [10, 2, 32], state: "minecraft:candle{candles:4,lit:false,waterlogged:false}"},
        {pos: [10, 2, 33], state: "minecraft:candle{candles:4,lit:false,waterlogged:false}"},
        {pos: [10, 2, 34], state: "minecraft:candle{candles:4,lit:false,waterlogged:false}"},
        {pos: [10, 2, 35], state: "minecraft:deepslate_bricks"},
        {pos: [11, 2, 0], state: "minecraft:deepslate_bricks"},
        {pos: [11, 2, 1], state: "minecraft:deepslate_bricks"},
        {pos: [11, 2, 2], state: "minecraft:deepslate_bricks"},
        {pos: [11, 2, 3], state: "minecraft:deepslate_bricks"},
        {pos: [11, 2, 4], state: "minecraft:deepslate_bricks"},
        {pos: [11, 2, 5], state: "minecraft:deepslate_bricks"},
        {pos: [11, 2, 6], state: "minecraft:deepslate_bricks"},
        {pos: [11, 2, 7], state: "minecraft:cobbled_deepslate"},
        {pos: [11, 2, 8], state: "minecraft:cobbled_deepslate"},
        {pos: [11, 2, 9], state: "minecraft:cobbled_deepslate"},
        {pos: [11, 2, 10], state: "minecraft:candle{candles:4,lit:false,waterlogged:false}"},
        {pos: [11, 2, 11], state: "minecraft:cave_air"},
        {pos: [11, 2, 12], state: "minecraft:cave_air"},
        {pos: [11, 2, 13], state: "minecraft:deepslate_brick_stairs{facing:south,half:top,shape:straight,waterlogged:false}"},
        {pos: [11, 2, 14], state: "minecraft:deepslate_bricks"},
        {pos: [11, 2, 15], state: "minecraft:sticky_piston{extended:true,facing:east}"},
        {pos: [11, 2, 16], state: "minecraft:deepslate_bricks"},
        {pos: [11, 2, 17], state: "minecraft:deepslate_bricks"},
        {pos: [11, 2, 18], state: "minecraft:deepslate_brick_stairs{facing:west,half:top,shape:straight,waterlogged:false}"},
        {pos: [11, 2, 19], state: "minecraft:deepslate_bricks"},
        {pos: [11, 2, 20], state: "minecraft:deepslate_brick_stairs{facing:south,half:bottom,shape:straight,waterlogged:false}"},
        {pos: [11, 2, 21], state: "trailiertales:coffin{facing:west,part:foot,state:inactive}", nbt: {id: "trailiertales:coffin", max_active_light_level: 7, uuid: "0ec9295a-d4f8-40e8-a332-1368f0c99921"}},
        {pos: [11, 2, 22], state: "minecraft:deepslate_brick_stairs{facing:north,half:bottom,shape:straight,waterlogged:false}"},
        {pos: [11, 2, 23], state: "minecraft:deepslate_bricks"},
        {pos: [11, 2, 24], state: "minecraft:deepslate_brick_stairs{facing:west,half:top,shape:straight,waterlogged:false}"},
        {pos: [11, 2, 25], state: "minecraft:deepslate_bricks"},
        {pos: [11, 2, 26], state: "minecraft:deepslate_brick_stairs{facing:south,half:bottom,shape:straight,waterlogged:false}"},
        {pos: [11, 2, 27], state: "trailiertales:coffin{facing:west,part:foot,state:inactive}", nbt: {id: "trailiertales:coffin", max_active_light_level: 7, uuid: "0ec9295a-d4f8-40e8-a332-1368f0c99921"}},
        {pos: [11, 2, 28], state: "minecraft:deepslate_brick_stairs{facing:north,half:bottom,shape:straight,waterlogged:false}"},
        {pos: [11, 2, 29], state: "minecraft:deepslate_bricks"},
        {pos: [11, 2, 30], state: "minecraft:deepslate_brick_stairs{facing:west,half:top,shape:straight,waterlogged:false}"},
        {pos: [11, 2, 31], state: "minecraft:deepslate_bricks"},
        {pos: [11, 2, 32], state: "minecraft:candle{candles:4,lit:false,waterlogged:false}"},
        {pos: [11, 2, 33], state: "minecraft:cave_air"},
        {pos: [11, 2, 34], state: "minecraft:decorated_pot{cracked:false,facing:south,waterlogged:false}", nbt: {id: "minecraft:decorated_pot"}},
        {pos: [11, 2, 35], state: "minecraft:deepslate_bricks"},
        {pos: [12, 2, 0], state: "minecraft:deepslate_bricks"},
        {pos: [12, 2, 1], state: "minecraft:deepslate_bricks"},
        {pos: [12, 2, 2], state: "minecraft:deepslate_bricks"},
        {pos: [12, 2, 3], state: "minecraft:candle{candles:4,lit:false,waterlogged:false}"},
        {pos: [12, 2, 4], state: "minecraft:candle{candles:4,lit:false,waterlogged:false}"},
        {pos: [12, 2, 5], state: "minecraft:cobbled_deepslate"},
        {pos: [12, 2, 6], state: "minecraft:deepslate_bricks"},
        {pos: [12, 2, 7], state: "minecraft:cobbled_deepslate"},
        {pos: [12, 2, 8], state: "minecraft:cobbled_deepslate"},
        {pos: [12, 2, 9], state: "minecraft:cobbled_deepslate"},
        {pos: [12, 2, 10], state: "minecraft:deepslate_bricks"},
        {pos: [12, 2, 11], state: "minecraft:candle{candles:4,lit:false,waterlogged:false}"},
        {pos: [12, 2, 12], state: "minecraft:cave_air"},
        {pos: [12, 2, 13], state: "minecraft:candle{candles:4,lit:false,waterlogged:false}"},
        {pos: [12, 2, 14], state: "minecraft:deepslate_bricks"},
        {pos: [12, 2, 15], state: "minecraft:piston_head{facing:east,short:false,type:sticky}"},
        {pos: [12, 2, 16], state: "minecraft:deepslate_bricks"},
        {pos: [12, 2, 17], state: "minecraft:decorated_pot{cracked:false,facing:west,waterlogged:false}", nbt: {id: "minecraft:decorated_pot"}},
        {pos: [12, 2, 18], state: "minecraft:candle{candles:4,lit:false,waterlogged:false}"},
        {pos: [12, 2, 19], state: "minecraft:candle{candles:4,lit:false,waterlogged:false}"},
        {pos: [12, 2, 20], state: "minecraft:candle{candles:4,lit:false,waterlogged:false}"},
        {pos: [12, 2, 21], state: "minecraft:candle{candles:4,lit:false,waterlogged:false}"},
        {pos: [12, 2, 22], state: "minecraft:candle{candles:4,lit:false,waterlogged:false}"},
        {pos: [12, 2, 23], state: "minecraft:candle{candles:4,lit:false,waterlogged:false}"},
        {pos: [12, 2, 24], state: "minecraft:candle{candles:4,lit:false,waterlogged:false}"},
        {pos: [12, 2, 25], state: "minecraft:candle{candles:4,lit:false,waterlogged:false}"},
        {pos: [12, 2, 26], state: "minecraft:candle{candles:4,lit:false,waterlogged:false}"},
        {pos: [12, 2, 27], state: "minecraft:candle{candles:4,lit:false,waterlogged:false}"},
        {pos: [12, 2, 28], state: "minecraft:candle{candles:4,lit:false,waterlogged:false}"},
        {pos: [12, 2, 29], state: "minecraft:candle{candles:4,lit:false,waterlogged:false}"},
        {pos: [12, 2, 30], state: "minecraft:candle{candles:4,lit:false,waterlogged:false}"},
        {pos: [12, 2, 31], state: "minecraft:candle{candles:4,lit:false,waterlogged:false}"},
        {pos: [12, 2, 32], state: "minecraft:cave_air"},
        {pos: [12, 2, 33], state: "minecraft:candle{candles:4,lit:false,waterlogged:false}"},
        {pos: [12, 2, 34], state: "minecraft:deepslate_brick_stairs{facing:south,half:top,shape:straight,waterlogged:false}"},
        {pos: [12, 2, 35], state: "minecraft:deepslate_bricks"},
        {pos: [13, 2, 0], state: "minecraft:deepslate_bricks"},
        {pos: [13, 2, 1], state: "minecraft:deepslate_bricks"},
        {pos: [13, 2, 2], state: "minecraft:deepslate_bricks"},
        {pos: [13, 2, 3], state: "minecraft:cobbled_deepslate"},
        {pos: [13, 2, 4], state: "minecraft:cave_air"},
        {pos: [13, 2, 5], state: "minecraft:cave_air"},
        {pos: [13, 2, 6], state: "minecraft:cave_air"},
        {pos: [13, 2, 7], state: "minecraft:cave_air"},
        {pos: [13, 2, 8], state: "minecraft:cobbled_deepslate"},
        {pos: [13, 2, 9], state: "minecraft:cobbled_deepslate"},
        {pos: [13, 2, 10], state: "minecraft:deepslate_bricks"},
        {pos: [13, 2, 11], state: "minecraft:candle{candles:4,lit:false,waterlogged:false}"},
        {pos: [13, 2, 12], state: "minecraft:cave_air"},
        {pos: [13, 2, 13], state: "minecraft:cave_air"},
        {pos: [13, 2, 14], state: "minecraft:cave_air"},
        {pos: [13, 2, 15], state: "minecraft:deepslate_tiles"},
        {pos: [13, 2, 16], state: "minecraft:cave_air"},
        {pos: [13, 2, 17], state: "minecraft:cave_air"},
        {pos: [13, 2, 18], state: "minecraft:cave_air"},
        {pos: [13, 2, 19], state: "minecraft:cave_air"},
        {pos: [13, 2, 20], state: "minecraft:cave_air"},
        {pos: [13, 2, 21], state: "minecraft:cave_air"},
        {pos: [13, 2, 22], state: "minecraft:cave_air"},
        {pos: [13, 2, 23], state: "minecraft:cave_air"},
        {pos: [13, 2, 24], state: "minecraft:cave_air"},
        {pos: [13, 2, 25], state: "minecraft:cave_air"},
        {pos: [13, 2, 26], state: "minecraft:cave_air"},
        {pos: [13, 2, 27], state: "minecraft:cave_air"},
        {pos: [13, 2, 28], state: "minecraft:cave_air"},
        {pos: [13, 2, 29], state: "minecraft:cave_air"},
        {pos: [13, 2, 30], state: "minecraft:cave_air"},
        {pos: [13, 2, 31], state: "minecraft:cave_air"},
        {pos: [13, 2, 32], state: "minecraft:cave_air"},
        {pos: [13, 2, 33], state: "minecraft:candle{candles:4,lit:false,waterlogged:false}"},
        {pos: [13, 2, 34], state: "minecraft:deepslate_brick_stairs{facing:south,half:top,shape:straight,waterlogged:false}"},
        {pos: [13, 2, 35], state: "minecraft:deepslate_bricks"},
        {pos: [14, 2, 0], state: "minecraft:deepslate_bricks"},
        {pos: [14, 2, 1], state: "minecraft:deepslate_bricks"},
        {pos: [14, 2, 2], state: "minecraft:deepslate_bricks"},
        {pos: [14, 2, 3], state: "minecraft:cobbled_deepslate"},
        {pos: [14, 2, 4], state: "minecraft:cobbled_deepslate"},
        {pos: [14, 2, 5], state: "minecraft:skeleton_skull{powered:false,rotation:12}", nbt: {id: "minecraft:skull"}},
        {pos: [14, 2, 6], state: "minecraft:deepslate_bricks"},
        {pos: [14, 2, 7], state: "minecraft:deepslate_bricks"},
        {pos: [14, 2, 8], state: "minecraft:deepslate_bricks"},
        {pos: [14, 2, 9], state: "minecraft:deepslate_bricks"},
        {pos: [14, 2, 10], state: "minecraft:deepslate_bricks"},
        {pos: [14, 2, 11], state: "minecraft:candle{candles:4,lit:false,waterlogged:false}"},
        {pos: [14, 2, 12], state: "minecraft:cave_air"},
        {pos: [14, 2, 13], state: "minecraft:skeleton_skull{powered:false,rotation:0}", nbt: {id: "minecraft:skull"}},
        {pos: [14, 2, 14], state: "minecraft:deepslate_bricks"},
        {pos: [14, 2, 15], state: "minecraft:deepslate_bricks"},
        {pos: [14, 2, 16], state: "minecraft:deepslate_bricks"},
        {pos: [14, 2, 17], state: "minecraft:candle{candles:4,lit:false,waterlogged:false}"},
        {pos: [14, 2, 18], state: "minecraft:candle{candles:4,lit:false,waterlogged:false}"},
        {pos: [14, 2, 19], state: "minecraft:candle{candles:4,lit:false,waterlogged:false}"},
        {pos: [14, 2, 20], state: "minecraft:candle{candles:4,lit:false,waterlogged:false}"},
        {pos: [14, 2, 21], state: "minecraft:candle{candles:4,lit:false,waterlogged:false}"},
        {pos: [14, 2, 22], state: "minecraft:candle{candles:4,lit:false,waterlogged:false}"},
        {pos: [14, 2, 23], state: "minecraft:decorated_pot{cracked:false,facing:south,waterlogged:false}", nbt: {id: "minecraft:decorated_pot"}},
        {pos: [14, 2, 24], state: "minecraft:candle{candles:4,lit:false,waterlogged:false}"},
        {pos: [14, 2, 25], state: "minecraft:candle{candles:4,lit:false,waterlogged:false}"},
        {pos: [14, 2, 26], state: "minecraft:candle{candles:4,lit:false,waterlogged:false}"},
        {pos: [14, 2, 27], state: "minecraft:candle{candles:4,lit:false,waterlogged:false}"},
        {pos: [14, 2, 28], state: "minecraft:decorated_pot{cracked:false,facing:south,waterlogged:false}", nbt: {id: "minecraft:decorated_pot"}},
        {pos: [14, 2, 29], state: "minecraft:skeleton_skull{powered:false,rotation:12}", nbt: {id: "minecraft:skull"}},
        {pos: [14, 2, 30], state: "minecraft:cave_air"},
        {pos: [14, 2, 31], state: "minecraft:decorated_pot{cracked:false,facing:south,waterlogged:false}", nbt: {id: "minecraft:decorated_pot"}},
        {pos: [14, 2, 32], state: "minecraft:cave_air"},
        {pos: [14, 2, 33], state: "minecraft:candle{candles:4,lit:false,waterlogged:false}"},
        {pos: [14, 2, 34], state: "minecraft:deepslate_brick_stairs{facing:south,half:top,shape:straight,waterlogged:false}"},
        {pos: [14, 2, 35], state: "minecraft:deepslate_bricks"},
        {pos: [15, 2, 2], state: "minecraft:deepslate_bricks"},
        {pos: [15, 2, 3], state: "minecraft:deepslate_bricks"},
        {pos: [15, 2, 4], state: "minecraft:deepslate_bricks"},
        {pos: [15, 2, 5], state: "minecraft:deepslate_bricks"},
        {pos: [15, 2, 6], state: "minecraft:deepslate_bricks"},
        {pos: [15, 2, 7], state: "minecraft:deepslate_brick_stairs{facing:west,half:top,shape:straight,waterlogged:false}"},
        {pos: [15, 2, 8], state: "minecraft:deepslate_brick_stairs{facing:west,half:top,shape:straight,waterlogged:false}"},
        {pos: [15, 2, 9], state: "minecraft:deepslate_brick_stairs{facing:west,half:top,shape:straight,waterlogged:false}"},
        {pos: [15, 2, 10], state: "minecraft:decorated_pot{cracked:false,facing:west,waterlogged:false}", nbt: {id: "minecraft:decorated_pot"}},
        {pos: [15, 2, 11], state: "minecraft:cave_air"},
        {pos: [15, 2, 12], state: "minecraft:cave_air"},
        {pos: [15, 2, 13], state: "minecraft:deepslate_brick_stairs{facing:south,half:top,shape:straight,waterlogged:false}"},
        {pos: [15, 2, 14], state: "minecraft:deepslate_bricks"},
        {pos: [15, 2, 15], state: "minecraft:deepslate_bricks"},
        {pos: [15, 2, 16], state: "minecraft:deepslate_bricks"},
        {pos: [15, 2, 17], state: "minecraft:deepslate_bricks"},
        {pos: [15, 2, 18], state: "minecraft:deepslate_brick_stairs{facing:east,half:top,shape:straight,waterlogged:false}"},
        {pos: [15, 2, 19], state: "minecraft:deepslate_bricks"},
        {pos: [15, 2, 20], state: "minecraft:deepslate_brick_stairs{facing:south,half:bottom,shape:straight,waterlogged:false}"},
        {pos: [15, 2, 21], state: "trailiertales:coffin{facing:west,part:head,state:inactive}", nbt: {id: "trailiertales:coffin"}},
        {pos: [15, 2, 22], state: "minecraft:deepslate_brick_stairs{facing:north,half:bottom,shape:straight,waterlogged:false}"},
        {pos: [15, 2, 23], state: "minecraft:deepslate_bricks"},
        {pos: [15, 2, 24], state: "minecraft:deepslate_brick_stairs{facing:east,half:top,shape:straight,waterlogged:false}"},
        {pos: [15, 2, 25], state: "minecraft:deepslate_bricks"},
        {pos: [15, 2, 26], state: "minecraft:deepslate_brick_stairs{facing:south,half:bottom,shape:straight,waterlogged:false}"},
        {pos: [15, 2, 27], state: "trailiertales:coffin{facing:west,part:head,state:inactive}", nbt: {id: "trailiertales:coffin"}},
        {pos: [15, 2, 28], state: "minecraft:deepslate_brick_stairs{facing:north,half:bottom,shape:straight,waterlogged:false}"},
        {pos: [15, 2, 29], state: "minecraft:deepslate_bricks"},
        {pos: [15, 2, 30], state: "minecraft:deepslate_brick_stairs{facing:east,half:top,shape:straight,waterlogged:false}"},
        {pos: [15, 2, 31], state: "minecraft:deepslate_bricks"},
        {pos: [15, 2, 32], state: "minecraft:candle{candles:4,lit:false,waterlogged:false}"},
        {pos: [15, 2, 33], state: "minecraft:cave_air"},
        {pos: [15, 2, 34], state: "minecraft:skeleton_skull{powered:false,rotation:0}", nbt: {id: "minecraft:skull"}},
        {pos: [15, 2, 35], state: "minecraft:deepslate_bricks"},
        {pos: [16, 2, 4], state: "minecraft:deepslate_bricks"},
        {pos: [16, 2, 5], state: "minecraft:deepslate_bricks"},
        {pos: [16, 2, 6], state: "minecraft:deepslate_bricks"},
        {pos: [16, 2, 7], state: "minecraft:skeleton_skull{powered:false,rotation:4}", nbt: {id: "minecraft:skull"}},
        {pos: [16, 2, 8], state: "minecraft:cave_air"},
        {pos: [16, 2, 9], state: "minecraft:cave_air"},
        {pos: [16, 2, 10], state: "minecraft:cave_air"},
        {pos: [16, 2, 11], state: "minecraft:cave_air"},
        {pos: [16, 2, 12], state: "minecraft:cave_air"},
        {pos: [16, 2, 13], state: "minecraft:deepslate_brick_stairs{facing:south,half:top,shape:straight,waterlogged:false}"},
        {pos: [16, 2, 14], state: "minecraft:deepslate_bricks"},
        {pos: [16, 2, 15], state: "minecraft:deepslate_bricks"},
        {pos: [16, 2, 16], state: "minecraft:deepslate_bricks"},
        {pos: [16, 2, 17], state: "minecraft:deepslate_bricks"},
        {pos: [16, 2, 18], state: "minecraft:deepslate_bricks"},
        {pos: [16, 2, 19], state: "minecraft:deepslate_bricks"},
        {pos: [16, 2, 20], state: "minecraft:deepslate_brick_stairs{facing:south,half:bottom,shape:straight,waterlogged:false}"},
        {pos: [16, 2, 21], state: "trailiertales:coffin{facing:west,part:foot,state:inactive}", nbt: {id: "trailiertales:coffin", max_active_light_level: 7, uuid: "8a09f825-2c55-4431-aa85-9b82b8eade06"}},
        {pos: [16, 2, 22], state: "minecraft:deepslate_brick_stairs{facing:north,half:bottom,shape:straight,waterlogged:false}"},
        {pos: [16, 2, 23], state: "minecraft:deepslate_bricks"},
        {pos: [16, 2, 24], state: "minecraft:deepslate_bricks"},
        {pos: [16, 2, 25], state: "minecraft:deepslate_bricks"},
        {pos: [16, 2, 26], state: "minecraft:deepslate_brick_stairs{facing:south,half:bottom,shape:straight,waterlogged:false}"},
        {pos: [16, 2, 27], state: "trailiertales:coffin{facing:west,part:foot,state:inactive}", nbt: {id: "trailiertales:coffin", max_active_light_level: 7, uuid: "8a09f825-2c55-4431-aa85-9b82b8eade06"}},
        {pos: [16, 2, 28], state: "minecraft:deepslate_brick_stairs{facing:north,half:bottom,shape:straight,waterlogged:false}"},
        {pos: [16, 2, 29], state: "minecraft:deepslate_bricks"},
        {pos: [16, 2, 30], state: "minecraft:deepslate_bricks"},
        {pos: [16, 2, 31], state: "minecraft:deepslate_bricks"},
        {pos: [16, 2, 32], state: "minecraft:candle{candles:4,lit:false,waterlogged:false}"},
        {pos: [16, 2, 33], state: "minecraft:candle{candles:4,lit:false,waterlogged:false}"},
        {pos: [16, 2, 34], state: "minecraft:candle{candles:4,lit:false,waterlogged:false}"},
        {pos: [16, 2, 35], state: "minecraft:deepslate_bricks"},
        {pos: [17, 2, 4], state: "minecraft:deepslate_bricks"},
        {pos: [17, 2, 5], state: "minecraft:deepslate_bricks"},
        {pos: [17, 2, 6], state: "minecraft:deepslate_bricks"},
        {pos: [17, 2, 7], state: "minecraft:candle{candles:4,lit:false,waterlogged:false}"},
        {pos: [17, 2, 8], state: "minecraft:cave_air"},
        {pos: [17, 2, 9], state: "minecraft:cave_air"},
        {pos: [17, 2, 10], state: "minecraft:candle{candles:4,lit:false,waterlogged:false}"},
        {pos: [17, 2, 11], state: "minecraft:candle{candles:4,lit:false,waterlogged:false}"},
        {pos: [17, 2, 12], state: "minecraft:candle{candles:4,lit:false,waterlogged:false}"},
        {pos: [17, 2, 13], state: "minecraft:deepslate_brick_stairs{facing:south,half:top,shape:straight,waterlogged:false}"},
        {pos: [17, 2, 14], state: "minecraft:deepslate_bricks"},
        {pos: [17, 2, 17], state: "minecraft:deepslate_bricks"},
        {pos: [17, 2, 18], state: "minecraft:deepslate_bricks"},
        {pos: [17, 2, 19], state: "minecraft:deepslate_bricks"},
        {pos: [17, 2, 20], state: "minecraft:deepslate_bricks"},
        {pos: [17, 2, 21], state: "minecraft:deepslate_bricks"},
        {pos: [17, 2, 22], state: "minecraft:deepslate_bricks"},
        {pos: [17, 2, 23], state: "minecraft:deepslate_bricks"},
        {pos: [17, 2, 24], state: "minecraft:deepslate_bricks"},
        {pos: [17, 2, 25], state: "minecraft:deepslate_bricks"},
        {pos: [17, 2, 26], state: "minecraft:deepslate_bricks"},
        {pos: [17, 2, 27], state: "minecraft:deepslate_bricks"},
        {pos: [17, 2, 28], state: "minecraft:deepslate_bricks"},
        {pos: [17, 2, 29], state: "minecraft:deepslate_bricks"},
        {pos: [17, 2, 30], state: "minecraft:deepslate_bricks"},
        {pos: [17, 2, 31], state: "minecraft:deepslate_bricks"},
        {pos: [17, 2, 32], state: "minecraft:deepslate_brick_stairs{facing:south,half:bottom,shape:straight,waterlogged:false}"},
        {pos: [17, 2, 33], state: "minecraft:chest{facing:west,type:single,waterlogged:false}", nbt: {Items: [], id: "minecraft:chest"}},
        {pos: [17, 2, 34], state: "minecraft:deepslate_brick_stairs{facing:north,half:bottom,shape:straight,waterlogged:false}"},
        {pos: [17, 2, 35], state: "minecraft:deepslate_bricks"},
        {pos: [18, 2, 4], state: "minecraft:deepslate_bricks"},
        {pos: [18, 2, 5], state: "minecraft:deepslate_bricks"},
        {pos: [18, 2, 6], state: "minecraft:deepslate_bricks"},
        {pos: [18, 2, 7], state: "minecraft:candle{candles:4,lit:false,waterlogged:false}"},
        {pos: [18, 2, 8], state: "minecraft:cave_air"},
        {pos: [18, 2, 9], state: "minecraft:candle{candles:4,lit:false,waterlogged:false}"},
        {pos: [18, 2, 10], state: "minecraft:deepslate_bricks"},
        {pos: [18, 2, 11], state: "minecraft:deepslate_bricks"},
        {pos: [18, 2, 12], state: "minecraft:deepslate_bricks"},
        {pos: [18, 2, 13], state: "minecraft:deepslate_bricks"},
        {pos: [18, 2, 14], state: "minecraft:deepslate_bricks"},
        {pos: [18, 2, 17], state: "minecraft:deepslate_bricks"},
        {pos: [18, 2, 18], state: "minecraft:deepslate_bricks"},
        {pos: [18, 2, 19], state: "minecraft:deepslate_bricks"},
        {pos: [18, 2, 20], state: "minecraft:deepslate_bricks"},
        {pos: [18, 2, 21], state: "minecraft:deepslate_bricks"},
        {pos: [18, 2, 22], state: "minecraft:deepslate_bricks"},
        {pos: [18, 2, 23], state: "minecraft:deepslate_bricks"},
        {pos: [18, 2, 24], state: "minecraft:deepslate_bricks"},
        {pos: [18, 2, 25], state: "minecraft:deepslate_bricks"},
        {pos: [18, 2, 26], state: "minecraft:deepslate_bricks"},
        {pos: [18, 2, 27], state: "minecraft:deepslate_bricks"},
        {pos: [18, 2, 28], state: "minecraft:deepslate_bricks"},
        {pos: [18, 2, 29], state: "minecraft:deepslate_bricks"},
        {pos: [18, 2, 30], state: "minecraft:deepslate_bricks"},
        {pos: [18, 2, 31], state: "minecraft:deepslate_bricks"},
        {pos: [18, 2, 32], state: "minecraft:deepslate_bricks"},
        {pos: [18, 2, 33], state: "minecraft:deepslate_bricks"},
        {pos: [18, 2, 34], state: "minecraft:deepslate_bricks"},
        {pos: [18, 2, 35], state: "minecraft:deepslate_bricks"},
        {pos: [19, 2, 4], state: "minecraft:deepslate_bricks"},
        {pos: [19, 2, 5], state: "minecraft:deepslate_bricks"},
        {pos: [19, 2, 6], state: "minecraft:deepslate_bricks"},
        {pos: [19, 2, 7], state: "minecraft:candle{candles:4,lit:false,waterlogged:false}"},
        {pos: [19, 2, 8], state: "minecraft:cave_air"},
        {pos: [19, 2, 9], state: "minecraft:candle{candles:4,lit:false,waterlogged:false}"},
        {pos: [19, 2, 10], state: "minecraft:deepslate_brick_stairs{facing:south,half:top,shape:straight,waterlogged:false}"},
        {pos: [19, 2, 11], state: "minecraft:deepslate_bricks"},
        {pos: [19, 2, 12], state: "minecraft:deepslate_bricks"},
        {pos: [20, 2, 4], state: "minecraft:deepslate_bricks"},
        {pos: [20, 2, 5], state: "minecraft:deepslate_bricks"},
        {pos: [20, 2, 6], state: "minecraft:deepslate_bricks"},
        {pos: [20, 2, 7], state: "minecraft:candle{candles:4,lit:false,waterlogged:false}"},
        {pos: [20, 2, 8], state: "minecraft:jigsaw{orientation:east_up}", nbt: {final_state: "minecraft:cave_air", id: "minecraft:jigsaw", joint: "rollable", name: "trailiertales:corridor", placement_priority: 0, pool: "trailiertales:catacombs/corridor_connector", selection_priority: 0, target: "trailiertales:corridor"}},
        {pos: [20, 2, 9], state: "minecraft:candle{candles:4,lit:false,waterlogged:false}"},
        {pos: [20, 2, 10], state: "minecraft:deepslate_bricks"},
        {pos: [20, 2, 11], state: "minecraft:deepslate_bricks"},
        {pos: [20, 2, 12], state: "minecraft:deepslate_bricks"},
        {pos: [0, 3, 5], state: "minecraft:deepslate_bricks"},
        {pos: [0, 3, 6], state: "minecraft:deepslate_bricks"},
        {pos: [0, 3, 7], state: "minecraft:cave_air"},
        {pos: [0, 3, 8], state: "minecraft:cave_air"},
        {pos: [0, 3, 9], state: "minecraft:cave_air"},
        {pos: [0, 3, 10], state: "minecraft:deepslate_bricks"},
        {pos: [0, 3, 11], state: "minecraft:deepslate_bricks"},
        {pos: [1, 3, 5], state: "minecraft:deepslate_bricks"},
        {pos: [1, 3, 6], state: "minecraft:skeleton_skull{powered:false,rotation:8}", nbt: {id: "minecraft:skull"}},
        {pos: [1, 3, 7], state: "minecraft:cave_air"},
        {pos: [1, 3, 8], state: "minecraft:cave_air"},
        {pos: [1, 3, 9], state: "minecraft:cave_air"},
        {pos: [1, 3, 10], state: "minecraft:skeleton_skull{powered:false,rotation:0}", nbt: {id: "minecraft:skull"}},
        {pos: [1, 3, 11], state: "minecraft:deepslate_bricks"},
        {pos: [2, 3, 5], state: "minecraft:deepslate_bricks"},
        {pos: [2, 3, 6], state: "minecraft:deepslate_bricks"},
        {pos: [2, 3, 7], state: "minecraft:cave_air"},
        {pos: [2, 3, 8], state: "minecraft:cave_air"},
        {pos: [2, 3, 9], state: "minecraft:cave_air"},
        {pos: [2, 3, 10], state: "minecraft:deepslate_bricks"},
        {pos: [2, 3, 11], state: "minecraft:deepslate_bricks"},
        {pos: [2, 3, 12], state: "minecraft:deepslate_bricks"},
        {pos: [2, 3, 13], state: "minecraft:deepslate_bricks"},
        {pos: [2, 3, 14], state: "minecraft:deepslate_bricks"},
        {pos: [3, 3, 5], state: "minecraft:deepslate_bricks"},
        {pos: [3, 3, 6], state: "minecraft:skeleton_skull{powered:false,rotation:8}", nbt: {id: "minecraft:skull"}},
        {pos: [3, 3, 7], state: "minecraft:cave_air"},
        {pos: [3, 3, 8], state: "minecraft:cave_air"},
        {pos: [3, 3, 9], state: "minecraft:cave_air"},
        {pos: [3, 3, 10], state: "minecraft:cave_air"},
        {pos: [3, 3, 11], state: "minecraft:cave_air"},
        {pos: [3, 3, 12], state: "minecraft:cave_air"},
        {pos: [3, 3, 13], state: "minecraft:deepslate_bricks"},
        {pos: [3, 3, 14], state: "minecraft:deepslate_bricks"},
        {pos: [4, 3, 5], state: "minecraft:deepslate_bricks"},
        {pos: [4, 3, 6], state: "minecraft:deepslate_bricks"},
        {pos: [4, 3, 7], state: "minecraft:cave_air"},
        {pos: [4, 3, 8], state: "minecraft:cave_air"},
        {pos: [4, 3, 9], state: "minecraft:cave_air"},
        {pos: [4, 3, 10], state: "minecraft:cave_air"},
        {pos: [4, 3, 11], state: "minecraft:cave_air"},
        {pos: [4, 3, 12], state: "minecraft:cave_air"},
        {pos: [4, 3, 13], state: "minecraft:deepslate_bricks"},
        {pos: [4, 3, 14], state: "minecraft:deepslate_bricks"},
        {pos: [5, 3, 5], state: "minecraft:deepslate_bricks"},
        {pos: [5, 3, 6], state: "minecraft:skeleton_skull{powered:false,rotation:8}", nbt: {id: "minecraft:skull"}},
        {pos: [5, 3, 7], state: "minecraft:cave_air"},
        {pos: [5, 3, 8], state: "minecraft:cave_air"},
        {pos: [5, 3, 9], state: "minecraft:cave_air"},
