{
    DataVersion: 3953,
    size: [20, 15, 25],
    data: [
        {pos: [7, 0, 10], state: "minecraft:deepslate_bricks"},
        {pos: [7, 0, 11], state: "minecraft:deepslate_bricks"},
        {pos: [7, 0, 12], state: "minecraft:deepslate_bricks"},
        {pos: [7, 0, 13], state: "minecraft:deepslate_bricks"},
        {pos: [7, 0, 14], state: "minecraft:deepslate_bricks"},
        {pos: [7, 0, 15], state: "minecraft:deepslate_bricks"},
        {pos: [7, 0, 16], state: "minecraft:deepslate_bricks"},
        {pos: [8, 0, 10], state: "minecraft:deepslate_bricks"},
        {pos: [8, 0, 11], state: "minecraft:deepslate_bricks"},
        {pos: [8, 0, 12], state: "minecraft:deepslate_bricks"},
        {pos: [8, 0, 13], state: "minecraft:deepslate_bricks"},
        {pos: [8, 0, 14], state: "minecraft:deepslate_bricks"},
        {pos: [8, 0, 15], state: "minecraft:deepslate_bricks"},
        {pos: [8, 0, 16], state: "minecraft:deepslate_bricks"},
        {pos: [9, 0, 10], state: "minecraft:deepslate_bricks"},
        {pos: [9, 0, 11], state: "minecraft:deepslate_bricks"},
        {pos: [9, 0, 12], state: "minecraft:deepslate_bricks"},
        {pos: [9, 0, 13], state: "minecraft:deepslate_bricks"},
        {pos: [9, 0, 14], state: "minecraft:deepslate_bricks"},
        {pos: [9, 0, 15], state: "minecraft:deepslate_bricks"},
        {pos: [9, 0, 16], state: "minecraft:deepslate_bricks"},
        {pos: [10, 0, 10], state: "minecraft:deepslate_bricks"},
        {pos: [10, 0, 11], state: "minecraft:deepslate_bricks"},
        {pos: [10, 0, 12], state: "minecraft:deepslate_bricks"},
        {pos: [10, 0, 13], state: "minecraft:deepslate_bricks"},
        {pos: [10, 0, 14], state: "minecraft:deepslate_bricks"},
        {pos: [10, 0, 15], state: "minecraft:deepslate_bricks"},
        {pos: [10, 0, 16], state: "minecraft:deepslate_bricks"},
        {pos: [11, 0, 10], state: "minecraft:deepslate_bricks"},
        {pos: [11, 0, 11], state: "minecraft:deepslate_bricks"},
        {pos: [11, 0, 12], state: "minecraft:deepslate_bricks"},
        {pos: [11, 0, 13], state: "minecraft:deepslate_bricks"},
        {pos: [11, 0, 14], state: "minecraft:deepslate_bricks"},
        {pos: [11, 0, 15], state: "minecraft:deepslate_bricks"},
        {pos: [11, 0, 16], state: "minecraft:deepslate_bricks"},
        {pos: [12, 0, 10], state: "minecraft:deepslate_bricks"},
        {pos: [12, 0, 11], state: "minecraft:deepslate_bricks"},
        {pos: [12, 0, 12], state: "minecraft:deepslate_bricks"},
        {pos: [12, 0, 13], state: "minecraft:deepslate_bricks"},
        {pos: [12, 0, 14], state: "minecraft:deepslate_bricks"},
        {pos: [12, 0, 15], state: "minecraft:deepslate_bricks"},
        {pos: [12, 0, 16], state: "minecraft:deepslate_bricks"},
        {pos: [13, 0, 10], state: "minecraft:deepslate_bricks"},
        {pos: [13, 0, 11], state: "minecraft:deepslate_bricks"},
        {pos: [13, 0, 12], state: "minecraft:deepslate_bricks"},
        {pos: [13, 0, 13], state: "minecraft:deepslate_bricks"},
        {pos: [13, 0, 14], state: "minecraft:deepslate_bricks"},
        {pos: [13, 0, 15], state: "minecraft:deepslate_bricks"},
        {pos: [13, 0, 16], state: "minecraft:deepslate_bricks"},
        {pos: [14, 0, 10], state: "minecraft:deepslate_bricks"},
        {pos: [14, 0, 11], state: "minecraft:deepslate_bricks"},
        {pos: [14, 0, 12], state: "minecraft:deepslate_bricks"},
        {pos: [14, 0, 13], state: "minecraft:deepslate_bricks"},
        {pos: [14, 0, 14], state: "minecraft:deepslate_bricks"},
        {pos: [14, 0, 15], state: "minecraft:deepslate_bricks"},
        {pos: [14, 0, 16], state: "minecraft:deepslate_bricks"},
        {pos: [15, 0, 10], state: "minecraft:deepslate_bricks"},
        {pos: [15, 0, 11], state: "minecraft:deepslate_bricks"},
        {pos: [15, 0, 12], state: "minecraft:deepslate_bricks"},
        {pos: [15, 0, 13], state: "minecraft:deepslate_bricks"},
        {pos: [15, 0, 14], state: "minecraft:deepslate_bricks"},
        {pos: [15, 0, 15], state: "minecraft:deepslate_bricks"},
        {pos: [15, 0, 16], state: "minecraft:deepslate_bricks"},
        {pos: [16, 0, 10], state: "minecraft:deepslate_bricks"},
        {pos: [16, 0, 11], state: "minecraft:deepslate_bricks"},
        {pos: [16, 0, 12], state: "minecraft:deepslate_bricks"},
        {pos: [16, 0, 13], state: "minecraft:deepslate_bricks"},
        {pos: [16, 0, 14], state: "minecraft:deepslate_bricks"},
        {pos: [16, 0, 15], state: "minecraft:deepslate_bricks"},
        {pos: [16, 0, 16], state: "minecraft:deepslate_bricks"},
        {pos: [17, 0, 10], state: "minecraft:deepslate_bricks"},
        {pos: [17, 0, 11], state: "minecraft:deepslate_bricks"},
        {pos: [17, 0, 12], state: "minecraft:deepslate_bricks"},
        {pos: [17, 0, 13], state: "minecraft:deepslate_bricks"},
        {pos: [17, 0, 14], state: "minecraft:deepslate_bricks"},
        {pos: [17, 0, 15], state: "minecraft:deepslate_bricks"},
        {pos: [17, 0, 16], state: "minecraft:deepslate_bricks"},
        {pos: [18, 0, 10], state: "minecraft:deepslate_bricks"},
        {pos: [18, 0, 11], state: "minecraft:deepslate_bricks"},
        {pos: [18, 0, 12], state: "minecraft:deepslate_bricks"},
        {pos: [18, 0, 13], state: "minecraft:deepslate_bricks"},
        {pos: [18, 0, 14], state: "minecraft:deepslate_bricks"},
        {pos: [18, 0, 15], state: "minecraft:deepslate_bricks"},
        {pos: [18, 0, 16], state: "minecraft:deepslate_bricks"},
        {pos: [19, 0, 11], state: "minecraft:deepslate_bricks"},
        {pos: [19, 0, 12], state: "minecraft:deepslate_bricks"},
        {pos: [19, 0, 13], state: "minecraft:deepslate_bricks"},
        {pos: [7, 1, 10], state: "minecraft:deepslate_bricks"},
        {pos: [7, 1, 11], state: "minecraft:deepslate_bricks"},
        {pos: [7, 1, 12], state: "minecraft:deepslate_bricks"},
        {pos: [7, 1, 13], state: "minecraft:deepslate_bricks"},
        {pos: [7, 1, 14], state: "minecraft:deepslate_bricks"},
        {pos: [7, 1, 15], state: "minecraft:deepslate_bricks"},
        {pos: [7, 1, 16], state: "minecraft:deepslate_bricks"},
        {pos: [8, 1, 10], state: "minecraft:deepslate_bricks"},
        {pos: [8, 1, 11], state: "minecraft:redstone_wall_torch{facing:west,lit:true}"},
        {pos: [8, 1, 12], state: "minecraft:redstone_wall_torch{facing:west,lit:true}"},
        {pos: [8, 1, 13], state: "minecraft:redstone_wall_torch{facing:west,lit:true}"},
        {pos: [8, 1, 14], state: "minecraft:deepslate_bricks"},
        {pos: [8, 1, 15], state: "minecraft:deepslate_bricks"},
        {pos: [8, 1, 16], state: "minecraft:deepslate_bricks"},
        {pos: [9, 1, 10], state: "minecraft:deepslate_bricks"},
        {pos: [9, 1, 11], state: "minecraft:deepslate_bricks"},
        {pos: [9, 1, 12], state: "minecraft:deepslate_bricks"},
        {pos: [9, 1, 13], state: "minecraft:deepslate_bricks"},
        {pos: [9, 1, 14], state: "minecraft:deepslate_bricks"},
        {pos: [9, 1, 15], state: "minecraft:deepslate_bricks"},
        {pos: [9, 1, 16], state: "minecraft:deepslate_bricks"},
        {pos: [10, 1, 10], state: "minecraft:deepslate_bricks"},
        {pos: [10, 1, 11], state: "minecraft:repeater{delay:1,facing:east,locked:false,powered:false}"},
        {pos: [10, 1, 12], state: "minecraft:repeater{delay:1,facing:east,locked:false,powered:false}"},
        {pos: [10, 1, 13], state: "minecraft:repeater{delay:1,facing:east,locked:false,powered:false}"},
        {pos: [10, 1, 14], state: "minecraft:deepslate_bricks"},
        {pos: [10, 1, 15], state: "minecraft:deepslate_bricks"},
        {pos: [10, 1, 16], state: "minecraft:deepslate_bricks"},
        {pos: [11, 1, 10], state: "minecraft:deepslate_bricks"},
        {pos: [11, 1, 11], state: "minecraft:redstone_wire{east:none,north:none,power:0,south:side,west:side}"},
        {pos: [11, 1, 12], state: "minecraft:redstone_wire{east:side,north:side,power:0,south:side,west:side}"},
        {pos: [11, 1, 13], state: "minecraft:redstone_wire{east:none,north:side,power:0,south:none,west:side}"},
        {pos: [11, 1, 14], state: "minecraft:deepslate_bricks"},
        {pos: [11, 1, 15], state: "minecraft:deepslate_bricks"},
        {pos: [11, 1, 16], state: "minecraft:deepslate_bricks"},
        {pos: [12, 1, 10], state: "minecraft:deepslate_bricks"},
        {pos: [12, 1, 11], state: "minecraft:deepslate_bricks"},
        {pos: [12, 1, 12], state: "minecraft:redstone_wall_torch{facing:west,lit:false}"},
        {pos: [12, 1, 13], state: "minecraft:deepslate_bricks"},
        {pos: [12, 1, 14], state: "minecraft:deepslate_bricks"},
        {pos: [12, 1, 15], state: "minecraft:deepslate_bricks"},
        {pos: [12, 1, 16], state: "minecraft:deepslate_bricks"},
        {pos: [13, 1, 10], state: "minecraft:deepslate_bricks"},
        {pos: [13, 1, 11], state: "minecraft:deepslate_bricks"},
        {pos: [13, 1, 12], state: "minecraft:deepslate_bricks"},
        {pos: [13, 1, 13], state: "minecraft:deepslate_bricks"},
        {pos: [13, 1, 14], state: "minecraft:deepslate_bricks"},
        {pos: [13, 1, 15], state: "minecraft:deepslate_bricks"},
        {pos: [13, 1, 16], state: "minecraft:deepslate_bricks"},
        {pos: [14, 1, 10], state: "minecraft:deepslate_bricks"},
        {pos: [14, 1, 11], state: "minecraft:deepslate_bricks"},
        {pos: [14, 1, 12], state: "minecraft:repeater{delay:1,facing:east,locked:false,powered:true}"},
        {pos: [14, 1, 13], state: "minecraft:deepslate_bricks"},
        {pos: [14, 1, 14], state: "minecraft:deepslate_bricks"},
        {pos: [14, 1, 15], state: "minecraft:deepslate_bricks"},
        {pos: [14, 1, 16], state: "minecraft:deepslate_bricks"},
        {pos: [15, 1, 10], state: "minecraft:deepslate_bricks"},
        {pos: [15, 1, 11], state: "minecraft:cave_air"},
        {pos: [15, 1, 12], state: "minecraft:redstone_block"},
        {pos: [15, 1, 13], state: "minecraft:piston{extended:false,facing:north}"},
        {pos: [15, 1, 14], state: "minecraft:repeater{delay:1,facing:south,locked:false,powered:false}"},
        {pos: [15, 1, 15], state: "minecraft:redstone_wire{east:side,north:side,power:0,south:none,west:none}"},
        {pos: [15, 1, 16], state: "minecraft:deepslate_bricks"},
        {pos: [16, 1, 10], state: "minecraft:deepslate_bricks"},
        {pos: [16, 1, 11], state: "minecraft:deepslate_bricks"},
        {pos: [16, 1, 12], state: "minecraft:deepslate_bricks"},
        {pos: [16, 1, 13], state: "minecraft:deepslate_bricks"},
        {pos: [16, 1, 14], state: "minecraft:deepslate_bricks"},
        {pos: [16, 1, 15], state: "minecraft:redstone_wire{east:side,north:none,power:0,south:none,west:side}"},
        {pos: [16, 1, 16], state: "minecraft:deepslate_bricks"},
        {pos: [17, 1, 10], state: "minecraft:deepslate_bricks"},
        {pos: [17, 1, 11], state: "minecraft:deepslate_bricks"},
        {pos: [17, 1, 12], state: "minecraft:redstone_wire{east:up,north:none,power:0,south:side,west:none}"},
        {pos: [17, 1, 13], state: "minecraft:repeater{delay:1,facing:north,locked:false,powered:false}"},
        {pos: [17, 1, 14], state: "minecraft:redstone_wire{east:none,north:side,power:0,south:side,west:none}"},
        {pos: [17, 1, 15], state: "minecraft:redstone_wire{east:none,north:side,power:0,south:none,west:side}"},
        {pos: [17, 1, 16], state: "minecraft:deepslate_bricks"},
        {pos: [18, 1, 10], state: "minecraft:deepslate_bricks"},
        {pos: [18, 1, 11], state: "minecraft:deepslate_bricks"},
        {pos: [18, 1, 12], state: "minecraft:deepslate_bricks"},
        {pos: [18, 1, 13], state: "minecraft:deepslate_bricks"},
        {pos: [18, 1, 14], state: "minecraft:deepslate_bricks"},
        {pos: [18, 1, 15], state: "minecraft:deepslate_bricks"},
        {pos: [18, 1, 16], state: "minecraft:deepslate_bricks"},
        {pos: [19, 1, 11], state: "minecraft:deepslate_bricks"},
        {pos: [19, 1, 12], state: "minecraft:deepslate_bricks"},
        {pos: [19, 1, 13], state: "minecraft:deepslate_bricks"},
        {pos: [0, 2, 9], state: "minecraft:deepslate{axis:y}"},
        {pos: [0, 2, 10], state: "minecraft:deepslate{axis:y}"},
        {pos: [0, 2, 11], state: "minecraft:deepslate{axis:y}"},
        {pos: [0, 2, 12], state: "minecraft:deepslate{axis:y}"},
        {pos: [0, 2, 13], state: "minecraft:deepslate{axis:y}"},
        {pos: [0, 2, 14], state: "minecraft:deepslate{axis:y}"},
        {pos: [0, 2, 15], state: "minecraft:deepslate{axis:y}"},
        {pos: [1, 2, 9], state: "minecraft:deepslate{axis:y}"},
        {pos: [1, 2, 10], state: "minecraft:deepslate{axis:y}"},
        {pos: [1, 2, 11], state: "minecraft:deepslate{axis:y}"},
        {pos: [1, 2, 12], state: "minecraft:deepslate{axis:y}"},
        {pos: [1, 2, 13], state: "minecraft:deepslate{axis:y}"},
        {pos: [1, 2, 14], state: "minecraft:deepslate{axis:y}"},
        {pos: [1, 2, 15], state: "minecraft:deepslate{axis:y}"},
        {pos: [2, 2, 5], state: "minecraft:deepslate{axis:y}"},
        {pos: [2, 2, 6], state: "minecraft:deepslate{axis:y}"},
        {pos: [2, 2, 7], state: "minecraft:deepslate{axis:y}"},
        {pos: [2, 2, 8], state: "minecraft:deepslate{axis:y}"},
        {pos: [2, 2, 9], state: "minecraft:deepslate{axis:y}"},
        {pos: [2, 2, 10], state: "minecraft:deepslate{axis:y}"},
        {pos: [2, 2, 11], state: "minecraft:deepslate{axis:y}"},
        {pos: [2, 2, 12], state: "minecraft:deepslate{axis:y}"},
        {pos: [2, 2, 13], state: "minecraft:deepslate{axis:y}"},
        {pos: [2, 2, 14], state: "minecraft:deepslate{axis:y}"},
        {pos: [2, 2, 15], state: "minecraft:deepslate{axis:y}"},
        {pos: [2, 2, 16], state: "minecraft:deepslate{axis:y}"},
        {pos: [2, 2, 17], state: "minecraft:deepslate{axis:y}"},
        {pos: [2, 2, 18], state: "minecraft:deepslate{axis:y}"},
        {pos: [2, 2, 19], state: "minecraft:deepslate{axis:y}"},
        {pos: [3, 2, 5], state: "minecraft:deepslate{axis:y}"},
        {pos: [3, 2, 6], state: "minecraft:deepslate{axis:y}"},
        {pos: [3, 2, 7], state: "minecraft:deepslate{axis:y}"},
        {pos: [3, 2, 8], state: "minecraft:deepslate{axis:y}"},
        {pos: [3, 2, 9], state: "minecraft:deepslate{axis:y}"},
        {pos: [3, 2, 10], state: "minecraft:deepslate{axis:y}"},
        {pos: [3, 2, 11], state: "minecraft:deepslate{axis:y}"},
        {pos: [3, 2, 12], state: "minecraft:deepslate{axis:y}"},
        {pos: [3, 2, 13], state: "minecraft:deepslate{axis:y}"},
        {pos: [3, 2, 14], state: "minecraft:deepslate{axis:y}"},
        {pos: [3, 2, 15], state: "minecraft:deepslate{axis:y}"},
        {pos: [3, 2, 16], state: "minecraft:deepslate{axis:y}"},
        {pos: [3, 2, 17], state: "minecraft:deepslate{axis:y}"},
        {pos: [3, 2, 18], state: "minecraft:deepslate{axis:y}"},
        {pos: [3, 2, 19], state: "minecraft:deepslate{axis:y}"},
        {pos: [4, 2, 0], state: "minecraft:deepslate{axis:y}"},
        {pos: [4, 2, 1], state: "minecraft:deepslate{axis:y}"},
        {pos: [4, 2, 2], state: "minecraft:deepslate{axis:y}"},
        {pos: [4, 2, 3], state: "minecraft:deepslate{axis:y}"},
        {pos: [4, 2, 4], state: "minecraft:deepslate{axis:y}"},
        {pos: [4, 2, 5], state: "minecraft:deepslate{axis:y}"},
        {pos: [4, 2, 6], state: "minecraft:deepslate{axis:y}"},
        {pos: [4, 2, 7], state: "minecraft:deepslate{axis:y}"},
        {pos: [4, 2, 8], state: "minecraft:deepslate{axis:y}"},
        {pos: [4, 2, 9], state: "minecraft:deepslate{axis:y}"},
        {pos: [4, 2, 10], state: "minecraft:deepslate{axis:y}"},
        {pos: [4, 2, 11], state: "minecraft:deepslate{axis:y}"},
        {pos: [4, 2, 12], state: "minecraft:deepslate{axis:y}"},
        {pos: [4, 2, 13], state: "minecraft:deepslate{axis:y}"},
        {pos: [4, 2, 14], state: "minecraft:deepslate{axis:y}"},
        {pos: [4, 2, 15], state: "minecraft:deepslate{axis:y}"},
        {pos: [4, 2, 16], state: "minecraft:deepslate{axis:y}"},
        {pos: [4, 2, 17], state: "minecraft:deepslate{axis:y}"},
        {pos: [4, 2, 18], state: "minecraft:deepslate{axis:y}"},
        {pos: [4, 2, 19], state: "minecraft:deepslate{axis:y}"},
        {pos: [4, 2, 20], state: "minecraft:deepslate{axis:y}"},
        {pos: [4, 2, 21], state: "minecraft:deepslate{axis:y}"},
        {pos: [4, 2, 22], state: "minecraft:deepslate{axis:y}"},
        {pos: [4, 2, 23], state: "minecraft:deepslate{axis:y}"},
        {pos: [4, 2, 24], state: "minecraft:deepslate{axis:y}"},
        {pos: [5, 2, 0], state: "minecraft:deepslate{axis:y}"},
        {pos: [5, 2, 1], state: "minecraft:deepslate{axis:y}"},
        {pos: [5, 2, 2], state: "minecraft:deepslate{axis:y}"},
        {pos: [5, 2, 3], state: "minecraft:deepslate{axis:y}"},
        {pos: [5, 2, 4], state: "minecraft:deepslate{axis:y}"},
        {pos: [5, 2, 5], state: "minecraft:deepslate{axis:y}"},
        {pos: [5, 2, 6], state: "minecraft:deepslate{axis:y}"},
        {pos: [5, 2, 7], state: "minecraft:deepslate{axis:y}"},
        {pos: [5, 2, 8], state: "minecraft:deepslate{axis:y}"},
        {pos: [5, 2, 9], state: "minecraft:deepslate{axis:y}"},
        {pos: [5, 2, 10], state: "minecraft:deepslate{axis:y}"},
        {pos: [5, 2, 11], state: "minecraft:deepslate{axis:y}"},
        {pos: [5, 2, 12], state: "minecraft:deepslate{axis:y}"},
        {pos: [5, 2, 13], state: "minecraft:deepslate{axis:y}"},
        {pos: [5, 2, 14], state: "minecraft:deepslate{axis:y}"},
        {pos: [5, 2, 15], state: "minecraft:deepslate{axis:y}"},
        {pos: [5, 2, 16], state: "minecraft:deepslate{axis:y}"},
        {pos: [5, 2, 17], state: "minecraft:deepslate{axis:y}"},
        {pos: [5, 2, 18], state: "minecraft:deepslate{axis:y}"},
        {pos: [5, 2, 19], state: "minecraft:deepslate{axis:y}"},
        {pos: [5, 2, 20], state: "minecraft:deepslate{axis:y}"},
        {pos: [5, 2, 21], state: "minecraft:deepslate{axis:y}"},
        {pos: [5, 2, 22], state: "minecraft:deepslate{axis:y}"},
        {pos: [5, 2, 23], state: "minecraft:deepslate{axis:y}"},
        {pos: [5, 2, 24], state: "minecraft:deepslate{axis:y}"},
        {pos: [6, 2, 0], state: "minecraft:deepslate{axis:y}"},
        {pos: [6, 2, 1], state: "minecraft:deepslate{axis:y}"},
        {pos: [6, 2, 2], state: "minecraft:deepslate{axis:y}"},
        {pos: [6, 2, 3], state: "minecraft:deepslate{axis:y}"},
        {pos: [6, 2, 4], state: "minecraft:deepslate{axis:y}"},
        {pos: [6, 2, 5], state: "minecraft:deepslate{axis:y}"},
        {pos: [6, 2, 6], state: "minecraft:deepslate{axis:y}"},
        {pos: [6, 2, 7], state: "minecraft:deepslate{axis:y}"},
        {pos: [6, 2, 8], state: "minecraft:deepslate{axis:y}"},
        {pos: [6, 2, 9], state: "minecraft:deepslate{axis:y}"},
        {pos: [6, 2, 10], state: "minecraft:deepslate{axis:y}"},
        {pos: [6, 2, 11], state: "minecraft:deepslate{axis:y}"},
        {pos: [6, 2, 12], state: "minecraft:deepslate{axis:y}"},
        {pos: [6, 2, 13], state: "minecraft:deepslate{axis:y}"},
        {pos: [6, 2, 14], state: "minecraft:deepslate{axis:y}"},
        {pos: [6, 2, 15], state: "minecraft:deepslate{axis:y}"},
        {pos: [6, 2, 16], state: "minecraft:deepslate{axis:y}"},
        {pos: [6, 2, 17], state: "minecraft:deepslate{axis:y}"},
        {pos: [6, 2, 18], state: "minecraft:deepslate{axis:y}"},
        {pos: [6, 2, 19], state: "minecraft:deepslate{axis:y}"},
        {pos: [6, 2, 20], state: "minecraft:deepslate{axis:y}"},
        {pos: [6, 2, 21], state: "minecraft:deepslate{axis:y}"},
        {pos: [6, 2, 22], state: "minecraft:deepslate{axis:y}"},
        {pos: [6, 2, 23], state: "minecraft:deepslate{axis:y}"},
        {pos: [6, 2, 24], state: "minecraft:deepslate{axis:y}"},
        {pos: [7, 2, 0], state: "minecraft:deepslate{axis:y}"},
        {pos: [7, 2, 1], state: "minecraft:deepslate{axis:y}"},
        {pos: [7, 2, 2], state: "minecraft:deepslate{axis:y}"},
        {pos: [7, 2, 3], state: "minecraft:deepslate{axis:y}"},
        {pos: [7, 2, 4], state: "minecraft:deepslate{axis:y}"},
        {pos: [7, 2, 5], state: "minecraft:deepslate{axis:y}"},
        {pos: [7, 2, 6], state: "minecraft:deepslate{axis:y}"},
        {pos: [7, 2, 7], state: "minecraft:deepslate{axis:y}"},
        {pos: [7, 2, 8], state: "minecraft:deepslate{axis:y}"},
        {pos: [7, 2, 9], state: "minecraft:deepslate{axis:y}"},
        {pos: [7, 2, 10], state: "minecraft:deepslate{axis:y}"},
        {pos: [7, 2, 11], state: "minecraft:deepslate{axis:y}"},
        {pos: [7, 2, 12], state: "minecraft:deepslate{axis:y}"},
        {pos: [7, 2, 13], state: "minecraft:deepslate{axis:y}"},
        {pos: [7, 2, 14], state: "minecraft:deepslate{axis:y}"},
        {pos: [7, 2, 15], state: "minecraft:deepslate{axis:y}"},
        {pos: [7, 2, 16], state: "minecraft:deepslate{axis:y}"},
        {pos: [7, 2, 17], state: "minecraft:deepslate{axis:y}"},
        {pos: [7, 2, 18], state: "minecraft:deepslate{axis:y}"},
        {pos: [7, 2, 19], state: "minecraft:deepslate{axis:y}"},
        {pos: [7, 2, 20], state: "minecraft:deepslate{axis:y}"},
        {pos: [7, 2, 21], state: "minecraft:deepslate{axis:y}"},
        {pos: [7, 2, 22], state: "minecraft:deepslate{axis:y}"},
        {pos: [7, 2, 23], state: "minecraft:deepslate{axis:y}"},
        {pos: [7, 2, 24], state: "minecraft:deepslate{axis:y}"},
        {pos: [8, 2, 0], state: "minecraft:deepslate{axis:y}"},
        {pos: [8, 2, 1], state: "minecraft:deepslate{axis:y}"},
        {pos: [8, 2, 2], state: "minecraft:deepslate{axis:y}"},
        {pos: [8, 2, 3], state: "minecraft:deepslate{axis:y}"},
        {pos: [8, 2, 4], state: "minecraft:deepslate{axis:y}"},
        {pos: [8, 2, 5], state: "minecraft:deepslate{axis:y}"},
        {pos: [8, 2, 6], state: "minecraft:deepslate{axis:y}"},
        {pos: [8, 2, 7], state: "minecraft:deepslate{axis:y}"},
        {pos: [8, 2, 8], state: "minecraft:deepslate{axis:y}"},
        {pos: [8, 2, 9], state: "minecraft:deepslate{axis:y}"},
        {pos: [8, 2, 10], state: "minecraft:deepslate{axis:y}"},
        {pos: [8, 2, 11], state: "minecraft:sticky_piston{extended:true,facing:up}"},
        {pos: [8, 2, 12], state: "minecraft:sticky_piston{extended:true,facing:up}"},
        {pos: [8, 2, 13], state: "minecraft:sticky_piston{extended:true,facing:up}"},
        {pos: [8, 2, 14], state: "minecraft:deepslate{axis:y}"},
        {pos: [8, 2, 15], state: "minecraft:deepslate{axis:y}"},
        {pos: [8, 2, 16], state: "minecraft:deepslate{axis:y}"},
        {pos: [8, 2, 17], state: "minecraft:deepslate{axis:y}"},
        {pos: [8, 2, 18], state: "minecraft:deepslate{axis:y}"},
        {pos: [8, 2, 19], state: "minecraft:deepslate{axis:y}"},
        {pos: [8, 2, 20], state: "minecraft:deepslate{axis:y}"},
        {pos: [8, 2, 21], state: "minecraft:deepslate{axis:y}"},
        {pos: [8, 2, 22], state: "minecraft:deepslate{axis:y}"},
        {pos: [8, 2, 23], state: "minecraft:deepslate{axis:y}"},
        {pos: [8, 2, 24], state: "minecraft:deepslate{axis:y}"},
        {pos: [9, 2, 0], state: "minecraft:deepslate{axis:y}"},
        {pos: [9, 2, 1], state: "minecraft:deepslate{axis:y}"},
        {pos: [9, 2, 2], state: "minecraft:deepslate{axis:y}"},
        {pos: [9, 2, 3], state: "minecraft:deepslate{axis:y}"},
        {pos: [9, 2, 4], state: "minecraft:deepslate{axis:y}"},
        {pos: [9, 2, 5], state: "minecraft:deepslate{axis:y}"},
        {pos: [9, 2, 6], state: "minecraft:deepslate{axis:y}"},
        {pos: [9, 2, 7], state: "minecraft:deepslate{axis:y}"},
        {pos: [9, 2, 8], state: "minecraft:deepslate{axis:y}"},
        {pos: [9, 2, 9], state: "minecraft:deepslate{axis:y}"},
        {pos: [9, 2, 10], state: "minecraft:deepslate{axis:y}"},
        {pos: [9, 2, 11], state: "minecraft:deepslate{axis:y}"},
        {pos: [9, 2, 12], state: "minecraft:deepslate{axis:y}"},
        {pos: [9, 2, 13], state: "minecraft:deepslate{axis:y}"},
        {pos: [9, 2, 14], state: "minecraft:deepslate{axis:y}"},
        {pos: [9, 2, 15], state: "minecraft:deepslate{axis:y}"},
        {pos: [9, 2, 16], state: "minecraft:deepslate{axis:y}"},
        {pos: [9, 2, 17], state: "minecraft:deepslate{axis:y}"},
        {pos: [9, 2, 18], state: "minecraft:deepslate{axis:y}"},
        {pos: [9, 2, 19], state: "minecraft:deepslate{axis:y}"},
        {pos: [9, 2, 20], state: "minecraft:deepslate{axis:y}"},
        {pos: [9, 2, 21], state: "minecraft:deepslate{axis:y}"},
        {pos: [9, 2, 22], state: "minecraft:deepslate{axis:y}"},
        {pos: [9, 2, 23], state: "minecraft:deepslate{axis:y}"},
        {pos: [9, 2, 24], state: "minecraft:deepslate{axis:y}"},
        {pos: [10, 2, 0], state: "minecraft:deepslate{axis:y}"},
        {pos: [10, 2, 1], state: "minecraft:deepslate{axis:y}"},
        {pos: [10, 2, 2], state: "minecraft:deepslate{axis:y}"},
        {pos: [10, 2, 3], state: "minecraft:deepslate{axis:y}"},
        {pos: [10, 2, 4], state: "minecraft:deepslate{axis:y}"},
        {pos: [10, 2, 5], state: "minecraft:deepslate{axis:y}"},
        {pos: [10, 2, 6], state: "minecraft:deepslate{axis:y}"},
        {pos: [10, 2, 7], state: "minecraft:deepslate{axis:y}"},
        {pos: [10, 2, 8], state: "minecraft:deepslate{axis:y}"},
        {pos: [10, 2, 9], state: "minecraft:deepslate{axis:y}"},
        {pos: [10, 2, 10], state: "minecraft:deepslate{axis:y}"},
        {pos: [10, 2, 11], state: "minecraft:deepslate{axis:y}"},
        {pos: [10, 2, 12], state: "minecraft:deepslate{axis:y}"},
        {pos: [10, 2, 13], state: "minecraft:deepslate{axis:y}"},
        {pos: [10, 2, 14], state: "minecraft:deepslate{axis:y}"},
        {pos: [10, 2, 15], state: "minecraft:deepslate{axis:y}"},
        {pos: [10, 2, 16], state: "minecraft:deepslate{axis:y}"},
        {pos: [10, 2, 17], state: "minecraft:deepslate{axis:y}"},
        {pos: [10, 2, 18], state: "minecraft:deepslate{axis:y}"},
        {pos: [10, 2, 19], state: "minecraft:deepslate{axis:y}"},
        {pos: [10, 2, 20], state: "minecraft:deepslate{axis:y}"},
        {pos: [10, 2, 21], state: "minecraft:deepslate{axis:y}"},
        {pos: [10, 2, 22], state: "minecraft:deepslate{axis:y}"},
        {pos: [10, 2, 23], state: "minecraft:deepslate{axis:y}"},
        {pos: [10, 2, 24], state: "minecraft:deepslate{axis:y}"},
        {pos: [11, 2, 0], state: "minecraft:deepslate{axis:y}"},
        {pos: [11, 2, 1], state: "minecraft:deepslate{axis:y}"},
        {pos: [11, 2, 2], state: "minecraft:deepslate{axis:y}"},
        {pos: [11, 2, 3], state: "minecraft:deepslate{axis:y}"},
        {pos: [11, 2, 4], state: "minecraft:deepslate{axis:y}"},
        {pos: [11, 2, 5], state: "minecraft:deepslate{axis:y}"},
        {pos: [11, 2, 6], state: "minecraft:deepslate{axis:y}"},
        {pos: [11, 2, 7], state: "minecraft:deepslate{axis:y}"},
        {pos: [11, 2, 8], state: "minecraft:deepslate{axis:y}"},
        {pos: [11, 2, 9], state: "minecraft:deepslate{axis:y}"},
        {pos: [11, 2, 10], state: "minecraft:deepslate{axis:y}"},
        {pos: [11, 2, 11], state: "minecraft:deepslate{axis:y}"},
        {pos: [11, 2, 12], state: "minecraft:deepslate{axis:y}"},
        {pos: [11, 2, 13], state: "minecraft:deepslate{axis:y}"},
        {pos: [11, 2, 14], state: "minecraft:deepslate{axis:y}"},
        {pos: [11, 2, 15], state: "minecraft:deepslate{axis:y}"},
        {pos: [11, 2, 16], state: "minecraft:deepslate{axis:y}"},
        {pos: [11, 2, 17], state: "minecraft:deepslate{axis:y}"},
        {pos: [11, 2, 18], state: "minecraft:deepslate{axis:y}"},
        {pos: [11, 2, 19], state: "minecraft:deepslate{axis:y}"},
        {pos: [11, 2, 20], state: "minecraft:deepslate{axis:y}"},
        {pos: [11, 2, 21], state: "minecraft:deepslate{axis:y}"},
        {pos: [11, 2, 22], state: "minecraft:deepslate{axis:y}"},
        {pos: [11, 2, 23], state: "minecraft:deepslate{axis:y}"},
        {pos: [11, 2, 24], state: "minecraft:deepslate{axis:y}"},
        {pos: [12, 2, 0], state: "minecraft:deepslate{axis:y}"},
        {pos: [12, 2, 1], state: "minecraft:deepslate{axis:y}"},
        {pos: [12, 2, 2], state: "minecraft:deepslate{axis:y}"},
        {pos: [12, 2, 3], state: "minecraft:deepslate{axis:y}"},
        {pos: [12, 2, 4], state: "minecraft:deepslate{axis:y}"},
        {pos: [12, 2, 5], state: "minecraft:deepslate{axis:y}"},
        {pos: [12, 2, 6], state: "minecraft:deepslate{axis:y}"},
        {pos: [12, 2, 7], state: "minecraft:deepslate{axis:y}"},
        {pos: [12, 2, 8], state: "minecraft:deepslate{axis:y}"},
        {pos: [12, 2, 9], state: "minecraft:deepslate{axis:y}"},
        {pos: [12, 2, 10], state: "minecraft:deepslate{axis:y}"},
        {pos: [12, 2, 11], state: "minecraft:deepslate{axis:y}"},
        {pos: [12, 2, 12], state: "minecraft:deepslate{axis:y}"},
        {pos: [12, 2, 13], state: "minecraft:deepslate{axis:y}"},
        {pos: [12, 2, 14], state: "minecraft:deepslate{axis:y}"},
        {pos: [12, 2, 15], state: "minecraft:deepslate{axis:y}"},
        {pos: [12, 2, 16], state: "minecraft:deepslate{axis:y}"},
        {pos: [12, 2, 17], state: "minecraft:deepslate{axis:y}"},
        {pos: [12, 2, 18], state: "minecraft:deepslate{axis:y}"},
        {pos: [12, 2, 19], state: "minecraft:deepslate{axis:y}"},
        {pos: [12, 2, 20], state: "minecraft:deepslate{axis:y}"},
        {pos: [12, 2, 21], state: "minecraft:deepslate{axis:y}"},
        {pos: [12, 2, 22], state: "minecraft:deepslate{axis:y}"},
        {pos: [12, 2, 23], state: "minecraft:deepslate{axis:y}"},
        {pos: [12, 2, 24], state: "minecraft:deepslate{axis:y}"},
        {pos: [13, 2, 0], state: "minecraft:deepslate{axis:y}"},
        {pos: [13, 2, 1], state: "minecraft:deepslate{axis:y}"},
        {pos: [13, 2, 2], state: "minecraft:deepslate{axis:y}"},
        {pos: [13, 2, 3], state: "minecraft:deepslate{axis:y}"},
        {pos: [13, 2, 4], state: "minecraft:deepslate{axis:y}"},
        {pos: [13, 2, 5], state: "minecraft:deepslate{axis:y}"},
        {pos: [13, 2, 6], state: "minecraft:deepslate{axis:y}"},
        {pos: [13, 2, 7], state: "minecraft:deepslate{axis:y}"},
        {pos: [13, 2, 8], state: "minecraft:deepslate{axis:y}"},
        {pos: [13, 2, 9], state: "minecraft:deepslate{axis:y}"},
        {pos: [13, 2, 10], state: "minecraft:deepslate{axis:y}"},
        {pos: [13, 2, 11], state: "minecraft:deepslate{axis:y}"},
        {pos: [13, 2, 12], state: "minecraft:deepslate{axis:y}"},
        {pos: [13, 2, 13], state: "minecraft:deepslate{axis:y}"},
        {pos: [13, 2, 14], state: "minecraft:deepslate{axis:y}"},
        {pos: [13, 2, 15], state: "minecraft:deepslate{axis:y}"},
        {pos: [13, 2, 16], state: "minecraft:deepslate{axis:y}"},
        {pos: [13, 2, 17], state: "minecraft:deepslate{axis:y}"},
        {pos: [13, 2, 18], state: "minecraft:deepslate{axis:y}"},
        {pos: [13, 2, 19], state: "minecraft:deepslate{axis:y}"},
        {pos: [13, 2, 20], state: "minecraft:deepslate{axis:y}"},
        {pos: [13, 2, 21], state: "minecraft:deepslate{axis:y}"},
        {pos: [13, 2, 22], state: "minecraft:deepslate{axis:y}"},
        {pos: [13, 2, 23], state: "minecraft:deepslate{axis:y}"},
        {pos: [13, 2, 24], state: "minecraft:deepslate{axis:y}"},
        {pos: [14, 2, 0], state: "minecraft:deepslate{axis:y}"},
        {pos: [14, 2, 1], state: "minecraft:deepslate{axis:y}"},
        {pos: [14, 2, 2], state: "minecraft:deepslate{axis:y}"},
        {pos: [14, 2, 3], state: "minecraft:deepslate{axis:y}"},
        {pos: [14, 2, 4], state: "minecraft:deepslate{axis:y}"},
        {pos: [14, 2, 5], state: "minecraft:deepslate{axis:y}"},
        {pos: [14, 2, 6], state: "minecraft:deepslate{axis:y}"},
        {pos: [14, 2, 7], state: "minecraft:deepslate{axis:y}"},
        {pos: [14, 2, 8], state: "minecraft:deepslate{axis:y}"},
        {pos: [14, 2, 9], state: "minecraft:deepslate{axis:y}"},
        {pos: [14, 2, 10], state: "minecraft:deepslate{axis:y}"},
        {pos: [14, 2, 11], state: "minecraft:deepslate{axis:y}"},
        {pos: [14, 2, 12], state: "minecraft:deepslate{axis:y}"},
        {pos: [14, 2, 13], state: "minecraft:deepslate{axis:y}"},
        {pos: [14, 2, 14], state: "minecraft:deepslate{axis:y}"},
        {pos: [14, 2, 15], state: "minecraft:deepslate{axis:y}"},
        {pos: [14, 2, 16], state: "minecraft:deepslate{axis:y}"},
        {pos: [14, 2, 17], state: "minecraft:deepslate{axis:y}"},
        {pos: [14, 2, 18], state: "minecraft:deepslate{axis:y}"},
        {pos: [14, 2, 19], state: "minecraft:deepslate{axis:y}"},
        {pos: [14, 2, 20], state: "minecraft:deepslate{axis:y}"},
        {pos: [14, 2, 21], state: "minecraft:deepslate{axis:y}"},
        {pos: [14, 2, 22], state: "minecraft:deepslate{axis:y}"},
        {pos: [14, 2, 23], state: "minecraft:deepslate{axis:y}"},
        {pos: [14, 2, 24], state: "minecraft:deepslate{axis:y}"},
        {pos: [15, 2, 0], state: "minecraft:deepslate{axis:y}"},
        {pos: [15, 2, 1], state: "minecraft:deepslate{axis:y}"},
        {pos: [15, 2, 2], state: "minecraft:deepslate{axis:y}"},
        {pos: [15, 2, 3], state: "minecraft:deepslate{axis:y}"},
        {pos: [15, 2, 4], state: "minecraft:deepslate{axis:y}"},
        {pos: [15, 2, 5], state: "minecraft:deepslate{axis:y}"},
        {pos: [15, 2, 6], state: "minecraft:deepslate{axis:y}"},
        {pos: [15, 2, 7], state: "minecraft:deepslate{axis:y}"},
        {pos: [15, 2, 8], state: "minecraft:deepslate{axis:y}"},
        {pos: [15, 2, 9], state: "minecraft:deepslate{axis:y}"},
        {pos: [15, 2, 10], state: "minecraft:deepslate{axis:y}"},
        {pos: [15, 2, 11], state: "minecraft:deepslate{axis:y}"},
        {pos: [15, 2, 12], state: "minecraft:deepslate{axis:y}"},
        {pos: [15, 2, 13], state: "minecraft:deepslate{axis:y}"},
        {pos: [15, 2, 14], state: "minecraft:deepslate{axis:y}"},
        {pos: [15, 2, 15], state: "minecraft:deepslate{axis:y}"},
        {pos: [15, 2, 16], state: "minecraft:deepslate{axis:y}"},
        {pos: [15, 2, 17], state: "minecraft:deepslate{axis:y}"},
        {pos: [15, 2, 18], state: "minecraft:deepslate{axis:y}"},
        {pos: [15, 2, 19], state: "minecraft:deepslate{axis:y}"},
        {pos: [15, 2, 20], state: "minecraft:deepslate{axis:y}"},
        {pos: [15, 2, 21], state: "minecraft:deepslate{axis:y}"},
        {pos: [15, 2, 22], state: "minecraft:deepslate{axis:y}"},
        {pos: [15, 2, 23], state: "minecraft:deepslate{axis:y}"},
        {pos: [15, 2, 24], state: "minecraft:deepslate{axis:y}"},
        {pos: [16, 2, 0], state: "minecraft:deepslate{axis:y}"},
        {pos: [16, 2, 1], state: "minecraft:deepslate{axis:y}"},
        {pos: [16, 2, 2], state: "minecraft:deepslate{axis:y}"},
        {pos: [16, 2, 3], state: "minecraft:deepslate{axis:y}"},
        {pos: [16, 2, 4], state: "minecraft:deepslate{axis:y}"},
        {pos: [16, 2, 5], state: "minecraft:deepslate{axis:y}"},
        {pos: [16, 2, 6], state: "minecraft:deepslate{axis:y}"},
        {pos: [16, 2, 7], state: "minecraft:deepslate{axis:y}"},
        {pos: [16, 2, 8], state: "minecraft:deepslate{axis:y}"},
        {pos: [16, 2, 9], state: "minecraft:deepslate{axis:y}"},
        {pos: [16, 2, 10], state: "minecraft:deepslate{axis:y}"},
        {pos: [16, 2, 11], state: "minecraft:deepslate_bricks"},
        {pos: [16, 2, 12], state: "minecraft:deepslate_bricks"},
        {pos: [16, 2, 13], state: "minecraft:deepslate{axis:y}"},
        {pos: [16, 2, 14], state: "minecraft:deepslate{axis:y}"},
        {pos: [16, 2, 15], state: "minecraft:deepslate{axis:y}"},
        {pos: [16, 2, 16], state: "minecraft:deepslate{axis:y}"},
        {pos: [16, 2, 17], state: "minecraft:deepslate{axis:y}"},
        {pos: [16, 2, 18], state: "minecraft:deepslate{axis:y}"},
        {pos: [16, 2, 19], state: "minecraft:deepslate{axis:y}"},
        {pos: [16, 2, 20], state: "minecraft:deepslate{axis:y}"},
        {pos: [16, 2, 21], state: "minecraft:deepslate{axis:y}"},
        {pos: [16, 2, 22], state: "minecraft:deepslate{axis:y}"},
        {pos: [16, 2, 23], state: "minecraft:deepslate{axis:y}"},
        {pos: [16, 2, 24], state: "minecraft:deepslate{axis:y}"},
        {pos: [17, 2, 10], state: "minecraft:deepslate_bricks"},
        {pos: [17, 2, 11], state: "minecraft:deepslate_bricks"},
        {pos: [17, 2, 12], state: "minecraft:cave_air"},
        {pos: [17, 2, 13], state: "minecraft:deepslate_bricks"},
        {pos: [17, 2, 14], state: "minecraft:deepslate_bricks"},
        {pos: [17, 2, 15], state: "minecraft:deepslate_bricks"},
        {pos: [17, 2, 16], state: "minecraft:deepslate_bricks"},
        {pos: [18, 2, 10], state: "minecraft:deepslate_bricks"},
        {pos: [18, 2, 11], state: "minecraft:deepslate_bricks"},
        {pos: [18, 2, 12], state: "minecraft:redstone_wire{east:none,north:none,power:0,south:up,west:side}"},
        {pos: [18, 2, 13], state: "minecraft:deepslate_bricks"},
        {pos: [18, 2, 14], state: "minecraft:deepslate_bricks"},
        {pos: [18, 2, 15], state: "minecraft:deepslate_bricks"},
        {pos: [18, 2, 16], state: "minecraft:deepslate_bricks"},
        {pos: [19, 2, 11], state: "minecraft:deepslate_bricks"},
        {pos: [19, 2, 12], state: "minecraft:deepslate_bricks"},
        {pos: [19, 2, 13], state: "minecraft:deepslate_bricks"},
        {pos: [0, 3, 9], state: "minecraft:deepslate_bricks"},
        {pos: [0, 3, 10], state: "minecraft:deepslate_bricks"},
        {pos: [0, 3, 11], state: "minecraft:gravel"},
        {pos: [0, 3, 12], state: "minecraft:gravel"},
        {pos: [0, 3, 13], state: "minecraft:gravel"},
        {pos: [0, 3, 14], state: "minecraft:deepslate_bricks"},
        {pos: [0, 3, 15], state: "minecraft:deepslate_bricks"},
        {pos: [1, 3, 9], state: "minecraft:deepslate_bricks"},
        {pos: [1, 3, 10], state: "minecraft:gravel"},
        {pos: [1, 3, 11], state: "minecraft:gravel"},
        {pos: [1, 3, 12], state: "minecraft:gravel"},
        {pos: [1, 3, 13], state: "minecraft:gravel"},
        {pos: [1, 3, 14], state: "minecraft:gravel"},
        {pos: [1, 3, 15], state: "minecraft:deepslate_bricks"},
        {pos: [2, 3, 5], state: "minecraft:deepslate_bricks"},
        {pos: [2, 3, 6], state: "minecraft:deepslate_bricks"},
        {pos: [2, 3, 7], state: "minecraft:deepslate_bricks"},
        {pos: [2, 3, 8], state: "minecraft:deepslate_bricks"},
        {pos: [2, 3, 9], state: "minecraft:gravel"},
        {pos: [2, 3, 10], state: "minecraft:deepslate_bricks"},
        {pos: [2, 3, 11], state: "minecraft:gravel"},
        {pos: [2, 3, 12], state: "minecraft:gravel"},
        {pos: [2, 3, 13], state: "minecraft:gravel"},
        {pos: [2, 3, 14], state: "minecraft:deepslate_bricks"},
        {pos: [2, 3, 15], state: "minecraft:gravel"},
        {pos: [2, 3, 16], state: "minecraft:deepslate_bricks"},
        {pos: [2, 3, 17], state: "minecraft:deepslate_bricks"},
        {pos: [2, 3, 18], state: "minecraft:deepslate_bricks"},
        {pos: [2, 3, 19], state: "minecraft:deepslate_bricks"},
        {pos: [3, 3, 5], state: "minecraft:deepslate_bricks"},
        {pos: [3, 3, 6], state: "minecraft:gravel"},
        {pos: [3, 3, 7], state: "minecraft:gravel"},
        {pos: [3, 3, 8], state: "minecraft:gravel"},
        {pos: [3, 3, 9], state: "minecraft:gravel"},
        {pos: [3, 3, 10], state: "minecraft:gravel"},
        {pos: [3, 3, 11], state: "minecraft:gravel"},
        {pos: [3, 3, 12], state: "minecraft:gravel"},
        {pos: [3, 3, 13], state: "minecraft:gravel"},
        {pos: [3, 3, 14], state: "minecraft:gravel"},
        {pos: [3, 3, 15], state: "minecraft:gravel"},
        {pos: [3, 3, 16], state: "minecraft:gravel"},
        {pos: [3, 3, 17], state: "minecraft:gravel"},
        {pos: [3, 3, 18], state: "minecraft:gravel"},
        {pos: [3, 3, 19], state: "minecraft:deepslate_bricks"},
        {pos: [4, 3, 0], state: "minecraft:deepslate_bricks"},
        {pos: [4, 3, 1], state: "minecraft:deepslate_bricks"},
        {pos: [4, 3, 2], state: "minecraft:deepslate_bricks"},
        {pos: [4, 3, 3], state: "minecraft:deepslate_bricks"},
        {pos: [4, 3, 4], state: "minecraft:deepslate_bricks"},
        {pos: [4, 3, 5], state: "minecraft:gravel"},
        {pos: [4, 3, 6], state: "minecraft:gravel"},
        {pos: [4, 3, 7], state: "minecraft:gravel"},
        {pos: [4, 3, 8], state: "minecraft:gravel"},
        {pos: [4, 3, 9], state: "minecraft:gravel"},
        {pos: [4, 3, 10], state: "minecraft:gravel"},
        {pos: [4, 3, 11], state: "minecraft:gravel"},
        {pos: [4, 3, 12], state: "minecraft:gravel"},
        {pos: [4, 3, 13], state: "minecraft:gravel"},
        {pos: [4, 3, 14], state: "minecraft:gravel"},
        {pos: [4, 3, 15], state: "minecraft:gravel"},
        {pos: [4, 3, 16], state: "minecraft:gravel"},
        {pos: [4, 3, 17], state: "minecraft:gravel"},
        {pos: [4, 3, 18], state: "minecraft:gravel"},
        {pos: [4, 3, 19], state: "minecraft:gravel"},
        {pos: [4, 3, 20], state: "minecraft:deepslate_bricks"},
        {pos: [4, 3, 21], state: "minecraft:deepslate_bricks"},
        {pos: [4, 3, 22], state: "minecraft:deepslate_bricks"},
        {pos: [4, 3, 23], state: "minecraft:deepslate_bricks"},
        {pos: [4, 3, 24], state: "minecraft:deepslate_bricks"},
        {pos: [5, 3, 0], state: "minecraft:deepslate_bricks"},
        {pos: [5, 3, 1], state: "minecraft:gravel"},
        {pos: [5, 3, 2], state: "minecraft:gravel"},
        {pos: [5, 3, 3], state: "minecraft:gravel"},
        {pos: [5, 3, 4], state: "minecraft:deepslate_bricks"},
        {pos: [5, 3, 5], state: "minecraft:gravel"},
        {pos: [5, 3, 6], state: "minecraft:gravel"},
        {pos: [5, 3, 7], state: "minecraft:gravel"},
        {pos: [5, 3, 8], state: "minecraft:gravel"},
        {pos: [5, 3, 9], state: "minecraft:gravel"},
        {pos: [5, 3, 10], state: "minecraft:gravel"},
        {pos: [5, 3, 11], state: "minecraft:gravel"},
        {pos: [5, 3, 12], state: "minecraft:gravel"},
        {pos: [5, 3, 13], state: "minecraft:gravel"},
        {pos: [5, 3, 14], state: "minecraft:gravel"},
        {pos: [5, 3, 15], state: "minecraft:gravel"},
        {pos: [5, 3, 16], state: "minecraft:gravel"},
        {pos: [5, 3, 17], state: "minecraft:gravel"},
        {pos: [5, 3, 18], state: "minecraft:gravel"},
        {pos: [5, 3, 19], state: "minecraft:gravel"},
        {pos: [5, 3, 20], state: "minecraft:gravel"},
        {pos: [5, 3, 21], state: "minecraft:gravel"},
        {pos: [5, 3, 22], state: "minecraft:deepslate_bricks"},
        {pos: [5, 3, 23], state: "minecraft:deepslate_bricks"},
        {pos: [5, 3, 24], state: "minecraft:deepslate_bricks"},
        {pos: [6, 3, 0], state: "minecraft:deepslate_bricks"},
        {pos: [6, 3, 1], state: "minecraft:deepslate_bricks"},
        {pos: [6, 3, 2], state: "minecraft:gravel"},
        {pos: [6, 3, 3], state: "minecraft:gravel"},
        {pos: [6, 3, 4], state: "minecraft:gravel"},
        {pos: [6, 3, 5], state: "minecraft:gravel"},
        {pos: [6, 3, 6], state: "minecraft:gravel"},
        {pos: [6, 3, 7], state: "minecraft:gravel"},
        {pos: [6, 3, 8], state: "minecraft:gravel"},
        {pos: [6, 3, 9], state: "minecraft:gravel"},
        {pos: [6, 3, 10], state: "minecraft:gravel"},
        {pos: [6, 3, 11], state: "minecraft:gravel"},
        {pos: [6, 3, 12], state: "minecraft:gravel"},
        {pos: [6, 3, 13], state: "minecraft:gravel"},
        {pos: [6, 3, 14], state: "minecraft:gravel"},
        {pos: [6, 3, 15], state: "minecraft:gravel"},
        {pos: [6, 3, 16], state: "minecraft:gravel"},
        {pos: [6, 3, 17], state: "minecraft:gravel"},
        {pos: [6, 3, 18], state: "minecraft:gravel"},
        {pos: [6, 3, 19], state: "minecraft:gravel"},
        {pos: [6, 3, 20], state: "minecraft:gravel"},
        {pos: [6, 3, 21], state: "minecraft:gravel"},
        {pos: [6, 3, 22], state: "minecraft:gravel"},
        {pos: [6, 3, 23], state: "minecraft:deepslate_bricks"},
        {pos: [6, 3, 24], state: "minecraft:deepslate_bricks"},
        {pos: [7, 3, 0], state: "minecraft:deepslate_bricks"},
        {pos: [7, 3, 1], state: "minecraft:deepslate_bricks"},
        {pos: [7, 3, 2], state: "minecraft:deepslate_bricks"},
        {pos: [7, 3, 3], state: "minecraft:gravel"},
        {pos: [7, 3, 4], state: "minecraft:deepslate_bricks"},
        {pos: [7, 3, 5], state: "minecraft:gravel"},
        {pos: [7, 3, 6], state: "minecraft:gravel"},
        {pos: [7, 3, 7], state: "minecraft:gravel"},
        {pos: [7, 3, 8], state: "minecraft:gravel"},
        {pos: [7, 3, 9], state: "minecraft:gravel"},
        {pos: [7, 3, 10], state: "minecraft:gravel"},
        {pos: [7, 3, 11], state: "minecraft:gravel"},
        {pos: [7, 3, 12], state: "minecraft:gravel"},
        {pos: [7, 3, 13], state: "minecraft:gravel"},
        {pos: [7, 3, 14], state: "minecraft:gravel"},
        {pos: [7, 3, 15], state: "minecraft:gravel"},
        {pos: [7, 3, 16], state: "minecraft:gravel"},
        {pos: [7, 3, 17], state: "minecraft:gravel"},
        {pos: [7, 3, 18], state: "minecraft:gravel"},
        {pos: [7, 3, 19], state: "minecraft:gravel"},
        {pos: [7, 3, 20], state: "minecraft:gravel"},
        {pos: [7, 3, 21], state: "minecraft:gravel"},
        {pos: [7, 3, 22], state: "minecraft:deepslate_bricks"},
        {pos: [7, 3, 23], state: "minecraft:gravel"},
        {pos: [7, 3, 24], state: "minecraft:deepslate_bricks"},
        {pos: [8, 3, 0], state: "minecraft:deepslate_bricks"},
        {pos: [8, 3, 1], state: "minecraft:gravel"},
        {pos: [8, 3, 2], state: "minecraft:gravel"},
        {pos: [8, 3, 3], state: "minecraft:gravel"},
        {pos: [8, 3, 4], state: "minecraft:gravel"},
        {pos: [8, 3, 5], state: "minecraft:gravel"},
        {pos: [8, 3, 6], state: "minecraft:gravel"},
        {pos: [8, 3, 7], state: "minecraft:gravel"},
        {pos: [8, 3, 8], state: "minecraft:gravel"},
        {pos: [8, 3, 9], state: "minecraft:gravel"},
        {pos: [8, 3, 10], state: "minecraft:gravel"},
        {pos: [8, 3, 11], state: "minecraft:piston_head{facing:up,short:false,type:sticky}"},
        {pos: [8, 3, 12], state: "minecraft:piston_head{facing:up,short:false,type:sticky}"},
        {pos: [8, 3, 13], state: "minecraft:piston_head{facing:up,short:false,type:sticky}"},
        {pos: [8, 3, 14], state: "minecraft:gravel"},
        {pos: [8, 3, 15], state: "minecraft:gravel"},
        {pos: [8, 3, 16], state: "minecraft:gravel"},
        {pos: [8, 3, 17], state: "minecraft:gravel"},
        {pos: [8, 3, 18], state: "minecraft:gravel"},
        {pos: [8, 3, 19], state: "minecraft:gravel"},
        {pos: [8, 3, 20], state: "minecraft:gravel"},
        {pos: [8, 3, 21], state: "minecraft:gravel"},
        {pos: [8, 3, 22], state: "minecraft:gravel"},
        {pos: [8, 3, 23], state: "minecraft:gravel"},
        {pos: [8, 3, 24], state: "minecraft:deepslate_bricks"},
        {pos: [9, 3, 0], state: "minecraft:deepslate_bricks"},
        {pos: [9, 3, 1], state: "minecraft:gravel"},
        {pos: [9, 3, 2], state: "minecraft:gravel"},
        {pos: [9, 3, 3], state: "minecraft:gravel"},
        {pos: [9, 3, 4], state: "minecraft:gravel"},
        {pos: [9, 3, 5], state: "minecraft:gravel"},
        {pos: [9, 3, 6], state: "minecraft:gravel"},
        {pos: [9, 3, 7], state: "minecraft:gravel"},
        {pos: [9, 3, 8], state: "minecraft:gravel"},
        {pos: [9, 3, 9], state: "minecraft:gravel"},
        {pos: [9, 3, 10], state: "minecraft:gravel"},
        {pos: [9, 3, 11], state: "minecraft:gravel"},
        {pos: [9, 3, 12], state: "minecraft:gravel"},
        {pos: [9, 3, 13], state: "minecraft:gravel"},
        {pos: [9, 3, 14], state: "minecraft:gravel"},
        {pos: [9, 3, 15], state: "minecraft:gravel"},
        {pos: [9, 3, 16], state: "minecraft:gravel"},
        {pos: [9, 3, 17], state: "minecraft:gravel"},
        {pos: [9, 3, 18], state: "minecraft:gravel"},
        {pos: [9, 3, 19], state: "minecraft:gravel"},
        {pos: [9, 3, 20], state: "minecraft:gravel"},
        {pos: [9, 3, 21], state: "minecraft:gravel"},
        {pos: [9, 3, 22], state: "minecraft:gravel"},
        {pos: [9, 3, 23], state: "minecraft:gravel"},
        {pos: [9, 3, 24], state: "minecraft:deepslate_bricks"},
        {pos: [10, 3, 0], state: "minecraft:deepslate_bricks"},
        {pos: [10, 3, 1], state: "minecraft:gravel"},
        {pos: [10, 3, 2], state: "minecraft:gravel"},
        {pos: [10, 3, 3], state: "minecraft:gravel"},
        {pos: [10, 3, 4], state: "minecraft:gravel"},
        {pos: [10, 3, 5], state: "minecraft:gravel"},
        {pos: [10, 3, 6], state: "minecraft:gravel"},
        {pos: [10, 3, 7], state: "minecraft:gravel"},
        {pos: [10, 3, 8], state: "minecraft:gravel"},
        {pos: [10, 3, 9], state: "minecraft:gravel"},
        {pos: [10, 3, 10], state: "minecraft:gravel"},
        {pos: [10, 3, 11], state: "minecraft:gravel"},
        {pos: [10, 3, 12], state: "minecraft:gravel"},
        {pos: [10, 3, 13], state: "minecraft:gravel"},
        {pos: [10, 3, 14], state: "minecraft:gravel"},
        {pos: [10, 3, 15], state: "minecraft:gravel"},
        {pos: [10, 3, 16], state: "minecraft:gravel"},
        {pos: [10, 3, 17], state: "minecraft:gravel"},
        {pos: [10, 3, 18], state: "minecraft:gravel"},
        {pos: [10, 3, 19], state: "minecraft:gravel"},
        {pos: [10, 3, 20], state: "minecraft:gravel"},
        {pos: [10, 3, 21], state: "minecraft:gravel"},
        {pos: [10, 3, 22], state: "minecraft:gravel"},
        {pos: [10, 3, 23], state: "minecraft:gravel"},
        {pos: [10, 3, 24], state: "minecraft:deepslate_bricks"},
        {pos: [11, 3, 0], state: "minecraft:deepslate_bricks"},
        {pos: [11, 3, 1], state: "minecraft:gravel"},
        {pos: [11, 3, 2], state: "minecraft:gravel"},
        {pos: [11, 3, 3], state: "minecraft:gravel"},
        {pos: [11, 3, 4], state: "minecraft:gravel"},
        {pos: [11, 3, 5], state: "minecraft:deepslate_bricks"},
        {pos: [11, 3, 6], state: "minecraft:gravel"},
        {pos: [11, 3, 7], state: "minecraft:gravel"},
        {pos: [11, 3, 8], state: "minecraft:gravel"},
        {pos: [11, 3, 9], state: "minecraft:gravel"},
        {pos: [11, 3, 10], state: "minecraft:gravel"},
        {pos: [11, 3, 11], state: "minecraft:gravel"},
        {pos: [11, 3, 12], state: "minecraft:gravel"},
        {pos: [11, 3, 13], state: "minecraft:gravel"},
        {pos: [11, 3, 14], state: "minecraft:gravel"},
        {pos: [11, 3, 15], state: "minecraft:gravel"},
        {pos: [11, 3, 16], state: "minecraft:gravel"},
        {pos: [11, 3, 17], state: "minecraft:gravel"},
        {pos: [11, 3, 18], state: "minecraft:gravel"},
        {pos: [11, 3, 19], state: "minecraft:gravel"},
        {pos: [11, 3, 20], state: "minecraft:gravel"},
        {pos: [11, 3, 21], state: "minecraft:gravel"},
        {pos: [11, 3, 22], state: "minecraft:gravel"},
        {pos: [11, 3, 23], state: "minecraft:gravel"},
        {pos: [11, 3, 24], state: "minecraft:deepslate_bricks"},
        {pos: [12, 3, 0], state: "minecraft:deepslate_bricks"},
        {pos: [12, 3, 1], state: "minecraft:gravel"},
        {pos: [12, 3, 2], state: "minecraft:gravel"},
        {pos: [12, 3, 3], state: "minecraft:gravel"},
        {pos: [12, 3, 4], state: "minecraft:gravel"},
        {pos: [12, 3, 5], state: "minecraft:gravel"},
        {pos: [12, 3, 6], state: "minecraft:gravel"},
        {pos: [12, 3, 7], state: "minecraft:gravel"},
        {pos: [12, 3, 8], state: "minecraft:gravel"},
        {pos: [12, 3, 9], state: "minecraft:gravel"},
        {pos: [12, 3, 10], state: "minecraft:gravel"},
        {pos: [12, 3, 11], state: "minecraft:gravel"},
        {pos: [12, 3, 12], state: "minecraft:gravel"},
        {pos: [12, 3, 13], state: "minecraft:gravel"},
        {pos: [12, 3, 14], state: "minecraft:gravel"},
        {pos: [12, 3, 15], state: "minecraft:gravel"},
        {pos: [12, 3, 16], state: "minecraft:gravel"},
        {pos: [12, 3, 17], state: "minecraft:gravel"},
        {pos: [12, 3, 18], state: "minecraft:gravel"},
        {pos: [12, 3, 19], state: "minecraft:gravel"},
        {pos: [12, 3, 20], state: "minecraft:gravel"},
        {pos: [12, 3, 21], state: "minecraft:gravel"},
        {pos: [12, 3, 22], state: "minecraft:gravel"},
        {pos: [12, 3, 23], state: "minecraft:gravel"},
        {pos: [12, 3, 24], state: "minecraft:deepslate_bricks"},
        {pos: [13, 3, 0], state: "minecraft:deepslate_bricks"},
        {pos: [13, 3, 1], state: "minecraft:gravel"},
        {pos: [13, 3, 2], state: "minecraft:gravel"},
        {pos: [13, 3, 3], state: "minecraft:gravel"},
        {pos: [13, 3, 4], state: "minecraft:gravel"},
        {pos: [13, 3, 5], state: "minecraft:gravel"},
        {pos: [13, 3, 6], state: "minecraft:gravel"},
        {pos: [13, 3, 7], state: "minecraft:gravel"},
        {pos: [13, 3, 8], state: "minecraft:gravel"},
        {pos: [13, 3, 9], state: "minecraft:gravel"},
        {pos: [13, 3, 10], state: "minecraft:gravel"},
        {pos: [13, 3, 11], state: "minecraft:gravel"},
        {pos: [13, 3, 12], state: "minecraft:gravel"},
        {pos: [13, 3, 13], state: "minecraft:gravel"},
        {pos: [13, 3, 14], state: "minecraft:gravel"},
        {pos: [13, 3, 15], state: "minecraft:gravel"},
        {pos: [13, 3, 16], state: "minecraft:gravel"},
        {pos: [13, 3, 17], state: "minecraft:gravel"},
        {pos: [13, 3, 18], state: "minecraft:gravel"},
        {pos: [13, 3, 19], state: "minecraft:gravel"},
        {pos: [13, 3, 20], state: "minecraft:gravel"},
        {pos: [13, 3, 21], state: "minecraft:gravel"},
        {pos: [13, 3, 22], state: "minecraft:gravel"},
        {pos: [13, 3, 23], state: "minecraft:gravel"},
        {pos: [13, 3, 24], state: "minecraft:deepslate_bricks"},
        {pos: [14, 3, 0], state: "minecraft:deepslate_bricks"},
        {pos: [14, 3, 1], state: "minecraft:gravel"},
        {pos: [14, 3, 2], state: "minecraft:gravel"},
        {pos: [14, 3, 3], state: "minecraft:gravel"},
        {pos: [14, 3, 4], state: "minecraft:gravel"},
        {pos: [14, 3, 5], state: "minecraft:gravel"},
        {pos: [14, 3, 6], state: "minecraft:gravel"},
        {pos: [14, 3, 7], state: "minecraft:gravel"},
        {pos: [14, 3, 8], state: "minecraft:gravel"},
        {pos: [14, 3, 9], state: "minecraft:gravel"},
        {pos: [14, 3, 10], state: "minecraft:gravel"},
        {pos: [14, 3, 11], state: "minecraft:gravel"},
        {pos: [14, 3, 12], state: "minecraft:gravel"},
        {pos: [14, 3, 13], state: "minecraft:gravel"},
        {pos: [14, 3, 14], state: "minecraft:gravel"},
        {pos: [14, 3, 15], state: "minecraft:gravel"},
        {pos: [14, 3, 16], state: "minecraft:gravel"},
        {pos: [14, 3, 17], state: "minecraft:gravel"},
        {pos: [14, 3, 18], state: "minecraft:gravel"},
        {pos: [14, 3, 19], state: "minecraft:gravel"},
        {pos: [14, 3, 20], state: "minecraft:gravel"},
        {pos: [14, 3, 21], state: "minecraft:gravel"},
        {pos: [14, 3, 22], state: "minecraft:gravel"},
        {pos: [14, 3, 23], state: "minecraft:gravel"},
        {pos: [14, 3, 24], state: "minecraft:deepslate_bricks"},
        {pos: [15, 3, 0], state: "minecraft:deepslate_bricks"},
        {pos: [15, 3, 1], state: "minecraft:gravel"},
        {pos: [15, 3, 2], state: "minecraft:gravel"},
        {pos: [15, 3, 3], state: "minecraft:gravel"},
        {pos: [15, 3, 4], state: "minecraft:gravel"},
        {pos: [15, 3, 5], state: "minecraft:gravel"},
        {pos: [15, 3, 6], state: "minecraft:gravel"},
        {pos: [15, 3, 7], state: "minecraft:gravel"},
        {pos: [15, 3, 8], state: "minecraft:gravel"},
        {pos: [15, 3, 9], state: "minecraft:gravel"},
        {pos: [15, 3, 10], state: "minecraft:gravel"},
        {pos: [15, 3, 11], state: "minecraft:gravel"},
        {pos: [15, 3, 12], state: "minecraft:gravel"},
        {pos: [15, 3, 13], state: "minecraft:deepslate_bricks"},
        {pos: [15, 3, 14], state: "minecraft:gravel"},
        {pos: [15, 3, 15], state: "minecraft:gravel"},
        {pos: [15, 3, 16], state: "minecraft:gravel"},
        {pos: [15, 3, 17], state: "minecraft:gravel"},
        {pos: [15, 3, 18], state: "minecraft:gravel"},
        {pos: [15, 3, 19], state: "minecraft:gravel"},
        {pos: [15, 3, 20], state: "minecraft:gravel"},
        {pos: [15, 3, 21], state: "minecraft:gravel"},
        {pos: [15, 3, 22], state: "minecraft:gravel"},
        {pos: [15, 3, 23], state: "minecraft:gravel"},
        {pos: [15, 3, 24], state: "minecraft:deepslate_bricks"},
        {pos: [16, 3, 0], state: "minecraft:deepslate_bricks"},
        {pos: [16, 3, 1], state: "minecraft:deepslate_bricks"},
        {pos: [16, 3, 2], state: "minecraft:deepslate_bricks"},
        {pos: [16, 3, 3], state: "minecraft:deepslate_bricks"},
        {pos: [16, 3, 4], state: "minecraft:deepslate_bricks"},
        {pos: [16, 3, 5], state: "minecraft:deepslate_bricks"},
        {pos: [16, 3, 6], state: "minecraft:deepslate_bricks"},
        {pos: [16, 3, 7], state: "minecraft:deepslate_bricks"},
        {pos: [16, 3, 8], state: "minecraft:deepslate_bricks"},
        {pos: [16, 3, 9], state: "minecraft:deepslate_bricks"},
        {pos: [16, 3, 10], state: "minecraft:gravel"},
        {pos: [16, 3, 11], state: "minecraft:deepslate_bricks"},
        {pos: [16, 3, 12], state: "minecraft:deepslate_bricks"},
        {pos: [16, 3, 13], state: "minecraft:deepslate_bricks"},
        {pos: [16, 3, 14], state: "minecraft:gravel"},
        {pos: [16, 3, 15], state: "minecraft:deepslate_bricks"},
        {pos: [16, 3, 16], state: "minecraft:deepslate_bricks"},
        {pos: [16, 3, 17], state: "minecraft:deepslate_bricks"},
        {pos: [16, 3, 18], state: "minecraft:deepslate_bricks"},
        {pos: [16, 3, 19], state: "minecraft:deepslate_bricks"},
        {pos: [16, 3, 20], state: "minecraft:deepslate_bricks"},
        {pos: [16, 3, 21], state: "minecraft:deepslate_bricks"},
        {pos: [16, 3, 22], state: "minecraft:deepslate_bricks"},
        {pos: [16, 3, 23], state: "minecraft:deepslate_bricks"},
        {pos: [16, 3, 24], state: "minecraft:deepslate_bricks"},
        {pos: [17, 3, 10], state: "minecraft:deepslate_bricks"},
        {pos: [17, 3, 11], state: "minecraft:deepslate_bricks"},
        {pos: [17, 3, 12], state: "minecraft:deepslate_bricks"},
        {pos: [17, 3, 13], state: "minecraft:redstone_wire{east:side,north:up,power:0,south:none,west:none}"},
        {pos: [17, 3, 14], state: "minecraft:deepslate_bricks"},
        {pos: [17, 3, 15], state: "minecraft:deepslate_bricks"},
        {pos: [17, 3, 16], state: "minecraft:deepslate_bricks"},
        {pos: [18, 3, 10], state: "minecraft:deepslate_bricks"},
        {pos: [18, 3, 11], state: "minecraft:deepslate_bricks"},
        {pos: [18, 3, 12], state: "minecraft:cave_air"},
        {pos: [18, 3, 13], state: "minecraft:redstone_wire{east:none,north:side,power:0,south:none,west:side}"},
        {pos: [18, 3, 14], state: "minecraft:deepslate_bricks"},
        {pos: [18, 3, 15], state: "minecraft:deepslate_bricks"},
        {pos: [18, 3, 16], state: "minecraft:deepslate_bricks"},
        {pos: [19, 3, 11], state: "minecraft:deepslate_bricks"},
        {pos: [19, 3, 12], state: "minecraft:deepslate_bricks"},
        {pos: [19, 3, 13], state: "minecraft:deepslate_bricks"},
        {pos: [0, 4, 9], state: "minecraft:deepslate_bricks"},
        {pos: [0, 4, 10], state: "minecraft:deepslate_bricks"},
        {pos: [0, 4, 11], state: "minecraft:candle{candles:4,lit:false,waterlogged:false}"},
        {pos: [0, 4, 12], state: "minecraft:jigsaw{orientation:west_up}", nbt: {final_state: "minecraft:cave_air", id: "minecraft:jigsaw", joint: "rollable", name: "trailiertales:corridor", placement_priority: 0, pool: "trailiertales:catacombs/corridor_connector", selection_priority: 0, target: "trailiertales:corridor"}},
        {pos: [0, 4, 13], state: "minecraft:candle{candles:4,lit:false,waterlogged:false}"},
        {pos: [0, 4, 14], state: "minecraft:deepslate_bricks"},
        {pos: [0, 4, 15], state: "minecraft:deepslate_bricks"},
        {pos: [1, 4, 9], state: "minecraft:deepslate_bricks"},
        {pos: [1, 4, 10], state: "minecraft:deepslate_brick_stairs{facing:north,half:top,shape:straight,waterlogged:false}"},
        {pos: [1, 4, 11], state: "minecraft:candle{candles:4,lit:false,waterlogged:false}"},
        {pos: [1, 4, 12], state: "minecraft:cave_air"},
        {pos: [1, 4, 13], state: "minecraft:candle{candles:4,lit:false,waterlogged:false}"},
        {pos: [1, 4, 14], state: "minecraft:deepslate_brick_stairs{facing:south,half:top,shape:straight,waterlogged:false}"},
        {pos: [1, 4, 15], state: "minecraft:deepslate_bricks"},
        {pos: [2, 4, 5], state: "minecraft:deepslate_bricks"},
        {pos: [2, 4, 6], state: "minecraft:deepslate_bricks"},
        {pos: [2, 4, 7], state: "minecraft:deepslate_bricks"},
        {pos: [2, 4, 8], state: "minecraft:deepslate_bricks"},
        {pos: [2, 4, 9], state: "minecraft:deepslate_bricks"},
        {pos: [2, 4, 10], state: "minecraft:deepslate_bricks"},
        {pos: [2, 4, 11], state: "minecraft:candle{candles:4,lit:false,waterlogged:false}"},
        {pos: [2, 4, 12], state: "minecraft:cave_air"},
        {pos: [2, 4, 13], state: "minecraft:candle{candles:4,lit:false,waterlogged:false}"},
        {pos: [2, 4, 14], state: "minecraft:deepslate_bricks"},
        {pos: [2, 4, 15], state: "minecraft:deepslate_bricks"},
        {pos: [2, 4, 16], state: "minecraft:deepslate_bricks"},
        {pos: [2, 4, 17], state: "minecraft:deepslate_bricks"},
        {pos: [2, 4, 18], state: "minecraft:deepslate_bricks"},
        {pos: [2, 4, 19], state: "minecraft:deepslate_bricks"},
        {pos: [3, 4, 5], state: "minecraft:deepslate_bricks"},
        {pos: [3, 4, 6], state: "minecraft:deepslate_bricks"},
        {pos: [3, 4, 7], state: "minecraft:decorated_pot{cracked:false,facing:north,waterlogged:false}", nbt: {id: "minecraft:decorated_pot"}},
        {pos: [3, 4, 8], state: "minecraft:candle{candles:4,lit:false,waterlogged:false}"},
        {pos: [3, 4, 9], state: "minecraft:skeleton_skull{powered:false,rotation:4}", nbt: {id: "minecraft:skull"}},
        {pos: [3, 4, 10], state: "minecraft:candle{candles:4,lit:false,waterlogged:false}"},
        {pos: [3, 4, 11], state: "minecraft:cave_air"},
        {pos: [3, 4, 12], state: "minecraft:cave_air"},
        {pos: [3, 4, 13], state: "minecraft:cave_air"},
        {pos: [3, 4, 14], state: "minecraft:candle{candles:4,lit:false,waterlogged:false}"},
        {pos: [3, 4, 15], state: "minecraft:candle{candles:4,lit:false,waterlogged:false}"},
        {pos: [3, 4, 16], state: "minecraft:skeleton_skull{powered:false,rotation:0}", nbt: {id: "minecraft:skull"}},
        {pos: [3, 4, 17], state: "minecraft:decorated_pot{cracked:false,facing:south,waterlogged:false}", nbt: {id: "minecraft:decorated_pot"}},
        {pos: [3, 4, 18], state: "minecraft:deepslate_bricks"},
        {pos: [3, 4, 19], state: "minecraft:deepslate_bricks"},
        {pos: [4, 4, 0], state: "minecraft:deepslate_bricks"},
        {pos: [4, 4, 1], state: "minecraft:deepslate_bricks"},
        {pos: [4, 4, 2], state: "minecraft:deepslate_bricks"},
        {pos: [4, 4, 3], state: "minecraft:deepslate_bricks"},
        {pos: [4, 4, 4], state: "minecraft:deepslate_bricks"},
        {pos: [4, 4, 5], state: "minecraft:deepslate_bricks"},
        {pos: [4, 4, 6], state: "minecraft:deepslate_brick_stairs{facing:north,half:top,shape:straight,waterlogged:false}"},
        {pos: [4, 4, 7], state: "minecraft:candle{candles:4,lit:false,waterlogged:false}"},
        {pos: [4, 4, 8], state: "minecraft:cave_air"},
        {pos: [4, 4, 9], state: "minecraft:candle{candles:4,lit:false,waterlogged:false}"},
        {pos: [4, 4, 10], state: "minecraft:cave_air"},
        {pos: [4, 4, 11], state: "minecraft:cave_air"},
        {pos: [4, 4, 12], state: "minecraft:cave_air"},
        {pos: [4, 4, 13], state: "minecraft:cave_air"},
        {pos: [4, 4, 14], state: "minecraft:skeleton_skull{powered:false,rotation:0}", nbt: {id: "minecraft:skull"}},
        {pos: [4, 4, 15], state: "minecraft:cave_air"},
        {pos: [4, 4, 16], state: "minecraft:cave_air"},
        {pos: [4, 4, 17], state: "minecraft:candle{candles:4,lit:false,waterlogged:false}"},
        {pos: [4, 4, 18], state: "minecraft:deepslate_brick_stairs{facing:south,half:top,shape:straight,waterlogged:false}"},
        {pos: [4, 4, 19], state: "minecraft:deepslate_bricks"},
        {pos: [4, 4, 20], state: "minecraft:deepslate_bricks"},
        {pos: [4, 4, 21], state: "minecraft:deepslate_bricks"},
        {pos: [4, 4, 22], state: "minecraft:deepslate_bricks"},
        {pos: [4, 4, 23], state: "minecraft:deepslate_bricks"},
        {pos: [4, 4, 24], state: "minecraft:deepslate_bricks"},
        {pos: [5, 4, 0], state: "minecraft:deepslate_bricks"},
        {pos: [5, 4, 1], state: "minecraft:skeleton_skull{powered:false,rotation:8}", nbt: {id: "minecraft:skull"}},
        {pos: [5, 4, 2], state: "minecraft:candle{candles:4,lit:false,waterlogged:false}"},
        {pos: [5, 4, 3], state: "minecraft:candle{candles:4,lit:false,waterlogged:false}"},
        {pos: [5, 4, 4], state: "minecraft:deepslate_bricks"},
        {pos: [5, 4, 5], state: "minecraft:deepslate_bricks"},
        {pos: [5, 4, 6], state: "minecraft:deepslate_bricks"},
        {pos: [5, 4, 7], state: "minecraft:candle{candles:4,lit:false,waterlogged:false}"},
        {pos: [5, 4, 8], state: "minecraft:cave_air"},
        {pos: [5, 4, 9], state: "minecraft:cave_air"},
        {pos: [5, 4, 10], state: "minecraft:cave_air"},
        {pos: [5, 4, 11], state: "minecraft:cave_air"},
        {pos: [5, 4, 12], state: "minecraft:cave_air"},
        {pos: [5, 4, 13], state: "minecraft:cave_air"},
        {pos: [5, 4, 14], state: "minecraft:cave_air"},
        {pos: [5, 4, 15], state: "minecraft:cave_air"},
        {pos: [5, 4, 16], state: "minecraft:cave_air"},
        {pos: [5, 4, 17], state: "minecraft:skeleton_skull{powered:false,rotation:0}", nbt: {id: "minecraft:skull"}},
        {pos: [5, 4, 18], state: "minecraft:deepslate_bricks"},
        {pos: [5, 4, 19], state: "minecraft:deepslate_bricks"},
        {pos: [5, 4, 20], state: "minecraft:deepslate_bricks"},
        {pos: [5, 4, 21], state: "minecraft:candle{candles:4,lit:false,waterlogged:false}"},
        {pos: [5, 4, 22], state: "minecraft:candle{candles:4,lit:false,waterlogged:false}"},
        {pos: [5, 4, 23], state: "minecraft:skeleton_skull{powered:false,rotation:4}", nbt: {id: "minecraft:skull"}},
        {pos: [5, 4, 24], state: "minecraft:deepslate_bricks"},
        {pos: [6, 4, 0], state: "minecraft:deepslate_bricks"},
        {pos: [6, 4, 1], state: "minecraft:skeleton_skull{powered:false,rotation:8}", nbt: {id: "minecraft:skull"}},
        {pos: [6, 4, 2], state: "minecraft:cave_air"},
        {pos: [6, 4, 3], state: "minecraft:cave_air"},
        {pos: [6, 4, 4], state: "minecraft:cave_air"},
        {pos: [6, 4, 5], state: "minecraft:deepslate_tiles"},
        {pos: [6, 4, 6], state: "minecraft:cave_air"},
        {pos: [6, 4, 7], state: "minecraft:cave_air"},
        {pos: [6, 4, 8], state: "minecraft:cave_air"},
        {pos: [6, 4, 9], state: "minecraft:cave_air"},
        {pos: [6, 4, 10], state: "minecraft:cave_air"},
        {pos: [6, 4, 11], state: "minecraft:cave_air"},
        {pos: [6, 4, 12], state: "minecraft:cave_air"},
        {pos: [6, 4, 13], state: "minecraft:cave_air"},
        {pos: [6, 4, 14], state: "minecraft:cave_air"},
        {pos: [6, 4, 15], state: "minecraft:cave_air"},
        {pos: [6, 4, 16], state: "minecraft:cave_air"},
        {pos: [6, 4, 17], state: "minecraft:cave_air"},
        {pos: [6, 4, 18], state: "minecraft:cave_air"},
        {pos: [6, 4, 19], state: "minecraft:deepslate_tiles"},
        {pos: [6, 4, 20], state: "minecraft:cave_air"},
        {pos: [6, 4, 21], state: "minecraft:cave_air"},
        {pos: [6, 4, 22], state: "minecraft:cave_air"},
        {pos: [6, 4, 23], state: "minecraft:candle{candles:4,lit:false,waterlogged:false}"},
        {pos: [6, 4, 24], state: "minecraft:deepslate_bricks"},
        {pos: [7, 4, 0], state: "minecraft:deepslate_bricks"},
        {pos: [7, 4, 1], state: "minecraft:candle{candles:4,lit:false,waterlogged:false}"},
        {pos: [7, 4, 2], state: "minecraft:cave_air"},
        {pos: [7, 4, 3], state: "minecraft:candle{candles:4,lit:false,waterlogged:false}"},
        {pos: [7, 4, 4], state: "minecraft:deepslate_bricks"},
        {pos: [7, 4, 5], state: "minecraft:piston_head{facing:west,short:false,type:sticky}"},
        {pos: [7, 4, 6], state: "minecraft:deepslate_bricks"},
        {pos: [7, 4, 7], state: "minecraft:deepslate_brick_stairs{facing:east,half:top,shape:straight,waterlogged:false}"},
        {pos: [7, 4, 8], state: "minecraft:deepslate_brick_stairs{facing:east,half:top,shape:straight,waterlogged:false}"},
        {pos: [7, 4, 9], state: "minecraft:deepslate_brick_stairs{facing:east,half:top,shape:straight,waterlogged:false}"},
        {pos: [7, 4, 10], state: "minecraft:candle{candles:4,lit:false,waterlogged:false}"},
        {pos: [7, 4, 11], state: "minecraft:cave_air"},
        {pos: [7, 4, 12], state: "minecraft:cave_air"},
        {pos: [7, 4, 13], state: "minecraft:cave_air"},
        {pos: [7, 4, 14], state: "minecraft:candle{candles:4,lit:false,waterlogged:false}"},
        {pos: [7, 4, 15], state: "minecraft:deepslate_brick_stairs{facing:east,half:top,shape:straight,waterlogged:false}"},
        {pos: [7, 4, 16], state: "minecraft:deepslate_brick_stairs{facing:east,half:top,shape:straight,waterlogged:false}"},
        {pos: [7, 4, 17], state: "minecraft:deepslate_brick_stairs{facing:east,half:top,shape:straight,waterlogged:false}"},
        {pos: [7, 4, 18], state: "minecraft:deepslate_bricks"},
        {pos: [7, 4, 19], state: "minecraft:piston_head{facing:west,short:false,type:sticky}"},
        {pos: [7, 4, 20], state: "minecraft:deepslate_bricks"},
        {pos: [7, 4, 21], state: "minecraft:candle{candles:4,lit:false,waterlogged:false}"},
        {pos: [7, 4, 22], state: "minecraft:cave_air"},
        {pos: [7, 4, 23], state: "minecraft:candle{candles:4,lit:false,waterlogged:false}"},
        {pos: [7, 4, 24], state: "minecraft:deepslate_bricks"},
        {pos: [8, 4, 0], state: "minecraft:deepslate_bricks"},
        {pos: [8, 4, 1], state: "minecraft:deepslate_brick_stairs{facing:east,half:bottom,shape:straight,waterlogged:false}"},
        {pos: [8, 4, 2], state: "minecraft:deepslate_brick_stairs{facing:east,half:bottom,shape:straight,waterlogged:false}"},
        {pos: [8, 4, 3], state: "minecraft:deepslate_brick_stairs{facing:east,half:bottom,shape:straight,waterlogged:false}"},
        {pos: [8, 4, 4], state: "minecraft:deepslate_bricks"},
        {pos: [8, 4, 5], state: "minecraft:sticky_piston{extended:true,facing:west}"},
        {pos: [8, 4, 6], state: "minecraft:deepslate_bricks"},
        {pos: [8, 4, 7], state: "minecraft:deepslate_bricks"},
        {pos: [8, 4, 8], state: "minecraft:deepslate_bricks"},
        {pos: [8, 4, 9], state: "minecraft:deepslate_bricks"},
        {pos: [8, 4, 10], state: "minecraft:deepslate_bricks"},
        {pos: [8, 4, 11], state: "minecraft:deepslate_tiles"},
        {pos: [8, 4, 12], state: "minecraft:deepslate_tiles"},
        {pos: [8, 4, 13], state: "minecraft:deepslate_tiles"},
        {pos: [8, 4, 14], state: "minecraft:deepslate_bricks"},
        {pos: [8, 4, 15], state: "minecraft:deepslate_bricks"},
        {pos: [8, 4, 16], state: "minecraft:deepslate_bricks"},
        {pos: [8, 4, 17], state: "minecraft:deepslate_bricks"},
        {pos: [8, 4, 18], state: "minecraft:deepslate_bricks"},
        {pos: [8, 4, 19], state: "minecraft:sticky_piston{extended:true,facing:west}"},
        {pos: [8, 4, 20], state: "minecraft:deepslate_bricks"},
        {pos: [8, 4, 21], state: "minecraft:deepslate_brick_stairs{facing:east,half:bottom,shape:straight,waterlogged:false}"},
        {pos: [8, 4, 22], state: "minecraft:deepslate_brick_stairs{facing:east,half:bottom,shape:straight,waterlogged:false}"},
        {pos: [8, 4, 23], state: "minecraft:deepslate_brick_stairs{facing:east,half:bottom,shape:straight,waterlogged:false}"},
        {pos: [8, 4, 24], state: "minecraft:deepslate_bricks"},
        {pos: [9, 4, 0], state: "minecraft:deepslate_bricks"},
        {pos: [9, 4, 1], state: "minecraft:deepslate_bricks"},
        {pos: [9, 4, 2], state: "minecraft:deepslate_bricks"},
        {pos: [9, 4, 3], state: "minecraft:deepslate_bricks"},
        {pos: [9, 4, 4], state: "minecraft:deepslate_bricks"},
        {pos: [9, 4, 5], state: "minecraft:deepslate_bricks"},
        {pos: [9, 4, 6], state: "minecraft:deepslate_bricks"},
        {pos: [9, 4, 7], state: "minecraft:deepslate_bricks"},
        {pos: [9, 4, 8], state: "minecraft:candle{candles:4,lit:false,waterlogged:false}"},
        {pos: [9, 4, 9], state: "minecraft:skeleton_skull{powered:false,rotation:8}", nbt: {id: "minecraft:skull"}},
        {pos: [9, 4, 10], state: "minecraft:candle{candles:4,lit:false,waterlogged:false}"},
        {pos: [9, 4, 11], state: "minecraft:cave_air"},
        {pos: [9, 4, 12], state: "minecraft:cave_air"},
        {pos: [9, 4, 13], state: "minecraft:cave_air"},
        {pos: [9, 4, 14], state: "minecraft:skeleton_skull{powered:false,rotation:0}", nbt: {id: "minecraft:skull"}},
        {pos: [9, 4, 15], state: "minecraft:candle{candles:4,lit:false,waterlogged:false}"},
        {pos: [9, 4, 16], state: "minecraft:decorated_pot{cracked:false,facing:south,waterlogged:false}", nbt: {id: "minecraft:decorated_pot"}},
        {pos: [9, 4, 17], state: "minecraft:deepslate_bricks"},
        {pos: [9, 4, 18], state: "minecraft:deepslate_bricks"},
        {pos: [9, 4, 19], state: "minecraft:deepslate_bricks"},
        {pos: [9, 4, 20], state: "minecraft:deepslate_bricks"},
        {pos: [9, 4, 21], state: "minecraft:deepslate_bricks"},
        {pos: [9, 4, 22], state: "minecraft:deepslate_bricks"},
        {pos: [9, 4, 23], state: "minecraft:deepslate_bricks"},
        {pos: [9, 4, 24], state: "minecraft:deepslate_bricks"},
        {pos: [10, 4, 0], state: "minecraft:deepslate_bricks"},
        {pos: [10, 4, 1], state: "minecraft:deepslate_bricks"},
        {pos: [10, 4, 2], state: "minecraft:deepslate_bricks"},
        {pos: [10, 4, 3], state: "minecraft:deepslate_bricks"},
        {pos: [10, 4, 4], state: "minecraft:deepslate_bricks"},
        {pos: [10, 4, 5], state: "minecraft:deepslate_bricks"},
        {pos: [10, 4, 6], state: "minecraft:deepslate_bricks"},
        {pos: [10, 4, 7], state: "minecraft:deepslate_bricks"},
        {pos: [10, 4, 8], state: "trailiertales:coffin{facing:north,part:head,state:inactive}", nbt: {id: "trailiertales:coffin"}},
        {pos: [10, 4, 9], state: "trailiertales:coffin{facing:north,part:foot,state:inactive}", nbt: {id: "trailiertales:coffin", max_active_light_level: 7, uuid: "94c14388-24cc-4906-b262-236212a36b4a"}},
        {pos: [10, 4, 10], state: "minecraft:cave_air"},
        {pos: [10, 4, 11], state: "minecraft:cave_air"},
        {pos: [10, 4, 12], state: "minecraft:cave_air"},
        {pos: [10, 4, 13], state: "minecraft:cave_air"},
        {pos: [10, 4, 14], state: "minecraft:cave_air"},
        {pos: [10, 4, 15], state: "trailiertales:coffin{facing:north,part:head,state:inactive}", nbt: {id: "trailiertales:coffin"}},
        {pos: [10, 4, 16], state: "trailiertales:coffin{facing:north,part:foot,state:inactive}", nbt: {id: "trailiertales:coffin", max_active_light_level: 7, uuid: "b8738857-b19b-4673-a2d4-4b2d0173f1bb"}},
        {pos: [10, 4, 17], state: "minecraft:deepslate_bricks"},
        {pos: [10, 4, 18], state: "minecraft:deepslate_bricks"},
        {pos: [10, 4, 19], state: "minecraft:deepslate_bricks"},
        {pos: [10, 4, 20], state: "minecraft:deepslate_bricks"},
        {pos: [10, 4, 21], state: "minecraft:deepslate_bricks"},
        {pos: [10, 4, 22], state: "minecraft:deepslate_bricks"},
        {pos: [10, 4, 23], state: "minecraft:deepslate_bricks"},
        {pos: [10, 4, 24], state: "minecraft:deepslate_bricks"},
        {pos: [11, 4, 0], state: "minecraft:deepslate_bricks"},
        {pos: [11, 4, 1], state: "minecraft:deepslate_bricks"},
        {pos: [11, 4, 2], state: "minecraft:deepslate_bricks"},
        {pos: [11, 4, 3], state: "minecraft:deepslate_bricks"},
        {pos: [11, 4, 4], state: "minecraft:deepslate_bricks"},
        {pos: [11, 4, 5], state: "minecraft:deepslate_bricks"},
        {pos: [11, 4, 6], state: "minecraft:deepslate_bricks"},
        {pos: [11, 4, 7], state: "minecraft:deepslate_bricks"},
        {pos: [11, 4, 8], state: "minecraft:skeleton_skull{powered:false,rotation:8}", nbt: {id: "minecraft:skull"}},
        {pos: [11, 4, 9], state: "minecraft:candle{candles:4,lit:false,waterlogged:false}"},
        {pos: [11, 4, 10], state: "minecraft:skeleton_skull{powered:false,rotation:8}", nbt: {id: "minecraft:skull"}},
        {pos: [11, 4, 11], state: "minecraft:cave_air"},
        {pos: [11, 4, 12], state: "minecraft:cave_air"},
        {pos: [11, 4, 13], state: "minecraft:cave_air"},
        {pos: [11, 4, 14], state: "minecraft:candle{candles:4,lit:false,waterlogged:false}"},
        {pos: [11, 4, 15], state: "minecraft:skeleton_skull{powered:false,rotation:0}", nbt: {id: "minecraft:skull"}},
        {pos: [11, 4, 16], state: "minecraft:candle{candles:4,lit:false,waterlogged:false}"},
        {pos: [11, 4, 17], state: "minecraft:deepslate_bricks"},
        {pos: [11, 4, 18], state: "minecraft:deepslate_bricks"},
        {pos: [11, 4, 19], state: "minecraft:deepslate_bricks"},
        {pos: [11, 4, 20], state: "minecraft:deepslate_bricks"},
        {pos: [11, 4, 21], state: "minecraft:deepslate_bricks"},
        {pos: [11, 4, 22], state: "minecraft:deepslate_bricks"},
        {pos: [11, 4, 23], state: "minecraft:deepslate_bricks"},
        {pos: [11, 4, 24], state: "minecraft:deepslate_bricks"},
        {pos: [12, 4, 0], state: "minecraft:deepslate_bricks"},
        {pos: [12, 4, 1], state: "minecraft:deepslate_bricks"},
        {pos: [12, 4, 2], state: "minecraft:deepslate_bricks"},
        {pos: [12, 4, 3], state: "minecraft:deepslate_bricks"},
        {pos: [12, 4, 4], state: "minecraft:deepslate_bricks"},
        {pos: [12, 4, 5], state: "minecraft:deepslate_bricks"},
        {pos: [12, 4, 6], state: "minecraft:deepslate_bricks"},
        {pos: [12, 4, 7], state: "minecraft:deepslate_bricks"},
        {pos: [12, 4, 8], state: "minecraft:deepslate_bricks"},
        {pos: [12, 4, 9], state: "minecraft:deepslate_bricks"},
        {pos: [12, 4, 10], state: "minecraft:deepslate_bricks"},
        {pos: [12, 4, 11], state: "minecraft:candle{candles:4,lit:false,waterlogged:false}"},
        {pos: [12, 4, 12], state: "minecraft:cave_air"},
        {pos: [12, 4, 13], state: "minecraft:candle{candles:4,lit:false,waterlogged:false}"},
        {pos: [12, 4, 14], state: "minecraft:deepslate_bricks"},
        {pos: [12, 4, 15], state: "minecraft:deepslate_bricks"},
        {pos: [12, 4, 16], state: "minecraft:deepslate_bricks"},
        {pos: [12, 4, 17], state: "minecraft:deepslate_bricks"},
        {pos: [12, 4, 18], state: "minecraft:deepslate_bricks"},
        {pos: [12, 4, 19], state: "minecraft:deepslate_bricks"},
        {pos: [12, 4, 20], state: "minecraft:deepslate_bricks"},
        {pos: [12, 4, 21], state: "minecraft:deepslate_bricks"},
        {pos: [12, 4, 22], state: "minecraft:deepslate_bricks"},
        {pos: [12, 4, 23], state: "minecraft:deepslate_bricks"},
        {pos: [12, 4, 24], state: "minecraft:deepslate_bricks"},
        {pos: [13, 4, 0], state: "minecraft:deepslate_bricks"},
        {pos: [13, 4, 1], state: "minecraft:deepslate_bricks"},
        {pos: [13, 4, 2], state: "minecraft:deepslate_bricks"},
        {pos: [13, 4, 3], state: "minecraft:deepslate_bricks"},
        {pos: [13, 4, 4], state: "minecraft:deepslate_bricks"},
        {pos: [13, 4, 5], state: "minecraft:deepslate_bricks"},
        {pos: [13, 4, 6], state: "minecraft:deepslate_bricks"},
        {pos: [13, 4, 7], state: "minecraft:deepslate_bricks"},
        {pos: [13, 4, 8], state: "minecraft:deepslate_bricks"},
        {pos: [13, 4, 9], state: "minecraft:deepslate_bricks"},
        {pos: [13, 4, 10], state: "minecraft:deepslate_bricks"},
        {pos: [13, 4, 11], state: "minecraft:candle{candles:4,lit:false,waterlogged:false}"},
        {pos: [13, 4, 12], state: "minecraft:cave_air"},
        {pos: [13, 4, 13], state: "minecraft:candle{candles:4,lit:false,waterlogged:false}"},
        {pos: [13, 4, 14], state: "minecraft:deepslate_bricks"},
        {pos: [13, 4, 15], state: "minecraft:deepslate_bricks"},
        {pos: [13, 4, 16], state: "minecraft:deepslate_bricks"},
        {pos: [13, 4, 17], state: "minecraft:deepslate_bricks"},
        {pos: [13, 4, 18], state: "minecraft:deepslate_bricks"},
        {pos: [13, 4, 19], state: "minecraft:deepslate_bricks"},
        {pos: [13, 4, 20], state: "minecraft:deepslate_bricks"},
        {pos: [13, 4, 21], state: "minecraft:deepslate_bricks"},
        {pos: [13, 4, 22], state: "minecraft:deepslate_bricks"},
        {pos: [13, 4, 23], state: "minecraft:deepslate_bricks"},
        {pos: [13, 4, 24], state: "minecraft:deepslate_bricks"},
        {pos: [14, 4, 0], state: "minecraft:deepslate_bricks"},
        {pos: [14, 4, 1], state: "minecraft:deepslate_bricks"},
        {pos: [14, 4, 2], state: "minecraft:deepslate_bricks"},
        {pos: [14, 4, 3], state: "minecraft:deepslate_bricks"},
        {pos: [14, 4, 4], state: "minecraft:deepslate_bricks"},
        {pos: [14, 4, 5], state: "minecraft:deepslate_bricks"},
        {pos: [14, 4, 6], state: "minecraft:deepslate_bricks"},
        {pos: [14, 4, 7], state: "minecraft:deepslate_bricks"},
        {pos: [14, 4, 8], state: "minecraft:deepslate_bricks"},
        {pos: [14, 4, 9], state: "minecraft:deepslate_bricks"},
        {pos: [14, 4, 10], state: "minecraft:deepslate_bricks"},
        {pos: [14, 4, 11], state: "minecraft:decorated_pot{cracked:false,facing:east,waterlogged:false}", nbt: {id: "minecraft:decorated_pot"}},
        {pos: [14, 4, 12], state: "minecraft:candle{candles:4,lit:false,waterlogged:false}"},
        {pos: [14, 4, 13], state: "minecraft:candle{candles:4,lit:false,waterlogged:false}"},
        {pos: [14, 4, 14], state: "minecraft:deepslate_bricks"},
        {pos: [14, 4, 15], state: "minecraft:deepslate_bricks"},
        {pos: [14, 4, 16], state: "minecraft:deepslate_bricks"},
        {pos: [14, 4, 17], state: "minecraft:deepslate_bricks"},
        {pos: [14, 4, 18], state: "minecraft:deepslate_bricks"},
        {pos: [14, 4, 19], state: "minecraft:deepslate_bricks"},
        {pos: [14, 4, 20], state: "minecraft:cave_air"},
        {pos: [14, 4, 21], state: "minecraft:deepslate_bricks"},
        {pos: [14, 4, 22], state: "minecraft:deepslate_bricks"},
        {pos: [14, 4, 23], state: "minecraft:deepslate_bricks"},
        {pos: [14, 4, 24], state: "minecraft:deepslate_bricks"},
        {pos: [15, 4, 0], state: "minecraft:deepslate_bricks"},
        {pos: [15, 4, 1], state: "minecraft:deepslate_bricks"},
        {pos: [15, 4, 2], state: "minecraft:deepslate_bricks"},
        {pos: [15, 4, 3], state: "minecraft:deepslate_bricks"},
        {pos: [15, 4, 4], state: "minecraft:deepslate_bricks"},
        {pos: [15, 4, 5], state: "minecraft:deepslate_bricks"},
        {pos: [15, 4, 6], state: "minecraft:deepslate_bricks"},
        {pos: [15, 4, 7], state: "minecraft:deepslate_bricks"},
        {pos: [15, 4, 8], state: "minecraft:deepslate_bricks"},
        {pos: [15, 4, 9], state: "minecraft:deepslate_bricks"},
        {pos: [15, 4, 10], state: "minecraft:deepslate_bricks"},
        {pos: [15, 4, 11], state: "minecraft:deepslate_bricks"},
        {pos: [15, 4, 12], state: "minecraft:deepslate_bricks"},
        {pos: [15, 4, 13], state: "minecraft:deepslate_bricks"},
        {pos: [15, 4, 14], state: "minecraft:deepslate_bricks"},
        {pos: [15, 4, 15], state: "minecraft:deepslate_bricks"},
        {pos: [15, 4, 16], state: "minecraft:deepslate_bricks"},
        {pos: [15, 4, 17], state: "minecraft:deepslate_bricks"},
        {pos: [15, 4, 18], state: "minecraft:deepslate_bricks"},
        {pos: [15, 4, 19], state: "minecraft:deepslate_bricks"},
        {pos: [15, 4, 20], state: "minecraft:deepslate_bricks"},
        {pos: [15, 4, 21], state: "minecraft:deepslate_bricks"},
        {pos: [15, 4, 22], state: "minecraft:deepslate_bricks"},
        {pos: [15, 4, 23], state: "minecraft:deepslate_bricks"},
        {pos: [15, 4, 24], state: "minecraft:deepslate_bricks"},
        {pos: [16, 4, 0], state: "minecraft:deepslate_bricks"},
        {pos: [16, 4, 1], state: "minecraft:deepslate_bricks"},
        {pos: [16, 4, 2], state: "minecraft:deepslate_bricks"},
        {pos: [16, 4, 3], state: "minecraft:deepslate_bricks"},
        {pos: [16, 4, 4], state: "minecraft:deepslate_bricks"},
        {pos: [16, 4, 5], state: "minecraft:deepslate_bricks"},
        {pos: [16, 4, 6], state: "minecraft:deepslate_bricks"},
        {pos: [16, 4, 7], state: "minecraft:deepslate_bricks"},
        {pos: [16, 4, 8], state: "minecraft:deepslate_bricks"},
        {pos: [16, 4, 9], state: "minecraft:deepslate_bricks"},
        {pos: [16, 4, 10], state: "minecraft:deepslate_bricks"},
        {pos: [16, 4, 11], state: "minecraft:deepslate_bricks"},
        {pos: [16, 4, 12], state: "minecraft:deepslate_bricks"},
        {pos: [16, 4, 13], state: "minecraft:deepslate_bricks"},
        {pos: [16, 4, 14], state: "minecraft:deepslate_bricks"},
        {pos: [16, 4, 15], state: "minecraft:deepslate_bricks"},
        {pos: [16, 4, 16], state: "minecraft:deepslate_bricks"},
        {pos: [16, 4, 17], state: "minecraft:deepslate_bricks"},
        {pos: [16, 4, 18], state: "minecraft:deepslate_bricks"},
        {pos: [16, 4, 19], state: "minecraft:deepslate_bricks"},
        {pos: [16, 4, 20], state: "minecraft:deepslate_bricks"},
        {pos: [16, 4, 21], state: "minecraft:deepslate_bricks"},
        {pos: [16, 4, 22], state: "minecraft:deepslate_bricks"},
        {pos: [16, 4, 23], state: "minecraft:deepslate_bricks"},
        {pos: [16, 4, 24], state: "minecraft:deepslate_bricks"},
        {pos: [17, 4, 10], state: "minecraft:deepslate_bricks"},
        {pos: [17, 4, 11], state: "minecraft:deepslate_bricks"},
        {pos: [17, 4, 12], state: "minecraft:redstone_wire{east:none,north:side,power:0,south:side,west:none}"},
        {pos: [17, 4, 13], state: "minecraft:cave_air"},
        {pos: [17, 4, 14], state: "minecraft:deepslate_bricks"},
        {pos: [17, 4, 15], state: "minecraft:deepslate_bricks"},
        {pos: [17, 4, 16], state: "minecraft:deepslate_bricks"},
        {pos: [18, 4, 10], state: "minecraft:deepslate_bricks"},
        {pos: [18, 4, 11], state: "minecraft:deepslate_bricks"},
        {pos: [18, 4, 12], state: "minecraft:deepslate_bricks"},
        {pos: [18, 4, 13], state: "minecraft:deepslate_bricks"},
        {pos: [18, 4, 14], state: "minecraft:deepslate_bricks"},
        {pos: [18, 4, 15], state: "minecraft:deepslate_bricks"},
        {pos: [18, 4, 16], state: "minecraft:deepslate_bricks"},
        {pos: [19, 4, 11], state: "minecraft:deepslate_bricks"},
        {pos: [19, 4, 12], state: "minecraft:deepslate_bricks"},
        {pos: [19, 4, 13], state: "minecraft:deepslate_bricks"},
        {pos: [0, 5, 9], state: "minecraft:deepslate_bricks"},
        {pos: [0, 5, 10], state: "minecraft:deepslate_bricks"},
        {pos: [0, 5, 11], state: "minecraft:cave_air"},
        {pos: [0, 5, 12], state: "minecraft:cave_air"},
        {pos: [0, 5, 13], state: "minecraft:cave_air"},
        {pos: [0, 5, 14], state: "minecraft:deepslate_bricks"},
        {pos: [0, 5, 15], state: "minecraft:deepslate_bricks"},
        {pos: [1, 5, 9], state: "minecraft:deepslate_bricks"},
        {pos: [1, 5, 10], state: "minecraft:skeleton_skull{powered:false,rotation:8}", nbt: {id: "minecraft:skull"}},
        {pos: [1, 5, 11], state: "minecraft:cave_air"},
        {pos: [1, 5, 12], state: "minecraft:cave_air"},
        {pos: [1, 5, 13], state: "minecraft:cave_air"},
        {pos: [1, 5, 14], state: "minecraft:skeleton_skull{powered:false,rotation:0}", nbt: {id: "minecraft:skull"}},
        {pos: [1, 5, 15], state: "minecraft:deepslate_bricks"},
        {pos: [2, 5, 5], state: "minecraft:deepslate_bricks"},
        {pos: [2, 5, 6], state: "minecraft:deepslate_bricks"},
        {pos: [2, 5, 7], state: "minecraft:deepslate_bricks"},
        {pos: [2, 5, 8], state: "minecraft:deepslate_bricks"},
        {pos: [2, 5, 9], state: "minecraft:deepslate_bricks"},
        {pos: [2, 5, 10], state: "minecraft:deepslate_bricks"},
        {pos: [2, 5, 11], state: "minecraft:cave_air"},
        {pos: [2, 5, 12], state: "minecraft:cave_air"},
        {pos: [2, 5, 13], state: "minecraft:cave_air"},
        {pos: [2, 5, 14], state: "minecraft:deepslate_bricks"},
        {pos: [2, 5, 15], state: "minecraft:deepslate_bricks"},
        {pos: [2, 5, 16], state: "minecraft:deepslate_bricks"},
        {pos: [2, 5, 17], state: "minecraft:deepslate_bricks"},
        {pos: [2, 5, 18], state: "minecraft:deepslate_bricks"},
        {pos: [2, 5, 19], state: "minecraft:deepslate_bricks"},
        {pos: [3, 5, 5], state: "minecraft:deepslate_bricks"},
        {pos: [3, 5, 6], state: "minecraft:deepslate_bricks"},
        {pos: [3, 5, 7], state: "minecraft:cave_air"},
        {pos: [3, 5, 8], state: "minecraft:cave_air"},
        {pos: [3, 5, 9], state: "minecraft:cave_air"},
        {pos: [3, 5, 10], state: "minecraft:cave_air"},
        {pos: [3, 5, 11], state: "minecraft:cave_air"},
        {pos: [3, 5, 12], state: "minecraft:cave_air"},
        {pos: [3, 5, 13], state: "minecraft:cave_air"},
        {pos: [3, 5, 14], state: "minecraft:cave_air"},
        {pos: [3, 5, 15], state: "minecraft:cave_air"},
        {pos: [3, 5, 16], state: "minecraft:cave_air"},
        {pos: [3, 5, 17], state: "minecraft:cave_air"},
        {pos: [3, 5, 18], state: "minecraft:deepslate_bricks"},
        {pos: [3, 5, 19], state: "minecraft:deepslate_bricks"},
        {pos: [4, 5, 0], state: "minecraft:deepslate_bricks"},
        {pos: [4, 5, 1], state: "minecraft:deepslate_bricks"},
        {pos: [4, 5, 2], state: "minecraft:deepslate_bricks"},
        {pos: [4, 5, 3], state: "minecraft:deepslate_bricks"},
        {pos: [4, 5, 4], state: "minecraft:deepslate_bricks"},
        {pos: [4, 5, 5], state: "minecraft:deepslate_bricks"},
        {pos: [4, 5, 6], state: "minecraft:skeleton_skull{powered:false,rotation:8}", nbt: {id: "minecraft:skull"}},
        {pos: [4, 5, 7], state: "minecraft:cave_air"},
        {pos: [4, 5, 8], state: "minecraft:cave_air"},
        {pos: [4, 5, 9], state: "minecraft:cave_air"},
        {pos: [4, 5, 10], state: "minecraft:cave_air"},
        {pos: [4, 5, 11], state: "minecraft:cave_air"},
        {pos: [4, 5, 12], state: "minecraft:cave_air"},
        {pos: [4, 5, 13], state: "minecraft:cave_air"},
        {pos: [4, 5, 14], state: "minecraft:cave_air"},
        {pos: [4, 5, 15], state: "minecraft:cave_air"},
        {pos: [4, 5, 16], state: "minecraft:cave_air"},
        {pos: [4, 5, 17], state: "minecraft:cave_air"},
        {pos: [4, 5, 18], state: "minecraft:skeleton_skull{powered:false,rotation:0}", nbt: {id: "minecraft:skull"}},
        {pos: [4, 5, 19], state: "minecraft:deepslate_bricks"},
        {pos: [4, 5, 20], state: "minecraft:deepslate_bricks"},
        {pos: [4, 5, 21], state: "minecraft:deepslate_bricks"},
        {pos: [4, 5, 22], state: "minecraft:deepslate_bricks"},
        {pos: [4, 5, 23], state: "minecraft:deepslate_bricks"},
        {pos: [4, 5, 24], state: "minecraft:deepslate_bricks"},
        {pos: [5, 5, 0], state: "minecraft:deepslate_bricks"},
        {pos: [5, 5, 1], state: "minecraft:cave_air"},
        {pos: [5, 5, 2], state: "minecraft:cave_air"},
        {pos: [5, 5, 3], state: "minecraft:cave_air"},
        {pos: [5, 5, 4], state: "minecraft:deepslate_bricks"},
        {pos: [5, 5, 5], state: "minecraft:deepslate_bricks"},
        {pos: [5, 5, 6], state: "minecraft:deepslate_bricks"},
        {pos: [5, 5, 7], state: "minecraft:cave_air"},
        {pos: [5, 5, 8], state: "minecraft:cave_air"},
        {pos: [5, 5, 9], state: "minecraft:cave_air"},
        {pos: [5, 5, 10], state: "minecraft:cave_air"},
        {pos: [5, 5, 11], state: "minecraft:cave_air"},
        {pos: [5, 5, 12], state: "minecraft:cave_air"},
        {pos: [5, 5, 13], state: "minecraft:cave_air"},
        {pos: [5, 5, 14], state: "minecraft:cave_air"},
        {pos: [5, 5, 15], state: "minecraft:cave_air"},
        {pos: [5, 5, 16], state: "minecraft:cave_air"},
        {pos: [5, 5, 17], state: "minecraft:cave_air"},
        {pos: [5, 5, 18], state: "minecraft:deepslate_bricks"},
        {pos: [5, 5, 19], state: "minecraft:deepslate_bricks"},
        {pos: [5, 5, 20], state: "minecraft:deepslate_bricks"},
        {pos: [5, 5, 21], state: "minecraft:cave_air"},
        {pos: [5, 5, 22], state: "minecraft:cave_air"},
        {pos: [5, 5, 23], state: "minecraft:cave_air"},
        {pos: [5, 5, 24], state: "minecraft:deepslate_bricks"},
        {pos: [6, 5, 0], state: "minecraft:deepslate_bricks"},
        {pos: [6, 5, 1], state: "minecraft:cave_air"},
        {pos: [6, 5, 2], state: "minecraft:cave_air"},
        {pos: [6, 5, 3], state: "minecraft:cave_air"},
        {pos: [6, 5, 4], state: "minecraft:cave_air"},
        {pos: [6, 5, 5], state: "minecraft:deepslate_tiles"},
        {pos: [6, 5, 6], state: "minecraft:cave_air"},
        {pos: [6, 5, 7], state: "minecraft:cave_air"},
        {pos: [6, 5, 8], state: "minecraft:cave_air"},
        {pos: [6, 5, 9], state: "minecraft:cave_air"},
        {pos: [6, 5, 10], state: "minecraft:cave_air"},
        {pos: [6, 5, 11], state: "minecraft:cave_air"},
        {pos: [6, 5, 12], state: "minecraft:cave_air"},
        {pos: [6, 5, 13], state: "minecraft:cave_air"},
        {pos: [6, 5, 14], state: "minecraft:cave_air"},
        {pos: [6, 5, 15], state: "minecraft:cave_air"},
        {pos: [6, 5, 16], state: "minecraft:cave_air"},
        {pos: [6, 5, 17], state: "minecraft:cave_air"},
        {pos: [6, 5, 18], state: "minecraft:cave_air"},
        {pos: [6, 5, 19], state: "minecraft:deepslate_tiles"},
        {pos: [6, 5, 20], state: "minecraft:cave_air"},
        {pos: [6, 5, 21], state: "minecraft:cave_air"},
        {pos: [6, 5, 22], state: "minecraft:cave_air"},
        {pos: [6, 5, 23], state: "minecraft:cave_air"},
        {pos: [6, 5, 24], state: "minecraft:deepslate_bricks"},
        {pos: [7, 5, 0], state: "minecraft:deepslate_bricks"},
        {pos: [7, 5, 1], state: "minecraft:cave_air"},
        {pos: [7, 5, 2], state: "minecraft:cave_air"},
        {pos: [7, 5, 3], state: "minecraft:cave_air"},
        {pos: [7, 5, 4], state: "minecraft:deepslate_bricks"},
        {pos: [7, 5, 5], state: "minecraft:piston_head{facing:west,short:false,type:sticky}"},
        {pos: [7, 5, 6], state: "minecraft:deepslate_bricks"},
        {pos: [7, 5, 7], state: "minecraft:candle{candles:4,lit:false,waterlogged:false}"},
        {pos: [7, 5, 8], state: "minecraft:skeleton_skull{powered:false,rotation:12}", nbt: {id: "minecraft:skull"}},
        {pos: [7, 5, 9], state: "minecraft:candle{candles:4,lit:false,waterlogged:false}"},
        {pos: [7, 5, 10], state: "minecraft:cave_air"},
        {pos: [7, 5, 11], state: "minecraft:cave_air"},
        {pos: [7, 5, 12], state: "minecraft:cave_air"},
        {pos: [7, 5, 13], state: "minecraft:cave_air"},
        {pos: [7, 5, 14], state: "minecraft:cave_air"},
        {pos: [7, 5, 15], state: "minecraft:skeleton_skull{powered:false,rotation:12}", nbt: {id: "minecraft:skull"}},
        {pos: [7, 5, 16], state: "minecraft:skeleton_skull{powered:false,rotation:12}", nbt: {id: "minecraft:skull"}},
        {pos: [7, 5, 17], state: "minecraft:candle{candles:4,lit:false,waterlogged:false}"},
        {pos: [7, 5, 18], state: "minecraft:deepslate_bricks"},
        {pos: [7, 5, 19], state: "minecraft:piston_head{facing:west,short:false,type:sticky}"},
        {pos: [7, 5, 20], state: "minecraft:deepslate_bricks"},
        {pos: [7, 5, 21], state: "minecraft:cave_air"},
        {pos: [7, 5, 22], state: "minecraft:cave_air"},
        {pos: [7, 5, 23], state: "minecraft:cave_air"},
        {pos: [7, 5, 24], state: "minecraft:deepslate_bricks"},
        {pos: [8, 5, 0], state: "minecraft:deepslate_bricks"},
        {pos: [8, 5, 1], state: "minecraft:cave_air"},
        {pos: [8, 5, 2], state: "minecraft:cave_air"},
        {pos: [8, 5, 3], state: "minecraft:cave_air"},
        {pos: [8, 5, 4], state: "minecraft:deepslate_bricks"},
        {pos: [8, 5, 5], state: "minecraft:sticky_piston{extended:true,facing:west}"},
        {pos: [8, 5, 6], state: "minecraft:deepslate_bricks"},
        {pos: [8, 5, 7], state: "minecraft:deepslate_bricks"},
        {pos: [8, 5, 8], state: "minecraft:deepslate_bricks"},
        {pos: [8, 5, 9], state: "minecraft:deepslate_bricks"},
        {pos: [8, 5, 10], state: "minecraft:deepslate_brick_stairs{facing:north,half:top,shape:straight,waterlogged:false}"},
        {pos: [8, 5, 11], state: "minecraft:cave_air"},
        {pos: [8, 5, 12], state: "minecraft:cave_air"},
        {pos: [8, 5, 13], state: "minecraft:cave_air"},
        {pos: [8, 5, 14], state: "minecraft:deepslate_brick_stairs{facing:south,half:top,shape:straight,waterlogged:false}"},
        {pos: [8, 5, 15], state: "minecraft:deepslate_bricks"},
        {pos: [8, 5, 16], state: "minecraft:deepslate_bricks"},
        {pos: [8, 5, 17], state: "minecraft:deepslate_bricks"},
        {pos: [8, 5, 18], state: "minecraft:deepslate_bricks"},
        {pos: [8, 5, 19], state: "minecraft:sticky_piston{extended:true,facing:west}"},
        {pos: [8, 5, 20], state: "minecraft:deepslate_bricks"},
        {pos: [8, 5, 21], state: "minecraft:cave_air"},
        {pos: [8, 5, 22], state: "minecraft:cave_air"},
        {pos: [8, 5, 23], state: "minecraft:cave_air"},
        {pos: [8, 5, 24], state: "minecraft:deepslate_bricks"},
        {pos: [9, 5, 0], state: "minecraft:deepslate_bricks"},
        {pos: [9, 5, 1], state: "minecraft:deepslate_brick_stairs{facing:east,half:bottom,shape:straight,waterlogged:false}"},
        {pos: [9, 5, 2], state: "minecraft:deepslate_brick_stairs{facing:east,half:bottom,shape:straight,waterlogged:false}"},
        {pos: [9, 5, 3], state: "minecraft:deepslate_brick_stairs{facing:east,half:bottom,shape:straight,waterlogged:false}"},
        {pos: [9, 5, 4], state: "minecraft:deepslate_bricks"},
        {pos: [9, 5, 5], state: "minecraft:repeater{delay:1,facing:east,locked:false,powered:true}"},
        {pos: [9, 5, 6], state: "minecraft:deepslate_bricks"},
        {pos: [9, 5, 7], state: "minecraft:deepslate_bricks"},
        {pos: [9, 5, 8], state: "minecraft:cave_air"},
        {pos: [9, 5, 9], state: "minecraft:cave_air"},
        {pos: [9, 5, 10], state: "minecraft:cave_air"},
        {pos: [9, 5, 11], state: "minecraft:cave_air"},
        {pos: [9, 5, 12], state: "minecraft:cave_air"},
        {pos: [9, 5, 13], state: "minecraft:cave_air"},
        {pos: [9, 5, 14], state: "minecraft:cave_air"},
        {pos: [9, 5, 15], state: "minecraft:cave_air"},
        {pos: [9, 5, 16], state: "minecraft:cave_air"},
        {pos: [9, 5, 17], state: "minecraft:deepslate_bricks"},
        {pos: [9, 5, 18], state: "minecraft:deepslate_bricks"},
        {pos: [9, 5, 19], state: "minecraft:repeater{delay:1,facing:east,locked:false,powered:true}"},
        {pos: [9, 5, 20], state: "minecraft:deepslate_bricks"},
        {pos: [9, 5, 21], state: "minecraft:deepslate_brick_stairs{facing:east,half:bottom,shape:straight,waterlogged:false}"},
