{
    DataVersion: 3953,
    size: [25, 18, 29],
    data: [
        {pos: [13, 0, 13], state: "minecraft:deepslate_bricks"},
        {pos: [13, 0, 14], state: "minecraft:deepslate_bricks"},
        {pos: [13, 0, 15], state: "minecraft:deepslate_bricks"},
        {pos: [14, 0, 13], state: "minecraft:deepslate_bricks"},
        {pos: [14, 0, 14], state: "minecraft:deepslate_bricks"},
        {pos: [14, 0, 15], state: "minecraft:deepslate_bricks"},
        {pos: [15, 0, 13], state: "minecraft:deepslate_bricks"},
        {pos: [15, 0, 14], state: "minecraft:deepslate_bricks"},
        {pos: [15, 0, 15], state: "minecraft:deepslate_bricks"},
        {pos: [16, 0, 13], state: "minecraft:deepslate_bricks"},
        {pos: [16, 0, 14], state: "minecraft:deepslate_bricks"},
        {pos: [16, 0, 15], state: "minecraft:deepslate_bricks"},
        {pos: [17, 0, 13], state: "minecraft:deepslate_bricks"},
        {pos: [17, 0, 14], state: "minecraft:deepslate_bricks"},
        {pos: [17, 0, 15], state: "minecraft:deepslate_bricks"},
        {pos: [18, 0, 13], state: "minecraft:deepslate_bricks"},
        {pos: [18, 0, 14], state: "minecraft:deepslate_bricks"},
        {pos: [18, 0, 15], state: "minecraft:deepslate_bricks"},
        {pos: [19, 0, 13], state: "minecraft:deepslate_bricks"},
        {pos: [19, 0, 14], state: "minecraft:deepslate_bricks"},
        {pos: [19, 0, 15], state: "minecraft:deepslate_bricks"},
        {pos: [20, 0, 13], state: "minecraft:deepslate_bricks"},
        {pos: [20, 0, 14], state: "minecraft:deepslate_bricks"},
        {pos: [20, 0, 15], state: "minecraft:deepslate_bricks"},
        {pos: [13, 1, 13], state: "minecraft:deepslate_bricks"},
        {pos: [13, 1, 14], state: "minecraft:deepslate_bricks"},
        {pos: [13, 1, 15], state: "minecraft:deepslate_bricks"},
        {pos: [14, 1, 13], state: "minecraft:deepslate_bricks"},
        {pos: [14, 1, 14], state: "minecraft:redstone_wire{east:side,north:none,power:15,south:none,west:side}"},
        {pos: [14, 1, 15], state: "minecraft:deepslate_bricks"},
        {pos: [15, 1, 13], state: "minecraft:deepslate_bricks"},
        {pos: [15, 1, 14], state: "minecraft:redstone_wire{east:side,north:none,power:14,south:none,west:side}"},
        {pos: [15, 1, 15], state: "minecraft:deepslate_bricks"},
        {pos: [16, 1, 13], state: "minecraft:deepslate_bricks"},
        {pos: [16, 1, 14], state: "minecraft:redstone_wire{east:side,north:none,power:13,south:none,west:side}"},
        {pos: [16, 1, 15], state: "minecraft:deepslate_bricks"},
        {pos: [17, 1, 13], state: "minecraft:deepslate_bricks"},
        {pos: [17, 1, 14], state: "minecraft:repeater{delay:1,facing:west,locked:false,powered:true}"},
        {pos: [17, 1, 15], state: "minecraft:deepslate_bricks"},
        {pos: [18, 1, 13], state: "minecraft:deepslate_bricks"},
        {pos: [18, 1, 14], state: "minecraft:deepslate_bricks"},
        {pos: [18, 1, 15], state: "minecraft:deepslate_bricks"},
        {pos: [18, 1, 16], state: "minecraft:deepslate_bricks"},
        {pos: [18, 1, 17], state: "minecraft:deepslate_bricks"},
        {pos: [18, 1, 18], state: "minecraft:deepslate_bricks"},
        {pos: [18, 1, 19], state: "minecraft:deepslate_bricks"},
        {pos: [18, 1, 20], state: "minecraft:deepslate_bricks"},
        {pos: [18, 1, 21], state: "minecraft:deepslate_bricks"},
        {pos: [18, 1, 22], state: "minecraft:deepslate_bricks"},
        {pos: [18, 1, 23], state: "minecraft:deepslate_bricks"},
        {pos: [19, 1, 5], state: "minecraft:deepslate_bricks"},
        {pos: [19, 1, 6], state: "minecraft:deepslate_bricks"},
        {pos: [19, 1, 7], state: "minecraft:deepslate_bricks"},
        {pos: [19, 1, 8], state: "minecraft:deepslate_bricks"},
        {pos: [19, 1, 9], state: "minecraft:deepslate_bricks"},
        {pos: [19, 1, 10], state: "minecraft:deepslate_bricks"},
        {pos: [19, 1, 11], state: "minecraft:deepslate_bricks"},
        {pos: [19, 1, 12], state: "minecraft:deepslate_bricks"},
        {pos: [19, 1, 13], state: "minecraft:deepslate_bricks"},
        {pos: [19, 1, 14], state: "minecraft:redstone_wall_torch{facing:east,lit:false}"},
        {pos: [19, 1, 15], state: "minecraft:deepslate_bricks"},
        {pos: [19, 1, 16], state: "minecraft:deepslate_bricks"},
        {pos: [19, 1, 17], state: "minecraft:deepslate_bricks"},
        {pos: [19, 1, 18], state: "minecraft:deepslate_bricks"},
        {pos: [19, 1, 19], state: "minecraft:deepslate_bricks"},
        {pos: [19, 1, 20], state: "minecraft:deepslate_bricks"},
        {pos: [19, 1, 21], state: "minecraft:deepslate_bricks"},
        {pos: [19, 1, 22], state: "minecraft:deepslate_bricks"},
        {pos: [19, 1, 23], state: "minecraft:deepslate_bricks"},
        {pos: [20, 1, 5], state: "minecraft:deepslate_bricks"},
        {pos: [20, 1, 6], state: "minecraft:deepslate_bricks"},
        {pos: [20, 1, 7], state: "minecraft:deepslate_bricks"},
        {pos: [20, 1, 8], state: "minecraft:deepslate_bricks"},
        {pos: [20, 1, 9], state: "minecraft:deepslate_bricks"},
        {pos: [20, 1, 10], state: "minecraft:deepslate_bricks"},
        {pos: [20, 1, 11], state: "minecraft:deepslate_bricks"},
        {pos: [20, 1, 12], state: "minecraft:deepslate_bricks"},
        {pos: [20, 1, 13], state: "minecraft:deepslate_bricks"},
        {pos: [20, 1, 14], state: "minecraft:redstone_wire{east:none,north:up,power:0,south:up,west:side}"},
        {pos: [20, 1, 15], state: "minecraft:deepslate_bricks"},
        {pos: [20, 1, 16], state: "minecraft:deepslate_bricks"},
        {pos: [20, 1, 17], state: "minecraft:deepslate_bricks"},
        {pos: [20, 1, 18], state: "minecraft:deepslate_bricks"},
        {pos: [20, 1, 19], state: "minecraft:deepslate_bricks"},
        {pos: [20, 1, 20], state: "minecraft:deepslate_bricks"},
        {pos: [20, 1, 21], state: "minecraft:deepslate_bricks"},
        {pos: [20, 1, 22], state: "minecraft:deepslate_bricks"},
        {pos: [20, 1, 23], state: "minecraft:deepslate_bricks"},
        {pos: [21, 1, 5], state: "minecraft:deepslate_bricks"},
        {pos: [21, 1, 6], state: "minecraft:deepslate_bricks"},
        {pos: [21, 1, 7], state: "minecraft:deepslate_bricks"},
        {pos: [21, 1, 8], state: "minecraft:deepslate_bricks"},
        {pos: [21, 1, 9], state: "minecraft:deepslate_bricks"},
        {pos: [21, 1, 10], state: "minecraft:deepslate_bricks"},
        {pos: [21, 1, 11], state: "minecraft:deepslate_bricks"},
        {pos: [21, 1, 12], state: "minecraft:deepslate_bricks"},
        {pos: [21, 1, 13], state: "minecraft:deepslate_bricks"},
        {pos: [21, 1, 14], state: "minecraft:deepslate_bricks"},
        {pos: [21, 1, 15], state: "minecraft:deepslate_bricks"},
        {pos: [21, 1, 16], state: "minecraft:deepslate_bricks"},
        {pos: [21, 1, 17], state: "minecraft:deepslate_bricks"},
        {pos: [21, 1, 18], state: "minecraft:deepslate_bricks"},
        {pos: [21, 1, 19], state: "minecraft:deepslate_bricks"},
        {pos: [21, 1, 20], state: "minecraft:deepslate_bricks"},
        {pos: [21, 1, 21], state: "minecraft:deepslate_bricks"},
        {pos: [21, 1, 22], state: "minecraft:deepslate_bricks"},
        {pos: [22, 1, 5], state: "minecraft:deepslate_bricks"},
        {pos: [22, 1, 6], state: "minecraft:deepslate_bricks"},
        {pos: [22, 1, 7], state: "minecraft:deepslate_bricks"},
        {pos: [22, 1, 8], state: "minecraft:deepslate_bricks"},
        {pos: [22, 1, 9], state: "minecraft:deepslate_bricks"},
        {pos: [22, 1, 10], state: "minecraft:deepslate_bricks"},
        {pos: [22, 1, 11], state: "minecraft:deepslate_bricks"},
        {pos: [22, 1, 12], state: "minecraft:deepslate_bricks"},
        {pos: [22, 1, 13], state: "minecraft:deepslate_bricks"},
        {pos: [22, 1, 14], state: "minecraft:deepslate_bricks"},
        {pos: [22, 1, 15], state: "minecraft:deepslate_bricks"},
        {pos: [22, 1, 16], state: "minecraft:deepslate_bricks"},
        {pos: [22, 1, 17], state: "minecraft:deepslate_bricks"},
        {pos: [22, 1, 18], state: "minecraft:deepslate_bricks"},
        {pos: [22, 1, 19], state: "minecraft:deepslate_bricks"},
        {pos: [22, 1, 20], state: "minecraft:deepslate_bricks"},
        {pos: [13, 2, 13], state: "minecraft:deepslate_bricks"},
        {pos: [13, 2, 14], state: "minecraft:deepslate_bricks"},
        {pos: [13, 2, 15], state: "minecraft:deepslate_bricks"},
        {pos: [14, 2, 13], state: "minecraft:deepslate_bricks"},
        {pos: [14, 2, 14], state: "minecraft:redstone_block"},
        {pos: [14, 2, 15], state: "minecraft:deepslate_bricks"},
        {pos: [15, 2, 13], state: "minecraft:deepslate_bricks"},
        {pos: [15, 2, 14], state: "minecraft:deepslate_bricks"},
        {pos: [15, 2, 15], state: "minecraft:deepslate_bricks"},
        {pos: [16, 2, 13], state: "minecraft:deepslate_bricks"},
        {pos: [16, 2, 14], state: "minecraft:deepslate_bricks"},
        {pos: [16, 2, 15], state: "minecraft:deepslate_bricks"},
        {pos: [17, 2, 13], state: "minecraft:deepslate_bricks"},
        {pos: [17, 2, 14], state: "minecraft:deepslate_bricks"},
        {pos: [17, 2, 15], state: "minecraft:deepslate_bricks"},
        {pos: [18, 2, 13], state: "minecraft:deepslate_bricks"},
        {pos: [18, 2, 14], state: "minecraft:deepslate_bricks"},
        {pos: [18, 2, 15], state: "minecraft:deepslate_bricks"},
        {pos: [18, 2, 16], state: "minecraft:deepslate_bricks"},
        {pos: [18, 2, 17], state: "minecraft:deepslate_bricks"},
        {pos: [18, 2, 18], state: "minecraft:deepslate_bricks"},
        {pos: [18, 2, 19], state: "minecraft:deepslate_bricks"},
        {pos: [18, 2, 20], state: "minecraft:deepslate_bricks"},
        {pos: [18, 2, 21], state: "minecraft:deepslate_bricks"},
        {pos: [18, 2, 22], state: "minecraft:deepslate_bricks"},
        {pos: [18, 2, 23], state: "minecraft:deepslate_bricks"},
        {pos: [19, 2, 5], state: "minecraft:deepslate_bricks"},
        {pos: [19, 2, 6], state: "minecraft:deepslate_bricks"},
        {pos: [19, 2, 7], state: "minecraft:deepslate_bricks"},
        {pos: [19, 2, 8], state: "minecraft:deepslate_bricks"},
        {pos: [19, 2, 9], state: "minecraft:deepslate_bricks"},
        {pos: [19, 2, 10], state: "minecraft:deepslate_bricks"},
        {pos: [19, 2, 11], state: "minecraft:deepslate_bricks"},
        {pos: [19, 2, 12], state: "minecraft:deepslate_bricks"},
        {pos: [19, 2, 13], state: "minecraft:deepslate_bricks"},
        {pos: [19, 2, 14], state: "minecraft:deepslate_bricks"},
        {pos: [19, 2, 15], state: "minecraft:deepslate_bricks"},
        {pos: [19, 2, 16], state: "minecraft:deepslate_bricks"},
        {pos: [19, 2, 17], state: "minecraft:deepslate_bricks"},
        {pos: [19, 2, 18], state: "minecraft:deepslate_bricks"},
        {pos: [19, 2, 19], state: "minecraft:deepslate_bricks"},
        {pos: [19, 2, 20], state: "minecraft:deepslate_bricks"},
        {pos: [19, 2, 21], state: "minecraft:deepslate_bricks"},
        {pos: [19, 2, 22], state: "minecraft:deepslate_bricks"},
        {pos: [19, 2, 23], state: "minecraft:deepslate_bricks"},
        {pos: [20, 2, 5], state: "minecraft:deepslate_bricks"},
        {pos: [20, 2, 6], state: "minecraft:redstone_wire{east:up,north:none,power:0,south:side,west:up}"},
        {pos: [20, 2, 7], state: "minecraft:repeater{delay:1,facing:south,locked:false,powered:false}"},
        {pos: [20, 2, 8], state: "minecraft:redstone_wire{east:none,north:side,power:0,south:side,west:none}"},
        {pos: [20, 2, 9], state: "minecraft:redstone_wire{east:none,north:side,power:0,south:side,west:none}"},
        {pos: [20, 2, 10], state: "minecraft:redstone_wire{east:none,north:side,power:0,south:side,west:none}"},
        {pos: [20, 2, 11], state: "minecraft:redstone_wire{east:none,north:side,power:0,south:side,west:none}"},
        {pos: [20, 2, 12], state: "minecraft:redstone_wire{east:none,north:side,power:0,south:side,west:none}"},
        {pos: [20, 2, 13], state: "minecraft:redstone_wire{east:none,north:side,power:0,south:side,west:none}"},
        {pos: [20, 2, 14], state: "minecraft:cave_air"},
        {pos: [20, 2, 15], state: "minecraft:redstone_wire{east:none,north:side,power:0,south:side,west:none}"},
        {pos: [20, 2, 16], state: "minecraft:redstone_wire{east:none,north:side,power:0,south:side,west:none}"},
        {pos: [20, 2, 17], state: "minecraft:redstone_wire{east:none,north:side,power:0,south:side,west:none}"},
        {pos: [20, 2, 18], state: "minecraft:redstone_wire{east:none,north:side,power:0,south:side,west:none}"},
        {pos: [20, 2, 19], state: "minecraft:redstone_wire{east:none,north:side,power:0,south:side,west:none}"},
        {pos: [20, 2, 20], state: "minecraft:redstone_wire{east:none,north:side,power:0,south:side,west:none}"},
        {pos: [20, 2, 21], state: "minecraft:repeater{delay:1,facing:north,locked:false,powered:false}"},
        {pos: [20, 2, 22], state: "minecraft:redstone_wire{east:none,north:side,power:0,south:none,west:up}"},
        {pos: [20, 2, 23], state: "minecraft:deepslate_bricks"},
        {pos: [21, 2, 5], state: "minecraft:deepslate_bricks"},
        {pos: [21, 2, 6], state: "minecraft:deepslate_bricks"},
        {pos: [21, 2, 7], state: "minecraft:deepslate_bricks"},
        {pos: [21, 2, 8], state: "minecraft:deepslate_bricks"},
        {pos: [21, 2, 9], state: "minecraft:deepslate_bricks"},
        {pos: [21, 2, 10], state: "minecraft:deepslate_bricks"},
        {pos: [21, 2, 11], state: "minecraft:deepslate_bricks"},
        {pos: [21, 2, 12], state: "minecraft:deepslate_bricks"},
        {pos: [21, 2, 13], state: "minecraft:deepslate_bricks"},
        {pos: [21, 2, 14], state: "minecraft:deepslate_bricks"},
        {pos: [21, 2, 15], state: "minecraft:deepslate_bricks"},
        {pos: [21, 2, 16], state: "minecraft:deepslate_bricks"},
        {pos: [21, 2, 17], state: "minecraft:deepslate_bricks"},
        {pos: [21, 2, 18], state: "minecraft:deepslate_bricks"},
        {pos: [21, 2, 19], state: "minecraft:deepslate_bricks"},
        {pos: [21, 2, 20], state: "minecraft:deepslate_bricks"},
        {pos: [21, 2, 21], state: "minecraft:deepslate_bricks"},
        {pos: [21, 2, 22], state: "minecraft:deepslate_bricks"},
        {pos: [22, 2, 5], state: "minecraft:deepslate_bricks"},
        {pos: [22, 2, 6], state: "minecraft:deepslate_bricks"},
        {pos: [22, 2, 7], state: "minecraft:deepslate_bricks"},
        {pos: [22, 2, 8], state: "minecraft:deepslate_bricks"},
        {pos: [22, 2, 9], state: "minecraft:deepslate_bricks"},
        {pos: [22, 2, 10], state: "minecraft:deepslate_bricks"},
        {pos: [22, 2, 11], state: "minecraft:deepslate_bricks"},
        {pos: [22, 2, 12], state: "minecraft:deepslate_bricks"},
        {pos: [22, 2, 13], state: "minecraft:deepslate_bricks"},
        {pos: [22, 2, 14], state: "minecraft:deepslate_bricks"},
        {pos: [22, 2, 15], state: "minecraft:deepslate_bricks"},
        {pos: [22, 2, 16], state: "minecraft:deepslate_bricks"},
        {pos: [22, 2, 17], state: "minecraft:deepslate_bricks"},
        {pos: [22, 2, 18], state: "minecraft:deepslate_bricks"},
        {pos: [22, 2, 19], state: "minecraft:deepslate_bricks"},
        {pos: [22, 2, 20], state: "minecraft:deepslate_bricks"},
        {pos: [0, 3, 7], state: "minecraft:deepslate{axis:y}"},
        {pos: [0, 3, 8], state: "minecraft:deepslate{axis:y}"},
        {pos: [0, 3, 9], state: "minecraft:deepslate{axis:y}"},
        {pos: [0, 3, 10], state: "minecraft:deepslate{axis:y}"},
        {pos: [0, 3, 11], state: "minecraft:deepslate{axis:y}"},
        {pos: [0, 3, 12], state: "minecraft:deepslate{axis:y}"},
        {pos: [0, 3, 13], state: "minecraft:deepslate{axis:y}"},
        {pos: [0, 3, 14], state: "minecraft:deepslate{axis:y}"},
        {pos: [0, 3, 15], state: "minecraft:deepslate{axis:y}"},
        {pos: [0, 3, 16], state: "minecraft:deepslate{axis:y}"},
        {pos: [0, 3, 17], state: "minecraft:deepslate{axis:y}"},
        {pos: [0, 3, 18], state: "minecraft:deepslate{axis:y}"},
        {pos: [0, 3, 19], state: "minecraft:deepslate{axis:y}"},
        {pos: [0, 3, 20], state: "minecraft:deepslate{axis:y}"},
        {pos: [0, 3, 21], state: "minecraft:deepslate{axis:y}"},
        {pos: [1, 3, 7], state: "minecraft:deepslate{axis:y}"},
        {pos: [1, 3, 8], state: "minecraft:deepslate{axis:y}"},
        {pos: [1, 3, 9], state: "minecraft:deepslate{axis:y}"},
        {pos: [1, 3, 10], state: "minecraft:deepslate{axis:y}"},
        {pos: [1, 3, 11], state: "minecraft:deepslate{axis:y}"},
        {pos: [1, 3, 12], state: "minecraft:deepslate{axis:y}"},
        {pos: [1, 3, 13], state: "minecraft:deepslate{axis:y}"},
        {pos: [1, 3, 14], state: "minecraft:deepslate{axis:y}"},
        {pos: [1, 3, 15], state: "minecraft:deepslate{axis:y}"},
        {pos: [1, 3, 16], state: "minecraft:deepslate{axis:y}"},
        {pos: [1, 3, 17], state: "minecraft:deepslate{axis:y}"},
        {pos: [1, 3, 18], state: "minecraft:deepslate{axis:y}"},
        {pos: [1, 3, 19], state: "minecraft:deepslate{axis:y}"},
        {pos: [1, 3, 20], state: "minecraft:deepslate{axis:y}"},
        {pos: [1, 3, 21], state: "minecraft:deepslate{axis:y}"},
        {pos: [2, 3, 7], state: "minecraft:deepslate{axis:y}"},
        {pos: [2, 3, 8], state: "minecraft:deepslate{axis:y}"},
        {pos: [2, 3, 9], state: "minecraft:deepslate{axis:y}"},
        {pos: [2, 3, 10], state: "minecraft:deepslate{axis:y}"},
        {pos: [2, 3, 11], state: "minecraft:deepslate{axis:y}"},
        {pos: [2, 3, 12], state: "minecraft:deepslate{axis:y}"},
        {pos: [2, 3, 13], state: "minecraft:deepslate{axis:y}"},
        {pos: [2, 3, 14], state: "minecraft:deepslate{axis:y}"},
        {pos: [2, 3, 15], state: "minecraft:deepslate{axis:y}"},
        {pos: [2, 3, 16], state: "minecraft:deepslate{axis:y}"},
        {pos: [2, 3, 17], state: "minecraft:deepslate{axis:y}"},
        {pos: [2, 3, 18], state: "minecraft:deepslate{axis:y}"},
        {pos: [2, 3, 19], state: "minecraft:deepslate{axis:y}"},
        {pos: [2, 3, 20], state: "minecraft:deepslate{axis:y}"},
        {pos: [2, 3, 21], state: "minecraft:deepslate{axis:y}"},
        {pos: [3, 3, 0], state: "minecraft:deepslate{axis:y}"},
        {pos: [3, 3, 1], state: "minecraft:deepslate{axis:y}"},
        {pos: [3, 3, 2], state: "minecraft:deepslate{axis:y}"},
        {pos: [3, 3, 3], state: "minecraft:deepslate{axis:y}"},
        {pos: [3, 3, 4], state: "minecraft:deepslate{axis:y}"},
        {pos: [3, 3, 5], state: "minecraft:deepslate{axis:y}"},
        {pos: [3, 3, 6], state: "minecraft:deepslate{axis:y}"},
        {pos: [3, 3, 7], state: "minecraft:deepslate{axis:y}"},
        {pos: [3, 3, 8], state: "minecraft:deepslate{axis:y}"},
        {pos: [3, 3, 9], state: "minecraft:deepslate{axis:y}"},
        {pos: [3, 3, 10], state: "minecraft:deepslate{axis:y}"},
        {pos: [3, 3, 11], state: "minecraft:deepslate{axis:y}"},
        {pos: [3, 3, 12], state: "minecraft:deepslate{axis:y}"},
        {pos: [3, 3, 13], state: "minecraft:deepslate{axis:y}"},
        {pos: [3, 3, 14], state: "minecraft:deepslate{axis:y}"},
        {pos: [3, 3, 15], state: "minecraft:deepslate{axis:y}"},
        {pos: [3, 3, 16], state: "minecraft:deepslate{axis:y}"},
        {pos: [3, 3, 17], state: "minecraft:deepslate{axis:y}"},
        {pos: [3, 3, 18], state: "minecraft:deepslate{axis:y}"},
        {pos: [3, 3, 19], state: "minecraft:deepslate{axis:y}"},
        {pos: [3, 3, 20], state: "minecraft:deepslate{axis:y}"},
        {pos: [3, 3, 21], state: "minecraft:deepslate{axis:y}"},
        {pos: [3, 3, 22], state: "minecraft:deepslate{axis:y}"},
        {pos: [3, 3, 23], state: "minecraft:deepslate{axis:y}"},
        {pos: [3, 3, 24], state: "minecraft:deepslate{axis:y}"},
        {pos: [3, 3, 25], state: "minecraft:deepslate{axis:y}"},
        {pos: [3, 3, 26], state: "minecraft:deepslate{axis:y}"},
        {pos: [3, 3, 27], state: "minecraft:deepslate{axis:y}"},
        {pos: [3, 3, 28], state: "minecraft:deepslate{axis:y}"},
        {pos: [4, 3, 0], state: "minecraft:deepslate{axis:y}"},
        {pos: [4, 3, 1], state: "minecraft:deepslate{axis:y}"},
        {pos: [4, 3, 2], state: "minecraft:deepslate{axis:y}"},
        {pos: [4, 3, 3], state: "minecraft:deepslate{axis:y}"},
        {pos: [4, 3, 4], state: "minecraft:deepslate{axis:y}"},
        {pos: [4, 3, 5], state: "minecraft:deepslate{axis:y}"},
        {pos: [4, 3, 6], state: "minecraft:deepslate{axis:y}"},
        {pos: [4, 3, 7], state: "minecraft:deepslate{axis:y}"},
        {pos: [4, 3, 8], state: "minecraft:deepslate{axis:y}"},
        {pos: [4, 3, 9], state: "minecraft:deepslate{axis:y}"},
        {pos: [4, 3, 10], state: "minecraft:deepslate{axis:y}"},
        {pos: [4, 3, 11], state: "minecraft:deepslate{axis:y}"},
        {pos: [4, 3, 12], state: "minecraft:deepslate{axis:y}"},
        {pos: [4, 3, 13], state: "minecraft:deepslate{axis:y}"},
        {pos: [4, 3, 14], state: "minecraft:deepslate{axis:y}"},
        {pos: [4, 3, 15], state: "minecraft:deepslate{axis:y}"},
        {pos: [4, 3, 16], state: "minecraft:deepslate{axis:y}"},
        {pos: [4, 3, 17], state: "minecraft:deepslate{axis:y}"},
        {pos: [4, 3, 18], state: "minecraft:deepslate{axis:y}"},
        {pos: [4, 3, 19], state: "minecraft:deepslate{axis:y}"},
        {pos: [4, 3, 20], state: "minecraft:deepslate{axis:y}"},
        {pos: [4, 3, 21], state: "minecraft:deepslate{axis:y}"},
        {pos: [4, 3, 22], state: "minecraft:deepslate{axis:y}"},
        {pos: [4, 3, 23], state: "minecraft:deepslate{axis:y}"},
        {pos: [4, 3, 24], state: "minecraft:deepslate{axis:y}"},
        {pos: [4, 3, 25], state: "minecraft:deepslate{axis:y}"},
        {pos: [4, 3, 26], state: "minecraft:deepslate{axis:y}"},
        {pos: [4, 3, 27], state: "minecraft:deepslate{axis:y}"},
        {pos: [4, 3, 28], state: "minecraft:deepslate{axis:y}"},
        {pos: [5, 3, 0], state: "minecraft:deepslate{axis:y}"},
        {pos: [5, 3, 1], state: "minecraft:deepslate{axis:y}"},
        {pos: [5, 3, 2], state: "minecraft:deepslate{axis:y}"},
        {pos: [5, 3, 3], state: "minecraft:deepslate{axis:y}"},
        {pos: [5, 3, 4], state: "minecraft:deepslate{axis:y}"},
        {pos: [5, 3, 5], state: "minecraft:deepslate{axis:y}"},
        {pos: [5, 3, 6], state: "minecraft:deepslate{axis:y}"},
        {pos: [5, 3, 7], state: "minecraft:deepslate{axis:y}"},
        {pos: [5, 3, 8], state: "minecraft:deepslate{axis:y}"},
        {pos: [5, 3, 9], state: "minecraft:deepslate{axis:y}"},
        {pos: [5, 3, 10], state: "minecraft:deepslate{axis:y}"},
        {pos: [5, 3, 11], state: "minecraft:deepslate{axis:y}"},
        {pos: [5, 3, 12], state: "minecraft:deepslate{axis:y}"},
        {pos: [5, 3, 13], state: "minecraft:deepslate{axis:y}"},
        {pos: [5, 3, 14], state: "minecraft:deepslate{axis:y}"},
        {pos: [5, 3, 15], state: "minecraft:deepslate{axis:y}"},
        {pos: [5, 3, 16], state: "minecraft:deepslate{axis:y}"},
        {pos: [5, 3, 17], state: "minecraft:deepslate{axis:y}"},
        {pos: [5, 3, 18], state: "minecraft:deepslate{axis:y}"},
        {pos: [5, 3, 19], state: "minecraft:deepslate{axis:y}"},
        {pos: [5, 3, 20], state: "minecraft:deepslate{axis:y}"},
        {pos: [5, 3, 21], state: "minecraft:deepslate{axis:y}"},
        {pos: [5, 3, 22], state: "minecraft:deepslate{axis:y}"},
        {pos: [5, 3, 23], state: "minecraft:deepslate{axis:y}"},
        {pos: [5, 3, 24], state: "minecraft:deepslate{axis:y}"},
        {pos: [5, 3, 25], state: "minecraft:deepslate{axis:y}"},
        {pos: [5, 3, 26], state: "minecraft:deepslate{axis:y}"},
        {pos: [5, 3, 27], state: "minecraft:deepslate{axis:y}"},
        {pos: [5, 3, 28], state: "minecraft:deepslate{axis:y}"},
        {pos: [6, 3, 0], state: "minecraft:deepslate{axis:y}"},
        {pos: [6, 3, 1], state: "minecraft:deepslate{axis:y}"},
        {pos: [6, 3, 2], state: "minecraft:deepslate{axis:y}"},
        {pos: [6, 3, 3], state: "minecraft:deepslate{axis:y}"},
        {pos: [6, 3, 4], state: "minecraft:deepslate{axis:y}"},
        {pos: [6, 3, 5], state: "minecraft:deepslate{axis:y}"},
        {pos: [6, 3, 6], state: "minecraft:deepslate{axis:y}"},
        {pos: [6, 3, 7], state: "minecraft:deepslate{axis:y}"},
        {pos: [6, 3, 8], state: "minecraft:deepslate{axis:y}"},
        {pos: [6, 3, 9], state: "minecraft:deepslate{axis:y}"},
        {pos: [6, 3, 10], state: "minecraft:deepslate{axis:y}"},
        {pos: [6, 3, 11], state: "minecraft:deepslate{axis:y}"},
        {pos: [6, 3, 12], state: "minecraft:deepslate{axis:y}"},
        {pos: [6, 3, 13], state: "minecraft:deepslate{axis:y}"},
        {pos: [6, 3, 14], state: "minecraft:deepslate{axis:y}"},
        {pos: [6, 3, 15], state: "minecraft:deepslate{axis:y}"},
        {pos: [6, 3, 16], state: "minecraft:deepslate{axis:y}"},
        {pos: [6, 3, 17], state: "minecraft:deepslate{axis:y}"},
        {pos: [6, 3, 18], state: "minecraft:deepslate{axis:y}"},
        {pos: [6, 3, 19], state: "minecraft:deepslate{axis:y}"},
        {pos: [6, 3, 20], state: "minecraft:deepslate{axis:y}"},
        {pos: [6, 3, 21], state: "minecraft:deepslate{axis:y}"},
        {pos: [6, 3, 22], state: "minecraft:deepslate{axis:y}"},
        {pos: [6, 3, 23], state: "minecraft:deepslate{axis:y}"},
        {pos: [6, 3, 24], state: "minecraft:deepslate{axis:y}"},
        {pos: [6, 3, 25], state: "minecraft:deepslate{axis:y}"},
        {pos: [6, 3, 26], state: "minecraft:deepslate{axis:y}"},
        {pos: [6, 3, 27], state: "minecraft:deepslate{axis:y}"},
        {pos: [6, 3, 28], state: "minecraft:deepslate{axis:y}"},
        {pos: [7, 3, 0], state: "minecraft:deepslate{axis:y}"},
        {pos: [7, 3, 1], state: "minecraft:deepslate{axis:y}"},
        {pos: [7, 3, 2], state: "minecraft:deepslate{axis:y}"},
        {pos: [7, 3, 3], state: "minecraft:deepslate{axis:y}"},
        {pos: [7, 3, 4], state: "minecraft:deepslate{axis:y}"},
        {pos: [7, 3, 5], state: "minecraft:deepslate{axis:y}"},
        {pos: [7, 3, 6], state: "minecraft:deepslate{axis:y}"},
        {pos: [7, 3, 7], state: "minecraft:deepslate{axis:y}"},
        {pos: [7, 3, 8], state: "minecraft:deepslate{axis:y}"},
        {pos: [7, 3, 9], state: "minecraft:deepslate{axis:y}"},
        {pos: [7, 3, 10], state: "minecraft:deepslate{axis:y}"},
        {pos: [7, 3, 11], state: "minecraft:deepslate{axis:y}"},
        {pos: [7, 3, 12], state: "minecraft:deepslate{axis:y}"},
        {pos: [7, 3, 13], state: "minecraft:deepslate{axis:y}"},
        {pos: [7, 3, 14], state: "minecraft:deepslate{axis:y}"},
        {pos: [7, 3, 15], state: "minecraft:deepslate{axis:y}"},
        {pos: [7, 3, 16], state: "minecraft:deepslate{axis:y}"},
        {pos: [7, 3, 17], state: "minecraft:deepslate{axis:y}"},
        {pos: [7, 3, 18], state: "minecraft:deepslate{axis:y}"},
        {pos: [7, 3, 19], state: "minecraft:deepslate{axis:y}"},
        {pos: [7, 3, 20], state: "minecraft:deepslate{axis:y}"},
        {pos: [7, 3, 21], state: "minecraft:deepslate{axis:y}"},
        {pos: [7, 3, 22], state: "minecraft:deepslate{axis:y}"},
        {pos: [7, 3, 23], state: "minecraft:deepslate{axis:y}"},
        {pos: [7, 3, 24], state: "minecraft:deepslate{axis:y}"},
        {pos: [7, 3, 25], state: "minecraft:deepslate{axis:y}"},
        {pos: [7, 3, 26], state: "minecraft:deepslate{axis:y}"},
        {pos: [7, 3, 27], state: "minecraft:deepslate{axis:y}"},
        {pos: [7, 3, 28], state: "minecraft:deepslate{axis:y}"},
        {pos: [8, 3, 0], state: "minecraft:deepslate{axis:y}"},
        {pos: [8, 3, 1], state: "minecraft:deepslate{axis:y}"},
        {pos: [8, 3, 2], state: "minecraft:deepslate{axis:y}"},
        {pos: [8, 3, 3], state: "minecraft:deepslate{axis:y}"},
        {pos: [8, 3, 4], state: "minecraft:deepslate{axis:y}"},
        {pos: [8, 3, 5], state: "minecraft:deepslate{axis:y}"},
        {pos: [8, 3, 6], state: "minecraft:deepslate{axis:y}"},
        {pos: [8, 3, 7], state: "minecraft:deepslate{axis:y}"},
        {pos: [8, 3, 8], state: "minecraft:deepslate{axis:y}"},
        {pos: [8, 3, 9], state: "minecraft:deepslate{axis:y}"},
        {pos: [8, 3, 10], state: "minecraft:deepslate{axis:y}"},
        {pos: [8, 3, 11], state: "minecraft:deepslate{axis:y}"},
        {pos: [8, 3, 12], state: "minecraft:deepslate{axis:y}"},
        {pos: [8, 3, 13], state: "minecraft:deepslate{axis:y}"},
        {pos: [8, 3, 14], state: "minecraft:deepslate{axis:y}"},
        {pos: [8, 3, 15], state: "minecraft:deepslate{axis:y}"},
        {pos: [8, 3, 16], state: "minecraft:deepslate{axis:y}"},
        {pos: [8, 3, 17], state: "minecraft:deepslate{axis:y}"},
        {pos: [8, 3, 18], state: "minecraft:deepslate{axis:y}"},
        {pos: [8, 3, 19], state: "minecraft:deepslate{axis:y}"},
        {pos: [8, 3, 20], state: "minecraft:deepslate{axis:y}"},
        {pos: [8, 3, 21], state: "minecraft:deepslate{axis:y}"},
        {pos: [8, 3, 22], state: "minecraft:deepslate{axis:y}"},
        {pos: [8, 3, 23], state: "minecraft:deepslate{axis:y}"},
        {pos: [8, 3, 24], state: "minecraft:deepslate{axis:y}"},
        {pos: [8, 3, 25], state: "minecraft:deepslate{axis:y}"},
        {pos: [8, 3, 26], state: "minecraft:deepslate{axis:y}"},
        {pos: [8, 3, 27], state: "minecraft:deepslate{axis:y}"},
        {pos: [8, 3, 28], state: "minecraft:deepslate{axis:y}"},
        {pos: [9, 3, 0], state: "minecraft:deepslate{axis:y}"},
        {pos: [9, 3, 1], state: "minecraft:deepslate{axis:y}"},
        {pos: [9, 3, 2], state: "minecraft:deepslate{axis:y}"},
        {pos: [9, 3, 3], state: "minecraft:deepslate{axis:y}"},
        {pos: [9, 3, 4], state: "minecraft:deepslate{axis:y}"},
        {pos: [9, 3, 5], state: "minecraft:deepslate{axis:y}"},
        {pos: [9, 3, 6], state: "minecraft:deepslate{axis:y}"},
        {pos: [9, 3, 7], state: "minecraft:deepslate{axis:y}"},
        {pos: [9, 3, 8], state: "minecraft:deepslate{axis:y}"},
        {pos: [9, 3, 9], state: "minecraft:deepslate{axis:y}"},
        {pos: [9, 3, 10], state: "minecraft:deepslate{axis:y}"},
        {pos: [9, 3, 11], state: "minecraft:deepslate{axis:y}"},
        {pos: [9, 3, 12], state: "minecraft:deepslate{axis:y}"},
        {pos: [9, 3, 13], state: "minecraft:deepslate{axis:y}"},
        {pos: [9, 3, 14], state: "minecraft:deepslate{axis:y}"},
        {pos: [9, 3, 15], state: "minecraft:deepslate{axis:y}"},
        {pos: [9, 3, 16], state: "minecraft:deepslate{axis:y}"},
        {pos: [9, 3, 17], state: "minecraft:deepslate{axis:y}"},
        {pos: [9, 3, 18], state: "minecraft:deepslate{axis:y}"},
        {pos: [9, 3, 19], state: "minecraft:deepslate{axis:y}"},
        {pos: [9, 3, 20], state: "minecraft:deepslate{axis:y}"},
        {pos: [9, 3, 21], state: "minecraft:deepslate{axis:y}"},
        {pos: [9, 3, 22], state: "minecraft:deepslate{axis:y}"},
        {pos: [9, 3, 23], state: "minecraft:deepslate{axis:y}"},
        {pos: [9, 3, 24], state: "minecraft:deepslate{axis:y}"},
        {pos: [9, 3, 25], state: "minecraft:deepslate{axis:y}"},
        {pos: [9, 3, 26], state: "minecraft:deepslate{axis:y}"},
        {pos: [9, 3, 27], state: "minecraft:deepslate{axis:y}"},
        {pos: [9, 3, 28], state: "minecraft:deepslate{axis:y}"},
        {pos: [10, 3, 0], state: "minecraft:deepslate{axis:y}"},
        {pos: [10, 3, 1], state: "minecraft:deepslate{axis:y}"},
        {pos: [10, 3, 2], state: "minecraft:deepslate{axis:y}"},
        {pos: [10, 3, 3], state: "minecraft:deepslate{axis:y}"},
        {pos: [10, 3, 4], state: "minecraft:deepslate{axis:y}"},
        {pos: [10, 3, 5], state: "minecraft:deepslate{axis:y}"},
        {pos: [10, 3, 6], state: "minecraft:deepslate{axis:y}"},
        {pos: [10, 3, 7], state: "minecraft:deepslate{axis:y}"},
        {pos: [10, 3, 8], state: "minecraft:deepslate{axis:y}"},
        {pos: [10, 3, 9], state: "minecraft:deepslate{axis:y}"},
        {pos: [10, 3, 10], state: "minecraft:deepslate{axis:y}"},
        {pos: [10, 3, 11], state: "minecraft:deepslate{axis:y}"},
        {pos: [10, 3, 12], state: "minecraft:deepslate{axis:y}"},
        {pos: [10, 3, 13], state: "minecraft:deepslate{axis:y}"},
        {pos: [10, 3, 14], state: "minecraft:deepslate{axis:y}"},
        {pos: [10, 3, 15], state: "minecraft:deepslate{axis:y}"},
        {pos: [10, 3, 16], state: "minecraft:deepslate{axis:y}"},
        {pos: [10, 3, 17], state: "minecraft:deepslate{axis:y}"},
        {pos: [10, 3, 18], state: "minecraft:deepslate{axis:y}"},
        {pos: [10, 3, 19], state: "minecraft:deepslate{axis:y}"},
        {pos: [10, 3, 20], state: "minecraft:deepslate{axis:y}"},
        {pos: [10, 3, 21], state: "minecraft:deepslate{axis:y}"},
        {pos: [10, 3, 22], state: "minecraft:deepslate{axis:y}"},
        {pos: [10, 3, 23], state: "minecraft:deepslate{axis:y}"},
        {pos: [10, 3, 24], state: "minecraft:deepslate{axis:y}"},
        {pos: [10, 3, 25], state: "minecraft:deepslate{axis:y}"},
        {pos: [10, 3, 26], state: "minecraft:deepslate{axis:y}"},
        {pos: [10, 3, 27], state: "minecraft:deepslate{axis:y}"},
        {pos: [10, 3, 28], state: "minecraft:deepslate{axis:y}"},
        {pos: [11, 3, 0], state: "minecraft:deepslate{axis:y}"},
        {pos: [11, 3, 1], state: "minecraft:deepslate{axis:y}"},
        {pos: [11, 3, 2], state: "minecraft:deepslate{axis:y}"},
        {pos: [11, 3, 3], state: "minecraft:deepslate{axis:y}"},
        {pos: [11, 3, 4], state: "minecraft:deepslate{axis:y}"},
        {pos: [11, 3, 5], state: "minecraft:deepslate{axis:y}"},
        {pos: [11, 3, 6], state: "minecraft:deepslate{axis:y}"},
        {pos: [11, 3, 7], state: "minecraft:deepslate{axis:y}"},
        {pos: [11, 3, 8], state: "minecraft:deepslate{axis:y}"},
        {pos: [11, 3, 9], state: "minecraft:deepslate{axis:y}"},
        {pos: [11, 3, 10], state: "minecraft:deepslate{axis:y}"},
        {pos: [11, 3, 11], state: "minecraft:deepslate{axis:y}"},
        {pos: [11, 3, 12], state: "minecraft:deepslate{axis:y}"},
        {pos: [11, 3, 13], state: "minecraft:deepslate{axis:y}"},
        {pos: [11, 3, 14], state: "minecraft:deepslate{axis:y}"},
        {pos: [11, 3, 15], state: "minecraft:deepslate{axis:y}"},
        {pos: [11, 3, 16], state: "minecraft:deepslate{axis:y}"},
        {pos: [11, 3, 17], state: "minecraft:deepslate{axis:y}"},
        {pos: [11, 3, 18], state: "minecraft:deepslate{axis:y}"},
        {pos: [11, 3, 19], state: "minecraft:deepslate{axis:y}"},
        {pos: [11, 3, 20], state: "minecraft:deepslate{axis:y}"},
        {pos: [11, 3, 21], state: "minecraft:deepslate{axis:y}"},
        {pos: [11, 3, 22], state: "minecraft:deepslate{axis:y}"},
        {pos: [11, 3, 23], state: "minecraft:deepslate{axis:y}"},
        {pos: [11, 3, 24], state: "minecraft:deepslate{axis:y}"},
        {pos: [11, 3, 25], state: "minecraft:deepslate{axis:y}"},
        {pos: [11, 3, 26], state: "minecraft:deepslate{axis:y}"},
        {pos: [11, 3, 27], state: "minecraft:deepslate{axis:y}"},
        {pos: [11, 3, 28], state: "minecraft:deepslate{axis:y}"},
        {pos: [12, 3, 0], state: "minecraft:deepslate{axis:y}"},
        {pos: [12, 3, 1], state: "minecraft:deepslate{axis:y}"},
        {pos: [12, 3, 2], state: "minecraft:deepslate{axis:y}"},
        {pos: [12, 3, 3], state: "minecraft:deepslate{axis:y}"},
        {pos: [12, 3, 4], state: "minecraft:deepslate{axis:y}"},
        {pos: [12, 3, 5], state: "minecraft:deepslate{axis:y}"},
        {pos: [12, 3, 6], state: "minecraft:deepslate{axis:y}"},
        {pos: [12, 3, 7], state: "minecraft:deepslate{axis:y}"},
        {pos: [12, 3, 8], state: "minecraft:deepslate{axis:y}"},
        {pos: [12, 3, 9], state: "minecraft:deepslate{axis:y}"},
        {pos: [12, 3, 10], state: "minecraft:deepslate{axis:y}"},
        {pos: [12, 3, 11], state: "minecraft:deepslate{axis:y}"},
        {pos: [12, 3, 12], state: "minecraft:deepslate{axis:y}"},
        {pos: [12, 3, 13], state: "minecraft:deepslate{axis:y}"},
        {pos: [12, 3, 14], state: "minecraft:deepslate{axis:y}"},
        {pos: [12, 3, 15], state: "minecraft:deepslate{axis:y}"},
        {pos: [12, 3, 16], state: "minecraft:deepslate{axis:y}"},
        {pos: [12, 3, 17], state: "minecraft:deepslate{axis:y}"},
        {pos: [12, 3, 18], state: "minecraft:deepslate{axis:y}"},
        {pos: [12, 3, 19], state: "minecraft:deepslate{axis:y}"},
        {pos: [12, 3, 20], state: "minecraft:deepslate{axis:y}"},
        {pos: [12, 3, 21], state: "minecraft:deepslate{axis:y}"},
        {pos: [12, 3, 22], state: "minecraft:deepslate{axis:y}"},
        {pos: [12, 3, 23], state: "minecraft:deepslate{axis:y}"},
        {pos: [12, 3, 24], state: "minecraft:deepslate{axis:y}"},
        {pos: [12, 3, 25], state: "minecraft:deepslate{axis:y}"},
        {pos: [12, 3, 26], state: "minecraft:deepslate{axis:y}"},
        {pos: [12, 3, 27], state: "minecraft:deepslate{axis:y}"},
        {pos: [12, 3, 28], state: "minecraft:deepslate{axis:y}"},
        {pos: [13, 3, 0], state: "minecraft:deepslate{axis:y}"},
        {pos: [13, 3, 1], state: "minecraft:deepslate{axis:y}"},
        {pos: [13, 3, 2], state: "minecraft:deepslate{axis:y}"},
        {pos: [13, 3, 3], state: "minecraft:deepslate{axis:y}"},
        {pos: [13, 3, 4], state: "minecraft:deepslate{axis:y}"},
        {pos: [13, 3, 5], state: "minecraft:deepslate{axis:y}"},
        {pos: [13, 3, 6], state: "minecraft:deepslate{axis:y}"},
        {pos: [13, 3, 7], state: "minecraft:deepslate{axis:y}"},
        {pos: [13, 3, 8], state: "minecraft:deepslate{axis:y}"},
        {pos: [13, 3, 9], state: "minecraft:deepslate{axis:y}"},
        {pos: [13, 3, 10], state: "minecraft:deepslate{axis:y}"},
        {pos: [13, 3, 11], state: "minecraft:deepslate{axis:y}"},
        {pos: [13, 3, 12], state: "minecraft:deepslate{axis:y}"},
        {pos: [13, 3, 13], state: "minecraft:deepslate_bricks"},
        {pos: [13, 3, 14], state: "minecraft:deepslate_bricks"},
        {pos: [13, 3, 15], state: "minecraft:deepslate_bricks"},
        {pos: [13, 3, 16], state: "minecraft:deepslate{axis:y}"},
        {pos: [13, 3, 17], state: "minecraft:deepslate{axis:y}"},
        {pos: [13, 3, 18], state: "minecraft:deepslate{axis:y}"},
        {pos: [13, 3, 19], state: "minecraft:deepslate{axis:y}"},
        {pos: [13, 3, 20], state: "minecraft:deepslate{axis:y}"},
        {pos: [13, 3, 21], state: "minecraft:deepslate{axis:y}"},
        {pos: [13, 3, 22], state: "minecraft:deepslate{axis:y}"},
        {pos: [13, 3, 23], state: "minecraft:deepslate{axis:y}"},
        {pos: [13, 3, 24], state: "minecraft:deepslate{axis:y}"},
        {pos: [13, 3, 25], state: "minecraft:deepslate{axis:y}"},
        {pos: [13, 3, 26], state: "minecraft:deepslate{axis:y}"},
        {pos: [13, 3, 27], state: "minecraft:deepslate{axis:y}"},
        {pos: [13, 3, 28], state: "minecraft:deepslate{axis:y}"},
        {pos: [14, 3, 0], state: "minecraft:deepslate{axis:y}"},
        {pos: [14, 3, 1], state: "minecraft:deepslate{axis:y}"},
        {pos: [14, 3, 2], state: "minecraft:deepslate{axis:y}"},
        {pos: [14, 3, 3], state: "minecraft:deepslate{axis:y}"},
        {pos: [14, 3, 4], state: "minecraft:deepslate{axis:y}"},
        {pos: [14, 3, 5], state: "minecraft:deepslate{axis:y}"},
        {pos: [14, 3, 6], state: "minecraft:deepslate{axis:y}"},
        {pos: [14, 3, 7], state: "minecraft:deepslate{axis:y}"},
        {pos: [14, 3, 8], state: "minecraft:deepslate{axis:y}"},
        {pos: [14, 3, 9], state: "minecraft:deepslate{axis:y}"},
        {pos: [14, 3, 10], state: "minecraft:deepslate{axis:y}"},
        {pos: [14, 3, 11], state: "minecraft:deepslate{axis:y}"},
        {pos: [14, 3, 12], state: "minecraft:deepslate{axis:y}"},
        {pos: [14, 3, 13], state: "minecraft:deepslate_bricks"},
        {pos: [14, 3, 14], state: "minecraft:cave_air"},
        {pos: [14, 3, 15], state: "minecraft:deepslate_bricks"},
        {pos: [14, 3, 16], state: "minecraft:deepslate{axis:y}"},
        {pos: [14, 3, 17], state: "minecraft:deepslate{axis:y}"},
        {pos: [14, 3, 18], state: "minecraft:deepslate{axis:y}"},
        {pos: [14, 3, 19], state: "minecraft:deepslate{axis:y}"},
        {pos: [14, 3, 20], state: "minecraft:deepslate{axis:y}"},
        {pos: [14, 3, 21], state: "minecraft:deepslate{axis:y}"},
        {pos: [14, 3, 22], state: "minecraft:deepslate{axis:y}"},
        {pos: [14, 3, 23], state: "minecraft:deepslate{axis:y}"},
        {pos: [14, 3, 24], state: "minecraft:deepslate{axis:y}"},
        {pos: [14, 3, 25], state: "minecraft:deepslate{axis:y}"},
        {pos: [14, 3, 26], state: "minecraft:deepslate{axis:y}"},
        {pos: [14, 3, 27], state: "minecraft:deepslate{axis:y}"},
        {pos: [14, 3, 28], state: "minecraft:deepslate{axis:y}"},
        {pos: [15, 3, 0], state: "minecraft:deepslate{axis:y}"},
        {pos: [15, 3, 1], state: "minecraft:deepslate{axis:y}"},
        {pos: [15, 3, 2], state: "minecraft:deepslate{axis:y}"},
        {pos: [15, 3, 3], state: "minecraft:deepslate{axis:y}"},
        {pos: [15, 3, 4], state: "minecraft:deepslate{axis:y}"},
        {pos: [15, 3, 5], state: "minecraft:deepslate_bricks"},
        {pos: [15, 3, 6], state: "minecraft:deepslate_bricks"},
        {pos: [15, 3, 7], state: "minecraft:deepslate{axis:y}"},
        {pos: [15, 3, 8], state: "minecraft:deepslate{axis:y}"},
        {pos: [15, 3, 9], state: "minecraft:deepslate{axis:y}"},
        {pos: [15, 3, 10], state: "minecraft:deepslate{axis:y}"},
        {pos: [15, 3, 11], state: "minecraft:deepslate{axis:y}"},
        {pos: [15, 3, 12], state: "minecraft:deepslate{axis:y}"},
        {pos: [15, 3, 13], state: "minecraft:deepslate_bricks"},
        {pos: [15, 3, 14], state: "minecraft:deepslate_bricks"},
        {pos: [15, 3, 15], state: "minecraft:deepslate_bricks"},
        {pos: [15, 3, 16], state: "minecraft:deepslate{axis:y}"},
        {pos: [15, 3, 17], state: "minecraft:deepslate{axis:y}"},
        {pos: [15, 3, 18], state: "minecraft:deepslate{axis:y}"},
        {pos: [15, 3, 19], state: "minecraft:deepslate{axis:y}"},
        {pos: [15, 3, 20], state: "minecraft:deepslate{axis:y}"},
        {pos: [15, 3, 21], state: "minecraft:deepslate{axis:y}"},
        {pos: [15, 3, 22], state: "minecraft:deepslate{axis:y}"},
        {pos: [15, 3, 23], state: "minecraft:deepslate{axis:y}"},
        {pos: [15, 3, 24], state: "minecraft:deepslate{axis:y}"},
        {pos: [15, 3, 25], state: "minecraft:deepslate{axis:y}"},
        {pos: [15, 3, 26], state: "minecraft:deepslate{axis:y}"},
        {pos: [15, 3, 27], state: "minecraft:deepslate{axis:y}"},
        {pos: [15, 3, 28], state: "minecraft:deepslate{axis:y}"},
        {pos: [16, 3, 5], state: "minecraft:deepslate_bricks"},
        {pos: [16, 3, 6], state: "minecraft:deepslate_bricks"},
        {pos: [16, 3, 7], state: "minecraft:deepslate{axis:y}"},
        {pos: [16, 3, 8], state: "minecraft:deepslate{axis:y}"},
        {pos: [16, 3, 9], state: "minecraft:deepslate{axis:y}"},
        {pos: [16, 3, 10], state: "minecraft:deepslate{axis:y}"},
        {pos: [16, 3, 11], state: "minecraft:deepslate{axis:y}"},
        {pos: [16, 3, 12], state: "minecraft:deepslate{axis:y}"},
        {pos: [16, 3, 13], state: "minecraft:deepslate{axis:y}"},
        {pos: [16, 3, 14], state: "minecraft:deepslate{axis:y}"},
        {pos: [16, 3, 15], state: "minecraft:deepslate{axis:y}"},
        {pos: [16, 3, 16], state: "minecraft:deepslate{axis:y}"},
        {pos: [16, 3, 17], state: "minecraft:deepslate{axis:y}"},
        {pos: [16, 3, 18], state: "minecraft:deepslate{axis:y}"},
        {pos: [16, 3, 19], state: "minecraft:deepslate{axis:y}"},
        {pos: [16, 3, 20], state: "minecraft:deepslate{axis:y}"},
        {pos: [16, 3, 21], state: "minecraft:deepslate{axis:y}"},
        {pos: [16, 3, 22], state: "minecraft:deepslate{axis:y}"},
        {pos: [16, 3, 23], state: "minecraft:deepslate{axis:y}"},
        {pos: [17, 3, 5], state: "minecraft:deepslate_bricks"},
        {pos: [17, 3, 6], state: "minecraft:deepslate_bricks"},
        {pos: [17, 3, 7], state: "minecraft:deepslate{axis:y}"},
        {pos: [17, 3, 8], state: "minecraft:deepslate{axis:y}"},
        {pos: [17, 3, 9], state: "minecraft:deepslate{axis:y}"},
        {pos: [17, 3, 10], state: "minecraft:deepslate{axis:y}"},
        {pos: [17, 3, 11], state: "minecraft:deepslate{axis:y}"},
        {pos: [17, 3, 12], state: "minecraft:deepslate{axis:y}"},
        {pos: [17, 3, 13], state: "minecraft:deepslate{axis:y}"},
        {pos: [17, 3, 14], state: "minecraft:deepslate{axis:y}"},
        {pos: [17, 3, 15], state: "minecraft:deepslate{axis:y}"},
        {pos: [17, 3, 16], state: "minecraft:deepslate{axis:y}"},
        {pos: [17, 3, 17], state: "minecraft:deepslate{axis:y}"},
        {pos: [17, 3, 18], state: "minecraft:deepslate{axis:y}"},
        {pos: [17, 3, 19], state: "minecraft:deepslate{axis:y}"},
        {pos: [17, 3, 20], state: "minecraft:deepslate{axis:y}"},
        {pos: [17, 3, 21], state: "minecraft:deepslate{axis:y}"},
        {pos: [17, 3, 22], state: "minecraft:deepslate{axis:y}"},
        {pos: [17, 3, 23], state: "minecraft:deepslate{axis:y}"},
        {pos: [18, 3, 5], state: "minecraft:deepslate_bricks"},
        {pos: [18, 3, 6], state: "minecraft:deepslate_bricks"},
        {pos: [18, 3, 7], state: "minecraft:deepslate{axis:y}"},
        {pos: [18, 3, 8], state: "minecraft:deepslate{axis:y}"},
        {pos: [18, 3, 9], state: "minecraft:deepslate{axis:y}"},
        {pos: [18, 3, 10], state: "minecraft:deepslate{axis:y}"},
        {pos: [18, 3, 11], state: "minecraft:deepslate{axis:y}"},
        {pos: [18, 3, 12], state: "minecraft:deepslate{axis:y}"},
        {pos: [18, 3, 13], state: "minecraft:deepslate{axis:y}"},
        {pos: [18, 3, 14], state: "minecraft:deepslate{axis:y}"},
        {pos: [18, 3, 15], state: "minecraft:deepslate{axis:y}"},
        {pos: [18, 3, 16], state: "minecraft:deepslate{axis:y}"},
        {pos: [18, 3, 17], state: "minecraft:deepslate{axis:y}"},
        {pos: [18, 3, 18], state: "minecraft:deepslate{axis:y}"},
        {pos: [18, 3, 19], state: "minecraft:deepslate{axis:y}"},
        {pos: [18, 3, 20], state: "minecraft:deepslate{axis:y}"},
        {pos: [18, 3, 21], state: "minecraft:deepslate{axis:y}"},
        {pos: [18, 3, 22], state: "minecraft:deepslate_bricks"},
        {pos: [18, 3, 23], state: "minecraft:deepslate_bricks"},
        {pos: [19, 3, 5], state: "minecraft:deepslate_bricks"},
        {pos: [19, 3, 6], state: "minecraft:redstone_wire{east:side,north:none,power:0,south:none,west:up}"},
        {pos: [19, 3, 7], state: "minecraft:deepslate{axis:y}"},
        {pos: [19, 3, 8], state: "minecraft:deepslate{axis:y}"},
        {pos: [19, 3, 9], state: "minecraft:deepslate{axis:y}"},
        {pos: [19, 3, 10], state: "minecraft:deepslate{axis:y}"},
        {pos: [19, 3, 11], state: "minecraft:deepslate{axis:y}"},
        {pos: [19, 3, 12], state: "minecraft:deepslate{axis:y}"},
        {pos: [19, 3, 13], state: "minecraft:deepslate{axis:y}"},
        {pos: [19, 3, 14], state: "minecraft:deepslate{axis:y}"},
        {pos: [19, 3, 15], state: "minecraft:deepslate{axis:y}"},
        {pos: [19, 3, 16], state: "minecraft:deepslate{axis:y}"},
        {pos: [19, 3, 17], state: "minecraft:deepslate{axis:y}"},
        {pos: [19, 3, 18], state: "minecraft:deepslate{axis:y}"},
        {pos: [19, 3, 19], state: "minecraft:deepslate{axis:y}"},
        {pos: [19, 3, 20], state: "minecraft:deepslate{axis:y}"},
        {pos: [19, 3, 21], state: "minecraft:deepslate{axis:y}"},
        {pos: [19, 3, 22], state: "minecraft:redstone_wire{east:side,north:none,power:0,south:none,west:up}"},
        {pos: [19, 3, 23], state: "minecraft:deepslate_bricks"},
        {pos: [20, 3, 5], state: "minecraft:deepslate_bricks"},
        {pos: [20, 3, 6], state: "minecraft:cave_air"},
        {pos: [20, 3, 7], state: "minecraft:deepslate{axis:y}"},
        {pos: [20, 3, 8], state: "minecraft:deepslate{axis:y}"},
        {pos: [20, 3, 9], state: "minecraft:deepslate{axis:y}"},
        {pos: [20, 3, 10], state: "minecraft:deepslate{axis:y}"},
        {pos: [20, 3, 11], state: "minecraft:deepslate{axis:y}"},
        {pos: [20, 3, 12], state: "minecraft:deepslate{axis:y}"},
        {pos: [20, 3, 13], state: "minecraft:deepslate{axis:y}"},
        {pos: [20, 3, 14], state: "minecraft:deepslate{axis:y}"},
        {pos: [20, 3, 15], state: "minecraft:deepslate{axis:y}"},
        {pos: [20, 3, 16], state: "minecraft:deepslate{axis:y}"},
        {pos: [20, 3, 17], state: "minecraft:deepslate{axis:y}"},
        {pos: [20, 3, 18], state: "minecraft:deepslate{axis:y}"},
        {pos: [20, 3, 19], state: "minecraft:deepslate{axis:y}"},
        {pos: [20, 3, 20], state: "minecraft:deepslate{axis:y}"},
        {pos: [20, 3, 21], state: "minecraft:deepslate{axis:y}"},
        {pos: [20, 3, 22], state: "minecraft:cave_air"},
        {pos: [20, 3, 23], state: "minecraft:deepslate_bricks"},
        {pos: [21, 3, 5], state: "minecraft:deepslate_bricks"},
        {pos: [21, 3, 6], state: "minecraft:redstone_wire{east:side,north:none,power:0,south:none,west:side}"},
        {pos: [21, 3, 7], state: "minecraft:deepslate{axis:y}"},
        {pos: [21, 3, 8], state: "minecraft:deepslate{axis:y}"},
        {pos: [21, 3, 9], state: "minecraft:deepslate{axis:y}"},
        {pos: [21, 3, 10], state: "minecraft:deepslate{axis:y}"},
        {pos: [21, 3, 11], state: "minecraft:deepslate{axis:y}"},
        {pos: [21, 3, 12], state: "minecraft:deepslate{axis:y}"},
        {pos: [21, 3, 13], state: "minecraft:deepslate{axis:y}"},
        {pos: [21, 3, 14], state: "minecraft:deepslate{axis:y}"},
        {pos: [21, 3, 15], state: "minecraft:deepslate{axis:y}"},
        {pos: [21, 3, 16], state: "minecraft:deepslate{axis:y}"},
        {pos: [21, 3, 17], state: "minecraft:deepslate{axis:y}"},
        {pos: [21, 3, 18], state: "minecraft:deepslate{axis:y}"},
        {pos: [21, 3, 19], state: "minecraft:deepslate{axis:y}"},
        {pos: [21, 3, 20], state: "minecraft:deepslate{axis:y}"},
        {pos: [21, 3, 21], state: "minecraft:deepslate_bricks"},
        {pos: [21, 3, 22], state: "minecraft:deepslate_bricks"},
        {pos: [22, 3, 5], state: "minecraft:deepslate_bricks"},
        {pos: [22, 3, 6], state: "minecraft:deepslate_bricks"},
        {pos: [22, 3, 7], state: "minecraft:deepslate_bricks"},
        {pos: [22, 3, 8], state: "minecraft:deepslate_bricks"},
        {pos: [22, 3, 9], state: "minecraft:deepslate_bricks"},
        {pos: [22, 3, 10], state: "minecraft:deepslate_bricks"},
        {pos: [22, 3, 11], state: "minecraft:deepslate_bricks"},
        {pos: [22, 3, 12], state: "minecraft:deepslate_bricks"},
        {pos: [22, 3, 13], state: "minecraft:deepslate_bricks"},
        {pos: [22, 3, 14], state: "minecraft:deepslate_bricks"},
        {pos: [22, 3, 15], state: "minecraft:deepslate_bricks"},
        {pos: [22, 3, 16], state: "minecraft:deepslate_bricks"},
        {pos: [22, 3, 17], state: "minecraft:deepslate_bricks"},
        {pos: [22, 3, 18], state: "minecraft:deepslate_bricks"},
        {pos: [22, 3, 19], state: "minecraft:deepslate_bricks"},
        {pos: [22, 3, 20], state: "minecraft:deepslate_bricks"},
        {pos: [23, 3, 11], state: "minecraft:deepslate{axis:y}"},
        {pos: [23, 3, 12], state: "minecraft:deepslate{axis:y}"},
        {pos: [23, 3, 13], state: "minecraft:deepslate{axis:y}"},
        {pos: [23, 3, 14], state: "minecraft:deepslate{axis:y}"},
        {pos: [23, 3, 15], state: "minecraft:deepslate{axis:y}"},
        {pos: [23, 3, 16], state: "minecraft:deepslate{axis:y}"},
        {pos: [23, 3, 17], state: "minecraft:deepslate{axis:y}"},
        {pos: [24, 3, 11], state: "minecraft:deepslate{axis:y}"},
        {pos: [24, 3, 12], state: "minecraft:deepslate{axis:y}"},
        {pos: [24, 3, 13], state: "minecraft:deepslate{axis:y}"},
        {pos: [24, 3, 14], state: "minecraft:deepslate{axis:y}"},
        {pos: [24, 3, 15], state: "minecraft:deepslate{axis:y}"},
        {pos: [24, 3, 16], state: "minecraft:deepslate{axis:y}"},
        {pos: [24, 3, 17], state: "minecraft:deepslate{axis:y}"},
        {pos: [0, 4, 7], state: "minecraft:deepslate_bricks"},
        {pos: [0, 4, 8], state: "minecraft:deepslate_bricks"},
        {pos: [0, 4, 9], state: "minecraft:deepslate_bricks"},
        {pos: [0, 4, 10], state: "minecraft:deepslate_bricks"},
        {pos: [0, 4, 11], state: "minecraft:deepslate_bricks"},
        {pos: [0, 4, 12], state: "minecraft:deepslate_bricks"},
        {pos: [0, 4, 13], state: "minecraft:gravel"},
        {pos: [0, 4, 14], state: "minecraft:gravel"},
        {pos: [0, 4, 15], state: "minecraft:gravel"},
        {pos: [0, 4, 16], state: "minecraft:deepslate_bricks"},
        {pos: [0, 4, 17], state: "minecraft:deepslate_bricks"},
        {pos: [0, 4, 18], state: "minecraft:deepslate_bricks"},
        {pos: [0, 4, 19], state: "minecraft:deepslate_bricks"},
        {pos: [0, 4, 20], state: "minecraft:deepslate_bricks"},
        {pos: [0, 4, 21], state: "minecraft:deepslate_bricks"},
        {pos: [1, 4, 7], state: "minecraft:deepslate_bricks"},
        {pos: [1, 4, 8], state: "minecraft:deepslate_bricks"},
        {pos: [1, 4, 9], state: "minecraft:deepslate_bricks"},
        {pos: [1, 4, 10], state: "minecraft:deepslate_bricks"},
        {pos: [1, 4, 11], state: "minecraft:deepslate_bricks"},
        {pos: [1, 4, 12], state: "minecraft:gravel"},
        {pos: [1, 4, 13], state: "minecraft:gravel"},
        {pos: [1, 4, 14], state: "minecraft:gravel"},
        {pos: [1, 4, 15], state: "minecraft:gravel"},
        {pos: [1, 4, 16], state: "minecraft:gravel"},
        {pos: [1, 4, 17], state: "minecraft:deepslate_bricks"},
        {pos: [1, 4, 18], state: "minecraft:deepslate_bricks"},
        {pos: [1, 4, 19], state: "minecraft:deepslate_bricks"},
        {pos: [1, 4, 20], state: "minecraft:deepslate_bricks"},
        {pos: [1, 4, 21], state: "minecraft:deepslate_bricks"},
        {pos: [2, 4, 7], state: "minecraft:deepslate_bricks"},
        {pos: [2, 4, 8], state: "minecraft:deepslate_bricks"},
        {pos: [2, 4, 9], state: "minecraft:deepslate_bricks"},
        {pos: [2, 4, 10], state: "minecraft:deepslate_bricks"},
        {pos: [2, 4, 11], state: "minecraft:deepslate_bricks"},
        {pos: [2, 4, 12], state: "minecraft:deepslate_bricks"},
        {pos: [2, 4, 13], state: "minecraft:gravel"},
        {pos: [2, 4, 14], state: "minecraft:gravel"},
        {pos: [2, 4, 15], state: "minecraft:gravel"},
        {pos: [2, 4, 16], state: "minecraft:deepslate_bricks"},
        {pos: [2, 4, 17], state: "minecraft:deepslate_bricks"},
        {pos: [2, 4, 18], state: "minecraft:deepslate_bricks"},
        {pos: [2, 4, 19], state: "minecraft:deepslate_bricks"},
        {pos: [2, 4, 20], state: "minecraft:deepslate_bricks"},
        {pos: [2, 4, 21], state: "minecraft:deepslate_bricks"},
        {pos: [3, 4, 0], state: "minecraft:deepslate_bricks"},
        {pos: [3, 4, 1], state: "minecraft:deepslate_bricks"},
        {pos: [3, 4, 2], state: "minecraft:deepslate_bricks"},
        {pos: [3, 4, 3], state: "minecraft:deepslate_bricks"},
        {pos: [3, 4, 4], state: "minecraft:deepslate_bricks"},
        {pos: [3, 4, 5], state: "minecraft:deepslate_bricks"},
        {pos: [3, 4, 6], state: "minecraft:deepslate_bricks"},
        {pos: [3, 4, 7], state: "minecraft:deepslate_bricks"},
        {pos: [3, 4, 8], state: "minecraft:gravel"},
        {pos: [3, 4, 9], state: "minecraft:gravel"},
        {pos: [3, 4, 10], state: "minecraft:gravel"},
        {pos: [3, 4, 11], state: "minecraft:gravel"},
        {pos: [3, 4, 12], state: "minecraft:gravel"},
        {pos: [3, 4, 13], state: "minecraft:gravel"},
        {pos: [3, 4, 14], state: "minecraft:gravel"},
        {pos: [3, 4, 15], state: "minecraft:gravel"},
        {pos: [3, 4, 16], state: "minecraft:gravel"},
        {pos: [3, 4, 17], state: "minecraft:gravel"},
        {pos: [3, 4, 18], state: "minecraft:gravel"},
        {pos: [3, 4, 19], state: "minecraft:gravel"},
        {pos: [3, 4, 20], state: "minecraft:gravel"},
        {pos: [3, 4, 21], state: "minecraft:deepslate_bricks"},
        {pos: [3, 4, 22], state: "minecraft:deepslate_bricks"},
        {pos: [3, 4, 23], state: "minecraft:deepslate_bricks"},
        {pos: [3, 4, 24], state: "minecraft:deepslate_bricks"},
        {pos: [3, 4, 25], state: "minecraft:deepslate_bricks"},
        {pos: [3, 4, 26], state: "minecraft:deepslate_bricks"},
        {pos: [3, 4, 27], state: "minecraft:deepslate_bricks"},
        {pos: [3, 4, 28], state: "minecraft:deepslate_bricks"},
        {pos: [4, 4, 0], state: "minecraft:deepslate_bricks"},
        {pos: [4, 4, 1], state: "minecraft:deepslate_bricks"},
        {pos: [4, 4, 2], state: "minecraft:deepslate_bricks"},
        {pos: [4, 4, 3], state: "minecraft:deepslate_bricks"},
        {pos: [4, 4, 4], state: "minecraft:deepslate_bricks"},
        {pos: [4, 4, 5], state: "minecraft:deepslate_bricks"},
        {pos: [4, 4, 6], state: "minecraft:deepslate_bricks"},
        {pos: [4, 4, 7], state: "minecraft:deepslate_bricks"},
        {pos: [4, 4, 8], state: "minecraft:gravel"},
        {pos: [4, 4, 9], state: "minecraft:gravel"},
        {pos: [4, 4, 10], state: "minecraft:gravel"},
        {pos: [4, 4, 11], state: "minecraft:gravel"},
        {pos: [4, 4, 12], state: "minecraft:gravel"},
        {pos: [4, 4, 13], state: "minecraft:gravel"},
        {pos: [4, 4, 14], state: "minecraft:gravel"},
        {pos: [4, 4, 15], state: "minecraft:gravel"},
        {pos: [4, 4, 16], state: "minecraft:gravel"},
        {pos: [4, 4, 17], state: "minecraft:gravel"},
        {pos: [4, 4, 18], state: "minecraft:gravel"},
        {pos: [4, 4, 19], state: "minecraft:gravel"},
        {pos: [4, 4, 20], state: "minecraft:gravel"},
        {pos: [4, 4, 21], state: "minecraft:deepslate_bricks"},
        {pos: [4, 4, 22], state: "minecraft:deepslate_bricks"},
        {pos: [4, 4, 23], state: "minecraft:deepslate_bricks"},
        {pos: [4, 4, 24], state: "minecraft:deepslate_bricks"},
        {pos: [4, 4, 25], state: "minecraft:deepslate_bricks"},
        {pos: [4, 4, 26], state: "minecraft:deepslate_bricks"},
        {pos: [4, 4, 27], state: "minecraft:deepslate_bricks"},
        {pos: [4, 4, 28], state: "minecraft:deepslate_bricks"},
        {pos: [5, 4, 0], state: "minecraft:deepslate_bricks"},
        {pos: [5, 4, 1], state: "minecraft:deepslate_bricks"},
        {pos: [5, 4, 2], state: "minecraft:deepslate_bricks"},
        {pos: [5, 4, 3], state: "minecraft:deepslate_bricks"},
        {pos: [5, 4, 4], state: "minecraft:deepslate_bricks"},
        {pos: [5, 4, 5], state: "minecraft:deepslate_bricks"},
        {pos: [5, 4, 6], state: "minecraft:deepslate_bricks"},
        {pos: [5, 4, 7], state: "minecraft:deepslate_bricks"},
        {pos: [5, 4, 8], state: "minecraft:gravel"},
        {pos: [5, 4, 9], state: "minecraft:gravel"},
        {pos: [5, 4, 10], state: "minecraft:gravel"},
        {pos: [5, 4, 11], state: "minecraft:gravel"},
        {pos: [5, 4, 12], state: "minecraft:gravel"},
        {pos: [5, 4, 13], state: "minecraft:gravel"},
        {pos: [5, 4, 14], state: "minecraft:gravel"},
        {pos: [5, 4, 15], state: "minecraft:gravel"},
        {pos: [5, 4, 16], state: "minecraft:gravel"},
        {pos: [5, 4, 17], state: "minecraft:gravel"},
        {pos: [5, 4, 18], state: "minecraft:gravel"},
        {pos: [5, 4, 19], state: "minecraft:gravel"},
        {pos: [5, 4, 20], state: "minecraft:gravel"},
        {pos: [5, 4, 21], state: "minecraft:deepslate_bricks"},
        {pos: [5, 4, 22], state: "minecraft:deepslate_bricks"},
        {pos: [5, 4, 23], state: "minecraft:deepslate_bricks"},
        {pos: [5, 4, 24], state: "minecraft:deepslate_bricks"},
        {pos: [5, 4, 25], state: "minecraft:deepslate_bricks"},
        {pos: [5, 4, 26], state: "minecraft:deepslate_bricks"},
        {pos: [5, 4, 27], state: "minecraft:deepslate_bricks"},
        {pos: [5, 4, 28], state: "minecraft:deepslate_bricks"},
        {pos: [6, 4, 0], state: "minecraft:deepslate_bricks"},
        {pos: [6, 4, 1], state: "minecraft:deepslate_bricks"},
        {pos: [6, 4, 2], state: "minecraft:deepslate_bricks"},
        {pos: [6, 4, 3], state: "minecraft:deepslate_bricks"},
        {pos: [6, 4, 4], state: "minecraft:deepslate_bricks"},
        {pos: [6, 4, 5], state: "minecraft:deepslate_bricks"},
        {pos: [6, 4, 6], state: "minecraft:deepslate_bricks"},
        {pos: [6, 4, 7], state: "minecraft:deepslate_bricks"},
        {pos: [6, 4, 8], state: "minecraft:gravel"},
        {pos: [6, 4, 9], state: "minecraft:gravel"},
        {pos: [6, 4, 10], state: "minecraft:gravel"},
        {pos: [6, 4, 11], state: "minecraft:gravel"},
        {pos: [6, 4, 12], state: "minecraft:gravel"},
        {pos: [6, 4, 13], state: "minecraft:gravel"},
        {pos: [6, 4, 14], state: "minecraft:gravel"},
        {pos: [6, 4, 15], state: "minecraft:gravel"},
        {pos: [6, 4, 16], state: "minecraft:gravel"},
        {pos: [6, 4, 17], state: "minecraft:gravel"},
        {pos: [6, 4, 18], state: "minecraft:gravel"},
        {pos: [6, 4, 19], state: "minecraft:gravel"},
        {pos: [6, 4, 20], state: "minecraft:gravel"},
        {pos: [6, 4, 21], state: "minecraft:deepslate_bricks"},
        {pos: [6, 4, 22], state: "minecraft:deepslate_bricks"},
        {pos: [6, 4, 23], state: "minecraft:deepslate_bricks"},
        {pos: [6, 4, 24], state: "minecraft:deepslate_bricks"},
        {pos: [6, 4, 25], state: "minecraft:deepslate_bricks"},
        {pos: [6, 4, 26], state: "minecraft:deepslate_bricks"},
        {pos: [6, 4, 27], state: "minecraft:deepslate_bricks"},
        {pos: [6, 4, 28], state: "minecraft:deepslate_bricks"},
        {pos: [7, 4, 0], state: "minecraft:deepslate_bricks"},
        {pos: [7, 4, 1], state: "minecraft:deepslate_bricks"},
        {pos: [7, 4, 2], state: "minecraft:deepslate_bricks"},
        {pos: [7, 4, 3], state: "minecraft:deepslate_bricks"},
        {pos: [7, 4, 4], state: "minecraft:deepslate_bricks"},
        {pos: [7, 4, 5], state: "minecraft:deepslate_bricks"},
        {pos: [7, 4, 6], state: "minecraft:deepslate_bricks"},
        {pos: [7, 4, 7], state: "minecraft:deepslate_bricks"},
        {pos: [7, 4, 8], state: "minecraft:gravel"},
        {pos: [7, 4, 9], state: "minecraft:gravel"},
        {pos: [7, 4, 10], state: "minecraft:gravel"},
        {pos: [7, 4, 11], state: "minecraft:gravel"},
        {pos: [7, 4, 12], state: "minecraft:gravel"},
        {pos: [7, 4, 13], state: "minecraft:gravel"},
        {pos: [7, 4, 14], state: "minecraft:gravel"},
        {pos: [7, 4, 15], state: "minecraft:gravel"},
        {pos: [7, 4, 16], state: "minecraft:gravel"},
        {pos: [7, 4, 17], state: "minecraft:gravel"},
        {pos: [7, 4, 18], state: "minecraft:gravel"},
        {pos: [7, 4, 19], state: "minecraft:gravel"},
        {pos: [7, 4, 20], state: "minecraft:gravel"},
        {pos: [7, 4, 21], state: "minecraft:deepslate_bricks"},
        {pos: [7, 4, 22], state: "minecraft:deepslate_bricks"},
        {pos: [7, 4, 23], state: "minecraft:deepslate_bricks"},
        {pos: [7, 4, 24], state: "minecraft:deepslate_bricks"},
        {pos: [7, 4, 25], state: "minecraft:deepslate_bricks"},
        {pos: [7, 4, 26], state: "minecraft:deepslate_bricks"},
        {pos: [7, 4, 27], state: "minecraft:deepslate_bricks"},
        {pos: [7, 4, 28], state: "minecraft:deepslate_bricks"},
        {pos: [8, 4, 0], state: "minecraft:deepslate_bricks"},
        {pos: [8, 4, 1], state: "minecraft:deepslate_bricks"},
        {pos: [8, 4, 2], state: "minecraft:deepslate_bricks"},
        {pos: [8, 4, 3], state: "minecraft:deepslate_bricks"},
        {pos: [8, 4, 4], state: "minecraft:deepslate_bricks"},
        {pos: [8, 4, 5], state: "minecraft:deepslate_bricks"},
        {pos: [8, 4, 6], state: "minecraft:deepslate_bricks"},
        {pos: [8, 4, 7], state: "minecraft:gravel"},
        {pos: [8, 4, 8], state: "minecraft:gravel"},
        {pos: [8, 4, 9], state: "minecraft:gravel"},
        {pos: [8, 4, 10], state: "minecraft:gravel"},
        {pos: [8, 4, 11], state: "minecraft:gravel"},
        {pos: [8, 4, 12], state: "minecraft:gravel"},
        {pos: [8, 4, 13], state: "minecraft:gravel"},
        {pos: [8, 4, 14], state: "minecraft:gravel"},
        {pos: [8, 4, 15], state: "minecraft:gravel"},
        {pos: [8, 4, 16], state: "minecraft:gravel"},
        {pos: [8, 4, 17], state: "minecraft:gravel"},
        {pos: [8, 4, 18], state: "minecraft:gravel"},
        {pos: [8, 4, 19], state: "minecraft:gravel"},
        {pos: [8, 4, 20], state: "minecraft:gravel"},
        {pos: [8, 4, 21], state: "minecraft:gravel"},
        {pos: [8, 4, 22], state: "minecraft:deepslate_bricks"},
        {pos: [8, 4, 23], state: "minecraft:deepslate_bricks"},
        {pos: [8, 4, 24], state: "minecraft:deepslate_bricks"},
        {pos: [8, 4, 25], state: "minecraft:deepslate_bricks"},
        {pos: [8, 4, 26], state: "minecraft:deepslate_bricks"},
        {pos: [8, 4, 27], state: "minecraft:deepslate_bricks"},
        {pos: [8, 4, 28], state: "minecraft:deepslate_bricks"},
        {pos: [9, 4, 0], state: "minecraft:deepslate_bricks"},
        {pos: [9, 4, 1], state: "minecraft:deepslate_bricks"},
        {pos: [9, 4, 2], state: "minecraft:deepslate_bricks"},
        {pos: [9, 4, 3], state: "minecraft:deepslate_bricks"},
        {pos: [9, 4, 4], state: "minecraft:deepslate_bricks"},
        {pos: [9, 4, 5], state: "minecraft:deepslate_bricks"},
        {pos: [9, 4, 6], state: "minecraft:deepslate_bricks"},
        {pos: [9, 4, 7], state: "minecraft:gravel"},
        {pos: [9, 4, 8], state: "minecraft:gravel"},
        {pos: [9, 4, 9], state: "minecraft:gravel"},
        {pos: [9, 4, 10], state: "minecraft:gravel"},
        {pos: [9, 4, 11], state: "minecraft:deepslate_bricks"},
        {pos: [9, 4, 12], state: "minecraft:deepslate_bricks"},
        {pos: [9, 4, 13], state: "minecraft:gravel"},
        {pos: [9, 4, 14], state: "minecraft:gravel"},
        {pos: [9, 4, 15], state: "minecraft:gravel"},
        {pos: [9, 4, 16], state: "minecraft:deepslate_bricks"},
        {pos: [9, 4, 17], state: "minecraft:deepslate_bricks"},
        {pos: [9, 4, 18], state: "minecraft:gravel"},
        {pos: [9, 4, 19], state: "minecraft:gravel"},
        {pos: [9, 4, 20], state: "minecraft:gravel"},
        {pos: [9, 4, 21], state: "minecraft:gravel"},
        {pos: [9, 4, 22], state: "minecraft:deepslate_bricks"},
        {pos: [9, 4, 23], state: "minecraft:deepslate_bricks"},
        {pos: [9, 4, 24], state: "minecraft:deepslate_bricks"},
        {pos: [9, 4, 25], state: "minecraft:deepslate_bricks"},
        {pos: [9, 4, 26], state: "minecraft:deepslate_bricks"},
        {pos: [9, 4, 27], state: "minecraft:deepslate_bricks"},
        {pos: [9, 4, 28], state: "minecraft:deepslate_bricks"},
        {pos: [10, 4, 0], state: "minecraft:deepslate_bricks"},
        {pos: [10, 4, 1], state: "minecraft:deepslate_bricks"},
        {pos: [10, 4, 2], state: "minecraft:deepslate_bricks"},
        {pos: [10, 4, 3], state: "minecraft:deepslate_bricks"},
        {pos: [10, 4, 4], state: "minecraft:deepslate_bricks"},
        {pos: [10, 4, 5], state: "minecraft:deepslate_bricks"},
        {pos: [10, 4, 6], state: "minecraft:deepslate_bricks"},
        {pos: [10, 4, 7], state: "minecraft:gravel"},
        {pos: [10, 4, 8], state: "minecraft:gravel"},
        {pos: [10, 4, 9], state: "minecraft:gravel"},
        {pos: [10, 4, 10], state: "minecraft:gravel"},
        {pos: [10, 4, 11], state: "minecraft:deepslate_bricks"},
        {pos: [10, 4, 12], state: "minecraft:gravel"},
        {pos: [10, 4, 13], state: "minecraft:gravel"},
        {pos: [10, 4, 14], state: "minecraft:gravel"},
        {pos: [10, 4, 15], state: "minecraft:gravel"},
        {pos: [10, 4, 16], state: "minecraft:gravel"},
        {pos: [10, 4, 17], state: "minecraft:deepslate_bricks"},
        {pos: [10, 4, 18], state: "minecraft:gravel"},
        {pos: [10, 4, 19], state: "minecraft:gravel"},
        {pos: [10, 4, 20], state: "minecraft:gravel"},
        {pos: [10, 4, 21], state: "minecraft:gravel"},
        {pos: [10, 4, 22], state: "minecraft:deepslate_bricks"},
        {pos: [10, 4, 23], state: "minecraft:deepslate_bricks"},
        {pos: [10, 4, 24], state: "minecraft:deepslate_bricks"},
        {pos: [10, 4, 25], state: "minecraft:deepslate_bricks"},
        {pos: [10, 4, 26], state: "minecraft:deepslate_bricks"},
        {pos: [10, 4, 27], state: "minecraft:deepslate_bricks"},
        {pos: [10, 4, 28], state: "minecraft:deepslate_bricks"},
        {pos: [11, 4, 0], state: "minecraft:deepslate_bricks"},
        {pos: [11, 4, 1], state: "minecraft:deepslate_bricks"},
        {pos: [11, 4, 2], state: "minecraft:gravel"},
        {pos: [11, 4, 3], state: "minecraft:gravel"},
        {pos: [11, 4, 4], state: "minecraft:gravel"},
        {pos: [11, 4, 5], state: "minecraft:deepslate_bricks"},
        {pos: [11, 4, 6], state: "minecraft:deepslate_bricks"},
        {pos: [11, 4, 7], state: "minecraft:deepslate_bricks"},
        {pos: [11, 4, 8], state: "minecraft:gravel"},
        {pos: [11, 4, 9], state: "minecraft:gravel"},
        {pos: [11, 4, 10], state: "minecraft:gravel"},
        {pos: [11, 4, 11], state: "minecraft:deepslate_bricks"},
        {pos: [11, 4, 12], state: "minecraft:gravel"},
        {pos: [11, 4, 13], state: "minecraft:gravel"},
        {pos: [11, 4, 14], state: "minecraft:gravel"},
        {pos: [11, 4, 15], state: "minecraft:gravel"},
        {pos: [11, 4, 16], state: "minecraft:gravel"},
        {pos: [11, 4, 17], state: "minecraft:deepslate_bricks"},
        {pos: [11, 4, 18], state: "minecraft:gravel"},
        {pos: [11, 4, 19], state: "minecraft:gravel"},
        {pos: [11, 4, 20], state: "minecraft:gravel"},
        {pos: [11, 4, 21], state: "minecraft:deepslate_bricks"},
        {pos: [11, 4, 22], state: "minecraft:deepslate_bricks"},
        {pos: [11, 4, 23], state: "minecraft:deepslate_bricks"},
        {pos: [11, 4, 24], state: "minecraft:gravel"},
        {pos: [11, 4, 25], state: "minecraft:gravel"},
        {pos: [11, 4, 26], state: "minecraft:gravel"},
        {pos: [11, 4, 27], state: "minecraft:deepslate_bricks"},
        {pos: [11, 4, 28], state: "minecraft:deepslate_bricks"},
        {pos: [12, 4, 0], state: "minecraft:deepslate_bricks"},
        {pos: [12, 4, 1], state: "minecraft:deepslate_bricks"},
        {pos: [12, 4, 2], state: "minecraft:gravel"},
        {pos: [12, 4, 3], state: "minecraft:gravel"},
        {pos: [12, 4, 4], state: "minecraft:gravel"},
        {pos: [12, 4, 5], state: "minecraft:gravel"},
        {pos: [12, 4, 6], state: "minecraft:gravel"},
        {pos: [12, 4, 7], state: "minecraft:gravel"},
        {pos: [12, 4, 8], state: "minecraft:gravel"},
        {pos: [12, 4, 9], state: "minecraft:gravel"},
        {pos: [12, 4, 10], state: "minecraft:gravel"},
        {pos: [12, 4, 11], state: "minecraft:deepslate_bricks"},
        {pos: [12, 4, 12], state: "minecraft:gravel"},
        {pos: [12, 4, 13], state: "minecraft:gravel"},
        {pos: [12, 4, 14], state: "minecraft:gravel"},
        {pos: [12, 4, 15], state: "minecraft:gravel"},
        {pos: [12, 4, 16], state: "minecraft:gravel"},
        {pos: [12, 4, 17], state: "minecraft:deepslate_bricks"},
        {pos: [12, 4, 18], state: "minecraft:gravel"},
        {pos: [12, 4, 19], state: "minecraft:gravel"},
        {pos: [12, 4, 20], state: "minecraft:gravel"},
        {pos: [12, 4, 21], state: "minecraft:gravel"},
        {pos: [12, 4, 22], state: "minecraft:gravel"},
        {pos: [12, 4, 23], state: "minecraft:gravel"},
        {pos: [12, 4, 24], state: "minecraft:gravel"},
        {pos: [12, 4, 25], state: "minecraft:gravel"},
        {pos: [12, 4, 26], state: "minecraft:gravel"},
        {pos: [12, 4, 27], state: "minecraft:deepslate_bricks"},
        {pos: [12, 4, 28], state: "minecraft:deepslate_bricks"},
        {pos: [13, 4, 0], state: "minecraft:deepslate_bricks"},
        {pos: [13, 4, 1], state: "minecraft:deepslate_bricks"},
        {pos: [13, 4, 2], state: "minecraft:gravel"},
        {pos: [13, 4, 3], state: "minecraft:gravel"},
        {pos: [13, 4, 4], state: "minecraft:gravel"},
        {pos: [13, 4, 5], state: "minecraft:deepslate_bricks"},
        {pos: [13, 4, 6], state: "minecraft:deepslate_bricks"},
        {pos: [13, 4, 7], state: "minecraft:deepslate_bricks"},
        {pos: [13, 4, 8], state: "minecraft:gravel"},
        {pos: [13, 4, 9], state: "minecraft:gravel"},
        {pos: [13, 4, 10], state: "minecraft:gravel"},
        {pos: [13, 4, 11], state: "minecraft:deepslate_bricks"},
        {pos: [13, 4, 12], state: "minecraft:gravel"},
        {pos: [13, 4, 13], state: "minecraft:gravel"},
        {pos: [13, 4, 14], state: "minecraft:gravel"},
        {pos: [13, 4, 15], state: "minecraft:gravel"},
        {pos: [13, 4, 16], state: "minecraft:gravel"},
        {pos: [13, 4, 17], state: "minecraft:deepslate_bricks"},
        {pos: [13, 4, 18], state: "minecraft:gravel"},
        {pos: [13, 4, 19], state: "minecraft:gravel"},
        {pos: [13, 4, 20], state: "minecraft:gravel"},
        {pos: [13, 4, 21], state: "minecraft:deepslate_bricks"},
        {pos: [13, 4, 22], state: "minecraft:deepslate_bricks"},
        {pos: [13, 4, 23], state: "minecraft:deepslate_bricks"},
        {pos: [13, 4, 24], state: "minecraft:gravel"},
        {pos: [13, 4, 25], state: "minecraft:gravel"},
        {pos: [13, 4, 26], state: "minecraft:gravel"},
        {pos: [13, 4, 27], state: "minecraft:deepslate_bricks"},
        {pos: [13, 4, 28], state: "minecraft:deepslate_bricks"},
        {pos: [14, 4, 0], state: "minecraft:deepslate_bricks"},
        {pos: [14, 4, 1], state: "minecraft:deepslate_bricks"},
        {pos: [14, 4, 2], state: "minecraft:deepslate_bricks"},
        {pos: [14, 4, 3], state: "minecraft:deepslate_bricks"},
        {pos: [14, 4, 4], state: "minecraft:deepslate_bricks"},
        {pos: [14, 4, 5], state: "minecraft:deepslate_bricks"},
        {pos: [14, 4, 6], state: "minecraft:deepslate_bricks"},
        {pos: [14, 4, 7], state: "minecraft:deepslate_bricks"},
        {pos: [14, 4, 8], state: "minecraft:gravel"},
        {pos: [14, 4, 9], state: "minecraft:gravel"},
        {pos: [14, 4, 10], state: "minecraft:gravel"},
        {pos: [14, 4, 11], state: "minecraft:deepslate_bricks"},
        {pos: [14, 4, 12], state: "minecraft:gravel"},
        {pos: [14, 4, 13], state: "minecraft:gravel"},
        {pos: [14, 4, 14], state: "minecraft:piston{extended:false,facing:down}"},
        {pos: [14, 4, 15], state: "minecraft:gravel"},
        {pos: [14, 4, 16], state: "minecraft:gravel"},
        {pos: [14, 4, 17], state: "minecraft:deepslate_bricks"},
        {pos: [14, 4, 18], state: "minecraft:gravel"},
        {pos: [14, 4, 19], state: "minecraft:gravel"},
        {pos: [14, 4, 20], state: "minecraft:gravel"},
        {pos: [14, 4, 21], state: "minecraft:deepslate_bricks"},
        {pos: [14, 4, 22], state: "minecraft:deepslate_bricks"},
        {pos: [14, 4, 23], state: "minecraft:deepslate_bricks"},
        {pos: [14, 4, 24], state: "minecraft:deepslate_bricks"},
        {pos: [14, 4, 25], state: "minecraft:deepslate_bricks"},
        {pos: [14, 4, 26], state: "minecraft:deepslate_bricks"},
        {pos: [14, 4, 27], state: "minecraft:deepslate_bricks"},
        {pos: [14, 4, 28], state: "minecraft:deepslate_bricks"},
        {pos: [15, 4, 0], state: "minecraft:deepslate_bricks"},
        {pos: [15, 4, 1], state: "minecraft:deepslate_bricks"},
        {pos: [15, 4, 2], state: "minecraft:deepslate_bricks"},
        {pos: [15, 4, 3], state: "minecraft:deepslate_bricks"},
        {pos: [15, 4, 4], state: "minecraft:deepslate_bricks"},
        {pos: [15, 4, 5], state: "minecraft:deepslate_bricks"},
        {pos: [15, 4, 6], state: "minecraft:deepslate_bricks"},
        {pos: [15, 4, 7], state: "minecraft:deepslate_bricks"},
        {pos: [15, 4, 8], state: "minecraft:gravel"},
        {pos: [15, 4, 9], state: "minecraft:gravel"},
        {pos: [15, 4, 10], state: "minecraft:gravel"},
        {pos: [15, 4, 11], state: "minecraft:deepslate_bricks"},
        {pos: [15, 4, 12], state: "minecraft:deepslate_bricks"},
        {pos: [15, 4, 13], state: "minecraft:deepslate_bricks"},
        {pos: [15, 4, 14], state: "minecraft:deepslate_bricks"},
        {pos: [15, 4, 15], state: "minecraft:deepslate_bricks"},
        {pos: [15, 4, 16], state: "minecraft:deepslate_bricks"},
        {pos: [15, 4, 17], state: "minecraft:deepslate_bricks"},
        {pos: [15, 4, 18], state: "minecraft:gravel"},
        {pos: [15, 4, 19], state: "minecraft:gravel"},
        {pos: [15, 4, 20], state: "minecraft:gravel"},
        {pos: [15, 4, 21], state: "minecraft:deepslate_bricks"},
        {pos: [15, 4, 22], state: "minecraft:deepslate_bricks"},
        {pos: [15, 4, 23], state: "minecraft:deepslate_bricks"},
        {pos: [15, 4, 24], state: "minecraft:deepslate_bricks"},
        {pos: [15, 4, 25], state: "minecraft:deepslate_bricks"},
        {pos: [15, 4, 26], state: "minecraft:deepslate_bricks"},
        {pos: [15, 4, 27], state: "minecraft:deepslate_bricks"},
        {pos: [15, 4, 28], state: "minecraft:deepslate_bricks"},
        {pos: [16, 4, 5], state: "minecraft:deepslate_bricks"},
        {pos: [16, 4, 6], state: "minecraft:deepslate_bricks"},
        {pos: [16, 4, 7], state: "minecraft:deepslate_bricks"},
        {pos: [16, 4, 8], state: "minecraft:gravel"},
        {pos: [16, 4, 9], state: "minecraft:gravel"},
        {pos: [16, 4, 10], state: "minecraft:gravel"},
        {pos: [16, 4, 11], state: "minecraft:gravel"},
        {pos: [16, 4, 12], state: "minecraft:gravel"},
        {pos: [16, 4, 13], state: "minecraft:gravel"},
        {pos: [16, 4, 14], state: "minecraft:gravel"},
        {pos: [16, 4, 15], state: "minecraft:gravel"},
        {pos: [16, 4, 16], state: "minecraft:gravel"},
        {pos: [16, 4, 17], state: "minecraft:gravel"},
        {pos: [16, 4, 18], state: "minecraft:gravel"},
        {pos: [16, 4, 19], state: "minecraft:gravel"},
        {pos: [16, 4, 20], state: "minecraft:gravel"},
        {pos: [16, 4, 21], state: "minecraft:deepslate_bricks"},
        {pos: [16, 4, 22], state: "minecraft:deepslate_bricks"},
        {pos: [16, 4, 23], state: "minecraft:deepslate_bricks"},
        {pos: [17, 4, 5], state: "minecraft:deepslate_bricks"},
        {pos: [17, 4, 6], state: "minecraft:deepslate_bricks"},
        {pos: [17, 4, 7], state: "minecraft:deepslate_bricks"},
        {pos: [17, 4, 8], state: "minecraft:gravel"},
        {pos: [17, 4, 9], state: "minecraft:gravel"},
        {pos: [17, 4, 10], state: "minecraft:gravel"},
        {pos: [17, 4, 11], state: "minecraft:gravel"},
        {pos: [17, 4, 12], state: "minecraft:gravel"},
        {pos: [17, 4, 13], state: "minecraft:gravel"},
        {pos: [17, 4, 14], state: "minecraft:gravel"},
        {pos: [17, 4, 15], state: "minecraft:gravel"},
        {pos: [17, 4, 16], state: "minecraft:gravel"},
        {pos: [17, 4, 17], state: "minecraft:gravel"},
        {pos: [17, 4, 18], state: "minecraft:gravel"},
        {pos: [17, 4, 19], state: "minecraft:gravel"},
        {pos: [17, 4, 20], state: "minecraft:gravel"},
        {pos: [17, 4, 21], state: "minecraft:deepslate_bricks"},
        {pos: [17, 4, 22], state: "minecraft:deepslate_bricks"},
        {pos: [17, 4, 23], state: "minecraft:deepslate_bricks"},
        {pos: [18, 4, 5], state: "minecraft:deepslate_bricks"},
        {pos: [18, 4, 6], state: "minecraft:redstone_wire{east:side,north:none,power:0,south:none,west:up}"},
        {pos: [18, 4, 7], state: "minecraft:deepslate_bricks"},
        {pos: [18, 4, 8], state: "minecraft:gravel"},
        {pos: [18, 4, 9], state: "minecraft:gravel"},
        {pos: [18, 4, 10], state: "minecraft:gravel"},
        {pos: [18, 4, 11], state: "minecraft:gravel"},
        {pos: [18, 4, 12], state: "minecraft:gravel"},
        {pos: [18, 4, 13], state: "minecraft:gravel"},
        {pos: [18, 4, 14], state: "minecraft:gravel"},
        {pos: [18, 4, 15], state: "minecraft:gravel"},
        {pos: [18, 4, 16], state: "minecraft:gravel"},
        {pos: [18, 4, 17], state: "minecraft:gravel"},
        {pos: [18, 4, 18], state: "minecraft:gravel"},
        {pos: [18, 4, 19], state: "minecraft:gravel"},
        {pos: [18, 4, 20], state: "minecraft:gravel"},
        {pos: [18, 4, 21], state: "minecraft:deepslate_bricks"},
        {pos: [18, 4, 22], state: "minecraft:redstone_wire{east:side,north:none,power:0,south:none,west:up}"},
        {pos: [18, 4, 23], state: "minecraft:deepslate_bricks"},
        {pos: [19, 4, 5], state: "minecraft:deepslate_bricks"},
        {pos: [19, 4, 7], state: "minecraft:deepslate_bricks"},
        {pos: [19, 4, 8], state: "minecraft:deepslate_bricks"},
        {pos: [19, 4, 9], state: "minecraft:deepslate_bricks"},
        {pos: [19, 4, 10], state: "minecraft:gravel"},
        {pos: [19, 4, 11], state: "minecraft:gravel"},
        {pos: [19, 4, 12], state: "minecraft:gravel"},
        {pos: [19, 4, 13], state: "minecraft:gravel"},
        {pos: [19, 4, 14], state: "minecraft:gravel"},
        {pos: [19, 4, 15], state: "minecraft:gravel"},
        {pos: [19, 4, 16], state: "minecraft:gravel"},
        {pos: [19, 4, 17], state: "minecraft:gravel"},
        {pos: [19, 4, 18], state: "minecraft:gravel"},
        {pos: [19, 4, 19], state: "minecraft:deepslate_bricks"},
        {pos: [19, 4, 20], state: "minecraft:deepslate_bricks"},
        {pos: [19, 4, 21], state: "minecraft:deepslate_bricks"},
        {pos: [19, 4, 22], state: "minecraft:cave_air"},
        {pos: [19, 4, 23], state: "minecraft:deepslate_bricks"},
        {pos: [20, 4, 5], state: "minecraft:deepslate_bricks"},
        {pos: [20, 4, 6], state: "minecraft:deepslate_bricks"},
        {pos: [20, 4, 7], state: "minecraft:deepslate_bricks"},
        {pos: [20, 4, 8], state: "minecraft:deepslate_bricks"},
        {pos: [20, 4, 9], state: "minecraft:gravel"},
        {pos: [20, 4, 10], state: "minecraft:gravel"},
        {pos: [20, 4, 11], state: "minecraft:gravel"},
        {pos: [20, 4, 12], state: "minecraft:gravel"},
        {pos: [20, 4, 13], state: "minecraft:gravel"},
        {pos: [20, 4, 14], state: "minecraft:gravel"},
        {pos: [20, 4, 15], state: "minecraft:gravel"},
        {pos: [20, 4, 16], state: "minecraft:gravel"},
        {pos: [20, 4, 17], state: "minecraft:gravel"},
        {pos: [20, 4, 18], state: "minecraft:gravel"},
        {pos: [20, 4, 19], state: "minecraft:gravel"},
        {pos: [20, 4, 20], state: "minecraft:deepslate_bricks"},
        {pos: [20, 4, 21], state: "minecraft:deepslate_bricks"},
        {pos: [20, 4, 22], state: "minecraft:deepslate_bricks"},
        {pos: [20, 4, 23], state: "minecraft:deepslate_bricks"},
        {pos: [21, 4, 5], state: "minecraft:deepslate_bricks"},
        {pos: [21, 4, 6], state: "minecraft:deepslate_bricks"},
        {pos: [21, 4, 7], state: "minecraft:deepslate_bricks"},
        {pos: [21, 4, 8], state: "minecraft:deepslate_bricks"},
        {pos: [21, 4, 9], state: "minecraft:deepslate_bricks"},
        {pos: [21, 4, 10], state: "minecraft:gravel"},
        {pos: [21, 4, 11], state: "minecraft:gravel"},
        {pos: [21, 4, 12], state: "minecraft:gravel"},
        {pos: [21, 4, 13], state: "minecraft:gravel"},
        {pos: [21, 4, 14], state: "minecraft:gravel"},
        {pos: [21, 4, 15], state: "minecraft:gravel"},
        {pos: [21, 4, 16], state: "minecraft:gravel"},
        {pos: [21, 4, 17], state: "minecraft:gravel"},
        {pos: [21, 4, 18], state: "minecraft:gravel"},
        {pos: [21, 4, 19], state: "minecraft:deepslate_bricks"},
        {pos: [21, 4, 20], state: "minecraft:deepslate_bricks"},
        {pos: [21, 4, 21], state: "minecraft:deepslate_bricks"},
        {pos: [21, 4, 22], state: "minecraft:deepslate_bricks"},
        {pos: [22, 4, 5], state: "minecraft:deepslate_bricks"},
        {pos: [22, 4, 6], state: "minecraft:deepslate_bricks"},
        {pos: [22, 4, 7], state: "minecraft:deepslate_bricks"},
        {pos: [22, 4, 8], state: "minecraft:deepslate_bricks"},
        {pos: [22, 4, 9], state: "minecraft:deepslate_bricks"},
        {pos: [22, 4, 10], state: "minecraft:deepslate_bricks"},
        {pos: [22, 4, 11], state: "minecraft:deepslate_bricks"},
        {pos: [22, 4, 12], state: "minecraft:deepslate_bricks"},
        {pos: [22, 4, 13], state: "minecraft:gravel"},
        {pos: [22, 4, 14], state: "minecraft:gravel"},
        {pos: [22, 4, 15], state: "minecraft:gravel"},
        {pos: [22, 4, 16], state: "minecraft:deepslate_bricks"},
        {pos: [22, 4, 17], state: "minecraft:deepslate_bricks"},
        {pos: [22, 4, 18], state: "minecraft:deepslate_bricks"},
        {pos: [22, 4, 19], state: "minecraft:deepslate_bricks"},
        {pos: [22, 4, 20], state: "minecraft:deepslate_bricks"},
        {pos: [23, 4, 11], state: "minecraft:deepslate_bricks"},
        {pos: [23, 4, 12], state: "minecraft:gravel"},
        {pos: [23, 4, 13], state: "minecraft:gravel"},
        {pos: [23, 4, 14], state: "minecraft:gravel"},
        {pos: [23, 4, 15], state: "minecraft:gravel"},
        {pos: [23, 4, 16], state: "minecraft:gravel"},
        {pos: [23, 4, 17], state: "minecraft:deepslate_bricks"},
        {pos: [24, 4, 11], state: "minecraft:deepslate_bricks"},
        {pos: [24, 4, 12], state: "minecraft:deepslate_bricks"},
        {pos: [24, 4, 13], state: "minecraft:gravel"},
        {pos: [24, 4, 14], state: "minecraft:gravel"},
        {pos: [24, 4, 15], state: "minecraft:gravel"},
        {pos: [24, 4, 16], state: "minecraft:deepslate_bricks"},
        {pos: [24, 4, 17], state: "minecraft:deepslate_bricks"},
        {pos: [0, 5, 7], state: "minecraft:deepslate_bricks"},
        {pos: [0, 5, 8], state: "minecraft:deepslate_bricks"},
        {pos: [0, 5, 9], state: "minecraft:deepslate_bricks"},
        {pos: [0, 5, 10], state: "minecraft:deepslate_bricks"},
        {pos: [0, 5, 11], state: "minecraft:deepslate_bricks"},
        {pos: [0, 5, 12], state: "minecraft:deepslate_bricks"},
        {pos: [0, 5, 13], state: "minecraft:candle{candles:4,lit:false,waterlogged:false}"},
        {pos: [0, 5, 14], state: "minecraft:jigsaw{orientation:west_up}", nbt: {final_state: "minecraft:cave_air", id: "minecraft:jigsaw", joint: "rollable", name: "trailiertales:corridor", placement_priority: 0, pool: "trailiertales:catacombs/corridor_connector", selection_priority: 0, target: "trailiertales:corridor"}},
        {pos: [0, 5, 15], state: "minecraft:candle{candles:4,lit:false,waterlogged:false}"},
        {pos: [0, 5, 16], state: "minecraft:deepslate_bricks"},
        {pos: [0, 5, 17], state: "minecraft:deepslate_bricks"},
        {pos: [0, 5, 18], state: "minecraft:deepslate_bricks"},
        {pos: [0, 5, 19], state: "minecraft:deepslate_bricks"},
        {pos: [0, 5, 20], state: "minecraft:deepslate_bricks"},
        {pos: [0, 5, 21], state: "minecraft:deepslate_bricks"},
        {pos: [1, 5, 7], state: "minecraft:deepslate_bricks"},
        {pos: [1, 5, 8], state: "minecraft:deepslate_bricks"},
        {pos: [1, 5, 9], state: "minecraft:deepslate_bricks"},
        {pos: [1, 5, 10], state: "minecraft:deepslate_bricks"},
        {pos: [1, 5, 11], state: "minecraft:deepslate_bricks"},
        {pos: [1, 5, 12], state: "minecraft:deepslate_brick_stairs{facing:north,half:top,shape:straight,waterlogged:false}"},
        {pos: [1, 5, 13], state: "minecraft:candle{candles:4,lit:false,waterlogged:false}"},
        {pos: [1, 5, 14], state: "minecraft:cave_air"},
        {pos: [1, 5, 15], state: "minecraft:candle{candles:4,lit:false,waterlogged:false}"},
        {pos: [1, 5, 16], state: "minecraft:deepslate_brick_stairs{facing:south,half:top,shape:straight,waterlogged:false}"},
        {pos: [1, 5, 17], state: "minecraft:deepslate_bricks"},
        {pos: [1, 5, 18], state: "minecraft:deepslate_bricks"},
        {pos: [1, 5, 19], state: "minecraft:deepslate_bricks"},
        {pos: [1, 5, 20], state: "minecraft:deepslate_bricks"},
        {pos: [1, 5, 21], state: "minecraft:deepslate_bricks"},
        {pos: [2, 5, 7], state: "minecraft:deepslate_bricks"},
        {pos: [2, 5, 8], state: "minecraft:deepslate_bricks"},
        {pos: [2, 5, 9], state: "minecraft:deepslate_bricks"},
        {pos: [2, 5, 10], state: "minecraft:deepslate_bricks"},
        {pos: [2, 5, 11], state: "minecraft:deepslate_bricks"},
        {pos: [2, 5, 12], state: "minecraft:deepslate_bricks"},
        {pos: [2, 5, 13], state: "minecraft:candle{candles:4,lit:false,waterlogged:false}"},
        {pos: [2, 5, 14], state: "minecraft:cave_air"},
        {pos: [2, 5, 15], state: "minecraft:decorated_pot{cracked:false,facing:west,waterlogged:false}", nbt: {id: "minecraft:decorated_pot"}},
        {pos: [2, 5, 16], state: "minecraft:deepslate_bricks"},
        {pos: [2, 5, 17], state: "minecraft:deepslate_bricks"},
        {pos: [2, 5, 18], state: "minecraft:deepslate_bricks"},
        {pos: [2, 5, 19], state: "minecraft:deepslate_bricks"},
        {pos: [2, 5, 20], state: "minecraft:deepslate_bricks"},
        {pos: [2, 5, 21], state: "minecraft:deepslate_bricks"},
        {pos: [3, 5, 0], state: "minecraft:deepslate_bricks"},
        {pos: [3, 5, 1], state: "minecraft:deepslate_bricks"},
        {pos: [3, 5, 2], state: "minecraft:deepslate_bricks"},
        {pos: [3, 5, 3], state: "minecraft:deepslate_bricks"},
        {pos: [3, 5, 4], state: "minecraft:deepslate_bricks"},
        {pos: [3, 5, 5], state: "minecraft:deepslate_bricks"},
        {pos: [3, 5, 6], state: "minecraft:deepslate_bricks"},
        {pos: [3, 5, 7], state: "minecraft:deepslate_bricks"},
        {pos: [3, 5, 8], state: "minecraft:candle{candles:4,lit:false,waterlogged:false}"},
        {pos: [3, 5, 9], state: "minecraft:deepslate_brick_stairs{facing:south,half:bottom,shape:straight,waterlogged:false}"},
        {pos: [3, 5, 10], state: "trailiertales:coffin{facing:west,part:head,state:inactive}", nbt: {id: "trailiertales:coffin"}},
        {pos: [3, 5, 11], state: "minecraft:deepslate_brick_stairs{facing:north,half:bottom,shape:straight,waterlogged:false}"},
        {pos: [3, 5, 12], state: "minecraft:candle{candles:4,lit:false,waterlogged:false}"},
        {pos: [3, 5, 13], state: "minecraft:cave_air"},
        {pos: [3, 5, 14], state: "minecraft:cave_air"},
        {pos: [3, 5, 15], state: "minecraft:cave_air"},
        {pos: [3, 5, 16], state: "minecraft:skeleton_skull{powered:false,rotation:4}", nbt: {id: "minecraft:skull"}},
        {pos: [3, 5, 17], state: "minecraft:deepslate_brick_stairs{facing:south,half:bottom,shape:straight,waterlogged:false}"},
        {pos: [3, 5, 18], state: "trailiertales:coffin{facing:east,part:foot,state:inactive}", nbt: {id: "trailiertales:coffin", max_active_light_level: 7, uuid: "14006663-271f-4845-9434-65db1edd823c"}},
        {pos: [3, 5, 19], state: "minecraft:deepslate_brick_stairs{facing:north,half:bottom,shape:straight,waterlogged:false}"},
        {pos: [3, 5, 20], state: "minecraft:decorated_pot{cracked:false,facing:south,waterlogged:false}", nbt: {id: "minecraft:decorated_pot"}},
        {pos: [3, 5, 21], state: "minecraft:deepslate_bricks"},
        {pos: [3, 5, 22], state: "minecraft:deepslate_bricks"},
        {pos: [3, 5, 23], state: "minecraft:deepslate_bricks"},
        {pos: [3, 5, 24], state: "minecraft:deepslate_bricks"},
        {pos: [3, 5, 25], state: "minecraft:deepslate_bricks"},
        {pos: [3, 5, 26], state: "minecraft:deepslate_bricks"},
        {pos: [3, 5, 27], state: "minecraft:deepslate_bricks"},
        {pos: [3, 5, 28], state: "minecraft:deepslate_bricks"},
        {pos: [4, 5, 0], state: "minecraft:deepslate_bricks"},
        {pos: [4, 5, 1], state: "minecraft:deepslate_bricks"},
        {pos: [4, 5, 2], state: "minecraft:deepslate_bricks"},
        {pos: [4, 5, 3], state: "minecraft:deepslate_bricks"},
        {pos: [4, 5, 4], state: "minecraft:deepslate_bricks"},
        {pos: [4, 5, 5], state: "minecraft:deepslate_bricks"},
        {pos: [4, 5, 6], state: "minecraft:deepslate_bricks"},
        {pos: [4, 5, 7], state: "minecraft:deepslate_bricks"},
        {pos: [4, 5, 8], state: "minecraft:candle{candles:4,lit:false,waterlogged:false}"},
        {pos: [4, 5, 9], state: "minecraft:deepslate_brick_stairs{facing:south,half:bottom,shape:straight,waterlogged:false}"},
        {pos: [4, 5, 10], state: "trailiertales:coffin{facing:west,part:foot,state:inactive}", nbt: {id: "trailiertales:coffin", max_active_light_level: 7, uuid: "9aa5485a-39a4-49de-a771-c48f03ec129e"}},
        {pos: [4, 5, 11], state: "minecraft:deepslate_brick_stairs{facing:north,half:bottom,shape:straight,waterlogged:false}"},
        {pos: [4, 5, 12], state: "minecraft:candle{candles:4,lit:false,waterlogged:false}"},
        {pos: [4, 5, 13], state: "minecraft:cave_air"},
        {pos: [4, 5, 14], state: "minecraft:cave_air"},
        {pos: [4, 5, 15], state: "minecraft:cave_air"},
        {pos: [4, 5, 16], state: "minecraft:candle{candles:4,lit:false,waterlogged:false}"},
        {pos: [4, 5, 17], state: "minecraft:deepslate_brick_stairs{facing:south,half:bottom,shape:straight,waterlogged:false}"},
        {pos: [4, 5, 18], state: "trailiertales:coffin{facing:east,part:head,state:inactive}", nbt: {id: "trailiertales:coffin"}},
        {pos: [4, 5, 19], state: "minecraft:deepslate_brick_stairs{facing:north,half:bottom,shape:straight,waterlogged:false}"},
        {pos: [4, 5, 20], state: "minecraft:candle{candles:4,lit:false,waterlogged:false}"},
        {pos: [4, 5, 21], state: "minecraft:deepslate_bricks"},
        {pos: [4, 5, 22], state: "minecraft:deepslate_bricks"},
        {pos: [4, 5, 23], state: "minecraft:deepslate_bricks"},
        {pos: [4, 5, 24], state: "minecraft:deepslate_bricks"},
        {pos: [4, 5, 25], state: "minecraft:deepslate_bricks"},
        {pos: [4, 5, 26], state: "minecraft:deepslate_bricks"},
        {pos: [4, 5, 27], state: "minecraft:deepslate_bricks"},
        {pos: [4, 5, 28], state: "minecraft:deepslate_bricks"},
        {pos: [5, 5, 0], state: "minecraft:deepslate_bricks"},
        {pos: [5, 5, 1], state: "minecraft:deepslate_bricks"},
        {pos: [5, 5, 2], state: "minecraft:deepslate_bricks"},
        {pos: [5, 5, 3], state: "minecraft:deepslate_bricks"},
        {pos: [5, 5, 4], state: "minecraft:deepslate_bricks"},
        {pos: [5, 5, 5], state: "minecraft:deepslate_bricks"},
        {pos: [5, 5, 6], state: "minecraft:deepslate_bricks"},
        {pos: [5, 5, 7], state: "minecraft:deepslate_brick_stairs{facing:north,half:bottom,shape:straight,waterlogged:false}"},
        {pos: [5, 5, 8], state: "minecraft:cave_air"},
        {pos: [5, 5, 9], state: "minecraft:candle{candles:4,lit:false,waterlogged:false}"},
        {pos: [5, 5, 10], state: "minecraft:candle{candles:4,lit:false,waterlogged:false}"},
        {pos: [5, 5, 11], state: "minecraft:candle{candles:4,lit:false,waterlogged:false}"},
        {pos: [5, 5, 12], state: "minecraft:cave_air"},
        {pos: [5, 5, 13], state: "minecraft:cave_air"},
        {pos: [5, 5, 14], state: "minecraft:candle{candles:4,lit:false,waterlogged:false}"},
        {pos: [5, 5, 15], state: "minecraft:cave_air"},
        {pos: [5, 5, 16], state: "minecraft:cave_air"},
        {pos: [5, 5, 17], state: "minecraft:candle{candles:4,lit:false,waterlogged:false}"},
        {pos: [5, 5, 18], state: "minecraft:candle{candles:4,lit:false,waterlogged:false}"},
        {pos: [5, 5, 19], state: "minecraft:candle{candles:4,lit:false,waterlogged:false}"},
        {pos: [5, 5, 20], state: "minecraft:cave_air"},
        {pos: [5, 5, 21], state: "minecraft:deepslate_brick_stairs{facing:south,half:bottom,shape:straight,waterlogged:false}"},
        {pos: [5, 5, 22], state: "minecraft:deepslate_bricks"},
        {pos: [5, 5, 23], state: "minecraft:deepslate_bricks"},
        {pos: [5, 5, 24], state: "minecraft:deepslate_bricks"},
        {pos: [5, 5, 25], state: "minecraft:deepslate_bricks"},
        {pos: [5, 5, 26], state: "minecraft:deepslate_bricks"},
        {pos: [5, 5, 27], state: "minecraft:deepslate_bricks"},
        {pos: [5, 5, 28], state: "minecraft:deepslate_bricks"},
        {pos: [6, 5, 0], state: "minecraft:deepslate_bricks"},
        {pos: [6, 5, 1], state: "minecraft:deepslate_bricks"},
        {pos: [6, 5, 2], state: "minecraft:deepslate_bricks"},
        {pos: [6, 5, 3], state: "minecraft:deepslate_bricks"},
        {pos: [6, 5, 4], state: "minecraft:deepslate_bricks"},
        {pos: [6, 5, 5], state: "minecraft:deepslate_bricks"},
        {pos: [6, 5, 6], state: "minecraft:deepslate_bricks"},
        {pos: [6, 5, 7], state: "minecraft:deepslate_brick_stairs{facing:north,half:bottom,shape:straight,waterlogged:false}"},
        {pos: [6, 5, 8], state: "minecraft:cave_air"},
        {pos: [6, 5, 9], state: "minecraft:cave_air"},
        {pos: [6, 5, 10], state: "minecraft:cave_air"},
        {pos: [6, 5, 11], state: "minecraft:cave_air"},
        {pos: [6, 5, 12], state: "minecraft:candle{candles:4,lit:false,waterlogged:false}"},
        {pos: [6, 5, 13], state: "minecraft:cave_air"},
        {pos: [6, 5, 14], state: "minecraft:cave_air"},
        {pos: [6, 5, 15], state: "minecraft:cave_air"},
        {pos: [6, 5, 16], state: "minecraft:cave_air"},
        {pos: [6, 5, 17], state: "minecraft:cave_air"},
        {pos: [6, 5, 18], state: "minecraft:cave_air"},
        {pos: [6, 5, 19], state: "minecraft:cave_air"},
        {pos: [6, 5, 20], state: "minecraft:cave_air"},
        {pos: [6, 5, 21], state: "minecraft:deepslate_brick_stairs{facing:south,half:bottom,shape:straight,waterlogged:false}"},
        {pos: [6, 5, 22], state: "minecraft:deepslate_bricks"},
        {pos: [6, 5, 23], state: "minecraft:deepslate_bricks"},
        {pos: [6, 5, 24], state: "minecraft:deepslate_bricks"},
        {pos: [6, 5, 25], state: "minecraft:deepslate_bricks"},
        {pos: [6, 5, 26], state: "minecraft:deepslate_bricks"},
        {pos: [6, 5, 27], state: "minecraft:deepslate_bricks"},
        {pos: [6, 5, 28], state: "minecraft:deepslate_bricks"},
        {pos: [7, 5, 0], state: "minecraft:deepslate_bricks"},
        {pos: [7, 5, 1], state: "minecraft:deepslate_bricks"},
        {pos: [7, 5, 2], state: "minecraft:deepslate_bricks"},
        {pos: [7, 5, 3], state: "minecraft:deepslate_bricks"},
        {pos: [7, 5, 4], state: "minecraft:deepslate_bricks"},
        {pos: [7, 5, 5], state: "minecraft:deepslate_bricks"},
        {pos: [7, 5, 6], state: "minecraft:deepslate_bricks"},
        {pos: [7, 5, 7], state: "minecraft:deepslate_brick_stairs{facing:north,half:bottom,shape:straight,waterlogged:false}"},
        {pos: [7, 5, 8], state: "minecraft:cave_air"},
        {pos: [7, 5, 9], state: "minecraft:cave_air"},
        {pos: [7, 5, 10], state: "minecraft:cave_air"},
        {pos: [7, 5, 11], state: "minecraft:skeleton_skull{powered:false,rotation:8}", nbt: {id: "minecraft:skull"}},
        {pos: [7, 5, 12], state: "minecraft:cave_air"},
        {pos: [7, 5, 13], state: "minecraft:cave_air"},
        {pos: [7, 5, 14], state: "minecraft:cave_air"},
        {pos: [7, 5, 15], state: "minecraft:cave_air"},
        {pos: [7, 5, 16], state: "minecraft:cave_air"},
        {pos: [7, 5, 17], state: "minecraft:cave_air"},
        {pos: [7, 5, 18], state: "minecraft:cave_air"},
        {pos: [7, 5, 19], state: "minecraft:cave_air"},
        {pos: [7, 5, 20], state: "minecraft:skeleton_skull{powered:false,rotation:0}", nbt: {id: "minecraft:skull"}},
        {pos: [7, 5, 21], state: "minecraft:deepslate_brick_stairs{facing:south,half:bottom,shape:straight,waterlogged:false}"},
        {pos: [7, 5, 22], state: "minecraft:deepslate_bricks"},
        {pos: [7, 5, 23], state: "minecraft:deepslate_bricks"},
