{
    DataVersion: 3953,
    size: [26, 16, 25],
    data: [
        {pos: [21, 0, 10], state: "minecraft:deepslate_bricks"},
        {pos: [21, 0, 11], state: "minecraft:deepslate_bricks"},
        {pos: [21, 0, 12], state: "minecraft:deepslate_bricks"},
        {pos: [21, 0, 13], state: "minecraft:deepslate_bricks"},
        {pos: [21, 0, 14], state: "minecraft:deepslate_bricks"},
        {pos: [22, 0, 10], state: "minecraft:deepslate_bricks"},
        {pos: [22, 0, 11], state: "minecraft:deepslate_bricks"},
        {pos: [22, 0, 12], state: "minecraft:deepslate_bricks"},
        {pos: [22, 0, 13], state: "minecraft:deepslate_bricks"},
        {pos: [22, 0, 14], state: "minecraft:deepslate_bricks"},
        {pos: [23, 0, 10], state: "minecraft:deepslate_bricks"},
        {pos: [23, 0, 11], state: "minecraft:deepslate_bricks"},
        {pos: [23, 0, 12], state: "minecraft:deepslate_bricks"},
        {pos: [23, 0, 13], state: "minecraft:deepslate_bricks"},
        {pos: [23, 0, 14], state: "minecraft:deepslate_bricks"},
        {pos: [24, 0, 10], state: "minecraft:deepslate_bricks"},
        {pos: [24, 0, 11], state: "minecraft:deepslate_bricks"},
        {pos: [24, 0, 12], state: "minecraft:deepslate_bricks"},
        {pos: [24, 0, 13], state: "minecraft:deepslate_bricks"},
        {pos: [24, 0, 14], state: "minecraft:deepslate_bricks"},
        {pos: [3, 1, 0], state: "minecraft:deepslate_bricks"},
        {pos: [3, 1, 1], state: "minecraft:deepslate_bricks"},
        {pos: [3, 1, 2], state: "minecraft:deepslate_bricks"},
        {pos: [3, 1, 3], state: "minecraft:deepslate_bricks"},
        {pos: [3, 1, 4], state: "minecraft:deepslate_bricks"},
        {pos: [3, 1, 21], state: "minecraft:deepslate_bricks"},
        {pos: [3, 1, 22], state: "minecraft:deepslate_bricks"},
        {pos: [3, 1, 23], state: "minecraft:deepslate_bricks"},
        {pos: [3, 1, 24], state: "minecraft:deepslate_bricks"},
        {pos: [4, 1, 0], state: "minecraft:deepslate_bricks"},
        {pos: [4, 1, 1], state: "minecraft:deepslate_bricks"},
        {pos: [4, 1, 2], state: "minecraft:deepslate_bricks"},
        {pos: [4, 1, 3], state: "minecraft:deepslate_bricks"},
        {pos: [4, 1, 4], state: "minecraft:deepslate_bricks"},
        {pos: [4, 1, 21], state: "minecraft:deepslate_bricks"},
        {pos: [4, 1, 22], state: "minecraft:deepslate_bricks"},
        {pos: [4, 1, 23], state: "minecraft:deepslate_bricks"},
        {pos: [4, 1, 24], state: "minecraft:deepslate_bricks"},
        {pos: [5, 1, 0], state: "minecraft:deepslate_bricks"},
        {pos: [5, 1, 1], state: "minecraft:deepslate_bricks"},
        {pos: [5, 1, 2], state: "minecraft:deepslate_bricks"},
        {pos: [5, 1, 3], state: "minecraft:deepslate_bricks"},
        {pos: [5, 1, 4], state: "minecraft:deepslate_bricks"},
        {pos: [5, 1, 21], state: "minecraft:deepslate_bricks"},
        {pos: [5, 1, 22], state: "minecraft:deepslate_bricks"},
        {pos: [5, 1, 23], state: "minecraft:deepslate_bricks"},
        {pos: [5, 1, 24], state: "minecraft:deepslate_bricks"},
        {pos: [6, 1, 0], state: "minecraft:deepslate_bricks"},
        {pos: [6, 1, 1], state: "minecraft:deepslate_bricks"},
        {pos: [6, 1, 2], state: "minecraft:deepslate_bricks"},
        {pos: [6, 1, 3], state: "minecraft:deepslate_bricks"},
        {pos: [6, 1, 4], state: "minecraft:deepslate_bricks"},
        {pos: [6, 1, 21], state: "minecraft:deepslate_bricks"},
        {pos: [6, 1, 22], state: "minecraft:deepslate_bricks"},
        {pos: [6, 1, 23], state: "minecraft:deepslate_bricks"},
        {pos: [6, 1, 24], state: "minecraft:deepslate_bricks"},
        {pos: [7, 1, 0], state: "minecraft:deepslate_bricks"},
        {pos: [7, 1, 1], state: "minecraft:deepslate_bricks"},
        {pos: [7, 1, 2], state: "minecraft:deepslate_bricks"},
        {pos: [7, 1, 3], state: "minecraft:deepslate_bricks"},
        {pos: [7, 1, 4], state: "minecraft:deepslate_bricks"},
        {pos: [7, 1, 21], state: "minecraft:deepslate_bricks"},
        {pos: [7, 1, 22], state: "minecraft:deepslate_bricks"},
        {pos: [7, 1, 23], state: "minecraft:deepslate_bricks"},
        {pos: [7, 1, 24], state: "minecraft:deepslate_bricks"},
        {pos: [8, 1, 0], state: "minecraft:deepslate_bricks"},
        {pos: [8, 1, 1], state: "minecraft:deepslate_bricks"},
        {pos: [8, 1, 2], state: "minecraft:deepslate_bricks"},
        {pos: [8, 1, 3], state: "minecraft:deepslate_bricks"},
        {pos: [8, 1, 4], state: "minecraft:deepslate_bricks"},
        {pos: [8, 1, 21], state: "minecraft:deepslate_bricks"},
        {pos: [8, 1, 22], state: "minecraft:deepslate_bricks"},
        {pos: [8, 1, 23], state: "minecraft:deepslate_bricks"},
        {pos: [8, 1, 24], state: "minecraft:deepslate_bricks"},
        {pos: [9, 1, 0], state: "minecraft:deepslate_bricks"},
        {pos: [9, 1, 1], state: "minecraft:deepslate_bricks"},
        {pos: [9, 1, 2], state: "minecraft:deepslate_bricks"},
        {pos: [9, 1, 3], state: "minecraft:deepslate_bricks"},
        {pos: [9, 1, 4], state: "minecraft:deepslate_bricks"},
        {pos: [9, 1, 21], state: "minecraft:deepslate_bricks"},
        {pos: [9, 1, 22], state: "minecraft:deepslate_bricks"},
        {pos: [9, 1, 23], state: "minecraft:deepslate_bricks"},
        {pos: [9, 1, 24], state: "minecraft:deepslate_bricks"},
        {pos: [10, 1, 0], state: "minecraft:deepslate_bricks"},
        {pos: [10, 1, 1], state: "minecraft:deepslate_bricks"},
        {pos: [10, 1, 2], state: "minecraft:deepslate_bricks"},
        {pos: [10, 1, 3], state: "minecraft:deepslate_bricks"},
        {pos: [10, 1, 4], state: "minecraft:deepslate_bricks"},
        {pos: [10, 1, 21], state: "minecraft:deepslate_bricks"},
        {pos: [10, 1, 22], state: "minecraft:deepslate_bricks"},
        {pos: [10, 1, 23], state: "minecraft:deepslate_bricks"},
        {pos: [10, 1, 24], state: "minecraft:deepslate_bricks"},
        {pos: [11, 1, 0], state: "minecraft:deepslate_bricks"},
        {pos: [11, 1, 1], state: "minecraft:deepslate_bricks"},
        {pos: [11, 1, 2], state: "minecraft:deepslate_bricks"},
        {pos: [11, 1, 3], state: "minecraft:deepslate_bricks"},
        {pos: [11, 1, 4], state: "minecraft:deepslate_bricks"},
        {pos: [11, 1, 21], state: "minecraft:deepslate_bricks"},
        {pos: [11, 1, 22], state: "minecraft:deepslate_bricks"},
        {pos: [11, 1, 23], state: "minecraft:deepslate_bricks"},
        {pos: [11, 1, 24], state: "minecraft:deepslate_bricks"},
        {pos: [12, 1, 0], state: "minecraft:deepslate_bricks"},
        {pos: [12, 1, 1], state: "minecraft:deepslate_bricks"},
        {pos: [12, 1, 2], state: "minecraft:deepslate_bricks"},
        {pos: [12, 1, 3], state: "minecraft:deepslate_bricks"},
        {pos: [12, 1, 4], state: "minecraft:deepslate_bricks"},
        {pos: [12, 1, 21], state: "minecraft:deepslate_bricks"},
        {pos: [12, 1, 22], state: "minecraft:deepslate_bricks"},
        {pos: [12, 1, 23], state: "minecraft:deepslate_bricks"},
        {pos: [12, 1, 24], state: "minecraft:deepslate_bricks"},
        {pos: [13, 1, 0], state: "minecraft:deepslate_bricks"},
        {pos: [13, 1, 1], state: "minecraft:deepslate_bricks"},
        {pos: [13, 1, 2], state: "minecraft:deepslate_bricks"},
        {pos: [13, 1, 3], state: "minecraft:deepslate_bricks"},
        {pos: [13, 1, 4], state: "minecraft:deepslate_bricks"},
        {pos: [13, 1, 21], state: "minecraft:deepslate_bricks"},
        {pos: [13, 1, 22], state: "minecraft:deepslate_bricks"},
        {pos: [13, 1, 23], state: "minecraft:deepslate_bricks"},
        {pos: [13, 1, 24], state: "minecraft:deepslate_bricks"},
        {pos: [14, 1, 0], state: "minecraft:deepslate_bricks"},
        {pos: [14, 1, 1], state: "minecraft:deepslate_bricks"},
        {pos: [14, 1, 2], state: "minecraft:deepslate_bricks"},
        {pos: [14, 1, 3], state: "minecraft:deepslate_bricks"},
        {pos: [14, 1, 4], state: "minecraft:deepslate_bricks"},
        {pos: [14, 1, 21], state: "minecraft:deepslate_bricks"},
        {pos: [14, 1, 22], state: "minecraft:deepslate_bricks"},
        {pos: [14, 1, 23], state: "minecraft:deepslate_bricks"},
        {pos: [14, 1, 24], state: "minecraft:deepslate_bricks"},
        {pos: [15, 1, 0], state: "minecraft:deepslate_bricks"},
        {pos: [15, 1, 1], state: "minecraft:deepslate_bricks"},
        {pos: [15, 1, 2], state: "minecraft:deepslate_bricks"},
        {pos: [15, 1, 3], state: "minecraft:deepslate_bricks"},
        {pos: [15, 1, 4], state: "minecraft:deepslate_bricks"},
        {pos: [15, 1, 10], state: "minecraft:deepslate_bricks"},
        {pos: [15, 1, 11], state: "minecraft:deepslate_bricks"},
        {pos: [15, 1, 12], state: "minecraft:deepslate_bricks"},
        {pos: [15, 1, 13], state: "minecraft:deepslate_bricks"},
        {pos: [15, 1, 14], state: "minecraft:deepslate_bricks"},
        {pos: [15, 1, 15], state: "minecraft:deepslate_bricks"},
        {pos: [15, 1, 16], state: "minecraft:deepslate_bricks"},
        {pos: [15, 1, 17], state: "minecraft:deepslate_bricks"},
        {pos: [15, 1, 18], state: "minecraft:deepslate_bricks"},
        {pos: [15, 1, 21], state: "minecraft:deepslate_bricks"},
        {pos: [15, 1, 22], state: "minecraft:deepslate_bricks"},
        {pos: [15, 1, 23], state: "minecraft:deepslate_bricks"},
        {pos: [15, 1, 24], state: "minecraft:deepslate_bricks"},
        {pos: [16, 1, 0], state: "minecraft:deepslate_bricks"},
        {pos: [16, 1, 1], state: "minecraft:deepslate_bricks"},
        {pos: [16, 1, 2], state: "minecraft:deepslate_bricks"},
        {pos: [16, 1, 3], state: "minecraft:deepslate_bricks"},
        {pos: [16, 1, 4], state: "minecraft:deepslate_bricks"},
        {pos: [16, 1, 10], state: "minecraft:deepslate_bricks"},
        {pos: [16, 1, 11], state: "minecraft:deepslate_bricks"},
        {pos: [16, 1, 12], state: "minecraft:deepslate_bricks"},
        {pos: [16, 1, 13], state: "minecraft:deepslate_bricks"},
        {pos: [16, 1, 14], state: "minecraft:deepslate_bricks"},
        {pos: [16, 1, 15], state: "minecraft:deepslate_bricks"},
        {pos: [16, 1, 16], state: "minecraft:deepslate_bricks"},
        {pos: [16, 1, 17], state: "minecraft:deepslate_bricks"},
        {pos: [16, 1, 18], state: "minecraft:deepslate_bricks"},
        {pos: [16, 1, 21], state: "minecraft:deepslate_bricks"},
        {pos: [16, 1, 22], state: "minecraft:deepslate_bricks"},
        {pos: [16, 1, 23], state: "minecraft:deepslate_bricks"},
        {pos: [16, 1, 24], state: "minecraft:deepslate_bricks"},
        {pos: [17, 1, 0], state: "minecraft:deepslate_bricks"},
        {pos: [17, 1, 1], state: "minecraft:deepslate_bricks"},
        {pos: [17, 1, 2], state: "minecraft:deepslate_bricks"},
        {pos: [17, 1, 3], state: "minecraft:deepslate_bricks"},
        {pos: [17, 1, 4], state: "minecraft:deepslate_bricks"},
        {pos: [17, 1, 10], state: "minecraft:deepslate_bricks"},
        {pos: [17, 1, 11], state: "minecraft:deepslate_bricks"},
        {pos: [17, 1, 12], state: "minecraft:deepslate_bricks"},
        {pos: [17, 1, 13], state: "minecraft:deepslate_bricks"},
        {pos: [17, 1, 14], state: "minecraft:deepslate_bricks"},
        {pos: [17, 1, 15], state: "minecraft:deepslate_bricks"},
        {pos: [17, 1, 16], state: "minecraft:deepslate_bricks"},
        {pos: [17, 1, 17], state: "minecraft:deepslate_bricks"},
        {pos: [17, 1, 18], state: "minecraft:deepslate_bricks"},
        {pos: [17, 1, 21], state: "minecraft:deepslate_bricks"},
        {pos: [17, 1, 22], state: "minecraft:deepslate_bricks"},
        {pos: [17, 1, 23], state: "minecraft:deepslate_bricks"},
        {pos: [17, 1, 24], state: "minecraft:deepslate_bricks"},
        {pos: [18, 1, 0], state: "minecraft:deepslate_bricks"},
        {pos: [18, 1, 1], state: "minecraft:deepslate_bricks"},
        {pos: [18, 1, 2], state: "minecraft:deepslate_bricks"},
        {pos: [18, 1, 3], state: "minecraft:deepslate_bricks"},
        {pos: [18, 1, 4], state: "minecraft:deepslate_bricks"},
        {pos: [18, 1, 10], state: "minecraft:deepslate_bricks"},
        {pos: [18, 1, 11], state: "minecraft:deepslate_bricks"},
        {pos: [18, 1, 12], state: "minecraft:deepslate_bricks"},
        {pos: [18, 1, 13], state: "minecraft:deepslate_bricks"},
        {pos: [18, 1, 14], state: "minecraft:deepslate_bricks"},
        {pos: [18, 1, 15], state: "minecraft:deepslate_bricks"},
        {pos: [18, 1, 16], state: "minecraft:deepslate_bricks"},
        {pos: [18, 1, 17], state: "minecraft:deepslate_bricks"},
        {pos: [18, 1, 18], state: "minecraft:deepslate_bricks"},
        {pos: [18, 1, 21], state: "minecraft:deepslate_bricks"},
        {pos: [18, 1, 22], state: "minecraft:deepslate_bricks"},
        {pos: [18, 1, 23], state: "minecraft:deepslate_bricks"},
        {pos: [18, 1, 24], state: "minecraft:deepslate_bricks"},
        {pos: [19, 1, 0], state: "minecraft:deepslate_bricks"},
        {pos: [19, 1, 1], state: "minecraft:deepslate_bricks"},
        {pos: [19, 1, 2], state: "minecraft:deepslate_bricks"},
        {pos: [19, 1, 3], state: "minecraft:deepslate_bricks"},
        {pos: [19, 1, 4], state: "minecraft:deepslate_bricks"},
        {pos: [19, 1, 10], state: "minecraft:deepslate_bricks"},
        {pos: [19, 1, 11], state: "minecraft:deepslate_bricks"},
        {pos: [19, 1, 12], state: "minecraft:deepslate_bricks"},
        {pos: [19, 1, 13], state: "minecraft:deepslate_bricks"},
        {pos: [19, 1, 14], state: "minecraft:deepslate_bricks"},
        {pos: [19, 1, 15], state: "minecraft:deepslate_bricks"},
        {pos: [19, 1, 16], state: "minecraft:deepslate_bricks"},
        {pos: [19, 1, 17], state: "minecraft:deepslate_bricks"},
        {pos: [19, 1, 18], state: "minecraft:deepslate_bricks"},
        {pos: [19, 1, 21], state: "minecraft:deepslate_bricks"},
        {pos: [19, 1, 22], state: "minecraft:deepslate_bricks"},
        {pos: [19, 1, 23], state: "minecraft:deepslate_bricks"},
        {pos: [19, 1, 24], state: "minecraft:deepslate_bricks"},
        {pos: [20, 1, 0], state: "minecraft:deepslate_bricks"},
        {pos: [20, 1, 1], state: "minecraft:deepslate_bricks"},
        {pos: [20, 1, 2], state: "minecraft:deepslate_bricks"},
        {pos: [20, 1, 3], state: "minecraft:deepslate_bricks"},
        {pos: [20, 1, 4], state: "minecraft:deepslate_bricks"},
        {pos: [20, 1, 10], state: "minecraft:deepslate_bricks"},
        {pos: [20, 1, 11], state: "minecraft:deepslate_bricks"},
        {pos: [20, 1, 12], state: "minecraft:deepslate_bricks"},
        {pos: [20, 1, 13], state: "minecraft:deepslate_bricks"},
        {pos: [20, 1, 14], state: "minecraft:deepslate_bricks"},
        {pos: [20, 1, 15], state: "minecraft:deepslate_bricks"},
        {pos: [20, 1, 16], state: "minecraft:deepslate_bricks"},
        {pos: [20, 1, 17], state: "minecraft:deepslate_bricks"},
        {pos: [20, 1, 18], state: "minecraft:deepslate_bricks"},
        {pos: [20, 1, 21], state: "minecraft:deepslate_bricks"},
        {pos: [20, 1, 22], state: "minecraft:deepslate_bricks"},
        {pos: [20, 1, 23], state: "minecraft:deepslate_bricks"},
        {pos: [20, 1, 24], state: "minecraft:deepslate_bricks"},
        {pos: [21, 1, 0], state: "minecraft:deepslate_bricks"},
        {pos: [21, 1, 1], state: "minecraft:deepslate_bricks"},
        {pos: [21, 1, 2], state: "minecraft:deepslate_bricks"},
        {pos: [21, 1, 3], state: "minecraft:deepslate_bricks"},
        {pos: [21, 1, 4], state: "minecraft:deepslate_bricks"},
        {pos: [21, 1, 10], state: "minecraft:deepslate_bricks"},
        {pos: [21, 1, 11], state: "minecraft:deepslate_bricks"},
        {pos: [21, 1, 12], state: "minecraft:deepslate_bricks"},
        {pos: [21, 1, 13], state: "minecraft:deepslate_bricks"},
        {pos: [21, 1, 14], state: "minecraft:deepslate_bricks"},
        {pos: [21, 1, 15], state: "minecraft:deepslate_bricks"},
        {pos: [21, 1, 16], state: "minecraft:deepslate_bricks"},
        {pos: [21, 1, 17], state: "minecraft:deepslate_bricks"},
        {pos: [21, 1, 18], state: "minecraft:deepslate_bricks"},
        {pos: [21, 1, 21], state: "minecraft:deepslate_bricks"},
        {pos: [21, 1, 22], state: "minecraft:deepslate_bricks"},
        {pos: [21, 1, 23], state: "minecraft:deepslate_bricks"},
        {pos: [21, 1, 24], state: "minecraft:deepslate_bricks"},
        {pos: [22, 1, 0], state: "minecraft:deepslate_bricks"},
        {pos: [22, 1, 1], state: "minecraft:deepslate_bricks"},
        {pos: [22, 1, 2], state: "minecraft:deepslate_bricks"},
        {pos: [22, 1, 3], state: "minecraft:deepslate_bricks"},
        {pos: [22, 1, 4], state: "minecraft:deepslate_bricks"},
        {pos: [22, 1, 10], state: "minecraft:deepslate_bricks"},
        {pos: [22, 1, 11], state: "minecraft:cave_air"},
        {pos: [22, 1, 12], state: "minecraft:cave_air"},
        {pos: [22, 1, 13], state: "minecraft:cave_air"},
        {pos: [22, 1, 14], state: "minecraft:deepslate_bricks"},
        {pos: [22, 1, 15], state: "minecraft:deepslate_bricks"},
        {pos: [22, 1, 16], state: "minecraft:deepslate_bricks"},
        {pos: [22, 1, 17], state: "minecraft:deepslate_bricks"},
        {pos: [22, 1, 18], state: "minecraft:deepslate_bricks"},
        {pos: [22, 1, 21], state: "minecraft:deepslate_bricks"},
        {pos: [22, 1, 22], state: "minecraft:deepslate_bricks"},
        {pos: [22, 1, 23], state: "minecraft:deepslate_bricks"},
        {pos: [22, 1, 24], state: "minecraft:deepslate_bricks"},
        {pos: [23, 1, 0], state: "minecraft:deepslate_bricks"},
        {pos: [23, 1, 1], state: "minecraft:deepslate_bricks"},
        {pos: [23, 1, 2], state: "minecraft:deepslate_bricks"},
        {pos: [23, 1, 3], state: "minecraft:deepslate_bricks"},
        {pos: [23, 1, 4], state: "minecraft:deepslate_bricks"},
        {pos: [23, 1, 10], state: "minecraft:deepslate_bricks"},
        {pos: [23, 1, 11], state: "minecraft:deepslate_bricks"},
        {pos: [23, 1, 12], state: "minecraft:deepslate_bricks"},
        {pos: [23, 1, 13], state: "minecraft:deepslate_bricks"},
        {pos: [23, 1, 14], state: "minecraft:deepslate_bricks"},
        {pos: [23, 1, 15], state: "minecraft:deepslate_bricks"},
        {pos: [23, 1, 16], state: "minecraft:deepslate_bricks"},
        {pos: [23, 1, 17], state: "minecraft:deepslate_bricks"},
        {pos: [23, 1, 18], state: "minecraft:deepslate_bricks"},
        {pos: [23, 1, 21], state: "minecraft:deepslate_bricks"},
        {pos: [23, 1, 22], state: "minecraft:deepslate_bricks"},
        {pos: [23, 1, 23], state: "minecraft:deepslate_bricks"},
        {pos: [23, 1, 24], state: "minecraft:deepslate_bricks"},
        {pos: [24, 1, 10], state: "minecraft:deepslate_bricks"},
        {pos: [24, 1, 11], state: "minecraft:deepslate_bricks"},
        {pos: [24, 1, 12], state: "minecraft:deepslate_bricks"},
        {pos: [24, 1, 13], state: "minecraft:deepslate_bricks"},
        {pos: [24, 1, 14], state: "minecraft:deepslate_bricks"},
        {pos: [24, 1, 15], state: "minecraft:deepslate_bricks"},
        {pos: [24, 1, 16], state: "minecraft:deepslate_bricks"},
        {pos: [24, 1, 17], state: "minecraft:deepslate_bricks"},
        {pos: [24, 1, 18], state: "minecraft:deepslate_bricks"},
        {pos: [3, 2, 0], state: "minecraft:deepslate_bricks"},
        {pos: [3, 2, 1], state: "minecraft:deepslate_bricks"},
        {pos: [3, 2, 2], state: "minecraft:deepslate_bricks"},
        {pos: [3, 2, 3], state: "minecraft:deepslate_bricks"},
        {pos: [3, 2, 4], state: "minecraft:deepslate_bricks"},
        {pos: [3, 2, 21], state: "minecraft:deepslate_bricks"},
        {pos: [3, 2, 22], state: "minecraft:deepslate_bricks"},
        {pos: [3, 2, 23], state: "minecraft:deepslate_bricks"},
        {pos: [3, 2, 24], state: "minecraft:deepslate_bricks"},
        {pos: [4, 2, 0], state: "minecraft:deepslate_bricks"},
        {pos: [4, 2, 1], state: "minecraft:redstone_wire{east:side,north:none,power:13,south:side,west:none}"},
        {pos: [4, 2, 2], state: "minecraft:repeater{delay:1,facing:north,locked:false,powered:true}"},
        {pos: [4, 2, 3], state: "minecraft:deepslate_bricks"},
        {pos: [4, 2, 4], state: "minecraft:deepslate_bricks"},
        {pos: [4, 2, 21], state: "minecraft:deepslate_bricks"},
        {pos: [4, 2, 22], state: "minecraft:repeater{delay:1,facing:south,locked:false,powered:true}"},
        {pos: [4, 2, 23], state: "minecraft:redstone_wire{east:side,north:side,power:13,south:none,west:none}"},
        {pos: [4, 2, 24], state: "minecraft:deepslate_bricks"},
        {pos: [5, 2, 0], state: "minecraft:deepslate_bricks"},
        {pos: [5, 2, 1], state: "minecraft:redstone_wire{east:side,north:none,power:14,south:side,west:side}"},
        {pos: [5, 2, 2], state: "minecraft:repeater{delay:1,facing:north,locked:false,powered:true}"},
        {pos: [5, 2, 3], state: "minecraft:deepslate_bricks"},
        {pos: [5, 2, 4], state: "minecraft:deepslate_bricks"},
        {pos: [5, 2, 21], state: "minecraft:deepslate_bricks"},
        {pos: [5, 2, 22], state: "minecraft:repeater{delay:1,facing:south,locked:false,powered:true}"},
        {pos: [5, 2, 23], state: "minecraft:redstone_wire{east:side,north:side,power:14,south:none,west:side}"},
        {pos: [5, 2, 24], state: "minecraft:deepslate_bricks"},
        {pos: [6, 2, 0], state: "minecraft:deepslate_bricks"},
        {pos: [6, 2, 1], state: "minecraft:redstone_wire{east:side,north:none,power:15,south:side,west:side}"},
        {pos: [6, 2, 2], state: "minecraft:repeater{delay:1,facing:north,locked:false,powered:true}"},
        {pos: [6, 2, 3], state: "minecraft:deepslate_bricks"},
        {pos: [6, 2, 4], state: "minecraft:deepslate_bricks"},
        {pos: [6, 2, 21], state: "minecraft:deepslate_bricks"},
        {pos: [6, 2, 22], state: "minecraft:repeater{delay:1,facing:south,locked:false,powered:true}"},
        {pos: [6, 2, 23], state: "minecraft:redstone_wire{east:side,north:side,power:15,south:none,west:side}"},
        {pos: [6, 2, 24], state: "minecraft:deepslate_bricks"},
        {pos: [7, 2, 0], state: "minecraft:deepslate_bricks"},
        {pos: [7, 2, 1], state: "minecraft:repeater{delay:1,facing:east,locked:false,powered:true}"},
        {pos: [7, 2, 2], state: "minecraft:cave_air"},
        {pos: [7, 2, 3], state: "minecraft:cave_air"},
        {pos: [7, 2, 4], state: "minecraft:deepslate_bricks"},
        {pos: [7, 2, 21], state: "minecraft:deepslate_bricks"},
        {pos: [7, 2, 22], state: "minecraft:deepslate_bricks"},
        {pos: [7, 2, 23], state: "minecraft:repeater{delay:1,facing:east,locked:false,powered:true}"},
        {pos: [7, 2, 24], state: "minecraft:deepslate_bricks"},
        {pos: [8, 2, 0], state: "minecraft:deepslate_bricks"},
        {pos: [8, 2, 1], state: "minecraft:redstone_wire{east:side,north:none,power:13,south:side,west:side}"},
        {pos: [8, 2, 2], state: "minecraft:repeater{delay:1,facing:north,locked:false,powered:true}"},
        {pos: [8, 2, 3], state: "minecraft:deepslate_bricks"},
        {pos: [8, 2, 4], state: "minecraft:deepslate_bricks"},
        {pos: [8, 2, 21], state: "minecraft:deepslate_bricks"},
        {pos: [8, 2, 22], state: "minecraft:repeater{delay:1,facing:south,locked:false,powered:true}"},
        {pos: [8, 2, 23], state: "minecraft:redstone_wire{east:side,north:side,power:13,south:none,west:side}"},
        {pos: [8, 2, 24], state: "minecraft:deepslate_bricks"},
        {pos: [9, 2, 0], state: "minecraft:deepslate_bricks"},
        {pos: [9, 2, 1], state: "minecraft:redstone_wire{east:side,north:none,power:14,south:side,west:side}"},
        {pos: [9, 2, 2], state: "minecraft:repeater{delay:1,facing:north,locked:false,powered:true}"},
        {pos: [9, 2, 3], state: "minecraft:deepslate_bricks"},
        {pos: [9, 2, 4], state: "minecraft:deepslate_bricks"},
        {pos: [9, 2, 21], state: "minecraft:deepslate_bricks"},
        {pos: [9, 2, 22], state: "minecraft:repeater{delay:1,facing:south,locked:false,powered:true}"},
        {pos: [9, 2, 23], state: "minecraft:redstone_wire{east:side,north:side,power:14,south:none,west:side}"},
        {pos: [9, 2, 24], state: "minecraft:deepslate_bricks"},
        {pos: [10, 2, 0], state: "minecraft:deepslate_bricks"},
        {pos: [10, 2, 1], state: "minecraft:redstone_wire{east:side,north:none,power:15,south:side,west:side}"},
        {pos: [10, 2, 2], state: "minecraft:repeater{delay:1,facing:north,locked:false,powered:true}"},
        {pos: [10, 2, 3], state: "minecraft:deepslate_bricks"},
        {pos: [10, 2, 4], state: "minecraft:deepslate_bricks"},
        {pos: [10, 2, 21], state: "minecraft:deepslate_bricks"},
        {pos: [10, 2, 22], state: "minecraft:repeater{delay:1,facing:south,locked:false,powered:true}"},
        {pos: [10, 2, 23], state: "minecraft:redstone_wire{east:side,north:side,power:15,south:none,west:side}"},
        {pos: [10, 2, 24], state: "minecraft:deepslate_bricks"},
        {pos: [11, 2, 0], state: "minecraft:deepslate_bricks"},
        {pos: [11, 2, 1], state: "minecraft:repeater{delay:1,facing:east,locked:false,powered:true}"},
        {pos: [11, 2, 2], state: "minecraft:cave_air"},
        {pos: [11, 2, 3], state: "minecraft:cave_air"},
        {pos: [11, 2, 4], state: "minecraft:deepslate_bricks"},
        {pos: [11, 2, 21], state: "minecraft:deepslate_bricks"},
        {pos: [11, 2, 22], state: "minecraft:deepslate_bricks"},
        {pos: [11, 2, 23], state: "minecraft:repeater{delay:1,facing:east,locked:false,powered:true}"},
        {pos: [11, 2, 24], state: "minecraft:deepslate_bricks"},
        {pos: [12, 2, 0], state: "minecraft:deepslate_bricks"},
        {pos: [12, 2, 1], state: "minecraft:redstone_wire{east:side,north:none,power:13,south:side,west:side}"},
        {pos: [12, 2, 2], state: "minecraft:repeater{delay:1,facing:north,locked:false,powered:true}"},
        {pos: [12, 2, 3], state: "minecraft:deepslate_bricks"},
        {pos: [12, 2, 4], state: "minecraft:deepslate_bricks"},
        {pos: [12, 2, 21], state: "minecraft:deepslate_bricks"},
        {pos: [12, 2, 22], state: "minecraft:repeater{delay:1,facing:south,locked:false,powered:true}"},
        {pos: [12, 2, 23], state: "minecraft:redstone_wire{east:side,north:side,power:13,south:none,west:side}"},
        {pos: [12, 2, 24], state: "minecraft:deepslate_bricks"},
        {pos: [13, 2, 0], state: "minecraft:deepslate_bricks"},
        {pos: [13, 2, 1], state: "minecraft:redstone_wire{east:side,north:none,power:14,south:side,west:side}"},
        {pos: [13, 2, 2], state: "minecraft:repeater{delay:1,facing:north,locked:false,powered:true}"},
        {pos: [13, 2, 3], state: "minecraft:deepslate_bricks"},
        {pos: [13, 2, 4], state: "minecraft:deepslate_bricks"},
        {pos: [13, 2, 21], state: "minecraft:deepslate_bricks"},
        {pos: [13, 2, 22], state: "minecraft:repeater{delay:1,facing:south,locked:false,powered:true}"},
        {pos: [13, 2, 23], state: "minecraft:redstone_wire{east:side,north:side,power:14,south:none,west:side}"},
        {pos: [13, 2, 24], state: "minecraft:deepslate_bricks"},
        {pos: [14, 2, 0], state: "minecraft:deepslate_bricks"},
        {pos: [14, 2, 1], state: "minecraft:redstone_wire{east:side,north:none,power:15,south:side,west:side}"},
        {pos: [14, 2, 2], state: "minecraft:repeater{delay:1,facing:north,locked:false,powered:true}"},
        {pos: [14, 2, 3], state: "minecraft:deepslate_bricks"},
        {pos: [14, 2, 4], state: "minecraft:deepslate_bricks"},
        {pos: [14, 2, 21], state: "minecraft:deepslate_bricks"},
        {pos: [14, 2, 22], state: "minecraft:repeater{delay:1,facing:south,locked:false,powered:true}"},
        {pos: [14, 2, 23], state: "minecraft:redstone_wire{east:side,north:side,power:15,south:none,west:side}"},
        {pos: [14, 2, 24], state: "minecraft:deepslate_bricks"},
        {pos: [15, 2, 0], state: "minecraft:deepslate_bricks"},
        {pos: [15, 2, 1], state: "minecraft:repeater{delay:2,facing:east,locked:false,powered:true}"},
        {pos: [15, 2, 2], state: "minecraft:cave_air"},
        {pos: [15, 2, 3], state: "minecraft:cave_air"},
        {pos: [15, 2, 4], state: "minecraft:deepslate_bricks"},
        {pos: [15, 2, 10], state: "minecraft:deepslate_bricks"},
        {pos: [15, 2, 11], state: "minecraft:deepslate_bricks"},
        {pos: [15, 2, 12], state: "minecraft:deepslate_bricks"},
        {pos: [15, 2, 13], state: "minecraft:deepslate_bricks"},
        {pos: [15, 2, 14], state: "minecraft:deepslate_bricks"},
        {pos: [15, 2, 15], state: "minecraft:deepslate_bricks"},
        {pos: [15, 2, 16], state: "minecraft:deepslate_bricks"},
        {pos: [15, 2, 17], state: "minecraft:deepslate_bricks"},
        {pos: [15, 2, 18], state: "minecraft:deepslate_bricks"},
        {pos: [15, 2, 21], state: "minecraft:deepslate_bricks"},
        {pos: [15, 2, 22], state: "minecraft:deepslate_bricks"},
        {pos: [15, 2, 23], state: "minecraft:repeater{delay:1,facing:east,locked:false,powered:true}"},
        {pos: [15, 2, 24], state: "minecraft:deepslate_bricks"},
        {pos: [16, 2, 0], state: "minecraft:deepslate_bricks"},
        {pos: [16, 2, 1], state: "minecraft:redstone_wire{east:side,north:none,power:12,south:side,west:side}"},
        {pos: [16, 2, 2], state: "minecraft:repeater{delay:1,facing:north,locked:false,powered:true}"},
        {pos: [16, 2, 3], state: "minecraft:deepslate_bricks"},
        {pos: [16, 2, 4], state: "minecraft:deepslate_bricks"},
        {pos: [16, 2, 10], state: "minecraft:deepslate_bricks"},
        {pos: [16, 2, 11], state: "minecraft:deepslate_bricks"},
        {pos: [16, 2, 12], state: "minecraft:deepslate_bricks"},
        {pos: [16, 2, 13], state: "minecraft:redstone_wire{east:side,north:none,power:0,south:side,west:none}"},
        {pos: [16, 2, 14], state: "minecraft:redstone_wire{east:none,north:side,power:0,south:side,west:none}"},
        {pos: [16, 2, 15], state: "minecraft:repeater{delay:1,facing:south,locked:false,powered:false}"},
        {pos: [16, 2, 16], state: "minecraft:redstone_wire{east:none,north:side,power:0,south:side,west:none}"},
        {pos: [16, 2, 17], state: "minecraft:redstone_wire{east:side,north:side,power:0,south:none,west:none}"},
        {pos: [16, 2, 18], state: "minecraft:deepslate_bricks"},
        {pos: [16, 2, 21], state: "minecraft:deepslate_bricks"},
        {pos: [16, 2, 22], state: "minecraft:repeater{delay:1,facing:south,locked:false,powered:true}"},
        {pos: [16, 2, 23], state: "minecraft:redstone_wire{east:side,north:side,power:5,south:none,west:side}"},
        {pos: [16, 2, 24], state: "minecraft:deepslate_bricks"},
        {pos: [17, 2, 0], state: "minecraft:deepslate_bricks"},
        {pos: [17, 2, 1], state: "minecraft:redstone_wire{east:side,north:none,power:13,south:side,west:side}"},
        {pos: [17, 2, 2], state: "minecraft:repeater{delay:1,facing:north,locked:false,powered:true}"},
        {pos: [17, 2, 3], state: "minecraft:deepslate_bricks"},
        {pos: [17, 2, 4], state: "minecraft:deepslate_bricks"},
        {pos: [17, 2, 10], state: "minecraft:deepslate_bricks"},
        {pos: [17, 2, 11], state: "minecraft:redstone_wire{east:side,north:none,power:0,south:side,west:none}"},
        {pos: [17, 2, 12], state: "minecraft:redstone_wire{east:side,north:side,power:0,south:side,west:none}"},
        {pos: [17, 2, 13], state: "minecraft:redstone_wire{east:side,north:side,power:0,south:none,west:side}"},
        {pos: [17, 2, 14], state: "minecraft:deepslate_bricks"},
        {pos: [17, 2, 15], state: "minecraft:deepslate_bricks"},
        {pos: [17, 2, 16], state: "minecraft:deepslate_bricks"},
        {pos: [17, 2, 17], state: "minecraft:redstone_wire{east:side,north:none,power:0,south:none,west:side}"},
        {pos: [17, 2, 18], state: "minecraft:deepslate_bricks"},
        {pos: [17, 2, 21], state: "minecraft:deepslate_bricks"},
        {pos: [17, 2, 22], state: "minecraft:repeater{delay:1,facing:south,locked:false,powered:true}"},
        {pos: [17, 2, 23], state: "minecraft:redstone_wire{east:side,north:side,power:6,south:none,west:side}"},
        {pos: [17, 2, 24], state: "minecraft:deepslate_bricks"},
        {pos: [18, 2, 0], state: "minecraft:deepslate_bricks"},
        {pos: [18, 2, 1], state: "minecraft:redstone_wire{east:side,north:none,power:14,south:side,west:side}"},
        {pos: [18, 2, 2], state: "minecraft:repeater{delay:1,facing:north,locked:false,powered:true}"},
        {pos: [18, 2, 3], state: "minecraft:deepslate_bricks"},
        {pos: [18, 2, 4], state: "minecraft:deepslate_bricks"},
        {pos: [18, 2, 10], state: "minecraft:deepslate_bricks"},
        {pos: [18, 2, 11], state: "minecraft:repeater{delay:1,facing:west,locked:false,powered:false}"},
        {pos: [18, 2, 12], state: "minecraft:repeater{delay:1,facing:west,locked:false,powered:false}"},
        {pos: [18, 2, 13], state: "minecraft:repeater{delay:1,facing:west,locked:false,powered:false}"},
        {pos: [18, 2, 14], state: "minecraft:deepslate_bricks"},
        {pos: [18, 2, 15], state: "minecraft:deepslate_bricks"},
        {pos: [18, 2, 16], state: "minecraft:deepslate_bricks"},
        {pos: [18, 2, 17], state: "minecraft:redstone_wire{east:side,north:none,power:0,south:none,west:side}"},
        {pos: [18, 2, 18], state: "minecraft:deepslate_bricks"},
        {pos: [18, 2, 21], state: "minecraft:deepslate_bricks"},
        {pos: [18, 2, 22], state: "minecraft:repeater{delay:1,facing:south,locked:false,powered:true}"},
        {pos: [18, 2, 23], state: "minecraft:redstone_wire{east:side,north:side,power:7,south:none,west:side}"},
        {pos: [18, 2, 24], state: "minecraft:deepslate_bricks"},
        {pos: [19, 2, 0], state: "minecraft:deepslate_bricks"},
        {pos: [19, 2, 1], state: "minecraft:redstone_wire{east:side,north:none,power:15,south:none,west:side}"},
        {pos: [19, 2, 2], state: "minecraft:deepslate_bricks"},
        {pos: [19, 2, 3], state: "minecraft:deepslate_bricks"},
        {pos: [19, 2, 4], state: "minecraft:deepslate_bricks"},
        {pos: [19, 2, 10], state: "minecraft:deepslate_bricks"},
        {pos: [19, 2, 11], state: "minecraft:deepslate_bricks"},
        {pos: [19, 2, 12], state: "minecraft:deepslate_bricks"},
        {pos: [19, 2, 13], state: "minecraft:deepslate_bricks"},
        {pos: [19, 2, 14], state: "minecraft:deepslate_bricks"},
        {pos: [19, 2, 15], state: "minecraft:deepslate_bricks"},
        {pos: [19, 2, 16], state: "minecraft:deepslate_bricks"},
        {pos: [19, 2, 17], state: "minecraft:redstone_wire{east:side,north:none,power:0,south:none,west:side}"},
        {pos: [19, 2, 18], state: "minecraft:deepslate_bricks"},
        {pos: [19, 2, 21], state: "minecraft:deepslate_bricks"},
        {pos: [19, 2, 22], state: "minecraft:deepslate_bricks"},
        {pos: [19, 2, 23], state: "minecraft:redstone_wire{east:side,north:none,power:8,south:none,west:side}"},
        {pos: [19, 2, 24], state: "minecraft:deepslate_bricks"},
        {pos: [20, 2, 0], state: "minecraft:deepslate_bricks"},
        {pos: [20, 2, 1], state: "minecraft:repeater{delay:1,facing:east,locked:false,powered:true}"},
        {pos: [20, 2, 2], state: "minecraft:deepslate_bricks"},
        {pos: [20, 2, 3], state: "minecraft:deepslate_bricks"},
        {pos: [20, 2, 4], state: "minecraft:deepslate_bricks"},
        {pos: [20, 2, 10], state: "minecraft:deepslate_bricks"},
        {pos: [20, 2, 11], state: "minecraft:redstone_wall_torch{facing:east,lit:true}"},
        {pos: [20, 2, 12], state: "minecraft:redstone_wall_torch{facing:east,lit:true}"},
        {pos: [20, 2, 13], state: "minecraft:redstone_wall_torch{facing:east,lit:true}"},
        {pos: [20, 2, 14], state: "minecraft:deepslate_bricks"},
        {pos: [20, 2, 15], state: "minecraft:deepslate_bricks"},
        {pos: [20, 2, 16], state: "minecraft:deepslate_bricks"},
        {pos: [20, 2, 17], state: "minecraft:redstone_wire{east:side,north:none,power:0,south:none,west:side}"},
        {pos: [20, 2, 18], state: "minecraft:deepslate_bricks"},
        {pos: [20, 2, 21], state: "minecraft:deepslate_bricks"},
        {pos: [20, 2, 22], state: "minecraft:deepslate_bricks"},
        {pos: [20, 2, 23], state: "minecraft:redstone_wire{east:side,north:none,power:9,south:none,west:side}"},
        {pos: [20, 2, 24], state: "minecraft:deepslate_bricks"},
        {pos: [21, 2, 0], state: "minecraft:deepslate_bricks"},
        {pos: [21, 2, 1], state: "minecraft:redstone_wire{east:none,north:none,power:10,south:side,west:side}"},
        {pos: [21, 2, 2], state: "minecraft:redstone_wire{east:none,north:side,power:11,south:side,west:none}"},
        {pos: [21, 2, 3], state: "minecraft:redstone_wire{east:none,north:side,power:12,south:none,west:up}"},
        {pos: [21, 2, 4], state: "minecraft:deepslate_bricks"},
        {pos: [21, 2, 10], state: "minecraft:deepslate_bricks"},
        {pos: [21, 2, 11], state: "minecraft:deepslate_bricks"},
        {pos: [21, 2, 12], state: "minecraft:deepslate_bricks"},
        {pos: [21, 2, 13], state: "minecraft:deepslate_bricks"},
        {pos: [21, 2, 14], state: "minecraft:deepslate_bricks"},
        {pos: [21, 2, 15], state: "minecraft:deepslate_bricks"},
        {pos: [21, 2, 16], state: "minecraft:deepslate_bricks"},
        {pos: [21, 2, 17], state: "minecraft:repeater{delay:1,facing:east,locked:false,powered:false}"},
        {pos: [21, 2, 18], state: "minecraft:deepslate_bricks"},
        {pos: [21, 2, 21], state: "minecraft:deepslate_bricks"},
        {pos: [21, 2, 22], state: "minecraft:deepslate_bricks"},
        {pos: [21, 2, 23], state: "minecraft:redstone_wire{east:none,north:up,power:10,south:none,west:side}"},
        {pos: [21, 2, 24], state: "minecraft:deepslate_bricks"},
        {pos: [22, 2, 0], state: "minecraft:deepslate_bricks"},
        {pos: [22, 2, 1], state: "minecraft:deepslate_bricks"},
        {pos: [22, 2, 2], state: "minecraft:deepslate_bricks"},
        {pos: [22, 2, 3], state: "minecraft:deepslate_bricks"},
        {pos: [22, 2, 4], state: "minecraft:deepslate_bricks"},
        {pos: [22, 2, 10], state: "minecraft:deepslate_bricks"},
        {pos: [22, 2, 11], state: "minecraft:cave_air"},
        {pos: [22, 2, 12], state: "minecraft:cave_air"},
        {pos: [22, 2, 13], state: "minecraft:cave_air"},
        {pos: [22, 2, 14], state: "minecraft:deepslate_bricks"},
        {pos: [22, 2, 15], state: "minecraft:deepslate_bricks"},
        {pos: [22, 2, 16], state: "minecraft:deepslate_bricks"},
        {pos: [22, 2, 17], state: "minecraft:redstone_wire{east:up,north:none,power:0,south:none,west:side}"},
        {pos: [22, 2, 18], state: "minecraft:deepslate_bricks"},
        {pos: [22, 2, 21], state: "minecraft:deepslate_bricks"},
        {pos: [22, 2, 22], state: "minecraft:deepslate_bricks"},
        {pos: [22, 2, 23], state: "minecraft:deepslate_bricks"},
        {pos: [22, 2, 24], state: "minecraft:deepslate_bricks"},
        {pos: [23, 2, 0], state: "minecraft:deepslate_bricks"},
        {pos: [23, 2, 1], state: "minecraft:deepslate_bricks"},
        {pos: [23, 2, 2], state: "minecraft:deepslate_bricks"},
        {pos: [23, 2, 3], state: "minecraft:deepslate_bricks"},
        {pos: [23, 2, 4], state: "minecraft:deepslate_bricks"},
        {pos: [23, 2, 10], state: "minecraft:deepslate_bricks"},
        {pos: [23, 2, 11], state: "minecraft:deepslate_bricks"},
        {pos: [23, 2, 12], state: "minecraft:deepslate_bricks"},
        {pos: [23, 2, 13], state: "minecraft:deepslate_bricks"},
        {pos: [23, 2, 14], state: "minecraft:deepslate_bricks"},
        {pos: [23, 2, 15], state: "minecraft:deepslate_bricks"},
        {pos: [23, 2, 16], state: "minecraft:deepslate_bricks"},
        {pos: [23, 2, 17], state: "minecraft:deepslate_bricks"},
        {pos: [23, 2, 18], state: "minecraft:deepslate_bricks"},
        {pos: [23, 2, 21], state: "minecraft:deepslate_bricks"},
        {pos: [23, 2, 22], state: "minecraft:deepslate_bricks"},
        {pos: [23, 2, 23], state: "minecraft:deepslate_bricks"},
        {pos: [23, 2, 24], state: "minecraft:deepslate_bricks"},
        {pos: [24, 2, 10], state: "minecraft:deepslate_bricks"},
        {pos: [24, 2, 11], state: "minecraft:deepslate_bricks"},
        {pos: [24, 2, 12], state: "minecraft:deepslate_bricks"},
        {pos: [24, 2, 13], state: "minecraft:deepslate_bricks"},
        {pos: [24, 2, 14], state: "minecraft:deepslate_bricks"},
        {pos: [24, 2, 15], state: "minecraft:deepslate_bricks"},
        {pos: [24, 2, 16], state: "minecraft:deepslate_bricks"},
        {pos: [24, 2, 17], state: "minecraft:deepslate_bricks"},
        {pos: [24, 2, 18], state: "minecraft:deepslate_bricks"},
        {pos: [0, 3, 7], state: "minecraft:deepslate{axis:y}"},
        {pos: [0, 3, 8], state: "minecraft:deepslate{axis:y}"},
        {pos: [0, 3, 9], state: "minecraft:deepslate{axis:y}"},
        {pos: [0, 3, 10], state: "minecraft:deepslate{axis:y}"},
        {pos: [0, 3, 11], state: "minecraft:deepslate{axis:y}"},
        {pos: [0, 3, 12], state: "minecraft:deepslate{axis:y}"},
        {pos: [0, 3, 13], state: "minecraft:deepslate{axis:y}"},
        {pos: [0, 3, 14], state: "minecraft:deepslate{axis:y}"},
        {pos: [0, 3, 15], state: "minecraft:deepslate{axis:y}"},
        {pos: [0, 3, 16], state: "minecraft:deepslate{axis:y}"},
        {pos: [0, 3, 17], state: "minecraft:deepslate{axis:y}"},
        {pos: [1, 3, 7], state: "minecraft:deepslate{axis:y}"},
        {pos: [1, 3, 8], state: "minecraft:deepslate{axis:y}"},
        {pos: [1, 3, 9], state: "minecraft:deepslate{axis:y}"},
        {pos: [1, 3, 10], state: "minecraft:deepslate{axis:y}"},
        {pos: [1, 3, 11], state: "minecraft:deepslate{axis:y}"},
        {pos: [1, 3, 12], state: "minecraft:deepslate{axis:y}"},
        {pos: [1, 3, 13], state: "minecraft:deepslate{axis:y}"},
        {pos: [1, 3, 14], state: "minecraft:deepslate{axis:y}"},
        {pos: [1, 3, 15], state: "minecraft:deepslate{axis:y}"},
        {pos: [1, 3, 16], state: "minecraft:deepslate{axis:y}"},
        {pos: [1, 3, 17], state: "minecraft:deepslate{axis:y}"},
        {pos: [2, 3, 6], state: "minecraft:deepslate{axis:y}"},
        {pos: [2, 3, 7], state: "minecraft:deepslate{axis:y}"},
        {pos: [2, 3, 8], state: "minecraft:deepslate{axis:y}"},
        {pos: [2, 3, 9], state: "minecraft:deepslate{axis:y}"},
        {pos: [2, 3, 10], state: "minecraft:deepslate{axis:y}"},
        {pos: [2, 3, 11], state: "minecraft:deepslate{axis:y}"},
        {pos: [2, 3, 12], state: "minecraft:deepslate{axis:y}"},
        {pos: [2, 3, 13], state: "minecraft:deepslate{axis:y}"},
        {pos: [2, 3, 14], state: "minecraft:deepslate{axis:y}"},
        {pos: [2, 3, 15], state: "minecraft:deepslate{axis:y}"},
        {pos: [2, 3, 16], state: "minecraft:deepslate{axis:y}"},
        {pos: [2, 3, 17], state: "minecraft:deepslate{axis:y}"},
        {pos: [2, 3, 18], state: "minecraft:deepslate{axis:y}"},
        {pos: [3, 3, 0], state: "minecraft:deepslate_bricks"},
        {pos: [3, 3, 1], state: "minecraft:deepslate_bricks"},
        {pos: [3, 3, 2], state: "minecraft:deepslate_bricks"},
        {pos: [3, 3, 3], state: "minecraft:deepslate_bricks"},
        {pos: [3, 3, 4], state: "minecraft:deepslate_bricks"},
        {pos: [3, 3, 5], state: "minecraft:deepslate{axis:y}"},
        {pos: [3, 3, 6], state: "minecraft:deepslate{axis:y}"},
        {pos: [3, 3, 7], state: "minecraft:deepslate{axis:y}"},
        {pos: [3, 3, 8], state: "minecraft:deepslate{axis:y}"},
        {pos: [3, 3, 9], state: "minecraft:deepslate{axis:y}"},
        {pos: [3, 3, 10], state: "minecraft:deepslate{axis:y}"},
        {pos: [3, 3, 11], state: "minecraft:deepslate{axis:y}"},
        {pos: [3, 3, 12], state: "minecraft:deepslate{axis:y}"},
        {pos: [3, 3, 13], state: "minecraft:deepslate{axis:y}"},
        {pos: [3, 3, 14], state: "minecraft:deepslate{axis:y}"},
        {pos: [3, 3, 15], state: "minecraft:deepslate{axis:y}"},
        {pos: [3, 3, 16], state: "minecraft:deepslate{axis:y}"},
        {pos: [3, 3, 17], state: "minecraft:deepslate{axis:y}"},
        {pos: [3, 3, 18], state: "minecraft:deepslate{axis:y}"},
        {pos: [3, 3, 19], state: "minecraft:deepslate{axis:y}"},
        {pos: [3, 3, 20], state: "minecraft:deepslate{axis:y}"},
        {pos: [3, 3, 21], state: "minecraft:deepslate_bricks"},
        {pos: [3, 3, 22], state: "minecraft:deepslate_bricks"},
        {pos: [3, 3, 23], state: "minecraft:deepslate_bricks"},
        {pos: [3, 3, 24], state: "minecraft:deepslate_bricks"},
        {pos: [4, 3, 0], state: "minecraft:deepslate_bricks"},
        {pos: [4, 3, 1], state: "minecraft:deepslate{axis:y}"},
        {pos: [4, 3, 2], state: "minecraft:deepslate{axis:y}"},
        {pos: [4, 3, 3], state: "minecraft:sticky_piston{extended:true,facing:up}"},
        {pos: [4, 3, 4], state: "minecraft:deepslate{axis:y}"},
        {pos: [4, 3, 5], state: "minecraft:deepslate{axis:y}"},
        {pos: [4, 3, 6], state: "minecraft:deepslate{axis:y}"},
        {pos: [4, 3, 7], state: "minecraft:deepslate{axis:y}"},
        {pos: [4, 3, 8], state: "minecraft:deepslate{axis:y}"},
        {pos: [4, 3, 9], state: "minecraft:deepslate{axis:y}"},
        {pos: [4, 3, 10], state: "minecraft:deepslate{axis:y}"},
        {pos: [4, 3, 11], state: "minecraft:deepslate{axis:y}"},
        {pos: [4, 3, 12], state: "minecraft:deepslate{axis:y}"},
        {pos: [4, 3, 13], state: "minecraft:deepslate{axis:y}"},
        {pos: [4, 3, 14], state: "minecraft:deepslate{axis:y}"},
        {pos: [4, 3, 15], state: "minecraft:deepslate{axis:y}"},
        {pos: [4, 3, 16], state: "minecraft:deepslate{axis:y}"},
        {pos: [4, 3, 17], state: "minecraft:deepslate{axis:y}"},
        {pos: [4, 3, 18], state: "minecraft:deepslate{axis:y}"},
        {pos: [4, 3, 19], state: "minecraft:deepslate{axis:y}"},
        {pos: [4, 3, 20], state: "minecraft:deepslate{axis:y}"},
        {pos: [4, 3, 21], state: "minecraft:sticky_piston{extended:true,facing:up}"},
        {pos: [4, 3, 22], state: "minecraft:deepslate{axis:y}"},
        {pos: [4, 3, 23], state: "minecraft:deepslate{axis:y}"},
        {pos: [4, 3, 24], state: "minecraft:deepslate_bricks"},
        {pos: [5, 3, 0], state: "minecraft:deepslate_bricks"},
        {pos: [5, 3, 1], state: "minecraft:deepslate{axis:y}"},
        {pos: [5, 3, 2], state: "minecraft:deepslate{axis:y}"},
        {pos: [5, 3, 3], state: "minecraft:sticky_piston{extended:true,facing:up}"},
        {pos: [5, 3, 4], state: "minecraft:deepslate{axis:y}"},
        {pos: [5, 3, 5], state: "minecraft:deepslate{axis:y}"},
        {pos: [5, 3, 6], state: "minecraft:deepslate{axis:y}"},
        {pos: [5, 3, 7], state: "minecraft:deepslate{axis:y}"},
        {pos: [5, 3, 8], state: "minecraft:deepslate{axis:y}"},
        {pos: [5, 3, 9], state: "minecraft:deepslate{axis:y}"},
        {pos: [5, 3, 10], state: "minecraft:deepslate{axis:y}"},
        {pos: [5, 3, 11], state: "minecraft:deepslate{axis:y}"},
        {pos: [5, 3, 12], state: "minecraft:deepslate{axis:y}"},
        {pos: [5, 3, 13], state: "minecraft:deepslate{axis:y}"},
        {pos: [5, 3, 14], state: "minecraft:deepslate{axis:y}"},
        {pos: [5, 3, 15], state: "minecraft:deepslate{axis:y}"},
        {pos: [5, 3, 16], state: "minecraft:deepslate{axis:y}"},
        {pos: [5, 3, 17], state: "minecraft:deepslate{axis:y}"},
        {pos: [5, 3, 18], state: "minecraft:deepslate{axis:y}"},
        {pos: [5, 3, 19], state: "minecraft:deepslate{axis:y}"},
        {pos: [5, 3, 20], state: "minecraft:deepslate{axis:y}"},
        {pos: [5, 3, 21], state: "minecraft:sticky_piston{extended:true,facing:up}"},
        {pos: [5, 3, 22], state: "minecraft:deepslate{axis:y}"},
        {pos: [5, 3, 23], state: "minecraft:deepslate{axis:y}"},
        {pos: [5, 3, 24], state: "minecraft:deepslate_bricks"},
        {pos: [6, 3, 0], state: "minecraft:deepslate_bricks"},
        {pos: [6, 3, 1], state: "minecraft:deepslate{axis:y}"},
        {pos: [6, 3, 2], state: "minecraft:deepslate{axis:y}"},
        {pos: [6, 3, 3], state: "minecraft:sticky_piston{extended:true,facing:up}"},
        {pos: [6, 3, 4], state: "minecraft:deepslate{axis:y}"},
        {pos: [6, 3, 5], state: "minecraft:deepslate{axis:y}"},
        {pos: [6, 3, 6], state: "minecraft:deepslate{axis:y}"},
        {pos: [6, 3, 7], state: "minecraft:deepslate{axis:y}"},
        {pos: [6, 3, 8], state: "minecraft:deepslate{axis:y}"},
        {pos: [6, 3, 9], state: "minecraft:deepslate{axis:y}"},
        {pos: [6, 3, 10], state: "minecraft:deepslate{axis:y}"},
        {pos: [6, 3, 11], state: "minecraft:deepslate{axis:y}"},
        {pos: [6, 3, 12], state: "minecraft:deepslate{axis:y}"},
        {pos: [6, 3, 13], state: "minecraft:deepslate{axis:y}"},
        {pos: [6, 3, 14], state: "minecraft:deepslate{axis:y}"},
        {pos: [6, 3, 15], state: "minecraft:deepslate{axis:y}"},
        {pos: [6, 3, 16], state: "minecraft:deepslate{axis:y}"},
        {pos: [6, 3, 17], state: "minecraft:deepslate{axis:y}"},
        {pos: [6, 3, 18], state: "minecraft:deepslate{axis:y}"},
        {pos: [6, 3, 19], state: "minecraft:deepslate{axis:y}"},
        {pos: [6, 3, 20], state: "minecraft:deepslate{axis:y}"},
        {pos: [6, 3, 21], state: "minecraft:sticky_piston{extended:true,facing:up}"},
        {pos: [6, 3, 22], state: "minecraft:deepslate{axis:y}"},
        {pos: [6, 3, 23], state: "minecraft:deepslate{axis:y}"},
        {pos: [6, 3, 24], state: "minecraft:deepslate_bricks"},
        {pos: [7, 3, 0], state: "minecraft:deepslate_bricks"},
        {pos: [7, 3, 1], state: "minecraft:deepslate{axis:y}"},
        {pos: [7, 3, 2], state: "minecraft:deepslate{axis:y}"},
        {pos: [7, 3, 3], state: "minecraft:deepslate{axis:y}"},
        {pos: [7, 3, 4], state: "minecraft:deepslate{axis:y}"},
        {pos: [7, 3, 5], state: "minecraft:deepslate{axis:y}"},
        {pos: [7, 3, 6], state: "minecraft:deepslate{axis:y}"},
        {pos: [7, 3, 7], state: "minecraft:deepslate{axis:y}"},
        {pos: [7, 3, 8], state: "minecraft:deepslate{axis:y}"},
        {pos: [7, 3, 9], state: "minecraft:deepslate{axis:y}"},
        {pos: [7, 3, 10], state: "minecraft:deepslate{axis:y}"},
        {pos: [7, 3, 11], state: "minecraft:deepslate{axis:y}"},
        {pos: [7, 3, 12], state: "minecraft:deepslate{axis:y}"},
        {pos: [7, 3, 13], state: "minecraft:deepslate{axis:y}"},
        {pos: [7, 3, 14], state: "minecraft:deepslate{axis:y}"},
        {pos: [7, 3, 15], state: "minecraft:deepslate{axis:y}"},
        {pos: [7, 3, 16], state: "minecraft:deepslate{axis:y}"},
        {pos: [7, 3, 17], state: "minecraft:deepslate{axis:y}"},
        {pos: [7, 3, 18], state: "minecraft:deepslate{axis:y}"},
        {pos: [7, 3, 19], state: "minecraft:deepslate{axis:y}"},
        {pos: [7, 3, 20], state: "minecraft:deepslate{axis:y}"},
        {pos: [7, 3, 21], state: "minecraft:deepslate{axis:y}"},
        {pos: [7, 3, 22], state: "minecraft:deepslate{axis:y}"},
        {pos: [7, 3, 23], state: "minecraft:deepslate{axis:y}"},
        {pos: [7, 3, 24], state: "minecraft:deepslate_bricks"},
        {pos: [8, 3, 0], state: "minecraft:deepslate_bricks"},
        {pos: [8, 3, 1], state: "minecraft:deepslate{axis:y}"},
        {pos: [8, 3, 2], state: "minecraft:deepslate{axis:y}"},
        {pos: [8, 3, 3], state: "minecraft:sticky_piston{extended:true,facing:up}"},
        {pos: [8, 3, 4], state: "minecraft:deepslate{axis:y}"},
        {pos: [8, 3, 5], state: "minecraft:deepslate{axis:y}"},
        {pos: [8, 3, 6], state: "minecraft:deepslate{axis:y}"},
        {pos: [8, 3, 7], state: "minecraft:deepslate{axis:y}"},
        {pos: [8, 3, 8], state: "minecraft:deepslate{axis:y}"},
        {pos: [8, 3, 9], state: "minecraft:deepslate{axis:y}"},
        {pos: [8, 3, 10], state: "minecraft:deepslate{axis:y}"},
        {pos: [8, 3, 11], state: "minecraft:deepslate{axis:y}"},
        {pos: [8, 3, 12], state: "minecraft:deepslate{axis:y}"},
        {pos: [8, 3, 13], state: "minecraft:deepslate{axis:y}"},
        {pos: [8, 3, 14], state: "minecraft:deepslate{axis:y}"},
        {pos: [8, 3, 15], state: "minecraft:deepslate{axis:y}"},
        {pos: [8, 3, 16], state: "minecraft:deepslate{axis:y}"},
        {pos: [8, 3, 17], state: "minecraft:deepslate{axis:y}"},
        {pos: [8, 3, 18], state: "minecraft:deepslate{axis:y}"},
        {pos: [8, 3, 19], state: "minecraft:deepslate{axis:y}"},
        {pos: [8, 3, 20], state: "minecraft:deepslate{axis:y}"},
        {pos: [8, 3, 21], state: "minecraft:sticky_piston{extended:true,facing:up}"},
        {pos: [8, 3, 22], state: "minecraft:deepslate{axis:y}"},
        {pos: [8, 3, 23], state: "minecraft:deepslate{axis:y}"},
        {pos: [8, 3, 24], state: "minecraft:deepslate_bricks"},
        {pos: [9, 3, 0], state: "minecraft:deepslate_bricks"},
        {pos: [9, 3, 1], state: "minecraft:deepslate{axis:y}"},
        {pos: [9, 3, 2], state: "minecraft:deepslate{axis:y}"},
        {pos: [9, 3, 3], state: "minecraft:sticky_piston{extended:true,facing:up}"},
        {pos: [9, 3, 4], state: "minecraft:deepslate{axis:y}"},
        {pos: [9, 3, 5], state: "minecraft:deepslate{axis:y}"},
        {pos: [9, 3, 6], state: "minecraft:deepslate{axis:y}"},
        {pos: [9, 3, 7], state: "minecraft:deepslate{axis:y}"},
        {pos: [9, 3, 8], state: "minecraft:deepslate{axis:y}"},
        {pos: [9, 3, 9], state: "minecraft:deepslate{axis:y}"},
        {pos: [9, 3, 10], state: "minecraft:deepslate{axis:y}"},
        {pos: [9, 3, 11], state: "minecraft:deepslate{axis:y}"},
        {pos: [9, 3, 12], state: "minecraft:deepslate{axis:y}"},
        {pos: [9, 3, 13], state: "minecraft:deepslate{axis:y}"},
        {pos: [9, 3, 14], state: "minecraft:deepslate{axis:y}"},
        {pos: [9, 3, 15], state: "minecraft:deepslate{axis:y}"},
        {pos: [9, 3, 16], state: "minecraft:deepslate{axis:y}"},
        {pos: [9, 3, 17], state: "minecraft:deepslate{axis:y}"},
        {pos: [9, 3, 18], state: "minecraft:deepslate{axis:y}"},
        {pos: [9, 3, 19], state: "minecraft:deepslate{axis:y}"},
        {pos: [9, 3, 20], state: "minecraft:deepslate{axis:y}"},
        {pos: [9, 3, 21], state: "minecraft:sticky_piston{extended:true,facing:up}"},
        {pos: [9, 3, 22], state: "minecraft:deepslate{axis:y}"},
        {pos: [9, 3, 23], state: "minecraft:deepslate{axis:y}"},
        {pos: [9, 3, 24], state: "minecraft:deepslate_bricks"},
        {pos: [10, 3, 0], state: "minecraft:deepslate_bricks"},
        {pos: [10, 3, 1], state: "minecraft:deepslate{axis:y}"},
        {pos: [10, 3, 2], state: "minecraft:deepslate{axis:y}"},
        {pos: [10, 3, 3], state: "minecraft:sticky_piston{extended:true,facing:up}"},
        {pos: [10, 3, 4], state: "minecraft:deepslate{axis:y}"},
        {pos: [10, 3, 5], state: "minecraft:deepslate{axis:y}"},
        {pos: [10, 3, 6], state: "minecraft:deepslate{axis:y}"},
        {pos: [10, 3, 7], state: "minecraft:deepslate{axis:y}"},
        {pos: [10, 3, 8], state: "minecraft:deepslate{axis:y}"},
        {pos: [10, 3, 9], state: "minecraft:deepslate{axis:y}"},
        {pos: [10, 3, 10], state: "minecraft:deepslate{axis:y}"},
        {pos: [10, 3, 11], state: "minecraft:deepslate{axis:y}"},
        {pos: [10, 3, 12], state: "minecraft:deepslate{axis:y}"},
        {pos: [10, 3, 13], state: "minecraft:deepslate{axis:y}"},
        {pos: [10, 3, 14], state: "minecraft:deepslate{axis:y}"},
        {pos: [10, 3, 15], state: "minecraft:deepslate{axis:y}"},
        {pos: [10, 3, 16], state: "minecraft:deepslate{axis:y}"},
        {pos: [10, 3, 17], state: "minecraft:deepslate{axis:y}"},
        {pos: [10, 3, 18], state: "minecraft:deepslate{axis:y}"},
        {pos: [10, 3, 19], state: "minecraft:deepslate{axis:y}"},
        {pos: [10, 3, 20], state: "minecraft:deepslate{axis:y}"},
        {pos: [10, 3, 21], state: "minecraft:sticky_piston{extended:true,facing:up}"},
        {pos: [10, 3, 22], state: "minecraft:deepslate{axis:y}"},
        {pos: [10, 3, 23], state: "minecraft:deepslate{axis:y}"},
        {pos: [10, 3, 24], state: "minecraft:deepslate_bricks"},
        {pos: [11, 3, 0], state: "minecraft:deepslate_bricks"},
        {pos: [11, 3, 1], state: "minecraft:deepslate{axis:y}"},
        {pos: [11, 3, 2], state: "minecraft:deepslate{axis:y}"},
        {pos: [11, 3, 3], state: "minecraft:deepslate{axis:y}"},
        {pos: [11, 3, 4], state: "minecraft:deepslate{axis:y}"},
        {pos: [11, 3, 5], state: "minecraft:deepslate{axis:y}"},
        {pos: [11, 3, 6], state: "minecraft:deepslate{axis:y}"},
        {pos: [11, 3, 7], state: "minecraft:deepslate{axis:y}"},
        {pos: [11, 3, 8], state: "minecraft:deepslate{axis:y}"},
        {pos: [11, 3, 9], state: "minecraft:deepslate{axis:y}"},
        {pos: [11, 3, 10], state: "minecraft:deepslate{axis:y}"},
        {pos: [11, 3, 11], state: "minecraft:deepslate{axis:y}"},
        {pos: [11, 3, 12], state: "minecraft:deepslate{axis:y}"},
        {pos: [11, 3, 13], state: "minecraft:deepslate{axis:y}"},
        {pos: [11, 3, 14], state: "minecraft:deepslate{axis:y}"},
        {pos: [11, 3, 15], state: "minecraft:deepslate{axis:y}"},
        {pos: [11, 3, 16], state: "minecraft:deepslate{axis:y}"},
        {pos: [11, 3, 17], state: "minecraft:deepslate{axis:y}"},
        {pos: [11, 3, 18], state: "minecraft:deepslate{axis:y}"},
        {pos: [11, 3, 19], state: "minecraft:deepslate{axis:y}"},
        {pos: [11, 3, 20], state: "minecraft:deepslate{axis:y}"},
        {pos: [11, 3, 21], state: "minecraft:deepslate{axis:y}"},
        {pos: [11, 3, 22], state: "minecraft:deepslate{axis:y}"},
        {pos: [11, 3, 23], state: "minecraft:deepslate{axis:y}"},
        {pos: [11, 3, 24], state: "minecraft:deepslate_bricks"},
        {pos: [12, 3, 0], state: "minecraft:deepslate_bricks"},
        {pos: [12, 3, 1], state: "minecraft:deepslate{axis:y}"},
        {pos: [12, 3, 2], state: "minecraft:deepslate{axis:y}"},
        {pos: [12, 3, 3], state: "minecraft:sticky_piston{extended:true,facing:up}"},
        {pos: [12, 3, 4], state: "minecraft:deepslate{axis:y}"},
        {pos: [12, 3, 5], state: "minecraft:deepslate{axis:y}"},
        {pos: [12, 3, 6], state: "minecraft:deepslate{axis:y}"},
        {pos: [12, 3, 7], state: "minecraft:deepslate{axis:y}"},
        {pos: [12, 3, 8], state: "minecraft:deepslate{axis:y}"},
        {pos: [12, 3, 9], state: "minecraft:deepslate{axis:y}"},
        {pos: [12, 3, 10], state: "minecraft:deepslate{axis:y}"},
        {pos: [12, 3, 11], state: "minecraft:deepslate{axis:y}"},
        {pos: [12, 3, 12], state: "minecraft:deepslate{axis:y}"},
        {pos: [12, 3, 13], state: "minecraft:deepslate{axis:y}"},
        {pos: [12, 3, 14], state: "minecraft:deepslate{axis:y}"},
        {pos: [12, 3, 15], state: "minecraft:deepslate{axis:y}"},
        {pos: [12, 3, 16], state: "minecraft:deepslate{axis:y}"},
        {pos: [12, 3, 17], state: "minecraft:deepslate{axis:y}"},
        {pos: [12, 3, 18], state: "minecraft:deepslate{axis:y}"},
        {pos: [12, 3, 19], state: "minecraft:deepslate{axis:y}"},
        {pos: [12, 3, 20], state: "minecraft:deepslate{axis:y}"},
        {pos: [12, 3, 21], state: "minecraft:sticky_piston{extended:true,facing:up}"},
        {pos: [12, 3, 22], state: "minecraft:deepslate{axis:y}"},
        {pos: [12, 3, 23], state: "minecraft:deepslate{axis:y}"},
        {pos: [12, 3, 24], state: "minecraft:deepslate_bricks"},
        {pos: [13, 3, 0], state: "minecraft:deepslate_bricks"},
        {pos: [13, 3, 1], state: "minecraft:deepslate{axis:y}"},
        {pos: [13, 3, 2], state: "minecraft:deepslate{axis:y}"},
        {pos: [13, 3, 3], state: "minecraft:sticky_piston{extended:true,facing:up}"},
        {pos: [13, 3, 4], state: "minecraft:deepslate{axis:y}"},
        {pos: [13, 3, 5], state: "minecraft:deepslate{axis:y}"},
        {pos: [13, 3, 6], state: "minecraft:deepslate{axis:y}"},
        {pos: [13, 3, 7], state: "minecraft:deepslate{axis:y}"},
        {pos: [13, 3, 8], state: "minecraft:deepslate{axis:y}"},
        {pos: [13, 3, 9], state: "minecraft:deepslate{axis:y}"},
        {pos: [13, 3, 10], state: "minecraft:deepslate{axis:y}"},
        {pos: [13, 3, 11], state: "minecraft:deepslate{axis:y}"},
        {pos: [13, 3, 12], state: "minecraft:deepslate{axis:y}"},
        {pos: [13, 3, 13], state: "minecraft:deepslate{axis:y}"},
        {pos: [13, 3, 14], state: "minecraft:deepslate{axis:y}"},
        {pos: [13, 3, 15], state: "minecraft:deepslate{axis:y}"},
        {pos: [13, 3, 16], state: "minecraft:deepslate{axis:y}"},
        {pos: [13, 3, 17], state: "minecraft:deepslate{axis:y}"},
        {pos: [13, 3, 18], state: "minecraft:deepslate{axis:y}"},
        {pos: [13, 3, 19], state: "minecraft:deepslate{axis:y}"},
        {pos: [13, 3, 20], state: "minecraft:deepslate{axis:y}"},
        {pos: [13, 3, 21], state: "minecraft:sticky_piston{extended:true,facing:up}"},
        {pos: [13, 3, 22], state: "minecraft:deepslate{axis:y}"},
        {pos: [13, 3, 23], state: "minecraft:deepslate{axis:y}"},
        {pos: [13, 3, 24], state: "minecraft:deepslate_bricks"},
        {pos: [14, 3, 0], state: "minecraft:deepslate_bricks"},
        {pos: [14, 3, 1], state: "minecraft:deepslate{axis:y}"},
        {pos: [14, 3, 2], state: "minecraft:deepslate{axis:y}"},
        {pos: [14, 3, 3], state: "minecraft:sticky_piston{extended:true,facing:up}"},
        {pos: [14, 3, 4], state: "minecraft:deepslate{axis:y}"},
        {pos: [14, 3, 5], state: "minecraft:deepslate{axis:y}"},
        {pos: [14, 3, 6], state: "minecraft:deepslate{axis:y}"},
        {pos: [14, 3, 7], state: "minecraft:deepslate{axis:y}"},
        {pos: [14, 3, 8], state: "minecraft:deepslate{axis:y}"},
        {pos: [14, 3, 9], state: "minecraft:deepslate{axis:y}"},
        {pos: [14, 3, 10], state: "minecraft:deepslate{axis:y}"},
        {pos: [14, 3, 11], state: "minecraft:deepslate{axis:y}"},
        {pos: [14, 3, 12], state: "minecraft:deepslate{axis:y}"},
        {pos: [14, 3, 13], state: "minecraft:deepslate{axis:y}"},
        {pos: [14, 3, 14], state: "minecraft:deepslate{axis:y}"},
        {pos: [14, 3, 15], state: "minecraft:deepslate{axis:y}"},
        {pos: [14, 3, 16], state: "minecraft:deepslate{axis:y}"},
        {pos: [14, 3, 17], state: "minecraft:deepslate{axis:y}"},
        {pos: [14, 3, 18], state: "minecraft:deepslate{axis:y}"},
        {pos: [14, 3, 19], state: "minecraft:deepslate{axis:y}"},
        {pos: [14, 3, 20], state: "minecraft:deepslate{axis:y}"},
        {pos: [14, 3, 21], state: "minecraft:sticky_piston{extended:true,facing:up}"},
        {pos: [14, 3, 22], state: "minecraft:deepslate{axis:y}"},
        {pos: [14, 3, 23], state: "minecraft:deepslate{axis:y}"},
        {pos: [14, 3, 24], state: "minecraft:deepslate_bricks"},
        {pos: [15, 3, 0], state: "minecraft:deepslate_bricks"},
        {pos: [15, 3, 1], state: "minecraft:deepslate{axis:y}"},
        {pos: [15, 3, 2], state: "minecraft:deepslate{axis:y}"},
        {pos: [15, 3, 3], state: "minecraft:deepslate{axis:y}"},
        {pos: [15, 3, 4], state: "minecraft:deepslate{axis:y}"},
        {pos: [15, 3, 5], state: "minecraft:deepslate{axis:y}"},
        {pos: [15, 3, 6], state: "minecraft:deepslate{axis:y}"},
        {pos: [15, 3, 7], state: "minecraft:deepslate{axis:y}"},
        {pos: [15, 3, 8], state: "minecraft:deepslate{axis:y}"},
        {pos: [15, 3, 9], state: "minecraft:deepslate{axis:y}"},
        {pos: [15, 3, 10], state: "minecraft:deepslate{axis:y}"},
        {pos: [15, 3, 11], state: "minecraft:deepslate{axis:y}"},
        {pos: [15, 3, 12], state: "minecraft:deepslate{axis:y}"},
        {pos: [15, 3, 13], state: "minecraft:deepslate{axis:y}"},
        {pos: [15, 3, 14], state: "minecraft:deepslate{axis:y}"},
        {pos: [15, 3, 15], state: "minecraft:deepslate{axis:y}"},
        {pos: [15, 3, 16], state: "minecraft:deepslate{axis:y}"},
        {pos: [15, 3, 17], state: "minecraft:deepslate{axis:y}"},
        {pos: [15, 3, 18], state: "minecraft:deepslate{axis:y}"},
        {pos: [15, 3, 19], state: "minecraft:deepslate{axis:y}"},
        {pos: [15, 3, 20], state: "minecraft:deepslate{axis:y}"},
        {pos: [15, 3, 21], state: "minecraft:deepslate{axis:y}"},
        {pos: [15, 3, 22], state: "minecraft:deepslate{axis:y}"},
        {pos: [15, 3, 23], state: "minecraft:deepslate{axis:y}"},
        {pos: [15, 3, 24], state: "minecraft:deepslate_bricks"},
        {pos: [16, 3, 0], state: "minecraft:deepslate_bricks"},
        {pos: [16, 3, 1], state: "minecraft:deepslate{axis:y}"},
        {pos: [16, 3, 2], state: "minecraft:deepslate{axis:y}"},
        {pos: [16, 3, 3], state: "minecraft:sticky_piston{extended:true,facing:up}"},
        {pos: [16, 3, 4], state: "minecraft:deepslate{axis:y}"},
        {pos: [16, 3, 5], state: "minecraft:deepslate{axis:y}"},
        {pos: [16, 3, 6], state: "minecraft:deepslate{axis:y}"},
        {pos: [16, 3, 7], state: "minecraft:deepslate{axis:y}"},
        {pos: [16, 3, 8], state: "minecraft:deepslate{axis:y}"},
        {pos: [16, 3, 9], state: "minecraft:deepslate{axis:y}"},
        {pos: [16, 3, 10], state: "minecraft:deepslate{axis:y}"},
        {pos: [16, 3, 11], state: "minecraft:deepslate{axis:y}"},
        {pos: [16, 3, 12], state: "minecraft:deepslate{axis:y}"},
        {pos: [16, 3, 13], state: "minecraft:deepslate{axis:y}"},
        {pos: [16, 3, 14], state: "minecraft:deepslate{axis:y}"},
        {pos: [16, 3, 15], state: "minecraft:deepslate{axis:y}"},
        {pos: [16, 3, 16], state: "minecraft:deepslate{axis:y}"},
        {pos: [16, 3, 17], state: "minecraft:deepslate{axis:y}"},
        {pos: [16, 3, 18], state: "minecraft:deepslate{axis:y}"},
        {pos: [16, 3, 19], state: "minecraft:deepslate{axis:y}"},
        {pos: [16, 3, 20], state: "minecraft:deepslate{axis:y}"},
        {pos: [16, 3, 21], state: "minecraft:sticky_piston{extended:true,facing:up}"},
        {pos: [16, 3, 22], state: "minecraft:deepslate{axis:y}"},
        {pos: [16, 3, 23], state: "minecraft:deepslate{axis:y}"},
        {pos: [16, 3, 24], state: "minecraft:deepslate_bricks"},
        {pos: [17, 3, 0], state: "minecraft:deepslate_bricks"},
        {pos: [17, 3, 1], state: "minecraft:deepslate{axis:y}"},
        {pos: [17, 3, 2], state: "minecraft:deepslate{axis:y}"},
        {pos: [17, 3, 3], state: "minecraft:sticky_piston{extended:true,facing:up}"},
        {pos: [17, 3, 4], state: "minecraft:deepslate{axis:y}"},
        {pos: [17, 3, 5], state: "minecraft:deepslate{axis:y}"},
        {pos: [17, 3, 6], state: "minecraft:deepslate{axis:y}"},
        {pos: [17, 3, 7], state: "minecraft:deepslate{axis:y}"},
        {pos: [17, 3, 8], state: "minecraft:deepslate{axis:y}"},
        {pos: [17, 3, 9], state: "minecraft:deepslate{axis:y}"},
        {pos: [17, 3, 10], state: "minecraft:deepslate{axis:y}"},
        {pos: [17, 3, 11], state: "minecraft:deepslate{axis:y}"},
        {pos: [17, 3, 12], state: "minecraft:deepslate{axis:y}"},
        {pos: [17, 3, 13], state: "minecraft:deepslate{axis:y}"},
        {pos: [17, 3, 14], state: "minecraft:deepslate{axis:y}"},
        {pos: [17, 3, 15], state: "minecraft:deepslate{axis:y}"},
        {pos: [17, 3, 16], state: "minecraft:deepslate{axis:y}"},
        {pos: [17, 3, 17], state: "minecraft:deepslate{axis:y}"},
        {pos: [17, 3, 18], state: "minecraft:deepslate{axis:y}"},
        {pos: [17, 3, 19], state: "minecraft:deepslate{axis:y}"},
        {pos: [17, 3, 20], state: "minecraft:deepslate{axis:y}"},
        {pos: [17, 3, 21], state: "minecraft:sticky_piston{extended:true,facing:up}"},
        {pos: [17, 3, 22], state: "minecraft:deepslate{axis:y}"},
        {pos: [17, 3, 23], state: "minecraft:deepslate{axis:y}"},
        {pos: [17, 3, 24], state: "minecraft:deepslate_bricks"},
        {pos: [18, 3, 0], state: "minecraft:deepslate_bricks"},
        {pos: [18, 3, 1], state: "minecraft:deepslate{axis:y}"},
        {pos: [18, 3, 2], state: "minecraft:deepslate{axis:y}"},
        {pos: [18, 3, 3], state: "minecraft:sticky_piston{extended:true,facing:up}"},
        {pos: [18, 3, 4], state: "minecraft:deepslate{axis:y}"},
        {pos: [18, 3, 5], state: "minecraft:deepslate{axis:y}"},
        {pos: [18, 3, 6], state: "minecraft:deepslate{axis:y}"},
        {pos: [18, 3, 7], state: "minecraft:deepslate{axis:y}"},
        {pos: [18, 3, 8], state: "minecraft:deepslate{axis:y}"},
        {pos: [18, 3, 9], state: "minecraft:deepslate{axis:y}"},
        {pos: [18, 3, 10], state: "minecraft:deepslate{axis:y}"},
        {pos: [18, 3, 11], state: "minecraft:deepslate{axis:y}"},
        {pos: [18, 3, 12], state: "minecraft:deepslate{axis:y}"},
        {pos: [18, 3, 13], state: "minecraft:deepslate{axis:y}"},
        {pos: [18, 3, 14], state: "minecraft:deepslate{axis:y}"},
        {pos: [18, 3, 15], state: "minecraft:deepslate{axis:y}"},
        {pos: [18, 3, 16], state: "minecraft:deepslate{axis:y}"},
        {pos: [18, 3, 17], state: "minecraft:deepslate{axis:y}"},
        {pos: [18, 3, 18], state: "minecraft:deepslate{axis:y}"},
        {pos: [18, 3, 19], state: "minecraft:deepslate{axis:y}"},
        {pos: [18, 3, 20], state: "minecraft:deepslate{axis:y}"},
        {pos: [18, 3, 21], state: "minecraft:sticky_piston{extended:true,facing:up}"},
        {pos: [18, 3, 22], state: "minecraft:deepslate{axis:y}"},
        {pos: [18, 3, 23], state: "minecraft:deepslate{axis:y}"},
        {pos: [18, 3, 24], state: "minecraft:deepslate_bricks"},
        {pos: [19, 3, 0], state: "minecraft:deepslate_bricks"},
        {pos: [19, 3, 1], state: "minecraft:deepslate{axis:y}"},
        {pos: [19, 3, 2], state: "minecraft:deepslate{axis:y}"},
        {pos: [19, 3, 3], state: "minecraft:cave_air"},
        {pos: [19, 3, 4], state: "minecraft:deepslate{axis:y}"},
        {pos: [19, 3, 5], state: "minecraft:deepslate{axis:y}"},
        {pos: [19, 3, 6], state: "minecraft:deepslate{axis:y}"},
        {pos: [19, 3, 7], state: "minecraft:deepslate{axis:y}"},
        {pos: [19, 3, 8], state: "minecraft:deepslate{axis:y}"},
        {pos: [19, 3, 9], state: "minecraft:deepslate{axis:y}"},
        {pos: [19, 3, 10], state: "minecraft:deepslate{axis:y}"},
        {pos: [19, 3, 11], state: "minecraft:deepslate{axis:y}"},
        {pos: [19, 3, 12], state: "minecraft:deepslate{axis:y}"},
        {pos: [19, 3, 13], state: "minecraft:deepslate{axis:y}"},
        {pos: [19, 3, 14], state: "minecraft:deepslate{axis:y}"},
        {pos: [19, 3, 15], state: "minecraft:deepslate{axis:y}"},
        {pos: [19, 3, 16], state: "minecraft:deepslate{axis:y}"},
        {pos: [19, 3, 17], state: "minecraft:deepslate{axis:y}"},
        {pos: [19, 3, 18], state: "minecraft:deepslate{axis:y}"},
        {pos: [19, 3, 19], state: "minecraft:deepslate{axis:y}"},
        {pos: [19, 3, 20], state: "minecraft:deepslate{axis:y}"},
        {pos: [19, 3, 21], state: "minecraft:deepslate{axis:y}"},
        {pos: [19, 3, 22], state: "minecraft:deepslate{axis:y}"},
        {pos: [19, 3, 23], state: "minecraft:deepslate{axis:y}"},
        {pos: [19, 3, 24], state: "minecraft:deepslate_bricks"},
        {pos: [20, 3, 0], state: "minecraft:deepslate_bricks"},
        {pos: [20, 3, 1], state: "minecraft:cave_air"},
        {pos: [20, 3, 2], state: "minecraft:deepslate_bricks"},
        {pos: [20, 3, 3], state: "minecraft:redstone_wire{east:side,north:up,power:13,south:none,west:none}"},
        {pos: [20, 3, 4], state: "minecraft:deepslate_bricks"},
        {pos: [20, 3, 5], state: "minecraft:deepslate{axis:y}"},
        {pos: [20, 3, 6], state: "minecraft:deepslate{axis:y}"},
        {pos: [20, 3, 7], state: "minecraft:deepslate{axis:y}"},
        {pos: [20, 3, 8], state: "minecraft:deepslate{axis:y}"},
        {pos: [20, 3, 9], state: "minecraft:deepslate{axis:y}"},
        {pos: [20, 3, 10], state: "minecraft:deepslate{axis:y}"},
        {pos: [20, 3, 11], state: "minecraft:sticky_piston{extended:true,facing:east}"},
        {pos: [20, 3, 12], state: "minecraft:sticky_piston{extended:true,facing:east}"},
        {pos: [20, 3, 13], state: "minecraft:sticky_piston{extended:true,facing:east}"},
        {pos: [20, 3, 14], state: "minecraft:deepslate{axis:y}"},
        {pos: [20, 3, 15], state: "minecraft:deepslate{axis:y}"},
        {pos: [20, 3, 16], state: "minecraft:deepslate{axis:y}"},
        {pos: [20, 3, 17], state: "minecraft:deepslate{axis:y}"},
        {pos: [20, 3, 18], state: "minecraft:deepslate_bricks"},
        {pos: [20, 3, 19], state: "minecraft:deepslate_bricks"},
        {pos: [20, 3, 20], state: "minecraft:deepslate_bricks"},
        {pos: [20, 3, 21], state: "minecraft:deepslate_bricks"},
        {pos: [20, 3, 22], state: "minecraft:deepslate_bricks"},
        {pos: [20, 3, 23], state: "minecraft:deepslate_bricks"},
        {pos: [20, 3, 24], state: "minecraft:deepslate_bricks"},
        {pos: [21, 3, 0], state: "minecraft:deepslate_bricks"},
        {pos: [21, 3, 1], state: "minecraft:cave_air"},
        {pos: [21, 3, 2], state: "minecraft:deepslate_bricks"},
        {pos: [21, 3, 3], state: "minecraft:cave_air"},
        {pos: [21, 3, 4], state: "minecraft:deepslate_bricks"},
        {pos: [21, 3, 7], state: "minecraft:deepslate{axis:y}"},
        {pos: [21, 3, 8], state: "minecraft:deepslate{axis:y}"},
        {pos: [21, 3, 9], state: "minecraft:deepslate{axis:y}"},
        {pos: [21, 3, 10], state: "minecraft:deepslate_bricks"},
        {pos: [21, 3, 11], state: "minecraft:piston_head{facing:east,short:false,type:sticky}"},
        {pos: [21, 3, 12], state: "minecraft:piston_head{facing:east,short:false,type:sticky}"},
        {pos: [21, 3, 13], state: "minecraft:piston_head{facing:east,short:false,type:sticky}"},
        {pos: [21, 3, 14], state: "minecraft:deepslate_bricks"},
        {pos: [21, 3, 15], state: "minecraft:deepslate{axis:y}"},
        {pos: [21, 3, 16], state: "minecraft:deepslate{axis:y}"},
        {pos: [21, 3, 17], state: "minecraft:deepslate{axis:y}"},
        {pos: [21, 3, 18], state: "minecraft:deepslate_bricks"},
        {pos: [21, 3, 20], state: "minecraft:deepslate_bricks"},
        {pos: [21, 3, 21], state: "minecraft:redstone_wire{east:none,north:none,power:12,south:side,west:up}"},
        {pos: [21, 3, 22], state: "minecraft:redstone_wire{east:none,north:side,power:11,south:side,west:none}"},
        {pos: [21, 3, 23], state: "minecraft:cave_air"},
        {pos: [21, 3, 24], state: "minecraft:deepslate_bricks"},
        {pos: [22, 3, 0], state: "minecraft:deepslate_bricks"},
        {pos: [22, 3, 1], state: "minecraft:deepslate_bricks"},
        {pos: [22, 3, 2], state: "minecraft:deepslate_bricks"},
        {pos: [22, 3, 3], state: "minecraft:deepslate_bricks"},
        {pos: [22, 3, 4], state: "minecraft:deepslate_bricks"},
        {pos: [22, 3, 7], state: "minecraft:deepslate{axis:y}"},
        {pos: [22, 3, 8], state: "minecraft:deepslate{axis:y}"},
        {pos: [22, 3, 9], state: "minecraft:deepslate{axis:y}"},
        {pos: [22, 3, 10], state: "minecraft:deepslate_bricks"},
        {pos: [22, 3, 11], state: "minecraft:deepslate_tiles"},
        {pos: [22, 3, 12], state: "minecraft:deepslate_tiles"},
        {pos: [22, 3, 13], state: "minecraft:deepslate_tiles"},
        {pos: [22, 3, 14], state: "minecraft:deepslate_bricks"},
        {pos: [22, 3, 15], state: "minecraft:deepslate{axis:y}"},
        {pos: [22, 3, 16], state: "minecraft:deepslate{axis:y}"},
        {pos: [22, 3, 17], state: "minecraft:cave_air"},
        {pos: [22, 3, 18], state: "minecraft:deepslate_bricks"},
        {pos: [22, 3, 20], state: "minecraft:deepslate_bricks"},
        {pos: [22, 3, 21], state: "minecraft:deepslate_bricks"},
        {pos: [22, 3, 22], state: "minecraft:deepslate_bricks"},
        {pos: [22, 3, 23], state: "minecraft:deepslate_bricks"},
        {pos: [22, 3, 24], state: "minecraft:deepslate_bricks"},
        {pos: [23, 3, 0], state: "minecraft:deepslate_bricks"},
        {pos: [23, 3, 1], state: "minecraft:deepslate_bricks"},
        {pos: [23, 3, 2], state: "minecraft:deepslate_bricks"},
        {pos: [23, 3, 3], state: "minecraft:deepslate_bricks"},
        {pos: [23, 3, 4], state: "minecraft:deepslate_bricks"},
        {pos: [23, 3, 7], state: "minecraft:deepslate{axis:y}"},
        {pos: [23, 3, 8], state: "minecraft:deepslate{axis:y}"},
        {pos: [23, 3, 9], state: "minecraft:deepslate{axis:y}"},
        {pos: [23, 3, 10], state: "minecraft:deepslate_bricks"},
        {pos: [23, 3, 11], state: "minecraft:deepslate_bricks"},
        {pos: [23, 3, 12], state: "minecraft:deepslate_bricks"},
        {pos: [23, 3, 13], state: "minecraft:deepslate_bricks"},
        {pos: [23, 3, 14], state: "minecraft:deepslate_bricks"},
        {pos: [23, 3, 15], state: "minecraft:deepslate_bricks"},
        {pos: [23, 3, 16], state: "minecraft:deepslate_bricks"},
        {pos: [23, 3, 17], state: "minecraft:redstone_wire{east:up,north:none,power:0,south:none,west:side}"},
        {pos: [23, 3, 18], state: "minecraft:deepslate_bricks"},
        {pos: [23, 3, 20], state: "minecraft:deepslate_bricks"},
        {pos: [23, 3, 21], state: "minecraft:deepslate_bricks"},
        {pos: [23, 3, 22], state: "minecraft:deepslate_bricks"},
        {pos: [23, 3, 23], state: "minecraft:deepslate_bricks"},
        {pos: [23, 3, 24], state: "minecraft:deepslate_bricks"},
        {pos: [24, 3, 7], state: "minecraft:deepslate{axis:y}"},
        {pos: [24, 3, 8], state: "minecraft:deepslate{axis:y}"},
        {pos: [24, 3, 9], state: "minecraft:deepslate{axis:y}"},
        {pos: [24, 3, 10], state: "minecraft:deepslate{axis:y}"},
        {pos: [24, 3, 11], state: "minecraft:deepslate{axis:y}"},
        {pos: [24, 3, 12], state: "minecraft:deepslate{axis:y}"},
        {pos: [24, 3, 13], state: "minecraft:deepslate{axis:y}"},
        {pos: [24, 3, 14], state: "minecraft:deepslate{axis:y}"},
        {pos: [24, 3, 15], state: "minecraft:deepslate_bricks"},
        {pos: [24, 3, 16], state: "minecraft:deepslate_bricks"},
        {pos: [24, 3, 17], state: "minecraft:deepslate_bricks"},
        {pos: [24, 3, 18], state: "minecraft:deepslate_bricks"},
        {pos: [25, 3, 7], state: "minecraft:deepslate{axis:y}"},
        {pos: [25, 3, 8], state: "minecraft:deepslate{axis:y}"},
        {pos: [25, 3, 9], state: "minecraft:deepslate{axis:y}"},
        {pos: [25, 3, 10], state: "minecraft:deepslate{axis:y}"},
        {pos: [25, 3, 11], state: "minecraft:deepslate{axis:y}"},
        {pos: [25, 3, 12], state: "minecraft:deepslate{axis:y}"},
        {pos: [25, 3, 13], state: "minecraft:deepslate{axis:y}"},
        {pos: [25, 3, 14], state: "minecraft:deepslate{axis:y}"},
        {pos: [25, 3, 15], state: "minecraft:deepslate{axis:y}"},
        {pos: [25, 3, 16], state: "minecraft:deepslate{axis:y}"},
        {pos: [25, 3, 17], state: "minecraft:deepslate{axis:y}"},
        {pos: [25, 3, 18], state: "minecraft:deepslate{axis:y}"},
        {pos: [0, 4, 7], state: "minecraft:deepslate_bricks"},
        {pos: [0, 4, 8], state: "minecraft:deepslate_bricks"},
        {pos: [0, 4, 9], state: "minecraft:deepslate_bricks"},
        {pos: [0, 4, 10], state: "minecraft:deepslate_bricks"},
        {pos: [0, 4, 11], state: "minecraft:gravel"},
        {pos: [0, 4, 12], state: "minecraft:gravel"},
        {pos: [0, 4, 13], state: "minecraft:gravel"},
        {pos: [0, 4, 14], state: "minecraft:deepslate_bricks"},
        {pos: [0, 4, 15], state: "minecraft:deepslate_bricks"},
        {pos: [0, 4, 16], state: "minecraft:deepslate_bricks"},
        {pos: [0, 4, 17], state: "minecraft:deepslate_bricks"},
        {pos: [1, 4, 7], state: "minecraft:deepslate_bricks"},
        {pos: [1, 4, 8], state: "minecraft:gravel"},
        {pos: [1, 4, 9], state: "minecraft:gravel"},
        {pos: [1, 4, 10], state: "minecraft:gravel"},
        {pos: [1, 4, 11], state: "minecraft:gravel"},
        {pos: [1, 4, 12], state: "minecraft:gravel"},
        {pos: [1, 4, 13], state: "minecraft:gravel"},
        {pos: [1, 4, 14], state: "minecraft:gravel"},
        {pos: [1, 4, 15], state: "minecraft:gravel"},
        {pos: [1, 4, 16], state: "minecraft:gravel"},
        {pos: [1, 4, 17], state: "minecraft:deepslate_bricks"},
        {pos: [2, 4, 6], state: "minecraft:deepslate_bricks"},
        {pos: [2, 4, 7], state: "minecraft:gravel"},
        {pos: [2, 4, 8], state: "minecraft:gravel"},
        {pos: [2, 4, 9], state: "minecraft:gravel"},
        {pos: [2, 4, 10], state: "minecraft:gravel"},
        {pos: [2, 4, 11], state: "minecraft:gravel"},
        {pos: [2, 4, 12], state: "minecraft:gravel"},
        {pos: [2, 4, 13], state: "minecraft:gravel"},
        {pos: [2, 4, 14], state: "minecraft:gravel"},
        {pos: [2, 4, 15], state: "minecraft:gravel"},
        {pos: [2, 4, 16], state: "minecraft:gravel"},
        {pos: [2, 4, 17], state: "minecraft:gravel"},
        {pos: [2, 4, 18], state: "minecraft:deepslate_bricks"},
        {pos: [3, 4, 0], state: "minecraft:deepslate_bricks"},
        {pos: [3, 4, 1], state: "minecraft:deepslate_bricks"},
        {pos: [3, 4, 2], state: "minecraft:deepslate_bricks"},
        {pos: [3, 4, 3], state: "minecraft:deepslate_bricks"},
        {pos: [3, 4, 4], state: "minecraft:deepslate_bricks"},
        {pos: [3, 4, 5], state: "minecraft:deepslate_bricks"},
        {pos: [3, 4, 6], state: "minecraft:gravel"},
        {pos: [3, 4, 7], state: "minecraft:deepslate_bricks"},
        {pos: [3, 4, 8], state: "minecraft:gravel"},
        {pos: [3, 4, 9], state: "minecraft:gravel"},
        {pos: [3, 4, 10], state: "minecraft:gravel"},
        {pos: [3, 4, 11], state: "minecraft:deepslate_bricks"},
        {pos: [3, 4, 12], state: "minecraft:deepslate_bricks"},
        {pos: [3, 4, 13], state: "minecraft:deepslate_bricks"},
        {pos: [3, 4, 14], state: "minecraft:gravel"},
        {pos: [3, 4, 15], state: "minecraft:gravel"},
        {pos: [3, 4, 16], state: "minecraft:gravel"},
        {pos: [3, 4, 17], state: "minecraft:deepslate_bricks"},
        {pos: [3, 4, 18], state: "minecraft:gravel"},
        {pos: [3, 4, 19], state: "minecraft:deepslate_bricks"},
        {pos: [3, 4, 20], state: "minecraft:deepslate_bricks"},
        {pos: [3, 4, 21], state: "minecraft:deepslate_bricks"},
        {pos: [3, 4, 22], state: "minecraft:deepslate_bricks"},
        {pos: [3, 4, 23], state: "minecraft:deepslate_bricks"},
        {pos: [3, 4, 24], state: "minecraft:deepslate_bricks"},
        {pos: [4, 4, 0], state: "minecraft:deepslate_bricks"},
        {pos: [4, 4, 1], state: "minecraft:gravel"},
        {pos: [4, 4, 2], state: "minecraft:gravel"},
        {pos: [4, 4, 3], state: "minecraft:piston_head{facing:up,short:false,type:sticky}"},
        {pos: [4, 4, 4], state: "minecraft:gravel"},
        {pos: [4, 4, 5], state: "minecraft:gravel"},
        {pos: [4, 4, 6], state: "minecraft:gravel"},
        {pos: [4, 4, 7], state: "minecraft:gravel"},
        {pos: [4, 4, 8], state: "minecraft:gravel"},
        {pos: [4, 4, 9], state: "minecraft:gravel"},
        {pos: [4, 4, 10], state: "minecraft:gravel"},
        {pos: [4, 4, 11], state: "minecraft:gravel"},
        {pos: [4, 4, 12], state: "minecraft:gravel"},
        {pos: [4, 4, 13], state: "minecraft:gravel"},
        {pos: [4, 4, 14], state: "minecraft:gravel"},
        {pos: [4, 4, 15], state: "minecraft:gravel"},
        {pos: [4, 4, 16], state: "minecraft:gravel"},
        {pos: [4, 4, 17], state: "minecraft:gravel"},
        {pos: [4, 4, 18], state: "minecraft:gravel"},
        {pos: [4, 4, 19], state: "minecraft:gravel"},
        {pos: [4, 4, 20], state: "minecraft:gravel"},
        {pos: [4, 4, 21], state: "minecraft:piston_head{facing:up,short:false,type:sticky}"},
        {pos: [4, 4, 22], state: "minecraft:gravel"},
        {pos: [4, 4, 23], state: "minecraft:gravel"},
        {pos: [4, 4, 24], state: "minecraft:deepslate_bricks"},
        {pos: [5, 4, 0], state: "minecraft:deepslate_bricks"},
        {pos: [5, 4, 1], state: "minecraft:gravel"},
        {pos: [5, 4, 2], state: "minecraft:gravel"},
        {pos: [5, 4, 3], state: "minecraft:piston_head{facing:up,short:false,type:sticky}"},
        {pos: [5, 4, 4], state: "minecraft:gravel"},
        {pos: [5, 4, 5], state: "minecraft:gravel"},
        {pos: [5, 4, 6], state: "minecraft:gravel"},
        {pos: [5, 4, 7], state: "minecraft:gravel"},
        {pos: [5, 4, 8], state: "minecraft:gravel"},
        {pos: [5, 4, 9], state: "minecraft:gravel"},
        {pos: [5, 4, 10], state: "minecraft:gravel"},
        {pos: [5, 4, 11], state: "minecraft:gravel"},
        {pos: [5, 4, 12], state: "minecraft:gravel"},
        {pos: [5, 4, 13], state: "minecraft:gravel"},
        {pos: [5, 4, 14], state: "minecraft:gravel"},
        {pos: [5, 4, 15], state: "minecraft:gravel"},
        {pos: [5, 4, 16], state: "minecraft:gravel"},
        {pos: [5, 4, 17], state: "minecraft:gravel"},
        {pos: [5, 4, 18], state: "minecraft:gravel"},
        {pos: [5, 4, 19], state: "minecraft:gravel"},
        {pos: [5, 4, 20], state: "minecraft:gravel"},
        {pos: [5, 4, 21], state: "minecraft:piston_head{facing:up,short:false,type:sticky}"},
        {pos: [5, 4, 22], state: "minecraft:gravel"},
        {pos: [5, 4, 23], state: "minecraft:gravel"},
        {pos: [5, 4, 24], state: "minecraft:deepslate_bricks"},
        {pos: [6, 4, 0], state: "minecraft:deepslate_bricks"},
        {pos: [6, 4, 1], state: "minecraft:gravel"},
        {pos: [6, 4, 2], state: "minecraft:gravel"},
        {pos: [6, 4, 3], state: "minecraft:piston_head{facing:up,short:false,type:sticky}"},
        {pos: [6, 4, 4], state: "minecraft:gravel"},
        {pos: [6, 4, 5], state: "minecraft:gravel"},
        {pos: [6, 4, 6], state: "minecraft:gravel"},
        {pos: [6, 4, 7], state: "minecraft:gravel"},
        {pos: [6, 4, 8], state: "minecraft:gravel"},
        {pos: [6, 4, 9], state: "minecraft:gravel"},
        {pos: [6, 4, 10], state: "minecraft:gravel"},
        {pos: [6, 4, 11], state: "minecraft:gravel"},
        {pos: [6, 4, 12], state: "minecraft:gravel"},
        {pos: [6, 4, 13], state: "minecraft:gravel"},
        {pos: [6, 4, 14], state: "minecraft:gravel"},
        {pos: [6, 4, 15], state: "minecraft:gravel"},
        {pos: [6, 4, 16], state: "minecraft:gravel"},
        {pos: [6, 4, 17], state: "minecraft:gravel"},
        {pos: [6, 4, 18], state: "minecraft:gravel"},
        {pos: [6, 4, 19], state: "minecraft:gravel"},
        {pos: [6, 4, 20], state: "minecraft:gravel"},
        {pos: [6, 4, 21], state: "minecraft:piston_head{facing:up,short:false,type:sticky}"},
        {pos: [6, 4, 22], state: "minecraft:gravel"},
        {pos: [6, 4, 23], state: "minecraft:gravel"},
        {pos: [6, 4, 24], state: "minecraft:deepslate_bricks"},
        {pos: [7, 4, 0], state: "minecraft:deepslate_bricks"},
        {pos: [7, 4, 1], state: "minecraft:deepslate_bricks"},
        {pos: [7, 4, 2], state: "minecraft:deepslate_bricks"},
        {pos: [7, 4, 3], state: "minecraft:deepslate_bricks"},
        {pos: [7, 4, 4], state: "minecraft:deepslate_bricks"},
        {pos: [7, 4, 5], state: "minecraft:gravel"},
        {pos: [7, 4, 6], state: "minecraft:gravel"},
        {pos: [7, 4, 7], state: "minecraft:gravel"},
        {pos: [7, 4, 8], state: "minecraft:gravel"},
        {pos: [7, 4, 9], state: "minecraft:gravel"},
        {pos: [7, 4, 10], state: "minecraft:gravel"},
        {pos: [7, 4, 11], state: "minecraft:gravel"},
        {pos: [7, 4, 12], state: "minecraft:gravel"},
        {pos: [7, 4, 13], state: "minecraft:gravel"},
        {pos: [7, 4, 14], state: "minecraft:gravel"},
        {pos: [7, 4, 15], state: "minecraft:gravel"},
        {pos: [7, 4, 16], state: "minecraft:gravel"},
        {pos: [7, 4, 17], state: "minecraft:gravel"},
        {pos: [7, 4, 18], state: "minecraft:gravel"},
        {pos: [7, 4, 19], state: "minecraft:gravel"},
        {pos: [7, 4, 20], state: "minecraft:deepslate_bricks"},
        {pos: [7, 4, 21], state: "minecraft:deepslate_bricks"},
        {pos: [7, 4, 22], state: "minecraft:deepslate_bricks"},
        {pos: [7, 4, 23], state: "minecraft:deepslate_bricks"},
        {pos: [7, 4, 24], state: "minecraft:deepslate_bricks"},
        {pos: [8, 4, 0], state: "minecraft:deepslate_bricks"},
        {pos: [8, 4, 1], state: "minecraft:gravel"},
        {pos: [8, 4, 2], state: "minecraft:gravel"},
        {pos: [8, 4, 3], state: "minecraft:piston_head{facing:up,short:false,type:sticky}"},
        {pos: [8, 4, 4], state: "minecraft:gravel"},
        {pos: [8, 4, 5], state: "minecraft:gravel"},
        {pos: [8, 4, 6], state: "minecraft:gravel"},
        {pos: [8, 4, 7], state: "minecraft:gravel"},
        {pos: [8, 4, 8], state: "minecraft:gravel"},
        {pos: [8, 4, 9], state: "minecraft:gravel"},
        {pos: [8, 4, 10], state: "minecraft:gravel"},
        {pos: [8, 4, 11], state: "minecraft:gravel"},
        {pos: [8, 4, 12], state: "minecraft:gravel"},
        {pos: [8, 4, 13], state: "minecraft:gravel"},
        {pos: [8, 4, 14], state: "minecraft:gravel"},
        {pos: [8, 4, 15], state: "minecraft:gravel"},
        {pos: [8, 4, 16], state: "minecraft:gravel"},
        {pos: [8, 4, 17], state: "minecraft:gravel"},
        {pos: [8, 4, 18], state: "minecraft:gravel"},
        {pos: [8, 4, 19], state: "minecraft:gravel"},
        {pos: [8, 4, 20], state: "minecraft:gravel"},
        {pos: [8, 4, 21], state: "minecraft:piston_head{facing:up,short:false,type:sticky}"},
        {pos: [8, 4, 22], state: "minecraft:gravel"},
        {pos: [8, 4, 23], state: "minecraft:gravel"},
        {pos: [8, 4, 24], state: "minecraft:deepslate_bricks"},
        {pos: [9, 4, 0], state: "minecraft:deepslate_bricks"},
        {pos: [9, 4, 1], state: "minecraft:gravel"},
        {pos: [9, 4, 2], state: "minecraft:gravel"},
        {pos: [9, 4, 3], state: "minecraft:piston_head{facing:up,short:false,type:sticky}"},
        {pos: [9, 4, 4], state: "minecraft:gravel"},
        {pos: [9, 4, 5], state: "minecraft:gravel"},
        {pos: [9, 4, 6], state: "minecraft:gravel"},
        {pos: [9, 4, 7], state: "minecraft:gravel"},
        {pos: [9, 4, 8], state: "minecraft:gravel"},
        {pos: [9, 4, 9], state: "minecraft:gravel"},
        {pos: [9, 4, 10], state: "minecraft:gravel"},
        {pos: [9, 4, 11], state: "minecraft:gravel"},
        {pos: [9, 4, 12], state: "minecraft:gravel"},
        {pos: [9, 4, 13], state: "minecraft:gravel"},
        {pos: [9, 4, 14], state: "minecraft:gravel"},
        {pos: [9, 4, 15], state: "minecraft:gravel"},
        {pos: [9, 4, 16], state: "minecraft:gravel"},
        {pos: [9, 4, 17], state: "minecraft:gravel"},
        {pos: [9, 4, 18], state: "minecraft:gravel"},
        {pos: [9, 4, 19], state: "minecraft:gravel"},
        {pos: [9, 4, 20], state: "minecraft:gravel"},
        {pos: [9, 4, 21], state: "minecraft:piston_head{facing:up,short:false,type:sticky}"},
        {pos: [9, 4, 22], state: "minecraft:gravel"},
        {pos: [9, 4, 23], state: "minecraft:gravel"},
        {pos: [9, 4, 24], state: "minecraft:deepslate_bricks"},
        {pos: [10, 4, 0], state: "minecraft:deepslate_bricks"},
        {pos: [10, 4, 1], state: "minecraft:gravel"},
        {pos: [10, 4, 2], state: "minecraft:gravel"},
        {pos: [10, 4, 3], state: "minecraft:piston_head{facing:up,short:false,type:sticky}"},
        {pos: [10, 4, 4], state: "minecraft:gravel"},
        {pos: [10, 4, 5], state: "minecraft:gravel"},
        {pos: [10, 4, 6], state: "minecraft:gravel"},
        {pos: [10, 4, 7], state: "minecraft:gravel"},
        {pos: [10, 4, 8], state: "minecraft:gravel"},
        {pos: [10, 4, 9], state: "minecraft:gravel"},
        {pos: [10, 4, 10], state: "minecraft:gravel"},
        {pos: [10, 4, 11], state: "minecraft:deepslate_bricks"},
        {pos: [10, 4, 12], state: "minecraft:deepslate_bricks"},
        {pos: [10, 4, 13], state: "minecraft:deepslate_bricks"},
        {pos: [10, 4, 14], state: "minecraft:gravel"},
        {pos: [10, 4, 15], state: "minecraft:gravel"},
        {pos: [10, 4, 16], state: "minecraft:gravel"},
        {pos: [10, 4, 17], state: "minecraft:gravel"},
        {pos: [10, 4, 18], state: "minecraft:gravel"},
        {pos: [10, 4, 19], state: "minecraft:gravel"},
        {pos: [10, 4, 20], state: "minecraft:gravel"},
        {pos: [10, 4, 21], state: "minecraft:piston_head{facing:up,short:false,type:sticky}"},
        {pos: [10, 4, 22], state: "minecraft:gravel"},
        {pos: [10, 4, 23], state: "minecraft:gravel"},
        {pos: [10, 4, 24], state: "minecraft:deepslate_bricks"},
        {pos: [11, 4, 0], state: "minecraft:deepslate_bricks"},
        {pos: [11, 4, 1], state: "minecraft:deepslate_bricks"},
        {pos: [11, 4, 2], state: "minecraft:deepslate_bricks"},
        {pos: [11, 4, 3], state: "minecraft:deepslate_bricks"},
        {pos: [11, 4, 4], state: "minecraft:deepslate_bricks"},
        {pos: [11, 4, 5], state: "minecraft:gravel"},
        {pos: [11, 4, 6], state: "minecraft:gravel"},
        {pos: [11, 4, 7], state: "minecraft:gravel"},
        {pos: [11, 4, 8], state: "minecraft:gravel"},
        {pos: [11, 4, 9], state: "minecraft:gravel"},
        {pos: [11, 4, 10], state: "minecraft:gravel"},
        {pos: [11, 4, 11], state: "minecraft:deepslate_bricks"},
        {pos: [11, 4, 12], state: "minecraft:deepslate_bricks"},
        {pos: [11, 4, 13], state: "minecraft:deepslate_bricks"},
        {pos: [11, 4, 14], state: "minecraft:gravel"},
        {pos: [11, 4, 15], state: "minecraft:gravel"},
        {pos: [11, 4, 16], state: "minecraft:gravel"},
        {pos: [11, 4, 17], state: "minecraft:gravel"},
        {pos: [11, 4, 18], state: "minecraft:gravel"},
        {pos: [11, 4, 19], state: "minecraft:gravel"},
        {pos: [11, 4, 20], state: "minecraft:deepslate_bricks"},
        {pos: [11, 4, 21], state: "minecraft:deepslate_bricks"},
        {pos: [11, 4, 22], state: "minecraft:deepslate_bricks"},
        {pos: [11, 4, 23], state: "minecraft:deepslate_bricks"},
        {pos: [11, 4, 24], state: "minecraft:deepslate_bricks"},
        {pos: [12, 4, 0], state: "minecraft:deepslate_bricks"},
        {pos: [12, 4, 1], state: "minecraft:gravel"},
        {pos: [12, 4, 2], state: "minecraft:gravel"},
        {pos: [12, 4, 3], state: "minecraft:piston_head{facing:up,short:false,type:sticky}"},
        {pos: [12, 4, 4], state: "minecraft:gravel"},
        {pos: [12, 4, 5], state: "minecraft:gravel"},
        {pos: [12, 4, 6], state: "minecraft:gravel"},
        {pos: [12, 4, 7], state: "minecraft:gravel"},
        {pos: [12, 4, 8], state: "minecraft:gravel"},
        {pos: [12, 4, 9], state: "minecraft:gravel"},
        {pos: [12, 4, 10], state: "minecraft:gravel"},
        {pos: [12, 4, 11], state: "minecraft:deepslate_bricks"},
        {pos: [12, 4, 12], state: "minecraft:deepslate_bricks"},
        {pos: [12, 4, 13], state: "minecraft:deepslate_bricks"},
        {pos: [12, 4, 14], state: "minecraft:gravel"},
        {pos: [12, 4, 15], state: "minecraft:gravel"},
        {pos: [12, 4, 16], state: "minecraft:gravel"},
        {pos: [12, 4, 17], state: "minecraft:gravel"},
        {pos: [12, 4, 18], state: "minecraft:gravel"},
        {pos: [12, 4, 19], state: "minecraft:gravel"},
        {pos: [12, 4, 20], state: "minecraft:gravel"},
        {pos: [12, 4, 21], state: "minecraft:piston_head{facing:up,short:false,type:sticky}"},
        {pos: [12, 4, 22], state: "minecraft:gravel"},
        {pos: [12, 4, 23], state: "minecraft:gravel"},
        {pos: [12, 4, 24], state: "minecraft:deepslate_bricks"},
        {pos: [13, 4, 0], state: "minecraft:deepslate_bricks"},
        {pos: [13, 4, 1], state: "minecraft:gravel"},
        {pos: [13, 4, 2], state: "minecraft:gravel"},
        {pos: [13, 4, 3], state: "minecraft:piston_head{facing:up,short:false,type:sticky}"},
        {pos: [13, 4, 4], state: "minecraft:gravel"},
        {pos: [13, 4, 5], state: "minecraft:gravel"},
        {pos: [13, 4, 6], state: "minecraft:gravel"},
        {pos: [13, 4, 7], state: "minecraft:gravel"},
        {pos: [13, 4, 8], state: "minecraft:gravel"},
        {pos: [13, 4, 9], state: "minecraft:gravel"},
        {pos: [13, 4, 10], state: "minecraft:gravel"},
        {pos: [13, 4, 11], state: "minecraft:gravel"},
        {pos: [13, 4, 12], state: "minecraft:gravel"},
        {pos: [13, 4, 13], state: "minecraft:gravel"},
        {pos: [13, 4, 14], state: "minecraft:gravel"},
        {pos: [13, 4, 15], state: "minecraft:gravel"},
        {pos: [13, 4, 16], state: "minecraft:gravel"},
        {pos: [13, 4, 17], state: "minecraft:gravel"},
        {pos: [13, 4, 18], state: "minecraft:gravel"},
        {pos: [13, 4, 19], state: "minecraft:gravel"},
        {pos: [13, 4, 20], state: "minecraft:gravel"},
        {pos: [13, 4, 21], state: "minecraft:piston_head{facing:up,short:false,type:sticky}"},
        {pos: [13, 4, 22], state: "minecraft:gravel"},
        {pos: [13, 4, 23], state: "minecraft:gravel"},
        {pos: [13, 4, 24], state: "minecraft:deepslate_bricks"},
        {pos: [14, 4, 0], state: "minecraft:deepslate_bricks"},
        {pos: [14, 4, 1], state: "minecraft:gravel"},
        {pos: [14, 4, 2], state: "minecraft:gravel"},
        {pos: [14, 4, 3], state: "minecraft:piston_head{facing:up,short:false,type:sticky}"},
        {pos: [14, 4, 4], state: "minecraft:gravel"},
        {pos: [14, 4, 5], state: "minecraft:gravel"},
        {pos: [14, 4, 6], state: "minecraft:gravel"},
        {pos: [14, 4, 7], state: "minecraft:gravel"},
        {pos: [14, 4, 8], state: "minecraft:gravel"},
        {pos: [14, 4, 9], state: "minecraft:gravel"},
        {pos: [14, 4, 10], state: "minecraft:gravel"},
        {pos: [14, 4, 11], state: "minecraft:gravel"},
        {pos: [14, 4, 12], state: "minecraft:gravel"},
        {pos: [14, 4, 13], state: "minecraft:gravel"},
        {pos: [14, 4, 14], state: "minecraft:gravel"},
        {pos: [14, 4, 15], state: "minecraft:gravel"},
        {pos: [14, 4, 16], state: "minecraft:gravel"},
        {pos: [14, 4, 17], state: "minecraft:gravel"},
        {pos: [14, 4, 18], state: "minecraft:gravel"},
        {pos: [14, 4, 19], state: "minecraft:gravel"},
        {pos: [14, 4, 20], state: "minecraft:gravel"},
        {pos: [14, 4, 21], state: "minecraft:piston_head{facing:up,short:false,type:sticky}"},
        {pos: [14, 4, 22], state: "minecraft:gravel"},
        {pos: [14, 4, 23], state: "minecraft:gravel"},
        {pos: [14, 4, 24], state: "minecraft:deepslate_bricks"},
        {pos: [15, 4, 0], state: "minecraft:deepslate_bricks"},
        {pos: [15, 4, 1], state: "minecraft:deepslate_bricks"},
        {pos: [15, 4, 2], state: "minecraft:deepslate_bricks"},
        {pos: [15, 4, 3], state: "minecraft:deepslate_bricks"},
        {pos: [15, 4, 4], state: "minecraft:deepslate_bricks"},
        {pos: [15, 4, 5], state: "minecraft:gravel"},
        {pos: [15, 4, 6], state: "minecraft:gravel"},
        {pos: [15, 4, 7], state: "minecraft:gravel"},
        {pos: [15, 4, 8], state: "minecraft:gravel"},
        {pos: [15, 4, 9], state: "minecraft:gravel"},
        {pos: [15, 4, 10], state: "minecraft:gravel"},
        {pos: [15, 4, 11], state: "minecraft:gravel"},
        {pos: [15, 4, 12], state: "minecraft:gravel"},
        {pos: [15, 4, 13], state: "minecraft:gravel"},
        {pos: [15, 4, 14], state: "minecraft:gravel"},
        {pos: [15, 4, 15], state: "minecraft:gravel"},
        {pos: [15, 4, 16], state: "minecraft:gravel"},
        {pos: [15, 4, 17], state: "minecraft:gravel"},
        {pos: [15, 4, 18], state: "minecraft:gravel"},
        {pos: [15, 4, 19], state: "minecraft:gravel"},
        {pos: [15, 4, 20], state: "minecraft:deepslate_bricks"},
        {pos: [15, 4, 21], state: "minecraft:deepslate_bricks"},
        {pos: [15, 4, 22], state: "minecraft:deepslate_bricks"},
        {pos: [15, 4, 23], state: "minecraft:deepslate_bricks"},
