{
    DataVersion: 3953,
    size: [31, 21, 35],
    data: [
        {pos: [6, 0, 18], state: "minecraft:deepslate_bricks"},
        {pos: [6, 0, 19], state: "minecraft:deepslate_bricks"},
        {pos: [6, 0, 20], state: "minecraft:deepslate_bricks"},
        {pos: [6, 0, 21], state: "minecraft:deepslate_bricks"},
        {pos: [6, 0, 22], state: "minecraft:deepslate_bricks"},
        {pos: [7, 0, 12], state: "minecraft:deepslate_bricks"},
        {pos: [7, 0, 13], state: "minecraft:deepslate_bricks"},
        {pos: [7, 0, 14], state: "minecraft:deepslate_bricks"},
        {pos: [7, 0, 15], state: "minecraft:deepslate_bricks"},
        {pos: [7, 0, 16], state: "minecraft:deepslate_bricks"},
        {pos: [7, 0, 17], state: "minecraft:deepslate_bricks"},
        {pos: [7, 0, 18], state: "minecraft:deepslate_bricks"},
        {pos: [7, 0, 19], state: "minecraft:deepslate_bricks"},
        {pos: [7, 0, 20], state: "minecraft:deepslate_bricks"},
        {pos: [7, 0, 21], state: "minecraft:deepslate_bricks"},
        {pos: [7, 0, 22], state: "minecraft:deepslate_bricks"},
        {pos: [8, 0, 12], state: "minecraft:deepslate_bricks"},
        {pos: [8, 0, 13], state: "minecraft:deepslate_bricks"},
        {pos: [8, 0, 14], state: "minecraft:deepslate_bricks"},
        {pos: [8, 0, 15], state: "minecraft:deepslate_bricks"},
        {pos: [8, 0, 16], state: "minecraft:deepslate_bricks"},
        {pos: [8, 0, 17], state: "minecraft:deepslate_bricks"},
        {pos: [8, 0, 18], state: "minecraft:deepslate_bricks"},
        {pos: [8, 0, 19], state: "minecraft:deepslate_bricks"},
        {pos: [8, 0, 20], state: "minecraft:deepslate_bricks"},
        {pos: [8, 0, 21], state: "minecraft:deepslate_bricks"},
        {pos: [8, 0, 22], state: "minecraft:deepslate_bricks"},
        {pos: [9, 0, 12], state: "minecraft:deepslate_bricks"},
        {pos: [9, 0, 13], state: "minecraft:deepslate_bricks"},
        {pos: [9, 0, 14], state: "minecraft:deepslate_bricks"},
        {pos: [9, 0, 15], state: "minecraft:deepslate_bricks"},
        {pos: [9, 0, 16], state: "minecraft:deepslate_bricks"},
        {pos: [9, 0, 17], state: "minecraft:deepslate_bricks"},
        {pos: [9, 0, 18], state: "minecraft:deepslate_bricks"},
        {pos: [9, 0, 19], state: "minecraft:deepslate_bricks"},
        {pos: [9, 0, 20], state: "minecraft:deepslate_bricks"},
        {pos: [9, 0, 21], state: "minecraft:deepslate_bricks"},
        {pos: [9, 0, 22], state: "minecraft:deepslate_bricks"},
        {pos: [10, 0, 12], state: "minecraft:deepslate_bricks"},
        {pos: [10, 0, 13], state: "minecraft:deepslate_bricks"},
        {pos: [10, 0, 14], state: "minecraft:deepslate_bricks"},
        {pos: [10, 0, 15], state: "minecraft:deepslate_bricks"},
        {pos: [10, 0, 16], state: "minecraft:deepslate_bricks"},
        {pos: [10, 0, 17], state: "minecraft:deepslate_bricks"},
        {pos: [10, 0, 18], state: "minecraft:deepslate_bricks"},
        {pos: [10, 0, 19], state: "minecraft:deepslate_bricks"},
        {pos: [10, 0, 20], state: "minecraft:deepslate_bricks"},
        {pos: [10, 0, 21], state: "minecraft:deepslate_bricks"},
        {pos: [10, 0, 22], state: "minecraft:deepslate_bricks"},
        {pos: [11, 0, 12], state: "minecraft:deepslate_bricks"},
        {pos: [11, 0, 13], state: "minecraft:deepslate_bricks"},
        {pos: [11, 0, 14], state: "minecraft:deepslate_bricks"},
        {pos: [11, 0, 15], state: "minecraft:deepslate_bricks"},
        {pos: [11, 0, 16], state: "minecraft:deepslate_bricks"},
        {pos: [11, 0, 17], state: "minecraft:deepslate_bricks"},
        {pos: [11, 0, 18], state: "minecraft:deepslate_bricks"},
        {pos: [11, 0, 19], state: "minecraft:deepslate_bricks"},
        {pos: [11, 0, 20], state: "minecraft:deepslate_bricks"},
        {pos: [11, 0, 21], state: "minecraft:deepslate_bricks"},
        {pos: [11, 0, 22], state: "minecraft:deepslate_bricks"},
        {pos: [12, 0, 12], state: "minecraft:deepslate_bricks"},
        {pos: [12, 0, 13], state: "minecraft:deepslate_bricks"},
        {pos: [12, 0, 14], state: "minecraft:deepslate_bricks"},
        {pos: [12, 0, 15], state: "minecraft:deepslate_bricks"},
        {pos: [12, 0, 16], state: "minecraft:deepslate_bricks"},
        {pos: [12, 0, 17], state: "minecraft:deepslate_bricks"},
        {pos: [12, 0, 18], state: "minecraft:deepslate_bricks"},
        {pos: [12, 0, 19], state: "minecraft:deepslate_bricks"},
        {pos: [12, 0, 20], state: "minecraft:deepslate_bricks"},
        {pos: [12, 0, 21], state: "minecraft:deepslate_bricks"},
        {pos: [12, 0, 22], state: "minecraft:deepslate_bricks"},
        {pos: [13, 0, 12], state: "minecraft:deepslate_bricks"},
        {pos: [13, 0, 13], state: "minecraft:deepslate_bricks"},
        {pos: [13, 0, 14], state: "minecraft:deepslate_bricks"},
        {pos: [13, 0, 15], state: "minecraft:deepslate_bricks"},
        {pos: [13, 0, 16], state: "minecraft:deepslate_bricks"},
        {pos: [13, 0, 17], state: "minecraft:deepslate_bricks"},
        {pos: [13, 0, 18], state: "minecraft:deepslate_bricks"},
        {pos: [13, 0, 19], state: "minecraft:deepslate_bricks"},
        {pos: [13, 0, 20], state: "minecraft:deepslate_bricks"},
        {pos: [13, 0, 21], state: "minecraft:deepslate_bricks"},
        {pos: [13, 0, 22], state: "minecraft:deepslate_bricks"},
        {pos: [14, 0, 12], state: "minecraft:deepslate_bricks"},
        {pos: [14, 0, 13], state: "minecraft:deepslate_bricks"},
        {pos: [14, 0, 14], state: "minecraft:deepslate_bricks"},
        {pos: [14, 0, 15], state: "minecraft:deepslate_bricks"},
        {pos: [14, 0, 16], state: "minecraft:deepslate_bricks"},
        {pos: [14, 0, 17], state: "minecraft:deepslate_bricks"},
        {pos: [14, 0, 18], state: "minecraft:deepslate_bricks"},
        {pos: [14, 0, 19], state: "minecraft:deepslate_bricks"},
        {pos: [14, 0, 20], state: "minecraft:deepslate_bricks"},
        {pos: [14, 0, 21], state: "minecraft:deepslate_bricks"},
        {pos: [14, 0, 22], state: "minecraft:deepslate_bricks"},
        {pos: [15, 0, 12], state: "minecraft:deepslate_bricks"},
        {pos: [15, 0, 13], state: "minecraft:deepslate_bricks"},
        {pos: [15, 0, 14], state: "minecraft:deepslate_bricks"},
        {pos: [15, 0, 15], state: "minecraft:deepslate_bricks"},
        {pos: [15, 0, 16], state: "minecraft:deepslate_bricks"},
        {pos: [15, 0, 17], state: "minecraft:deepslate_bricks"},
        {pos: [15, 0, 18], state: "minecraft:deepslate_bricks"},
        {pos: [15, 0, 19], state: "minecraft:deepslate_bricks"},
        {pos: [15, 0, 20], state: "minecraft:deepslate_bricks"},
        {pos: [15, 0, 21], state: "minecraft:deepslate_bricks"},
        {pos: [15, 0, 22], state: "minecraft:deepslate_bricks"},
        {pos: [16, 0, 12], state: "minecraft:deepslate_bricks"},
        {pos: [16, 0, 13], state: "minecraft:deepslate_bricks"},
        {pos: [16, 0, 14], state: "minecraft:deepslate_bricks"},
        {pos: [16, 0, 15], state: "minecraft:deepslate_bricks"},
        {pos: [16, 0, 16], state: "minecraft:deepslate_bricks"},
        {pos: [16, 0, 17], state: "minecraft:deepslate_bricks"},
        {pos: [16, 0, 18], state: "minecraft:deepslate_bricks"},
        {pos: [16, 0, 19], state: "minecraft:deepslate_bricks"},
        {pos: [16, 0, 20], state: "minecraft:deepslate_bricks"},
        {pos: [16, 0, 21], state: "minecraft:deepslate_bricks"},
        {pos: [16, 0, 22], state: "minecraft:deepslate_bricks"},
        {pos: [17, 0, 12], state: "minecraft:deepslate_bricks"},
        {pos: [17, 0, 13], state: "minecraft:deepslate_bricks"},
        {pos: [17, 0, 14], state: "minecraft:deepslate_bricks"},
        {pos: [17, 0, 15], state: "minecraft:deepslate_bricks"},
        {pos: [17, 0, 16], state: "minecraft:deepslate_bricks"},
        {pos: [17, 0, 17], state: "minecraft:deepslate_bricks"},
        {pos: [17, 0, 18], state: "minecraft:deepslate_bricks"},
        {pos: [17, 0, 19], state: "minecraft:deepslate_bricks"},
        {pos: [17, 0, 20], state: "minecraft:deepslate_bricks"},
        {pos: [17, 0, 21], state: "minecraft:deepslate_bricks"},
        {pos: [17, 0, 22], state: "minecraft:deepslate_bricks"},
        {pos: [18, 0, 12], state: "minecraft:deepslate_bricks"},
        {pos: [18, 0, 13], state: "minecraft:deepslate_bricks"},
        {pos: [18, 0, 14], state: "minecraft:deepslate_bricks"},
        {pos: [18, 0, 15], state: "minecraft:deepslate_bricks"},
        {pos: [18, 0, 16], state: "minecraft:deepslate_bricks"},
        {pos: [18, 0, 17], state: "minecraft:deepslate_bricks"},
        {pos: [18, 0, 18], state: "minecraft:deepslate_bricks"},
        {pos: [18, 0, 19], state: "minecraft:deepslate_bricks"},
        {pos: [18, 0, 20], state: "minecraft:deepslate_bricks"},
        {pos: [18, 0, 21], state: "minecraft:deepslate_bricks"},
        {pos: [18, 0, 22], state: "minecraft:deepslate_bricks"},
        {pos: [19, 0, 12], state: "minecraft:deepslate_bricks"},
        {pos: [19, 0, 13], state: "minecraft:deepslate_bricks"},
        {pos: [19, 0, 14], state: "minecraft:deepslate_bricks"},
        {pos: [19, 0, 15], state: "minecraft:deepslate_bricks"},
        {pos: [19, 0, 16], state: "minecraft:deepslate_bricks"},
        {pos: [19, 0, 17], state: "minecraft:deepslate_bricks"},
        {pos: [19, 0, 18], state: "minecraft:deepslate_bricks"},
        {pos: [19, 0, 19], state: "minecraft:deepslate_bricks"},
        {pos: [19, 0, 20], state: "minecraft:deepslate_bricks"},
        {pos: [19, 0, 21], state: "minecraft:deepslate_bricks"},
        {pos: [19, 0, 22], state: "minecraft:deepslate_bricks"},
        {pos: [20, 0, 12], state: "minecraft:deepslate_bricks"},
        {pos: [20, 0, 13], state: "minecraft:deepslate_bricks"},
        {pos: [20, 0, 14], state: "minecraft:deepslate_bricks"},
        {pos: [20, 0, 15], state: "minecraft:deepslate_bricks"},
        {pos: [20, 0, 16], state: "minecraft:deepslate_bricks"},
        {pos: [20, 0, 17], state: "minecraft:deepslate_bricks"},
        {pos: [20, 0, 18], state: "minecraft:deepslate_bricks"},
        {pos: [20, 0, 19], state: "minecraft:deepslate_bricks"},
        {pos: [20, 0, 20], state: "minecraft:deepslate_bricks"},
        {pos: [20, 0, 21], state: "minecraft:deepslate_bricks"},
        {pos: [20, 0, 22], state: "minecraft:deepslate_bricks"},
        {pos: [21, 0, 12], state: "minecraft:deepslate_bricks"},
        {pos: [21, 0, 13], state: "minecraft:deepslate_bricks"},
        {pos: [21, 0, 14], state: "minecraft:deepslate_bricks"},
        {pos: [21, 0, 15], state: "minecraft:deepslate_bricks"},
        {pos: [21, 0, 16], state: "minecraft:deepslate_bricks"},
        {pos: [21, 0, 17], state: "minecraft:deepslate_bricks"},
        {pos: [21, 0, 18], state: "minecraft:deepslate_bricks"},
        {pos: [21, 0, 19], state: "minecraft:deepslate_bricks"},
        {pos: [21, 0, 20], state: "minecraft:deepslate_bricks"},
        {pos: [21, 0, 21], state: "minecraft:deepslate_bricks"},
        {pos: [21, 0, 22], state: "minecraft:deepslate_bricks"},
        {pos: [22, 0, 12], state: "minecraft:deepslate_bricks"},
        {pos: [22, 0, 13], state: "minecraft:deepslate_bricks"},
        {pos: [22, 0, 14], state: "minecraft:deepslate_bricks"},
        {pos: [22, 0, 15], state: "minecraft:deepslate_bricks"},
        {pos: [22, 0, 16], state: "minecraft:deepslate_bricks"},
        {pos: [22, 0, 17], state: "minecraft:deepslate_bricks"},
        {pos: [22, 0, 18], state: "minecraft:deepslate_bricks"},
        {pos: [22, 0, 19], state: "minecraft:deepslate_bricks"},
        {pos: [22, 0, 20], state: "minecraft:deepslate_bricks"},
        {pos: [22, 0, 21], state: "minecraft:deepslate_bricks"},
        {pos: [22, 0, 22], state: "minecraft:deepslate_bricks"},
        {pos: [23, 0, 12], state: "minecraft:deepslate_bricks"},
        {pos: [23, 0, 13], state: "minecraft:deepslate_bricks"},
        {pos: [23, 0, 14], state: "minecraft:deepslate_bricks"},
        {pos: [23, 0, 15], state: "minecraft:deepslate_bricks"},
        {pos: [23, 0, 16], state: "minecraft:deepslate_bricks"},
        {pos: [23, 0, 17], state: "minecraft:deepslate_bricks"},
        {pos: [23, 0, 18], state: "minecraft:deepslate_bricks"},
        {pos: [23, 0, 19], state: "minecraft:deepslate_bricks"},
        {pos: [23, 0, 20], state: "minecraft:deepslate_bricks"},
        {pos: [23, 0, 21], state: "minecraft:deepslate_bricks"},
        {pos: [23, 0, 22], state: "minecraft:deepslate_bricks"},
        {pos: [24, 0, 12], state: "minecraft:deepslate_bricks"},
        {pos: [24, 0, 13], state: "minecraft:deepslate_bricks"},
        {pos: [24, 0, 14], state: "minecraft:deepslate_bricks"},
        {pos: [24, 0, 15], state: "minecraft:deepslate_bricks"},
        {pos: [24, 0, 16], state: "minecraft:deepslate_bricks"},
        {pos: [24, 0, 17], state: "minecraft:deepslate_bricks"},
        {pos: [6, 1, 18], state: "minecraft:deepslate_bricks"},
        {pos: [6, 1, 19], state: "minecraft:deepslate_bricks"},
        {pos: [6, 1, 20], state: "minecraft:deepslate_bricks"},
        {pos: [6, 1, 21], state: "minecraft:deepslate_bricks"},
        {pos: [6, 1, 22], state: "minecraft:deepslate_bricks"},
        {pos: [7, 1, 12], state: "minecraft:deepslate_bricks"},
        {pos: [7, 1, 13], state: "minecraft:deepslate_bricks"},
        {pos: [7, 1, 14], state: "minecraft:deepslate_bricks"},
        {pos: [7, 1, 15], state: "minecraft:deepslate_bricks"},
        {pos: [7, 1, 16], state: "minecraft:deepslate_bricks"},
        {pos: [7, 1, 17], state: "minecraft:deepslate_bricks"},
        {pos: [7, 1, 18], state: "minecraft:deepslate_bricks"},
        {pos: [7, 1, 19], state: "minecraft:gravel"},
        {pos: [7, 1, 20], state: "minecraft:gravel"},
        {pos: [7, 1, 21], state: "minecraft:gravel"},
        {pos: [7, 1, 22], state: "minecraft:deepslate_bricks"},
        {pos: [8, 1, 12], state: "minecraft:deepslate_bricks"},
        {pos: [8, 1, 13], state: "minecraft:gravel"},
        {pos: [8, 1, 14], state: "minecraft:gravel"},
        {pos: [8, 1, 15], state: "minecraft:gravel"},
        {pos: [8, 1, 16], state: "minecraft:deepslate_bricks"},
        {pos: [8, 1, 17], state: "minecraft:deepslate_bricks"},
        {pos: [8, 1, 18], state: "minecraft:deepslate_bricks"},
        {pos: [8, 1, 19], state: "minecraft:gravel"},
        {pos: [8, 1, 20], state: "minecraft:gravel"},
        {pos: [8, 1, 21], state: "minecraft:gravel"},
        {pos: [8, 1, 22], state: "minecraft:deepslate_bricks"},
        {pos: [9, 1, 12], state: "minecraft:deepslate_bricks"},
        {pos: [9, 1, 13], state: "minecraft:gravel"},
        {pos: [9, 1, 14], state: "minecraft:gravel"},
        {pos: [9, 1, 15], state: "minecraft:gravel"},
        {pos: [9, 1, 16], state: "minecraft:deepslate_bricks"},
        {pos: [9, 1, 17], state: "minecraft:deepslate_bricks"},
        {pos: [9, 1, 18], state: "minecraft:deepslate_bricks"},
        {pos: [9, 1, 19], state: "minecraft:gravel"},
        {pos: [9, 1, 20], state: "minecraft:gravel"},
        {pos: [9, 1, 21], state: "minecraft:gravel"},
        {pos: [9, 1, 22], state: "minecraft:deepslate_bricks"},
        {pos: [10, 1, 12], state: "minecraft:deepslate_bricks"},
        {pos: [10, 1, 13], state: "minecraft:gravel"},
        {pos: [10, 1, 14], state: "minecraft:gravel"},
        {pos: [10, 1, 15], state: "minecraft:gravel"},
        {pos: [10, 1, 16], state: "minecraft:deepslate_bricks"},
        {pos: [10, 1, 17], state: "minecraft:gravel"},
        {pos: [10, 1, 18], state: "minecraft:gravel"},
        {pos: [10, 1, 19], state: "minecraft:gravel"},
        {pos: [10, 1, 20], state: "minecraft:gravel"},
        {pos: [10, 1, 21], state: "minecraft:gravel"},
        {pos: [10, 1, 22], state: "minecraft:deepslate_bricks"},
        {pos: [11, 1, 12], state: "minecraft:deepslate_bricks"},
        {pos: [11, 1, 13], state: "minecraft:gravel"},
        {pos: [11, 1, 14], state: "minecraft:gravel"},
        {pos: [11, 1, 15], state: "minecraft:gravel"},
        {pos: [11, 1, 16], state: "minecraft:gravel"},
        {pos: [11, 1, 17], state: "minecraft:gravel"},
        {pos: [11, 1, 18], state: "minecraft:gravel"},
        {pos: [11, 1, 19], state: "minecraft:gravel"},
        {pos: [11, 1, 20], state: "minecraft:gravel"},
        {pos: [11, 1, 21], state: "minecraft:gravel"},
        {pos: [11, 1, 22], state: "minecraft:deepslate_bricks"},
        {pos: [12, 1, 12], state: "minecraft:deepslate_bricks"},
        {pos: [12, 1, 13], state: "minecraft:gravel"},
        {pos: [12, 1, 14], state: "minecraft:gravel"},
        {pos: [12, 1, 15], state: "minecraft:gravel"},
        {pos: [12, 1, 16], state: "minecraft:gravel"},
        {pos: [12, 1, 17], state: "minecraft:gravel"},
        {pos: [12, 1, 18], state: "minecraft:gravel"},
        {pos: [12, 1, 19], state: "minecraft:gravel"},
        {pos: [12, 1, 20], state: "minecraft:gravel"},
        {pos: [12, 1, 21], state: "minecraft:gravel"},
        {pos: [12, 1, 22], state: "minecraft:deepslate_bricks"},
        {pos: [13, 1, 12], state: "minecraft:deepslate_bricks"},
        {pos: [13, 1, 13], state: "minecraft:gravel"},
        {pos: [13, 1, 14], state: "minecraft:gravel"},
        {pos: [13, 1, 15], state: "minecraft:gravel"},
        {pos: [13, 1, 16], state: "minecraft:gravel"},
        {pos: [13, 1, 17], state: "minecraft:gravel"},
        {pos: [13, 1, 18], state: "minecraft:gravel"},
        {pos: [13, 1, 19], state: "minecraft:gravel"},
        {pos: [13, 1, 20], state: "minecraft:gravel"},
        {pos: [13, 1, 21], state: "minecraft:gravel"},
        {pos: [13, 1, 22], state: "minecraft:deepslate_bricks"},
        {pos: [14, 1, 12], state: "minecraft:deepslate_bricks"},
        {pos: [14, 1, 13], state: "minecraft:gravel"},
        {pos: [14, 1, 14], state: "minecraft:gravel"},
        {pos: [14, 1, 15], state: "minecraft:gravel"},
        {pos: [14, 1, 16], state: "minecraft:deepslate_bricks"},
        {pos: [14, 1, 17], state: "minecraft:gravel"},
        {pos: [14, 1, 18], state: "minecraft:deepslate_bricks"},
        {pos: [14, 1, 19], state: "minecraft:gravel"},
        {pos: [14, 1, 20], state: "minecraft:gravel"},
        {pos: [14, 1, 21], state: "minecraft:deepslate_bricks"},
        {pos: [14, 1, 22], state: "minecraft:deepslate_bricks"},
        {pos: [15, 1, 12], state: "minecraft:deepslate_bricks"},
        {pos: [15, 1, 13], state: "minecraft:deepslate_bricks"},
        {pos: [15, 1, 14], state: "minecraft:gravel"},
        {pos: [15, 1, 15], state: "minecraft:gravel"},
        {pos: [15, 1, 16], state: "minecraft:gravel"},
        {pos: [15, 1, 17], state: "minecraft:deepslate_bricks"},
        {pos: [15, 1, 18], state: "minecraft:gravel"},
        {pos: [15, 1, 19], state: "minecraft:gravel"},
        {pos: [15, 1, 20], state: "minecraft:gravel"},
        {pos: [15, 1, 21], state: "minecraft:deepslate_bricks"},
        {pos: [15, 1, 22], state: "minecraft:deepslate_bricks"},
        {pos: [16, 1, 12], state: "minecraft:deepslate_bricks"},
        {pos: [16, 1, 13], state: "minecraft:deepslate_bricks"},
        {pos: [16, 1, 14], state: "minecraft:gravel"},
        {pos: [16, 1, 15], state: "minecraft:gravel"},
        {pos: [16, 1, 16], state: "minecraft:deepslate_bricks"},
        {pos: [16, 1, 17], state: "minecraft:gravel"},
        {pos: [16, 1, 18], state: "minecraft:deepslate_bricks"},
        {pos: [16, 1, 19], state: "minecraft:gravel"},
        {pos: [16, 1, 20], state: "minecraft:gravel"},
        {pos: [16, 1, 21], state: "minecraft:gravel"},
        {pos: [16, 1, 22], state: "minecraft:deepslate_bricks"},
        {pos: [17, 1, 12], state: "minecraft:deepslate_bricks"},
        {pos: [17, 1, 13], state: "minecraft:gravel"},
        {pos: [17, 1, 14], state: "minecraft:gravel"},
        {pos: [17, 1, 15], state: "minecraft:gravel"},
        {pos: [17, 1, 16], state: "minecraft:gravel"},
        {pos: [17, 1, 17], state: "minecraft:gravel"},
        {pos: [17, 1, 18], state: "minecraft:gravel"},
        {pos: [17, 1, 19], state: "minecraft:gravel"},
        {pos: [17, 1, 20], state: "minecraft:gravel"},
        {pos: [17, 1, 21], state: "minecraft:gravel"},
        {pos: [17, 1, 22], state: "minecraft:deepslate_bricks"},
        {pos: [18, 1, 12], state: "minecraft:deepslate_bricks"},
        {pos: [18, 1, 13], state: "minecraft:gravel"},
        {pos: [18, 1, 14], state: "minecraft:gravel"},
        {pos: [18, 1, 15], state: "minecraft:gravel"},
        {pos: [18, 1, 16], state: "minecraft:gravel"},
        {pos: [18, 1, 17], state: "minecraft:gravel"},
        {pos: [18, 1, 18], state: "minecraft:gravel"},
        {pos: [18, 1, 19], state: "minecraft:gravel"},
        {pos: [18, 1, 20], state: "minecraft:gravel"},
        {pos: [18, 1, 21], state: "minecraft:gravel"},
        {pos: [18, 1, 22], state: "minecraft:deepslate_bricks"},
        {pos: [19, 1, 12], state: "minecraft:deepslate_bricks"},
        {pos: [19, 1, 13], state: "minecraft:gravel"},
        {pos: [19, 1, 14], state: "minecraft:gravel"},
        {pos: [19, 1, 15], state: "minecraft:gravel"},
        {pos: [19, 1, 16], state: "minecraft:gravel"},
        {pos: [19, 1, 17], state: "minecraft:gravel"},
        {pos: [19, 1, 18], state: "minecraft:gravel"},
        {pos: [19, 1, 19], state: "minecraft:gravel"},
        {pos: [19, 1, 20], state: "minecraft:gravel"},
        {pos: [19, 1, 21], state: "minecraft:gravel"},
        {pos: [19, 1, 22], state: "minecraft:deepslate_bricks"},
        {pos: [20, 1, 12], state: "minecraft:deepslate_bricks"},
        {pos: [20, 1, 13], state: "minecraft:gravel"},
        {pos: [20, 1, 14], state: "minecraft:gravel"},
        {pos: [20, 1, 15], state: "minecraft:gravel"},
        {pos: [20, 1, 16], state: "minecraft:gravel"},
        {pos: [20, 1, 17], state: "minecraft:gravel"},
        {pos: [20, 1, 18], state: "minecraft:deepslate_bricks"},
        {pos: [20, 1, 19], state: "minecraft:gravel"},
        {pos: [20, 1, 20], state: "minecraft:gravel"},
        {pos: [20, 1, 21], state: "minecraft:gravel"},
        {pos: [20, 1, 22], state: "minecraft:deepslate_bricks"},
        {pos: [21, 1, 12], state: "minecraft:deepslate_bricks"},
        {pos: [21, 1, 13], state: "minecraft:gravel"},
        {pos: [21, 1, 14], state: "minecraft:gravel"},
        {pos: [21, 1, 15], state: "minecraft:gravel"},
        {pos: [21, 1, 16], state: "minecraft:deepslate_bricks"},
        {pos: [21, 1, 17], state: "minecraft:gravel"},
        {pos: [21, 1, 18], state: "minecraft:deepslate_bricks"},
        {pos: [21, 1, 19], state: "minecraft:gravel"},
        {pos: [21, 1, 20], state: "minecraft:gravel"},
        {pos: [21, 1, 21], state: "minecraft:gravel"},
        {pos: [21, 1, 22], state: "minecraft:deepslate_bricks"},
        {pos: [22, 1, 12], state: "minecraft:deepslate_bricks"},
        {pos: [22, 1, 13], state: "minecraft:gravel"},
        {pos: [22, 1, 14], state: "minecraft:gravel"},
        {pos: [22, 1, 15], state: "minecraft:gravel"},
        {pos: [22, 1, 16], state: "minecraft:deepslate_bricks"},
        {pos: [22, 1, 17], state: "minecraft:deepslate_bricks"},
        {pos: [22, 1, 18], state: "minecraft:deepslate_bricks"},
        {pos: [22, 1, 19], state: "minecraft:gravel"},
        {pos: [22, 1, 20], state: "minecraft:gravel"},
        {pos: [22, 1, 21], state: "minecraft:gravel"},
        {pos: [22, 1, 22], state: "minecraft:deepslate_bricks"},
        {pos: [23, 1, 12], state: "minecraft:deepslate_bricks"},
        {pos: [23, 1, 13], state: "minecraft:gravel"},
        {pos: [23, 1, 14], state: "minecraft:gravel"},
        {pos: [23, 1, 15], state: "minecraft:gravel"},
        {pos: [23, 1, 16], state: "minecraft:deepslate_bricks"},
        {pos: [23, 1, 17], state: "minecraft:deepslate_bricks"},
        {pos: [23, 1, 18], state: "minecraft:deepslate_bricks"},
        {pos: [23, 1, 19], state: "minecraft:deepslate_bricks"},
        {pos: [23, 1, 20], state: "minecraft:deepslate_bricks"},
        {pos: [23, 1, 21], state: "minecraft:deepslate_bricks"},
        {pos: [23, 1, 22], state: "minecraft:deepslate_bricks"},
        {pos: [24, 1, 12], state: "minecraft:deepslate_bricks"},
        {pos: [24, 1, 13], state: "minecraft:deepslate_bricks"},
        {pos: [24, 1, 14], state: "minecraft:deepslate_bricks"},
        {pos: [24, 1, 15], state: "minecraft:deepslate_bricks"},
        {pos: [24, 1, 16], state: "minecraft:deepslate_bricks"},
        {pos: [24, 1, 17], state: "minecraft:deepslate_bricks"},
        {pos: [6, 2, 18], state: "minecraft:deepslate_bricks"},
        {pos: [6, 2, 19], state: "minecraft:deepslate_bricks"},
        {pos: [6, 2, 20], state: "minecraft:deepslate_bricks"},
        {pos: [6, 2, 21], state: "minecraft:deepslate_bricks"},
        {pos: [6, 2, 22], state: "minecraft:deepslate_bricks"},
        {pos: [7, 2, 12], state: "minecraft:deepslate_bricks"},
        {pos: [7, 2, 13], state: "minecraft:deepslate_bricks"},
        {pos: [7, 2, 14], state: "minecraft:deepslate_bricks"},
        {pos: [7, 2, 15], state: "minecraft:deepslate_bricks"},
        {pos: [7, 2, 16], state: "minecraft:deepslate_bricks"},
        {pos: [7, 2, 17], state: "minecraft:deepslate_bricks"},
        {pos: [7, 2, 18], state: "minecraft:deepslate_bricks"},
        {pos: [7, 2, 19], state: "minecraft:deepslate_bricks"},
        {pos: [7, 2, 20], state: "minecraft:deepslate_bricks"},
        {pos: [7, 2, 21], state: "minecraft:deepslate_bricks"},
        {pos: [7, 2, 22], state: "minecraft:deepslate_bricks"},
        {pos: [8, 2, 12], state: "minecraft:deepslate_bricks"},
        {pos: [8, 2, 13], state: "minecraft:deepslate_bricks"},
        {pos: [8, 2, 14], state: "minecraft:deepslate_bricks"},
        {pos: [8, 2, 15], state: "minecraft:deepslate_bricks"},
        {pos: [8, 2, 16], state: "minecraft:deepslate_bricks"},
        {pos: [8, 2, 17], state: "minecraft:deepslate_bricks"},
        {pos: [8, 2, 18], state: "minecraft:deepslate_bricks"},
        {pos: [8, 2, 19], state: "minecraft:deepslate_brick_stairs{facing:south,half:bottom,shape:straight,waterlogged:false}"},
        {pos: [8, 2, 20], state: "trailiertales:coffin{facing:east,part:foot,state:inactive}", nbt: {id: "trailiertales:coffin", max_active_light_level: 7, uuid: "672e5e3d-b2d4-4657-9672-94c17d021dad"}},
        {pos: [8, 2, 21], state: "minecraft:deepslate_brick_stairs{facing:north,half:bottom,shape:straight,waterlogged:false}"},
        {pos: [8, 2, 22], state: "minecraft:deepslate_bricks"},
        {pos: [9, 2, 12], state: "minecraft:deepslate_bricks"},
        {pos: [9, 2, 13], state: "minecraft:deepslate_brick_stairs{facing:south,half:bottom,shape:straight,waterlogged:false}"},
        {pos: [9, 2, 14], state: "trailiertales:coffin{facing:west,part:head,state:inactive}", nbt: {id: "trailiertales:coffin"}},
        {pos: [9, 2, 15], state: "minecraft:deepslate_brick_stairs{facing:north,half:bottom,shape:straight,waterlogged:false}"},
        {pos: [9, 2, 16], state: "minecraft:deepslate_bricks"},
        {pos: [9, 2, 17], state: "minecraft:deepslate_bricks"},
        {pos: [9, 2, 18], state: "minecraft:deepslate_bricks"},
        {pos: [9, 2, 19], state: "minecraft:deepslate_brick_stairs{facing:south,half:bottom,shape:straight,waterlogged:false}"},
        {pos: [9, 2, 20], state: "trailiertales:coffin{facing:east,part:head,state:inactive}", nbt: {id: "trailiertales:coffin"}},
        {pos: [9, 2, 21], state: "minecraft:deepslate_brick_stairs{facing:north,half:bottom,shape:straight,waterlogged:false}"},
        {pos: [9, 2, 22], state: "minecraft:deepslate_bricks"},
        {pos: [10, 2, 12], state: "minecraft:deepslate_bricks"},
        {pos: [10, 2, 13], state: "minecraft:deepslate_brick_stairs{facing:south,half:bottom,shape:straight,waterlogged:false}"},
        {pos: [10, 2, 14], state: "trailiertales:coffin{facing:west,part:foot,state:inactive}", nbt: {id: "trailiertales:coffin", max_active_light_level: 7, uuid: "77c551ea-b614-4584-a89b-7aeb603b3c05"}},
        {pos: [10, 2, 15], state: "minecraft:deepslate_brick_stairs{facing:north,half:bottom,shape:straight,waterlogged:false}"},
        {pos: [10, 2, 16], state: "minecraft:deepslate_bricks"},
        {pos: [10, 2, 17], state: "minecraft:deepslate_brick_stairs{facing:west,half:top,shape:straight,waterlogged:false}"},
        {pos: [10, 2, 18], state: "minecraft:deepslate_bricks"},
        {pos: [10, 2, 19], state: "minecraft:skeleton_skull{powered:false,rotation:4}", nbt: {id: "minecraft:skull"}},
        {pos: [10, 2, 20], state: "minecraft:candle{candles:4,lit:false,waterlogged:false}"},
        {pos: [10, 2, 21], state: "minecraft:candle{candles:4,lit:false,waterlogged:false}"},
        {pos: [10, 2, 22], state: "minecraft:deepslate_bricks"},
        {pos: [11, 2, 12], state: "minecraft:deepslate_bricks"},
        {pos: [11, 2, 13], state: "minecraft:candle{candles:4,lit:false,waterlogged:false}"},
        {pos: [11, 2, 14], state: "minecraft:candle{candles:4,lit:false,waterlogged:false}"},
        {pos: [11, 2, 15], state: "minecraft:candle{candles:4,lit:false,waterlogged:false}"},
        {pos: [11, 2, 16], state: "minecraft:skeleton_skull{powered:false,rotation:4}", nbt: {id: "minecraft:skull"}},
        {pos: [11, 2, 17], state: "minecraft:candle{candles:4,lit:false,waterlogged:false}"},
        {pos: [11, 2, 18], state: "minecraft:candle{candles:4,lit:false,waterlogged:false}"},
        {pos: [11, 2, 19], state: "minecraft:cave_air"},
        {pos: [11, 2, 20], state: "minecraft:cave_air"},
        {pos: [11, 2, 21], state: "minecraft:candle{candles:4,lit:false,waterlogged:false}"},
        {pos: [11, 2, 22], state: "minecraft:deepslate_bricks"},
        {pos: [12, 2, 12], state: "minecraft:deepslate_bricks"},
        {pos: [12, 2, 13], state: "minecraft:skeleton_skull{powered:false,rotation:8}", nbt: {id: "minecraft:skull"}},
        {pos: [12, 2, 14], state: "minecraft:cave_air"},
        {pos: [12, 2, 15], state: "minecraft:cave_air"},
        {pos: [12, 2, 16], state: "minecraft:cave_air"},
        {pos: [12, 2, 17], state: "minecraft:cave_air"},
        {pos: [12, 2, 18], state: "minecraft:cave_air"},
        {pos: [12, 2, 19], state: "minecraft:cave_air"},
        {pos: [12, 2, 20], state: "minecraft:cave_air"},
        {pos: [12, 2, 21], state: "minecraft:candle{candles:4,lit:false,waterlogged:false}"},
        {pos: [12, 2, 22], state: "minecraft:deepslate_bricks"},
        {pos: [13, 2, 10], state: "minecraft:deepslate_bricks"},
        {pos: [13, 2, 11], state: "minecraft:deepslate_bricks"},
        {pos: [13, 2, 12], state: "minecraft:deepslate_bricks"},
        {pos: [13, 2, 13], state: "minecraft:candle{candles:4,lit:false,waterlogged:false}"},
        {pos: [13, 2, 14], state: "minecraft:cave_air"},
        {pos: [13, 2, 15], state: "minecraft:cave_air"},
        {pos: [13, 2, 16], state: "minecraft:candle{candles:4,lit:false,waterlogged:false}"},
        {pos: [13, 2, 17], state: "minecraft:candle{candles:4,lit:false,waterlogged:false}"},
        {pos: [13, 2, 18], state: "minecraft:decorated_pot{cracked:false,facing:south,waterlogged:false}", nbt: {id: "minecraft:decorated_pot"}},
        {pos: [13, 2, 19], state: "minecraft:cave_air"},
        {pos: [13, 2, 20], state: "minecraft:cave_air"},
        {pos: [13, 2, 21], state: "minecraft:candle{candles:4,lit:false,waterlogged:false}"},
        {pos: [13, 2, 22], state: "minecraft:deepslate_bricks"},
        {pos: [13, 2, 23], state: "minecraft:deepslate_bricks"},
        {pos: [13, 2, 24], state: "minecraft:deepslate_bricks"},
        {pos: [14, 2, 10], state: "minecraft:deepslate_bricks"},
        {pos: [14, 2, 11], state: "minecraft:deepslate_bricks"},
        {pos: [14, 2, 12], state: "minecraft:deepslate_brick_stairs{facing:north,half:bottom,shape:straight,waterlogged:false}"},
        {pos: [14, 2, 13], state: "minecraft:cave_air"},
        {pos: [14, 2, 14], state: "minecraft:cave_air"},
        {pos: [14, 2, 15], state: "minecraft:candle{candles:4,lit:false,waterlogged:false}"},
        {pos: [14, 2, 16], state: "minecraft:deepslate_bricks"},
        {pos: [14, 2, 17], state: "minecraft:deepslate_brick_stairs{facing:east,half:top,shape:straight,waterlogged:false}"},
        {pos: [14, 2, 18], state: "minecraft:deepslate_bricks"},
        {pos: [14, 2, 19], state: "minecraft:candle{candles:4,lit:false,waterlogged:false}"},
        {pos: [14, 2, 20], state: "minecraft:cave_air"},
        {pos: [14, 2, 21], state: "minecraft:cave_air"},
        {pos: [14, 2, 22], state: "minecraft:deepslate_brick_stairs{facing:south,half:bottom,shape:straight,waterlogged:false}"},
        {pos: [14, 2, 23], state: "minecraft:deepslate_bricks"},
        {pos: [14, 2, 24], state: "minecraft:deepslate_bricks"},
        {pos: [15, 2, 10], state: "minecraft:deepslate_bricks"},
        {pos: [15, 2, 11], state: "minecraft:deepslate_bricks"},
        {pos: [15, 2, 12], state: "minecraft:deepslate_brick_stairs{facing:north,half:bottom,shape:straight,waterlogged:false}"},
        {pos: [15, 2, 13], state: "minecraft:cave_air"},
        {pos: [15, 2, 14], state: "minecraft:cave_air"},
        {pos: [15, 2, 15], state: "minecraft:candle{candles:4,lit:false,waterlogged:false}"},
        {pos: [15, 2, 16], state: "minecraft:chest{facing:north,type:single,waterlogged:false}", nbt: {Items: [], id: "minecraft:chest"}},
        {pos: [15, 2, 17], state: "minecraft:deepslate_bricks"},
        {pos: [15, 2, 18], state: "minecraft:chest{facing:south,type:single,waterlogged:false}", nbt: {Items: [], id: "minecraft:chest"}},
        {pos: [15, 2, 19], state: "minecraft:candle{candles:4,lit:false,waterlogged:false}"},
        {pos: [15, 2, 20], state: "minecraft:cave_air"},
        {pos: [15, 2, 21], state: "minecraft:cave_air"},
        {pos: [15, 2, 22], state: "minecraft:deepslate_brick_stairs{facing:south,half:bottom,shape:straight,waterlogged:false}"},
        {pos: [15, 2, 23], state: "minecraft:deepslate_bricks"},
        {pos: [15, 2, 24], state: "minecraft:deepslate_bricks"},
        {pos: [16, 2, 10], state: "minecraft:deepslate_bricks"},
        {pos: [16, 2, 11], state: "minecraft:deepslate_bricks"},
        {pos: [16, 2, 12], state: "minecraft:deepslate_brick_stairs{facing:north,half:bottom,shape:straight,waterlogged:false}"},
        {pos: [16, 2, 13], state: "minecraft:cave_air"},
        {pos: [16, 2, 14], state: "minecraft:cave_air"},
        {pos: [16, 2, 15], state: "minecraft:candle{candles:4,lit:false,waterlogged:false}"},
        {pos: [16, 2, 16], state: "minecraft:deepslate_bricks"},
        {pos: [16, 2, 17], state: "minecraft:deepslate_brick_stairs{facing:west,half:top,shape:straight,waterlogged:false}"},
        {pos: [16, 2, 18], state: "minecraft:deepslate_bricks"},
        {pos: [16, 2, 19], state: "minecraft:candle{candles:4,lit:false,waterlogged:false}"},
        {pos: [16, 2, 20], state: "minecraft:cave_air"},
        {pos: [16, 2, 21], state: "minecraft:cave_air"},
        {pos: [16, 2, 22], state: "minecraft:deepslate_brick_stairs{facing:south,half:bottom,shape:straight,waterlogged:false}"},
        {pos: [16, 2, 23], state: "minecraft:deepslate_bricks"},
        {pos: [16, 2, 24], state: "minecraft:deepslate_bricks"},
        {pos: [17, 2, 10], state: "minecraft:deepslate_bricks"},
        {pos: [17, 2, 11], state: "minecraft:deepslate_bricks"},
        {pos: [17, 2, 12], state: "minecraft:deepslate_bricks"},
        {pos: [17, 2, 13], state: "minecraft:candle{candles:4,lit:false,waterlogged:false}"},
        {pos: [17, 2, 14], state: "minecraft:cave_air"},
        {pos: [17, 2, 15], state: "minecraft:cave_air"},
        {pos: [17, 2, 16], state: "minecraft:decorated_pot{cracked:false,facing:north,waterlogged:false}", nbt: {id: "minecraft:decorated_pot"}},
        {pos: [17, 2, 17], state: "minecraft:candle{candles:4,lit:false,waterlogged:false}"},
        {pos: [17, 2, 18], state: "minecraft:candle{candles:4,lit:false,waterlogged:false}"},
        {pos: [17, 2, 19], state: "minecraft:skeleton_skull{powered:false,rotation:8}", nbt: {id: "minecraft:skull"}},
        {pos: [17, 2, 20], state: "minecraft:cave_air"},
        {pos: [17, 2, 21], state: "minecraft:candle{candles:4,lit:false,waterlogged:false}"},
        {pos: [17, 2, 22], state: "minecraft:deepslate_bricks"},
        {pos: [17, 2, 23], state: "minecraft:deepslate_bricks"},
        {pos: [17, 2, 24], state: "minecraft:deepslate_bricks"},
        {pos: [18, 2, 12], state: "minecraft:deepslate_bricks"},
        {pos: [18, 2, 13], state: "minecraft:candle{candles:4,lit:false,waterlogged:false}"},
        {pos: [18, 2, 14], state: "minecraft:cave_air"},
        {pos: [18, 2, 15], state: "minecraft:cave_air"},
        {pos: [18, 2, 16], state: "minecraft:cave_air"},
        {pos: [18, 2, 17], state: "minecraft:cave_air"},
        {pos: [18, 2, 18], state: "minecraft:cave_air"},
        {pos: [18, 2, 19], state: "minecraft:cave_air"},
        {pos: [18, 2, 20], state: "minecraft:cave_air"},
        {pos: [18, 2, 21], state: "minecraft:candle{candles:4,lit:false,waterlogged:false}"},
        {pos: [18, 2, 22], state: "minecraft:deepslate_bricks"},
        {pos: [19, 2, 12], state: "minecraft:deepslate_bricks"},
        {pos: [19, 2, 13], state: "minecraft:candle{candles:4,lit:false,waterlogged:false}"},
        {pos: [19, 2, 14], state: "minecraft:cave_air"},
        {pos: [19, 2, 15], state: "minecraft:cave_air"},
        {pos: [19, 2, 16], state: "minecraft:candle{candles:4,lit:false,waterlogged:false}"},
        {pos: [19, 2, 17], state: "minecraft:candle{candles:4,lit:false,waterlogged:false}"},
        {pos: [19, 2, 18], state: "minecraft:candle{candles:4,lit:false,waterlogged:false}"},
        {pos: [19, 2, 19], state: "minecraft:candle{candles:4,lit:false,waterlogged:false}"},
        {pos: [19, 2, 20], state: "minecraft:candle{candles:4,lit:false,waterlogged:false}"},
        {pos: [19, 2, 21], state: "minecraft:candle{candles:4,lit:false,waterlogged:false}"},
        {pos: [19, 2, 22], state: "minecraft:deepslate_bricks"},
        {pos: [20, 2, 12], state: "minecraft:deepslate_bricks"},
        {pos: [20, 2, 13], state: "minecraft:skeleton_skull{powered:false,rotation:8}", nbt: {id: "minecraft:skull"}},
        {pos: [20, 2, 14], state: "minecraft:candle{candles:4,lit:false,waterlogged:false}"},
        {pos: [20, 2, 15], state: "minecraft:candle{candles:4,lit:false,waterlogged:false}"},
        {pos: [20, 2, 16], state: "minecraft:deepslate_bricks"},
        {pos: [20, 2, 17], state: "minecraft:deepslate_brick_stairs{facing:east,half:top,shape:straight,waterlogged:false}"},
        {pos: [20, 2, 18], state: "minecraft:deepslate_bricks"},
        {pos: [20, 2, 19], state: "minecraft:deepslate_brick_stairs{facing:south,half:bottom,shape:straight,waterlogged:false}"},
        {pos: [20, 2, 20], state: "trailiertales:coffin{facing:east,part:foot,state:inactive}", nbt: {id: "trailiertales:coffin", max_active_light_level: 7, uuid: "77c551ea-b614-4584-a89b-7aeb603b3c05"}},
        {pos: [20, 2, 21], state: "minecraft:deepslate_brick_stairs{facing:north,half:bottom,shape:straight,waterlogged:false}"},
        {pos: [20, 2, 22], state: "minecraft:deepslate_bricks"},
        {pos: [21, 2, 12], state: "minecraft:deepslate_bricks"},
        {pos: [21, 2, 13], state: "minecraft:deepslate_brick_stairs{facing:south,half:bottom,shape:straight,waterlogged:false}"},
        {pos: [21, 2, 14], state: "trailiertales:coffin{facing:west,part:head,state:inactive}", nbt: {id: "trailiertales:coffin"}},
        {pos: [21, 2, 15], state: "minecraft:deepslate_brick_stairs{facing:north,half:bottom,shape:straight,waterlogged:false}"},
        {pos: [21, 2, 16], state: "minecraft:deepslate_bricks"},
        {pos: [21, 2, 17], state: "minecraft:deepslate_bricks"},
        {pos: [21, 2, 18], state: "minecraft:deepslate_bricks"},
        {pos: [21, 2, 19], state: "minecraft:deepslate_brick_stairs{facing:south,half:bottom,shape:straight,waterlogged:false}"},
        {pos: [21, 2, 20], state: "trailiertales:coffin{facing:east,part:head,state:inactive}", nbt: {id: "trailiertales:coffin"}},
        {pos: [21, 2, 21], state: "minecraft:deepslate_brick_stairs{facing:north,half:bottom,shape:straight,waterlogged:false}"},
        {pos: [21, 2, 22], state: "minecraft:deepslate_bricks"},
        {pos: [22, 2, 12], state: "minecraft:deepslate_bricks"},
        {pos: [22, 2, 13], state: "minecraft:deepslate_brick_stairs{facing:south,half:bottom,shape:straight,waterlogged:false}"},
        {pos: [22, 2, 14], state: "trailiertales:coffin{facing:west,part:foot,state:inactive}", nbt: {id: "trailiertales:coffin", max_active_light_level: 7, uuid: "672e5e3d-b2d4-4657-9672-94c17d021dad"}},
        {pos: [22, 2, 15], state: "minecraft:deepslate_brick_stairs{facing:north,half:bottom,shape:straight,waterlogged:false}"},
        {pos: [22, 2, 16], state: "minecraft:deepslate_bricks"},
        {pos: [22, 2, 17], state: "minecraft:deepslate_bricks"},
        {pos: [22, 2, 18], state: "minecraft:deepslate_bricks"},
        {pos: [22, 2, 19], state: "minecraft:deepslate_bricks"},
        {pos: [22, 2, 20], state: "minecraft:deepslate_bricks"},
        {pos: [22, 2, 21], state: "minecraft:deepslate_bricks"},
        {pos: [22, 2, 22], state: "minecraft:deepslate_bricks"},
        {pos: [23, 2, 12], state: "minecraft:deepslate_bricks"},
        {pos: [23, 2, 13], state: "minecraft:deepslate_bricks"},
        {pos: [23, 2, 14], state: "minecraft:deepslate_bricks"},
        {pos: [23, 2, 15], state: "minecraft:deepslate_bricks"},
        {pos: [23, 2, 16], state: "minecraft:deepslate_bricks"},
        {pos: [23, 2, 17], state: "minecraft:deepslate_bricks"},
        {pos: [23, 2, 18], state: "minecraft:deepslate_bricks"},
        {pos: [23, 2, 19], state: "minecraft:deepslate_bricks"},
        {pos: [23, 2, 20], state: "minecraft:deepslate_bricks"},
        {pos: [23, 2, 21], state: "minecraft:deepslate_bricks"},
        {pos: [23, 2, 22], state: "minecraft:deepslate_bricks"},
        {pos: [24, 2, 12], state: "minecraft:deepslate_bricks"},
        {pos: [24, 2, 13], state: "minecraft:deepslate_bricks"},
        {pos: [24, 2, 14], state: "minecraft:deepslate_bricks"},
        {pos: [24, 2, 15], state: "minecraft:deepslate_bricks"},
        {pos: [24, 2, 16], state: "minecraft:deepslate_bricks"},
        {pos: [24, 2, 17], state: "minecraft:deepslate_bricks"},
        {pos: [6, 3, 18], state: "minecraft:deepslate_bricks"},
        {pos: [6, 3, 19], state: "minecraft:deepslate_bricks"},
        {pos: [6, 3, 20], state: "minecraft:deepslate_bricks"},
        {pos: [6, 3, 21], state: "minecraft:deepslate_bricks"},
        {pos: [6, 3, 22], state: "minecraft:deepslate_bricks"},
        {pos: [7, 3, 5], state: "minecraft:deepslate_bricks"},
        {pos: [7, 3, 6], state: "minecraft:deepslate_bricks"},
        {pos: [7, 3, 7], state: "minecraft:deepslate_bricks"},
        {pos: [7, 3, 8], state: "minecraft:deepslate_bricks"},
        {pos: [7, 3, 9], state: "minecraft:deepslate_bricks"},
        {pos: [7, 3, 10], state: "minecraft:deepslate_bricks"},
        {pos: [7, 3, 11], state: "minecraft:deepslate_bricks"},
        {pos: [7, 3, 12], state: "minecraft:deepslate_bricks"},
        {pos: [7, 3, 13], state: "minecraft:deepslate_bricks"},
        {pos: [7, 3, 14], state: "minecraft:deepslate_bricks"},
        {pos: [7, 3, 15], state: "minecraft:deepslate_bricks"},
        {pos: [7, 3, 16], state: "minecraft:deepslate_bricks"},
        {pos: [7, 3, 17], state: "minecraft:deepslate_bricks"},
        {pos: [7, 3, 18], state: "minecraft:deepslate_bricks"},
        {pos: [7, 3, 19], state: "minecraft:skeleton_skull{powered:false,rotation:4}", nbt: {id: "minecraft:skull"}},
        {pos: [7, 3, 20], state: "minecraft:candle{candles:4,lit:false,waterlogged:false}"},
        {pos: [7, 3, 21], state: "minecraft:skeleton_skull{powered:false,rotation:4}", nbt: {id: "minecraft:skull"}},
        {pos: [7, 3, 22], state: "minecraft:deepslate_bricks"},
        {pos: [7, 3, 23], state: "minecraft:deepslate_bricks"},
        {pos: [7, 3, 24], state: "minecraft:deepslate_bricks"},
        {pos: [7, 3, 25], state: "minecraft:deepslate_bricks"},
        {pos: [7, 3, 26], state: "minecraft:deepslate_bricks"},
        {pos: [7, 3, 27], state: "minecraft:deepslate_bricks"},
        {pos: [7, 3, 28], state: "minecraft:deepslate_bricks"},
        {pos: [7, 3, 29], state: "minecraft:deepslate_bricks"},
        {pos: [8, 3, 5], state: "minecraft:deepslate_bricks"},
        {pos: [8, 3, 6], state: "minecraft:deepslate_bricks"},
        {pos: [8, 3, 7], state: "minecraft:deepslate_bricks"},
        {pos: [8, 3, 8], state: "minecraft:deepslate_bricks"},
        {pos: [8, 3, 9], state: "minecraft:deepslate_bricks"},
        {pos: [8, 3, 10], state: "minecraft:deepslate_bricks"},
        {pos: [8, 3, 11], state: "minecraft:deepslate_bricks"},
        {pos: [8, 3, 12], state: "minecraft:deepslate_bricks"},
        {pos: [8, 3, 13], state: "minecraft:candle{candles:4,lit:false,waterlogged:false}"},
        {pos: [8, 3, 14], state: "minecraft:skeleton_skull{powered:false,rotation:4}", nbt: {id: "minecraft:skull"}},
        {pos: [8, 3, 15], state: "minecraft:skeleton_skull{powered:false,rotation:4}", nbt: {id: "minecraft:skull"}},
        {pos: [8, 3, 16], state: "minecraft:deepslate_bricks"},
        {pos: [8, 3, 17], state: "minecraft:deepslate_bricks"},
        {pos: [8, 3, 18], state: "minecraft:deepslate_bricks"},
        {pos: [8, 3, 19], state: "minecraft:cave_air"},
        {pos: [8, 3, 20], state: "minecraft:cave_air"},
        {pos: [8, 3, 21], state: "minecraft:cave_air"},
        {pos: [8, 3, 22], state: "minecraft:deepslate_bricks"},
        {pos: [8, 3, 23], state: "minecraft:deepslate_bricks"},
        {pos: [8, 3, 24], state: "minecraft:deepslate_bricks"},
        {pos: [8, 3, 25], state: "minecraft:deepslate_bricks"},
        {pos: [8, 3, 26], state: "minecraft:deepslate_bricks"},
        {pos: [8, 3, 27], state: "minecraft:deepslate_bricks"},
        {pos: [8, 3, 28], state: "minecraft:deepslate_bricks"},
        {pos: [8, 3, 29], state: "minecraft:deepslate_bricks"},
        {pos: [9, 3, 5], state: "minecraft:deepslate_bricks"},
        {pos: [9, 3, 6], state: "minecraft:deepslate_bricks"},
        {pos: [9, 3, 7], state: "minecraft:deepslate_bricks"},
        {pos: [9, 3, 8], state: "minecraft:deepslate_bricks"},
        {pos: [9, 3, 9], state: "minecraft:deepslate_bricks"},
        {pos: [9, 3, 10], state: "minecraft:deepslate_bricks"},
        {pos: [9, 3, 11], state: "minecraft:deepslate_bricks"},
        {pos: [9, 3, 12], state: "minecraft:deepslate_bricks"},
        {pos: [9, 3, 13], state: "minecraft:cave_air"},
        {pos: [9, 3, 14], state: "minecraft:cave_air"},
        {pos: [9, 3, 15], state: "minecraft:cave_air"},
        {pos: [9, 3, 16], state: "minecraft:deepslate_bricks"},
        {pos: [9, 3, 17], state: "minecraft:deepslate_bricks"},
        {pos: [9, 3, 18], state: "minecraft:deepslate_bricks"},
        {pos: [9, 3, 19], state: "minecraft:cave_air"},
        {pos: [9, 3, 20], state: "minecraft:cave_air"},
        {pos: [9, 3, 21], state: "minecraft:cave_air"},
        {pos: [9, 3, 22], state: "minecraft:deepslate_bricks"},
        {pos: [9, 3, 23], state: "minecraft:deepslate_bricks"},
        {pos: [9, 3, 24], state: "minecraft:deepslate_bricks"},
        {pos: [9, 3, 25], state: "minecraft:deepslate_bricks"},
        {pos: [9, 3, 26], state: "minecraft:deepslate_bricks"},
        {pos: [9, 3, 27], state: "minecraft:deepslate_bricks"},
        {pos: [9, 3, 28], state: "minecraft:deepslate_bricks"},
        {pos: [9, 3, 29], state: "minecraft:deepslate_bricks"},
        {pos: [10, 3, 5], state: "minecraft:deepslate_bricks"},
        {pos: [10, 3, 6], state: "minecraft:deepslate_bricks"},
        {pos: [10, 3, 7], state: "minecraft:deepslate_bricks"},
        {pos: [10, 3, 8], state: "minecraft:deepslate_bricks"},
        {pos: [10, 3, 9], state: "minecraft:deepslate_bricks"},
        {pos: [10, 3, 10], state: "minecraft:deepslate_bricks"},
        {pos: [10, 3, 11], state: "minecraft:deepslate_bricks"},
        {pos: [10, 3, 12], state: "minecraft:deepslate_bricks"},
        {pos: [10, 3, 13], state: "minecraft:cave_air"},
        {pos: [10, 3, 14], state: "minecraft:cave_air"},
        {pos: [10, 3, 15], state: "minecraft:cave_air"},
        {pos: [10, 3, 16], state: "minecraft:deepslate_bricks"},
        {pos: [10, 3, 17], state: "minecraft:skeleton_skull{powered:false,rotation:4}", nbt: {id: "minecraft:skull"}},
        {pos: [10, 3, 18], state: "minecraft:deepslate_bricks"},
        {pos: [10, 3, 19], state: "minecraft:cave_air"},
        {pos: [10, 3, 20], state: "minecraft:cave_air"},
        {pos: [10, 3, 21], state: "minecraft:cave_air"},
        {pos: [10, 3, 22], state: "minecraft:deepslate_bricks"},
        {pos: [10, 3, 23], state: "minecraft:deepslate_bricks"},
        {pos: [10, 3, 24], state: "minecraft:deepslate_bricks"},
        {pos: [10, 3, 25], state: "minecraft:deepslate_bricks"},
        {pos: [10, 3, 26], state: "minecraft:deepslate_bricks"},
        {pos: [10, 3, 27], state: "minecraft:deepslate_bricks"},
        {pos: [10, 3, 28], state: "minecraft:deepslate_bricks"},
        {pos: [10, 3, 29], state: "minecraft:deepslate_bricks"},
        {pos: [11, 3, 5], state: "minecraft:deepslate_bricks"},
        {pos: [11, 3, 6], state: "minecraft:deepslate_bricks"},
        {pos: [11, 3, 7], state: "minecraft:deepslate_bricks"},
        {pos: [11, 3, 8], state: "minecraft:deepslate_bricks"},
        {pos: [11, 3, 9], state: "minecraft:deepslate_bricks"},
        {pos: [11, 3, 10], state: "minecraft:deepslate_bricks"},
        {pos: [11, 3, 11], state: "minecraft:deepslate_bricks"},
        {pos: [11, 3, 12], state: "minecraft:deepslate_bricks"},
        {pos: [11, 3, 13], state: "minecraft:cave_air"},
        {pos: [11, 3, 14], state: "minecraft:cave_air"},
        {pos: [11, 3, 15], state: "minecraft:cave_air"},
        {pos: [11, 3, 16], state: "minecraft:cave_air"},
        {pos: [11, 3, 17], state: "minecraft:cave_air"},
        {pos: [11, 3, 18], state: "minecraft:cave_air"},
        {pos: [11, 3, 19], state: "minecraft:cave_air"},
        {pos: [11, 3, 20], state: "minecraft:cave_air"},
        {pos: [11, 3, 21], state: "minecraft:cave_air"},
        {pos: [11, 3, 22], state: "minecraft:deepslate_bricks"},
        {pos: [11, 3, 23], state: "minecraft:deepslate_bricks"},
        {pos: [11, 3, 24], state: "minecraft:deepslate_bricks"},
        {pos: [11, 3, 25], state: "minecraft:deepslate_bricks"},
        {pos: [11, 3, 26], state: "minecraft:deepslate_bricks"},
        {pos: [11, 3, 27], state: "minecraft:deepslate_bricks"},
        {pos: [11, 3, 28], state: "minecraft:deepslate_bricks"},
        {pos: [11, 3, 29], state: "minecraft:deepslate_bricks"},
        {pos: [12, 3, 5], state: "minecraft:deepslate_bricks"},
        {pos: [12, 3, 6], state: "minecraft:deepslate_bricks"},
        {pos: [12, 3, 7], state: "minecraft:deepslate_bricks"},
        {pos: [12, 3, 8], state: "minecraft:deepslate_bricks"},
        {pos: [12, 3, 9], state: "minecraft:deepslate_bricks"},
        {pos: [12, 3, 10], state: "minecraft:deepslate_bricks"},
        {pos: [12, 3, 11], state: "minecraft:deepslate_bricks"},
        {pos: [12, 3, 12], state: "minecraft:deepslate_bricks"},
        {pos: [12, 3, 13], state: "minecraft:cave_air"},
        {pos: [12, 3, 14], state: "minecraft:cave_air"},
        {pos: [12, 3, 15], state: "minecraft:cave_air"},
        {pos: [12, 3, 16], state: "minecraft:cave_air"},
        {pos: [12, 3, 17], state: "minecraft:cave_air"},
        {pos: [12, 3, 18], state: "minecraft:cave_air"},
        {pos: [12, 3, 19], state: "minecraft:cave_air"},
        {pos: [12, 3, 20], state: "minecraft:cave_air"},
        {pos: [12, 3, 21], state: "minecraft:cave_air"},
        {pos: [12, 3, 22], state: "minecraft:deepslate_bricks"},
        {pos: [12, 3, 23], state: "minecraft:deepslate_bricks"},
        {pos: [12, 3, 24], state: "minecraft:deepslate_bricks"},
        {pos: [12, 3, 25], state: "minecraft:deepslate_bricks"},
        {pos: [12, 3, 26], state: "minecraft:deepslate_bricks"},
        {pos: [12, 3, 27], state: "minecraft:deepslate_bricks"},
        {pos: [12, 3, 28], state: "minecraft:deepslate_bricks"},
        {pos: [12, 3, 29], state: "minecraft:deepslate_bricks"},
        {pos: [13, 3, 5], state: "minecraft:deepslate_bricks"},
        {pos: [13, 3, 6], state: "minecraft:deepslate_bricks"},
        {pos: [13, 3, 7], state: "minecraft:deepslate_bricks"},
        {pos: [13, 3, 8], state: "minecraft:deepslate_bricks"},
        {pos: [13, 3, 9], state: "minecraft:deepslate_bricks"},
        {pos: [13, 3, 10], state: "minecraft:deepslate_bricks"},
        {pos: [13, 3, 11], state: "minecraft:deepslate_bricks"},
        {pos: [13, 3, 12], state: "minecraft:deepslate_bricks"},
        {pos: [13, 3, 13], state: "minecraft:cave_air"},
        {pos: [13, 3, 14], state: "minecraft:cave_air"},
        {pos: [13, 3, 15], state: "minecraft:cave_air"},
        {pos: [13, 3, 16], state: "minecraft:cave_air"},
        {pos: [13, 3, 17], state: "minecraft:cave_air"},
        {pos: [13, 3, 18], state: "minecraft:cave_air"},
        {pos: [13, 3, 19], state: "minecraft:cave_air"},
        {pos: [13, 3, 20], state: "minecraft:cave_air"},
        {pos: [13, 3, 21], state: "minecraft:cave_air"},
        {pos: [13, 3, 22], state: "minecraft:deepslate_bricks"},
        {pos: [13, 3, 23], state: "minecraft:deepslate_bricks"},
        {pos: [13, 3, 24], state: "minecraft:deepslate_bricks"},
        {pos: [13, 3, 25], state: "minecraft:deepslate_bricks"},
        {pos: [13, 3, 26], state: "minecraft:deepslate_bricks"},
        {pos: [13, 3, 27], state: "minecraft:deepslate_bricks"},
        {pos: [13, 3, 28], state: "minecraft:deepslate_bricks"},
        {pos: [13, 3, 29], state: "minecraft:deepslate_bricks"},
        {pos: [14, 3, 5], state: "minecraft:deepslate_bricks"},
        {pos: [14, 3, 6], state: "minecraft:deepslate_bricks"},
        {pos: [14, 3, 7], state: "minecraft:deepslate_bricks"},
        {pos: [14, 3, 8], state: "minecraft:deepslate_bricks"},
        {pos: [14, 3, 9], state: "minecraft:deepslate_bricks"},
        {pos: [14, 3, 10], state: "minecraft:deepslate_bricks"},
        {pos: [14, 3, 11], state: "minecraft:deepslate_brick_stairs{facing:north,half:bottom,shape:straight,waterlogged:false}"},
        {pos: [14, 3, 12], state: "minecraft:cave_air"},
        {pos: [14, 3, 13], state: "minecraft:cave_air"},
        {pos: [14, 3, 14], state: "minecraft:cave_air"},
        {pos: [14, 3, 15], state: "minecraft:cave_air"},
        {pos: [14, 3, 16], state: "minecraft:deepslate_bricks"},
        {pos: [14, 3, 17], state: "minecraft:skeleton_skull{powered:false,rotation:12}", nbt: {id: "minecraft:skull"}},
        {pos: [14, 3, 18], state: "minecraft:deepslate_bricks"},
        {pos: [14, 3, 19], state: "minecraft:cave_air"},
        {pos: [14, 3, 20], state: "minecraft:cave_air"},
        {pos: [14, 3, 21], state: "minecraft:cave_air"},
        {pos: [14, 3, 22], state: "minecraft:cave_air"},
        {pos: [14, 3, 23], state: "minecraft:deepslate_brick_stairs{facing:south,half:bottom,shape:straight,waterlogged:false}"},
        {pos: [14, 3, 24], state: "minecraft:deepslate_bricks"},
        {pos: [14, 3, 25], state: "minecraft:deepslate_bricks"},
        {pos: [14, 3, 26], state: "minecraft:deepslate_bricks"},
        {pos: [14, 3, 27], state: "minecraft:deepslate_bricks"},
        {pos: [14, 3, 28], state: "minecraft:deepslate_bricks"},
        {pos: [14, 3, 29], state: "minecraft:deepslate_bricks"},
        {pos: [15, 3, 5], state: "minecraft:deepslate_bricks"},
        {pos: [15, 3, 6], state: "minecraft:deepslate_bricks"},
        {pos: [15, 3, 7], state: "minecraft:deepslate_bricks"},
        {pos: [15, 3, 8], state: "minecraft:deepslate_bricks"},
        {pos: [15, 3, 9], state: "minecraft:deepslate_bricks"},
        {pos: [15, 3, 10], state: "minecraft:deepslate_bricks"},
        {pos: [15, 3, 11], state: "minecraft:deepslate_brick_stairs{facing:north,half:bottom,shape:straight,waterlogged:false}"},
        {pos: [15, 3, 12], state: "minecraft:cave_air"},
        {pos: [15, 3, 13], state: "minecraft:cave_air"},
        {pos: [15, 3, 14], state: "minecraft:cave_air"},
        {pos: [15, 3, 15], state: "minecraft:cave_air"},
        {pos: [15, 3, 16], state: "minecraft:cave_air"},
        {pos: [15, 3, 17], state: "minecraft:deepslate_bricks"},
        {pos: [15, 3, 18], state: "minecraft:cave_air"},
        {pos: [15, 3, 19], state: "minecraft:cave_air"},
        {pos: [15, 3, 20], state: "minecraft:cave_air"},
        {pos: [15, 3, 21], state: "minecraft:cave_air"},
        {pos: [15, 3, 22], state: "minecraft:cave_air"},
        {pos: [15, 3, 23], state: "minecraft:deepslate_brick_stairs{facing:south,half:bottom,shape:straight,waterlogged:false}"},
        {pos: [15, 3, 24], state: "minecraft:deepslate_bricks"},
        {pos: [15, 3, 25], state: "minecraft:deepslate_bricks"},
        {pos: [15, 3, 26], state: "minecraft:deepslate_bricks"},
        {pos: [15, 3, 27], state: "minecraft:deepslate_bricks"},
        {pos: [15, 3, 28], state: "minecraft:deepslate_bricks"},
        {pos: [15, 3, 29], state: "minecraft:deepslate_bricks"},
        {pos: [16, 3, 5], state: "minecraft:deepslate_bricks"},
        {pos: [16, 3, 6], state: "minecraft:deepslate_bricks"},
        {pos: [16, 3, 7], state: "minecraft:deepslate_bricks"},
        {pos: [16, 3, 8], state: "minecraft:deepslate_bricks"},
        {pos: [16, 3, 9], state: "minecraft:deepslate_bricks"},
        {pos: [16, 3, 10], state: "minecraft:deepslate_bricks"},
        {pos: [16, 3, 11], state: "minecraft:deepslate_brick_stairs{facing:north,half:bottom,shape:straight,waterlogged:false}"},
        {pos: [16, 3, 12], state: "minecraft:cave_air"},
        {pos: [16, 3, 13], state: "minecraft:cave_air"},
        {pos: [16, 3, 14], state: "minecraft:cave_air"},
        {pos: [16, 3, 15], state: "minecraft:cave_air"},
        {pos: [16, 3, 16], state: "minecraft:deepslate_bricks"},
        {pos: [16, 3, 17], state: "minecraft:skeleton_skull{powered:false,rotation:4}", nbt: {id: "minecraft:skull"}},
        {pos: [16, 3, 18], state: "minecraft:deepslate_bricks"},
        {pos: [16, 3, 19], state: "minecraft:cave_air"},
        {pos: [16, 3, 20], state: "minecraft:cave_air"},
        {pos: [16, 3, 21], state: "minecraft:cave_air"},
        {pos: [16, 3, 22], state: "minecraft:cave_air"},
        {pos: [16, 3, 23], state: "minecraft:deepslate_brick_stairs{facing:south,half:bottom,shape:straight,waterlogged:false}"},
        {pos: [16, 3, 24], state: "minecraft:deepslate_bricks"},
        {pos: [16, 3, 25], state: "minecraft:deepslate_bricks"},
        {pos: [16, 3, 26], state: "minecraft:deepslate_bricks"},
        {pos: [16, 3, 27], state: "minecraft:deepslate_bricks"},
        {pos: [16, 3, 28], state: "minecraft:deepslate_bricks"},
        {pos: [16, 3, 29], state: "minecraft:deepslate_bricks"},
        {pos: [17, 3, 5], state: "minecraft:deepslate_bricks"},
        {pos: [17, 3, 6], state: "minecraft:deepslate_bricks"},
        {pos: [17, 3, 7], state: "minecraft:deepslate_bricks"},
        {pos: [17, 3, 8], state: "minecraft:deepslate_bricks"},
        {pos: [17, 3, 9], state: "minecraft:deepslate_bricks"},
        {pos: [17, 3, 10], state: "minecraft:deepslate_bricks"},
        {pos: [17, 3, 11], state: "minecraft:deepslate_bricks"},
        {pos: [17, 3, 12], state: "minecraft:deepslate_bricks"},
        {pos: [17, 3, 13], state: "minecraft:cave_air"},
        {pos: [17, 3, 14], state: "minecraft:cave_air"},
        {pos: [17, 3, 15], state: "minecraft:cave_air"},
        {pos: [17, 3, 16], state: "minecraft:cave_air"},
        {pos: [17, 3, 17], state: "minecraft:cave_air"},
        {pos: [17, 3, 18], state: "minecraft:cave_air"},
        {pos: [17, 3, 19], state: "minecraft:cave_air"},
        {pos: [17, 3, 20], state: "minecraft:cave_air"},
        {pos: [17, 3, 21], state: "minecraft:cave_air"},
        {pos: [17, 3, 22], state: "minecraft:deepslate_bricks"},
        {pos: [17, 3, 23], state: "minecraft:deepslate_bricks"},
        {pos: [17, 3, 24], state: "minecraft:deepslate_bricks"},
        {pos: [17, 3, 25], state: "minecraft:deepslate_bricks"},
        {pos: [17, 3, 26], state: "minecraft:deepslate_bricks"},
        {pos: [17, 3, 27], state: "minecraft:deepslate_bricks"},
        {pos: [17, 3, 28], state: "minecraft:deepslate_bricks"},
        {pos: [17, 3, 29], state: "minecraft:deepslate_bricks"},
        {pos: [18, 3, 5], state: "minecraft:deepslate_bricks"},
        {pos: [18, 3, 6], state: "minecraft:deepslate_bricks"},
        {pos: [18, 3, 7], state: "minecraft:deepslate_bricks"},
        {pos: [18, 3, 8], state: "minecraft:deepslate_bricks"},
        {pos: [18, 3, 9], state: "minecraft:deepslate_bricks"},
        {pos: [18, 3, 10], state: "minecraft:deepslate_bricks"},
        {pos: [18, 3, 11], state: "minecraft:deepslate_bricks"},
        {pos: [18, 3, 12], state: "minecraft:deepslate_bricks"},
        {pos: [18, 3, 13], state: "minecraft:cave_air"},
        {pos: [18, 3, 14], state: "minecraft:cave_air"},
        {pos: [18, 3, 15], state: "minecraft:cave_air"},
        {pos: [18, 3, 16], state: "minecraft:cave_air"},
        {pos: [18, 3, 17], state: "minecraft:cave_air"},
        {pos: [18, 3, 18], state: "minecraft:cave_air"},
        {pos: [18, 3, 19], state: "minecraft:cave_air"},
        {pos: [18, 3, 20], state: "minecraft:cave_air"},
        {pos: [18, 3, 21], state: "minecraft:cave_air"},
        {pos: [18, 3, 22], state: "minecraft:deepslate_bricks"},
        {pos: [18, 3, 23], state: "minecraft:deepslate_bricks"},
        {pos: [18, 3, 24], state: "minecraft:deepslate_bricks"},
        {pos: [18, 3, 25], state: "minecraft:deepslate_bricks"},
        {pos: [18, 3, 26], state: "minecraft:deepslate_bricks"},
        {pos: [18, 3, 27], state: "minecraft:deepslate_bricks"},
        {pos: [18, 3, 28], state: "minecraft:deepslate_bricks"},
        {pos: [18, 3, 29], state: "minecraft:deepslate_bricks"},
        {pos: [19, 3, 5], state: "minecraft:deepslate_bricks"},
        {pos: [19, 3, 6], state: "minecraft:deepslate_bricks"},
        {pos: [19, 3, 7], state: "minecraft:deepslate_bricks"},
        {pos: [19, 3, 8], state: "minecraft:deepslate_bricks"},
        {pos: [19, 3, 9], state: "minecraft:deepslate_bricks"},
        {pos: [19, 3, 10], state: "minecraft:deepslate_bricks"},
        {pos: [19, 3, 11], state: "minecraft:deepslate_bricks"},
        {pos: [19, 3, 12], state: "minecraft:deepslate_bricks"},
        {pos: [19, 3, 13], state: "minecraft:cave_air"},
        {pos: [19, 3, 14], state: "minecraft:cave_air"},
        {pos: [19, 3, 15], state: "minecraft:cave_air"},
        {pos: [19, 3, 16], state: "minecraft:cave_air"},
        {pos: [19, 3, 17], state: "minecraft:cave_air"},
        {pos: [19, 3, 18], state: "minecraft:cave_air"},
        {pos: [19, 3, 19], state: "minecraft:cave_air"},
        {pos: [19, 3, 20], state: "minecraft:cave_air"},
        {pos: [19, 3, 21], state: "minecraft:cave_air"},
        {pos: [19, 3, 22], state: "minecraft:deepslate_bricks"},
        {pos: [19, 3, 23], state: "minecraft:deepslate_bricks"},
        {pos: [19, 3, 24], state: "minecraft:deepslate_bricks"},
        {pos: [19, 3, 25], state: "minecraft:deepslate_bricks"},
        {pos: [19, 3, 26], state: "minecraft:deepslate_bricks"},
        {pos: [19, 3, 27], state: "minecraft:deepslate_bricks"},
        {pos: [19, 3, 28], state: "minecraft:deepslate_bricks"},
        {pos: [19, 3, 29], state: "minecraft:deepslate_bricks"},
        {pos: [20, 3, 5], state: "minecraft:deepslate_bricks"},
        {pos: [20, 3, 6], state: "minecraft:deepslate_bricks"},
        {pos: [20, 3, 7], state: "minecraft:deepslate_bricks"},
        {pos: [20, 3, 8], state: "minecraft:deepslate_bricks"},
        {pos: [20, 3, 9], state: "minecraft:deepslate_bricks"},
        {pos: [20, 3, 10], state: "minecraft:deepslate_bricks"},
        {pos: [20, 3, 11], state: "minecraft:deepslate_bricks"},
        {pos: [20, 3, 12], state: "minecraft:deepslate_bricks"},
        {pos: [20, 3, 13], state: "minecraft:cave_air"},
        {pos: [20, 3, 14], state: "minecraft:cave_air"},
        {pos: [20, 3, 15], state: "minecraft:cave_air"},
        {pos: [20, 3, 16], state: "minecraft:deepslate_bricks"},
        {pos: [20, 3, 17], state: "minecraft:skeleton_skull{powered:false,rotation:12}", nbt: {id: "minecraft:skull"}},
        {pos: [20, 3, 18], state: "minecraft:deepslate_bricks"},
        {pos: [20, 3, 19], state: "minecraft:cave_air"},
        {pos: [20, 3, 20], state: "minecraft:cave_air"},
        {pos: [20, 3, 21], state: "minecraft:cave_air"},
        {pos: [20, 3, 22], state: "minecraft:deepslate_bricks"},
        {pos: [20, 3, 23], state: "minecraft:deepslate_bricks"},
        {pos: [20, 3, 24], state: "minecraft:deepslate_bricks"},
        {pos: [20, 3, 25], state: "minecraft:deepslate_bricks"},
        {pos: [20, 3, 26], state: "minecraft:deepslate_bricks"},
        {pos: [20, 3, 27], state: "minecraft:deepslate_bricks"},
        {pos: [20, 3, 28], state: "minecraft:deepslate_bricks"},
        {pos: [20, 3, 29], state: "minecraft:deepslate_bricks"},
        {pos: [21, 3, 5], state: "minecraft:deepslate_bricks"},
        {pos: [21, 3, 6], state: "minecraft:deepslate_bricks"},
        {pos: [21, 3, 7], state: "minecraft:deepslate_bricks"},
        {pos: [21, 3, 8], state: "minecraft:deepslate_bricks"},
        {pos: [21, 3, 9], state: "minecraft:deepslate_bricks"},
        {pos: [21, 3, 10], state: "minecraft:deepslate_bricks"},
        {pos: [21, 3, 11], state: "minecraft:deepslate_bricks"},
        {pos: [21, 3, 12], state: "minecraft:deepslate_bricks"},
        {pos: [21, 3, 13], state: "minecraft:cave_air"},
        {pos: [21, 3, 14], state: "minecraft:cave_air"},
        {pos: [21, 3, 15], state: "minecraft:cave_air"},
        {pos: [21, 3, 16], state: "minecraft:deepslate_bricks"},
        {pos: [21, 3, 17], state: "minecraft:deepslate_bricks"},
        {pos: [21, 3, 18], state: "minecraft:deepslate_bricks"},
        {pos: [21, 3, 19], state: "minecraft:cave_air"},
        {pos: [21, 3, 20], state: "minecraft:cave_air"},
        {pos: [21, 3, 21], state: "minecraft:cave_air"},
        {pos: [21, 3, 22], state: "minecraft:deepslate_bricks"},
        {pos: [21, 3, 23], state: "minecraft:deepslate_bricks"},
        {pos: [21, 3, 24], state: "minecraft:deepslate_bricks"},
        {pos: [21, 3, 25], state: "minecraft:deepslate_bricks"},
        {pos: [21, 3, 26], state: "minecraft:deepslate_bricks"},
        {pos: [21, 3, 27], state: "minecraft:deepslate_bricks"},
        {pos: [21, 3, 28], state: "minecraft:deepslate_bricks"},
        {pos: [21, 3, 29], state: "minecraft:deepslate_bricks"},
        {pos: [22, 3, 5], state: "minecraft:deepslate_bricks"},
        {pos: [22, 3, 6], state: "minecraft:deepslate_bricks"},
        {pos: [22, 3, 7], state: "minecraft:deepslate_bricks"},
        {pos: [22, 3, 8], state: "minecraft:deepslate_bricks"},
        {pos: [22, 3, 9], state: "minecraft:deepslate_bricks"},
        {pos: [22, 3, 10], state: "minecraft:deepslate_bricks"},
        {pos: [22, 3, 11], state: "minecraft:deepslate_bricks"},
        {pos: [22, 3, 12], state: "minecraft:deepslate_bricks"},
        {pos: [22, 3, 13], state: "minecraft:cave_air"},
        {pos: [22, 3, 14], state: "minecraft:cave_air"},
        {pos: [22, 3, 15], state: "minecraft:cave_air"},
        {pos: [22, 3, 16], state: "minecraft:deepslate_bricks"},
        {pos: [22, 3, 17], state: "minecraft:deepslate_bricks"},
        {pos: [22, 3, 18], state: "minecraft:deepslate_bricks"},
        {pos: [22, 3, 19], state: "minecraft:candle{candles:4,lit:false,waterlogged:false}"},
        {pos: [22, 3, 20], state: "minecraft:skeleton_skull{powered:false,rotation:12}", nbt: {id: "minecraft:skull"}},
        {pos: [22, 3, 21], state: "minecraft:skeleton_skull{powered:false,rotation:12}", nbt: {id: "minecraft:skull"}},
        {pos: [22, 3, 22], state: "minecraft:deepslate_bricks"},
        {pos: [22, 3, 23], state: "minecraft:deepslate_bricks"},
        {pos: [22, 3, 24], state: "minecraft:deepslate_bricks"},
        {pos: [22, 3, 25], state: "minecraft:deepslate_bricks"},
        {pos: [22, 3, 26], state: "minecraft:deepslate_bricks"},
        {pos: [22, 3, 27], state: "minecraft:deepslate_bricks"},
        {pos: [22, 3, 28], state: "minecraft:deepslate_bricks"},
        {pos: [22, 3, 29], state: "minecraft:deepslate_bricks"},
        {pos: [23, 3, 5], state: "minecraft:deepslate_bricks"},
        {pos: [23, 3, 6], state: "minecraft:deepslate_bricks"},
        {pos: [23, 3, 7], state: "minecraft:deepslate_bricks"},
        {pos: [23, 3, 8], state: "minecraft:deepslate_bricks"},
        {pos: [23, 3, 9], state: "minecraft:deepslate_bricks"},
        {pos: [23, 3, 10], state: "minecraft:deepslate_bricks"},
        {pos: [23, 3, 11], state: "minecraft:deepslate_bricks"},
        {pos: [23, 3, 12], state: "minecraft:deepslate_bricks"},
        {pos: [23, 3, 13], state: "minecraft:cobweb"},
        {pos: [23, 3, 14], state: "minecraft:skeleton_skull{powered:false,rotation:12}", nbt: {id: "minecraft:skull"}},
        {pos: [23, 3, 15], state: "minecraft:candle{candles:4,lit:false,waterlogged:false}"},
        {pos: [23, 3, 16], state: "minecraft:deepslate_bricks"},
        {pos: [23, 3, 17], state: "minecraft:deepslate_bricks"},
        {pos: [23, 3, 18], state: "minecraft:deepslate_bricks"},
        {pos: [23, 3, 19], state: "minecraft:deepslate_bricks"},
        {pos: [23, 3, 20], state: "minecraft:deepslate_bricks"},
        {pos: [23, 3, 21], state: "minecraft:deepslate_bricks"},
        {pos: [23, 3, 22], state: "minecraft:deepslate_bricks"},
        {pos: [23, 3, 23], state: "minecraft:deepslate_bricks"},
        {pos: [23, 3, 24], state: "minecraft:deepslate_bricks"},
        {pos: [23, 3, 25], state: "minecraft:deepslate_bricks"},
        {pos: [23, 3, 26], state: "minecraft:deepslate_bricks"},
        {pos: [23, 3, 27], state: "minecraft:deepslate_bricks"},
        {pos: [23, 3, 28], state: "minecraft:deepslate_bricks"},
        {pos: [23, 3, 29], state: "minecraft:deepslate_bricks"},
        {pos: [24, 3, 12], state: "minecraft:deepslate_bricks"},
        {pos: [24, 3, 13], state: "minecraft:deepslate_bricks"},
        {pos: [24, 3, 14], state: "minecraft:deepslate_bricks"},
        {pos: [24, 3, 15], state: "minecraft:deepslate_bricks"},
        {pos: [24, 3, 16], state: "minecraft:deepslate_bricks"},
        {pos: [24, 3, 17], state: "minecraft:deepslate_bricks"},
        {pos: [6, 4, 18], state: "minecraft:deepslate_bricks"},
        {pos: [6, 4, 19], state: "minecraft:deepslate_bricks"},
        {pos: [6, 4, 20], state: "minecraft:deepslate_bricks"},
        {pos: [6, 4, 21], state: "minecraft:deepslate_bricks"},
        {pos: [6, 4, 22], state: "minecraft:deepslate_bricks"},
        {pos: [7, 4, 5], state: "minecraft:deepslate_bricks"},
        {pos: [7, 4, 6], state: "minecraft:deepslate_bricks"},
        {pos: [7, 4, 7], state: "minecraft:deepslate_bricks"},
        {pos: [7, 4, 8], state: "minecraft:deepslate_bricks"},
        {pos: [7, 4, 9], state: "minecraft:deepslate_bricks"},
        {pos: [7, 4, 10], state: "minecraft:deepslate_bricks"},
        {pos: [7, 4, 11], state: "minecraft:deepslate_bricks"},
        {pos: [7, 4, 12], state: "minecraft:deepslate_bricks"},
        {pos: [7, 4, 13], state: "minecraft:deepslate_bricks"},
        {pos: [7, 4, 14], state: "minecraft:deepslate_bricks"},
        {pos: [7, 4, 15], state: "minecraft:deepslate_bricks"},
        {pos: [7, 4, 16], state: "minecraft:deepslate_bricks"},
        {pos: [7, 4, 17], state: "minecraft:deepslate_bricks"},
        {pos: [7, 4, 18], state: "minecraft:deepslate_bricks"},
        {pos: [7, 4, 19], state: "minecraft:deepslate_brick_stairs{facing:west,half:top,shape:straight,waterlogged:false}"},
        {pos: [7, 4, 20], state: "minecraft:deepslate_brick_stairs{facing:west,half:top,shape:straight,waterlogged:false}"},
        {pos: [7, 4, 21], state: "minecraft:deepslate_brick_stairs{facing:west,half:top,shape:straight,waterlogged:false}"},
        {pos: [7, 4, 22], state: "minecraft:deepslate_bricks"},
        {pos: [7, 4, 23], state: "minecraft:deepslate_bricks"},
        {pos: [7, 4, 24], state: "minecraft:deepslate_bricks"},
        {pos: [7, 4, 25], state: "minecraft:deepslate_bricks"},
        {pos: [7, 4, 26], state: "minecraft:deepslate_bricks"},
        {pos: [7, 4, 27], state: "minecraft:deepslate_bricks"},
        {pos: [7, 4, 28], state: "minecraft:deepslate_bricks"},
        {pos: [7, 4, 29], state: "minecraft:deepslate_bricks"},
        {pos: [8, 4, 5], state: "minecraft:deepslate_bricks"},
        {pos: [8, 4, 6], state: "minecraft:deepslate_bricks"},
        {pos: [8, 4, 7], state: "minecraft:gravel"},
        {pos: [8, 4, 8], state: "minecraft:gravel"},
        {pos: [8, 4, 9], state: "minecraft:deepslate_bricks"},
        {pos: [8, 4, 10], state: "minecraft:deepslate_bricks"},
        {pos: [8, 4, 11], state: "minecraft:deepslate_bricks"},
        {pos: [8, 4, 12], state: "minecraft:deepslate_bricks"},
        {pos: [8, 4, 13], state: "minecraft:deepslate_brick_stairs{facing:west,half:top,shape:straight,waterlogged:false}"},
        {pos: [8, 4, 14], state: "minecraft:deepslate_brick_stairs{facing:west,half:top,shape:straight,waterlogged:false}"},
        {pos: [8, 4, 15], state: "minecraft:deepslate_brick_stairs{facing:west,half:top,shape:straight,waterlogged:false}"},
        {pos: [8, 4, 16], state: "minecraft:deepslate_bricks"},
        {pos: [8, 4, 17], state: "minecraft:deepslate_bricks"},
        {pos: [8, 4, 18], state: "minecraft:deepslate_bricks"},
        {pos: [8, 4, 19], state: "minecraft:cave_air"},
        {pos: [8, 4, 20], state: "minecraft:cave_air"},
        {pos: [8, 4, 21], state: "minecraft:cave_air"},
        {pos: [8, 4, 22], state: "minecraft:deepslate_bricks"},
        {pos: [8, 4, 23], state: "minecraft:deepslate_bricks"},
        {pos: [8, 4, 24], state: "minecraft:deepslate_bricks"},
        {pos: [8, 4, 25], state: "minecraft:deepslate_bricks"},
        {pos: [8, 4, 26], state: "minecraft:gravel"},
        {pos: [8, 4, 27], state: "minecraft:gravel"},
        {pos: [8, 4, 28], state: "minecraft:deepslate_bricks"},
        {pos: [8, 4, 29], state: "minecraft:deepslate_bricks"},
        {pos: [9, 4, 5], state: "minecraft:deepslate_bricks"},
        {pos: [9, 4, 6], state: "minecraft:deepslate_bricks"},
        {pos: [9, 4, 7], state: "minecraft:gravel"},
        {pos: [9, 4, 8], state: "minecraft:deepslate_bricks"},
        {pos: [9, 4, 9], state: "minecraft:deepslate_bricks"},
        {pos: [9, 4, 10], state: "minecraft:cave_air"},
        {pos: [9, 4, 11], state: "minecraft:deepslate_bricks"},
        {pos: [9, 4, 12], state: "minecraft:deepslate_bricks"},
        {pos: [9, 4, 13], state: "minecraft:cobweb"},
        {pos: [9, 4, 14], state: "minecraft:cave_air"},
        {pos: [9, 4, 15], state: "minecraft:cave_air"},
        {pos: [9, 4, 16], state: "minecraft:deepslate_bricks"},
        {pos: [9, 4, 17], state: "minecraft:deepslate_bricks"},
        {pos: [9, 4, 18], state: "minecraft:deepslate_bricks"},
        {pos: [9, 4, 19], state: "minecraft:cave_air"},
        {pos: [9, 4, 20], state: "minecraft:cave_air"},
        {pos: [9, 4, 21], state: "minecraft:cave_air"},
        {pos: [9, 4, 22], state: "minecraft:deepslate_bricks"},
        {pos: [9, 4, 23], state: "minecraft:deepslate_bricks"},
        {pos: [9, 4, 24], state: "minecraft:deepslate_bricks"},
        {pos: [9, 4, 25], state: "minecraft:deepslate_bricks"},
        {pos: [9, 4, 26], state: "minecraft:deepslate_bricks"},
        {pos: [9, 4, 27], state: "minecraft:gravel"},
        {pos: [9, 4, 28], state: "minecraft:deepslate_bricks"},
        {pos: [9, 4, 29], state: "minecraft:deepslate_bricks"},
        {pos: [10, 4, 5], state: "minecraft:deepslate_bricks"},
        {pos: [10, 4, 6], state: "minecraft:deepslate_bricks"},
        {pos: [10, 4, 7], state: "minecraft:gravel"},
        {pos: [10, 4, 8], state: "minecraft:gravel"},
        {pos: [10, 4, 9], state: "minecraft:deepslate_bricks"},
        {pos: [10, 4, 10], state: "minecraft:deepslate_bricks"},
        {pos: [10, 4, 11], state: "minecraft:deepslate_bricks"},
        {pos: [10, 4, 12], state: "minecraft:deepslate_bricks"},
        {pos: [10, 4, 13], state: "minecraft:cobweb"},
        {pos: [10, 4, 14], state: "minecraft:cave_air"},
        {pos: [10, 4, 15], state: "minecraft:cave_air"},
        {pos: [10, 4, 16], state: "minecraft:deepslate_bricks"},
        {pos: [10, 4, 17], state: "minecraft:deepslate_bricks"},
        {pos: [10, 4, 18], state: "minecraft:deepslate_bricks"},
        {pos: [10, 4, 19], state: "minecraft:cave_air"},
        {pos: [10, 4, 20], state: "minecraft:cave_air"},
        {pos: [10, 4, 21], state: "minecraft:cave_air"},
        {pos: [10, 4, 22], state: "minecraft:deepslate_bricks"},
        {pos: [10, 4, 23], state: "minecraft:deepslate_bricks"},
        {pos: [10, 4, 24], state: "minecraft:deepslate_bricks"},
        {pos: [10, 4, 25], state: "minecraft:deepslate_bricks"},
        {pos: [10, 4, 26], state: "minecraft:deepslate_bricks"},
        {pos: [10, 4, 27], state: "minecraft:gravel"},
        {pos: [10, 4, 28], state: "minecraft:deepslate_bricks"},
        {pos: [10, 4, 29], state: "minecraft:deepslate_bricks"},
        {pos: [11, 4, 5], state: "minecraft:deepslate_bricks"},
        {pos: [11, 4, 6], state: "minecraft:deepslate_bricks"},
        {pos: [11, 4, 7], state: "minecraft:gravel"},
        {pos: [11, 4, 8], state: "minecraft:gravel"},
        {pos: [11, 4, 9], state: "minecraft:gravel"},
        {pos: [11, 4, 10], state: "minecraft:deepslate_bricks"},
        {pos: [11, 4, 11], state: "minecraft:deepslate_bricks"},
        {pos: [11, 4, 12], state: "minecraft:deepslate_bricks"},
        {pos: [11, 4, 13], state: "minecraft:cave_air"},
        {pos: [11, 4, 14], state: "minecraft:cave_air"},
        {pos: [11, 4, 15], state: "minecraft:cave_air"},
        {pos: [11, 4, 16], state: "minecraft:cave_air"},
        {pos: [11, 4, 17], state: "minecraft:cave_air"},
        {pos: [11, 4, 18], state: "minecraft:cave_air"},
        {pos: [11, 4, 19], state: "minecraft:cave_air"},
        {pos: [11, 4, 20], state: "minecraft:cave_air"},
        {pos: [11, 4, 21], state: "minecraft:cave_air"},
        {pos: [11, 4, 22], state: "minecraft:deepslate_bricks"},
        {pos: [11, 4, 23], state: "minecraft:deepslate_bricks"},
        {pos: [11, 4, 24], state: "minecraft:deepslate_bricks"},
        {pos: [11, 4, 25], state: "minecraft:gravel"},
        {pos: [11, 4, 26], state: "minecraft:gravel"},
        {pos: [11, 4, 27], state: "minecraft:gravel"},
        {pos: [11, 4, 28], state: "minecraft:deepslate_bricks"},
        {pos: [11, 4, 29], state: "minecraft:deepslate_bricks"},
        {pos: [12, 4, 5], state: "minecraft:deepslate_bricks"},
        {pos: [12, 4, 6], state: "minecraft:gravel"},
        {pos: [12, 4, 7], state: "minecraft:gravel"},
        {pos: [12, 4, 8], state: "minecraft:gravel"},
        {pos: [12, 4, 9], state: "minecraft:gravel"},
        {pos: [12, 4, 10], state: "minecraft:gravel"},
        {pos: [12, 4, 11], state: "minecraft:deepslate_bricks"},
        {pos: [12, 4, 12], state: "minecraft:deepslate_bricks"},
        {pos: [12, 4, 13], state: "minecraft:cave_air"},
        {pos: [12, 4, 14], state: "minecraft:cave_air"},
        {pos: [12, 4, 15], state: "minecraft:cave_air"},
        {pos: [12, 4, 16], state: "minecraft:cave_air"},
        {pos: [12, 4, 17], state: "minecraft:cave_air"},
        {pos: [12, 4, 18], state: "minecraft:cave_air"},
        {pos: [12, 4, 19], state: "minecraft:cave_air"},
        {pos: [12, 4, 20], state: "minecraft:cave_air"},
        {pos: [12, 4, 21], state: "minecraft:cave_air"},
        {pos: [12, 4, 22], state: "minecraft:deepslate_bricks"},
        {pos: [12, 4, 23], state: "minecraft:deepslate_bricks"},
        {pos: [12, 4, 24], state: "minecraft:gravel"},
        {pos: [12, 4, 25], state: "minecraft:gravel"},
        {pos: [12, 4, 26], state: "minecraft:gravel"},
        {pos: [12, 4, 27], state: "minecraft:gravel"},
        {pos: [12, 4, 28], state: "minecraft:gravel"},
        {pos: [12, 4, 29], state: "minecraft:deepslate_bricks"},
        {pos: [13, 4, 5], state: "minecraft:deepslate_bricks"},
        {pos: [13, 4, 6], state: "minecraft:deepslate_bricks"},
        {pos: [13, 4, 7], state: "minecraft:gravel"},
        {pos: [13, 4, 8], state: "minecraft:gravel"},
        {pos: [13, 4, 9], state: "minecraft:gravel"},
        {pos: [13, 4, 10], state: "minecraft:deepslate_bricks"},
        {pos: [13, 4, 11], state: "minecraft:deepslate_bricks"},
        {pos: [13, 4, 12], state: "minecraft:deepslate_bricks"},
        {pos: [13, 4, 13], state: "minecraft:cave_air"},
        {pos: [13, 4, 14], state: "minecraft:cave_air"},
        {pos: [13, 4, 15], state: "minecraft:cave_air"},
        {pos: [13, 4, 16], state: "minecraft:cave_air"},
        {pos: [13, 4, 17], state: "minecraft:cave_air"},
        {pos: [13, 4, 18], state: "minecraft:cave_air"},
        {pos: [13, 4, 19], state: "minecraft:cave_air"},
        {pos: [13, 4, 20], state: "minecraft:cave_air"},
        {pos: [13, 4, 21], state: "minecraft:cave_air"},
        {pos: [13, 4, 22], state: "minecraft:deepslate_bricks"},
        {pos: [13, 4, 23], state: "minecraft:deepslate_bricks"},
        {pos: [13, 4, 24], state: "minecraft:deepslate_bricks"},
        {pos: [13, 4, 25], state: "minecraft:gravel"},
        {pos: [13, 4, 26], state: "minecraft:gravel"},
        {pos: [13, 4, 27], state: "minecraft:gravel"},
        {pos: [13, 4, 28], state: "minecraft:deepslate_bricks"},
        {pos: [13, 4, 29], state: "minecraft:deepslate_bricks"},
        {pos: [14, 4, 5], state: "minecraft:deepslate_bricks"},
        {pos: [14, 4, 6], state: "minecraft:deepslate_bricks"},
        {pos: [14, 4, 7], state: "minecraft:gravel"},
        {pos: [14, 4, 8], state: "minecraft:gravel"},
        {pos: [14, 4, 9], state: "minecraft:gravel"},
        {pos: [14, 4, 10], state: "minecraft:deepslate_brick_stairs{facing:north,half:bottom,shape:straight,waterlogged:false}"},
        {pos: [14, 4, 11], state: "minecraft:cave_air"},
        {pos: [14, 4, 12], state: "minecraft:cave_air"},
        {pos: [14, 4, 13], state: "minecraft:cave_air"},
        {pos: [14, 4, 14], state: "minecraft:cave_air"},
        {pos: [14, 4, 15], state: "minecraft:cave_air"},
        {pos: [14, 4, 16], state: "minecraft:deepslate_bricks"},
        {pos: [14, 4, 17], state: "minecraft:deepslate_bricks"},
        {pos: [14, 4, 18], state: "minecraft:deepslate_bricks"},
        {pos: [14, 4, 19], state: "minecraft:cave_air"},
        {pos: [14, 4, 20], state: "minecraft:cave_air"},
        {pos: [14, 4, 21], state: "minecraft:cave_air"},
        {pos: [14, 4, 22], state: "minecraft:cave_air"},
        {pos: [14, 4, 23], state: "minecraft:cave_air"},
        {pos: [14, 4, 24], state: "minecraft:deepslate_brick_stairs{facing:south,half:bottom,shape:straight,waterlogged:false}"},
        {pos: [14, 4, 25], state: "minecraft:deepslate_bricks"},
        {pos: [14, 4, 26], state: "minecraft:gravel"},
        {pos: [14, 4, 27], state: "minecraft:gravel"},
        {pos: [14, 4, 28], state: "minecraft:deepslate_bricks"},
        {pos: [14, 4, 29], state: "minecraft:deepslate_bricks"},
        {pos: [15, 4, 5], state: "minecraft:deepslate_bricks"},
        {pos: [15, 4, 6], state: "minecraft:deepslate_bricks"},
        {pos: [15, 4, 7], state: "minecraft:gravel"},
        {pos: [15, 4, 8], state: "minecraft:gravel"},
        {pos: [15, 4, 9], state: "minecraft:gravel"},
        {pos: [15, 4, 10], state: "minecraft:deepslate_brick_stairs{facing:north,half:bottom,shape:straight,waterlogged:false}"},
        {pos: [15, 4, 11], state: "minecraft:cave_air"},
        {pos: [15, 4, 12], state: "minecraft:cave_air"},
        {pos: [15, 4, 13], state: "minecraft:cave_air"},
        {pos: [15, 4, 14], state: "minecraft:cave_air"},
        {pos: [15, 4, 15], state: "minecraft:cave_air"},
        {pos: [15, 4, 16], state: "minecraft:deepslate_bricks"},
        {pos: [15, 4, 17], state: "minecraft:deepslate_bricks"},
        {pos: [15, 4, 18], state: "minecraft:deepslate_bricks"},
        {pos: [15, 4, 19], state: "minecraft:cave_air"},
        {pos: [15, 4, 20], state: "minecraft:cave_air"},
        {pos: [15, 4, 21], state: "minecraft:cave_air"},
        {pos: [15, 4, 22], state: "minecraft:cave_air"},
        {pos: [15, 4, 23], state: "minecraft:cave_air"},
        {pos: [15, 4, 24], state: "minecraft:deepslate_brick_stairs{facing:south,half:bottom,shape:straight,waterlogged:false}"},
        {pos: [15, 4, 25], state: "minecraft:deepslate_bricks"},
        {pos: [15, 4, 26], state: "minecraft:gravel"},
        {pos: [15, 4, 27], state: "minecraft:gravel"},
        {pos: [15, 4, 28], state: "minecraft:deepslate_bricks"},
        {pos: [15, 4, 29], state: "minecraft:deepslate_bricks"},
        {pos: [16, 4, 5], state: "minecraft:deepslate_bricks"},
        {pos: [16, 4, 6], state: "minecraft:deepslate_bricks"},
        {pos: [16, 4, 7], state: "minecraft:gravel"},
        {pos: [16, 4, 8], state: "minecraft:gravel"},
        {pos: [16, 4, 9], state: "minecraft:gravel"},
        {pos: [16, 4, 10], state: "minecraft:deepslate_brick_stairs{facing:north,half:bottom,shape:straight,waterlogged:false}"},
        {pos: [16, 4, 11], state: "minecraft:cave_air"},
        {pos: [16, 4, 12], state: "minecraft:cave_air"},
        {pos: [16, 4, 13], state: "minecraft:cave_air"},
        {pos: [16, 4, 14], state: "minecraft:cave_air"},
        {pos: [16, 4, 15], state: "minecraft:cave_air"},
        {pos: [16, 4, 16], state: "minecraft:deepslate_bricks"},
        {pos: [16, 4, 17], state: "minecraft:deepslate_bricks"},
        {pos: [16, 4, 18], state: "minecraft:deepslate_bricks"},
        {pos: [16, 4, 19], state: "minecraft:cave_air"},
        {pos: [16, 4, 20], state: "minecraft:cave_air"},
        {pos: [16, 4, 21], state: "minecraft:cobweb"},
        {pos: [16, 4, 22], state: "minecraft:cave_air"},
        {pos: [16, 4, 23], state: "minecraft:cave_air"},
        {pos: [16, 4, 24], state: "minecraft:deepslate_brick_stairs{facing:south,half:bottom,shape:straight,waterlogged:false}"},
        {pos: [16, 4, 25], state: "minecraft:gravel"},
        {pos: [16, 4, 26], state: "minecraft:gravel"},
        {pos: [16, 4, 27], state: "minecraft:gravel"},
        {pos: [16, 4, 28], state: "minecraft:deepslate_bricks"},
        {pos: [16, 4, 29], state: "minecraft:deepslate_bricks"},
        {pos: [17, 4, 5], state: "minecraft:deepslate_bricks"},
        {pos: [17, 4, 6], state: "minecraft:deepslate_bricks"},
        {pos: [17, 4, 7], state: "minecraft:gravel"},
        {pos: [17, 4, 8], state: "minecraft:gravel"},
        {pos: [17, 4, 9], state: "minecraft:gravel"},
        {pos: [17, 4, 10], state: "minecraft:deepslate_bricks"},
        {pos: [17, 4, 11], state: "minecraft:deepslate_bricks"},
        {pos: [17, 4, 12], state: "minecraft:deepslate_bricks"},
        {pos: [17, 4, 13], state: "minecraft:cave_air"},
        {pos: [17, 4, 14], state: "minecraft:cave_air"},
        {pos: [17, 4, 15], state: "minecraft:cave_air"},
        {pos: [17, 4, 16], state: "minecraft:cave_air"},
        {pos: [17, 4, 17], state: "minecraft:cave_air"},
        {pos: [17, 4, 18], state: "minecraft:cave_air"},
        {pos: [17, 4, 19], state: "minecraft:cave_air"},
        {pos: [17, 4, 20], state: "minecraft:cave_air"},
        {pos: [17, 4, 21], state: "minecraft:cave_air"},
        {pos: [17, 4, 22], state: "minecraft:deepslate_bricks"},
        {pos: [17, 4, 23], state: "minecraft:deepslate_bricks"},
        {pos: [17, 4, 24], state: "minecraft:deepslate_bricks"},
        {pos: [17, 4, 25], state: "minecraft:gravel"},
        {pos: [17, 4, 26], state: "minecraft:gravel"},
        {pos: [17, 4, 27], state: "minecraft:gravel"},
        {pos: [17, 4, 28], state: "minecraft:deepslate_bricks"},
        {pos: [17, 4, 29], state: "minecraft:deepslate_bricks"},
        {pos: [18, 4, 5], state: "minecraft:deepslate_bricks"},
        {pos: [18, 4, 6], state: "minecraft:gravel"},
        {pos: [18, 4, 7], state: "minecraft:gravel"},
        {pos: [18, 4, 8], state: "minecraft:gravel"},
        {pos: [18, 4, 9], state: "minecraft:gravel"},
        {pos: [18, 4, 10], state: "minecraft:gravel"},
        {pos: [18, 4, 11], state: "minecraft:deepslate_bricks"},
        {pos: [18, 4, 12], state: "minecraft:deepslate_bricks"},
        {pos: [18, 4, 13], state: "minecraft:cave_air"},
        {pos: [18, 4, 14], state: "minecraft:cave_air"},
        {pos: [18, 4, 15], state: "minecraft:cave_air"},
        {pos: [18, 4, 16], state: "minecraft:cave_air"},
        {pos: [18, 4, 17], state: "minecraft:cave_air"},
        {pos: [18, 4, 18], state: "minecraft:cave_air"},
        {pos: [18, 4, 19], state: "minecraft:cave_air"},
        {pos: [18, 4, 20], state: "minecraft:cave_air"},
        {pos: [18, 4, 21], state: "minecraft:cave_air"},
        {pos: [18, 4, 22], state: "minecraft:deepslate_bricks"},
        {pos: [18, 4, 23], state: "minecraft:deepslate_bricks"},
        {pos: [18, 4, 24], state: "minecraft:gravel"},
        {pos: [18, 4, 25], state: "minecraft:gravel"},
        {pos: [18, 4, 26], state: "minecraft:gravel"},
        {pos: [18, 4, 27], state: "minecraft:gravel"},
        {pos: [18, 4, 28], state: "minecraft:gravel"},
        {pos: [18, 4, 29], state: "minecraft:deepslate_bricks"},
        {pos: [19, 4, 5], state: "minecraft:deepslate_bricks"},
        {pos: [19, 4, 6], state: "minecraft:deepslate_bricks"},
        {pos: [19, 4, 7], state: "minecraft:gravel"},
        {pos: [19, 4, 8], state: "minecraft:gravel"},
        {pos: [19, 4, 9], state: "minecraft:gravel"},
        {pos: [19, 4, 10], state: "minecraft:deepslate_bricks"},
        {pos: [19, 4, 11], state: "minecraft:deepslate_bricks"},
        {pos: [19, 4, 12], state: "minecraft:deepslate_bricks"},
        {pos: [19, 4, 13], state: "minecraft:cave_air"},
        {pos: [19, 4, 14], state: "minecraft:cave_air"},
        {pos: [19, 4, 15], state: "minecraft:cave_air"},
        {pos: [19, 4, 16], state: "minecraft:cave_air"},
        {pos: [19, 4, 17], state: "minecraft:cave_air"},
        {pos: [19, 4, 18], state: "minecraft:cobweb"},
        {pos: [19, 4, 19], state: "minecraft:cave_air"},
        {pos: [19, 4, 20], state: "minecraft:cave_air"},
        {pos: [19, 4, 21], state: "minecraft:cave_air"},
        {pos: [19, 4, 22], state: "minecraft:deepslate_bricks"},
        {pos: [19, 4, 23], state: "minecraft:deepslate_bricks"},
        {pos: [19, 4, 24], state: "minecraft:deepslate_bricks"},
        {pos: [19, 4, 25], state: "minecraft:gravel"},
        {pos: [19, 4, 26], state: "minecraft:gravel"},
        {pos: [19, 4, 27], state: "minecraft:gravel"},
        {pos: [19, 4, 28], state: "minecraft:deepslate_bricks"},
        {pos: [19, 4, 29], state: "minecraft:deepslate_bricks"},
        {pos: [20, 4, 5], state: "minecraft:deepslate_bricks"},
        {pos: [20, 4, 6], state: "minecraft:deepslate_bricks"},
        {pos: [20, 4, 7], state: "minecraft:gravel"},
        {pos: [20, 4, 8], state: "minecraft:deepslate_bricks"},
        {pos: [20, 4, 9], state: "minecraft:deepslate_bricks"},
        {pos: [20, 4, 10], state: "minecraft:deepslate_bricks"},
        {pos: [20, 4, 11], state: "minecraft:deepslate_bricks"},
        {pos: [20, 4, 12], state: "minecraft:deepslate_bricks"},
        {pos: [20, 4, 13], state: "minecraft:cave_air"},
        {pos: [20, 4, 14], state: "minecraft:cave_air"},
        {pos: [20, 4, 15], state: "minecraft:cave_air"},
        {pos: [20, 4, 16], state: "minecraft:deepslate_bricks"},
        {pos: [20, 4, 17], state: "minecraft:deepslate_bricks"},
        {pos: [20, 4, 18], state: "minecraft:deepslate_bricks"},
        {pos: [20, 4, 19], state: "minecraft:cave_air"},
        {pos: [20, 4, 20], state: "minecraft:cave_air"},
        {pos: [20, 4, 21], state: "minecraft:cave_air"},
        {pos: [20, 4, 22], state: "minecraft:deepslate_bricks"},
        {pos: [20, 4, 23], state: "minecraft:deepslate_bricks"},
        {pos: [20, 4, 24], state: "minecraft:deepslate_bricks"},
        {pos: [20, 4, 25], state: "minecraft:deepslate_bricks"},
        {pos: [20, 4, 26], state: "minecraft:gravel"},
        {pos: [20, 4, 27], state: "minecraft:gravel"},
        {pos: [20, 4, 28], state: "minecraft:deepslate_bricks"},
        {pos: [20, 4, 29], state: "minecraft:deepslate_bricks"},
        {pos: [21, 4, 5], state: "minecraft:deepslate_bricks"},
        {pos: [21, 4, 6], state: "minecraft:deepslate_bricks"},
        {pos: [21, 4, 7], state: "minecraft:gravel"},
        {pos: [21, 4, 8], state: "minecraft:deepslate_bricks"},
        {pos: [21, 4, 9], state: "minecraft:deepslate_bricks"},
        {pos: [21, 4, 10], state: "minecraft:deepslate_bricks"},
        {pos: [21, 4, 11], state: "minecraft:deepslate_bricks"},
        {pos: [21, 4, 12], state: "minecraft:deepslate_bricks"},
        {pos: [21, 4, 13], state: "minecraft:cave_air"},
        {pos: [21, 4, 14], state: "minecraft:cave_air"},
        {pos: [21, 4, 15], state: "minecraft:cave_air"},
        {pos: [21, 4, 16], state: "minecraft:deepslate_bricks"},
        {pos: [21, 4, 17], state: "minecraft:deepslate_bricks"},
        {pos: [21, 4, 18], state: "minecraft:deepslate_bricks"},
        {pos: [21, 4, 19], state: "minecraft:cobweb"},
        {pos: [21, 4, 20], state: "minecraft:cave_air"},
        {pos: [21, 4, 21], state: "minecraft:cobweb"},
        {pos: [21, 4, 22], state: "minecraft:deepslate_bricks"},
        {pos: [21, 4, 23], state: "minecraft:deepslate_bricks"},
        {pos: [21, 4, 24], state: "minecraft:cave_air"},
        {pos: [21, 4, 25], state: "minecraft:deepslate_bricks"},
        {pos: [21, 4, 26], state: "minecraft:deepslate_bricks"},
        {pos: [21, 4, 27], state: "minecraft:gravel"},
        {pos: [21, 4, 28], state: "minecraft:deepslate_bricks"},
        {pos: [21, 4, 29], state: "minecraft:deepslate_bricks"},
        {pos: [22, 4, 5], state: "minecraft:deepslate_bricks"},
        {pos: [22, 4, 6], state: "minecraft:deepslate_bricks"},
        {pos: [22, 4, 7], state: "minecraft:gravel"},
        {pos: [22, 4, 8], state: "minecraft:gravel"},
        {pos: [22, 4, 9], state: "minecraft:deepslate_bricks"},
        {pos: [22, 4, 10], state: "minecraft:deepslate_bricks"},
        {pos: [22, 4, 11], state: "minecraft:deepslate_bricks"},
        {pos: [22, 4, 12], state: "minecraft:deepslate_bricks"},
        {pos: [22, 4, 13], state: "minecraft:cave_air"},
        {pos: [22, 4, 14], state: "minecraft:cave_air"},
        {pos: [22, 4, 15], state: "minecraft:cobweb"},
        {pos: [22, 4, 16], state: "minecraft:deepslate_bricks"},
        {pos: [22, 4, 17], state: "minecraft:deepslate_bricks"},
        {pos: [22, 4, 18], state: "minecraft:deepslate_bricks"},
        {pos: [22, 4, 19], state: "minecraft:deepslate_brick_stairs{facing:east,half:top,shape:straight,waterlogged:false}"},
        {pos: [22, 4, 20], state: "minecraft:deepslate_brick_stairs{facing:east,half:top,shape:straight,waterlogged:false}"},
        {pos: [22, 4, 21], state: "minecraft:deepslate_brick_stairs{facing:east,half:top,shape:straight,waterlogged:false}"},
        {pos: [22, 4, 22], state: "minecraft:deepslate_bricks"},
        {pos: [22, 4, 23], state: "minecraft:deepslate_bricks"},
        {pos: [22, 4, 24], state: "minecraft:deepslate_bricks"},
        {pos: [22, 4, 25], state: "minecraft:deepslate_bricks"},
        {pos: [22, 4, 26], state: "minecraft:gravel"},
        {pos: [22, 4, 27], state: "minecraft:gravel"},
        {pos: [22, 4, 28], state: "minecraft:deepslate_bricks"},
        {pos: [22, 4, 29], state: "minecraft:deepslate_bricks"},
        {pos: [23, 4, 5], state: "minecraft:deepslate_bricks"},
        {pos: [23, 4, 6], state: "minecraft:deepslate_bricks"},
        {pos: [23, 4, 7], state: "minecraft:deepslate_bricks"},
        {pos: [23, 4, 8], state: "minecraft:deepslate_bricks"},
        {pos: [23, 4, 9], state: "minecraft:deepslate_bricks"},
        {pos: [23, 4, 10], state: "minecraft:deepslate_bricks"},
        {pos: [23, 4, 11], state: "minecraft:deepslate_bricks"},
        {pos: [23, 4, 12], state: "minecraft:deepslate_bricks"},
        {pos: [23, 4, 13], state: "minecraft:deepslate_brick_stairs{facing:east,half:top,shape:straight,waterlogged:false}"},
        {pos: [23, 4, 14], state: "minecraft:deepslate_brick_stairs{facing:east,half:top,shape:straight,waterlogged:false}"},
        {pos: [23, 4, 15], state: "minecraft:deepslate_brick_stairs{facing:east,half:top,shape:straight,waterlogged:false}"},
        {pos: [23, 4, 16], state: "minecraft:deepslate_bricks"},
        {pos: [23, 4, 17], state: "minecraft:deepslate_bricks"},
        {pos: [23, 4, 18], state: "minecraft:deepslate_bricks"},
        {pos: [23, 4, 19], state: "minecraft:deepslate_bricks"},
        {pos: [23, 4, 20], state: "minecraft:deepslate_bricks"},
        {pos: [23, 4, 21], state: "minecraft:deepslate_bricks"},
        {pos: [23, 4, 22], state: "minecraft:deepslate_bricks"},
        {pos: [23, 4, 23], state: "minecraft:deepslate_bricks"},
        {pos: [23, 4, 24], state: "minecraft:deepslate_bricks"},
        {pos: [23, 4, 25], state: "minecraft:deepslate_bricks"},
        {pos: [23, 4, 26], state: "minecraft:deepslate_bricks"},
        {pos: [23, 4, 27], state: "minecraft:deepslate_bricks"},
        {pos: [23, 4, 28], state: "minecraft:deepslate_bricks"},
        {pos: [23, 4, 29], state: "minecraft:deepslate_bricks"},
        {pos: [24, 4, 12], state: "minecraft:deepslate_bricks"},
        {pos: [24, 4, 13], state: "minecraft:deepslate_bricks"},
        {pos: [24, 4, 14], state: "minecraft:deepslate_bricks"},
        {pos: [24, 4, 15], state: "minecraft:deepslate_bricks"},
        {pos: [24, 4, 16], state: "minecraft:deepslate_bricks"},
        {pos: [24, 4, 17], state: "minecraft:deepslate_bricks"},
        {pos: [6, 5, 18], state: "minecraft:deepslate_bricks"},
        {pos: [6, 5, 19], state: "minecraft:deepslate_bricks"},
        {pos: [6, 5, 20], state: "minecraft:deepslate_bricks"},
        {pos: [6, 5, 21], state: "minecraft:deepslate_bricks"},
        {pos: [6, 5, 22], state: "minecraft:deepslate_bricks"},
        {pos: [7, 5, 5], state: "minecraft:deepslate_bricks"},
        {pos: [7, 5, 6], state: "minecraft:deepslate_bricks"},
        {pos: [7, 5, 7], state: "minecraft:deepslate_bricks"},
        {pos: [7, 5, 8], state: "minecraft:deepslate_bricks"},
        {pos: [7, 5, 9], state: "minecraft:deepslate_bricks"},
        {pos: [7, 5, 10], state: "minecraft:deepslate_bricks"},
        {pos: [7, 5, 11], state: "minecraft:deepslate_bricks"},
        {pos: [7, 5, 12], state: "minecraft:deepslate_bricks"},
        {pos: [7, 5, 13], state: "minecraft:deepslate_bricks"},
        {pos: [7, 5, 14], state: "minecraft:deepslate_bricks"},
        {pos: [7, 5, 15], state: "minecraft:deepslate_bricks"},
        {pos: [7, 5, 16], state: "minecraft:deepslate_bricks"},
        {pos: [7, 5, 17], state: "minecraft:deepslate_bricks"},
        {pos: [7, 5, 18], state: "minecraft:deepslate_bricks"},
        {pos: [7, 5, 19], state: "minecraft:deepslate_bricks"},
        {pos: [7, 5, 20], state: "minecraft:deepslate_bricks"},
        {pos: [7, 5, 21], state: "minecraft:deepslate_bricks"},
        {pos: [7, 5, 22], state: "minecraft:deepslate_bricks"},
        {pos: [7, 5, 23], state: "minecraft:deepslate_bricks"},
        {pos: [7, 5, 24], state: "minecraft:deepslate_bricks"},
