{
    DataVersion: 3955,
    size: [42, 20, 31],
    data: [
        {pos: [16, 0, 14], state: "minecraft:deepslate_bricks"},
        {pos: [16, 0, 15], state: "minecraft:deepslate_bricks"},
        {pos: [16, 0, 16], state: "minecraft:deepslate_bricks"},
        {pos: [16, 0, 17], state: "minecraft:deepslate_bricks"},
        {pos: [16, 0, 18], state: "minecraft:deepslate_bricks"},
        {pos: [17, 0, 14], state: "minecraft:deepslate_bricks"},
        {pos: [17, 0, 15], state: "minecraft:deepslate_bricks"},
        {pos: [17, 0, 16], state: "minecraft:deepslate_bricks"},
        {pos: [17, 0, 17], state: "minecraft:deepslate_bricks"},
        {pos: [17, 0, 18], state: "minecraft:deepslate_bricks"},
        {pos: [18, 0, 14], state: "minecraft:deepslate_bricks"},
        {pos: [18, 0, 15], state: "minecraft:deepslate_bricks"},
        {pos: [18, 0, 16], state: "minecraft:deepslate_bricks"},
        {pos: [18, 0, 17], state: "minecraft:deepslate_bricks"},
        {pos: [18, 0, 18], state: "minecraft:deepslate_bricks"},
        {pos: [16, 1, 14], state: "minecraft:deepslate_bricks"},
        {pos: [16, 1, 15], state: "minecraft:deepslate_bricks"},
        {pos: [16, 1, 16], state: "minecraft:deepslate_bricks"},
        {pos: [16, 1, 17], state: "minecraft:deepslate_bricks"},
        {pos: [16, 1, 18], state: "minecraft:deepslate_bricks"},
        {pos: [17, 1, 14], state: "minecraft:deepslate_bricks"},
        {pos: [17, 1, 15], state: "minecraft:gravel"},
        {pos: [17, 1, 16], state: "minecraft:gravel"},
        {pos: [17, 1, 17], state: "minecraft:gravel"},
        {pos: [17, 1, 18], state: "minecraft:deepslate_bricks"},
        {pos: [18, 1, 14], state: "minecraft:deepslate_bricks"},
        {pos: [18, 1, 15], state: "minecraft:deepslate_bricks"},
        {pos: [18, 1, 16], state: "minecraft:deepslate_bricks"},
        {pos: [18, 1, 17], state: "minecraft:deepslate_bricks"},
        {pos: [18, 1, 18], state: "minecraft:deepslate_bricks"},
        {pos: [16, 2, 14], state: "minecraft:deepslate_bricks"},
        {pos: [16, 2, 15], state: "minecraft:deepslate_bricks"},
        {pos: [16, 2, 16], state: "minecraft:deepslate_bricks"},
        {pos: [16, 2, 17], state: "minecraft:deepslate_bricks"},
        {pos: [16, 2, 18], state: "minecraft:deepslate_bricks"},
        {pos: [17, 2, 14], state: "minecraft:deepslate_bricks"},
        {pos: [17, 2, 15], state: "minecraft:cave_air"},
        {pos: [17, 2, 16], state: "minecraft:cave_air"},
        {pos: [17, 2, 17], state: "minecraft:cave_air"},
        {pos: [17, 2, 18], state: "minecraft:deepslate_bricks"},
        {pos: [18, 2, 14], state: "minecraft:deepslate_bricks"},
        {pos: [18, 2, 15], state: "minecraft:deepslate_bricks"},
        {pos: [18, 2, 16], state: "minecraft:deepslate_bricks"},
        {pos: [18, 2, 17], state: "minecraft:deepslate_bricks"},
        {pos: [18, 2, 18], state: "minecraft:deepslate_bricks"},
        {pos: [8, 3, 7], state: "minecraft:deepslate_bricks"},
        {pos: [8, 3, 8], state: "minecraft:deepslate_bricks"},
        {pos: [8, 3, 9], state: "minecraft:deepslate_bricks"},
        {pos: [8, 3, 10], state: "minecraft:deepslate_bricks"},
        {pos: [8, 3, 11], state: "minecraft:deepslate_bricks"},
        {pos: [8, 3, 12], state: "minecraft:deepslate_bricks"},
        {pos: [8, 3, 13], state: "minecraft:deepslate_bricks"},
        {pos: [8, 3, 14], state: "minecraft:deepslate_bricks"},
        {pos: [8, 3, 15], state: "minecraft:deepslate_bricks"},
        {pos: [8, 3, 16], state: "minecraft:deepslate_bricks"},
        {pos: [8, 3, 17], state: "minecraft:deepslate_bricks"},
        {pos: [9, 3, 7], state: "minecraft:deepslate_bricks"},
        {pos: [9, 3, 8], state: "minecraft:deepslate_bricks"},
        {pos: [9, 3, 9], state: "minecraft:deepslate_bricks"},
        {pos: [9, 3, 10], state: "minecraft:deepslate_bricks"},
        {pos: [9, 3, 11], state: "minecraft:deepslate_bricks"},
        {pos: [9, 3, 12], state: "minecraft:deepslate_bricks"},
        {pos: [9, 3, 13], state: "minecraft:deepslate_bricks"},
        {pos: [9, 3, 14], state: "minecraft:deepslate_bricks"},
        {pos: [9, 3, 15], state: "minecraft:deepslate_bricks"},
        {pos: [9, 3, 16], state: "minecraft:deepslate_bricks"},
        {pos: [9, 3, 17], state: "minecraft:deepslate_bricks"},
        {pos: [10, 3, 7], state: "minecraft:deepslate_bricks"},
        {pos: [10, 3, 8], state: "minecraft:deepslate_bricks"},
        {pos: [10, 3, 9], state: "minecraft:deepslate_bricks"},
        {pos: [10, 3, 10], state: "minecraft:deepslate_bricks"},
        {pos: [10, 3, 11], state: "minecraft:deepslate_bricks"},
        {pos: [10, 3, 12], state: "minecraft:deepslate_bricks"},
        {pos: [10, 3, 13], state: "minecraft:deepslate_bricks"},
        {pos: [10, 3, 14], state: "minecraft:deepslate_bricks"},
        {pos: [10, 3, 15], state: "minecraft:deepslate_bricks"},
        {pos: [10, 3, 16], state: "minecraft:deepslate_bricks"},
        {pos: [10, 3, 17], state: "minecraft:deepslate_bricks"},
        {pos: [11, 3, 7], state: "minecraft:deepslate_bricks"},
        {pos: [11, 3, 8], state: "minecraft:deepslate_bricks"},
        {pos: [11, 3, 9], state: "minecraft:deepslate_bricks"},
        {pos: [12, 3, 7], state: "minecraft:deepslate_bricks"},
        {pos: [12, 3, 8], state: "minecraft:deepslate_bricks"},
        {pos: [12, 3, 9], state: "minecraft:deepslate_bricks"},
        {pos: [13, 3, 7], state: "minecraft:deepslate_bricks"},
        {pos: [13, 3, 8], state: "minecraft:deepslate_bricks"},
        {pos: [13, 3, 9], state: "minecraft:deepslate_bricks"},
        {pos: [14, 3, 7], state: "minecraft:deepslate_bricks"},
        {pos: [14, 3, 8], state: "minecraft:deepslate_bricks"},
        {pos: [14, 3, 9], state: "minecraft:deepslate_bricks"},
        {pos: [15, 3, 7], state: "minecraft:deepslate_bricks"},
        {pos: [15, 3, 8], state: "minecraft:deepslate_bricks"},
        {pos: [15, 3, 9], state: "minecraft:deepslate_bricks"},
        {pos: [16, 3, 7], state: "minecraft:deepslate_bricks"},
        {pos: [16, 3, 8], state: "minecraft:deepslate_bricks"},
        {pos: [16, 3, 9], state: "minecraft:deepslate_bricks"},
        {pos: [16, 3, 14], state: "minecraft:deepslate_bricks"},
        {pos: [16, 3, 15], state: "minecraft:deepslate_bricks"},
        {pos: [16, 3, 16], state: "minecraft:deepslate_bricks"},
        {pos: [16, 3, 17], state: "minecraft:deepslate_bricks"},
        {pos: [16, 3, 18], state: "minecraft:deepslate_bricks"},
        {pos: [17, 3, 7], state: "minecraft:deepslate_bricks"},
        {pos: [17, 3, 8], state: "minecraft:deepslate_bricks"},
        {pos: [17, 3, 9], state: "minecraft:deepslate_bricks"},
        {pos: [17, 3, 14], state: "minecraft:deepslate_bricks"},
        {pos: [17, 3, 15], state: "minecraft:cave_air"},
        {pos: [17, 3, 16], state: "minecraft:cave_air"},
        {pos: [17, 3, 17], state: "minecraft:cave_air"},
        {pos: [17, 3, 18], state: "minecraft:deepslate_bricks"},
        {pos: [18, 3, 7], state: "minecraft:deepslate_bricks"},
        {pos: [18, 3, 8], state: "minecraft:deepslate_bricks"},
        {pos: [18, 3, 9], state: "minecraft:deepslate_bricks"},
        {pos: [18, 3, 14], state: "minecraft:deepslate_bricks"},
        {pos: [18, 3, 15], state: "minecraft:deepslate_bricks"},
        {pos: [18, 3, 16], state: "minecraft:deepslate_bricks"},
        {pos: [18, 3, 17], state: "minecraft:deepslate_bricks"},
        {pos: [18, 3, 18], state: "minecraft:deepslate_bricks"},
        {pos: [19, 3, 7], state: "minecraft:deepslate_bricks"},
        {pos: [19, 3, 8], state: "minecraft:deepslate_bricks"},
        {pos: [19, 3, 9], state: "minecraft:deepslate_bricks"},
        {pos: [19, 3, 14], state: "minecraft:deepslate_bricks"},
        {pos: [19, 3, 15], state: "minecraft:deepslate_bricks"},
        {pos: [19, 3, 16], state: "minecraft:deepslate_bricks"},
        {pos: [19, 3, 17], state: "minecraft:deepslate_bricks"},
        {pos: [19, 3, 18], state: "minecraft:deepslate_bricks"},
        {pos: [20, 3, 7], state: "minecraft:deepslate_bricks"},
        {pos: [20, 3, 8], state: "minecraft:deepslate_bricks"},
        {pos: [20, 3, 9], state: "minecraft:deepslate_bricks"},
        {pos: [20, 3, 14], state: "minecraft:deepslate_bricks"},
        {pos: [20, 3, 15], state: "minecraft:deepslate_bricks"},
        {pos: [20, 3, 16], state: "minecraft:deepslate_bricks"},
        {pos: [20, 3, 17], state: "minecraft:deepslate_bricks"},
        {pos: [20, 3, 18], state: "minecraft:deepslate_bricks"},
        {pos: [21, 3, 7], state: "minecraft:deepslate_bricks"},
        {pos: [21, 3, 8], state: "minecraft:deepslate_bricks"},
        {pos: [21, 3, 9], state: "minecraft:deepslate_bricks"},
        {pos: [21, 3, 14], state: "minecraft:deepslate_bricks"},
        {pos: [21, 3, 15], state: "minecraft:deepslate_bricks"},
        {pos: [21, 3, 16], state: "minecraft:deepslate_bricks"},
        {pos: [21, 3, 17], state: "minecraft:deepslate_bricks"},
        {pos: [21, 3, 18], state: "minecraft:deepslate_bricks"},
        {pos: [22, 3, 7], state: "minecraft:deepslate_bricks"},
        {pos: [22, 3, 8], state: "minecraft:deepslate_bricks"},
        {pos: [22, 3, 9], state: "minecraft:deepslate_bricks"},
        {pos: [22, 3, 14], state: "minecraft:deepslate_bricks"},
        {pos: [22, 3, 15], state: "minecraft:deepslate_bricks"},
        {pos: [22, 3, 16], state: "minecraft:deepslate_bricks"},
        {pos: [22, 3, 17], state: "minecraft:deepslate_bricks"},
        {pos: [22, 3, 18], state: "minecraft:deepslate_bricks"},
        {pos: [23, 3, 7], state: "minecraft:deepslate_bricks"},
        {pos: [23, 3, 8], state: "minecraft:deepslate_bricks"},
        {pos: [23, 3, 9], state: "minecraft:deepslate_bricks"},
        {pos: [23, 3, 10], state: "minecraft:deepslate_bricks"},
        {pos: [23, 3, 11], state: "minecraft:deepslate_bricks"},
        {pos: [23, 3, 12], state: "minecraft:deepslate_bricks"},
        {pos: [23, 3, 13], state: "minecraft:deepslate_bricks"},
        {pos: [23, 3, 14], state: "minecraft:deepslate_bricks"},
        {pos: [23, 3, 15], state: "minecraft:deepslate_bricks"},
        {pos: [23, 3, 16], state: "minecraft:deepslate_bricks"},
        {pos: [23, 3, 17], state: "minecraft:deepslate_bricks"},
        {pos: [23, 3, 18], state: "minecraft:deepslate_bricks"},
        {pos: [24, 3, 7], state: "minecraft:deepslate_bricks"},
        {pos: [24, 3, 8], state: "minecraft:deepslate_bricks"},
        {pos: [24, 3, 9], state: "minecraft:deepslate_bricks"},
        {pos: [24, 3, 10], state: "minecraft:deepslate_bricks"},
        {pos: [24, 3, 11], state: "minecraft:deepslate_bricks"},
        {pos: [24, 3, 12], state: "minecraft:deepslate_bricks"},
        {pos: [24, 3, 13], state: "minecraft:deepslate_bricks"},
        {pos: [24, 3, 14], state: "minecraft:deepslate_bricks"},
        {pos: [24, 3, 15], state: "minecraft:deepslate_bricks"},
        {pos: [24, 3, 16], state: "minecraft:deepslate_bricks"},
        {pos: [24, 3, 17], state: "minecraft:deepslate_bricks"},
        {pos: [25, 3, 10], state: "minecraft:deepslate_bricks"},
        {pos: [25, 3, 11], state: "minecraft:deepslate_bricks"},
        {pos: [25, 3, 12], state: "minecraft:deepslate_bricks"},
        {pos: [25, 3, 13], state: "minecraft:deepslate_bricks"},
        {pos: [25, 3, 14], state: "minecraft:deepslate_bricks"},
        {pos: [25, 3, 15], state: "minecraft:deepslate_bricks"},
        {pos: [25, 3, 16], state: "minecraft:deepslate_bricks"},
        {pos: [25, 3, 17], state: "minecraft:deepslate_bricks"},
        {pos: [8, 4, 7], state: "minecraft:deepslate_bricks"},
        {pos: [8, 4, 8], state: "minecraft:deepslate_bricks"},
        {pos: [8, 4, 9], state: "minecraft:deepslate_bricks"},
        {pos: [8, 4, 10], state: "minecraft:deepslate_bricks"},
        {pos: [8, 4, 11], state: "minecraft:deepslate_bricks"},
        {pos: [8, 4, 12], state: "minecraft:deepslate_bricks"},
        {pos: [8, 4, 13], state: "minecraft:deepslate_bricks"},
        {pos: [8, 4, 14], state: "minecraft:deepslate_bricks"},
        {pos: [8, 4, 15], state: "minecraft:deepslate_bricks"},
        {pos: [8, 4, 16], state: "minecraft:deepslate_bricks"},
        {pos: [8, 4, 17], state: "minecraft:deepslate_bricks"},
        {pos: [9, 4, 7], state: "minecraft:deepslate_bricks"},
        {pos: [9, 4, 8], state: "minecraft:redstone_wire{east:side,north:none,power:0,south:side,west:none}"},
        {pos: [9, 4, 9], state: "minecraft:redstone_wire{east:none,north:side,power:0,south:side,west:none}"},
        {pos: [9, 4, 10], state: "minecraft:redstone_wire{east:none,north:side,power:0,south:side,west:none}"},
        {pos: [9, 4, 11], state: "minecraft:redstone_wire{east:none,north:side,power:0,south:side,west:none}"},
        {pos: [9, 4, 12], state: "minecraft:repeater{delay:1,facing:south,locked:false,powered:false}"},
        {pos: [9, 4, 13], state: "minecraft:redstone_wire{east:none,north:side,power:0,south:up,west:none}"},
        {pos: [9, 4, 14], state: "minecraft:deepslate_bricks"},
        {pos: [9, 4, 15], state: "minecraft:deepslate_bricks"},
        {pos: [9, 4, 16], state: "minecraft:deepslate_bricks"},
        {pos: [9, 4, 17], state: "minecraft:deepslate_bricks"},
        {pos: [10, 4, 7], state: "minecraft:deepslate_bricks"},
        {pos: [10, 4, 8], state: "minecraft:redstone_wire{east:side,north:none,power:0,south:none,west:side}"},
        {pos: [10, 4, 9], state: "minecraft:deepslate_bricks"},
        {pos: [10, 4, 10], state: "minecraft:deepslate_bricks"},
        {pos: [10, 4, 11], state: "minecraft:deepslate_bricks"},
        {pos: [10, 4, 12], state: "minecraft:deepslate_bricks"},
        {pos: [10, 4, 13], state: "minecraft:deepslate_bricks"},
        {pos: [10, 4, 14], state: "minecraft:deepslate_bricks"},
        {pos: [10, 4, 15], state: "minecraft:deepslate_bricks"},
        {pos: [10, 4, 16], state: "minecraft:deepslate_bricks"},
        {pos: [10, 4, 17], state: "minecraft:deepslate_bricks"},
        {pos: [11, 4, 7], state: "minecraft:deepslate_bricks"},
        {pos: [11, 4, 8], state: "minecraft:repeater{delay:1,facing:west,locked:false,powered:false}"},
        {pos: [11, 4, 9], state: "minecraft:deepslate_bricks"},
        {pos: [12, 4, 7], state: "minecraft:deepslate_bricks"},
        {pos: [12, 4, 8], state: "minecraft:redstone_wire{east:side,north:none,power:0,south:none,west:side}"},
        {pos: [12, 4, 9], state: "minecraft:deepslate_bricks"},
        {pos: [13, 4, 7], state: "minecraft:deepslate_bricks"},
        {pos: [13, 4, 8], state: "minecraft:redstone_wire{east:side,north:none,power:0,south:none,west:side}"},
        {pos: [13, 4, 9], state: "minecraft:deepslate_bricks"},
        {pos: [14, 4, 7], state: "minecraft:deepslate_bricks"},
        {pos: [14, 4, 8], state: "minecraft:redstone_wire{east:side,north:none,power:0,south:none,west:side}"},
        {pos: [14, 4, 9], state: "minecraft:deepslate_bricks"},
        {pos: [15, 4, 7], state: "minecraft:deepslate_bricks"},
        {pos: [15, 4, 8], state: "minecraft:repeater{delay:1,facing:west,locked:false,powered:false}"},
        {pos: [15, 4, 9], state: "minecraft:deepslate_bricks"},
        {pos: [16, 4, 7], state: "minecraft:deepslate_bricks"},
        {pos: [16, 4, 8], state: "minecraft:redstone_wire{east:side,north:none,power:0,south:none,west:side}"},
        {pos: [16, 4, 9], state: "minecraft:deepslate_bricks"},
        {pos: [16, 4, 14], state: "minecraft:deepslate_bricks"},
        {pos: [16, 4, 15], state: "minecraft:deepslate_bricks"},
        {pos: [16, 4, 16], state: "minecraft:deepslate_bricks"},
        {pos: [16, 4, 17], state: "minecraft:deepslate_bricks"},
        {pos: [16, 4, 18], state: "minecraft:deepslate_bricks"},
        {pos: [17, 4, 7], state: "minecraft:deepslate_bricks"},
        {pos: [17, 4, 8], state: "minecraft:redstone_wire{east:side,north:none,power:0,south:none,west:side}"},
        {pos: [17, 4, 9], state: "minecraft:deepslate_bricks"},
        {pos: [17, 4, 14], state: "minecraft:deepslate_bricks"},
        {pos: [17, 4, 15], state: "minecraft:cave_air"},
        {pos: [17, 4, 16], state: "minecraft:cave_air"},
        {pos: [17, 4, 17], state: "minecraft:cave_air"},
        {pos: [17, 4, 18], state: "minecraft:deepslate_bricks"},
        {pos: [18, 4, 7], state: "minecraft:deepslate_bricks"},
        {pos: [18, 4, 8], state: "minecraft:redstone_wire{east:side,north:none,power:0,south:none,west:side}"},
        {pos: [18, 4, 9], state: "minecraft:deepslate_bricks"},
        {pos: [18, 4, 14], state: "minecraft:deepslate_bricks"},
        {pos: [18, 4, 15], state: "minecraft:deepslate_bricks"},
        {pos: [18, 4, 16], state: "minecraft:deepslate_bricks"},
        {pos: [18, 4, 17], state: "minecraft:deepslate_bricks"},
        {pos: [18, 4, 18], state: "minecraft:deepslate_bricks"},
        {pos: [19, 4, 7], state: "minecraft:deepslate_bricks"},
        {pos: [19, 4, 8], state: "minecraft:redstone_wire{east:side,north:none,power:0,south:none,west:side}"},
        {pos: [19, 4, 9], state: "minecraft:deepslate_bricks"},
        {pos: [19, 4, 14], state: "minecraft:deepslate_bricks"},
        {pos: [19, 4, 15], state: "minecraft:redstone_wall_torch{facing:west,lit:true}"},
        {pos: [19, 4, 16], state: "minecraft:redstone_wall_torch{facing:west,lit:true}"},
        {pos: [19, 4, 17], state: "minecraft:redstone_wall_torch{facing:west,lit:true}"},
        {pos: [19, 4, 18], state: "minecraft:deepslate_bricks"},
        {pos: [20, 4, 7], state: "minecraft:deepslate_bricks"},
        {pos: [20, 4, 8], state: "minecraft:redstone_wire{east:side,north:none,power:0,south:none,west:side}"},
        {pos: [20, 4, 9], state: "minecraft:deepslate_bricks"},
        {pos: [20, 4, 14], state: "minecraft:deepslate_bricks"},
        {pos: [20, 4, 15], state: "minecraft:deepslate_bricks"},
        {pos: [20, 4, 16], state: "minecraft:deepslate_bricks"},
        {pos: [20, 4, 17], state: "minecraft:deepslate_bricks"},
        {pos: [20, 4, 18], state: "minecraft:deepslate_bricks"},
        {pos: [21, 4, 7], state: "minecraft:deepslate_bricks"},
        {pos: [21, 4, 8], state: "minecraft:repeater{delay:1,facing:west,locked:false,powered:false}"},
        {pos: [21, 4, 9], state: "minecraft:deepslate_bricks"},
        {pos: [21, 4, 14], state: "minecraft:deepslate_bricks"},
        {pos: [21, 4, 15], state: "minecraft:repeater{delay:1,facing:east,locked:false,powered:false}"},
        {pos: [21, 4, 16], state: "minecraft:repeater{delay:1,facing:east,locked:false,powered:false}"},
        {pos: [21, 4, 17], state: "minecraft:repeater{delay:1,facing:east,locked:false,powered:false}"},
        {pos: [21, 4, 18], state: "minecraft:deepslate_bricks"},
        {pos: [22, 4, 7], state: "minecraft:deepslate_bricks"},
        {pos: [22, 4, 8], state: "minecraft:redstone_wire{east:side,north:none,power:0,south:none,west:side}"},
        {pos: [22, 4, 9], state: "minecraft:deepslate_bricks"},
        {pos: [22, 4, 14], state: "minecraft:deepslate_bricks"},
        {pos: [22, 4, 15], state: "minecraft:redstone_wire{east:none,north:none,power:0,south:side,west:side}"},
        {pos: [22, 4, 16], state: "minecraft:redstone_wire{east:side,north:side,power:0,south:side,west:side}"},
        {pos: [22, 4, 17], state: "minecraft:redstone_wire{east:none,north:side,power:0,south:none,west:side}"},
        {pos: [22, 4, 18], state: "minecraft:deepslate_bricks"},
        {pos: [23, 4, 7], state: "minecraft:deepslate_bricks"},
        {pos: [23, 4, 8], state: "minecraft:redstone_wire{east:none,north:up,power:0,south:none,west:side}"},
        {pos: [23, 4, 9], state: "minecraft:deepslate_bricks"},
        {pos: [23, 4, 10], state: "minecraft:deepslate_bricks"},
        {pos: [23, 4, 11], state: "minecraft:deepslate_bricks"},
        {pos: [23, 4, 12], state: "minecraft:deepslate_bricks"},
        {pos: [23, 4, 13], state: "minecraft:deepslate_bricks"},
        {pos: [23, 4, 14], state: "minecraft:deepslate_bricks"},
        {pos: [23, 4, 15], state: "minecraft:deepslate_bricks"},
        {pos: [23, 4, 16], state: "minecraft:redstone_wall_torch{facing:west,lit:false}"},
        {pos: [23, 4, 17], state: "minecraft:deepslate_bricks"},
        {pos: [23, 4, 18], state: "minecraft:deepslate_bricks"},
        {pos: [24, 4, 7], state: "minecraft:deepslate_bricks"},
        {pos: [24, 4, 8], state: "minecraft:deepslate_bricks"},
        {pos: [24, 4, 9], state: "minecraft:deepslate_bricks"},
        {pos: [24, 4, 10], state: "minecraft:deepslate_bricks"},
        {pos: [24, 4, 11], state: "minecraft:deepslate_bricks"},
        {pos: [24, 4, 12], state: "minecraft:redstone_wire{east:none,north:up,power:7,south:side,west:none}"},
        {pos: [24, 4, 13], state: "minecraft:repeater{delay:1,facing:north,locked:false,powered:true}"},
        {pos: [24, 4, 14], state: "minecraft:redstone_wire{east:none,north:side,power:15,south:side,west:none}"},
        {pos: [24, 4, 15], state: "minecraft:repeater{delay:1,facing:north,locked:false,powered:true}"},
        {pos: [24, 4, 16], state: "minecraft:deepslate_bricks"},
        {pos: [24, 4, 17], state: "minecraft:deepslate_bricks"},
        {pos: [25, 4, 10], state: "minecraft:deepslate_bricks"},
        {pos: [25, 4, 11], state: "minecraft:deepslate_bricks"},
        {pos: [25, 4, 12], state: "minecraft:deepslate_bricks"},
        {pos: [25, 4, 13], state: "minecraft:deepslate_bricks"},
        {pos: [25, 4, 14], state: "minecraft:deepslate_bricks"},
        {pos: [25, 4, 15], state: "minecraft:deepslate_bricks"},
        {pos: [25, 4, 16], state: "minecraft:deepslate_bricks"},
        {pos: [25, 4, 17], state: "minecraft:deepslate_bricks"},
        {pos: [0, 5, 5], state: "minecraft:deepslate{axis:y}"},
        {pos: [0, 5, 6], state: "minecraft:deepslate{axis:y}"},
        {pos: [0, 5, 7], state: "minecraft:deepslate{axis:y}"},
        {pos: [0, 5, 8], state: "minecraft:deepslate{axis:y}"},
        {pos: [0, 5, 9], state: "minecraft:deepslate{axis:y}"},
        {pos: [0, 5, 10], state: "minecraft:deepslate{axis:y}"},
        {pos: [0, 5, 11], state: "minecraft:deepslate{axis:y}"},
        {pos: [0, 5, 12], state: "minecraft:deepslate{axis:y}"},
        {pos: [0, 5, 13], state: "minecraft:deepslate{axis:y}"},
        {pos: [0, 5, 14], state: "minecraft:deepslate{axis:y}"},
        {pos: [0, 5, 15], state: "minecraft:deepslate{axis:y}"},
        {pos: [0, 5, 16], state: "minecraft:deepslate{axis:y}"},
        {pos: [0, 5, 17], state: "minecraft:deepslate{axis:y}"},
        {pos: [0, 5, 18], state: "minecraft:deepslate{axis:y}"},
        {pos: [0, 5, 19], state: "minecraft:deepslate{axis:y}"},
        {pos: [0, 5, 20], state: "minecraft:deepslate{axis:y}"},
        {pos: [0, 5, 21], state: "minecraft:deepslate{axis:y}"},
        {pos: [0, 5, 22], state: "minecraft:deepslate{axis:y}"},
        {pos: [0, 5, 23], state: "minecraft:deepslate{axis:y}"},
        {pos: [0, 5, 24], state: "minecraft:deepslate{axis:y}"},
        {pos: [0, 5, 25], state: "minecraft:deepslate{axis:y}"},
        {pos: [1, 5, 5], state: "minecraft:deepslate{axis:y}"},
        {pos: [1, 5, 6], state: "minecraft:deepslate{axis:y}"},
        {pos: [1, 5, 7], state: "minecraft:deepslate{axis:y}"},
        {pos: [1, 5, 8], state: "minecraft:deepslate{axis:y}"},
        {pos: [1, 5, 9], state: "minecraft:deepslate{axis:y}"},
        {pos: [1, 5, 10], state: "minecraft:deepslate{axis:y}"},
        {pos: [1, 5, 11], state: "minecraft:deepslate{axis:y}"},
        {pos: [1, 5, 12], state: "minecraft:deepslate{axis:y}"},
        {pos: [1, 5, 13], state: "minecraft:deepslate{axis:y}"},
        {pos: [1, 5, 14], state: "minecraft:deepslate{axis:y}"},
        {pos: [1, 5, 15], state: "minecraft:deepslate{axis:y}"},
        {pos: [1, 5, 16], state: "minecraft:deepslate{axis:y}"},
        {pos: [1, 5, 17], state: "minecraft:deepslate{axis:y}"},
        {pos: [1, 5, 18], state: "minecraft:deepslate{axis:y}"},
        {pos: [1, 5, 19], state: "minecraft:deepslate{axis:y}"},
        {pos: [1, 5, 20], state: "minecraft:deepslate{axis:y}"},
        {pos: [1, 5, 21], state: "minecraft:deepslate{axis:y}"},
        {pos: [1, 5, 22], state: "minecraft:deepslate{axis:y}"},
        {pos: [1, 5, 23], state: "minecraft:deepslate{axis:y}"},
        {pos: [1, 5, 24], state: "minecraft:deepslate{axis:y}"},
        {pos: [1, 5, 25], state: "minecraft:deepslate{axis:y}"},
        {pos: [2, 5, 5], state: "minecraft:deepslate{axis:y}"},
        {pos: [2, 5, 6], state: "minecraft:deepslate{axis:y}"},
        {pos: [2, 5, 7], state: "minecraft:deepslate{axis:y}"},
        {pos: [2, 5, 8], state: "minecraft:deepslate{axis:y}"},
        {pos: [2, 5, 9], state: "minecraft:deepslate{axis:y}"},
        {pos: [2, 5, 10], state: "minecraft:deepslate{axis:y}"},
        {pos: [2, 5, 11], state: "minecraft:deepslate{axis:y}"},
        {pos: [2, 5, 12], state: "minecraft:deepslate{axis:y}"},
        {pos: [2, 5, 13], state: "minecraft:deepslate{axis:y}"},
        {pos: [2, 5, 14], state: "minecraft:deepslate{axis:y}"},
        {pos: [2, 5, 15], state: "minecraft:deepslate{axis:y}"},
        {pos: [2, 5, 16], state: "minecraft:deepslate{axis:y}"},
        {pos: [2, 5, 17], state: "minecraft:deepslate{axis:y}"},
        {pos: [2, 5, 18], state: "minecraft:deepslate{axis:y}"},
        {pos: [2, 5, 19], state: "minecraft:deepslate{axis:y}"},
        {pos: [2, 5, 20], state: "minecraft:deepslate{axis:y}"},
        {pos: [2, 5, 21], state: "minecraft:deepslate{axis:y}"},
        {pos: [2, 5, 22], state: "minecraft:deepslate{axis:y}"},
        {pos: [2, 5, 23], state: "minecraft:deepslate{axis:y}"},
        {pos: [2, 5, 24], state: "minecraft:deepslate{axis:y}"},
        {pos: [2, 5, 25], state: "minecraft:deepslate{axis:y}"},
        {pos: [3, 5, 2], state: "minecraft:deepslate{axis:y}"},
        {pos: [3, 5, 3], state: "minecraft:deepslate{axis:y}"},
        {pos: [3, 5, 4], state: "minecraft:deepslate{axis:y}"},
        {pos: [3, 5, 5], state: "minecraft:deepslate{axis:y}"},
        {pos: [3, 5, 6], state: "minecraft:deepslate{axis:y}"},
        {pos: [3, 5, 7], state: "minecraft:deepslate{axis:y}"},
        {pos: [3, 5, 8], state: "minecraft:deepslate{axis:y}"},
        {pos: [3, 5, 9], state: "minecraft:deepslate{axis:y}"},
        {pos: [3, 5, 10], state: "minecraft:deepslate{axis:y}"},
        {pos: [3, 5, 11], state: "minecraft:deepslate{axis:y}"},
        {pos: [3, 5, 12], state: "minecraft:deepslate{axis:y}"},
        {pos: [3, 5, 13], state: "minecraft:deepslate{axis:y}"},
        {pos: [3, 5, 14], state: "minecraft:deepslate{axis:y}"},
        {pos: [3, 5, 15], state: "minecraft:deepslate{axis:y}"},
        {pos: [3, 5, 16], state: "minecraft:deepslate{axis:y}"},
        {pos: [3, 5, 17], state: "minecraft:deepslate{axis:y}"},
        {pos: [3, 5, 18], state: "minecraft:deepslate{axis:y}"},
        {pos: [3, 5, 19], state: "minecraft:deepslate{axis:y}"},
        {pos: [3, 5, 20], state: "minecraft:deepslate{axis:y}"},
        {pos: [3, 5, 21], state: "minecraft:deepslate{axis:y}"},
        {pos: [3, 5, 22], state: "minecraft:deepslate{axis:y}"},
        {pos: [3, 5, 23], state: "minecraft:deepslate{axis:y}"},
        {pos: [3, 5, 24], state: "minecraft:deepslate{axis:y}"},
        {pos: [3, 5, 25], state: "minecraft:deepslate{axis:y}"},
        {pos: [3, 5, 26], state: "minecraft:deepslate{axis:y}"},
        {pos: [3, 5, 27], state: "minecraft:deepslate{axis:y}"},
        {pos: [3, 5, 28], state: "minecraft:deepslate{axis:y}"},
        {pos: [4, 5, 2], state: "minecraft:deepslate{axis:y}"},
        {pos: [4, 5, 3], state: "minecraft:deepslate{axis:y}"},
        {pos: [4, 5, 4], state: "minecraft:deepslate{axis:y}"},
        {pos: [4, 5, 5], state: "minecraft:deepslate{axis:y}"},
        {pos: [4, 5, 6], state: "minecraft:deepslate{axis:y}"},
        {pos: [4, 5, 7], state: "minecraft:deepslate{axis:y}"},
        {pos: [4, 5, 8], state: "minecraft:deepslate{axis:y}"},
        {pos: [4, 5, 9], state: "minecraft:deepslate{axis:y}"},
        {pos: [4, 5, 10], state: "minecraft:deepslate{axis:y}"},
        {pos: [4, 5, 11], state: "minecraft:deepslate{axis:y}"},
        {pos: [4, 5, 12], state: "minecraft:deepslate{axis:y}"},
        {pos: [4, 5, 13], state: "minecraft:deepslate{axis:y}"},
        {pos: [4, 5, 14], state: "minecraft:deepslate{axis:y}"},
        {pos: [4, 5, 15], state: "minecraft:deepslate{axis:y}"},
        {pos: [4, 5, 16], state: "minecraft:deepslate{axis:y}"},
        {pos: [4, 5, 17], state: "minecraft:deepslate{axis:y}"},
        {pos: [4, 5, 18], state: "minecraft:deepslate{axis:y}"},
        {pos: [4, 5, 19], state: "minecraft:deepslate{axis:y}"},
        {pos: [4, 5, 20], state: "minecraft:deepslate{axis:y}"},
        {pos: [4, 5, 21], state: "minecraft:deepslate{axis:y}"},
        {pos: [4, 5, 22], state: "minecraft:deepslate{axis:y}"},
        {pos: [4, 5, 23], state: "minecraft:deepslate{axis:y}"},
        {pos: [4, 5, 24], state: "minecraft:deepslate{axis:y}"},
        {pos: [4, 5, 25], state: "minecraft:deepslate{axis:y}"},
        {pos: [4, 5, 26], state: "minecraft:deepslate{axis:y}"},
        {pos: [4, 5, 27], state: "minecraft:deepslate{axis:y}"},
        {pos: [4, 5, 28], state: "minecraft:deepslate{axis:y}"},
        {pos: [5, 5, 2], state: "minecraft:deepslate{axis:y}"},
        {pos: [5, 5, 3], state: "minecraft:deepslate{axis:y}"},
        {pos: [5, 5, 4], state: "minecraft:deepslate{axis:y}"},
        {pos: [5, 5, 5], state: "minecraft:deepslate{axis:y}"},
        {pos: [5, 5, 6], state: "minecraft:deepslate{axis:y}"},
        {pos: [5, 5, 7], state: "minecraft:deepslate{axis:y}"},
        {pos: [5, 5, 8], state: "minecraft:deepslate{axis:y}"},
        {pos: [5, 5, 9], state: "minecraft:deepslate{axis:y}"},
        {pos: [5, 5, 10], state: "minecraft:deepslate{axis:y}"},
        {pos: [5, 5, 11], state: "minecraft:deepslate{axis:y}"},
        {pos: [5, 5, 12], state: "minecraft:deepslate{axis:y}"},
        {pos: [5, 5, 13], state: "minecraft:deepslate{axis:y}"},
        {pos: [5, 5, 14], state: "minecraft:deepslate{axis:y}"},
        {pos: [5, 5, 15], state: "minecraft:deepslate{axis:y}"},
        {pos: [5, 5, 16], state: "minecraft:deepslate{axis:y}"},
        {pos: [5, 5, 17], state: "minecraft:deepslate{axis:y}"},
        {pos: [5, 5, 18], state: "minecraft:deepslate{axis:y}"},
        {pos: [5, 5, 19], state: "minecraft:deepslate{axis:y}"},
        {pos: [5, 5, 20], state: "minecraft:deepslate{axis:y}"},
        {pos: [5, 5, 21], state: "minecraft:deepslate{axis:y}"},
        {pos: [5, 5, 22], state: "minecraft:deepslate{axis:y}"},
        {pos: [5, 5, 23], state: "minecraft:deepslate{axis:y}"},
        {pos: [5, 5, 24], state: "minecraft:deepslate{axis:y}"},
        {pos: [5, 5, 25], state: "minecraft:deepslate{axis:y}"},
        {pos: [5, 5, 26], state: "minecraft:deepslate{axis:y}"},
        {pos: [5, 5, 27], state: "minecraft:deepslate{axis:y}"},
        {pos: [5, 5, 28], state: "minecraft:deepslate{axis:y}"},
        {pos: [6, 5, 2], state: "minecraft:deepslate{axis:y}"},
        {pos: [6, 5, 3], state: "minecraft:deepslate{axis:y}"},
        {pos: [6, 5, 4], state: "minecraft:deepslate{axis:y}"},
        {pos: [6, 5, 5], state: "minecraft:deepslate{axis:y}"},
        {pos: [6, 5, 6], state: "minecraft:deepslate{axis:y}"},
        {pos: [6, 5, 7], state: "minecraft:deepslate{axis:y}"},
        {pos: [6, 5, 8], state: "minecraft:deepslate{axis:y}"},
        {pos: [6, 5, 9], state: "minecraft:deepslate{axis:y}"},
        {pos: [6, 5, 10], state: "minecraft:deepslate{axis:y}"},
        {pos: [6, 5, 11], state: "minecraft:deepslate{axis:y}"},
        {pos: [6, 5, 12], state: "minecraft:deepslate{axis:y}"},
        {pos: [6, 5, 13], state: "minecraft:deepslate{axis:y}"},
        {pos: [6, 5, 14], state: "minecraft:deepslate{axis:y}"},
        {pos: [6, 5, 15], state: "minecraft:deepslate{axis:y}"},
        {pos: [6, 5, 16], state: "minecraft:deepslate{axis:y}"},
        {pos: [6, 5, 17], state: "minecraft:deepslate{axis:y}"},
        {pos: [6, 5, 18], state: "minecraft:deepslate{axis:y}"},
        {pos: [6, 5, 19], state: "minecraft:deepslate{axis:y}"},
        {pos: [6, 5, 20], state: "minecraft:deepslate{axis:y}"},
        {pos: [6, 5, 21], state: "minecraft:deepslate{axis:y}"},
        {pos: [6, 5, 22], state: "minecraft:deepslate{axis:y}"},
        {pos: [6, 5, 23], state: "minecraft:deepslate{axis:y}"},
        {pos: [6, 5, 24], state: "minecraft:deepslate{axis:y}"},
        {pos: [6, 5, 25], state: "minecraft:deepslate{axis:y}"},
        {pos: [6, 5, 26], state: "minecraft:deepslate{axis:y}"},
        {pos: [6, 5, 27], state: "minecraft:deepslate{axis:y}"},
        {pos: [6, 5, 28], state: "minecraft:deepslate{axis:y}"},
        {pos: [7, 5, 0], state: "minecraft:deepslate{axis:y}"},
        {pos: [7, 5, 1], state: "minecraft:deepslate{axis:y}"},
        {pos: [7, 5, 2], state: "minecraft:deepslate{axis:y}"},
        {pos: [7, 5, 3], state: "minecraft:deepslate{axis:y}"},
        {pos: [7, 5, 4], state: "minecraft:deepslate{axis:y}"},
        {pos: [7, 5, 5], state: "minecraft:deepslate{axis:y}"},
        {pos: [7, 5, 6], state: "minecraft:deepslate{axis:y}"},
        {pos: [7, 5, 7], state: "minecraft:deepslate{axis:y}"},
        {pos: [7, 5, 8], state: "minecraft:deepslate{axis:y}"},
        {pos: [7, 5, 9], state: "minecraft:deepslate{axis:y}"},
        {pos: [7, 5, 10], state: "minecraft:deepslate{axis:y}"},
        {pos: [7, 5, 11], state: "minecraft:deepslate{axis:y}"},
        {pos: [7, 5, 12], state: "minecraft:deepslate{axis:y}"},
        {pos: [7, 5, 13], state: "minecraft:deepslate{axis:y}"},
        {pos: [7, 5, 14], state: "minecraft:deepslate{axis:y}"},
        {pos: [7, 5, 15], state: "minecraft:deepslate{axis:y}"},
        {pos: [7, 5, 16], state: "minecraft:deepslate{axis:y}"},
        {pos: [7, 5, 17], state: "minecraft:deepslate{axis:y}"},
        {pos: [7, 5, 18], state: "minecraft:deepslate{axis:y}"},
        {pos: [7, 5, 19], state: "minecraft:deepslate{axis:y}"},
        {pos: [7, 5, 20], state: "minecraft:deepslate{axis:y}"},
        {pos: [7, 5, 21], state: "minecraft:deepslate{axis:y}"},
        {pos: [7, 5, 22], state: "minecraft:deepslate{axis:y}"},
        {pos: [7, 5, 23], state: "minecraft:deepslate{axis:y}"},
        {pos: [7, 5, 24], state: "minecraft:deepslate{axis:y}"},
        {pos: [7, 5, 25], state: "minecraft:deepslate{axis:y}"},
        {pos: [7, 5, 26], state: "minecraft:deepslate{axis:y}"},
        {pos: [7, 5, 27], state: "minecraft:deepslate{axis:y}"},
        {pos: [7, 5, 28], state: "minecraft:deepslate{axis:y}"},
        {pos: [8, 5, 0], state: "minecraft:deepslate{axis:y}"},
        {pos: [8, 5, 1], state: "minecraft:deepslate{axis:y}"},
        {pos: [8, 5, 2], state: "minecraft:deepslate{axis:y}"},
        {pos: [8, 5, 3], state: "minecraft:deepslate{axis:y}"},
        {pos: [8, 5, 4], state: "minecraft:deepslate{axis:y}"},
        {pos: [8, 5, 5], state: "minecraft:deepslate{axis:y}"},
        {pos: [8, 5, 6], state: "minecraft:deepslate{axis:y}"},
        {pos: [8, 5, 7], state: "minecraft:deepslate{axis:y}"},
        {pos: [8, 5, 8], state: "minecraft:deepslate{axis:y}"},
        {pos: [8, 5, 9], state: "minecraft:deepslate{axis:y}"},
        {pos: [8, 5, 10], state: "minecraft:deepslate{axis:y}"},
        {pos: [8, 5, 11], state: "minecraft:deepslate{axis:y}"},
        {pos: [8, 5, 12], state: "minecraft:deepslate{axis:y}"},
        {pos: [8, 5, 13], state: "minecraft:deepslate{axis:y}"},
        {pos: [8, 5, 14], state: "minecraft:deepslate{axis:y}"},
        {pos: [8, 5, 15], state: "minecraft:deepslate_bricks"},
        {pos: [8, 5, 16], state: "minecraft:deepslate_bricks"},
        {pos: [8, 5, 17], state: "minecraft:deepslate_bricks"},
        {pos: [8, 5, 18], state: "minecraft:deepslate{axis:y}"},
        {pos: [8, 5, 19], state: "minecraft:deepslate{axis:y}"},
        {pos: [8, 5, 20], state: "minecraft:deepslate{axis:y}"},
        {pos: [8, 5, 21], state: "minecraft:deepslate{axis:y}"},
        {pos: [8, 5, 22], state: "minecraft:deepslate{axis:y}"},
        {pos: [8, 5, 23], state: "minecraft:deepslate{axis:y}"},
        {pos: [8, 5, 24], state: "minecraft:deepslate{axis:y}"},
        {pos: [8, 5, 25], state: "minecraft:deepslate{axis:y}"},
        {pos: [8, 5, 26], state: "minecraft:deepslate{axis:y}"},
        {pos: [8, 5, 27], state: "minecraft:deepslate{axis:y}"},
        {pos: [8, 5, 28], state: "minecraft:deepslate{axis:y}"},
        {pos: [9, 5, 0], state: "minecraft:deepslate{axis:y}"},
        {pos: [9, 5, 1], state: "minecraft:deepslate{axis:y}"},
        {pos: [9, 5, 2], state: "minecraft:deepslate{axis:y}"},
        {pos: [9, 5, 3], state: "minecraft:deepslate{axis:y}"},
        {pos: [9, 5, 4], state: "minecraft:deepslate{axis:y}"},
        {pos: [9, 5, 5], state: "minecraft:deepslate{axis:y}"},
        {pos: [9, 5, 6], state: "minecraft:deepslate{axis:y}"},
        {pos: [9, 5, 7], state: "minecraft:deepslate{axis:y}"},
        {pos: [9, 5, 8], state: "minecraft:deepslate{axis:y}"},
        {pos: [9, 5, 9], state: "minecraft:deepslate{axis:y}"},
        {pos: [9, 5, 10], state: "minecraft:deepslate{axis:y}"},
        {pos: [9, 5, 11], state: "minecraft:deepslate{axis:y}"},
        {pos: [9, 5, 12], state: "minecraft:deepslate{axis:y}"},
        {pos: [9, 5, 13], state: "minecraft:deepslate_brick_slab{type:top,waterlogged:false}"},
        {pos: [9, 5, 14], state: "minecraft:redstone_wire{east:none,north:side,power:0,south:side,west:none}"},
        {pos: [9, 5, 15], state: "minecraft:repeater{delay:1,facing:south,locked:false,powered:false}"},
        {pos: [9, 5, 16], state: "minecraft:redstone_wire{east:none,north:side,power:0,south:side,west:none}"},
        {pos: [9, 5, 17], state: "minecraft:deepslate_bricks"},
        {pos: [9, 5, 18], state: "minecraft:deepslate{axis:y}"},
        {pos: [9, 5, 19], state: "minecraft:deepslate{axis:y}"},
        {pos: [9, 5, 20], state: "minecraft:deepslate{axis:y}"},
        {pos: [9, 5, 21], state: "minecraft:deepslate{axis:y}"},
        {pos: [9, 5, 22], state: "minecraft:deepslate{axis:y}"},
        {pos: [9, 5, 23], state: "minecraft:deepslate{axis:y}"},
        {pos: [9, 5, 24], state: "minecraft:deepslate{axis:y}"},
        {pos: [9, 5, 25], state: "minecraft:deepslate{axis:y}"},
        {pos: [9, 5, 26], state: "minecraft:deepslate{axis:y}"},
        {pos: [9, 5, 27], state: "minecraft:deepslate{axis:y}"},
        {pos: [9, 5, 28], state: "minecraft:deepslate{axis:y}"},
        {pos: [10, 5, 0], state: "minecraft:deepslate{axis:y}"},
        {pos: [10, 5, 1], state: "minecraft:deepslate{axis:y}"},
        {pos: [10, 5, 2], state: "minecraft:deepslate{axis:y}"},
        {pos: [10, 5, 3], state: "minecraft:deepslate{axis:y}"},
        {pos: [10, 5, 4], state: "minecraft:deepslate{axis:y}"},
        {pos: [10, 5, 5], state: "minecraft:deepslate{axis:y}"},
        {pos: [10, 5, 6], state: "minecraft:deepslate{axis:y}"},
        {pos: [10, 5, 7], state: "minecraft:deepslate{axis:y}"},
        {pos: [10, 5, 8], state: "minecraft:deepslate{axis:y}"},
        {pos: [10, 5, 9], state: "minecraft:deepslate{axis:y}"},
        {pos: [10, 5, 10], state: "minecraft:deepslate{axis:y}"},
        {pos: [10, 5, 11], state: "minecraft:deepslate{axis:y}"},
        {pos: [10, 5, 12], state: "minecraft:deepslate{axis:y}"},
        {pos: [10, 5, 13], state: "minecraft:deepslate{axis:y}"},
        {pos: [10, 5, 14], state: "minecraft:deepslate{axis:y}"},
        {pos: [10, 5, 15], state: "minecraft:deepslate_bricks"},
        {pos: [10, 5, 16], state: "minecraft:deepslate_bricks"},
        {pos: [10, 5, 17], state: "minecraft:deepslate_bricks"},
        {pos: [10, 5, 18], state: "minecraft:deepslate{axis:y}"},
        {pos: [10, 5, 19], state: "minecraft:deepslate{axis:y}"},
        {pos: [10, 5, 20], state: "minecraft:deepslate{axis:y}"},
        {pos: [10, 5, 21], state: "minecraft:deepslate{axis:y}"},
        {pos: [10, 5, 22], state: "minecraft:deepslate{axis:y}"},
        {pos: [10, 5, 23], state: "minecraft:deepslate{axis:y}"},
        {pos: [10, 5, 24], state: "minecraft:deepslate{axis:y}"},
        {pos: [10, 5, 25], state: "minecraft:deepslate{axis:y}"},
        {pos: [10, 5, 26], state: "minecraft:deepslate{axis:y}"},
        {pos: [10, 5, 27], state: "minecraft:deepslate{axis:y}"},
        {pos: [10, 5, 28], state: "minecraft:deepslate{axis:y}"},
        {pos: [11, 5, 0], state: "minecraft:deepslate{axis:y}"},
        {pos: [11, 5, 1], state: "minecraft:deepslate{axis:y}"},
        {pos: [11, 5, 2], state: "minecraft:deepslate{axis:y}"},
        {pos: [11, 5, 3], state: "minecraft:deepslate{axis:y}"},
        {pos: [11, 5, 4], state: "minecraft:deepslate{axis:y}"},
        {pos: [11, 5, 5], state: "minecraft:deepslate{axis:y}"},
        {pos: [11, 5, 6], state: "minecraft:deepslate{axis:y}"},
        {pos: [11, 5, 7], state: "minecraft:deepslate{axis:y}"},
        {pos: [11, 5, 8], state: "minecraft:deepslate{axis:y}"},
        {pos: [11, 5, 9], state: "minecraft:deepslate{axis:y}"},
        {pos: [11, 5, 10], state: "minecraft:deepslate{axis:y}"},
        {pos: [11, 5, 11], state: "minecraft:deepslate{axis:y}"},
        {pos: [11, 5, 12], state: "minecraft:deepslate{axis:y}"},
        {pos: [11, 5, 13], state: "minecraft:deepslate{axis:y}"},
        {pos: [11, 5, 14], state: "minecraft:deepslate{axis:y}"},
        {pos: [11, 5, 15], state: "minecraft:deepslate{axis:y}"},
        {pos: [11, 5, 16], state: "minecraft:deepslate{axis:y}"},
        {pos: [11, 5, 17], state: "minecraft:deepslate{axis:y}"},
        {pos: [11, 5, 18], state: "minecraft:deepslate{axis:y}"},
        {pos: [11, 5, 19], state: "minecraft:deepslate{axis:y}"},
        {pos: [11, 5, 20], state: "minecraft:deepslate{axis:y}"},
        {pos: [11, 5, 21], state: "minecraft:deepslate{axis:y}"},
        {pos: [11, 5, 22], state: "minecraft:deepslate{axis:y}"},
        {pos: [11, 5, 23], state: "minecraft:deepslate{axis:y}"},
        {pos: [11, 5, 24], state: "minecraft:deepslate{axis:y}"},
        {pos: [11, 5, 25], state: "minecraft:deepslate{axis:y}"},
        {pos: [11, 5, 26], state: "minecraft:deepslate{axis:y}"},
        {pos: [11, 5, 27], state: "minecraft:deepslate{axis:y}"},
        {pos: [11, 5, 28], state: "minecraft:deepslate{axis:y}"},
        {pos: [11, 5, 29], state: "minecraft:deepslate{axis:y}"},
        {pos: [11, 5, 30], state: "minecraft:deepslate{axis:y}"},
        {pos: [12, 5, 0], state: "minecraft:deepslate{axis:y}"},
        {pos: [12, 5, 1], state: "minecraft:deepslate{axis:y}"},
        {pos: [12, 5, 2], state: "minecraft:deepslate{axis:y}"},
        {pos: [12, 5, 3], state: "minecraft:deepslate{axis:y}"},
        {pos: [12, 5, 4], state: "minecraft:deepslate{axis:y}"},
        {pos: [12, 5, 5], state: "minecraft:deepslate{axis:y}"},
        {pos: [12, 5, 6], state: "minecraft:deepslate{axis:y}"},
        {pos: [12, 5, 7], state: "minecraft:deepslate{axis:y}"},
        {pos: [12, 5, 8], state: "minecraft:deepslate{axis:y}"},
        {pos: [12, 5, 9], state: "minecraft:deepslate{axis:y}"},
        {pos: [12, 5, 10], state: "minecraft:deepslate{axis:y}"},
        {pos: [12, 5, 11], state: "minecraft:deepslate{axis:y}"},
        {pos: [12, 5, 12], state: "minecraft:deepslate{axis:y}"},
        {pos: [12, 5, 13], state: "minecraft:deepslate{axis:y}"},
        {pos: [12, 5, 14], state: "minecraft:deepslate{axis:y}"},
        {pos: [12, 5, 15], state: "minecraft:deepslate{axis:y}"},
        {pos: [12, 5, 16], state: "minecraft:deepslate{axis:y}"},
        {pos: [12, 5, 17], state: "minecraft:deepslate{axis:y}"},
        {pos: [12, 5, 18], state: "minecraft:deepslate{axis:y}"},
        {pos: [12, 5, 19], state: "minecraft:deepslate{axis:y}"},
        {pos: [12, 5, 20], state: "minecraft:deepslate{axis:y}"},
        {pos: [12, 5, 21], state: "minecraft:deepslate{axis:y}"},
        {pos: [12, 5, 22], state: "minecraft:deepslate{axis:y}"},
        {pos: [12, 5, 23], state: "minecraft:deepslate{axis:y}"},
        {pos: [12, 5, 24], state: "minecraft:deepslate{axis:y}"},
        {pos: [12, 5, 25], state: "minecraft:deepslate{axis:y}"},
        {pos: [12, 5, 26], state: "minecraft:deepslate{axis:y}"},
        {pos: [12, 5, 27], state: "minecraft:deepslate{axis:y}"},
        {pos: [12, 5, 28], state: "minecraft:deepslate{axis:y}"},
        {pos: [12, 5, 29], state: "minecraft:deepslate{axis:y}"},
        {pos: [12, 5, 30], state: "minecraft:deepslate{axis:y}"},
        {pos: [13, 5, 0], state: "minecraft:deepslate{axis:y}"},
        {pos: [13, 5, 1], state: "minecraft:deepslate{axis:y}"},
        {pos: [13, 5, 2], state: "minecraft:deepslate{axis:y}"},
        {pos: [13, 5, 3], state: "minecraft:deepslate{axis:y}"},
        {pos: [13, 5, 4], state: "minecraft:deepslate{axis:y}"},
        {pos: [13, 5, 5], state: "minecraft:deepslate{axis:y}"},
        {pos: [13, 5, 6], state: "minecraft:deepslate{axis:y}"},
        {pos: [13, 5, 7], state: "minecraft:deepslate{axis:y}"},
        {pos: [13, 5, 8], state: "minecraft:deepslate{axis:y}"},
        {pos: [13, 5, 9], state: "minecraft:deepslate{axis:y}"},
        {pos: [13, 5, 10], state: "minecraft:deepslate{axis:y}"},
        {pos: [13, 5, 11], state: "minecraft:deepslate{axis:y}"},
        {pos: [13, 5, 12], state: "minecraft:deepslate{axis:y}"},
        {pos: [13, 5, 13], state: "minecraft:deepslate{axis:y}"},
        {pos: [13, 5, 14], state: "minecraft:deepslate{axis:y}"},
        {pos: [13, 5, 15], state: "minecraft:deepslate{axis:y}"},
        {pos: [13, 5, 16], state: "minecraft:deepslate{axis:y}"},
        {pos: [13, 5, 17], state: "minecraft:deepslate{axis:y}"},
        {pos: [13, 5, 18], state: "minecraft:deepslate{axis:y}"},
        {pos: [13, 5, 19], state: "minecraft:deepslate{axis:y}"},
        {pos: [13, 5, 20], state: "minecraft:deepslate{axis:y}"},
        {pos: [13, 5, 21], state: "minecraft:deepslate{axis:y}"},
        {pos: [13, 5, 22], state: "minecraft:deepslate{axis:y}"},
        {pos: [13, 5, 23], state: "minecraft:deepslate{axis:y}"},
        {pos: [13, 5, 24], state: "minecraft:deepslate{axis:y}"},
        {pos: [13, 5, 25], state: "minecraft:deepslate{axis:y}"},
        {pos: [13, 5, 26], state: "minecraft:deepslate{axis:y}"},
        {pos: [13, 5, 27], state: "minecraft:deepslate{axis:y}"},
        {pos: [13, 5, 28], state: "minecraft:deepslate{axis:y}"},
        {pos: [13, 5, 29], state: "minecraft:deepslate{axis:y}"},
        {pos: [13, 5, 30], state: "minecraft:deepslate{axis:y}"},
        {pos: [14, 5, 0], state: "minecraft:deepslate{axis:y}"},
        {pos: [14, 5, 1], state: "minecraft:deepslate{axis:y}"},
        {pos: [14, 5, 2], state: "minecraft:deepslate{axis:y}"},
        {pos: [14, 5, 3], state: "minecraft:deepslate{axis:y}"},
        {pos: [14, 5, 4], state: "minecraft:deepslate{axis:y}"},
        {pos: [14, 5, 5], state: "minecraft:deepslate{axis:y}"},
        {pos: [14, 5, 6], state: "minecraft:deepslate{axis:y}"},
        {pos: [14, 5, 7], state: "minecraft:deepslate{axis:y}"},
        {pos: [14, 5, 8], state: "minecraft:deepslate{axis:y}"},
        {pos: [14, 5, 9], state: "minecraft:deepslate{axis:y}"},
        {pos: [14, 5, 10], state: "minecraft:deepslate{axis:y}"},
        {pos: [14, 5, 11], state: "minecraft:deepslate{axis:y}"},
        {pos: [14, 5, 12], state: "minecraft:deepslate{axis:y}"},
        {pos: [14, 5, 13], state: "minecraft:deepslate{axis:y}"},
        {pos: [14, 5, 14], state: "minecraft:deepslate{axis:y}"},
        {pos: [14, 5, 15], state: "minecraft:deepslate{axis:y}"},
        {pos: [14, 5, 16], state: "minecraft:deepslate{axis:y}"},
        {pos: [14, 5, 17], state: "minecraft:deepslate{axis:y}"},
        {pos: [14, 5, 18], state: "minecraft:deepslate{axis:y}"},
        {pos: [14, 5, 19], state: "minecraft:deepslate{axis:y}"},
        {pos: [14, 5, 20], state: "minecraft:deepslate{axis:y}"},
        {pos: [14, 5, 21], state: "minecraft:deepslate{axis:y}"},
        {pos: [14, 5, 22], state: "minecraft:deepslate{axis:y}"},
        {pos: [14, 5, 23], state: "minecraft:deepslate{axis:y}"},
        {pos: [14, 5, 24], state: "minecraft:deepslate{axis:y}"},
        {pos: [14, 5, 25], state: "minecraft:deepslate{axis:y}"},
        {pos: [14, 5, 26], state: "minecraft:deepslate{axis:y}"},
        {pos: [14, 5, 27], state: "minecraft:deepslate{axis:y}"},
        {pos: [14, 5, 28], state: "minecraft:deepslate{axis:y}"},
        {pos: [14, 5, 29], state: "minecraft:deepslate{axis:y}"},
        {pos: [14, 5, 30], state: "minecraft:deepslate{axis:y}"},
        {pos: [15, 5, 0], state: "minecraft:deepslate{axis:y}"},
        {pos: [15, 5, 1], state: "minecraft:deepslate{axis:y}"},
        {pos: [15, 5, 2], state: "minecraft:deepslate{axis:y}"},
        {pos: [15, 5, 3], state: "minecraft:deepslate{axis:y}"},
        {pos: [15, 5, 4], state: "minecraft:deepslate{axis:y}"},
        {pos: [15, 5, 5], state: "minecraft:deepslate{axis:y}"},
        {pos: [15, 5, 6], state: "minecraft:deepslate{axis:y}"},
        {pos: [15, 5, 7], state: "minecraft:deepslate{axis:y}"},
        {pos: [15, 5, 8], state: "minecraft:deepslate{axis:y}"},
        {pos: [15, 5, 9], state: "minecraft:deepslate{axis:y}"},
        {pos: [15, 5, 10], state: "minecraft:deepslate{axis:y}"},
        {pos: [15, 5, 11], state: "minecraft:deepslate{axis:y}"},
        {pos: [15, 5, 12], state: "minecraft:deepslate{axis:y}"},
        {pos: [15, 5, 13], state: "minecraft:deepslate{axis:y}"},
        {pos: [15, 5, 14], state: "minecraft:deepslate{axis:y}"},
        {pos: [15, 5, 15], state: "minecraft:deepslate{axis:y}"},
        {pos: [15, 5, 16], state: "minecraft:deepslate{axis:y}"},
        {pos: [15, 5, 17], state: "minecraft:deepslate{axis:y}"},
        {pos: [15, 5, 18], state: "minecraft:deepslate{axis:y}"},
        {pos: [15, 5, 19], state: "minecraft:deepslate{axis:y}"},
        {pos: [15, 5, 20], state: "minecraft:deepslate{axis:y}"},
        {pos: [15, 5, 21], state: "minecraft:deepslate{axis:y}"},
        {pos: [15, 5, 22], state: "minecraft:deepslate{axis:y}"},
        {pos: [15, 5, 23], state: "minecraft:deepslate{axis:y}"},
        {pos: [15, 5, 24], state: "minecraft:deepslate{axis:y}"},
        {pos: [15, 5, 25], state: "minecraft:deepslate{axis:y}"},
        {pos: [15, 5, 26], state: "minecraft:deepslate{axis:y}"},
        {pos: [15, 5, 27], state: "minecraft:deepslate{axis:y}"},
        {pos: [15, 5, 28], state: "minecraft:deepslate{axis:y}"},
        {pos: [15, 5, 29], state: "minecraft:deepslate{axis:y}"},
        {pos: [15, 5, 30], state: "minecraft:deepslate{axis:y}"},
        {pos: [16, 5, 7], state: "minecraft:deepslate_bricks"},
        {pos: [16, 5, 8], state: "minecraft:deepslate{axis:y}"},
        {pos: [16, 5, 9], state: "minecraft:deepslate{axis:y}"},
        {pos: [16, 5, 10], state: "minecraft:deepslate{axis:y}"},
        {pos: [16, 5, 11], state: "minecraft:deepslate{axis:y}"},
        {pos: [16, 5, 12], state: "minecraft:deepslate{axis:y}"},
        {pos: [16, 5, 13], state: "minecraft:deepslate{axis:y}"},
        {pos: [16, 5, 14], state: "minecraft:deepslate{axis:y}"},
        {pos: [16, 5, 15], state: "minecraft:deepslate_bricks"},
        {pos: [16, 5, 16], state: "minecraft:deepslate_bricks"},
        {pos: [16, 5, 17], state: "minecraft:deepslate_bricks"},
        {pos: [16, 5, 18], state: "minecraft:deepslate{axis:y}"},
        {pos: [16, 5, 19], state: "minecraft:deepslate{axis:y}"},
        {pos: [16, 5, 20], state: "minecraft:deepslate{axis:y}"},
        {pos: [16, 5, 21], state: "minecraft:deepslate{axis:y}"},
        {pos: [16, 5, 22], state: "minecraft:deepslate{axis:y}"},
        {pos: [16, 5, 23], state: "minecraft:deepslate{axis:y}"},
        {pos: [16, 5, 24], state: "minecraft:deepslate{axis:y}"},
        {pos: [16, 5, 25], state: "minecraft:deepslate{axis:y}"},
        {pos: [17, 5, 7], state: "minecraft:deepslate_bricks"},
        {pos: [17, 5, 8], state: "minecraft:deepslate{axis:y}"},
        {pos: [17, 5, 9], state: "minecraft:deepslate{axis:y}"},
        {pos: [17, 5, 10], state: "minecraft:deepslate{axis:y}"},
        {pos: [17, 5, 11], state: "minecraft:deepslate{axis:y}"},
        {pos: [17, 5, 12], state: "minecraft:deepslate{axis:y}"},
        {pos: [17, 5, 13], state: "minecraft:deepslate{axis:y}"},
        {pos: [17, 5, 14], state: "minecraft:deepslate_bricks"},
        {pos: [17, 5, 15], state: "minecraft:deepslate_bricks"},
        {pos: [17, 5, 16], state: "minecraft:deepslate_bricks"},
        {pos: [17, 5, 17], state: "minecraft:deepslate_bricks"},
        {pos: [17, 5, 18], state: "minecraft:deepslate_bricks"},
        {pos: [17, 5, 19], state: "minecraft:deepslate{axis:y}"},
        {pos: [17, 5, 20], state: "minecraft:deepslate{axis:y}"},
        {pos: [18, 5, 7], state: "minecraft:deepslate_bricks"},
        {pos: [18, 5, 8], state: "minecraft:deepslate{axis:y}"},
        {pos: [18, 5, 9], state: "minecraft:deepslate{axis:y}"},
        {pos: [18, 5, 10], state: "minecraft:deepslate{axis:y}"},
        {pos: [18, 5, 11], state: "minecraft:deepslate{axis:y}"},
        {pos: [18, 5, 12], state: "minecraft:deepslate{axis:y}"},
        {pos: [18, 5, 13], state: "minecraft:deepslate{axis:y}"},
        {pos: [18, 5, 14], state: "minecraft:deepslate{axis:y}"},
        {pos: [18, 5, 15], state: "minecraft:piston_head{facing:west,short:false,type:sticky}"},
        {pos: [18, 5, 16], state: "minecraft:piston_head{facing:west,short:false,type:sticky}"},
        {pos: [18, 5, 17], state: "minecraft:piston_head{facing:west,short:false,type:sticky}"},
        {pos: [18, 5, 18], state: "minecraft:deepslate{axis:y}"},
        {pos: [18, 5, 19], state: "minecraft:deepslate{axis:y}"},
        {pos: [18, 5, 20], state: "minecraft:deepslate{axis:y}"},
        {pos: [19, 5, 7], state: "minecraft:deepslate_bricks"},
        {pos: [19, 5, 8], state: "minecraft:deepslate{axis:y}"},
        {pos: [19, 5, 9], state: "minecraft:deepslate{axis:y}"},
        {pos: [19, 5, 10], state: "minecraft:deepslate{axis:y}"},
        {pos: [19, 5, 11], state: "minecraft:deepslate{axis:y}"},
        {pos: [19, 5, 12], state: "minecraft:deepslate{axis:y}"},
        {pos: [19, 5, 13], state: "minecraft:deepslate{axis:y}"},
        {pos: [19, 5, 14], state: "minecraft:deepslate{axis:y}"},
        {pos: [19, 5, 15], state: "minecraft:sticky_piston{extended:true,facing:west}"},
        {pos: [19, 5, 16], state: "minecraft:sticky_piston{extended:true,facing:west}"},
        {pos: [19, 5, 17], state: "minecraft:sticky_piston{extended:true,facing:west}"},
        {pos: [19, 5, 18], state: "minecraft:deepslate{axis:y}"},
        {pos: [19, 5, 19], state: "minecraft:deepslate{axis:y}"},
        {pos: [19, 5, 20], state: "minecraft:deepslate{axis:y}"},
        {pos: [20, 5, 7], state: "minecraft:deepslate_bricks"},
        {pos: [20, 5, 8], state: "minecraft:deepslate{axis:y}"},
        {pos: [20, 5, 9], state: "minecraft:deepslate{axis:y}"},
        {pos: [20, 5, 10], state: "minecraft:deepslate{axis:y}"},
        {pos: [20, 5, 11], state: "minecraft:deepslate{axis:y}"},
        {pos: [20, 5, 12], state: "minecraft:deepslate{axis:y}"},
        {pos: [20, 5, 13], state: "minecraft:deepslate{axis:y}"},
        {pos: [20, 5, 14], state: "minecraft:deepslate{axis:y}"},
        {pos: [20, 5, 15], state: "minecraft:deepslate{axis:y}"},
        {pos: [20, 5, 16], state: "minecraft:deepslate{axis:y}"},
        {pos: [20, 5, 17], state: "minecraft:deepslate{axis:y}"},
        {pos: [20, 5, 18], state: "minecraft:deepslate{axis:y}"},
        {pos: [20, 5, 19], state: "minecraft:deepslate{axis:y}"},
        {pos: [20, 5, 20], state: "minecraft:deepslate{axis:y}"},
        {pos: [21, 5, 6], state: "minecraft:deepslate_bricks"},
        {pos: [21, 5, 7], state: "minecraft:deepslate_bricks"},
        {pos: [21, 5, 8], state: "minecraft:deepslate_bricks"},
        {pos: [21, 5, 9], state: "minecraft:deepslate_bricks"},
        {pos: [21, 5, 10], state: "minecraft:deepslate_bricks"},
        {pos: [21, 5, 11], state: "minecraft:deepslate_bricks"},
        {pos: [21, 5, 12], state: "minecraft:deepslate_bricks"},
        {pos: [21, 5, 13], state: "minecraft:deepslate_bricks"},
        {pos: [21, 5, 14], state: "minecraft:deepslate_bricks"},
        {pos: [21, 5, 15], state: "minecraft:deepslate_bricks"},
        {pos: [21, 5, 16], state: "minecraft:deepslate_bricks"},
        {pos: [21, 5, 17], state: "minecraft:deepslate_bricks"},
        {pos: [21, 5, 18], state: "minecraft:deepslate_bricks"},
        {pos: [22, 5, 6], state: "minecraft:deepslate_bricks"},
        {pos: [22, 5, 7], state: "minecraft:deepslate_bricks"},
        {pos: [22, 5, 8], state: "minecraft:deepslate_bricks"},
        {pos: [22, 5, 9], state: "minecraft:deepslate_bricks"},
        {pos: [22, 5, 10], state: "minecraft:deepslate_bricks"},
        {pos: [22, 5, 11], state: "minecraft:deepslate_bricks"},
        {pos: [22, 5, 12], state: "minecraft:deepslate_bricks"},
        {pos: [22, 5, 13], state: "minecraft:deepslate_bricks"},
        {pos: [22, 5, 14], state: "minecraft:deepslate_bricks"},
        {pos: [22, 5, 15], state: "minecraft:deepslate_bricks"},
        {pos: [22, 5, 16], state: "minecraft:deepslate_bricks"},
        {pos: [22, 5, 17], state: "minecraft:deepslate_bricks"},
        {pos: [22, 5, 18], state: "minecraft:deepslate_bricks"},
        {pos: [23, 5, 6], state: "minecraft:deepslate_bricks"},
        {pos: [23, 5, 7], state: "minecraft:redstone_wire{east:up,north:none,power:0,south:side,west:none}"},
        {pos: [23, 5, 8], state: "minecraft:cave_air"},
        {pos: [23, 5, 9], state: "minecraft:deepslate_bricks"},
        {pos: [23, 5, 10], state: "minecraft:deepslate_bricks"},
        {pos: [23, 5, 11], state: "minecraft:deepslate_bricks"},
        {pos: [23, 5, 12], state: "minecraft:deepslate_bricks"},
        {pos: [23, 5, 13], state: "minecraft:deepslate_bricks"},
        {pos: [23, 5, 14], state: "minecraft:deepslate_bricks"},
        {pos: [23, 5, 15], state: "minecraft:deepslate_bricks"},
        {pos: [23, 5, 16], state: "minecraft:deepslate_bricks"},
        {pos: [23, 5, 17], state: "minecraft:deepslate_bricks"},
        {pos: [23, 5, 18], state: "minecraft:deepslate_bricks"},
        {pos: [24, 5, 6], state: "minecraft:deepslate_bricks"},
        {pos: [24, 5, 7], state: "minecraft:deepslate_bricks"},
        {pos: [24, 5, 8], state: "minecraft:deepslate_bricks"},
        {pos: [24, 5, 9], state: "minecraft:deepslate_bricks"},
        {pos: [24, 5, 10], state: "minecraft:deepslate_bricks"},
        {pos: [24, 5, 11], state: "minecraft:redstone_wire{east:none,north:none,power:8,south:side,west:up}"},
        {pos: [24, 5, 12], state: "minecraft:cave_air"},
        {pos: [24, 5, 13], state: "minecraft:deepslate_bricks"},
        {pos: [24, 5, 14], state: "minecraft:deepslate_bricks"},
        {pos: [24, 5, 15], state: "minecraft:deepslate_bricks"},
        {pos: [24, 5, 16], state: "minecraft:deepslate_bricks"},
        {pos: [24, 5, 17], state: "minecraft:deepslate_bricks"},
        {pos: [24, 5, 18], state: "minecraft:deepslate_bricks"},
        {pos: [25, 5, 6], state: "minecraft:deepslate_bricks"},
        {pos: [25, 5, 7], state: "minecraft:deepslate_bricks"},
        {pos: [25, 5, 8], state: "minecraft:deepslate_bricks"},
        {pos: [25, 5, 9], state: "minecraft:deepslate_bricks"},
        {pos: [25, 5, 10], state: "minecraft:deepslate_bricks"},
        {pos: [25, 5, 11], state: "minecraft:deepslate_bricks"},
        {pos: [25, 5, 12], state: "minecraft:deepslate_bricks"},
        {pos: [25, 5, 13], state: "minecraft:deepslate_bricks"},
        {pos: [25, 5, 14], state: "minecraft:deepslate_bricks"},
        {pos: [25, 5, 15], state: "minecraft:deepslate_bricks"},
        {pos: [25, 5, 16], state: "minecraft:deepslate_bricks"},
        {pos: [25, 5, 17], state: "minecraft:deepslate_bricks"},
        {pos: [25, 5, 18], state: "minecraft:deepslate_bricks"},
        {pos: [26, 5, 14], state: "minecraft:deepslate_bricks"},
        {pos: [26, 5, 15], state: "minecraft:deepslate_bricks"},
        {pos: [26, 5, 16], state: "minecraft:deepslate_bricks"},
        {pos: [26, 5, 17], state: "minecraft:deepslate_bricks"},
        {pos: [26, 5, 18], state: "minecraft:deepslate_bricks"},
        {pos: [27, 5, 14], state: "minecraft:deepslate_bricks"},
        {pos: [27, 5, 15], state: "minecraft:deepslate_bricks"},
        {pos: [27, 5, 16], state: "minecraft:deepslate_bricks"},
        {pos: [27, 5, 17], state: "minecraft:deepslate_bricks"},
        {pos: [27, 5, 18], state: "minecraft:deepslate_bricks"},
        {pos: [28, 5, 12], state: "minecraft:deepslate_bricks"},
        {pos: [28, 5, 13], state: "minecraft:deepslate_bricks"},
        {pos: [28, 5, 14], state: "minecraft:deepslate_bricks"},
        {pos: [28, 5, 15], state: "minecraft:deepslate_bricks"},
        {pos: [28, 5, 16], state: "minecraft:deepslate_bricks"},
        {pos: [28, 5, 17], state: "minecraft:deepslate_bricks"},
        {pos: [28, 5, 18], state: "minecraft:deepslate_bricks"},
        {pos: [28, 5, 19], state: "minecraft:deepslate_bricks"},
        {pos: [28, 5, 20], state: "minecraft:deepslate_bricks"},
        {pos: [29, 5, 12], state: "minecraft:deepslate_bricks"},
        {pos: [29, 5, 13], state: "minecraft:deepslate_bricks"},
        {pos: [29, 5, 14], state: "minecraft:deepslate_bricks"},
        {pos: [29, 5, 15], state: "minecraft:deepslate_bricks"},
        {pos: [29, 5, 16], state: "minecraft:deepslate_bricks"},
        {pos: [29, 5, 17], state: "minecraft:deepslate_bricks"},
        {pos: [29, 5, 18], state: "minecraft:deepslate_bricks"},
        {pos: [29, 5, 19], state: "minecraft:deepslate_bricks"},
        {pos: [29, 5, 20], state: "minecraft:deepslate_bricks"},
        {pos: [30, 5, 11], state: "minecraft:deepslate_bricks"},
        {pos: [30, 5, 12], state: "minecraft:deepslate_bricks"},
        {pos: [30, 5, 13], state: "minecraft:deepslate_bricks"},
        {pos: [30, 5, 14], state: "minecraft:deepslate_bricks"},
        {pos: [30, 5, 15], state: "minecraft:deepslate_bricks"},
        {pos: [30, 5, 16], state: "minecraft:deepslate_bricks"},
        {pos: [30, 5, 17], state: "minecraft:deepslate_bricks"},
        {pos: [30, 5, 18], state: "minecraft:deepslate_bricks"},
        {pos: [30, 5, 19], state: "minecraft:deepslate_bricks"},
        {pos: [30, 5, 20], state: "minecraft:deepslate_bricks"},
        {pos: [30, 5, 21], state: "minecraft:deepslate_bricks"},
        {pos: [31, 5, 11], state: "minecraft:deepslate_bricks"},
        {pos: [31, 5, 12], state: "minecraft:deepslate_bricks"},
        {pos: [31, 5, 13], state: "minecraft:deepslate_bricks"},
        {pos: [31, 5, 14], state: "minecraft:deepslate_bricks"},
        {pos: [31, 5, 15], state: "minecraft:deepslate_bricks"},
        {pos: [31, 5, 16], state: "minecraft:deepslate_bricks"},
        {pos: [31, 5, 17], state: "minecraft:deepslate_bricks"},
        {pos: [31, 5, 18], state: "minecraft:deepslate_bricks"},
        {pos: [31, 5, 19], state: "minecraft:deepslate_bricks"},
        {pos: [31, 5, 20], state: "minecraft:deepslate_bricks"},
        {pos: [31, 5, 21], state: "minecraft:deepslate_bricks"},
        {pos: [32, 5, 11], state: "minecraft:deepslate_bricks"},
        {pos: [32, 5, 12], state: "minecraft:deepslate_bricks"},
        {pos: [32, 5, 13], state: "minecraft:deepslate_bricks"},
        {pos: [32, 5, 14], state: "minecraft:deepslate_bricks"},
        {pos: [32, 5, 15], state: "minecraft:deepslate_bricks"},
        {pos: [32, 5, 16], state: "minecraft:deepslate_bricks"},
        {pos: [32, 5, 17], state: "minecraft:deepslate_bricks"},
        {pos: [32, 5, 18], state: "minecraft:deepslate_bricks"},
        {pos: [32, 5, 19], state: "minecraft:deepslate_bricks"},
        {pos: [32, 5, 20], state: "minecraft:deepslate_bricks"},
        {pos: [32, 5, 21], state: "minecraft:deepslate_bricks"},
        {pos: [33, 5, 11], state: "minecraft:deepslate_bricks"},
        {pos: [33, 5, 12], state: "minecraft:deepslate_bricks"},
        {pos: [33, 5, 13], state: "minecraft:deepslate_bricks"},
        {pos: [33, 5, 14], state: "minecraft:deepslate_bricks"},
        {pos: [33, 5, 15], state: "minecraft:deepslate_bricks"},
        {pos: [33, 5, 16], state: "minecraft:deepslate_bricks"},
        {pos: [33, 5, 17], state: "minecraft:deepslate_bricks"},
        {pos: [33, 5, 18], state: "minecraft:deepslate_bricks"},
        {pos: [33, 5, 19], state: "minecraft:deepslate_bricks"},
        {pos: [33, 5, 20], state: "minecraft:deepslate_bricks"},
        {pos: [33, 5, 21], state: "minecraft:deepslate_bricks"},
        {pos: [34, 5, 11], state: "minecraft:deepslate_bricks"},
        {pos: [34, 5, 12], state: "minecraft:deepslate_bricks"},
        {pos: [34, 5, 13], state: "minecraft:deepslate_bricks"},
        {pos: [34, 5, 14], state: "minecraft:deepslate_bricks"},
        {pos: [34, 5, 15], state: "minecraft:deepslate_bricks"},
        {pos: [34, 5, 16], state: "minecraft:deepslate_bricks"},
        {pos: [34, 5, 17], state: "minecraft:deepslate_bricks"},
        {pos: [34, 5, 18], state: "minecraft:deepslate_bricks"},
        {pos: [34, 5, 19], state: "minecraft:deepslate_bricks"},
        {pos: [34, 5, 20], state: "minecraft:deepslate_bricks"},
        {pos: [34, 5, 21], state: "minecraft:deepslate_bricks"},
        {pos: [35, 5, 11], state: "minecraft:deepslate_bricks"},
        {pos: [35, 5, 12], state: "minecraft:deepslate_bricks"},
        {pos: [35, 5, 13], state: "minecraft:deepslate_bricks"},
        {pos: [35, 5, 14], state: "minecraft:deepslate_bricks"},
        {pos: [35, 5, 15], state: "minecraft:deepslate_bricks"},
        {pos: [35, 5, 16], state: "minecraft:deepslate_bricks"},
        {pos: [35, 5, 17], state: "minecraft:deepslate_bricks"},
        {pos: [35, 5, 18], state: "minecraft:deepslate_bricks"},
        {pos: [35, 5, 19], state: "minecraft:deepslate_bricks"},
        {pos: [35, 5, 20], state: "minecraft:deepslate_bricks"},
        {pos: [35, 5, 21], state: "minecraft:deepslate_bricks"},
        {pos: [36, 5, 11], state: "minecraft:deepslate_bricks"},
        {pos: [36, 5, 12], state: "minecraft:deepslate_bricks"},
        {pos: [36, 5, 13], state: "minecraft:deepslate_bricks"},
        {pos: [36, 5, 14], state: "minecraft:deepslate_bricks"},
        {pos: [36, 5, 15], state: "minecraft:deepslate_bricks"},
        {pos: [36, 5, 16], state: "minecraft:deepslate_bricks"},
        {pos: [36, 5, 17], state: "minecraft:deepslate_bricks"},
        {pos: [36, 5, 18], state: "minecraft:deepslate_bricks"},
        {pos: [36, 5, 19], state: "minecraft:deepslate_bricks"},
        {pos: [36, 5, 20], state: "minecraft:deepslate_bricks"},
        {pos: [36, 5, 21], state: "minecraft:deepslate_bricks"},
        {pos: [37, 5, 11], state: "minecraft:deepslate_bricks"},
        {pos: [37, 5, 12], state: "minecraft:deepslate_bricks"},
        {pos: [37, 5, 13], state: "minecraft:deepslate_bricks"},
        {pos: [37, 5, 14], state: "minecraft:deepslate_bricks"},
        {pos: [37, 5, 15], state: "minecraft:deepslate_bricks"},
        {pos: [37, 5, 16], state: "minecraft:deepslate_bricks"},
        {pos: [37, 5, 17], state: "minecraft:deepslate_bricks"},
        {pos: [37, 5, 18], state: "minecraft:deepslate_bricks"},
        {pos: [37, 5, 19], state: "minecraft:deepslate_bricks"},
        {pos: [37, 5, 20], state: "minecraft:deepslate_bricks"},
        {pos: [37, 5, 21], state: "minecraft:deepslate_bricks"},
        {pos: [38, 5, 11], state: "minecraft:deepslate_bricks"},
        {pos: [38, 5, 12], state: "minecraft:deepslate_bricks"},
        {pos: [38, 5, 13], state: "minecraft:deepslate_bricks"},
        {pos: [38, 5, 14], state: "minecraft:deepslate_bricks"},
        {pos: [38, 5, 15], state: "minecraft:deepslate_bricks"},
        {pos: [38, 5, 16], state: "minecraft:deepslate_bricks"},
        {pos: [38, 5, 17], state: "minecraft:deepslate_bricks"},
        {pos: [38, 5, 18], state: "minecraft:deepslate_bricks"},
        {pos: [38, 5, 19], state: "minecraft:deepslate_bricks"},
        {pos: [38, 5, 20], state: "minecraft:deepslate_bricks"},
        {pos: [38, 5, 21], state: "minecraft:deepslate_bricks"},
        {pos: [39, 5, 12], state: "minecraft:deepslate_bricks"},
        {pos: [39, 5, 13], state: "minecraft:deepslate_bricks"},
        {pos: [39, 5, 14], state: "minecraft:deepslate_bricks"},
        {pos: [39, 5, 15], state: "minecraft:deepslate_bricks"},
        {pos: [39, 5, 16], state: "minecraft:deepslate_bricks"},
        {pos: [39, 5, 17], state: "minecraft:deepslate_bricks"},
        {pos: [39, 5, 18], state: "minecraft:deepslate_bricks"},
        {pos: [39, 5, 19], state: "minecraft:deepslate_bricks"},
        {pos: [39, 5, 20], state: "minecraft:deepslate_bricks"},
        {pos: [39, 5, 21], state: "minecraft:deepslate_bricks"},
        {pos: [40, 5, 14], state: "minecraft:deepslate_bricks"},
        {pos: [40, 5, 15], state: "minecraft:deepslate_bricks"},
        {pos: [40, 5, 16], state: "minecraft:deepslate_bricks"},
        {pos: [40, 5, 17], state: "minecraft:deepslate_bricks"},
        {pos: [40, 5, 18], state: "minecraft:deepslate_bricks"},
        {pos: [41, 5, 14], state: "minecraft:deepslate_bricks"},
        {pos: [41, 5, 15], state: "minecraft:deepslate_bricks"},
        {pos: [41, 5, 16], state: "minecraft:deepslate_bricks"},
        {pos: [41, 5, 17], state: "minecraft:deepslate_bricks"},
        {pos: [41, 5, 18], state: "minecraft:deepslate_bricks"},
        {pos: [0, 6, 5], state: "minecraft:deepslate_bricks"},
        {pos: [0, 6, 6], state: "minecraft:deepslate_bricks"},
        {pos: [0, 6, 7], state: "minecraft:deepslate_bricks"},
        {pos: [0, 6, 8], state: "minecraft:deepslate_bricks"},
        {pos: [0, 6, 9], state: "minecraft:deepslate_bricks"},
        {pos: [0, 6, 10], state: "minecraft:deepslate_bricks"},
        {pos: [0, 6, 11], state: "minecraft:deepslate_bricks"},
        {pos: [0, 6, 12], state: "minecraft:deepslate_bricks"},
        {pos: [0, 6, 13], state: "minecraft:deepslate_bricks"},
        {pos: [0, 6, 14], state: "minecraft:deepslate_bricks"},
        {pos: [0, 6, 15], state: "minecraft:gravel"},
        {pos: [0, 6, 16], state: "minecraft:gravel"},
        {pos: [0, 6, 17], state: "minecraft:gravel"},
        {pos: [0, 6, 18], state: "minecraft:deepslate_bricks"},
        {pos: [0, 6, 19], state: "minecraft:deepslate_bricks"},
        {pos: [0, 6, 20], state: "minecraft:deepslate_bricks"},
        {pos: [0, 6, 21], state: "minecraft:deepslate_bricks"},
        {pos: [0, 6, 22], state: "minecraft:deepslate_bricks"},
        {pos: [0, 6, 23], state: "minecraft:deepslate_bricks"},
        {pos: [0, 6, 24], state: "minecraft:deepslate_bricks"},
        {pos: [0, 6, 25], state: "minecraft:deepslate_bricks"},
        {pos: [1, 6, 5], state: "minecraft:deepslate_bricks"},
        {pos: [1, 6, 6], state: "minecraft:deepslate{axis:y}"},
        {pos: [1, 6, 7], state: "minecraft:gravel"},
        {pos: [1, 6, 8], state: "minecraft:gravel"},
        {pos: [1, 6, 9], state: "minecraft:gravel"},
        {pos: [1, 6, 10], state: "minecraft:gravel"},
        {pos: [1, 6, 11], state: "minecraft:gravel"},
        {pos: [1, 6, 12], state: "minecraft:gravel"},
        {pos: [1, 6, 13], state: "minecraft:gravel"},
        {pos: [1, 6, 14], state: "minecraft:gravel"},
        {pos: [1, 6, 15], state: "minecraft:gravel"},
        {pos: [1, 6, 16], state: "minecraft:gravel"},
        {pos: [1, 6, 17], state: "minecraft:gravel"},
        {pos: [1, 6, 18], state: "minecraft:gravel"},
        {pos: [1, 6, 19], state: "minecraft:gravel"},
        {pos: [1, 6, 20], state: "minecraft:gravel"},
        {pos: [1, 6, 21], state: "minecraft:gravel"},
        {pos: [1, 6, 22], state: "minecraft:gravel"},
        {pos: [1, 6, 23], state: "minecraft:gravel"},
        {pos: [1, 6, 24], state: "minecraft:gravel"},
        {pos: [1, 6, 25], state: "minecraft:deepslate_bricks"},
        {pos: [2, 6, 5], state: "minecraft:deepslate_bricks"},
        {pos: [2, 6, 6], state: "minecraft:deepslate{axis:y}"},
        {pos: [2, 6, 7], state: "minecraft:gravel"},
        {pos: [2, 6, 8], state: "minecraft:gravel"},
        {pos: [2, 6, 9], state: "minecraft:gravel"},
        {pos: [2, 6, 10], state: "minecraft:gravel"},
        {pos: [2, 6, 11], state: "minecraft:gravel"},
        {pos: [2, 6, 12], state: "minecraft:gravel"},
        {pos: [2, 6, 13], state: "minecraft:gravel"},
        {pos: [2, 6, 14], state: "minecraft:gravel"},
        {pos: [2, 6, 15], state: "minecraft:gravel"},
        {pos: [2, 6, 16], state: "minecraft:gravel"},
        {pos: [2, 6, 17], state: "minecraft:gravel"},
        {pos: [2, 6, 18], state: "minecraft:gravel"},
        {pos: [2, 6, 19], state: "minecraft:gravel"},
        {pos: [2, 6, 20], state: "minecraft:gravel"},
        {pos: [2, 6, 21], state: "minecraft:gravel"},
        {pos: [2, 6, 22], state: "minecraft:gravel"},
        {pos: [2, 6, 23], state: "minecraft:gravel"},
        {pos: [2, 6, 24], state: "minecraft:gravel"},
        {pos: [2, 6, 25], state: "minecraft:deepslate_bricks"},
        {pos: [3, 6, 2], state: "minecraft:deepslate_bricks"},
        {pos: [3, 6, 3], state: "minecraft:deepslate_bricks"},
        {pos: [3, 6, 4], state: "minecraft:deepslate_bricks"},
        {pos: [3, 6, 5], state: "minecraft:gravel"},
        {pos: [3, 6, 6], state: "minecraft:gravel"},
        {pos: [3, 6, 7], state: "minecraft:gravel"},
        {pos: [3, 6, 8], state: "minecraft:gravel"},
        {pos: [3, 6, 9], state: "minecraft:gravel"},
        {pos: [3, 6, 10], state: "minecraft:gravel"},
        {pos: [3, 6, 11], state: "minecraft:gravel"},
        {pos: [3, 6, 12], state: "minecraft:gravel"},
        {pos: [3, 6, 13], state: "minecraft:gravel"},
        {pos: [3, 6, 14], state: "minecraft:gravel"},
        {pos: [3, 6, 15], state: "minecraft:gravel"},
        {pos: [3, 6, 16], state: "minecraft:gravel"},
        {pos: [3, 6, 17], state: "minecraft:gravel"},
        {pos: [3, 6, 18], state: "minecraft:gravel"},
        {pos: [3, 6, 19], state: "minecraft:gravel"},
        {pos: [3, 6, 20], state: "minecraft:gravel"},
        {pos: [3, 6, 21], state: "minecraft:gravel"},
        {pos: [3, 6, 22], state: "minecraft:gravel"},
        {pos: [3, 6, 23], state: "minecraft:gravel"},
        {pos: [3, 6, 24], state: "minecraft:gravel"},
        {pos: [3, 6, 25], state: "minecraft:gravel"},
        {pos: [3, 6, 26], state: "minecraft:deepslate_bricks"},
        {pos: [3, 6, 27], state: "minecraft:deepslate_bricks"},
        {pos: [3, 6, 28], state: "minecraft:deepslate_bricks"},
        {pos: [4, 6, 2], state: "minecraft:deepslate_bricks"},
        {pos: [4, 6, 3], state: "minecraft:gravel"},
        {pos: [4, 6, 4], state: "minecraft:gravel"},
        {pos: [4, 6, 5], state: "minecraft:gravel"},
        {pos: [4, 6, 6], state: "minecraft:gravel"},
        {pos: [4, 6, 7], state: "minecraft:gravel"},
        {pos: [4, 6, 8], state: "minecraft:gravel"},
        {pos: [4, 6, 9], state: "minecraft:gravel"},
        {pos: [4, 6, 10], state: "minecraft:gravel"},
        {pos: [4, 6, 11], state: "minecraft:gravel"},
        {pos: [4, 6, 12], state: "minecraft:gravel"},
        {pos: [4, 6, 13], state: "minecraft:gravel"},
        {pos: [4, 6, 14], state: "minecraft:gravel"},
        {pos: [4, 6, 15], state: "minecraft:gravel"},
        {pos: [4, 6, 16], state: "minecraft:gravel"},
        {pos: [4, 6, 17], state: "minecraft:gravel"},
        {pos: [4, 6, 18], state: "minecraft:gravel"},
        {pos: [4, 6, 19], state: "minecraft:gravel"},
        {pos: [4, 6, 20], state: "minecraft:gravel"},
        {pos: [4, 6, 21], state: "minecraft:gravel"},
        {pos: [4, 6, 22], state: "minecraft:gravel"},
        {pos: [4, 6, 23], state: "minecraft:gravel"},
        {pos: [4, 6, 24], state: "minecraft:gravel"},
        {pos: [4, 6, 25], state: "minecraft:gravel"},
        {pos: [4, 6, 26], state: "minecraft:gravel"},
        {pos: [4, 6, 27], state: "minecraft:gravel"},
        {pos: [4, 6, 28], state: "minecraft:deepslate_bricks"},
        {pos: [5, 6, 2], state: "minecraft:deepslate_bricks"},
        {pos: [5, 6, 3], state: "minecraft:gravel"},
        {pos: [5, 6, 4], state: "minecraft:gravel"},
        {pos: [5, 6, 5], state: "minecraft:gravel"},
        {pos: [5, 6, 6], state: "minecraft:gravel"},
        {pos: [5, 6, 7], state: "minecraft:gravel"},
        {pos: [5, 6, 8], state: "minecraft:gravel"},
        {pos: [5, 6, 9], state: "minecraft:gravel"},
        {pos: [5, 6, 10], state: "minecraft:gravel"},
        {pos: [5, 6, 11], state: "minecraft:gravel"},
        {pos: [5, 6, 12], state: "minecraft:gravel"},
        {pos: [5, 6, 13], state: "minecraft:gravel"},
        {pos: [5, 6, 14], state: "minecraft:gravel"},
        {pos: [5, 6, 15], state: "minecraft:gravel"},
        {pos: [5, 6, 16], state: "minecraft:gravel"},
        {pos: [5, 6, 17], state: "minecraft:gravel"},
        {pos: [5, 6, 18], state: "minecraft:gravel"},
        {pos: [5, 6, 19], state: "minecraft:gravel"},
        {pos: [5, 6, 20], state: "minecraft:gravel"},
        {pos: [5, 6, 21], state: "minecraft:gravel"},
        {pos: [5, 6, 22], state: "minecraft:gravel"},
        {pos: [5, 6, 23], state: "minecraft:gravel"},
        {pos: [5, 6, 24], state: "minecraft:gravel"},
        {pos: [5, 6, 25], state: "minecraft:gravel"},
        {pos: [5, 6, 26], state: "minecraft:gravel"},
        {pos: [5, 6, 27], state: "minecraft:gravel"},
        {pos: [5, 6, 28], state: "minecraft:deepslate_bricks"},
        {pos: [6, 6, 2], state: "minecraft:deepslate_bricks"},
        {pos: [6, 6, 3], state: "minecraft:gravel"},
        {pos: [6, 6, 4], state: "minecraft:gravel"},
        {pos: [6, 6, 5], state: "minecraft:gravel"},
        {pos: [6, 6, 6], state: "minecraft:gravel"},
        {pos: [6, 6, 7], state: "minecraft:gravel"},
        {pos: [6, 6, 8], state: "minecraft:gravel"},
        {pos: [6, 6, 9], state: "minecraft:gravel"},
        {pos: [6, 6, 10], state: "minecraft:gravel"},
        {pos: [6, 6, 11], state: "minecraft:gravel"},
        {pos: [6, 6, 12], state: "minecraft:gravel"},
        {pos: [6, 6, 13], state: "minecraft:gravel"},
        {pos: [6, 6, 14], state: "minecraft:gravel"},
        {pos: [6, 6, 15], state: "minecraft:gravel"},
        {pos: [6, 6, 16], state: "minecraft:gravel"},
        {pos: [6, 6, 17], state: "minecraft:gravel"},
        {pos: [6, 6, 18], state: "minecraft:gravel"},
        {pos: [6, 6, 19], state: "minecraft:gravel"},
        {pos: [6, 6, 20], state: "minecraft:gravel"},
        {pos: [6, 6, 21], state: "minecraft:gravel"},
        {pos: [6, 6, 22], state: "minecraft:gravel"},
        {pos: [6, 6, 23], state: "minecraft:gravel"},
        {pos: [6, 6, 24], state: "minecraft:gravel"},
        {pos: [6, 6, 25], state: "minecraft:gravel"},
        {pos: [6, 6, 26], state: "minecraft:gravel"},
        {pos: [6, 6, 27], state: "minecraft:gravel"},
        {pos: [6, 6, 28], state: "minecraft:deepslate_bricks"},
        {pos: [7, 6, 0], state: "minecraft:deepslate_bricks"},
        {pos: [7, 6, 1], state: "minecraft:deepslate_bricks"},
        {pos: [7, 6, 2], state: "minecraft:gravel"},
        {pos: [7, 6, 3], state: "minecraft:gravel"},
        {pos: [7, 6, 4], state: "minecraft:gravel"},
        {pos: [7, 6, 5], state: "minecraft:gravel"},
        {pos: [7, 6, 6], state: "minecraft:gravel"},
        {pos: [7, 6, 7], state: "minecraft:gravel"},
        {pos: [7, 6, 8], state: "minecraft:gravel"},
        {pos: [7, 6, 9], state: "minecraft:gravel"},
        {pos: [7, 6, 10], state: "minecraft:gravel"},
        {pos: [7, 6, 11], state: "minecraft:gravel"},
        {pos: [7, 6, 12], state: "minecraft:gravel"},
        {pos: [7, 6, 13], state: "minecraft:gravel"},
        {pos: [7, 6, 14], state: "minecraft:deepslate_bricks"},
        {pos: [7, 6, 15], state: "minecraft:deepslate_bricks"},
        {pos: [7, 6, 16], state: "minecraft:deepslate_bricks"},
        {pos: [7, 6, 17], state: "minecraft:deepslate_bricks"},
        {pos: [7, 6, 18], state: "minecraft:deepslate_bricks"},
        {pos: [7, 6, 19], state: "minecraft:gravel"},
        {pos: [7, 6, 20], state: "minecraft:gravel"},
        {pos: [7, 6, 21], state: "minecraft:gravel"},
        {pos: [7, 6, 22], state: "minecraft:gravel"},
        {pos: [7, 6, 23], state: "minecraft:gravel"},
        {pos: [7, 6, 24], state: "minecraft:gravel"},
        {pos: [7, 6, 25], state: "minecraft:gravel"},
        {pos: [7, 6, 26], state: "minecraft:gravel"},
        {pos: [7, 6, 27], state: "minecraft:gravel"},
        {pos: [7, 6, 28], state: "minecraft:deepslate_bricks"},
        {pos: [8, 6, 0], state: "minecraft:deepslate_bricks"},
        {pos: [8, 6, 1], state: "minecraft:gravel"},
        {pos: [8, 6, 2], state: "minecraft:gravel"},
        {pos: [8, 6, 3], state: "minecraft:gravel"},
        {pos: [8, 6, 4], state: "minecraft:gravel"},
        {pos: [8, 6, 5], state: "minecraft:gravel"},
        {pos: [8, 6, 6], state: "minecraft:gravel"},
        {pos: [8, 6, 7], state: "minecraft:gravel"},
        {pos: [8, 6, 8], state: "minecraft:gravel"},
        {pos: [8, 6, 9], state: "minecraft:gravel"},
        {pos: [8, 6, 10], state: "minecraft:gravel"},
        {pos: [8, 6, 11], state: "minecraft:gravel"},
        {pos: [8, 6, 12], state: "minecraft:gravel"},
        {pos: [8, 6, 13], state: "minecraft:gravel"},
        {pos: [8, 6, 14], state: "minecraft:deepslate_bricks"},
        {pos: [8, 6, 15], state: "minecraft:gravel"},
        {pos: [8, 6, 16], state: "minecraft:gravel"},
        {pos: [8, 6, 17], state: "minecraft:gravel"},
        {pos: [8, 6, 18], state: "minecraft:deepslate_bricks"},
        {pos: [8, 6, 19], state: "minecraft:gravel"},
        {pos: [8, 6, 20], state: "minecraft:gravel"},
        {pos: [8, 6, 21], state: "minecraft:gravel"},
        {pos: [8, 6, 22], state: "minecraft:gravel"},
        {pos: [8, 6, 23], state: "minecraft:gravel"},
        {pos: [8, 6, 24], state: "minecraft:gravel"},
        {pos: [8, 6, 25], state: "minecraft:gravel"},
        {pos: [8, 6, 26], state: "minecraft:gravel"},
        {pos: [8, 6, 27], state: "minecraft:gravel"},
        {pos: [8, 6, 28], state: "minecraft:deepslate_bricks"},
        {pos: [9, 6, 0], state: "minecraft:deepslate_bricks"},
        {pos: [9, 6, 1], state: "minecraft:gravel"},
        {pos: [9, 6, 2], state: "minecraft:gravel"},
        {pos: [9, 6, 3], state: "minecraft:gravel"},
        {pos: [9, 6, 4], state: "minecraft:gravel"},
        {pos: [9, 6, 5], state: "minecraft:gravel"},
        {pos: [9, 6, 6], state: "minecraft:gravel"},
        {pos: [9, 6, 7], state: "minecraft:gravel"},
        {pos: [9, 6, 8], state: "minecraft:gravel"},
        {pos: [9, 6, 9], state: "minecraft:gravel"},
        {pos: [9, 6, 10], state: "minecraft:gravel"},
        {pos: [9, 6, 11], state: "minecraft:gravel"},
        {pos: [9, 6, 12], state: "minecraft:gravel"},
        {pos: [9, 6, 13], state: "minecraft:gravel"},
        {pos: [9, 6, 14], state: "minecraft:deepslate_bricks"},
        {pos: [9, 6, 15], state: "minecraft:gravel"},
        {pos: [9, 6, 16], state: "minecraft:chiseled_deepslate"},
        {pos: [9, 6, 17], state: "minecraft:gravel"},
        {pos: [9, 6, 18], state: "minecraft:deepslate_bricks"},
        {pos: [9, 6, 19], state: "minecraft:gravel"},
        {pos: [9, 6, 20], state: "minecraft:gravel"},
        {pos: [9, 6, 21], state: "minecraft:gravel"},
        {pos: [9, 6, 22], state: "minecraft:gravel"},
        {pos: [9, 6, 23], state: "minecraft:gravel"},
        {pos: [9, 6, 24], state: "minecraft:gravel"},
        {pos: [9, 6, 25], state: "minecraft:gravel"},
        {pos: [9, 6, 26], state: "minecraft:gravel"},
        {pos: [9, 6, 27], state: "minecraft:gravel"},
        {pos: [9, 6, 28], state: "minecraft:deepslate_bricks"},
        {pos: [10, 6, 0], state: "minecraft:deepslate_bricks"},
        {pos: [10, 6, 1], state: "minecraft:gravel"},
        {pos: [10, 6, 2], state: "minecraft:gravel"},
        {pos: [10, 6, 3], state: "minecraft:gravel"},
        {pos: [10, 6, 4], state: "minecraft:gravel"},
        {pos: [10, 6, 5], state: "minecraft:gravel"},
        {pos: [10, 6, 6], state: "minecraft:gravel"},
        {pos: [10, 6, 7], state: "minecraft:gravel"},
        {pos: [10, 6, 8], state: "minecraft:gravel"},
        {pos: [10, 6, 9], state: "minecraft:gravel"},
        {pos: [10, 6, 10], state: "minecraft:gravel"},
        {pos: [10, 6, 11], state: "minecraft:gravel"},
        {pos: [10, 6, 12], state: "minecraft:gravel"},
        {pos: [10, 6, 13], state: "minecraft:gravel"},
        {pos: [10, 6, 14], state: "minecraft:deepslate_bricks"},
        {pos: [10, 6, 15], state: "minecraft:gravel"},
        {pos: [10, 6, 16], state: "minecraft:gravel"},
        {pos: [10, 6, 17], state: "minecraft:gravel"},
        {pos: [10, 6, 18], state: "minecraft:deepslate_bricks"},
        {pos: [10, 6, 19], state: "minecraft:gravel"},
        {pos: [10, 6, 20], state: "minecraft:gravel"},
        {pos: [10, 6, 21], state: "minecraft:gravel"},
        {pos: [10, 6, 22], state: "minecraft:gravel"},
        {pos: [10, 6, 23], state: "minecraft:gravel"},
        {pos: [10, 6, 24], state: "minecraft:gravel"},
        {pos: [10, 6, 25], state: "minecraft:gravel"},
        {pos: [10, 6, 26], state: "minecraft:gravel"},
        {pos: [10, 6, 27], state: "minecraft:gravel"},
        {pos: [10, 6, 28], state: "minecraft:deepslate_bricks"},
        {pos: [11, 6, 0], state: "minecraft:deepslate_bricks"},
        {pos: [11, 6, 1], state: "minecraft:gravel"},
        {pos: [11, 6, 2], state: "minecraft:gravel"},
        {pos: [11, 6, 3], state: "minecraft:gravel"},
        {pos: [11, 6, 4], state: "minecraft:gravel"},
        {pos: [11, 6, 5], state: "minecraft:gravel"},
        {pos: [11, 6, 6], state: "minecraft:gravel"},
        {pos: [11, 6, 7], state: "minecraft:gravel"},
        {pos: [11, 6, 8], state: "minecraft:gravel"},
        {pos: [11, 6, 9], state: "minecraft:gravel"},
        {pos: [11, 6, 10], state: "minecraft:gravel"},
        {pos: [11, 6, 11], state: "minecraft:gravel"},
        {pos: [11, 6, 12], state: "minecraft:gravel"},
        {pos: [11, 6, 13], state: "minecraft:gravel"},
        {pos: [11, 6, 14], state: "minecraft:deepslate_bricks"},
        {pos: [11, 6, 15], state: "minecraft:deepslate_bricks"},
        {pos: [11, 6, 16], state: "minecraft:deepslate_bricks"},
        {pos: [11, 6, 17], state: "minecraft:deepslate_bricks"},
        {pos: [11, 6, 18], state: "minecraft:deepslate_bricks"},
        {pos: [11, 6, 19], state: "minecraft:gravel"},
        {pos: [11, 6, 20], state: "minecraft:gravel"},
        {pos: [11, 6, 21], state: "minecraft:gravel"},
        {pos: [11, 6, 22], state: "minecraft:gravel"},
        {pos: [11, 6, 23], state: "minecraft:gravel"},
        {pos: [11, 6, 24], state: "minecraft:gravel"},
        {pos: [11, 6, 25], state: "minecraft:gravel"},
        {pos: [11, 6, 26], state: "minecraft:gravel"},
        {pos: [11, 6, 27], state: "minecraft:gravel"},
        {pos: [11, 6, 28], state: "minecraft:gravel"},
        {pos: [11, 6, 29], state: "minecraft:deepslate_bricks"},
        {pos: [11, 6, 30], state: "minecraft:deepslate_bricks"},
        {pos: [12, 6, 0], state: "minecraft:deepslate_bricks"},
        {pos: [12, 6, 1], state: "minecraft:gravel"},
        {pos: [12, 6, 2], state: "minecraft:gravel"},
        {pos: [12, 6, 3], state: "minecraft:gravel"},
        {pos: [12, 6, 4], state: "minecraft:gravel"},
        {pos: [12, 6, 5], state: "minecraft:gravel"},
        {pos: [12, 6, 6], state: "minecraft:gravel"},
        {pos: [12, 6, 7], state: "minecraft:gravel"},
        {pos: [12, 6, 8], state: "minecraft:gravel"},
        {pos: [12, 6, 9], state: "minecraft:gravel"},
        {pos: [12, 6, 10], state: "minecraft:gravel"},
        {pos: [12, 6, 11], state: "minecraft:gravel"},
        {pos: [12, 6, 12], state: "minecraft:gravel"},
        {pos: [12, 6, 13], state: "minecraft:gravel"},
        {pos: [12, 6, 14], state: "minecraft:gravel"},
        {pos: [12, 6, 15], state: "minecraft:gravel"},
        {pos: [12, 6, 16], state: "minecraft:gravel"},
        {pos: [12, 6, 17], state: "minecraft:gravel"},
        {pos: [12, 6, 18], state: "minecraft:gravel"},
        {pos: [12, 6, 19], state: "minecraft:gravel"},
        {pos: [12, 6, 20], state: "minecraft:gravel"},
        {pos: [12, 6, 21], state: "minecraft:gravel"},
        {pos: [12, 6, 22], state: "minecraft:gravel"},
        {pos: [12, 6, 23], state: "minecraft:gravel"},
        {pos: [12, 6, 24], state: "minecraft:gravel"},
        {pos: [12, 6, 25], state: "minecraft:gravel"},
        {pos: [12, 6, 26], state: "minecraft:gravel"},
        {pos: [12, 6, 27], state: "minecraft:gravel"},
        {pos: [12, 6, 28], state: "minecraft:gravel"},
        {pos: [12, 6, 29], state: "minecraft:gravel"},
        {pos: [12, 6, 30], state: "minecraft:deepslate_bricks"},
        {pos: [13, 6, 0], state: "minecraft:deepslate_bricks"},
        {pos: [13, 6, 1], state: "minecraft:gravel"},
        {pos: [13, 6, 2], state: "minecraft:gravel"},
        {pos: [13, 6, 3], state: "minecraft:gravel"},
        {pos: [13, 6, 4], state: "minecraft:gravel"},
        {pos: [13, 6, 5], state: "minecraft:gravel"},
        {pos: [13, 6, 6], state: "minecraft:gravel"},
        {pos: [13, 6, 7], state: "minecraft:gravel"},
        {pos: [13, 6, 8], state: "minecraft:gravel"},
        {pos: [13, 6, 9], state: "minecraft:gravel"},
        {pos: [13, 6, 10], state: "minecraft:gravel"},
        {pos: [13, 6, 11], state: "minecraft:gravel"},
        {pos: [13, 6, 12], state: "minecraft:gravel"},
        {pos: [13, 6, 13], state: "minecraft:gravel"},
        {pos: [13, 6, 14], state: "minecraft:gravel"},
        {pos: [13, 6, 15], state: "minecraft:gravel"},
        {pos: [13, 6, 16], state: "minecraft:gravel"},
        {pos: [13, 6, 17], state: "minecraft:gravel"},
        {pos: [13, 6, 18], state: "minecraft:gravel"},
        {pos: [13, 6, 19], state: "minecraft:gravel"},
        {pos: [13, 6, 20], state: "minecraft:gravel"},
        {pos: [13, 6, 21], state: "minecraft:gravel"},
        {pos: [13, 6, 22], state: "minecraft:gravel"},
        {pos: [13, 6, 23], state: "minecraft:gravel"},
        {pos: [13, 6, 24], state: "minecraft:gravel"},
        {pos: [13, 6, 25], state: "minecraft:gravel"},
        {pos: [13, 6, 26], state: "minecraft:gravel"},
        {pos: [13, 6, 27], state: "minecraft:gravel"},
        {pos: [13, 6, 28], state: "minecraft:gravel"},
        {pos: [13, 6, 29], state: "minecraft:gravel"},
        {pos: [13, 6, 30], state: "minecraft:deepslate_bricks"},
        {pos: [14, 6, 0], state: "minecraft:deepslate_bricks"},
        {pos: [14, 6, 1], state: "minecraft:gravel"},
        {pos: [14, 6, 2], state: "minecraft:gravel"},
        {pos: [14, 6, 3], state: "minecraft:gravel"},
        {pos: [14, 6, 4], state: "minecraft:gravel"},
        {pos: [14, 6, 5], state: "minecraft:gravel"},
        {pos: [14, 6, 6], state: "minecraft:gravel"},
        {pos: [14, 6, 7], state: "minecraft:gravel"},
        {pos: [14, 6, 8], state: "minecraft:gravel"},
        {pos: [14, 6, 9], state: "minecraft:gravel"},
        {pos: [14, 6, 10], state: "minecraft:gravel"},
        {pos: [14, 6, 11], state: "minecraft:gravel"},
        {pos: [14, 6, 12], state: "minecraft:gravel"},
        {pos: [14, 6, 13], state: "minecraft:gravel"},
        {pos: [14, 6, 14], state: "minecraft:gravel"},
        {pos: [14, 6, 15], state: "minecraft:gravel"},
        {pos: [14, 6, 16], state: "minecraft:gravel"},
        {pos: [14, 6, 17], state: "minecraft:gravel"},
        {pos: [14, 6, 18], state: "minecraft:gravel"},
        {pos: [14, 6, 19], state: "minecraft:gravel"},
        {pos: [14, 6, 20], state: "minecraft:gravel"},
        {pos: [14, 6, 21], state: "minecraft:gravel"},
        {pos: [14, 6, 22], state: "minecraft:gravel"},
        {pos: [14, 6, 23], state: "minecraft:gravel"},
        {pos: [14, 6, 24], state: "minecraft:gravel"},
        {pos: [14, 6, 25], state: "minecraft:gravel"},
        {pos: [14, 6, 26], state: "minecraft:gravel"},
        {pos: [14, 6, 27], state: "minecraft:gravel"},
        {pos: [14, 6, 28], state: "minecraft:gravel"},
        {pos: [14, 6, 29], state: "minecraft:gravel"},
        {pos: [14, 6, 30], state: "minecraft:deepslate_bricks"},
        {pos: [15, 6, 0], state: "minecraft:deepslate_bricks"},
        {pos: [15, 6, 1], state: "minecraft:deepslate_bricks"},
        {pos: [15, 6, 2], state: "minecraft:deepslate_bricks"},
        {pos: [15, 6, 3], state: "minecraft:deepslate_bricks"},
        {pos: [15, 6, 4], state: "minecraft:deepslate_bricks"},
        {pos: [15, 6, 5], state: "minecraft:deepslate_bricks"},
        {pos: [15, 6, 6], state: "minecraft:deepslate_bricks"},
        {pos: [15, 6, 7], state: "minecraft:gravel"},
        {pos: [15, 6, 8], state: "minecraft:gravel"},
        {pos: [15, 6, 9], state: "minecraft:gravel"},
        {pos: [15, 6, 10], state: "minecraft:gravel"},
        {pos: [15, 6, 11], state: "minecraft:gravel"},
        {pos: [15, 6, 12], state: "minecraft:gravel"},
        {pos: [15, 6, 13], state: "minecraft:gravel"},
        {pos: [15, 6, 14], state: "minecraft:gravel"},
        {pos: [15, 6, 15], state: "minecraft:gravel"},
        {pos: [15, 6, 16], state: "minecraft:gravel"},
        {pos: [15, 6, 17], state: "minecraft:gravel"},
        {pos: [15, 6, 18], state: "minecraft:gravel"},
        {pos: [15, 6, 19], state: "minecraft:gravel"},
        {pos: [15, 6, 20], state: "minecraft:gravel"},
        {pos: [15, 6, 21], state: "minecraft:gravel"},
        {pos: [15, 6, 22], state: "minecraft:gravel"},
        {pos: [15, 6, 23], state: "minecraft:gravel"},
        {pos: [15, 6, 24], state: "minecraft:gravel"},
        {pos: [15, 6, 25], state: "minecraft:gravel"},
        {pos: [15, 6, 26], state: "minecraft:deepslate_bricks"},
        {pos: [15, 6, 27], state: "minecraft:deepslate_bricks"},
        {pos: [15, 6, 28], state: "minecraft:deepslate_bricks"},
        {pos: [15, 6, 29], state: "minecraft:deepslate_bricks"},
        {pos: [15, 6, 30], state: "minecraft:deepslate_bricks"},
        {pos: [16, 6, 7], state: "minecraft:deepslate_bricks"},
        {pos: [16, 6, 8], state: "minecraft:gravel"},
        {pos: [16, 6, 9], state: "minecraft:gravel"},
        {pos: [16, 6, 10], state: "minecraft:gravel"},
        {pos: [16, 6, 11], state: "minecraft:gravel"},
        {pos: [16, 6, 12], state: "minecraft:gravel"},
        {pos: [16, 6, 13], state: "minecraft:gravel"},
        {pos: [16, 6, 14], state: "minecraft:gravel"},
        {pos: [16, 6, 15], state: "minecraft:gravel"},
        {pos: [16, 6, 16], state: "minecraft:gravel"},
        {pos: [16, 6, 17], state: "minecraft:gravel"},
        {pos: [16, 6, 18], state: "minecraft:gravel"},
        {pos: [16, 6, 19], state: "minecraft:gravel"},
        {pos: [16, 6, 20], state: "minecraft:gravel"},
        {pos: [16, 6, 21], state: "minecraft:deepslate_bricks"},
        {pos: [16, 6, 22], state: "minecraft:deepslate_bricks"},
        {pos: [16, 6, 23], state: "minecraft:deepslate_bricks"},
        {pos: [16, 6, 24], state: "minecraft:deepslate_bricks"},
        {pos: [16, 6, 25], state: "minecraft:deepslate_bricks"},
        {pos: [17, 6, 7], state: "minecraft:deepslate_bricks"},
        {pos: [17, 6, 8], state: "minecraft:gravel"},
        {pos: [17, 6, 9], state: "minecraft:gravel"},
        {pos: [17, 6, 10], state: "minecraft:gravel"},
        {pos: [17, 6, 11], state: "minecraft:gravel"},
        {pos: [17, 6, 12], state: "minecraft:gravel"},
        {pos: [17, 6, 13], state: "minecraft:gravel"},
        {pos: [17, 6, 14], state: "minecraft:gravel"},
        {pos: [17, 6, 15], state: "minecraft:sand"},
        {pos: [17, 6, 16], state: "minecraft:sand"},
        {pos: [17, 6, 17], state: "minecraft:sand"},
        {pos: [17, 6, 18], state: "minecraft:gravel"},
        {pos: [17, 6, 19], state: "minecraft:gravel"},
        {pos: [17, 6, 20], state: "minecraft:deepslate_bricks"},
        {pos: [18, 6, 7], state: "minecraft:deepslate_bricks"},
        {pos: [18, 6, 8], state: "minecraft:gravel"},
        {pos: [18, 6, 9], state: "minecraft:gravel"},
        {pos: [18, 6, 10], state: "minecraft:gravel"},
        {pos: [18, 6, 11], state: "minecraft:gravel"},
        {pos: [18, 6, 12], state: "minecraft:gravel"},
        {pos: [18, 6, 13], state: "minecraft:gravel"},
        {pos: [18, 6, 14], state: "minecraft:gravel"},
        {pos: [18, 6, 15], state: "minecraft:gravel"},
        {pos: [18, 6, 16], state: "minecraft:gravel"},
        {pos: [18, 6, 17], state: "minecraft:gravel"},
        {pos: [18, 6, 18], state: "minecraft:gravel"},
        {pos: [18, 6, 19], state: "minecraft:gravel"},
        {pos: [18, 6, 20], state: "minecraft:deepslate_bricks"},
        {pos: [19, 6, 7], state: "minecraft:deepslate_bricks"},
        {pos: [19, 6, 8], state: "minecraft:gravel"},
        {pos: [19, 6, 9], state: "minecraft:gravel"},
        {pos: [19, 6, 10], state: "minecraft:gravel"},
        {pos: [19, 6, 11], state: "minecraft:gravel"},
        {pos: [19, 6, 12], state: "minecraft:gravel"},
        {pos: [19, 6, 13], state: "minecraft:gravel"},
        {pos: [19, 6, 14], state: "minecraft:gravel"},
        {pos: [19, 6, 15], state: "minecraft:gravel"},
        {pos: [19, 6, 16], state: "minecraft:gravel"},
        {pos: [19, 6, 17], state: "minecraft:gravel"},
        {pos: [19, 6, 18], state: "minecraft:gravel"},
        {pos: [19, 6, 19], state: "minecraft:gravel"},
        {pos: [19, 6, 20], state: "minecraft:deepslate_bricks"},
        {pos: [20, 6, 7], state: "minecraft:deepslate_bricks"},
        {pos: [20, 6, 8], state: "minecraft:gravel"},
        {pos: [20, 6, 9], state: "minecraft:gravel"},
        {pos: [20, 6, 10], state: "minecraft:gravel"},
        {pos: [20, 6, 11], state: "minecraft:gravel"},
        {pos: [20, 6, 12], state: "minecraft:gravel"},
        {pos: [20, 6, 13], state: "minecraft:gravel"},
        {pos: [20, 6, 14], state: "minecraft:gravel"},
        {pos: [20, 6, 15], state: "minecraft:gravel"},
        {pos: [20, 6, 16], state: "minecraft:gravel"},
        {pos: [20, 6, 17], state: "minecraft:gravel"},
        {pos: [20, 6, 18], state: "minecraft:gravel"},
        {pos: [20, 6, 19], state: "minecraft:deepslate_bricks"},
        {pos: [20, 6, 20], state: "minecraft:deepslate_bricks"},
        {pos: [21, 6, 6], state: "minecraft:deepslate_bricks"},
        {pos: [21, 6, 7], state: "minecraft:deepslate_bricks"},
        {pos: [21, 6, 8], state: "minecraft:deepslate_bricks"},
        {pos: [21, 6, 9], state: "minecraft:deepslate_bricks"},
        {pos: [21, 6, 10], state: "minecraft:deepslate_bricks"},
        {pos: [21, 6, 11], state: "minecraft:deepslate_bricks"},
        {pos: [21, 6, 12], state: "minecraft:deepslate_bricks"},
        {pos: [21, 6, 13], state: "minecraft:deepslate_bricks"},
        {pos: [21, 6, 14], state: "minecraft:deepslate_bricks"},
        {pos: [21, 6, 15], state: "minecraft:gravel"},
        {pos: [21, 6, 16], state: "minecraft:gravel"},
        {pos: [21, 6, 17], state: "minecraft:gravel"},
        {pos: [21, 6, 18], state: "minecraft:deepslate_bricks"},
        {pos: [21, 6, 19], state: "minecraft:deepslate_bricks"},
        {pos: [21, 6, 20], state: "minecraft:deepslate_bricks"},
        {pos: [22, 6, 6], state: "minecraft:deepslate_bricks"},
        {pos: [22, 6, 7], state: "minecraft:deepslate_bricks"},
        {pos: [22, 6, 8], state: "minecraft:deepslate_bricks"},
        {pos: [22, 6, 9], state: "minecraft:deepslate_bricks"},
        {pos: [22, 6, 10], state: "minecraft:deepslate_bricks"},
        {pos: [22, 6, 11], state: "minecraft:deepslate_bricks"},
