{
    DataVersion: 3953,
    size: [7, 6, 7],
    data: [
        {pos: [0, 0, 0], state: "minecraft:deepslate{axis:y}"},
        {pos: [0, 0, 1], state: "minecraft:deepslate{axis:y}"},
        {pos: [0, 0, 2], state: "minecraft:deepslate{axis:y}"},
        {pos: [0, 0, 3], state: "minecraft:deepslate{axis:y}"},
        {pos: [0, 0, 4], state: "minecraft:deepslate{axis:y}"},
        {pos: [0, 0, 5], state: "minecraft:deepslate{axis:y}"},
        {pos: [0, 0, 6], state: "minecraft:deepslate{axis:y}"},
        {pos: [1, 0, 0], state: "minecraft:deepslate{axis:y}"},
        {pos: [1, 0, 1], state: "minecraft:deepslate{axis:y}"},
        {pos: [1, 0, 2], state: "minecraft:deepslate{axis:y}"},
        {pos: [1, 0, 3], state: "minecraft:deepslate{axis:y}"},
        {pos: [1, 0, 4], state: "minecraft:deepslate{axis:y}"},
        {pos: [1, 0, 5], state: "minecraft:deepslate{axis:y}"},
        {pos: [1, 0, 6], state: "minecraft:deepslate{axis:y}"},
        {pos: [2, 0, 0], state: "minecraft:deepslate{axis:y}"},
        {pos: [2, 0, 1], state: "minecraft:deepslate{axis:y}"},
        {pos: [2, 0, 2], state: "minecraft:deepslate{axis:y}"},
        {pos: [2, 0, 3], state: "minecraft:deepslate{axis:y}"},
        {pos: [2, 0, 4], state: "minecraft:deepslate{axis:y}"},
        {pos: [2, 0, 5], state: "minecraft:deepslate{axis:y}"},
        {pos: [2, 0, 6], state: "minecraft:deepslate{axis:y}"},
        {pos: [3, 0, 0], state: "minecraft:deepslate{axis:y}"},
        {pos: [3, 0, 1], state: "minecraft:deepslate{axis:y}"},
        {pos: [3, 0, 2], state: "minecraft:deepslate{axis:y}"},
        {pos: [3, 0, 3], state: "minecraft:deepslate{axis:y}"},
        {pos: [3, 0, 4], state: "minecraft:deepslate{axis:y}"},
        {pos: [3, 0, 5], state: "minecraft:deepslate{axis:y}"},
        {pos: [3, 0, 6], state: "minecraft:deepslate{axis:y}"},
        {pos: [4, 0, 0], state: "minecraft:deepslate{axis:y}"},
        {pos: [4, 0, 1], state: "minecraft:deepslate{axis:y}"},
        {pos: [4, 0, 2], state: "minecraft:deepslate{axis:y}"},
        {pos: [4, 0, 3], state: "minecraft:deepslate{axis:y}"},
        {pos: [4, 0, 4], state: "minecraft:deepslate{axis:y}"},
        {pos: [4, 0, 5], state: "minecraft:deepslate{axis:y}"},
        {pos: [4, 0, 6], state: "minecraft:deepslate{axis:y}"},
        {pos: [5, 0, 0], state: "minecraft:deepslate{axis:y}"},
        {pos: [5, 0, 1], state: "minecraft:deepslate{axis:y}"},
        {pos: [5, 0, 2], state: "minecraft:deepslate{axis:y}"},
        {pos: [5, 0, 3], state: "minecraft:deepslate{axis:y}"},
        {pos: [5, 0, 4], state: "minecraft:deepslate{axis:y}"},
        {pos: [5, 0, 5], state: "minecraft:deepslate{axis:y}"},
        {pos: [5, 0, 6], state: "minecraft:deepslate{axis:y}"},
        {pos: [6, 0, 0], state: "minecraft:deepslate{axis:y}"},
        {pos: [6, 0, 1], state: "minecraft:deepslate{axis:y}"},
        {pos: [6, 0, 2], state: "minecraft:deepslate{axis:y}"},
        {pos: [6, 0, 3], state: "minecraft:deepslate{axis:y}"},
        {pos: [6, 0, 4], state: "minecraft:deepslate{axis:y}"},
        {pos: [6, 0, 5], state: "minecraft:deepslate{axis:y}"},
        {pos: [6, 0, 6], state: "minecraft:deepslate{axis:y}"},
        {pos: [0, 1, 0], state: "minecraft:deepslate_bricks"},
        {pos: [0, 1, 1], state: "minecraft:deepslate_bricks"},
        {pos: [0, 1, 2], state: "minecraft:deepslate_bricks"},
        {pos: [0, 1, 3], state: "minecraft:deepslate_bricks"},
        {pos: [0, 1, 4], state: "minecraft:deepslate_bricks"},
        {pos: [0, 1, 5], state: "minecraft:deepslate_bricks"},
        {pos: [0, 1, 6], state: "minecraft:deepslate_bricks"},
        {pos: [1, 1, 0], state: "minecraft:deepslate_bricks"},
        {pos: [1, 1, 1], state: "minecraft:gravel"},
        {pos: [1, 1, 2], state: "minecraft:gravel"},
        {pos: [1, 1, 3], state: "minecraft:gravel"},
        {pos: [1, 1, 4], state: "minecraft:gravel"},
        {pos: [1, 1, 5], state: "minecraft:gravel"},
        {pos: [1, 1, 6], state: "minecraft:deepslate_bricks"},
        {pos: [2, 1, 0], state: "minecraft:deepslate_bricks"},
        {pos: [2, 1, 1], state: "minecraft:gravel"},
        {pos: [2, 1, 2], state: "minecraft:gravel"},
        {pos: [2, 1, 3], state: "minecraft:gravel"},
        {pos: [2, 1, 4], state: "minecraft:gravel"},
        {pos: [2, 1, 5], state: "minecraft:gravel"},
        {pos: [2, 1, 6], state: "minecraft:deepslate_bricks"},
        {pos: [3, 1, 0], state: "minecraft:deepslate_bricks"},
        {pos: [3, 1, 1], state: "minecraft:gravel"},
        {pos: [3, 1, 2], state: "minecraft:gravel"},
        {pos: [3, 1, 3], state: "minecraft:gravel"},
        {pos: [3, 1, 4], state: "minecraft:gravel"},
        {pos: [3, 1, 5], state: "minecraft:gravel"},
        {pos: [3, 1, 6], state: "minecraft:gravel"},
        {pos: [4, 1, 0], state: "minecraft:deepslate_bricks"},
        {pos: [4, 1, 1], state: "minecraft:gravel"},
        {pos: [4, 1, 2], state: "minecraft:gravel"},
        {pos: [4, 1, 3], state: "minecraft:gravel"},
        {pos: [4, 1, 4], state: "minecraft:gravel"},
        {pos: [4, 1, 5], state: "minecraft:gravel"},
        {pos: [4, 1, 6], state: "minecraft:deepslate_bricks"},
        {pos: [5, 1, 0], state: "minecraft:deepslate_bricks"},
        {pos: [5, 1, 1], state: "minecraft:gravel"},
        {pos: [5, 1, 2], state: "minecraft:gravel"},
        {pos: [5, 1, 3], state: "minecraft:gravel"},
        {pos: [5, 1, 4], state: "minecraft:gravel"},
        {pos: [5, 1, 5], state: "minecraft:gravel"},
        {pos: [5, 1, 6], state: "minecraft:deepslate_bricks"},
        {pos: [6, 1, 0], state: "minecraft:deepslate_bricks"},
        {pos: [6, 1, 1], state: "minecraft:deepslate_bricks"},
        {pos: [6, 1, 2], state: "minecraft:deepslate_bricks"},
        {pos: [6, 1, 3], state: "minecraft:deepslate_bricks"},
        {pos: [6, 1, 4], state: "minecraft:deepslate_bricks"},
        {pos: [6, 1, 5], state: "minecraft:deepslate_bricks"},
        {pos: [6, 1, 6], state: "minecraft:deepslate_bricks"},
        {pos: [0, 2, 0], state: "minecraft:deepslate_bricks"},
        {pos: [0, 2, 1], state: "minecraft:deepslate_bricks"},
        {pos: [0, 2, 2], state: "minecraft:deepslate_bricks"},
        {pos: [0, 2, 3], state: "minecraft:deepslate_bricks"},
        {pos: [0, 2, 4], state: "minecraft:deepslate_bricks"},
        {pos: [0, 2, 5], state: "minecraft:deepslate_bricks"},
        {pos: [0, 2, 6], state: "minecraft:deepslate_bricks"},
        {pos: [1, 2, 0], state: "minecraft:deepslate_bricks"},
        {pos: [1, 2, 1], state: "minecraft:candle{candles:4,lit:false,waterlogged:false}"},
        {pos: [1, 2, 2], state: "minecraft:candle{candles:4,lit:false,waterlogged:false}"},
        {pos: [1, 2, 3], state: "minecraft:candle{candles:4,lit:false,waterlogged:false}"},
        {pos: [1, 2, 4], state: "minecraft:candle{candles:4,lit:false,waterlogged:false}"},
        {pos: [1, 2, 5], state: "minecraft:candle{candles:4,lit:false,waterlogged:false}"},
        {pos: [1, 2, 6], state: "minecraft:deepslate_bricks"},
        {pos: [2, 2, 0], state: "minecraft:deepslate_bricks"},
        {pos: [2, 2, 1], state: "minecraft:candle{candles:4,lit:false,waterlogged:false}"},
        {pos: [2, 2, 2], state: "minecraft:deepslate_brick_stairs{facing:south,half:bottom,shape:straight,waterlogged:false}"},
        {pos: [2, 2, 3], state: "minecraft:deepslate_bricks"},
        {pos: [2, 2, 4], state: "minecraft:deepslate_bricks"},
        {pos: [2, 2, 5], state: "minecraft:candle{candles:4,lit:false,waterlogged:false}"},
        {pos: [2, 2, 6], state: "minecraft:deepslate_bricks"},
        {pos: [3, 2, 0], state: "minecraft:deepslate_bricks"},
        {pos: [3, 2, 1], state: "minecraft:candle{candles:4,lit:false,waterlogged:false}"},
        {pos: [3, 2, 2], state: "minecraft:deepslate_bricks"},
        {pos: [3, 2, 3], state: "minecraft:deepslate_bricks"},
        {pos: [3, 2, 4], state: "minecraft:deepslate_brick_stairs{facing:north,half:bottom,shape:straight,waterlogged:false}"},
        {pos: [3, 2, 5], state: "minecraft:cave_air"},
        {pos: [3, 2, 6], state: "minecraft:jigsaw{orientation:south_up}", nbt: {final_state: "minecraft:cave_air", id: "minecraft:jigsaw", joint: "rollable", name: "trailiertales:small_room", placement_priority: 0, pool: "minecraft:empty", selection_priority: 0, target: "trailiertales:small_room"}},
        {pos: [4, 2, 0], state: "minecraft:deepslate_bricks"},
        {pos: [4, 2, 1], state: "minecraft:candle{candles:4,lit:false,waterlogged:false}"},
        {pos: [4, 2, 2], state: "minecraft:deepslate_bricks"},
        {pos: [4, 2, 3], state: "minecraft:deepslate_bricks"},
        {pos: [4, 2, 4], state: "minecraft:deepslate_brick_stairs{facing:north,half:bottom,shape:straight,waterlogged:false}"},
        {pos: [4, 2, 5], state: "minecraft:candle{candles:4,lit:false,waterlogged:false}"},
        {pos: [4, 2, 6], state: "minecraft:deepslate_bricks"},
        {pos: [5, 2, 0], state: "minecraft:deepslate_bricks"},
        {pos: [5, 2, 1], state: "minecraft:candle{candles:4,lit:false,waterlogged:false}"},
        {pos: [5, 2, 2], state: "minecraft:candle{candles:4,lit:false,waterlogged:false}"},
        {pos: [5, 2, 3], state: "minecraft:candle{candles:4,lit:false,waterlogged:false}"},
        {pos: [5, 2, 4], state: "minecraft:candle{candles:4,lit:false,waterlogged:false}"},
        {pos: [5, 2, 5], state: "minecraft:candle{candles:4,lit:false,waterlogged:false}"},
        {pos: [5, 2, 6], state: "minecraft:deepslate_bricks"},
        {pos: [6, 2, 0], state: "minecraft:deepslate_bricks"},
        {pos: [6, 2, 1], state: "minecraft:deepslate_bricks"},
        {pos: [6, 2, 2], state: "minecraft:deepslate_bricks"},
        {pos: [6, 2, 3], state: "minecraft:deepslate_bricks"},
        {pos: [6, 2, 4], state: "minecraft:deepslate_bricks"},
        {pos: [6, 2, 5], state: "minecraft:deepslate_bricks"},
        {pos: [6, 2, 6], state: "minecraft:deepslate_bricks"},
        {pos: [0, 3, 0], state: "minecraft:deepslate_bricks"},
        {pos: [0, 3, 1], state: "minecraft:deepslate_bricks"},
        {pos: [0, 3, 2], state: "minecraft:deepslate_bricks"},
        {pos: [0, 3, 3], state: "minecraft:deepslate_bricks"},
        {pos: [0, 3, 4], state: "minecraft:deepslate_bricks"},
        {pos: [0, 3, 5], state: "minecraft:deepslate_bricks"},
        {pos: [0, 3, 6], state: "minecraft:deepslate_bricks"},
        {pos: [1, 3, 0], state: "minecraft:deepslate_bricks"},
        {pos: [1, 3, 1], state: "minecraft:cave_air"},
        {pos: [1, 3, 2], state: "minecraft:cave_air"},
        {pos: [1, 3, 3], state: "minecraft:cave_air"},
        {pos: [1, 3, 4], state: "minecraft:cave_air"},
        {pos: [1, 3, 5], state: "minecraft:cave_air"},
        {pos: [1, 3, 6], state: "minecraft:deepslate_bricks"},
        {pos: [2, 3, 0], state: "minecraft:deepslate_bricks"},
        {pos: [2, 3, 1], state: "minecraft:cave_air"},
        {pos: [2, 3, 2], state: "minecraft:cave_air"},
        {pos: [2, 3, 3], state: "minecraft:candle{candles:4,lit:false,waterlogged:false}"},
        {pos: [2, 3, 4], state: "minecraft:candle{candles:4,lit:false,waterlogged:false}"},
        {pos: [2, 3, 5], state: "minecraft:cave_air"},
        {pos: [2, 3, 6], state: "minecraft:deepslate_bricks"},
        {pos: [3, 3, 0], state: "minecraft:deepslate_bricks"},
        {pos: [3, 3, 1], state: "minecraft:cave_air"},
        {pos: [3, 3, 2], state: "minecraft:candle{candles:4,lit:false,waterlogged:false}"},
        {pos: [3, 3, 3], state: "minecraft:decorated_pot{cracked:false,facing:north,waterlogged:false}", nbt: {id: "minecraft:decorated_pot"}},
        {pos: [3, 3, 4], state: "minecraft:cave_air"},
        {pos: [3, 3, 5], state: "minecraft:cave_air"},
        {pos: [3, 3, 6], state: "minecraft:cave_air"},
        {pos: [4, 3, 0], state: "minecraft:deepslate_bricks"},
        {pos: [4, 3, 1], state: "minecraft:cave_air"},
        {pos: [4, 3, 2], state: "minecraft:candle{candles:4,lit:false,waterlogged:false}"},
        {pos: [4, 3, 3], state: "minecraft:candle{candles:4,lit:false,waterlogged:false}"},
        {pos: [4, 3, 4], state: "minecraft:cave_air"},
        {pos: [4, 3, 5], state: "minecraft:cave_air"},
        {pos: [4, 3, 6], state: "minecraft:deepslate_bricks"},
        {pos: [5, 3, 0], state: "minecraft:deepslate_bricks"},
        {pos: [5, 3, 1], state: "minecraft:cave_air"},
        {pos: [5, 3, 2], state: "minecraft:cave_air"},
        {pos: [5, 3, 3], state: "minecraft:cave_air"},
        {pos: [5, 3, 4], state: "minecraft:cave_air"},
        {pos: [5, 3, 5], state: "minecraft:cave_air"},
        {pos: [5, 3, 6], state: "minecraft:deepslate_bricks"},
        {pos: [6, 3, 0], state: "minecraft:deepslate_bricks"},
        {pos: [6, 3, 1], state: "minecraft:deepslate_bricks"},
        {pos: [6, 3, 2], state: "minecraft:deepslate_bricks"},
        {pos: [6, 3, 3], state: "minecraft:deepslate_bricks"},
        {pos: [6, 3, 4], state: "minecraft:deepslate_bricks"},
        {pos: [6, 3, 5], state: "minecraft:deepslate_bricks"},
        {pos: [6, 3, 6], state: "minecraft:deepslate_bricks"},
        {pos: [0, 4, 0], state: "minecraft:deepslate_bricks"},
        {pos: [0, 4, 1], state: "minecraft:deepslate_bricks"},
        {pos: [0, 4, 2], state: "minecraft:deepslate_bricks"},
        {pos: [0, 4, 3], state: "minecraft:deepslate_bricks"},
        {pos: [0, 4, 4], state: "minecraft:deepslate_bricks"},
        {pos: [0, 4, 5], state: "minecraft:deepslate_bricks"},
        {pos: [0, 4, 6], state: "minecraft:deepslate_bricks"},
        {pos: [1, 4, 0], state: "minecraft:deepslate_bricks"},
        {pos: [1, 4, 1], state: "minecraft:cave_air"},
        {pos: [1, 4, 2], state: "minecraft:cobweb"},
        {pos: [1, 4, 3], state: "minecraft:cave_air"},
        {pos: [1, 4, 4], state: "minecraft:cave_air"},
        {pos: [1, 4, 5], state: "minecraft:cobweb"},
        {pos: [1, 4, 6], state: "minecraft:deepslate_bricks"},
        {pos: [2, 4, 0], state: "minecraft:deepslate_bricks"},
        {pos: [2, 4, 1], state: "minecraft:cave_air"},
        {pos: [2, 4, 2], state: "minecraft:cave_air"},
        {pos: [2, 4, 3], state: "minecraft:cave_air"},
        {pos: [2, 4, 4], state: "minecraft:cave_air"},
        {pos: [2, 4, 5], state: "minecraft:cobweb"},
        {pos: [2, 4, 6], state: "minecraft:deepslate_bricks"},
        {pos: [3, 4, 0], state: "minecraft:deepslate_bricks"},
        {pos: [3, 4, 1], state: "minecraft:cave_air"},
        {pos: [3, 4, 2], state: "minecraft:cave_air"},
        {pos: [3, 4, 3], state: "minecraft:cave_air"},
        {pos: [3, 4, 4], state: "minecraft:cave_air"},
        {pos: [3, 4, 5], state: "minecraft:cave_air"},
        {pos: [3, 4, 6], state: "minecraft:deepslate_bricks"},
        {pos: [4, 4, 0], state: "minecraft:deepslate_bricks"},
        {pos: [4, 4, 1], state: "minecraft:cave_air"},
        {pos: [4, 4, 2], state: "minecraft:cave_air"},
        {pos: [4, 4, 3], state: "minecraft:cave_air"},
        {pos: [4, 4, 4], state: "minecraft:cave_air"},
        {pos: [4, 4, 5], state: "minecraft:cave_air"},
        {pos: [4, 4, 6], state: "minecraft:deepslate_bricks"},
        {pos: [5, 4, 0], state: "minecraft:deepslate_bricks"},
        {pos: [5, 4, 1], state: "minecraft:cave_air"},
        {pos: [5, 4, 2], state: "minecraft:cave_air"},
        {pos: [5, 4, 3], state: "minecraft:cave_air"},
        {pos: [5, 4, 4], state: "minecraft:cave_air"},
        {pos: [5, 4, 5], state: "minecraft:cobweb"},
        {pos: [5, 4, 6], state: "minecraft:deepslate_bricks"},
        {pos: [6, 4, 0], state: "minecraft:deepslate_bricks"},
        {pos: [6, 4, 1], state: "minecraft:deepslate_bricks"},
        {pos: [6, 4, 2], state: "minecraft:deepslate_bricks"},
        {pos: [6, 4, 3], state: "minecraft:deepslate_bricks"},
        {pos: [6, 4, 4], state: "minecraft:deepslate_bricks"},
        {pos: [6, 4, 5], state: "minecraft:deepslate_bricks"},
        {pos: [6, 4, 6], state: "minecraft:deepslate_bricks"},
        {pos: [0, 5, 0], state: "minecraft:deepslate_bricks"},
        {pos: [0, 5, 1], state: "minecraft:deepslate_bricks"},
        {pos: [0, 5, 2], state: "minecraft:deepslate_bricks"},
        {pos: [0, 5, 3], state: "minecraft:deepslate_bricks"},
        {pos: [0, 5, 4], state: "minecraft:deepslate_bricks"},
        {pos: [0, 5, 5], state: "minecraft:deepslate_bricks"},
        {pos: [0, 5, 6], state: "minecraft:deepslate_bricks"},
        {pos: [1, 5, 0], state: "minecraft:deepslate_bricks"},
        {pos: [1, 5, 1], state: "minecraft:jigsaw{orientation:down_east}", nbt: {final_state: "minecraft:deepslate_bricks", id: "minecraft:jigsaw", joint: "rollable", name: "trailiertales:chain", placement_priority: 0, pool: "trailiertales:catacombs/decoration/chain_3", selection_priority: 0, target: "trailiertales:chain"}},
        {pos: [1, 5, 2], state: "minecraft:deepslate_bricks"},
        {pos: [1, 5, 3], state: "minecraft:jigsaw{orientation:down_east}", nbt: {final_state: "minecraft:deepslate_bricks", id: "minecraft:jigsaw", joint: "rollable", name: "trailiertales:chain", placement_priority: 0, pool: "trailiertales:catacombs/decoration/chain_3", selection_priority: 0, target: "trailiertales:chain"}},
        {pos: [1, 5, 4], state: "minecraft:jigsaw{orientation:down_east}", nbt: {final_state: "minecraft:deepslate_bricks", id: "minecraft:jigsaw", joint: "rollable", name: "trailiertales:chain", placement_priority: 0, pool: "trailiertales:catacombs/decoration/chain_3", selection_priority: 0, target: "trailiertales:chain"}},
        {pos: [1, 5, 5], state: "minecraft:deepslate_bricks"},
        {pos: [1, 5, 6], state: "minecraft:deepslate_bricks"},
        {pos: [2, 5, 0], state: "minecraft:deepslate_bricks"},
        {pos: [2, 5, 1], state: "minecraft:jigsaw{orientation:down_east}", nbt: {final_state: "minecraft:deepslate_bricks", id: "minecraft:jigsaw", joint: "rollable", name: "trailiertales:chain", placement_priority: 0, pool: "trailiertales:catacombs/decoration/chain_3", selection_priority: 0, target: "trailiertales:chain"}},
        {pos: [2, 5, 2], state: "minecraft:jigsaw{orientation:down_south}", nbt: {final_state: "minecraft:deepslate_bricks", id: "minecraft:jigsaw", joint: "rollable", name: "trailiertales:chain", placement_priority: 0, pool: "trailiertales:catacombs/decoration/chain_2", selection_priority: 0, target: "trailiertales:chain"}},
        {pos: [2, 5, 3], state: "minecraft:jigsaw{orientation:down_south}", nbt: {final_state: "minecraft:deepslate_bricks", id: "minecraft:jigsaw", joint: "rollable", name: "trailiertales:chain", placement_priority: 0, pool: "trailiertales:catacombs/decoration/chain_2", selection_priority: 0, target: "trailiertales:chain"}},
        {pos: [2, 5, 4], state: "minecraft:jigsaw{orientation:down_east}", nbt: {final_state: "minecraft:deepslate_bricks", id: "minecraft:jigsaw", joint: "rollable", name: "trailiertales:chain", placement_priority: 0, pool: "trailiertales:catacombs/decoration/chain_2", selection_priority: 0, target: "trailiertales:chain"}},
        {pos: [2, 5, 5], state: "minecraft:deepslate_bricks"},
        {pos: [2, 5, 6], state: "minecraft:deepslate_bricks"},
        {pos: [3, 5, 0], state: "minecraft:deepslate_bricks"},
        {pos: [3, 5, 1], state: "minecraft:jigsaw{orientation:down_south}", nbt: {final_state: "minecraft:deepslate_bricks", id: "minecraft:jigsaw", joint: "rollable", name: "trailiertales:chain", placement_priority: 0, pool: "trailiertales:catacombs/decoration/chain_3", selection_priority: 0, target: "trailiertales:chain"}},
        {pos: [3, 5, 2], state: "minecraft:jigsaw{orientation:down_south}", nbt: {final_state: "minecraft:deepslate_bricks", id: "minecraft:jigsaw", joint: "rollable", name: "trailiertales:chain", placement_priority: 0, pool: "trailiertales:catacombs/decoration/chain_2", selection_priority: 0, target: "trailiertales:chain"}},
        {pos: [3, 5, 3], state: "minecraft:jigsaw{orientation:down_south}", nbt: {final_state: "minecraft:deepslate_bricks", id: "minecraft:jigsaw", joint: "rollable", name: "trailiertales:chain", placement_priority: 0, pool: "trailiertales:catacombs/decoration/chain_1", selection_priority: 0, target: "trailiertales:chain"}},
        {pos: [3, 5, 4], state: "minecraft:jigsaw{orientation:down_south}", nbt: {final_state: "minecraft:deepslate_bricks", id: "minecraft:jigsaw", joint: "rollable", name: "trailiertales:chain", placement_priority: 0, pool: "trailiertales:catacombs/decoration/chain_2", selection_priority: 0, target: "trailiertales:chain"}},
        {pos: [3, 5, 5], state: "minecraft:deepslate_bricks"},
        {pos: [3, 5, 6], state: "minecraft:deepslate_bricks"},
        {pos: [4, 5, 0], state: "minecraft:deepslate_bricks"},
        {pos: [4, 5, 1], state: "minecraft:jigsaw{orientation:down_west}", nbt: {final_state: "minecraft:deepslate_bricks", id: "minecraft:jigsaw", joint: "rollable", name: "trailiertales:chain", placement_priority: 0, pool: "trailiertales:catacombs/decoration/chain_3", selection_priority: 0, target: "trailiertales:chain"}},
        {pos: [4, 5, 2], state: "minecraft:jigsaw{orientation:down_south}", nbt: {final_state: "minecraft:deepslate_bricks", id: "minecraft:jigsaw", joint: "rollable", name: "trailiertales:chain", placement_priority: 0, pool: "trailiertales:catacombs/decoration/chain_2", selection_priority: 0, target: "trailiertales:chain"}},
        {pos: [4, 5, 3], state: "minecraft:jigsaw{orientation:down_south}", nbt: {final_state: "minecraft:deepslate_bricks", id: "minecraft:jigsaw", joint: "rollable", name: "trailiertales:chain", placement_priority: 0, pool: "trailiertales:catacombs/decoration/chain_2", selection_priority: 0, target: "trailiertales:chain"}},
        {pos: [4, 5, 4], state: "minecraft:jigsaw{orientation:down_west}", nbt: {final_state: "minecraft:deepslate_bricks", id: "minecraft:jigsaw", joint: "rollable", name: "trailiertales:chain", placement_priority: 0, pool: "trailiertales:catacombs/decoration/chain_2", selection_priority: 0, target: "trailiertales:chain"}},
        {pos: [4, 5, 5], state: "minecraft:deepslate_bricks"},
        {pos: [4, 5, 6], state: "minecraft:deepslate_bricks"},
        {pos: [5, 5, 0], state: "minecraft:deepslate_bricks"},
        {pos: [5, 5, 1], state: "minecraft:jigsaw{orientation:down_south}", nbt: {final_state: "minecraft:deepslate_bricks", id: "minecraft:jigsaw", joint: "rollable", name: "trailiertales:chain", placement_priority: 0, pool: "trailiertales:catacombs/decoration/chain_3", selection_priority: 0, target: "trailiertales:chain"}},
        {pos: [5, 5, 2], state: "minecraft:jigsaw{orientation:down_west}", nbt: {final_state: "minecraft:deepslate_bricks", id: "minecraft:jigsaw", joint: "rollable", name: "trailiertales:chain", placement_priority: 0, pool: "trailiertales:catacombs/decoration/chain_3", selection_priority: 0, target: "trailiertales:chain"}},
        {pos: [5, 5, 3], state: "minecraft:jigsaw{orientation:down_west}", nbt: {final_state: "minecraft:deepslate_bricks", id: "minecraft:jigsaw", joint: "rollable", name: "trailiertales:chain", placement_priority: 0, pool: "trailiertales:catacombs/decoration/chain_3", selection_priority: 0, target: "trailiertales:chain"}},
        {pos: [5, 5, 4], state: "minecraft:jigsaw{orientation:down_west}", nbt: {final_state: "minecraft:deepslate_bricks", id: "minecraft:jigsaw", joint: "rollable", name: "trailiertales:chain", placement_priority: 0, pool: "trailiertales:catacombs/decoration/chain_3", selection_priority: 0, target: "trailiertales:chain"}},
        {pos: [5, 5, 5], state: "minecraft:deepslate_bricks"},
        {pos: [5, 5, 6], state: "minecraft:deepslate_bricks"},
        {pos: [6, 5, 0], state: "minecraft:deepslate_bricks"},
        {pos: [6, 5, 1], state: "minecraft:deepslate_bricks"},
        {pos: [6, 5, 2], state: "minecraft:deepslate_bricks"},
        {pos: [6, 5, 3], state: "minecraft:deepslate_bricks"},
        {pos: [6, 5, 4], state: "minecraft:deepslate_bricks"},
        {pos: [6, 5, 5], state: "minecraft:deepslate_bricks"},
        {pos: [6, 5, 6], state: "minecraft:deepslate_bricks"}
    ],
    entities: [],
    palette: [
        "minecraft:deepslate{axis:y}",
        "minecraft:deepslate_bricks",
        "minecraft:gravel",
        "minecraft:candle{candles:4,lit:false,waterlogged:false}",
        "minecraft:deepslate_brick_stairs{facing:south,half:bottom,shape:straight,waterlogged:false}",
        "minecraft:deepslate_brick_stairs{facing:north,half:bottom,shape:straight,waterlogged:false}",
        "minecraft:cave_air",
        "minecraft:cobweb",
        "minecraft:jigsaw{orientation:south_up}",
        "minecraft:decorated_pot{cracked:false,facing:north,waterlogged:false}",
        "minecraft:jigsaw{orientation:down_east}",
        "minecraft:jigsaw{orientation:down_south}",
        "minecraft:jigsaw{orientation:down_west}"
    ],
    trailiertales_DataVersion: 3
}
