{
    DataVersion: 3953,
    size: [9, 17, 17],
    data: [
        {pos: [1, 0, 9], state: "minecraft:cobblestone"},
        {pos: [1, 0, 10], state: "minecraft:cobblestone"},
        {pos: [2, 0, 8], state: "minecraft:cobblestone"},
        {pos: [2, 0, 9], state: "minecraft:cobblestone"},
        {pos: [2, 0, 10], state: "minecraft:cobblestone"},
        {pos: [2, 0, 11], state: "minecraft:cobblestone"},
        {pos: [2, 0, 12], state: "minecraft:cobblestone"},
        {pos: [3, 0, 4], state: "minecraft:cobblestone"},
        {pos: [3, 0, 5], state: "minecraft:cobblestone"},
        {pos: [3, 0, 6], state: "minecraft:cobblestone"},
        {pos: [3, 0, 7], state: "minecraft:cobblestone"},
        {pos: [3, 0, 8], state: "minecraft:cobblestone"},
        {pos: [3, 0, 9], state: "minecraft:cobblestone"},
        {pos: [3, 0, 10], state: "minecraft:cobblestone"},
        {pos: [3, 0, 11], state: "minecraft:cobblestone"},
        {pos: [3, 0, 12], state: "minecraft:cobblestone"},
        {pos: [4, 0, 4], state: "minecraft:cobblestone"},
        {pos: [4, 0, 5], state: "minecraft:cobblestone"},
        {pos: [4, 0, 6], state: "minecraft:cobblestone"},
        {pos: [4, 0, 7], state: "minecraft:cobblestone"},
        {pos: [4, 0, 8], state: "minecraft:cobblestone"},
        {pos: [4, 0, 9], state: "minecraft:cobblestone"},
        {pos: [4, 0, 10], state: "minecraft:cobblestone"},
        {pos: [4, 0, 11], state: "minecraft:cobblestone"},
        {pos: [4, 0, 12], state: "minecraft:cobblestone"},
        {pos: [4, 0, 13], state: "minecraft:cobblestone"},
        {pos: [5, 0, 4], state: "minecraft:cobblestone"},
        {pos: [5, 0, 5], state: "minecraft:cobblestone"},
        {pos: [5, 0, 6], state: "minecraft:cobblestone"},
        {pos: [5, 0, 7], state: "minecraft:cobblestone"},
        {pos: [5, 0, 8], state: "minecraft:cobblestone"},
        {pos: [5, 0, 9], state: "minecraft:cobblestone"},
        {pos: [5, 0, 10], state: "minecraft:cobblestone"},
        {pos: [5, 0, 11], state: "minecraft:cobblestone"},
        {pos: [5, 0, 12], state: "minecraft:cobblestone"},
        {pos: [6, 0, 8], state: "minecraft:cobblestone"},
        {pos: [6, 0, 9], state: "minecraft:cobblestone"},
        {pos: [6, 0, 10], state: "minecraft:cobblestone"},
        {pos: [6, 0, 11], state: "minecraft:cobblestone"},
        {pos: [7, 0, 9], state: "minecraft:cobblestone"},
        {pos: [7, 0, 10], state: "minecraft:cobblestone"},
        {pos: [7, 0, 11], state: "minecraft:cobblestone"},
        {pos: [1, 1, 9], state: "minecraft:cobblestone"},
        {pos: [1, 1, 10], state: "minecraft:cobblestone"},
        {pos: [1, 1, 11], state: "minecraft:cobblestone"},
        {pos: [2, 1, 1], state: "minecraft:cobblestone"},
        {pos: [2, 1, 2], state: "minecraft:cobblestone"},
        {pos: [2, 1, 3], state: "minecraft:cobblestone"},
        {pos: [2, 1, 7], state: "minecraft:cobblestone"},
        {pos: [2, 1, 8], state: "minecraft:cobblestone"},
        {pos: [2, 1, 9], state: "minecraft:cobblestone"},
        {pos: [2, 1, 10], state: "minecraft:cobblestone"},
        {pos: [2, 1, 11], state: "minecraft:cobblestone"},
        {pos: [2, 1, 12], state: "minecraft:cobblestone"},
        {pos: [3, 1, 0], state: "minecraft:cobblestone"},
        {pos: [3, 1, 1], state: "minecraft:cobblestone"},
        {pos: [3, 1, 2], state: "minecraft:cobblestone"},
        {pos: [3, 1, 3], state: "minecraft:cobblestone"},
        {pos: [3, 1, 4], state: "minecraft:cobblestone"},
        {pos: [3, 1, 5], state: "minecraft:cobblestone"},
        {pos: [3, 1, 6], state: "minecraft:cobblestone"},
        {pos: [3, 1, 7], state: "minecraft:cobblestone"},
        {pos: [3, 1, 8], state: "minecraft:cobblestone"},
        {pos: [3, 1, 9], state: "minecraft:gravel"},
        {pos: [3, 1, 10], state: "minecraft:tnt{unstable:false}"},
        {pos: [3, 1, 11], state: "minecraft:gravel"},
        {pos: [3, 1, 12], state: "minecraft:cobblestone"},
        {pos: [3, 1, 13], state: "minecraft:cobblestone"},
        {pos: [4, 1, 0], state: "minecraft:cobblestone"},
        {pos: [4, 1, 1], state: "minecraft:cobblestone"},
        {pos: [4, 1, 2], state: "minecraft:cobblestone"},
        {pos: [4, 1, 3], state: "minecraft:cobblestone"},
        {pos: [4, 1, 4], state: "minecraft:cobblestone"},
        {pos: [4, 1, 5], state: "minecraft:cobblestone"},
        {pos: [4, 1, 6], state: "minecraft:cobblestone"},
        {pos: [4, 1, 7], state: "minecraft:cobblestone"},
        {pos: [4, 1, 8], state: "minecraft:cobblestone"},
        {pos: [4, 1, 9], state: "minecraft:tnt{unstable:false}"},
        {pos: [4, 1, 10], state: "minecraft:tnt{unstable:false}"},
        {pos: [4, 1, 11], state: "minecraft:tnt{unstable:false}"},
        {pos: [4, 1, 12], state: "minecraft:cobblestone"},
        {pos: [4, 1, 13], state: "minecraft:cobblestone"},
        {pos: [5, 1, 0], state: "minecraft:cobblestone"},
        {pos: [5, 1, 1], state: "minecraft:cobblestone"},
        {pos: [5, 1, 2], state: "minecraft:cobblestone"},
        {pos: [5, 1, 3], state: "minecraft:cobblestone"},
        {pos: [5, 1, 4], state: "minecraft:cobblestone"},
        {pos: [5, 1, 5], state: "minecraft:cobblestone"},
        {pos: [5, 1, 6], state: "minecraft:cobblestone"},
        {pos: [5, 1, 7], state: "minecraft:cobblestone"},
        {pos: [5, 1, 8], state: "minecraft:cobblestone"},
        {pos: [5, 1, 9], state: "minecraft:gravel"},
        {pos: [5, 1, 10], state: "minecraft:tnt{unstable:false}"},
        {pos: [5, 1, 11], state: "minecraft:gravel"},
        {pos: [5, 1, 12], state: "minecraft:cobblestone"},
        {pos: [5, 1, 13], state: "minecraft:cobblestone"},
        {pos: [6, 1, 1], state: "minecraft:cobblestone"},
        {pos: [6, 1, 2], state: "minecraft:cobblestone"},
        {pos: [6, 1, 3], state: "minecraft:cobblestone"},
        {pos: [6, 1, 7], state: "minecraft:cobblestone"},
        {pos: [6, 1, 8], state: "minecraft:cobblestone"},
        {pos: [6, 1, 9], state: "minecraft:cobblestone"},
        {pos: [6, 1, 10], state: "minecraft:cobblestone"},
        {pos: [6, 1, 11], state: "minecraft:cobblestone"},
        {pos: [6, 1, 12], state: "minecraft:cobblestone"},
        {pos: [7, 1, 9], state: "minecraft:cobblestone"},
        {pos: [7, 1, 10], state: "minecraft:cobblestone"},
        {pos: [7, 1, 11], state: "minecraft:cobblestone"},
        {pos: [0, 2, 10], state: "minecraft:cobblestone"},
        {pos: [1, 2, 8], state: "minecraft:cobblestone"},
        {pos: [1, 2, 9], state: "minecraft:cobblestone"},
        {pos: [1, 2, 10], state: "minecraft:gravel"},
        {pos: [1, 2, 11], state: "minecraft:cobblestone"},
        {pos: [2, 2, 0], state: "minecraft:cobblestone"},
        {pos: [2, 2, 1], state: "minecraft:cobblestone"},
        {pos: [2, 2, 2], state: "minecraft:cobblestone"},
        {pos: [2, 2, 3], state: "minecraft:cobblestone"},
        {pos: [2, 2, 4], state: "minecraft:cobblestone"},
        {pos: [2, 2, 7], state: "minecraft:cobblestone"},
        {pos: [2, 2, 8], state: "minecraft:cobblestone"},
        {pos: [2, 2, 9], state: "minecraft:cobblestone"},
        {pos: [2, 2, 10], state: "minecraft:gravel"},
        {pos: [2, 2, 11], state: "minecraft:cobblestone"},
        {pos: [2, 2, 12], state: "minecraft:cobblestone"},
        {pos: [3, 2, 0], state: "minecraft:cobblestone"},
        {pos: [3, 2, 1], state: "minecraft:cobblestone"},
        {pos: [3, 2, 2], state: "minecraft:gravel"},
        {pos: [3, 2, 3], state: "minecraft:gravel"},
        {pos: [3, 2, 4], state: "minecraft:cobblestone"},
        {pos: [3, 2, 5], state: "minecraft:cobblestone"},
        {pos: [3, 2, 6], state: "minecraft:gravel"},
        {pos: [3, 2, 7], state: "minecraft:cobblestone"},
        {pos: [3, 2, 8], state: "minecraft:cobblestone"},
        {pos: [3, 2, 9], state: "minecraft:gravel"},
        {pos: [3, 2, 10], state: "minecraft:gravel"},
        {pos: [3, 2, 11], state: "minecraft:gravel"},
        {pos: [3, 2, 12], state: "minecraft:cobblestone"},
        {pos: [3, 2, 13], state: "minecraft:cobblestone"},
        {pos: [4, 2, 0], state: "minecraft:cobblestone"},
        {pos: [4, 2, 1], state: "minecraft:cobblestone"},
        {pos: [4, 2, 2], state: "minecraft:gravel"},
        {pos: [4, 2, 3], state: "minecraft:gravel"},
        {pos: [4, 2, 4], state: "minecraft:gravel"},
        {pos: [4, 2, 5], state: "minecraft:gravel"},
        {pos: [4, 2, 6], state: "minecraft:gravel"},
        {pos: [4, 2, 7], state: "minecraft:gravel"},
        {pos: [4, 2, 8], state: "minecraft:gravel"},
        {pos: [4, 2, 9], state: "minecraft:gravel"},
        {pos: [4, 2, 10], state: "minecraft:gravel"},
        {pos: [4, 2, 11], state: "minecraft:gravel"},
        {pos: [4, 2, 12], state: "minecraft:gravel"},
        {pos: [4, 2, 13], state: "minecraft:gravel"},
        {pos: [5, 2, 0], state: "minecraft:cobblestone"},
        {pos: [5, 2, 1], state: "minecraft:gravel"},
        {pos: [5, 2, 2], state: "minecraft:cobblestone"},
        {pos: [5, 2, 3], state: "minecraft:gravel"},
        {pos: [5, 2, 4], state: "minecraft:gravel"},
        {pos: [5, 2, 5], state: "minecraft:cobblestone"},
        {pos: [5, 2, 6], state: "minecraft:cobblestone"},
        {pos: [5, 2, 7], state: "minecraft:cobblestone"},
        {pos: [5, 2, 8], state: "minecraft:cobblestone"},
        {pos: [5, 2, 9], state: "minecraft:gravel"},
        {pos: [5, 2, 10], state: "minecraft:gravel"},
        {pos: [5, 2, 11], state: "minecraft:gravel"},
        {pos: [5, 2, 12], state: "minecraft:cobblestone"},
        {pos: [5, 2, 13], state: "minecraft:cobblestone"},
        {pos: [6, 2, 0], state: "minecraft:cobblestone"},
        {pos: [6, 2, 1], state: "minecraft:cobblestone"},
        {pos: [6, 2, 2], state: "minecraft:cobblestone"},
        {pos: [6, 2, 3], state: "minecraft:cobblestone"},
        {pos: [6, 2, 4], state: "minecraft:cobblestone"},
        {pos: [6, 2, 7], state: "minecraft:cobblestone"},
        {pos: [6, 2, 8], state: "minecraft:cobblestone"},
        {pos: [6, 2, 9], state: "minecraft:cobblestone"},
        {pos: [6, 2, 10], state: "minecraft:gravel"},
        {pos: [6, 2, 11], state: "minecraft:cobblestone"},
        {pos: [6, 2, 12], state: "minecraft:cobblestone"},
        {pos: [7, 2, 8], state: "minecraft:cobblestone"},
        {pos: [7, 2, 9], state: "minecraft:cobblestone"},
        {pos: [7, 2, 10], state: "minecraft:gravel"},
        {pos: [7, 2, 11], state: "minecraft:cobblestone"},
        {pos: [8, 2, 9], state: "minecraft:cobblestone"},
        {pos: [8, 2, 10], state: "minecraft:cobblestone"},
        {pos: [0, 3, 9], state: "minecraft:cobblestone"},
        {pos: [0, 3, 10], state: "minecraft:cobblestone"},
        {pos: [0, 3, 11], state: "minecraft:cobblestone"},
        {pos: [1, 3, 8], state: "minecraft:cobblestone"},
        {pos: [1, 3, 9], state: "minecraft:gravel"},
        {pos: [1, 3, 10], state: "minecraft:gravel"},
        {pos: [1, 3, 11], state: "minecraft:gravel"},
        {pos: [1, 3, 12], state: "minecraft:cobblestone"},
        {pos: [2, 3, 0], state: "minecraft:cobblestone"},
        {pos: [2, 3, 1], state: "minecraft:cobblestone"},
        {pos: [2, 3, 2], state: "minecraft:cobblestone"},
        {pos: [2, 3, 3], state: "minecraft:cobblestone"},
        {pos: [2, 3, 4], state: "minecraft:cobblestone"},
        {pos: [2, 3, 7], state: "minecraft:cobblestone"},
        {pos: [2, 3, 8], state: "minecraft:cobblestone"},
        {pos: [2, 3, 9], state: "minecraft:cobblestone"},
        {pos: [2, 3, 10], state: "minecraft:gravel"},
        {pos: [2, 3, 11], state: "minecraft:cobblestone"},
        {pos: [2, 3, 12], state: "minecraft:cobblestone"},
        {pos: [3, 3, 0], state: "minecraft:cobblestone"},
        {pos: [3, 3, 1], state: "minecraft:gravel"},
        {pos: [3, 3, 2], state: "minecraft:gravel"},
        {pos: [3, 3, 3], state: "minecraft:gravel"},
        {pos: [3, 3, 4], state: "minecraft:gravel"},
        {pos: [3, 3, 5], state: "minecraft:gravel"},
        {pos: [3, 3, 6], state: "minecraft:gravel"},
        {pos: [3, 3, 7], state: "minecraft:cobblestone"},
        {pos: [3, 3, 8], state: "minecraft:cobblestone"},
        {pos: [3, 3, 9], state: "minecraft:gravel"},
        {pos: [3, 3, 10], state: "minecraft:air"},
        {pos: [3, 3, 11], state: "minecraft:gravel"},
        {pos: [3, 3, 12], state: "minecraft:cobblestone"},
        {pos: [3, 3, 13], state: "minecraft:gravel"},
        {pos: [3, 3, 14], state: "minecraft:cobblestone"},
        {pos: [4, 3, 0], state: "minecraft:cobblestone"},
        {pos: [4, 3, 1], state: "minecraft:gravel"},
        {pos: [4, 3, 2], state: "minecraft:gravel"},
        {pos: [4, 3, 3], state: "minecraft:gravel"},
        {pos: [4, 3, 4], state: "minecraft:gravel"},
        {pos: [4, 3, 5], state: "minecraft:gravel"},
        {pos: [4, 3, 6], state: "minecraft:gravel"},
        {pos: [4, 3, 7], state: "minecraft:gravel"},
        {pos: [4, 3, 8], state: "minecraft:gravel"},
        {pos: [4, 3, 9], state: "minecraft:gravel"},
        {pos: [4, 3, 10], state: "minecraft:stone_pressure_plate{powered:false}"},
        {pos: [4, 3, 11], state: "minecraft:air"},
        {pos: [4, 3, 12], state: "minecraft:air"},
        {pos: [4, 3, 13], state: "minecraft:gravel"},
        {pos: [4, 3, 14], state: "minecraft:cobblestone"},
        {pos: [5, 3, 0], state: "minecraft:cobblestone"},
        {pos: [5, 3, 1], state: "minecraft:gravel"},
        {pos: [5, 3, 2], state: "minecraft:gravel"},
        {pos: [5, 3, 3], state: "minecraft:gravel"},
        {pos: [5, 3, 4], state: "minecraft:gravel"},
        {pos: [5, 3, 5], state: "minecraft:gravel"},
        {pos: [5, 3, 6], state: "minecraft:gravel"},
        {pos: [5, 3, 7], state: "minecraft:cobblestone"},
        {pos: [5, 3, 8], state: "minecraft:cobblestone"},
        {pos: [5, 3, 9], state: "minecraft:air"},
        {pos: [5, 3, 10], state: "minecraft:air"},
        {pos: [5, 3, 11], state: "minecraft:gravel"},
        {pos: [5, 3, 12], state: "minecraft:cobblestone"},
        {pos: [5, 3, 13], state: "minecraft:gravel"},
        {pos: [6, 3, 0], state: "minecraft:cobblestone"},
        {pos: [6, 3, 1], state: "minecraft:cobblestone"},
        {pos: [6, 3, 2], state: "minecraft:cobblestone"},
        {pos: [6, 3, 3], state: "minecraft:cobblestone"},
        {pos: [6, 3, 4], state: "minecraft:cobblestone"},
        {pos: [6, 3, 7], state: "minecraft:cobblestone"},
        {pos: [6, 3, 8], state: "minecraft:cobblestone"},
        {pos: [6, 3, 9], state: "minecraft:cobblestone"},
        {pos: [6, 3, 10], state: "minecraft:air"},
        {pos: [6, 3, 11], state: "minecraft:cobblestone"},
        {pos: [6, 3, 12], state: "minecraft:cobblestone"},
        {pos: [7, 3, 8], state: "minecraft:cobblestone"},
        {pos: [7, 3, 9], state: "minecraft:gravel"},
        {pos: [7, 3, 10], state: "minecraft:gravel"},
        {pos: [7, 3, 11], state: "minecraft:gravel"},
        {pos: [8, 3, 9], state: "minecraft:cobblestone"},
        {pos: [8, 3, 10], state: "minecraft:cobblestone"},
        {pos: [8, 3, 11], state: "minecraft:cobblestone"},
        {pos: [0, 4, 9], state: "minecraft:cobblestone"},
        {pos: [0, 4, 10], state: "minecraft:cobblestone"},
        {pos: [0, 4, 11], state: "minecraft:cobblestone"},
        {pos: [1, 4, 8], state: "minecraft:cobblestone"},
        {pos: [1, 4, 9], state: "minecraft:gravel"},
        {pos: [1, 4, 10], state: "minecraft:gravel"},
        {pos: [1, 4, 11], state: "minecraft:gravel"},
        {pos: [1, 4, 12], state: "minecraft:cobblestone"},
        {pos: [2, 4, 1], state: "minecraft:cobblestone"},
        {pos: [2, 4, 2], state: "minecraft:cobblestone"},
        {pos: [2, 4, 3], state: "minecraft:cobblestone"},
        {pos: [2, 4, 4], state: "minecraft:cobblestone"},
        {pos: [2, 4, 8], state: "minecraft:cobblestone"},
        {pos: [2, 4, 9], state: "minecraft:cobblestone"},
        {pos: [2, 4, 10], state: "minecraft:air"},
        {pos: [2, 4, 11], state: "minecraft:cobblestone"},
        {pos: [2, 4, 12], state: "minecraft:cobblestone"},
        {pos: [2, 4, 13], state: "minecraft:cobblestone"},
        {pos: [3, 4, 0], state: "minecraft:cobblestone"},
        {pos: [3, 4, 1], state: "minecraft:gravel"},
        {pos: [3, 4, 2], state: "minecraft:gravel"},
        {pos: [3, 4, 3], state: "minecraft:gravel"},
        {pos: [3, 4, 4], state: "minecraft:gravel"},
        {pos: [3, 4, 5], state: "minecraft:gravel"},
        {pos: [3, 4, 6], state: "minecraft:gravel"},
        {pos: [3, 4, 7], state: "minecraft:cobblestone"},
        {pos: [3, 4, 8], state: "minecraft:cobblestone"},
        {pos: [3, 4, 9], state: "minecraft:air"},
        {pos: [3, 4, 10], state: "minecraft:air"},
        {pos: [3, 4, 11], state: "minecraft:gravel"},
        {pos: [3, 4, 12], state: "minecraft:cobblestone"},
        {pos: [3, 4, 13], state: "minecraft:gravel"},
        {pos: [3, 4, 14], state: "minecraft:cobblestone"},
        {pos: [3, 4, 15], state: "minecraft:cobblestone"},
        {pos: [4, 4, 0], state: "minecraft:cobblestone"},
        {pos: [4, 4, 1], state: "minecraft:gravel"},
        {pos: [4, 4, 2], state: "minecraft:gravel"},
        {pos: [4, 4, 3], state: "minecraft:gravel"},
        {pos: [4, 4, 4], state: "minecraft:gravel"},
        {pos: [4, 4, 5], state: "minecraft:gravel"},
        {pos: [4, 4, 6], state: "minecraft:gravel"},
        {pos: [4, 4, 7], state: "minecraft:gravel"},
        {pos: [4, 4, 8], state: "minecraft:gravel"},
        {pos: [4, 4, 9], state: "minecraft:air"},
        {pos: [4, 4, 10], state: "minecraft:air"},
        {pos: [4, 4, 11], state: "minecraft:air"},
        {pos: [4, 4, 12], state: "minecraft:air"},
        {pos: [4, 4, 13], state: "minecraft:gravel"},
        {pos: [4, 4, 14], state: "minecraft:cobblestone"},
        {pos: [4, 4, 15], state: "minecraft:cobblestone"},
        {pos: [5, 4, 0], state: "minecraft:cobblestone"},
        {pos: [5, 4, 1], state: "minecraft:gravel"},
        {pos: [5, 4, 2], state: "minecraft:gravel"},
        {pos: [5, 4, 3], state: "minecraft:gravel"},
        {pos: [5, 4, 4], state: "minecraft:gravel"},
        {pos: [5, 4, 6], state: "minecraft:gravel"},
        {pos: [5, 4, 7], state: "minecraft:cobblestone"},
        {pos: [5, 4, 8], state: "minecraft:cobblestone"},
        {pos: [5, 4, 9], state: "minecraft:air"},
        {pos: [5, 4, 10], state: "minecraft:air"},
        {pos: [5, 4, 11], state: "minecraft:air"},
        {pos: [5, 4, 12], state: "minecraft:cobblestone"},
        {pos: [5, 4, 13], state: "minecraft:gravel"},
        {pos: [5, 4, 14], state: "minecraft:cobblestone"},
        {pos: [6, 4, 1], state: "minecraft:cobblestone"},
        {pos: [6, 4, 2], state: "minecraft:cobblestone"},
        {pos: [6, 4, 3], state: "minecraft:cobblestone"},
        {pos: [6, 4, 4], state: "minecraft:cobblestone"},
        {pos: [6, 4, 8], state: "minecraft:cobblestone"},
        {pos: [6, 4, 9], state: "minecraft:cobblestone"},
        {pos: [6, 4, 10], state: "minecraft:air"},
        {pos: [6, 4, 11], state: "minecraft:cobblestone"},
        {pos: [6, 4, 12], state: "minecraft:cobblestone"},
        {pos: [6, 4, 13], state: "minecraft:cobblestone"},
        {pos: [7, 4, 9], state: "minecraft:gravel"},
        {pos: [7, 4, 10], state: "minecraft:gravel"},
        {pos: [7, 4, 11], state: "minecraft:gravel"},
        {pos: [8, 4, 9], state: "minecraft:cobblestone"},
        {pos: [8, 4, 10], state: "minecraft:cobblestone"},
        {pos: [0, 5, 10], state: "minecraft:cobblestone"},
        {pos: [1, 5, 8], state: "minecraft:cobblestone"},
        {pos: [1, 5, 9], state: "minecraft:cobblestone"},
        {pos: [1, 5, 10], state: "minecraft:cobblestone"},
        {pos: [1, 5, 11], state: "minecraft:cobblestone"},
        {pos: [2, 5, 8], state: "minecraft:cobblestone"},
        {pos: [2, 5, 9], state: "minecraft:cobblestone"},
        {pos: [2, 5, 10], state: "minecraft:cobblestone"},
        {pos: [2, 5, 11], state: "minecraft:cobblestone"},
        {pos: [2, 5, 12], state: "minecraft:cobblestone"},
        {pos: [2, 5, 13], state: "minecraft:cobblestone"},
        {pos: [3, 5, 2], state: "minecraft:gravel"},
        {pos: [3, 5, 3], state: "minecraft:cobblestone"},
        {pos: [3, 5, 4], state: "minecraft:cobblestone"},
        {pos: [3, 5, 7], state: "minecraft:cobblestone"},
        {pos: [3, 5, 8], state: "minecraft:cobblestone"},
        {pos: [3, 5, 9], state: "minecraft:air"},
        {pos: [3, 5, 10], state: "minecraft:air"},
        {pos: [3, 5, 11], state: "minecraft:air"},
        {pos: [3, 5, 12], state: "minecraft:cobblestone"},
        {pos: [3, 5, 13], state: "minecraft:cobblestone"},
        {pos: [3, 5, 14], state: "minecraft:cobblestone"},
        {pos: [3, 5, 15], state: "minecraft:cobblestone"},
        {pos: [4, 5, 1], state: "minecraft:cobblestone"},
        {pos: [4, 5, 2], state: "minecraft:gravel"},
        {pos: [4, 5, 3], state: "minecraft:gravel"},
        {pos: [4, 5, 4], state: "minecraft:cobblestone"},
        {pos: [4, 5, 7], state: "minecraft:cobblestone"},
        {pos: [4, 5, 8], state: "minecraft:cobblestone"},
        {pos: [4, 5, 9], state: "minecraft:air"},
        {pos: [4, 5, 10], state: "minecraft:air"},
        {pos: [4, 5, 11], state: "minecraft:air"},
        {pos: [4, 5, 12], state: "minecraft:cobblestone"},
        {pos: [4, 5, 13], state: "minecraft:cobblestone"},
        {pos: [4, 5, 14], state: "minecraft:cobblestone"},
        {pos: [4, 5, 15], state: "minecraft:cobblestone"},
        {pos: [4, 5, 16], state: "minecraft:cobblestone"},
        {pos: [5, 5, 1], state: "minecraft:cobblestone"},
        {pos: [5, 5, 2], state: "minecraft:cobblestone"},
        {pos: [5, 5, 3], state: "minecraft:cobblestone"},
        {pos: [5, 5, 7], state: "minecraft:cobblestone"},
        {pos: [5, 5, 8], state: "minecraft:cobblestone"},
        {pos: [5, 5, 9], state: "minecraft:air"},
        {pos: [5, 5, 10], state: "minecraft:air"},
        {pos: [5, 5, 11], state: "minecraft:air"},
        {pos: [5, 5, 12], state: "minecraft:cobblestone"},
        {pos: [5, 5, 13], state: "minecraft:cobblestone"},
        {pos: [5, 5, 14], state: "minecraft:cobblestone"},
        {pos: [5, 5, 15], state: "minecraft:cobblestone"},
        {pos: [6, 5, 1], state: "minecraft:cobblestone"},
        {pos: [6, 5, 2], state: "minecraft:cobblestone"},
        {pos: [6, 5, 8], state: "minecraft:cobblestone"},
        {pos: [6, 5, 9], state: "minecraft:gravel"},
        {pos: [6, 5, 10], state: "minecraft:cobblestone"},
        {pos: [6, 5, 11], state: "minecraft:cobblestone"},
        {pos: [6, 5, 12], state: "minecraft:cobblestone"},
        {pos: [6, 5, 13], state: "minecraft:cobblestone"},
        {pos: [6, 5, 14], state: "minecraft:cobblestone"},
        {pos: [7, 5, 9], state: "minecraft:cobblestone"},
        {pos: [7, 5, 10], state: "minecraft:cobblestone"},
        {pos: [1, 6, 9], state: "minecraft:cobblestone"},
        {pos: [1, 6, 10], state: "minecraft:cobblestone"},
        {pos: [2, 6, 8], state: "minecraft:cobblestone"},
        {pos: [2, 6, 9], state: "minecraft:cobblestone"},
        {pos: [2, 6, 10], state: "minecraft:cobblestone"},
        {pos: [2, 6, 11], state: "minecraft:cobblestone"},
        {pos: [2, 6, 12], state: "minecraft:cobblestone"},
        {pos: [2, 6, 13], state: "minecraft:cobblestone"},
        {pos: [2, 6, 14], state: "minecraft:cobblestone"},
        {pos: [2, 6, 15], state: "minecraft:cobblestone"},
        {pos: [3, 6, 7], state: "minecraft:cobblestone"},
        {pos: [3, 6, 8], state: "minecraft:cobblestone"},
        {pos: [3, 6, 9], state: "minecraft:air"},
        {pos: [3, 6, 10], state: "minecraft:air"},
        {pos: [3, 6, 11], state: "minecraft:air"},
        {pos: [3, 6, 12], state: "minecraft:cobblestone"},
        {pos: [3, 6, 13], state: "minecraft:gravel"},
        {pos: [3, 6, 14], state: "minecraft:gravel"},
        {pos: [3, 6, 15], state: "minecraft:cobblestone"},
        {pos: [3, 6, 16], state: "minecraft:cobblestone"},
        {pos: [4, 6, 7], state: "minecraft:cobblestone"},
        {pos: [4, 6, 8], state: "minecraft:cobblestone"},
        {pos: [4, 6, 9], state: "minecraft:air"},
        {pos: [4, 6, 10], state: "minecraft:air"},
        {pos: [4, 6, 11], state: "minecraft:air"},
        {pos: [4, 6, 12], state: "minecraft:cobblestone"},
        {pos: [4, 6, 13], state: "minecraft:cobblestone"},
        {pos: [4, 6, 14], state: "minecraft:gravel"},
        {pos: [4, 6, 15], state: "minecraft:gravel"},
        {pos: [4, 6, 16], state: "minecraft:cobblestone"},
        {pos: [5, 6, 8], state: "minecraft:gravel"},
        {pos: [5, 6, 9], state: "minecraft:air"},
        {pos: [5, 6, 10], state: "minecraft:air"},
        {pos: [5, 6, 11], state: "minecraft:air"},
        {pos: [5, 6, 12], state: "minecraft:gravel"},
        {pos: [5, 6, 13], state: "minecraft:cobblestone"},
        {pos: [5, 6, 14], state: "minecraft:cobblestone"},
        {pos: [5, 6, 15], state: "minecraft:gravel"},
        {pos: [5, 6, 16], state: "minecraft:cobblestone"},
        {pos: [6, 6, 8], state: "minecraft:cobblestone"},
        {pos: [6, 6, 9], state: "minecraft:gravel"},
        {pos: [6, 6, 10], state: "minecraft:gravel"},
        {pos: [6, 6, 11], state: "minecraft:cobblestone"},
        {pos: [6, 6, 12], state: "minecraft:cobblestone"},
        {pos: [6, 6, 13], state: "minecraft:cobblestone"},
        {pos: [6, 6, 14], state: "minecraft:cobblestone"},
        {pos: [6, 6, 15], state: "minecraft:cobblestone"},
        {pos: [2, 7, 8], state: "minecraft:cobblestone"},
        {pos: [2, 7, 9], state: "minecraft:cobblestone"},
        {pos: [2, 7, 10], state: "minecraft:cobblestone"},
        {pos: [2, 7, 11], state: "minecraft:cobblestone"},
        {pos: [2, 7, 12], state: "minecraft:cobblestone"},
        {pos: [2, 7, 13], state: "minecraft:cobblestone"},
        {pos: [2, 7, 14], state: "minecraft:cobblestone"},
        {pos: [2, 7, 15], state: "minecraft:cobblestone"},
        {pos: [2, 7, 16], state: "minecraft:cobblestone"},
        {pos: [3, 7, 8], state: "minecraft:cobblestone"},
        {pos: [3, 7, 9], state: "minecraft:air"},
        {pos: [3, 7, 10], state: "minecraft:air"},
        {pos: [3, 7, 11], state: "minecraft:air"},
        {pos: [3, 7, 12], state: "minecraft:cobblestone"},
        {pos: [3, 7, 13], state: "minecraft:gravel"},
        {pos: [3, 7, 14], state: "minecraft:gravel"},
        {pos: [3, 7, 15], state: "minecraft:decorated_pot{cracked:false,facing:north,waterlogged:false}", nbt: {id: "minecraft:decorated_pot"}},
        {pos: [3, 7, 16], state: "minecraft:cobblestone"},
        {pos: [4, 7, 8], state: "minecraft:cobblestone"},
        {pos: [4, 7, 9], state: "minecraft:air"},
        {pos: [4, 7, 10], state: "minecraft:air"},
        {pos: [4, 7, 11], state: "minecraft:air"},
        {pos: [4, 7, 12], state: "minecraft:gravel"},
        {pos: [4, 7, 13], state: "minecraft:gravel"},
        {pos: [4, 7, 14], state: "minecraft:gravel"},
        {pos: [4, 7, 15], state: "minecraft:gravel"},
        {pos: [4, 7, 16], state: "minecraft:cobblestone"},
        {pos: [5, 7, 8], state: "minecraft:gravel"},
        {pos: [5, 7, 9], state: "minecraft:air"},
        {pos: [5, 7, 10], state: "minecraft:air"},
        {pos: [5, 7, 11], state: "minecraft:air"},
        {pos: [5, 7, 12], state: "minecraft:gravel"},
        {pos: [5, 7, 13], state: "minecraft:decorated_pot{cracked:false,facing:north,waterlogged:false}", nbt: {id: "minecraft:decorated_pot"}},
        {pos: [5, 7, 14], state: "minecraft:gravel"},
        {pos: [5, 7, 15], state: "minecraft:gravel"},
        {pos: [5, 7, 16], state: "minecraft:cobblestone"},
        {pos: [6, 7, 8], state: "minecraft:cobblestone"},
        {pos: [6, 7, 9], state: "minecraft:gravel"},
        {pos: [6, 7, 10], state: "minecraft:gravel"},
        {pos: [6, 7, 11], state: "minecraft:cobblestone"},
        {pos: [6, 7, 12], state: "minecraft:cobblestone"},
        {pos: [6, 7, 13], state: "minecraft:cobblestone"},
        {pos: [6, 7, 14], state: "minecraft:cobblestone"},
        {pos: [6, 7, 15], state: "minecraft:cobblestone"},
        {pos: [2, 8, 8], state: "minecraft:cobblestone"},
        {pos: [2, 8, 9], state: "minecraft:cobblestone"},
        {pos: [2, 8, 10], state: "minecraft:cobblestone"},
        {pos: [2, 8, 11], state: "minecraft:cobblestone"},
        {pos: [2, 8, 12], state: "minecraft:cobblestone"},
        {pos: [2, 8, 13], state: "minecraft:cobblestone"},
        {pos: [2, 8, 14], state: "minecraft:cobblestone"},
        {pos: [2, 8, 15], state: "minecraft:cobblestone"},
        {pos: [3, 8, 8], state: "minecraft:cobblestone"},
        {pos: [3, 8, 9], state: "minecraft:air"},
        {pos: [3, 8, 10], state: "minecraft:air"},
        {pos: [3, 8, 11], state: "minecraft:air"},
        {pos: [3, 8, 12], state: "minecraft:cobblestone"},
        {pos: [3, 8, 13], state: "minecraft:gravel"},
        {pos: [3, 8, 14], state: "minecraft:gravel"},
        {pos: [3, 8, 15], state: "minecraft:gravel"},
        {pos: [3, 8, 16], state: "minecraft:cobblestone"},
        {pos: [4, 8, 8], state: "minecraft:cobblestone"},
        {pos: [4, 8, 9], state: "minecraft:air"},
        {pos: [4, 8, 10], state: "minecraft:air"},
        {pos: [4, 8, 11], state: "minecraft:air"},
        {pos: [4, 8, 12], state: "minecraft:gravel"},
        {pos: [4, 8, 13], state: "minecraft:cobblestone"},
        {pos: [4, 8, 14], state: "minecraft:gravel"},
        {pos: [4, 8, 15], state: "minecraft:gravel"},
        {pos: [4, 8, 16], state: "minecraft:cobblestone"},
        {pos: [5, 8, 8], state: "minecraft:cobblestone"},
        {pos: [5, 8, 9], state: "minecraft:air"},
        {pos: [5, 8, 10], state: "minecraft:air"},
        {pos: [5, 8, 11], state: "minecraft:air"},
        {pos: [5, 8, 12], state: "minecraft:cobblestone"},
        {pos: [5, 8, 13], state: "minecraft:gravel"},
        {pos: [5, 8, 14], state: "minecraft:gravel"},
        {pos: [5, 8, 15], state: "minecraft:gravel"},
        {pos: [5, 8, 16], state: "minecraft:cobblestone"},
        {pos: [6, 8, 8], state: "minecraft:cobblestone"},
        {pos: [6, 8, 9], state: "minecraft:gravel"},
        {pos: [6, 8, 10], state: "minecraft:cobblestone"},
        {pos: [6, 8, 11], state: "minecraft:cobblestone"},
        {pos: [6, 8, 12], state: "minecraft:cobblestone"},
        {pos: [6, 8, 13], state: "minecraft:cobblestone"},
        {pos: [6, 8, 14], state: "minecraft:cobblestone"},
        {pos: [6, 8, 15], state: "minecraft:cobblestone"},
        {pos: [2, 9, 8], state: "minecraft:cobblestone"},
        {pos: [2, 9, 9], state: "minecraft:cobblestone"},
        {pos: [2, 9, 10], state: "minecraft:cobblestone"},
        {pos: [2, 9, 11], state: "minecraft:cobblestone"},
        {pos: [2, 9, 12], state: "minecraft:cobblestone"},
        {pos: [3, 9, 8], state: "minecraft:gravel"},
        {pos: [3, 9, 9], state: "minecraft:air"},
        {pos: [3, 9, 10], state: "minecraft:air"},
        {pos: [3, 9, 11], state: "minecraft:air"},
        {pos: [3, 9, 12], state: "minecraft:cobblestone"},
        {pos: [3, 9, 13], state: "minecraft:cobblestone"},
        {pos: [3, 9, 14], state: "minecraft:cobblestone"},
        {pos: [3, 9, 15], state: "minecraft:cobblestone"},
        {pos: [4, 9, 8], state: "minecraft:cobblestone"},
        {pos: [4, 9, 9], state: "minecraft:air"},
        {pos: [4, 9, 10], state: "minecraft:air"},
        {pos: [4, 9, 11], state: "minecraft:air"},
        {pos: [4, 9, 12], state: "minecraft:cobblestone"},
        {pos: [4, 9, 13], state: "minecraft:cobblestone"},
        {pos: [4, 9, 14], state: "minecraft:cobblestone"},
        {pos: [4, 9, 15], state: "minecraft:cobblestone"},
        {pos: [5, 9, 8], state: "minecraft:cobblestone"},
        {pos: [5, 9, 9], state: "minecraft:air"},
        {pos: [5, 9, 10], state: "minecraft:air"},
        {pos: [5, 9, 11], state: "minecraft:air"},
        {pos: [5, 9, 12], state: "minecraft:cobblestone"},
        {pos: [5, 9, 13], state: "minecraft:cobblestone"},
        {pos: [5, 9, 14], state: "minecraft:cobblestone"},
        {pos: [5, 9, 15], state: "minecraft:cobblestone"},
        {pos: [6, 9, 8], state: "minecraft:cobblestone"},
        {pos: [6, 9, 9], state: "minecraft:cobblestone"},
        {pos: [6, 9, 10], state: "minecraft:cobblestone"},
        {pos: [6, 9, 11], state: "minecraft:cobblestone"},
        {pos: [6, 9, 12], state: "minecraft:cobblestone"},
        {pos: [6, 9, 13], state: "minecraft:cobblestone"},
        {pos: [6, 9, 14], state: "minecraft:cobblestone"},
        {pos: [2, 10, 8], state: "minecraft:gravel"},
        {pos: [2, 10, 9], state: "minecraft:gravel"},
        {pos: [2, 10, 10], state: "minecraft:cobblestone"},
        {pos: [2, 10, 11], state: "minecraft:cobblestone"},
        {pos: [3, 10, 8], state: "minecraft:gravel"},
        {pos: [3, 10, 9], state: "minecraft:air"},
        {pos: [3, 10, 10], state: "minecraft:air"},
        {pos: [3, 10, 11], state: "minecraft:air"},
        {pos: [3, 10, 12], state: "minecraft:cobblestone"},
        {pos: [4, 10, 8], state: "minecraft:gravel"},
        {pos: [4, 10, 9], state: "minecraft:air"},
        {pos: [4, 10, 10], state: "minecraft:air"},
        {pos: [4, 10, 11], state: "minecraft:air"},
        {pos: [4, 10, 12], state: "minecraft:cobblestone"},
        {pos: [5, 10, 8], state: "minecraft:gravel"},
        {pos: [5, 10, 9], state: "minecraft:air"},
        {pos: [5, 10, 10], state: "minecraft:air"},
        {pos: [5, 10, 11], state: "minecraft:air"},
        {pos: [5, 10, 12], state: "minecraft:cobblestone"},
        {pos: [5, 10, 13], state: "minecraft:cobblestone"},
        {pos: [6, 10, 8], state: "minecraft:cobblestone"},
        {pos: [6, 10, 9], state: "minecraft:cobblestone"},
        {pos: [6, 10, 10], state: "minecraft:cobblestone"},
        {pos: [6, 10, 11], state: "minecraft:cobblestone"},
        {pos: [6, 10, 12], state: "minecraft:cobblestone"},
        {pos: [2, 11, 8], state: "minecraft:gravel"},
        {pos: [2, 11, 9], state: "minecraft:gravel"},
        {pos: [2, 11, 10], state: "minecraft:gravel"},
        {pos: [2, 11, 11], state: "minecraft:cobblestone"},
        {pos: [3, 11, 8], state: "minecraft:gravel"},
        {pos: [3, 11, 9], state: "minecraft:air"},
        {pos: [3, 11, 10], state: "minecraft:air"},
        {pos: [3, 11, 11], state: "minecraft:air"},
        {pos: [3, 11, 12], state: "minecraft:cobblestone"},
        {pos: [4, 11, 8], state: "minecraft:gravel"},
        {pos: [4, 11, 9], state: "minecraft:air"},
        {pos: [4, 11, 10], state: "minecraft:air"},
        {pos: [4, 11, 11], state: "minecraft:air"},
        {pos: [4, 11, 12], state: "minecraft:gravel"},
        {pos: [5, 11, 8], state: "minecraft:gravel"},
        {pos: [5, 11, 9], state: "minecraft:air"},
        {pos: [5, 11, 10], state: "minecraft:air"},
        {pos: [5, 11, 11], state: "minecraft:air"},
        {pos: [5, 11, 12], state: "minecraft:gravel"},
        {pos: [6, 11, 8], state: "minecraft:cobblestone"},
        {pos: [6, 11, 9], state: "minecraft:cobblestone"},
        {pos: [6, 11, 10], state: "minecraft:cobblestone"},
        {pos: [6, 11, 11], state: "minecraft:gravel"},
        {pos: [6, 11, 12], state: "minecraft:cobblestone"},
        {pos: [2, 12, 8], state: "minecraft:gravel"},
        {pos: [2, 12, 9], state: "minecraft:gravel"},
        {pos: [2, 12, 10], state: "minecraft:cobblestone"},
        {pos: [2, 12, 11], state: "minecraft:cobblestone"},
        {pos: [3, 12, 8], state: "minecraft:gravel"},
        {pos: [3, 12, 9], state: "minecraft:air"},
        {pos: [3, 12, 10], state: "minecraft:air"},
        {pos: [3, 12, 11], state: "minecraft:air"},
        {pos: [3, 12, 12], state: "minecraft:cobblestone"},
        {pos: [4, 12, 8], state: "minecraft:gravel"},
        {pos: [4, 12, 9], state: "minecraft:air"},
        {pos: [4, 12, 10], state: "minecraft:air"},
        {pos: [4, 12, 11], state: "minecraft:air"},
        {pos: [4, 12, 12], state: "minecraft:cobblestone"},
        {pos: [5, 12, 8], state: "minecraft:cobblestone"},
        {pos: [5, 12, 9], state: "minecraft:air"},
        {pos: [5, 12, 10], state: "minecraft:air"},
        {pos: [5, 12, 11], state: "minecraft:air"},
        {pos: [5, 12, 12], state: "minecraft:gravel"},
        {pos: [6, 12, 8], state: "minecraft:gravel"},
        {pos: [6, 12, 9], state: "minecraft:cobblestone"},
        {pos: [6, 12, 10], state: "minecraft:cobblestone"},
        {pos: [6, 12, 11], state: "minecraft:cobblestone"},
        {pos: [6, 12, 12], state: "minecraft:gravel"},
        {pos: [2, 13, 9], state: "minecraft:cobblestone"},
        {pos: [2, 13, 10], state: "minecraft:cobblestone"},
        {pos: [2, 13, 11], state: "minecraft:cobblestone"},
        {pos: [3, 13, 8], state: "minecraft:cobblestone"},
        {pos: [3, 13, 9], state: "minecraft:air"},
        {pos: [3, 13, 10], state: "minecraft:air"},
        {pos: [3, 13, 11], state: "minecraft:air"},
        {pos: [3, 13, 12], state: "minecraft:cobblestone"},
        {pos: [4, 13, 8], state: "minecraft:cobblestone"},
        {pos: [4, 13, 9], state: "minecraft:air"},
        {pos: [4, 13, 10], state: "minecraft:air"},
        {pos: [4, 13, 11], state: "minecraft:air"},
        {pos: [4, 13, 12], state: "minecraft:cobblestone"},
        {pos: [5, 13, 8], state: "minecraft:cobblestone"},
        {pos: [5, 13, 9], state: "minecraft:cobblestone"},
        {pos: [5, 13, 10], state: "minecraft:air"},
        {pos: [5, 13, 11], state: "minecraft:air"},
        {pos: [5, 13, 12], state: "minecraft:cobblestone"},
        {pos: [6, 13, 8], state: "minecraft:gravel"},
        {pos: [6, 13, 9], state: "minecraft:cobblestone"},
        {pos: [6, 13, 10], state: "minecraft:cobblestone"},
        {pos: [6, 13, 11], state: "minecraft:cobblestone"},
        {pos: [6, 13, 12], state: "minecraft:gravel"},
        {pos: [2, 14, 9], state: "minecraft:cobblestone"},
        {pos: [2, 14, 10], state: "minecraft:cobblestone"},
        {pos: [2, 14, 11], state: "minecraft:cobblestone"},
        {pos: [3, 14, 8], state: "minecraft:cobblestone"},
        {pos: [3, 14, 9], state: "minecraft:air"},
        {pos: [3, 14, 10], state: "minecraft:air"},
        {pos: [3, 14, 11], state: "minecraft:cobblestone"},
        {pos: [3, 14, 12], state: "minecraft:cobblestone"},
        {pos: [4, 14, 8], state: "minecraft:cobblestone"},
        {pos: [4, 14, 9], state: "minecraft:cobblestone"},
        {pos: [4, 14, 10], state: "minecraft:air"},
        {pos: [4, 14, 11], state: "minecraft:air"},
        {pos: [4, 14, 12], state: "minecraft:cobblestone"},
        {pos: [5, 14, 8], state: "minecraft:cobblestone"},
        {pos: [5, 14, 9], state: "minecraft:gravel"},
        {pos: [5, 14, 10], state: "minecraft:cobblestone"},
        {pos: [5, 14, 11], state: "minecraft:air"},
        {pos: [5, 14, 12], state: "minecraft:cobblestone"},
        {pos: [6, 14, 8], state: "minecraft:gravel"},
        {pos: [6, 14, 9], state: "minecraft:cobblestone"},
        {pos: [6, 14, 10], state: "minecraft:cobblestone"},
        {pos: [6, 14, 11], state: "minecraft:cobblestone"},
        {pos: [2, 15, 10], state: "minecraft:cobblestone"},
        {pos: [2, 15, 11], state: "minecraft:cobblestone"},
        {pos: [3, 15, 9], state: "minecraft:air"},
        {pos: [3, 15, 10], state: "minecraft:air"},
        {pos: [3, 15, 12], state: "minecraft:cobblestone"},
        {pos: [4, 15, 8], state: "minecraft:cobblestone"},
        {pos: [4, 15, 10], state: "minecraft:air"},
        {pos: [4, 15, 11], state: "minecraft:air"},
        {pos: [4, 15, 12], state: "minecraft:cobblestone"},
        {pos: [5, 15, 8], state: "minecraft:cobblestone"},
        {pos: [5, 15, 9], state: "minecraft:gravel"},
        {pos: [5, 15, 11], state: "minecraft:air"},
        {pos: [6, 15, 9], state: "minecraft:cobblestone"},
        {pos: [6, 15, 10], state: "minecraft:cobblestone"},
        {pos: [2, 16, 10], state: "minecraft:cobblestone"},
        {pos: [3, 16, 9], state: "minecraft:air"},
        {pos: [3, 16, 10], state: "minecraft:air"},
        {pos: [3, 16, 12], state: "minecraft:cobblestone"},
        {pos: [4, 16, 10], state: "minecraft:air"},
        {pos: [4, 16, 11], state: "minecraft:air"},
        {pos: [5, 16, 8], state: "minecraft:cobblestone"},
        {pos: [5, 16, 11], state: "minecraft:air"},
        {pos: [6, 16, 9], state: "minecraft:cobblestone"},
        {pos: [6, 16, 10], state: "minecraft:cobblestone"}
    ],
    entities: [],
    palette: [
        "minecraft:cobblestone",
        "minecraft:gravel",
        "minecraft:tnt{unstable:false}",
        "minecraft:air",
        "minecraft:stone_pressure_plate{powered:false}",
        "minecraft:decorated_pot{cracked:false,facing:north,waterlogged:false}"
    ],
    trailiertales_DataVersion: 2
}
