{
    DataVersion: 3953,
    size: [16, 8, 6],
    data: [
        {pos: [1, 0, 1], state: "minecraft:stone_bricks"},
        {pos: [1, 0, 2], state: "minecraft:stone_bricks"},
        {pos: [1, 0, 3], state: "minecraft:stone_bricks"},
        {pos: [2, 0, 0], state: "minecraft:stone_bricks"},
        {pos: [2, 0, 1], state: "minecraft:polished_andesite"},
        {pos: [2, 0, 2], state: "minecraft:stone_bricks"},
        {pos: [2, 0, 3], state: "minecraft:stone_bricks"},
        {pos: [3, 0, 0], state: "minecraft:stone_bricks"},
        {pos: [3, 0, 1], state: "minecraft:stone_bricks"},
        {pos: [3, 0, 2], state: "minecraft:stone_bricks"},
        {pos: [3, 0, 3], state: "minecraft:stone_bricks"},
        {pos: [3, 0, 4], state: "minecraft:stone_bricks"},
        {pos: [4, 0, 0], state: "minecraft:stone_bricks"},
        {pos: [4, 0, 1], state: "minecraft:stone_bricks"},
        {pos: [4, 0, 2], state: "minecraft:stone_bricks"},
        {pos: [4, 0, 3], state: "minecraft:stone_bricks"},
        {pos: [4, 0, 4], state: "minecraft:stone_bricks"},
        {pos: [5, 0, 1], state: "minecraft:stone_bricks"},
        {pos: [5, 0, 2], state: "minecraft:stone_bricks"},
        {pos: [5, 0, 3], state: "minecraft:stone_bricks"},
        {pos: [5, 0, 4], state: "minecraft:stone_bricks"},
        {pos: [6, 0, 2], state: "minecraft:stone_bricks"},
        {pos: [6, 0, 3], state: "minecraft:stone_bricks"},
        {pos: [9, 0, 2], state: "minecraft:stone_bricks"},
        {pos: [9, 0, 3], state: "minecraft:stone_bricks"},
        {pos: [10, 0, 1], state: "minecraft:stone_bricks"},
        {pos: [10, 0, 2], state: "minecraft:stone_bricks"},
        {pos: [10, 0, 3], state: "minecraft:stone_bricks"},
        {pos: [11, 0, 0], state: "minecraft:stone_bricks"},
        {pos: [11, 0, 1], state: "minecraft:stone_bricks"},
        {pos: [11, 0, 2], state: "minecraft:stone_bricks"},
        {pos: [11, 0, 3], state: "minecraft:stone_bricks"},
        {pos: [11, 0, 4], state: "minecraft:stone_bricks"},
        {pos: [12, 0, 0], state: "minecraft:stone_bricks"},
        {pos: [12, 0, 1], state: "minecraft:stone_bricks"},
        {pos: [12, 0, 2], state: "minecraft:stone_bricks"},
        {pos: [12, 0, 3], state: "minecraft:stone_bricks"},
        {pos: [12, 0, 4], state: "minecraft:stone_bricks"},
        {pos: [13, 0, 1], state: "minecraft:stone_bricks"},
        {pos: [13, 0, 2], state: "minecraft:stone_bricks"},
        {pos: [13, 0, 3], state: "minecraft:stone_bricks"},
        {pos: [13, 0, 4], state: "minecraft:stone_bricks"},
        {pos: [14, 0, 2], state: "minecraft:stone_bricks"},
        {pos: [14, 0, 3], state: "minecraft:stone_bricks"},
        {pos: [14, 0, 4], state: "minecraft:stone_bricks"},
        {pos: [14, 0, 5], state: "minecraft:stone_bricks"},
        {pos: [15, 0, 4], state: "minecraft:stone_bricks"},
        {pos: [15, 0, 5], state: "minecraft:stone_bricks"},
        {pos: [1, 1, 1], state: "minecraft:gravel"},
        {pos: [1, 1, 2], state: "minecraft:gravel"},
        {pos: [1, 1, 3], state: "minecraft:gravel"},
        {pos: [2, 1, 0], state: "minecraft:gravel"},
        {pos: [2, 1, 1], state: "minecraft:stone_bricks"},
        {pos: [2, 1, 2], state: "minecraft:gravel"},
        {pos: [2, 1, 3], state: "minecraft:gravel"},
        {pos: [3, 1, 0], state: "minecraft:stone_bricks"},
        {pos: [3, 1, 1], state: "minecraft:stone_bricks"},
        {pos: [3, 1, 2], state: "minecraft:gravel"},
        {pos: [3, 1, 3], state: "minecraft:stone_bricks"},
        {pos: [3, 1, 4], state: "minecraft:gravel"},
        {pos: [4, 1, 0], state: "minecraft:gravel"},
        {pos: [4, 1, 1], state: "minecraft:stone_bricks"},
        {pos: [4, 1, 2], state: "minecraft:stone_bricks"},
        {pos: [4, 1, 3], state: "minecraft:stone_bricks"},
        {pos: [4, 1, 4], state: "minecraft:stone_bricks"},
        {pos: [5, 1, 1], state: "minecraft:stone_bricks"},
        {pos: [5, 1, 2], state: "minecraft:stone_bricks"},
        {pos: [5, 1, 3], state: "minecraft:stone_bricks"},
        {pos: [5, 1, 4], state: "minecraft:stone_bricks"},
        {pos: [6, 1, 2], state: "minecraft:gravel"},
        {pos: [6, 1, 3], state: "minecraft:gravel"},
        {pos: [9, 1, 2], state: "minecraft:gravel"},
        {pos: [9, 1, 3], state: "minecraft:gravel"},
        {pos: [10, 1, 1], state: "minecraft:gravel"},
        {pos: [10, 1, 2], state: "minecraft:stone_bricks"},
        {pos: [10, 1, 3], state: "minecraft:stone_bricks"},
        {pos: [11, 1, 0], state: "minecraft:gravel"},
        {pos: [11, 1, 1], state: "minecraft:stone_bricks"},
        {pos: [11, 1, 2], state: "minecraft:stone_bricks"},
        {pos: [11, 1, 3], state: "minecraft:stone_bricks"},
        {pos: [11, 1, 4], state: "minecraft:gravel"},
        {pos: [12, 1, 0], state: "minecraft:gravel"},
        {pos: [12, 1, 1], state: "minecraft:stone_bricks"},
        {pos: [12, 1, 2], state: "minecraft:stone_bricks"},
        {pos: [12, 1, 3], state: "minecraft:stone_bricks"},
        {pos: [12, 1, 4], state: "minecraft:gravel"},
        {pos: [13, 1, 1], state: "minecraft:gravel"},
        {pos: [13, 1, 2], state: "minecraft:stone_bricks"},
        {pos: [13, 1, 3], state: "minecraft:stone_bricks"},
        {pos: [13, 1, 4], state: "minecraft:stone_bricks"},
        {pos: [14, 1, 2], state: "minecraft:gravel"},
        {pos: [14, 1, 3], state: "minecraft:stone_bricks"},
        {pos: [14, 1, 4], state: "minecraft:stone_bricks"},
        {pos: [14, 1, 5], state: "minecraft:gravel"},
        {pos: [15, 1, 4], state: "minecraft:gravel"},
        {pos: [15, 1, 5], state: "minecraft:gravel"},
        {pos: [1, 2, 1], state: "minecraft:gravel"},
        {pos: [1, 2, 2], state: "minecraft:gravel"},
        {pos: [1, 2, 3], state: "minecraft:gravel"},
        {pos: [2, 2, 0], state: "minecraft:gravel"},
        {pos: [2, 2, 1], state: "minecraft:gravel"},
        {pos: [2, 2, 2], state: "minecraft:gravel"},
        {pos: [2, 2, 3], state: "minecraft:gravel"},
        {pos: [3, 2, 0], state: "minecraft:gravel"},
        {pos: [3, 2, 1], state: "minecraft:stone_bricks"},
        {pos: [3, 2, 2], state: "minecraft:gravel"},
        {pos: [3, 2, 3], state: "minecraft:stone_bricks"},
        {pos: [3, 2, 4], state: "minecraft:gravel"},
        {pos: [4, 2, 0], state: "minecraft:gravel"},
        {pos: [4, 2, 1], state: "minecraft:polished_andesite"},
        {pos: [4, 2, 2], state: "minecraft:stone_bricks"},
        {pos: [4, 2, 3], state: "minecraft:stone_bricks"},
        {pos: [4, 2, 4], state: "minecraft:gravel"},
        {pos: [5, 2, 1], state: "minecraft:stone_bricks"},
        {pos: [5, 2, 2], state: "minecraft:stone_bricks"},
        {pos: [5, 2, 3], state: "minecraft:stone_bricks"},
        {pos: [5, 2, 4], state: "minecraft:gravel"},
        {pos: [6, 2, 2], state: "minecraft:gravel"},
        {pos: [6, 2, 3], state: "minecraft:gravel"},
        {pos: [9, 2, 2], state: "minecraft:gravel"},
        {pos: [9, 2, 3], state: "minecraft:gravel"},
        {pos: [10, 2, 1], state: "minecraft:gravel"},
        {pos: [10, 2, 2], state: "minecraft:gravel"},
        {pos: [10, 2, 3], state: "minecraft:gravel"},
        {pos: [11, 2, 0], state: "minecraft:gravel"},
        {pos: [11, 2, 1], state: "minecraft:stone_bricks"},
        {pos: [11, 2, 2], state: "minecraft:stone_bricks"},
        {pos: [11, 2, 3], state: "minecraft:stone_bricks"},
        {pos: [11, 2, 4], state: "minecraft:gravel"},
        {pos: [12, 2, 0], state: "minecraft:gravel"},
        {pos: [12, 2, 1], state: "minecraft:stone_bricks"},
        {pos: [12, 2, 2], state: "minecraft:stone_bricks"},
        {pos: [12, 2, 3], state: "minecraft:stone_bricks"},
        {pos: [12, 2, 4], state: "minecraft:gravel"},
        {pos: [13, 2, 1], state: "minecraft:gravel"},
        {pos: [13, 2, 2], state: "minecraft:stone_bricks"},
        {pos: [13, 2, 3], state: "minecraft:stone_bricks"},
        {pos: [13, 2, 4], state: "minecraft:gravel"},
        {pos: [14, 2, 2], state: "minecraft:gravel"},
        {pos: [14, 2, 3], state: "minecraft:gravel"},
        {pos: [14, 2, 4], state: "minecraft:gravel"},
        {pos: [14, 2, 5], state: "minecraft:gravel"},
        {pos: [15, 2, 4], state: "minecraft:gravel"},
        {pos: [15, 2, 5], state: "minecraft:gravel"},
        {pos: [1, 3, 1], state: "minecraft:gravel"},
        {pos: [1, 3, 2], state: "minecraft:gravel"},
        {pos: [2, 3, 0], state: "minecraft:gravel"},
        {pos: [2, 3, 1], state: "minecraft:gravel"},
        {pos: [2, 3, 2], state: "minecraft:gravel"},
        {pos: [2, 3, 3], state: "minecraft:gravel"},
        {pos: [3, 3, 0], state: "minecraft:gravel"},
        {pos: [3, 3, 1], state: "minecraft:stone_bricks"},
        {pos: [3, 3, 2], state: "minecraft:stone_bricks"},
        {pos: [3, 3, 3], state: "minecraft:stone_bricks"},
        {pos: [3, 3, 4], state: "minecraft:gravel"},
        {pos: [4, 3, 0], state: "minecraft:gravel"},
        {pos: [4, 3, 1], state: "minecraft:stone_bricks"},
        {pos: [4, 3, 2], state: "minecraft:stone_bricks"},
        {pos: [4, 3, 3], state: "minecraft:stone_bricks"},
        {pos: [4, 3, 4], state: "minecraft:gravel"},
        {pos: [5, 3, 1], state: "minecraft:gravel"},
        {pos: [5, 3, 2], state: "minecraft:stone_bricks"},
        {pos: [5, 3, 3], state: "minecraft:polished_andesite"},
        {pos: [5, 3, 4], state: "minecraft:gravel"},
        {pos: [6, 3, 2], state: "minecraft:gravel"},
        {pos: [6, 3, 3], state: "minecraft:gravel"},
        {pos: [9, 3, 2], state: "minecraft:gravel"},
        {pos: [9, 3, 3], state: "minecraft:gravel"},
        {pos: [10, 3, 1], state: "minecraft:gravel"},
        {pos: [10, 3, 2], state: "minecraft:gravel"},
        {pos: [10, 3, 3], state: "minecraft:gravel"},
        {pos: [11, 3, 0], state: "minecraft:gravel"},
        {pos: [11, 3, 1], state: "minecraft:stone_bricks"},
        {pos: [11, 3, 2], state: "minecraft:stone_bricks"},
        {pos: [11, 3, 3], state: "minecraft:gravel"},
        {pos: [11, 3, 4], state: "minecraft:gravel"},
        {pos: [12, 3, 0], state: "minecraft:gravel"},
        {pos: [12, 3, 1], state: "minecraft:gravel"},
        {pos: [12, 3, 2], state: "minecraft:stone_bricks"},
        {pos: [12, 3, 3], state: "minecraft:stone_bricks"},
        {pos: [12, 3, 4], state: "minecraft:gravel"},
        {pos: [13, 3, 1], state: "minecraft:gravel"},
        {pos: [13, 3, 2], state: "minecraft:gravel"},
        {pos: [13, 3, 3], state: "minecraft:stone_bricks"},
        {pos: [13, 3, 4], state: "minecraft:gravel"},
        {pos: [14, 3, 2], state: "minecraft:gravel"},
        {pos: [14, 3, 3], state: "minecraft:gravel"},
        {pos: [14, 3, 4], state: "minecraft:gravel"},
        {pos: [14, 3, 5], state: "minecraft:gravel"},
        {pos: [15, 3, 4], state: "minecraft:gravel"},
        {pos: [2, 4, 1], state: "minecraft:gravel"},
        {pos: [2, 4, 2], state: "minecraft:gravel"},
        {pos: [3, 4, 0], state: "minecraft:gravel"},
        {pos: [3, 4, 1], state: "minecraft:stone_bricks"},
        {pos: [3, 4, 2], state: "minecraft:stone_bricks"},
        {pos: [3, 4, 3], state: "minecraft:gravel"},
        {pos: [3, 4, 4], state: "minecraft:gravel"},
        {pos: [4, 4, 0], state: "minecraft:gravel"},
        {pos: [4, 4, 1], state: "minecraft:stone_bricks"},
        {pos: [4, 4, 2], state: "minecraft:stone_bricks"},
        {pos: [4, 4, 3], state: "minecraft:stone_bricks"},
        {pos: [4, 4, 4], state: "minecraft:gravel"},
        {pos: [5, 4, 1], state: "minecraft:stone_bricks"},
        {pos: [5, 4, 2], state: "minecraft:stone_bricks"},
        {pos: [5, 4, 3], state: "minecraft:stone_bricks"},
        {pos: [5, 4, 4], state: "minecraft:gravel"},
        {pos: [6, 4, 1], state: "minecraft:stone_bricks"},
        {pos: [6, 4, 2], state: "minecraft:stone_bricks"},
        {pos: [6, 4, 3], state: "minecraft:gravel"},
        {pos: [7, 4, 1], state: "minecraft:stone_bricks"},
        {pos: [7, 4, 2], state: "minecraft:stone_bricks"},
        {pos: [9, 4, 2], state: "minecraft:gravel"},
        {pos: [9, 4, 3], state: "minecraft:gravel"},
        {pos: [10, 4, 1], state: "minecraft:gravel"},
        {pos: [10, 4, 2], state: "minecraft:stone_bricks"},
        {pos: [10, 4, 3], state: "minecraft:gravel"},
        {pos: [11, 4, 1], state: "minecraft:gravel"},
        {pos: [11, 4, 2], state: "minecraft:stone_bricks"},
        {pos: [11, 4, 3], state: "minecraft:stone_bricks"},
        {pos: [11, 4, 4], state: "minecraft:gravel"},
        {pos: [12, 4, 1], state: "minecraft:gravel"},
        {pos: [12, 4, 2], state: "minecraft:stone_bricks"},
        {pos: [12, 4, 3], state: "minecraft:stone_bricks"},
        {pos: [12, 4, 4], state: "minecraft:gravel"},
        {pos: [13, 4, 2], state: "minecraft:gravel"},
        {pos: [13, 4, 3], state: "minecraft:stone_bricks"},
        {pos: [13, 4, 4], state: "minecraft:gravel"},
        {pos: [14, 4, 3], state: "minecraft:gravel"},
        {pos: [3, 5, 1], state: "minecraft:gravel"},
        {pos: [3, 5, 2], state: "minecraft:gravel"},
        {pos: [3, 5, 3], state: "minecraft:gravel"},
        {pos: [4, 5, 1], state: "minecraft:stone_bricks"},
        {pos: [4, 5, 2], state: "minecraft:polished_andesite"},
        {pos: [4, 5, 3], state: "minecraft:stone_bricks"},
        {pos: [5, 5, 1], state: "minecraft:stone_bricks"},
        {pos: [5, 5, 2], state: "minecraft:stone_bricks"},
        {pos: [5, 5, 3], state: "minecraft:stone_bricks"},
        {pos: [6, 5, 1], state: "minecraft:stone_bricks"},
        {pos: [6, 5, 2], state: "minecraft:stone_bricks"},
        {pos: [6, 5, 3], state: "minecraft:stone_bricks"},
        {pos: [7, 5, 1], state: "minecraft:stone_bricks"},
        {pos: [7, 5, 2], state: "minecraft:stone_bricks"},
        {pos: [8, 5, 1], state: "minecraft:stone_bricks"},
        {pos: [8, 5, 2], state: "minecraft:stone_bricks"},
        {pos: [8, 5, 3], state: "minecraft:stone_bricks"},
        {pos: [9, 5, 1], state: "minecraft:stone_bricks"},
        {pos: [9, 5, 2], state: "minecraft:stone_bricks"},
        {pos: [9, 5, 3], state: "minecraft:stone_bricks"},
        {pos: [10, 5, 1], state: "minecraft:stone_bricks"},
        {pos: [10, 5, 2], state: "minecraft:stone_bricks"},
        {pos: [10, 5, 3], state: "minecraft:stone_bricks"},
        {pos: [11, 5, 1], state: "minecraft:stone_bricks"},
        {pos: [11, 5, 2], state: "minecraft:stone_bricks"},
        {pos: [11, 5, 3], state: "minecraft:gravel"},
        {pos: [11, 5, 4], state: "minecraft:gravel"},
        {pos: [12, 5, 1], state: "minecraft:gravel"},
        {pos: [12, 5, 2], state: "minecraft:stone_bricks"},
        {pos: [12, 5, 3], state: "minecraft:gravel"},
        {pos: [13, 5, 2], state: "minecraft:gravel"},
        {pos: [13, 5, 3], state: "minecraft:gravel"},
        {pos: [4, 6, 1], state: "minecraft:gravel"},
        {pos: [4, 6, 2], state: "minecraft:gravel"},
        {pos: [4, 6, 3], state: "minecraft:gravel"},
        {pos: [5, 6, 1], state: "minecraft:gravel"},
        {pos: [5, 6, 2], state: "minecraft:gravel"},
        {pos: [5, 6, 3], state: "minecraft:gravel"},
        {pos: [6, 6, 1], state: "minecraft:gravel"},
        {pos: [6, 6, 2], state: "minecraft:gravel"},
        {pos: [6, 6, 3], state: "minecraft:gravel"},
        {pos: [7, 6, 1], state: "minecraft:gravel"},
        {pos: [7, 6, 2], state: "minecraft:stone_bricks"},
        {pos: [8, 6, 1], state: "minecraft:gravel"},
        {pos: [8, 6, 2], state: "minecraft:stone_bricks"},
        {pos: [8, 6, 3], state: "minecraft:stone_bricks"},
        {pos: [9, 6, 1], state: "minecraft:stone_bricks"},
        {pos: [9, 6, 2], state: "minecraft:stone_bricks"},
        {pos: [9, 6, 3], state: "minecraft:stone_bricks"},
        {pos: [10, 6, 1], state: "minecraft:stone_bricks"},
        {pos: [10, 6, 2], state: "minecraft:stone_bricks"},
        {pos: [10, 6, 3], state: "minecraft:gravel"},
        {pos: [11, 6, 1], state: "minecraft:stone_bricks"},
        {pos: [11, 6, 2], state: "minecraft:stone_bricks"},
        {pos: [11, 6, 3], state: "minecraft:gravel"},
        {pos: [12, 6, 1], state: "minecraft:gravel"},
        {pos: [12, 6, 2], state: "minecraft:gravel"},
        {pos: [12, 6, 3], state: "minecraft:gravel"},
        {pos: [11, 7, 1], state: "minecraft:gravel"}
    ],
    entities: [],
    palette: [
        "minecraft:stone_bricks",
        "minecraft:polished_andesite",
        "minecraft:gravel"
    ],
    trailiertales_DataVersion: 2
}
