{
    DataVersion: 3953,
    size: [9, 4, 7],
    data: [
        {pos: [0, 0, 1], state: "minecraft:stone_bricks"},
        {pos: [0, 0, 2], state: "minecraft:stone_bricks"},
        {pos: [1, 0, 0], state: "minecraft:stone_bricks"},
        {pos: [1, 0, 1], state: "minecraft:stone_bricks"},
        {pos: [1, 0, 2], state: "minecraft:stone_bricks"},
        {pos: [1, 0, 3], state: "minecraft:stone_bricks"},
        {pos: [2, 0, 0], state: "minecraft:stone_bricks"},
        {pos: [2, 0, 1], state: "minecraft:stone_bricks"},
        {pos: [2, 0, 2], state: "minecraft:stone_bricks"},
        {pos: [2, 0, 3], state: "minecraft:stone_bricks"},
        {pos: [2, 0, 4], state: "minecraft:stone_bricks"},
        {pos: [3, 0, 0], state: "minecraft:stone_bricks"},
        {pos: [3, 0, 1], state: "minecraft:stone_bricks"},
        {pos: [3, 0, 2], state: "minecraft:stone_bricks"},
        {pos: [3, 0, 3], state: "minecraft:stone_bricks"},
        {pos: [4, 0, 2], state: "minecraft:stone_bricks"},
        {pos: [4, 0, 3], state: "minecraft:polished_andesite"},
        {pos: [6, 0, 3], state: "minecraft:stone_bricks"},
        {pos: [6, 0, 4], state: "minecraft:stone_bricks"},
        {pos: [6, 0, 5], state: "minecraft:stone_bricks"},
        {pos: [6, 0, 6], state: "minecraft:stone_bricks"},
        {pos: [7, 0, 3], state: "minecraft:stone_bricks"},
        {pos: [7, 0, 4], state: "minecraft:gravel"},
        {pos: [7, 0, 5], state: "minecraft:polished_andesite"},
        {pos: [7, 0, 6], state: "minecraft:stone_bricks"},
        {pos: [8, 0, 3], state: "minecraft:stone_bricks"},
        {pos: [8, 0, 4], state: "minecraft:stone_bricks"},
        {pos: [8, 0, 5], state: "minecraft:stone_bricks"},
        {pos: [0, 1, 1], state: "minecraft:stone_bricks"},
        {pos: [0, 1, 2], state: "minecraft:gravel"},
        {pos: [1, 1, 0], state: "minecraft:gravel"},
        {pos: [1, 1, 1], state: "minecraft:stone_bricks"},
        {pos: [1, 1, 2], state: "minecraft:stone_bricks"},
        {pos: [1, 1, 3], state: "minecraft:stone_bricks"},
        {pos: [2, 1, 0], state: "minecraft:gravel"},
        {pos: [2, 1, 1], state: "minecraft:stone_bricks"},
        {pos: [2, 1, 2], state: "minecraft:gravel"},
        {pos: [2, 1, 3], state: "minecraft:stone_bricks"},
        {pos: [2, 1, 4], state: "minecraft:gravel"},
        {pos: [3, 1, 0], state: "minecraft:gravel"},
        {pos: [3, 1, 1], state: "minecraft:gravel"},
        {pos: [3, 1, 2], state: "minecraft:gravel"},
        {pos: [3, 1, 3], state: "minecraft:gravel"},
        {pos: [4, 1, 2], state: "minecraft:gravel"},
        {pos: [4, 1, 3], state: "minecraft:gravel"},
        {pos: [6, 1, 3], state: "minecraft:gravel"},
        {pos: [6, 1, 4], state: "minecraft:gravel"},
        {pos: [6, 1, 5], state: "minecraft:gravel"},
        {pos: [6, 1, 6], state: "minecraft:gravel"},
        {pos: [7, 1, 3], state: "minecraft:gravel"},
        {pos: [7, 1, 4], state: "minecraft:gravel"},
        {pos: [7, 1, 5], state: "minecraft:gravel"},
        {pos: [7, 1, 6], state: "minecraft:gravel"},
        {pos: [8, 1, 3], state: "minecraft:gravel"},
        {pos: [8, 1, 4], state: "minecraft:gravel"},
        {pos: [8, 1, 5], state: "minecraft:gravel"},
        {pos: [0, 2, 1], state: "minecraft:gravel"},
        {pos: [0, 2, 2], state: "minecraft:gravel"},
        {pos: [1, 2, 0], state: "minecraft:gravel"},
        {pos: [1, 2, 1], state: "minecraft:stone_bricks"},
        {pos: [1, 2, 2], state: "minecraft:gravel"},
        {pos: [1, 2, 3], state: "minecraft:stone_bricks"},
        {pos: [2, 2, 0], state: "minecraft:gravel"},
        {pos: [2, 2, 1], state: "minecraft:stone_bricks"},
        {pos: [2, 2, 2], state: "minecraft:gravel"},
        {pos: [2, 2, 3], state: "minecraft:gravel"},
        {pos: [2, 2, 4], state: "minecraft:gravel"},
        {pos: [3, 2, 0], state: "minecraft:gravel"},
        {pos: [3, 2, 1], state: "minecraft:gravel"},
        {pos: [3, 2, 2], state: "minecraft:gravel"},
        {pos: [3, 2, 3], state: "minecraft:gravel"},
        {pos: [6, 2, 3], state: "minecraft:gravel"},
        {pos: [6, 2, 4], state: "minecraft:gravel"},
        {pos: [6, 2, 5], state: "minecraft:gravel"},
        {pos: [7, 2, 4], state: "minecraft:gravel"},
        {pos: [7, 2, 5], state: "minecraft:gravel"},
        {pos: [1, 3, 1], state: "minecraft:gravel"},
        {pos: [1, 3, 2], state: "minecraft:stone_bricks"},
        {pos: [1, 3, 3], state: "minecraft:stone_bricks"},
        {pos: [2, 3, 1], state: "minecraft:stone_bricks"},
        {pos: [2, 3, 2], state: "minecraft:gravel"},
        {pos: [3, 3, 1], state: "minecraft:stone_bricks"},
        {pos: [3, 3, 2], state: "minecraft:stone_bricks"}
    ],
    entities: [],
    palette: [
        "minecraft:stone_bricks",
        "minecraft:polished_andesite",
        "minecraft:gravel"
    ],
    trailiertales_DataVersion: 2
}
