{
    DataVersion: 3953,
    size: [12, 8, 9],
    data: [
        {pos: [0, 0, 1], state: "minecraft:gravel"},
        {pos: [0, 0, 2], state: "minecraft:gravel"},
        {pos: [0, 0, 3], state: "minecraft:gravel"},
        {pos: [0, 0, 5], state: "minecraft:gravel"},
        {pos: [0, 0, 6], state: "minecraft:gravel"},
        {pos: [0, 0, 7], state: "minecraft:gravel"},
        {pos: [0, 0, 8], state: "minecraft:gravel"},
        {pos: [1, 0, 0], state: "minecraft:gravel"},
        {pos: [1, 0, 1], state: "minecraft:gravel"},
        {pos: [1, 0, 2], state: "minecraft:gravel"},
        {pos: [1, 0, 3], state: "minecraft:gravel"},
        {pos: [1, 0, 4], state: "minecraft:gravel"},
        {pos: [1, 0, 5], state: "minecraft:gravel"},
        {pos: [1, 0, 6], state: "minecraft:gravel"},
        {pos: [1, 0, 7], state: "minecraft:gravel"},
        {pos: [1, 0, 8], state: "minecraft:gravel"},
        {pos: [2, 0, 0], state: "minecraft:gravel"},
        {pos: [2, 0, 1], state: "minecraft:gravel"},
        {pos: [2, 0, 2], state: "minecraft:gravel"},
        {pos: [2, 0, 3], state: "minecraft:gravel"},
        {pos: [2, 0, 4], state: "minecraft:gravel"},
        {pos: [2, 0, 5], state: "minecraft:gravel"},
        {pos: [2, 0, 6], state: "minecraft:gravel"},
        {pos: [2, 0, 7], state: "minecraft:gravel"},
        {pos: [2, 0, 8], state: "minecraft:gravel"},
        {pos: [3, 0, 0], state: "minecraft:gravel"},
        {pos: [3, 0, 1], state: "minecraft:gravel"},
        {pos: [3, 0, 2], state: "minecraft:gravel"},
        {pos: [3, 0, 3], state: "minecraft:gravel"},
        {pos: [3, 0, 4], state: "minecraft:gravel"},
        {pos: [3, 0, 5], state: "minecraft:gravel"},
        {pos: [3, 0, 6], state: "minecraft:gravel"},
        {pos: [3, 0, 7], state: "minecraft:gravel"},
        {pos: [3, 0, 8], state: "minecraft:gravel"},
        {pos: [4, 0, 0], state: "minecraft:gravel"},
        {pos: [4, 0, 1], state: "minecraft:gravel"},
        {pos: [4, 0, 2], state: "minecraft:gravel"},
        {pos: [4, 0, 3], state: "minecraft:water{level:0}"},
        {pos: [4, 0, 4], state: "minecraft:water{level:0}"},
        {pos: [4, 0, 5], state: "minecraft:gravel"},
        {pos: [4, 0, 6], state: "minecraft:gravel"},
        {pos: [4, 0, 7], state: "minecraft:gravel"},
        {pos: [4, 0, 8], state: "minecraft:gravel"},
        {pos: [5, 0, 1], state: "minecraft:gravel"},
        {pos: [5, 0, 2], state: "minecraft:gravel"},
        {pos: [5, 0, 3], state: "minecraft:water{level:0}"},
        {pos: [5, 0, 4], state: "minecraft:water{level:0}"},
        {pos: [5, 0, 5], state: "minecraft:water{level:0}"},
        {pos: [5, 0, 6], state: "minecraft:gravel"},
        {pos: [5, 0, 7], state: "minecraft:gravel"},
        {pos: [6, 0, 2], state: "minecraft:gravel"},
        {pos: [6, 0, 3], state: "minecraft:gravel"},
        {pos: [6, 0, 4], state: "minecraft:water{level:0}"},
        {pos: [6, 0, 5], state: "minecraft:water{level:0}"},
        {pos: [6, 0, 6], state: "minecraft:gravel"},
        {pos: [6, 0, 7], state: "minecraft:gravel"},
        {pos: [7, 0, 1], state: "minecraft:gravel"},
        {pos: [7, 0, 2], state: "minecraft:gravel"},
        {pos: [7, 0, 3], state: "minecraft:gravel"},
        {pos: [7, 0, 4], state: "minecraft:gravel"},
        {pos: [7, 0, 5], state: "minecraft:gravel"},
        {pos: [7, 0, 6], state: "minecraft:gravel"},
        {pos: [7, 0, 7], state: "minecraft:gravel"},
        {pos: [7, 0, 8], state: "minecraft:gravel"},
        {pos: [8, 0, 1], state: "minecraft:gravel"},
        {pos: [8, 0, 2], state: "minecraft:gravel"},
        {pos: [8, 0, 3], state: "minecraft:gravel"},
        {pos: [8, 0, 4], state: "minecraft:gravel"},
        {pos: [8, 0, 5], state: "minecraft:gravel"},
        {pos: [8, 0, 6], state: "minecraft:gravel"},
        {pos: [8, 0, 7], state: "minecraft:gravel"},
        {pos: [8, 0, 8], state: "minecraft:gravel"},
        {pos: [9, 0, 1], state: "minecraft:gravel"},
        {pos: [9, 0, 2], state: "minecraft:gravel"},
        {pos: [9, 0, 3], state: "minecraft:gravel"},
        {pos: [9, 0, 4], state: "minecraft:gravel"},
        {pos: [9, 0, 5], state: "minecraft:gravel"},
        {pos: [9, 0, 6], state: "minecraft:gravel"},
        {pos: [9, 0, 7], state: "minecraft:gravel"},
        {pos: [9, 0, 8], state: "minecraft:gravel"},
        {pos: [10, 0, 2], state: "minecraft:gravel"},
        {pos: [10, 0, 3], state: "minecraft:gravel"},
        {pos: [10, 0, 4], state: "minecraft:gravel"},
        {pos: [10, 0, 5], state: "minecraft:gravel"},
        {pos: [10, 0, 6], state: "minecraft:gravel"},
        {pos: [10, 0, 7], state: "minecraft:gravel"},
        {pos: [10, 0, 8], state: "minecraft:gravel"},
        {pos: [11, 0, 5], state: "minecraft:gravel"},
        {pos: [11, 0, 6], state: "minecraft:gravel"},
        {pos: [1, 1, 6], state: "minecraft:stone_bricks"},
        {pos: [1, 1, 7], state: "minecraft:gravel"},
        {pos: [2, 1, 1], state: "minecraft:chiseled_stone_bricks"},
        {pos: [2, 1, 2], state: "minecraft:gravel"},
        {pos: [2, 1, 6], state: "minecraft:stone_bricks"},
        {pos: [2, 1, 7], state: "minecraft:stone_bricks"},
        {pos: [3, 1, 1], state: "minecraft:stone_bricks"},
        {pos: [3, 1, 2], state: "minecraft:gravel"},
        {pos: [3, 1, 3], state: "minecraft:air"},
        {pos: [3, 1, 4], state: "minecraft:air"},
        {pos: [4, 1, 2], state: "minecraft:air"},
        {pos: [4, 1, 3], state: "minecraft:air"},
        {pos: [4, 1, 4], state: "minecraft:air"},
        {pos: [4, 1, 5], state: "minecraft:air"},
        {pos: [5, 1, 2], state: "minecraft:air"},
        {pos: [5, 1, 3], state: "minecraft:air"},
        {pos: [5, 1, 4], state: "minecraft:air"},
        {pos: [5, 1, 5], state: "minecraft:air"},
        {pos: [5, 1, 6], state: "minecraft:air"},
        {pos: [6, 1, 3], state: "minecraft:air"},
        {pos: [6, 1, 4], state: "minecraft:air"},
        {pos: [6, 1, 5], state: "minecraft:air"},
        {pos: [6, 1, 6], state: "minecraft:air"},
        {pos: [7, 1, 4], state: "minecraft:air"},
        {pos: [7, 1, 5], state: "minecraft:air"},
        {pos: [8, 1, 2], state: "minecraft:stone_bricks"},
        {pos: [8, 1, 3], state: "minecraft:stone_bricks"},
        {pos: [8, 1, 6], state: "minecraft:stone_bricks"},
        {pos: [8, 1, 7], state: "minecraft:stone_bricks"},
        {pos: [9, 1, 2], state: "minecraft:stone_bricks"},
        {pos: [9, 1, 3], state: "minecraft:stone_bricks"},
        {pos: [9, 1, 4], state: "minecraft:stone_bricks"},
        {pos: [9, 1, 6], state: "minecraft:stone_bricks"},
        {pos: [9, 1, 7], state: "minecraft:stone_bricks"},
        {pos: [9, 1, 8], state: "minecraft:air"},
        {pos: [10, 1, 3], state: "minecraft:stone_bricks"},
        {pos: [10, 1, 4], state: "minecraft:stone_bricks"},
        {pos: [1, 2, 6], state: "minecraft:stone_bricks"},
        {pos: [1, 2, 7], state: "minecraft:stone_bricks"},
        {pos: [2, 2, 1], state: "minecraft:stone_bricks"},
        {pos: [2, 2, 2], state: "minecraft:stone_bricks"},
        {pos: [2, 2, 6], state: "minecraft:stone_bricks"},
        {pos: [2, 2, 7], state: "minecraft:stone_bricks"},
        {pos: [3, 2, 1], state: "minecraft:stone_bricks"},
        {pos: [3, 2, 2], state: "minecraft:gravel"},
        {pos: [4, 2, 3], state: "minecraft:air"},
        {pos: [4, 2, 4], state: "minecraft:air"},
        {pos: [5, 2, 3], state: "minecraft:air"},
        {pos: [5, 2, 4], state: "minecraft:air"},
        {pos: [5, 2, 5], state: "minecraft:air"},
        {pos: [6, 2, 4], state: "minecraft:air"},
        {pos: [6, 2, 5], state: "minecraft:air"},
        {pos: [8, 2, 3], state: "minecraft:stone_bricks"},
        {pos: [8, 2, 6], state: "minecraft:stone_bricks"},
        {pos: [8, 2, 7], state: "minecraft:stone_bricks"},
        {pos: [9, 2, 2], state: "minecraft:stone_bricks"},
        {pos: [9, 2, 3], state: "minecraft:stone_bricks"},
        {pos: [9, 2, 6], state: "minecraft:stone_bricks"},
        {pos: [9, 2, 7], state: "minecraft:stone_bricks"},
        {pos: [1, 3, 6], state: "minecraft:stone_bricks"},
        {pos: [1, 3, 7], state: "minecraft:stone_bricks"},
        {pos: [2, 3, 1], state: "minecraft:stone_bricks"},
        {pos: [2, 3, 2], state: "minecraft:stone_bricks"},
        {pos: [2, 3, 6], state: "minecraft:stone_bricks"},
        {pos: [2, 3, 7], state: "minecraft:stone_bricks"},
        {pos: [3, 3, 1], state: "minecraft:stone_bricks"},
        {pos: [3, 3, 2], state: "minecraft:stone_bricks"},
        {pos: [8, 3, 6], state: "minecraft:stone_bricks"},
        {pos: [8, 3, 7], state: "minecraft:stone_bricks"},
        {pos: [9, 3, 6], state: "minecraft:stone_bricks"},
        {pos: [9, 3, 7], state: "minecraft:stone_bricks"},
        {pos: [1, 4, 6], state: "minecraft:stone_bricks"},
        {pos: [1, 4, 7], state: "minecraft:stone_bricks"},
        {pos: [2, 4, 1], state: "minecraft:stone_bricks"},
        {pos: [2, 4, 2], state: "minecraft:stone_bricks"},
        {pos: [2, 4, 6], state: "minecraft:stone_bricks"},
        {pos: [2, 4, 7], state: "minecraft:stone_bricks"},
        {pos: [3, 4, 1], state: "minecraft:stone_bricks"},
        {pos: [8, 4, 6], state: "minecraft:polished_andesite"},
        {pos: [8, 4, 7], state: "minecraft:stone_bricks"},
        {pos: [9, 4, 6], state: "minecraft:stone_bricks"},
        {pos: [9, 4, 7], state: "minecraft:stone_bricks"},
        {pos: [8, 5, 6], state: "minecraft:stone_bricks"},
        {pos: [8, 5, 7], state: "minecraft:stone_bricks"},
        {pos: [9, 5, 6], state: "minecraft:stone_bricks"},
        {pos: [9, 5, 7], state: "minecraft:chiseled_stone_bricks"},
        {pos: [8, 6, 6], state: "minecraft:stone_bricks"},
        {pos: [8, 6, 7], state: "minecraft:stone_bricks"},
        {pos: [9, 6, 6], state: "minecraft:polished_andesite"},
        {pos: [9, 6, 7], state: "minecraft:stone_bricks"},
        {pos: [8, 7, 7], state: "minecraft:stone_bricks"},
        {pos: [9, 7, 6], state: "minecraft:stone_bricks"},
        {pos: [9, 7, 7], state: "minecraft:stone_bricks"}
    ],
    entities: [],
    palette: [
        "minecraft:gravel",
        "minecraft:stone_bricks",
        "minecraft:chiseled_stone_bricks",
        "minecraft:polished_andesite",
        "minecraft:water{level:0}",
        "minecraft:air"
    ],
    trailiertales_DataVersion: 2
}
