{
    DataVersion: 3953,
    size: [17, 12, 19],
    data: [
        {pos: [0, 0, 4], state: "minecraft:mud_bricks"},
        {pos: [0, 0, 5], state: "minecraft:mud_bricks"},
        {pos: [0, 0, 6], state: "minecraft:mud_bricks"},
        {pos: [0, 0, 12], state: "minecraft:mud_bricks"},
        {pos: [0, 0, 13], state: "minecraft:mud_bricks"},
        {pos: [0, 0, 14], state: "minecraft:mud_bricks"},
        {pos: [0, 0, 15], state: "minecraft:mud_bricks"},
        {pos: [1, 0, 3], state: "minecraft:mud_bricks"},
        {pos: [1, 0, 4], state: "minecraft:mud_bricks"},
        {pos: [1, 0, 5], state: "minecraft:mud_bricks"},
        {pos: [1, 0, 6], state: "minecraft:mud_bricks"},
        {pos: [1, 0, 7], state: "minecraft:mud_bricks"},
        {pos: [1, 0, 8], state: "minecraft:mud_bricks"},
        {pos: [1, 0, 11], state: "minecraft:mud_bricks"},
        {pos: [1, 0, 12], state: "minecraft:mud_bricks"},
        {pos: [1, 0, 13], state: "minecraft:mud_bricks"},
        {pos: [1, 0, 14], state: "minecraft:mud_bricks"},
        {pos: [1, 0, 15], state: "minecraft:mud_bricks"},
        {pos: [1, 0, 16], state: "minecraft:mud_bricks"},
        {pos: [1, 0, 17], state: "minecraft:mud_bricks"},
        {pos: [2, 0, 3], state: "minecraft:mud_bricks"},
        {pos: [2, 0, 4], state: "minecraft:mud_bricks"},
        {pos: [2, 0, 5], state: "minecraft:mud_bricks"},
        {pos: [2, 0, 6], state: "minecraft:mud_bricks"},
        {pos: [2, 0, 7], state: "minecraft:mud_bricks"},
        {pos: [2, 0, 8], state: "minecraft:mud_bricks"},
        {pos: [2, 0, 9], state: "minecraft:mud_bricks"},
        {pos: [2, 0, 10], state: "minecraft:mud_bricks"},
        {pos: [2, 0, 11], state: "minecraft:mud_bricks"},
        {pos: [2, 0, 12], state: "minecraft:mud_bricks"},
        {pos: [2, 0, 13], state: "minecraft:mud_bricks"},
        {pos: [2, 0, 14], state: "minecraft:mud_bricks"},
        {pos: [2, 0, 15], state: "minecraft:mud_bricks"},
        {pos: [2, 0, 16], state: "minecraft:mud_bricks"},
        {pos: [2, 0, 17], state: "minecraft:mud_bricks"},
        {pos: [2, 0, 18], state: "minecraft:mud_bricks"},
        {pos: [3, 0, 3], state: "minecraft:mud_bricks"},
        {pos: [3, 0, 4], state: "minecraft:mud_bricks"},
        {pos: [3, 0, 5], state: "minecraft:mud_bricks"},
        {pos: [3, 0, 6], state: "minecraft:mud_bricks"},
        {pos: [3, 0, 7], state: "minecraft:mud_bricks"},
        {pos: [3, 0, 8], state: "minecraft:mud_bricks"},
        {pos: [3, 0, 9], state: "minecraft:mud_bricks"},
        {pos: [3, 0, 10], state: "minecraft:mud_bricks"},
        {pos: [3, 0, 11], state: "minecraft:mud_bricks"},
        {pos: [3, 0, 12], state: "minecraft:mud_bricks"},
        {pos: [3, 0, 13], state: "minecraft:mud_bricks"},
        {pos: [3, 0, 14], state: "minecraft:mud_bricks"},
        {pos: [3, 0, 15], state: "minecraft:mud_bricks"},
        {pos: [3, 0, 16], state: "minecraft:mud_bricks"},
        {pos: [3, 0, 17], state: "minecraft:mud_bricks"},
        {pos: [4, 0, 3], state: "minecraft:mud_bricks"},
        {pos: [4, 0, 4], state: "minecraft:mud_bricks"},
        {pos: [4, 0, 5], state: "minecraft:mud_bricks"},
        {pos: [4, 0, 6], state: "minecraft:mud_bricks"},
        {pos: [4, 0, 7], state: "minecraft:mud_bricks"},
        {pos: [4, 0, 8], state: "minecraft:mud_bricks"},
        {pos: [4, 0, 9], state: "minecraft:mud_bricks"},
        {pos: [4, 0, 10], state: "minecraft:mud_bricks"},
        {pos: [4, 0, 11], state: "minecraft:mud_bricks"},
        {pos: [4, 0, 12], state: "minecraft:mud_bricks"},
        {pos: [4, 0, 13], state: "minecraft:mud_bricks"},
        {pos: [4, 0, 14], state: "minecraft:mud_bricks"},
        {pos: [4, 0, 15], state: "minecraft:mud_bricks"},
        {pos: [4, 0, 16], state: "minecraft:mud_bricks"},
        {pos: [4, 0, 17], state: "minecraft:mud_bricks"},
        {pos: [5, 0, 4], state: "minecraft:mud_bricks"},
        {pos: [5, 0, 5], state: "minecraft:mud_bricks"},
        {pos: [5, 0, 6], state: "minecraft:mud_bricks"},
        {pos: [5, 0, 7], state: "minecraft:mud_bricks"},
        {pos: [5, 0, 8], state: "minecraft:mud_bricks"},
        {pos: [5, 0, 11], state: "minecraft:mud_bricks"},
        {pos: [5, 0, 12], state: "minecraft:mud_bricks"},
        {pos: [5, 0, 13], state: "minecraft:mud_bricks"},
        {pos: [5, 0, 14], state: "minecraft:mud_bricks"},
        {pos: [5, 0, 15], state: "minecraft:mud_bricks"},
        {pos: [5, 0, 16], state: "minecraft:mud_bricks"},
        {pos: [5, 0, 17], state: "minecraft:mud_bricks"},
        {pos: [6, 0, 5], state: "minecraft:mud_bricks"},
        {pos: [6, 0, 6], state: "minecraft:mud_bricks"},
        {pos: [6, 0, 7], state: "minecraft:mud_bricks"},
        {pos: [6, 0, 14], state: "minecraft:mud_bricks"},
        {pos: [6, 0, 15], state: "minecraft:mud_bricks"},
        {pos: [6, 0, 16], state: "minecraft:mud_bricks"},
        {pos: [7, 0, 4], state: "minecraft:mud_bricks"},
        {pos: [7, 0, 5], state: "minecraft:mud_bricks"},
        {pos: [7, 0, 6], state: "minecraft:mud_bricks"},
        {pos: [7, 0, 13], state: "minecraft:mud_bricks"},
        {pos: [7, 0, 14], state: "minecraft:mud_bricks"},
        {pos: [7, 0, 15], state: "minecraft:mud_bricks"},
        {pos: [7, 0, 16], state: "minecraft:mud_bricks"},
        {pos: [7, 0, 17], state: "minecraft:mud_bricks"},
        {pos: [8, 0, 3], state: "minecraft:mud_bricks"},
        {pos: [8, 0, 4], state: "minecraft:mud_bricks"},
        {pos: [8, 0, 5], state: "minecraft:mud_bricks"},
        {pos: [8, 0, 6], state: "minecraft:mud_bricks"},
        {pos: [8, 0, 12], state: "minecraft:mud_bricks"},
        {pos: [8, 0, 13], state: "minecraft:mud_bricks"},
        {pos: [8, 0, 14], state: "minecraft:mud_bricks"},
        {pos: [8, 0, 15], state: "minecraft:mud_bricks"},
        {pos: [8, 0, 16], state: "minecraft:mud_bricks"},
        {pos: [8, 0, 17], state: "minecraft:mud_bricks"},
        {pos: [9, 0, 1], state: "minecraft:mud_bricks"},
        {pos: [9, 0, 2], state: "minecraft:mud_bricks"},
        {pos: [9, 0, 3], state: "minecraft:mud_bricks"},
        {pos: [9, 0, 4], state: "minecraft:mud_bricks"},
        {pos: [9, 0, 5], state: "minecraft:mud_bricks"},
        {pos: [9, 0, 6], state: "minecraft:mud_bricks"},
        {pos: [9, 0, 7], state: "minecraft:mud_bricks"},
        {pos: [9, 0, 12], state: "minecraft:mud_bricks"},
        {pos: [9, 0, 13], state: "minecraft:mud_bricks"},
        {pos: [9, 0, 14], state: "minecraft:mud_bricks"},
        {pos: [9, 0, 15], state: "minecraft:mud_bricks"},
        {pos: [9, 0, 16], state: "minecraft:mud_bricks"},
        {pos: [9, 0, 17], state: "minecraft:mud_bricks"},
        {pos: [9, 0, 18], state: "minecraft:mud_bricks"},
        {pos: [10, 0, 0], state: "minecraft:mud_bricks"},
        {pos: [10, 0, 1], state: "minecraft:mud_bricks"},
        {pos: [10, 0, 2], state: "minecraft:mud_bricks"},
        {pos: [10, 0, 3], state: "minecraft:mud_bricks"},
        {pos: [10, 0, 4], state: "minecraft:mud_bricks"},
        {pos: [10, 0, 5], state: "minecraft:mud_bricks"},
        {pos: [10, 0, 6], state: "minecraft:orange_glazed_terracotta{facing:north}"},
        {pos: [10, 0, 7], state: "minecraft:orange_glazed_terracotta{facing:west}"},
        {pos: [10, 0, 8], state: "minecraft:mud_bricks"},
        {pos: [10, 0, 12], state: "minecraft:mud_bricks"},
        {pos: [10, 0, 13], state: "minecraft:mud_bricks"},
        {pos: [10, 0, 14], state: "minecraft:mud_bricks"},
        {pos: [10, 0, 15], state: "minecraft:mud_bricks"},
        {pos: [10, 0, 16], state: "minecraft:mud_bricks"},
        {pos: [10, 0, 17], state: "minecraft:mud_bricks"},
        {pos: [10, 0, 18], state: "minecraft:mud_bricks"},
        {pos: [11, 0, 0], state: "minecraft:mud_bricks"},
        {pos: [11, 0, 1], state: "minecraft:mud_bricks"},
        {pos: [11, 0, 2], state: "minecraft:mud_bricks"},
        {pos: [11, 0, 3], state: "minecraft:mud_bricks"},
        {pos: [11, 0, 4], state: "minecraft:mud_bricks"},
        {pos: [11, 0, 5], state: "minecraft:mud_bricks"},
        {pos: [11, 0, 6], state: "minecraft:orange_glazed_terracotta{facing:east}"},
        {pos: [11, 0, 7], state: "minecraft:mud_bricks"},
        {pos: [11, 0, 8], state: "minecraft:mud_bricks"},
        {pos: [11, 0, 14], state: "minecraft:mud_bricks"},
        {pos: [11, 0, 15], state: "minecraft:mud_bricks"},
        {pos: [11, 0, 16], state: "minecraft:mud_bricks"},
        {pos: [11, 0, 17], state: "minecraft:mud_bricks"},
        {pos: [12, 0, 0], state: "minecraft:mud_bricks"},
        {pos: [12, 0, 1], state: "minecraft:mud_bricks"},
        {pos: [12, 0, 2], state: "minecraft:orange_glazed_terracotta{facing:north}"},
        {pos: [12, 0, 3], state: "minecraft:orange_glazed_terracotta{facing:west}"},
        {pos: [12, 0, 4], state: "minecraft:mud_bricks"},
        {pos: [12, 0, 5], state: "minecraft:mud_bricks"},
        {pos: [12, 0, 6], state: "minecraft:mud_bricks"},
        {pos: [12, 0, 7], state: "minecraft:mud_bricks"},
        {pos: [12, 0, 8], state: "minecraft:mud_bricks"},
        {pos: [12, 0, 9], state: "minecraft:mud_bricks"},
        {pos: [12, 0, 14], state: "minecraft:mud_bricks"},
        {pos: [12, 0, 15], state: "minecraft:mud_bricks"},
        {pos: [12, 0, 16], state: "minecraft:mud_bricks"},
        {pos: [13, 0, 0], state: "minecraft:mud_bricks"},
        {pos: [13, 0, 1], state: "minecraft:mud_bricks"},
        {pos: [13, 0, 2], state: "minecraft:orange_glazed_terracotta{facing:east}"},
        {pos: [13, 0, 3], state: "minecraft:orange_glazed_terracotta{facing:south}"},
        {pos: [13, 0, 4], state: "minecraft:mud_bricks"},
        {pos: [13, 0, 5], state: "minecraft:mud_bricks"},
        {pos: [13, 0, 6], state: "minecraft:mud_bricks"},
        {pos: [13, 0, 7], state: "minecraft:mud_bricks"},
        {pos: [13, 0, 8], state: "minecraft:mud_bricks"},
        {pos: [13, 0, 9], state: "minecraft:mud_bricks"},
        {pos: [14, 0, 0], state: "minecraft:mud_bricks"},
        {pos: [14, 0, 1], state: "minecraft:mud_bricks"},
        {pos: [14, 0, 2], state: "minecraft:mud_bricks"},
        {pos: [14, 0, 3], state: "minecraft:mud_bricks"},
        {pos: [14, 0, 4], state: "minecraft:mud_bricks"},
        {pos: [14, 0, 5], state: "minecraft:mud_bricks"},
        {pos: [14, 0, 6], state: "minecraft:mud_bricks"},
        {pos: [14, 0, 7], state: "minecraft:mud_bricks"},
        {pos: [14, 0, 8], state: "minecraft:mud_bricks"},
        {pos: [15, 0, 1], state: "minecraft:mud_bricks"},
        {pos: [15, 0, 2], state: "minecraft:mud_bricks"},
        {pos: [15, 0, 3], state: "minecraft:mud_bricks"},
        {pos: [15, 0, 4], state: "minecraft:mud_bricks"},
        {pos: [15, 0, 5], state: "minecraft:mud_bricks"},
        {pos: [15, 0, 6], state: "minecraft:mud_bricks"},
        {pos: [16, 0, 3], state: "minecraft:mud_bricks"},
        {pos: [16, 0, 4], state: "minecraft:mud_bricks"},
        {pos: [16, 0, 5], state: "minecraft:mud_bricks"},
        {pos: [0, 1, 4], state: "minecraft:gravel"},
        {pos: [0, 1, 5], state: "minecraft:gravel"},
        {pos: [0, 1, 6], state: "minecraft:gravel"},
        {pos: [0, 1, 12], state: "minecraft:gravel"},
        {pos: [0, 1, 13], state: "minecraft:gravel"},
        {pos: [0, 1, 14], state: "minecraft:gravel"},
        {pos: [0, 1, 15], state: "minecraft:gravel"},
        {pos: [1, 1, 3], state: "minecraft:gravel"},
        {pos: [1, 1, 4], state: "minecraft:mud_bricks"},
        {pos: [1, 1, 5], state: "minecraft:mud_bricks"},
        {pos: [1, 1, 6], state: "minecraft:mud_bricks"},
        {pos: [1, 1, 7], state: "minecraft:gravel"},
        {pos: [1, 1, 8], state: "minecraft:gravel"},
        {pos: [1, 1, 11], state: "minecraft:gravel"},
        {pos: [1, 1, 12], state: "minecraft:gravel"},
        {pos: [1, 1, 13], state: "minecraft:gravel"},
        {pos: [1, 1, 14], state: "minecraft:gravel"},
        {pos: [1, 1, 15], state: "minecraft:gravel"},
        {pos: [1, 1, 16], state: "minecraft:gravel"},
        {pos: [1, 1, 17], state: "minecraft:gravel"},
        {pos: [2, 1, 3], state: "minecraft:gravel"},
        {pos: [2, 1, 4], state: "minecraft:mud_bricks"},
        {pos: [2, 1, 5], state: "minecraft:mud_bricks"},
        {pos: [2, 1, 6], state: "minecraft:mud_bricks"},
        {pos: [2, 1, 7], state: "minecraft:gravel"},
        {pos: [2, 1, 8], state: "minecraft:gravel"},
        {pos: [2, 1, 9], state: "minecraft:gravel"},
        {pos: [2, 1, 10], state: "minecraft:gravel"},
        {pos: [2, 1, 11], state: "minecraft:gravel"},
        {pos: [2, 1, 12], state: "minecraft:mud_bricks"},
        {pos: [2, 1, 13], state: "minecraft:mud_bricks"},
        {pos: [2, 1, 14], state: "minecraft:mud_bricks"},
        {pos: [2, 1, 15], state: "minecraft:mud_bricks"},
        {pos: [2, 1, 16], state: "minecraft:mud_bricks"},
        {pos: [2, 1, 17], state: "minecraft:gravel"},
        {pos: [2, 1, 18], state: "minecraft:gravel"},
        {pos: [3, 1, 3], state: "minecraft:gravel"},
        {pos: [3, 1, 4], state: "minecraft:mud_bricks"},
        {pos: [3, 1, 5], state: "minecraft:gravel"},
        {pos: [3, 1, 6], state: "minecraft:gravel"},
        {pos: [3, 1, 7], state: "minecraft:gravel"},
        {pos: [3, 1, 8], state: "minecraft:gravel"},
        {pos: [3, 1, 9], state: "minecraft:gravel"},
        {pos: [3, 1, 10], state: "minecraft:gravel"},
        {pos: [3, 1, 11], state: "minecraft:mud_bricks"},
        {pos: [3, 1, 12], state: "minecraft:mud_bricks"},
        {pos: [3, 1, 13], state: "minecraft:mud_bricks"},
        {pos: [3, 1, 14], state: "minecraft:mud_bricks"},
        {pos: [3, 1, 15], state: "minecraft:gravel"},
        {pos: [3, 1, 16], state: "minecraft:mud_bricks"},
        {pos: [3, 1, 17], state: "minecraft:gravel"},
        {pos: [4, 1, 3], state: "minecraft:gravel"},
        {pos: [4, 1, 4], state: "minecraft:gravel"},
        {pos: [4, 1, 5], state: "minecraft:gravel"},
        {pos: [4, 1, 6], state: "minecraft:gravel"},
        {pos: [4, 1, 7], state: "minecraft:mud_bricks"},
        {pos: [4, 1, 8], state: "minecraft:gravel"},
        {pos: [4, 1, 9], state: "minecraft:gravel"},
        {pos: [4, 1, 10], state: "minecraft:gravel"},
        {pos: [4, 1, 11], state: "minecraft:mud_bricks"},
        {pos: [4, 1, 12], state: "minecraft:mud_bricks"},
        {pos: [4, 1, 13], state: "minecraft:mud_bricks"},
        {pos: [4, 1, 14], state: "minecraft:mud_bricks"},
        {pos: [4, 1, 15], state: "minecraft:gravel"},
        {pos: [4, 1, 16], state: "minecraft:mud_bricks"},
        {pos: [4, 1, 17], state: "minecraft:gravel"},
        {pos: [5, 1, 4], state: "minecraft:gravel"},
        {pos: [5, 1, 5], state: "minecraft:gravel"},
        {pos: [5, 1, 6], state: "minecraft:gravel"},
        {pos: [5, 1, 7], state: "minecraft:gravel"},
        {pos: [5, 1, 8], state: "minecraft:gravel"},
        {pos: [5, 1, 11], state: "minecraft:gravel"},
        {pos: [5, 1, 12], state: "minecraft:mud_brick_stairs{facing:west,half:top,shape:straight,waterlogged:false}"},
        {pos: [5, 1, 13], state: "minecraft:mud_brick_stairs{facing:west,half:top,shape:straight,waterlogged:false}"},
        {pos: [5, 1, 14], state: "minecraft:gravel"},
        {pos: [5, 1, 15], state: "minecraft:gravel"},
        {pos: [5, 1, 16], state: "minecraft:gravel"},
        {pos: [5, 1, 17], state: "minecraft:gravel"},
        {pos: [6, 1, 5], state: "minecraft:gravel"},
        {pos: [6, 1, 6], state: "minecraft:gravel"},
        {pos: [6, 1, 7], state: "minecraft:gravel"},
        {pos: [6, 1, 14], state: "minecraft:gravel"},
        {pos: [6, 1, 15], state: "minecraft:gravel"},
        {pos: [6, 1, 16], state: "minecraft:gravel"},
        {pos: [7, 1, 4], state: "minecraft:gravel"},
        {pos: [7, 1, 5], state: "minecraft:gravel"},
        {pos: [7, 1, 6], state: "minecraft:gravel"},
        {pos: [7, 1, 13], state: "minecraft:gravel"},
        {pos: [7, 1, 14], state: "minecraft:gravel"},
        {pos: [7, 1, 15], state: "minecraft:gravel"},
        {pos: [7, 1, 16], state: "minecraft:gravel"},
        {pos: [7, 1, 17], state: "minecraft:gravel"},
        {pos: [8, 1, 3], state: "minecraft:gravel"},
        {pos: [8, 1, 4], state: "minecraft:gravel"},
        {pos: [8, 1, 5], state: "minecraft:gravel"},
        {pos: [8, 1, 6], state: "minecraft:gravel"},
        {pos: [8, 1, 12], state: "minecraft:gravel"},
        {pos: [8, 1, 13], state: "minecraft:gravel"},
        {pos: [8, 1, 14], state: "minecraft:mud_bricks"},
        {pos: [8, 1, 15], state: "minecraft:mud_bricks"},
        {pos: [8, 1, 16], state: "minecraft:mud_bricks"},
        {pos: [8, 1, 17], state: "minecraft:gravel"},
        {pos: [9, 1, 1], state: "minecraft:gravel"},
        {pos: [9, 1, 2], state: "minecraft:gravel"},
        {pos: [9, 1, 3], state: "minecraft:mud_bricks"},
        {pos: [9, 1, 4], state: "minecraft:mud_bricks"},
        {pos: [9, 1, 5], state: "minecraft:mud_bricks"},
        {pos: [9, 1, 6], state: "minecraft:gravel"},
        {pos: [9, 1, 7], state: "minecraft:gravel"},
        {pos: [9, 1, 12], state: "minecraft:gravel"},
        {pos: [9, 1, 13], state: "minecraft:gravel"},
        {pos: [9, 1, 14], state: "minecraft:mud_bricks"},
        {pos: [9, 1, 15], state: "minecraft:mud_bricks"},
        {pos: [9, 1, 16], state: "minecraft:mud_bricks"},
        {pos: [9, 1, 17], state: "minecraft:mud_bricks"},
        {pos: [9, 1, 18], state: "minecraft:gravel"},
        {pos: [10, 1, 0], state: "minecraft:gravel"},
        {pos: [10, 1, 1], state: "minecraft:gravel"},
        {pos: [10, 1, 2], state: "minecraft:mud_bricks"},
        {pos: [10, 1, 3], state: "minecraft:gravel"},
        {pos: [10, 1, 4], state: "minecraft:gravel"},
        {pos: [10, 1, 5], state: "minecraft:gravel"},
        {pos: [10, 1, 6], state: "minecraft:gravel"},
        {pos: [10, 1, 7], state: "minecraft:gravel"},
        {pos: [10, 1, 8], state: "minecraft:gravel"},
        {pos: [10, 1, 12], state: "minecraft:gravel"},
        {pos: [10, 1, 13], state: "minecraft:gravel"},
        {pos: [10, 1, 14], state: "minecraft:mud_bricks"},
        {pos: [10, 1, 15], state: "minecraft:mud_bricks"},
        {pos: [10, 1, 16], state: "minecraft:mud_bricks"},
        {pos: [10, 1, 17], state: "minecraft:mud_bricks"},
        {pos: [10, 1, 18], state: "minecraft:gravel"},
        {pos: [11, 1, 0], state: "minecraft:gravel"},
        {pos: [11, 1, 1], state: "minecraft:mud_bricks"},
        {pos: [11, 1, 2], state: "minecraft:mud_brick_stairs{facing:north,half:top,shape:straight,waterlogged:false}"},
        {pos: [11, 1, 3], state: "minecraft:gravel"},
        {pos: [11, 1, 4], state: "minecraft:gravel"},
        {pos: [11, 1, 5], state: "minecraft:gravel"},
        {pos: [11, 1, 6], state: "minecraft:gravel"},
        {pos: [11, 1, 7], state: "minecraft:gravel"},
        {pos: [11, 1, 8], state: "minecraft:mud_brick_stairs{facing:east,half:top,shape:straight,waterlogged:false}"},
        {pos: [11, 1, 14], state: "minecraft:gravel"},
        {pos: [11, 1, 15], state: "minecraft:mud_brick_stairs{facing:west,half:top,shape:straight,waterlogged:false}"},
        {pos: [11, 1, 16], state: "minecraft:mud_brick_stairs{facing:west,half:top,shape:straight,waterlogged:false}"},
        {pos: [11, 1, 17], state: "minecraft:gravel"},
        {pos: [12, 1, 0], state: "minecraft:gravel"},
        {pos: [12, 1, 1], state: "minecraft:mud_bricks"},
        {pos: [12, 1, 2], state: "minecraft:mud_brick_stairs{facing:north,half:top,shape:straight,waterlogged:false}"},
        {pos: [12, 1, 3], state: "minecraft:gravel"},
        {pos: [12, 1, 4], state: "minecraft:gravel"},
        {pos: [12, 1, 5], state: "minecraft:gravel"},
        {pos: [12, 1, 6], state: "minecraft:gravel"},
        {pos: [12, 1, 7], state: "minecraft:gravel"},
        {pos: [12, 1, 8], state: "minecraft:mud_bricks"},
        {pos: [12, 1, 9], state: "minecraft:gravel"},
        {pos: [12, 1, 14], state: "minecraft:gravel"},
        {pos: [12, 1, 15], state: "minecraft:gravel"},
        {pos: [12, 1, 16], state: "minecraft:gravel"},
        {pos: [13, 1, 0], state: "minecraft:gravel"},
        {pos: [13, 1, 1], state: "minecraft:mud_bricks"},
        {pos: [13, 1, 2], state: "minecraft:gravel"},
        {pos: [13, 1, 3], state: "minecraft:gravel"},
        {pos: [13, 1, 4], state: "minecraft:gravel"},
        {pos: [13, 1, 5], state: "minecraft:gravel"},
        {pos: [13, 1, 6], state: "minecraft:gravel"},
        {pos: [13, 1, 7], state: "minecraft:mud_bricks"},
        {pos: [13, 1, 8], state: "minecraft:gravel"},
        {pos: [13, 1, 9], state: "minecraft:gravel"},
        {pos: [14, 1, 0], state: "minecraft:gravel"},
        {pos: [14, 1, 1], state: "minecraft:gravel"},
        {pos: [14, 1, 2], state: "minecraft:mud_bricks"},
        {pos: [14, 1, 3], state: "minecraft:mud_bricks"},
        {pos: [14, 1, 4], state: "minecraft:mud_bricks"},
        {pos: [14, 1, 5], state: "minecraft:mud_bricks"},
        {pos: [14, 1, 6], state: "minecraft:mud_bricks"},
        {pos: [14, 1, 7], state: "minecraft:gravel"},
        {pos: [14, 1, 8], state: "minecraft:gravel"},
        {pos: [15, 1, 1], state: "minecraft:gravel"},
        {pos: [15, 1, 2], state: "minecraft:gravel"},
        {pos: [15, 1, 3], state: "minecraft:mud_bricks"},
        {pos: [15, 1, 4], state: "minecraft:mud_bricks"},
        {pos: [15, 1, 5], state: "minecraft:mud_bricks"},
        {pos: [15, 1, 6], state: "minecraft:gravel"},
        {pos: [16, 1, 3], state: "minecraft:gravel"},
        {pos: [16, 1, 4], state: "minecraft:gravel"},
        {pos: [16, 1, 5], state: "minecraft:gravel"},
        {pos: [0, 2, 4], state: "minecraft:gravel"},
        {pos: [0, 2, 5], state: "minecraft:gravel"},
        {pos: [0, 2, 6], state: "minecraft:gravel"},
        {pos: [0, 2, 13], state: "minecraft:gravel"},
        {pos: [0, 2, 14], state: "minecraft:gravel"},
        {pos: [0, 2, 15], state: "minecraft:gravel"},
        {pos: [1, 2, 3], state: "minecraft:gravel"},
        {pos: [1, 2, 4], state: "minecraft:mud_bricks"},
        {pos: [1, 2, 5], state: "minecraft:orange_glazed_terracotta{facing:west}"},
        {pos: [1, 2, 6], state: "minecraft:mud_bricks"},
        {pos: [1, 2, 7], state: "minecraft:gravel"},
        {pos: [1, 2, 8], state: "minecraft:gravel"},
        {pos: [1, 2, 11], state: "minecraft:gravel"},
        {pos: [1, 2, 12], state: "minecraft:gravel"},
        {pos: [1, 2, 13], state: "minecraft:gravel"},
        {pos: [1, 2, 14], state: "minecraft:gravel"},
        {pos: [1, 2, 15], state: "minecraft:gravel"},
        {pos: [1, 2, 16], state: "minecraft:gravel"},
        {pos: [1, 2, 17], state: "minecraft:gravel"},
        {pos: [2, 2, 3], state: "minecraft:gravel"},
        {pos: [2, 2, 4], state: "minecraft:gravel"},
        {pos: [2, 2, 5], state: "minecraft:gravel"},
        {pos: [2, 2, 6], state: "minecraft:mud_bricks"},
        {pos: [2, 2, 7], state: "minecraft:mud_bricks"},
        {pos: [2, 2, 8], state: "minecraft:gravel"},
        {pos: [2, 2, 9], state: "minecraft:gravel"},
        {pos: [2, 2, 10], state: "minecraft:gravel"},
        {pos: [2, 2, 11], state: "minecraft:gravel"},
        {pos: [2, 2, 12], state: "minecraft:gravel"},
        {pos: [2, 2, 13], state: "minecraft:mud_bricks"},
        {pos: [2, 2, 14], state: "minecraft:mud_bricks"},
        {pos: [2, 2, 15], state: "minecraft:mud_bricks"},
        {pos: [2, 2, 16], state: "minecraft:mud_bricks"},
        {pos: [2, 2, 17], state: "minecraft:gravel"},
        {pos: [2, 2, 18], state: "minecraft:gravel"},
        {pos: [3, 2, 4], state: "minecraft:gravel"},
        {pos: [3, 2, 5], state: "minecraft:gravel"},
        {pos: [3, 2, 6], state: "minecraft:gravel"},
        {pos: [3, 2, 7], state: "minecraft:gravel"},
        {pos: [3, 2, 8], state: "minecraft:gravel"},
        {pos: [3, 2, 9], state: "minecraft:gravel"},
        {pos: [3, 2, 10], state: "minecraft:gravel"},
        {pos: [3, 2, 11], state: "minecraft:gravel"},
        {pos: [3, 2, 12], state: "minecraft:mud_bricks"},
        {pos: [3, 2, 13], state: "minecraft:mud_bricks"},
        {pos: [3, 2, 14], state: "minecraft:mud_bricks"},
        {pos: [3, 2, 15], state: "minecraft:gravel"},
        {pos: [3, 2, 16], state: "minecraft:gravel"},
        {pos: [3, 2, 17], state: "minecraft:gravel"},
        {pos: [4, 2, 4], state: "minecraft:gravel"},
        {pos: [4, 2, 5], state: "minecraft:gravel"},
        {pos: [4, 2, 6], state: "minecraft:gravel"},
        {pos: [4, 2, 7], state: "minecraft:mud_bricks"},
        {pos: [4, 2, 8], state: "minecraft:gravel"},
        {pos: [4, 2, 9], state: "minecraft:gravel"},
        {pos: [4, 2, 10], state: "minecraft:gravel"},
        {pos: [4, 2, 11], state: "minecraft:mud_bricks"},
        {pos: [4, 2, 12], state: "minecraft:mud_bricks"},
        {pos: [4, 2, 13], state: "minecraft:mud_bricks"},
        {pos: [4, 2, 14], state: "minecraft:mud_bricks"},
        {pos: [4, 2, 15], state: "minecraft:gravel"},
        {pos: [4, 2, 16], state: "minecraft:mud_bricks"},
        {pos: [4, 2, 17], state: "minecraft:gravel"},
        {pos: [5, 2, 4], state: "minecraft:gravel"},
        {pos: [5, 2, 5], state: "minecraft:gravel"},
        {pos: [5, 2, 6], state: "minecraft:gravel"},
        {pos: [5, 2, 7], state: "minecraft:gravel"},
        {pos: [5, 2, 8], state: "minecraft:gravel"},
        {pos: [5, 2, 11], state: "minecraft:gravel"},
        {pos: [5, 2, 12], state: "minecraft:gravel"},
        {pos: [5, 2, 13], state: "minecraft:gravel"},
        {pos: [5, 2, 14], state: "minecraft:gravel"},
        {pos: [5, 2, 15], state: "minecraft:gravel"},
        {pos: [5, 2, 16], state: "minecraft:gravel"},
        {pos: [5, 2, 17], state: "minecraft:gravel"},
        {pos: [6, 2, 5], state: "minecraft:gravel"},
        {pos: [6, 2, 6], state: "minecraft:gravel"},
        {pos: [6, 2, 7], state: "minecraft:gravel"},
        {pos: [6, 2, 14], state: "minecraft:gravel"},
        {pos: [6, 2, 15], state: "minecraft:gravel"},
        {pos: [6, 2, 16], state: "minecraft:gravel"},
        {pos: [7, 2, 4], state: "minecraft:gravel"},
        {pos: [7, 2, 5], state: "minecraft:gravel"},
        {pos: [7, 2, 6], state: "minecraft:gravel"},
        {pos: [7, 2, 13], state: "minecraft:gravel"},
        {pos: [7, 2, 14], state: "minecraft:gravel"},
        {pos: [7, 2, 15], state: "minecraft:gravel"},
        {pos: [7, 2, 16], state: "minecraft:gravel"},
        {pos: [7, 2, 17], state: "minecraft:gravel"},
        {pos: [8, 2, 3], state: "minecraft:gravel"},
        {pos: [8, 2, 4], state: "minecraft:gravel"},
        {pos: [8, 2, 5], state: "minecraft:gravel"},
        {pos: [8, 2, 6], state: "minecraft:gravel"},
        {pos: [8, 2, 12], state: "minecraft:gravel"},
        {pos: [8, 2, 13], state: "minecraft:gravel"},
        {pos: [8, 2, 14], state: "minecraft:mud_bricks"},
        {pos: [8, 2, 15], state: "minecraft:mud_bricks"},
        {pos: [8, 2, 16], state: "minecraft:mud_bricks"},
        {pos: [8, 2, 17], state: "minecraft:gravel"},
        {pos: [9, 2, 1], state: "minecraft:gravel"},
        {pos: [9, 2, 2], state: "minecraft:gravel"},
        {pos: [9, 2, 3], state: "minecraft:gravel"},
        {pos: [9, 2, 4], state: "minecraft:gravel"},
        {pos: [9, 2, 5], state: "minecraft:mud_bricks"},
        {pos: [9, 2, 6], state: "minecraft:gravel"},
        {pos: [9, 2, 7], state: "minecraft:gravel"},
        {pos: [9, 2, 12], state: "minecraft:gravel"},
        {pos: [9, 2, 13], state: "minecraft:gravel"},
        {pos: [9, 2, 14], state: "minecraft:mud_bricks"},
        {pos: [9, 2, 15], state: "minecraft:mud_bricks"},
        {pos: [9, 2, 16], state: "minecraft:mud_bricks"},
        {pos: [9, 2, 17], state: "minecraft:gravel"},
        {pos: [9, 2, 18], state: "minecraft:gravel"},
        {pos: [10, 2, 0], state: "minecraft:gravel"},
        {pos: [10, 2, 1], state: "minecraft:gravel"},
        {pos: [10, 2, 2], state: "minecraft:mud_bricks"},
        {pos: [10, 2, 3], state: "minecraft:gravel"},
        {pos: [10, 2, 4], state: "minecraft:gravel"},
        {pos: [10, 2, 5], state: "minecraft:gravel"},
        {pos: [10, 2, 6], state: "minecraft:gravel"},
        {pos: [10, 2, 7], state: "minecraft:gravel"},
        {pos: [10, 2, 8], state: "minecraft:gravel"},
        {pos: [10, 2, 12], state: "minecraft:gravel"},
        {pos: [10, 2, 13], state: "minecraft:gravel"},
        {pos: [10, 2, 14], state: "minecraft:mud_bricks"},
        {pos: [10, 2, 15], state: "minecraft:mud_bricks"},
        {pos: [10, 2, 16], state: "minecraft:mud_bricks"},
        {pos: [10, 2, 17], state: "minecraft:gravel"},
        {pos: [10, 2, 18], state: "minecraft:gravel"},
        {pos: [11, 2, 0], state: "minecraft:gravel"},
        {pos: [11, 2, 1], state: "minecraft:mud_bricks"},
        {pos: [11, 2, 2], state: "minecraft:gravel"},
        {pos: [11, 2, 3], state: "minecraft:gravel"},
        {pos: [11, 2, 4], state: "minecraft:gravel"},
        {pos: [11, 2, 5], state: "minecraft:gravel"},
        {pos: [11, 2, 6], state: "minecraft:gravel"},
        {pos: [11, 2, 7], state: "minecraft:gravel"},
        {pos: [11, 2, 8], state: "minecraft:gravel"},
        {pos: [11, 2, 14], state: "minecraft:gravel"},
        {pos: [11, 2, 15], state: "minecraft:gravel"},
        {pos: [11, 2, 16], state: "minecraft:gravel"},
        {pos: [11, 2, 17], state: "minecraft:gravel"},
        {pos: [12, 2, 0], state: "minecraft:gravel"},
        {pos: [12, 2, 1], state: "minecraft:mud_bricks"},
        {pos: [12, 2, 2], state: "minecraft:gravel"},
        {pos: [12, 2, 3], state: "minecraft:gravel"},
        {pos: [12, 2, 4], state: "minecraft:gravel"},
        {pos: [12, 2, 5], state: "minecraft:gravel"},
        {pos: [12, 2, 6], state: "minecraft:gravel"},
        {pos: [12, 2, 7], state: "minecraft:gravel"},
        {pos: [12, 2, 8], state: "minecraft:mud_bricks"},
        {pos: [12, 2, 9], state: "minecraft:gravel"},
        {pos: [12, 2, 14], state: "minecraft:gravel"},
        {pos: [12, 2, 15], state: "minecraft:gravel"},
        {pos: [12, 2, 16], state: "minecraft:gravel"},
        {pos: [13, 2, 0], state: "minecraft:gravel"},
        {pos: [13, 2, 1], state: "minecraft:mud_bricks"},
        {pos: [13, 2, 2], state: "minecraft:gravel"},
        {pos: [13, 2, 3], state: "minecraft:gravel"},
        {pos: [13, 2, 4], state: "minecraft:gravel"},
        {pos: [13, 2, 5], state: "minecraft:gravel"},
        {pos: [13, 2, 6], state: "minecraft:gravel"},
        {pos: [13, 2, 7], state: "minecraft:mud_bricks"},
        {pos: [13, 2, 8], state: "minecraft:gravel"},
        {pos: [13, 2, 9], state: "minecraft:gravel"},
        {pos: [14, 2, 0], state: "minecraft:gravel"},
        {pos: [14, 2, 1], state: "minecraft:gravel"},
        {pos: [14, 2, 2], state: "minecraft:mud_bricks"},
        {pos: [14, 2, 3], state: "minecraft:mud_bricks"},
        {pos: [14, 2, 4], state: "minecraft:mud_bricks"},
        {pos: [14, 2, 5], state: "minecraft:gravel"},
        {pos: [14, 2, 6], state: "minecraft:mud_bricks"},
        {pos: [14, 2, 7], state: "minecraft:gravel"},
        {pos: [14, 2, 8], state: "minecraft:gravel"},
        {pos: [15, 2, 1], state: "minecraft:gravel"},
        {pos: [15, 2, 2], state: "minecraft:gravel"},
        {pos: [15, 2, 3], state: "minecraft:gravel"},
        {pos: [15, 2, 4], state: "minecraft:mud_bricks"},
        {pos: [15, 2, 5], state: "minecraft:gravel"},
        {pos: [15, 2, 6], state: "minecraft:gravel"},
        {pos: [16, 2, 3], state: "minecraft:gravel"},
        {pos: [16, 2, 4], state: "minecraft:gravel"},
        {pos: [16, 2, 5], state: "minecraft:gravel"},
        {pos: [1, 3, 4], state: "minecraft:gravel"},
        {pos: [1, 3, 5], state: "minecraft:gravel"},
        {pos: [1, 3, 6], state: "minecraft:gravel"},
        {pos: [1, 3, 7], state: "minecraft:gravel"},
        {pos: [1, 3, 11], state: "minecraft:gravel"},
        {pos: [1, 3, 12], state: "minecraft:gravel"},
        {pos: [1, 3, 13], state: "minecraft:gravel"},
        {pos: [1, 3, 14], state: "minecraft:gravel"},
        {pos: [1, 3, 15], state: "minecraft:gravel"},
        {pos: [1, 3, 16], state: "minecraft:gravel"},
        {pos: [1, 3, 17], state: "minecraft:gravel"},
        {pos: [2, 3, 4], state: "minecraft:gravel"},
        {pos: [2, 3, 5], state: "minecraft:mud_bricks"},
        {pos: [2, 3, 6], state: "minecraft:mud_bricks"},
        {pos: [2, 3, 7], state: "minecraft:mud_bricks"},
        {pos: [2, 3, 8], state: "minecraft:gravel"},
        {pos: [2, 3, 9], state: "minecraft:gravel"},
        {pos: [2, 3, 10], state: "minecraft:gravel"},
        {pos: [2, 3, 11], state: "minecraft:gravel"},
        {pos: [2, 3, 12], state: "minecraft:gravel"},
        {pos: [2, 3, 13], state: "minecraft:mud_bricks"},
        {pos: [2, 3, 14], state: "minecraft:gravel"},
        {pos: [2, 3, 15], state: "minecraft:mud_bricks"},
        {pos: [2, 3, 16], state: "minecraft:mud_bricks"},
        {pos: [2, 3, 17], state: "minecraft:gravel"},
        {pos: [2, 3, 18], state: "minecraft:gravel"},
        {pos: [3, 3, 4], state: "minecraft:gravel"},
        {pos: [3, 3, 5], state: "minecraft:mud_bricks"},
        {pos: [3, 3, 6], state: "minecraft:mud_bricks"},
        {pos: [3, 3, 7], state: "minecraft:mud_bricks"},
        {pos: [3, 3, 8], state: "minecraft:gravel"},
        {pos: [3, 3, 9], state: "minecraft:gravel"},
        {pos: [3, 3, 10], state: "minecraft:gravel"},
        {pos: [3, 3, 11], state: "minecraft:mud_bricks"},
        {pos: [3, 3, 12], state: "minecraft:mud_bricks"},
        {pos: [3, 3, 13], state: "minecraft:mud_bricks"},
        {pos: [3, 3, 14], state: "minecraft:mud_bricks"},
        {pos: [3, 3, 15], state: "minecraft:mud_bricks"},
        {pos: [3, 3, 16], state: "minecraft:mud_bricks"},
        {pos: [3, 3, 17], state: "minecraft:gravel"},
        {pos: [4, 3, 4], state: "minecraft:gravel"},
        {pos: [4, 3, 5], state: "minecraft:mud_bricks"},
        {pos: [4, 3, 6], state: "minecraft:gravel"},
        {pos: [4, 3, 7], state: "minecraft:mud_bricks"},
        {pos: [4, 3, 8], state: "minecraft:gravel"},
        {pos: [4, 3, 9], state: "minecraft:gravel"},
        {pos: [4, 3, 10], state: "minecraft:gravel"},
        {pos: [4, 3, 11], state: "minecraft:mud_bricks"},
        {pos: [4, 3, 12], state: "minecraft:mud_bricks"},
        {pos: [4, 3, 13], state: "minecraft:mud_bricks"},
        {pos: [4, 3, 14], state: "minecraft:mud_bricks"},
        {pos: [4, 3, 15], state: "minecraft:mud_bricks"},
        {pos: [4, 3, 16], state: "minecraft:mud_bricks"},
        {pos: [4, 3, 17], state: "minecraft:gravel"},
        {pos: [5, 3, 4], state: "minecraft:gravel"},
        {pos: [5, 3, 5], state: "minecraft:gravel"},
        {pos: [5, 3, 6], state: "minecraft:gravel"},
        {pos: [5, 3, 7], state: "minecraft:gravel"},
        {pos: [5, 3, 8], state: "minecraft:gravel"},
        {pos: [5, 3, 11], state: "minecraft:gravel"},
        {pos: [5, 3, 12], state: "minecraft:gravel"},
        {pos: [5, 3, 13], state: "minecraft:gravel"},
        {pos: [5, 3, 14], state: "minecraft:gravel"},
        {pos: [5, 3, 15], state: "minecraft:gravel"},
        {pos: [5, 3, 16], state: "minecraft:gravel"},
        {pos: [5, 3, 17], state: "minecraft:gravel"},
        {pos: [6, 3, 5], state: "minecraft:gravel"},
        {pos: [6, 3, 6], state: "minecraft:gravel"},
        {pos: [6, 3, 14], state: "minecraft:mud_bricks"},
        {pos: [6, 3, 15], state: "minecraft:gravel"},
        {pos: [6, 3, 16], state: "minecraft:gravel"},
        {pos: [7, 3, 4], state: "minecraft:gravel"},
        {pos: [7, 3, 5], state: "minecraft:gravel"},
        {pos: [7, 3, 13], state: "minecraft:gravel"},
        {pos: [7, 3, 14], state: "minecraft:mud_bricks"},
        {pos: [7, 3, 15], state: "minecraft:mud_bricks"},
        {pos: [7, 3, 16], state: "minecraft:gravel"},
        {pos: [7, 3, 17], state: "minecraft:gravel"},
        {pos: [8, 3, 3], state: "minecraft:gravel"},
        {pos: [8, 3, 4], state: "minecraft:gravel"},
        {pos: [8, 3, 5], state: "minecraft:gravel"},
        {pos: [8, 3, 6], state: "minecraft:gravel"},
        {pos: [8, 3, 12], state: "minecraft:gravel"},
        {pos: [8, 3, 13], state: "minecraft:gravel"},
        {pos: [8, 3, 14], state: "minecraft:mud_bricks"},
        {pos: [8, 3, 15], state: "minecraft:mud_bricks"},
        {pos: [8, 3, 16], state: "minecraft:mud_bricks"},
        {pos: [8, 3, 17], state: "minecraft:gravel"},
        {pos: [9, 3, 2], state: "minecraft:gravel"},
        {pos: [9, 3, 3], state: "minecraft:mud_bricks"},
        {pos: [9, 3, 4], state: "minecraft:mud_bricks"},
        {pos: [9, 3, 5], state: "minecraft:mud_bricks"},
        {pos: [9, 3, 6], state: "minecraft:gravel"},
        {pos: [9, 3, 7], state: "minecraft:gravel"},
        {pos: [9, 3, 12], state: "minecraft:gravel"},
        {pos: [9, 3, 13], state: "minecraft:gravel"},
        {pos: [9, 3, 14], state: "minecraft:mud_bricks"},
        {pos: [9, 3, 15], state: "minecraft:mud_bricks"},
        {pos: [9, 3, 16], state: "minecraft:mud_bricks"},
        {pos: [9, 3, 17], state: "minecraft:gravel"},
        {pos: [9, 3, 18], state: "minecraft:gravel"},
        {pos: [10, 3, 1], state: "minecraft:gravel"},
        {pos: [10, 3, 2], state: "minecraft:mud_bricks"},
        {pos: [10, 3, 3], state: "minecraft:gravel"},
        {pos: [10, 3, 4], state: "minecraft:gravel"},
        {pos: [10, 3, 5], state: "minecraft:gravel"},
        {pos: [10, 3, 6], state: "minecraft:gravel"},
        {pos: [10, 3, 7], state: "minecraft:gravel"},
        {pos: [10, 3, 8], state: "minecraft:gravel"},
        {pos: [10, 3, 12], state: "minecraft:gravel"},
        {pos: [10, 3, 13], state: "minecraft:gravel"},
        {pos: [10, 3, 14], state: "minecraft:gravel"},
        {pos: [10, 3, 15], state: "minecraft:mud_bricks"},
        {pos: [10, 3, 16], state: "minecraft:mud_bricks"},
        {pos: [10, 3, 17], state: "minecraft:gravel"},
        {pos: [10, 3, 18], state: "minecraft:gravel"},
        {pos: [11, 3, 0], state: "minecraft:gravel"},
        {pos: [11, 3, 1], state: "minecraft:mud_bricks"},
        {pos: [11, 3, 2], state: "minecraft:gravel"},
        {pos: [11, 3, 3], state: "minecraft:gravel"},
        {pos: [11, 3, 4], state: "minecraft:gravel"},
        {pos: [11, 3, 5], state: "minecraft:gravel"},
        {pos: [11, 3, 6], state: "minecraft:gravel"},
        {pos: [11, 3, 7], state: "minecraft:gravel"},
        {pos: [11, 3, 8], state: "minecraft:gravel"},
        {pos: [11, 3, 14], state: "minecraft:gravel"},
        {pos: [11, 3, 15], state: "minecraft:gravel"},
        {pos: [11, 3, 16], state: "minecraft:gravel"},
        {pos: [11, 3, 17], state: "minecraft:gravel"},
        {pos: [12, 3, 0], state: "minecraft:gravel"},
        {pos: [12, 3, 1], state: "minecraft:mud_bricks"},
        {pos: [12, 3, 2], state: "minecraft:gravel"},
        {pos: [12, 3, 3], state: "minecraft:gravel"},
        {pos: [12, 3, 4], state: "minecraft:gravel"},
        {pos: [12, 3, 5], state: "minecraft:gravel"},
        {pos: [12, 3, 6], state: "minecraft:gravel"},
        {pos: [12, 3, 7], state: "minecraft:gravel"},
        {pos: [12, 3, 8], state: "minecraft:mud_bricks"},
        {pos: [12, 3, 9], state: "minecraft:gravel"},
        {pos: [12, 3, 14], state: "minecraft:gravel"},
        {pos: [12, 3, 15], state: "minecraft:gravel"},
        {pos: [12, 3, 16], state: "minecraft:gravel"},
        {pos: [13, 3, 0], state: "minecraft:gravel"},
        {pos: [13, 3, 1], state: "minecraft:mud_bricks"},
        {pos: [13, 3, 2], state: "minecraft:gravel"},
        {pos: [13, 3, 3], state: "minecraft:gravel"},
        {pos: [13, 3, 4], state: "minecraft:gravel"},
        {pos: [13, 3, 5], state: "minecraft:gravel"},
        {pos: [13, 3, 6], state: "minecraft:gravel"},
        {pos: [13, 3, 7], state: "minecraft:mud_bricks"},
        {pos: [13, 3, 8], state: "minecraft:gravel"},
        {pos: [13, 3, 9], state: "minecraft:gravel"},
        {pos: [14, 3, 1], state: "minecraft:gravel"},
        {pos: [14, 3, 2], state: "minecraft:mud_bricks"},
        {pos: [14, 3, 3], state: "minecraft:mud_bricks"},
        {pos: [14, 3, 4], state: "minecraft:mud_bricks"},
        {pos: [14, 3, 5], state: "minecraft:mud_bricks"},
        {pos: [14, 3, 6], state: "minecraft:mud_bricks"},
        {pos: [14, 3, 7], state: "minecraft:gravel"},
        {pos: [14, 3, 8], state: "minecraft:gravel"},
        {pos: [15, 3, 2], state: "minecraft:gravel"},
        {pos: [15, 3, 3], state: "minecraft:gravel"},
        {pos: [15, 3, 4], state: "minecraft:gravel"},
        {pos: [15, 3, 5], state: "minecraft:gravel"},
        {pos: [15, 3, 6], state: "minecraft:gravel"},
        {pos: [1, 4, 5], state: "minecraft:gravel"},
        {pos: [1, 4, 6], state: "minecraft:gravel"},
        {pos: [1, 4, 7], state: "minecraft:gravel"},
        {pos: [1, 4, 13], state: "minecraft:gravel"},
        {pos: [1, 4, 14], state: "minecraft:gravel"},
        {pos: [1, 4, 15], state: "minecraft:gravel"},
        {pos: [1, 4, 16], state: "minecraft:gravel"},
        {pos: [2, 4, 4], state: "minecraft:gravel"},
        {pos: [2, 4, 5], state: "minecraft:mud_bricks"},
        {pos: [2, 4, 6], state: "minecraft:gravel"},
        {pos: [2, 4, 7], state: "minecraft:mud_bricks"},
        {pos: [2, 4, 8], state: "minecraft:gravel"},
        {pos: [2, 4, 9], state: "minecraft:gravel"},
        {pos: [2, 4, 10], state: "minecraft:gravel"},
        {pos: [2, 4, 12], state: "minecraft:gravel"},
        {pos: [2, 4, 13], state: "minecraft:gravel"},
        {pos: [2, 4, 14], state: "minecraft:gravel"},
        {pos: [2, 4, 15], state: "minecraft:gravel"},
        {pos: [2, 4, 16], state: "minecraft:mud_bricks"},
        {pos: [2, 4, 17], state: "minecraft:gravel"},
        {pos: [3, 4, 4], state: "minecraft:gravel"},
        {pos: [3, 4, 5], state: "minecraft:gravel"},
        {pos: [3, 4, 6], state: "minecraft:mud_bricks"},
        {pos: [3, 4, 7], state: "minecraft:mud_bricks"},
        {pos: [3, 4, 8], state: "minecraft:gravel"},
        {pos: [3, 4, 9], state: "minecraft:gravel"},
        {pos: [3, 4, 11], state: "minecraft:gravel"},
        {pos: [3, 4, 12], state: "minecraft:gravel"},
        {pos: [3, 4, 13], state: "minecraft:mud_bricks"},
        {pos: [3, 4, 14], state: "minecraft:mud_bricks"},
        {pos: [3, 4, 15], state: "minecraft:mud_bricks"},
        {pos: [3, 4, 16], state: "minecraft:mud_bricks"},
        {pos: [3, 4, 17], state: "minecraft:gravel"},
        {pos: [4, 4, 4], state: "minecraft:gravel"},
        {pos: [4, 4, 5], state: "minecraft:gravel"},
        {pos: [4, 4, 6], state: "minecraft:mud_bricks"},
        {pos: [4, 4, 7], state: "minecraft:mud_bricks"},
        {pos: [4, 4, 8], state: "minecraft:gravel"},
        {pos: [4, 4, 9], state: "minecraft:gravel"},
        {pos: [4, 4, 11], state: "minecraft:gravel"},
        {pos: [4, 4, 12], state: "minecraft:mud_bricks"},
        {pos: [4, 4, 13], state: "minecraft:mud_bricks"},
        {pos: [4, 4, 14], state: "minecraft:mud_bricks"},
        {pos: [4, 4, 15], state: "minecraft:mud_bricks"},
        {pos: [4, 4, 16], state: "minecraft:mud_bricks"},
        {pos: [4, 4, 17], state: "minecraft:gravel"},
        {pos: [5, 4, 4], state: "minecraft:gravel"},
        {pos: [5, 4, 5], state: "minecraft:gravel"},
        {pos: [5, 4, 6], state: "minecraft:gravel"},
        {pos: [5, 4, 7], state: "minecraft:gravel"},
        {pos: [5, 4, 8], state: "minecraft:gravel"},
        {pos: [5, 4, 12], state: "minecraft:gravel"},
        {pos: [5, 4, 13], state: "minecraft:gravel"},
        {pos: [5, 4, 14], state: "minecraft:mud_bricks"},
        {pos: [5, 4, 15], state: "minecraft:mud_bricks"},
        {pos: [5, 4, 16], state: "minecraft:mud_bricks"},
        {pos: [5, 4, 17], state: "minecraft:gravel"},
        {pos: [6, 4, 6], state: "minecraft:gravel"},
        {pos: [6, 4, 14], state: "minecraft:mud_bricks"},
        {pos: [6, 4, 15], state: "minecraft:mud_bricks"},
        {pos: [6, 4, 16], state: "minecraft:mud_bricks"},
        {pos: [7, 4, 13], state: "minecraft:gravel"},
        {pos: [7, 4, 14], state: "minecraft:mud_bricks"},
        {pos: [7, 4, 15], state: "minecraft:mud_bricks"},
        {pos: [7, 4, 16], state: "minecraft:mud_bricks"},
        {pos: [7, 4, 17], state: "minecraft:gravel"},
        {pos: [8, 4, 5], state: "minecraft:gravel"},
        {pos: [8, 4, 13], state: "minecraft:gravel"},
        {pos: [8, 4, 14], state: "minecraft:mud_bricks"},
        {pos: [8, 4, 15], state: "minecraft:mud_bricks"},
        {pos: [8, 4, 16], state: "minecraft:mud_bricks"},
        {pos: [8, 4, 17], state: "minecraft:gravel"},
        {pos: [9, 4, 3], state: "minecraft:gravel"},
        {pos: [9, 4, 4], state: "minecraft:gravel"},
        {pos: [9, 4, 5], state: "minecraft:mud_bricks"},
        {pos: [9, 4, 6], state: "minecraft:gravel"},
        {pos: [9, 4, 7], state: "minecraft:gravel"},
        {pos: [9, 4, 12], state: "minecraft:gravel"},
        {pos: [9, 4, 13], state: "minecraft:gravel"},
        {pos: [9, 4, 14], state: "minecraft:mud_bricks"},
        {pos: [9, 4, 15], state: "minecraft:mud_bricks"},
        {pos: [9, 4, 16], state: "minecraft:mud_bricks"},
        {pos: [9, 4, 17], state: "minecraft:gravel"},
        {pos: [10, 4, 2], state: "minecraft:gravel"},
        {pos: [10, 4, 3], state: "minecraft:mud_bricks"},
        {pos: [10, 4, 4], state: "minecraft:mud_bricks"},
        {pos: [10, 4, 5], state: "minecraft:mud_bricks"},
        {pos: [10, 4, 6], state: "minecraft:mud_bricks"},
        {pos: [10, 4, 7], state: "minecraft:gravel"},
        {pos: [10, 4, 12], state: "minecraft:gravel"},
        {pos: [10, 4, 13], state: "minecraft:gravel"},
        {pos: [10, 4, 14], state: "minecraft:gravel"},
        {pos: [10, 4, 15], state: "minecraft:gravel"},
        {pos: [10, 4, 16], state: "minecraft:mud_bricks"},
        {pos: [10, 4, 17], state: "minecraft:gravel"},
        {pos: [11, 4, 1], state: "minecraft:gravel"},
        {pos: [11, 4, 2], state: "minecraft:mud_bricks"},
        {pos: [11, 4, 3], state: "minecraft:gravel"},
        {pos: [11, 4, 4], state: "minecraft:mud_bricks"},
        {pos: [11, 4, 5], state: "minecraft:gravel"},
        {pos: [11, 4, 6], state: "minecraft:mud_bricks"},
        {pos: [11, 4, 7], state: "minecraft:mud_bricks"},
        {pos: [11, 4, 8], state: "minecraft:gravel"},
        {pos: [11, 4, 14], state: "minecraft:gravel"},
        {pos: [11, 4, 15], state: "minecraft:gravel"},
        {pos: [11, 4, 16], state: "minecraft:gravel"},
        {pos: [12, 4, 1], state: "minecraft:gravel"},
        {pos: [12, 4, 2], state: "minecraft:mud_bricks"},
        {pos: [12, 4, 3], state: "minecraft:gravel"},
        {pos: [12, 4, 4], state: "minecraft:mud_bricks"},
        {pos: [12, 4, 5], state: "minecraft:mud_bricks"},
        {pos: [12, 4, 6], state: "minecraft:mud_bricks"},
        {pos: [12, 4, 7], state: "minecraft:mud_bricks"},
        {pos: [12, 4, 8], state: "minecraft:gravel"},
        {pos: [13, 4, 1], state: "minecraft:gravel"},
        {pos: [13, 4, 2], state: "minecraft:mud_bricks"},
        {pos: [13, 4, 3], state: "minecraft:mud_bricks"},
        {pos: [13, 4, 4], state: "minecraft:gravel"},
        {pos: [13, 4, 5], state: "minecraft:mud_bricks"},
        {pos: [13, 4, 6], state: "minecraft:mud_bricks"},
        {pos: [13, 4, 7], state: "minecraft:mud_bricks"},
        {pos: [13, 4, 8], state: "minecraft:gravel"},
        {pos: [14, 4, 2], state: "minecraft:gravel"},
        {pos: [14, 4, 3], state: "minecraft:gravel"},
        {pos: [14, 4, 4], state: "minecraft:gravel"},
        {pos: [14, 4, 5], state: "minecraft:gravel"},
        {pos: [14, 4, 6], state: "minecraft:gravel"},
        {pos: [14, 4, 7], state: "minecraft:gravel"},
        {pos: [15, 4, 4], state: "minecraft:gravel"},
        {pos: [1, 5, 5], state: "minecraft:gravel"},
        {pos: [1, 5, 6], state: "minecraft:gravel"},
        {pos: [1, 5, 7], state: "minecraft:gravel"},
        {pos: [1, 5, 13], state: "minecraft:gravel"},
        {pos: [1, 5, 14], state: "minecraft:gravel"},
        {pos: [1, 5, 15], state: "minecraft:gravel"},
        {pos: [1, 5, 16], state: "minecraft:gravel"},
        {pos: [2, 5, 4], state: "minecraft:gravel"},
        {pos: [2, 5, 5], state: "minecraft:mud_bricks"},
        {pos: [2, 5, 6], state: "minecraft:gravel"},
        {pos: [2, 5, 7], state: "minecraft:gravel"},
        {pos: [2, 5, 8], state: "minecraft:gravel"},
        {pos: [2, 5, 9], state: "minecraft:gravel"},
        {pos: [2, 5, 12], state: "minecraft:gravel"},
        {pos: [2, 5, 13], state: "minecraft:gravel"},
        {pos: [2, 5, 14], state: "minecraft:gravel"},
        {pos: [2, 5, 15], state: "minecraft:gravel"},
        {pos: [2, 5, 16], state: "minecraft:mud_bricks"},
        {pos: [2, 5, 17], state: "minecraft:gravel"},
        {pos: [3, 5, 4], state: "minecraft:gravel"},
        {pos: [3, 5, 5], state: "minecraft:gravel"},
        {pos: [3, 5, 6], state: "minecraft:mud_bricks"},
        {pos: [3, 5, 7], state: "minecraft:gravel"},
        {pos: [3, 5, 8], state: "minecraft:gravel"},
        {pos: [3, 5, 9], state: "minecraft:gravel"},
        {pos: [3, 5, 12], state: "minecraft:gravel"},
        {pos: [3, 5, 13], state: "minecraft:gravel"},
        {pos: [3, 5, 14], state: "minecraft:mud_bricks"},
        {pos: [3, 5, 15], state: "minecraft:gravel"},
        {pos: [3, 5, 16], state: "minecraft:mud_bricks"},
        {pos: [3, 5, 17], state: "minecraft:gravel"},
        {pos: [4, 5, 4], state: "minecraft:gravel"},
        {pos: [4, 5, 5], state: "minecraft:gravel"},
        {pos: [4, 5, 6], state: "minecraft:gravel"},
        {pos: [4, 5, 7], state: "minecraft:gravel"},
        {pos: [4, 5, 8], state: "minecraft:gravel"},
        {pos: [4, 5, 9], state: "minecraft:gravel"},
        {pos: [4, 5, 12], state: "minecraft:gravel"},
        {pos: [4, 5, 13], state: "minecraft:gravel"},
        {pos: [4, 5, 14], state: "minecraft:mud_bricks"},
        {pos: [4, 5, 15], state: "minecraft:mud_bricks"},
        {pos: [4, 5, 16], state: "minecraft:mud_bricks"},
        {pos: [4, 5, 17], state: "minecraft:gravel"},
        {pos: [5, 5, 4], state: "minecraft:gravel"},
        {pos: [5, 5, 5], state: "minecraft:gravel"},
        {pos: [5, 5, 6], state: "minecraft:gravel"},
        {pos: [5, 5, 7], state: "minecraft:gravel"},
        {pos: [5, 5, 8], state: "minecraft:gravel"},
        {pos: [5, 5, 14], state: "minecraft:gravel"},
        {pos: [5, 5, 15], state: "minecraft:mud_bricks"},
        {pos: [5, 5, 16], state: "minecraft:mud_bricks"},
        {pos: [5, 5, 17], state: "minecraft:gravel"},
        {pos: [6, 5, 14], state: "minecraft:gravel"},
        {pos: [6, 5, 15], state: "minecraft:mud_bricks"},
        {pos: [6, 5, 16], state: "minecraft:mud_bricks"},
        {pos: [7, 5, 13], state: "minecraft:gravel"},
        {pos: [7, 5, 14], state: "minecraft:mud_bricks"},
        {pos: [7, 5, 15], state: "minecraft:mud_bricks"},
        {pos: [7, 5, 16], state: "minecraft:mud_bricks"},
        {pos: [7, 5, 17], state: "minecraft:gravel"},
        {pos: [8, 5, 13], state: "minecraft:gravel"},
        {pos: [8, 5, 14], state: "minecraft:mud_bricks"},
        {pos: [8, 5, 15], state: "minecraft:mud_bricks"},
        {pos: [8, 5, 16], state: "minecraft:mud_bricks"},
        {pos: [8, 5, 17], state: "minecraft:gravel"},
        {pos: [9, 5, 4], state: "minecraft:gravel"},
        {pos: [9, 5, 5], state: "minecraft:gravel"},
        {pos: [9, 5, 6], state: "minecraft:gravel"},
        {pos: [9, 5, 7], state: "minecraft:gravel"},
        {pos: [9, 5, 12], state: "minecraft:gravel"},
        {pos: [9, 5, 13], state: "minecraft:gravel"},
        {pos: [9, 5, 14], state: "minecraft:mud_bricks"},
        {pos: [9, 5, 15], state: "minecraft:mud_bricks"},
        {pos: [9, 5, 16], state: "minecraft:mud_bricks"},
        {pos: [9, 5, 17], state: "minecraft:gravel"},
        {pos: [10, 5, 3], state: "minecraft:gravel"},
        {pos: [10, 5, 4], state: "minecraft:mud_bricks"},
        {pos: [10, 5, 5], state: "minecraft:mud_bricks"},
        {pos: [10, 5, 6], state: "minecraft:mud_bricks"},
        {pos: [10, 5, 7], state: "minecraft:gravel"},
        {pos: [10, 5, 12], state: "minecraft:gravel"},
        {pos: [10, 5, 13], state: "minecraft:gravel"},
        {pos: [10, 5, 14], state: "minecraft:gravel"},
        {pos: [10, 5, 15], state: "minecraft:gravel"},
        {pos: [10, 5, 16], state: "minecraft:mud_bricks"},
        {pos: [10, 5, 17], state: "minecraft:gravel"},
        {pos: [11, 5, 2], state: "minecraft:gravel"},
        {pos: [11, 5, 3], state: "minecraft:gravel"},
        {pos: [11, 5, 4], state: "minecraft:mud_bricks"},
        {pos: [11, 5, 5], state: "minecraft:gravel"},
        {pos: [11, 5, 6], state: "minecraft:mud_bricks"},
        {pos: [11, 5, 7], state: "minecraft:gravel"},
        {pos: [11, 5, 14], state: "minecraft:gravel"},
        {pos: [11, 5, 15], state: "minecraft:gravel"},
        {pos: [11, 5, 16], state: "minecraft:gravel"},
        {pos: [12, 5, 2], state: "minecraft:gravel"},
        {pos: [12, 5, 3], state: "minecraft:gravel"},
        {pos: [12, 5, 4], state: "minecraft:gravel"},
        {pos: [12, 5, 5], state: "minecraft:mud_bricks"},
        {pos: [12, 5, 6], state: "minecraft:mud_bricks"},
        {pos: [12, 5, 7], state: "minecraft:gravel"},
        {pos: [13, 5, 2], state: "minecraft:gravel"},
        {pos: [13, 5, 3], state: "minecraft:gravel"},
        {pos: [13, 5, 4], state: "minecraft:gravel"},
        {pos: [13, 5, 5], state: "minecraft:gravel"},
        {pos: [13, 5, 6], state: "minecraft:gravel"},
        {pos: [13, 5, 7], state: "minecraft:gravel"},
        {pos: [14, 5, 3], state: "minecraft:gravel"},
        {pos: [1, 6, 6], state: "minecraft:gravel"},
        {pos: [1, 6, 7], state: "minecraft:gravel"},
        {pos: [1, 6, 13], state: "minecraft:gravel"},
        {pos: [1, 6, 14], state: "minecraft:gravel"},
        {pos: [1, 6, 15], state: "minecraft:gravel"},
        {pos: [1, 6, 16], state: "minecraft:gravel"},
        {pos: [2, 6, 5], state: "minecraft:gravel"},
        {pos: [2, 6, 6], state: "minecraft:mud_bricks"},
        {pos: [2, 6, 7], state: "minecraft:gravel"},
        {pos: [2, 6, 8], state: "minecraft:gravel"},
        {pos: [2, 6, 12], state: "minecraft:gravel"},
        {pos: [2, 6, 13], state: "minecraft:gravel"},
        {pos: [2, 6, 14], state: "minecraft:mud_bricks"},
        {pos: [2, 6, 15], state: "minecraft:gravel"},
        {pos: [2, 6, 16], state: "minecraft:mud_bricks"},
        {pos: [2, 6, 17], state: "minecraft:gravel"},
        {pos: [3, 6, 4], state: "minecraft:gravel"},
        {pos: [3, 6, 5], state: "minecraft:mud_bricks"},
        {pos: [3, 6, 6], state: "minecraft:mud_bricks"},
        {pos: [3, 6, 7], state: "minecraft:mud_bricks"},
        {pos: [3, 6, 8], state: "minecraft:gravel"},
        {pos: [3, 6, 9], state: "minecraft:gravel"},
        {pos: [3, 6, 12], state: "minecraft:gravel"},
        {pos: [3, 6, 13], state: "minecraft:gravel"},
        {pos: [3, 6, 14], state: "minecraft:mud_bricks"},
        {pos: [3, 6, 15], state: "minecraft:gravel"},
        {pos: [3, 6, 16], state: "minecraft:mud_bricks"},
        {pos: [3, 6, 17], state: "minecraft:gravel"},
        {pos: [4, 6, 4], state: "minecraft:gravel"},
        {pos: [4, 6, 5], state: "minecraft:mud_bricks"},
        {pos: [4, 6, 6], state: "minecraft:gravel"},
        {pos: [4, 6, 7], state: "minecraft:gravel"},
        {pos: [4, 6, 8], state: "minecraft:gravel"},
        {pos: [4, 6, 13], state: "minecraft:gravel"},
        {pos: [4, 6, 14], state: "minecraft:mud_bricks"},
        {pos: [4, 6, 15], state: "minecraft:mud_bricks"},
        {pos: [4, 6, 16], state: "minecraft:mud_bricks"},
        {pos: [4, 6, 17], state: "minecraft:gravel"},
        {pos: [5, 6, 4], state: "minecraft:gravel"},
        {pos: [5, 6, 5], state: "minecraft:gravel"},
        {pos: [5, 6, 6], state: "minecraft:gravel"},
        {pos: [5, 6, 7], state: "minecraft:gravel"},
        {pos: [5, 6, 8], state: "minecraft:gravel"},
        {pos: [5, 6, 14], state: "minecraft:gravel"},
        {pos: [5, 6, 15], state: "minecraft:gravel"},
        {pos: [5, 6, 16], state: "minecraft:gravel"},
        {pos: [6, 6, 14], state: "minecraft:gravel"},
        {pos: [6, 6, 15], state: "minecraft:gravel"},
        {pos: [6, 6, 16], state: "minecraft:gravel"},
        {pos: [7, 6, 14], state: "minecraft:gravel"},
        {pos: [7, 6, 15], state: "minecraft:mud_bricks"},
        {pos: [7, 6, 16], state: "minecraft:mud_bricks"},
        {pos: [7, 6, 17], state: "minecraft:gravel"},
        {pos: [8, 6, 13], state: "minecraft:gravel"},
        {pos: [8, 6, 14], state: "minecraft:mud_bricks"},
        {pos: [8, 6, 15], state: "minecraft:mud_bricks"},
        {pos: [8, 6, 16], state: "minecraft:mud_bricks"},
        {pos: [8, 6, 17], state: "minecraft:gravel"},
        {pos: [9, 6, 4], state: "minecraft:gravel"},
        {pos: [9, 6, 5], state: "minecraft:gravel"},
        {pos: [9, 6, 6], state: "minecraft:gravel"},
        {pos: [9, 6, 12], state: "minecraft:gravel"},
        {pos: [9, 6, 13], state: "minecraft:gravel"},
        {pos: [9, 6, 14], state: "minecraft:mud_bricks"},
        {pos: [9, 6, 15], state: "minecraft:gravel"},
        {pos: [9, 6, 16], state: "minecraft:gravel"},
        {pos: [9, 6, 17], state: "minecraft:gravel"},
        {pos: [10, 6, 3], state: "minecraft:gravel"},
        {pos: [10, 6, 4], state: "minecraft:mud_bricks"},
        {pos: [10, 6, 5], state: "minecraft:mud_bricks"},
        {pos: [10, 6, 6], state: "minecraft:mud_bricks"},
        {pos: [10, 6, 7], state: "minecraft:gravel"},
        {pos: [10, 6, 12], state: "minecraft:gravel"},
        {pos: [10, 6, 13], state: "minecraft:gravel"},
        {pos: [10, 6, 14], state: "minecraft:gravel"},
        {pos: [10, 6, 15], state: "minecraft:mud_bricks"},
        {pos: [10, 6, 16], state: "minecraft:mud_bricks"},
        {pos: [10, 6, 17], state: "minecraft:gravel"},
        {pos: [11, 6, 3], state: "minecraft:gravel"},
        {pos: [11, 6, 4], state: "minecraft:mud_bricks"},
        {pos: [11, 6, 5], state: "minecraft:gravel"},
        {pos: [11, 6, 6], state: "minecraft:mud_bricks"},
        {pos: [11, 6, 7], state: "minecraft:gravel"},
        {pos: [11, 6, 14], state: "minecraft:gravel"},
        {pos: [11, 6, 15], state: "minecraft:gravel"},
        {pos: [11, 6, 16], state: "minecraft:gravel"},
        {pos: [12, 6, 3], state: "minecraft:gravel"},
        {pos: [12, 6, 4], state: "minecraft:gravel"},
        {pos: [12, 6, 5], state: "minecraft:mud_bricks"},
        {pos: [12, 6, 6], state: "minecraft:mud_bricks"},
        {pos: [12, 6, 7], state: "minecraft:gravel"},
        {pos: [13, 6, 5], state: "minecraft:gravel"},
        {pos: [13, 6, 6], state: "minecraft:gravel"},
        {pos: [1, 7, 6], state: "minecraft:gravel"},
        {pos: [1, 7, 7], state: "minecraft:gravel"},
        {pos: [1, 7, 13], state: "minecraft:gravel"},
        {pos: [1, 7, 14], state: "minecraft:gravel"},
        {pos: [1, 7, 15], state: "minecraft:gravel"},
        {pos: [1, 7, 16], state: "minecraft:gravel"},
        {pos: [2, 7, 5], state: "minecraft:gravel"},
        {pos: [2, 7, 6], state: "minecraft:mud_bricks"},
        {pos: [2, 7, 7], state: "minecraft:mud_bricks"},
        {pos: [2, 7, 8], state: "minecraft:gravel"},
        {pos: [2, 7, 13], state: "minecraft:gravel"},
        {pos: [2, 7, 14], state: "minecraft:mud_bricks"},
        {pos: [2, 7, 15], state: "minecraft:mud_bricks"},
        {pos: [2, 7, 16], state: "minecraft:mud_bricks"},
        {pos: [2, 7, 17], state: "minecraft:gravel"},
        {pos: [3, 7, 4], state: "minecraft:gravel"},
        {pos: [3, 7, 5], state: "minecraft:mud_bricks"},
        {pos: [3, 7, 6], state: "minecraft:mud_bricks"},
        {pos: [3, 7, 7], state: "minecraft:mud_bricks"},
        {pos: [3, 7, 8], state: "minecraft:mud_bricks"},
        {pos: [3, 7, 12], state: "minecraft:gravel"},
        {pos: [3, 7, 13], state: "minecraft:gravel"},
        {pos: [3, 7, 14], state: "minecraft:mud_bricks"},
        {pos: [3, 7, 15], state: "minecraft:mud_bricks"},
        {pos: [3, 7, 16], state: "minecraft:mud_bricks"},
        {pos: [3, 7, 17], state: "minecraft:gravel"},
        {pos: [4, 7, 4], state: "minecraft:gravel"},
        {pos: [4, 7, 5], state: "minecraft:mud_bricks"},
        {pos: [4, 7, 6], state: "minecraft:mud_bricks"},
        {pos: [4, 7, 7], state: "minecraft:mud_bricks"},
        {pos: [4, 7, 8], state: "minecraft:gravel"},
        {pos: [4, 7, 13], state: "minecraft:gravel"},
        {pos: [4, 7, 14], state: "minecraft:mud_bricks"},
        {pos: [4, 7, 15], state: "minecraft:mud_bricks"},
        {pos: [4, 7, 16], state: "minecraft:mud_bricks"},
        {pos: [4, 7, 17], state: "minecraft:gravel"},
        {pos: [5, 7, 5], state: "minecraft:gravel"},
        {pos: [5, 7, 6], state: "minecraft:gravel"},
        {pos: [5, 7, 7], state: "minecraft:gravel"},
        {pos: [5, 7, 8], state: "minecraft:gravel"},
        {pos: [5, 7, 14], state: "minecraft:gravel"},
        {pos: [5, 7, 15], state: "minecraft:gravel"},
        {pos: [5, 7, 16], state: "minecraft:gravel"},
        {pos: [6, 7, 14], state: "minecraft:gravel"},
        {pos: [6, 7, 15], state: "minecraft:gravel"},
        {pos: [6, 7, 16], state: "minecraft:gravel"},
        {pos: [7, 7, 14], state: "minecraft:gravel"},
        {pos: [7, 7, 15], state: "minecraft:gravel"},
        {pos: [7, 7, 16], state: "minecraft:gravel"},
        {pos: [8, 7, 13], state: "minecraft:gravel"},
        {pos: [8, 7, 14], state: "minecraft:mud_bricks"},
        {pos: [8, 7, 15], state: "minecraft:mud_bricks"},
        {pos: [8, 7, 16], state: "minecraft:gravel"},
        {pos: [8, 7, 17], state: "minecraft:gravel"},
        {pos: [9, 7, 4], state: "minecraft:gravel"},
        {pos: [9, 7, 5], state: "minecraft:gravel"},
        {pos: [9, 7, 12], state: "minecraft:gravel"},
        {pos: [9, 7, 13], state: "minecraft:gravel"},
        {pos: [9, 7, 14], state: "minecraft:mud_bricks"},
        {pos: [9, 7, 15], state: "minecraft:gravel"},
        {pos: [9, 7, 16], state: "minecraft:gravel"},
        {pos: [9, 7, 17], state: "minecraft:gravel"},
        {pos: [10, 7, 3], state: "minecraft:gravel"},
        {pos: [10, 7, 4], state: "minecraft:mud_bricks"},
        {pos: [10, 7, 5], state: "minecraft:mud_bricks"},
        {pos: [10, 7, 6], state: "minecraft:mud_bricks"},
        {pos: [10, 7, 7], state: "minecraft:gravel"},
        {pos: [10, 7, 13], state: "minecraft:gravel"},
        {pos: [10, 7, 14], state: "minecraft:mud_bricks"},
        {pos: [10, 7, 15], state: "minecraft:mud_bricks"},
        {pos: [10, 7, 16], state: "minecraft:mud_bricks"},
        {pos: [10, 7, 17], state: "minecraft:gravel"},
        {pos: [11, 7, 3], state: "minecraft:gravel"},
        {pos: [11, 7, 4], state: "minecraft:mud_bricks"},
        {pos: [11, 7, 5], state: "minecraft:gravel"},
        {pos: [11, 7, 6], state: "minecraft:mud_bricks"},
        {pos: [11, 7, 7], state: "minecraft:gravel"},
        {pos: [11, 7, 14], state: "minecraft:gravel"},
        {pos: [11, 7, 15], state: "minecraft:gravel"},
        {pos: [11, 7, 16], state: "minecraft:gravel"},
        {pos: [12, 7, 4], state: "minecraft:gravel"},
        {pos: [12, 7, 5], state: "minecraft:gravel"},
        {pos: [12, 7, 6], state: "minecraft:mud_bricks"},
        {pos: [12, 7, 7], state: "minecraft:gravel"},
        {pos: [13, 7, 6], state: "minecraft:gravel"},
        {pos: [1, 8, 7], state: "minecraft:gravel"},
        {pos: [1, 8, 14], state: "minecraft:gravel"},
        {pos: [1, 8, 15], state: "minecraft:gravel"},
        {pos: [1, 8, 16], state: "minecraft:gravel"},
        {pos: [2, 8, 5], state: "minecraft:gravel"},
        {pos: [2, 8, 6], state: "minecraft:mud_bricks"},
        {pos: [2, 8, 7], state: "minecraft:mud_bricks"},
        {pos: [2, 8, 8], state: "minecraft:gravel"},
        {pos: [2, 8, 9], state: "minecraft:mud_bricks"},
        {pos: [2, 8, 13], state: "minecraft:gravel"},
        {pos: [2, 8, 14], state: "minecraft:mud_bricks"},
        {pos: [2, 8, 15], state: "minecraft:mud_bricks"},
        {pos: [2, 8, 16], state: "minecraft:mud_bricks"},
        {pos: [2, 8, 17], state: "minecraft:gravel"},
        {pos: [3, 8, 4], state: "minecraft:gravel"},
        {pos: [3, 8, 5], state: "minecraft:mud_bricks"},
        {pos: [3, 8, 6], state: "minecraft:mud_bricks"},
        {pos: [3, 8, 7], state: "minecraft:mud_bricks"},
        {pos: [3, 8, 8], state: "minecraft:mud_bricks"},
        {pos: [3, 8, 9], state: "minecraft:mud_bricks"},
        {pos: [3, 8, 13], state: "minecraft:gravel"},
        {pos: [3, 8, 14], state: "minecraft:mud_bricks"},
        {pos: [3, 8, 15], state: "minecraft:mud_bricks"},
        {pos: [3, 8, 16], state: "minecraft:mud_bricks"},
        {pos: [3, 8, 17], state: "minecraft:gravel"},
        {pos: [4, 8, 4], state: "minecraft:gravel"},
        {pos: [4, 8, 5], state: "minecraft:mud_bricks"},
        {pos: [4, 8, 6], state: "minecraft:mud_bricks"},
        {pos: [4, 8, 7], state: "minecraft:mud_bricks"},
        {pos: [4, 8, 8], state: "minecraft:gravel"},
        {pos: [4, 8, 13], state: "minecraft:gravel"},
        {pos: [4, 8, 14], state: "minecraft:gravel"},
        {pos: [4, 8, 15], state: "minecraft:mud_bricks"},
        {pos: [4, 8, 16], state: "minecraft:mud_bricks"},
        {pos: [4, 8, 17], state: "minecraft:gravel"},
        {pos: [5, 8, 5], state: "minecraft:gravel"},
        {pos: [5, 8, 6], state: "minecraft:gravel"},
        {pos: [5, 8, 7], state: "minecraft:gravel"},
        {pos: [5, 8, 14], state: "minecraft:gravel"},
        {pos: [5, 8, 15], state: "minecraft:gravel"},
        {pos: [5, 8, 16], state: "minecraft:gravel"},
        {pos: [6, 8, 14], state: "minecraft:gravel"},
        {pos: [6, 8, 15], state: "minecraft:gravel"},
        {pos: [6, 8, 16], state: "minecraft:gravel"},
        {pos: [7, 8, 14], state: "minecraft:gravel"},
        {pos: [7, 8, 15], state: "minecraft:gravel"},
        {pos: [7, 8, 16], state: "minecraft:gravel"},
        {pos: [8, 8, 13], state: "minecraft:gravel"},
        {pos: [8, 8, 14], state: "minecraft:mud_bricks"},
        {pos: [8, 8, 15], state: "minecraft:mud_bricks"},
        {pos: [8, 8, 16], state: "minecraft:gravel"},
        {pos: [8, 8, 17], state: "minecraft:gravel"},
        {pos: [9, 8, 4], state: "minecraft:gravel"},
        {pos: [9, 8, 5], state: "minecraft:gravel"},
        {pos: [9, 8, 13], state: "minecraft:gravel"},
        {pos: [9, 8, 14], state: "minecraft:mud_bricks"},
        {pos: [9, 8, 15], state: "minecraft:mud_bricks"},
        {pos: [9, 8, 16], state: "minecraft:mud_bricks"},
        {pos: [9, 8, 17], state: "minecraft:gravel"},
        {pos: [10, 8, 3], state: "minecraft:gravel"},
        {pos: [10, 8, 4], state: "minecraft:mud_bricks"},
        {pos: [10, 8, 5], state: "minecraft:mud_bricks"},
        {pos: [10, 8, 6], state: "minecraft:mud_bricks"},
        {pos: [10, 8, 7], state: "minecraft:gravel"},
        {pos: [10, 8, 13], state: "minecraft:gravel"},
        {pos: [10, 8, 14], state: "minecraft:mud_bricks"},
        {pos: [10, 8, 15], state: "minecraft:mud_bricks"},
        {pos: [10, 8, 16], state: "minecraft:mud_bricks"},
        {pos: [10, 8, 17], state: "minecraft:gravel"},
        {pos: [11, 8, 3], state: "minecraft:gravel"},
        {pos: [11, 8, 4], state: "minecraft:mud_bricks"},
        {pos: [11, 8, 5], state: "minecraft:gravel"},
        {pos: [11, 8, 6], state: "minecraft:mud_bricks"},
        {pos: [11, 8, 7], state: "minecraft:gravel"},
        {pos: [11, 8, 14], state: "minecraft:gravel"},
        {pos: [11, 8, 15], state: "minecraft:gravel"},
        {pos: [11, 8, 16], state: "minecraft:gravel"},
        {pos: [12, 8, 5], state: "minecraft:gravel"},
        {pos: [12, 8, 6], state: "minecraft:mud_bricks"},
        {pos: [12, 8, 7], state: "minecraft:gravel"},
        {pos: [13, 8, 6], state: "minecraft:gravel"},
        {pos: [1, 9, 14], state: "minecraft:gravel"},
        {pos: [1, 9, 15], state: "minecraft:gravel"},
        {pos: [2, 9, 5], state: "minecraft:gravel"},
        {pos: [2, 9, 6], state: "minecraft:mud_bricks"},
        {pos: [2, 9, 7], state: "minecraft:mud_bricks"},
        {pos: [2, 9, 8], state: "minecraft:mud_bricks"},
        {pos: [2, 9, 9], state: "minecraft:mud_bricks"},
        {pos: [2, 9, 10], state: "minecraft:mud_bricks"},
        {pos: [2, 9, 11], state: "minecraft:mud_bricks"},
        {pos: [2, 9, 12], state: "minecraft:mud_bricks"},
        {pos: [2, 9, 13], state: "minecraft:mud_bricks"},
        {pos: [2, 9, 14], state: "minecraft:mud_bricks"},
        {pos: [2, 9, 15], state: "minecraft:mud_bricks"},
        {pos: [2, 9, 16], state: "minecraft:mud_bricks"},
        {pos: [2, 9, 17], state: "minecraft:gravel"},
        {pos: [3, 9, 4], state: "minecraft:gravel"},
        {pos: [3, 9, 5], state: "minecraft:mud_bricks"},
        {pos: [3, 9, 6], state: "minecraft:mud_bricks"},
        {pos: [3, 9, 7], state: "minecraft:mud_bricks"},
        {pos: [3, 9, 8], state: "minecraft:mud_bricks"},
        {pos: [3, 9, 9], state: "minecraft:mud_bricks"},
        {pos: [3, 9, 10], state: "minecraft:mud_bricks"},
        {pos: [3, 9, 11], state: "minecraft:mud_bricks"},
        {pos: [3, 9, 12], state: "minecraft:mud_bricks"},
        {pos: [3, 9, 13], state: "minecraft:mud_bricks"},
        {pos: [3, 9, 14], state: "minecraft:mud_bricks"},
        {pos: [3, 9, 15], state: "minecraft:mud_bricks"},
        {pos: [3, 9, 16], state: "minecraft:mud_bricks"},
        {pos: [3, 9, 17], state: "minecraft:gravel"},
        {pos: [4, 9, 4], state: "minecraft:gravel"},
        {pos: [4, 9, 5], state: "minecraft:mud_bricks"},
        {pos: [4, 9, 6], state: "minecraft:mud_bricks"},
        {pos: [4, 9, 7], state: "minecraft:mud_bricks"},
        {pos: [4, 9, 8], state: "minecraft:gravel"},
        {pos: [4, 9, 10], state: "minecraft:mud_bricks"},
        {pos: [4, 9, 11], state: "minecraft:mud_bricks"},
        {pos: [4, 9, 12], state: "minecraft:mud_bricks"},
        {pos: [4, 9, 13], state: "minecraft:gravel"},
        {pos: [4, 9, 14], state: "minecraft:gravel"},
        {pos: [4, 9, 15], state: "minecraft:mud_bricks"},
        {pos: [4, 9, 16], state: "minecraft:mud_bricks"},
        {pos: [5, 9, 5], state: "minecraft:gravel"},
        {pos: [5, 9, 6], state: "minecraft:gravel"},
        {pos: [5, 9, 14], state: "minecraft:gravel"},
        {pos: [5, 9, 15], state: "minecraft:gravel"},
        {pos: [5, 9, 16], state: "minecraft:gravel"},
        {pos: [6, 9, 14], state: "minecraft:gravel"},
        {pos: [6, 9, 15], state: "minecraft:gravel"},
        {pos: [6, 9, 16], state: "minecraft:gravel"},
        {pos: [7, 9, 14], state: "minecraft:gravel"},
        {pos: [7, 9, 15], state: "minecraft:gravel"},
        {pos: [7, 9, 16], state: "minecraft:gravel"},
        {pos: [8, 9, 14], state: "minecraft:mud_bricks"},
        {pos: [8, 9, 15], state: "minecraft:mud_bricks"},
        {pos: [8, 9, 16], state: "minecraft:mud_bricks"},
        {pos: [8, 9, 17], state: "minecraft:gravel"},
        {pos: [9, 9, 13], state: "minecraft:gravel"},
        {pos: [9, 9, 14], state: "minecraft:mud_bricks"},
        {pos: [9, 9, 15], state: "minecraft:mud_bricks"},
        {pos: [9, 9, 16], state: "minecraft:mud_bricks"},
        {pos: [9, 9, 17], state: "minecraft:gravel"},
        {pos: [10, 9, 4], state: "minecraft:gravel"},
        {pos: [10, 9, 5], state: "minecraft:mud_bricks"},
        {pos: [10, 9, 6], state: "minecraft:mud_bricks"},
        {pos: [10, 9, 13], state: "minecraft:gravel"},
        {pos: [10, 9, 14], state: "minecraft:mud_bricks"},
        {pos: [10, 9, 15], state: "minecraft:mud_bricks"},
        {pos: [10, 9, 16], state: "minecraft:mud_bricks"},
        {pos: [10, 9, 17], state: "minecraft:gravel"},
        {pos: [11, 9, 4], state: "minecraft:mud_bricks"},
        {pos: [11, 9, 5], state: "minecraft:gravel"},
        {pos: [11, 9, 6], state: "minecraft:mud_bricks"},
        {pos: [11, 9, 14], state: "minecraft:gravel"},
        {pos: [11, 9, 15], state: "minecraft:gravel"},
        {pos: [12, 9, 6], state: "minecraft:gravel"},
        {pos: [2, 10, 6], state: "minecraft:mud_bricks"},
        {pos: [2, 10, 7], state: "minecraft:mud_bricks"},
        {pos: [2, 10, 8], state: "minecraft:gravel"},
        {pos: [2, 10, 9], state: "minecraft:gravel"},
        {pos: [2, 10, 10], state: "minecraft:gravel"},
        {pos: [2, 10, 11], state: "minecraft:mud_bricks"},
        {pos: [2, 10, 12], state: "minecraft:mud_bricks"},
        {pos: [2, 10, 13], state: "minecraft:mud_bricks"},
        {pos: [2, 10, 14], state: "minecraft:mud_bricks"},
        {pos: [2, 10, 15], state: "minecraft:mud_bricks"},
        {pos: [2, 10, 16], state: "minecraft:mud_bricks"},
        {pos: [3, 10, 5], state: "minecraft:mud_bricks"},
        {pos: [3, 10, 6], state: "minecraft:mud_bricks"},
        {pos: [3, 10, 7], state: "minecraft:mud_bricks"},
        {pos: [3, 10, 8], state: "minecraft:gravel"},
        {pos: [3, 10, 9], state: "minecraft:gravel"},
        {pos: [3, 10, 10], state: "minecraft:gravel"},
        {pos: [3, 10, 11], state: "minecraft:gravel"},
        {pos: [3, 10, 12], state: "minecraft:mud_bricks"},
        {pos: [3, 10, 13], state: "minecraft:mud_bricks"},
        {pos: [3, 10, 14], state: "minecraft:mud_bricks"},
        {pos: [3, 10, 15], state: "minecraft:mud_bricks"},
        {pos: [3, 10, 16], state: "minecraft:mud_bricks"},
        {pos: [4, 10, 5], state: "minecraft:mud_bricks"},
        {pos: [4, 10, 6], state: "minecraft:mud_bricks"},
        {pos: [4, 10, 7], state: "minecraft:mud_bricks"},
        {pos: [4, 10, 8], state: "minecraft:gravel"},
        {pos: [4, 10, 10], state: "minecraft:gravel"},
        {pos: [4, 10, 11], state: "minecraft:gravel"},
        {pos: [4, 10, 12], state: "minecraft:mud_bricks"},
        {pos: [4, 10, 13], state: "minecraft:gravel"},
        {pos: [4, 10, 14], state: "minecraft:mud_bricks"},
        {pos: [4, 10, 15], state: "minecraft:mud_bricks"},
        {pos: [4, 10, 16], state: "minecraft:mud_bricks"},
        {pos: [5, 10, 14], state: "minecraft:gravel"},
        {pos: [5, 10, 15], state: "minecraft:gravel"},
        {pos: [5, 10, 16], state: "minecraft:gravel"},
        {pos: [6, 10, 14], state: "minecraft:gravel"},
        {pos: [6, 10, 15], state: "minecraft:gravel"},
        {pos: [7, 10, 14], state: "minecraft:gravel"},
        {pos: [8, 10, 14], state: "minecraft:mud_bricks"},
        {pos: [8, 10, 15], state: "minecraft:mud_bricks"},
        {pos: [8, 10, 16], state: "minecraft:mud_bricks"},
        {pos: [9, 10, 14], state: "minecraft:mud_bricks"},
        {pos: [9, 10, 15], state: "minecraft:mud_bricks"},
        {pos: [9, 10, 16], state: "minecraft:mud_bricks"},
        {pos: [9, 10, 17], state: "minecraft:gravel"},
        {pos: [10, 10, 4], state: "minecraft:gravel"},
        {pos: [10, 10, 5], state: "minecraft:mud_bricks"},
        {pos: [10, 10, 6], state: "minecraft:mud_bricks"},
        {pos: [10, 10, 14], state: "minecraft:mud_bricks"},
        {pos: [10, 10, 15], state: "minecraft:mud_bricks"},
        {pos: [10, 10, 16], state: "minecraft:mud_bricks"},
        {pos: [11, 10, 4], state: "minecraft:mud_bricks"},
        {pos: [2, 11, 7], state: "minecraft:mud_bricks"},
        {pos: [2, 11, 8], state: "minecraft:gravel"},
        {pos: [2, 11, 9], state: "minecraft:gravel"},
        {pos: [2, 11, 10], state: "minecraft:gravel"},
        {pos: [2, 11, 11], state: "minecraft:mud_bricks"},
        {pos: [2, 11, 12], state: "minecraft:mud_bricks"},
        {pos: [2, 11, 13], state: "minecraft:mud_bricks"},
        {pos: [2, 11, 15], state: "minecraft:mud_bricks"},
        {pos: [3, 11, 6], state: "minecraft:mud_bricks"},
        {pos: [3, 11, 7], state: "minecraft:gravel"},
        {pos: [3, 11, 8], state: "minecraft:gravel"},
        {pos: [3, 11, 9], state: "minecraft:gravel"},
        {pos: [3, 11, 10], state: "minecraft:gravel"},
        {pos: [3, 11, 11], state: "minecraft:mud_bricks"},
        {pos: [3, 11, 12], state: "minecraft:mud_bricks"},
        {pos: [3, 11, 13], state: "minecraft:mud_bricks"},
        {pos: [3, 11, 14], state: "minecraft:mud_bricks"},
        {pos: [3, 11, 15], state: "minecraft:mud_bricks"},
        {pos: [4, 11, 6], state: "minecraft:mud_bricks"},
        {pos: [4, 11, 7], state: "minecraft:mud_bricks"},
        {pos: [4, 11, 10], state: "minecraft:gravel"},
        {pos: [4, 11, 11], state: "minecraft:gravel"},
        {pos: [4, 11, 12], state: "minecraft:mud_bricks"},
        {pos: [4, 11, 13], state: "minecraft:mud_bricks"},
        {pos: [4, 11, 14], state: "minecraft:mud_bricks"},
        {pos: [4, 11, 15], state: "minecraft:mud_bricks"},
        {pos: [5, 11, 14], state: "minecraft:gravel"},
        {pos: [8, 11, 15], state: "minecraft:mud_bricks"},
        {pos: [8, 11, 16], state: "minecraft:mud_bricks"},
        {pos: [9, 11, 15], state: "minecraft:mud_bricks"},
        {pos: [9, 11, 16], state: "minecraft:mud_bricks"},
        {pos: [10, 11, 6], state: "minecraft:mud_bricks"},
        {pos: [10, 11, 14], state: "minecraft:mud_bricks"},
        {pos: [10, 11, 15], state: "minecraft:mud_bricks"},
        {pos: [11, 11, 4], state: "minecraft:mud_bricks"}
    ],
    entities: [],
    palette: [
        "minecraft:mud_bricks",
        "minecraft:orange_glazed_terracotta{facing:north}",
        "minecraft:orange_glazed_terracotta{facing:west}",
        "minecraft:orange_glazed_terracotta{facing:east}",
        "minecraft:orange_glazed_terracotta{facing:south}",
        "minecraft:gravel",
        "minecraft:mud_brick_stairs{facing:west,half:top,shape:straight,waterlogged:false}",
        "minecraft:mud_brick_stairs{facing:north,half:top,shape:straight,waterlogged:false}",
        "minecraft:mud_brick_stairs{facing:east,half:top,shape:straight,waterlogged:false}"
    ],
    trailiertales_DataVersion: 2
}
