{
    DataVersion: 3953,
    size: [10, 9, 11],
    data: [
        {pos: [0, 0, 3], state: "minecraft:mud_bricks"},
        {pos: [0, 0, 4], state: "minecraft:mud_bricks"},
        {pos: [0, 0, 5], state: "minecraft:mud_bricks"},
        {pos: [0, 0, 6], state: "minecraft:mud_bricks"},
        {pos: [0, 0, 7], state: "minecraft:mud_bricks"},
        {pos: [0, 0, 8], state: "minecraft:mud_bricks"},
        {pos: [0, 0, 9], state: "minecraft:mud_bricks"},
        {pos: [1, 0, 1], state: "minecraft:mud_bricks"},
        {pos: [1, 0, 2], state: "minecraft:mud_bricks"},
        {pos: [1, 0, 3], state: "minecraft:mud_bricks"},
        {pos: [1, 0, 4], state: "minecraft:mud_bricks"},
        {pos: [1, 0, 5], state: "minecraft:mud_bricks"},
        {pos: [1, 0, 6], state: "minecraft:mud_bricks"},
        {pos: [1, 0, 7], state: "minecraft:mud_bricks"},
        {pos: [1, 0, 8], state: "minecraft:mud_bricks"},
        {pos: [1, 0, 9], state: "minecraft:mud_bricks"},
        {pos: [1, 0, 10], state: "minecraft:mud_bricks"},
        {pos: [2, 0, 0], state: "minecraft:mud_bricks"},
        {pos: [2, 0, 1], state: "minecraft:mud_bricks"},
        {pos: [2, 0, 2], state: "minecraft:mud_bricks"},
        {pos: [2, 0, 3], state: "minecraft:mud_bricks"},
        {pos: [2, 0, 4], state: "minecraft:mud_bricks"},
        {pos: [2, 0, 5], state: "minecraft:yellow_glazed_terracotta{facing:north}"},
        {pos: [2, 0, 6], state: "minecraft:yellow_glazed_terracotta{facing:west}"},
        {pos: [2, 0, 7], state: "minecraft:mud_bricks"},
        {pos: [2, 0, 8], state: "minecraft:mud_bricks"},
        {pos: [2, 0, 9], state: "minecraft:mud_bricks"},
        {pos: [2, 0, 10], state: "minecraft:mud_bricks"},
        {pos: [3, 0, 0], state: "minecraft:mud_bricks"},
        {pos: [3, 0, 1], state: "minecraft:mud_bricks"},
        {pos: [3, 0, 2], state: "minecraft:mud_bricks"},
        {pos: [3, 0, 3], state: "minecraft:mud_bricks"},
        {pos: [3, 0, 4], state: "minecraft:mud_bricks"},
        {pos: [3, 0, 5], state: "minecraft:yellow_glazed_terracotta{facing:east}"},
        {pos: [3, 0, 6], state: "minecraft:yellow_glazed_terracotta{facing:south}"},
        {pos: [3, 0, 7], state: "minecraft:mud_bricks"},
        {pos: [3, 0, 8], state: "minecraft:mud_bricks"},
        {pos: [3, 0, 9], state: "minecraft:mud_bricks"},
        {pos: [3, 0, 10], state: "minecraft:mud_bricks"},
        {pos: [4, 0, 0], state: "minecraft:mud_bricks"},
        {pos: [4, 0, 1], state: "minecraft:mud_bricks"},
        {pos: [4, 0, 2], state: "minecraft:mud_bricks"},
        {pos: [4, 0, 3], state: "minecraft:mud_bricks"},
        {pos: [4, 0, 4], state: "minecraft:mud_bricks"},
        {pos: [4, 0, 5], state: "minecraft:mud_bricks"},
        {pos: [4, 0, 6], state: "minecraft:mud_bricks"},
        {pos: [4, 0, 7], state: "minecraft:mud_bricks"},
        {pos: [4, 0, 8], state: "minecraft:mud_bricks"},
        {pos: [4, 0, 9], state: "minecraft:mud_bricks"},
        {pos: [4, 0, 10], state: "minecraft:mud_bricks"},
        {pos: [5, 0, 0], state: "minecraft:mud_bricks"},
        {pos: [5, 0, 1], state: "minecraft:mud_bricks"},
        {pos: [5, 0, 2], state: "minecraft:mud_bricks"},
        {pos: [5, 0, 3], state: "minecraft:mud_bricks"},
        {pos: [5, 0, 4], state: "minecraft:mud_bricks"},
        {pos: [5, 0, 5], state: "minecraft:mud_bricks"},
        {pos: [5, 0, 6], state: "minecraft:mud_bricks"},
        {pos: [5, 0, 7], state: "minecraft:mud_bricks"},
        {pos: [5, 0, 8], state: "minecraft:mud_bricks"},
        {pos: [5, 0, 9], state: "minecraft:mud_bricks"},
        {pos: [5, 0, 10], state: "minecraft:mud_bricks"},
        {pos: [6, 0, 1], state: "minecraft:mud_bricks"},
        {pos: [6, 0, 2], state: "minecraft:mud_bricks"},
        {pos: [6, 0, 3], state: "minecraft:mud_bricks"},
        {pos: [6, 0, 4], state: "minecraft:mud_bricks"},
        {pos: [6, 0, 6], state: "minecraft:mud_bricks"},
        {pos: [6, 0, 7], state: "minecraft:mud_bricks"},
        {pos: [6, 0, 8], state: "minecraft:mud_bricks"},
        {pos: [6, 0, 9], state: "minecraft:mud_bricks"},
        {pos: [7, 0, 1], state: "minecraft:mud_bricks"},
        {pos: [7, 0, 2], state: "minecraft:mud_bricks"},
        {pos: [7, 0, 3], state: "minecraft:mud_bricks"},
        {pos: [7, 0, 4], state: "minecraft:mud_bricks"},
        {pos: [7, 0, 7], state: "minecraft:mud_bricks"},
        {pos: [7, 0, 8], state: "minecraft:mud_bricks"},
        {pos: [7, 0, 9], state: "minecraft:mud_bricks"},
        {pos: [0, 1, 3], state: "minecraft:mud_bricks"},
        {pos: [0, 1, 4], state: "minecraft:mud_bricks"},
        {pos: [0, 1, 5], state: "minecraft:mud_bricks"},
        {pos: [0, 1, 6], state: "minecraft:mud_bricks"},
        {pos: [0, 1, 7], state: "minecraft:gravel"},
        {pos: [0, 1, 8], state: "minecraft:mud_bricks"},
        {pos: [0, 1, 9], state: "minecraft:mud_bricks"},
        {pos: [1, 1, 1], state: "minecraft:mud_bricks"},
        {pos: [1, 1, 2], state: "minecraft:mud_bricks"},
        {pos: [1, 1, 3], state: "minecraft:mud_bricks"},
        {pos: [1, 1, 4], state: "minecraft:gravel"},
        {pos: [1, 1, 5], state: "minecraft:gravel"},
        {pos: [1, 1, 6], state: "minecraft:gravel"},
        {pos: [1, 1, 7], state: "minecraft:gravel"},
        {pos: [1, 1, 8], state: "minecraft:mud_bricks"},
        {pos: [1, 1, 9], state: "minecraft:mud_bricks"},
        {pos: [1, 1, 10], state: "minecraft:mud_bricks"},
        {pos: [2, 1, 0], state: "minecraft:mud_bricks"},
        {pos: [2, 1, 1], state: "minecraft:mud_brick_stairs{facing:north,half:top,shape:straight,waterlogged:false}"},
        {pos: [2, 1, 2], state: "minecraft:gravel"},
        {pos: [2, 1, 3], state: "minecraft:gravel"},
        {pos: [2, 1, 4], state: "minecraft:gravel"},
        {pos: [2, 1, 5], state: "minecraft:gravel"},
        {pos: [2, 1, 6], state: "minecraft:gravel"},
        {pos: [2, 1, 7], state: "minecraft:gravel"},
        {pos: [2, 1, 8], state: "minecraft:gravel"},
        {pos: [2, 1, 9], state: "minecraft:mud_bricks"},
        {pos: [2, 1, 10], state: "minecraft:mud_bricks"},
        {pos: [3, 1, 0], state: "minecraft:mud_bricks"},
        {pos: [3, 1, 1], state: "minecraft:mud_brick_stairs{facing:north,half:top,shape:straight,waterlogged:false}"},
        {pos: [3, 1, 2], state: "minecraft:gravel"},
        {pos: [3, 1, 3], state: "minecraft:gravel"},
        {pos: [3, 1, 4], state: "minecraft:gravel"},
        {pos: [3, 1, 5], state: "minecraft:gravel"},
        {pos: [3, 1, 6], state: "minecraft:gravel"},
        {pos: [3, 1, 7], state: "minecraft:gravel"},
        {pos: [3, 1, 8], state: "minecraft:gravel"},
        {pos: [3, 1, 9], state: "minecraft:gravel"},
        {pos: [3, 1, 10], state: "minecraft:mud_bricks"},
        {pos: [4, 1, 0], state: "minecraft:mud_bricks"},
        {pos: [4, 1, 1], state: "minecraft:mud_brick_stairs{facing:north,half:top,shape:straight,waterlogged:false}"},
        {pos: [4, 1, 2], state: "minecraft:gravel"},
        {pos: [4, 1, 3], state: "minecraft:gravel"},
        {pos: [4, 1, 4], state: "minecraft:gravel"},
        {pos: [4, 1, 5], state: "minecraft:mud_brick_stairs{facing:east,half:top,shape:straight,waterlogged:false}"},
        {pos: [4, 1, 6], state: "minecraft:mud_brick_stairs{facing:east,half:top,shape:straight,waterlogged:false}"},
        {pos: [4, 1, 7], state: "minecraft:mud_bricks"},
        {pos: [4, 1, 8], state: "minecraft:gravel"},
        {pos: [4, 1, 9], state: "minecraft:mud_bricks"},
        {pos: [4, 1, 10], state: "minecraft:mud_bricks"},
        {pos: [5, 1, 0], state: "minecraft:mud_bricks"},
        {pos: [5, 1, 1], state: "minecraft:gravel"},
        {pos: [5, 1, 2], state: "minecraft:gravel"},
        {pos: [5, 1, 3], state: "minecraft:gravel"},
        {pos: [5, 1, 4], state: "minecraft:gravel"},
        {pos: [5, 1, 5], state: "minecraft:mud_bricks"},
        {pos: [5, 1, 6], state: "minecraft:mud_bricks"},
        {pos: [5, 1, 7], state: "minecraft:mud_bricks"},
        {pos: [5, 1, 8], state: "minecraft:gravel"},
        {pos: [5, 1, 9], state: "minecraft:mud_bricks"},
        {pos: [5, 1, 10], state: "minecraft:mud_bricks"},
        {pos: [6, 1, 1], state: "minecraft:mud_bricks"},
        {pos: [6, 1, 2], state: "minecraft:gravel"},
        {pos: [6, 1, 3], state: "minecraft:gravel"},
        {pos: [6, 1, 4], state: "minecraft:mud_bricks"},
        {pos: [6, 1, 6], state: "minecraft:gravel"},
        {pos: [6, 1, 7], state: "minecraft:mud_bricks"},
        {pos: [6, 1, 8], state: "minecraft:gravel"},
        {pos: [6, 1, 9], state: "minecraft:mud_bricks"},
        {pos: [7, 1, 1], state: "minecraft:mud_bricks"},
        {pos: [7, 1, 2], state: "minecraft:gravel"},
        {pos: [7, 1, 3], state: "minecraft:mud_bricks"},
        {pos: [7, 1, 4], state: "minecraft:mud_bricks"},
        {pos: [7, 1, 7], state: "minecraft:mud_bricks"},
        {pos: [7, 1, 8], state: "minecraft:mud_bricks"},
        {pos: [7, 1, 9], state: "minecraft:mud_bricks"},
        {pos: [0, 2, 3], state: "minecraft:mud_bricks"},
        {pos: [0, 2, 4], state: "minecraft:mud_bricks"},
        {pos: [0, 2, 5], state: "minecraft:gravel"},
        {pos: [0, 2, 6], state: "minecraft:mud_bricks"},
        {pos: [0, 2, 7], state: "minecraft:mud_bricks"},
        {pos: [0, 2, 8], state: "minecraft:mud_bricks"},
        {pos: [0, 2, 9], state: "minecraft:mud_bricks"},
        {pos: [1, 2, 1], state: "minecraft:gravel"},
        {pos: [1, 2, 2], state: "minecraft:gravel"},
        {pos: [1, 2, 3], state: "minecraft:mud_bricks"},
        {pos: [1, 2, 4], state: "minecraft:gravel"},
        {pos: [1, 2, 5], state: "minecraft:gravel"},
        {pos: [1, 2, 6], state: "minecraft:gravel"},
        {pos: [1, 2, 7], state: "minecraft:gravel"},
        {pos: [1, 2, 8], state: "minecraft:gravel"},
        {pos: [1, 2, 9], state: "minecraft:gravel"},
        {pos: [1, 2, 10], state: "minecraft:mud_bricks"},
        {pos: [2, 2, 0], state: "minecraft:gravel"},
        {pos: [2, 2, 1], state: "minecraft:gravel"},
        {pos: [2, 2, 2], state: "minecraft:gravel"},
        {pos: [2, 2, 3], state: "minecraft:gravel"},
        {pos: [2, 2, 4], state: "minecraft:gravel"},
        {pos: [2, 2, 5], state: "minecraft:gravel"},
        {pos: [2, 2, 6], state: "minecraft:gravel"},
        {pos: [2, 2, 7], state: "minecraft:gravel"},
        {pos: [2, 2, 8], state: "minecraft:gravel"},
        {pos: [2, 2, 9], state: "minecraft:gravel"},
        {pos: [2, 2, 10], state: "minecraft:gravel"},
        {pos: [3, 2, 0], state: "minecraft:mud_bricks"},
        {pos: [3, 2, 1], state: "minecraft:gravel"},
        {pos: [3, 2, 2], state: "minecraft:gravel"},
        {pos: [3, 2, 3], state: "minecraft:gravel"},
        {pos: [3, 2, 4], state: "minecraft:gravel"},
        {pos: [3, 2, 5], state: "minecraft:gravel"},
        {pos: [3, 2, 6], state: "minecraft:gravel"},
        {pos: [3, 2, 7], state: "minecraft:gravel"},
        {pos: [3, 2, 8], state: "minecraft:gravel"},
        {pos: [3, 2, 9], state: "minecraft:gravel"},
        {pos: [3, 2, 10], state: "minecraft:gravel"},
        {pos: [4, 2, 0], state: "minecraft:mud_bricks"},
        {pos: [4, 2, 1], state: "minecraft:gravel"},
        {pos: [4, 2, 2], state: "minecraft:gravel"},
        {pos: [4, 2, 3], state: "minecraft:gravel"},
        {pos: [4, 2, 4], state: "minecraft:gravel"},
        {pos: [4, 2, 5], state: "minecraft:gravel"},
        {pos: [4, 2, 6], state: "minecraft:gravel"},
        {pos: [4, 2, 7], state: "minecraft:gravel"},
        {pos: [4, 2, 8], state: "minecraft:gravel"},
        {pos: [4, 2, 9], state: "minecraft:gravel"},
        {pos: [4, 2, 10], state: "minecraft:mud_bricks"},
        {pos: [5, 2, 0], state: "minecraft:mud_bricks"},
        {pos: [5, 2, 1], state: "minecraft:gravel"},
        {pos: [5, 2, 2], state: "minecraft:gravel"},
        {pos: [5, 2, 3], state: "minecraft:gravel"},
        {pos: [5, 2, 4], state: "minecraft:gravel"},
        {pos: [5, 2, 5], state: "minecraft:mud_bricks"},
        {pos: [5, 2, 6], state: "minecraft:mud_bricks"},
        {pos: [5, 2, 7], state: "minecraft:mud_bricks"},
        {pos: [5, 2, 8], state: "minecraft:gravel"},
        {pos: [5, 2, 9], state: "minecraft:mud_bricks"},
        {pos: [5, 2, 10], state: "minecraft:mud_bricks"},
        {pos: [6, 2, 1], state: "minecraft:gravel"},
        {pos: [6, 2, 2], state: "minecraft:gravel"},
        {pos: [6, 2, 3], state: "minecraft:gravel"},
        {pos: [6, 2, 4], state: "minecraft:mud_bricks"},
        {pos: [6, 2, 6], state: "minecraft:gravel"},
        {pos: [6, 2, 7], state: "minecraft:mud_bricks"},
        {pos: [6, 2, 8], state: "minecraft:gravel"},
        {pos: [6, 2, 9], state: "minecraft:mud_bricks"},
        {pos: [7, 2, 1], state: "minecraft:mud_bricks"},
        {pos: [7, 2, 2], state: "minecraft:gravel"},
        {pos: [7, 2, 3], state: "minecraft:mud_bricks"},
        {pos: [7, 2, 4], state: "minecraft:mud_bricks"},
        {pos: [7, 2, 7], state: "minecraft:mud_bricks"},
        {pos: [7, 2, 8], state: "minecraft:mud_bricks"},
        {pos: [7, 2, 9], state: "minecraft:mud_bricks"},
        {pos: [0, 3, 3], state: "minecraft:gravel"},
        {pos: [0, 3, 4], state: "minecraft:mud_bricks"},
        {pos: [0, 3, 5], state: "minecraft:mud_bricks"},
        {pos: [0, 3, 6], state: "minecraft:gravel"},
        {pos: [0, 3, 7], state: "minecraft:mud_bricks"},
        {pos: [0, 3, 8], state: "minecraft:mud_bricks"},
        {pos: [0, 3, 9], state: "minecraft:mud_bricks"},
        {pos: [1, 3, 1], state: "minecraft:gravel"},
        {pos: [1, 3, 2], state: "minecraft:gravel"},
        {pos: [1, 3, 3], state: "minecraft:gravel"},
        {pos: [1, 3, 4], state: "minecraft:gravel"},
        {pos: [1, 3, 5], state: "minecraft:gravel"},
        {pos: [1, 3, 6], state: "minecraft:gravel"},
        {pos: [1, 3, 7], state: "minecraft:gravel"},
        {pos: [1, 3, 8], state: "minecraft:gravel"},
        {pos: [1, 3, 9], state: "minecraft:gravel"},
        {pos: [1, 3, 10], state: "minecraft:gravel"},
        {pos: [2, 3, 0], state: "minecraft:gravel"},
        {pos: [2, 3, 1], state: "minecraft:gravel"},
        {pos: [2, 3, 2], state: "minecraft:gravel"},
        {pos: [2, 3, 3], state: "minecraft:gravel"},
        {pos: [2, 3, 4], state: "minecraft:gravel"},
        {pos: [2, 3, 5], state: "minecraft:gravel"},
        {pos: [2, 3, 6], state: "minecraft:gravel"},
        {pos: [2, 3, 7], state: "minecraft:gravel"},
        {pos: [2, 3, 8], state: "minecraft:gravel"},
        {pos: [2, 3, 9], state: "minecraft:gravel"},
        {pos: [2, 3, 10], state: "minecraft:mud_bricks"},
        {pos: [3, 3, 0], state: "minecraft:gravel"},
        {pos: [3, 3, 1], state: "minecraft:gravel"},
        {pos: [3, 3, 2], state: "minecraft:mud_bricks"},
        {pos: [3, 3, 3], state: "minecraft:mud_bricks"},
        {pos: [3, 3, 4], state: "minecraft:gravel"},
        {pos: [3, 3, 5], state: "minecraft:gravel"},
        {pos: [3, 3, 6], state: "minecraft:gravel"},
        {pos: [3, 3, 7], state: "minecraft:gravel"},
        {pos: [3, 3, 8], state: "minecraft:gravel"},
        {pos: [3, 3, 9], state: "minecraft:gravel"},
        {pos: [3, 3, 10], state: "minecraft:mud_bricks"},
        {pos: [4, 3, 0], state: "minecraft:mud_bricks"},
        {pos: [4, 3, 1], state: "minecraft:mud_bricks"},
        {pos: [4, 3, 2], state: "minecraft:mud_bricks"},
        {pos: [4, 3, 3], state: "minecraft:mud_bricks"},
        {pos: [4, 3, 4], state: "minecraft:mud_bricks"},
        {pos: [4, 3, 5], state: "minecraft:gravel"},
        {pos: [4, 3, 6], state: "minecraft:gravel"},
        {pos: [4, 3, 7], state: "minecraft:gravel"},
        {pos: [4, 3, 8], state: "minecraft:gravel"},
        {pos: [4, 3, 9], state: "minecraft:gravel"},
        {pos: [4, 3, 10], state: "minecraft:mud_bricks"},
        {pos: [5, 3, 1], state: "minecraft:gravel"},
        {pos: [5, 3, 2], state: "minecraft:mud_bricks"},
        {pos: [5, 3, 3], state: "minecraft:mud_bricks"},
        {pos: [5, 3, 4], state: "minecraft:mud_bricks"},
        {pos: [5, 3, 5], state: "minecraft:mud_bricks"},
        {pos: [5, 3, 6], state: "minecraft:gravel"},
        {pos: [5, 3, 7], state: "minecraft:mud_bricks"},
        {pos: [5, 3, 8], state: "minecraft:mud_bricks"},
        {pos: [5, 3, 9], state: "minecraft:mud_bricks"},
        {pos: [5, 3, 10], state: "minecraft:mud_bricks"},
        {pos: [6, 3, 2], state: "minecraft:gravel"},
        {pos: [6, 3, 3], state: "minecraft:gravel"},
        {pos: [6, 3, 4], state: "minecraft:mud_bricks"},
        {pos: [6, 3, 6], state: "minecraft:gravel"},
        {pos: [6, 3, 7], state: "minecraft:mud_bricks"},
        {pos: [6, 3, 8], state: "minecraft:gravel"},
        {pos: [6, 3, 9], state: "minecraft:mud_bricks"},
        {pos: [7, 3, 7], state: "minecraft:mud_bricks"},
        {pos: [7, 3, 8], state: "minecraft:mud_bricks"},
        {pos: [7, 3, 9], state: "minecraft:mud_bricks"},
        {pos: [0, 4, 4], state: "minecraft:gravel"},
        {pos: [0, 4, 5], state: "minecraft:gravel"},
        {pos: [0, 4, 6], state: "minecraft:mud_bricks"},
        {pos: [1, 4, 4], state: "minecraft:gravel"},
        {pos: [1, 4, 5], state: "minecraft:mud_bricks"},
        {pos: [1, 4, 6], state: "minecraft:mud_bricks"},
        {pos: [1, 4, 7], state: "minecraft:mud_bricks"},
        {pos: [2, 4, 3], state: "minecraft:gravel"},
        {pos: [2, 4, 4], state: "minecraft:gravel"},
        {pos: [2, 4, 5], state: "minecraft:mud_bricks"},
        {pos: [2, 4, 6], state: "minecraft:mud_bricks"},
        {pos: [2, 4, 7], state: "minecraft:mud_bricks"},
        {pos: [2, 4, 8], state: "minecraft:gravel"},
        {pos: [2, 4, 9], state: "minecraft:gravel"},
        {pos: [3, 4, 3], state: "minecraft:gravel"},
        {pos: [3, 4, 4], state: "minecraft:gravel"},
        {pos: [3, 4, 5], state: "minecraft:gravel"},
        {pos: [3, 4, 6], state: "minecraft:mud_bricks"},
        {pos: [3, 4, 7], state: "minecraft:mud_bricks"},
        {pos: [3, 4, 8], state: "minecraft:gravel"},
        {pos: [3, 4, 9], state: "minecraft:gravel"},
        {pos: [3, 4, 10], state: "minecraft:gravel"},
        {pos: [4, 4, 4], state: "minecraft:gravel"},
        {pos: [4, 4, 5], state: "minecraft:gravel"},
        {pos: [4, 4, 6], state: "minecraft:mud_bricks"},
        {pos: [4, 4, 7], state: "minecraft:mud_bricks"},
        {pos: [4, 4, 8], state: "minecraft:mud_bricks"},
        {pos: [4, 4, 9], state: "minecraft:gravel"},
        {pos: [4, 4, 10], state: "minecraft:mud_bricks"},
        {pos: [5, 4, 4], state: "minecraft:gravel"},
        {pos: [5, 4, 5], state: "minecraft:gravel"},
        {pos: [5, 4, 6], state: "minecraft:gravel"},
        {pos: [5, 4, 7], state: "minecraft:mud_bricks"},
        {pos: [5, 4, 8], state: "minecraft:mud_bricks"},
        {pos: [5, 4, 9], state: "minecraft:mud_bricks"},
        {pos: [5, 4, 10], state: "minecraft:mud_bricks"},
        {pos: [6, 4, 6], state: "minecraft:gravel"},
        {pos: [6, 4, 7], state: "minecraft:mud_bricks"},
        {pos: [6, 4, 8], state: "minecraft:gravel"},
        {pos: [6, 4, 9], state: "minecraft:mud_bricks"},
        {pos: [6, 4, 10], state: "minecraft:dirt"},
        {pos: [7, 4, 7], state: "minecraft:mud_bricks"},
        {pos: [7, 4, 8], state: "minecraft:mud_bricks"},
        {pos: [7, 4, 9], state: "minecraft:mud_bricks"},
        {pos: [7, 4, 10], state: "minecraft:dirt"},
        {pos: [8, 4, 8], state: "minecraft:dirt"},
        {pos: [8, 4, 9], state: "minecraft:dirt"},
        {pos: [2, 5, 7], state: "minecraft:gravel"},
        {pos: [2, 5, 8], state: "minecraft:gravel"},
        {pos: [3, 5, 6], state: "minecraft:gravel"},
        {pos: [3, 5, 7], state: "minecraft:gravel"},
        {pos: [3, 5, 8], state: "minecraft:gravel"},
        {pos: [3, 5, 9], state: "minecraft:gravel"},
        {pos: [4, 5, 6], state: "minecraft:gravel"},
        {pos: [4, 5, 7], state: "minecraft:dirt"},
        {pos: [4, 5, 8], state: "minecraft:dirt"},
        {pos: [4, 5, 9], state: "minecraft:gravel"},
        {pos: [4, 5, 10], state: "minecraft:dirt"},
        {pos: [5, 5, 7], state: "minecraft:dirt"},
        {pos: [5, 5, 8], state: "minecraft:mud_bricks"},
        {pos: [5, 5, 9], state: "minecraft:mud_bricks"},
        {pos: [5, 5, 10], state: "minecraft:dirt"},
        {pos: [6, 5, 7], state: "minecraft:mud_bricks"},
        {pos: [6, 5, 8], state: "minecraft:gravel"},
        {pos: [6, 5, 9], state: "minecraft:mud_bricks"},
        {pos: [6, 5, 10], state: "minecraft:dirt"},
        {pos: [7, 5, 7], state: "minecraft:mud_bricks"},
        {pos: [7, 5, 8], state: "minecraft:mud_bricks"},
        {pos: [7, 5, 9], state: "minecraft:mud_bricks"},
        {pos: [7, 5, 10], state: "minecraft:dirt"},
        {pos: [8, 5, 7], state: "minecraft:dirt"},
        {pos: [8, 5, 8], state: "minecraft:dirt"},
        {pos: [8, 5, 9], state: "minecraft:dirt"},
        {pos: [8, 5, 10], state: "minecraft:dirt"},
        {pos: [9, 5, 8], state: "minecraft:dirt"},
        {pos: [4, 6, 7], state: "minecraft:dirt"},
        {pos: [4, 6, 8], state: "minecraft:dirt"},
        {pos: [4, 6, 9], state: "minecraft:dirt"},
        {pos: [4, 6, 10], state: "minecraft:dirt"},
        {pos: [5, 6, 7], state: "minecraft:dirt"},
        {pos: [5, 6, 8], state: "minecraft:mud_bricks"},
        {pos: [5, 6, 9], state: "minecraft:dirt"},
        {pos: [5, 6, 10], state: "minecraft:dirt"},
        {pos: [6, 6, 7], state: "minecraft:dirt"},
        {pos: [6, 6, 8], state: "minecraft:gravel"},
        {pos: [6, 6, 9], state: "minecraft:mud_bricks"},
        {pos: [6, 6, 10], state: "minecraft:dirt"},
        {pos: [7, 6, 7], state: "minecraft:dirt"},
        {pos: [7, 6, 8], state: "minecraft:mud_bricks"},
        {pos: [7, 6, 9], state: "minecraft:mud_bricks"},
        {pos: [7, 6, 10], state: "minecraft:dirt"},
        {pos: [8, 6, 7], state: "minecraft:dirt"},
        {pos: [8, 6, 8], state: "minecraft:dirt"},
        {pos: [8, 6, 9], state: "minecraft:dirt"},
        {pos: [8, 6, 10], state: "minecraft:dirt"},
        {pos: [9, 6, 8], state: "minecraft:dirt"},
        {pos: [9, 6, 9], state: "minecraft:dirt"},
        {pos: [4, 7, 8], state: "minecraft:dirt"},
        {pos: [4, 7, 9], state: "minecraft:dirt"},
        {pos: [4, 7, 10], state: "minecraft:dirt"},
        {pos: [5, 7, 7], state: "minecraft:dirt"},
        {pos: [5, 7, 9], state: "minecraft:mud_bricks"},
        {pos: [5, 7, 10], state: "minecraft:dirt"},
        {pos: [6, 7, 7], state: "minecraft:dirt"},
        {pos: [6, 7, 8], state: "minecraft:gravel"},
        {pos: [6, 7, 9], state: "minecraft:mud_bricks"},
        {pos: [6, 7, 10], state: "minecraft:dirt"},
        {pos: [7, 7, 7], state: "minecraft:dirt"},
        {pos: [7, 7, 8], state: "minecraft:mud_bricks"},
        {pos: [7, 7, 9], state: "minecraft:dirt"},
        {pos: [7, 7, 10], state: "minecraft:dirt"},
        {pos: [8, 7, 7], state: "minecraft:dirt"},
        {pos: [8, 7, 8], state: "minecraft:dirt"},
        {pos: [8, 7, 9], state: "minecraft:dirt"},
        {pos: [8, 7, 10], state: "minecraft:dirt"},
        {pos: [9, 7, 8], state: "minecraft:dirt"},
        {pos: [9, 7, 9], state: "minecraft:dirt"},
        {pos: [5, 8, 9], state: "minecraft:mud_bricks"}
    ],
    entities: [],
    palette: [
        "minecraft:mud_bricks",
        "minecraft:yellow_glazed_terracotta{facing:north}",
        "minecraft:yellow_glazed_terracotta{facing:west}",
        "minecraft:yellow_glazed_terracotta{facing:east}",
        "minecraft:yellow_glazed_terracotta{facing:south}",
        "minecraft:gravel",
        "minecraft:dirt",
        "minecraft:mud_brick_stairs{facing:north,half:top,shape:straight,waterlogged:false}",
        "minecraft:mud_brick_stairs{facing:east,half:top,shape:straight,waterlogged:false}"
    ],
    trailiertales_DataVersion: 2
}
