{
    DataVersion: 3953,
    size: [15, 10, 24],
    data: [
        {pos: [0, 0, 7], state: "minecraft:mud_bricks"},
        {pos: [0, 0, 8], state: "minecraft:mud_bricks"},
        {pos: [0, 0, 17], state: "minecraft:mud_bricks"},
        {pos: [0, 0, 18], state: "minecraft:mud_bricks"},
        {pos: [0, 0, 19], state: "minecraft:mud_bricks"},
        {pos: [1, 0, 5], state: "minecraft:mud_bricks"},
        {pos: [1, 0, 6], state: "minecraft:mud_bricks"},
        {pos: [1, 0, 7], state: "minecraft:mud_bricks"},
        {pos: [1, 0, 8], state: "minecraft:mud_bricks"},
        {pos: [1, 0, 9], state: "minecraft:mud_bricks"},
        {pos: [1, 0, 10], state: "minecraft:mud_bricks"},
        {pos: [1, 0, 15], state: "minecraft:mud_bricks"},
        {pos: [1, 0, 16], state: "minecraft:mud_bricks"},
        {pos: [1, 0, 17], state: "minecraft:mud_bricks"},
        {pos: [1, 0, 18], state: "minecraft:mud_bricks"},
        {pos: [1, 0, 19], state: "minecraft:mud_bricks"},
        {pos: [1, 0, 20], state: "minecraft:mud_bricks"},
        {pos: [2, 0, 4], state: "minecraft:mud_bricks"},
        {pos: [2, 0, 5], state: "minecraft:mud_bricks"},
        {pos: [2, 0, 6], state: "minecraft:mud_bricks"},
        {pos: [2, 0, 7], state: "minecraft:mud_bricks"},
        {pos: [2, 0, 8], state: "minecraft:mud_bricks"},
        {pos: [2, 0, 9], state: "minecraft:mud_bricks"},
        {pos: [2, 0, 10], state: "minecraft:mud_bricks"},
        {pos: [2, 0, 11], state: "minecraft:mud_bricks"},
        {pos: [2, 0, 13], state: "minecraft:mud_bricks"},
        {pos: [2, 0, 14], state: "minecraft:mud_bricks"},
        {pos: [2, 0, 15], state: "minecraft:mud_bricks"},
        {pos: [2, 0, 16], state: "minecraft:mud_bricks"},
        {pos: [2, 0, 17], state: "minecraft:mud_bricks"},
        {pos: [2, 0, 18], state: "minecraft:mud_bricks"},
        {pos: [2, 0, 19], state: "minecraft:mud_bricks"},
        {pos: [2, 0, 20], state: "minecraft:mud_bricks"},
        {pos: [2, 0, 21], state: "minecraft:mud_bricks"},
        {pos: [3, 0, 2], state: "minecraft:mud_bricks"},
        {pos: [3, 0, 3], state: "minecraft:mud_bricks"},
        {pos: [3, 0, 4], state: "minecraft:mud_bricks"},
        {pos: [3, 0, 5], state: "minecraft:mud_bricks"},
        {pos: [3, 0, 6], state: "minecraft:mud_bricks"},
        {pos: [3, 0, 7], state: "minecraft:mud_bricks"},
        {pos: [3, 0, 8], state: "minecraft:mud_bricks"},
        {pos: [3, 0, 9], state: "minecraft:mud_bricks"},
        {pos: [3, 0, 10], state: "minecraft:mud_bricks"},
        {pos: [3, 0, 11], state: "minecraft:mud_bricks"},
        {pos: [3, 0, 12], state: "minecraft:mud_bricks"},
        {pos: [3, 0, 13], state: "minecraft:mud_bricks"},
        {pos: [3, 0, 14], state: "minecraft:mud_bricks"},
        {pos: [3, 0, 15], state: "minecraft:mud_bricks"},
        {pos: [3, 0, 16], state: "minecraft:mud_bricks"},
        {pos: [3, 0, 17], state: "minecraft:mud_bricks"},
        {pos: [3, 0, 18], state: "minecraft:mud_bricks"},
        {pos: [3, 0, 19], state: "minecraft:mud_bricks"},
        {pos: [3, 0, 20], state: "minecraft:mud_bricks"},
        {pos: [3, 0, 21], state: "minecraft:mud_bricks"},
        {pos: [4, 0, 1], state: "minecraft:mud_bricks"},
        {pos: [4, 0, 2], state: "minecraft:mud_bricks"},
        {pos: [4, 0, 3], state: "minecraft:mud_bricks"},
        {pos: [4, 0, 4], state: "minecraft:mud_bricks"},
        {pos: [4, 0, 5], state: "minecraft:mud_bricks"},
        {pos: [4, 0, 6], state: "minecraft:mud_bricks"},
        {pos: [4, 0, 7], state: "minecraft:mud_bricks"},
        {pos: [4, 0, 8], state: "minecraft:mud_bricks"},
        {pos: [4, 0, 9], state: "minecraft:mud_bricks"},
        {pos: [4, 0, 10], state: "minecraft:mud_bricks"},
        {pos: [4, 0, 11], state: "minecraft:mud_bricks"},
        {pos: [4, 0, 12], state: "minecraft:mud_bricks"},
        {pos: [4, 0, 13], state: "minecraft:mud_bricks"},
        {pos: [4, 0, 14], state: "minecraft:mud_bricks"},
        {pos: [4, 0, 15], state: "minecraft:mud_bricks"},
        {pos: [4, 0, 16], state: "minecraft:mud_bricks"},
        {pos: [4, 0, 17], state: "minecraft:mud_bricks"},
        {pos: [4, 0, 18], state: "minecraft:mud_bricks"},
        {pos: [4, 0, 19], state: "minecraft:mud_bricks"},
        {pos: [4, 0, 20], state: "minecraft:mud_bricks"},
        {pos: [4, 0, 21], state: "minecraft:mud_bricks"},
        {pos: [5, 0, 1], state: "minecraft:mud_bricks"},
        {pos: [5, 0, 2], state: "minecraft:mud_bricks"},
        {pos: [5, 0, 3], state: "minecraft:mud_bricks"},
        {pos: [5, 0, 4], state: "minecraft:mud_bricks"},
        {pos: [5, 0, 5], state: "minecraft:mud_bricks"},
        {pos: [5, 0, 6], state: "minecraft:mud_bricks"},
        {pos: [5, 0, 7], state: "minecraft:mud_bricks"},
        {pos: [5, 0, 8], state: "minecraft:mud_bricks"},
        {pos: [5, 0, 9], state: "minecraft:mud_bricks"},
        {pos: [5, 0, 10], state: "minecraft:mud_bricks"},
        {pos: [5, 0, 11], state: "minecraft:mud_bricks"},
        {pos: [5, 0, 12], state: "minecraft:mud_bricks"},
        {pos: [5, 0, 13], state: "minecraft:mud_bricks"},
        {pos: [5, 0, 14], state: "minecraft:mud_bricks"},
        {pos: [5, 0, 15], state: "minecraft:mud_bricks"},
        {pos: [5, 0, 16], state: "minecraft:mud_bricks"},
        {pos: [5, 0, 17], state: "minecraft:mud_bricks"},
        {pos: [5, 0, 18], state: "minecraft:mud_bricks"},
        {pos: [5, 0, 19], state: "minecraft:mud_bricks"},
        {pos: [5, 0, 20], state: "minecraft:mud_bricks"},
        {pos: [5, 0, 21], state: "minecraft:mud_bricks"},
        {pos: [5, 0, 22], state: "minecraft:mud_bricks"},
        {pos: [6, 0, 0], state: "minecraft:mud_bricks"},
        {pos: [6, 0, 1], state: "minecraft:mud_bricks"},
        {pos: [6, 0, 2], state: "minecraft:mud_bricks"},
        {pos: [6, 0, 3], state: "minecraft:mud_bricks"},
        {pos: [6, 0, 4], state: "minecraft:mud_bricks"},
        {pos: [6, 0, 5], state: "minecraft:mud_bricks"},
        {pos: [6, 0, 6], state: "minecraft:mud_bricks"},
        {pos: [6, 0, 7], state: "minecraft:mud_bricks"},
        {pos: [6, 0, 8], state: "minecraft:mud_bricks"},
        {pos: [6, 0, 9], state: "minecraft:mud_bricks"},
        {pos: [6, 0, 10], state: "minecraft:mud_bricks"},
        {pos: [6, 0, 11], state: "minecraft:mud_bricks"},
        {pos: [6, 0, 12], state: "minecraft:mud_bricks"},
        {pos: [6, 0, 15], state: "minecraft:mud_bricks"},
        {pos: [6, 0, 16], state: "minecraft:mud_bricks"},
        {pos: [6, 0, 17], state: "minecraft:mud_bricks"},
        {pos: [6, 0, 18], state: "minecraft:mud_bricks"},
        {pos: [6, 0, 19], state: "minecraft:mud_bricks"},
        {pos: [6, 0, 20], state: "minecraft:mud_bricks"},
        {pos: [6, 0, 21], state: "minecraft:mud_bricks"},
        {pos: [6, 0, 22], state: "minecraft:mud_bricks"},
        {pos: [7, 0, 0], state: "minecraft:mud_bricks"},
        {pos: [7, 0, 1], state: "minecraft:mud_bricks"},
        {pos: [7, 0, 2], state: "minecraft:mud_bricks"},
        {pos: [7, 0, 3], state: "minecraft:mud_bricks"},
        {pos: [7, 0, 4], state: "minecraft:mud_bricks"},
        {pos: [7, 0, 5], state: "minecraft:mud_bricks"},
        {pos: [7, 0, 8], state: "minecraft:mud_bricks"},
        {pos: [7, 0, 9], state: "minecraft:mud_bricks"},
        {pos: [7, 0, 10], state: "minecraft:mud_bricks"},
        {pos: [7, 0, 11], state: "minecraft:mud_bricks"},
        {pos: [7, 0, 12], state: "minecraft:mud_bricks"},
        {pos: [7, 0, 13], state: "minecraft:mud_bricks"},
        {pos: [7, 0, 15], state: "minecraft:mud_bricks"},
        {pos: [7, 0, 16], state: "minecraft:mud_bricks"},
        {pos: [7, 0, 17], state: "minecraft:mud_bricks"},
        {pos: [7, 0, 18], state: "minecraft:mud_bricks"},
        {pos: [7, 0, 19], state: "minecraft:mud_bricks"},
        {pos: [7, 0, 20], state: "minecraft:mud_bricks"},
        {pos: [7, 0, 21], state: "minecraft:mud_bricks"},
        {pos: [7, 0, 22], state: "minecraft:mud_bricks"},
        {pos: [7, 0, 23], state: "minecraft:mud_bricks"},
        {pos: [8, 0, 1], state: "minecraft:mud_bricks"},
        {pos: [8, 0, 2], state: "minecraft:mud_bricks"},
        {pos: [8, 0, 3], state: "minecraft:mud_bricks"},
        {pos: [8, 0, 4], state: "minecraft:mud_bricks"},
        {pos: [8, 0, 5], state: "minecraft:mud_bricks"},
        {pos: [8, 0, 6], state: "minecraft:mud_bricks"},
        {pos: [8, 0, 8], state: "minecraft:mud_bricks"},
        {pos: [8, 0, 9], state: "minecraft:mud_bricks"},
        {pos: [8, 0, 10], state: "minecraft:mud_bricks"},
        {pos: [8, 0, 11], state: "minecraft:mud_bricks"},
        {pos: [8, 0, 12], state: "minecraft:mud_bricks"},
        {pos: [8, 0, 13], state: "minecraft:mud_bricks"},
        {pos: [8, 0, 14], state: "minecraft:mud_bricks"},
        {pos: [8, 0, 15], state: "minecraft:mud_bricks"},
        {pos: [8, 0, 16], state: "minecraft:mud_bricks"},
        {pos: [8, 0, 17], state: "minecraft:mud_bricks"},
        {pos: [8, 0, 18], state: "minecraft:mud_bricks"},
        {pos: [8, 0, 19], state: "minecraft:mud_bricks"},
        {pos: [8, 0, 20], state: "minecraft:mud_bricks"},
        {pos: [8, 0, 21], state: "minecraft:mud_bricks"},
        {pos: [8, 0, 22], state: "minecraft:mud_bricks"},
        {pos: [8, 0, 23], state: "minecraft:mud_bricks"},
        {pos: [9, 0, 0], state: "minecraft:mud_bricks"},
        {pos: [9, 0, 1], state: "minecraft:mud_bricks"},
        {pos: [9, 0, 2], state: "minecraft:mud_bricks"},
        {pos: [9, 0, 3], state: "minecraft:mud_bricks"},
        {pos: [9, 0, 4], state: "minecraft:mud_bricks"},
        {pos: [9, 0, 5], state: "minecraft:mud_bricks"},
        {pos: [9, 0, 6], state: "minecraft:mud_bricks"},
        {pos: [9, 0, 7], state: "minecraft:mud_bricks"},
        {pos: [9, 0, 8], state: "minecraft:mud_bricks"},
        {pos: [9, 0, 9], state: "minecraft:mud_bricks"},
        {pos: [9, 0, 10], state: "minecraft:mud_bricks"},
        {pos: [9, 0, 11], state: "minecraft:mud_bricks"},
        {pos: [9, 0, 12], state: "minecraft:mud_bricks"},
        {pos: [9, 0, 13], state: "minecraft:mud_bricks"},
        {pos: [9, 0, 14], state: "minecraft:mud_bricks"},
        {pos: [9, 0, 15], state: "minecraft:mud_bricks"},
        {pos: [9, 0, 16], state: "minecraft:mud_bricks"},
        {pos: [9, 0, 17], state: "minecraft:mud_bricks"},
        {pos: [9, 0, 18], state: "minecraft:mud_bricks"},
        {pos: [9, 0, 19], state: "minecraft:mud_bricks"},
        {pos: [9, 0, 20], state: "minecraft:mud_bricks"},
        {pos: [9, 0, 21], state: "minecraft:mud_bricks"},
        {pos: [9, 0, 22], state: "minecraft:mud_bricks"},
        {pos: [10, 0, 1], state: "minecraft:mud_bricks"},
        {pos: [10, 0, 2], state: "minecraft:mud_bricks"},
        {pos: [10, 0, 3], state: "minecraft:mud_bricks"},
        {pos: [10, 0, 4], state: "minecraft:mud_bricks"},
        {pos: [10, 0, 5], state: "minecraft:mud_bricks"},
        {pos: [10, 0, 6], state: "minecraft:mud_bricks"},
        {pos: [10, 0, 7], state: "minecraft:mud_bricks"},
        {pos: [10, 0, 8], state: "minecraft:mud_bricks"},
        {pos: [10, 0, 9], state: "minecraft:mud_bricks"},
        {pos: [10, 0, 10], state: "minecraft:mud_bricks"},
        {pos: [10, 0, 11], state: "minecraft:mud_bricks"},
        {pos: [10, 0, 12], state: "minecraft:mud_bricks"},
        {pos: [10, 0, 16], state: "minecraft:mud_bricks"},
        {pos: [10, 0, 17], state: "minecraft:mud_bricks"},
        {pos: [10, 0, 18], state: "minecraft:mud_bricks"},
        {pos: [10, 0, 19], state: "minecraft:mud_bricks"},
        {pos: [10, 0, 20], state: "minecraft:mud_bricks"},
        {pos: [10, 0, 21], state: "minecraft:mud_bricks"},
        {pos: [11, 0, 2], state: "minecraft:mud_bricks"},
        {pos: [11, 0, 3], state: "minecraft:mud_bricks"},
        {pos: [11, 0, 4], state: "minecraft:mud_bricks"},
        {pos: [11, 0, 5], state: "minecraft:mud_bricks"},
        {pos: [11, 0, 6], state: "minecraft:mud_bricks"},
        {pos: [11, 0, 8], state: "minecraft:mud_bricks"},
        {pos: [11, 0, 9], state: "minecraft:mud_bricks"},
        {pos: [11, 0, 13], state: "minecraft:mud_bricks"},
        {pos: [11, 0, 15], state: "minecraft:mud_bricks"},
        {pos: [11, 0, 16], state: "minecraft:mud_bricks"},
        {pos: [11, 0, 17], state: "minecraft:mud_bricks"},
        {pos: [11, 0, 18], state: "minecraft:mud_bricks"},
        {pos: [11, 0, 19], state: "minecraft:mud_bricks"},
        {pos: [11, 0, 20], state: "minecraft:mud_bricks"},
        {pos: [12, 0, 3], state: "minecraft:mud_bricks"},
        {pos: [12, 0, 4], state: "minecraft:mud_bricks"},
        {pos: [12, 0, 5], state: "minecraft:mud_bricks"},
        {pos: [12, 0, 6], state: "minecraft:mud_bricks"},
        {pos: [12, 0, 7], state: "minecraft:mud_bricks"},
        {pos: [12, 0, 8], state: "minecraft:mud_bricks"},
        {pos: [12, 0, 9], state: "minecraft:mud_bricks"},
        {pos: [12, 0, 10], state: "minecraft:mud_bricks"},
        {pos: [12, 0, 11], state: "minecraft:mud_bricks"},
        {pos: [12, 0, 13], state: "minecraft:mud_bricks"},
        {pos: [12, 0, 14], state: "minecraft:mud_bricks"},
        {pos: [12, 0, 15], state: "minecraft:mud_bricks"},
        {pos: [12, 0, 16], state: "minecraft:mud_bricks"},
        {pos: [12, 0, 17], state: "minecraft:mud_bricks"},
        {pos: [12, 0, 18], state: "minecraft:mud_bricks"},
        {pos: [12, 0, 19], state: "minecraft:mud_bricks"},
        {pos: [12, 0, 20], state: "minecraft:mud_bricks"},
        {pos: [12, 0, 21], state: "minecraft:mud_bricks"},
        {pos: [13, 0, 5], state: "minecraft:mud_bricks"},
        {pos: [13, 0, 6], state: "minecraft:mud_bricks"},
        {pos: [13, 0, 7], state: "minecraft:mud_bricks"},
        {pos: [13, 0, 8], state: "minecraft:mud_bricks"},
        {pos: [13, 0, 9], state: "minecraft:mud_bricks"},
        {pos: [13, 0, 10], state: "minecraft:mud_bricks"},
        {pos: [13, 0, 11], state: "minecraft:mud_bricks"},
        {pos: [13, 0, 12], state: "minecraft:mud_bricks"},
        {pos: [13, 0, 13], state: "minecraft:mud_bricks"},
        {pos: [13, 0, 14], state: "minecraft:mud_bricks"},
        {pos: [13, 0, 15], state: "minecraft:mud_bricks"},
        {pos: [13, 0, 16], state: "minecraft:mud_bricks"},
        {pos: [13, 0, 17], state: "minecraft:mud_bricks"},
        {pos: [13, 0, 18], state: "minecraft:mud_bricks"},
        {pos: [13, 0, 19], state: "minecraft:mud_bricks"},
        {pos: [13, 0, 20], state: "minecraft:mud_bricks"},
        {pos: [13, 0, 21], state: "minecraft:mud_bricks"},
        {pos: [14, 0, 8], state: "minecraft:mud_bricks"},
        {pos: [14, 0, 9], state: "minecraft:mud_bricks"},
        {pos: [14, 0, 10], state: "minecraft:mud_bricks"},
        {pos: [14, 0, 12], state: "minecraft:mud_bricks"},
        {pos: [14, 0, 14], state: "minecraft:mud_bricks"},
        {pos: [14, 0, 17], state: "minecraft:mud_bricks"},
        {pos: [14, 0, 18], state: "minecraft:mud_bricks"},
        {pos: [14, 0, 19], state: "minecraft:mud_bricks"},
        {pos: [14, 0, 20], state: "minecraft:mud_bricks"},
        {pos: [14, 0, 21], state: "minecraft:mud_bricks"},
        {pos: [0, 1, 7], state: "minecraft:gravel"},
        {pos: [0, 1, 8], state: "minecraft:gravel"},
        {pos: [0, 1, 17], state: "minecraft:gravel"},
        {pos: [1, 1, 5], state: "minecraft:gravel"},
        {pos: [1, 1, 6], state: "minecraft:mud_bricks"},
        {pos: [1, 1, 7], state: "minecraft:gravel"},
        {pos: [1, 1, 8], state: "minecraft:mud_bricks"},
        {pos: [1, 1, 9], state: "minecraft:gravel"},
        {pos: [1, 1, 10], state: "minecraft:gravel"},
        {pos: [1, 1, 15], state: "minecraft:gravel"},
        {pos: [1, 1, 16], state: "minecraft:gravel"},
        {pos: [1, 1, 17], state: "minecraft:gravel"},
        {pos: [1, 1, 18], state: "minecraft:mud_bricks"},
        {pos: [1, 1, 19], state: "minecraft:mud_bricks"},
        {pos: [1, 1, 20], state: "minecraft:mud_bricks"},
        {pos: [2, 1, 4], state: "minecraft:gravel"},
        {pos: [2, 1, 5], state: "minecraft:mud_bricks"},
        {pos: [2, 1, 6], state: "minecraft:gravel"},
        {pos: [2, 1, 7], state: "minecraft:gravel"},
        {pos: [2, 1, 8], state: "minecraft:gravel"},
        {pos: [2, 1, 9], state: "minecraft:mud_bricks"},
        {pos: [2, 1, 10], state: "minecraft:mud_bricks"},
        {pos: [2, 1, 11], state: "minecraft:gravel"},
        {pos: [2, 1, 13], state: "minecraft:mud_bricks"},
        {pos: [2, 1, 15], state: "minecraft:mud_bricks"},
        {pos: [2, 1, 16], state: "minecraft:mud_bricks"},
        {pos: [2, 1, 17], state: "minecraft:gravel"},
        {pos: [2, 1, 18], state: "minecraft:mud_bricks"},
        {pos: [2, 1, 19], state: "minecraft:gravel"},
        {pos: [2, 1, 20], state: "minecraft:mud_bricks"},
        {pos: [2, 1, 21], state: "minecraft:gravel"},
        {pos: [3, 1, 2], state: "minecraft:gravel"},
        {pos: [3, 1, 3], state: "minecraft:mud_bricks"},
        {pos: [3, 1, 4], state: "minecraft:gravel"},
        {pos: [3, 1, 5], state: "minecraft:gravel"},
        {pos: [3, 1, 6], state: "minecraft:gravel"},
        {pos: [3, 1, 7], state: "minecraft:mud_bricks"},
        {pos: [3, 1, 8], state: "minecraft:gravel"},
        {pos: [3, 1, 9], state: "minecraft:gravel"},
        {pos: [3, 1, 10], state: "minecraft:gravel"},
        {pos: [3, 1, 11], state: "minecraft:gravel"},
        {pos: [3, 1, 12], state: "minecraft:gravel"},
        {pos: [3, 1, 13], state: "minecraft:gravel"},
        {pos: [3, 1, 14], state: "minecraft:gravel"},
        {pos: [3, 1, 15], state: "minecraft:gravel"},
        {pos: [3, 1, 16], state: "minecraft:gravel"},
        {pos: [3, 1, 17], state: "minecraft:gravel"},
        {pos: [3, 1, 18], state: "minecraft:mud_bricks"},
        {pos: [3, 1, 19], state: "minecraft:mud_bricks"},
        {pos: [3, 1, 20], state: "minecraft:mud_bricks"},
        {pos: [3, 1, 21], state: "minecraft:gravel"},
        {pos: [4, 1, 1], state: "minecraft:gravel"},
        {pos: [4, 1, 2], state: "minecraft:gravel"},
        {pos: [4, 1, 3], state: "minecraft:gravel"},
        {pos: [4, 1, 4], state: "minecraft:gravel"},
        {pos: [4, 1, 5], state: "minecraft:gravel"},
        {pos: [4, 1, 6], state: "minecraft:gravel"},
        {pos: [4, 1, 7], state: "minecraft:gravel"},
        {pos: [4, 1, 8], state: "minecraft:gravel"},
        {pos: [4, 1, 9], state: "minecraft:gravel"},
        {pos: [4, 1, 10], state: "minecraft:gravel"},
        {pos: [4, 1, 11], state: "minecraft:gravel"},
        {pos: [4, 1, 12], state: "minecraft:gravel"},
        {pos: [4, 1, 13], state: "minecraft:gravel"},
        {pos: [4, 1, 14], state: "minecraft:gravel"},
        {pos: [4, 1, 15], state: "minecraft:gravel"},
        {pos: [4, 1, 16], state: "minecraft:gravel"},
        {pos: [4, 1, 17], state: "minecraft:gravel"},
        {pos: [4, 1, 18], state: "minecraft:gravel"},
        {pos: [4, 1, 19], state: "minecraft:gravel"},
        {pos: [4, 1, 20], state: "minecraft:gravel"},
        {pos: [4, 1, 21], state: "minecraft:gravel"},
        {pos: [5, 1, 1], state: "minecraft:mud_bricks"},
        {pos: [5, 1, 2], state: "minecraft:gravel"},
        {pos: [5, 1, 3], state: "minecraft:gravel"},
        {pos: [5, 1, 4], state: "minecraft:gravel"},
        {pos: [5, 1, 5], state: "minecraft:mud_bricks"},
        {pos: [5, 1, 6], state: "minecraft:gravel"},
        {pos: [5, 1, 7], state: "minecraft:gravel"},
        {pos: [5, 1, 8], state: "minecraft:mud_brick_stairs{facing:north,half:bottom,shape:straight,waterlogged:false}"},
        {pos: [5, 1, 9], state: "minecraft:gravel"},
        {pos: [5, 1, 10], state: "minecraft:gravel"},
        {pos: [5, 1, 11], state: "minecraft:mud_brick_stairs{facing:north,half:bottom,shape:straight,waterlogged:false}"},
        {pos: [5, 1, 12], state: "minecraft:gravel"},
        {pos: [5, 1, 13], state: "minecraft:gravel"},
        {pos: [5, 1, 14], state: "minecraft:gravel"},
        {pos: [5, 1, 15], state: "minecraft:gravel"},
        {pos: [5, 1, 16], state: "minecraft:gravel"},
        {pos: [5, 1, 17], state: "minecraft:mud_bricks"},
        {pos: [5, 1, 18], state: "minecraft:mud_bricks"},
        {pos: [5, 1, 19], state: "minecraft:mud_bricks"},
        {pos: [5, 1, 20], state: "minecraft:mud_bricks"},
        {pos: [5, 1, 21], state: "minecraft:mud_bricks"},
        {pos: [5, 1, 22], state: "minecraft:gravel"},
        {pos: [6, 1, 0], state: "minecraft:gravel"},
        {pos: [6, 1, 1], state: "minecraft:gravel"},
        {pos: [6, 1, 2], state: "minecraft:gravel"},
        {pos: [6, 1, 3], state: "minecraft:gravel"},
        {pos: [6, 1, 4], state: "minecraft:gravel"},
        {pos: [6, 1, 5], state: "minecraft:mud_brick_stairs{facing:west,half:bottom,shape:straight,waterlogged:false}"},
        {pos: [6, 1, 6], state: "minecraft:gravel"},
        {pos: [6, 1, 7], state: "minecraft:gravel"},
        {pos: [6, 1, 8], state: "minecraft:mud_brick_stairs{facing:north,half:bottom,shape:straight,waterlogged:false}"},
        {pos: [6, 1, 9], state: "minecraft:gravel"},
        {pos: [6, 1, 10], state: "minecraft:gravel"},
        {pos: [6, 1, 11], state: "minecraft:mud_bricks"},
        {pos: [6, 1, 12], state: "minecraft:gravel"},
        {pos: [6, 1, 15], state: "minecraft:gravel"},
        {pos: [6, 1, 16], state: "minecraft:gravel"},
        {pos: [6, 1, 17], state: "minecraft:mud_bricks"},
        {pos: [6, 1, 18], state: "minecraft:gravel"},
        {pos: [6, 1, 19], state: "minecraft:gravel"},
        {pos: [6, 1, 20], state: "minecraft:gravel"},
        {pos: [6, 1, 21], state: "minecraft:mud_bricks"},
        {pos: [6, 1, 22], state: "minecraft:gravel"},
        {pos: [7, 1, 0], state: "minecraft:gravel"},
        {pos: [7, 1, 1], state: "minecraft:gravel"},
        {pos: [7, 1, 2], state: "minecraft:gravel"},
        {pos: [7, 1, 3], state: "minecraft:gravel"},
        {pos: [7, 1, 4], state: "minecraft:gravel"},
        {pos: [7, 1, 5], state: "minecraft:gravel"},
        {pos: [7, 1, 8], state: "minecraft:gravel"},
        {pos: [7, 1, 9], state: "minecraft:gravel"},
        {pos: [7, 1, 10], state: "minecraft:gravel"},
        {pos: [7, 1, 11], state: "minecraft:gravel"},
        {pos: [7, 1, 12], state: "minecraft:gravel"},
        {pos: [7, 1, 13], state: "minecraft:gravel"},
        {pos: [7, 1, 15], state: "minecraft:gravel"},
        {pos: [7, 1, 16], state: "minecraft:gravel"},
        {pos: [7, 1, 17], state: "minecraft:mud_bricks"},
        {pos: [7, 1, 18], state: "minecraft:gravel"},
        {pos: [7, 1, 19], state: "minecraft:gravel"},
        {pos: [7, 1, 20], state: "minecraft:gravel"},
        {pos: [7, 1, 21], state: "minecraft:gravel"},
        {pos: [7, 1, 22], state: "minecraft:gravel"},
        {pos: [7, 1, 23], state: "minecraft:gravel"},
        {pos: [8, 1, 1], state: "minecraft:gravel"},
        {pos: [8, 1, 2], state: "minecraft:gravel"},
        {pos: [8, 1, 3], state: "minecraft:gravel"},
        {pos: [8, 1, 4], state: "minecraft:gravel"},
        {pos: [8, 1, 5], state: "minecraft:mud_brick_stairs{facing:north,half:bottom,shape:straight,waterlogged:false}"},
        {pos: [8, 1, 6], state: "minecraft:gravel"},
        {pos: [8, 1, 8], state: "minecraft:mud_brick_stairs{facing:north,half:bottom,shape:straight,waterlogged:false}"},
        {pos: [8, 1, 9], state: "minecraft:gravel"},
        {pos: [8, 1, 10], state: "minecraft:gravel"},
        {pos: [8, 1, 11], state: "minecraft:mud_brick_stairs{facing:north,half:bottom,shape:straight,waterlogged:false}"},
        {pos: [8, 1, 12], state: "minecraft:gravel"},
        {pos: [8, 1, 13], state: "minecraft:gravel"},
        {pos: [8, 1, 14], state: "minecraft:gravel"},
        {pos: [8, 1, 15], state: "minecraft:gravel"},
        {pos: [8, 1, 16], state: "minecraft:gravel"},
        {pos: [8, 1, 17], state: "minecraft:mud_bricks"},
        {pos: [8, 1, 18], state: "minecraft:gravel"},
        {pos: [8, 1, 19], state: "minecraft:gravel"},
        {pos: [8, 1, 20], state: "minecraft:gravel"},
        {pos: [8, 1, 21], state: "minecraft:mud_bricks"},
        {pos: [8, 1, 22], state: "minecraft:gravel"},
        {pos: [8, 1, 23], state: "minecraft:gravel"},
        {pos: [9, 1, 0], state: "minecraft:gravel"},
        {pos: [9, 1, 1], state: "minecraft:mud_bricks"},
        {pos: [9, 1, 2], state: "minecraft:gravel"},
        {pos: [9, 1, 3], state: "minecraft:gravel"},
        {pos: [9, 1, 4], state: "minecraft:gravel"},
        {pos: [9, 1, 5], state: "minecraft:mud_bricks"},
        {pos: [9, 1, 6], state: "minecraft:gravel"},
        {pos: [9, 1, 7], state: "minecraft:gravel"},
        {pos: [9, 1, 8], state: "minecraft:mud_brick_stairs{facing:north,half:bottom,shape:straight,waterlogged:false}"},
        {pos: [9, 1, 9], state: "minecraft:gravel"},
        {pos: [9, 1, 10], state: "minecraft:gravel"},
        {pos: [9, 1, 11], state: "minecraft:mud_brick_stairs{facing:north,half:bottom,shape:straight,waterlogged:false}"},
        {pos: [9, 1, 12], state: "minecraft:gravel"},
        {pos: [9, 1, 13], state: "minecraft:gravel"},
        {pos: [9, 1, 14], state: "minecraft:gravel"},
        {pos: [9, 1, 15], state: "minecraft:gravel"},
        {pos: [9, 1, 16], state: "minecraft:gravel"},
        {pos: [9, 1, 17], state: "minecraft:mud_bricks"},
        {pos: [9, 1, 18], state: "minecraft:mud_bricks"},
        {pos: [9, 1, 19], state: "minecraft:mud_bricks"},
        {pos: [9, 1, 20], state: "minecraft:mud_bricks"},
        {pos: [9, 1, 21], state: "minecraft:mud_bricks"},
        {pos: [9, 1, 22], state: "minecraft:gravel"},
        {pos: [10, 1, 1], state: "minecraft:gravel"},
        {pos: [10, 1, 2], state: "minecraft:gravel"},
        {pos: [10, 1, 3], state: "minecraft:gravel"},
        {pos: [10, 1, 4], state: "minecraft:gravel"},
        {pos: [10, 1, 5], state: "minecraft:gravel"},
        {pos: [10, 1, 6], state: "minecraft:gravel"},
        {pos: [10, 1, 7], state: "minecraft:gravel"},
        {pos: [10, 1, 8], state: "minecraft:gravel"},
        {pos: [10, 1, 9], state: "minecraft:gravel"},
        {pos: [10, 1, 10], state: "minecraft:gravel"},
        {pos: [10, 1, 11], state: "minecraft:gravel"},
        {pos: [10, 1, 12], state: "minecraft:gravel"},
        {pos: [10, 1, 16], state: "minecraft:gravel"},
        {pos: [10, 1, 17], state: "minecraft:gravel"},
        {pos: [10, 1, 18], state: "minecraft:gravel"},
        {pos: [10, 1, 19], state: "minecraft:gravel"},
        {pos: [10, 1, 20], state: "minecraft:gravel"},
        {pos: [10, 1, 21], state: "minecraft:gravel"},
        {pos: [11, 1, 2], state: "minecraft:gravel"},
        {pos: [11, 1, 3], state: "minecraft:mud_bricks"},
        {pos: [11, 1, 4], state: "minecraft:mud_bricks"},
        {pos: [11, 1, 5], state: "minecraft:gravel"},
        {pos: [11, 1, 6], state: "minecraft:gravel"},
        {pos: [11, 1, 8], state: "minecraft:gravel"},
        {pos: [11, 1, 9], state: "minecraft:gravel"},
        {pos: [11, 1, 13], state: "minecraft:gravel"},
        {pos: [11, 1, 15], state: "minecraft:gravel"},
        {pos: [11, 1, 16], state: "minecraft:gravel"},
        {pos: [11, 1, 17], state: "minecraft:gravel"},
        {pos: [11, 1, 18], state: "minecraft:mud_bricks"},
        {pos: [11, 1, 19], state: "minecraft:mud_bricks"},
        {pos: [11, 1, 20], state: "minecraft:mud_bricks"},
        {pos: [12, 1, 3], state: "minecraft:gravel"},
        {pos: [12, 1, 4], state: "minecraft:gravel"},
        {pos: [12, 1, 5], state: "minecraft:mud_bricks"},
        {pos: [12, 1, 6], state: "minecraft:gravel"},
        {pos: [12, 1, 7], state: "minecraft:mud_bricks"},
        {pos: [12, 1, 8], state: "minecraft:gravel"},
        {pos: [12, 1, 9], state: "minecraft:gravel"},
        {pos: [12, 1, 10], state: "minecraft:gravel"},
        {pos: [12, 1, 11], state: "minecraft:gravel"},
        {pos: [12, 1, 13], state: "minecraft:gravel"},
        {pos: [12, 1, 14], state: "minecraft:gravel"},
        {pos: [12, 1, 15], state: "minecraft:gravel"},
        {pos: [12, 1, 16], state: "minecraft:mud_bricks"},
        {pos: [12, 1, 17], state: "minecraft:gravel"},
        {pos: [12, 1, 18], state: "minecraft:mud_bricks"},
        {pos: [12, 1, 19], state: "minecraft:mud_bricks"},
        {pos: [12, 1, 20], state: "minecraft:mud_bricks"},
        {pos: [12, 1, 21], state: "minecraft:mud_bricks"},
        {pos: [13, 1, 5], state: "minecraft:gravel"},
        {pos: [13, 1, 6], state: "minecraft:gravel"},
        {pos: [13, 1, 7], state: "minecraft:gravel"},
        {pos: [13, 1, 8], state: "minecraft:mud_bricks"},
        {pos: [13, 1, 9], state: "minecraft:mud_bricks"},
        {pos: [13, 1, 10], state: "minecraft:mud_bricks"},
        {pos: [13, 1, 11], state: "minecraft:mud_bricks"},
        {pos: [13, 1, 12], state: "minecraft:gravel"},
        {pos: [13, 1, 13], state: "minecraft:gravel"},
        {pos: [13, 1, 14], state: "minecraft:mud_bricks"},
        {pos: [13, 1, 15], state: "minecraft:mud_bricks"},
        {pos: [13, 1, 16], state: "minecraft:gravel"},
        {pos: [13, 1, 17], state: "minecraft:gravel"},
        {pos: [13, 1, 18], state: "minecraft:mud_bricks"},
        {pos: [13, 1, 19], state: "minecraft:mud_bricks"},
        {pos: [13, 1, 20], state: "minecraft:mud_bricks"},
        {pos: [13, 1, 21], state: "minecraft:mud_bricks"},
        {pos: [14, 1, 8], state: "minecraft:mud_bricks"},
        {pos: [14, 1, 9], state: "minecraft:gravel"},
        {pos: [14, 1, 10], state: "minecraft:mud_bricks"},
        {pos: [14, 1, 12], state: "minecraft:gravel"},
        {pos: [14, 1, 14], state: "minecraft:gravel"},
        {pos: [14, 1, 17], state: "minecraft:gravel"},
        {pos: [14, 1, 18], state: "minecraft:mud_bricks"},
        {pos: [14, 1, 19], state: "minecraft:mud_bricks"},
        {pos: [14, 1, 20], state: "minecraft:gravel"},
        {pos: [14, 1, 21], state: "minecraft:gravel"},
        {pos: [0, 2, 7], state: "minecraft:gravel"},
        {pos: [0, 2, 8], state: "minecraft:gravel"},
        {pos: [1, 2, 5], state: "minecraft:gravel"},
        {pos: [1, 2, 6], state: "minecraft:mud_bricks"},
        {pos: [1, 2, 7], state: "minecraft:mud_bricks"},
        {pos: [1, 2, 8], state: "minecraft:mud_bricks"},
        {pos: [1, 2, 9], state: "minecraft:gravel"},
        {pos: [1, 2, 10], state: "minecraft:gravel"},
        {pos: [1, 2, 15], state: "minecraft:gravel"},
        {pos: [1, 2, 16], state: "minecraft:gravel"},
        {pos: [1, 2, 17], state: "minecraft:gravel"},
        {pos: [1, 2, 18], state: "minecraft:mud_bricks"},
        {pos: [1, 2, 19], state: "minecraft:mud_bricks"},
        {pos: [1, 2, 20], state: "minecraft:mud_bricks"},
        {pos: [2, 2, 4], state: "minecraft:mud_bricks"},
        {pos: [2, 2, 5], state: "minecraft:mud_bricks"},
        {pos: [2, 2, 6], state: "minecraft:gravel"},
        {pos: [2, 2, 7], state: "minecraft:gravel"},
        {pos: [2, 2, 8], state: "minecraft:gravel"},
        {pos: [2, 2, 9], state: "minecraft:mud_bricks"},
        {pos: [2, 2, 10], state: "minecraft:mud_bricks"},
        {pos: [2, 2, 11], state: "minecraft:mud_bricks"},
        {pos: [2, 2, 13], state: "minecraft:gravel"},
        {pos: [2, 2, 14], state: "minecraft:mud_bricks"},
        {pos: [2, 2, 15], state: "minecraft:mud_bricks"},
        {pos: [2, 2, 16], state: "minecraft:mud_bricks"},
        {pos: [2, 2, 17], state: "minecraft:gravel"},
        {pos: [2, 2, 18], state: "minecraft:mud_bricks"},
        {pos: [2, 2, 19], state: "minecraft:gravel"},
        {pos: [2, 2, 20], state: "minecraft:mud_bricks"},
        {pos: [2, 2, 21], state: "minecraft:gravel"},
        {pos: [3, 2, 2], state: "minecraft:gravel"},
        {pos: [3, 2, 3], state: "minecraft:gravel"},
        {pos: [3, 2, 4], state: "minecraft:gravel"},
        {pos: [3, 2, 5], state: "minecraft:gravel"},
        {pos: [3, 2, 6], state: "minecraft:gravel"},
        {pos: [3, 2, 7], state: "minecraft:gravel"},
        {pos: [3, 2, 8], state: "minecraft:gravel"},
        {pos: [3, 2, 9], state: "minecraft:gravel"},
        {pos: [3, 2, 10], state: "minecraft:gravel"},
        {pos: [3, 2, 11], state: "minecraft:gravel"},
        {pos: [3, 2, 12], state: "minecraft:gravel"},
        {pos: [3, 2, 13], state: "minecraft:gravel"},
        {pos: [3, 2, 14], state: "minecraft:gravel"},
        {pos: [3, 2, 15], state: "minecraft:gravel"},
        {pos: [3, 2, 16], state: "minecraft:gravel"},
        {pos: [3, 2, 17], state: "minecraft:gravel"},
        {pos: [3, 2, 18], state: "minecraft:mud_bricks"},
        {pos: [3, 2, 19], state: "minecraft:mud_bricks"},
        {pos: [3, 2, 20], state: "minecraft:mud_bricks"},
        {pos: [3, 2, 21], state: "minecraft:gravel"},
        {pos: [4, 2, 1], state: "minecraft:gravel"},
        {pos: [4, 2, 2], state: "minecraft:gravel"},
        {pos: [4, 2, 3], state: "minecraft:gravel"},
        {pos: [4, 2, 4], state: "minecraft:gravel"},
        {pos: [4, 2, 5], state: "minecraft:gravel"},
        {pos: [4, 2, 6], state: "minecraft:gravel"},
        {pos: [4, 2, 7], state: "minecraft:gravel"},
        {pos: [4, 2, 8], state: "minecraft:gravel"},
        {pos: [4, 2, 9], state: "minecraft:gravel"},
        {pos: [4, 2, 10], state: "minecraft:gravel"},
        {pos: [4, 2, 11], state: "minecraft:gravel"},
        {pos: [4, 2, 12], state: "minecraft:gravel"},
        {pos: [4, 2, 13], state: "minecraft:gravel"},
        {pos: [4, 2, 14], state: "minecraft:gravel"},
        {pos: [4, 2, 15], state: "minecraft:gravel"},
        {pos: [4, 2, 16], state: "minecraft:gravel"},
        {pos: [4, 2, 17], state: "minecraft:gravel"},
        {pos: [4, 2, 18], state: "minecraft:gravel"},
        {pos: [4, 2, 19], state: "minecraft:gravel"},
        {pos: [4, 2, 20], state: "minecraft:gravel"},
        {pos: [4, 2, 21], state: "minecraft:gravel"},
        {pos: [5, 2, 1], state: "minecraft:mud_bricks"},
        {pos: [5, 2, 2], state: "minecraft:gravel"},
        {pos: [5, 2, 3], state: "minecraft:gravel"},
        {pos: [5, 2, 4], state: "minecraft:gravel"},
        {pos: [5, 2, 5], state: "minecraft:gravel"},
        {pos: [5, 2, 6], state: "minecraft:gravel"},
        {pos: [5, 2, 7], state: "minecraft:gravel"},
        {pos: [5, 2, 8], state: "minecraft:gravel"},
        {pos: [5, 2, 9], state: "minecraft:gravel"},
        {pos: [5, 2, 10], state: "minecraft:gravel"},
        {pos: [5, 2, 11], state: "minecraft:gravel"},
        {pos: [5, 2, 12], state: "minecraft:gravel"},
        {pos: [5, 2, 13], state: "minecraft:gravel"},
        {pos: [5, 2, 14], state: "minecraft:gravel"},
        {pos: [5, 2, 15], state: "minecraft:gravel"},
        {pos: [5, 2, 16], state: "minecraft:gravel"},
        {pos: [5, 2, 17], state: "minecraft:gravel"},
        {pos: [5, 2, 18], state: "minecraft:gravel"},
        {pos: [5, 2, 19], state: "minecraft:gravel"},
        {pos: [5, 2, 20], state: "minecraft:gravel"},
        {pos: [5, 2, 21], state: "minecraft:gravel"},
        {pos: [5, 2, 22], state: "minecraft:gravel"},
        {pos: [6, 2, 0], state: "minecraft:gravel"},
        {pos: [6, 2, 1], state: "minecraft:gravel"},
        {pos: [6, 2, 2], state: "minecraft:gravel"},
        {pos: [6, 2, 3], state: "minecraft:gravel"},
        {pos: [6, 2, 4], state: "minecraft:gravel"},
        {pos: [6, 2, 5], state: "minecraft:gravel"},
        {pos: [6, 2, 6], state: "minecraft:gravel"},
        {pos: [6, 2, 7], state: "minecraft:gravel"},
        {pos: [6, 2, 8], state: "minecraft:gravel"},
        {pos: [6, 2, 9], state: "minecraft:gravel"},
        {pos: [6, 2, 10], state: "minecraft:gravel"},
        {pos: [6, 2, 11], state: "minecraft:gravel"},
        {pos: [6, 2, 12], state: "minecraft:gravel"},
        {pos: [6, 2, 15], state: "minecraft:gravel"},
        {pos: [6, 2, 16], state: "minecraft:gravel"},
        {pos: [6, 2, 17], state: "minecraft:gravel"},
        {pos: [6, 2, 18], state: "minecraft:mud_brick_stairs{facing:south,half:bottom,shape:outer_left,waterlogged:false}"},
        {pos: [6, 2, 19], state: "minecraft:mud_brick_stairs{facing:east,half:bottom,shape:straight,waterlogged:false}"},
        {pos: [6, 2, 20], state: "minecraft:mud_bricks"},
        {pos: [6, 2, 21], state: "minecraft:gravel"},
        {pos: [6, 2, 22], state: "minecraft:gravel"},
        {pos: [7, 2, 0], state: "minecraft:gravel"},
        {pos: [7, 2, 1], state: "minecraft:gravel"},
        {pos: [7, 2, 2], state: "minecraft:gravel"},
        {pos: [7, 2, 3], state: "minecraft:gravel"},
        {pos: [7, 2, 4], state: "minecraft:gravel"},
        {pos: [7, 2, 5], state: "minecraft:gravel"},
        {pos: [7, 2, 8], state: "minecraft:gravel"},
        {pos: [7, 2, 9], state: "minecraft:gravel"},
        {pos: [7, 2, 10], state: "minecraft:gravel"},
        {pos: [7, 2, 11], state: "minecraft:gravel"},
        {pos: [7, 2, 12], state: "minecraft:gravel"},
        {pos: [7, 2, 13], state: "minecraft:gravel"},
        {pos: [7, 2, 15], state: "minecraft:gravel"},
        {pos: [7, 2, 16], state: "minecraft:gravel"},
        {pos: [7, 2, 17], state: "minecraft:gravel"},
        {pos: [7, 2, 18], state: "minecraft:mud_brick_stairs{facing:south,half:bottom,shape:straight,waterlogged:false}"},
        {pos: [7, 2, 19], state: "minecraft:gravel"},
        {pos: [7, 2, 20], state: "minecraft:mud_bricks"},
        {pos: [7, 2, 21], state: "minecraft:gravel"},
        {pos: [7, 2, 22], state: "minecraft:gravel"},
        {pos: [7, 2, 23], state: "minecraft:gravel"},
        {pos: [8, 2, 1], state: "minecraft:gravel"},
        {pos: [8, 2, 2], state: "minecraft:gravel"},
        {pos: [8, 2, 3], state: "minecraft:gravel"},
        {pos: [8, 2, 4], state: "minecraft:gravel"},
        {pos: [8, 2, 5], state: "minecraft:gravel"},
        {pos: [8, 2, 6], state: "minecraft:gravel"},
        {pos: [8, 2, 8], state: "minecraft:gravel"},
        {pos: [8, 2, 9], state: "minecraft:gravel"},
        {pos: [8, 2, 10], state: "minecraft:gravel"},
        {pos: [8, 2, 11], state: "minecraft:gravel"},
        {pos: [8, 2, 12], state: "minecraft:gravel"},
        {pos: [8, 2, 13], state: "minecraft:gravel"},
        {pos: [8, 2, 14], state: "minecraft:gravel"},
        {pos: [8, 2, 15], state: "minecraft:gravel"},
        {pos: [8, 2, 16], state: "minecraft:gravel"},
        {pos: [8, 2, 17], state: "minecraft:gravel"},
        {pos: [8, 2, 18], state: "minecraft:mud_brick_stairs{facing:west,half:bottom,shape:outer_left,waterlogged:false}"},
        {pos: [8, 2, 19], state: "minecraft:mud_brick_stairs{facing:west,half:bottom,shape:straight,waterlogged:false}"},
        {pos: [8, 2, 20], state: "minecraft:mud_brick_stairs{facing:west,half:bottom,shape:straight,waterlogged:false}"},
        {pos: [8, 2, 21], state: "minecraft:gravel"},
        {pos: [8, 2, 22], state: "minecraft:gravel"},
        {pos: [8, 2, 23], state: "minecraft:gravel"},
        {pos: [9, 2, 0], state: "minecraft:gravel"},
        {pos: [9, 2, 1], state: "minecraft:mud_bricks"},
        {pos: [9, 2, 2], state: "minecraft:gravel"},
        {pos: [9, 2, 3], state: "minecraft:gravel"},
        {pos: [9, 2, 4], state: "minecraft:gravel"},
        {pos: [9, 2, 5], state: "minecraft:gravel"},
        {pos: [9, 2, 6], state: "minecraft:gravel"},
        {pos: [9, 2, 7], state: "minecraft:gravel"},
        {pos: [9, 2, 8], state: "minecraft:gravel"},
        {pos: [9, 2, 9], state: "minecraft:gravel"},
        {pos: [9, 2, 10], state: "minecraft:gravel"},
        {pos: [9, 2, 11], state: "minecraft:gravel"},
        {pos: [9, 2, 12], state: "minecraft:gravel"},
        {pos: [9, 2, 13], state: "minecraft:gravel"},
        {pos: [9, 2, 14], state: "minecraft:gravel"},
        {pos: [9, 2, 15], state: "minecraft:gravel"},
        {pos: [9, 2, 16], state: "minecraft:gravel"},
        {pos: [9, 2, 17], state: "minecraft:gravel"},
        {pos: [9, 2, 18], state: "minecraft:gravel"},
        {pos: [9, 2, 19], state: "minecraft:gravel"},
        {pos: [9, 2, 20], state: "minecraft:gravel"},
        {pos: [9, 2, 21], state: "minecraft:gravel"},
        {pos: [9, 2, 22], state: "minecraft:gravel"},
        {pos: [10, 2, 1], state: "minecraft:gravel"},
        {pos: [10, 2, 2], state: "minecraft:gravel"},
        {pos: [10, 2, 3], state: "minecraft:gravel"},
        {pos: [10, 2, 4], state: "minecraft:gravel"},
        {pos: [10, 2, 5], state: "minecraft:gravel"},
        {pos: [10, 2, 6], state: "minecraft:gravel"},
        {pos: [10, 2, 7], state: "minecraft:gravel"},
        {pos: [10, 2, 8], state: "minecraft:gravel"},
        {pos: [10, 2, 9], state: "minecraft:gravel"},
        {pos: [10, 2, 10], state: "minecraft:gravel"},
        {pos: [10, 2, 11], state: "minecraft:gravel"},
        {pos: [10, 2, 12], state: "minecraft:gravel"},
        {pos: [10, 2, 16], state: "minecraft:gravel"},
        {pos: [10, 2, 17], state: "minecraft:gravel"},
        {pos: [10, 2, 18], state: "minecraft:gravel"},
        {pos: [10, 2, 19], state: "minecraft:gravel"},
        {pos: [10, 2, 20], state: "minecraft:gravel"},
        {pos: [10, 2, 21], state: "minecraft:gravel"},
        {pos: [11, 2, 2], state: "minecraft:gravel"},
        {pos: [11, 2, 3], state: "minecraft:mud_bricks"},
        {pos: [11, 2, 4], state: "minecraft:mud_bricks"},
        {pos: [11, 2, 5], state: "minecraft:gravel"},
        {pos: [11, 2, 6], state: "minecraft:gravel"},
        {pos: [11, 2, 8], state: "minecraft:gravel"},
        {pos: [11, 2, 9], state: "minecraft:gravel"},
        {pos: [11, 2, 13], state: "minecraft:gravel"},
        {pos: [11, 2, 15], state: "minecraft:gravel"},
        {pos: [11, 2, 16], state: "minecraft:gravel"},
        {pos: [11, 2, 17], state: "minecraft:gravel"},
        {pos: [11, 2, 18], state: "minecraft:mud_bricks"},
        {pos: [11, 2, 19], state: "minecraft:mud_bricks"},
        {pos: [11, 2, 20], state: "minecraft:mud_bricks"},
        {pos: [12, 2, 3], state: "minecraft:gravel"},
        {pos: [12, 2, 4], state: "minecraft:gravel"},
        {pos: [12, 2, 5], state: "minecraft:mud_bricks"},
        {pos: [12, 2, 6], state: "minecraft:mud_bricks"},
        {pos: [12, 2, 7], state: "minecraft:gravel"},
        {pos: [12, 2, 8], state: "minecraft:gravel"},
        {pos: [12, 2, 9], state: "minecraft:gravel"},
        {pos: [12, 2, 10], state: "minecraft:gravel"},
        {pos: [12, 2, 11], state: "minecraft:gravel"},
        {pos: [12, 2, 13], state: "minecraft:gravel"},
        {pos: [12, 2, 14], state: "minecraft:gravel"},
        {pos: [12, 2, 15], state: "minecraft:gravel"},
        {pos: [12, 2, 16], state: "minecraft:mud_bricks"},
        {pos: [12, 2, 17], state: "minecraft:mud_bricks"},
        {pos: [12, 2, 18], state: "minecraft:mud_bricks"},
        {pos: [12, 2, 19], state: "minecraft:gravel"},
        {pos: [12, 2, 20], state: "minecraft:mud_bricks"},
        {pos: [12, 2, 21], state: "minecraft:gravel"},
        {pos: [13, 2, 5], state: "minecraft:gravel"},
        {pos: [13, 2, 6], state: "minecraft:gravel"},
        {pos: [13, 2, 7], state: "minecraft:gravel"},
        {pos: [13, 2, 8], state: "minecraft:mud_bricks"},
        {pos: [13, 2, 9], state: "minecraft:mud_bricks"},
        {pos: [13, 2, 10], state: "minecraft:gravel"},
        {pos: [13, 2, 11], state: "minecraft:mud_bricks"},
        {pos: [13, 2, 12], state: "minecraft:mud_bricks"},
        {pos: [13, 2, 13], state: "minecraft:mud_bricks"},
        {pos: [13, 2, 14], state: "minecraft:mud_bricks"},
        {pos: [13, 2, 15], state: "minecraft:mud_bricks"},
        {pos: [13, 2, 16], state: "minecraft:gravel"},
        {pos: [13, 2, 17], state: "minecraft:gravel"},
        {pos: [13, 2, 18], state: "minecraft:mud_bricks"},
        {pos: [13, 2, 19], state: "minecraft:mud_bricks"},
        {pos: [13, 2, 20], state: "minecraft:mud_bricks"},
        {pos: [13, 2, 21], state: "minecraft:gravel"},
        {pos: [14, 2, 8], state: "minecraft:gravel"},
        {pos: [14, 2, 9], state: "minecraft:gravel"},
        {pos: [14, 2, 10], state: "minecraft:gravel"},
        {pos: [14, 2, 12], state: "minecraft:gravel"},
        {pos: [14, 2, 14], state: "minecraft:gravel"},
        {pos: [14, 2, 17], state: "minecraft:gravel"},
        {pos: [14, 2, 18], state: "minecraft:gravel"},
        {pos: [14, 2, 19], state: "minecraft:gravel"},
        {pos: [14, 2, 20], state: "minecraft:gravel"},
        {pos: [14, 2, 21], state: "minecraft:gravel"},
        {pos: [0, 3, 7], state: "minecraft:gravel"},
        {pos: [0, 3, 8], state: "minecraft:gravel"},
        {pos: [1, 3, 5], state: "minecraft:gravel"},
        {pos: [1, 3, 6], state: "minecraft:gravel"},
        {pos: [1, 3, 7], state: "minecraft:gravel"},
        {pos: [1, 3, 8], state: "minecraft:gravel"},
        {pos: [1, 3, 15], state: "minecraft:gravel"},
        {pos: [1, 3, 16], state: "minecraft:gravel"},
        {pos: [1, 3, 17], state: "minecraft:gravel"},
        {pos: [1, 3, 18], state: "minecraft:mud_bricks"},
        {pos: [1, 3, 19], state: "minecraft:mud_bricks"},
        {pos: [1, 3, 20], state: "minecraft:mud_bricks"},
        {pos: [2, 3, 4], state: "minecraft:gravel"},
        {pos: [2, 3, 5], state: "minecraft:gravel"},
        {pos: [2, 3, 6], state: "minecraft:gravel"},
        {pos: [2, 3, 7], state: "minecraft:gravel"},
        {pos: [2, 3, 8], state: "minecraft:gravel"},
        {pos: [2, 3, 9], state: "minecraft:gravel"},
        {pos: [2, 3, 10], state: "minecraft:gravel"},
        {pos: [2, 3, 11], state: "minecraft:gravel"},
        {pos: [2, 3, 13], state: "minecraft:gravel"},
        {pos: [2, 3, 14], state: "minecraft:gravel"},
        {pos: [2, 3, 15], state: "minecraft:gravel"},
        {pos: [2, 3, 16], state: "minecraft:gravel"},
        {pos: [2, 3, 17], state: "minecraft:gravel"},
        {pos: [2, 3, 18], state: "minecraft:mud_bricks"},
        {pos: [2, 3, 19], state: "minecraft:gravel"},
        {pos: [2, 3, 20], state: "minecraft:mud_bricks"},
        {pos: [2, 3, 21], state: "minecraft:gravel"},
        {pos: [3, 3, 2], state: "minecraft:gravel"},
        {pos: [3, 3, 3], state: "minecraft:gravel"},
        {pos: [3, 3, 4], state: "minecraft:gravel"},
        {pos: [3, 3, 5], state: "minecraft:gravel"},
        {pos: [3, 3, 6], state: "minecraft:gravel"},
        {pos: [3, 3, 7], state: "minecraft:gravel"},
        {pos: [3, 3, 8], state: "minecraft:gravel"},
        {pos: [3, 3, 9], state: "minecraft:gravel"},
        {pos: [3, 3, 10], state: "minecraft:gravel"},
        {pos: [3, 3, 11], state: "minecraft:gravel"},
        {pos: [3, 3, 12], state: "minecraft:gravel"},
        {pos: [3, 3, 13], state: "minecraft:gravel"},
        {pos: [3, 3, 14], state: "minecraft:gravel"},
        {pos: [3, 3, 15], state: "minecraft:gravel"},
        {pos: [3, 3, 16], state: "minecraft:gravel"},
        {pos: [3, 3, 17], state: "minecraft:gravel"},
        {pos: [3, 3, 18], state: "minecraft:mud_bricks"},
        {pos: [3, 3, 19], state: "minecraft:mud_bricks"},
        {pos: [3, 3, 20], state: "minecraft:mud_bricks"},
        {pos: [3, 3, 21], state: "minecraft:gravel"},
        {pos: [4, 3, 1], state: "minecraft:gravel"},
        {pos: [4, 3, 2], state: "minecraft:gravel"},
        {pos: [4, 3, 3], state: "minecraft:gravel"},
        {pos: [4, 3, 4], state: "minecraft:gravel"},
        {pos: [4, 3, 5], state: "minecraft:gravel"},
        {pos: [4, 3, 6], state: "minecraft:gravel"},
        {pos: [4, 3, 7], state: "minecraft:gravel"},
        {pos: [4, 3, 8], state: "minecraft:gravel"},
        {pos: [4, 3, 9], state: "minecraft:gravel"},
        {pos: [4, 3, 10], state: "minecraft:gravel"},
        {pos: [4, 3, 11], state: "minecraft:gravel"},
        {pos: [4, 3, 12], state: "minecraft:gravel"},
        {pos: [4, 3, 13], state: "minecraft:gravel"},
        {pos: [4, 3, 14], state: "minecraft:gravel"},
        {pos: [4, 3, 15], state: "minecraft:gravel"},
        {pos: [4, 3, 16], state: "minecraft:gravel"},
        {pos: [4, 3, 17], state: "minecraft:gravel"},
        {pos: [4, 3, 18], state: "minecraft:gravel"},
        {pos: [4, 3, 19], state: "minecraft:gravel"},
        {pos: [4, 3, 20], state: "minecraft:gravel"},
        {pos: [4, 3, 21], state: "minecraft:gravel"},
        {pos: [5, 3, 1], state: "minecraft:mud_bricks"},
        {pos: [5, 3, 2], state: "minecraft:gravel"},
        {pos: [5, 3, 3], state: "minecraft:gravel"},
        {pos: [5, 3, 4], state: "minecraft:gravel"},
        {pos: [5, 3, 5], state: "minecraft:gravel"},
        {pos: [5, 3, 6], state: "minecraft:gravel"},
        {pos: [5, 3, 7], state: "minecraft:gravel"},
        {pos: [5, 3, 8], state: "minecraft:gravel"},
        {pos: [5, 3, 9], state: "minecraft:gravel"},
        {pos: [5, 3, 10], state: "minecraft:gravel"},
        {pos: [5, 3, 11], state: "minecraft:gravel"},
        {pos: [5, 3, 12], state: "minecraft:gravel"},
        {pos: [5, 3, 13], state: "minecraft:gravel"},
        {pos: [5, 3, 14], state: "minecraft:gravel"},
        {pos: [5, 3, 15], state: "minecraft:gravel"},
        {pos: [5, 3, 16], state: "minecraft:gravel"},
        {pos: [5, 3, 17], state: "minecraft:gravel"},
        {pos: [5, 3, 18], state: "minecraft:gravel"},
        {pos: [5, 3, 19], state: "minecraft:gravel"},
        {pos: [5, 3, 20], state: "minecraft:gravel"},
        {pos: [5, 3, 21], state: "minecraft:gravel"},
        {pos: [5, 3, 22], state: "minecraft:gravel"},
        {pos: [6, 3, 0], state: "minecraft:gravel"},
        {pos: [6, 3, 1], state: "minecraft:gravel"},
        {pos: [6, 3, 2], state: "minecraft:gravel"},
        {pos: [6, 3, 3], state: "minecraft:gravel"},
        {pos: [6, 3, 4], state: "minecraft:gravel"},
        {pos: [6, 3, 5], state: "minecraft:gravel"},
        {pos: [6, 3, 6], state: "minecraft:gravel"},
        {pos: [6, 3, 7], state: "minecraft:gravel"},
        {pos: [6, 3, 8], state: "minecraft:gravel"},
        {pos: [6, 3, 9], state: "minecraft:gravel"},
        {pos: [6, 3, 10], state: "minecraft:gravel"},
        {pos: [6, 3, 11], state: "minecraft:gravel"},
        {pos: [6, 3, 12], state: "minecraft:gravel"},
        {pos: [6, 3, 15], state: "minecraft:gravel"},
        {pos: [6, 3, 16], state: "minecraft:gravel"},
        {pos: [6, 3, 17], state: "minecraft:gravel"},
        {pos: [6, 3, 18], state: "minecraft:mud_bricks"},
        {pos: [6, 3, 19], state: "minecraft:mud_bricks"},
        {pos: [6, 3, 20], state: "minecraft:mud_bricks"},
        {pos: [6, 3, 21], state: "minecraft:gravel"},
        {pos: [6, 3, 22], state: "minecraft:gravel"},
        {pos: [7, 3, 0], state: "minecraft:gravel"},
        {pos: [7, 3, 1], state: "minecraft:gravel"},
        {pos: [7, 3, 2], state: "minecraft:gravel"},
        {pos: [7, 3, 3], state: "minecraft:gravel"},
        {pos: [7, 3, 4], state: "minecraft:gravel"},
        {pos: [7, 3, 5], state: "minecraft:gravel"},
        {pos: [7, 3, 8], state: "minecraft:gravel"},
        {pos: [7, 3, 9], state: "minecraft:gravel"},
        {pos: [7, 3, 10], state: "minecraft:gravel"},
        {pos: [7, 3, 11], state: "minecraft:gravel"},
        {pos: [7, 3, 12], state: "minecraft:gravel"},
        {pos: [7, 3, 13], state: "minecraft:gravel"},
        {pos: [7, 3, 15], state: "minecraft:gravel"},
        {pos: [7, 3, 16], state: "minecraft:gravel"},
        {pos: [7, 3, 17], state: "minecraft:gravel"},
        {pos: [7, 3, 18], state: "minecraft:mud_brick_stairs{facing:south,half:top,shape:straight,waterlogged:false}"},
        {pos: [7, 3, 19], state: "minecraft:mud_bricks"},
        {pos: [7, 3, 20], state: "minecraft:mud_bricks"},
        {pos: [7, 3, 21], state: "minecraft:gravel"},
        {pos: [7, 3, 22], state: "minecraft:gravel"},
        {pos: [7, 3, 23], state: "minecraft:gravel"},
        {pos: [8, 3, 1], state: "minecraft:gravel"},
        {pos: [8, 3, 2], state: "minecraft:gravel"},
        {pos: [8, 3, 3], state: "minecraft:gravel"},
        {pos: [8, 3, 4], state: "minecraft:gravel"},
        {pos: [8, 3, 5], state: "minecraft:gravel"},
        {pos: [8, 3, 6], state: "minecraft:gravel"},
        {pos: [8, 3, 8], state: "minecraft:gravel"},
        {pos: [8, 3, 9], state: "minecraft:gravel"},
        {pos: [8, 3, 10], state: "minecraft:gravel"},
        {pos: [8, 3, 11], state: "minecraft:gravel"},
        {pos: [8, 3, 12], state: "minecraft:gravel"},
        {pos: [8, 3, 13], state: "minecraft:gravel"},
        {pos: [8, 3, 14], state: "minecraft:gravel"},
        {pos: [8, 3, 15], state: "minecraft:gravel"},
        {pos: [8, 3, 16], state: "minecraft:gravel"},
        {pos: [8, 3, 17], state: "minecraft:gravel"},
        {pos: [8, 3, 18], state: "minecraft:mud_bricks"},
        {pos: [8, 3, 19], state: "minecraft:mud_bricks"},
        {pos: [8, 3, 20], state: "minecraft:mud_bricks"},
        {pos: [8, 3, 21], state: "minecraft:gravel"},
        {pos: [8, 3, 22], state: "minecraft:gravel"},
        {pos: [8, 3, 23], state: "minecraft:gravel"},
        {pos: [9, 3, 0], state: "minecraft:gravel"},
        {pos: [9, 3, 1], state: "minecraft:gravel"},
        {pos: [9, 3, 2], state: "minecraft:gravel"},
        {pos: [9, 3, 3], state: "minecraft:gravel"},
        {pos: [9, 3, 4], state: "minecraft:gravel"},
        {pos: [9, 3, 5], state: "minecraft:gravel"},
        {pos: [9, 3, 6], state: "minecraft:gravel"},
        {pos: [9, 3, 7], state: "minecraft:gravel"},
        {pos: [9, 3, 8], state: "minecraft:gravel"},
        {pos: [9, 3, 9], state: "minecraft:gravel"},
        {pos: [9, 3, 10], state: "minecraft:gravel"},
        {pos: [9, 3, 11], state: "minecraft:gravel"},
        {pos: [9, 3, 12], state: "minecraft:gravel"},
        {pos: [9, 3, 13], state: "minecraft:gravel"},
        {pos: [9, 3, 14], state: "minecraft:gravel"},
        {pos: [9, 3, 15], state: "minecraft:gravel"},
        {pos: [9, 3, 16], state: "minecraft:gravel"},
        {pos: [9, 3, 17], state: "minecraft:gravel"},
        {pos: [9, 3, 18], state: "minecraft:gravel"},
        {pos: [9, 3, 19], state: "minecraft:gravel"},
        {pos: [9, 3, 20], state: "minecraft:gravel"},
        {pos: [9, 3, 21], state: "minecraft:gravel"},
        {pos: [9, 3, 22], state: "minecraft:gravel"},
        {pos: [10, 3, 1], state: "minecraft:gravel"},
        {pos: [10, 3, 2], state: "minecraft:gravel"},
        {pos: [10, 3, 3], state: "minecraft:gravel"},
        {pos: [10, 3, 4], state: "minecraft:gravel"},
        {pos: [10, 3, 5], state: "minecraft:gravel"},
        {pos: [10, 3, 6], state: "minecraft:gravel"},
        {pos: [10, 3, 7], state: "minecraft:gravel"},
        {pos: [10, 3, 8], state: "minecraft:gravel"},
        {pos: [10, 3, 9], state: "minecraft:gravel"},
        {pos: [10, 3, 10], state: "minecraft:gravel"},
        {pos: [10, 3, 11], state: "minecraft:gravel"},
        {pos: [10, 3, 12], state: "minecraft:gravel"},
        {pos: [10, 3, 16], state: "minecraft:gravel"},
        {pos: [10, 3, 17], state: "minecraft:gravel"},
        {pos: [10, 3, 18], state: "minecraft:gravel"},
        {pos: [10, 3, 19], state: "minecraft:gravel"},
        {pos: [10, 3, 20], state: "minecraft:gravel"},
        {pos: [10, 3, 21], state: "minecraft:gravel"},
        {pos: [11, 3, 2], state: "minecraft:gravel"},
        {pos: [11, 3, 3], state: "minecraft:gravel"},
        {pos: [11, 3, 4], state: "minecraft:gravel"},
        {pos: [11, 3, 5], state: "minecraft:gravel"},
        {pos: [11, 3, 6], state: "minecraft:gravel"},
        {pos: [11, 3, 8], state: "minecraft:gravel"},
        {pos: [11, 3, 9], state: "minecraft:gravel"},
        {pos: [11, 3, 13], state: "minecraft:gravel"},
        {pos: [11, 3, 15], state: "minecraft:gravel"},
        {pos: [11, 3, 16], state: "minecraft:gravel"},
        {pos: [11, 3, 17], state: "minecraft:gravel"},
        {pos: [11, 3, 18], state: "minecraft:mud_bricks"},
        {pos: [11, 3, 19], state: "minecraft:mud_bricks"},
        {pos: [11, 3, 20], state: "minecraft:mud_bricks"},
        {pos: [12, 3, 3], state: "minecraft:gravel"},
        {pos: [12, 3, 4], state: "minecraft:gravel"},
        {pos: [12, 3, 5], state: "minecraft:gravel"},
        {pos: [12, 3, 6], state: "minecraft:gravel"},
        {pos: [12, 3, 7], state: "minecraft:gravel"},
        {pos: [12, 3, 8], state: "minecraft:gravel"},
        {pos: [12, 3, 9], state: "minecraft:gravel"},
        {pos: [12, 3, 10], state: "minecraft:gravel"},
        {pos: [12, 3, 11], state: "minecraft:gravel"},
        {pos: [12, 3, 13], state: "minecraft:gravel"},
        {pos: [12, 3, 14], state: "minecraft:gravel"},
        {pos: [12, 3, 15], state: "minecraft:gravel"},
        {pos: [12, 3, 16], state: "minecraft:gravel"},
        {pos: [12, 3, 17], state: "minecraft:gravel"},
        {pos: [12, 3, 18], state: "minecraft:mud_bricks"},
        {pos: [12, 3, 19], state: "minecraft:gravel"},
        {pos: [12, 3, 20], state: "minecraft:mud_bricks"},
        {pos: [12, 3, 21], state: "minecraft:gravel"},
        {pos: [13, 3, 5], state: "minecraft:gravel"},
        {pos: [13, 3, 6], state: "minecraft:gravel"},
        {pos: [13, 3, 7], state: "minecraft:gravel"},
        {pos: [13, 3, 8], state: "minecraft:gravel"},
        {pos: [13, 3, 9], state: "minecraft:mud_bricks"},
        {pos: [13, 3, 10], state: "minecraft:gravel"},
        {pos: [13, 3, 11], state: "minecraft:gravel"},
        {pos: [13, 3, 12], state: "minecraft:gravel"},
        {pos: [13, 3, 13], state: "minecraft:gravel"},
        {pos: [13, 3, 14], state: "minecraft:gravel"},
        {pos: [13, 3, 15], state: "minecraft:gravel"},
        {pos: [13, 3, 16], state: "minecraft:gravel"},
        {pos: [13, 3, 17], state: "minecraft:gravel"},
        {pos: [13, 3, 18], state: "minecraft:mud_bricks"},
        {pos: [13, 3, 19], state: "minecraft:mud_bricks"},
        {pos: [13, 3, 20], state: "minecraft:mud_bricks"},
        {pos: [13, 3, 21], state: "minecraft:gravel"},
        {pos: [14, 3, 8], state: "minecraft:gravel"},
        {pos: [14, 3, 9], state: "minecraft:gravel"},
        {pos: [14, 3, 10], state: "minecraft:gravel"},
        {pos: [14, 3, 14], state: "minecraft:gravel"},
        {pos: [14, 3, 17], state: "minecraft:gravel"},
        {pos: [14, 3, 18], state: "minecraft:gravel"},
        {pos: [14, 3, 19], state: "minecraft:gravel"},
        {pos: [14, 3, 20], state: "minecraft:gravel"},
        {pos: [14, 3, 21], state: "minecraft:gravel"},
        {pos: [1, 4, 17], state: "minecraft:gravel"},
        {pos: [1, 4, 18], state: "minecraft:mud_bricks"},
        {pos: [1, 4, 19], state: "minecraft:mud_bricks"},
        {pos: [1, 4, 20], state: "minecraft:mud_bricks"},
        {pos: [2, 4, 15], state: "minecraft:gravel"},
        {pos: [2, 4, 16], state: "minecraft:gravel"},
        {pos: [2, 4, 17], state: "minecraft:gravel"},
        {pos: [2, 4, 18], state: "minecraft:mud_bricks"},
        {pos: [2, 4, 19], state: "minecraft:gravel"},
        {pos: [2, 4, 20], state: "minecraft:mud_bricks"},
        {pos: [2, 4, 21], state: "minecraft:gravel"},
        {pos: [3, 4, 4], state: "minecraft:gravel"},
        {pos: [3, 4, 5], state: "minecraft:gravel"},
        {pos: [3, 4, 12], state: "minecraft:gravel"},
        {pos: [3, 4, 13], state: "minecraft:gravel"},
        {pos: [3, 4, 14], state: "minecraft:gravel"},
        {pos: [3, 4, 15], state: "minecraft:gravel"},
        {pos: [3, 4, 16], state: "minecraft:gravel"},
        {pos: [3, 4, 17], state: "minecraft:gravel"},
        {pos: [3, 4, 18], state: "minecraft:mud_bricks"},
        {pos: [3, 4, 19], state: "minecraft:mud_bricks"},
        {pos: [3, 4, 20], state: "minecraft:mud_bricks"},
        {pos: [3, 4, 21], state: "minecraft:gravel"},
        {pos: [4, 4, 3], state: "minecraft:gravel"},
        {pos: [4, 4, 4], state: "minecraft:gravel"},
        {pos: [4, 4, 5], state: "minecraft:gravel"},
        {pos: [4, 4, 11], state: "minecraft:gravel"},
        {pos: [4, 4, 12], state: "minecraft:gravel"},
        {pos: [4, 4, 13], state: "minecraft:gravel"},
        {pos: [4, 4, 14], state: "minecraft:gravel"},
        {pos: [4, 4, 15], state: "minecraft:gravel"},
        {pos: [4, 4, 16], state: "minecraft:gravel"},
        {pos: [4, 4, 17], state: "minecraft:gravel"},
        {pos: [4, 4, 18], state: "minecraft:gravel"},
        {pos: [4, 4, 19], state: "minecraft:gravel"},
        {pos: [4, 4, 20], state: "minecraft:gravel"},
        {pos: [4, 4, 21], state: "minecraft:gravel"},
        {pos: [5, 4, 1], state: "minecraft:gravel"},
        {pos: [5, 4, 2], state: "minecraft:gravel"},
        {pos: [5, 4, 3], state: "minecraft:gravel"},
        {pos: [5, 4, 4], state: "minecraft:gravel"},
        {pos: [5, 4, 5], state: "minecraft:gravel"},
        {pos: [5, 4, 6], state: "minecraft:gravel"},
        {pos: [5, 4, 9], state: "minecraft:gravel"},
        {pos: [5, 4, 10], state: "minecraft:gravel"},
        {pos: [5, 4, 11], state: "minecraft:gravel"},
        {pos: [5, 4, 12], state: "minecraft:gravel"},
        {pos: [5, 4, 13], state: "minecraft:gravel"},
        {pos: [5, 4, 16], state: "minecraft:gravel"},
        {pos: [5, 4, 17], state: "minecraft:gravel"},
        {pos: [5, 4, 18], state: "minecraft:gravel"},
        {pos: [5, 4, 19], state: "minecraft:gravel"},
        {pos: [5, 4, 20], state: "minecraft:gravel"},
        {pos: [5, 4, 21], state: "minecraft:gravel"},
        {pos: [6, 4, 1], state: "minecraft:gravel"},
        {pos: [6, 4, 2], state: "minecraft:gravel"},
        {pos: [6, 4, 3], state: "minecraft:gravel"},
        {pos: [6, 4, 4], state: "minecraft:gravel"},
        {pos: [6, 4, 5], state: "minecraft:gravel"},
        {pos: [6, 4, 9], state: "minecraft:gravel"},
        {pos: [6, 4, 10], state: "minecraft:gravel"},
        {pos: [6, 4, 11], state: "minecraft:gravel"},
        {pos: [6, 4, 12], state: "minecraft:gravel"},
        {pos: [6, 4, 16], state: "minecraft:gravel"},
        {pos: [6, 4, 17], state: "minecraft:gravel"},
        {pos: [6, 4, 18], state: "minecraft:mud_brick_stairs{facing:south,half:top,shape:straight,waterlogged:false}"},
        {pos: [6, 4, 19], state: "minecraft:mud_bricks"},
        {pos: [6, 4, 20], state: "minecraft:mud_bricks"},
        {pos: [6, 4, 21], state: "minecraft:gravel"},
        {pos: [6, 4, 22], state: "minecraft:gravel"},
        {pos: [7, 4, 2], state: "minecraft:gravel"},
        {pos: [7, 4, 3], state: "minecraft:gravel"},
        {pos: [7, 4, 4], state: "minecraft:gravel"},
        {pos: [7, 4, 8], state: "minecraft:gravel"},
        {pos: [7, 4, 9], state: "minecraft:gravel"},
        {pos: [7, 4, 10], state: "minecraft:gravel"},
        {pos: [7, 4, 11], state: "minecraft:gravel"},
        {pos: [7, 4, 16], state: "minecraft:gravel"},
        {pos: [7, 4, 17], state: "minecraft:gravel"},
        {pos: [7, 4, 18], state: "minecraft:mud_bricks"},
        {pos: [7, 4, 19], state: "minecraft:mud_bricks"},
        {pos: [7, 4, 20], state: "minecraft:mud_bricks"},
        {pos: [7, 4, 21], state: "minecraft:gravel"},
        {pos: [7, 4, 22], state: "minecraft:gravel"},
        {pos: [8, 4, 9], state: "minecraft:gravel"},
        {pos: [8, 4, 10], state: "minecraft:gravel"},
        {pos: [8, 4, 11], state: "minecraft:gravel"},
        {pos: [8, 4, 16], state: "minecraft:gravel"},
        {pos: [8, 4, 17], state: "minecraft:gravel"},
        {pos: [8, 4, 18], state: "minecraft:mud_brick_stairs{facing:south,half:top,shape:straight,waterlogged:false}"},
        {pos: [8, 4, 19], state: "minecraft:mud_bricks"},
        {pos: [8, 4, 20], state: "minecraft:mud_bricks"},
        {pos: [8, 4, 21], state: "minecraft:gravel"},
        {pos: [8, 4, 22], state: "minecraft:gravel"},
        {pos: [9, 4, 3], state: "minecraft:gravel"},
        {pos: [9, 4, 4], state: "minecraft:gravel"},
        {pos: [9, 4, 5], state: "minecraft:gravel"},
        {pos: [9, 4, 6], state: "minecraft:gravel"},
        {pos: [9, 4, 7], state: "minecraft:gravel"},
        {pos: [9, 4, 17], state: "minecraft:gravel"},
        {pos: [9, 4, 18], state: "minecraft:gravel"},
        {pos: [9, 4, 19], state: "minecraft:gravel"},
        {pos: [9, 4, 20], state: "minecraft:gravel"},
        {pos: [10, 4, 3], state: "minecraft:gravel"},
        {pos: [10, 4, 4], state: "minecraft:gravel"},
        {pos: [10, 4, 5], state: "minecraft:gravel"},
        {pos: [10, 4, 6], state: "minecraft:gravel"},
        {pos: [10, 4, 7], state: "minecraft:gravel"},
        {pos: [10, 4, 8], state: "minecraft:gravel"},
        {pos: [10, 4, 16], state: "minecraft:gravel"},
        {pos: [10, 4, 17], state: "minecraft:gravel"},
        {pos: [10, 4, 18], state: "minecraft:gravel"},
        {pos: [10, 4, 19], state: "minecraft:gravel"},
        {pos: [10, 4, 20], state: "minecraft:gravel"},
        {pos: [11, 4, 3], state: "minecraft:gravel"},
        {pos: [11, 4, 4], state: "minecraft:gravel"},
        {pos: [11, 4, 5], state: "minecraft:gravel"},
        {pos: [11, 4, 6], state: "minecraft:gravel"},
        {pos: [11, 4, 15], state: "minecraft:gravel"},
        {pos: [11, 4, 16], state: "minecraft:gravel"},
        {pos: [11, 4, 17], state: "minecraft:gravel"},
        {pos: [11, 4, 18], state: "minecraft:mud_bricks"},
        {pos: [11, 4, 19], state: "minecraft:mud_bricks"},
        {pos: [11, 4, 20], state: "minecraft:mud_bricks"},
        {pos: [12, 4, 4], state: "minecraft:gravel"},
        {pos: [12, 4, 5], state: "minecraft:gravel"},
        {pos: [12, 4, 6], state: "minecraft:gravel"},
        {pos: [12, 4, 8], state: "minecraft:gravel"},
        {pos: [12, 4, 9], state: "minecraft:gravel"},
        {pos: [12, 4, 10], state: "minecraft:gravel"},
        {pos: [12, 4, 11], state: "minecraft:gravel"},
        {pos: [12, 4, 13], state: "minecraft:gravel"},
        {pos: [12, 4, 14], state: "minecraft:gravel"},
        {pos: [12, 4, 15], state: "minecraft:gravel"},
        {pos: [12, 4, 16], state: "minecraft:gravel"},
        {pos: [12, 4, 17], state: "minecraft:gravel"},
        {pos: [12, 4, 18], state: "minecraft:mud_bricks"},
        {pos: [12, 4, 19], state: "minecraft:gravel"},
        {pos: [12, 4, 20], state: "minecraft:mud_bricks"},
        {pos: [12, 4, 21], state: "minecraft:gravel"},
        {pos: [13, 4, 5], state: "minecraft:gravel"},
        {pos: [13, 4, 8], state: "minecraft:gravel"},
        {pos: [13, 4, 9], state: "minecraft:gravel"},
        {pos: [13, 4, 10], state: "minecraft:gravel"},
        {pos: [13, 4, 12], state: "minecraft:gravel"},
        {pos: [13, 4, 13], state: "minecraft:gravel"},
        {pos: [13, 4, 14], state: "minecraft:gravel"},
        {pos: [13, 4, 15], state: "minecraft:gravel"},
        {pos: [13, 4, 16], state: "minecraft:gravel"},
        {pos: [13, 4, 17], state: "minecraft:gravel"},
        {pos: [13, 4, 18], state: "minecraft:mud_bricks"},
        {pos: [13, 4, 19], state: "minecraft:mud_bricks"},
        {pos: [13, 4, 20], state: "minecraft:mud_bricks"},
        {pos: [13, 4, 21], state: "minecraft:gravel"},
        {pos: [14, 4, 8], state: "minecraft:gravel"},
        {pos: [14, 4, 9], state: "minecraft:gravel"},
        {pos: [14, 4, 17], state: "minecraft:gravel"},
        {pos: [14, 4, 18], state: "minecraft:gravel"},
        {pos: [14, 4, 19], state: "minecraft:gravel"},
        {pos: [14, 4, 20], state: "minecraft:gravel"},
        {pos: [1, 5, 17], state: "minecraft:gravel"},
        {pos: [1, 5, 18], state: "minecraft:mud_bricks"},
        {pos: [1, 5, 19], state: "minecraft:mud_bricks"},
        {pos: [1, 5, 20], state: "minecraft:mud_bricks"},
        {pos: [2, 5, 17], state: "minecraft:gravel"},
        {pos: [2, 5, 18], state: "minecraft:mud_bricks"},
        {pos: [2, 5, 19], state: "minecraft:gravel"},
        {pos: [2, 5, 20], state: "minecraft:mud_bricks"},
        {pos: [2, 5, 21], state: "minecraft:gravel"},
        {pos: [3, 5, 17], state: "minecraft:gravel"},
        {pos: [3, 5, 18], state: "minecraft:mud_bricks"},
        {pos: [3, 5, 19], state: "minecraft:mud_bricks"},
        {pos: [3, 5, 20], state: "minecraft:mud_bricks"},
        {pos: [3, 5, 21], state: "minecraft:gravel"},
        {pos: [4, 5, 4], state: "minecraft:gravel"},
        {pos: [4, 5, 18], state: "minecraft:gravel"},
        {pos: [4, 5, 19], state: "minecraft:gravel"},
        {pos: [4, 5, 20], state: "minecraft:gravel"},
        {pos: [4, 5, 21], state: "minecraft:gravel"},
        {pos: [5, 5, 3], state: "minecraft:gravel"},
        {pos: [5, 5, 4], state: "minecraft:gravel"},
        {pos: [5, 5, 5], state: "minecraft:gravel"},
        {pos: [5, 5, 10], state: "minecraft:gravel"},
        {pos: [5, 5, 11], state: "minecraft:gravel"},
        {pos: [5, 5, 18], state: "minecraft:gravel"},
        {pos: [5, 5, 19], state: "minecraft:gravel"},
        {pos: [6, 5, 2], state: "minecraft:gravel"},
        {pos: [6, 5, 3], state: "minecraft:gravel"},
        {pos: [6, 5, 4], state: "minecraft:gravel"},
        {pos: [6, 5, 5], state: "minecraft:gravel"},
        {pos: [6, 5, 9], state: "minecraft:gravel"},
        {pos: [6, 5, 10], state: "minecraft:gravel"},
        {pos: [6, 5, 11], state: "minecraft:gravel"},
        {pos: [6, 5, 17], state: "minecraft:gravel"},
        {pos: [6, 5, 18], state: "minecraft:gravel"},
        {pos: [6, 5, 19], state: "minecraft:gravel"},
        {pos: [6, 5, 20], state: "minecraft:gravel"},
        {pos: [6, 5, 21], state: "minecraft:gravel"},
        {pos: [7, 5, 4], state: "minecraft:gravel"},
        {pos: [7, 5, 10], state: "minecraft:gravel"},
        {pos: [7, 5, 17], state: "minecraft:gravel"},
        {pos: [7, 5, 18], state: "minecraft:gravel"},
        {pos: [7, 5, 19], state: "minecraft:gravel"},
        {pos: [7, 5, 20], state: "minecraft:gravel"},
        {pos: [7, 5, 21], state: "minecraft:gravel"},
        {pos: [8, 5, 17], state: "minecraft:gravel"},
        {pos: [8, 5, 18], state: "minecraft:gravel"},
        {pos: [8, 5, 19], state: "minecraft:gravel"},
        {pos: [8, 5, 20], state: "minecraft:gravel"},
        {pos: [8, 5, 21], state: "minecraft:gravel"},
        {pos: [9, 5, 17], state: "minecraft:gravel"},
        {pos: [9, 5, 18], state: "minecraft:gravel"},
        {pos: [9, 5, 19], state: "minecraft:gravel"},
        {pos: [10, 5, 4], state: "minecraft:gravel"},
        {pos: [10, 5, 5], state: "minecraft:gravel"},
        {pos: [10, 5, 6], state: "minecraft:gravel"},
        {pos: [10, 5, 17], state: "minecraft:gravel"},
        {pos: [10, 5, 18], state: "minecraft:gravel"},
        {pos: [10, 5, 19], state: "minecraft:gravel"},
        {pos: [10, 5, 20], state: "minecraft:gravel"},
        {pos: [11, 5, 4], state: "minecraft:gravel"},
        {pos: [11, 5, 5], state: "minecraft:gravel"},
        {pos: [11, 5, 18], state: "minecraft:gravel"},
        {pos: [11, 5, 19], state: "minecraft:mud_bricks"},
        {pos: [11, 5, 20], state: "minecraft:mud_bricks"},
        {pos: [12, 5, 8], state: "minecraft:gravel"},
        {pos: [12, 5, 9], state: "minecraft:gravel"},
        {pos: [12, 5, 17], state: "minecraft:gravel"},
        {pos: [12, 5, 18], state: "minecraft:gravel"},
        {pos: [12, 5, 19], state: "minecraft:gravel"},
        {pos: [12, 5, 20], state: "minecraft:mud_bricks"},
        {pos: [13, 5, 8], state: "minecraft:gravel"},
        {pos: [13, 5, 9], state: "minecraft:gravel"},
        {pos: [13, 5, 17], state: "minecraft:gravel"},
        {pos: [13, 5, 18], state: "minecraft:mud_bricks"},
        {pos: [13, 5, 19], state: "minecraft:mud_bricks"},
        {pos: [13, 5, 20], state: "minecraft:mud_bricks"},
        {pos: [13, 5, 21], state: "minecraft:gravel"},
        {pos: [14, 5, 18], state: "minecraft:gravel"},
        {pos: [14, 5, 19], state: "minecraft:gravel"},
        {pos: [1, 6, 18], state: "minecraft:mud_bricks"},
        {pos: [1, 6, 19], state: "minecraft:mud_bricks"},
        {pos: [1, 6, 20], state: "minecraft:mud_bricks"},
        {pos: [2, 6, 17], state: "minecraft:gravel"},
        {pos: [2, 6, 18], state: "minecraft:mud_bricks"},
        {pos: [2, 6, 19], state: "minecraft:gravel"},
        {pos: [2, 6, 20], state: "minecraft:mud_bricks"},
        {pos: [2, 6, 21], state: "minecraft:gravel"},
        {pos: [3, 6, 17], state: "minecraft:gravel"},
        {pos: [3, 6, 18], state: "minecraft:mud_bricks"},
        {pos: [3, 6, 19], state: "minecraft:mud_bricks"},
        {pos: [3, 6, 20], state: "minecraft:mud_bricks"},
        {pos: [3, 6, 21], state: "minecraft:gravel"},
        {pos: [4, 6, 18], state: "minecraft:gravel"},
        {pos: [4, 6, 19], state: "minecraft:gravel"},
        {pos: [4, 6, 20], state: "minecraft:gravel"},
        {pos: [6, 6, 18], state: "minecraft:gravel"},
        {pos: [6, 6, 19], state: "minecraft:gravel"},
        {pos: [6, 6, 20], state: "minecraft:gravel"},
        {pos: [7, 6, 18], state: "minecraft:gravel"},
        {pos: [7, 6, 19], state: "minecraft:gravel"},
        {pos: [7, 6, 20], state: "minecraft:gravel"},
        {pos: [8, 6, 18], state: "minecraft:gravel"},
        {pos: [8, 6, 19], state: "minecraft:gravel"},
        {pos: [8, 6, 20], state: "minecraft:gravel"},
        {pos: [9, 6, 18], state: "minecraft:gravel"},
        {pos: [9, 6, 19], state: "minecraft:gravel"},
        {pos: [11, 6, 19], state: "minecraft:gravel"},
        {pos: [11, 6, 20], state: "minecraft:mud_bricks"},
        {pos: [12, 6, 18], state: "minecraft:gravel"},
        {pos: [12, 6, 19], state: "minecraft:gravel"},
        {pos: [12, 6, 20], state: "minecraft:mud_bricks"},
        {pos: [13, 6, 18], state: "minecraft:gravel"},
        {pos: [13, 6, 19], state: "minecraft:gravel"},
        {pos: [13, 6, 20], state: "minecraft:mud_bricks"},
        {pos: [1, 7, 20], state: "minecraft:mud_bricks"},
        {pos: [2, 7, 18], state: "minecraft:mud_bricks"},
        {pos: [2, 7, 19], state: "minecraft:gravel"},
        {pos: [2, 7, 20], state: "minecraft:mud_bricks"},
        {pos: [2, 7, 21], state: "minecraft:gravel"},
        {pos: [3, 7, 18], state: "minecraft:mud_bricks"},
        {pos: [3, 7, 19], state: "minecraft:mud_bricks"},
        {pos: [3, 7, 20], state: "minecraft:mud_bricks"},
        {pos: [4, 7, 19], state: "minecraft:gravel"},
        {pos: [4, 7, 20], state: "minecraft:gravel"},
        {pos: [11, 7, 20], state: "minecraft:mud_bricks"},
        {pos: [12, 7, 20], state: "minecraft:mud_bricks"},
        {pos: [13, 7, 20], state: "minecraft:mud_bricks"},
        {pos: [2, 8, 19], state: "minecraft:gravel"},
        {pos: [2, 8, 20], state: "minecraft:mud_bricks"},
        {pos: [3, 8, 18], state: "minecraft:mud_bricks"},
        {pos: [3, 8, 19], state: "minecraft:mud_bricks"},
        {pos: [3, 8, 20], state: "minecraft:mud_bricks"},
        {pos: [4, 8, 19], state: "minecraft:gravel"},
        {pos: [12, 8, 20], state: "minecraft:mud_bricks"},
        {pos: [2, 9, 20], state: "minecraft:mud_bricks"},
        {pos: [3, 9, 19], state: "minecraft:mud_bricks"},
        {pos: [3, 9, 20], state: "minecraft:mud_bricks"}
    ],
    entities: [],
    palette: [
        "minecraft:mud_bricks",
        "minecraft:gravel",
        "minecraft:mud_brick_stairs{facing:north,half:bottom,shape:straight,waterlogged:false}",
        "minecraft:mud_brick_stairs{facing:west,half:bottom,shape:straight,waterlogged:false}",
        "minecraft:mud_brick_stairs{facing:south,half:bottom,shape:outer_left,waterlogged:false}",
        "minecraft:mud_brick_stairs{facing:east,half:bottom,shape:straight,waterlogged:false}",
        "minecraft:mud_brick_stairs{facing:south,half:bottom,shape:straight,waterlogged:false}",
        "minecraft:mud_brick_stairs{facing:west,half:bottom,shape:outer_left,waterlogged:false}",
        "minecraft:mud_brick_stairs{facing:south,half:top,shape:straight,waterlogged:false}"
    ],
    trailiertales_DataVersion: 2
}
