{
    DataVersion: 3953,
    size: [8, 14, 9],
    data: [
        {pos: [0, 0, 2], state: "minecraft:mud_bricks"},
        {pos: [0, 0, 3], state: "minecraft:mud_bricks"},
        {pos: [0, 0, 4], state: "minecraft:mud_bricks"},
        {pos: [0, 0, 5], state: "minecraft:mud_bricks"},
        {pos: [1, 0, 1], state: "minecraft:mud_bricks"},
        {pos: [1, 0, 2], state: "minecraft:mud_bricks"},
        {pos: [1, 0, 3], state: "minecraft:mud_bricks"},
        {pos: [1, 0, 4], state: "minecraft:mud_bricks"},
        {pos: [1, 0, 5], state: "minecraft:mud_bricks"},
        {pos: [1, 0, 6], state: "minecraft:mud_bricks"},
        {pos: [1, 0, 7], state: "minecraft:mud_bricks"},
        {pos: [2, 0, 1], state: "minecraft:mud_bricks"},
        {pos: [2, 0, 2], state: "minecraft:mud_bricks"},
        {pos: [2, 0, 3], state: "minecraft:mud_bricks"},
        {pos: [2, 0, 4], state: "minecraft:mud_bricks"},
        {pos: [2, 0, 5], state: "minecraft:mud_bricks"},
        {pos: [2, 0, 6], state: "minecraft:mud_bricks"},
        {pos: [2, 0, 7], state: "minecraft:mud_bricks"},
        {pos: [3, 0, 0], state: "minecraft:mud_bricks"},
        {pos: [3, 0, 1], state: "minecraft:mud_bricks"},
        {pos: [3, 0, 2], state: "minecraft:mud_bricks"},
        {pos: [3, 0, 3], state: "minecraft:mud_bricks"},
        {pos: [3, 0, 4], state: "minecraft:yellow_glazed_terracotta{facing:north}"},
        {pos: [3, 0, 5], state: "minecraft:yellow_glazed_terracotta{facing:west}"},
        {pos: [3, 0, 6], state: "minecraft:mud_bricks"},
        {pos: [3, 0, 7], state: "minecraft:mud_bricks"},
        {pos: [4, 0, 0], state: "minecraft:mud_bricks"},
        {pos: [4, 0, 1], state: "minecraft:mud_bricks"},
        {pos: [4, 0, 2], state: "minecraft:mud_bricks"},
        {pos: [4, 0, 3], state: "minecraft:mud_bricks"},
        {pos: [4, 0, 4], state: "minecraft:yellow_glazed_terracotta{facing:east}"},
        {pos: [4, 0, 5], state: "minecraft:yellow_glazed_terracotta{facing:south}"},
        {pos: [4, 0, 6], state: "minecraft:mud_bricks"},
        {pos: [4, 0, 7], state: "minecraft:mud_bricks"},
        {pos: [4, 0, 8], state: "minecraft:mud_bricks"},
        {pos: [5, 0, 1], state: "minecraft:mud_bricks"},
        {pos: [5, 0, 2], state: "minecraft:mud_bricks"},
        {pos: [5, 0, 3], state: "minecraft:mud_bricks"},
        {pos: [5, 0, 4], state: "minecraft:mud_bricks"},
        {pos: [5, 0, 5], state: "minecraft:mud_bricks"},
        {pos: [5, 0, 6], state: "minecraft:mud_bricks"},
        {pos: [5, 0, 7], state: "minecraft:mud_bricks"},
        {pos: [5, 0, 8], state: "minecraft:mud_bricks"},
        {pos: [6, 0, 2], state: "minecraft:mud_bricks"},
        {pos: [6, 0, 3], state: "minecraft:mud_bricks"},
        {pos: [6, 0, 4], state: "minecraft:mud_bricks"},
        {pos: [6, 0, 5], state: "minecraft:mud_bricks"},
        {pos: [6, 0, 6], state: "minecraft:mud_bricks"},
        {pos: [6, 0, 7], state: "minecraft:mud_bricks"},
        {pos: [7, 0, 3], state: "minecraft:mud_bricks"},
        {pos: [7, 0, 4], state: "minecraft:mud_bricks"},
        {pos: [7, 0, 5], state: "minecraft:mud_bricks"},
        {pos: [0, 1, 2], state: "minecraft:mud_brick_stairs{facing:east,half:top,shape:straight,waterlogged:false}"},
        {pos: [0, 1, 3], state: "minecraft:mud_brick_stairs{facing:east,half:top,shape:straight,waterlogged:false}"},
        {pos: [0, 1, 4], state: "minecraft:mud_brick_stairs{facing:east,half:top,shape:straight,waterlogged:false}"},
        {pos: [0, 1, 5], state: "minecraft:gravel"},
        {pos: [1, 1, 1], state: "minecraft:gravel"},
        {pos: [1, 1, 2], state: "minecraft:mud_bricks"},
        {pos: [1, 1, 3], state: "minecraft:mud_bricks"},
        {pos: [1, 1, 4], state: "minecraft:mud_bricks"},
        {pos: [1, 1, 5], state: "minecraft:mud_bricks"},
        {pos: [1, 1, 6], state: "minecraft:gravel"},
        {pos: [1, 1, 7], state: "minecraft:gravel"},
        {pos: [2, 1, 1], state: "minecraft:gravel"},
        {pos: [2, 1, 2], state: "minecraft:mud_bricks"},
        {pos: [2, 1, 3], state: "minecraft:mud_brick_stairs{facing:north,half:top,shape:straight,waterlogged:false}"},
        {pos: [2, 1, 4], state: "minecraft:gravel"},
        {pos: [2, 1, 5], state: "minecraft:gravel"},
        {pos: [2, 1, 6], state: "minecraft:gravel"},
        {pos: [2, 1, 7], state: "minecraft:mud_bricks"},
        {pos: [3, 1, 0], state: "minecraft:gravel"},
        {pos: [3, 1, 1], state: "minecraft:gravel"},
        {pos: [3, 1, 2], state: "minecraft:mud_bricks"},
        {pos: [3, 1, 3], state: "minecraft:mud_brick_stairs{facing:north,half:top,shape:straight,waterlogged:false}"},
        {pos: [3, 1, 4], state: "minecraft:gravel"},
        {pos: [3, 1, 5], state: "minecraft:gravel"},
        {pos: [3, 1, 6], state: "minecraft:gravel"},
        {pos: [3, 1, 7], state: "minecraft:mud_bricks"},
        {pos: [4, 1, 0], state: "minecraft:gravel"},
        {pos: [4, 1, 1], state: "minecraft:gravel"},
        {pos: [4, 1, 2], state: "minecraft:mud_bricks"},
        {pos: [4, 1, 3], state: "minecraft:gravel"},
        {pos: [4, 1, 4], state: "minecraft:gravel"},
        {pos: [4, 1, 5], state: "minecraft:gravel"},
        {pos: [4, 1, 6], state: "minecraft:gravel"},
        {pos: [4, 1, 7], state: "minecraft:gravel"},
        {pos: [4, 1, 8], state: "minecraft:gravel"},
        {pos: [5, 1, 1], state: "minecraft:gravel"},
        {pos: [5, 1, 2], state: "minecraft:mud_bricks"},
        {pos: [5, 1, 3], state: "minecraft:gravel"},
        {pos: [5, 1, 4], state: "minecraft:gravel"},
        {pos: [5, 1, 5], state: "minecraft:gravel"},
        {pos: [5, 1, 6], state: "minecraft:gravel"},
        {pos: [5, 1, 7], state: "minecraft:gravel"},
        {pos: [5, 1, 8], state: "minecraft:gravel"},
        {pos: [6, 1, 2], state: "minecraft:mud_bricks"},
        {pos: [6, 1, 3], state: "minecraft:mud_bricks"},
        {pos: [6, 1, 4], state: "minecraft:mud_bricks"},
        {pos: [6, 1, 5], state: "minecraft:gravel"},
        {pos: [6, 1, 6], state: "minecraft:gravel"},
        {pos: [6, 1, 7], state: "minecraft:gravel"},
        {pos: [7, 1, 3], state: "minecraft:mud_brick_stairs{facing:west,half:top,shape:straight,waterlogged:false}"},
        {pos: [7, 1, 4], state: "minecraft:mud_brick_stairs{facing:west,half:top,shape:straight,waterlogged:false}"},
        {pos: [7, 1, 5], state: "minecraft:gravel"},
        {pos: [0, 2, 2], state: "minecraft:gravel"},
        {pos: [0, 2, 3], state: "minecraft:gravel"},
        {pos: [0, 2, 4], state: "minecraft:gravel"},
        {pos: [0, 2, 5], state: "minecraft:gravel"},
        {pos: [1, 2, 1], state: "minecraft:gravel"},
        {pos: [1, 2, 2], state: "minecraft:mud_bricks"},
        {pos: [1, 2, 3], state: "minecraft:mud_bricks"},
        {pos: [1, 2, 4], state: "minecraft:mud_bricks"},
        {pos: [1, 2, 5], state: "minecraft:mud_bricks"},
        {pos: [1, 2, 6], state: "minecraft:gravel"},
        {pos: [1, 2, 7], state: "minecraft:gravel"},
        {pos: [2, 2, 1], state: "minecraft:gravel"},
        {pos: [2, 2, 2], state: "minecraft:mud_bricks"},
        {pos: [2, 2, 3], state: "minecraft:gravel"},
        {pos: [2, 2, 4], state: "minecraft:gravel"},
        {pos: [2, 2, 5], state: "minecraft:gravel"},
        {pos: [2, 2, 6], state: "minecraft:gravel"},
        {pos: [2, 2, 7], state: "minecraft:mud_bricks"},
        {pos: [3, 2, 0], state: "minecraft:gravel"},
        {pos: [3, 2, 1], state: "minecraft:gravel"},
        {pos: [3, 2, 2], state: "minecraft:mud_bricks"},
        {pos: [3, 2, 3], state: "minecraft:gravel"},
        {pos: [3, 2, 4], state: "minecraft:gravel"},
        {pos: [3, 2, 5], state: "minecraft:gravel"},
        {pos: [3, 2, 6], state: "minecraft:gravel"},
        {pos: [3, 2, 7], state: "minecraft:mud_bricks"},
        {pos: [4, 2, 0], state: "minecraft:gravel"},
        {pos: [4, 2, 1], state: "minecraft:gravel"},
        {pos: [4, 2, 2], state: "minecraft:mud_bricks"},
        {pos: [4, 2, 3], state: "minecraft:gravel"},
        {pos: [4, 2, 4], state: "minecraft:gravel"},
        {pos: [4, 2, 5], state: "minecraft:gravel"},
        {pos: [4, 2, 6], state: "minecraft:gravel"},
        {pos: [4, 2, 7], state: "minecraft:gravel"},
        {pos: [4, 2, 8], state: "minecraft:gravel"},
        {pos: [5, 2, 1], state: "minecraft:gravel"},
        {pos: [5, 2, 2], state: "minecraft:mud_bricks"},
        {pos: [5, 2, 3], state: "minecraft:gravel"},
        {pos: [5, 2, 4], state: "minecraft:gravel"},
        {pos: [5, 2, 5], state: "minecraft:gravel"},
        {pos: [5, 2, 6], state: "minecraft:gravel"},
        {pos: [5, 2, 7], state: "minecraft:gravel"},
        {pos: [5, 2, 8], state: "minecraft:gravel"},
        {pos: [6, 2, 2], state: "minecraft:mud_bricks"},
        {pos: [6, 2, 3], state: "minecraft:mud_bricks"},
        {pos: [6, 2, 4], state: "minecraft:mud_bricks"},
        {pos: [6, 2, 5], state: "minecraft:gravel"},
        {pos: [6, 2, 6], state: "minecraft:gravel"},
        {pos: [6, 2, 7], state: "minecraft:gravel"},
        {pos: [7, 2, 3], state: "minecraft:gravel"},
        {pos: [7, 2, 4], state: "minecraft:gravel"},
        {pos: [7, 2, 5], state: "minecraft:gravel"},
        {pos: [0, 3, 2], state: "minecraft:gravel"},
        {pos: [0, 3, 3], state: "minecraft:gravel"},
        {pos: [0, 3, 4], state: "minecraft:gravel"},
        {pos: [0, 3, 5], state: "minecraft:gravel"},
        {pos: [1, 3, 1], state: "minecraft:gravel"},
        {pos: [1, 3, 2], state: "minecraft:mud_bricks"},
        {pos: [1, 3, 3], state: "minecraft:mud_bricks"},
        {pos: [1, 3, 4], state: "minecraft:mud_bricks"},
        {pos: [1, 3, 5], state: "minecraft:mud_bricks"},
        {pos: [1, 3, 6], state: "minecraft:gravel"},
        {pos: [1, 3, 7], state: "minecraft:gravel"},
        {pos: [2, 3, 1], state: "minecraft:gravel"},
        {pos: [2, 3, 2], state: "minecraft:mud_bricks"},
        {pos: [2, 3, 3], state: "minecraft:gravel"},
        {pos: [2, 3, 4], state: "minecraft:gravel"},
        {pos: [2, 3, 5], state: "minecraft:gravel"},
        {pos: [2, 3, 6], state: "minecraft:gravel"},
        {pos: [2, 3, 7], state: "minecraft:gravel"},
        {pos: [3, 3, 0], state: "minecraft:gravel"},
        {pos: [3, 3, 1], state: "minecraft:gravel"},
        {pos: [3, 3, 2], state: "minecraft:mud_bricks"},
        {pos: [3, 3, 3], state: "minecraft:gravel"},
        {pos: [3, 3, 4], state: "minecraft:gravel"},
        {pos: [3, 3, 5], state: "minecraft:gravel"},
        {pos: [3, 3, 6], state: "minecraft:gravel"},
        {pos: [3, 3, 7], state: "minecraft:mud_bricks"},
        {pos: [4, 3, 0], state: "minecraft:gravel"},
        {pos: [4, 3, 1], state: "minecraft:gravel"},
        {pos: [4, 3, 2], state: "minecraft:mud_bricks"},
        {pos: [4, 3, 3], state: "minecraft:gravel"},
        {pos: [4, 3, 4], state: "minecraft:gravel"},
        {pos: [4, 3, 5], state: "minecraft:gravel"},
        {pos: [4, 3, 6], state: "minecraft:gravel"},
        {pos: [4, 3, 7], state: "minecraft:mud_bricks"},
        {pos: [4, 3, 8], state: "minecraft:gravel"},
        {pos: [5, 3, 1], state: "minecraft:gravel"},
        {pos: [5, 3, 2], state: "minecraft:gravel"},
        {pos: [5, 3, 3], state: "minecraft:gravel"},
        {pos: [5, 3, 4], state: "minecraft:gravel"},
        {pos: [5, 3, 5], state: "minecraft:gravel"},
        {pos: [5, 3, 6], state: "minecraft:gravel"},
        {pos: [5, 3, 7], state: "minecraft:mud_bricks"},
        {pos: [5, 3, 8], state: "minecraft:gravel"},
        {pos: [6, 3, 2], state: "minecraft:gravel"},
        {pos: [6, 3, 3], state: "minecraft:mud_bricks"},
        {pos: [6, 3, 4], state: "minecraft:mud_bricks"},
        {pos: [6, 3, 5], state: "minecraft:gravel"},
        {pos: [6, 3, 6], state: "minecraft:gravel"},
        {pos: [6, 3, 7], state: "minecraft:gravel"},
        {pos: [7, 3, 3], state: "minecraft:gravel"},
        {pos: [7, 3, 4], state: "minecraft:gravel"},
        {pos: [7, 3, 5], state: "minecraft:gravel"},
        {pos: [0, 4, 2], state: "minecraft:gravel"},
        {pos: [0, 4, 3], state: "minecraft:gravel"},
        {pos: [0, 4, 4], state: "minecraft:gravel"},
        {pos: [0, 4, 5], state: "minecraft:gravel"},
        {pos: [1, 4, 1], state: "minecraft:gravel"},
        {pos: [1, 4, 2], state: "minecraft:mud_bricks"},
        {pos: [1, 4, 3], state: "minecraft:mud_bricks"},
        {pos: [1, 4, 4], state: "minecraft:mud_bricks"},
        {pos: [1, 4, 5], state: "minecraft:mud_bricks"},
        {pos: [1, 4, 6], state: "minecraft:gravel"},
        {pos: [1, 4, 7], state: "minecraft:gravel"},
        {pos: [2, 4, 1], state: "minecraft:gravel"},
        {pos: [2, 4, 2], state: "minecraft:mud_bricks"},
        {pos: [2, 4, 3], state: "minecraft:mud_bricks"},
        {pos: [2, 4, 4], state: "minecraft:mud_bricks"},
        {pos: [2, 4, 5], state: "minecraft:mud_bricks"},
        {pos: [2, 4, 6], state: "minecraft:gravel"},
        {pos: [2, 4, 7], state: "minecraft:gravel"},
        {pos: [3, 4, 1], state: "minecraft:gravel"},
        {pos: [3, 4, 2], state: "minecraft:mud_bricks"},
        {pos: [3, 4, 3], state: "minecraft:mud_bricks"},
        {pos: [3, 4, 4], state: "minecraft:mud_bricks"},
        {pos: [3, 4, 5], state: "minecraft:gravel"},
        {pos: [3, 4, 6], state: "minecraft:gravel"},
        {pos: [3, 4, 7], state: "minecraft:mud_bricks"},
        {pos: [4, 4, 0], state: "minecraft:gravel"},
        {pos: [4, 4, 1], state: "minecraft:gravel"},
        {pos: [4, 4, 2], state: "minecraft:mud_bricks"},
        {pos: [4, 4, 3], state: "minecraft:mud_bricks"},
        {pos: [4, 4, 4], state: "minecraft:gravel"},
        {pos: [4, 4, 5], state: "minecraft:gravel"},
        {pos: [4, 4, 6], state: "minecraft:gravel"},
        {pos: [4, 4, 7], state: "minecraft:mud_bricks"},
        {pos: [5, 4, 1], state: "minecraft:gravel"},
        {pos: [5, 4, 2], state: "minecraft:gravel"},
        {pos: [5, 4, 3], state: "minecraft:gravel"},
        {pos: [5, 4, 4], state: "minecraft:gravel"},
        {pos: [5, 4, 5], state: "minecraft:gravel"},
        {pos: [5, 4, 6], state: "minecraft:gravel"},
        {pos: [5, 4, 7], state: "minecraft:mud_bricks"},
        {pos: [5, 4, 8], state: "minecraft:gravel"},
        {pos: [6, 4, 2], state: "minecraft:gravel"},
        {pos: [6, 4, 3], state: "minecraft:mud_bricks"},
        {pos: [6, 4, 4], state: "minecraft:mud_bricks"},
        {pos: [6, 4, 5], state: "minecraft:gravel"},
        {pos: [6, 4, 6], state: "minecraft:gravel"},
        {pos: [6, 4, 7], state: "minecraft:gravel"},
        {pos: [7, 4, 3], state: "minecraft:gravel"},
        {pos: [7, 4, 4], state: "minecraft:gravel"},
        {pos: [7, 4, 5], state: "minecraft:gravel"},
        {pos: [0, 5, 2], state: "minecraft:gravel"},
        {pos: [0, 5, 3], state: "minecraft:gravel"},
        {pos: [0, 5, 4], state: "minecraft:gravel"},
        {pos: [0, 5, 5], state: "minecraft:gravel"},
        {pos: [1, 5, 1], state: "minecraft:gravel"},
        {pos: [1, 5, 2], state: "minecraft:mud_bricks"},
        {pos: [1, 5, 3], state: "minecraft:mud_bricks"},
        {pos: [1, 5, 4], state: "minecraft:mud_bricks"},
        {pos: [1, 5, 5], state: "minecraft:gravel"},
        {pos: [1, 5, 6], state: "minecraft:gravel"},
        {pos: [1, 5, 7], state: "minecraft:gravel"},
        {pos: [2, 5, 1], state: "minecraft:gravel"},
        {pos: [2, 5, 2], state: "minecraft:mud_bricks"},
        {pos: [2, 5, 3], state: "minecraft:gravel"},
        {pos: [2, 5, 4], state: "minecraft:gravel"},
        {pos: [2, 5, 5], state: "minecraft:gravel"},
        {pos: [2, 5, 6], state: "minecraft:gravel"},
        {pos: [2, 5, 7], state: "minecraft:gravel"},
        {pos: [3, 5, 1], state: "minecraft:gravel"},
        {pos: [3, 5, 2], state: "minecraft:gravel"},
        {pos: [3, 5, 3], state: "minecraft:gravel"},
        {pos: [3, 5, 4], state: "minecraft:gravel"},
        {pos: [3, 5, 5], state: "minecraft:gravel"},
        {pos: [3, 5, 6], state: "minecraft:gravel"},
        {pos: [3, 5, 7], state: "minecraft:mud_bricks"},
        {pos: [4, 5, 1], state: "minecraft:gravel"},
        {pos: [4, 5, 2], state: "minecraft:gravel"},
        {pos: [4, 5, 3], state: "minecraft:gravel"},
        {pos: [4, 5, 4], state: "minecraft:gravel"},
        {pos: [4, 5, 5], state: "minecraft:gravel"},
        {pos: [4, 5, 6], state: "minecraft:gravel"},
        {pos: [4, 5, 7], state: "minecraft:mud_bricks"},
        {pos: [5, 5, 1], state: "minecraft:gravel"},
        {pos: [5, 5, 2], state: "minecraft:gravel"},
        {pos: [5, 5, 3], state: "minecraft:gravel"},
        {pos: [5, 5, 4], state: "minecraft:gravel"},
        {pos: [5, 5, 5], state: "minecraft:gravel"},
        {pos: [5, 5, 6], state: "minecraft:gravel"},
        {pos: [5, 5, 7], state: "minecraft:mud_bricks"},
        {pos: [6, 5, 2], state: "minecraft:gravel"},
        {pos: [6, 5, 3], state: "minecraft:mud_bricks"},
        {pos: [6, 5, 4], state: "minecraft:mud_bricks"},
        {pos: [6, 5, 5], state: "minecraft:mud_bricks"},
        {pos: [6, 5, 6], state: "minecraft:mud_bricks"},
        {pos: [6, 5, 7], state: "minecraft:mud_bricks"},
        {pos: [7, 5, 3], state: "minecraft:gravel"},
        {pos: [7, 5, 4], state: "minecraft:gravel"},
        {pos: [7, 5, 5], state: "minecraft:gravel"},
        {pos: [0, 6, 2], state: "minecraft:gravel"},
        {pos: [0, 6, 3], state: "minecraft:gravel"},
        {pos: [0, 6, 4], state: "minecraft:gravel"},
        {pos: [1, 6, 1], state: "minecraft:gravel"},
        {pos: [1, 6, 2], state: "minecraft:mud_bricks"},
        {pos: [1, 6, 3], state: "minecraft:mud_bricks"},
        {pos: [1, 6, 4], state: "minecraft:mud_bricks"},
        {pos: [1, 6, 5], state: "minecraft:gravel"},
        {pos: [1, 6, 6], state: "minecraft:gravel"},
        {pos: [1, 6, 7], state: "minecraft:gravel"},
        {pos: [2, 6, 1], state: "minecraft:gravel"},
        {pos: [2, 6, 2], state: "minecraft:mud_bricks"},
        {pos: [2, 6, 3], state: "minecraft:gravel"},
        {pos: [2, 6, 4], state: "minecraft:gravel"},
        {pos: [2, 6, 5], state: "minecraft:gravel"},
        {pos: [2, 6, 6], state: "minecraft:gravel"},
        {pos: [2, 6, 7], state: "minecraft:gravel"},
        {pos: [3, 6, 1], state: "minecraft:gravel"},
        {pos: [3, 6, 2], state: "minecraft:gravel"},
        {pos: [3, 6, 3], state: "minecraft:gravel"},
        {pos: [3, 6, 4], state: "minecraft:gravel"},
        {pos: [3, 6, 5], state: "minecraft:gravel"},
        {pos: [3, 6, 6], state: "minecraft:gravel"},
        {pos: [3, 6, 7], state: "minecraft:mud_bricks"},
        {pos: [4, 6, 1], state: "minecraft:gravel"},
        {pos: [4, 6, 2], state: "minecraft:gravel"},
        {pos: [4, 6, 3], state: "minecraft:gravel"},
        {pos: [4, 6, 4], state: "minecraft:gravel"},
        {pos: [4, 6, 5], state: "minecraft:gravel"},
        {pos: [4, 6, 6], state: "minecraft:gravel"},
        {pos: [4, 6, 7], state: "minecraft:mud_bricks"},
        {pos: [5, 6, 1], state: "minecraft:gravel"},
        {pos: [5, 6, 2], state: "minecraft:gravel"},
        {pos: [5, 6, 3], state: "minecraft:gravel"},
        {pos: [5, 6, 4], state: "minecraft:gravel"},
        {pos: [5, 6, 5], state: "minecraft:gravel"},
        {pos: [5, 6, 6], state: "minecraft:gravel"},
        {pos: [5, 6, 7], state: "minecraft:mud_bricks"},
        {pos: [6, 6, 2], state: "minecraft:gravel"},
        {pos: [6, 6, 3], state: "minecraft:gravel"},
        {pos: [6, 6, 4], state: "minecraft:gravel"},
        {pos: [6, 6, 5], state: "minecraft:mud_bricks"},
        {pos: [6, 6, 6], state: "minecraft:mud_bricks"},
        {pos: [6, 6, 7], state: "minecraft:mud_bricks"},
        {pos: [7, 6, 3], state: "minecraft:gravel"},
        {pos: [7, 6, 4], state: "minecraft:gravel"},
        {pos: [7, 6, 5], state: "minecraft:gravel"},
        {pos: [0, 7, 2], state: "minecraft:gravel"},
        {pos: [0, 7, 3], state: "minecraft:gravel"},
        {pos: [0, 7, 4], state: "minecraft:gravel"},
        {pos: [1, 7, 1], state: "minecraft:gravel"},
        {pos: [1, 7, 2], state: "minecraft:mud_bricks"},
        {pos: [1, 7, 3], state: "minecraft:mud_bricks"},
        {pos: [1, 7, 4], state: "minecraft:gravel"},
        {pos: [1, 7, 5], state: "minecraft:gravel"},
        {pos: [1, 7, 6], state: "minecraft:gravel"},
        {pos: [1, 7, 7], state: "minecraft:gravel"},
        {pos: [2, 7, 1], state: "minecraft:gravel"},
        {pos: [2, 7, 2], state: "minecraft:mud_bricks"},
        {pos: [2, 7, 3], state: "minecraft:gravel"},
        {pos: [2, 7, 4], state: "minecraft:gravel"},
        {pos: [2, 7, 5], state: "minecraft:gravel"},
        {pos: [2, 7, 6], state: "minecraft:gravel"},
        {pos: [2, 7, 7], state: "minecraft:gravel"},
        {pos: [3, 7, 1], state: "minecraft:gravel"},
        {pos: [3, 7, 2], state: "minecraft:gravel"},
        {pos: [3, 7, 3], state: "minecraft:gravel"},
        {pos: [3, 7, 4], state: "minecraft:gravel"},
        {pos: [3, 7, 5], state: "minecraft:gravel"},
        {pos: [3, 7, 6], state: "minecraft:gravel"},
        {pos: [3, 7, 7], state: "minecraft:mud_bricks"},
        {pos: [4, 7, 2], state: "minecraft:gravel"},
        {pos: [4, 7, 3], state: "minecraft:gravel"},
        {pos: [4, 7, 4], state: "minecraft:mud_bricks"},
        {pos: [4, 7, 5], state: "minecraft:mud_bricks"},
        {pos: [4, 7, 6], state: "minecraft:mud_bricks"},
        {pos: [4, 7, 7], state: "minecraft:mud_bricks"},
        {pos: [5, 7, 1], state: "minecraft:gravel"},
        {pos: [5, 7, 2], state: "minecraft:gravel"},
        {pos: [5, 7, 3], state: "minecraft:gravel"},
        {pos: [5, 7, 4], state: "minecraft:mud_bricks"},
        {pos: [5, 7, 5], state: "minecraft:mud_bricks"},
        {pos: [5, 7, 6], state: "minecraft:mud_bricks"},
        {pos: [5, 7, 7], state: "minecraft:mud_bricks"},
        {pos: [6, 7, 2], state: "minecraft:gravel"},
        {pos: [6, 7, 3], state: "minecraft:gravel"},
        {pos: [6, 7, 4], state: "minecraft:gravel"},
        {pos: [6, 7, 5], state: "minecraft:gravel"},
        {pos: [6, 7, 6], state: "minecraft:gravel"},
        {pos: [6, 7, 7], state: "minecraft:mud_bricks"},
        {pos: [7, 7, 3], state: "minecraft:gravel"},
        {pos: [7, 7, 4], state: "minecraft:gravel"},
        {pos: [7, 7, 5], state: "minecraft:gravel"},
        {pos: [0, 8, 2], state: "minecraft:gravel"},
        {pos: [0, 8, 3], state: "minecraft:gravel"},
        {pos: [1, 8, 1], state: "minecraft:gravel"},
        {pos: [1, 8, 2], state: "minecraft:mud_bricks"},
        {pos: [1, 8, 3], state: "minecraft:mud_bricks"},
        {pos: [1, 8, 4], state: "minecraft:gravel"},
        {pos: [1, 8, 5], state: "minecraft:gravel"},
        {pos: [1, 8, 6], state: "minecraft:gravel"},
        {pos: [1, 8, 7], state: "minecraft:gravel"},
        {pos: [2, 8, 1], state: "minecraft:gravel"},
        {pos: [2, 8, 2], state: "minecraft:mud_bricks"},
        {pos: [2, 8, 3], state: "minecraft:gravel"},
        {pos: [2, 8, 4], state: "minecraft:gravel"},
        {pos: [2, 8, 5], state: "minecraft:gravel"},
        {pos: [2, 8, 6], state: "minecraft:gravel"},
        {pos: [2, 8, 7], state: "minecraft:gravel"},
        {pos: [3, 8, 1], state: "minecraft:gravel"},
        {pos: [3, 8, 2], state: "minecraft:gravel"},
        {pos: [3, 8, 3], state: "minecraft:gravel"},
        {pos: [3, 8, 4], state: "minecraft:gravel"},
        {pos: [3, 8, 5], state: "minecraft:gravel"},
        {pos: [3, 8, 6], state: "minecraft:gravel"},
        {pos: [3, 8, 7], state: "minecraft:mud_bricks"},
        {pos: [4, 8, 2], state: "minecraft:gravel"},
        {pos: [4, 8, 3], state: "minecraft:gravel"},
        {pos: [4, 8, 4], state: "minecraft:gravel"},
        {pos: [4, 8, 5], state: "minecraft:gravel"},
        {pos: [4, 8, 6], state: "minecraft:gravel"},
        {pos: [4, 8, 7], state: "minecraft:mud_bricks"},
        {pos: [5, 8, 1], state: "minecraft:gravel"},
        {pos: [5, 8, 2], state: "minecraft:gravel"},
        {pos: [5, 8, 3], state: "minecraft:gravel"},
        {pos: [5, 8, 4], state: "minecraft:gravel"},
        {pos: [5, 8, 5], state: "minecraft:gravel"},
        {pos: [5, 8, 6], state: "minecraft:gravel"},
        {pos: [5, 8, 7], state: "minecraft:mud_bricks"},
        {pos: [6, 8, 2], state: "minecraft:gravel"},
        {pos: [6, 8, 3], state: "minecraft:gravel"},
        {pos: [6, 8, 4], state: "minecraft:gravel"},
        {pos: [6, 8, 5], state: "minecraft:gravel"},
        {pos: [6, 8, 6], state: "minecraft:gravel"},
        {pos: [6, 8, 7], state: "minecraft:gravel"},
        {pos: [7, 8, 3], state: "minecraft:gravel"},
        {pos: [7, 8, 4], state: "minecraft:gravel"},
        {pos: [7, 8, 5], state: "minecraft:gravel"},
        {pos: [0, 9, 2], state: "minecraft:gravel"},
        {pos: [1, 9, 1], state: "minecraft:gravel"},
        {pos: [1, 9, 2], state: "minecraft:mud_bricks"},
        {pos: [1, 9, 3], state: "minecraft:gravel"},
        {pos: [1, 9, 4], state: "minecraft:gravel"},
        {pos: [1, 9, 5], state: "minecraft:gravel"},
        {pos: [1, 9, 6], state: "minecraft:gravel"},
        {pos: [1, 9, 7], state: "minecraft:gravel"},
        {pos: [2, 9, 1], state: "minecraft:gravel"},
        {pos: [2, 9, 2], state: "minecraft:mud_bricks"},
        {pos: [2, 9, 3], state: "minecraft:gravel"},
        {pos: [2, 9, 4], state: "minecraft:gravel"},
        {pos: [2, 9, 5], state: "minecraft:gravel"},
        {pos: [2, 9, 6], state: "minecraft:gravel"},
        {pos: [2, 9, 7], state: "minecraft:mud_bricks"},
        {pos: [3, 9, 2], state: "minecraft:mud_bricks"},
        {pos: [3, 9, 3], state: "minecraft:gravel"},
        {pos: [3, 9, 4], state: "minecraft:gravel"},
        {pos: [3, 9, 5], state: "minecraft:gravel"},
        {pos: [3, 9, 6], state: "minecraft:gravel"},
        {pos: [3, 9, 7], state: "minecraft:mud_bricks"},
        {pos: [4, 9, 2], state: "minecraft:mud_bricks"},
        {pos: [4, 9, 3], state: "minecraft:gravel"},
        {pos: [4, 9, 4], state: "minecraft:gravel"},
        {pos: [4, 9, 5], state: "minecraft:gravel"},
        {pos: [4, 9, 6], state: "minecraft:gravel"},
        {pos: [4, 9, 7], state: "minecraft:mud_bricks"},
        {pos: [5, 9, 2], state: "minecraft:gravel"},
        {pos: [5, 9, 3], state: "minecraft:gravel"},
        {pos: [5, 9, 4], state: "minecraft:gravel"},
        {pos: [5, 9, 5], state: "minecraft:gravel"},
        {pos: [5, 9, 6], state: "minecraft:gravel"},
        {pos: [5, 9, 7], state: "minecraft:gravel"},
        {pos: [6, 9, 2], state: "minecraft:gravel"},
        {pos: [6, 9, 3], state: "minecraft:gravel"},
        {pos: [6, 9, 4], state: "minecraft:gravel"},
        {pos: [6, 9, 5], state: "minecraft:gravel"},
        {pos: [6, 9, 6], state: "minecraft:gravel"},
        {pos: [6, 9, 7], state: "minecraft:gravel"},
        {pos: [7, 9, 3], state: "minecraft:gravel"},
        {pos: [7, 9, 4], state: "minecraft:gravel"},
        {pos: [7, 9, 5], state: "minecraft:gravel"},
        {pos: [1, 10, 1], state: "minecraft:gravel"},
        {pos: [1, 10, 2], state: "minecraft:mud_bricks"},
        {pos: [1, 10, 3], state: "minecraft:mud_bricks"},
        {pos: [1, 10, 4], state: "minecraft:mud_bricks"},
        {pos: [1, 10, 5], state: "minecraft:mud_bricks"},
        {pos: [1, 10, 6], state: "minecraft:mud_bricks"},
        {pos: [1, 10, 7], state: "minecraft:mud_bricks"},
        {pos: [2, 10, 2], state: "minecraft:mud_bricks"},
        {pos: [2, 10, 3], state: "minecraft:gravel"},
        {pos: [2, 10, 4], state: "minecraft:gravel"},
        {pos: [2, 10, 5], state: "minecraft:gravel"},
        {pos: [2, 10, 6], state: "minecraft:gravel"},
        {pos: [2, 10, 7], state: "minecraft:mud_bricks"},
        {pos: [3, 10, 2], state: "minecraft:mud_bricks"},
        {pos: [3, 10, 3], state: "minecraft:gravel"},
        {pos: [3, 10, 4], state: "minecraft:gravel"},
        {pos: [3, 10, 5], state: "minecraft:gravel"},
        {pos: [3, 10, 6], state: "minecraft:gravel"},
        {pos: [3, 10, 7], state: "minecraft:mud_bricks"},
        {pos: [4, 10, 2], state: "minecraft:mud_bricks"},
        {pos: [4, 10, 3], state: "minecraft:gravel"},
        {pos: [4, 10, 4], state: "minecraft:gravel"},
        {pos: [4, 10, 5], state: "minecraft:gravel"},
        {pos: [4, 10, 6], state: "minecraft:gravel"},
        {pos: [4, 10, 7], state: "minecraft:mud_bricks"},
        {pos: [5, 10, 2], state: "minecraft:mud_bricks"},
        {pos: [5, 10, 3], state: "minecraft:gravel"},
        {pos: [5, 10, 4], state: "minecraft:gravel"},
        {pos: [5, 10, 5], state: "minecraft:gravel"},
        {pos: [5, 10, 6], state: "minecraft:gravel"},
        {pos: [5, 10, 7], state: "minecraft:mud_bricks"},
        {pos: [6, 10, 2], state: "minecraft:mud_bricks"},
        {pos: [6, 10, 3], state: "minecraft:mud_bricks"},
        {pos: [6, 10, 4], state: "minecraft:mud_bricks"},
        {pos: [6, 10, 5], state: "minecraft:mud_bricks"},
        {pos: [6, 10, 6], state: "minecraft:mud_bricks"},
        {pos: [6, 10, 7], state: "minecraft:mud_bricks"},
        {pos: [7, 10, 4], state: "minecraft:gravel"},
        {pos: [7, 10, 5], state: "minecraft:gravel"},
        {pos: [1, 11, 2], state: "minecraft:mud_bricks"},
        {pos: [1, 11, 3], state: "minecraft:mud_bricks"},
        {pos: [1, 11, 4], state: "minecraft:mud_bricks"},
        {pos: [1, 11, 5], state: "minecraft:gravel"},
        {pos: [1, 11, 6], state: "minecraft:gravel"},
        {pos: [2, 11, 2], state: "minecraft:gravel"},
        {pos: [2, 11, 3], state: "minecraft:gravel"},
        {pos: [2, 11, 4], state: "minecraft:gravel"},
        {pos: [2, 11, 5], state: "minecraft:gravel"},
        {pos: [2, 11, 6], state: "minecraft:gravel"},
        {pos: [2, 11, 7], state: "minecraft:gravel"},
        {pos: [3, 11, 2], state: "minecraft:mud_bricks"},
        {pos: [3, 11, 3], state: "minecraft:gravel"},
        {pos: [3, 11, 4], state: "minecraft:gravel"},
        {pos: [3, 11, 5], state: "minecraft:gravel"},
        {pos: [3, 11, 6], state: "minecraft:gravel"},
        {pos: [3, 11, 7], state: "minecraft:mud_bricks"},
        {pos: [4, 11, 2], state: "minecraft:mud_bricks"},
        {pos: [4, 11, 3], state: "minecraft:gravel"},
        {pos: [4, 11, 4], state: "minecraft:gravel"},
        {pos: [4, 11, 5], state: "minecraft:gravel"},
        {pos: [4, 11, 6], state: "minecraft:gravel"},
        {pos: [4, 11, 7], state: "minecraft:mud_bricks"},
        {pos: [5, 11, 2], state: "minecraft:mud_bricks"},
        {pos: [5, 11, 3], state: "minecraft:gravel"},
        {pos: [5, 11, 4], state: "minecraft:gravel"},
        {pos: [5, 11, 5], state: "minecraft:gravel"},
        {pos: [5, 11, 6], state: "minecraft:gravel"},
        {pos: [5, 11, 7], state: "minecraft:mud_bricks"},
        {pos: [6, 11, 2], state: "minecraft:mud_bricks"},
        {pos: [6, 11, 3], state: "minecraft:mud_bricks"},
        {pos: [6, 11, 4], state: "minecraft:mud_bricks"},
        {pos: [6, 11, 5], state: "minecraft:mud_bricks"},
        {pos: [6, 11, 6], state: "minecraft:gravel"},
        {pos: [6, 11, 7], state: "minecraft:gravel"},
        {pos: [1, 12, 2], state: "minecraft:mud_bricks"},
        {pos: [1, 12, 3], state: "minecraft:mud_bricks"},
        {pos: [2, 12, 2], state: "minecraft:gravel"},
        {pos: [2, 12, 3], state: "minecraft:gravel"},
        {pos: [3, 12, 2], state: "minecraft:gravel"},
        {pos: [4, 12, 2], state: "minecraft:mud_bricks"},
        {pos: [4, 12, 5], state: "minecraft:gravel"},
        {pos: [4, 12, 6], state: "minecraft:gravel"},
        {pos: [4, 12, 7], state: "minecraft:mud_bricks"},
        {pos: [5, 12, 2], state: "minecraft:mud_bricks"},
        {pos: [5, 12, 3], state: "minecraft:gravel"},
        {pos: [5, 12, 5], state: "minecraft:gravel"},
        {pos: [5, 12, 6], state: "minecraft:gravel"},
        {pos: [5, 12, 7], state: "minecraft:mud_bricks"},
        {pos: [6, 12, 3], state: "minecraft:mud_bricks"},
        {pos: [6, 12, 4], state: "minecraft:mud_bricks"},
        {pos: [6, 12, 6], state: "minecraft:gravel"},
        {pos: [6, 12, 7], state: "minecraft:gravel"},
        {pos: [1, 13, 2], state: "minecraft:mud_bricks"},
        {pos: [1, 13, 3], state: "minecraft:mud_bricks"},
        {pos: [4, 13, 2], state: "minecraft:mud_bricks"},
        {pos: [4, 13, 7], state: "minecraft:mud_bricks"},
        {pos: [5, 13, 2], state: "minecraft:mud_bricks"},
        {pos: [5, 13, 7], state: "minecraft:mud_bricks"}
    ],
    entities: [],
    palette: [
        "minecraft:mud_bricks",
        "minecraft:yellow_glazed_terracotta{facing:north}",
        "minecraft:yellow_glazed_terracotta{facing:west}",
        "minecraft:yellow_glazed_terracotta{facing:east}",
        "minecraft:yellow_glazed_terracotta{facing:south}",
        "minecraft:gravel",
        "minecraft:mud_brick_stairs{facing:east,half:top,shape:straight,waterlogged:false}",
        "minecraft:mud_brick_stairs{facing:north,half:top,shape:straight,waterlogged:false}",
        "minecraft:mud_brick_stairs{facing:west,half:top,shape:straight,waterlogged:false}"
    ],
    trailiertales_DataVersion: 2
}
