{
    DataVersion: 3953,
    size: [16, 13, 33],
    data: [
        {pos: [0, 0, 10], state: "minecraft:mud_bricks"},
        {pos: [0, 0, 11], state: "minecraft:mud_bricks"},
        {pos: [0, 0, 12], state: "minecraft:mud_bricks"},
        {pos: [0, 0, 21], state: "minecraft:mud_bricks"},
        {pos: [0, 0, 22], state: "minecraft:mud_bricks"},
        {pos: [1, 0, 9], state: "minecraft:mud_bricks"},
        {pos: [1, 0, 10], state: "minecraft:mud_bricks"},
        {pos: [1, 0, 11], state: "minecraft:mud_bricks"},
        {pos: [1, 0, 12], state: "minecraft:mud_bricks"},
        {pos: [1, 0, 20], state: "minecraft:mud_bricks"},
        {pos: [1, 0, 21], state: "minecraft:mud_bricks"},
        {pos: [1, 0, 22], state: "minecraft:mud_bricks"},
        {pos: [1, 0, 23], state: "minecraft:mud_bricks"},
        {pos: [2, 0, 9], state: "minecraft:mud_bricks"},
        {pos: [2, 0, 10], state: "minecraft:mud_bricks"},
        {pos: [2, 0, 11], state: "minecraft:mud_bricks"},
        {pos: [2, 0, 12], state: "minecraft:mud_bricks"},
        {pos: [2, 0, 19], state: "minecraft:mud_bricks"},
        {pos: [2, 0, 20], state: "minecraft:mud_bricks"},
        {pos: [2, 0, 21], state: "minecraft:yellow_glazed_terracotta{facing:west}"},
        {pos: [2, 0, 22], state: "minecraft:mud_bricks"},
        {pos: [2, 0, 23], state: "minecraft:mud_bricks"},
        {pos: [3, 0, 2], state: "minecraft:mud_bricks"},
        {pos: [3, 0, 3], state: "minecraft:mud_bricks"},
        {pos: [3, 0, 4], state: "minecraft:mud_bricks"},
        {pos: [3, 0, 5], state: "minecraft:mud_bricks"},
        {pos: [3, 0, 10], state: "minecraft:mud_bricks"},
        {pos: [3, 0, 11], state: "minecraft:mud_bricks"},
        {pos: [3, 0, 18], state: "minecraft:mud_bricks"},
        {pos: [3, 0, 19], state: "minecraft:mud_bricks"},
        {pos: [3, 0, 20], state: "minecraft:mud_bricks"},
        {pos: [3, 0, 21], state: "minecraft:yellow_glazed_terracotta{facing:south}"},
        {pos: [3, 0, 22], state: "minecraft:mud_bricks"},
        {pos: [3, 0, 23], state: "minecraft:mud_bricks"},
        {pos: [4, 0, 1], state: "minecraft:mud_bricks"},
        {pos: [4, 0, 2], state: "minecraft:mud_bricks"},
        {pos: [4, 0, 3], state: "minecraft:mud_bricks"},
        {pos: [4, 0, 4], state: "minecraft:yellow_glazed_terracotta{facing:west}"},
        {pos: [4, 0, 5], state: "minecraft:mud_bricks"},
        {pos: [4, 0, 6], state: "minecraft:mud_bricks"},
        {pos: [4, 0, 10], state: "minecraft:mud_bricks"},
        {pos: [4, 0, 11], state: "minecraft:mud_bricks"},
        {pos: [4, 0, 17], state: "minecraft:mud_bricks"},
        {pos: [4, 0, 18], state: "minecraft:mud_bricks"},
        {pos: [4, 0, 19], state: "minecraft:mud_bricks"},
        {pos: [4, 0, 20], state: "minecraft:mud_bricks"},
        {pos: [4, 0, 21], state: "minecraft:mud_bricks"},
        {pos: [4, 0, 22], state: "minecraft:mud_bricks"},
        {pos: [4, 0, 27], state: "minecraft:mud_bricks"},
        {pos: [4, 0, 28], state: "minecraft:mud_bricks"},
        {pos: [4, 0, 29], state: "minecraft:mud_bricks"},
        {pos: [4, 0, 30], state: "minecraft:mud_bricks"},
        {pos: [4, 0, 31], state: "minecraft:mud_bricks"},
        {pos: [5, 0, 0], state: "minecraft:mud_bricks"},
        {pos: [5, 0, 1], state: "minecraft:mud_bricks"},
        {pos: [5, 0, 2], state: "minecraft:mud_bricks"},
        {pos: [5, 0, 3], state: "minecraft:mud_bricks"},
        {pos: [5, 0, 4], state: "minecraft:mud_bricks"},
        {pos: [5, 0, 5], state: "minecraft:mud_bricks"},
        {pos: [5, 0, 6], state: "minecraft:mud_bricks"},
        {pos: [5, 0, 7], state: "minecraft:mud_bricks"},
        {pos: [5, 0, 9], state: "minecraft:mud_bricks"},
        {pos: [5, 0, 10], state: "minecraft:mud_bricks"},
        {pos: [5, 0, 11], state: "minecraft:mud_bricks"},
        {pos: [5, 0, 12], state: "minecraft:mud_bricks"},
        {pos: [5, 0, 15], state: "minecraft:mud_bricks"},
        {pos: [5, 0, 16], state: "minecraft:mud_bricks"},
        {pos: [5, 0, 17], state: "minecraft:mud_bricks"},
        {pos: [5, 0, 18], state: "minecraft:mud_bricks"},
        {pos: [5, 0, 19], state: "minecraft:mud_bricks"},
        {pos: [5, 0, 20], state: "minecraft:mud_bricks"},
        {pos: [5, 0, 21], state: "minecraft:mud_bricks"},
        {pos: [5, 0, 26], state: "minecraft:mud_bricks"},
        {pos: [5, 0, 27], state: "minecraft:mud_bricks"},
        {pos: [5, 0, 28], state: "minecraft:mud_bricks"},
        {pos: [5, 0, 29], state: "minecraft:mud_bricks"},
        {pos: [5, 0, 30], state: "minecraft:mud_bricks"},
        {pos: [5, 0, 31], state: "minecraft:mud_bricks"},
        {pos: [5, 0, 32], state: "minecraft:mud_bricks"},
        {pos: [6, 0, 0], state: "minecraft:mud_bricks"},
        {pos: [6, 0, 1], state: "minecraft:yellow_glazed_terracotta{facing:north}"},
        {pos: [6, 0, 2], state: "minecraft:yellow_glazed_terracotta{facing:west}"},
        {pos: [6, 0, 3], state: "minecraft:yellow_glazed_terracotta{facing:north}"},
        {pos: [6, 0, 4], state: "minecraft:yellow_glazed_terracotta{facing:west}"},
        {pos: [6, 0, 5], state: "minecraft:mud_bricks"},
        {pos: [6, 0, 6], state: "minecraft:mud_bricks"},
        {pos: [6, 0, 7], state: "minecraft:mud_bricks"},
        {pos: [6, 0, 8], state: "minecraft:mud_bricks"},
        {pos: [6, 0, 9], state: "minecraft:mud_bricks"},
        {pos: [6, 0, 10], state: "minecraft:mud_bricks"},
        {pos: [6, 0, 11], state: "minecraft:mud_bricks"},
        {pos: [6, 0, 12], state: "minecraft:mud_bricks"},
        {pos: [6, 0, 13], state: "minecraft:mud_bricks"},
        {pos: [6, 0, 14], state: "minecraft:mud_bricks"},
        {pos: [6, 0, 15], state: "minecraft:mud_bricks"},
        {pos: [6, 0, 16], state: "minecraft:mud_bricks"},
        {pos: [6, 0, 17], state: "minecraft:mud_bricks"},
        {pos: [6, 0, 18], state: "minecraft:mud_bricks"},
        {pos: [6, 0, 20], state: "minecraft:mud_bricks"},
        {pos: [6, 0, 21], state: "minecraft:mud_bricks"},
        {pos: [6, 0, 23], state: "minecraft:mud_bricks"},
        {pos: [6, 0, 24], state: "minecraft:mud_bricks"},
        {pos: [6, 0, 25], state: "minecraft:mud_bricks"},
        {pos: [6, 0, 26], state: "minecraft:mud_bricks"},
        {pos: [6, 0, 27], state: "minecraft:mud_bricks"},
        {pos: [6, 0, 28], state: "minecraft:mud_bricks"},
        {pos: [6, 0, 29], state: "minecraft:mud_bricks"},
        {pos: [6, 0, 30], state: "minecraft:mud_bricks"},
        {pos: [6, 0, 31], state: "minecraft:mud_bricks"},
        {pos: [6, 0, 32], state: "minecraft:mud_bricks"},
        {pos: [7, 0, 0], state: "minecraft:mud_bricks"},
        {pos: [7, 0, 1], state: "minecraft:mud_bricks"},
        {pos: [7, 0, 2], state: "minecraft:yellow_glazed_terracotta{facing:south}"},
        {pos: [7, 0, 3], state: "minecraft:yellow_glazed_terracotta{facing:east}"},
        {pos: [7, 0, 4], state: "minecraft:yellow_glazed_terracotta{facing:south}"},
        {pos: [7, 0, 5], state: "minecraft:mud_bricks"},
        {pos: [7, 0, 6], state: "minecraft:mud_bricks"},
        {pos: [7, 0, 7], state: "minecraft:mud_bricks"},
        {pos: [7, 0, 8], state: "minecraft:mud_bricks"},
        {pos: [7, 0, 9], state: "minecraft:mud_bricks"},
        {pos: [7, 0, 10], state: "minecraft:mud_bricks"},
        {pos: [7, 0, 11], state: "minecraft:mud_bricks"},
        {pos: [7, 0, 12], state: "minecraft:mud_bricks"},
        {pos: [7, 0, 13], state: "minecraft:mud_bricks"},
        {pos: [7, 0, 14], state: "minecraft:mud_bricks"},
        {pos: [7, 0, 15], state: "minecraft:mud_bricks"},
        {pos: [7, 0, 16], state: "minecraft:mud_bricks"},
        {pos: [7, 0, 17], state: "minecraft:mud_bricks"},
        {pos: [7, 0, 18], state: "minecraft:mud_bricks"},
        {pos: [7, 0, 19], state: "minecraft:mud_bricks"},
        {pos: [7, 0, 20], state: "minecraft:mud_bricks"},
        {pos: [7, 0, 21], state: "minecraft:mud_bricks"},
        {pos: [7, 0, 22], state: "minecraft:mud_bricks"},
        {pos: [7, 0, 23], state: "minecraft:mud_bricks"},
        {pos: [7, 0, 24], state: "minecraft:mud_bricks"},
        {pos: [7, 0, 25], state: "minecraft:mud_bricks"},
        {pos: [7, 0, 26], state: "minecraft:mud_bricks"},
        {pos: [7, 0, 27], state: "minecraft:mud_bricks"},
        {pos: [7, 0, 28], state: "minecraft:mud_bricks"},
        {pos: [7, 0, 29], state: "minecraft:mud_bricks"},
        {pos: [7, 0, 30], state: "minecraft:mud_bricks"},
        {pos: [7, 0, 31], state: "minecraft:mud_bricks"},
        {pos: [7, 0, 32], state: "minecraft:mud_bricks"},
        {pos: [8, 0, 0], state: "minecraft:mud_bricks"},
        {pos: [8, 0, 1], state: "minecraft:mud_bricks"},
        {pos: [8, 0, 2], state: "minecraft:mud_bricks"},
        {pos: [8, 0, 3], state: "minecraft:yellow_glazed_terracotta{facing:north}"},
        {pos: [8, 0, 4], state: "minecraft:yellow_glazed_terracotta{facing:west}"},
        {pos: [8, 0, 5], state: "minecraft:mud_bricks"},
        {pos: [8, 0, 6], state: "minecraft:mud_bricks"},
        {pos: [8, 0, 9], state: "minecraft:mud_bricks"},
        {pos: [8, 0, 10], state: "minecraft:mud_bricks"},
        {pos: [8, 0, 11], state: "minecraft:mud_bricks"},
        {pos: [8, 0, 14], state: "minecraft:mud_bricks"},
        {pos: [8, 0, 15], state: "minecraft:mud_bricks"},
        {pos: [8, 0, 18], state: "minecraft:mud_bricks"},
        {pos: [8, 0, 20], state: "minecraft:mud_bricks"},
        {pos: [8, 0, 21], state: "minecraft:mud_bricks"},
        {pos: [8, 0, 22], state: "minecraft:mud_bricks"},
        {pos: [8, 0, 25], state: "minecraft:mud_bricks"},
        {pos: [8, 0, 26], state: "minecraft:mud_bricks"},
        {pos: [8, 0, 27], state: "minecraft:mud_bricks"},
        {pos: [8, 0, 28], state: "minecraft:mud_bricks"},
        {pos: [8, 0, 29], state: "minecraft:mud_bricks"},
        {pos: [8, 0, 30], state: "minecraft:mud_bricks"},
        {pos: [8, 0, 31], state: "minecraft:mud_bricks"},
        {pos: [8, 0, 32], state: "minecraft:mud_bricks"},
        {pos: [9, 0, 0], state: "minecraft:mud_bricks"},
        {pos: [9, 0, 1], state: "minecraft:mud_bricks"},
        {pos: [9, 0, 2], state: "minecraft:mud_bricks"},
        {pos: [9, 0, 3], state: "minecraft:yellow_glazed_terracotta{facing:east}"},
        {pos: [9, 0, 4], state: "minecraft:yellow_glazed_terracotta{facing:south}"},
        {pos: [9, 0, 5], state: "minecraft:mud_bricks"},
        {pos: [9, 0, 6], state: "minecraft:mud_bricks"},
        {pos: [9, 0, 13], state: "minecraft:mud_bricks"},
        {pos: [9, 0, 14], state: "minecraft:mud_bricks"},
        {pos: [9, 0, 20], state: "minecraft:mud_bricks"},
        {pos: [9, 0, 21], state: "minecraft:mud_bricks"},
        {pos: [9, 0, 26], state: "minecraft:mud_bricks"},
        {pos: [9, 0, 27], state: "minecraft:mud_bricks"},
        {pos: [9, 0, 28], state: "minecraft:mud_bricks"},
        {pos: [9, 0, 29], state: "minecraft:mud_bricks"},
        {pos: [9, 0, 30], state: "minecraft:mud_bricks"},
        {pos: [9, 0, 31], state: "minecraft:mud_bricks"},
        {pos: [10, 0, 1], state: "minecraft:mud_bricks"},
        {pos: [10, 0, 2], state: "minecraft:mud_bricks"},
        {pos: [10, 0, 3], state: "minecraft:mud_bricks"},
        {pos: [10, 0, 4], state: "minecraft:mud_bricks"},
        {pos: [10, 0, 5], state: "minecraft:mud_bricks"},
        {pos: [10, 0, 13], state: "minecraft:mud_bricks"},
        {pos: [10, 0, 14], state: "minecraft:mud_bricks"},
        {pos: [10, 0, 16], state: "minecraft:mud_bricks"},
        {pos: [10, 0, 20], state: "minecraft:mud_bricks"},
        {pos: [10, 0, 21], state: "minecraft:mud_bricks"},
        {pos: [10, 0, 27], state: "minecraft:mud_bricks"},
        {pos: [10, 0, 28], state: "minecraft:mud_bricks"},
        {pos: [10, 0, 29], state: "minecraft:mud_bricks"},
        {pos: [10, 0, 30], state: "minecraft:mud_bricks"},
        {pos: [11, 0, 1], state: "minecraft:mud_bricks"},
        {pos: [11, 0, 2], state: "minecraft:mud_bricks"},
        {pos: [11, 0, 3], state: "minecraft:mud_bricks"},
        {pos: [11, 0, 4], state: "minecraft:mud_bricks"},
        {pos: [11, 0, 5], state: "minecraft:mud_bricks"},
        {pos: [11, 0, 11], state: "minecraft:mud_bricks"},
        {pos: [11, 0, 12], state: "minecraft:mud_bricks"},
        {pos: [11, 0, 13], state: "minecraft:mud_bricks"},
        {pos: [11, 0, 14], state: "minecraft:mud_bricks"},
        {pos: [11, 0, 15], state: "minecraft:mud_bricks"},
        {pos: [11, 0, 16], state: "minecraft:mud_bricks"},
        {pos: [11, 0, 19], state: "minecraft:mud_bricks"},
        {pos: [11, 0, 20], state: "minecraft:mud_bricks"},
        {pos: [11, 0, 21], state: "minecraft:mud_bricks"},
        {pos: [11, 0, 22], state: "minecraft:mud_bricks"},
        {pos: [12, 0, 1], state: "minecraft:mud_bricks"},
        {pos: [12, 0, 2], state: "minecraft:mud_bricks"},
        {pos: [12, 0, 3], state: "minecraft:mud_bricks"},
        {pos: [12, 0, 4], state: "minecraft:mud_bricks"},
        {pos: [12, 0, 11], state: "minecraft:mud_bricks"},
        {pos: [12, 0, 12], state: "minecraft:mud_bricks"},
        {pos: [12, 0, 13], state: "minecraft:mud_bricks"},
        {pos: [12, 0, 14], state: "minecraft:mud_bricks"},
        {pos: [12, 0, 15], state: "minecraft:mud_bricks"},
        {pos: [12, 0, 16], state: "minecraft:mud_bricks"},
        {pos: [12, 0, 19], state: "minecraft:mud_bricks"},
        {pos: [12, 0, 20], state: "minecraft:mud_bricks"},
        {pos: [12, 0, 21], state: "minecraft:mud_bricks"},
        {pos: [12, 0, 22], state: "minecraft:mud_bricks"},
        {pos: [13, 0, 2], state: "minecraft:mud_bricks"},
        {pos: [13, 0, 3], state: "minecraft:mud_bricks"},
        {pos: [13, 0, 4], state: "minecraft:mud_bricks"},
        {pos: [13, 0, 12], state: "minecraft:mud_bricks"},
        {pos: [13, 0, 13], state: "minecraft:mud_bricks"},
        {pos: [13, 0, 14], state: "minecraft:mud_bricks"},
        {pos: [13, 0, 18], state: "minecraft:mud_bricks"},
        {pos: [13, 0, 19], state: "minecraft:mud_bricks"},
        {pos: [13, 0, 20], state: "minecraft:mud_bricks"},
        {pos: [13, 0, 21], state: "minecraft:mud_bricks"},
        {pos: [13, 0, 22], state: "minecraft:mud_bricks"},
        {pos: [14, 0, 3], state: "minecraft:mud_bricks"},
        {pos: [14, 0, 4], state: "minecraft:mud_bricks"},
        {pos: [14, 0, 13], state: "minecraft:mud_bricks"},
        {pos: [14, 0, 19], state: "minecraft:mud_bricks"},
        {pos: [14, 0, 20], state: "minecraft:mud_bricks"},
        {pos: [14, 0, 21], state: "minecraft:mud_bricks"},
        {pos: [14, 0, 22], state: "minecraft:mud_bricks"},
        {pos: [15, 0, 2], state: "minecraft:mud_bricks"},
        {pos: [15, 0, 3], state: "minecraft:mud_bricks"},
        {pos: [15, 0, 4], state: "minecraft:mud_bricks"},
        {pos: [15, 0, 20], state: "minecraft:mud_bricks"},
        {pos: [15, 0, 21], state: "minecraft:mud_bricks"},
        {pos: [0, 1, 9], state: "minecraft:mud_brick_stairs{facing:east,half:top,shape:straight,waterlogged:false}"},
        {pos: [0, 1, 10], state: "minecraft:gravel"},
        {pos: [0, 1, 11], state: "minecraft:gravel"},
        {pos: [0, 1, 12], state: "minecraft:mud_brick_stairs{facing:east,half:top,shape:straight,waterlogged:false}"},
        {pos: [0, 1, 21], state: "minecraft:mud_bricks"},
        {pos: [0, 1, 22], state: "minecraft:gravel"},
        {pos: [1, 1, 9], state: "minecraft:mud_bricks"},
        {pos: [1, 1, 10], state: "minecraft:gravel"},
        {pos: [1, 1, 11], state: "minecraft:gravel"},
        {pos: [1, 1, 12], state: "minecraft:mud_bricks"},
        {pos: [1, 1, 20], state: "minecraft:mud_bricks"},
        {pos: [1, 1, 21], state: "minecraft:gravel"},
        {pos: [1, 1, 22], state: "minecraft:gravel"},
        {pos: [1, 1, 23], state: "minecraft:mud_bricks"},
        {pos: [2, 1, 9], state: "minecraft:mud_brick_stairs{facing:west,half:top,shape:straight,waterlogged:false}"},
        {pos: [2, 1, 10], state: "minecraft:gravel"},
        {pos: [2, 1, 11], state: "minecraft:gravel"},
        {pos: [2, 1, 12], state: "minecraft:mud_brick_stairs{facing:west,half:top,shape:straight,waterlogged:false}"},
        {pos: [2, 1, 19], state: "minecraft:mud_bricks"},
        {pos: [2, 1, 20], state: "minecraft:gravel"},
        {pos: [2, 1, 21], state: "minecraft:gravel"},
        {pos: [2, 1, 22], state: "minecraft:gravel"},
        {pos: [2, 1, 23], state: "minecraft:mud_bricks"},
        {pos: [3, 1, 2], state: "minecraft:mud_bricks"},
        {pos: [3, 1, 3], state: "minecraft:mud_bricks"},
        {pos: [3, 1, 4], state: "minecraft:mud_bricks"},
        {pos: [3, 1, 5], state: "minecraft:mud_bricks"},
        {pos: [3, 1, 10], state: "minecraft:gravel"},
        {pos: [3, 1, 11], state: "minecraft:gravel"},
        {pos: [3, 1, 18], state: "minecraft:gravel"},
        {pos: [3, 1, 19], state: "minecraft:mud_bricks"},
        {pos: [3, 1, 20], state: "minecraft:gravel"},
        {pos: [3, 1, 21], state: "minecraft:gravel"},
        {pos: [3, 1, 22], state: "minecraft:gravel"},
        {pos: [3, 1, 23], state: "minecraft:mud_bricks"},
        {pos: [4, 1, 1], state: "minecraft:mud_bricks"},
        {pos: [4, 1, 2], state: "minecraft:gravel"},
        {pos: [4, 1, 3], state: "minecraft:gravel"},
        {pos: [4, 1, 4], state: "minecraft:gravel"},
        {pos: [4, 1, 5], state: "minecraft:mud_brick_stairs{facing:south,half:top,shape:straight,waterlogged:false}"},
        {pos: [4, 1, 6], state: "minecraft:mud_bricks"},
        {pos: [4, 1, 10], state: "minecraft:gravel"},
        {pos: [4, 1, 11], state: "minecraft:gravel"},
        {pos: [4, 1, 17], state: "minecraft:gravel"},
        {pos: [4, 1, 18], state: "minecraft:gravel"},
        {pos: [4, 1, 19], state: "minecraft:mud_bricks"},
        {pos: [4, 1, 20], state: "minecraft:mud_bricks"},
        {pos: [4, 1, 21], state: "minecraft:gravel"},
        {pos: [4, 1, 22], state: "minecraft:gravel"},
        {pos: [4, 1, 27], state: "minecraft:mud_bricks"},
        {pos: [4, 1, 28], state: "minecraft:mud_bricks"},
        {pos: [4, 1, 29], state: "minecraft:gravel"},
        {pos: [4, 1, 30], state: "minecraft:mud_bricks"},
        {pos: [4, 1, 31], state: "minecraft:mud_bricks"},
        {pos: [5, 1, 0], state: "minecraft:mud_bricks"},
        {pos: [5, 1, 1], state: "minecraft:gravel"},
        {pos: [5, 1, 2], state: "minecraft:gravel"},
        {pos: [5, 1, 3], state: "minecraft:gravel"},
        {pos: [5, 1, 4], state: "minecraft:gravel"},
        {pos: [5, 1, 5], state: "minecraft:gravel"},
        {pos: [5, 1, 6], state: "minecraft:mud_bricks"},
        {pos: [5, 1, 7], state: "minecraft:gravel"},
        {pos: [5, 1, 9], state: "minecraft:gravel"},
        {pos: [5, 1, 10], state: "minecraft:gravel"},
        {pos: [5, 1, 11], state: "minecraft:gravel"},
        {pos: [5, 1, 12], state: "minecraft:gravel"},
        {pos: [5, 1, 15], state: "minecraft:gravel"},
        {pos: [5, 1, 16], state: "minecraft:gravel"},
        {pos: [5, 1, 17], state: "minecraft:gravel"},
        {pos: [5, 1, 18], state: "minecraft:gravel"},
        {pos: [5, 1, 19], state: "minecraft:gravel"},
        {pos: [5, 1, 20], state: "minecraft:gravel"},
        {pos: [5, 1, 21], state: "minecraft:gravel"},
        {pos: [5, 1, 26], state: "minecraft:mud_bricks"},
        {pos: [5, 1, 27], state: "minecraft:mud_bricks"},
        {pos: [5, 1, 28], state: "minecraft:gravel"},
        {pos: [5, 1, 29], state: "minecraft:gravel"},
        {pos: [5, 1, 30], state: "minecraft:mud_bricks"},
        {pos: [5, 1, 31], state: "minecraft:mud_bricks"},
        {pos: [5, 1, 32], state: "minecraft:mud_bricks"},
        {pos: [6, 1, 0], state: "minecraft:mud_bricks"},
        {pos: [6, 1, 1], state: "minecraft:gravel"},
        {pos: [6, 1, 2], state: "minecraft:gravel"},
        {pos: [6, 1, 3], state: "minecraft:gravel"},
        {pos: [6, 1, 4], state: "minecraft:gravel"},
        {pos: [6, 1, 5], state: "minecraft:gravel"},
        {pos: [6, 1, 6], state: "minecraft:gravel"},
        {pos: [6, 1, 7], state: "minecraft:gravel"},
        {pos: [6, 1, 8], state: "minecraft:gravel"},
        {pos: [6, 1, 9], state: "minecraft:gravel"},
        {pos: [6, 1, 10], state: "minecraft:gravel"},
        {pos: [6, 1, 11], state: "minecraft:gravel"},
        {pos: [6, 1, 12], state: "minecraft:gravel"},
        {pos: [6, 1, 13], state: "minecraft:gravel"},
        {pos: [6, 1, 14], state: "minecraft:gravel"},
        {pos: [6, 1, 15], state: "minecraft:gravel"},
        {pos: [6, 1, 16], state: "minecraft:gravel"},
        {pos: [6, 1, 17], state: "minecraft:gravel"},
        {pos: [6, 1, 18], state: "minecraft:gravel"},
        {pos: [6, 1, 20], state: "minecraft:gravel"},
        {pos: [6, 1, 21], state: "minecraft:gravel"},
        {pos: [6, 1, 23], state: "minecraft:gravel"},
        {pos: [6, 1, 24], state: "minecraft:gravel"},
        {pos: [6, 1, 25], state: "minecraft:gravel"},
        {pos: [6, 1, 26], state: "minecraft:gravel"},
        {pos: [6, 1, 27], state: "minecraft:gravel"},
        {pos: [6, 1, 28], state: "minecraft:gravel"},
        {pos: [6, 1, 29], state: "minecraft:gravel"},
        {pos: [6, 1, 30], state: "minecraft:gravel"},
        {pos: [6, 1, 31], state: "minecraft:mud_bricks"},
        {pos: [6, 1, 32], state: "minecraft:mud_bricks"},
        {pos: [7, 1, 0], state: "minecraft:mud_bricks"},
        {pos: [7, 1, 1], state: "minecraft:gravel"},
        {pos: [7, 1, 2], state: "minecraft:gravel"},
        {pos: [7, 1, 3], state: "minecraft:gravel"},
        {pos: [7, 1, 4], state: "minecraft:gravel"},
        {pos: [7, 1, 5], state: "minecraft:gravel"},
        {pos: [7, 1, 6], state: "minecraft:mud_bricks"},
        {pos: [7, 1, 7], state: "minecraft:gravel"},
        {pos: [7, 1, 8], state: "minecraft:gravel"},
        {pos: [7, 1, 9], state: "minecraft:gravel"},
        {pos: [7, 1, 10], state: "minecraft:gravel"},
        {pos: [7, 1, 11], state: "minecraft:gravel"},
        {pos: [7, 1, 12], state: "minecraft:gravel"},
        {pos: [7, 1, 13], state: "minecraft:gravel"},
        {pos: [7, 1, 14], state: "minecraft:gravel"},
        {pos: [7, 1, 15], state: "minecraft:gravel"},
        {pos: [7, 1, 16], state: "minecraft:campfire{facing:south,lit:false,signal_fire:false,waterlogged:false}", nbt: {CookingTimes: [I; 0, 0, 0, 0], CookingTotalTimes: [I; 0, 0, 0, 0], Items: [], id: "minecraft:campfire"}},
        {pos: [7, 1, 17], state: "minecraft:gravel"},
        {pos: [7, 1, 18], state: "minecraft:gravel"},
        {pos: [7, 1, 19], state: "minecraft:gravel"},
        {pos: [7, 1, 20], state: "minecraft:gravel"},
        {pos: [7, 1, 21], state: "minecraft:gravel"},
        {pos: [7, 1, 22], state: "minecraft:gravel"},
        {pos: [7, 1, 23], state: "minecraft:gravel"},
        {pos: [7, 1, 24], state: "minecraft:gravel"},
        {pos: [7, 1, 25], state: "minecraft:gravel"},
        {pos: [7, 1, 26], state: "minecraft:gravel"},
        {pos: [7, 1, 27], state: "minecraft:gravel"},
        {pos: [7, 1, 28], state: "minecraft:gravel"},
        {pos: [7, 1, 29], state: "minecraft:gravel"},
        {pos: [7, 1, 30], state: "minecraft:gravel"},
        {pos: [7, 1, 31], state: "minecraft:gravel"},
        {pos: [7, 1, 32], state: "minecraft:mud_bricks"},
        {pos: [8, 1, 0], state: "minecraft:mud_bricks"},
        {pos: [8, 1, 1], state: "minecraft:gravel"},
        {pos: [8, 1, 2], state: "minecraft:gravel"},
        {pos: [8, 1, 3], state: "minecraft:gravel"},
        {pos: [8, 1, 4], state: "minecraft:gravel"},
        {pos: [8, 1, 5], state: "minecraft:gravel"},
        {pos: [8, 1, 6], state: "minecraft:mud_bricks"},
        {pos: [8, 1, 9], state: "minecraft:gravel"},
        {pos: [8, 1, 10], state: "minecraft:gravel"},
        {pos: [8, 1, 11], state: "minecraft:gravel"},
        {pos: [8, 1, 14], state: "minecraft:gravel"},
        {pos: [8, 1, 15], state: "minecraft:gravel"},
        {pos: [8, 1, 18], state: "minecraft:gravel"},
        {pos: [8, 1, 20], state: "minecraft:gravel"},
        {pos: [8, 1, 21], state: "minecraft:gravel"},
        {pos: [8, 1, 22], state: "minecraft:gravel"},
        {pos: [8, 1, 25], state: "minecraft:gravel"},
        {pos: [8, 1, 26], state: "minecraft:gravel"},
        {pos: [8, 1, 27], state: "minecraft:gravel"},
        {pos: [8, 1, 28], state: "minecraft:gravel"},
        {pos: [8, 1, 29], state: "minecraft:gravel"},
        {pos: [8, 1, 30], state: "minecraft:gravel"},
        {pos: [8, 1, 31], state: "minecraft:barrel{facing:north,open:false}", nbt: {Items: [], id: "minecraft:barrel"}},
        {pos: [8, 1, 32], state: "minecraft:mud_bricks"},
        {pos: [9, 1, 0], state: "minecraft:mud_bricks"},
        {pos: [9, 1, 1], state: "minecraft:mud_brick_stairs{facing:north,half:top,shape:straight,waterlogged:false}"},
        {pos: [9, 1, 2], state: "minecraft:gravel"},
        {pos: [9, 1, 3], state: "minecraft:gravel"},
        {pos: [9, 1, 4], state: "minecraft:gravel"},
        {pos: [9, 1, 5], state: "minecraft:mud_bricks"},
        {pos: [9, 1, 6], state: "minecraft:gravel"},
        {pos: [9, 1, 13], state: "minecraft:gravel"},
        {pos: [9, 1, 14], state: "minecraft:gravel"},
        {pos: [9, 1, 20], state: "minecraft:gravel"},
        {pos: [9, 1, 21], state: "minecraft:gravel"},
        {pos: [9, 1, 26], state: "minecraft:mud_bricks"},
        {pos: [9, 1, 27], state: "minecraft:mud_bricks"},
        {pos: [9, 1, 28], state: "minecraft:mud_bricks"},
        {pos: [9, 1, 29], state: "minecraft:smoker{facing:west,lit:false}", nbt: {BurnTime: 0s, CookTime: 0s, CookTimeTotal: 0s, Items: [], RecipesUsed: {}, id: "minecraft:smoker"}},
        {pos: [9, 1, 30], state: "minecraft:mud_brick_stairs{facing:east,half:top,shape:straight,waterlogged:false}"},
        {pos: [9, 1, 31], state: "minecraft:mud_bricks"},
        {pos: [9, 1, 32], state: "minecraft:mud_bricks"},
        {pos: [10, 1, 1], state: "minecraft:mud_bricks"},
        {pos: [10, 1, 2], state: "minecraft:gravel"},
        {pos: [10, 1, 3], state: "minecraft:gravel"},
        {pos: [10, 1, 4], state: "minecraft:gravel"},
        {pos: [10, 1, 5], state: "minecraft:gravel"},
        {pos: [10, 1, 13], state: "minecraft:gravel"},
        {pos: [10, 1, 14], state: "minecraft:gravel"},
        {pos: [10, 1, 16], state: "minecraft:gravel"},
        {pos: [10, 1, 20], state: "minecraft:gravel"},
        {pos: [10, 1, 21], state: "minecraft:gravel"},
        {pos: [10, 1, 27], state: "minecraft:mud_bricks"},
        {pos: [10, 1, 28], state: "minecraft:mud_bricks"},
        {pos: [10, 1, 29], state: "minecraft:mud_bricks"},
        {pos: [10, 1, 30], state: "minecraft:mud_bricks"},
        {pos: [10, 1, 31], state: "minecraft:mud_bricks"},
        {pos: [11, 1, 1], state: "trailiertales:suspicious_clay{can_place_item:true,dusted:0}", nbt: {id: "minecraft:brushable_block"}},
        {pos: [11, 1, 2], state: "minecraft:clay"},
        {pos: [11, 1, 3], state: "minecraft:gravel"},
        {pos: [11, 1, 4], state: "minecraft:gravel"},
        {pos: [11, 1, 5], state: "minecraft:gravel"},
        {pos: [11, 1, 11], state: "minecraft:gravel"},
        {pos: [11, 1, 12], state: "minecraft:gravel"},
        {pos: [11, 1, 13], state: "minecraft:gravel"},
        {pos: [11, 1, 14], state: "minecraft:gravel"},
        {pos: [11, 1, 15], state: "minecraft:gravel"},
        {pos: [11, 1, 16], state: "minecraft:gravel"},
        {pos: [11, 1, 19], state: "minecraft:gravel"},
        {pos: [11, 1, 20], state: "minecraft:gravel"},
        {pos: [11, 1, 21], state: "minecraft:gravel"},
        {pos: [11, 1, 22], state: "minecraft:mud_bricks"},
        {pos: [12, 1, 1], state: "minecraft:clay"},
        {pos: [12, 1, 2], state: "minecraft:gravel"},
        {pos: [12, 1, 3], state: "minecraft:gravel"},
        {pos: [12, 1, 4], state: "minecraft:gravel"},
        {pos: [12, 1, 11], state: "minecraft:mud_brick_stairs{facing:south,half:top,shape:straight,waterlogged:false}"},
        {pos: [12, 1, 12], state: "minecraft:mud_bricks"},
        {pos: [12, 1, 13], state: "minecraft:mud_bricks"},
        {pos: [12, 1, 14], state: "minecraft:mud_bricks"},
        {pos: [12, 1, 15], state: "minecraft:mud_brick_stairs{facing:north,half:top,shape:straight,waterlogged:false}"},
        {pos: [12, 1, 16], state: "minecraft:gravel"},
        {pos: [12, 1, 19], state: "minecraft:gravel"},
        {pos: [12, 1, 20], state: "minecraft:gravel"},
        {pos: [12, 1, 21], state: "minecraft:gravel"},
        {pos: [12, 1, 22], state: "minecraft:mud_bricks"},
        {pos: [13, 1, 2], state: "minecraft:gravel"},
        {pos: [13, 1, 3], state: "minecraft:gravel"},
        {pos: [13, 1, 4], state: "minecraft:mud_brick_wall{east:tall,north:tall,south:none,up:true,waterlogged:false,west:tall}"},
        {pos: [13, 1, 12], state: "minecraft:gravel"},
        {pos: [13, 1, 13], state: "minecraft:gravel"},
        {pos: [13, 1, 14], state: "minecraft:gravel"},
        {pos: [13, 1, 18], state: "minecraft:mud_bricks"},
        {pos: [13, 1, 19], state: "minecraft:mud_bricks"},
        {pos: [13, 1, 20], state: "minecraft:gravel"},
        {pos: [13, 1, 21], state: "minecraft:gravel"},
        {pos: [13, 1, 22], state: "minecraft:gravel"},
        {pos: [14, 1, 3], state: "minecraft:gravel"},
        {pos: [14, 1, 4], state: "minecraft:gravel"},
        {pos: [14, 1, 13], state: "minecraft:gravel"},
        {pos: [14, 1, 19], state: "minecraft:mud_bricks"},
        {pos: [14, 1, 20], state: "minecraft:mud_bricks"},
        {pos: [14, 1, 21], state: "minecraft:gravel"},
        {pos: [14, 1, 22], state: "minecraft:mud_bricks"},
        {pos: [15, 1, 2], state: "minecraft:gravel"},
        {pos: [15, 1, 3], state: "minecraft:gravel"},
        {pos: [15, 1, 4], state: "minecraft:gravel"},
        {pos: [15, 1, 20], state: "minecraft:mud_bricks"},
        {pos: [15, 1, 21], state: "minecraft:mud_bricks"},
        {pos: [0, 2, 9], state: "minecraft:orange_glazed_terracotta{facing:east}"},
        {pos: [0, 2, 10], state: "minecraft:gravel"},
        {pos: [0, 2, 11], state: "minecraft:gravel"},
        {pos: [0, 2, 12], state: "minecraft:gravel"},
        {pos: [0, 2, 21], state: "minecraft:mud_bricks"},
        {pos: [0, 2, 22], state: "minecraft:gravel"},
        {pos: [1, 2, 9], state: "minecraft:gravel"},
        {pos: [1, 2, 10], state: "minecraft:gravel"},
        {pos: [1, 2, 11], state: "minecraft:gravel"},
        {pos: [1, 2, 12], state: "minecraft:yellow_glazed_terracotta{facing:west}"},
        {pos: [1, 2, 20], state: "minecraft:mud_bricks"},
        {pos: [1, 2, 21], state: "minecraft:gravel"},
        {pos: [1, 2, 22], state: "minecraft:gravel"},
        {pos: [1, 2, 23], state: "minecraft:gravel"},
        {pos: [2, 2, 9], state: "minecraft:orange_glazed_terracotta{facing:east}"},
        {pos: [2, 2, 10], state: "minecraft:gravel"},
        {pos: [2, 2, 11], state: "minecraft:gravel"},
        {pos: [2, 2, 12], state: "minecraft:yellow_glazed_terracotta{facing:west}"},
        {pos: [2, 2, 19], state: "minecraft:gravel"},
        {pos: [2, 2, 20], state: "minecraft:gravel"},
        {pos: [2, 2, 21], state: "minecraft:gravel"},
        {pos: [2, 2, 22], state: "minecraft:gravel"},
        {pos: [2, 2, 23], state: "minecraft:mud_bricks"},
        {pos: [3, 2, 2], state: "minecraft:mud_bricks"},
        {pos: [3, 2, 3], state: "minecraft:mud_bricks"},
        {pos: [3, 2, 4], state: "minecraft:gravel"},
        {pos: [3, 2, 5], state: "minecraft:mud_bricks"},
        {pos: [3, 2, 10], state: "minecraft:gravel"},
        {pos: [3, 2, 11], state: "minecraft:gravel"},
        {pos: [3, 2, 18], state: "minecraft:gravel"},
        {pos: [3, 2, 19], state: "minecraft:mud_bricks"},
        {pos: [3, 2, 20], state: "minecraft:gravel"},
        {pos: [3, 2, 21], state: "minecraft:gravel"},
        {pos: [3, 2, 22], state: "minecraft:gravel"},
        {pos: [3, 2, 23], state: "minecraft:mud_bricks"},
        {pos: [4, 2, 1], state: "minecraft:gravel"},
        {pos: [4, 2, 2], state: "minecraft:gravel"},
        {pos: [4, 2, 3], state: "minecraft:gravel"},
        {pos: [4, 2, 4], state: "minecraft:gravel"},
        {pos: [4, 2, 5], state: "minecraft:gravel"},
        {pos: [4, 2, 6], state: "minecraft:mud_bricks"},
        {pos: [4, 2, 10], state: "minecraft:gravel"},
        {pos: [4, 2, 11], state: "minecraft:gravel"},
        {pos: [4, 2, 17], state: "minecraft:gravel"},
        {pos: [4, 2, 18], state: "minecraft:gravel"},
        {pos: [4, 2, 19], state: "minecraft:mud_bricks"},
        {pos: [4, 2, 20], state: "minecraft:mud_bricks"},
        {pos: [4, 2, 21], state: "minecraft:gravel"},
        {pos: [4, 2, 22], state: "minecraft:gravel"},
        {pos: [4, 2, 27], state: "minecraft:mud_bricks"},
        {pos: [4, 2, 28], state: "minecraft:mud_bricks"},
        {pos: [4, 2, 29], state: "minecraft:gravel"},
        {pos: [4, 2, 30], state: "minecraft:mud_bricks"},
        {pos: [4, 2, 31], state: "minecraft:mud_bricks"},
        {pos: [5, 2, 0], state: "minecraft:mud_bricks"},
        {pos: [5, 2, 1], state: "minecraft:gravel"},
        {pos: [5, 2, 2], state: "minecraft:gravel"},
        {pos: [5, 2, 3], state: "minecraft:gravel"},
        {pos: [5, 2, 4], state: "minecraft:gravel"},
        {pos: [5, 2, 5], state: "minecraft:mud_brick_stairs{facing:south,half:top,shape:straight,waterlogged:false}"},
        {pos: [5, 2, 6], state: "minecraft:mud_bricks"},
        {pos: [5, 2, 7], state: "minecraft:gravel"},
        {pos: [5, 2, 9], state: "minecraft:gravel"},
        {pos: [5, 2, 10], state: "minecraft:gravel"},
        {pos: [5, 2, 11], state: "minecraft:gravel"},
        {pos: [5, 2, 12], state: "minecraft:gravel"},
        {pos: [5, 2, 15], state: "minecraft:gravel"},
        {pos: [5, 2, 16], state: "minecraft:gravel"},
        {pos: [5, 2, 17], state: "minecraft:gravel"},
        {pos: [5, 2, 18], state: "minecraft:gravel"},
        {pos: [5, 2, 19], state: "minecraft:gravel"},
        {pos: [5, 2, 20], state: "minecraft:gravel"},
        {pos: [5, 2, 21], state: "minecraft:gravel"},
        {pos: [5, 2, 26], state: "minecraft:mud_bricks"},
        {pos: [5, 2, 27], state: "minecraft:gravel"},
        {pos: [5, 2, 28], state: "minecraft:gravel"},
        {pos: [5, 2, 29], state: "minecraft:gravel"},
        {pos: [5, 2, 30], state: "minecraft:gravel"},
        {pos: [5, 2, 31], state: "minecraft:gravel"},
        {pos: [5, 2, 32], state: "minecraft:mud_bricks"},
        {pos: [6, 2, 0], state: "minecraft:gravel"},
        {pos: [6, 2, 1], state: "minecraft:gravel"},
        {pos: [6, 2, 2], state: "minecraft:gravel"},
        {pos: [6, 2, 3], state: "minecraft:gravel"},
        {pos: [6, 2, 4], state: "minecraft:gravel"},
        {pos: [6, 2, 5], state: "minecraft:gravel"},
        {pos: [6, 2, 6], state: "minecraft:gravel"},
        {pos: [6, 2, 7], state: "minecraft:gravel"},
        {pos: [6, 2, 8], state: "minecraft:gravel"},
        {pos: [6, 2, 9], state: "minecraft:gravel"},
        {pos: [6, 2, 10], state: "minecraft:gravel"},
        {pos: [6, 2, 11], state: "minecraft:gravel"},
        {pos: [6, 2, 12], state: "minecraft:gravel"},
        {pos: [6, 2, 13], state: "minecraft:gravel"},
        {pos: [6, 2, 14], state: "minecraft:gravel"},
        {pos: [6, 2, 15], state: "minecraft:gravel"},
        {pos: [6, 2, 16], state: "minecraft:gravel"},
        {pos: [6, 2, 17], state: "minecraft:gravel"},
        {pos: [6, 2, 18], state: "minecraft:gravel"},
        {pos: [6, 2, 20], state: "minecraft:gravel"},
        {pos: [6, 2, 21], state: "minecraft:gravel"},
        {pos: [6, 2, 23], state: "minecraft:gravel"},
        {pos: [6, 2, 24], state: "minecraft:gravel"},
        {pos: [6, 2, 25], state: "minecraft:gravel"},
        {pos: [6, 2, 26], state: "minecraft:gravel"},
        {pos: [6, 2, 27], state: "minecraft:gravel"},
        {pos: [6, 2, 28], state: "minecraft:gravel"},
        {pos: [6, 2, 29], state: "minecraft:gravel"},
        {pos: [6, 2, 30], state: "minecraft:gravel"},
        {pos: [6, 2, 31], state: "minecraft:gravel"},
        {pos: [6, 2, 32], state: "minecraft:mud_bricks"},
        {pos: [7, 2, 0], state: "minecraft:gravel"},
        {pos: [7, 2, 1], state: "minecraft:gravel"},
        {pos: [7, 2, 2], state: "minecraft:gravel"},
        {pos: [7, 2, 3], state: "minecraft:gravel"},
        {pos: [7, 2, 4], state: "minecraft:gravel"},
        {pos: [7, 2, 5], state: "minecraft:gravel"},
        {pos: [7, 2, 6], state: "minecraft:mud_bricks"},
        {pos: [7, 2, 7], state: "minecraft:gravel"},
        {pos: [7, 2, 8], state: "minecraft:gravel"},
        {pos: [7, 2, 9], state: "minecraft:gravel"},
        {pos: [7, 2, 10], state: "minecraft:gravel"},
        {pos: [7, 2, 11], state: "minecraft:gravel"},
        {pos: [7, 2, 12], state: "minecraft:gravel"},
        {pos: [7, 2, 13], state: "minecraft:gravel"},
        {pos: [7, 2, 14], state: "minecraft:gravel"},
        {pos: [7, 2, 15], state: "minecraft:gravel"},
        {pos: [7, 2, 16], state: "minecraft:gravel"},
        {pos: [7, 2, 17], state: "minecraft:gravel"},
        {pos: [7, 2, 18], state: "minecraft:gravel"},
        {pos: [7, 2, 19], state: "minecraft:gravel"},
        {pos: [7, 2, 20], state: "minecraft:gravel"},
        {pos: [7, 2, 21], state: "minecraft:gravel"},
        {pos: [7, 2, 22], state: "minecraft:gravel"},
        {pos: [7, 2, 23], state: "minecraft:gravel"},
        {pos: [7, 2, 24], state: "minecraft:gravel"},
        {pos: [7, 2, 25], state: "minecraft:gravel"},
        {pos: [7, 2, 26], state: "minecraft:gravel"},
        {pos: [7, 2, 27], state: "minecraft:gravel"},
        {pos: [7, 2, 28], state: "minecraft:gravel"},
        {pos: [7, 2, 29], state: "minecraft:gravel"},
        {pos: [7, 2, 30], state: "minecraft:gravel"},
        {pos: [7, 2, 31], state: "minecraft:gravel"},
        {pos: [7, 2, 32], state: "minecraft:gravel"},
        {pos: [8, 2, 0], state: "minecraft:gravel"},
        {pos: [8, 2, 1], state: "minecraft:gravel"},
        {pos: [8, 2, 2], state: "minecraft:gravel"},
        {pos: [8, 2, 3], state: "minecraft:gravel"},
        {pos: [8, 2, 4], state: "minecraft:gravel"},
        {pos: [8, 2, 5], state: "minecraft:gravel"},
        {pos: [8, 2, 6], state: "minecraft:gravel"},
        {pos: [8, 2, 9], state: "minecraft:gravel"},
        {pos: [8, 2, 10], state: "minecraft:gravel"},
        {pos: [8, 2, 11], state: "minecraft:gravel"},
        {pos: [8, 2, 14], state: "minecraft:gravel"},
        {pos: [8, 2, 15], state: "minecraft:gravel"},
        {pos: [8, 2, 18], state: "minecraft:gravel"},
        {pos: [8, 2, 20], state: "minecraft:gravel"},
        {pos: [8, 2, 21], state: "minecraft:gravel"},
        {pos: [8, 2, 22], state: "minecraft:gravel"},
        {pos: [8, 2, 25], state: "minecraft:gravel"},
        {pos: [8, 2, 26], state: "minecraft:gravel"},
        {pos: [8, 2, 27], state: "minecraft:gravel"},
        {pos: [8, 2, 28], state: "minecraft:gravel"},
        {pos: [8, 2, 29], state: "minecraft:gravel"},
        {pos: [8, 2, 30], state: "minecraft:gravel"},
        {pos: [8, 2, 31], state: "minecraft:gravel"},
        {pos: [8, 2, 32], state: "minecraft:mud_bricks"},
        {pos: [9, 2, 0], state: "minecraft:mud_bricks"},
        {pos: [9, 2, 1], state: "minecraft:gravel"},
        {pos: [9, 2, 2], state: "minecraft:gravel"},
        {pos: [9, 2, 3], state: "minecraft:gravel"},
        {pos: [9, 2, 4], state: "minecraft:gravel"},
        {pos: [9, 2, 5], state: "minecraft:mud_bricks"},
        {pos: [9, 2, 6], state: "minecraft:gravel"},
        {pos: [9, 2, 13], state: "minecraft:gravel"},
        {pos: [9, 2, 14], state: "minecraft:gravel"},
        {pos: [9, 2, 20], state: "minecraft:gravel"},
        {pos: [9, 2, 21], state: "minecraft:gravel"},
        {pos: [9, 2, 26], state: "minecraft:gravel"},
        {pos: [9, 2, 27], state: "minecraft:gravel"},
        {pos: [9, 2, 28], state: "minecraft:gravel"},
        {pos: [9, 2, 29], state: "minecraft:gravel"},
        {pos: [9, 2, 30], state: "minecraft:gravel"},
        {pos: [9, 2, 31], state: "minecraft:barrel{facing:north,open:false}", nbt: {Items: [], id: "minecraft:barrel"}},
        {pos: [9, 2, 32], state: "minecraft:mud_bricks"},
        {pos: [10, 2, 1], state: "minecraft:mud_bricks"},
        {pos: [10, 2, 2], state: "minecraft:gravel"},
        {pos: [10, 2, 3], state: "minecraft:gravel"},
        {pos: [10, 2, 4], state: "minecraft:gravel"},
        {pos: [10, 2, 5], state: "minecraft:gravel"},
        {pos: [10, 2, 13], state: "minecraft:gravel"},
        {pos: [10, 2, 14], state: "minecraft:gravel"},
        {pos: [10, 2, 16], state: "minecraft:gravel"},
        {pos: [10, 2, 20], state: "minecraft:gravel"},
        {pos: [10, 2, 21], state: "minecraft:gravel"},
        {pos: [10, 2, 27], state: "minecraft:mud_bricks"},
        {pos: [10, 2, 28], state: "minecraft:mud_bricks"},
        {pos: [10, 2, 29], state: "minecraft:gravel"},
        {pos: [10, 2, 30], state: "minecraft:mud_bricks"},
        {pos: [10, 2, 31], state: "minecraft:mud_bricks"},
        {pos: [11, 2, 1], state: "minecraft:gravel"},
        {pos: [11, 2, 2], state: "minecraft:gravel"},
        {pos: [11, 2, 3], state: "minecraft:gravel"},
        {pos: [11, 2, 4], state: "minecraft:gravel"},
        {pos: [11, 2, 5], state: "minecraft:gravel"},
        {pos: [11, 2, 11], state: "minecraft:gravel"},
        {pos: [11, 2, 12], state: "minecraft:gravel"},
        {pos: [11, 2, 13], state: "minecraft:gravel"},
        {pos: [11, 2, 14], state: "minecraft:gravel"},
        {pos: [11, 2, 15], state: "minecraft:gravel"},
        {pos: [11, 2, 16], state: "minecraft:gravel"},
        {pos: [11, 2, 19], state: "minecraft:gravel"},
        {pos: [11, 2, 20], state: "minecraft:gravel"},
        {pos: [11, 2, 21], state: "minecraft:gravel"},
        {pos: [11, 2, 22], state: "minecraft:mud_bricks"},
        {pos: [12, 2, 1], state: "minecraft:gravel"},
        {pos: [12, 2, 2], state: "minecraft:gravel"},
        {pos: [12, 2, 3], state: "minecraft:gravel"},
        {pos: [12, 2, 4], state: "minecraft:gravel"},
        {pos: [12, 2, 11], state: "minecraft:gravel"},
        {pos: [12, 2, 12], state: "minecraft:orange_glazed_terracotta{facing:south}"},
        {pos: [12, 2, 13], state: "minecraft:orange_glazed_terracotta{facing:west}"},
        {pos: [12, 2, 14], state: "minecraft:gravel"},
        {pos: [12, 2, 15], state: "minecraft:orange_glazed_terracotta{facing:west}"},
        {pos: [12, 2, 16], state: "minecraft:gravel"},
        {pos: [12, 2, 19], state: "minecraft:gravel"},
        {pos: [12, 2, 20], state: "minecraft:gravel"},
        {pos: [12, 2, 21], state: "minecraft:gravel"},
        {pos: [12, 2, 22], state: "minecraft:gravel"},
        {pos: [13, 2, 2], state: "minecraft:gravel"},
        {pos: [13, 2, 3], state: "minecraft:gravel"},
        {pos: [13, 2, 4], state: "minecraft:mud_brick_wall{east:tall,north:tall,south:none,up:true,waterlogged:false,west:tall}"},
        {pos: [13, 2, 12], state: "minecraft:gravel"},
        {pos: [13, 2, 13], state: "minecraft:gravel"},
        {pos: [13, 2, 14], state: "minecraft:gravel"},
        {pos: [13, 2, 18], state: "minecraft:mud_bricks"},
        {pos: [13, 2, 19], state: "minecraft:gravel"},
        {pos: [13, 2, 20], state: "minecraft:gravel"},
        {pos: [13, 2, 21], state: "minecraft:gravel"},
        {pos: [13, 2, 22], state: "minecraft:gravel"},
        {pos: [14, 2, 3], state: "minecraft:gravel"},
        {pos: [14, 2, 4], state: "minecraft:gravel"},
        {pos: [14, 2, 13], state: "minecraft:gravel"},
        {pos: [14, 2, 19], state: "minecraft:mud_bricks"},
        {pos: [14, 2, 20], state: "minecraft:gravel"},
        {pos: [14, 2, 21], state: "minecraft:gravel"},
        {pos: [14, 2, 22], state: "minecraft:gravel"},
        {pos: [15, 2, 2], state: "minecraft:gravel"},
        {pos: [15, 2, 3], state: "minecraft:gravel"},
        {pos: [15, 2, 4], state: "minecraft:gravel"},
        {pos: [15, 2, 20], state: "minecraft:mud_bricks"},
        {pos: [15, 2, 21], state: "minecraft:mud_bricks"},
        {pos: [0, 3, 9], state: "minecraft:gravel"},
        {pos: [0, 3, 10], state: "minecraft:gravel"},
        {pos: [0, 3, 11], state: "minecraft:gravel"},
        {pos: [0, 3, 21], state: "minecraft:gravel"},
        {pos: [0, 3, 22], state: "minecraft:gravel"},
        {pos: [1, 3, 9], state: "minecraft:gravel"},
        {pos: [1, 3, 10], state: "minecraft:gravel"},
        {pos: [1, 3, 11], state: "minecraft:gravel"},
        {pos: [1, 3, 12], state: "minecraft:gravel"},
        {pos: [1, 3, 20], state: "minecraft:gravel"},
        {pos: [1, 3, 21], state: "minecraft:gravel"},
        {pos: [1, 3, 22], state: "minecraft:gravel"},
        {pos: [1, 3, 23], state: "minecraft:gravel"},
        {pos: [2, 3, 9], state: "minecraft:gravel"},
        {pos: [2, 3, 10], state: "minecraft:gravel"},
        {pos: [2, 3, 11], state: "minecraft:gravel"},
        {pos: [2, 3, 12], state: "minecraft:gravel"},
        {pos: [2, 3, 19], state: "minecraft:mud_bricks"},
        {pos: [2, 3, 20], state: "minecraft:gravel"},
        {pos: [2, 3, 21], state: "minecraft:gravel"},
        {pos: [2, 3, 22], state: "minecraft:gravel"},
        {pos: [2, 3, 23], state: "minecraft:gravel"},
        {pos: [3, 3, 2], state: "minecraft:mud_bricks"},
        {pos: [3, 3, 3], state: "minecraft:mud_bricks"},
        {pos: [3, 3, 4], state: "minecraft:mud_bricks"},
        {pos: [3, 3, 5], state: "minecraft:mud_bricks"},
        {pos: [3, 3, 10], state: "minecraft:gravel"},
        {pos: [3, 3, 11], state: "minecraft:gravel"},
        {pos: [3, 3, 18], state: "minecraft:gravel"},
        {pos: [3, 3, 19], state: "minecraft:mud_bricks"},
        {pos: [3, 3, 20], state: "minecraft:gravel"},
        {pos: [3, 3, 21], state: "minecraft:gravel"},
        {pos: [3, 3, 22], state: "minecraft:gravel"},
        {pos: [3, 3, 23], state: "minecraft:gravel"},
        {pos: [4, 3, 1], state: "minecraft:mud_bricks"},
        {pos: [4, 3, 2], state: "minecraft:gravel"},
        {pos: [4, 3, 3], state: "minecraft:gravel"},
        {pos: [4, 3, 4], state: "minecraft:gravel"},
        {pos: [4, 3, 5], state: "minecraft:gravel"},
        {pos: [4, 3, 6], state: "minecraft:mud_bricks"},
        {pos: [4, 3, 10], state: "minecraft:gravel"},
        {pos: [4, 3, 11], state: "minecraft:gravel"},
        {pos: [4, 3, 17], state: "minecraft:gravel"},
        {pos: [4, 3, 18], state: "minecraft:gravel"},
        {pos: [4, 3, 19], state: "minecraft:gravel"},
        {pos: [4, 3, 20], state: "minecraft:mud_bricks"},
        {pos: [4, 3, 21], state: "minecraft:mud_bricks"},
        {pos: [4, 3, 22], state: "minecraft:mud_bricks"},
        {pos: [4, 3, 27], state: "minecraft:mud_bricks"},
        {pos: [4, 3, 28], state: "minecraft:mud_bricks"},
        {pos: [4, 3, 29], state: "minecraft:mud_bricks"},
        {pos: [4, 3, 30], state: "minecraft:mud_bricks"},
        {pos: [4, 3, 31], state: "minecraft:mud_bricks"},
        {pos: [5, 3, 0], state: "minecraft:mud_bricks"},
        {pos: [5, 3, 1], state: "minecraft:gravel"},
        {pos: [5, 3, 2], state: "minecraft:gravel"},
        {pos: [5, 3, 3], state: "minecraft:gravel"},
        {pos: [5, 3, 4], state: "minecraft:gravel"},
        {pos: [5, 3, 5], state: "minecraft:gravel"},
        {pos: [5, 3, 6], state: "minecraft:mud_bricks"},
        {pos: [5, 3, 7], state: "minecraft:gravel"},
        {pos: [5, 3, 9], state: "minecraft:gravel"},
        {pos: [5, 3, 10], state: "minecraft:gravel"},
        {pos: [5, 3, 11], state: "minecraft:gravel"},
        {pos: [5, 3, 12], state: "minecraft:gravel"},
        {pos: [5, 3, 15], state: "minecraft:gravel"},
        {pos: [5, 3, 16], state: "minecraft:gravel"},
        {pos: [5, 3, 17], state: "minecraft:gravel"},
        {pos: [5, 3, 18], state: "minecraft:gravel"},
        {pos: [5, 3, 19], state: "minecraft:gravel"},
        {pos: [5, 3, 20], state: "minecraft:gravel"},
        {pos: [5, 3, 21], state: "minecraft:gravel"},
        {pos: [5, 3, 26], state: "minecraft:mud_bricks"},
        {pos: [5, 3, 27], state: "minecraft:gravel"},
        {pos: [5, 3, 28], state: "minecraft:gravel"},
        {pos: [5, 3, 29], state: "minecraft:gravel"},
        {pos: [5, 3, 30], state: "minecraft:gravel"},
        {pos: [5, 3, 31], state: "minecraft:gravel"},
        {pos: [5, 3, 32], state: "minecraft:mud_bricks"},
        {pos: [6, 3, 0], state: "minecraft:mud_bricks"},
        {pos: [6, 3, 1], state: "minecraft:gravel"},
        {pos: [6, 3, 2], state: "minecraft:gravel"},
        {pos: [6, 3, 3], state: "minecraft:gravel"},
        {pos: [6, 3, 4], state: "minecraft:gravel"},
        {pos: [6, 3, 5], state: "minecraft:gravel"},
        {pos: [6, 3, 6], state: "minecraft:mud_bricks"},
        {pos: [6, 3, 7], state: "minecraft:gravel"},
        {pos: [6, 3, 8], state: "minecraft:gravel"},
        {pos: [6, 3, 9], state: "minecraft:gravel"},
        {pos: [6, 3, 10], state: "minecraft:gravel"},
        {pos: [6, 3, 11], state: "minecraft:gravel"},
        {pos: [6, 3, 12], state: "minecraft:gravel"},
        {pos: [6, 3, 13], state: "minecraft:gravel"},
        {pos: [6, 3, 14], state: "minecraft:gravel"},
        {pos: [6, 3, 15], state: "minecraft:gravel"},
        {pos: [6, 3, 16], state: "minecraft:gravel"},
        {pos: [6, 3, 17], state: "minecraft:gravel"},
        {pos: [6, 3, 18], state: "minecraft:gravel"},
        {pos: [6, 3, 20], state: "minecraft:gravel"},
        {pos: [6, 3, 21], state: "minecraft:gravel"},
        {pos: [6, 3, 23], state: "minecraft:gravel"},
        {pos: [6, 3, 24], state: "minecraft:gravel"},
        {pos: [6, 3, 25], state: "minecraft:gravel"},
        {pos: [6, 3, 26], state: "minecraft:mud_bricks"},
        {pos: [6, 3, 27], state: "minecraft:gravel"},
        {pos: [6, 3, 28], state: "minecraft:gravel"},
        {pos: [6, 3, 29], state: "minecraft:gravel"},
        {pos: [6, 3, 30], state: "minecraft:gravel"},
        {pos: [6, 3, 31], state: "minecraft:gravel"},
        {pos: [6, 3, 32], state: "minecraft:mud_bricks"},
        {pos: [7, 3, 0], state: "minecraft:mud_bricks"},
        {pos: [7, 3, 1], state: "minecraft:gravel"},
        {pos: [7, 3, 2], state: "minecraft:gravel"},
        {pos: [7, 3, 3], state: "minecraft:gravel"},
        {pos: [7, 3, 4], state: "minecraft:gravel"},
        {pos: [7, 3, 5], state: "minecraft:gravel"},
        {pos: [7, 3, 6], state: "minecraft:mud_bricks"},
        {pos: [7, 3, 7], state: "minecraft:gravel"},
        {pos: [7, 3, 8], state: "minecraft:gravel"},
        {pos: [7, 3, 9], state: "minecraft:gravel"},
        {pos: [7, 3, 10], state: "minecraft:gravel"},
        {pos: [7, 3, 11], state: "minecraft:gravel"},
        {pos: [7, 3, 12], state: "minecraft:gravel"},
        {pos: [7, 3, 13], state: "minecraft:gravel"},
        {pos: [7, 3, 14], state: "minecraft:gravel"},
        {pos: [7, 3, 15], state: "minecraft:gravel"},
        {pos: [7, 3, 16], state: "minecraft:gravel"},
        {pos: [7, 3, 17], state: "minecraft:gravel"},
        {pos: [7, 3, 18], state: "minecraft:gravel"},
        {pos: [7, 3, 19], state: "minecraft:gravel"},
        {pos: [7, 3, 20], state: "minecraft:gravel"},
        {pos: [7, 3, 21], state: "minecraft:gravel"},
        {pos: [7, 3, 22], state: "minecraft:gravel"},
        {pos: [7, 3, 23], state: "minecraft:gravel"},
        {pos: [7, 3, 24], state: "minecraft:gravel"},
        {pos: [7, 3, 25], state: "minecraft:gravel"},
        {pos: [7, 3, 26], state: "minecraft:mud_bricks"},
        {pos: [7, 3, 27], state: "minecraft:gravel"},
        {pos: [7, 3, 28], state: "minecraft:gravel"},
        {pos: [7, 3, 29], state: "minecraft:gravel"},
        {pos: [7, 3, 30], state: "minecraft:gravel"},
        {pos: [7, 3, 31], state: "minecraft:gravel"},
        {pos: [7, 3, 32], state: "minecraft:mud_bricks"},
        {pos: [8, 3, 0], state: "minecraft:mud_bricks"},
        {pos: [8, 3, 1], state: "minecraft:gravel"},
        {pos: [8, 3, 2], state: "minecraft:gravel"},
        {pos: [8, 3, 3], state: "minecraft:gravel"},
        {pos: [8, 3, 4], state: "minecraft:gravel"},
        {pos: [8, 3, 5], state: "minecraft:mud_bricks"},
        {pos: [8, 3, 6], state: "minecraft:mud_bricks"},
        {pos: [8, 3, 9], state: "minecraft:gravel"},
        {pos: [8, 3, 10], state: "minecraft:gravel"},
        {pos: [8, 3, 11], state: "minecraft:gravel"},
        {pos: [8, 3, 14], state: "minecraft:gravel"},
        {pos: [8, 3, 15], state: "minecraft:gravel"},
        {pos: [8, 3, 18], state: "minecraft:gravel"},
        {pos: [8, 3, 20], state: "minecraft:gravel"},
        {pos: [8, 3, 21], state: "minecraft:gravel"},
        {pos: [8, 3, 22], state: "minecraft:gravel"},
        {pos: [8, 3, 25], state: "minecraft:gravel"},
        {pos: [8, 3, 26], state: "minecraft:mud_bricks"},
        {pos: [8, 3, 27], state: "minecraft:gravel"},
        {pos: [8, 3, 28], state: "minecraft:gravel"},
        {pos: [8, 3, 29], state: "minecraft:gravel"},
        {pos: [8, 3, 30], state: "minecraft:gravel"},
        {pos: [8, 3, 31], state: "minecraft:gravel"},
        {pos: [8, 3, 32], state: "minecraft:mud_bricks"},
        {pos: [9, 3, 0], state: "minecraft:mud_bricks"},
        {pos: [9, 3, 1], state: "minecraft:gravel"},
        {pos: [9, 3, 2], state: "minecraft:gravel"},
        {pos: [9, 3, 3], state: "minecraft:gravel"},
        {pos: [9, 3, 4], state: "minecraft:gravel"},
        {pos: [9, 3, 5], state: "minecraft:mud_bricks"},
        {pos: [9, 3, 6], state: "minecraft:gravel"},
        {pos: [9, 3, 13], state: "minecraft:gravel"},
        {pos: [9, 3, 14], state: "minecraft:gravel"},
        {pos: [9, 3, 20], state: "minecraft:gravel"},
        {pos: [9, 3, 21], state: "minecraft:gravel"},
        {pos: [9, 3, 27], state: "minecraft:gravel"},
        {pos: [9, 3, 28], state: "minecraft:gravel"},
        {pos: [9, 3, 29], state: "minecraft:gravel"},
        {pos: [9, 3, 30], state: "minecraft:gravel"},
        {pos: [9, 3, 31], state: "minecraft:gravel"},
        {pos: [9, 3, 32], state: "minecraft:mud_bricks"},
        {pos: [10, 3, 1], state: "minecraft:mud_bricks"},
        {pos: [10, 3, 2], state: "minecraft:mud_bricks"},
        {pos: [10, 3, 3], state: "minecraft:mud_bricks"},
        {pos: [10, 3, 4], state: "minecraft:mud_bricks"},
        {pos: [10, 3, 5], state: "minecraft:gravel"},
        {pos: [10, 3, 13], state: "minecraft:gravel"},
        {pos: [10, 3, 14], state: "minecraft:gravel"},
        {pos: [10, 3, 20], state: "minecraft:gravel"},
        {pos: [10, 3, 21], state: "minecraft:gravel"},
        {pos: [10, 3, 27], state: "minecraft:mud_bricks"},
        {pos: [10, 3, 28], state: "minecraft:mud_bricks"},
        {pos: [10, 3, 29], state: "minecraft:mud_bricks"},
        {pos: [10, 3, 30], state: "minecraft:mud_bricks"},
        {pos: [10, 3, 31], state: "minecraft:mud_bricks"},
        {pos: [11, 3, 1], state: "minecraft:gravel"},
        {pos: [11, 3, 2], state: "minecraft:mud_bricks"},
        {pos: [11, 3, 3], state: "minecraft:mud_bricks"},
        {pos: [11, 3, 4], state: "minecraft:mud_bricks"},
        {pos: [11, 3, 5], state: "minecraft:gravel"},
        {pos: [11, 3, 11], state: "minecraft:gravel"},
        {pos: [11, 3, 12], state: "minecraft:gravel"},
        {pos: [11, 3, 13], state: "minecraft:gravel"},
        {pos: [11, 3, 14], state: "minecraft:gravel"},
        {pos: [11, 3, 15], state: "minecraft:gravel"},
        {pos: [11, 3, 16], state: "minecraft:gravel"},
        {pos: [11, 3, 20], state: "minecraft:gravel"},
        {pos: [11, 3, 21], state: "minecraft:gravel"},
        {pos: [12, 3, 1], state: "minecraft:gravel"},
        {pos: [12, 3, 2], state: "minecraft:mud_bricks"},
        {pos: [12, 3, 3], state: "minecraft:mud_bricks"},
        {pos: [12, 3, 4], state: "minecraft:mud_bricks"},
        {pos: [12, 3, 11], state: "minecraft:gravel"},
        {pos: [12, 3, 12], state: "minecraft:gravel"},
        {pos: [12, 3, 13], state: "minecraft:gravel"},
        {pos: [12, 3, 14], state: "minecraft:gravel"},
        {pos: [12, 3, 15], state: "minecraft:gravel"},
        {pos: [12, 3, 16], state: "minecraft:gravel"},
        {pos: [12, 3, 19], state: "minecraft:gravel"},
        {pos: [12, 3, 20], state: "minecraft:gravel"},
        {pos: [12, 3, 21], state: "minecraft:gravel"},
        {pos: [12, 3, 22], state: "minecraft:gravel"},
        {pos: [13, 3, 2], state: "minecraft:gravel"},
        {pos: [13, 3, 3], state: "minecraft:mud_bricks"},
        {pos: [13, 3, 4], state: "minecraft:mud_bricks"},
        {pos: [13, 3, 12], state: "minecraft:gravel"},
        {pos: [13, 3, 13], state: "minecraft:gravel"},
        {pos: [13, 3, 14], state: "minecraft:gravel"},
        {pos: [13, 3, 18], state: "minecraft:gravel"},
        {pos: [13, 3, 19], state: "minecraft:gravel"},
        {pos: [13, 3, 20], state: "minecraft:gravel"},
        {pos: [13, 3, 21], state: "minecraft:gravel"},
        {pos: [13, 3, 22], state: "minecraft:gravel"},
        {pos: [14, 3, 3], state: "minecraft:gravel"},
        {pos: [14, 3, 4], state: "minecraft:gravel"},
        {pos: [14, 3, 13], state: "minecraft:gravel"},
        {pos: [14, 3, 19], state: "minecraft:gravel"},
        {pos: [14, 3, 20], state: "minecraft:gravel"},
        {pos: [14, 3, 21], state: "minecraft:gravel"},
        {pos: [15, 3, 3], state: "minecraft:gravel"},
        {pos: [15, 3, 20], state: "minecraft:gravel"},
        {pos: [15, 3, 21], state: "minecraft:gravel"},
        {pos: [1, 4, 10], state: "minecraft:gravel"},
        {pos: [1, 4, 11], state: "minecraft:gravel"},
        {pos: [2, 4, 10], state: "minecraft:gravel"},
        {pos: [2, 4, 11], state: "minecraft:gravel"},
        {pos: [2, 4, 20], state: "minecraft:gravel"},
        {pos: [2, 4, 21], state: "minecraft:gravel"},
        {pos: [3, 4, 2], state: "minecraft:gravel"},
        {pos: [3, 4, 3], state: "minecraft:gravel"},
        {pos: [3, 4, 4], state: "minecraft:gravel"},
        {pos: [3, 4, 5], state: "minecraft:gravel"},
        {pos: [3, 4, 10], state: "minecraft:gravel"},
        {pos: [3, 4, 19], state: "minecraft:gravel"},
        {pos: [3, 4, 20], state: "minecraft:gravel"},
        {pos: [3, 4, 21], state: "minecraft:gravel"},
        {pos: [3, 4, 22], state: "minecraft:gravel"},
        {pos: [4, 4, 1], state: "minecraft:gravel"},
        {pos: [4, 4, 2], state: "minecraft:mud_bricks"},
        {pos: [4, 4, 3], state: "minecraft:mud_bricks"},
        {pos: [4, 4, 4], state: "minecraft:mud_bricks"},
        {pos: [4, 4, 5], state: "minecraft:mud_bricks"},
        {pos: [4, 4, 6], state: "minecraft:gravel"},
        {pos: [4, 4, 19], state: "minecraft:gravel"},
        {pos: [4, 4, 20], state: "minecraft:gravel"},
        {pos: [4, 4, 21], state: "minecraft:gravel"},
        {pos: [4, 4, 28], state: "minecraft:gravel"},
        {pos: [4, 4, 29], state: "minecraft:gravel"},
        {pos: [4, 4, 30], state: "minecraft:gravel"},
        {pos: [4, 4, 31], state: "minecraft:gravel"},
        {pos: [5, 4, 0], state: "minecraft:mud_bricks"},
        {pos: [5, 4, 1], state: "minecraft:mud_bricks"},
        {pos: [5, 4, 2], state: "minecraft:gravel"},
        {pos: [5, 4, 3], state: "minecraft:gravel"},
        {pos: [5, 4, 4], state: "minecraft:gravel"},
        {pos: [5, 4, 5], state: "minecraft:gravel"},
        {pos: [5, 4, 6], state: "minecraft:mud_bricks"},
        {pos: [5, 4, 7], state: "minecraft:gravel"},
        {pos: [5, 4, 16], state: "minecraft:gravel"},
        {pos: [5, 4, 17], state: "minecraft:gravel"},
        {pos: [5, 4, 20], state: "minecraft:gravel"},
        {pos: [5, 4, 26], state: "minecraft:gravel"},
        {pos: [5, 4, 27], state: "minecraft:mud_bricks"},
        {pos: [5, 4, 28], state: "minecraft:mud_bricks"},
        {pos: [5, 4, 29], state: "minecraft:mud_bricks"},
        {pos: [5, 4, 30], state: "minecraft:mud_bricks"},
        {pos: [5, 4, 31], state: "minecraft:mud_bricks"},
        {pos: [5, 4, 32], state: "minecraft:gravel"},
        {pos: [6, 4, 0], state: "minecraft:mud_bricks"},
        {pos: [6, 4, 1], state: "minecraft:gravel"},
        {pos: [6, 4, 2], state: "minecraft:gravel"},
        {pos: [6, 4, 3], state: "minecraft:gravel"},
        {pos: [6, 4, 4], state: "minecraft:gravel"},
        {pos: [6, 4, 5], state: "minecraft:mud_bricks"},
        {pos: [6, 4, 6], state: "minecraft:mud_bricks"},
        {pos: [6, 4, 7], state: "minecraft:gravel"},
        {pos: [6, 4, 8], state: "minecraft:gravel"},
        {pos: [6, 4, 9], state: "minecraft:gravel"},
        {pos: [6, 4, 10], state: "minecraft:gravel"},
        {pos: [6, 4, 11], state: "minecraft:gravel"},
        {pos: [6, 4, 14], state: "minecraft:gravel"},
        {pos: [6, 4, 15], state: "minecraft:gravel"},
        {pos: [6, 4, 16], state: "minecraft:gravel"},
        {pos: [6, 4, 17], state: "minecraft:gravel"},
        {pos: [6, 4, 18], state: "minecraft:gravel"},
        {pos: [6, 4, 25], state: "minecraft:gravel"},
        {pos: [6, 4, 26], state: "minecraft:gravel"},
        {pos: [6, 4, 27], state: "minecraft:mud_bricks"},
        {pos: [6, 4, 28], state: "minecraft:mud_bricks"},
        {pos: [6, 4, 29], state: "minecraft:gravel"},
        {pos: [6, 4, 30], state: "minecraft:mud_bricks"},
        {pos: [6, 4, 31], state: "minecraft:mud_bricks"},
        {pos: [6, 4, 32], state: "minecraft:gravel"},
        {pos: [7, 4, 0], state: "minecraft:mud_bricks"},
        {pos: [7, 4, 1], state: "minecraft:mud_bricks"},
        {pos: [7, 4, 2], state: "minecraft:gravel"},
        {pos: [7, 4, 3], state: "minecraft:gravel"},
        {pos: [7, 4, 4], state: "minecraft:gravel"},
        {pos: [7, 4, 5], state: "minecraft:mud_bricks"},
        {pos: [7, 4, 6], state: "minecraft:mud_bricks"},
        {pos: [7, 4, 7], state: "minecraft:gravel"},
        {pos: [7, 4, 8], state: "minecraft:gravel"},
        {pos: [7, 4, 9], state: "minecraft:gravel"},
        {pos: [7, 4, 10], state: "minecraft:gravel"},
        {pos: [7, 4, 15], state: "minecraft:gravel"},
        {pos: [7, 4, 16], state: "minecraft:gravel"},
        {pos: [7, 4, 17], state: "minecraft:gravel"},
        {pos: [7, 4, 24], state: "minecraft:gravel"},
        {pos: [7, 4, 25], state: "minecraft:gravel"},
        {pos: [7, 4, 26], state: "minecraft:gravel"},
        {pos: [7, 4, 27], state: "minecraft:mud_bricks"},
        {pos: [7, 4, 28], state: "minecraft:mud_bricks"},
        {pos: [7, 4, 29], state: "minecraft:gravel"},
        {pos: [7, 4, 30], state: "minecraft:gravel"},
        {pos: [7, 4, 31], state: "minecraft:mud_bricks"},
        {pos: [7, 4, 32], state: "minecraft:gravel"},
        {pos: [8, 4, 0], state: "minecraft:mud_bricks"},
        {pos: [8, 4, 1], state: "minecraft:mud_bricks"},
        {pos: [8, 4, 2], state: "minecraft:mud_bricks"},
        {pos: [8, 4, 3], state: "minecraft:gravel"},
        {pos: [8, 4, 4], state: "minecraft:gravel"},
        {pos: [8, 4, 5], state: "minecraft:mud_bricks"},
        {pos: [8, 4, 6], state: "minecraft:gravel"},
        {pos: [8, 4, 26], state: "minecraft:gravel"},
        {pos: [8, 4, 27], state: "minecraft:mud_bricks"},
        {pos: [8, 4, 28], state: "minecraft:mud_bricks"},
        {pos: [8, 4, 29], state: "minecraft:gravel"},
        {pos: [8, 4, 30], state: "minecraft:mud_bricks"},
        {pos: [8, 4, 31], state: "minecraft:mud_bricks"},
        {pos: [8, 4, 32], state: "minecraft:gravel"},
        {pos: [9, 4, 0], state: "minecraft:mud_bricks"},
        {pos: [9, 4, 1], state: "minecraft:mud_bricks"},
        {pos: [9, 4, 2], state: "minecraft:mud_bricks"},
        {pos: [9, 4, 3], state: "minecraft:gravel"},
        {pos: [9, 4, 4], state: "minecraft:mud_bricks"},
        {pos: [9, 4, 5], state: "minecraft:gravel"},
        {pos: [9, 4, 6], state: "minecraft:gravel"},
        {pos: [9, 4, 13], state: "minecraft:gravel"},
        {pos: [9, 4, 20], state: "minecraft:gravel"},
        {pos: [9, 4, 27], state: "minecraft:mud_bricks"},
        {pos: [9, 4, 28], state: "minecraft:gravel"},
        {pos: [9, 4, 29], state: "minecraft:gravel"},
        {pos: [9, 4, 30], state: "minecraft:mud_bricks"},
        {pos: [9, 4, 31], state: "minecraft:mud_bricks"},
        {pos: [10, 4, 1], state: "minecraft:mud_bricks"},
        {pos: [10, 4, 2], state: "minecraft:mud_bricks"},
        {pos: [10, 4, 3], state: "minecraft:mud_bricks"},
        {pos: [10, 4, 4], state: "minecraft:mud_bricks"},
        {pos: [10, 4, 5], state: "minecraft:gravel"},
        {pos: [10, 4, 13], state: "minecraft:gravel"},
        {pos: [10, 4, 14], state: "minecraft:gravel"},
        {pos: [10, 4, 20], state: "minecraft:gravel"},
        {pos: [10, 4, 21], state: "minecraft:gravel"},
        {pos: [10, 4, 27], state: "minecraft:gravel"},
        {pos: [10, 4, 28], state: "minecraft:gravel"},
        {pos: [10, 4, 29], state: "minecraft:gravel"},
        {pos: [10, 4, 30], state: "minecraft:gravel"},
        {pos: [10, 4, 31], state: "minecraft:gravel"},
        {pos: [11, 4, 1], state: "minecraft:gravel"},
        {pos: [11, 4, 2], state: "minecraft:gravel"},
        {pos: [11, 4, 3], state: "minecraft:gravel"},
        {pos: [11, 4, 4], state: "minecraft:gravel"},
        {pos: [11, 4, 12], state: "minecraft:gravel"},
        {pos: [11, 4, 13], state: "minecraft:gravel"},
        {pos: [11, 4, 14], state: "minecraft:gravel"},
        {pos: [11, 4, 20], state: "minecraft:gravel"},
        {pos: [11, 4, 21], state: "minecraft:gravel"},
        {pos: [12, 4, 1], state: "minecraft:gravel"},
        {pos: [12, 4, 2], state: "minecraft:gravel"},
        {pos: [12, 4, 3], state: "minecraft:gravel"},
        {pos: [12, 4, 4], state: "minecraft:gravel"},
        {pos: [12, 4, 12], state: "minecraft:gravel"},
        {pos: [12, 4, 13], state: "minecraft:gravel"},
        {pos: [12, 4, 14], state: "minecraft:gravel"},
        {pos: [12, 4, 20], state: "minecraft:gravel"},
        {pos: [12, 4, 21], state: "minecraft:gravel"},
        {pos: [13, 4, 3], state: "minecraft:gravel"},
        {pos: [13, 4, 4], state: "minecraft:gravel"},
        {pos: [13, 4, 13], state: "minecraft:gravel"},
        {pos: [13, 4, 20], state: "minecraft:gravel"},
        {pos: [13, 4, 21], state: "minecraft:gravel"},
        {pos: [14, 4, 3], state: "minecraft:gravel"},
        {pos: [14, 4, 20], state: "minecraft:gravel"},
        {pos: [3, 5, 3], state: "minecraft:gravel"},
        {pos: [3, 5, 4], state: "minecraft:gravel"},
        {pos: [3, 5, 5], state: "minecraft:gravel"},
        {pos: [4, 5, 1], state: "minecraft:gravel"},
        {pos: [4, 5, 2], state: "minecraft:gravel"},
        {pos: [4, 5, 3], state: "minecraft:gravel"},
        {pos: [4, 5, 4], state: "minecraft:gravel"},
        {pos: [4, 5, 5], state: "minecraft:gravel"},
        {pos: [4, 5, 6], state: "minecraft:gravel"},
        {pos: [5, 5, 0], state: "minecraft:gravel"},
        {pos: [5, 5, 1], state: "minecraft:mud_bricks"},
        {pos: [5, 5, 2], state: "minecraft:mud_bricks"},
        {pos: [5, 5, 3], state: "minecraft:mud_bricks"},
        {pos: [5, 5, 4], state: "minecraft:mud_bricks"},
        {pos: [5, 5, 5], state: "minecraft:gravel"},
        {pos: [5, 5, 6], state: "minecraft:gravel"},
        {pos: [5, 5, 27], state: "minecraft:gravel"},
        {pos: [5, 5, 28], state: "minecraft:gravel"},
        {pos: [5, 5, 29], state: "minecraft:gravel"},
        {pos: [5, 5, 30], state: "minecraft:gravel"},
        {pos: [6, 5, 0], state: "minecraft:mud_bricks"},
        {pos: [6, 5, 1], state: "minecraft:gravel"},
        {pos: [6, 5, 2], state: "minecraft:gravel"},
        {pos: [6, 5, 3], state: "minecraft:gravel"},
        {pos: [6, 5, 4], state: "minecraft:mud_bricks"},
        {pos: [6, 5, 5], state: "minecraft:gravel"},
        {pos: [6, 5, 6], state: "minecraft:gravel"},
        {pos: [6, 5, 7], state: "minecraft:gravel"},
        {pos: [6, 5, 26], state: "minecraft:gravel"},
        {pos: [6, 5, 27], state: "minecraft:gravel"},
        {pos: [6, 5, 28], state: "minecraft:mud_bricks"},
        {pos: [6, 5, 29], state: "minecraft:gravel"},
        {pos: [6, 5, 30], state: "minecraft:mud_bricks"},
        {pos: [6, 5, 31], state: "minecraft:gravel"},
        {pos: [7, 5, 0], state: "minecraft:mud_bricks"},
        {pos: [7, 5, 1], state: "minecraft:gravel"},
        {pos: [7, 5, 2], state: "minecraft:gravel"},
        {pos: [7, 5, 3], state: "minecraft:gravel"},
        {pos: [7, 5, 4], state: "minecraft:mud_bricks"},
        {pos: [7, 5, 5], state: "minecraft:gravel"},
        {pos: [7, 5, 6], state: "minecraft:gravel"},
        {pos: [7, 5, 27], state: "minecraft:gravel"},
        {pos: [7, 5, 28], state: "minecraft:mud_bricks"},
        {pos: [7, 5, 29], state: "minecraft:gravel"},
        {pos: [7, 5, 30], state: "minecraft:gravel"},
        {pos: [7, 5, 31], state: "minecraft:gravel"},
        {pos: [8, 5, 0], state: "minecraft:mud_bricks"},
        {pos: [8, 5, 1], state: "minecraft:gravel"},
        {pos: [8, 5, 2], state: "minecraft:gravel"},
        {pos: [8, 5, 3], state: "minecraft:gravel"},
        {pos: [8, 5, 4], state: "minecraft:mud_bricks"},
        {pos: [8, 5, 5], state: "minecraft:gravel"},
        {pos: [8, 5, 6], state: "minecraft:gravel"},
        {pos: [8, 5, 27], state: "minecraft:gravel"},
        {pos: [8, 5, 28], state: "minecraft:gravel"},
        {pos: [8, 5, 29], state: "minecraft:gravel"},
        {pos: [8, 5, 30], state: "minecraft:mud_bricks"},
        {pos: [8, 5, 31], state: "minecraft:gravel"},
        {pos: [9, 5, 0], state: "minecraft:mud_bricks"},
        {pos: [9, 5, 1], state: "minecraft:gravel"},
        {pos: [9, 5, 2], state: "minecraft:gravel"},
        {pos: [9, 5, 3], state: "minecraft:gravel"},
        {pos: [9, 5, 4], state: "minecraft:mud_bricks"},
        {pos: [9, 5, 5], state: "minecraft:gravel"},
        {pos: [9, 5, 27], state: "minecraft:gravel"},
        {pos: [9, 5, 28], state: "minecraft:gravel"},
        {pos: [9, 5, 29], state: "minecraft:mud_bricks"},
        {pos: [9, 5, 30], state: "minecraft:mud_bricks"},
        {pos: [10, 5, 1], state: "minecraft:mud_bricks"},
        {pos: [10, 5, 2], state: "minecraft:mud_bricks"},
        {pos: [10, 5, 3], state: "minecraft:mud_bricks"},
        {pos: [10, 5, 4], state: "minecraft:mud_bricks"},
        {pos: [10, 5, 5], state: "minecraft:gravel"},
        {pos: [10, 5, 29], state: "minecraft:gravel"},
        {pos: [10, 5, 30], state: "minecraft:gravel"},
        {pos: [11, 5, 1], state: "minecraft:gravel"},
        {pos: [11, 5, 2], state: "minecraft:gravel"},
        {pos: [11, 5, 3], state: "minecraft:gravel"},
        {pos: [11, 5, 4], state: "minecraft:gravel"},
        {pos: [12, 5, 3], state: "minecraft:gravel"},
        {pos: [4, 6, 1], state: "minecraft:gravel"},
        {pos: [4, 6, 2], state: "minecraft:gravel"},
        {pos: [4, 6, 3], state: "minecraft:gravel"},
        {pos: [4, 6, 4], state: "minecraft:gravel"},
        {pos: [4, 6, 5], state: "minecraft:gravel"},
        {pos: [5, 6, 0], state: "minecraft:gravel"},
        {pos: [5, 6, 1], state: "minecraft:mud_bricks"},
        {pos: [5, 6, 2], state: "minecraft:mud_bricks"},
        {pos: [5, 6, 3], state: "minecraft:mud_bricks"},
        {pos: [5, 6, 4], state: "minecraft:mud_bricks"},
        {pos: [5, 6, 5], state: "minecraft:gravel"},
        {pos: [6, 6, 0], state: "minecraft:mud_bricks"},
        {pos: [6, 6, 1], state: "minecraft:gravel"},
        {pos: [6, 6, 2], state: "minecraft:gravel"},
        {pos: [6, 6, 3], state: "minecraft:gravel"},
        {pos: [6, 6, 4], state: "minecraft:mud_bricks"},
        {pos: [6, 6, 5], state: "minecraft:gravel"},
        {pos: [6, 6, 6], state: "minecraft:gravel"},
        {pos: [7, 6, 0], state: "minecraft:mud_bricks"},
        {pos: [7, 6, 1], state: "minecraft:gravel"},
        {pos: [7, 6, 2], state: "minecraft:gravel"},
        {pos: [7, 6, 3], state: "minecraft:gravel"},
        {pos: [7, 6, 4], state: "minecraft:mud_bricks"},
        {pos: [7, 6, 5], state: "minecraft:gravel"},
        {pos: [8, 6, 0], state: "minecraft:mud_bricks"},
        {pos: [8, 6, 1], state: "minecraft:gravel"},
        {pos: [8, 6, 2], state: "minecraft:gravel"},
        {pos: [8, 6, 3], state: "minecraft:gravel"},
        {pos: [8, 6, 4], state: "minecraft:mud_bricks"},
        {pos: [8, 6, 5], state: "minecraft:gravel"},
        {pos: [9, 6, 0], state: "minecraft:mud_bricks"},
        {pos: [9, 6, 1], state: "minecraft:gravel"},
        {pos: [9, 6, 2], state: "minecraft:gravel"},
        {pos: [9, 6, 3], state: "minecraft:gravel"},
        {pos: [9, 6, 4], state: "minecraft:mud_bricks"},
        {pos: [9, 6, 5], state: "minecraft:gravel"},
        {pos: [10, 6, 1], state: "minecraft:mud_bricks"},
        {pos: [10, 6, 2], state: "minecraft:mud_bricks"},
        {pos: [10, 6, 3], state: "minecraft:mud_bricks"},
        {pos: [10, 6, 4], state: "minecraft:mud_bricks"},
        {pos: [10, 6, 5], state: "minecraft:gravel"},
        {pos: [11, 6, 2], state: "minecraft:gravel"},
        {pos: [11, 6, 3], state: "minecraft:gravel"},
        {pos: [11, 6, 4], state: "minecraft:gravel"},
        {pos: [5, 7, 0], state: "minecraft:gravel"},
        {pos: [5, 7, 1], state: "minecraft:mud_bricks"},
        {pos: [5, 7, 2], state: "minecraft:mud_bricks"},
        {pos: [5, 7, 3], state: "minecraft:gravel"},
        {pos: [5, 7, 4], state: "minecraft:gravel"},
        {pos: [6, 7, 0], state: "minecraft:mud_bricks"},
        {pos: [6, 7, 1], state: "minecraft:gravel"},
        {pos: [6, 7, 2], state: "minecraft:gravel"},
        {pos: [6, 7, 3], state: "minecraft:gravel"},
        {pos: [6, 7, 4], state: "minecraft:mud_bricks"},
        {pos: [6, 7, 5], state: "minecraft:gravel"},
        {pos: [7, 7, 0], state: "minecraft:gravel"},
        {pos: [7, 7, 1], state: "minecraft:gravel"},
        {pos: [7, 7, 2], state: "minecraft:gravel"},
        {pos: [7, 7, 3], state: "minecraft:gravel"},
        {pos: [7, 7, 4], state: "minecraft:mud_bricks"},
        {pos: [7, 7, 5], state: "minecraft:gravel"},
        {pos: [8, 7, 0], state: "minecraft:mud_bricks"},
        {pos: [8, 7, 1], state: "minecraft:gravel"},
        {pos: [8, 7, 2], state: "minecraft:gravel"},
        {pos: [8, 7, 3], state: "minecraft:gravel"},
        {pos: [8, 7, 4], state: "minecraft:mud_bricks"},
        {pos: [8, 7, 5], state: "minecraft:gravel"},
        {pos: [9, 7, 0], state: "minecraft:mud_bricks"},
        {pos: [9, 7, 1], state: "minecraft:gravel"},
        {pos: [9, 7, 2], state: "minecraft:gravel"},
        {pos: [9, 7, 3], state: "minecraft:gravel"},
        {pos: [9, 7, 4], state: "minecraft:mud_bricks"},
        {pos: [9, 7, 5], state: "minecraft:gravel"},
        {pos: [10, 7, 1], state: "minecraft:mud_bricks"},
        {pos: [10, 7, 2], state: "minecraft:mud_bricks"},
        {pos: [10, 7, 3], state: "minecraft:mud_bricks"},
        {pos: [10, 7, 4], state: "minecraft:gravel"},
        {pos: [5, 8, 1], state: "minecraft:mud_bricks"},
        {pos: [5, 8, 2], state: "minecraft:mud_bricks"},
        {pos: [5, 8, 3], state: "minecraft:mud_bricks"},
        {pos: [5, 8, 4], state: "minecraft:gravel"},
        {pos: [6, 8, 0], state: "minecraft:gravel"},
        {pos: [6, 8, 1], state: "minecraft:gravel"},
        {pos: [6, 8, 2], state: "minecraft:gravel"},
        {pos: [6, 8, 3], state: "minecraft:gravel"},
        {pos: [6, 8, 4], state: "minecraft:mud_bricks"},
        {pos: [7, 8, 0], state: "minecraft:mud_bricks"},
        {pos: [7, 8, 1], state: "minecraft:gravel"},
        {pos: [7, 8, 2], state: "minecraft:gravel"},
        {pos: [7, 8, 3], state: "minecraft:gravel"},
        {pos: [7, 8, 4], state: "minecraft:mud_bricks"},
        {pos: [7, 8, 5], state: "minecraft:gravel"},
        {pos: [8, 8, 0], state: "minecraft:mud_bricks"},
        {pos: [8, 8, 1], state: "minecraft:gravel"},
        {pos: [8, 8, 2], state: "minecraft:gravel"},
        {pos: [8, 8, 3], state: "minecraft:gravel"},
        {pos: [8, 8, 4], state: "minecraft:mud_bricks"},
        {pos: [8, 8, 5], state: "minecraft:gravel"},
        {pos: [9, 8, 0], state: "minecraft:mud_bricks"},
        {pos: [9, 8, 1], state: "minecraft:gravel"},
        {pos: [9, 8, 2], state: "minecraft:gravel"},
        {pos: [9, 8, 3], state: "minecraft:gravel"},
        {pos: [9, 8, 4], state: "minecraft:mud_bricks"},
        {pos: [9, 8, 5], state: "minecraft:gravel"},
        {pos: [10, 8, 1], state: "minecraft:mud_bricks"},
        {pos: [10, 8, 2], state: "minecraft:mud_bricks"},
        {pos: [10, 8, 3], state: "minecraft:mud_bricks"},
        {pos: [10, 8, 4], state: "minecraft:gravel"},
        {pos: [5, 9, 1], state: "minecraft:mud_bricks"},
        {pos: [5, 9, 2], state: "minecraft:mud_bricks"},
        {pos: [5, 9, 3], state: "minecraft:mud_bricks"},
        {pos: [5, 9, 4], state: "minecraft:gravel"},
        {pos: [6, 9, 0], state: "minecraft:gravel"},
        {pos: [6, 9, 1], state: "minecraft:gravel"},
        {pos: [6, 9, 2], state: "minecraft:gravel"},
        {pos: [6, 9, 3], state: "minecraft:gravel"},
        {pos: [6, 9, 4], state: "minecraft:mud_bricks"},
        {pos: [7, 9, 0], state: "minecraft:mud_bricks"},
        {pos: [7, 9, 1], state: "minecraft:gravel"},
        {pos: [7, 9, 2], state: "minecraft:gravel"},
        {pos: [7, 9, 3], state: "minecraft:gravel"},
        {pos: [7, 9, 4], state: "minecraft:mud_bricks"},
        {pos: [8, 9, 0], state: "minecraft:mud_bricks"},
        {pos: [8, 9, 1], state: "minecraft:gravel"},
        {pos: [8, 9, 2], state: "minecraft:gravel"},
        {pos: [8, 9, 3], state: "minecraft:gravel"},
        {pos: [8, 9, 4], state: "minecraft:mud_bricks"},
        {pos: [9, 9, 0], state: "minecraft:mud_bricks"},
        {pos: [9, 9, 1], state: "minecraft:gravel"},
        {pos: [9, 9, 2], state: "minecraft:gravel"},
        {pos: [9, 9, 3], state: "minecraft:gravel"},
        {pos: [9, 9, 4], state: "minecraft:mud_bricks"},
        {pos: [10, 9, 1], state: "minecraft:mud_bricks"},
        {pos: [10, 9, 2], state: "minecraft:mud_bricks"},
        {pos: [10, 9, 3], state: "minecraft:mud_bricks"},
        {pos: [10, 9, 4], state: "minecraft:mud_bricks"},
        {pos: [5, 10, 1], state: "minecraft:mud_bricks"},
        {pos: [5, 10, 2], state: "minecraft:mud_bricks"},
        {pos: [6, 10, 3], state: "minecraft:gravel"},
        {pos: [7, 10, 4], state: "minecraft:mud_bricks"},
        {pos: [8, 10, 0], state: "minecraft:mud_bricks"},
        {pos: [8, 10, 1], state: "minecraft:gravel"},
        {pos: [8, 10, 4], state: "minecraft:mud_bricks"},
        {pos: [9, 10, 0], state: "minecraft:mud_bricks"},
        {pos: [9, 10, 1], state: "minecraft:gravel"},
        {pos: [9, 10, 2], state: "minecraft:gravel"},
        {pos: [9, 10, 4], state: "minecraft:mud_bricks"},
        {pos: [10, 10, 1], state: "minecraft:mud_bricks"},
        {pos: [10, 10, 2], state: "minecraft:mud_bricks"},
        {pos: [10, 10, 3], state: "minecraft:mud_bricks"},
        {pos: [5, 11, 2], state: "minecraft:mud_bricks"},
        {pos: [7, 11, 4], state: "minecraft:mud_bricks"},
        {pos: [8, 11, 4], state: "minecraft:mud_bricks"},
        {pos: [9, 11, 0], state: "minecraft:mud_bricks"},
        {pos: [10, 11, 1], state: "minecraft:mud_bricks"},
        {pos: [10, 11, 2], state: "minecraft:mud_bricks"},
        {pos: [9, 12, 0], state: "minecraft:mud_bricks"}
    ],
    entities: [],
    palette: [
        "minecraft:mud_bricks",
        "minecraft:yellow_glazed_terracotta{facing:west}",
        "minecraft:yellow_glazed_terracotta{facing:south}",
        "minecraft:yellow_glazed_terracotta{facing:north}",
        "minecraft:yellow_glazed_terracotta{facing:east}",
        "minecraft:gravel",
        "minecraft:clay",
        "minecraft:orange_glazed_terracotta{facing:east}",
        "minecraft:orange_glazed_terracotta{facing:south}",
        "minecraft:orange_glazed_terracotta{facing:west}",
        "minecraft:mud_brick_stairs{facing:east,half:top,shape:straight,waterlogged:false}",
        "minecraft:mud_brick_stairs{facing:west,half:top,shape:straight,waterlogged:false}",
        "minecraft:mud_brick_stairs{facing:south,half:top,shape:straight,waterlogged:false}",
        "minecraft:mud_brick_stairs{facing:north,half:top,shape:straight,waterlogged:false}",
        "minecraft:mud_brick_wall{east:tall,north:tall,south:none,up:true,waterlogged:false,west:tall}",
        "minecraft:campfire{facing:south,lit:false,signal_fire:false,waterlogged:false}",
        "minecraft:barrel{facing:north,open:false}",
        "minecraft:smoker{facing:west,lit:false}",
        "trailiertales:suspicious_clay{can_place_item:true,dusted:0}"
    ],
    trailiertales_DataVersion: 2
}
