{
    DataVersion: 3953,
    size: [15, 9, 16],
    data: [
        {pos: [0, 0, 8], state: "minecraft:red_sandstone"},
        {pos: [0, 0, 9], state: "minecraft:red_sandstone"},
        {pos: [0, 0, 10], state: "minecraft:red_sandstone"},
        {pos: [1, 0, 0], state: "minecraft:red_sandstone"},
        {pos: [1, 0, 1], state: "minecraft:red_sandstone"},
        {pos: [1, 0, 2], state: "minecraft:red_sandstone"},
        {pos: [1, 0, 3], state: "minecraft:red_sandstone"},
        {pos: [1, 0, 8], state: "minecraft:red_sandstone"},
        {pos: [1, 0, 9], state: "minecraft:red_sandstone"},
        {pos: [1, 0, 10], state: "minecraft:red_sandstone"},
        {pos: [1, 0, 11], state: "minecraft:red_sandstone"},
        {pos: [2, 0, 0], state: "minecraft:red_sandstone"},
        {pos: [2, 0, 1], state: "minecraft:red_sandstone"},
        {pos: [2, 0, 2], state: "minecraft:red_sandstone"},
        {pos: [2, 0, 3], state: "minecraft:red_sandstone"},
        {pos: [2, 0, 6], state: "minecraft:red_sandstone"},
        {pos: [2, 0, 7], state: "minecraft:red_sandstone"},
        {pos: [2, 0, 8], state: "minecraft:red_sandstone"},
        {pos: [2, 0, 9], state: "minecraft:red_sandstone"},
        {pos: [2, 0, 10], state: "minecraft:red_sandstone"},
        {pos: [2, 0, 11], state: "minecraft:red_sandstone"},
        {pos: [3, 0, 1], state: "minecraft:red_sandstone"},
        {pos: [3, 0, 2], state: "minecraft:red_sandstone"},
        {pos: [3, 0, 3], state: "minecraft:red_sandstone"},
        {pos: [3, 0, 5], state: "minecraft:red_sandstone"},
        {pos: [3, 0, 6], state: "minecraft:red_sandstone"},
        {pos: [3, 0, 7], state: "minecraft:red_sandstone"},
        {pos: [3, 0, 8], state: "minecraft:red_sandstone"},
        {pos: [3, 0, 9], state: "minecraft:red_sandstone"},
        {pos: [3, 0, 10], state: "minecraft:red_sandstone"},
        {pos: [3, 0, 11], state: "minecraft:red_sandstone"},
        {pos: [3, 0, 12], state: "minecraft:red_sandstone"},
        {pos: [4, 0, 3], state: "minecraft:red_sandstone"},
        {pos: [4, 0, 4], state: "minecraft:red_sandstone"},
        {pos: [4, 0, 5], state: "minecraft:red_sandstone"},
        {pos: [4, 0, 6], state: "minecraft:red_sandstone"},
        {pos: [4, 0, 7], state: "minecraft:red_sandstone"},
        {pos: [4, 0, 8], state: "minecraft:red_sandstone"},
        {pos: [4, 0, 9], state: "minecraft:red_sandstone"},
        {pos: [4, 0, 10], state: "minecraft:red_sandstone"},
        {pos: [4, 0, 11], state: "minecraft:red_sandstone"},
        {pos: [4, 0, 12], state: "minecraft:red_sandstone"},
        {pos: [4, 0, 13], state: "minecraft:red_sandstone"},
        {pos: [5, 0, 3], state: "minecraft:red_sandstone"},
        {pos: [5, 0, 4], state: "minecraft:red_sandstone"},
        {pos: [5, 0, 5], state: "minecraft:red_sandstone"},
        {pos: [5, 0, 6], state: "minecraft:red_sandstone"},
        {pos: [5, 0, 7], state: "minecraft:red_sandstone"},
        {pos: [5, 0, 8], state: "minecraft:red_sandstone"},
        {pos: [5, 0, 9], state: "minecraft:red_sandstone"},
        {pos: [5, 0, 10], state: "minecraft:red_sandstone"},
        {pos: [5, 0, 11], state: "minecraft:red_sandstone"},
        {pos: [5, 0, 12], state: "minecraft:red_sandstone"},
        {pos: [5, 0, 13], state: "minecraft:red_sandstone"},
        {pos: [6, 0, 4], state: "minecraft:red_sandstone"},
        {pos: [6, 0, 5], state: "minecraft:red_sandstone"},
        {pos: [6, 0, 6], state: "minecraft:red_sandstone"},
        {pos: [6, 0, 7], state: "minecraft:red_sandstone"},
        {pos: [6, 0, 8], state: "minecraft:red_sandstone"},
        {pos: [6, 0, 9], state: "minecraft:red_sandstone"},
        {pos: [6, 0, 10], state: "minecraft:red_sandstone"},
        {pos: [6, 0, 11], state: "minecraft:red_sandstone"},
        {pos: [6, 0, 12], state: "minecraft:red_sandstone"},
        {pos: [6, 0, 13], state: "minecraft:red_sandstone"},
        {pos: [6, 0, 14], state: "minecraft:red_sandstone"},
        {pos: [7, 0, 4], state: "minecraft:red_sandstone"},
        {pos: [7, 0, 5], state: "minecraft:red_sandstone"},
        {pos: [7, 0, 6], state: "minecraft:red_sandstone"},
        {pos: [7, 0, 7], state: "minecraft:red_sandstone"},
        {pos: [7, 0, 8], state: "minecraft:red_sandstone"},
        {pos: [7, 0, 9], state: "minecraft:red_sandstone"},
        {pos: [7, 0, 10], state: "minecraft:red_sandstone"},
        {pos: [7, 0, 11], state: "minecraft:red_sandstone"},
        {pos: [7, 0, 12], state: "minecraft:red_sandstone"},
        {pos: [7, 0, 13], state: "minecraft:red_sandstone"},
        {pos: [7, 0, 14], state: "minecraft:red_sandstone"},
        {pos: [8, 0, 3], state: "minecraft:red_sandstone"},
        {pos: [8, 0, 4], state: "minecraft:red_sandstone"},
        {pos: [8, 0, 5], state: "minecraft:red_sandstone"},
        {pos: [8, 0, 6], state: "minecraft:red_sandstone"},
        {pos: [8, 0, 7], state: "minecraft:red_sandstone"},
        {pos: [8, 0, 8], state: "minecraft:red_sandstone"},
        {pos: [8, 0, 9], state: "minecraft:red_sandstone"},
        {pos: [8, 0, 10], state: "minecraft:red_sandstone"},
        {pos: [8, 0, 11], state: "minecraft:red_sandstone"},
        {pos: [8, 0, 12], state: "minecraft:red_sandstone"},
        {pos: [8, 0, 13], state: "minecraft:red_sandstone"},
        {pos: [9, 0, 3], state: "minecraft:red_sandstone"},
        {pos: [9, 0, 4], state: "minecraft:red_sandstone"},
        {pos: [9, 0, 5], state: "minecraft:red_sandstone"},
        {pos: [9, 0, 6], state: "minecraft:red_sandstone"},
        {pos: [9, 0, 7], state: "minecraft:red_sandstone"},
        {pos: [9, 0, 8], state: "minecraft:red_sandstone"},
        {pos: [9, 0, 9], state: "minecraft:red_sandstone"},
        {pos: [9, 0, 10], state: "minecraft:red_sandstone"},
        {pos: [9, 0, 11], state: "minecraft:red_sandstone"},
        {pos: [9, 0, 12], state: "minecraft:red_sandstone"},
        {pos: [9, 0, 13], state: "minecraft:red_sandstone"},
        {pos: [9, 0, 14], state: "minecraft:red_sandstone"},
        {pos: [10, 0, 3], state: "minecraft:red_sandstone"},
        {pos: [10, 0, 4], state: "minecraft:red_sandstone"},
        {pos: [10, 0, 5], state: "minecraft:red_sandstone"},
        {pos: [10, 0, 6], state: "minecraft:red_sandstone"},
        {pos: [10, 0, 7], state: "minecraft:red_sandstone"},
        {pos: [10, 0, 8], state: "minecraft:red_sandstone"},
        {pos: [10, 0, 9], state: "minecraft:red_sandstone"},
        {pos: [10, 0, 10], state: "minecraft:red_sandstone"},
        {pos: [10, 0, 11], state: "minecraft:red_sandstone"},
        {pos: [10, 0, 12], state: "minecraft:red_sandstone"},
        {pos: [10, 0, 13], state: "minecraft:red_sandstone"},
        {pos: [10, 0, 14], state: "minecraft:red_sandstone"},
        {pos: [10, 0, 15], state: "minecraft:red_sandstone"},
        {pos: [11, 0, 2], state: "minecraft:red_sandstone"},
        {pos: [11, 0, 3], state: "minecraft:red_sandstone"},
        {pos: [11, 0, 4], state: "minecraft:red_sandstone"},
        {pos: [11, 0, 5], state: "minecraft:red_sandstone"},
        {pos: [11, 0, 6], state: "minecraft:red_sandstone"},
        {pos: [11, 0, 7], state: "minecraft:red_sandstone"},
        {pos: [11, 0, 8], state: "minecraft:red_sandstone"},
        {pos: [11, 0, 9], state: "minecraft:red_sandstone"},
        {pos: [11, 0, 10], state: "minecraft:red_sandstone"},
        {pos: [11, 0, 11], state: "minecraft:red_sandstone"},
        {pos: [11, 0, 12], state: "minecraft:red_sandstone"},
        {pos: [11, 0, 13], state: "minecraft:red_sandstone"},
        {pos: [11, 0, 14], state: "minecraft:red_sandstone"},
        {pos: [11, 0, 15], state: "minecraft:red_sandstone"},
        {pos: [12, 0, 1], state: "minecraft:red_sandstone"},
        {pos: [12, 0, 2], state: "minecraft:red_sandstone"},
        {pos: [12, 0, 3], state: "minecraft:red_sandstone"},
        {pos: [12, 0, 4], state: "minecraft:red_sandstone"},
        {pos: [12, 0, 7], state: "minecraft:red_sandstone"},
        {pos: [12, 0, 8], state: "minecraft:red_sandstone"},
        {pos: [12, 0, 9], state: "minecraft:red_sandstone"},
        {pos: [12, 0, 10], state: "minecraft:red_sandstone"},
        {pos: [12, 0, 11], state: "minecraft:red_sandstone"},
        {pos: [12, 0, 12], state: "minecraft:red_sandstone"},
        {pos: [12, 0, 13], state: "minecraft:red_sandstone"},
        {pos: [12, 0, 14], state: "minecraft:red_sandstone"},
        {pos: [13, 0, 1], state: "minecraft:red_sandstone"},
        {pos: [13, 0, 2], state: "minecraft:red_sandstone"},
        {pos: [13, 0, 3], state: "minecraft:red_sandstone"},
        {pos: [14, 0, 1], state: "minecraft:red_sandstone"},
        {pos: [14, 0, 2], state: "minecraft:red_sandstone"},
        {pos: [1, 1, 1], state: "minecraft:red_sand"},
        {pos: [1, 1, 2], state: "minecraft:red_sand"},
        {pos: [1, 1, 9], state: "minecraft:smooth_red_sandstone"},
        {pos: [1, 1, 10], state: "minecraft:red_sand"},
        {pos: [1, 1, 11], state: "minecraft:red_sand"},
        {pos: [2, 1, 1], state: "minecraft:smooth_red_sandstone"},
        {pos: [2, 1, 2], state: "minecraft:red_sand"},
        {pos: [2, 1, 6], state: "minecraft:red_sand"},
        {pos: [2, 1, 7], state: "minecraft:red_sand"},
        {pos: [2, 1, 9], state: "minecraft:red_sand"},
        {pos: [2, 1, 10], state: "minecraft:red_sand"},
        {pos: [2, 1, 11], state: "minecraft:red_sand"},
        {pos: [3, 1, 1], state: "minecraft:red_sand"},
        {pos: [3, 1, 2], state: "minecraft:red_sand"},
        {pos: [3, 1, 5], state: "minecraft:red_sand"},
        {pos: [3, 1, 6], state: "minecraft:red_sandstone"},
        {pos: [3, 1, 7], state: "minecraft:cut_red_sandstone"},
        {pos: [3, 1, 8], state: "minecraft:chiseled_red_sandstone"},
        {pos: [3, 1, 9], state: "minecraft:cut_red_sandstone"},
        {pos: [3, 1, 10], state: "minecraft:cut_red_sandstone"},
        {pos: [3, 1, 11], state: "minecraft:red_sand"},
        {pos: [3, 1, 12], state: "minecraft:red_sand"},
        {pos: [4, 1, 4], state: "minecraft:red_sand"},
        {pos: [4, 1, 5], state: "minecraft:cut_red_sandstone"},
        {pos: [4, 1, 6], state: "minecraft:red_sand"},
        {pos: [4, 1, 7], state: "minecraft:red_sand"},
        {pos: [4, 1, 8], state: "minecraft:red_sand"},
        {pos: [4, 1, 9], state: "minecraft:red_sand"},
        {pos: [4, 1, 10], state: "minecraft:red_sand"},
        {pos: [4, 1, 11], state: "minecraft:cut_red_sandstone"},
        {pos: [4, 1, 12], state: "minecraft:red_sand"},
        {pos: [4, 1, 13], state: "minecraft:red_sand"},
        {pos: [5, 1, 4], state: "minecraft:cut_red_sandstone"},
        {pos: [5, 1, 5], state: "minecraft:red_sandstone_stairs{facing:north,half:top,shape:straight,waterlogged:false}"},
        {pos: [5, 1, 6], state: "minecraft:red_sand"},
        {pos: [5, 1, 7], state: "minecraft:red_sand"},
        {pos: [5, 1, 8], state: "minecraft:red_sand"},
        {pos: [5, 1, 9], state: "minecraft:red_sand"},
        {pos: [5, 1, 10], state: "minecraft:red_sand"},
        {pos: [5, 1, 11], state: "minecraft:red_sand"},
        {pos: [5, 1, 12], state: "minecraft:red_sandstone"},
        {pos: [5, 1, 13], state: "minecraft:red_sand"},
        {pos: [6, 1, 4], state: "minecraft:cut_red_sandstone"},
        {pos: [6, 1, 5], state: "minecraft:red_sandstone_stairs{facing:north,half:top,shape:straight,waterlogged:false}"},
        {pos: [6, 1, 7], state: "minecraft:red_sand"},
        {pos: [6, 1, 8], state: "minecraft:red_sand"},
        {pos: [6, 1, 9], state: "minecraft:red_sand"},
        {pos: [6, 1, 10], state: "minecraft:red_sand"},
        {pos: [6, 1, 11], state: "minecraft:red_sand"},
        {pos: [6, 1, 12], state: "minecraft:red_sandstone"},
        {pos: [6, 1, 13], state: "minecraft:red_sandstone"},
        {pos: [7, 1, 6], state: "minecraft:red_sand"},
        {pos: [7, 1, 7], state: "minecraft:red_sand"},
        {pos: [7, 1, 8], state: "minecraft:red_sand"},
        {pos: [7, 1, 9], state: "minecraft:red_sand"},
        {pos: [7, 1, 10], state: "minecraft:red_sand"},
        {pos: [7, 1, 11], state: "minecraft:red_sandstone_stairs{facing:south,half:top,shape:straight,waterlogged:false}"},
        {pos: [7, 1, 12], state: "minecraft:red_sandstone"},
        {pos: [7, 1, 13], state: "minecraft:red_sand"},
        {pos: [8, 1, 4], state: "minecraft:cut_red_sandstone"},
        {pos: [8, 1, 5], state: "minecraft:red_sand"},
        {pos: [8, 1, 6], state: "minecraft:red_sand"},
        {pos: [8, 1, 7], state: "minecraft:red_sand"},
        {pos: [8, 1, 8], state: "minecraft:red_sand"},
        {pos: [8, 1, 9], state: "minecraft:red_sand"},
        {pos: [8, 1, 10], state: "minecraft:red_sand"},
        {pos: [8, 1, 11], state: "minecraft:red_sandstone_stairs{facing:south,half:top,shape:straight,waterlogged:false}"},
        {pos: [8, 1, 12], state: "minecraft:red_sandstone"},
        {pos: [9, 1, 4], state: "minecraft:red_sandstone"},
        {pos: [9, 1, 5], state: "minecraft:red_sand"},
        {pos: [9, 1, 6], state: "minecraft:red_sand"},
        {pos: [9, 1, 7], state: "minecraft:red_sand"},
        {pos: [9, 1, 8], state: "minecraft:red_sand"},
        {pos: [9, 1, 9], state: "minecraft:red_sand"},
        {pos: [9, 1, 10], state: "minecraft:red_sand"},
        {pos: [9, 1, 11], state: "minecraft:red_sandstone_stairs{facing:south,half:top,shape:straight,waterlogged:false}"},
        {pos: [9, 1, 12], state: "minecraft:red_sandstone"},
        {pos: [9, 1, 13], state: "minecraft:red_sand"},
        {pos: [10, 1, 4], state: "minecraft:red_sand"},
        {pos: [10, 1, 5], state: "minecraft:cut_red_sandstone"},
        {pos: [10, 1, 6], state: "minecraft:red_sand"},
        {pos: [10, 1, 7], state: "minecraft:red_sandstone_stairs{facing:east,half:top,shape:straight,waterlogged:false}"},
        {pos: [10, 1, 8], state: "minecraft:red_sandstone_stairs{facing:east,half:top,shape:straight,waterlogged:false}"},
        {pos: [10, 1, 9], state: "minecraft:red_sandstone_stairs{facing:east,half:top,shape:straight,waterlogged:false}"},
        {pos: [10, 1, 10], state: "minecraft:red_sand"},
        {pos: [10, 1, 11], state: "minecraft:red_sandstone"},
        {pos: [10, 1, 12], state: "minecraft:red_sand"},
        {pos: [10, 1, 13], state: "minecraft:red_sand"},
        {pos: [10, 1, 14], state: "minecraft:red_sand"},
        {pos: [10, 1, 15], state: "minecraft:red_sand"},
        {pos: [11, 1, 3], state: "minecraft:red_sand"},
        {pos: [11, 1, 4], state: "minecraft:red_sand"},
        {pos: [11, 1, 5], state: "minecraft:red_sand"},
        {pos: [11, 1, 6], state: "minecraft:red_sandstone"},
        {pos: [11, 1, 7], state: "minecraft:cut_red_sandstone"},
        {pos: [11, 1, 8], state: "minecraft:chiseled_red_sandstone"},
        {pos: [11, 1, 9], state: "minecraft:cut_red_sandstone"},
        {pos: [11, 1, 10], state: "minecraft:cut_red_sandstone"},
        {pos: [11, 1, 11], state: "minecraft:red_sand"},
        {pos: [11, 1, 12], state: "minecraft:red_sand"},
        {pos: [11, 1, 13], state: "minecraft:red_sand"},
        {pos: [11, 1, 14], state: "minecraft:smooth_red_sandstone"},
        {pos: [11, 1, 15], state: "minecraft:red_sand"},
        {pos: [12, 1, 1], state: "minecraft:red_sand"},
        {pos: [12, 1, 2], state: "minecraft:red_sand"},
        {pos: [12, 1, 3], state: "minecraft:red_sand"},
        {pos: [12, 1, 8], state: "minecraft:red_sand"},
        {pos: [12, 1, 9], state: "minecraft:red_sand"},
        {pos: [12, 1, 10], state: "minecraft:red_sand"},
        {pos: [12, 1, 12], state: "minecraft:red_sand"},
        {pos: [12, 1, 13], state: "minecraft:red_sand"},
        {pos: [12, 1, 14], state: "minecraft:red_sand"},
        {pos: [13, 1, 1], state: "minecraft:red_sand"},
        {pos: [13, 1, 2], state: "minecraft:smooth_red_sandstone"},
        {pos: [13, 1, 3], state: "minecraft:red_sand"},
        {pos: [1, 2, 9], state: "minecraft:smooth_red_sandstone"},
        {pos: [2, 2, 1], state: "minecraft:smooth_red_sandstone"},
        {pos: [3, 2, 5], state: "minecraft:red_sand"},
        {pos: [3, 2, 6], state: "minecraft:red_terracotta"},
        {pos: [3, 2, 7], state: "minecraft:red_terracotta"},
        {pos: [3, 2, 9], state: "minecraft:red_terracotta"},
        {pos: [3, 2, 10], state: "minecraft:red_terracotta"},
        {pos: [3, 2, 11], state: "minecraft:red_sand"},
        {pos: [4, 2, 5], state: "minecraft:red_terracotta"},
        {pos: [4, 2, 6], state: "minecraft:red_sand"},
        {pos: [4, 2, 7], state: "minecraft:red_sand"},
        {pos: [4, 2, 8], state: "minecraft:red_sand"},
        {pos: [4, 2, 9], state: "minecraft:red_sand"},
        {pos: [4, 2, 10], state: "minecraft:red_sand"},
        {pos: [4, 2, 11], state: "minecraft:terracotta"},
        {pos: [4, 2, 12], state: "minecraft:red_sand"},
        {pos: [5, 2, 4], state: "minecraft:red_terracotta"},
        {pos: [5, 2, 5], state: "minecraft:red_sand"},
        {pos: [5, 2, 6], state: "minecraft:red_sand"},
        {pos: [5, 2, 8], state: "minecraft:red_sand"},
        {pos: [5, 2, 9], state: "minecraft:red_sand"},
        {pos: [5, 2, 10], state: "minecraft:red_sand"},
        {pos: [5, 2, 11], state: "minecraft:terracotta"},
        {pos: [5, 2, 12], state: "minecraft:red_terracotta"},
        {pos: [5, 2, 13], state: "minecraft:red_sand"},
        {pos: [6, 2, 4], state: "minecraft:red_terracotta"},
        {pos: [6, 2, 9], state: "minecraft:red_sand"},
        {pos: [6, 2, 10], state: "minecraft:red_sand"},
        {pos: [6, 2, 11], state: "minecraft:red_sand"},
        {pos: [6, 2, 12], state: "minecraft:red_terracotta"},
        {pos: [6, 2, 13], state: "minecraft:red_sand"},
        {pos: [7, 2, 8], state: "minecraft:red_sand"},
        {pos: [7, 2, 9], state: "minecraft:red_sand"},
        {pos: [7, 2, 10], state: "minecraft:red_sand"},
        {pos: [7, 2, 11], state: "minecraft:red_sand"},
        {pos: [7, 2, 12], state: "minecraft:red_terracotta"},
        {pos: [8, 2, 4], state: "minecraft:red_terracotta"},
        {pos: [8, 2, 5], state: "minecraft:red_sand"},
        {pos: [8, 2, 6], state: "minecraft:red_sand"},
        {pos: [8, 2, 7], state: "minecraft:red_sand"},
        {pos: [8, 2, 8], state: "minecraft:red_sand"},
        {pos: [8, 2, 9], state: "minecraft:red_sand"},
        {pos: [8, 2, 10], state: "minecraft:red_sand"},
        {pos: [8, 2, 11], state: "minecraft:red_sand"},
        {pos: [8, 2, 12], state: "minecraft:red_terracotta"},
        {pos: [9, 2, 4], state: "minecraft:red_terracotta"},
        {pos: [9, 2, 5], state: "minecraft:red_sand"},
        {pos: [9, 2, 6], state: "minecraft:red_sand"},
        {pos: [9, 2, 7], state: "minecraft:red_sand"},
        {pos: [9, 2, 8], state: "minecraft:red_sand"},
        {pos: [9, 2, 9], state: "minecraft:red_sand"},
        {pos: [9, 2, 10], state: "minecraft:red_sand"},
        {pos: [9, 2, 11], state: "minecraft:red_sand"},
        {pos: [9, 2, 12], state: "minecraft:red_terracotta"},
        {pos: [9, 2, 13], state: "minecraft:red_sand"},
        {pos: [10, 2, 4], state: "minecraft:red_sand"},
        {pos: [10, 2, 5], state: "minecraft:red_terracotta"},
        {pos: [10, 2, 6], state: "minecraft:red_sand"},
        {pos: [10, 2, 7], state: "minecraft:red_sand"},
        {pos: [10, 2, 8], state: "minecraft:red_sand"},
        {pos: [10, 2, 9], state: "minecraft:red_sand"},
        {pos: [10, 2, 11], state: "minecraft:red_terracotta"},
        {pos: [10, 2, 12], state: "minecraft:red_sand"},
        {pos: [10, 2, 13], state: "minecraft:red_sand"},
        {pos: [11, 2, 6], state: "minecraft:red_terracotta"},
        {pos: [11, 2, 7], state: "minecraft:red_terracotta"},
        {pos: [11, 2, 9], state: "minecraft:red_terracotta"},
        {pos: [11, 2, 10], state: "minecraft:red_terracotta"},
        {pos: [11, 2, 11], state: "minecraft:red_sand"},
        {pos: [11, 2, 12], state: "minecraft:red_sand"},
        {pos: [11, 2, 13], state: "minecraft:red_sand"},
        {pos: [11, 2, 14], state: "minecraft:smooth_red_sandstone"},
        {pos: [13, 2, 2], state: "minecraft:smooth_red_sandstone"},
        {pos: [1, 3, 9], state: "minecraft:cut_red_sandstone"},
        {pos: [2, 3, 1], state: "minecraft:smooth_red_sandstone"},
        {pos: [3, 3, 7], state: "minecraft:red_terracotta"},
        {pos: [3, 3, 8], state: "minecraft:red_terracotta"},
        {pos: [3, 3, 9], state: "minecraft:red_terracotta"},
        {pos: [4, 3, 5], state: "minecraft:red_terracotta"},
        {pos: [4, 3, 6], state: "minecraft:red_terracotta"},
        {pos: [4, 3, 9], state: "minecraft:red_sand"},
        {pos: [4, 3, 10], state: "minecraft:terracotta"},
        {pos: [4, 3, 11], state: "minecraft:terracotta"},
        {pos: [5, 3, 5], state: "minecraft:red_terracotta"},
        {pos: [5, 3, 10], state: "minecraft:red_sand"},
        {pos: [5, 3, 11], state: "minecraft:terracotta"},
        {pos: [6, 3, 4], state: "minecraft:red_terracotta"},
        {pos: [6, 3, 10], state: "minecraft:red_sand"},
        {pos: [6, 3, 11], state: "minecraft:terracotta"},
        {pos: [6, 3, 12], state: "minecraft:red_terracotta"},
        {pos: [7, 3, 4], state: "minecraft:red_terracotta"},
        {pos: [7, 3, 9], state: "minecraft:red_sand"},
        {pos: [7, 3, 10], state: "minecraft:red_sand"},
        {pos: [7, 3, 11], state: "minecraft:red_sand"},
        {pos: [7, 3, 12], state: "minecraft:red_terracotta"},
        {pos: [8, 3, 4], state: "minecraft:red_terracotta"},
        {pos: [8, 3, 5], state: "minecraft:red_sand"},
        {pos: [8, 3, 6], state: "minecraft:red_sand"},
        {pos: [8, 3, 7], state: "minecraft:red_sand"},
        {pos: [8, 3, 8], state: "minecraft:red_sand"},
        {pos: [8, 3, 9], state: "minecraft:red_sand"},
        {pos: [8, 3, 10], state: "minecraft:red_sand"},
        {pos: [8, 3, 11], state: "minecraft:red_sand"},
        {pos: [8, 3, 12], state: "minecraft:red_terracotta"},
        {pos: [9, 3, 5], state: "minecraft:terracotta"},
        {pos: [9, 3, 6], state: "minecraft:red_sand"},
        {pos: [9, 3, 7], state: "minecraft:red_sand"},
        {pos: [9, 3, 8], state: "minecraft:red_sand"},
        {pos: [9, 3, 9], state: "minecraft:red_sand"},
        {pos: [9, 3, 10], state: "minecraft:red_sand"},
        {pos: [9, 3, 11], state: "minecraft:terracotta"},
        {pos: [10, 3, 5], state: "minecraft:red_terracotta"},
        {pos: [10, 3, 6], state: "minecraft:red_terracotta"},
        {pos: [10, 3, 7], state: "minecraft:red_sand"},
        {pos: [10, 3, 8], state: "minecraft:red_sand"},
        {pos: [10, 3, 9], state: "minecraft:red_sand"},
        {pos: [10, 3, 10], state: "minecraft:red_terracotta"},
        {pos: [10, 3, 11], state: "minecraft:red_terracotta"},
        {pos: [11, 3, 7], state: "minecraft:red_terracotta"},
        {pos: [11, 3, 8], state: "minecraft:red_terracotta"},
        {pos: [11, 3, 9], state: "minecraft:red_terracotta"},
        {pos: [11, 3, 14], state: "minecraft:smooth_red_sandstone"},
        {pos: [13, 3, 2], state: "minecraft:cut_red_sandstone"},
        {pos: [1, 4, 9], state: "minecraft:chiseled_red_sandstone"},
        {pos: [2, 4, 1], state: "minecraft:cut_red_sandstone"},
        {pos: [4, 4, 6], state: "minecraft:red_terracotta"},
        {pos: [4, 4, 7], state: "minecraft:red_terracotta"},
        {pos: [4, 4, 8], state: "minecraft:terracotta"},
        {pos: [4, 4, 9], state: "minecraft:terracotta"},
        {pos: [4, 4, 10], state: "minecraft:terracotta"},
        {pos: [5, 4, 5], state: "minecraft:red_terracotta"},
        {pos: [5, 4, 6], state: "minecraft:red_terracotta"},
        {pos: [5, 4, 9], state: "minecraft:terracotta"},
        {pos: [5, 4, 10], state: "minecraft:terracotta"},
        {pos: [5, 4, 11], state: "minecraft:terracotta"},
        {pos: [6, 4, 5], state: "minecraft:red_terracotta"},
        {pos: [6, 4, 10], state: "minecraft:terracotta"},
        {pos: [6, 4, 11], state: "minecraft:red_terracotta"},
        {pos: [7, 4, 5], state: "minecraft:red_terracotta"},
        {pos: [7, 4, 6], state: "minecraft:terracotta"},
        {pos: [7, 4, 10], state: "minecraft:red_sand"},
        {pos: [7, 4, 11], state: "minecraft:red_terracotta"},
        {pos: [8, 4, 5], state: "minecraft:terracotta"},
        {pos: [8, 4, 6], state: "minecraft:terracotta"},
        {pos: [8, 4, 7], state: "minecraft:red_sand"},
        {pos: [8, 4, 9], state: "minecraft:red_sand"},
        {pos: [8, 4, 10], state: "minecraft:red_sand"},
        {pos: [8, 4, 11], state: "minecraft:terracotta"},
        {pos: [9, 4, 5], state: "minecraft:terracotta"},
        {pos: [9, 4, 6], state: "minecraft:terracotta"},
        {pos: [9, 4, 7], state: "minecraft:terracotta"},
        {pos: [9, 4, 8], state: "minecraft:red_sand"},
        {pos: [9, 4, 9], state: "minecraft:red_sand"},
        {pos: [9, 4, 10], state: "minecraft:terracotta"},
        {pos: [9, 4, 11], state: "minecraft:terracotta"},
        {pos: [10, 4, 6], state: "minecraft:terracotta"},
        {pos: [10, 4, 7], state: "minecraft:terracotta"},
        {pos: [10, 4, 8], state: "minecraft:red_terracotta"},
        {pos: [10, 4, 9], state: "minecraft:red_terracotta"},
        {pos: [10, 4, 10], state: "minecraft:terracotta"},
        {pos: [11, 4, 14], state: "minecraft:cut_red_sandstone"},
        {pos: [13, 4, 2], state: "minecraft:chiseled_red_sandstone"},
        {pos: [2, 5, 1], state: "minecraft:chiseled_red_sandstone"},
        {pos: [5, 5, 7], state: "minecraft:terracotta"},
        {pos: [5, 5, 8], state: "minecraft:terracotta"},
        {pos: [5, 5, 9], state: "minecraft:terracotta"},
        {pos: [6, 5, 6], state: "minecraft:terracotta"},
        {pos: [6, 5, 10], state: "minecraft:terracotta"},
        {pos: [7, 5, 6], state: "minecraft:terracotta"},
        {pos: [7, 5, 10], state: "minecraft:terracotta"},
        {pos: [7, 5, 11], state: "minecraft:red_sand"},
        {pos: [8, 5, 6], state: "minecraft:terracotta"},
        {pos: [8, 5, 9], state: "minecraft:terracotta"},
        {pos: [8, 5, 10], state: "minecraft:terracotta"},
        {pos: [9, 5, 7], state: "minecraft:terracotta"},
        {pos: [9, 5, 8], state: "minecraft:terracotta"},
        {pos: [9, 5, 9], state: "minecraft:terracotta"},
        {pos: [11, 5, 14], state: "minecraft:chiseled_red_sandstone"},
        {pos: [5, 6, 8], state: "minecraft:terracotta"},
        {pos: [6, 6, 10], state: "minecraft:terracotta"},
        {pos: [8, 6, 6], state: "minecraft:terracotta"},
        {pos: [5, 7, 8], state: "minecraft:chiseled_red_sandstone"},
        {pos: [6, 7, 10], state: "minecraft:terracotta"},
        {pos: [8, 7, 6], state: "minecraft:chiseled_red_sandstone"},
        {pos: [6, 8, 10], state: "minecraft:chiseled_red_sandstone"}
    ],
    entities: [],
    palette: [
        "minecraft:red_sandstone",
        "minecraft:red_sand",
        "minecraft:smooth_red_sandstone",
        "minecraft:cut_red_sandstone",
        "minecraft:chiseled_red_sandstone",
        "minecraft:red_terracotta",
        "minecraft:terracotta",
        "minecraft:red_sandstone_stairs{facing:north,half:top,shape:straight,waterlogged:false}",
        "minecraft:red_sandstone_stairs{facing:south,half:top,shape:straight,waterlogged:false}",
        "minecraft:red_sandstone_stairs{facing:east,half:top,shape:straight,waterlogged:false}"
    ],
    trailiertales_DataVersion: 2
}
