{
    DataVersion: 3953,
    size: [13, 9, 8],
    data: [
        {pos: [0, 0, 3], state: "minecraft:red_sandstone"},
        {pos: [0, 0, 4], state: "minecraft:red_sandstone"},
        {pos: [1, 0, 2], state: "minecraft:red_sandstone"},
        {pos: [1, 0, 3], state: "minecraft:red_sandstone"},
        {pos: [1, 0, 4], state: "minecraft:red_sandstone"},
        {pos: [1, 0, 5], state: "minecraft:red_sandstone"},
        {pos: [1, 0, 6], state: "minecraft:red_sandstone"},
        {pos: [2, 0, 1], state: "minecraft:red_sandstone"},
        {pos: [2, 0, 2], state: "minecraft:red_sandstone"},
        {pos: [2, 0, 3], state: "minecraft:red_sandstone"},
        {pos: [2, 0, 4], state: "minecraft:red_sandstone"},
        {pos: [2, 0, 5], state: "minecraft:red_sandstone"},
        {pos: [2, 0, 6], state: "minecraft:red_sandstone"},
        {pos: [3, 0, 0], state: "minecraft:red_sandstone"},
        {pos: [3, 0, 1], state: "minecraft:red_sandstone"},
        {pos: [3, 0, 2], state: "minecraft:red_sandstone"},
        {pos: [3, 0, 3], state: "minecraft:red_sandstone"},
        {pos: [3, 0, 4], state: "minecraft:red_sandstone"},
        {pos: [3, 0, 5], state: "minecraft:red_sandstone"},
        {pos: [4, 0, 0], state: "minecraft:red_sandstone"},
        {pos: [4, 0, 1], state: "minecraft:red_sandstone"},
        {pos: [4, 0, 2], state: "minecraft:red_sandstone"},
        {pos: [4, 0, 3], state: "minecraft:red_sandstone"},
        {pos: [4, 0, 4], state: "minecraft:red_sandstone"},
        {pos: [4, 0, 5], state: "minecraft:red_sandstone"},
        {pos: [4, 0, 6], state: "minecraft:red_sandstone"},
        {pos: [5, 0, 0], state: "minecraft:red_sandstone"},
        {pos: [5, 0, 1], state: "minecraft:red_sandstone"},
        {pos: [5, 0, 2], state: "minecraft:red_sandstone"},
        {pos: [5, 0, 3], state: "minecraft:red_sandstone"},
        {pos: [5, 0, 4], state: "minecraft:red_sandstone"},
        {pos: [5, 0, 5], state: "minecraft:red_sandstone"},
        {pos: [5, 0, 6], state: "minecraft:red_sandstone"},
        {pos: [5, 0, 7], state: "minecraft:red_sandstone"},
        {pos: [6, 0, 1], state: "minecraft:red_sandstone"},
        {pos: [6, 0, 2], state: "minecraft:red_sandstone"},
        {pos: [6, 0, 3], state: "minecraft:red_sandstone"},
        {pos: [6, 0, 4], state: "minecraft:red_sandstone"},
        {pos: [6, 0, 5], state: "minecraft:red_sandstone"},
        {pos: [6, 0, 6], state: "minecraft:red_sandstone"},
        {pos: [6, 0, 7], state: "minecraft:red_sandstone"},
        {pos: [7, 0, 1], state: "minecraft:red_sandstone"},
        {pos: [7, 0, 2], state: "minecraft:red_sandstone"},
        {pos: [7, 0, 3], state: "minecraft:red_sandstone"},
        {pos: [7, 0, 4], state: "minecraft:red_sandstone"},
        {pos: [7, 0, 5], state: "minecraft:red_sandstone"},
        {pos: [7, 0, 6], state: "minecraft:red_sandstone"},
        {pos: [7, 0, 7], state: "minecraft:red_sandstone"},
        {pos: [8, 0, 1], state: "minecraft:red_sandstone"},
        {pos: [8, 0, 2], state: "minecraft:red_sandstone"},
        {pos: [8, 0, 3], state: "minecraft:red_sandstone"},
        {pos: [8, 0, 4], state: "minecraft:red_sandstone"},
        {pos: [8, 0, 5], state: "minecraft:red_sandstone"},
        {pos: [8, 0, 6], state: "minecraft:red_sandstone"},
        {pos: [9, 0, 2], state: "minecraft:red_sandstone"},
        {pos: [9, 0, 3], state: "minecraft:red_sandstone"},
        {pos: [9, 0, 4], state: "minecraft:red_sandstone"},
        {pos: [9, 0, 5], state: "minecraft:red_sandstone"},
        {pos: [9, 0, 6], state: "minecraft:red_sandstone"},
        {pos: [10, 0, 2], state: "minecraft:red_sandstone"},
        {pos: [10, 0, 3], state: "minecraft:red_sandstone"},
        {pos: [10, 0, 4], state: "minecraft:red_sandstone"},
        {pos: [10, 0, 5], state: "minecraft:red_sandstone"},
        {pos: [10, 0, 6], state: "minecraft:red_sandstone"},
        {pos: [10, 0, 7], state: "minecraft:red_sandstone"},
        {pos: [11, 0, 2], state: "minecraft:red_sandstone"},
        {pos: [11, 0, 3], state: "minecraft:red_sandstone"},
        {pos: [11, 0, 4], state: "minecraft:red_sandstone"},
        {pos: [11, 0, 5], state: "minecraft:red_sandstone"},
        {pos: [11, 0, 6], state: "minecraft:red_sandstone"},
        {pos: [11, 0, 7], state: "minecraft:red_sandstone"},
        {pos: [12, 0, 5], state: "minecraft:red_sandstone"},
        {pos: [12, 0, 6], state: "minecraft:red_sandstone"},
        {pos: [12, 0, 7], state: "minecraft:red_sandstone"},
        {pos: [2, 1, 1], state: "minecraft:red_sandstone"},
        {pos: [2, 1, 2], state: "minecraft:terracotta"},
        {pos: [2, 1, 3], state: "minecraft:terracotta"},
        {pos: [2, 1, 4], state: "minecraft:red_sandstone"},
        {pos: [2, 1, 5], state: "minecraft:cut_red_sandstone"},
        {pos: [3, 1, 1], state: "minecraft:cut_red_sandstone"},
        {pos: [3, 1, 2], state: "minecraft:red_sand"},
        {pos: [3, 1, 3], state: "minecraft:red_sand"},
        {pos: [3, 1, 4], state: "minecraft:red_sand"},
        {pos: [3, 1, 5], state: "minecraft:cut_red_sandstone"},
        {pos: [4, 1, 3], state: "minecraft:red_sand"},
        {pos: [4, 1, 4], state: "minecraft:red_sand"},
        {pos: [4, 1, 5], state: "minecraft:red_sandstone"},
        {pos: [5, 1, 1], state: "minecraft:cut_red_sandstone"},
        {pos: [5, 1, 2], state: "minecraft:decorated_pot{cracked:false,facing:east,waterlogged:false}", nbt: {id: "minecraft:decorated_pot"}},
        {pos: [5, 1, 3], state: "minecraft:red_sand"},
        {pos: [5, 1, 4], state: "minecraft:red_sand"},
        {pos: [5, 1, 5], state: "minecraft:terracotta"},
        {pos: [6, 1, 1], state: "minecraft:red_sandstone"},
        {pos: [6, 1, 2], state: "minecraft:terracotta"},
        {pos: [6, 1, 3], state: "minecraft:terracotta"},
        {pos: [6, 1, 4], state: "minecraft:red_sand"},
        {pos: [6, 1, 5], state: "minecraft:red_sandstone"},
        {pos: [6, 1, 6], state: "minecraft:red_sandstone"},
        {pos: [7, 1, 1], state: "minecraft:red_sandstone"},
        {pos: [7, 1, 2], state: "minecraft:red_sandstone"},
        {pos: [7, 1, 3], state: "minecraft:red_terracotta"},
        {pos: [7, 1, 4], state: "minecraft:red_sand"},
        {pos: [7, 1, 5], state: "minecraft:red_terracotta"},
        {pos: [7, 1, 6], state: "minecraft:red_sandstone"},
        {pos: [8, 1, 2], state: "minecraft:red_sandstone"},
        {pos: [8, 1, 3], state: "minecraft:red_sand"},
        {pos: [8, 1, 4], state: "minecraft:red_sand"},
        {pos: [8, 1, 5], state: "minecraft:red_sand"},
        {pos: [8, 1, 6], state: "minecraft:red_terracotta"},
        {pos: [9, 1, 2], state: "minecraft:red_terracotta"},
        {pos: [9, 1, 3], state: "minecraft:red_sand"},
        {pos: [9, 1, 4], state: "minecraft:red_sand"},
        {pos: [9, 1, 5], state: "minecraft:ladder{facing:north,waterlogged:false}"},
        {pos: [9, 1, 6], state: "minecraft:red_terracotta"},
        {pos: [10, 1, 2], state: "minecraft:red_terracotta"},
        {pos: [10, 1, 3], state: "minecraft:red_sand"},
        {pos: [10, 1, 4], state: "minecraft:red_sand"},
        {pos: [10, 1, 5], state: "minecraft:red_sand"},
        {pos: [10, 1, 6], state: "minecraft:red_terracotta"},
        {pos: [11, 1, 2], state: "minecraft:red_sandstone"},
        {pos: [11, 1, 3], state: "minecraft:red_sandstone"},
        {pos: [11, 1, 4], state: "minecraft:red_terracotta"},
        {pos: [11, 1, 5], state: "minecraft:red_terracotta"},
        {pos: [11, 1, 6], state: "minecraft:red_terracotta"},
        {pos: [11, 1, 7], state: "minecraft:red_sandstone"},
        {pos: [12, 1, 6], state: "minecraft:red_sandstone"},
        {pos: [12, 1, 7], state: "minecraft:red_sandstone"},
        {pos: [2, 2, 1], state: "minecraft:terracotta"},
        {pos: [2, 2, 2], state: "minecraft:terracotta"},
        {pos: [2, 2, 3], state: "minecraft:terracotta"},
        {pos: [2, 2, 4], state: "minecraft:terracotta"},
        {pos: [2, 2, 5], state: "minecraft:red_sandstone"},
        {pos: [3, 2, 1], state: "minecraft:terracotta"},
        {pos: [3, 2, 2], state: "minecraft:red_sand"},
        {pos: [3, 2, 3], state: "minecraft:red_sand"},
        {pos: [3, 2, 4], state: "minecraft:red_sand"},
        {pos: [3, 2, 5], state: "minecraft:red_sandstone"},
        {pos: [4, 2, 3], state: "minecraft:air"},
        {pos: [4, 2, 4], state: "minecraft:ladder{facing:north,waterlogged:false}"},
        {pos: [4, 2, 5], state: "minecraft:terracotta"},
        {pos: [5, 2, 1], state: "minecraft:terracotta"},
        {pos: [5, 2, 2], state: "minecraft:air"},
        {pos: [5, 2, 3], state: "minecraft:air"},
        {pos: [5, 2, 4], state: "minecraft:red_sand"},
        {pos: [5, 2, 5], state: "minecraft:terracotta"},
        {pos: [6, 2, 1], state: "minecraft:red_sandstone"},
        {pos: [6, 2, 2], state: "minecraft:terracotta"},
        {pos: [6, 2, 3], state: "minecraft:terracotta"},
        {pos: [6, 2, 4], state: "minecraft:red_sand"},
        {pos: [6, 2, 5], state: "minecraft:terracotta"},
        {pos: [7, 2, 2], state: "minecraft:red_sandstone"},
        {pos: [7, 2, 3], state: "minecraft:red_terracotta"},
        {pos: [7, 2, 4], state: "minecraft:red_sand"},
        {pos: [7, 2, 5], state: "minecraft:red_terracotta"},
        {pos: [7, 2, 6], state: "minecraft:red_terracotta"},
        {pos: [8, 2, 2], state: "minecraft:red_terracotta"},
        {pos: [8, 2, 3], state: "minecraft:red_sand"},
        {pos: [8, 2, 4], state: "minecraft:red_sand"},
        {pos: [8, 2, 5], state: "minecraft:red_sand"},
        {pos: [8, 2, 6], state: "minecraft:red_terracotta"},
        {pos: [9, 2, 3], state: "minecraft:red_sand"},
        {pos: [9, 2, 4], state: "minecraft:red_sand"},
        {pos: [9, 2, 5], state: "minecraft:ladder{facing:north,waterlogged:false}"},
        {pos: [9, 2, 6], state: "minecraft:red_terracotta"},
        {pos: [10, 2, 2], state: "minecraft:red_terracotta"},
        {pos: [10, 2, 3], state: "minecraft:red_sand"},
        {pos: [10, 2, 4], state: "minecraft:red_sand"},
        {pos: [10, 2, 5], state: "minecraft:red_sand"},
        {pos: [10, 2, 6], state: "minecraft:red_terracotta"},
        {pos: [11, 2, 2], state: "minecraft:red_terracotta"},
        {pos: [11, 2, 3], state: "minecraft:red_terracotta"},
        {pos: [11, 2, 4], state: "minecraft:red_terracotta"},
        {pos: [11, 2, 5], state: "minecraft:red_terracotta"},
        {pos: [11, 2, 6], state: "minecraft:red_terracotta"},
        {pos: [2, 3, 1], state: "minecraft:terracotta"},
        {pos: [2, 3, 2], state: "minecraft:terracotta"},
        {pos: [2, 3, 3], state: "minecraft:terracotta"},
        {pos: [2, 3, 4], state: "minecraft:terracotta"},
        {pos: [2, 3, 5], state: "minecraft:terracotta"},
        {pos: [3, 3, 1], state: "minecraft:terracotta"},
        {pos: [3, 3, 3], state: "minecraft:red_sand"},
        {pos: [3, 3, 4], state: "minecraft:red_sand"},
        {pos: [3, 3, 5], state: "minecraft:terracotta"},
        {pos: [4, 3, 1], state: "minecraft:terracotta"},
        {pos: [4, 3, 3], state: "minecraft:air"},
        {pos: [4, 3, 4], state: "minecraft:ladder{facing:north,waterlogged:false}"},
        {pos: [4, 3, 5], state: "minecraft:terracotta"},
        {pos: [5, 3, 1], state: "minecraft:terracotta"},
        {pos: [5, 3, 3], state: "minecraft:air"},
        {pos: [5, 3, 4], state: "minecraft:air"},
        {pos: [5, 3, 5], state: "minecraft:terracotta"},
        {pos: [6, 3, 1], state: "minecraft:terracotta"},
        {pos: [6, 3, 2], state: "minecraft:terracotta"},
        {pos: [6, 3, 3], state: "minecraft:terracotta"},
        {pos: [6, 3, 4], state: "minecraft:terracotta"},
        {pos: [6, 3, 5], state: "minecraft:terracotta"},
        {pos: [7, 3, 2], state: "minecraft:red_terracotta"},
        {pos: [7, 3, 3], state: "minecraft:red_terracotta"},
        {pos: [7, 3, 4], state: "minecraft:red_terracotta"},
        {pos: [7, 3, 5], state: "minecraft:red_terracotta"},
        {pos: [7, 3, 6], state: "minecraft:red_terracotta"},
        {pos: [8, 3, 2], state: "minecraft:red_terracotta"},
        {pos: [8, 3, 5], state: "minecraft:red_sand"},
        {pos: [8, 3, 6], state: "minecraft:red_terracotta"},
        {pos: [9, 3, 5], state: "minecraft:ladder{facing:north,waterlogged:false}"},
        {pos: [9, 3, 6], state: "minecraft:red_terracotta"},
        {pos: [10, 3, 2], state: "minecraft:red_terracotta"},
        {pos: [10, 3, 3], state: "minecraft:red_sand"},
        {pos: [10, 3, 6], state: "minecraft:red_terracotta"},
        {pos: [11, 3, 2], state: "minecraft:red_terracotta"},
        {pos: [11, 3, 3], state: "minecraft:red_terracotta"},
        {pos: [11, 3, 4], state: "minecraft:red_terracotta"},
        {pos: [11, 3, 5], state: "minecraft:red_terracotta"},
        {pos: [11, 3, 6], state: "minecraft:red_terracotta"},
        {pos: [2, 4, 1], state: "minecraft:smooth_red_sandstone"},
        {pos: [2, 4, 2], state: "minecraft:smooth_red_sandstone"},
        {pos: [2, 4, 3], state: "minecraft:smooth_red_sandstone"},
        {pos: [2, 4, 4], state: "minecraft:smooth_red_sandstone"},
        {pos: [2, 4, 5], state: "minecraft:smooth_red_sandstone"},
        {pos: [3, 4, 1], state: "minecraft:smooth_red_sandstone"},
        {pos: [3, 4, 2], state: "minecraft:smooth_red_sandstone"},
        {pos: [3, 4, 3], state: "minecraft:smooth_red_sandstone"},
        {pos: [3, 4, 4], state: "minecraft:smooth_red_sandstone"},
        {pos: [3, 4, 5], state: "minecraft:smooth_red_sandstone"},
        {pos: [4, 4, 1], state: "minecraft:smooth_red_sandstone"},
        {pos: [4, 4, 2], state: "minecraft:smooth_red_sandstone"},
        {pos: [4, 4, 3], state: "minecraft:smooth_red_sandstone"},
        {pos: [4, 4, 4], state: "minecraft:ladder{facing:north,waterlogged:false}"},
        {pos: [4, 4, 5], state: "minecraft:smooth_red_sandstone"},
        {pos: [5, 4, 1], state: "minecraft:smooth_red_sandstone"},
        {pos: [5, 4, 2], state: "minecraft:smooth_red_sandstone"},
        {pos: [5, 4, 3], state: "minecraft:smooth_red_sandstone"},
        {pos: [5, 4, 4], state: "minecraft:smooth_red_sandstone"},
        {pos: [5, 4, 5], state: "minecraft:smooth_red_sandstone"},
        {pos: [6, 4, 1], state: "minecraft:smooth_red_sandstone"},
        {pos: [6, 4, 2], state: "minecraft:smooth_red_sandstone"},
        {pos: [6, 4, 3], state: "minecraft:smooth_red_sandstone"},
        {pos: [6, 4, 4], state: "minecraft:smooth_red_sandstone"},
        {pos: [6, 4, 5], state: "minecraft:smooth_red_sandstone"},
        {pos: [7, 4, 2], state: "minecraft:red_terracotta"},
        {pos: [7, 4, 3], state: "minecraft:red_terracotta"},
        {pos: [7, 4, 4], state: "minecraft:red_terracotta"},
        {pos: [7, 4, 5], state: "minecraft:red_terracotta"},
        {pos: [7, 4, 6], state: "minecraft:smooth_red_sandstone"},
        {pos: [8, 4, 2], state: "minecraft:red_terracotta"},
        {pos: [8, 4, 6], state: "minecraft:red_terracotta"},
        {pos: [9, 4, 2], state: "minecraft:red_terracotta"},
        {pos: [9, 4, 5], state: "minecraft:ladder{facing:north,waterlogged:false}"},
        {pos: [9, 4, 6], state: "minecraft:red_terracotta"},
        {pos: [10, 4, 2], state: "minecraft:red_terracotta"},
        {pos: [10, 4, 6], state: "minecraft:red_terracotta"},
        {pos: [11, 4, 2], state: "minecraft:red_terracotta"},
        {pos: [11, 4, 3], state: "minecraft:red_terracotta"},
        {pos: [11, 4, 4], state: "minecraft:red_terracotta"},
        {pos: [11, 4, 5], state: "minecraft:red_terracotta"},
        {pos: [11, 4, 6], state: "minecraft:smooth_red_sandstone"},
        {pos: [2, 5, 1], state: "minecraft:chiseled_red_sandstone"},
        {pos: [2, 5, 2], state: "minecraft:cut_red_sandstone"},
        {pos: [2, 5, 3], state: "minecraft:chiseled_red_sandstone"},
        {pos: [2, 5, 4], state: "minecraft:cut_red_sandstone"},
        {pos: [3, 5, 1], state: "minecraft:cut_red_sandstone"},
        {pos: [3, 5, 2], state: "minecraft:orange_candle{candles:4,lit:false,waterlogged:false}"},
        {pos: [3, 5, 3], state: "minecraft:orange_candle{candles:4,lit:false,waterlogged:false}"},
        {pos: [3, 5, 4], state: "minecraft:orange_candle{candles:4,lit:false,waterlogged:false}"},
        {pos: [3, 5, 5], state: "minecraft:cut_red_sandstone"},
        {pos: [4, 5, 1], state: "minecraft:chiseled_red_sandstone"},
        {pos: [4, 5, 2], state: "minecraft:orange_candle{candles:4,lit:false,waterlogged:false}"},
        {pos: [4, 5, 3], state: "minecraft:air"},
        {pos: [4, 5, 4], state: "minecraft:ladder{facing:north,waterlogged:false}"},
        {pos: [4, 5, 5], state: "minecraft:chiseled_red_sandstone"},
        {pos: [5, 5, 1], state: "minecraft:cut_red_sandstone"},
        {pos: [5, 5, 2], state: "minecraft:orange_candle{candles:4,lit:false,waterlogged:false}"},
        {pos: [5, 5, 3], state: "minecraft:orange_candle{candles:4,lit:false,waterlogged:false}"},
        {pos: [5, 5, 4], state: "minecraft:decorated_pot{cracked:false,facing:east,waterlogged:false}", nbt: {id: "minecraft:decorated_pot"}},
        {pos: [5, 5, 5], state: "minecraft:cut_red_sandstone"},
        {pos: [6, 5, 1], state: "minecraft:chiseled_red_sandstone"},
        {pos: [6, 5, 2], state: "minecraft:cut_red_sandstone"},
        {pos: [6, 5, 3], state: "minecraft:chiseled_red_sandstone"},
        {pos: [6, 5, 4], state: "minecraft:cut_red_sandstone"},
        {pos: [6, 5, 5], state: "minecraft:chiseled_red_sandstone"},
        {pos: [7, 5, 2], state: "minecraft:red_terracotta"},
        {pos: [7, 5, 3], state: "minecraft:red_terracotta"},
        {pos: [7, 5, 4], state: "minecraft:red_terracotta"},
        {pos: [7, 5, 5], state: "minecraft:red_terracotta"},
        {pos: [7, 5, 6], state: "minecraft:smooth_red_sandstone"},
        {pos: [8, 5, 2], state: "minecraft:red_terracotta"},
        {pos: [8, 5, 6], state: "minecraft:red_terracotta"},
        {pos: [9, 5, 2], state: "minecraft:red_terracotta"},
        {pos: [9, 5, 5], state: "minecraft:ladder{facing:north,waterlogged:false}"},
        {pos: [9, 5, 6], state: "minecraft:smooth_red_sandstone"},
        {pos: [10, 5, 2], state: "minecraft:red_terracotta"},
        {pos: [10, 5, 6], state: "minecraft:smooth_red_sandstone"},
        {pos: [11, 5, 2], state: "minecraft:smooth_red_sandstone"},
        {pos: [11, 5, 3], state: "minecraft:smooth_red_sandstone"},
        {pos: [11, 5, 4], state: "minecraft:red_terracotta"},
        {pos: [11, 5, 5], state: "minecraft:red_terracotta"},
        {pos: [11, 5, 6], state: "minecraft:smooth_red_sandstone"},
        {pos: [3, 6, 2], state: "minecraft:air"},
        {pos: [3, 6, 3], state: "minecraft:air"},
        {pos: [3, 6, 4], state: "minecraft:air"},
        {pos: [4, 6, 2], state: "minecraft:air"},
        {pos: [4, 6, 3], state: "minecraft:air"},
        {pos: [4, 6, 4], state: "minecraft:air"},
        {pos: [5, 6, 2], state: "minecraft:air"},
        {pos: [5, 6, 3], state: "minecraft:air"},
        {pos: [5, 6, 4], state: "minecraft:air"},
        {pos: [5, 6, 5], state: "minecraft:red_sandstone_wall{east:low,north:none,south:none,up:true,waterlogged:false,west:none}"},
        {pos: [6, 6, 5], state: "minecraft:red_sandstone_wall{east:low,north:none,south:none,up:false,waterlogged:false,west:low}"},
        {pos: [7, 6, 2], state: "minecraft:smooth_red_sandstone"},
        {pos: [7, 6, 3], state: "minecraft:smooth_red_sandstone"},
        {pos: [7, 6, 4], state: "minecraft:smooth_red_sandstone"},
        {pos: [7, 6, 5], state: "minecraft:smooth_red_sandstone"},
        {pos: [7, 6, 6], state: "minecraft:smooth_red_sandstone"},
        {pos: [8, 6, 2], state: "minecraft:smooth_red_sandstone"},
        {pos: [8, 6, 3], state: "minecraft:smooth_red_sandstone"},
        {pos: [8, 6, 4], state: "minecraft:smooth_red_sandstone"},
        {pos: [8, 6, 5], state: "minecraft:smooth_red_sandstone"},
        {pos: [8, 6, 6], state: "minecraft:smooth_red_sandstone"},
        {pos: [9, 6, 2], state: "minecraft:smooth_red_sandstone"},
        {pos: [9, 6, 3], state: "minecraft:smooth_red_sandstone"},
        {pos: [9, 6, 4], state: "minecraft:smooth_red_sandstone"},
        {pos: [9, 6, 5], state: "minecraft:ladder{facing:north,waterlogged:false}"},
        {pos: [9, 6, 6], state: "minecraft:smooth_red_sandstone"},
        {pos: [10, 6, 2], state: "minecraft:smooth_red_sandstone"},
        {pos: [10, 6, 3], state: "minecraft:smooth_red_sandstone"},
        {pos: [10, 6, 4], state: "minecraft:smooth_red_sandstone"},
        {pos: [10, 6, 5], state: "minecraft:smooth_red_sandstone"},
        {pos: [10, 6, 6], state: "minecraft:smooth_red_sandstone"},
        {pos: [11, 6, 2], state: "minecraft:smooth_red_sandstone"},
        {pos: [11, 6, 3], state: "minecraft:smooth_red_sandstone"},
        {pos: [11, 6, 4], state: "minecraft:smooth_red_sandstone"},
        {pos: [11, 6, 5], state: "minecraft:smooth_red_sandstone"},
        {pos: [11, 6, 6], state: "minecraft:smooth_red_sandstone"},
        {pos: [7, 7, 2], state: "minecraft:chiseled_red_sandstone"},
        {pos: [7, 7, 3], state: "minecraft:cut_red_sandstone"},
        {pos: [7, 7, 4], state: "minecraft:chiseled_red_sandstone"},
        {pos: [7, 7, 5], state: "minecraft:cut_red_sandstone"},
        {pos: [7, 7, 6], state: "minecraft:chiseled_red_sandstone"},
        {pos: [8, 7, 2], state: "minecraft:cut_red_sandstone"},
        {pos: [8, 7, 3], state: "minecraft:decorated_pot{cracked:false,facing:north,waterlogged:false}", nbt: {id: "minecraft:decorated_pot"}},
        {pos: [8, 7, 4], state: "minecraft:orange_candle{candles:4,lit:false,waterlogged:false}"},
        {pos: [8, 7, 5], state: "minecraft:orange_candle{candles:4,lit:false,waterlogged:false}"},
        {pos: [8, 7, 6], state: "minecraft:cut_red_sandstone"},
        {pos: [9, 7, 2], state: "minecraft:chiseled_red_sandstone"},
        {pos: [9, 7, 3], state: "minecraft:orange_candle{candles:4,lit:false,waterlogged:false}"},
        {pos: [9, 7, 4], state: "minecraft:air"},
        {pos: [9, 7, 5], state: "minecraft:air"},
        {pos: [9, 7, 6], state: "minecraft:chiseled_red_sandstone"},
        {pos: [10, 7, 2], state: "minecraft:cut_red_sandstone"},
        {pos: [10, 7, 3], state: "minecraft:orange_candle{candles:4,lit:false,waterlogged:false}"},
        {pos: [10, 7, 4], state: "minecraft:orange_candle{candles:4,lit:false,waterlogged:false}"},
        {pos: [10, 7, 5], state: "minecraft:orange_candle{candles:4,lit:false,waterlogged:false}"},
        {pos: [10, 7, 6], state: "minecraft:cut_red_sandstone"},
        {pos: [11, 7, 2], state: "minecraft:chiseled_red_sandstone"},
        {pos: [11, 7, 3], state: "minecraft:cut_red_sandstone"},
        {pos: [11, 7, 4], state: "minecraft:chiseled_red_sandstone"},
        {pos: [11, 7, 5], state: "minecraft:cut_red_sandstone"},
        {pos: [11, 7, 6], state: "minecraft:chiseled_red_sandstone"},
        {pos: [7, 8, 6], state: "minecraft:red_sandstone_wall{east:none,north:none,south:none,up:true,waterlogged:false,west:none}"},
        {pos: [8, 8, 3], state: "minecraft:air"},
        {pos: [8, 8, 4], state: "minecraft:air"},
        {pos: [8, 8, 5], state: "minecraft:air"},
        {pos: [9, 8, 3], state: "minecraft:air"},
        {pos: [9, 8, 4], state: "minecraft:air"},
        {pos: [9, 8, 5], state: "minecraft:air"},
        {pos: [10, 8, 3], state: "minecraft:air"},
        {pos: [10, 8, 4], state: "minecraft:air"},
        {pos: [10, 8, 5], state: "minecraft:air"},
        {pos: [11, 8, 2], state: "minecraft:red_sandstone_wall{east:none,north:none,south:low,up:true,waterlogged:false,west:none}"},
        {pos: [11, 8, 3], state: "minecraft:red_sandstone_wall{east:none,north:low,south:none,up:true,waterlogged:false,west:none}"}
    ],
    entities: [],
    palette: [
        "minecraft:red_sandstone",
        "minecraft:terracotta",
        "minecraft:cut_red_sandstone",
        "minecraft:red_sand",
        "minecraft:red_terracotta",
        "minecraft:smooth_red_sandstone",
        "minecraft:chiseled_red_sandstone",
        "minecraft:ladder{facing:north,waterlogged:false}",
        "minecraft:air",
        "minecraft:orange_candle{candles:4,lit:false,waterlogged:false}",
        "minecraft:red_sandstone_wall{east:low,north:none,south:none,up:true,waterlogged:false,west:none}",
        "minecraft:red_sandstone_wall{east:low,north:none,south:none,up:false,waterlogged:false,west:low}",
        "minecraft:red_sandstone_wall{east:none,north:none,south:none,up:true,waterlogged:false,west:none}",
        "minecraft:red_sandstone_wall{east:none,north:none,south:low,up:true,waterlogged:false,west:none}",
        "minecraft:red_sandstone_wall{east:none,north:low,south:none,up:true,waterlogged:false,west:none}",
        "minecraft:decorated_pot{cracked:false,facing:east,waterlogged:false}",
        "minecraft:decorated_pot{cracked:false,facing:north,waterlogged:false}"
    ],
    trailiertales_DataVersion: 2
}
