{
    DataVersion: 3953,
    size: [5, 5, 7],
    data: [
        {pos: [0, 0, 3], state: "minecraft:cut_red_sandstone"},
        {pos: [0, 0, 4], state: "minecraft:cut_red_sandstone"},
        {pos: [0, 0, 5], state: "minecraft:cut_red_sandstone"},
        {pos: [0, 0, 6], state: "minecraft:cut_red_sandstone"},
        {pos: [1, 0, 0], state: "minecraft:cut_red_sandstone"},
        {pos: [1, 0, 1], state: "minecraft:cut_red_sandstone"},
        {pos: [1, 0, 2], state: "minecraft:cut_red_sandstone"},
        {pos: [1, 0, 3], state: "minecraft:cut_red_sandstone"},
        {pos: [1, 0, 4], state: "minecraft:cut_red_sandstone"},
        {pos: [1, 0, 5], state: "minecraft:cut_red_sandstone"},
        {pos: [1, 0, 6], state: "minecraft:cut_red_sandstone"},
        {pos: [2, 0, 0], state: "minecraft:cut_red_sandstone"},
        {pos: [2, 0, 1], state: "minecraft:cut_red_sandstone"},
        {pos: [2, 0, 2], state: "minecraft:yellow_glazed_terracotta{facing:north}"},
        {pos: [2, 0, 3], state: "minecraft:cut_red_sandstone"},
        {pos: [2, 0, 4], state: "minecraft:cut_red_sandstone"},
        {pos: [2, 0, 5], state: "minecraft:cut_red_sandstone"},
        {pos: [3, 0, 1], state: "minecraft:cut_red_sandstone"},
        {pos: [3, 0, 2], state: "minecraft:cut_red_sandstone"},
        {pos: [3, 0, 3], state: "minecraft:yellow_glazed_terracotta{facing:south}"},
        {pos: [3, 0, 4], state: "minecraft:cut_red_sandstone"},
        {pos: [4, 0, 1], state: "minecraft:cut_red_sandstone"},
        {pos: [4, 0, 2], state: "minecraft:cut_red_sandstone"},
        {pos: [4, 0, 3], state: "minecraft:cut_red_sandstone"},
        {pos: [0, 1, 3], state: "minecraft:cut_red_sandstone"},
        {pos: [0, 1, 4], state: "minecraft:cut_red_sandstone"},
        {pos: [0, 1, 5], state: "minecraft:red_sand"},
        {pos: [0, 1, 6], state: "minecraft:red_sand"},
        {pos: [1, 1, 0], state: "minecraft:red_sand"},
        {pos: [1, 1, 1], state: "minecraft:cut_red_sandstone"},
        {pos: [1, 1, 2], state: "minecraft:red_sand"},
        {pos: [1, 1, 3], state: "minecraft:red_sand"},
        {pos: [1, 1, 4], state: "minecraft:red_sand"},
        {pos: [1, 1, 5], state: "minecraft:red_sand"},
        {pos: [1, 1, 6], state: "minecraft:red_sand"},
        {pos: [2, 1, 0], state: "minecraft:red_sand"},
        {pos: [2, 1, 1], state: "minecraft:red_sand"},
        {pos: [2, 1, 2], state: "minecraft:red_sand"},
        {pos: [2, 1, 3], state: "minecraft:red_sand"},
        {pos: [2, 1, 4], state: "minecraft:red_sand"},
        {pos: [2, 1, 5], state: "minecraft:red_sand"},
        {pos: [3, 1, 1], state: "minecraft:red_sand"},
        {pos: [3, 1, 2], state: "minecraft:red_sand"},
        {pos: [3, 1, 3], state: "minecraft:red_sand"},
        {pos: [3, 1, 4], state: "minecraft:red_sand"},
        {pos: [4, 1, 1], state: "minecraft:cut_red_sandstone"},
        {pos: [4, 1, 2], state: "minecraft:cut_red_sandstone"},
        {pos: [4, 1, 3], state: "minecraft:cut_red_sandstone"},
        {pos: [0, 2, 2], state: "minecraft:cut_red_sandstone"},
        {pos: [0, 2, 3], state: "minecraft:cut_red_sandstone"},
        {pos: [0, 2, 4], state: "minecraft:cut_red_sandstone"},
        {pos: [0, 2, 5], state: "minecraft:red_sand"},
        {pos: [1, 2, 0], state: "minecraft:red_sand"},
        {pos: [1, 2, 1], state: "minecraft:cut_red_sandstone"},
        {pos: [1, 2, 2], state: "minecraft:red_sand"},
        {pos: [1, 2, 3], state: "minecraft:red_sand"},
        {pos: [1, 2, 4], state: "minecraft:cut_red_sandstone"},
        {pos: [1, 2, 5], state: "minecraft:red_sand"},
        {pos: [2, 2, 0], state: "minecraft:red_sand"},
        {pos: [2, 2, 1], state: "minecraft:red_sand"},
        {pos: [2, 2, 2], state: "minecraft:red_sand"},
        {pos: [2, 2, 3], state: "minecraft:red_sand"},
        {pos: [2, 2, 4], state: "minecraft:red_sand"},
        {pos: [2, 2, 5], state: "minecraft:red_sand"},
        {pos: [3, 2, 2], state: "minecraft:red_sand"},
        {pos: [3, 2, 3], state: "minecraft:red_sand"},
        {pos: [3, 2, 4], state: "minecraft:red_sand"},
        {pos: [4, 2, 1], state: "minecraft:cut_red_sandstone"},
        {pos: [4, 2, 2], state: "minecraft:cut_red_sandstone"},
        {pos: [4, 2, 3], state: "minecraft:cut_red_sandstone"},
        {pos: [4, 2, 4], state: "minecraft:cut_red_sandstone"},
        {pos: [0, 3, 2], state: "minecraft:cut_red_sandstone"},
        {pos: [0, 3, 3], state: "minecraft:cut_red_sandstone"},
        {pos: [0, 3, 4], state: "minecraft:cut_red_sandstone"},
        {pos: [1, 3, 1], state: "minecraft:cut_red_sandstone"},
        {pos: [1, 3, 2], state: "minecraft:red_sand"},
        {pos: [1, 3, 3], state: "minecraft:red_sand"},
        {pos: [1, 3, 4], state: "minecraft:cut_red_sandstone"},
        {pos: [2, 3, 0], state: "minecraft:red_sand"},
        {pos: [2, 3, 1], state: "minecraft:cut_red_sandstone"},
        {pos: [2, 3, 2], state: "minecraft:red_sand"},
        {pos: [2, 3, 3], state: "minecraft:red_sand"},
        {pos: [2, 3, 4], state: "minecraft:cut_red_sandstone"},
        {pos: [3, 3, 1], state: "minecraft:cut_red_sandstone"},
        {pos: [3, 3, 2], state: "minecraft:red_sand"},
        {pos: [3, 3, 3], state: "minecraft:red_sand"},
        {pos: [3, 3, 4], state: "minecraft:cut_red_sandstone"},
        {pos: [4, 3, 1], state: "minecraft:cut_red_sandstone"},
        {pos: [4, 3, 2], state: "minecraft:cut_red_sandstone"},
        {pos: [0, 4, 3], state: "minecraft:cut_red_sandstone"},
        {pos: [0, 4, 4], state: "minecraft:cut_red_sandstone"},
        {pos: [1, 4, 2], state: "minecraft:red_sand"},
        {pos: [1, 4, 3], state: "minecraft:red_sand"},
        {pos: [1, 4, 4], state: "minecraft:cut_red_sandstone"},
        {pos: [2, 4, 3], state: "minecraft:red_sand"},
        {pos: [3, 4, 1], state: "minecraft:red_sandstone_wall{east:low,north:none,south:none,up:true,waterlogged:false,west:none}"},
        {pos: [4, 4, 1], state: "minecraft:red_sandstone_wall{east:none,north:none,south:none,up:true,waterlogged:false,west:low}"}
    ],
    entities: [],
    palette: [
        "minecraft:cut_red_sandstone",
        "minecraft:yellow_glazed_terracotta{facing:north}",
        "minecraft:yellow_glazed_terracotta{facing:south}",
        "minecraft:red_sand",
        "minecraft:red_sandstone_wall{east:low,north:none,south:none,up:true,waterlogged:false,west:none}",
        "minecraft:red_sandstone_wall{east:none,north:none,south:none,up:true,waterlogged:false,west:low}"
    ],
    trailiertales_DataVersion: 2
}
