{
    DataVersion: 3953,
    size: [6, 6, 7],
    data: [
        {pos: [0, 0, 3], state: "minecraft:cut_red_sandstone"},
        {pos: [0, 0, 4], state: "minecraft:cut_red_sandstone"},
        {pos: [0, 0, 5], state: "minecraft:cut_red_sandstone"},
        {pos: [0, 0, 6], state: "minecraft:cut_red_sandstone"},
        {pos: [1, 0, 6], state: "minecraft:cut_red_sandstone"},
        {pos: [2, 0, 2], state: "minecraft:cut_red_sandstone"},
        {pos: [2, 0, 3], state: "minecraft:cut_red_sandstone"},
        {pos: [2, 0, 4], state: "minecraft:cut_red_sandstone"},
        {pos: [2, 0, 6], state: "minecraft:cut_red_sandstone"},
        {pos: [3, 0, 1], state: "minecraft:cut_red_sandstone"},
        {pos: [3, 0, 2], state: "minecraft:orange_glazed_terracotta{facing:north}"},
        {pos: [3, 0, 3], state: "minecraft:orange_glazed_terracotta{facing:west}"},
        {pos: [3, 0, 4], state: "minecraft:cut_red_sandstone"},
        {pos: [3, 0, 5], state: "minecraft:cut_red_sandstone"},
        {pos: [3, 0, 6], state: "minecraft:cut_red_sandstone"},
        {pos: [4, 0, 1], state: "minecraft:cut_red_sandstone"},
        {pos: [4, 0, 2], state: "minecraft:cut_red_sandstone"},
        {pos: [4, 0, 3], state: "minecraft:orange_glazed_terracotta{facing:south}"},
        {pos: [4, 0, 4], state: "minecraft:cut_red_sandstone"},
        {pos: [4, 0, 5], state: "minecraft:cut_red_sandstone"},
        {pos: [5, 0, 0], state: "minecraft:cut_red_sandstone"},
        {pos: [5, 0, 1], state: "minecraft:cut_red_sandstone"},
        {pos: [5, 0, 2], state: "minecraft:cut_red_sandstone"},
        {pos: [5, 0, 3], state: "minecraft:cut_red_sandstone"},
        {pos: [5, 0, 4], state: "minecraft:cut_red_sandstone"},
        {pos: [5, 0, 5], state: "minecraft:cut_red_sandstone"},
        {pos: [5, 0, 6], state: "minecraft:cut_red_sandstone"},
        {pos: [0, 1, 3], state: "minecraft:red_sand"},
        {pos: [0, 1, 4], state: "minecraft:cut_red_sandstone"},
        {pos: [0, 1, 5], state: "minecraft:cut_red_sandstone"},
        {pos: [0, 1, 6], state: "minecraft:cut_red_sandstone"},
        {pos: [1, 1, 6], state: "minecraft:cut_red_sandstone"},
        {pos: [2, 1, 2], state: "minecraft:red_sand"},
        {pos: [2, 1, 3], state: "minecraft:red_sand"},
        {pos: [2, 1, 4], state: "minecraft:red_sandstone_wall{east:tall,north:tall,south:none,up:true,waterlogged:false,west:none}"},
        {pos: [2, 1, 6], state: "minecraft:cut_red_sandstone"},
        {pos: [3, 1, 1], state: "minecraft:red_sand"},
        {pos: [3, 1, 2], state: "minecraft:red_sand"},
        {pos: [3, 1, 3], state: "minecraft:red_sand"},
        {pos: [3, 1, 4], state: "minecraft:red_sand"},
        {pos: [3, 1, 5], state: "minecraft:red_sand"},
        {pos: [3, 1, 6], state: "minecraft:red_sand"},
        {pos: [4, 1, 1], state: "minecraft:red_sand"},
        {pos: [4, 1, 2], state: "minecraft:red_sand"},
        {pos: [4, 1, 3], state: "minecraft:red_sand"},
        {pos: [4, 1, 4], state: "minecraft:red_sand"},
        {pos: [4, 1, 5], state: "minecraft:red_sand"},
        {pos: [5, 1, 0], state: "minecraft:red_sand"},
        {pos: [5, 1, 1], state: "minecraft:cut_red_sandstone"},
        {pos: [5, 1, 2], state: "minecraft:cut_red_sandstone"},
        {pos: [5, 1, 3], state: "minecraft:red_sand"},
        {pos: [5, 1, 4], state: "minecraft:cut_red_sandstone"},
        {pos: [5, 1, 5], state: "minecraft:cut_red_sandstone"},
        {pos: [5, 1, 6], state: "minecraft:cut_red_sandstone"},
        {pos: [0, 2, 3], state: "minecraft:red_sand"},
        {pos: [0, 2, 4], state: "minecraft:cut_red_sandstone"},
        {pos: [0, 2, 5], state: "minecraft:cut_red_sandstone"},
        {pos: [0, 2, 6], state: "minecraft:cut_red_sandstone"},
        {pos: [1, 2, 6], state: "minecraft:cut_red_sandstone"},
        {pos: [2, 2, 2], state: "minecraft:red_sand"},
        {pos: [2, 2, 3], state: "minecraft:red_sand"},
        {pos: [2, 2, 4], state: "minecraft:red_sand"},
        {pos: [2, 2, 6], state: "minecraft:red_sand"},
        {pos: [3, 2, 1], state: "minecraft:red_sand"},
        {pos: [3, 2, 2], state: "minecraft:red_sand"},
        {pos: [3, 2, 3], state: "minecraft:red_sand"},
        {pos: [3, 2, 4], state: "minecraft:red_sand"},
        {pos: [3, 2, 5], state: "minecraft:red_sand"},
        {pos: [3, 2, 6], state: "minecraft:red_sand"},
        {pos: [4, 2, 1], state: "minecraft:red_sand"},
        {pos: [4, 2, 2], state: "minecraft:red_sand"},
        {pos: [4, 2, 3], state: "minecraft:red_sand"},
        {pos: [4, 2, 4], state: "minecraft:red_sand"},
        {pos: [4, 2, 5], state: "minecraft:red_sand"},
        {pos: [5, 2, 0], state: "minecraft:red_sand"},
        {pos: [5, 2, 1], state: "minecraft:red_sand"},
        {pos: [5, 2, 2], state: "minecraft:cut_red_sandstone"},
        {pos: [5, 2, 3], state: "minecraft:red_sand"},
        {pos: [5, 2, 4], state: "minecraft:cut_red_sandstone"},
        {pos: [5, 2, 5], state: "minecraft:cut_red_sandstone"},
        {pos: [5, 2, 6], state: "minecraft:red_sand"},
        {pos: [0, 3, 3], state: "minecraft:red_sand"},
        {pos: [0, 3, 4], state: "minecraft:red_sand"},
        {pos: [0, 3, 5], state: "minecraft:cut_red_sandstone"},
        {pos: [0, 3, 6], state: "minecraft:cut_red_sandstone"},
        {pos: [1, 3, 6], state: "minecraft:cut_red_sandstone"},
        {pos: [2, 3, 3], state: "minecraft:red_sand"},
        {pos: [2, 3, 4], state: "minecraft:red_sand"},
        {pos: [2, 3, 6], state: "minecraft:red_sand"},
        {pos: [3, 3, 2], state: "minecraft:red_sand"},
        {pos: [3, 3, 3], state: "minecraft:red_sand"},
        {pos: [3, 3, 4], state: "minecraft:red_sand"},
        {pos: [3, 3, 5], state: "minecraft:red_sand"},
        {pos: [3, 3, 6], state: "minecraft:red_sand"},
        {pos: [4, 3, 1], state: "minecraft:red_sand"},
        {pos: [4, 3, 2], state: "minecraft:red_sand"},
        {pos: [4, 3, 3], state: "minecraft:red_sand"},
        {pos: [4, 3, 4], state: "minecraft:red_sand"},
        {pos: [4, 3, 5], state: "minecraft:red_sand"},
        {pos: [5, 3, 0], state: "minecraft:red_sand"},
        {pos: [5, 3, 1], state: "minecraft:red_sand"},
        {pos: [5, 3, 2], state: "minecraft:cut_red_sandstone"},
        {pos: [5, 3, 3], state: "minecraft:cut_red_sandstone"},
        {pos: [5, 3, 4], state: "minecraft:cut_red_sandstone"},
        {pos: [5, 3, 5], state: "minecraft:red_sand"},
        {pos: [5, 3, 6], state: "minecraft:red_sand"},
        {pos: [0, 4, 4], state: "minecraft:red_sand"},
        {pos: [0, 4, 5], state: "minecraft:cut_red_sandstone"},
        {pos: [0, 4, 6], state: "minecraft:cut_red_sandstone"},
        {pos: [1, 4, 6], state: "minecraft:red_sand"},
        {pos: [2, 4, 6], state: "minecraft:red_sand"},
        {pos: [3, 4, 4], state: "minecraft:red_sand"},
        {pos: [4, 4, 3], state: "minecraft:red_sand"},
        {pos: [4, 4, 4], state: "minecraft:red_sand"},
        {pos: [4, 4, 5], state: "minecraft:red_sand"},
        {pos: [5, 4, 2], state: "minecraft:red_sand"},
        {pos: [5, 4, 3], state: "minecraft:red_sandstone_wall{east:none,north:low,south:low,up:true,waterlogged:false,west:low}"},
        {pos: [5, 4, 4], state: "minecraft:red_sand"},
        {pos: [5, 4, 5], state: "minecraft:red_sand"},
        {pos: [5, 4, 6], state: "minecraft:red_sand"},
        {pos: [0, 5, 5], state: "minecraft:red_sandstone_wall{east:none,north:none,south:low,up:true,waterlogged:false,west:none}"},
        {pos: [0, 5, 6], state: "minecraft:red_sandstone_wall{east:none,north:low,south:none,up:true,waterlogged:false,west:none}"}
    ],
    entities: [],
    palette: [
        "minecraft:cut_red_sandstone",
        "minecraft:orange_glazed_terracotta{facing:north}",
        "minecraft:orange_glazed_terracotta{facing:west}",
        "minecraft:orange_glazed_terracotta{facing:south}",
        "minecraft:red_sand",
        "minecraft:red_sandstone_wall{east:tall,north:tall,south:none,up:true,waterlogged:false,west:none}",
        "minecraft:red_sandstone_wall{east:none,north:low,south:low,up:true,waterlogged:false,west:low}",
        "minecraft:red_sandstone_wall{east:none,north:none,south:low,up:true,waterlogged:false,west:none}",
        "minecraft:red_sandstone_wall{east:none,north:low,south:none,up:true,waterlogged:false,west:none}"
    ],
    trailiertales_DataVersion: 2
}
