{
    DataVersion: 3953,
    size: [6, 6, 6],
    data: [
        {pos: [0, 0, 1], state: "minecraft:cut_red_sandstone"},
        {pos: [0, 0, 2], state: "minecraft:cut_red_sandstone"},
        {pos: [0, 0, 3], state: "minecraft:cut_red_sandstone"},
        {pos: [1, 0, 0], state: "minecraft:cut_red_sandstone"},
        {pos: [1, 0, 1], state: "minecraft:cut_red_sandstone"},
        {pos: [1, 0, 2], state: "minecraft:cut_red_sandstone"},
        {pos: [1, 0, 3], state: "minecraft:cut_red_sandstone"},
        {pos: [1, 0, 4], state: "minecraft:cut_red_sandstone"},
        {pos: [1, 0, 5], state: "minecraft:cut_red_sandstone"},
        {pos: [2, 0, 0], state: "minecraft:cut_red_sandstone"},
        {pos: [2, 0, 1], state: "minecraft:cut_red_sandstone"},
        {pos: [2, 0, 2], state: "minecraft:orange_glazed_terracotta{facing:north}"},
        {pos: [2, 0, 3], state: "minecraft:cut_red_sandstone"},
        {pos: [2, 0, 4], state: "minecraft:cut_red_sandstone"},
        {pos: [2, 0, 5], state: "minecraft:cut_red_sandstone"},
        {pos: [3, 0, 0], state: "minecraft:cut_red_sandstone"},
        {pos: [3, 0, 1], state: "minecraft:cut_red_sandstone"},
        {pos: [3, 0, 2], state: "minecraft:orange_glazed_terracotta{facing:east}"},
        {pos: [3, 0, 3], state: "minecraft:orange_glazed_terracotta{facing:south}"},
        {pos: [3, 0, 4], state: "minecraft:cut_red_sandstone"},
        {pos: [3, 0, 5], state: "minecraft:cut_red_sandstone"},
        {pos: [4, 0, 1], state: "minecraft:cut_red_sandstone"},
        {pos: [4, 0, 2], state: "minecraft:cut_red_sandstone"},
        {pos: [4, 0, 3], state: "minecraft:cut_red_sandstone"},
        {pos: [4, 0, 4], state: "minecraft:cut_red_sandstone"},
        {pos: [5, 0, 3], state: "minecraft:cut_red_sandstone"},
        {pos: [5, 0, 4], state: "minecraft:cut_red_sandstone"},
        {pos: [0, 1, 1], state: "minecraft:red_sand"},
        {pos: [0, 1, 2], state: "minecraft:cut_red_sandstone"},
        {pos: [0, 1, 3], state: "minecraft:cut_red_sandstone"},
        {pos: [1, 1, 0], state: "minecraft:red_sand"},
        {pos: [1, 1, 1], state: "minecraft:red_sand"},
        {pos: [1, 1, 2], state: "minecraft:red_sandstone_stairs{facing:west,half:top,shape:straight,waterlogged:false}"},
        {pos: [1, 1, 3], state: "minecraft:red_sandstone_stairs{facing:west,half:top,shape:straight,waterlogged:false}"},
        {pos: [1, 1, 4], state: "minecraft:cut_red_sandstone"},
        {pos: [1, 1, 5], state: "minecraft:cut_red_sandstone"},
        {pos: [2, 1, 0], state: "minecraft:cut_red_sandstone"},
        {pos: [2, 1, 1], state: "minecraft:red_sand"},
        {pos: [2, 1, 2], state: "minecraft:red_sand"},
        {pos: [2, 1, 3], state: "minecraft:red_sand"},
        {pos: [2, 1, 4], state: "minecraft:red_sand"},
        {pos: [2, 1, 5], state: "minecraft:red_sand"},
        {pos: [3, 1, 0], state: "minecraft:cut_red_sandstone"},
        {pos: [3, 1, 1], state: "minecraft:red_sand"},
        {pos: [3, 1, 2], state: "minecraft:red_sand"},
        {pos: [3, 1, 3], state: "minecraft:red_sand"},
        {pos: [3, 1, 4], state: "minecraft:red_sand"},
        {pos: [3, 1, 5], state: "minecraft:cut_red_sandstone"},
        {pos: [4, 1, 1], state: "minecraft:cut_red_sandstone"},
        {pos: [4, 1, 2], state: "minecraft:red_sand"},
        {pos: [4, 1, 3], state: "minecraft:red_sandstone_stairs{facing:east,half:top,shape:straight,waterlogged:false}"},
        {pos: [4, 1, 4], state: "minecraft:cut_red_sandstone"},
        {pos: [5, 1, 3], state: "minecraft:cut_red_sandstone"},
        {pos: [5, 1, 4], state: "minecraft:cut_red_sandstone"},
        {pos: [0, 2, 1], state: "minecraft:red_sand"},
        {pos: [0, 2, 2], state: "minecraft:cut_red_sandstone"},
        {pos: [0, 2, 3], state: "minecraft:cut_red_sandstone"},
        {pos: [1, 2, 0], state: "minecraft:red_sand"},
        {pos: [1, 2, 1], state: "minecraft:red_sand"},
        {pos: [1, 2, 2], state: "minecraft:red_sand"},
        {pos: [1, 2, 3], state: "minecraft:red_sand"},
        {pos: [1, 2, 4], state: "minecraft:cut_red_sandstone"},
        {pos: [1, 2, 5], state: "minecraft:cut_red_sandstone"},
        {pos: [2, 2, 0], state: "minecraft:cut_red_sandstone"},
        {pos: [2, 2, 1], state: "minecraft:red_sand"},
        {pos: [2, 2, 2], state: "minecraft:red_sand"},
        {pos: [2, 2, 3], state: "minecraft:red_sand"},
        {pos: [2, 2, 4], state: "minecraft:red_sand"},
        {pos: [2, 2, 5], state: "minecraft:red_sand"},
        {pos: [3, 2, 0], state: "minecraft:cut_red_sandstone"},
        {pos: [3, 2, 1], state: "minecraft:red_sand"},
        {pos: [3, 2, 2], state: "minecraft:red_sand"},
        {pos: [3, 2, 3], state: "minecraft:red_sand"},
        {pos: [3, 2, 4], state: "minecraft:red_sand"},
        {pos: [3, 2, 5], state: "minecraft:cut_red_sandstone"},
        {pos: [4, 2, 1], state: "minecraft:cut_red_sandstone"},
        {pos: [4, 2, 2], state: "minecraft:red_sand"},
        {pos: [4, 2, 3], state: "minecraft:red_sand"},
        {pos: [4, 2, 4], state: "minecraft:cut_red_sandstone"},
        {pos: [5, 2, 3], state: "minecraft:cut_red_sandstone"},
        {pos: [5, 2, 4], state: "minecraft:cut_red_sandstone"},
        {pos: [0, 3, 1], state: "minecraft:red_sand"},
        {pos: [0, 3, 2], state: "minecraft:cut_red_sandstone"},
        {pos: [0, 3, 3], state: "minecraft:cut_red_sandstone"},
        {pos: [1, 3, 0], state: "minecraft:red_sand"},
        {pos: [1, 3, 1], state: "minecraft:red_sand"},
        {pos: [1, 3, 2], state: "minecraft:red_sand"},
        {pos: [1, 3, 3], state: "minecraft:red_sand"},
        {pos: [1, 3, 4], state: "minecraft:cut_red_sandstone"},
        {pos: [1, 3, 5], state: "minecraft:red_sand"},
        {pos: [2, 3, 0], state: "minecraft:red_sand"},
        {pos: [2, 3, 1], state: "minecraft:red_sand"},
        {pos: [2, 3, 2], state: "minecraft:red_sand"},
        {pos: [2, 3, 3], state: "minecraft:red_sand"},
        {pos: [2, 3, 4], state: "minecraft:red_sand"},
        {pos: [2, 3, 5], state: "minecraft:red_sand"},
        {pos: [3, 3, 0], state: "minecraft:cut_red_sandstone"},
        {pos: [3, 3, 1], state: "minecraft:red_sand"},
        {pos: [3, 3, 2], state: "minecraft:red_sand"},
        {pos: [3, 3, 3], state: "minecraft:red_sand"},
        {pos: [3, 3, 4], state: "minecraft:red_sand"},
        {pos: [3, 3, 5], state: "minecraft:cut_red_sandstone"},
        {pos: [4, 3, 1], state: "minecraft:cut_red_sandstone"},
        {pos: [4, 3, 2], state: "minecraft:red_sand"},
        {pos: [4, 3, 3], state: "minecraft:red_sand"},
        {pos: [4, 3, 4], state: "minecraft:cut_red_sandstone"},
        {pos: [5, 3, 3], state: "minecraft:cut_red_sandstone"},
        {pos: [5, 3, 4], state: "minecraft:cut_red_sandstone"},
        {pos: [1, 4, 1], state: "minecraft:red_sand"},
        {pos: [1, 4, 4], state: "minecraft:red_sand"},
        {pos: [2, 4, 0], state: "minecraft:red_sand"},
        {pos: [2, 4, 1], state: "minecraft:red_sand"},
        {pos: [2, 4, 2], state: "minecraft:red_sand"},
        {pos: [2, 4, 3], state: "minecraft:red_sand"},
        {pos: [2, 4, 4], state: "minecraft:red_sand"},
        {pos: [2, 4, 5], state: "minecraft:red_sand"},
        {pos: [3, 4, 0], state: "minecraft:cut_red_sandstone"},
        {pos: [3, 4, 1], state: "minecraft:red_sand"},
        {pos: [3, 4, 2], state: "minecraft:red_sand"},
        {pos: [3, 4, 3], state: "minecraft:red_sand"},
        {pos: [3, 4, 4], state: "minecraft:red_sand"},
        {pos: [3, 4, 5], state: "minecraft:cut_red_sandstone"},
        {pos: [4, 4, 1], state: "minecraft:cut_red_sandstone"},
        {pos: [4, 4, 2], state: "minecraft:red_sand"},
        {pos: [4, 4, 3], state: "minecraft:red_sand"},
        {pos: [3, 5, 0], state: "minecraft:red_sandstone_wall{east:none,north:none,south:none,up:true,waterlogged:false,west:none}"},
        {pos: [3, 5, 5], state: "minecraft:red_sandstone_wall{east:none,north:none,south:none,up:true,waterlogged:false,west:none}"},
        {pos: [4, 5, 1], state: "minecraft:red_sandstone_wall{east:none,north:none,south:none,up:true,waterlogged:false,west:none}"}
    ],
    entities: [],
    palette: [
        "minecraft:cut_red_sandstone",
        "minecraft:orange_glazed_terracotta{facing:north}",
        "minecraft:orange_glazed_terracotta{facing:east}",
        "minecraft:orange_glazed_terracotta{facing:south}",
        "minecraft:red_sand",
        "minecraft:red_sandstone_stairs{facing:west,half:top,shape:straight,waterlogged:false}",
        "minecraft:red_sandstone_stairs{facing:east,half:top,shape:straight,waterlogged:false}",
        "minecraft:red_sandstone_wall{east:none,north:none,south:none,up:true,waterlogged:false,west:none}"
    ],
    trailiertales_DataVersion: 2
}
