{
    DataVersion: 3953,
    size: [9, 5, 10],
    data: [
        {pos: [0, 0, 6], state: "minecraft:cut_red_sandstone"},
        {pos: [1, 0, 5], state: "minecraft:cut_red_sandstone"},
        {pos: [1, 0, 6], state: "minecraft:cut_red_sandstone"},
        {pos: [1, 0, 7], state: "minecraft:cut_red_sandstone"},
        {pos: [2, 0, 0], state: "minecraft:cut_red_sandstone"},
        {pos: [2, 0, 1], state: "minecraft:cut_red_sandstone"},
        {pos: [2, 0, 2], state: "minecraft:cut_red_sandstone"},
        {pos: [2, 0, 5], state: "minecraft:cut_red_sandstone"},
        {pos: [2, 0, 6], state: "minecraft:cut_red_sandstone"},
        {pos: [2, 0, 7], state: "minecraft:cut_red_sandstone"},
        {pos: [2, 0, 8], state: "minecraft:cut_red_sandstone"},
        {pos: [3, 0, 0], state: "minecraft:cut_red_sandstone"},
        {pos: [3, 0, 1], state: "minecraft:cut_red_sandstone"},
        {pos: [3, 0, 2], state: "minecraft:cut_red_sandstone"},
        {pos: [3, 0, 3], state: "minecraft:cut_red_sandstone"},
        {pos: [3, 0, 6], state: "minecraft:cut_red_sandstone"},
        {pos: [3, 0, 7], state: "minecraft:yellow_glazed_terracotta{facing:north}"},
        {pos: [3, 0, 8], state: "minecraft:cut_red_sandstone"},
        {pos: [3, 0, 9], state: "minecraft:cut_red_sandstone"},
        {pos: [4, 0, 0], state: "minecraft:cut_red_sandstone"},
        {pos: [4, 0, 1], state: "minecraft:cut_red_sandstone"},
        {pos: [4, 0, 2], state: "minecraft:cut_red_sandstone"},
        {pos: [4, 0, 3], state: "minecraft:cut_red_sandstone"},
        {pos: [4, 0, 6], state: "minecraft:cut_red_sandstone"},
        {pos: [4, 0, 7], state: "minecraft:yellow_glazed_terracotta{facing:east}"},
        {pos: [4, 0, 8], state: "minecraft:yellow_glazed_terracotta{facing:south}"},
        {pos: [4, 0, 9], state: "minecraft:cut_red_sandstone"},
        {pos: [5, 0, 1], state: "minecraft:cut_red_sandstone"},
        {pos: [5, 0, 2], state: "minecraft:cut_red_sandstone"},
        {pos: [5, 0, 3], state: "minecraft:cut_red_sandstone"},
        {pos: [5, 0, 5], state: "minecraft:cut_red_sandstone"},
        {pos: [5, 0, 6], state: "minecraft:cut_red_sandstone"},
        {pos: [5, 0, 7], state: "minecraft:cut_red_sandstone"},
        {pos: [5, 0, 8], state: "minecraft:cut_red_sandstone"},
        {pos: [5, 0, 9], state: "minecraft:cut_red_sandstone"},
        {pos: [6, 0, 5], state: "minecraft:cut_red_sandstone"},
        {pos: [6, 0, 6], state: "minecraft:yellow_glazed_terracotta{facing:west}"},
        {pos: [6, 0, 7], state: "minecraft:cut_red_sandstone"},
        {pos: [6, 0, 8], state: "minecraft:cut_red_sandstone"},
        {pos: [6, 0, 9], state: "minecraft:cut_red_sandstone"},
        {pos: [7, 0, 4], state: "minecraft:cut_red_sandstone"},
        {pos: [7, 0, 5], state: "minecraft:cut_red_sandstone"},
        {pos: [7, 0, 6], state: "minecraft:cut_red_sandstone"},
        {pos: [7, 0, 7], state: "minecraft:cut_red_sandstone"},
        {pos: [8, 0, 4], state: "minecraft:cut_red_sandstone"},
        {pos: [8, 0, 5], state: "minecraft:cut_red_sandstone"},
        {pos: [0, 1, 6], state: "minecraft:cut_red_sandstone"},
        {pos: [1, 1, 5], state: "minecraft:red_sand"},
        {pos: [1, 1, 6], state: "minecraft:cut_red_sandstone"},
        {pos: [1, 1, 7], state: "minecraft:red_sand"},
        {pos: [2, 1, 0], state: "minecraft:cut_red_sandstone"},
        {pos: [2, 1, 1], state: "minecraft:cut_red_sandstone"},
        {pos: [2, 1, 2], state: "minecraft:cut_red_sandstone"},
        {pos: [2, 1, 5], state: "minecraft:red_sand"},
        {pos: [2, 1, 6], state: "minecraft:red_sand"},
        {pos: [2, 1, 7], state: "minecraft:red_sand"},
        {pos: [2, 1, 8], state: "minecraft:red_sand"},
        {pos: [3, 1, 0], state: "minecraft:red_sand"},
        {pos: [3, 1, 1], state: "minecraft:red_sand"},
        {pos: [3, 1, 2], state: "minecraft:red_sand"},
        {pos: [3, 1, 3], state: "minecraft:red_sand"},
        {pos: [3, 1, 6], state: "minecraft:red_sand"},
        {pos: [3, 1, 7], state: "minecraft:red_sand"},
        {pos: [3, 1, 8], state: "minecraft:red_sand"},
        {pos: [3, 1, 9], state: "minecraft:cut_red_sandstone"},
        {pos: [4, 1, 0], state: "minecraft:cut_red_sandstone"},
        {pos: [4, 1, 1], state: "minecraft:red_sand"},
        {pos: [4, 1, 2], state: "minecraft:red_sand"},
        {pos: [4, 1, 3], state: "minecraft:red_sand"},
        {pos: [4, 1, 6], state: "minecraft:red_sand"},
        {pos: [4, 1, 7], state: "minecraft:red_sand"},
        {pos: [4, 1, 8], state: "minecraft:red_sand"},
        {pos: [4, 1, 9], state: "minecraft:cut_red_sandstone"},
        {pos: [5, 1, 1], state: "minecraft:cut_red_sandstone"},
        {pos: [5, 1, 2], state: "minecraft:red_sandstone_stairs{facing:east,half:top,shape:straight,waterlogged:false}"},
        {pos: [5, 1, 3], state: "minecraft:cut_red_sandstone"},
        {pos: [5, 1, 5], state: "minecraft:red_sand"},
        {pos: [5, 1, 6], state: "minecraft:red_sand"},
        {pos: [5, 1, 7], state: "minecraft:red_sand"},
        {pos: [5, 1, 8], state: "minecraft:cut_red_sandstone"},
        {pos: [5, 1, 9], state: "minecraft:cut_red_sandstone"},
        {pos: [6, 1, 5], state: "minecraft:red_sand"},
        {pos: [6, 1, 6], state: "minecraft:red_sand"},
        {pos: [6, 1, 7], state: "minecraft:red_sand"},
        {pos: [6, 1, 8], state: "minecraft:cut_red_sandstone"},
        {pos: [6, 1, 9], state: "minecraft:cut_red_sandstone"},
        {pos: [7, 1, 4], state: "minecraft:cut_red_sandstone"},
        {pos: [7, 1, 5], state: "minecraft:cut_red_sandstone"},
        {pos: [7, 1, 6], state: "minecraft:red_sand"},
        {pos: [7, 1, 7], state: "minecraft:red_sand"},
        {pos: [8, 1, 4], state: "minecraft:cut_red_sandstone"},
        {pos: [8, 1, 5], state: "minecraft:cut_red_sandstone"},
        {pos: [0, 2, 6], state: "minecraft:cut_red_sandstone"},
        {pos: [1, 2, 5], state: "minecraft:red_sand"},
        {pos: [1, 2, 6], state: "minecraft:red_sand"},
        {pos: [1, 2, 7], state: "minecraft:red_sand"},
        {pos: [2, 2, 0], state: "minecraft:cut_red_sandstone"},
        {pos: [2, 2, 1], state: "minecraft:cut_red_sandstone"},
        {pos: [2, 2, 2], state: "minecraft:cut_red_sandstone"},
        {pos: [2, 2, 5], state: "minecraft:red_sand"},
        {pos: [2, 2, 6], state: "minecraft:red_sand"},
        {pos: [2, 2, 7], state: "minecraft:red_sand"},
        {pos: [2, 2, 8], state: "minecraft:red_sand"},
        {pos: [3, 2, 0], state: "minecraft:red_sand"},
        {pos: [3, 2, 1], state: "minecraft:red_sand"},
        {pos: [3, 2, 2], state: "minecraft:red_sand"},
        {pos: [3, 2, 3], state: "minecraft:red_sand"},
        {pos: [3, 2, 6], state: "minecraft:red_sand"},
        {pos: [3, 2, 7], state: "minecraft:red_sand"},
        {pos: [3, 2, 8], state: "minecraft:cut_red_sandstone"},
        {pos: [3, 2, 9], state: "minecraft:cut_red_sandstone"},
        {pos: [4, 2, 0], state: "minecraft:cut_red_sandstone"},
        {pos: [4, 2, 1], state: "minecraft:red_sand"},
        {pos: [4, 2, 2], state: "minecraft:red_sand"},
        {pos: [4, 2, 3], state: "minecraft:red_sand"},
        {pos: [4, 2, 6], state: "minecraft:red_sand"},
        {pos: [4, 2, 7], state: "minecraft:red_sand"},
        {pos: [4, 2, 8], state: "minecraft:red_sand"},
        {pos: [4, 2, 9], state: "minecraft:red_sand"},
        {pos: [5, 2, 1], state: "minecraft:cut_red_sandstone"},
        {pos: [5, 2, 2], state: "minecraft:red_sand"},
        {pos: [5, 2, 3], state: "minecraft:cut_red_sandstone"},
        {pos: [5, 2, 5], state: "minecraft:red_sand"},
        {pos: [5, 2, 6], state: "minecraft:red_sand"},
        {pos: [5, 2, 7], state: "minecraft:red_sand"},
        {pos: [5, 2, 8], state: "minecraft:red_sand"},
        {pos: [5, 2, 9], state: "minecraft:cut_red_sandstone"},
        {pos: [6, 2, 5], state: "minecraft:red_sand"},
        {pos: [6, 2, 6], state: "minecraft:red_sand"},
        {pos: [6, 2, 7], state: "minecraft:red_sand"},
        {pos: [6, 2, 8], state: "minecraft:red_sand"},
        {pos: [6, 2, 9], state: "minecraft:cut_red_sandstone"},
        {pos: [7, 2, 4], state: "minecraft:cut_red_sandstone"},
        {pos: [7, 2, 5], state: "minecraft:cut_red_sandstone"},
        {pos: [7, 2, 6], state: "minecraft:red_sand"},
        {pos: [7, 2, 7], state: "minecraft:red_sand"},
        {pos: [8, 2, 4], state: "minecraft:cut_red_sandstone"},
        {pos: [8, 2, 5], state: "minecraft:cut_red_sandstone"},
        {pos: [0, 3, 6], state: "minecraft:cut_red_sandstone"},
        {pos: [1, 3, 5], state: "minecraft:red_sand"},
        {pos: [1, 3, 6], state: "minecraft:red_sand"},
        {pos: [1, 3, 7], state: "minecraft:red_sand"},
        {pos: [2, 3, 0], state: "minecraft:red_sand"},
        {pos: [2, 3, 1], state: "minecraft:red_sand"},
        {pos: [2, 3, 2], state: "minecraft:cut_red_sandstone"},
        {pos: [2, 3, 5], state: "minecraft:red_sand"},
        {pos: [2, 3, 6], state: "minecraft:red_sand"},
        {pos: [2, 3, 7], state: "minecraft:red_sand"},
        {pos: [2, 3, 8], state: "minecraft:red_sand"},
        {pos: [3, 3, 0], state: "minecraft:red_sand"},
        {pos: [3, 3, 1], state: "minecraft:red_sand"},
        {pos: [3, 3, 2], state: "minecraft:red_sand"},
        {pos: [3, 3, 3], state: "minecraft:red_sand"},
        {pos: [3, 3, 6], state: "minecraft:red_sand"},
        {pos: [3, 3, 7], state: "minecraft:red_sand"},
        {pos: [3, 3, 8], state: "minecraft:cut_red_sandstone"},
        {pos: [3, 3, 9], state: "minecraft:cut_red_sandstone"},
        {pos: [4, 3, 0], state: "minecraft:red_sand"},
        {pos: [4, 3, 1], state: "minecraft:red_sand"},
        {pos: [4, 3, 2], state: "minecraft:red_sand"},
        {pos: [4, 3, 3], state: "minecraft:red_sand"},
        {pos: [4, 3, 6], state: "minecraft:red_sand"},
        {pos: [4, 3, 7], state: "minecraft:red_sand"},
        {pos: [4, 3, 8], state: "minecraft:red_sand"},
        {pos: [4, 3, 9], state: "minecraft:red_sand"},
        {pos: [5, 3, 1], state: "minecraft:cut_red_sandstone"},
        {pos: [5, 3, 2], state: "minecraft:red_sand"},
        {pos: [5, 3, 3], state: "minecraft:red_sand"},
        {pos: [5, 3, 5], state: "minecraft:red_sand"},
        {pos: [5, 3, 6], state: "minecraft:red_sand"},
        {pos: [5, 3, 7], state: "minecraft:red_sand"},
        {pos: [5, 3, 8], state: "minecraft:red_sand"},
        {pos: [5, 3, 9], state: "minecraft:red_sand"},
        {pos: [6, 3, 5], state: "minecraft:red_sand"},
        {pos: [6, 3, 6], state: "minecraft:red_sand"},
        {pos: [6, 3, 7], state: "minecraft:red_sand"},
        {pos: [6, 3, 8], state: "minecraft:cut_red_sandstone"},
        {pos: [6, 3, 9], state: "minecraft:cut_red_sandstone"},
        {pos: [7, 3, 4], state: "minecraft:cut_red_sandstone"},
        {pos: [7, 3, 5], state: "minecraft:cut_red_sandstone"},
        {pos: [7, 3, 6], state: "minecraft:red_sand"},
        {pos: [7, 3, 7], state: "minecraft:red_sand"},
        {pos: [8, 3, 5], state: "minecraft:cut_red_sandstone"},
        {pos: [0, 4, 5], state: "minecraft:cut_red_sandstone"},
        {pos: [0, 4, 6], state: "minecraft:cut_red_sandstone"},
        {pos: [1, 4, 5], state: "minecraft:cut_red_sandstone"},
        {pos: [1, 4, 6], state: "minecraft:cut_red_sandstone"},
        {pos: [1, 4, 7], state: "minecraft:red_sand"},
        {pos: [2, 4, 1], state: "minecraft:red_sand"},
        {pos: [2, 4, 7], state: "minecraft:red_sand"},
        {pos: [3, 4, 0], state: "minecraft:red_sand"},
        {pos: [3, 4, 1], state: "minecraft:red_sand"},
        {pos: [3, 4, 2], state: "minecraft:red_sand"},
        {pos: [3, 4, 7], state: "minecraft:cut_red_sandstone"},
        {pos: [3, 4, 8], state: "minecraft:cut_red_sandstone"},
        {pos: [4, 4, 0], state: "minecraft:red_sand"},
        {pos: [4, 4, 1], state: "minecraft:red_sand"},
        {pos: [4, 4, 2], state: "minecraft:red_sand"},
        {pos: [4, 4, 7], state: "minecraft:red_sand"},
        {pos: [4, 4, 8], state: "minecraft:red_sand"},
        {pos: [4, 4, 9], state: "minecraft:red_sand"},
        {pos: [5, 4, 1], state: "minecraft:cut_red_sandstone"},
        {pos: [5, 4, 2], state: "minecraft:red_sand"},
        {pos: [5, 4, 6], state: "minecraft:red_sand"},
        {pos: [5, 4, 7], state: "minecraft:red_sand"},
        {pos: [5, 4, 8], state: "minecraft:red_sand"},
        {pos: [5, 4, 9], state: "minecraft:red_sand"},
        {pos: [6, 4, 5], state: "minecraft:red_sand"},
        {pos: [6, 4, 6], state: "minecraft:red_sand"},
        {pos: [6, 4, 7], state: "minecraft:cut_red_sandstone"},
        {pos: [6, 4, 8], state: "minecraft:cut_red_sandstone"},
        {pos: [6, 4, 9], state: "minecraft:cut_red_sandstone"},
        {pos: [7, 4, 4], state: "minecraft:cut_red_sandstone"},
        {pos: [7, 4, 5], state: "minecraft:cut_red_sandstone"},
        {pos: [7, 4, 6], state: "minecraft:red_sand"},
        {pos: [8, 4, 5], state: "minecraft:cut_red_sandstone"}
    ],
    entities: [],
    palette: [
        "minecraft:cut_red_sandstone",
        "minecraft:yellow_glazed_terracotta{facing:north}",
        "minecraft:yellow_glazed_terracotta{facing:east}",
        "minecraft:yellow_glazed_terracotta{facing:south}",
        "minecraft:yellow_glazed_terracotta{facing:west}",
        "minecraft:red_sand",
        "minecraft:red_sandstone_stairs{facing:east,half:top,shape:straight,waterlogged:false}"
    ],
    trailiertales_DataVersion: 2
}
