{
    DataVersion: 3953,
    size: [9, 8, 15],
    data: [
        {pos: [0, 0, 1], state: "minecraft:cut_red_sandstone"},
        {pos: [0, 0, 2], state: "minecraft:cut_red_sandstone"},
        {pos: [0, 0, 3], state: "minecraft:cut_red_sandstone"},
        {pos: [0, 0, 6], state: "minecraft:cut_red_sandstone"},
        {pos: [0, 0, 7], state: "minecraft:cut_red_sandstone"},
        {pos: [0, 0, 8], state: "minecraft:cut_red_sandstone"},
        {pos: [1, 0, 0], state: "minecraft:cut_red_sandstone"},
        {pos: [1, 0, 1], state: "minecraft:yellow_glazed_terracotta{facing:north}"},
        {pos: [1, 0, 2], state: "minecraft:cut_red_sandstone"},
        {pos: [1, 0, 3], state: "minecraft:cut_red_sandstone"},
        {pos: [1, 0, 4], state: "minecraft:cut_red_sandstone"},
        {pos: [1, 0, 5], state: "minecraft:cut_red_sandstone"},
        {pos: [1, 0, 6], state: "minecraft:cut_red_sandstone"},
        {pos: [1, 0, 7], state: "minecraft:cut_red_sandstone"},
        {pos: [1, 0, 8], state: "minecraft:cut_red_sandstone"},
        {pos: [1, 0, 9], state: "minecraft:cut_red_sandstone"},
        {pos: [2, 0, 0], state: "minecraft:cut_red_sandstone"},
        {pos: [2, 0, 1], state: "minecraft:yellow_glazed_terracotta{facing:east}"},
        {pos: [2, 0, 2], state: "minecraft:yellow_glazed_terracotta{facing:south}"},
        {pos: [2, 0, 3], state: "minecraft:cut_red_sandstone"},
        {pos: [2, 0, 4], state: "minecraft:cut_red_sandstone"},
        {pos: [2, 0, 5], state: "minecraft:cut_red_sandstone"},
        {pos: [2, 0, 6], state: "minecraft:cut_red_sandstone"},
        {pos: [2, 0, 7], state: "minecraft:cut_red_sandstone"},
        {pos: [2, 0, 8], state: "minecraft:cut_red_sandstone"},
        {pos: [2, 0, 9], state: "minecraft:cut_red_sandstone"},
        {pos: [3, 0, 0], state: "minecraft:cut_red_sandstone"},
        {pos: [3, 0, 1], state: "minecraft:cut_red_sandstone"},
        {pos: [3, 0, 2], state: "minecraft:cut_red_sandstone"},
        {pos: [3, 0, 3], state: "minecraft:cut_red_sandstone"},
        {pos: [3, 0, 4], state: "minecraft:cut_red_sandstone"},
        {pos: [3, 0, 5], state: "minecraft:cut_red_sandstone"},
        {pos: [3, 0, 6], state: "minecraft:cut_red_sandstone"},
        {pos: [3, 0, 7], state: "minecraft:cut_red_sandstone"},
        {pos: [3, 0, 8], state: "minecraft:cut_red_sandstone"},
        {pos: [3, 0, 9], state: "minecraft:cut_red_sandstone"},
        {pos: [4, 0, 0], state: "minecraft:cut_red_sandstone"},
        {pos: [4, 0, 1], state: "minecraft:cut_red_sandstone"},
        {pos: [4, 0, 2], state: "minecraft:cut_red_sandstone"},
        {pos: [4, 0, 3], state: "minecraft:cut_red_sandstone"},
        {pos: [4, 0, 6], state: "minecraft:cut_red_sandstone"},
        {pos: [4, 0, 7], state: "minecraft:cut_red_sandstone"},
        {pos: [4, 0, 8], state: "minecraft:cut_red_sandstone"},
        {pos: [4, 0, 12], state: "minecraft:cut_red_sandstone"},
        {pos: [4, 0, 13], state: "minecraft:cut_red_sandstone"},
        {pos: [4, 0, 14], state: "minecraft:cut_red_sandstone"},
        {pos: [5, 0, 11], state: "minecraft:cut_red_sandstone"},
        {pos: [5, 0, 12], state: "minecraft:cut_red_sandstone"},
        {pos: [5, 0, 13], state: "minecraft:cut_red_sandstone"},
        {pos: [5, 0, 14], state: "minecraft:cut_red_sandstone"},
        {pos: [6, 0, 10], state: "minecraft:cut_red_sandstone"},
        {pos: [6, 0, 11], state: "minecraft:cut_red_sandstone"},
        {pos: [6, 0, 12], state: "minecraft:orange_glazed_terracotta{facing:north}"},
        {pos: [6, 0, 13], state: "minecraft:orange_glazed_terracotta{facing:west}"},
        {pos: [6, 0, 14], state: "minecraft:cut_red_sandstone"},
        {pos: [7, 0, 9], state: "minecraft:cut_red_sandstone"},
        {pos: [7, 0, 10], state: "minecraft:cut_red_sandstone"},
        {pos: [7, 0, 11], state: "minecraft:cut_red_sandstone"},
        {pos: [7, 0, 12], state: "minecraft:orange_glazed_terracotta{facing:east}"},
        {pos: [7, 0, 13], state: "minecraft:orange_glazed_terracotta{facing:south}"},
        {pos: [7, 0, 14], state: "minecraft:cut_red_sandstone"},
        {pos: [8, 0, 10], state: "minecraft:cut_red_sandstone"},
        {pos: [8, 0, 11], state: "minecraft:cut_red_sandstone"},
        {pos: [8, 0, 12], state: "minecraft:cut_red_sandstone"},
        {pos: [8, 0, 13], state: "minecraft:cut_red_sandstone"},
        {pos: [8, 0, 14], state: "minecraft:cut_red_sandstone"},
        {pos: [0, 1, 1], state: "minecraft:cut_red_sandstone"},
        {pos: [0, 1, 2], state: "minecraft:cut_red_sandstone"},
        {pos: [0, 1, 3], state: "minecraft:cut_red_sandstone"},
        {pos: [0, 1, 6], state: "minecraft:cut_red_sandstone"},
        {pos: [0, 1, 7], state: "minecraft:cut_red_sandstone"},
        {pos: [0, 1, 8], state: "minecraft:cut_red_sandstone"},
        {pos: [1, 1, 0], state: "minecraft:red_sand"},
        {pos: [1, 1, 1], state: "minecraft:red_sand"},
        {pos: [1, 1, 2], state: "minecraft:red_sand"},
        {pos: [1, 1, 3], state: "minecraft:red_sand"},
        {pos: [1, 1, 4], state: "minecraft:red_sand"},
        {pos: [1, 1, 5], state: "minecraft:cut_red_sandstone"},
        {pos: [1, 1, 6], state: "minecraft:red_sand"},
        {pos: [1, 1, 7], state: "minecraft:red_sand"},
        {pos: [1, 1, 8], state: "minecraft:red_sand"},
        {pos: [1, 1, 9], state: "minecraft:cut_red_sandstone"},
        {pos: [2, 1, 0], state: "minecraft:red_sand"},
        {pos: [2, 1, 1], state: "minecraft:red_sand"},
        {pos: [2, 1, 2], state: "minecraft:red_sand"},
        {pos: [2, 1, 3], state: "minecraft:red_sand"},
        {pos: [2, 1, 4], state: "minecraft:red_sand"},
        {pos: [2, 1, 5], state: "minecraft:red_sand"},
        {pos: [2, 1, 6], state: "minecraft:red_sand"},
        {pos: [2, 1, 7], state: "minecraft:red_sand"},
        {pos: [2, 1, 8], state: "minecraft:red_sand"},
        {pos: [2, 1, 9], state: "minecraft:cut_red_sandstone"},
        {pos: [3, 1, 0], state: "minecraft:cut_red_sandstone"},
        {pos: [3, 1, 1], state: "minecraft:red_sandstone_stairs{facing:east,half:top,shape:straight,waterlogged:false}"},
        {pos: [3, 1, 2], state: "minecraft:red_sandstone_stairs{facing:east,half:top,shape:straight,waterlogged:false}"},
        {pos: [3, 1, 3], state: "minecraft:red_sand"},
        {pos: [3, 1, 4], state: "minecraft:red_sand"},
        {pos: [3, 1, 5], state: "minecraft:cut_red_sandstone"},
        {pos: [3, 1, 6], state: "minecraft:red_sand"},
        {pos: [3, 1, 7], state: "minecraft:red_sand"},
        {pos: [3, 1, 8], state: "minecraft:red_sand"},
        {pos: [3, 1, 9], state: "minecraft:cut_red_sandstone"},
        {pos: [4, 1, 0], state: "minecraft:cut_red_sandstone"},
        {pos: [4, 1, 1], state: "minecraft:cut_red_sandstone"},
        {pos: [4, 1, 2], state: "minecraft:cut_red_sandstone"},
        {pos: [4, 1, 3], state: "minecraft:red_sand"},
        {pos: [4, 1, 6], state: "minecraft:cut_red_sandstone"},
        {pos: [4, 1, 7], state: "minecraft:red_sand"},
        {pos: [4, 1, 8], state: "minecraft:cut_red_sandstone"},
        {pos: [4, 1, 12], state: "minecraft:cut_red_sandstone"},
        {pos: [4, 1, 13], state: "minecraft:cut_red_sandstone"},
        {pos: [4, 1, 14], state: "minecraft:cut_red_sandstone"},
        {pos: [5, 1, 11], state: "minecraft:red_sand"},
        {pos: [5, 1, 12], state: "minecraft:red_sand"},
        {pos: [5, 1, 13], state: "minecraft:red_sand"},
        {pos: [5, 1, 14], state: "minecraft:cut_red_sandstone"},
        {pos: [6, 1, 10], state: "minecraft:red_sand"},
        {pos: [6, 1, 11], state: "minecraft:red_sand"},
        {pos: [6, 1, 12], state: "minecraft:red_sand"},
        {pos: [6, 1, 13], state: "minecraft:red_sand"},
        {pos: [6, 1, 14], state: "minecraft:cut_red_sandstone"},
        {pos: [7, 1, 9], state: "minecraft:red_sand"},
        {pos: [7, 1, 10], state: "minecraft:red_sand"},
        {pos: [7, 1, 11], state: "minecraft:red_sandstone_stairs{facing:east,half:top,shape:straight,waterlogged:false}"},
        {pos: [7, 1, 12], state: "minecraft:red_sandstone_stairs{facing:east,half:top,shape:straight,waterlogged:false}"},
        {pos: [7, 1, 13], state: "minecraft:ladder{facing:north,waterlogged:false}"},
        {pos: [7, 1, 14], state: "minecraft:cut_red_sandstone"},
        {pos: [8, 1, 10], state: "minecraft:red_sand"},
        {pos: [8, 1, 11], state: "minecraft:cut_red_sandstone"},
        {pos: [8, 1, 12], state: "minecraft:cut_red_sandstone"},
        {pos: [8, 1, 13], state: "minecraft:cut_red_sandstone"},
        {pos: [8, 1, 14], state: "minecraft:cut_red_sandstone"},
        {pos: [0, 2, 1], state: "minecraft:cut_red_sandstone"},
        {pos: [0, 2, 2], state: "minecraft:cut_red_sandstone"},
        {pos: [0, 2, 3], state: "minecraft:cut_red_sandstone"},
        {pos: [0, 2, 6], state: "minecraft:cut_red_sandstone"},
        {pos: [0, 2, 7], state: "minecraft:cut_red_sandstone"},
        {pos: [0, 2, 8], state: "minecraft:cut_red_sandstone"},
        {pos: [1, 2, 0], state: "minecraft:red_sand"},
        {pos: [1, 2, 1], state: "minecraft:red_sand"},
        {pos: [1, 2, 2], state: "minecraft:red_sand"},
        {pos: [1, 2, 3], state: "minecraft:red_sand"},
        {pos: [1, 2, 4], state: "minecraft:red_sand"},
        {pos: [1, 2, 5], state: "minecraft:cut_red_sandstone"},
        {pos: [1, 2, 6], state: "minecraft:red_sand"},
        {pos: [1, 2, 7], state: "minecraft:red_sand"},
        {pos: [1, 2, 8], state: "minecraft:red_sand"},
        {pos: [1, 2, 9], state: "minecraft:cut_red_sandstone"},
        {pos: [2, 2, 0], state: "minecraft:red_sand"},
        {pos: [2, 2, 1], state: "minecraft:red_sand"},
        {pos: [2, 2, 2], state: "minecraft:red_sand"},
        {pos: [2, 2, 3], state: "minecraft:red_sand"},
        {pos: [2, 2, 4], state: "minecraft:red_sand"},
        {pos: [2, 2, 5], state: "minecraft:red_sand"},
        {pos: [2, 2, 6], state: "minecraft:red_sand"},
        {pos: [2, 2, 7], state: "minecraft:red_sand"},
        {pos: [2, 2, 8], state: "minecraft:red_sand"},
        {pos: [2, 2, 9], state: "minecraft:cut_red_sandstone"},
        {pos: [3, 2, 0], state: "minecraft:cut_red_sandstone"},
        {pos: [3, 2, 1], state: "minecraft:red_sand"},
        {pos: [3, 2, 2], state: "minecraft:red_sand"},
        {pos: [3, 2, 3], state: "minecraft:red_sand"},
        {pos: [3, 2, 4], state: "minecraft:red_sand"},
        {pos: [3, 2, 5], state: "minecraft:cut_red_sandstone"},
        {pos: [3, 2, 6], state: "minecraft:red_sand"},
        {pos: [3, 2, 7], state: "minecraft:red_sand"},
        {pos: [3, 2, 8], state: "minecraft:red_sand"},
        {pos: [3, 2, 9], state: "minecraft:cut_red_sandstone"},
        {pos: [4, 2, 0], state: "minecraft:cut_red_sandstone"},
        {pos: [4, 2, 1], state: "minecraft:cut_red_sandstone"},
        {pos: [4, 2, 2], state: "minecraft:cut_red_sandstone"},
        {pos: [4, 2, 3], state: "minecraft:red_sand"},
        {pos: [4, 2, 6], state: "minecraft:cut_red_sandstone"},
        {pos: [4, 2, 7], state: "minecraft:red_sand"},
        {pos: [4, 2, 8], state: "minecraft:red_sand"},
        {pos: [4, 2, 12], state: "minecraft:cut_red_sandstone"},
        {pos: [4, 2, 13], state: "minecraft:cut_red_sandstone"},
        {pos: [4, 2, 14], state: "minecraft:cut_red_sandstone"},
        {pos: [5, 2, 11], state: "minecraft:red_sand"},
        {pos: [5, 2, 12], state: "minecraft:red_sand"},
        {pos: [5, 2, 13], state: "minecraft:red_sand"},
        {pos: [5, 2, 14], state: "minecraft:cut_red_sandstone"},
        {pos: [6, 2, 10], state: "minecraft:red_sand"},
        {pos: [6, 2, 11], state: "minecraft:red_sand"},
        {pos: [6, 2, 12], state: "minecraft:red_sand"},
        {pos: [6, 2, 13], state: "minecraft:red_sand"},
        {pos: [6, 2, 14], state: "minecraft:cut_red_sandstone"},
        {pos: [7, 2, 9], state: "minecraft:red_sand"},
        {pos: [7, 2, 10], state: "minecraft:red_sand"},
        {pos: [7, 2, 11], state: "minecraft:red_sand"},
        {pos: [7, 2, 12], state: "minecraft:red_sand"},
        {pos: [7, 2, 13], state: "minecraft:ladder{facing:north,waterlogged:false}"},
        {pos: [7, 2, 14], state: "minecraft:cut_red_sandstone"},
        {pos: [8, 2, 10], state: "minecraft:red_sand"},
        {pos: [8, 2, 11], state: "minecraft:cut_red_sandstone"},
        {pos: [8, 2, 12], state: "minecraft:cut_red_sandstone"},
        {pos: [8, 2, 13], state: "minecraft:cut_red_sandstone"},
        {pos: [8, 2, 14], state: "minecraft:cut_red_sandstone"},
        {pos: [0, 3, 1], state: "minecraft:cut_red_sandstone"},
        {pos: [0, 3, 2], state: "minecraft:cut_red_sandstone"},
        {pos: [0, 3, 3], state: "minecraft:cut_red_sandstone"},
        {pos: [0, 3, 6], state: "minecraft:red_sand"},
        {pos: [0, 3, 7], state: "minecraft:cut_red_sandstone"},
        {pos: [0, 3, 8], state: "minecraft:cut_red_sandstone"},
        {pos: [1, 3, 0], state: "minecraft:red_sand"},
        {pos: [1, 3, 1], state: "minecraft:red_sand"},
        {pos: [1, 3, 2], state: "minecraft:red_sand"},
        {pos: [1, 3, 3], state: "minecraft:red_sand"},
        {pos: [1, 3, 4], state: "minecraft:red_sand"},
        {pos: [1, 3, 5], state: "minecraft:cut_red_sandstone"},
        {pos: [1, 3, 6], state: "minecraft:red_sand"},
        {pos: [1, 3, 7], state: "minecraft:red_sand"},
        {pos: [1, 3, 8], state: "minecraft:red_sand"},
        {pos: [1, 3, 9], state: "minecraft:cut_red_sandstone"},
        {pos: [2, 3, 0], state: "minecraft:red_sand"},
        {pos: [2, 3, 1], state: "minecraft:red_sand"},
        {pos: [2, 3, 2], state: "minecraft:red_sand"},
        {pos: [2, 3, 3], state: "minecraft:red_sand"},
        {pos: [2, 3, 4], state: "minecraft:red_sand"},
        {pos: [2, 3, 5], state: "minecraft:cut_red_sandstone"},
        {pos: [2, 3, 6], state: "minecraft:red_sand"},
        {pos: [2, 3, 7], state: "minecraft:red_sand"},
        {pos: [2, 3, 8], state: "minecraft:red_sand"},
        {pos: [2, 3, 9], state: "minecraft:cut_red_sandstone"},
        {pos: [3, 3, 0], state: "minecraft:cut_red_sandstone"},
        {pos: [3, 3, 1], state: "minecraft:red_sand"},
        {pos: [3, 3, 2], state: "minecraft:red_sand"},
        {pos: [3, 3, 3], state: "minecraft:red_sand"},
        {pos: [3, 3, 4], state: "minecraft:red_sand"},
        {pos: [3, 3, 5], state: "minecraft:cut_red_sandstone"},
        {pos: [3, 3, 6], state: "minecraft:red_sand"},
        {pos: [3, 3, 7], state: "minecraft:red_sand"},
        {pos: [3, 3, 8], state: "minecraft:red_sand"},
        {pos: [3, 3, 9], state: "minecraft:cut_red_sandstone"},
        {pos: [4, 3, 0], state: "minecraft:cut_red_sandstone"},
        {pos: [4, 3, 1], state: "minecraft:cut_red_sandstone"},
        {pos: [4, 3, 2], state: "minecraft:red_sand"},
        {pos: [4, 3, 3], state: "minecraft:red_sand"},
        {pos: [4, 3, 6], state: "minecraft:cut_red_sandstone"},
        {pos: [4, 3, 7], state: "minecraft:cut_red_sandstone"},
        {pos: [4, 3, 8], state: "minecraft:red_sand"},
        {pos: [4, 3, 12], state: "minecraft:cut_red_sandstone"},
        {pos: [4, 3, 13], state: "minecraft:cut_red_sandstone"},
        {pos: [4, 3, 14], state: "minecraft:cut_red_sandstone"},
        {pos: [5, 3, 11], state: "minecraft:red_sand"},
        {pos: [5, 3, 12], state: "minecraft:red_sand"},
        {pos: [5, 3, 13], state: "minecraft:red_sand"},
        {pos: [5, 3, 14], state: "minecraft:cut_red_sandstone"},
        {pos: [6, 3, 10], state: "minecraft:red_sand"},
        {pos: [6, 3, 11], state: "minecraft:red_sand"},
        {pos: [6, 3, 12], state: "minecraft:cut_red_sandstone"},
        {pos: [6, 3, 13], state: "minecraft:cut_red_sandstone"},
        {pos: [6, 3, 14], state: "minecraft:cut_red_sandstone"},
        {pos: [7, 3, 10], state: "minecraft:red_sand"},
        {pos: [7, 3, 11], state: "minecraft:red_sand"},
        {pos: [7, 3, 12], state: "minecraft:cut_red_sandstone"},
        {pos: [7, 3, 13], state: "minecraft:ladder{facing:north,waterlogged:false}"},
        {pos: [7, 3, 14], state: "minecraft:cut_red_sandstone"},
        {pos: [8, 3, 10], state: "minecraft:red_sand"},
        {pos: [8, 3, 11], state: "minecraft:cut_red_sandstone"},
        {pos: [8, 3, 12], state: "minecraft:cut_red_sandstone"},
        {pos: [8, 3, 13], state: "minecraft:cut_red_sandstone"},
        {pos: [8, 3, 14], state: "minecraft:cut_red_sandstone"},
        {pos: [0, 4, 1], state: "minecraft:cut_red_sandstone"},
        {pos: [0, 4, 2], state: "minecraft:cut_red_sandstone"},
        {pos: [0, 4, 3], state: "minecraft:cut_red_sandstone"},
        {pos: [0, 4, 7], state: "minecraft:red_sand"},
        {pos: [0, 4, 8], state: "minecraft:red_sand"},
        {pos: [1, 4, 0], state: "minecraft:red_sand"},
        {pos: [1, 4, 1], state: "minecraft:red_sand"},
        {pos: [1, 4, 2], state: "minecraft:red_sand"},
        {pos: [1, 4, 3], state: "minecraft:red_sand"},
        {pos: [1, 4, 4], state: "minecraft:red_sand"},
        {pos: [1, 4, 5], state: "minecraft:red_sand"},
        {pos: [1, 4, 6], state: "minecraft:red_sand"},
        {pos: [1, 4, 7], state: "minecraft:cut_red_sandstone"},
        {pos: [1, 4, 8], state: "minecraft:cut_red_sandstone"},
        {pos: [1, 4, 9], state: "minecraft:cut_red_sandstone"},
        {pos: [2, 4, 1], state: "minecraft:red_sand"},
        {pos: [2, 4, 2], state: "minecraft:red_sand"},
        {pos: [2, 4, 3], state: "minecraft:red_sand"},
        {pos: [2, 4, 4], state: "minecraft:red_sand"},
        {pos: [2, 4, 5], state: "minecraft:red_sand"},
        {pos: [2, 4, 6], state: "minecraft:cut_red_sandstone"},
        {pos: [2, 4, 7], state: "minecraft:cut_red_sandstone"},
        {pos: [2, 4, 8], state: "minecraft:cut_red_sandstone"},
        {pos: [2, 4, 9], state: "minecraft:cut_red_sandstone"},
        {pos: [3, 4, 2], state: "minecraft:red_sand"},
        {pos: [3, 4, 3], state: "minecraft:red_sand"},
        {pos: [3, 4, 6], state: "minecraft:cut_red_sandstone"},
        {pos: [3, 4, 7], state: "minecraft:cut_red_sandstone"},
        {pos: [3, 4, 8], state: "minecraft:red_sand"},
        {pos: [3, 4, 9], state: "minecraft:red_sand"},
        {pos: [4, 4, 6], state: "minecraft:red_sand"},
        {pos: [4, 4, 7], state: "minecraft:red_sand"},
        {pos: [4, 4, 8], state: "minecraft:red_sand"},
        {pos: [4, 4, 12], state: "minecraft:cut_red_sandstone"},
        {pos: [4, 4, 13], state: "minecraft:cut_red_sandstone"},
        {pos: [4, 4, 14], state: "minecraft:cut_red_sandstone"},
        {pos: [5, 4, 12], state: "minecraft:red_sand"},
        {pos: [5, 4, 13], state: "minecraft:red_sand"},
        {pos: [5, 4, 14], state: "minecraft:cut_red_sandstone"},
        {pos: [6, 4, 11], state: "minecraft:red_sand"},
        {pos: [6, 4, 12], state: "minecraft:red_sand"},
        {pos: [6, 4, 13], state: "minecraft:red_sand"},
        {pos: [6, 4, 14], state: "minecraft:red_sand"},
        {pos: [7, 4, 10], state: "minecraft:red_sand"},
        {pos: [7, 4, 11], state: "minecraft:red_sand"},
        {pos: [7, 4, 12], state: "minecraft:red_sand"},
        {pos: [7, 4, 13], state: "minecraft:ladder{facing:north,waterlogged:false}"},
        {pos: [7, 4, 14], state: "minecraft:cut_red_sandstone"},
        {pos: [8, 4, 10], state: "minecraft:red_sand"},
        {pos: [8, 4, 11], state: "minecraft:cut_red_sandstone"},
        {pos: [8, 4, 12], state: "minecraft:cut_red_sandstone"},
        {pos: [8, 4, 13], state: "minecraft:cut_red_sandstone"},
        {pos: [8, 4, 14], state: "minecraft:cut_red_sandstone"},
        {pos: [0, 5, 1], state: "minecraft:red_sand"},
        {pos: [0, 5, 2], state: "minecraft:cut_red_sandstone"},
        {pos: [0, 5, 3], state: "minecraft:cut_red_sandstone"},
        {pos: [0, 5, 8], state: "minecraft:red_sand"},
        {pos: [1, 5, 1], state: "minecraft:red_sand"},
        {pos: [1, 5, 2], state: "minecraft:red_sand"},
        {pos: [1, 5, 3], state: "minecraft:red_sand"},
        {pos: [1, 5, 4], state: "minecraft:red_sand"},
        {pos: [1, 5, 6], state: "minecraft:red_sand"},
        {pos: [1, 5, 7], state: "minecraft:red_sand"},
        {pos: [1, 5, 8], state: "minecraft:red_sand"},
        {pos: [1, 5, 9], state: "minecraft:red_sand"},
        {pos: [2, 5, 2], state: "minecraft:red_sand"},
        {pos: [2, 5, 3], state: "minecraft:red_sand"},
        {pos: [2, 5, 6], state: "minecraft:red_sand"},
        {pos: [2, 5, 7], state: "minecraft:red_sand"},
        {pos: [2, 5, 8], state: "minecraft:red_sand"},
        {pos: [2, 5, 9], state: "minecraft:red_sand"},
        {pos: [3, 5, 6], state: "minecraft:red_sand"},
        {pos: [3, 5, 7], state: "minecraft:red_sand"},
        {pos: [4, 5, 12], state: "minecraft:cut_red_sandstone"},
        {pos: [4, 5, 13], state: "minecraft:cut_red_sandstone"},
        {pos: [4, 5, 14], state: "minecraft:cut_red_sandstone"},
        {pos: [5, 5, 12], state: "minecraft:red_sand"},
        {pos: [5, 5, 13], state: "minecraft:red_sand"},
        {pos: [5, 5, 14], state: "minecraft:cut_red_sandstone"},
        {pos: [6, 5, 12], state: "minecraft:red_sand"},
        {pos: [6, 5, 13], state: "minecraft:red_sand"},
        {pos: [6, 5, 14], state: "minecraft:red_sand"},
        {pos: [7, 5, 11], state: "minecraft:red_sand"},
        {pos: [7, 5, 12], state: "minecraft:red_sand"},
        {pos: [7, 5, 13], state: "minecraft:red_sand"},
        {pos: [7, 5, 14], state: "minecraft:cut_red_sandstone"},
        {pos: [8, 5, 11], state: "minecraft:red_sand"},
        {pos: [8, 5, 12], state: "minecraft:cut_red_sandstone"},
        {pos: [8, 5, 13], state: "minecraft:cut_red_sandstone"},
        {pos: [8, 5, 14], state: "minecraft:cut_red_sandstone"},
        {pos: [0, 6, 2], state: "minecraft:cut_red_sandstone"},
        {pos: [0, 6, 3], state: "minecraft:cut_red_sandstone"},
        {pos: [4, 6, 12], state: "minecraft:cut_red_sandstone"},
        {pos: [4, 6, 13], state: "minecraft:cut_red_sandstone"},
        {pos: [4, 6, 14], state: "minecraft:cut_red_sandstone"},
        {pos: [5, 6, 13], state: "minecraft:red_sand"},
        {pos: [5, 6, 14], state: "minecraft:cut_red_sandstone"},
        {pos: [6, 6, 12], state: "minecraft:red_sand"},
        {pos: [6, 6, 13], state: "minecraft:red_sand"},
        {pos: [6, 6, 14], state: "minecraft:red_sand"},
        {pos: [7, 6, 12], state: "minecraft:red_sand"},
        {pos: [7, 6, 13], state: "minecraft:red_sand"},
        {pos: [7, 6, 14], state: "minecraft:red_sand"},
        {pos: [8, 6, 12], state: "minecraft:red_sand"},
        {pos: [8, 6, 13], state: "minecraft:cut_red_sandstone"},
        {pos: [8, 6, 14], state: "minecraft:cut_red_sandstone"},
        {pos: [0, 7, 2], state: "minecraft:red_sandstone_wall{east:none,north:none,south:tall,up:true,waterlogged:false,west:none}"},
        {pos: [0, 7, 3], state: "minecraft:red_sandstone_wall{east:none,north:low,south:none,up:true,waterlogged:false,west:none}"},
        {pos: [4, 7, 14], state: "minecraft:red_sandstone_wall{east:low,north:none,south:none,up:true,waterlogged:false,west:none}"},
        {pos: [5, 7, 14], state: "minecraft:red_sandstone_wall{east:none,north:none,south:none,up:true,waterlogged:false,west:low}"},
        {pos: [8, 7, 13], state: "minecraft:red_sandstone_wall{east:none,north:none,south:none,up:true,waterlogged:false,west:none}"}
    ],
    entities: [],
    palette: [
        "minecraft:cut_red_sandstone",
        "minecraft:yellow_glazed_terracotta{facing:north}",
        "minecraft:yellow_glazed_terracotta{facing:east}",
        "minecraft:yellow_glazed_terracotta{facing:south}",
        "minecraft:orange_glazed_terracotta{facing:north}",
        "minecraft:orange_glazed_terracotta{facing:west}",
        "minecraft:orange_glazed_terracotta{facing:east}",
        "minecraft:orange_glazed_terracotta{facing:south}",
        "minecraft:red_sand",
        "minecraft:red_sandstone_stairs{facing:east,half:top,shape:straight,waterlogged:false}",
        "minecraft:ladder{facing:north,waterlogged:false}",
        "minecraft:red_sandstone_wall{east:none,north:none,south:tall,up:true,waterlogged:false,west:none}",
        "minecraft:red_sandstone_wall{east:none,north:low,south:none,up:true,waterlogged:false,west:none}",
        "minecraft:red_sandstone_wall{east:low,north:none,south:none,up:true,waterlogged:false,west:none}",
        "minecraft:red_sandstone_wall{east:none,north:none,south:none,up:true,waterlogged:false,west:low}",
        "minecraft:red_sandstone_wall{east:none,north:none,south:none,up:true,waterlogged:false,west:none}"
    ],
    trailiertales_DataVersion: 2
}
