{
    DataVersion: 3953,
    size: [14, 6, 15],
    data: [
        {pos: [0, 0, 7], state: "minecraft:cut_red_sandstone"},
        {pos: [0, 0, 8], state: "minecraft:cut_red_sandstone"},
        {pos: [0, 0, 9], state: "minecraft:cut_red_sandstone"},
        {pos: [1, 0, 6], state: "minecraft:cut_red_sandstone"},
        {pos: [1, 0, 7], state: "minecraft:cut_red_sandstone"},
        {pos: [1, 0, 8], state: "minecraft:cut_red_sandstone"},
        {pos: [2, 0, 2], state: "minecraft:cut_red_sandstone"},
        {pos: [2, 0, 3], state: "minecraft:cut_red_sandstone"},
        {pos: [2, 0, 4], state: "minecraft:cut_red_sandstone"},
        {pos: [2, 0, 7], state: "minecraft:cut_red_sandstone"},
        {pos: [2, 0, 8], state: "minecraft:cut_red_sandstone"},
        {pos: [3, 0, 1], state: "minecraft:cut_red_sandstone"},
        {pos: [3, 0, 2], state: "minecraft:cut_red_sandstone"},
        {pos: [3, 0, 3], state: "minecraft:cut_red_sandstone"},
        {pos: [3, 0, 4], state: "minecraft:cut_red_sandstone"},
        {pos: [3, 0, 5], state: "minecraft:cut_red_sandstone"},
        {pos: [3, 0, 10], state: "minecraft:cut_red_sandstone"},
        {pos: [3, 0, 11], state: "minecraft:cut_red_sandstone"},
        {pos: [3, 0, 12], state: "minecraft:cut_red_sandstone"},
        {pos: [4, 0, 0], state: "minecraft:cut_red_sandstone"},
        {pos: [4, 0, 1], state: "minecraft:cut_red_sandstone"},
        {pos: [4, 0, 2], state: "minecraft:cut_red_sandstone"},
        {pos: [4, 0, 3], state: "minecraft:cut_red_sandstone"},
        {pos: [4, 0, 4], state: "minecraft:cut_red_sandstone"},
        {pos: [4, 0, 5], state: "minecraft:cut_red_sandstone"},
        {pos: [4, 0, 6], state: "minecraft:cut_red_sandstone"},
        {pos: [4, 0, 9], state: "minecraft:cut_red_sandstone"},
        {pos: [4, 0, 10], state: "minecraft:cut_red_sandstone"},
        {pos: [4, 0, 11], state: "minecraft:cut_red_sandstone"},
        {pos: [4, 0, 12], state: "minecraft:cut_red_sandstone"},
        {pos: [4, 0, 13], state: "minecraft:cut_red_sandstone"},
        {pos: [5, 0, 0], state: "minecraft:cut_red_sandstone"},
        {pos: [5, 0, 1], state: "minecraft:cut_red_sandstone"},
        {pos: [5, 0, 2], state: "minecraft:cut_red_sandstone"},
        {pos: [5, 0, 3], state: "minecraft:cut_red_sandstone"},
        {pos: [5, 0, 4], state: "minecraft:cut_red_sandstone"},
        {pos: [5, 0, 5], state: "minecraft:cut_red_sandstone"},
        {pos: [5, 0, 6], state: "minecraft:cut_red_sandstone"},
        {pos: [5, 0, 8], state: "minecraft:cut_red_sandstone"},
        {pos: [5, 0, 9], state: "minecraft:cut_red_sandstone"},
        {pos: [5, 0, 10], state: "minecraft:yellow_glazed_terracotta{facing:north}"},
        {pos: [5, 0, 11], state: "minecraft:cut_red_sandstone"},
        {pos: [5, 0, 12], state: "minecraft:cut_red_sandstone"},
        {pos: [5, 0, 13], state: "minecraft:cut_red_sandstone"},
        {pos: [6, 0, 0], state: "minecraft:cut_red_sandstone"},
        {pos: [6, 0, 1], state: "minecraft:cut_red_sandstone"},
        {pos: [6, 0, 2], state: "minecraft:cut_red_sandstone"},
        {pos: [6, 0, 4], state: "minecraft:cut_red_sandstone"},
        {pos: [6, 0, 5], state: "minecraft:cut_red_sandstone"},
        {pos: [6, 0, 6], state: "minecraft:cut_red_sandstone"},
        {pos: [6, 0, 7], state: "minecraft:cut_red_sandstone"},
        {pos: [6, 0, 8], state: "minecraft:cut_red_sandstone"},
        {pos: [6, 0, 9], state: "minecraft:cut_red_sandstone"},
        {pos: [6, 0, 10], state: "minecraft:yellow_glazed_terracotta{facing:east}"},
        {pos: [6, 0, 11], state: "minecraft:yellow_glazed_terracotta{facing:south}"},
        {pos: [6, 0, 12], state: "minecraft:cut_red_sandstone"},
        {pos: [6, 0, 13], state: "minecraft:cut_red_sandstone"},
        {pos: [6, 0, 14], state: "minecraft:cut_red_sandstone"},
        {pos: [7, 0, 1], state: "minecraft:cut_red_sandstone"},
        {pos: [7, 0, 2], state: "minecraft:cut_red_sandstone"},
        {pos: [7, 0, 4], state: "minecraft:cut_red_sandstone"},
        {pos: [7, 0, 6], state: "minecraft:cut_red_sandstone"},
        {pos: [7, 0, 7], state: "minecraft:cut_red_sandstone"},
        {pos: [7, 0, 8], state: "minecraft:cut_red_sandstone"},
        {pos: [7, 0, 9], state: "minecraft:cut_red_sandstone"},
        {pos: [7, 0, 10], state: "minecraft:cut_red_sandstone"},
        {pos: [7, 0, 11], state: "minecraft:cut_red_sandstone"},
        {pos: [7, 0, 12], state: "minecraft:cut_red_sandstone"},
        {pos: [7, 0, 13], state: "minecraft:cut_red_sandstone"},
        {pos: [7, 0, 14], state: "minecraft:cut_red_sandstone"},
        {pos: [8, 0, 1], state: "minecraft:cut_red_sandstone"},
        {pos: [8, 0, 2], state: "minecraft:cut_red_sandstone"},
        {pos: [8, 0, 3], state: "minecraft:cut_red_sandstone"},
        {pos: [8, 0, 4], state: "minecraft:cut_red_sandstone"},
        {pos: [8, 0, 5], state: "minecraft:cut_red_sandstone"},
        {pos: [8, 0, 9], state: "minecraft:cut_red_sandstone"},
        {pos: [8, 0, 10], state: "minecraft:cut_red_sandstone"},
        {pos: [8, 0, 11], state: "minecraft:cut_red_sandstone"},
        {pos: [8, 0, 12], state: "minecraft:cut_red_sandstone"},
        {pos: [8, 0, 13], state: "minecraft:cut_red_sandstone"},
        {pos: [9, 0, 1], state: "minecraft:cut_red_sandstone"},
        {pos: [9, 0, 2], state: "minecraft:cut_red_sandstone"},
        {pos: [9, 0, 3], state: "minecraft:cut_red_sandstone"},
        {pos: [9, 0, 4], state: "minecraft:cut_red_sandstone"},
        {pos: [9, 0, 5], state: "minecraft:cut_red_sandstone"},
        {pos: [9, 0, 10], state: "minecraft:cut_red_sandstone"},
        {pos: [9, 0, 11], state: "minecraft:cut_red_sandstone"},
        {pos: [9, 0, 12], state: "minecraft:cut_red_sandstone"},
        {pos: [10, 0, 3], state: "minecraft:cut_red_sandstone"},
        {pos: [10, 0, 4], state: "minecraft:cut_red_sandstone"},
        {pos: [10, 0, 7], state: "minecraft:cut_red_sandstone"},
        {pos: [10, 0, 8], state: "minecraft:cut_red_sandstone"},
        {pos: [11, 0, 6], state: "minecraft:cut_red_sandstone"},
        {pos: [11, 0, 7], state: "minecraft:cut_red_sandstone"},
        {pos: [11, 0, 8], state: "minecraft:cut_red_sandstone"},
        {pos: [12, 0, 7], state: "minecraft:cut_red_sandstone"},
        {pos: [12, 0, 8], state: "minecraft:cut_red_sandstone"},
        {pos: [13, 0, 7], state: "minecraft:cut_red_sandstone"},
        {pos: [0, 1, 7], state: "minecraft:cut_red_sandstone"},
        {pos: [0, 1, 8], state: "minecraft:cut_red_sandstone"},
        {pos: [0, 1, 9], state: "minecraft:red_sand"},
        {pos: [1, 1, 6], state: "minecraft:red_sand"},
        {pos: [1, 1, 7], state: "minecraft:cut_red_sandstone"},
        {pos: [1, 1, 8], state: "minecraft:cut_red_sandstone"},
        {pos: [2, 1, 2], state: "minecraft:red_sand"},
        {pos: [2, 1, 3], state: "minecraft:red_sand"},
        {pos: [2, 1, 4], state: "minecraft:red_sand"},
        {pos: [2, 1, 7], state: "minecraft:red_sand"},
        {pos: [2, 1, 8], state: "minecraft:red_sand"},
        {pos: [3, 1, 1], state: "minecraft:red_sand"},
        {pos: [3, 1, 2], state: "minecraft:red_sand"},
        {pos: [3, 1, 3], state: "minecraft:red_sand"},
        {pos: [3, 1, 4], state: "minecraft:red_sand"},
        {pos: [3, 1, 5], state: "minecraft:red_sand"},
        {pos: [3, 1, 10], state: "minecraft:cut_red_sandstone"},
        {pos: [3, 1, 11], state: "minecraft:cut_red_sandstone"},
        {pos: [3, 1, 12], state: "minecraft:red_sand"},
        {pos: [4, 1, 0], state: "minecraft:cut_red_sandstone"},
        {pos: [4, 1, 1], state: "minecraft:cut_red_sandstone"},
        {pos: [4, 1, 2], state: "minecraft:red_terracotta"},
        {pos: [4, 1, 3], state: "minecraft:red_terracotta"},
        {pos: [4, 1, 4], state: "minecraft:red_terracotta"},
        {pos: [4, 1, 5], state: "minecraft:cut_red_sandstone"},
        {pos: [4, 1, 6], state: "minecraft:red_sand"},
        {pos: [4, 1, 9], state: "minecraft:cut_red_sandstone"},
        {pos: [4, 1, 10], state: "minecraft:red_sandstone_stairs{facing:west,half:top,shape:straight,waterlogged:false}"},
        {pos: [4, 1, 11], state: "minecraft:red_sandstone_stairs{facing:west,half:top,shape:straight,waterlogged:false}"},
        {pos: [4, 1, 12], state: "minecraft:cut_red_sandstone"},
        {pos: [4, 1, 13], state: "minecraft:red_sand"},
        {pos: [5, 1, 0], state: "minecraft:red_sand"},
        {pos: [5, 1, 1], state: "minecraft:red_sand"},
        {pos: [5, 1, 2], state: "minecraft:red_sand"},
        {pos: [5, 1, 3], state: "minecraft:red_sand"},
        {pos: [5, 1, 4], state: "minecraft:red_sand"},
        {pos: [5, 1, 5], state: "minecraft:red_sand"},
        {pos: [5, 1, 6], state: "minecraft:red_sand"},
        {pos: [5, 1, 8], state: "minecraft:cut_red_sandstone"},
        {pos: [5, 1, 9], state: "minecraft:red_sand"},
        {pos: [5, 1, 10], state: "minecraft:red_sand"},
        {pos: [5, 1, 11], state: "minecraft:red_sand"},
        {pos: [5, 1, 12], state: "minecraft:cut_red_sandstone"},
        {pos: [5, 1, 13], state: "minecraft:red_sand"},
        {pos: [6, 1, 0], state: "minecraft:red_sand"},
        {pos: [6, 1, 1], state: "minecraft:red_sand"},
        {pos: [6, 1, 2], state: "minecraft:red_sand"},
        {pos: [6, 1, 4], state: "minecraft:red_sand"},
        {pos: [6, 1, 5], state: "minecraft:red_sand"},
        {pos: [6, 1, 6], state: "minecraft:red_sand"},
        {pos: [6, 1, 7], state: "minecraft:red_sand"},
        {pos: [6, 1, 8], state: "minecraft:red_sand"},
        {pos: [6, 1, 9], state: "minecraft:red_sand"},
        {pos: [6, 1, 10], state: "minecraft:red_sand"},
        {pos: [6, 1, 11], state: "minecraft:red_sand"},
        {pos: [6, 1, 12], state: "minecraft:cut_red_sandstone"},
        {pos: [6, 1, 13], state: "minecraft:red_sand"},
        {pos: [6, 1, 14], state: "minecraft:red_sand"},
        {pos: [7, 1, 1], state: "minecraft:red_sand"},
        {pos: [7, 1, 2], state: "minecraft:red_sand"},
        {pos: [7, 1, 4], state: "minecraft:red_sand"},
        {pos: [7, 1, 6], state: "minecraft:red_sand"},
        {pos: [7, 1, 7], state: "minecraft:red_sand"},
        {pos: [7, 1, 8], state: "minecraft:cut_red_sandstone"},
        {pos: [7, 1, 9], state: "minecraft:red_sand"},
        {pos: [7, 1, 10], state: "minecraft:red_sand"},
        {pos: [7, 1, 11], state: "minecraft:red_sand"},
        {pos: [7, 1, 12], state: "minecraft:cut_red_sandstone"},
        {pos: [7, 1, 13], state: "minecraft:red_sand"},
        {pos: [7, 1, 14], state: "minecraft:red_sand"},
        {pos: [8, 1, 1], state: "minecraft:cut_red_sandstone"},
        {pos: [8, 1, 2], state: "minecraft:cut_red_sandstone"},
        {pos: [8, 1, 3], state: "minecraft:red_terracotta"},
        {pos: [8, 1, 4], state: "minecraft:cut_red_sandstone"},
        {pos: [8, 1, 5], state: "minecraft:cut_red_sandstone"},
        {pos: [8, 1, 9], state: "minecraft:cut_red_sandstone"},
        {pos: [8, 1, 10], state: "minecraft:red_sand"},
        {pos: [8, 1, 11], state: "minecraft:red_sand"},
        {pos: [8, 1, 12], state: "minecraft:red_sand"},
        {pos: [8, 1, 13], state: "minecraft:red_sand"},
        {pos: [9, 1, 1], state: "minecraft:red_sand"},
        {pos: [9, 1, 2], state: "minecraft:red_sand"},
        {pos: [9, 1, 3], state: "minecraft:red_sand"},
        {pos: [9, 1, 4], state: "minecraft:red_sand"},
        {pos: [9, 1, 5], state: "minecraft:red_sand"},
        {pos: [9, 1, 10], state: "minecraft:cut_red_sandstone"},
        {pos: [9, 1, 11], state: "minecraft:cut_red_sandstone"},
        {pos: [9, 1, 12], state: "minecraft:red_sand"},
        {pos: [10, 1, 3], state: "minecraft:red_sand"},
        {pos: [10, 1, 4], state: "minecraft:red_sand"},
        {pos: [10, 1, 7], state: "minecraft:red_sand"},
        {pos: [10, 1, 8], state: "minecraft:red_sand"},
        {pos: [11, 1, 6], state: "minecraft:red_sand"},
        {pos: [11, 1, 7], state: "minecraft:cut_red_sandstone"},
        {pos: [11, 1, 8], state: "minecraft:cut_red_sandstone"},
        {pos: [12, 1, 7], state: "minecraft:cut_red_sandstone"},
        {pos: [12, 1, 8], state: "minecraft:cut_red_sandstone"},
        {pos: [13, 1, 7], state: "minecraft:red_sand"},
        {pos: [0, 2, 7], state: "minecraft:cut_red_sandstone"},
        {pos: [0, 2, 8], state: "minecraft:cut_red_sandstone"},
        {pos: [0, 2, 9], state: "minecraft:red_sand"},
        {pos: [1, 2, 6], state: "minecraft:red_sand"},
        {pos: [1, 2, 7], state: "minecraft:cut_red_sandstone"},
        {pos: [1, 2, 8], state: "minecraft:cut_red_sandstone"},
        {pos: [2, 2, 2], state: "minecraft:red_sand"},
        {pos: [2, 2, 3], state: "minecraft:red_sand"},
        {pos: [2, 2, 4], state: "minecraft:red_sand"},
        {pos: [2, 2, 7], state: "minecraft:red_sand"},
        {pos: [2, 2, 8], state: "minecraft:red_sand"},
        {pos: [3, 2, 1], state: "minecraft:red_sand"},
        {pos: [3, 2, 2], state: "minecraft:red_sand"},
        {pos: [3, 2, 3], state: "minecraft:red_sand"},
        {pos: [3, 2, 4], state: "minecraft:red_sand"},
        {pos: [3, 2, 5], state: "minecraft:red_sand"},
        {pos: [3, 2, 10], state: "minecraft:cut_red_sandstone"},
        {pos: [3, 2, 11], state: "minecraft:cut_red_sandstone"},
        {pos: [3, 2, 12], state: "minecraft:red_sand"},
        {pos: [4, 2, 0], state: "minecraft:cut_red_sandstone"},
        {pos: [4, 2, 1], state: "minecraft:cut_red_sandstone"},
        {pos: [4, 2, 2], state: "minecraft:cut_red_sandstone"},
        {pos: [4, 2, 3], state: "minecraft:cut_red_sandstone"},
        {pos: [4, 2, 4], state: "minecraft:cut_red_sandstone"},
        {pos: [4, 2, 5], state: "minecraft:cut_red_sandstone"},
        {pos: [4, 2, 6], state: "minecraft:red_sand"},
        {pos: [4, 2, 9], state: "minecraft:cut_red_sandstone"},
        {pos: [4, 2, 10], state: "minecraft:red_sand"},
        {pos: [4, 2, 11], state: "minecraft:red_sand"},
        {pos: [4, 2, 12], state: "minecraft:cut_red_sandstone"},
        {pos: [4, 2, 13], state: "minecraft:red_sand"},
        {pos: [5, 2, 0], state: "minecraft:red_sand"},
        {pos: [5, 2, 1], state: "minecraft:red_sand"},
        {pos: [5, 2, 2], state: "minecraft:red_sand"},
        {pos: [5, 2, 3], state: "minecraft:red_sand"},
        {pos: [5, 2, 4], state: "minecraft:red_sand"},
        {pos: [5, 2, 5], state: "minecraft:red_sand"},
        {pos: [5, 2, 6], state: "minecraft:red_sand"},
        {pos: [5, 2, 8], state: "minecraft:cut_red_sandstone"},
        {pos: [5, 2, 9], state: "minecraft:red_sand"},
        {pos: [5, 2, 10], state: "minecraft:red_sand"},
        {pos: [5, 2, 11], state: "minecraft:red_sand"},
        {pos: [5, 2, 12], state: "minecraft:cut_red_sandstone"},
        {pos: [5, 2, 13], state: "minecraft:red_sand"},
        {pos: [6, 2, 0], state: "minecraft:red_sand"},
        {pos: [6, 2, 1], state: "minecraft:red_sand"},
        {pos: [6, 2, 2], state: "minecraft:red_sand"},
        {pos: [6, 2, 4], state: "minecraft:red_sand"},
        {pos: [6, 2, 5], state: "minecraft:red_sand"},
        {pos: [6, 2, 6], state: "minecraft:red_sand"},
        {pos: [6, 2, 7], state: "minecraft:red_sand"},
        {pos: [6, 2, 8], state: "minecraft:red_sand"},
        {pos: [6, 2, 9], state: "minecraft:red_sand"},
        {pos: [6, 2, 10], state: "minecraft:red_sand"},
        {pos: [6, 2, 11], state: "minecraft:red_sand"},
        {pos: [6, 2, 12], state: "minecraft:cut_red_sandstone"},
        {pos: [6, 2, 13], state: "minecraft:red_sand"},
        {pos: [6, 2, 14], state: "minecraft:red_sand"},
        {pos: [7, 2, 1], state: "minecraft:red_sand"},
        {pos: [7, 2, 2], state: "minecraft:red_sand"},
        {pos: [7, 2, 4], state: "minecraft:red_sand"},
        {pos: [7, 2, 6], state: "minecraft:red_sand"},
        {pos: [7, 2, 7], state: "minecraft:red_sand"},
        {pos: [7, 2, 8], state: "minecraft:cut_red_sandstone"},
        {pos: [7, 2, 9], state: "minecraft:red_sand"},
        {pos: [7, 2, 10], state: "minecraft:red_sand"},
        {pos: [7, 2, 11], state: "minecraft:red_sand"},
        {pos: [7, 2, 12], state: "minecraft:cut_red_sandstone"},
        {pos: [7, 2, 13], state: "minecraft:red_sand"},
        {pos: [7, 2, 14], state: "minecraft:red_sand"},
        {pos: [8, 2, 1], state: "minecraft:cut_red_sandstone"},
        {pos: [8, 2, 2], state: "minecraft:red_terracotta"},
        {pos: [8, 2, 3], state: "minecraft:cut_red_sandstone"},
        {pos: [8, 2, 4], state: "minecraft:red_terracotta"},
        {pos: [8, 2, 5], state: "minecraft:cut_red_sandstone"},
        {pos: [8, 2, 9], state: "minecraft:cut_red_sandstone"},
        {pos: [8, 2, 10], state: "minecraft:red_sand"},
        {pos: [8, 2, 11], state: "minecraft:red_sand"},
        {pos: [8, 2, 12], state: "minecraft:red_sand"},
        {pos: [8, 2, 13], state: "minecraft:red_sand"},
        {pos: [9, 2, 1], state: "minecraft:red_sand"},
        {pos: [9, 2, 2], state: "minecraft:red_sand"},
        {pos: [9, 2, 3], state: "minecraft:red_sand"},
        {pos: [9, 2, 4], state: "minecraft:red_sand"},
        {pos: [9, 2, 5], state: "minecraft:red_sand"},
        {pos: [9, 2, 10], state: "minecraft:cut_red_sandstone"},
        {pos: [9, 2, 11], state: "minecraft:red_sand"},
        {pos: [9, 2, 12], state: "minecraft:red_sand"},
        {pos: [10, 2, 3], state: "minecraft:red_sand"},
        {pos: [10, 2, 4], state: "minecraft:red_sand"},
        {pos: [10, 2, 7], state: "minecraft:red_sand"},
        {pos: [10, 2, 8], state: "minecraft:red_sand"},
        {pos: [11, 2, 6], state: "minecraft:red_sand"},
        {pos: [11, 2, 7], state: "minecraft:cut_red_sandstone"},
        {pos: [11, 2, 8], state: "minecraft:cut_red_sandstone"},
        {pos: [12, 2, 7], state: "minecraft:cut_red_sandstone"},
        {pos: [12, 2, 8], state: "minecraft:cut_red_sandstone"},
        {pos: [13, 2, 7], state: "minecraft:red_sand"},
        {pos: [0, 3, 7], state: "minecraft:cut_red_sandstone"},
        {pos: [0, 3, 8], state: "minecraft:cut_red_sandstone"},
        {pos: [0, 3, 9], state: "minecraft:red_sand"},
        {pos: [1, 3, 6], state: "minecraft:red_sand"},
        {pos: [1, 3, 7], state: "minecraft:cut_red_sandstone"},
        {pos: [1, 3, 8], state: "minecraft:cut_red_sandstone"},
        {pos: [2, 3, 2], state: "minecraft:red_sand"},
        {pos: [2, 3, 3], state: "minecraft:red_sand"},
        {pos: [2, 3, 4], state: "minecraft:red_sand"},
        {pos: [2, 3, 7], state: "minecraft:red_sand"},
        {pos: [2, 3, 8], state: "minecraft:red_sand"},
        {pos: [3, 3, 1], state: "minecraft:red_sand"},
        {pos: [3, 3, 2], state: "minecraft:red_sand"},
        {pos: [3, 3, 3], state: "minecraft:red_sand"},
        {pos: [3, 3, 4], state: "minecraft:red_sand"},
        {pos: [3, 3, 5], state: "minecraft:red_sand"},
        {pos: [3, 3, 10], state: "minecraft:cut_red_sandstone"},
        {pos: [3, 3, 11], state: "minecraft:cut_red_sandstone"},
        {pos: [3, 3, 12], state: "minecraft:red_sand"},
        {pos: [4, 3, 0], state: "minecraft:red_sand"},
        {pos: [4, 3, 1], state: "minecraft:cut_red_sandstone"},
        {pos: [4, 3, 2], state: "minecraft:red_terracotta"},
        {pos: [4, 3, 3], state: "minecraft:red_terracotta"},
        {pos: [4, 3, 4], state: "minecraft:red_terracotta"},
        {pos: [4, 3, 5], state: "minecraft:cut_red_sandstone"},
        {pos: [4, 3, 6], state: "minecraft:red_sand"},
        {pos: [4, 3, 9], state: "minecraft:red_sand"},
        {pos: [4, 3, 10], state: "minecraft:red_sand"},
        {pos: [4, 3, 11], state: "minecraft:red_sand"},
        {pos: [4, 3, 12], state: "minecraft:cut_red_sandstone"},
        {pos: [5, 3, 0], state: "minecraft:red_sand"},
        {pos: [5, 3, 1], state: "minecraft:red_sand"},
        {pos: [5, 3, 2], state: "minecraft:red_sand"},
        {pos: [5, 3, 3], state: "minecraft:red_sand"},
        {pos: [5, 3, 4], state: "minecraft:red_sand"},
        {pos: [5, 3, 5], state: "minecraft:red_sand"},
        {pos: [5, 3, 6], state: "minecraft:red_sand"},
        {pos: [5, 3, 8], state: "minecraft:cut_red_sandstone"},
        {pos: [5, 3, 9], state: "minecraft:red_sand"},
        {pos: [5, 3, 10], state: "minecraft:red_sand"},
        {pos: [5, 3, 11], state: "minecraft:red_sand"},
        {pos: [5, 3, 12], state: "minecraft:cut_red_sandstone"},
        {pos: [5, 3, 13], state: "minecraft:red_sand"},
        {pos: [6, 3, 0], state: "minecraft:red_sand"},
        {pos: [6, 3, 1], state: "minecraft:red_sand"},
        {pos: [6, 3, 2], state: "minecraft:red_sand"},
        {pos: [6, 3, 4], state: "minecraft:red_sand"},
        {pos: [6, 3, 5], state: "minecraft:red_sand"},
        {pos: [6, 3, 6], state: "minecraft:red_sand"},
        {pos: [6, 3, 7], state: "minecraft:red_sand"},
        {pos: [6, 3, 8], state: "minecraft:cut_red_sandstone"},
        {pos: [6, 3, 9], state: "minecraft:red_sand"},
        {pos: [6, 3, 10], state: "minecraft:red_sand"},
        {pos: [6, 3, 11], state: "minecraft:red_sand"},
        {pos: [6, 3, 12], state: "minecraft:cut_red_sandstone"},
        {pos: [6, 3, 13], state: "minecraft:red_sand"},
        {pos: [7, 3, 1], state: "minecraft:red_sand"},
        {pos: [7, 3, 2], state: "minecraft:red_sand"},
        {pos: [7, 3, 4], state: "minecraft:red_sand"},
        {pos: [7, 3, 6], state: "minecraft:red_sand"},
        {pos: [7, 3, 7], state: "minecraft:red_sand"},
        {pos: [7, 3, 8], state: "minecraft:cut_red_sandstone"},
        {pos: [7, 3, 9], state: "minecraft:red_sand"},
        {pos: [7, 3, 10], state: "minecraft:red_sand"},
        {pos: [7, 3, 11], state: "minecraft:red_sand"},
        {pos: [7, 3, 12], state: "minecraft:cut_red_sandstone"},
        {pos: [7, 3, 13], state: "minecraft:red_sand"},
        {pos: [8, 3, 1], state: "minecraft:cut_red_sandstone"},
        {pos: [8, 3, 2], state: "minecraft:cut_red_sandstone"},
        {pos: [8, 3, 3], state: "minecraft:red_terracotta"},
        {pos: [8, 3, 4], state: "minecraft:cut_red_sandstone"},
        {pos: [8, 3, 5], state: "minecraft:red_sand"},
        {pos: [8, 3, 9], state: "minecraft:cut_red_sandstone"},
        {pos: [8, 3, 10], state: "minecraft:red_sand"},
        {pos: [8, 3, 11], state: "minecraft:red_sand"},
        {pos: [8, 3, 12], state: "minecraft:cut_red_sandstone"},
        {pos: [8, 3, 13], state: "minecraft:red_sand"},
        {pos: [9, 3, 1], state: "minecraft:red_sand"},
        {pos: [9, 3, 2], state: "minecraft:red_sand"},
        {pos: [9, 3, 3], state: "minecraft:red_sand"},
        {pos: [9, 3, 4], state: "minecraft:red_sand"},
        {pos: [9, 3, 5], state: "minecraft:red_sand"},
        {pos: [9, 3, 10], state: "minecraft:cut_red_sandstone"},
        {pos: [9, 3, 11], state: "minecraft:cut_red_sandstone"},
        {pos: [9, 3, 12], state: "minecraft:red_sand"},
        {pos: [10, 3, 3], state: "minecraft:red_sand"},
        {pos: [10, 3, 4], state: "minecraft:red_sand"},
        {pos: [10, 3, 7], state: "minecraft:red_sand"},
        {pos: [10, 3, 8], state: "minecraft:red_sand"},
        {pos: [11, 3, 6], state: "minecraft:red_sand"},
        {pos: [11, 3, 7], state: "minecraft:cut_red_sandstone"},
        {pos: [11, 3, 8], state: "minecraft:cut_red_sandstone"},
        {pos: [12, 3, 7], state: "minecraft:cut_red_sandstone"},
        {pos: [12, 3, 8], state: "minecraft:cut_red_sandstone"},
        {pos: [13, 3, 7], state: "minecraft:red_sand"},
        {pos: [0, 4, 7], state: "minecraft:cut_red_sandstone"},
        {pos: [0, 4, 8], state: "minecraft:cut_red_sandstone"},
        {pos: [1, 4, 7], state: "minecraft:red_sand"},
        {pos: [1, 4, 8], state: "minecraft:cut_red_sandstone"},
        {pos: [3, 4, 3], state: "minecraft:red_sand"},
        {pos: [3, 4, 4], state: "minecraft:red_sand"},
        {pos: [4, 4, 2], state: "minecraft:red_sand"},
        {pos: [4, 4, 3], state: "minecraft:cut_red_sandstone"},
        {pos: [4, 4, 4], state: "minecraft:cut_red_sandstone"},
        {pos: [4, 4, 5], state: "minecraft:cut_red_sandstone"},
        {pos: [4, 4, 11], state: "minecraft:red_sand"},
        {pos: [5, 4, 2], state: "minecraft:red_sand"},
        {pos: [5, 4, 3], state: "minecraft:red_sand"},
        {pos: [5, 4, 4], state: "minecraft:red_sand"},
        {pos: [5, 4, 9], state: "minecraft:cut_red_sandstone"},
        {pos: [5, 4, 10], state: "minecraft:cut_red_sandstone"},
        {pos: [5, 4, 11], state: "minecraft:red_sand"},
        {pos: [6, 4, 9], state: "minecraft:cut_red_sandstone"},
        {pos: [6, 4, 10], state: "minecraft:cut_red_sandstone"},
        {pos: [6, 4, 11], state: "minecraft:cut_red_sandstone"},
        {pos: [6, 4, 12], state: "minecraft:cut_red_sandstone"},
        {pos: [6, 4, 13], state: "minecraft:red_sand"},
        {pos: [7, 4, 4], state: "minecraft:red_sand"},
        {pos: [7, 4, 10], state: "minecraft:cut_red_sandstone"},
        {pos: [7, 4, 11], state: "minecraft:cut_red_sandstone"},
        {pos: [7, 4, 12], state: "minecraft:cut_red_sandstone"},
        {pos: [7, 4, 13], state: "minecraft:red_sand"},
        {pos: [8, 4, 2], state: "minecraft:cut_red_sandstone"},
        {pos: [8, 4, 3], state: "minecraft:cut_red_sandstone"},
        {pos: [8, 4, 4], state: "minecraft:cut_red_sandstone"},
        {pos: [8, 4, 5], state: "minecraft:red_sand"},
        {pos: [8, 4, 10], state: "minecraft:red_sand"},
        {pos: [8, 4, 11], state: "minecraft:red_sand"},
        {pos: [8, 4, 12], state: "minecraft:cut_red_sandstone"},
        {pos: [9, 4, 3], state: "minecraft:red_sand"},
        {pos: [9, 4, 4], state: "minecraft:red_sand"},
        {pos: [9, 4, 12], state: "minecraft:red_sand"},
        {pos: [10, 4, 7], state: "minecraft:red_sand"},
        {pos: [11, 4, 7], state: "minecraft:cut_red_sandstone"},
        {pos: [11, 4, 8], state: "minecraft:cut_red_sandstone"},
        {pos: [12, 4, 7], state: "minecraft:cut_red_sandstone"},
        {pos: [12, 4, 8], state: "minecraft:cut_red_sandstone"},
        {pos: [4, 5, 3], state: "minecraft:red_sand"},
        {pos: [4, 5, 4], state: "minecraft:red_sand"},
        {pos: [4, 5, 5], state: "minecraft:red_sandstone_wall{east:none,north:low,south:none,up:true,waterlogged:false,west:none}"},
        {pos: [8, 5, 2], state: "minecraft:red_sandstone_wall{east:none,north:none,south:low,up:true,waterlogged:false,west:none}"},
        {pos: [8, 5, 3], state: "minecraft:red_sandstone_wall{east:none,north:low,south:none,up:true,waterlogged:false,west:none}"},
        {pos: [11, 5, 7], state: "minecraft:cut_red_sandstone"},
        {pos: [11, 5, 8], state: "minecraft:cut_red_sandstone"}
    ],
    entities: [],
    palette: [
        "minecraft:cut_red_sandstone",
        "minecraft:yellow_glazed_terracotta{facing:north}",
        "minecraft:yellow_glazed_terracotta{facing:east}",
        "minecraft:yellow_glazed_terracotta{facing:south}",
        "minecraft:red_sand",
        "minecraft:red_terracotta",
        "minecraft:red_sandstone_stairs{facing:west,half:top,shape:straight,waterlogged:false}",
        "minecraft:red_sandstone_wall{east:none,north:low,south:none,up:true,waterlogged:false,west:none}",
        "minecraft:red_sandstone_wall{east:none,north:none,south:low,up:true,waterlogged:false,west:none}"
    ],
    trailiertales_DataVersion: 2
}
