{
    DataVersion: 3953,
    size: [14, 12, 12],
    data: [
        {pos: [0, 0, 4], state: "minecraft:cut_red_sandstone"},
        {pos: [1, 0, 3], state: "minecraft:cut_red_sandstone"},
        {pos: [1, 0, 4], state: "minecraft:cut_red_sandstone"},
        {pos: [1, 0, 5], state: "minecraft:cut_red_sandstone"},
        {pos: [1, 0, 8], state: "minecraft:cut_red_sandstone"},
        {pos: [1, 0, 9], state: "minecraft:cut_red_sandstone"},
        {pos: [1, 0, 10], state: "minecraft:cut_red_sandstone"},
        {pos: [2, 0, 3], state: "minecraft:cut_red_sandstone"},
        {pos: [2, 0, 4], state: "minecraft:red_terracotta"},
        {pos: [2, 0, 5], state: "minecraft:cut_red_sandstone"},
        {pos: [2, 0, 7], state: "minecraft:cut_red_sandstone"},
        {pos: [2, 0, 8], state: "minecraft:cut_red_sandstone"},
        {pos: [2, 0, 9], state: "minecraft:cut_red_sandstone"},
        {pos: [2, 0, 10], state: "minecraft:cut_red_sandstone"},
        {pos: [3, 0, 2], state: "minecraft:cut_red_sandstone"},
        {pos: [3, 0, 3], state: "minecraft:cut_red_sandstone"},
        {pos: [3, 0, 4], state: "minecraft:cut_red_sandstone"},
        {pos: [3, 0, 5], state: "minecraft:cut_red_sandstone"},
        {pos: [3, 0, 6], state: "minecraft:cut_red_sandstone"},
        {pos: [3, 0, 7], state: "minecraft:red_terracotta"},
        {pos: [3, 0, 8], state: "minecraft:red_terracotta"},
        {pos: [3, 0, 9], state: "minecraft:cut_red_sandstone"},
        {pos: [3, 0, 10], state: "minecraft:cut_red_sandstone"},
        {pos: [4, 0, 2], state: "minecraft:cut_red_sandstone"},
        {pos: [4, 0, 3], state: "minecraft:cut_red_sandstone"},
        {pos: [4, 0, 4], state: "minecraft:cut_red_sandstone"},
        {pos: [4, 0, 5], state: "minecraft:cut_red_sandstone"},
        {pos: [4, 0, 6], state: "minecraft:cut_red_sandstone"},
        {pos: [4, 0, 7], state: "minecraft:red_terracotta"},
        {pos: [4, 0, 8], state: "minecraft:red_terracotta"},
        {pos: [4, 0, 9], state: "minecraft:cut_red_sandstone"},
        {pos: [5, 0, 1], state: "minecraft:cut_red_sandstone"},
        {pos: [5, 0, 2], state: "minecraft:cut_red_sandstone"},
        {pos: [5, 0, 3], state: "minecraft:cut_red_sandstone"},
        {pos: [5, 0, 6], state: "minecraft:cut_red_sandstone"},
        {pos: [5, 0, 7], state: "minecraft:cut_red_sandstone"},
        {pos: [5, 0, 8], state: "minecraft:cut_red_sandstone"},
        {pos: [5, 0, 9], state: "minecraft:cut_red_sandstone"},
        {pos: [5, 0, 10], state: "minecraft:cut_red_sandstone"},
        {pos: [6, 0, 0], state: "minecraft:cut_red_sandstone"},
        {pos: [6, 0, 1], state: "minecraft:cut_red_sandstone"},
        {pos: [6, 0, 2], state: "minecraft:cut_red_sandstone"},
        {pos: [6, 0, 8], state: "minecraft:cut_red_sandstone"},
        {pos: [6, 0, 9], state: "minecraft:cut_red_sandstone"},
        {pos: [6, 0, 10], state: "minecraft:cut_red_sandstone"},
        {pos: [6, 0, 11], state: "minecraft:cut_red_sandstone"},
        {pos: [7, 0, 0], state: "minecraft:cut_red_sandstone"},
        {pos: [7, 0, 1], state: "minecraft:cut_red_sandstone"},
        {pos: [7, 0, 2], state: "minecraft:cut_red_sandstone"},
        {pos: [7, 0, 3], state: "minecraft:yellow_glazed_terracotta{facing:west}"},
        {pos: [7, 0, 4], state: "minecraft:cut_red_sandstone"},
        {pos: [7, 0, 9], state: "minecraft:cut_red_sandstone"},
        {pos: [7, 0, 10], state: "minecraft:cut_red_sandstone"},
        {pos: [7, 0, 11], state: "minecraft:cut_red_sandstone"},
        {pos: [8, 0, 0], state: "minecraft:cut_red_sandstone"},
        {pos: [8, 0, 1], state: "minecraft:cut_red_sandstone"},
        {pos: [8, 0, 2], state: "minecraft:cut_red_sandstone"},
        {pos: [8, 0, 3], state: "minecraft:yellow_glazed_terracotta{facing:south}"},
        {pos: [8, 0, 4], state: "minecraft:cut_red_sandstone"},
        {pos: [8, 0, 6], state: "minecraft:cut_red_sandstone"},
        {pos: [8, 0, 7], state: "minecraft:cut_red_sandstone"},
        {pos: [8, 0, 8], state: "minecraft:cut_red_sandstone"},
        {pos: [8, 0, 9], state: "minecraft:cut_red_sandstone"},
        {pos: [9, 0, 1], state: "minecraft:cut_red_sandstone"},
        {pos: [9, 0, 2], state: "minecraft:cut_red_sandstone"},
        {pos: [9, 0, 3], state: "minecraft:cut_red_sandstone"},
        {pos: [9, 0, 4], state: "minecraft:cut_red_sandstone"},
        {pos: [9, 0, 5], state: "minecraft:cut_red_sandstone"},
        {pos: [9, 0, 6], state: "minecraft:cut_red_sandstone"},
        {pos: [9, 0, 7], state: "minecraft:cut_red_sandstone"},
        {pos: [9, 0, 8], state: "minecraft:cut_red_sandstone"},
        {pos: [9, 0, 9], state: "minecraft:cut_red_sandstone"},
        {pos: [10, 0, 3], state: "minecraft:cut_red_sandstone"},
        {pos: [10, 0, 4], state: "minecraft:cut_red_sandstone"},
        {pos: [10, 0, 5], state: "minecraft:cut_red_sandstone"},
        {pos: [10, 0, 6], state: "minecraft:cut_red_sandstone"},
        {pos: [10, 0, 7], state: "minecraft:red_terracotta"},
        {pos: [10, 0, 8], state: "minecraft:red_terracotta"},
        {pos: [10, 0, 9], state: "minecraft:cut_red_sandstone"},
        {pos: [11, 0, 3], state: "minecraft:red_terracotta"},
        {pos: [11, 0, 4], state: "minecraft:red_terracotta"},
        {pos: [11, 0, 5], state: "minecraft:cut_red_sandstone"},
        {pos: [11, 0, 6], state: "minecraft:cut_red_sandstone"},
        {pos: [11, 0, 7], state: "minecraft:red_terracotta"},
        {pos: [11, 0, 8], state: "minecraft:red_terracotta"},
        {pos: [11, 0, 9], state: "minecraft:cut_red_sandstone"},
        {pos: [12, 0, 3], state: "minecraft:red_terracotta"},
        {pos: [12, 0, 4], state: "minecraft:red_terracotta"},
        {pos: [12, 0, 5], state: "minecraft:cut_red_sandstone"},
        {pos: [12, 0, 6], state: "minecraft:cut_red_sandstone"},
        {pos: [12, 0, 7], state: "minecraft:cut_red_sandstone"},
        {pos: [12, 0, 8], state: "minecraft:cut_red_sandstone"},
        {pos: [13, 0, 4], state: "minecraft:cut_red_sandstone"},
        {pos: [13, 0, 5], state: "minecraft:cut_red_sandstone"},
        {pos: [13, 0, 6], state: "minecraft:cut_red_sandstone"},
        {pos: [0, 1, 4], state: "minecraft:red_sand"},
        {pos: [1, 1, 3], state: "minecraft:red_sand"},
        {pos: [1, 1, 4], state: "minecraft:red_sand"},
        {pos: [1, 1, 5], state: "minecraft:red_sand"},
        {pos: [1, 1, 8], state: "minecraft:red_sand"},
        {pos: [1, 1, 9], state: "minecraft:red_sand"},
        {pos: [1, 1, 10], state: "minecraft:red_sand"},
        {pos: [2, 1, 3], state: "minecraft:cut_red_sandstone"},
        {pos: [2, 1, 4], state: "minecraft:red_terracotta"},
        {pos: [2, 1, 5], state: "minecraft:red_sand"},
        {pos: [2, 1, 7], state: "minecraft:red_sand"},
        {pos: [2, 1, 8], state: "minecraft:cut_red_sandstone"},
        {pos: [2, 1, 9], state: "minecraft:cut_red_sandstone"},
        {pos: [2, 1, 10], state: "minecraft:red_sand"},
        {pos: [3, 1, 2], state: "minecraft:red_sand"},
        {pos: [3, 1, 3], state: "minecraft:red_terracotta"},
        {pos: [3, 1, 4], state: "minecraft:red_terracotta"},
        {pos: [3, 1, 5], state: "minecraft:red_sand"},
        {pos: [3, 1, 6], state: "minecraft:red_sand"},
        {pos: [3, 1, 7], state: "minecraft:red_terracotta"},
        {pos: [3, 1, 8], state: "minecraft:red_terracotta"},
        {pos: [3, 1, 9], state: "minecraft:cut_red_sandstone"},
        {pos: [3, 1, 10], state: "minecraft:red_sand"},
        {pos: [4, 1, 2], state: "minecraft:red_sand"},
        {pos: [4, 1, 3], state: "minecraft:red_sand"},
        {pos: [4, 1, 4], state: "minecraft:red_sand"},
        {pos: [4, 1, 5], state: "minecraft:red_sand"},
        {pos: [4, 1, 6], state: "minecraft:red_sand"},
        {pos: [4, 1, 7], state: "minecraft:red_terracotta"},
        {pos: [4, 1, 8], state: "minecraft:red_terracotta"},
        {pos: [4, 1, 9], state: "minecraft:red_sand"},
        {pos: [5, 1, 1], state: "minecraft:red_sand"},
        {pos: [5, 1, 2], state: "minecraft:cut_red_sandstone"},
        {pos: [5, 1, 3], state: "minecraft:red_sand"},
        {pos: [5, 1, 6], state: "minecraft:red_sand"},
        {pos: [5, 1, 7], state: "minecraft:red_sand"},
        {pos: [5, 1, 8], state: "minecraft:red_sand"},
        {pos: [5, 1, 9], state: "minecraft:red_sand"},
        {pos: [5, 1, 10], state: "minecraft:red_sand"},
        {pos: [6, 1, 0], state: "minecraft:red_sand"},
        {pos: [6, 1, 1], state: "minecraft:cut_red_sandstone"},
        {pos: [6, 1, 2], state: "minecraft:cut_red_sandstone"},
        {pos: [6, 1, 8], state: "minecraft:red_sand"},
        {pos: [6, 1, 9], state: "minecraft:red_sand"},
        {pos: [6, 1, 10], state: "minecraft:red_sand"},
        {pos: [6, 1, 11], state: "minecraft:red_sand"},
        {pos: [7, 1, 0], state: "minecraft:red_sand"},
        {pos: [7, 1, 1], state: "minecraft:cut_red_sandstone"},
        {pos: [7, 1, 2], state: "minecraft:cut_red_sandstone"},
        {pos: [7, 1, 3], state: "minecraft:red_sand"},
        {pos: [7, 1, 4], state: "minecraft:red_sand"},
        {pos: [7, 1, 9], state: "minecraft:red_sand"},
        {pos: [7, 1, 10], state: "minecraft:red_sand"},
        {pos: [7, 1, 11], state: "minecraft:red_sand"},
        {pos: [8, 1, 0], state: "minecraft:red_sand"},
        {pos: [8, 1, 1], state: "minecraft:red_sand"},
        {pos: [8, 1, 2], state: "minecraft:cut_red_sandstone"},
        {pos: [8, 1, 3], state: "minecraft:red_sand"},
        {pos: [8, 1, 4], state: "minecraft:red_sand"},
        {pos: [8, 1, 6], state: "minecraft:red_sand"},
        {pos: [8, 1, 7], state: "minecraft:red_sand"},
        {pos: [8, 1, 8], state: "minecraft:red_sand"},
        {pos: [8, 1, 9], state: "minecraft:red_sand"},
        {pos: [9, 1, 1], state: "minecraft:red_sand"},
        {pos: [9, 1, 2], state: "minecraft:cut_red_sandstone"},
        {pos: [9, 1, 3], state: "minecraft:red_sand"},
        {pos: [9, 1, 4], state: "minecraft:red_sand"},
        {pos: [9, 1, 5], state: "minecraft:red_sand"},
        {pos: [9, 1, 6], state: "minecraft:red_sand"},
        {pos: [9, 1, 7], state: "minecraft:red_sand"},
        {pos: [9, 1, 8], state: "minecraft:red_sand"},
        {pos: [9, 1, 9], state: "minecraft:red_sand"},
        {pos: [10, 1, 3], state: "minecraft:red_sand"},
        {pos: [10, 1, 4], state: "minecraft:red_sand"},
        {pos: [10, 1, 5], state: "minecraft:red_sand"},
        {pos: [10, 1, 6], state: "minecraft:cut_red_sandstone"},
        {pos: [10, 1, 7], state: "minecraft:red_terracotta"},
        {pos: [10, 1, 8], state: "minecraft:red_terracotta"},
        {pos: [10, 1, 9], state: "minecraft:red_sand"},
        {pos: [11, 1, 3], state: "minecraft:red_terracotta"},
        {pos: [11, 1, 4], state: "minecraft:red_terracotta"},
        {pos: [11, 1, 5], state: "minecraft:red_sand"},
        {pos: [11, 1, 6], state: "minecraft:cut_red_sandstone"},
        {pos: [11, 1, 7], state: "minecraft:red_terracotta"},
        {pos: [11, 1, 8], state: "minecraft:red_terracotta"},
        {pos: [11, 1, 9], state: "minecraft:red_sand"},
        {pos: [12, 1, 3], state: "minecraft:red_terracotta"},
        {pos: [12, 1, 4], state: "minecraft:red_terracotta"},
        {pos: [12, 1, 5], state: "minecraft:red_sand"},
        {pos: [12, 1, 6], state: "minecraft:cut_red_sandstone"},
        {pos: [12, 1, 7], state: "minecraft:cut_red_sandstone"},
        {pos: [12, 1, 8], state: "minecraft:red_sand"},
        {pos: [13, 1, 4], state: "minecraft:red_sand"},
        {pos: [13, 1, 5], state: "minecraft:red_sand"},
        {pos: [13, 1, 6], state: "minecraft:red_sand"},
        {pos: [0, 2, 4], state: "minecraft:red_sand"},
        {pos: [1, 2, 3], state: "minecraft:red_sand"},
        {pos: [1, 2, 4], state: "minecraft:red_sand"},
        {pos: [1, 2, 5], state: "minecraft:red_sand"},
        {pos: [1, 2, 8], state: "minecraft:red_sand"},
        {pos: [1, 2, 9], state: "minecraft:red_sand"},
        {pos: [1, 2, 10], state: "minecraft:red_sand"},
        {pos: [2, 2, 3], state: "minecraft:red_terracotta"},
        {pos: [2, 2, 4], state: "minecraft:red_terracotta"},
        {pos: [2, 2, 5], state: "minecraft:red_sand"},
        {pos: [2, 2, 7], state: "minecraft:red_sand"},
        {pos: [2, 2, 8], state: "minecraft:red_sand"},
        {pos: [2, 2, 9], state: "minecraft:red_sand"},
        {pos: [2, 2, 10], state: "minecraft:red_sand"},
        {pos: [3, 2, 2], state: "minecraft:red_sand"},
        {pos: [3, 2, 3], state: "minecraft:red_terracotta"},
        {pos: [3, 2, 4], state: "minecraft:red_terracotta"},
        {pos: [3, 2, 5], state: "minecraft:red_sand"},
        {pos: [3, 2, 6], state: "minecraft:red_sand"},
        {pos: [3, 2, 7], state: "minecraft:red_terracotta"},
        {pos: [3, 2, 8], state: "minecraft:red_terracotta"},
        {pos: [3, 2, 9], state: "minecraft:red_sand"},
        {pos: [3, 2, 10], state: "minecraft:red_sand"},
        {pos: [4, 2, 2], state: "minecraft:red_sand"},
        {pos: [4, 2, 3], state: "minecraft:red_sand"},
        {pos: [4, 2, 4], state: "minecraft:red_sand"},
        {pos: [4, 2, 5], state: "minecraft:red_sand"},
        {pos: [4, 2, 6], state: "minecraft:red_sand"},
        {pos: [4, 2, 7], state: "minecraft:red_terracotta"},
        {pos: [4, 2, 8], state: "minecraft:red_terracotta"},
        {pos: [4, 2, 9], state: "minecraft:red_sand"},
        {pos: [5, 2, 1], state: "minecraft:red_sand"},
        {pos: [5, 2, 2], state: "minecraft:cut_red_sandstone"},
        {pos: [5, 2, 3], state: "minecraft:red_sand"},
        {pos: [5, 2, 6], state: "minecraft:red_sand"},
        {pos: [5, 2, 7], state: "minecraft:red_sand"},
        {pos: [5, 2, 8], state: "minecraft:red_sand"},
        {pos: [5, 2, 9], state: "minecraft:red_sand"},
        {pos: [5, 2, 10], state: "minecraft:red_sand"},
        {pos: [6, 2, 0], state: "minecraft:red_sand"},
        {pos: [6, 2, 1], state: "minecraft:red_sand"},
        {pos: [6, 2, 2], state: "minecraft:red_terracotta"},
        {pos: [6, 2, 8], state: "minecraft:red_sand"},
        {pos: [6, 2, 9], state: "minecraft:red_sand"},
        {pos: [6, 2, 10], state: "minecraft:red_sand"},
        {pos: [6, 2, 11], state: "minecraft:red_sand"},
        {pos: [7, 2, 0], state: "minecraft:red_sand"},
        {pos: [7, 2, 1], state: "minecraft:red_sand"},
        {pos: [7, 2, 2], state: "minecraft:red_terracotta"},
        {pos: [7, 2, 3], state: "minecraft:red_sand"},
        {pos: [7, 2, 4], state: "minecraft:red_sand"},
        {pos: [7, 2, 9], state: "minecraft:red_sand"},
        {pos: [7, 2, 10], state: "minecraft:red_sand"},
        {pos: [7, 2, 11], state: "minecraft:red_sand"},
        {pos: [8, 2, 0], state: "minecraft:red_sand"},
        {pos: [8, 2, 1], state: "minecraft:red_sand"},
        {pos: [8, 2, 2], state: "minecraft:red_terracotta"},
        {pos: [8, 2, 3], state: "minecraft:red_sand"},
        {pos: [8, 2, 4], state: "minecraft:red_sand"},
        {pos: [8, 2, 6], state: "minecraft:red_sand"},
        {pos: [8, 2, 7], state: "minecraft:red_sand"},
        {pos: [8, 2, 8], state: "minecraft:red_sand"},
        {pos: [8, 2, 9], state: "minecraft:red_sand"},
        {pos: [9, 2, 1], state: "minecraft:red_sand"},
        {pos: [9, 2, 2], state: "minecraft:cut_red_sandstone"},
        {pos: [9, 2, 3], state: "minecraft:red_sand"},
        {pos: [9, 2, 4], state: "minecraft:red_sand"},
        {pos: [9, 2, 5], state: "minecraft:red_sand"},
        {pos: [9, 2, 6], state: "minecraft:red_sand"},
        {pos: [9, 2, 7], state: "minecraft:red_sand"},
        {pos: [9, 2, 8], state: "minecraft:red_sand"},
        {pos: [9, 2, 9], state: "minecraft:red_sand"},
        {pos: [10, 2, 3], state: "minecraft:red_sand"},
        {pos: [10, 2, 4], state: "minecraft:red_sand"},
        {pos: [10, 2, 5], state: "minecraft:red_sand"},
        {pos: [10, 2, 6], state: "minecraft:red_sand"},
        {pos: [10, 2, 7], state: "minecraft:red_terracotta"},
        {pos: [10, 2, 8], state: "minecraft:red_terracotta"},
        {pos: [10, 2, 9], state: "minecraft:red_sand"},
        {pos: [11, 2, 3], state: "minecraft:red_terracotta"},
        {pos: [11, 2, 4], state: "minecraft:red_terracotta"},
        {pos: [11, 2, 5], state: "minecraft:red_sand"},
        {pos: [11, 2, 6], state: "minecraft:cut_red_sandstone"},
        {pos: [11, 2, 7], state: "minecraft:red_terracotta"},
        {pos: [11, 2, 8], state: "minecraft:red_terracotta"},
        {pos: [11, 2, 9], state: "minecraft:red_sand"},
        {pos: [12, 2, 3], state: "minecraft:red_terracotta"},
        {pos: [12, 2, 4], state: "minecraft:red_terracotta"},
        {pos: [12, 2, 5], state: "minecraft:red_sand"},
        {pos: [12, 2, 6], state: "minecraft:red_sand"},
        {pos: [12, 2, 7], state: "minecraft:red_sand"},
        {pos: [12, 2, 8], state: "minecraft:red_sand"},
        {pos: [13, 2, 4], state: "minecraft:red_sand"},
        {pos: [13, 2, 5], state: "minecraft:red_sand"},
        {pos: [13, 2, 6], state: "minecraft:red_sand"},
        {pos: [0, 3, 4], state: "minecraft:red_sand"},
        {pos: [1, 3, 3], state: "minecraft:red_sand"},
        {pos: [1, 3, 4], state: "minecraft:red_sand"},
        {pos: [1, 3, 5], state: "minecraft:red_sand"},
        {pos: [1, 3, 8], state: "minecraft:red_sand"},
        {pos: [1, 3, 9], state: "minecraft:red_sand"},
        {pos: [1, 3, 10], state: "minecraft:red_sand"},
        {pos: [2, 3, 3], state: "minecraft:red_terracotta"},
        {pos: [2, 3, 4], state: "minecraft:red_terracotta"},
        {pos: [2, 3, 5], state: "minecraft:red_sand"},
        {pos: [2, 3, 7], state: "minecraft:red_sand"},
        {pos: [2, 3, 8], state: "minecraft:red_sand"},
        {pos: [2, 3, 9], state: "minecraft:red_sand"},
        {pos: [2, 3, 10], state: "minecraft:red_sand"},
        {pos: [3, 3, 2], state: "minecraft:red_sand"},
        {pos: [3, 3, 3], state: "minecraft:red_terracotta"},
        {pos: [3, 3, 4], state: "minecraft:red_terracotta"},
        {pos: [3, 3, 5], state: "minecraft:red_sand"},
        {pos: [3, 3, 6], state: "minecraft:red_sand"},
        {pos: [3, 3, 7], state: "minecraft:red_terracotta"},
        {pos: [3, 3, 8], state: "minecraft:red_terracotta"},
        {pos: [3, 3, 9], state: "minecraft:red_sand"},
        {pos: [3, 3, 10], state: "minecraft:red_sand"},
        {pos: [4, 3, 2], state: "minecraft:red_sand"},
        {pos: [4, 3, 3], state: "minecraft:red_sand"},
        {pos: [4, 3, 4], state: "minecraft:red_sand"},
        {pos: [4, 3, 5], state: "minecraft:red_sand"},
        {pos: [4, 3, 6], state: "minecraft:red_sand"},
        {pos: [4, 3, 7], state: "minecraft:cut_red_sandstone"},
        {pos: [4, 3, 8], state: "minecraft:cut_red_sandstone"},
        {pos: [4, 3, 9], state: "minecraft:red_sand"},
        {pos: [5, 3, 1], state: "minecraft:red_sand"},
        {pos: [5, 3, 2], state: "minecraft:cut_red_sandstone"},
        {pos: [5, 3, 3], state: "minecraft:red_sand"},
        {pos: [5, 3, 6], state: "minecraft:red_sand"},
        {pos: [5, 3, 7], state: "minecraft:red_sand"},
        {pos: [5, 3, 8], state: "minecraft:red_sand"},
        {pos: [5, 3, 9], state: "minecraft:red_sand"},
        {pos: [5, 3, 10], state: "minecraft:red_sand"},
        {pos: [6, 3, 0], state: "minecraft:red_sand"},
        {pos: [6, 3, 1], state: "minecraft:red_sand"},
        {pos: [6, 3, 2], state: "minecraft:cut_red_sandstone"},
        {pos: [6, 3, 8], state: "minecraft:red_sand"},
        {pos: [6, 3, 9], state: "minecraft:red_sand"},
        {pos: [6, 3, 10], state: "minecraft:red_sand"},
        {pos: [7, 3, 0], state: "minecraft:red_sand"},
        {pos: [7, 3, 1], state: "minecraft:red_sand"},
        {pos: [7, 3, 2], state: "minecraft:cut_red_sandstone"},
        {pos: [7, 3, 3], state: "minecraft:red_sand"},
        {pos: [7, 3, 4], state: "minecraft:red_sand"},
        {pos: [7, 3, 9], state: "minecraft:red_sand"},
        {pos: [7, 3, 10], state: "minecraft:red_sand"},
        {pos: [7, 3, 11], state: "minecraft:red_sand"},
        {pos: [8, 3, 0], state: "minecraft:red_sand"},
        {pos: [8, 3, 1], state: "minecraft:red_sand"},
        {pos: [8, 3, 2], state: "minecraft:cut_red_sandstone"},
        {pos: [8, 3, 3], state: "minecraft:red_sand"},
        {pos: [8, 3, 4], state: "minecraft:red_sand"},
        {pos: [8, 3, 6], state: "minecraft:red_sand"},
        {pos: [8, 3, 7], state: "minecraft:red_sand"},
        {pos: [8, 3, 8], state: "minecraft:red_sand"},
        {pos: [8, 3, 9], state: "minecraft:red_sand"},
        {pos: [9, 3, 1], state: "minecraft:red_sand"},
        {pos: [9, 3, 2], state: "minecraft:cut_red_sandstone"},
        {pos: [9, 3, 3], state: "minecraft:red_sand"},
        {pos: [9, 3, 4], state: "minecraft:red_sand"},
        {pos: [9, 3, 5], state: "minecraft:red_sand"},
        {pos: [9, 3, 6], state: "minecraft:red_sand"},
        {pos: [9, 3, 7], state: "minecraft:red_sand"},
        {pos: [9, 3, 8], state: "minecraft:red_sand"},
        {pos: [9, 3, 9], state: "minecraft:red_sand"},
        {pos: [10, 3, 3], state: "minecraft:red_sand"},
        {pos: [10, 3, 4], state: "minecraft:red_sand"},
        {pos: [10, 3, 5], state: "minecraft:red_sand"},
        {pos: [10, 3, 6], state: "minecraft:red_sand"},
        {pos: [10, 3, 7], state: "minecraft:red_terracotta"},
        {pos: [10, 3, 8], state: "minecraft:red_terracotta"},
        {pos: [10, 3, 9], state: "minecraft:red_sand"},
        {pos: [11, 3, 3], state: "minecraft:red_terracotta"},
        {pos: [11, 3, 4], state: "minecraft:red_terracotta"},
        {pos: [11, 3, 5], state: "minecraft:red_sand"},
        {pos: [11, 3, 6], state: "minecraft:red_sand"},
        {pos: [11, 3, 7], state: "minecraft:red_terracotta"},
        {pos: [11, 3, 8], state: "minecraft:red_terracotta"},
        {pos: [11, 3, 9], state: "minecraft:red_sand"},
        {pos: [12, 3, 3], state: "minecraft:red_terracotta"},
        {pos: [12, 3, 4], state: "minecraft:red_terracotta"},
        {pos: [12, 3, 5], state: "minecraft:red_sand"},
        {pos: [12, 3, 6], state: "minecraft:red_sand"},
        {pos: [12, 3, 7], state: "minecraft:red_sand"},
        {pos: [12, 3, 8], state: "minecraft:red_sand"},
        {pos: [13, 3, 4], state: "minecraft:red_sand"},
        {pos: [13, 3, 5], state: "minecraft:red_sand"},
        {pos: [13, 3, 6], state: "minecraft:red_sand"},
        {pos: [0, 4, 4], state: "minecraft:red_sand"},
        {pos: [1, 4, 3], state: "minecraft:red_sand"},
        {pos: [1, 4, 4], state: "minecraft:red_sand"},
        {pos: [1, 4, 5], state: "minecraft:red_sand"},
        {pos: [2, 4, 3], state: "minecraft:red_terracotta"},
        {pos: [2, 4, 4], state: "minecraft:red_terracotta"},
        {pos: [2, 4, 5], state: "minecraft:red_sand"},
        {pos: [2, 4, 7], state: "minecraft:red_sand"},
        {pos: [2, 4, 8], state: "minecraft:red_sand"},
        {pos: [3, 4, 2], state: "minecraft:red_sand"},
        {pos: [3, 4, 3], state: "minecraft:red_terracotta"},
        {pos: [3, 4, 4], state: "minecraft:cut_red_sandstone"},
        {pos: [3, 4, 5], state: "minecraft:red_sand"},
        {pos: [3, 4, 6], state: "minecraft:red_sand"},
        {pos: [3, 4, 7], state: "minecraft:cut_red_sandstone"},
        {pos: [3, 4, 8], state: "minecraft:cut_red_sandstone"},
        {pos: [3, 4, 9], state: "minecraft:red_sand"},
        {pos: [4, 4, 2], state: "minecraft:red_sand"},
        {pos: [4, 4, 3], state: "minecraft:red_sand"},
        {pos: [4, 4, 4], state: "minecraft:red_sand"},
        {pos: [4, 4, 5], state: "minecraft:red_sand"},
        {pos: [4, 4, 6], state: "minecraft:red_sand"},
        {pos: [4, 4, 7], state: "minecraft:cut_red_sandstone"},
        {pos: [4, 4, 8], state: "minecraft:cut_red_sandstone"},
        {pos: [4, 4, 9], state: "minecraft:red_sand"},
        {pos: [5, 4, 1], state: "minecraft:red_sand"},
        {pos: [5, 4, 2], state: "minecraft:cut_red_sandstone"},
        {pos: [5, 4, 3], state: "minecraft:red_sand"},
        {pos: [5, 4, 6], state: "minecraft:red_sand"},
        {pos: [5, 4, 7], state: "minecraft:red_sand"},
        {pos: [5, 4, 8], state: "minecraft:red_sand"},
        {pos: [5, 4, 9], state: "minecraft:red_sand"},
        {pos: [6, 4, 0], state: "minecraft:red_sand"},
        {pos: [6, 4, 1], state: "minecraft:red_sand"},
        {pos: [6, 4, 2], state: "minecraft:red_terracotta"},
        {pos: [6, 4, 8], state: "minecraft:red_sand"},
        {pos: [6, 4, 9], state: "minecraft:red_sand"},
        {pos: [7, 4, 0], state: "minecraft:red_sand"},
        {pos: [7, 4, 1], state: "minecraft:red_sand"},
        {pos: [7, 4, 2], state: "minecraft:red_terracotta"},
        {pos: [7, 4, 3], state: "minecraft:red_sand"},
        {pos: [7, 4, 9], state: "minecraft:red_sand"},
        {pos: [7, 4, 10], state: "minecraft:red_sand"},
        {pos: [8, 4, 2], state: "minecraft:red_terracotta"},
        {pos: [8, 4, 3], state: "minecraft:red_sand"},
        {pos: [8, 4, 7], state: "minecraft:red_sand"},
        {pos: [8, 4, 8], state: "minecraft:red_sand"},
        {pos: [8, 4, 9], state: "minecraft:red_sand"},
        {pos: [9, 4, 2], state: "minecraft:cut_red_sandstone"},
        {pos: [9, 4, 3], state: "minecraft:red_sand"},
        {pos: [9, 4, 4], state: "minecraft:red_sand"},
        {pos: [9, 4, 6], state: "minecraft:red_sand"},
        {pos: [9, 4, 7], state: "minecraft:red_sand"},
        {pos: [9, 4, 8], state: "minecraft:red_sand"},
        {pos: [9, 4, 9], state: "minecraft:red_sand"},
        {pos: [10, 4, 3], state: "minecraft:red_sand"},
        {pos: [10, 4, 4], state: "minecraft:red_sand"},
        {pos: [10, 4, 5], state: "minecraft:red_sand"},
        {pos: [10, 4, 6], state: "minecraft:red_sand"},
        {pos: [10, 4, 7], state: "minecraft:red_terracotta"},
        {pos: [10, 4, 8], state: "minecraft:cut_red_sandstone"},
        {pos: [10, 4, 9], state: "minecraft:red_sand"},
        {pos: [11, 4, 3], state: "minecraft:red_terracotta"},
        {pos: [11, 4, 4], state: "minecraft:red_terracotta"},
        {pos: [11, 4, 5], state: "minecraft:red_sand"},
        {pos: [11, 4, 6], state: "minecraft:red_sand"},
        {pos: [11, 4, 7], state: "minecraft:red_terracotta"},
        {pos: [11, 4, 8], state: "minecraft:red_terracotta"},
        {pos: [11, 4, 9], state: "minecraft:red_sand"},
        {pos: [12, 4, 3], state: "minecraft:cut_red_sandstone"},
        {pos: [12, 4, 4], state: "minecraft:red_terracotta"},
        {pos: [12, 4, 5], state: "minecraft:red_sand"},
        {pos: [12, 4, 6], state: "minecraft:red_sand"},
        {pos: [12, 4, 7], state: "minecraft:red_sand"},
        {pos: [12, 4, 8], state: "minecraft:red_sand"},
        {pos: [13, 4, 4], state: "minecraft:red_sand"},
        {pos: [13, 4, 5], state: "minecraft:red_sand"},
        {pos: [13, 4, 6], state: "minecraft:red_sand"},
        {pos: [1, 5, 3], state: "minecraft:red_sand"},
        {pos: [1, 5, 4], state: "minecraft:red_sand"},
        {pos: [1, 5, 5], state: "minecraft:red_sand"},
        {pos: [2, 5, 3], state: "minecraft:cut_red_sandstone"},
        {pos: [2, 5, 4], state: "minecraft:cut_red_sandstone"},
        {pos: [2, 5, 5], state: "minecraft:red_sand"},
        {pos: [2, 5, 7], state: "minecraft:red_sand"},
        {pos: [2, 5, 8], state: "minecraft:red_sand"},
        {pos: [3, 5, 2], state: "minecraft:red_sand"},
        {pos: [3, 5, 3], state: "minecraft:cut_red_sandstone"},
        {pos: [3, 5, 4], state: "minecraft:cut_red_sandstone"},
        {pos: [3, 5, 5], state: "minecraft:red_sand"},
        {pos: [3, 5, 6], state: "minecraft:red_sand"},
        {pos: [3, 5, 7], state: "minecraft:cut_red_sandstone"},
        {pos: [3, 5, 8], state: "minecraft:cut_red_sandstone"},
        {pos: [3, 5, 9], state: "minecraft:red_sand"},
        {pos: [4, 5, 2], state: "minecraft:red_sand"},
        {pos: [4, 5, 3], state: "minecraft:red_sand"},
        {pos: [4, 5, 4], state: "minecraft:red_sand"},
        {pos: [4, 5, 5], state: "minecraft:red_sand"},
        {pos: [4, 5, 6], state: "minecraft:red_sand"},
        {pos: [4, 5, 7], state: "minecraft:cut_red_sandstone"},
        {pos: [4, 5, 8], state: "minecraft:chiseled_red_sandstone"},
        {pos: [4, 5, 9], state: "minecraft:red_sand"},
        {pos: [5, 5, 1], state: "minecraft:red_sand"},
        {pos: [5, 5, 2], state: "minecraft:cut_red_sandstone"},
        {pos: [5, 5, 3], state: "minecraft:red_sand"},
        {pos: [5, 5, 6], state: "minecraft:red_sand"},
        {pos: [5, 5, 7], state: "minecraft:cut_red_sandstone"},
        {pos: [5, 5, 8], state: "minecraft:cut_red_sandstone"},
        {pos: [5, 5, 9], state: "minecraft:red_sand"},
        {pos: [6, 5, 1], state: "minecraft:red_sand"},
        {pos: [6, 5, 2], state: "minecraft:cut_red_sandstone"},
        {pos: [6, 5, 7], state: "minecraft:cut_red_sandstone"},
        {pos: [6, 5, 8], state: "minecraft:cut_red_sandstone"},
        {pos: [6, 5, 9], state: "minecraft:red_sand"},
        {pos: [7, 5, 1], state: "minecraft:red_sand"},
        {pos: [7, 5, 2], state: "minecraft:cut_red_sandstone"},
        {pos: [7, 5, 3], state: "minecraft:red_sand"},
        {pos: [7, 5, 7], state: "minecraft:cut_red_sandstone"},
        {pos: [8, 5, 2], state: "minecraft:red_sand"},
        {pos: [8, 5, 3], state: "minecraft:red_sand"},
        {pos: [8, 5, 7], state: "minecraft:cut_red_sandstone"},
        {pos: [8, 5, 8], state: "minecraft:red_sand"},
        {pos: [8, 5, 9], state: "minecraft:red_sand"},
        {pos: [9, 5, 2], state: "minecraft:red_sand"},
        {pos: [9, 5, 3], state: "minecraft:red_sand"},
        {pos: [9, 5, 6], state: "minecraft:red_sand"},
        {pos: [9, 5, 7], state: "minecraft:cut_red_sandstone"},
        {pos: [9, 5, 8], state: "minecraft:cut_red_sandstone"},
        {pos: [9, 5, 9], state: "minecraft:red_sand"},
        {pos: [10, 5, 3], state: "minecraft:red_sand"},
        {pos: [10, 5, 4], state: "minecraft:red_sand"},
        {pos: [10, 5, 5], state: "minecraft:red_sand"},
        {pos: [10, 5, 6], state: "minecraft:red_sand"},
        {pos: [10, 5, 7], state: "minecraft:cut_red_sandstone"},
        {pos: [10, 5, 8], state: "minecraft:cut_red_sandstone"},
        {pos: [10, 5, 9], state: "minecraft:red_sand"},
        {pos: [11, 5, 3], state: "minecraft:red_terracotta"},
        {pos: [11, 5, 4], state: "minecraft:red_terracotta"},
        {pos: [11, 5, 5], state: "minecraft:red_sand"},
        {pos: [11, 5, 6], state: "minecraft:red_sand"},
        {pos: [11, 5, 7], state: "minecraft:red_terracotta"},
        {pos: [11, 5, 8], state: "minecraft:cut_red_sandstone"},
        {pos: [11, 5, 9], state: "minecraft:red_sand"},
        {pos: [12, 5, 3], state: "minecraft:cut_red_sandstone"},
        {pos: [12, 5, 4], state: "minecraft:cut_red_sandstone"},
        {pos: [12, 5, 5], state: "minecraft:red_sand"},
        {pos: [12, 5, 6], state: "minecraft:red_sand"},
        {pos: [12, 5, 7], state: "minecraft:red_sand"},
        {pos: [12, 5, 8], state: "minecraft:red_sand"},
        {pos: [13, 5, 4], state: "minecraft:red_sand"},
        {pos: [13, 5, 5], state: "minecraft:red_sand"},
        {pos: [13, 5, 6], state: "minecraft:red_sand"},
        {pos: [1, 6, 3], state: "minecraft:red_sand"},
        {pos: [1, 6, 4], state: "minecraft:red_sand"},
        {pos: [2, 6, 3], state: "minecraft:cut_red_sandstone"},
        {pos: [2, 6, 4], state: "minecraft:cut_red_sandstone"},
        {pos: [2, 6, 5], state: "minecraft:red_sand"},
        {pos: [2, 6, 8], state: "minecraft:red_sand"},
        {pos: [3, 6, 3], state: "minecraft:cut_red_sandstone"},
        {pos: [3, 6, 4], state: "minecraft:cut_red_sandstone"},
        {pos: [3, 6, 5], state: "minecraft:red_sand"},
        {pos: [3, 6, 6], state: "minecraft:red_sand"},
        {pos: [3, 6, 7], state: "minecraft:cut_red_sandstone"},
        {pos: [3, 6, 8], state: "minecraft:red_sand"},
        {pos: [4, 6, 2], state: "minecraft:red_sand"},
        {pos: [4, 6, 3], state: "minecraft:red_sand"},
        {pos: [4, 6, 4], state: "minecraft:red_sand"},
        {pos: [4, 6, 5], state: "minecraft:red_sand"},
        {pos: [4, 6, 6], state: "minecraft:red_sand"},
        {pos: [4, 6, 7], state: "minecraft:cut_red_sandstone"},
        {pos: [4, 6, 8], state: "minecraft:cut_red_sandstone"},
        {pos: [4, 6, 9], state: "minecraft:red_sand"},
        {pos: [5, 6, 2], state: "minecraft:red_sand"},
        {pos: [5, 6, 3], state: "minecraft:red_sand"},
        {pos: [5, 6, 7], state: "minecraft:cut_red_sandstone"},
        {pos: [5, 6, 8], state: "minecraft:cut_red_sandstone"},
        {pos: [5, 6, 9], state: "minecraft:red_sand"},
        {pos: [6, 6, 1], state: "minecraft:red_sand"},
        {pos: [6, 6, 2], state: "minecraft:red_sand"},
        {pos: [6, 6, 7], state: "minecraft:cut_red_sandstone"},
        {pos: [6, 6, 8], state: "minecraft:red_sand"},
        {pos: [6, 6, 9], state: "minecraft:red_sand"},
        {pos: [7, 6, 2], state: "minecraft:red_sand"},
        {pos: [7, 6, 7], state: "minecraft:cut_red_sandstone"},
        {pos: [8, 6, 7], state: "minecraft:cut_red_sandstone"},
        {pos: [8, 6, 8], state: "minecraft:cut_red_sandstone"},
        {pos: [8, 6, 9], state: "minecraft:red_sand"},
        {pos: [9, 6, 7], state: "minecraft:cut_red_sandstone"},
        {pos: [9, 6, 8], state: "minecraft:cut_red_sandstone"},
        {pos: [9, 6, 9], state: "minecraft:red_sand"},
        {pos: [10, 6, 7], state: "minecraft:red_terracotta"},
        {pos: [10, 6, 8], state: "minecraft:red_terracotta"},
        {pos: [10, 6, 9], state: "minecraft:red_sand"},
        {pos: [11, 6, 3], state: "minecraft:cut_red_sandstone"},
        {pos: [11, 6, 4], state: "minecraft:cut_red_sandstone"},
        {pos: [11, 6, 5], state: "minecraft:red_sand"},
        {pos: [11, 6, 6], state: "minecraft:red_sand"},
        {pos: [11, 6, 7], state: "minecraft:red_terracotta"},
        {pos: [11, 6, 8], state: "minecraft:red_terracotta"},
        {pos: [11, 6, 9], state: "minecraft:red_sand"},
        {pos: [12, 6, 3], state: "minecraft:chiseled_red_sandstone"},
        {pos: [12, 6, 4], state: "minecraft:cut_red_sandstone"},
        {pos: [12, 6, 5], state: "minecraft:red_sand"},
        {pos: [12, 6, 6], state: "minecraft:red_sand"},
        {pos: [12, 6, 7], state: "minecraft:red_sand"},
        {pos: [12, 6, 8], state: "minecraft:red_sand"},
        {pos: [13, 6, 4], state: "minecraft:red_sand"},
        {pos: [13, 6, 5], state: "minecraft:red_sand"},
        {pos: [1, 7, 3], state: "minecraft:red_sand"},
        {pos: [1, 7, 4], state: "minecraft:red_sand"},
        {pos: [2, 7, 3], state: "minecraft:cut_red_sandstone"},
        {pos: [2, 7, 4], state: "minecraft:chiseled_red_sandstone"},
        {pos: [3, 7, 3], state: "minecraft:red_sand"},
        {pos: [3, 7, 4], state: "minecraft:cut_red_sandstone"},
        {pos: [4, 7, 3], state: "minecraft:red_sand"},
        {pos: [4, 7, 4], state: "minecraft:red_sand"},
        {pos: [4, 7, 7], state: "minecraft:red_sand"},
        {pos: [4, 7, 8], state: "minecraft:red_sandstone_wall{east:low,north:low,south:none,up:true,waterlogged:false,west:none}"},
        {pos: [5, 7, 7], state: "minecraft:red_sand"},
        {pos: [5, 7, 8], state: "minecraft:red_sandstone_wall{east:none,north:low,south:none,up:true,waterlogged:false,west:low}"},
        {pos: [6, 7, 7], state: "minecraft:red_sand"},
        {pos: [8, 7, 7], state: "minecraft:red_sand"},
        {pos: [8, 7, 8], state: "minecraft:red_sand"},
        {pos: [9, 7, 7], state: "minecraft:cut_red_sandstone"},
        {pos: [9, 7, 8], state: "minecraft:red_sand"},
        {pos: [9, 7, 9], state: "minecraft:red_sand"},
        {pos: [10, 7, 7], state: "minecraft:red_terracotta"},
        {pos: [10, 7, 8], state: "minecraft:red_terracotta"},
        {pos: [10, 7, 9], state: "minecraft:red_sand"},
        {pos: [11, 7, 4], state: "minecraft:red_sandstone_wall{east:none,north:none,south:none,up:true,waterlogged:false,west:none}"},
        {pos: [11, 7, 7], state: "minecraft:red_terracotta"},
        {pos: [11, 7, 8], state: "minecraft:red_terracotta"},
        {pos: [11, 7, 9], state: "minecraft:red_sand"},
        {pos: [12, 7, 7], state: "minecraft:red_sand"},
        {pos: [12, 7, 8], state: "minecraft:red_sand"},
        {pos: [2, 8, 3], state: "minecraft:red_sandstone_wall{east:none,north:none,south:none,up:true,waterlogged:false,west:none}"},
        {pos: [3, 8, 4], state: "minecraft:red_sandstone_wall{east:none,north:none,south:none,up:true,waterlogged:false,west:none}"},
        {pos: [8, 8, 7], state: "minecraft:red_sand"},
        {pos: [9, 8, 7], state: "minecraft:red_sandstone_wall{east:tall,north:none,south:tall,up:true,waterlogged:false,west:tall}"},
        {pos: [9, 8, 8], state: "minecraft:red_sand"},
        {pos: [10, 8, 7], state: "minecraft:red_terracotta"},
        {pos: [10, 8, 8], state: "minecraft:red_terracotta"},
        {pos: [10, 8, 9], state: "minecraft:red_sand"},
        {pos: [11, 8, 7], state: "minecraft:red_terracotta"},
        {pos: [11, 8, 8], state: "minecraft:red_terracotta"},
        {pos: [11, 8, 9], state: "minecraft:red_sand"},
        {pos: [12, 8, 7], state: "minecraft:red_sand"},
        {pos: [12, 8, 8], state: "minecraft:red_sand"},
        {pos: [9, 9, 7], state: "minecraft:red_sand"},
        {pos: [10, 9, 7], state: "minecraft:cut_red_sandstone"},
        {pos: [10, 9, 8], state: "minecraft:cut_red_sandstone"},
        {pos: [10, 9, 9], state: "minecraft:red_sand"},
        {pos: [11, 9, 7], state: "minecraft:cut_red_sandstone"},
        {pos: [11, 9, 8], state: "minecraft:red_terracotta"},
        {pos: [12, 9, 8], state: "minecraft:red_sand"},
        {pos: [10, 10, 7], state: "minecraft:cut_red_sandstone"},
        {pos: [10, 10, 8], state: "minecraft:chiseled_red_sandstone"},
        {pos: [11, 10, 7], state: "minecraft:cut_red_sandstone"},
        {pos: [11, 10, 8], state: "minecraft:cut_red_sandstone"},
        {pos: [10, 11, 8], state: "minecraft:cut_red_sandstone"},
        {pos: [11, 11, 7], state: "minecraft:cut_red_sandstone"},
        {pos: [11, 11, 8], state: "minecraft:cut_red_sandstone"}
    ],
    entities: [],
    palette: [
        "minecraft:cut_red_sandstone",
        "minecraft:red_terracotta",
        "minecraft:yellow_glazed_terracotta{facing:west}",
        "minecraft:yellow_glazed_terracotta{facing:south}",
        "minecraft:red_sand",
        "minecraft:chiseled_red_sandstone",
        "minecraft:red_sandstone_wall{east:low,north:low,south:none,up:true,waterlogged:false,west:none}",
        "minecraft:red_sandstone_wall{east:none,north:low,south:none,up:true,waterlogged:false,west:low}",
        "minecraft:red_sandstone_wall{east:none,north:none,south:none,up:true,waterlogged:false,west:none}",
        "minecraft:red_sandstone_wall{east:tall,north:none,south:tall,up:true,waterlogged:false,west:tall}"
    ],
    trailiertales_DataVersion: 2
}
