{
    DataVersion: 3953,
    size: [14, 7, 20],
    data: [
        {pos: [0, 0, 6], state: "minecraft:cut_red_sandstone"},
        {pos: [0, 0, 7], state: "minecraft:cut_red_sandstone"},
        {pos: [1, 0, 5], state: "minecraft:cut_red_sandstone"},
        {pos: [1, 0, 6], state: "minecraft:cut_red_sandstone"},
        {pos: [1, 0, 7], state: "minecraft:cut_red_sandstone"},
        {pos: [1, 0, 8], state: "minecraft:cut_red_sandstone"},
        {pos: [2, 0, 3], state: "minecraft:cut_red_sandstone"},
        {pos: [2, 0, 4], state: "minecraft:cut_red_sandstone"},
        {pos: [2, 0, 5], state: "minecraft:cut_red_sandstone"},
        {pos: [2, 0, 6], state: "minecraft:cut_red_sandstone"},
        {pos: [2, 0, 7], state: "minecraft:red_terracotta"},
        {pos: [2, 0, 8], state: "minecraft:cut_red_sandstone"},
        {pos: [2, 0, 9], state: "minecraft:cut_red_sandstone"},
        {pos: [3, 0, 2], state: "minecraft:cut_red_sandstone"},
        {pos: [3, 0, 3], state: "minecraft:cut_red_sandstone"},
        {pos: [3, 0, 4], state: "minecraft:cut_red_sandstone"},
        {pos: [3, 0, 5], state: "minecraft:cut_red_sandstone"},
        {pos: [3, 0, 6], state: "minecraft:yellow_glazed_terracotta{facing:north}"},
        {pos: [3, 0, 7], state: "minecraft:cut_red_sandstone"},
        {pos: [3, 0, 8], state: "minecraft:cut_red_sandstone"},
        {pos: [3, 0, 9], state: "minecraft:cut_red_sandstone"},
        {pos: [3, 0, 16], state: "minecraft:cut_red_sandstone"},
        {pos: [3, 0, 17], state: "minecraft:cut_red_sandstone"},
        {pos: [3, 0, 18], state: "minecraft:cut_red_sandstone"},
        {pos: [4, 0, 1], state: "minecraft:cut_red_sandstone"},
        {pos: [4, 0, 2], state: "minecraft:cut_red_sandstone"},
        {pos: [4, 0, 3], state: "minecraft:red_terracotta"},
        {pos: [4, 0, 4], state: "minecraft:red_terracotta"},
        {pos: [4, 0, 5], state: "minecraft:cut_red_sandstone"},
        {pos: [4, 0, 6], state: "minecraft:orange_glazed_terracotta{facing:east}"},
        {pos: [4, 0, 7], state: "minecraft:orange_glazed_terracotta{facing:south}"},
        {pos: [4, 0, 8], state: "minecraft:cut_red_sandstone"},
        {pos: [4, 0, 9], state: "minecraft:cut_red_sandstone"},
        {pos: [4, 0, 15], state: "minecraft:cut_red_sandstone"},
        {pos: [4, 0, 16], state: "minecraft:red_terracotta"},
        {pos: [4, 0, 17], state: "minecraft:red_terracotta"},
        {pos: [4, 0, 18], state: "minecraft:cut_red_sandstone"},
        {pos: [4, 0, 19], state: "minecraft:cut_red_sandstone"},
        {pos: [5, 0, 1], state: "minecraft:cut_red_sandstone"},
        {pos: [5, 0, 2], state: "minecraft:cut_red_sandstone"},
        {pos: [5, 0, 3], state: "minecraft:red_terracotta"},
        {pos: [5, 0, 4], state: "minecraft:red_terracotta"},
        {pos: [5, 0, 5], state: "minecraft:cut_red_sandstone"},
        {pos: [5, 0, 6], state: "minecraft:cut_red_sandstone"},
        {pos: [5, 0, 7], state: "minecraft:cut_red_sandstone"},
        {pos: [5, 0, 8], state: "minecraft:cut_red_sandstone"},
        {pos: [5, 0, 9], state: "minecraft:cut_red_sandstone"},
        {pos: [5, 0, 10], state: "minecraft:cut_red_sandstone"},
        {pos: [5, 0, 13], state: "minecraft:cut_red_sandstone"},
        {pos: [5, 0, 14], state: "minecraft:cut_red_sandstone"},
        {pos: [5, 0, 15], state: "minecraft:cut_red_sandstone"},
        {pos: [5, 0, 16], state: "minecraft:cut_red_sandstone"},
        {pos: [5, 0, 17], state: "minecraft:red_terracotta"},
        {pos: [5, 0, 18], state: "minecraft:cut_red_sandstone"},
        {pos: [5, 0, 19], state: "minecraft:cut_red_sandstone"},
        {pos: [6, 0, 2], state: "minecraft:cut_red_sandstone"},
        {pos: [6, 0, 3], state: "minecraft:cut_red_sandstone"},
        {pos: [6, 0, 4], state: "minecraft:cut_red_sandstone"},
        {pos: [6, 0, 5], state: "minecraft:cut_red_sandstone"},
        {pos: [6, 0, 7], state: "minecraft:cut_red_sandstone"},
        {pos: [6, 0, 8], state: "minecraft:cut_red_sandstone"},
        {pos: [6, 0, 9], state: "minecraft:cut_red_sandstone"},
        {pos: [6, 0, 10], state: "minecraft:cut_red_sandstone"},
        {pos: [6, 0, 11], state: "minecraft:cut_red_sandstone"},
        {pos: [6, 0, 12], state: "minecraft:cut_red_sandstone"},
        {pos: [6, 0, 13], state: "minecraft:cut_red_sandstone"},
        {pos: [6, 0, 14], state: "minecraft:cut_red_sandstone"},
        {pos: [6, 0, 15], state: "minecraft:cut_red_sandstone"},
        {pos: [6, 0, 16], state: "minecraft:cut_red_sandstone"},
        {pos: [6, 0, 17], state: "minecraft:cut_red_sandstone"},
        {pos: [6, 0, 18], state: "minecraft:cut_red_sandstone"},
        {pos: [7, 0, 1], state: "minecraft:cut_red_sandstone"},
        {pos: [7, 0, 2], state: "minecraft:cut_red_sandstone"},
        {pos: [7, 0, 3], state: "minecraft:cut_red_sandstone"},
        {pos: [7, 0, 4], state: "minecraft:cut_red_sandstone"},
        {pos: [7, 0, 9], state: "minecraft:cut_red_sandstone"},
        {pos: [7, 0, 10], state: "minecraft:cut_red_sandstone"},
        {pos: [7, 0, 11], state: "minecraft:cut_red_sandstone"},
        {pos: [7, 0, 12], state: "minecraft:cut_red_sandstone"},
        {pos: [7, 0, 13], state: "minecraft:cut_red_sandstone"},
        {pos: [7, 0, 14], state: "minecraft:cut_red_sandstone"},
        {pos: [7, 0, 15], state: "minecraft:cut_red_sandstone"},
        {pos: [7, 0, 16], state: "minecraft:cut_red_sandstone"},
        {pos: [7, 0, 17], state: "minecraft:cut_red_sandstone"},
        {pos: [8, 0, 1], state: "minecraft:cut_red_sandstone"},
        {pos: [8, 0, 2], state: "minecraft:yellow_glazed_terracotta{facing:north}"},
        {pos: [8, 0, 3], state: "minecraft:yellow_glazed_terracotta{facing:west}"},
        {pos: [8, 0, 4], state: "minecraft:cut_red_sandstone"},
        {pos: [8, 0, 8], state: "minecraft:cut_red_sandstone"},
        {pos: [8, 0, 9], state: "minecraft:cut_red_sandstone"},
        {pos: [8, 0, 10], state: "minecraft:cut_red_sandstone"},
        {pos: [8, 0, 11], state: "minecraft:cut_red_sandstone"},
        {pos: [8, 0, 12], state: "minecraft:cut_red_sandstone"},
        {pos: [8, 0, 13], state: "minecraft:cut_red_sandstone"},
        {pos: [8, 0, 14], state: "minecraft:cut_red_sandstone"},
        {pos: [8, 0, 15], state: "minecraft:cut_red_sandstone"},
        {pos: [8, 0, 16], state: "minecraft:cut_red_sandstone"},
        {pos: [8, 0, 17], state: "minecraft:cut_red_sandstone"},
        {pos: [9, 0, 1], state: "minecraft:cut_red_sandstone"},
        {pos: [9, 0, 2], state: "minecraft:red_terracotta"},
        {pos: [9, 0, 3], state: "minecraft:red_terracotta"},
        {pos: [9, 0, 4], state: "minecraft:cut_red_sandstone"},
        {pos: [9, 0, 5], state: "minecraft:cut_red_sandstone"},
        {pos: [9, 0, 6], state: "minecraft:orange_glazed_terracotta{facing:north}"},
        {pos: [9, 0, 7], state: "minecraft:orange_glazed_terracotta{facing:west}"},
        {pos: [9, 0, 8], state: "minecraft:cut_red_sandstone"},
        {pos: [9, 0, 9], state: "minecraft:cut_red_sandstone"},
        {pos: [9, 0, 10], state: "minecraft:cut_red_sandstone"},
        {pos: [9, 0, 12], state: "minecraft:cut_red_sandstone"},
        {pos: [9, 0, 13], state: "minecraft:cut_red_sandstone"},
        {pos: [9, 0, 14], state: "minecraft:cut_red_sandstone"},
        {pos: [9, 0, 15], state: "minecraft:cut_red_sandstone"},
        {pos: [9, 0, 16], state: "minecraft:cut_red_sandstone"},
        {pos: [9, 0, 17], state: "minecraft:cut_red_sandstone"},
        {pos: [10, 0, 0], state: "minecraft:cut_red_sandstone"},
        {pos: [10, 0, 1], state: "minecraft:cut_red_sandstone"},
        {pos: [10, 0, 2], state: "minecraft:red_terracotta"},
        {pos: [10, 0, 3], state: "minecraft:red_terracotta"},
        {pos: [10, 0, 4], state: "minecraft:cut_red_sandstone"},
        {pos: [10, 0, 5], state: "minecraft:cut_red_sandstone"},
        {pos: [10, 0, 6], state: "minecraft:orange_glazed_terracotta{facing:east}"},
        {pos: [10, 0, 7], state: "minecraft:red_terracotta"},
        {pos: [10, 0, 8], state: "minecraft:cut_red_sandstone"},
        {pos: [10, 0, 9], state: "minecraft:cut_red_sandstone"},
        {pos: [10, 0, 14], state: "minecraft:cut_red_sandstone"},
        {pos: [10, 0, 15], state: "minecraft:red_terracotta"},
        {pos: [10, 0, 16], state: "minecraft:red_terracotta"},
        {pos: [10, 0, 17], state: "minecraft:cut_red_sandstone"},
        {pos: [11, 0, 0], state: "minecraft:cut_red_sandstone"},
        {pos: [11, 0, 1], state: "minecraft:cut_red_sandstone"},
        {pos: [11, 0, 2], state: "minecraft:cut_red_sandstone"},
        {pos: [11, 0, 3], state: "minecraft:cut_red_sandstone"},
        {pos: [11, 0, 4], state: "minecraft:cut_red_sandstone"},
        {pos: [11, 0, 5], state: "minecraft:cut_red_sandstone"},
        {pos: [11, 0, 6], state: "minecraft:cut_red_sandstone"},
        {pos: [11, 0, 7], state: "minecraft:red_terracotta"},
        {pos: [11, 0, 8], state: "minecraft:red_terracotta"},
        {pos: [11, 0, 9], state: "minecraft:cut_red_sandstone"},
        {pos: [11, 0, 10], state: "minecraft:cut_red_sandstone"},
        {pos: [11, 0, 14], state: "minecraft:cut_red_sandstone"},
        {pos: [11, 0, 15], state: "minecraft:red_terracotta"},
        {pos: [11, 0, 16], state: "minecraft:red_terracotta"},
        {pos: [11, 0, 17], state: "minecraft:cut_red_sandstone"},
        {pos: [11, 0, 18], state: "minecraft:cut_red_sandstone"},
        {pos: [12, 0, 3], state: "minecraft:cut_red_sandstone"},
        {pos: [12, 0, 4], state: "minecraft:cut_red_sandstone"},
        {pos: [12, 0, 5], state: "minecraft:cut_red_sandstone"},
        {pos: [12, 0, 6], state: "minecraft:cut_red_sandstone"},
        {pos: [12, 0, 7], state: "minecraft:cut_red_sandstone"},
        {pos: [12, 0, 8], state: "minecraft:cut_red_sandstone"},
        {pos: [12, 0, 9], state: "minecraft:cut_red_sandstone"},
        {pos: [12, 0, 10], state: "minecraft:cut_red_sandstone"},
        {pos: [12, 0, 15], state: "minecraft:cut_red_sandstone"},
        {pos: [12, 0, 16], state: "minecraft:cut_red_sandstone"},
        {pos: [12, 0, 17], state: "minecraft:cut_red_sandstone"},
        {pos: [13, 0, 5], state: "minecraft:cut_red_sandstone"},
        {pos: [13, 0, 6], state: "minecraft:cut_red_sandstone"},
        {pos: [13, 0, 7], state: "minecraft:cut_red_sandstone"},
        {pos: [13, 0, 8], state: "minecraft:cut_red_sandstone"},
        {pos: [13, 0, 9], state: "minecraft:cut_red_sandstone"},
        {pos: [0, 1, 6], state: "minecraft:red_sand"},
        {pos: [0, 1, 7], state: "minecraft:red_sand"},
        {pos: [1, 1, 5], state: "minecraft:red_sand"},
        {pos: [1, 1, 6], state: "minecraft:cut_red_sandstone"},
        {pos: [1, 1, 7], state: "minecraft:cut_red_sandstone"},
        {pos: [1, 1, 8], state: "minecraft:red_sand"},
        {pos: [2, 1, 3], state: "minecraft:red_sand"},
        {pos: [2, 1, 4], state: "minecraft:red_sand"},
        {pos: [2, 1, 5], state: "minecraft:red_sand"},
        {pos: [2, 1, 6], state: "minecraft:cut_red_sandstone"},
        {pos: [2, 1, 7], state: "minecraft:red_terracotta"},
        {pos: [2, 1, 8], state: "minecraft:red_terracotta"},
        {pos: [2, 1, 9], state: "minecraft:red_sand"},
        {pos: [3, 1, 2], state: "minecraft:red_sand"},
        {pos: [3, 1, 3], state: "minecraft:red_sand"},
        {pos: [3, 1, 4], state: "minecraft:red_sand"},
        {pos: [3, 1, 5], state: "minecraft:red_sand"},
        {pos: [3, 1, 6], state: "minecraft:red_sand"},
        {pos: [3, 1, 7], state: "minecraft:red_terracotta"},
        {pos: [3, 1, 8], state: "minecraft:red_terracotta"},
        {pos: [3, 1, 9], state: "minecraft:red_sand"},
        {pos: [3, 1, 16], state: "minecraft:cut_red_sandstone"},
        {pos: [3, 1, 17], state: "minecraft:cut_red_sandstone"},
        {pos: [3, 1, 18], state: "minecraft:red_sand"},
        {pos: [4, 1, 1], state: "minecraft:red_sand"},
        {pos: [4, 1, 2], state: "minecraft:cut_red_sandstone"},
        {pos: [4, 1, 3], state: "minecraft:red_terracotta"},
        {pos: [4, 1, 4], state: "minecraft:red_terracotta"},
        {pos: [4, 1, 5], state: "minecraft:cut_red_sandstone"},
        {pos: [4, 1, 6], state: "minecraft:red_sand"},
        {pos: [4, 1, 7], state: "minecraft:red_sand"},
        {pos: [4, 1, 8], state: "minecraft:red_sand"},
        {pos: [4, 1, 9], state: "minecraft:red_sand"},
        {pos: [4, 1, 15], state: "minecraft:red_sand"},
        {pos: [4, 1, 16], state: "minecraft:red_terracotta"},
        {pos: [4, 1, 17], state: "minecraft:red_terracotta"},
        {pos: [4, 1, 18], state: "minecraft:cut_red_sandstone"},
        {pos: [4, 1, 19], state: "minecraft:red_sand"},
        {pos: [5, 1, 1], state: "minecraft:red_sand"},
        {pos: [5, 1, 2], state: "minecraft:cut_red_sandstone"},
        {pos: [5, 1, 3], state: "minecraft:red_terracotta"},
        {pos: [5, 1, 4], state: "minecraft:red_terracotta"},
        {pos: [5, 1, 5], state: "minecraft:red_sand"},
        {pos: [5, 1, 6], state: "minecraft:red_sand"},
        {pos: [5, 1, 7], state: "minecraft:red_sand"},
        {pos: [5, 1, 8], state: "minecraft:red_sand"},
        {pos: [5, 1, 9], state: "minecraft:red_sand"},
        {pos: [5, 1, 10], state: "minecraft:red_sand"},
        {pos: [5, 1, 13], state: "minecraft:cut_red_sandstone"},
        {pos: [5, 1, 14], state: "minecraft:cut_red_sandstone"},
        {pos: [5, 1, 15], state: "minecraft:cut_red_sandstone"},
        {pos: [5, 1, 16], state: "minecraft:red_terracotta"},
        {pos: [5, 1, 17], state: "minecraft:red_terracotta"},
        {pos: [5, 1, 18], state: "minecraft:cut_red_sandstone"},
        {pos: [5, 1, 19], state: "minecraft:red_sand"},
        {pos: [6, 1, 2], state: "minecraft:cut_red_sandstone"},
        {pos: [6, 1, 3], state: "minecraft:cut_red_sandstone"},
        {pos: [6, 1, 4], state: "minecraft:red_sand"},
        {pos: [6, 1, 5], state: "minecraft:red_sand"},
        {pos: [6, 1, 7], state: "minecraft:red_sand"},
        {pos: [6, 1, 8], state: "minecraft:red_sand"},
        {pos: [6, 1, 9], state: "minecraft:red_sand"},
        {pos: [6, 1, 10], state: "minecraft:red_sand"},
        {pos: [6, 1, 11], state: "minecraft:red_sand"},
        {pos: [6, 1, 12], state: "minecraft:red_sand"},
        {pos: [6, 1, 13], state: "minecraft:red_sand"},
        {pos: [6, 1, 14], state: "minecraft:red_sand"},
        {pos: [6, 1, 15], state: "minecraft:red_sand"},
        {pos: [6, 1, 16], state: "minecraft:red_sand"},
        {pos: [6, 1, 17], state: "minecraft:cut_red_sandstone"},
        {pos: [6, 1, 18], state: "minecraft:red_sand"},
        {pos: [7, 1, 1], state: "minecraft:red_sand"},
        {pos: [7, 1, 2], state: "minecraft:red_sand"},
        {pos: [7, 1, 3], state: "minecraft:red_sand"},
        {pos: [7, 1, 4], state: "minecraft:red_sand"},
        {pos: [7, 1, 9], state: "minecraft:red_sand"},
        {pos: [7, 1, 10], state: "minecraft:red_sand"},
        {pos: [7, 1, 11], state: "minecraft:red_sand"},
        {pos: [7, 1, 12], state: "minecraft:red_sand"},
        {pos: [7, 1, 13], state: "minecraft:red_sand"},
        {pos: [7, 1, 14], state: "minecraft:red_sand"},
        {pos: [7, 1, 15], state: "minecraft:red_sand"},
        {pos: [7, 1, 16], state: "minecraft:red_sand"},
        {pos: [7, 1, 17], state: "minecraft:cut_red_sandstone"},
        {pos: [8, 1, 1], state: "minecraft:red_sand"},
        {pos: [8, 1, 2], state: "minecraft:red_sand"},
        {pos: [8, 1, 3], state: "minecraft:red_sand"},
        {pos: [8, 1, 4], state: "minecraft:red_sand"},
        {pos: [8, 1, 8], state: "minecraft:red_sand"},
        {pos: [8, 1, 9], state: "minecraft:red_sand"},
        {pos: [8, 1, 10], state: "minecraft:red_sand"},
        {pos: [8, 1, 11], state: "minecraft:red_sand"},
        {pos: [8, 1, 12], state: "minecraft:red_sand"},
        {pos: [8, 1, 13], state: "minecraft:red_sand"},
        {pos: [8, 1, 14], state: "minecraft:red_sandstone_stairs{facing:east,half:top,shape:straight,waterlogged:false}"},
        {pos: [8, 1, 15], state: "minecraft:red_sandstone_stairs{facing:east,half:top,shape:straight,waterlogged:false}"},
        {pos: [8, 1, 16], state: "minecraft:cut_red_sandstone"},
        {pos: [8, 1, 17], state: "minecraft:cut_red_sandstone"},
        {pos: [9, 1, 1], state: "minecraft:red_sand"},
        {pos: [9, 1, 2], state: "minecraft:red_terracotta"},
        {pos: [9, 1, 3], state: "minecraft:red_terracotta"},
        {pos: [9, 1, 4], state: "minecraft:red_sand"},
        {pos: [9, 1, 5], state: "minecraft:red_sand"},
        {pos: [9, 1, 6], state: "minecraft:red_sand"},
        {pos: [9, 1, 7], state: "minecraft:red_sand"},
        {pos: [9, 1, 8], state: "minecraft:red_sand"},
        {pos: [9, 1, 9], state: "minecraft:red_sand"},
        {pos: [9, 1, 10], state: "minecraft:red_sand"},
        {pos: [9, 1, 12], state: "minecraft:red_sand"},
        {pos: [9, 1, 13], state: "minecraft:cut_red_sandstone"},
        {pos: [9, 1, 14], state: "minecraft:cut_red_sandstone"},
        {pos: [9, 1, 15], state: "minecraft:cut_red_sandstone"},
        {pos: [9, 1, 16], state: "minecraft:cut_red_sandstone"},
        {pos: [9, 1, 17], state: "minecraft:cut_red_sandstone"},
        {pos: [10, 1, 0], state: "minecraft:red_sand"},
        {pos: [10, 1, 1], state: "minecraft:red_sand"},
        {pos: [10, 1, 2], state: "minecraft:red_terracotta"},
        {pos: [10, 1, 3], state: "minecraft:red_terracotta"},
        {pos: [10, 1, 4], state: "minecraft:cut_red_sandstone"},
        {pos: [10, 1, 5], state: "minecraft:red_sand"},
        {pos: [10, 1, 6], state: "minecraft:red_sand"},
        {pos: [10, 1, 7], state: "minecraft:red_terracotta"},
        {pos: [10, 1, 8], state: "minecraft:red_terracotta"},
        {pos: [10, 1, 9], state: "minecraft:red_sand"},
        {pos: [10, 1, 14], state: "minecraft:cut_red_sandstone"},
        {pos: [10, 1, 15], state: "minecraft:red_terracotta"},
        {pos: [10, 1, 16], state: "minecraft:red_terracotta"},
        {pos: [10, 1, 17], state: "minecraft:cut_red_sandstone"},
        {pos: [11, 1, 0], state: "minecraft:red_sand"},
        {pos: [11, 1, 1], state: "minecraft:red_sand"},
        {pos: [11, 1, 2], state: "minecraft:red_sand"},
        {pos: [11, 1, 3], state: "minecraft:cut_red_sandstone"},
        {pos: [11, 1, 4], state: "minecraft:cut_red_sandstone"},
        {pos: [11, 1, 5], state: "minecraft:red_sand"},
        {pos: [11, 1, 6], state: "minecraft:red_sand"},
        {pos: [11, 1, 7], state: "minecraft:red_terracotta"},
        {pos: [11, 1, 8], state: "minecraft:red_terracotta"},
        {pos: [11, 1, 9], state: "minecraft:cut_red_sandstone"},
        {pos: [11, 1, 10], state: "minecraft:red_sand"},
        {pos: [11, 1, 14], state: "minecraft:red_sand"},
        {pos: [11, 1, 15], state: "minecraft:red_terracotta"},
        {pos: [11, 1, 16], state: "minecraft:red_terracotta"},
        {pos: [11, 1, 17], state: "minecraft:cut_red_sandstone"},
        {pos: [11, 1, 18], state: "minecraft:red_sand"},
        {pos: [12, 1, 3], state: "minecraft:red_sand"},
        {pos: [12, 1, 4], state: "minecraft:red_sand"},
        {pos: [12, 1, 5], state: "minecraft:red_sand"},
        {pos: [12, 1, 6], state: "minecraft:red_sand"},
        {pos: [12, 1, 7], state: "minecraft:red_sand"},
        {pos: [12, 1, 8], state: "minecraft:cut_red_sandstone"},
        {pos: [12, 1, 9], state: "minecraft:cut_red_sandstone"},
        {pos: [12, 1, 10], state: "minecraft:red_sand"},
        {pos: [12, 1, 15], state: "minecraft:red_sand"},
        {pos: [12, 1, 16], state: "minecraft:red_sand"},
        {pos: [12, 1, 17], state: "minecraft:red_sand"},
        {pos: [13, 1, 5], state: "minecraft:red_sand"},
        {pos: [13, 1, 6], state: "minecraft:red_sand"},
        {pos: [13, 1, 7], state: "minecraft:red_sand"},
        {pos: [13, 1, 8], state: "minecraft:red_sand"},
        {pos: [13, 1, 9], state: "minecraft:red_sand"},
        {pos: [0, 2, 6], state: "minecraft:red_sand"},
        {pos: [0, 2, 7], state: "minecraft:red_sand"},
        {pos: [1, 2, 5], state: "minecraft:red_sand"},
        {pos: [1, 2, 6], state: "minecraft:red_sand"},
        {pos: [1, 2, 7], state: "minecraft:red_sand"},
        {pos: [1, 2, 8], state: "minecraft:red_sand"},
        {pos: [2, 2, 3], state: "minecraft:red_sand"},
        {pos: [2, 2, 4], state: "minecraft:red_sand"},
        {pos: [2, 2, 5], state: "minecraft:red_sand"},
        {pos: [2, 2, 6], state: "minecraft:red_sand"},
        {pos: [2, 2, 7], state: "minecraft:red_terracotta"},
        {pos: [2, 2, 8], state: "minecraft:red_terracotta"},
        {pos: [2, 2, 9], state: "minecraft:red_sand"},
        {pos: [3, 2, 2], state: "minecraft:red_sand"},
        {pos: [3, 2, 3], state: "minecraft:red_sand"},
        {pos: [3, 2, 4], state: "minecraft:red_sand"},
        {pos: [3, 2, 5], state: "minecraft:red_sand"},
        {pos: [3, 2, 6], state: "minecraft:red_sand"},
        {pos: [3, 2, 7], state: "minecraft:red_terracotta"},
        {pos: [3, 2, 8], state: "minecraft:red_terracotta"},
        {pos: [3, 2, 9], state: "minecraft:red_sand"},
        {pos: [3, 2, 16], state: "minecraft:red_sand"},
        {pos: [3, 2, 17], state: "minecraft:red_sand"},
        {pos: [3, 2, 18], state: "minecraft:red_sand"},
        {pos: [4, 2, 1], state: "minecraft:red_sand"},
        {pos: [4, 2, 2], state: "minecraft:red_sand"},
        {pos: [4, 2, 3], state: "minecraft:red_terracotta"},
        {pos: [4, 2, 4], state: "minecraft:red_terracotta"},
        {pos: [4, 2, 5], state: "minecraft:red_sand"},
        {pos: [4, 2, 6], state: "minecraft:red_sand"},
        {pos: [4, 2, 7], state: "minecraft:red_sand"},
        {pos: [4, 2, 8], state: "minecraft:red_sand"},
        {pos: [4, 2, 9], state: "minecraft:red_sand"},
        {pos: [4, 2, 15], state: "minecraft:red_sand"},
        {pos: [4, 2, 16], state: "minecraft:red_terracotta"},
        {pos: [4, 2, 17], state: "minecraft:red_terracotta"},
        {pos: [4, 2, 18], state: "minecraft:red_sand"},
        {pos: [4, 2, 19], state: "minecraft:red_sand"},
        {pos: [5, 2, 1], state: "minecraft:red_sand"},
        {pos: [5, 2, 2], state: "minecraft:red_sand"},
        {pos: [5, 2, 3], state: "minecraft:red_terracotta"},
        {pos: [5, 2, 4], state: "minecraft:red_terracotta"},
        {pos: [5, 2, 5], state: "minecraft:red_sand"},
        {pos: [5, 2, 6], state: "minecraft:red_sand"},
        {pos: [5, 2, 7], state: "minecraft:red_sand"},
        {pos: [5, 2, 8], state: "minecraft:red_sand"},
        {pos: [5, 2, 9], state: "minecraft:red_sand"},
        {pos: [5, 2, 10], state: "minecraft:red_sand"},
        {pos: [5, 2, 13], state: "minecraft:cut_red_sandstone"},
        {pos: [5, 2, 14], state: "minecraft:cut_red_sandstone"},
        {pos: [5, 2, 15], state: "minecraft:red_sand"},
        {pos: [5, 2, 16], state: "minecraft:red_terracotta"},
        {pos: [5, 2, 17], state: "minecraft:red_terracotta"},
        {pos: [5, 2, 18], state: "minecraft:red_sand"},
        {pos: [5, 2, 19], state: "minecraft:red_sand"},
        {pos: [6, 2, 2], state: "minecraft:red_sand"},
        {pos: [6, 2, 3], state: "minecraft:red_sand"},
        {pos: [6, 2, 4], state: "minecraft:red_sand"},
        {pos: [6, 2, 5], state: "minecraft:red_sand"},
        {pos: [6, 2, 7], state: "minecraft:red_sand"},
        {pos: [6, 2, 8], state: "minecraft:red_sand"},
        {pos: [6, 2, 9], state: "minecraft:red_sand"},
        {pos: [6, 2, 10], state: "minecraft:red_sand"},
        {pos: [6, 2, 11], state: "minecraft:red_sand"},
        {pos: [6, 2, 12], state: "minecraft:red_sand"},
        {pos: [6, 2, 13], state: "minecraft:red_sand"},
        {pos: [6, 2, 14], state: "minecraft:red_sand"},
        {pos: [6, 2, 15], state: "minecraft:red_sand"},
        {pos: [6, 2, 16], state: "minecraft:red_sand"},
        {pos: [6, 2, 17], state: "minecraft:cut_red_sandstone"},
        {pos: [6, 2, 18], state: "minecraft:red_sand"},
        {pos: [7, 2, 1], state: "minecraft:red_sand"},
        {pos: [7, 2, 2], state: "minecraft:red_sand"},
        {pos: [7, 2, 3], state: "minecraft:red_sand"},
        {pos: [7, 2, 4], state: "minecraft:red_sand"},
        {pos: [7, 2, 9], state: "minecraft:red_sand"},
        {pos: [7, 2, 10], state: "minecraft:red_sand"},
        {pos: [7, 2, 11], state: "minecraft:red_sand"},
        {pos: [7, 2, 12], state: "minecraft:red_sand"},
        {pos: [7, 2, 13], state: "minecraft:red_sand"},
        {pos: [7, 2, 14], state: "minecraft:red_sand"},
        {pos: [7, 2, 15], state: "minecraft:red_sand"},
        {pos: [7, 2, 16], state: "minecraft:red_sand"},
        {pos: [7, 2, 17], state: "minecraft:cut_red_sandstone"},
        {pos: [8, 2, 1], state: "minecraft:red_sand"},
        {pos: [8, 2, 2], state: "minecraft:red_sand"},
        {pos: [8, 2, 3], state: "minecraft:red_sand"},
        {pos: [8, 2, 4], state: "minecraft:red_sand"},
        {pos: [8, 2, 8], state: "minecraft:red_sand"},
        {pos: [8, 2, 9], state: "minecraft:red_sand"},
        {pos: [8, 2, 10], state: "minecraft:red_sand"},
        {pos: [8, 2, 11], state: "minecraft:red_sand"},
        {pos: [8, 2, 12], state: "minecraft:red_sand"},
        {pos: [8, 2, 13], state: "minecraft:red_sand"},
        {pos: [8, 2, 14], state: "minecraft:red_sand"},
        {pos: [8, 2, 15], state: "minecraft:red_sand"},
        {pos: [8, 2, 16], state: "minecraft:cut_red_sandstone"},
        {pos: [8, 2, 17], state: "minecraft:cut_red_sandstone"},
        {pos: [9, 2, 1], state: "minecraft:red_sand"},
        {pos: [9, 2, 2], state: "minecraft:red_terracotta"},
        {pos: [9, 2, 3], state: "minecraft:red_terracotta"},
        {pos: [9, 2, 4], state: "minecraft:red_sand"},
        {pos: [9, 2, 5], state: "minecraft:red_sand"},
        {pos: [9, 2, 6], state: "minecraft:red_sand"},
        {pos: [9, 2, 7], state: "minecraft:red_sand"},
        {pos: [9, 2, 8], state: "minecraft:red_sand"},
        {pos: [9, 2, 9], state: "minecraft:red_sand"},
        {pos: [9, 2, 10], state: "minecraft:red_sand"},
        {pos: [9, 2, 12], state: "minecraft:red_sand"},
        {pos: [9, 2, 13], state: "minecraft:cut_red_sandstone"},
        {pos: [9, 2, 14], state: "minecraft:red_sand"},
        {pos: [9, 2, 15], state: "minecraft:red_sand"},
        {pos: [9, 2, 16], state: "minecraft:cut_red_sandstone"},
        {pos: [9, 2, 17], state: "minecraft:cut_red_sandstone"},
        {pos: [10, 2, 0], state: "minecraft:red_sand"},
        {pos: [10, 2, 1], state: "minecraft:red_sand"},
        {pos: [10, 2, 2], state: "minecraft:red_terracotta"},
        {pos: [10, 2, 3], state: "minecraft:red_terracotta"},
        {pos: [10, 2, 4], state: "minecraft:red_sand"},
        {pos: [10, 2, 5], state: "minecraft:red_sand"},
        {pos: [10, 2, 6], state: "minecraft:red_sand"},
        {pos: [10, 2, 7], state: "minecraft:red_terracotta"},
        {pos: [10, 2, 8], state: "minecraft:red_terracotta"},
        {pos: [10, 2, 9], state: "minecraft:red_sand"},
        {pos: [10, 2, 14], state: "minecraft:red_sand"},
        {pos: [10, 2, 15], state: "minecraft:red_terracotta"},
        {pos: [10, 2, 16], state: "minecraft:red_terracotta"},
        {pos: [10, 2, 17], state: "minecraft:red_sand"},
        {pos: [11, 2, 0], state: "minecraft:red_sand"},
        {pos: [11, 2, 1], state: "minecraft:red_sand"},
        {pos: [11, 2, 2], state: "minecraft:red_sand"},
        {pos: [11, 2, 3], state: "minecraft:red_sand"},
        {pos: [11, 2, 4], state: "minecraft:red_sand"},
        {pos: [11, 2, 5], state: "minecraft:red_sand"},
        {pos: [11, 2, 6], state: "minecraft:red_sand"},
        {pos: [11, 2, 7], state: "minecraft:red_terracotta"},
        {pos: [11, 2, 8], state: "minecraft:red_terracotta"},
        {pos: [11, 2, 9], state: "minecraft:red_sand"},
        {pos: [11, 2, 10], state: "minecraft:red_sand"},
        {pos: [11, 2, 14], state: "minecraft:red_sand"},
        {pos: [11, 2, 15], state: "minecraft:red_terracotta"},
        {pos: [11, 2, 16], state: "minecraft:red_terracotta"},
        {pos: [11, 2, 17], state: "minecraft:red_sand"},
        {pos: [11, 2, 18], state: "minecraft:red_sand"},
        {pos: [12, 2, 3], state: "minecraft:red_sand"},
        {pos: [12, 2, 4], state: "minecraft:red_sand"},
        {pos: [12, 2, 5], state: "minecraft:red_sand"},
        {pos: [12, 2, 6], state: "minecraft:red_sand"},
        {pos: [12, 2, 7], state: "minecraft:red_sand"},
        {pos: [12, 2, 8], state: "minecraft:red_sand"},
        {pos: [12, 2, 9], state: "minecraft:red_sand"},
        {pos: [12, 2, 10], state: "minecraft:red_sand"},
        {pos: [12, 2, 15], state: "minecraft:red_sand"},
        {pos: [12, 2, 16], state: "minecraft:red_sand"},
        {pos: [12, 2, 17], state: "minecraft:red_sand"},
        {pos: [13, 2, 5], state: "minecraft:red_sand"},
        {pos: [13, 2, 6], state: "minecraft:red_sand"},
        {pos: [13, 2, 7], state: "minecraft:red_sand"},
        {pos: [13, 2, 8], state: "minecraft:red_sand"},
        {pos: [13, 2, 9], state: "minecraft:red_sand"},
        {pos: [0, 3, 6], state: "minecraft:red_sand"},
        {pos: [0, 3, 7], state: "minecraft:red_sand"},
        {pos: [1, 3, 5], state: "minecraft:red_sand"},
        {pos: [1, 3, 6], state: "minecraft:red_sand"},
        {pos: [1, 3, 7], state: "minecraft:red_sand"},
        {pos: [1, 3, 8], state: "minecraft:red_sand"},
        {pos: [2, 3, 3], state: "minecraft:red_sand"},
        {pos: [2, 3, 4], state: "minecraft:red_sand"},
        {pos: [2, 3, 5], state: "minecraft:red_sand"},
        {pos: [2, 3, 6], state: "minecraft:red_sand"},
        {pos: [2, 3, 7], state: "minecraft:cut_red_sandstone"},
        {pos: [2, 3, 8], state: "minecraft:red_terracotta"},
        {pos: [2, 3, 9], state: "minecraft:red_sand"},
        {pos: [3, 3, 2], state: "minecraft:red_sand"},
        {pos: [3, 3, 3], state: "minecraft:red_sand"},
        {pos: [3, 3, 4], state: "minecraft:red_sand"},
        {pos: [3, 3, 5], state: "minecraft:red_sand"},
        {pos: [3, 3, 6], state: "minecraft:red_sand"},
        {pos: [3, 3, 7], state: "minecraft:red_terracotta"},
        {pos: [3, 3, 8], state: "minecraft:cut_red_sandstone"},
        {pos: [3, 3, 9], state: "minecraft:red_sand"},
        {pos: [3, 3, 16], state: "minecraft:red_sand"},
        {pos: [3, 3, 17], state: "minecraft:red_sand"},
        {pos: [3, 3, 18], state: "minecraft:red_sand"},
        {pos: [4, 3, 1], state: "minecraft:red_sand"},
        {pos: [4, 3, 2], state: "minecraft:red_sand"},
        {pos: [4, 3, 3], state: "minecraft:red_terracotta"},
        {pos: [4, 3, 4], state: "minecraft:red_terracotta"},
        {pos: [4, 3, 5], state: "minecraft:red_sand"},
        {pos: [4, 3, 6], state: "minecraft:red_sand"},
        {pos: [4, 3, 7], state: "minecraft:red_sand"},
        {pos: [4, 3, 8], state: "minecraft:red_sand"},
        {pos: [4, 3, 9], state: "minecraft:red_sand"},
        {pos: [4, 3, 13], state: "minecraft:cut_red_sandstone"},
        {pos: [4, 3, 15], state: "minecraft:red_sand"},
        {pos: [4, 3, 16], state: "minecraft:red_terracotta"},
        {pos: [4, 3, 17], state: "minecraft:red_terracotta"},
        {pos: [4, 3, 18], state: "minecraft:red_sand"},
        {pos: [4, 3, 19], state: "minecraft:red_sand"},
        {pos: [5, 3, 1], state: "minecraft:red_sand"},
        {pos: [5, 3, 2], state: "minecraft:red_sand"},
        {pos: [5, 3, 3], state: "minecraft:cut_red_sandstone"},
        {pos: [5, 3, 4], state: "minecraft:cut_red_sandstone"},
        {pos: [5, 3, 5], state: "minecraft:red_sand"},
        {pos: [5, 3, 6], state: "minecraft:red_sand"},
        {pos: [5, 3, 7], state: "minecraft:red_sand"},
        {pos: [5, 3, 8], state: "minecraft:red_sand"},
        {pos: [5, 3, 9], state: "minecraft:red_sand"},
        {pos: [5, 3, 10], state: "minecraft:red_sand"},
        {pos: [5, 3, 13], state: "minecraft:cut_red_sandstone"},
        {pos: [5, 3, 14], state: "minecraft:red_sand"},
        {pos: [5, 3, 15], state: "minecraft:red_sand"},
        {pos: [5, 3, 16], state: "minecraft:red_terracotta"},
        {pos: [5, 3, 17], state: "minecraft:red_terracotta"},
        {pos: [5, 3, 18], state: "minecraft:red_sand"},
        {pos: [5, 3, 19], state: "minecraft:red_sand"},
        {pos: [6, 3, 2], state: "minecraft:red_sand"},
        {pos: [6, 3, 3], state: "minecraft:red_sand"},
        {pos: [6, 3, 4], state: "minecraft:red_sand"},
        {pos: [6, 3, 5], state: "minecraft:red_sand"},
        {pos: [6, 3, 7], state: "minecraft:red_sand"},
        {pos: [6, 3, 8], state: "minecraft:red_sand"},
        {pos: [6, 3, 9], state: "minecraft:red_sand"},
        {pos: [6, 3, 10], state: "minecraft:red_sand"},
        {pos: [6, 3, 11], state: "minecraft:red_sand"},
        {pos: [6, 3, 12], state: "minecraft:red_sand"},
        {pos: [6, 3, 13], state: "minecraft:cut_red_sandstone"},
        {pos: [6, 3, 14], state: "minecraft:red_sand"},
        {pos: [6, 3, 15], state: "minecraft:red_sand"},
        {pos: [6, 3, 16], state: "minecraft:red_sand"},
        {pos: [6, 3, 17], state: "minecraft:cut_red_sandstone"},
        {pos: [6, 3, 18], state: "minecraft:red_sand"},
        {pos: [7, 3, 1], state: "minecraft:red_sand"},
        {pos: [7, 3, 2], state: "minecraft:red_sand"},
        {pos: [7, 3, 3], state: "minecraft:red_sand"},
        {pos: [7, 3, 4], state: "minecraft:red_sand"},
        {pos: [7, 3, 9], state: "minecraft:red_sand"},
        {pos: [7, 3, 10], state: "minecraft:red_sand"},
        {pos: [7, 3, 11], state: "minecraft:red_sand"},
        {pos: [7, 3, 12], state: "minecraft:red_sand"},
        {pos: [7, 3, 13], state: "minecraft:chiseled_red_sandstone"},
        {pos: [7, 3, 14], state: "minecraft:red_sand"},
        {pos: [7, 3, 15], state: "minecraft:red_sand"},
        {pos: [7, 3, 16], state: "minecraft:red_sand"},
        {pos: [7, 3, 17], state: "minecraft:red_terracotta"},
        {pos: [8, 3, 1], state: "minecraft:red_sand"},
        {pos: [8, 3, 2], state: "minecraft:red_sand"},
        {pos: [8, 3, 3], state: "minecraft:red_sand"},
        {pos: [8, 3, 4], state: "minecraft:red_sand"},
        {pos: [8, 3, 8], state: "minecraft:red_sand"},
        {pos: [8, 3, 9], state: "minecraft:red_sand"},
        {pos: [8, 3, 10], state: "minecraft:red_sand"},
        {pos: [8, 3, 11], state: "minecraft:red_sand"},
        {pos: [8, 3, 12], state: "minecraft:red_sand"},
        {pos: [8, 3, 13], state: "minecraft:cut_red_sandstone"},
        {pos: [8, 3, 14], state: "minecraft:red_sand"},
        {pos: [8, 3, 15], state: "minecraft:red_sand"},
        {pos: [8, 3, 16], state: "minecraft:red_sand"},
        {pos: [8, 3, 17], state: "minecraft:red_terracotta"},
        {pos: [9, 3, 1], state: "minecraft:red_sand"},
        {pos: [9, 3, 2], state: "minecraft:cut_red_sandstone"},
        {pos: [9, 3, 3], state: "minecraft:red_terracotta"},
        {pos: [9, 3, 4], state: "minecraft:red_sand"},
        {pos: [9, 3, 5], state: "minecraft:red_sand"},
        {pos: [9, 3, 6], state: "minecraft:red_sand"},
        {pos: [9, 3, 7], state: "minecraft:red_sand"},
        {pos: [9, 3, 8], state: "minecraft:red_sand"},
        {pos: [9, 3, 9], state: "minecraft:red_sand"},
        {pos: [9, 3, 10], state: "minecraft:red_sand"},
        {pos: [9, 3, 13], state: "minecraft:cut_red_sandstone"},
        {pos: [9, 3, 14], state: "minecraft:red_sand"},
        {pos: [9, 3, 15], state: "minecraft:red_sand"},
        {pos: [9, 3, 16], state: "minecraft:red_sand"},
        {pos: [9, 3, 17], state: "minecraft:cut_red_sandstone"},
        {pos: [10, 3, 0], state: "minecraft:red_sand"},
        {pos: [10, 3, 1], state: "minecraft:red_sand"},
        {pos: [10, 3, 2], state: "minecraft:cut_red_sandstone"},
        {pos: [10, 3, 3], state: "minecraft:cut_red_sandstone"},
        {pos: [10, 3, 4], state: "minecraft:red_sand"},
        {pos: [10, 3, 5], state: "minecraft:red_sand"},
        {pos: [10, 3, 6], state: "minecraft:red_sand"},
        {pos: [10, 3, 7], state: "minecraft:red_terracotta"},
        {pos: [10, 3, 8], state: "minecraft:red_terracotta"},
        {pos: [10, 3, 9], state: "minecraft:red_sand"},
        {pos: [10, 3, 13], state: "minecraft:cut_red_sandstone"},
        {pos: [10, 3, 14], state: "minecraft:red_sand"},
        {pos: [10, 3, 15], state: "minecraft:red_terracotta"},
        {pos: [10, 3, 16], state: "minecraft:red_terracotta"},
        {pos: [10, 3, 17], state: "minecraft:red_sand"},
        {pos: [11, 3, 0], state: "minecraft:red_sand"},
        {pos: [11, 3, 1], state: "minecraft:red_sand"},
        {pos: [11, 3, 2], state: "minecraft:red_sand"},
        {pos: [11, 3, 3], state: "minecraft:red_sand"},
        {pos: [11, 3, 4], state: "minecraft:red_sand"},
        {pos: [11, 3, 5], state: "minecraft:red_sand"},
        {pos: [11, 3, 6], state: "minecraft:red_sand"},
        {pos: [11, 3, 7], state: "minecraft:cut_red_sandstone"},
        {pos: [11, 3, 8], state: "minecraft:cut_red_sandstone"},
        {pos: [11, 3, 9], state: "minecraft:red_sand"},
        {pos: [11, 3, 10], state: "minecraft:red_sand"},
        {pos: [11, 3, 14], state: "minecraft:red_sand"},
        {pos: [11, 3, 15], state: "minecraft:red_terracotta"},
        {pos: [11, 3, 16], state: "minecraft:red_terracotta"},
        {pos: [11, 3, 17], state: "minecraft:red_sand"},
        {pos: [11, 3, 18], state: "minecraft:red_sand"},
        {pos: [12, 3, 3], state: "minecraft:red_sand"},
        {pos: [12, 3, 4], state: "minecraft:red_sand"},
        {pos: [12, 3, 5], state: "minecraft:red_sand"},
        {pos: [12, 3, 6], state: "minecraft:red_sand"},
        {pos: [12, 3, 7], state: "minecraft:red_sand"},
        {pos: [12, 3, 8], state: "minecraft:red_sand"},
        {pos: [12, 3, 9], state: "minecraft:red_sand"},
        {pos: [12, 3, 10], state: "minecraft:red_sand"},
        {pos: [12, 3, 15], state: "minecraft:red_sand"},
        {pos: [12, 3, 16], state: "minecraft:red_sand"},
        {pos: [13, 3, 5], state: "minecraft:red_sand"},
        {pos: [13, 3, 6], state: "minecraft:red_sand"},
        {pos: [13, 3, 7], state: "minecraft:red_sand"},
        {pos: [13, 3, 8], state: "minecraft:red_sand"},
        {pos: [2, 4, 6], state: "minecraft:red_sand"},
        {pos: [2, 4, 7], state: "minecraft:cut_red_sandstone"},
        {pos: [2, 4, 8], state: "minecraft:cut_red_sandstone"},
        {pos: [3, 4, 3], state: "minecraft:red_sand"},
        {pos: [3, 4, 4], state: "minecraft:red_sand"},
        {pos: [3, 4, 5], state: "minecraft:red_sand"},
        {pos: [3, 4, 6], state: "minecraft:red_sand"},
        {pos: [3, 4, 7], state: "minecraft:red_terracotta"},
        {pos: [3, 4, 8], state: "minecraft:cut_red_sandstone"},
        {pos: [4, 4, 1], state: "minecraft:red_sand"},
        {pos: [4, 4, 2], state: "minecraft:red_sand"},
        {pos: [4, 4, 3], state: "minecraft:cut_red_sandstone"},
        {pos: [4, 4, 4], state: "minecraft:chiseled_red_sandstone"},
        {pos: [4, 4, 5], state: "minecraft:red_sand"},
        {pos: [4, 4, 6], state: "minecraft:red_sand"},
        {pos: [4, 4, 7], state: "minecraft:red_sand"},
        {pos: [4, 4, 13], state: "minecraft:cut_red_sandstone"},
        {pos: [4, 4, 15], state: "minecraft:red_sand"},
        {pos: [4, 4, 16], state: "minecraft:red_terracotta"},
        {pos: [4, 4, 17], state: "minecraft:cut_red_sandstone"},
        {pos: [4, 4, 18], state: "minecraft:red_sand"},
        {pos: [5, 4, 2], state: "minecraft:red_sand"},
        {pos: [5, 4, 3], state: "minecraft:red_sand"},
        {pos: [5, 4, 4], state: "minecraft:cut_red_sandstone"},
        {pos: [5, 4, 5], state: "minecraft:red_sand"},
        {pos: [5, 4, 13], state: "minecraft:red_terracotta"},
        {pos: [5, 4, 14], state: "minecraft:red_sand"},
        {pos: [5, 4, 15], state: "minecraft:red_sand"},
        {pos: [5, 4, 16], state: "minecraft:red_terracotta"},
        {pos: [5, 4, 17], state: "minecraft:red_terracotta"},
        {pos: [5, 4, 18], state: "minecraft:red_sand"},
        {pos: [6, 4, 2], state: "minecraft:red_sand"},
        {pos: [6, 4, 3], state: "minecraft:red_sand"},
        {pos: [6, 4, 4], state: "minecraft:red_sand"},
        {pos: [6, 4, 10], state: "minecraft:red_sand"},
        {pos: [6, 4, 11], state: "minecraft:red_sand"},
        {pos: [6, 4, 12], state: "minecraft:red_sand"},
        {pos: [6, 4, 13], state: "minecraft:cut_red_sandstone"},
        {pos: [6, 4, 14], state: "minecraft:red_sand"},
        {pos: [6, 4, 15], state: "minecraft:red_sand"},
        {pos: [6, 4, 16], state: "minecraft:red_sand"},
        {pos: [6, 4, 17], state: "minecraft:cut_red_sandstone"},
        {pos: [6, 4, 18], state: "minecraft:red_sand"},
        {pos: [7, 4, 10], state: "minecraft:red_sand"},
        {pos: [7, 4, 11], state: "minecraft:red_sand"},
        {pos: [7, 4, 12], state: "minecraft:red_sand"},
        {pos: [7, 4, 13], state: "minecraft:cut_red_sandstone"},
        {pos: [7, 4, 14], state: "minecraft:red_sand"},
        {pos: [7, 4, 15], state: "minecraft:red_sand"},
        {pos: [7, 4, 16], state: "minecraft:red_sand"},
        {pos: [7, 4, 17], state: "minecraft:cut_red_sandstone"},
        {pos: [8, 4, 1], state: "minecraft:red_sand"},
        {pos: [8, 4, 2], state: "minecraft:red_sand"},
        {pos: [8, 4, 3], state: "minecraft:red_sand"},
        {pos: [8, 4, 10], state: "minecraft:red_sand"},
        {pos: [8, 4, 11], state: "minecraft:red_sand"},
        {pos: [8, 4, 12], state: "minecraft:red_sand"},
        {pos: [8, 4, 13], state: "minecraft:cut_red_sandstone"},
        {pos: [8, 4, 14], state: "minecraft:red_sand"},
        {pos: [8, 4, 15], state: "minecraft:red_sand"},
        {pos: [8, 4, 16], state: "minecraft:red_sand"},
        {pos: [8, 4, 17], state: "minecraft:cut_red_sandstone"},
        {pos: [9, 4, 1], state: "minecraft:red_sand"},
        {pos: [9, 4, 2], state: "minecraft:cut_red_sandstone"},
        {pos: [9, 4, 3], state: "minecraft:cut_red_sandstone"},
        {pos: [9, 4, 4], state: "minecraft:red_sand"},
        {pos: [9, 4, 13], state: "minecraft:red_terracotta"},
        {pos: [9, 4, 14], state: "minecraft:red_sand"},
        {pos: [9, 4, 15], state: "minecraft:red_sand"},
        {pos: [9, 4, 16], state: "minecraft:red_sand"},
        {pos: [9, 4, 17], state: "minecraft:cut_red_sandstone"},
        {pos: [10, 4, 1], state: "minecraft:red_sand"},
        {pos: [10, 4, 2], state: "minecraft:chiseled_red_sandstone"},
        {pos: [10, 4, 3], state: "minecraft:cut_red_sandstone"},
        {pos: [10, 4, 7], state: "minecraft:cut_red_sandstone"},
        {pos: [10, 4, 8], state: "minecraft:chiseled_red_sandstone"},
        {pos: [10, 4, 13], state: "minecraft:cut_red_sandstone"},
        {pos: [10, 4, 14], state: "minecraft:red_sand"},
        {pos: [10, 4, 15], state: "minecraft:cut_red_sandstone"},
        {pos: [10, 4, 16], state: "minecraft:red_terracotta"},
        {pos: [10, 4, 17], state: "minecraft:red_sand"},
        {pos: [11, 4, 2], state: "minecraft:red_sand"},
        {pos: [11, 4, 3], state: "minecraft:red_sand"},
        {pos: [11, 4, 7], state: "minecraft:cut_red_sandstone"},
        {pos: [11, 4, 8], state: "minecraft:cut_red_sandstone"},
        {pos: [11, 4, 14], state: "minecraft:red_sand"},
        {pos: [11, 4, 15], state: "minecraft:cut_red_sandstone"},
        {pos: [11, 4, 16], state: "minecraft:cut_red_sandstone"},
        {pos: [11, 4, 17], state: "minecraft:red_sand"},
        {pos: [12, 4, 7], state: "minecraft:red_sand"},
        {pos: [12, 4, 8], state: "minecraft:red_sand"},
        {pos: [12, 4, 15], state: "minecraft:red_sand"},
        {pos: [13, 4, 7], state: "minecraft:red_sand"},
        {pos: [13, 4, 8], state: "minecraft:red_sand"},
        {pos: [2, 5, 7], state: "minecraft:cut_red_sandstone"},
        {pos: [2, 5, 8], state: "minecraft:cut_red_sandstone"},
        {pos: [3, 5, 7], state: "minecraft:cut_red_sandstone"},
        {pos: [3, 5, 8], state: "minecraft:cut_red_sandstone"},
        {pos: [4, 5, 3], state: "minecraft:red_sand"},
        {pos: [4, 5, 4], state: "minecraft:red_sand"},
        {pos: [4, 5, 13], state: "minecraft:cut_red_sandstone"},
        {pos: [4, 5, 16], state: "minecraft:red_terracotta"},
        {pos: [4, 5, 17], state: "minecraft:cut_red_sandstone"},
        {pos: [4, 5, 18], state: "minecraft:red_sand"},
        {pos: [5, 5, 3], state: "minecraft:red_sand"},
        {pos: [5, 5, 4], state: "minecraft:red_sand"},
        {pos: [5, 5, 5], state: "minecraft:red_sand"},
        {pos: [5, 5, 13], state: "minecraft:cut_red_sandstone"},
        {pos: [5, 5, 15], state: "minecraft:red_sand"},
        {pos: [5, 5, 16], state: "minecraft:red_terracotta"},
        {pos: [5, 5, 17], state: "minecraft:cut_red_sandstone"},
        {pos: [5, 5, 18], state: "minecraft:red_sand"},
        {pos: [6, 5, 10], state: "minecraft:red_sand"},
        {pos: [6, 5, 11], state: "minecraft:red_sand"},
        {pos: [6, 5, 12], state: "minecraft:red_sand"},
        {pos: [6, 5, 13], state: "minecraft:cut_red_sandstone"},
        {pos: [6, 5, 15], state: "minecraft:red_sand"},
        {pos: [6, 5, 16], state: "minecraft:red_sand"},
        {pos: [6, 5, 17], state: "minecraft:red_sand"},
        {pos: [7, 5, 11], state: "minecraft:red_sand"},
        {pos: [7, 5, 12], state: "minecraft:red_sand"},
        {pos: [7, 5, 13], state: "minecraft:cut_red_sandstone"},
        {pos: [8, 5, 12], state: "minecraft:red_sand"},
        {pos: [8, 5, 13], state: "minecraft:cut_red_sandstone"},
        {pos: [9, 5, 1], state: "minecraft:red_sand"},
        {pos: [9, 5, 2], state: "minecraft:red_sand"},
        {pos: [9, 5, 3], state: "minecraft:red_sand"},
        {pos: [9, 5, 13], state: "minecraft:cut_red_sandstone"},
        {pos: [9, 5, 15], state: "minecraft:red_sand"},
        {pos: [9, 5, 16], state: "minecraft:red_sand"},
        {pos: [9, 5, 17], state: "minecraft:red_sand"},
        {pos: [10, 5, 1], state: "minecraft:red_sand"},
        {pos: [10, 5, 2], state: "minecraft:red_sand"},
        {pos: [10, 5, 3], state: "minecraft:red_sand"},
        {pos: [10, 5, 13], state: "minecraft:cut_red_sandstone"},
        {pos: [10, 5, 14], state: "minecraft:red_sand"},
        {pos: [10, 5, 15], state: "minecraft:cut_red_sandstone"},
        {pos: [10, 5, 16], state: "minecraft:cut_red_sandstone"},
        {pos: [10, 5, 17], state: "minecraft:red_sand"},
        {pos: [11, 5, 2], state: "minecraft:red_sand"},
        {pos: [11, 5, 3], state: "minecraft:red_sand"},
        {pos: [11, 5, 14], state: "minecraft:red_sand"},
        {pos: [11, 5, 15], state: "minecraft:red_sand"},
        {pos: [11, 5, 16], state: "minecraft:cut_red_sandstone"},
        {pos: [12, 5, 15], state: "minecraft:red_sand"},
        {pos: [4, 6, 16], state: "minecraft:cut_red_sandstone"},
        {pos: [4, 6, 17], state: "minecraft:cut_red_sandstone"},
        {pos: [5, 6, 13], state: "minecraft:cut_red_sandstone"},
        {pos: [5, 6, 15], state: "minecraft:red_sand"},
        {pos: [5, 6, 16], state: "minecraft:cut_red_sandstone"},
        {pos: [5, 6, 17], state: "minecraft:cut_red_sandstone"},
        {pos: [6, 6, 12], state: "minecraft:red_sand"},
        {pos: [6, 6, 13], state: "minecraft:cut_red_sandstone"},
        {pos: [6, 6, 15], state: "minecraft:red_sand"},
        {pos: [6, 6, 16], state: "minecraft:red_sand"},
        {pos: [7, 6, 12], state: "minecraft:red_sand"},
        {pos: [7, 6, 13], state: "minecraft:cut_red_sandstone"},
        {pos: [8, 6, 13], state: "minecraft:cut_red_sandstone"},
        {pos: [9, 6, 13], state: "minecraft:cut_red_sandstone"},
        {pos: [10, 6, 15], state: "minecraft:red_sand"},
        {pos: [10, 6, 16], state: "minecraft:red_sand"},
        {pos: [11, 6, 15], state: "minecraft:red_sand"},
        {pos: [11, 6, 16], state: "minecraft:red_sand"}
    ],
    entities: [],
    palette: [
        "minecraft:cut_red_sandstone",
        "minecraft:red_terracotta",
        "minecraft:yellow_glazed_terracotta{facing:north}",
        "minecraft:orange_glazed_terracotta{facing:east}",
        "minecraft:orange_glazed_terracotta{facing:south}",
        "minecraft:yellow_glazed_terracotta{facing:west}",
        "minecraft:orange_glazed_terracotta{facing:north}",
        "minecraft:orange_glazed_terracotta{facing:west}",
        "minecraft:red_sand",
        "minecraft:chiseled_red_sandstone",
        "minecraft:red_sandstone_stairs{facing:east,half:top,shape:straight,waterlogged:false}"
    ],
    trailiertales_DataVersion: 2
}
