{
    DataVersion: 3953,
    size: [13, 7, 11],
    data: [
        {pos: [0, 0, 8], state: "minecraft:cut_red_sandstone"},
        {pos: [0, 0, 9], state: "minecraft:cut_red_sandstone"},
        {pos: [1, 0, 7], state: "minecraft:cut_red_sandstone"},
        {pos: [1, 0, 8], state: "minecraft:cut_red_sandstone"},
        {pos: [1, 0, 9], state: "minecraft:cut_red_sandstone"},
        {pos: [1, 0, 10], state: "minecraft:cut_red_sandstone"},
        {pos: [2, 0, 6], state: "minecraft:cut_red_sandstone"},
        {pos: [2, 0, 7], state: "minecraft:red_terracotta"},
        {pos: [2, 0, 8], state: "minecraft:red_terracotta"},
        {pos: [2, 0, 9], state: "minecraft:cut_red_sandstone"},
        {pos: [2, 0, 10], state: "minecraft:cut_red_sandstone"},
        {pos: [3, 0, 6], state: "minecraft:cut_red_sandstone"},
        {pos: [3, 0, 7], state: "minecraft:red_terracotta"},
        {pos: [3, 0, 8], state: "minecraft:red_terracotta"},
        {pos: [3, 0, 9], state: "minecraft:cut_red_sandstone"},
        {pos: [4, 0, 0], state: "minecraft:cut_red_sandstone"},
        {pos: [4, 0, 1], state: "minecraft:cut_red_sandstone"},
        {pos: [4, 0, 2], state: "minecraft:cut_red_sandstone"},
        {pos: [4, 0, 5], state: "minecraft:cut_red_sandstone"},
        {pos: [4, 0, 6], state: "minecraft:cut_red_sandstone"},
        {pos: [4, 0, 7], state: "minecraft:cut_red_sandstone"},
        {pos: [4, 0, 8], state: "minecraft:cut_red_sandstone"},
        {pos: [5, 0, 0], state: "minecraft:cut_red_sandstone"},
        {pos: [5, 0, 1], state: "minecraft:cut_red_sandstone"},
        {pos: [5, 0, 2], state: "minecraft:red_terracotta"},
        {pos: [5, 0, 3], state: "minecraft:red_terracotta"},
        {pos: [5, 0, 5], state: "minecraft:cut_red_sandstone"},
        {pos: [5, 0, 6], state: "minecraft:cut_red_sandstone"},
        {pos: [5, 0, 7], state: "minecraft:cut_red_sandstone"},
        {pos: [5, 0, 8], state: "minecraft:cut_red_sandstone"},
        {pos: [6, 0, 1], state: "minecraft:cut_red_sandstone"},
        {pos: [6, 0, 2], state: "minecraft:red_terracotta"},
        {pos: [6, 0, 3], state: "minecraft:red_terracotta"},
        {pos: [6, 0, 4], state: "minecraft:cut_red_sandstone"},
        {pos: [6, 0, 5], state: "minecraft:cut_red_sandstone"},
        {pos: [6, 0, 6], state: "minecraft:cut_red_sandstone"},
        {pos: [6, 0, 7], state: "minecraft:cut_red_sandstone"},
        {pos: [6, 0, 8], state: "minecraft:cut_red_sandstone"},
        {pos: [7, 0, 3], state: "minecraft:cut_red_sandstone"},
        {pos: [7, 0, 4], state: "minecraft:cut_red_sandstone"},
        {pos: [7, 0, 5], state: "minecraft:cut_red_sandstone"},
        {pos: [7, 0, 6], state: "minecraft:cut_red_sandstone"},
        {pos: [7, 0, 7], state: "minecraft:cut_red_sandstone"},
        {pos: [7, 0, 8], state: "minecraft:cut_red_sandstone"},
        {pos: [7, 0, 9], state: "minecraft:cut_red_sandstone"},
        {pos: [8, 0, 3], state: "minecraft:cut_red_sandstone"},
        {pos: [8, 0, 4], state: "minecraft:cut_red_sandstone"},
        {pos: [8, 0, 5], state: "minecraft:cut_red_sandstone"},
        {pos: [8, 0, 6], state: "minecraft:cut_red_sandstone"},
        {pos: [8, 0, 7], state: "minecraft:cut_red_sandstone"},
        {pos: [8, 0, 8], state: "minecraft:cut_red_sandstone"},
        {pos: [8, 0, 9], state: "minecraft:cut_red_sandstone"},
        {pos: [9, 0, 3], state: "minecraft:cut_red_sandstone"},
        {pos: [9, 0, 4], state: "minecraft:cut_red_sandstone"},
        {pos: [9, 0, 5], state: "minecraft:cut_red_sandstone"},
        {pos: [9, 0, 6], state: "minecraft:cut_red_sandstone"},
        {pos: [9, 0, 7], state: "minecraft:cut_red_sandstone"},
        {pos: [10, 0, 5], state: "minecraft:cut_red_sandstone"},
        {pos: [10, 0, 6], state: "minecraft:cut_red_sandstone"},
        {pos: [10, 0, 7], state: "minecraft:cut_red_sandstone"},
        {pos: [10, 0, 8], state: "minecraft:cut_red_sandstone"},
        {pos: [11, 0, 6], state: "minecraft:cut_red_sandstone"},
        {pos: [11, 0, 7], state: "minecraft:red_terracotta"},
        {pos: [11, 0, 8], state: "minecraft:cut_red_sandstone"},
        {pos: [12, 0, 7], state: "minecraft:cut_red_sandstone"},
        {pos: [12, 0, 8], state: "minecraft:cut_red_sandstone"},
        {pos: [0, 1, 8], state: "minecraft:red_sand"},
        {pos: [0, 1, 9], state: "minecraft:red_sand"},
        {pos: [1, 1, 7], state: "minecraft:red_sand"},
        {pos: [1, 1, 8], state: "minecraft:cut_red_sandstone"},
        {pos: [1, 1, 9], state: "minecraft:cut_red_sandstone"},
        {pos: [1, 1, 10], state: "minecraft:red_sand"},
        {pos: [2, 1, 6], state: "minecraft:red_sand"},
        {pos: [2, 1, 7], state: "minecraft:red_terracotta"},
        {pos: [2, 1, 8], state: "minecraft:red_terracotta"},
        {pos: [2, 1, 9], state: "minecraft:cut_red_sandstone"},
        {pos: [2, 1, 10], state: "minecraft:red_sand"},
        {pos: [3, 1, 6], state: "minecraft:red_sand"},
        {pos: [3, 1, 7], state: "minecraft:red_terracotta"},
        {pos: [3, 1, 8], state: "minecraft:red_terracotta"},
        {pos: [3, 1, 9], state: "minecraft:red_sand"},
        {pos: [4, 1, 0], state: "minecraft:red_sand"},
        {pos: [4, 1, 1], state: "minecraft:red_sand"},
        {pos: [4, 1, 2], state: "minecraft:red_sand"},
        {pos: [4, 1, 5], state: "minecraft:red_sand"},
        {pos: [4, 1, 6], state: "minecraft:red_sand"},
        {pos: [4, 1, 7], state: "minecraft:red_sand"},
        {pos: [4, 1, 8], state: "minecraft:red_sand"},
        {pos: [5, 1, 0], state: "minecraft:red_sand"},
        {pos: [5, 1, 1], state: "minecraft:red_sand"},
        {pos: [5, 1, 2], state: "minecraft:red_terracotta"},
        {pos: [5, 1, 3], state: "minecraft:red_terracotta"},
        {pos: [5, 1, 5], state: "minecraft:red_sand"},
        {pos: [5, 1, 6], state: "minecraft:red_sand"},
        {pos: [5, 1, 7], state: "minecraft:red_sand"},
        {pos: [5, 1, 8], state: "minecraft:red_sand"},
        {pos: [6, 1, 1], state: "minecraft:red_sand"},
        {pos: [6, 1, 2], state: "minecraft:red_terracotta"},
        {pos: [6, 1, 3], state: "minecraft:red_terracotta"},
        {pos: [6, 1, 4], state: "minecraft:red_sand"},
        {pos: [6, 1, 5], state: "minecraft:red_sand"},
        {pos: [6, 1, 6], state: "minecraft:red_sand"},
        {pos: [6, 1, 7], state: "minecraft:red_sand"},
        {pos: [6, 1, 8], state: "minecraft:red_sand"},
        {pos: [7, 1, 3], state: "minecraft:red_sand"},
        {pos: [7, 1, 4], state: "minecraft:red_sand"},
        {pos: [7, 1, 5], state: "minecraft:cut_red_sandstone"},
        {pos: [7, 1, 6], state: "minecraft:red_sandstone_stairs{facing:east,half:top,shape:straight,waterlogged:false}"},
        {pos: [7, 1, 7], state: "minecraft:cut_red_sandstone"},
        {pos: [7, 1, 8], state: "minecraft:red_sand"},
        {pos: [7, 1, 9], state: "minecraft:red_sand"},
        {pos: [8, 1, 3], state: "minecraft:red_sand"},
        {pos: [8, 1, 4], state: "minecraft:red_sand"},
        {pos: [8, 1, 5], state: "minecraft:red_sandstone_stairs{facing:south,half:top,shape:straight,waterlogged:false}"},
        {pos: [8, 1, 6], state: "minecraft:red_terracotta"},
        {pos: [8, 1, 7], state: "minecraft:red_sandstone_stairs{facing:north,half:top,shape:straight,waterlogged:false}"},
        {pos: [8, 1, 8], state: "minecraft:red_sand"},
        {pos: [8, 1, 9], state: "minecraft:red_sand"},
        {pos: [9, 1, 3], state: "minecraft:red_sand"},
        {pos: [9, 1, 4], state: "minecraft:red_sand"},
        {pos: [9, 1, 5], state: "minecraft:cut_red_sandstone"},
        {pos: [9, 1, 6], state: "minecraft:red_sandstone_stairs{facing:west,half:top,shape:straight,waterlogged:false}"},
        {pos: [9, 1, 7], state: "minecraft:cut_red_sandstone"},
        {pos: [10, 1, 5], state: "minecraft:red_sand"},
        {pos: [10, 1, 6], state: "minecraft:red_terracotta"},
        {pos: [10, 1, 7], state: "minecraft:red_terracotta"},
        {pos: [10, 1, 8], state: "minecraft:red_sand"},
        {pos: [11, 1, 6], state: "minecraft:red_terracotta"},
        {pos: [11, 1, 7], state: "minecraft:red_terracotta"},
        {pos: [11, 1, 8], state: "minecraft:red_sand"},
        {pos: [12, 1, 7], state: "minecraft:red_sand"},
        {pos: [12, 1, 8], state: "minecraft:red_sand"},
        {pos: [0, 2, 8], state: "minecraft:red_sand"},
        {pos: [0, 2, 9], state: "minecraft:red_sand"},
        {pos: [1, 2, 7], state: "minecraft:red_sand"},
        {pos: [1, 2, 8], state: "minecraft:red_sand"},
        {pos: [1, 2, 9], state: "minecraft:red_sand"},
        {pos: [1, 2, 10], state: "minecraft:red_sand"},
        {pos: [2, 2, 6], state: "minecraft:red_sand"},
        {pos: [2, 2, 7], state: "minecraft:red_terracotta"},
        {pos: [2, 2, 8], state: "minecraft:red_terracotta"},
        {pos: [2, 2, 9], state: "minecraft:red_sand"},
        {pos: [2, 2, 10], state: "minecraft:red_sand"},
        {pos: [3, 2, 6], state: "minecraft:red_sand"},
        {pos: [3, 2, 7], state: "minecraft:red_terracotta"},
        {pos: [3, 2, 8], state: "minecraft:red_terracotta"},
        {pos: [3, 2, 9], state: "minecraft:red_sand"},
        {pos: [4, 2, 0], state: "minecraft:red_sand"},
        {pos: [4, 2, 1], state: "minecraft:red_sand"},
        {pos: [4, 2, 2], state: "minecraft:red_sand"},
        {pos: [4, 2, 5], state: "minecraft:red_sand"},
        {pos: [4, 2, 6], state: "minecraft:red_sand"},
        {pos: [4, 2, 7], state: "minecraft:red_sand"},
        {pos: [4, 2, 8], state: "minecraft:red_sand"},
        {pos: [5, 2, 0], state: "minecraft:red_sand"},
        {pos: [5, 2, 1], state: "minecraft:red_sand"},
        {pos: [5, 2, 2], state: "minecraft:red_terracotta"},
        {pos: [5, 2, 3], state: "minecraft:red_terracotta"},
        {pos: [5, 2, 5], state: "minecraft:red_sand"},
        {pos: [5, 2, 6], state: "minecraft:red_sand"},
        {pos: [5, 2, 7], state: "minecraft:red_sand"},
        {pos: [5, 2, 8], state: "minecraft:red_sand"},
        {pos: [6, 2, 1], state: "minecraft:red_sand"},
        {pos: [6, 2, 2], state: "minecraft:red_terracotta"},
        {pos: [6, 2, 3], state: "minecraft:red_terracotta"},
        {pos: [6, 2, 4], state: "minecraft:red_sand"},
        {pos: [6, 2, 5], state: "minecraft:red_sand"},
        {pos: [6, 2, 6], state: "minecraft:red_sand"},
        {pos: [6, 2, 7], state: "minecraft:red_sand"},
        {pos: [6, 2, 8], state: "minecraft:red_sand"},
        {pos: [7, 2, 3], state: "minecraft:red_sand"},
        {pos: [7, 2, 4], state: "minecraft:red_sand"},
        {pos: [7, 2, 5], state: "minecraft:red_sand"},
        {pos: [7, 2, 6], state: "minecraft:red_sand"},
        {pos: [7, 2, 7], state: "minecraft:red_sand"},
        {pos: [7, 2, 8], state: "minecraft:red_sand"},
        {pos: [7, 2, 9], state: "minecraft:red_sand"},
        {pos: [8, 2, 3], state: "minecraft:red_sand"},
        {pos: [8, 2, 4], state: "minecraft:red_sand"},
        {pos: [8, 2, 5], state: "minecraft:red_sand"},
        {pos: [8, 2, 6], state: "minecraft:red_sand"},
        {pos: [8, 2, 7], state: "minecraft:red_sand"},
        {pos: [8, 2, 8], state: "minecraft:red_sand"},
        {pos: [8, 2, 9], state: "minecraft:red_sand"},
        {pos: [9, 2, 3], state: "minecraft:red_sand"},
        {pos: [9, 2, 4], state: "minecraft:red_sand"},
        {pos: [9, 2, 5], state: "minecraft:red_sand"},
        {pos: [9, 2, 6], state: "minecraft:red_sand"},
        {pos: [9, 2, 7], state: "minecraft:red_sand"},
        {pos: [10, 2, 5], state: "minecraft:red_sand"},
        {pos: [10, 2, 6], state: "minecraft:red_terracotta"},
        {pos: [10, 2, 7], state: "minecraft:red_terracotta"},
        {pos: [10, 2, 8], state: "minecraft:red_sand"},
        {pos: [11, 2, 6], state: "minecraft:red_terracotta"},
        {pos: [11, 2, 7], state: "minecraft:red_terracotta"},
        {pos: [11, 2, 8], state: "minecraft:red_sand"},
        {pos: [12, 2, 7], state: "minecraft:red_sand"},
        {pos: [12, 2, 8], state: "minecraft:red_sand"},
        {pos: [0, 3, 8], state: "minecraft:red_sand"},
        {pos: [0, 3, 9], state: "minecraft:red_sand"},
        {pos: [1, 3, 7], state: "minecraft:red_sand"},
        {pos: [1, 3, 8], state: "minecraft:red_sand"},
        {pos: [1, 3, 9], state: "minecraft:red_sand"},
        {pos: [1, 3, 10], state: "minecraft:red_sand"},
        {pos: [2, 3, 6], state: "minecraft:red_sand"},
        {pos: [2, 3, 7], state: "minecraft:red_terracotta"},
        {pos: [2, 3, 8], state: "minecraft:red_terracotta"},
        {pos: [2, 3, 9], state: "minecraft:red_sand"},
        {pos: [2, 3, 10], state: "minecraft:red_sand"},
        {pos: [3, 3, 6], state: "minecraft:red_sand"},
        {pos: [3, 3, 7], state: "minecraft:red_terracotta"},
        {pos: [3, 3, 8], state: "minecraft:red_terracotta"},
        {pos: [3, 3, 9], state: "minecraft:red_sand"},
        {pos: [4, 3, 0], state: "minecraft:red_sand"},
        {pos: [4, 3, 1], state: "minecraft:red_sand"},
        {pos: [4, 3, 2], state: "minecraft:red_sand"},
        {pos: [4, 3, 5], state: "minecraft:red_sand"},
        {pos: [4, 3, 6], state: "minecraft:red_sand"},
        {pos: [4, 3, 7], state: "minecraft:red_sand"},
        {pos: [4, 3, 8], state: "minecraft:red_sand"},
        {pos: [5, 3, 0], state: "minecraft:red_sand"},
        {pos: [5, 3, 1], state: "minecraft:red_sand"},
        {pos: [5, 3, 2], state: "minecraft:cut_red_sandstone"},
        {pos: [5, 3, 3], state: "minecraft:red_terracotta"},
        {pos: [5, 3, 5], state: "minecraft:red_sand"},
        {pos: [5, 3, 6], state: "minecraft:red_sand"},
        {pos: [5, 3, 7], state: "minecraft:red_sand"},
        {pos: [5, 3, 8], state: "minecraft:red_sand"},
        {pos: [6, 3, 1], state: "minecraft:red_sand"},
        {pos: [6, 3, 2], state: "minecraft:cut_red_sandstone"},
        {pos: [6, 3, 3], state: "minecraft:red_terracotta"},
        {pos: [6, 3, 4], state: "minecraft:red_sand"},
        {pos: [6, 3, 5], state: "minecraft:red_sand"},
        {pos: [6, 3, 6], state: "minecraft:red_sand"},
        {pos: [6, 3, 7], state: "minecraft:red_sand"},
        {pos: [6, 3, 8], state: "minecraft:red_sand"},
        {pos: [7, 3, 3], state: "minecraft:red_sand"},
        {pos: [7, 3, 4], state: "minecraft:red_sand"},
        {pos: [7, 3, 5], state: "minecraft:red_sand"},
        {pos: [7, 3, 6], state: "minecraft:red_sand"},
        {pos: [7, 3, 7], state: "minecraft:red_sand"},
        {pos: [7, 3, 8], state: "minecraft:red_sand"},
        {pos: [7, 3, 9], state: "minecraft:red_sand"},
        {pos: [8, 3, 3], state: "minecraft:red_sand"},
        {pos: [8, 3, 4], state: "minecraft:red_sand"},
        {pos: [8, 3, 5], state: "minecraft:red_sand"},
        {pos: [8, 3, 6], state: "minecraft:red_sand"},
        {pos: [8, 3, 7], state: "minecraft:red_sand"},
        {pos: [8, 3, 8], state: "minecraft:red_sand"},
        {pos: [8, 3, 9], state: "minecraft:red_sand"},
        {pos: [9, 3, 3], state: "minecraft:red_sand"},
        {pos: [9, 3, 4], state: "minecraft:red_sand"},
        {pos: [9, 3, 5], state: "minecraft:red_sand"},
        {pos: [9, 3, 6], state: "minecraft:red_sand"},
        {pos: [9, 3, 7], state: "minecraft:red_sand"},
        {pos: [10, 3, 5], state: "minecraft:red_sand"},
        {pos: [10, 3, 6], state: "minecraft:red_terracotta"},
        {pos: [10, 3, 7], state: "minecraft:red_terracotta"},
        {pos: [10, 3, 8], state: "minecraft:red_sand"},
        {pos: [11, 3, 6], state: "minecraft:red_terracotta"},
        {pos: [11, 3, 7], state: "minecraft:red_terracotta"},
        {pos: [11, 3, 8], state: "minecraft:red_sand"},
        {pos: [12, 3, 7], state: "minecraft:red_sand"},
        {pos: [12, 3, 8], state: "minecraft:red_sand"},
        {pos: [1, 4, 7], state: "minecraft:red_sand"},
        {pos: [1, 4, 8], state: "minecraft:red_sand"},
        {pos: [1, 4, 9], state: "minecraft:red_sand"},
        {pos: [2, 4, 7], state: "minecraft:red_terracotta"},
        {pos: [2, 4, 8], state: "minecraft:cut_red_sandstone"},
        {pos: [2, 4, 9], state: "minecraft:red_sand"},
        {pos: [3, 4, 6], state: "minecraft:red_sand"},
        {pos: [3, 4, 7], state: "minecraft:red_terracotta"},
        {pos: [3, 4, 8], state: "minecraft:red_terracotta"},
        {pos: [3, 4, 9], state: "minecraft:red_sand"},
        {pos: [4, 4, 1], state: "minecraft:red_sand"},
        {pos: [4, 4, 2], state: "minecraft:red_sand"},
        {pos: [4, 4, 7], state: "minecraft:red_sand"},
        {pos: [4, 4, 8], state: "minecraft:red_sand"},
        {pos: [5, 4, 1], state: "minecraft:red_sand"},
        {pos: [5, 4, 2], state: "minecraft:cut_red_sandstone"},
        {pos: [5, 4, 3], state: "minecraft:cut_red_sandstone"},
        {pos: [5, 4, 7], state: "minecraft:red_sand"},
        {pos: [6, 4, 2], state: "minecraft:cut_red_sandstone"},
        {pos: [6, 4, 3], state: "minecraft:red_terracotta"},
        {pos: [6, 4, 4], state: "minecraft:red_sand"},
        {pos: [6, 4, 5], state: "minecraft:red_sand"},
        {pos: [7, 4, 3], state: "minecraft:red_sand"},
        {pos: [7, 4, 4], state: "minecraft:red_sand"},
        {pos: [7, 4, 5], state: "minecraft:red_sand"},
        {pos: [7, 4, 6], state: "minecraft:red_sand"},
        {pos: [8, 4, 3], state: "minecraft:red_sand"},
        {pos: [8, 4, 4], state: "minecraft:red_sand"},
        {pos: [8, 4, 5], state: "minecraft:red_sand"},
        {pos: [10, 4, 6], state: "minecraft:red_terracotta"},
        {pos: [10, 4, 7], state: "minecraft:cut_red_sandstone"},
        {pos: [11, 4, 6], state: "minecraft:red_terracotta"},
        {pos: [11, 4, 7], state: "minecraft:red_terracotta"},
        {pos: [11, 4, 8], state: "minecraft:red_sand"},
        {pos: [12, 4, 7], state: "minecraft:red_sand"},
        {pos: [12, 4, 8], state: "minecraft:red_sand"},
        {pos: [1, 5, 8], state: "minecraft:red_sand"},
        {pos: [1, 5, 9], state: "minecraft:red_sand"},
        {pos: [2, 5, 7], state: "minecraft:cut_red_sandstone"},
        {pos: [2, 5, 8], state: "minecraft:red_terracotta"},
        {pos: [2, 5, 9], state: "minecraft:red_sand"},
        {pos: [3, 5, 7], state: "minecraft:cut_red_sandstone"},
        {pos: [3, 5, 8], state: "minecraft:red_terracotta"},
        {pos: [5, 5, 2], state: "minecraft:cut_red_sandstone"},
        {pos: [5, 5, 3], state: "minecraft:cut_red_sandstone"},
        {pos: [6, 5, 2], state: "minecraft:cut_red_sandstone"},
        {pos: [6, 5, 3], state: "minecraft:cut_red_sandstone"},
        {pos: [10, 5, 6], state: "minecraft:cut_red_sandstone"},
        {pos: [10, 5, 7], state: "minecraft:cut_red_sandstone"},
        {pos: [11, 5, 6], state: "minecraft:cut_red_sandstone"},
        {pos: [11, 5, 7], state: "minecraft:cut_red_sandstone"},
        {pos: [2, 6, 7], state: "minecraft:cut_red_sandstone"},
        {pos: [2, 6, 8], state: "minecraft:cut_red_sandstone"},
        {pos: [3, 6, 7], state: "minecraft:cut_red_sandstone"},
        {pos: [3, 6, 8], state: "minecraft:cut_red_sandstone"}
    ],
    entities: [],
    palette: [
        "minecraft:cut_red_sandstone",
        "minecraft:red_terracotta",
        "minecraft:red_sand",
        "minecraft:red_sandstone_stairs{facing:east,half:top,shape:straight,waterlogged:false}",
        "minecraft:red_sandstone_stairs{facing:south,half:top,shape:straight,waterlogged:false}",
        "minecraft:red_sandstone_stairs{facing:north,half:top,shape:straight,waterlogged:false}",
        "minecraft:red_sandstone_stairs{facing:west,half:top,shape:straight,waterlogged:false}"
    ],
    trailiertales_DataVersion: 2
}
