{
    DataVersion: 3953,
    size: [15, 6, 18],
    data: [
        {pos: [0, 0, 5], state: "minecraft:cut_red_sandstone"},
        {pos: [0, 0, 6], state: "minecraft:cut_red_sandstone"},
        {pos: [0, 0, 7], state: "minecraft:cut_red_sandstone"},
        {pos: [0, 0, 15], state: "minecraft:cut_red_sandstone"},
        {pos: [0, 0, 16], state: "minecraft:cut_red_sandstone"},
        {pos: [1, 0, 4], state: "minecraft:cut_red_sandstone"},
        {pos: [1, 0, 5], state: "minecraft:cut_red_sandstone"},
        {pos: [1, 0, 6], state: "minecraft:cut_red_sandstone"},
        {pos: [1, 0, 7], state: "minecraft:cut_red_sandstone"},
        {pos: [1, 0, 8], state: "minecraft:cut_red_sandstone"},
        {pos: [1, 0, 14], state: "minecraft:cut_red_sandstone"},
        {pos: [1, 0, 15], state: "minecraft:cut_red_sandstone"},
        {pos: [1, 0, 16], state: "minecraft:cut_red_sandstone"},
        {pos: [2, 0, 1], state: "minecraft:cut_red_sandstone"},
        {pos: [2, 0, 2], state: "minecraft:cut_red_sandstone"},
        {pos: [2, 0, 3], state: "minecraft:cut_red_sandstone"},
        {pos: [2, 0, 4], state: "minecraft:cut_red_sandstone"},
        {pos: [2, 0, 5], state: "minecraft:cut_red_sandstone"},
        {pos: [2, 0, 6], state: "minecraft:cut_red_sandstone"},
        {pos: [2, 0, 7], state: "minecraft:cut_red_sandstone"},
        {pos: [2, 0, 8], state: "minecraft:cut_red_sandstone"},
        {pos: [2, 0, 13], state: "minecraft:cut_red_sandstone"},
        {pos: [2, 0, 14], state: "minecraft:red_terracotta"},
        {pos: [2, 0, 15], state: "minecraft:red_terracotta"},
        {pos: [2, 0, 16], state: "minecraft:cut_red_sandstone"},
        {pos: [2, 0, 17], state: "minecraft:cut_red_sandstone"},
        {pos: [3, 0, 0], state: "minecraft:cut_red_sandstone"},
        {pos: [3, 0, 1], state: "minecraft:cut_red_sandstone"},
        {pos: [3, 0, 2], state: "minecraft:cut_red_sandstone"},
        {pos: [3, 0, 3], state: "minecraft:cut_red_sandstone"},
        {pos: [3, 0, 4], state: "minecraft:cut_red_sandstone"},
        {pos: [3, 0, 5], state: "minecraft:cut_red_sandstone"},
        {pos: [3, 0, 6], state: "minecraft:cut_red_sandstone"},
        {pos: [3, 0, 7], state: "minecraft:cut_red_sandstone"},
        {pos: [3, 0, 8], state: "minecraft:cut_red_sandstone"},
        {pos: [3, 0, 13], state: "minecraft:cut_red_sandstone"},
        {pos: [3, 0, 14], state: "minecraft:cut_red_sandstone"},
        {pos: [3, 0, 15], state: "minecraft:cut_red_sandstone"},
        {pos: [3, 0, 16], state: "minecraft:cut_red_sandstone"},
        {pos: [3, 0, 17], state: "minecraft:cut_red_sandstone"},
        {pos: [4, 0, 0], state: "minecraft:cut_red_sandstone"},
        {pos: [4, 0, 1], state: "minecraft:cut_red_sandstone"},
        {pos: [4, 0, 2], state: "minecraft:cut_red_sandstone"},
        {pos: [4, 0, 3], state: "minecraft:cut_red_sandstone"},
        {pos: [4, 0, 4], state: "minecraft:cut_red_sandstone"},
        {pos: [4, 0, 5], state: "minecraft:cut_red_sandstone"},
        {pos: [4, 0, 6], state: "minecraft:cut_red_sandstone"},
        {pos: [4, 0, 7], state: "minecraft:cut_red_sandstone"},
        {pos: [4, 0, 8], state: "minecraft:cut_red_sandstone"},
        {pos: [4, 0, 11], state: "minecraft:cut_red_sandstone"},
        {pos: [4, 0, 12], state: "minecraft:cut_red_sandstone"},
        {pos: [4, 0, 13], state: "minecraft:cut_red_sandstone"},
        {pos: [4, 0, 14], state: "minecraft:cut_red_sandstone"},
        {pos: [4, 0, 15], state: "minecraft:cut_red_sandstone"},
        {pos: [4, 0, 16], state: "minecraft:cut_red_sandstone"},
        {pos: [4, 0, 17], state: "minecraft:cut_red_sandstone"},
        {pos: [5, 0, 0], state: "minecraft:cut_red_sandstone"},
        {pos: [5, 0, 1], state: "minecraft:cut_red_sandstone"},
        {pos: [5, 0, 2], state: "minecraft:cut_red_sandstone"},
        {pos: [5, 0, 3], state: "minecraft:cut_red_sandstone"},
        {pos: [5, 0, 4], state: "minecraft:cut_red_sandstone"},
        {pos: [5, 0, 5], state: "minecraft:cut_red_sandstone"},
        {pos: [5, 0, 10], state: "minecraft:cut_red_sandstone"},
        {pos: [5, 0, 11], state: "minecraft:cut_red_sandstone"},
        {pos: [5, 0, 12], state: "minecraft:cut_red_sandstone"},
        {pos: [5, 0, 13], state: "minecraft:cut_red_sandstone"},
        {pos: [5, 0, 14], state: "minecraft:cut_red_sandstone"},
        {pos: [5, 0, 15], state: "minecraft:cut_red_sandstone"},
        {pos: [5, 0, 16], state: "minecraft:cut_red_sandstone"},
        {pos: [5, 0, 17], state: "minecraft:cut_red_sandstone"},
        {pos: [6, 0, 0], state: "minecraft:cut_red_sandstone"},
        {pos: [6, 0, 1], state: "minecraft:cut_red_sandstone"},
        {pos: [6, 0, 2], state: "minecraft:cut_red_sandstone"},
        {pos: [6, 0, 3], state: "minecraft:cut_red_sandstone"},
        {pos: [6, 0, 4], state: "minecraft:cut_red_sandstone"},
        {pos: [6, 0, 10], state: "minecraft:cut_red_sandstone"},
        {pos: [6, 0, 11], state: "minecraft:cut_red_sandstone"},
        {pos: [6, 0, 12], state: "minecraft:cut_red_sandstone"},
        {pos: [6, 0, 13], state: "minecraft:cut_red_sandstone"},
        {pos: [6, 0, 14], state: "minecraft:cut_red_sandstone"},
        {pos: [6, 0, 15], state: "minecraft:cut_red_sandstone"},
        {pos: [6, 0, 16], state: "minecraft:cut_red_sandstone"},
        {pos: [7, 0, 1], state: "minecraft:cut_red_sandstone"},
        {pos: [7, 0, 2], state: "minecraft:cut_red_sandstone"},
        {pos: [7, 0, 3], state: "minecraft:cut_red_sandstone"},
        {pos: [7, 0, 4], state: "minecraft:cut_red_sandstone"},
        {pos: [7, 0, 5], state: "minecraft:cut_red_sandstone"},
        {pos: [7, 0, 6], state: "minecraft:cut_red_sandstone"},
        {pos: [7, 0, 7], state: "minecraft:cut_red_sandstone"},
        {pos: [7, 0, 11], state: "minecraft:cut_red_sandstone"},
        {pos: [7, 0, 12], state: "minecraft:cut_red_sandstone"},
        {pos: [7, 0, 13], state: "minecraft:cut_red_sandstone"},
        {pos: [7, 0, 14], state: "minecraft:cut_red_sandstone"},
        {pos: [7, 0, 15], state: "minecraft:cut_red_sandstone"},
        {pos: [7, 0, 16], state: "minecraft:cut_red_sandstone"},
        {pos: [8, 0, 3], state: "minecraft:cut_red_sandstone"},
        {pos: [8, 0, 4], state: "minecraft:cut_red_sandstone"},
        {pos: [8, 0, 5], state: "minecraft:cut_red_sandstone"},
        {pos: [8, 0, 6], state: "minecraft:cut_red_sandstone"},
        {pos: [8, 0, 7], state: "minecraft:cut_red_sandstone"},
        {pos: [8, 0, 8], state: "minecraft:cut_red_sandstone"},
        {pos: [8, 0, 10], state: "minecraft:cut_red_sandstone"},
        {pos: [8, 0, 11], state: "minecraft:cut_red_sandstone"},
        {pos: [8, 0, 12], state: "minecraft:cut_red_sandstone"},
        {pos: [8, 0, 13], state: "minecraft:cut_red_sandstone"},
        {pos: [8, 0, 14], state: "minecraft:cut_red_sandstone"},
        {pos: [8, 0, 15], state: "minecraft:cut_red_sandstone"},
        {pos: [9, 0, 5], state: "minecraft:cut_red_sandstone"},
        {pos: [9, 0, 6], state: "minecraft:cut_red_sandstone"},
        {pos: [9, 0, 7], state: "minecraft:cut_red_sandstone"},
        {pos: [9, 0, 8], state: "minecraft:cut_red_sandstone"},
        {pos: [9, 0, 9], state: "minecraft:cut_red_sandstone"},
        {pos: [9, 0, 10], state: "minecraft:cut_red_sandstone"},
        {pos: [9, 0, 11], state: "minecraft:cut_red_sandstone"},
        {pos: [9, 0, 12], state: "minecraft:cut_red_sandstone"},
        {pos: [9, 0, 13], state: "minecraft:cut_red_sandstone"},
        {pos: [9, 0, 14], state: "minecraft:cut_red_sandstone"},
        {pos: [9, 0, 15], state: "minecraft:cut_red_sandstone"},
        {pos: [9, 0, 16], state: "minecraft:cut_red_sandstone"},
        {pos: [10, 0, 4], state: "minecraft:cut_red_sandstone"},
        {pos: [10, 0, 5], state: "minecraft:cut_red_sandstone"},
        {pos: [10, 0, 6], state: "minecraft:cut_red_sandstone"},
        {pos: [10, 0, 7], state: "minecraft:cut_red_sandstone"},
        {pos: [10, 0, 8], state: "minecraft:cut_red_sandstone"},
        {pos: [10, 0, 9], state: "minecraft:cut_red_sandstone"},
        {pos: [10, 0, 10], state: "minecraft:cut_red_sandstone"},
        {pos: [10, 0, 11], state: "minecraft:cut_red_sandstone"},
        {pos: [10, 0, 12], state: "minecraft:cut_red_sandstone"},
        {pos: [10, 0, 13], state: "minecraft:cut_red_sandstone"},
        {pos: [10, 0, 14], state: "minecraft:cut_red_sandstone"},
        {pos: [10, 0, 15], state: "minecraft:cut_red_sandstone"},
        {pos: [11, 0, 3], state: "minecraft:cut_red_sandstone"},
        {pos: [11, 0, 4], state: "minecraft:cut_red_sandstone"},
        {pos: [11, 0, 5], state: "minecraft:cut_red_sandstone"},
        {pos: [11, 0, 6], state: "minecraft:cut_red_sandstone"},
        {pos: [11, 0, 9], state: "minecraft:cut_red_sandstone"},
        {pos: [11, 0, 10], state: "minecraft:cut_red_sandstone"},
        {pos: [11, 0, 11], state: "minecraft:cut_red_sandstone"},
        {pos: [11, 0, 12], state: "minecraft:cut_red_sandstone"},
        {pos: [11, 0, 13], state: "minecraft:cut_red_sandstone"},
        {pos: [11, 0, 14], state: "minecraft:cut_red_sandstone"},
        {pos: [11, 0, 15], state: "minecraft:cut_red_sandstone"},
        {pos: [12, 0, 3], state: "minecraft:cut_red_sandstone"},
        {pos: [12, 0, 4], state: "minecraft:cut_red_sandstone"},
        {pos: [12, 0, 5], state: "minecraft:cut_red_sandstone"},
        {pos: [12, 0, 10], state: "minecraft:cut_red_sandstone"},
        {pos: [12, 0, 11], state: "minecraft:cut_red_sandstone"},
        {pos: [12, 0, 12], state: "minecraft:cut_red_sandstone"},
        {pos: [12, 0, 13], state: "minecraft:red_terracotta"},
        {pos: [12, 0, 14], state: "minecraft:cut_red_sandstone"},
        {pos: [12, 0, 15], state: "minecraft:cut_red_sandstone"},
        {pos: [13, 0, 3], state: "minecraft:cut_red_sandstone"},
        {pos: [13, 0, 4], state: "minecraft:cut_red_sandstone"},
        {pos: [13, 0, 11], state: "minecraft:cut_red_sandstone"},
        {pos: [13, 0, 12], state: "minecraft:cut_red_sandstone"},
        {pos: [13, 0, 13], state: "minecraft:red_terracotta"},
        {pos: [13, 0, 14], state: "minecraft:cut_red_sandstone"},
        {pos: [13, 0, 15], state: "minecraft:cut_red_sandstone"},
        {pos: [14, 0, 12], state: "minecraft:cut_red_sandstone"},
        {pos: [14, 0, 13], state: "minecraft:cut_red_sandstone"},
        {pos: [14, 0, 14], state: "minecraft:cut_red_sandstone"},
        {pos: [0, 1, 5], state: "minecraft:red_sand"},
        {pos: [0, 1, 6], state: "minecraft:red_sand"},
        {pos: [0, 1, 7], state: "minecraft:red_sand"},
        {pos: [0, 1, 15], state: "minecraft:red_sand"},
        {pos: [0, 1, 16], state: "minecraft:red_sand"},
        {pos: [1, 1, 4], state: "minecraft:red_sand"},
        {pos: [1, 1, 5], state: "minecraft:red_sand"},
        {pos: [1, 1, 6], state: "minecraft:red_sand"},
        {pos: [1, 1, 7], state: "minecraft:red_sand"},
        {pos: [1, 1, 8], state: "minecraft:red_sand"},
        {pos: [1, 1, 14], state: "minecraft:red_sand"},
        {pos: [1, 1, 15], state: "minecraft:red_sand"},
        {pos: [1, 1, 16], state: "minecraft:red_sand"},
        {pos: [2, 1, 1], state: "minecraft:red_sand"},
        {pos: [2, 1, 2], state: "minecraft:red_sand"},
        {pos: [2, 1, 3], state: "minecraft:red_sand"},
        {pos: [2, 1, 4], state: "minecraft:red_sand"},
        {pos: [2, 1, 5], state: "minecraft:red_sand"},
        {pos: [2, 1, 6], state: "minecraft:cut_red_sandstone"},
        {pos: [2, 1, 7], state: "minecraft:cut_red_sandstone"},
        {pos: [2, 1, 8], state: "minecraft:cut_red_sandstone"},
        {pos: [2, 1, 13], state: "minecraft:red_sand"},
        {pos: [2, 1, 14], state: "minecraft:red_terracotta"},
        {pos: [2, 1, 15], state: "minecraft:red_terracotta"},
        {pos: [2, 1, 16], state: "minecraft:red_sand"},
        {pos: [2, 1, 17], state: "minecraft:red_sand"},
        {pos: [3, 1, 0], state: "minecraft:cut_red_sandstone"},
        {pos: [3, 1, 1], state: "minecraft:cut_red_sandstone"},
        {pos: [3, 1, 2], state: "minecraft:red_sand"},
        {pos: [3, 1, 3], state: "minecraft:red_sand"},
        {pos: [3, 1, 4], state: "minecraft:red_sand"},
        {pos: [3, 1, 5], state: "minecraft:red_sand"},
        {pos: [3, 1, 6], state: "minecraft:red_sandstone_stairs{facing:west,half:top,shape:straight,waterlogged:false}"},
        {pos: [3, 1, 7], state: "minecraft:red_sandstone_stairs{facing:west,half:top,shape:straight,waterlogged:false}"},
        {pos: [3, 1, 8], state: "minecraft:red_sand"},
        {pos: [3, 1, 13], state: "minecraft:red_sand"},
        {pos: [3, 1, 14], state: "minecraft:red_terracotta"},
        {pos: [3, 1, 15], state: "minecraft:red_terracotta"},
        {pos: [3, 1, 16], state: "minecraft:red_sand"},
        {pos: [3, 1, 17], state: "minecraft:red_sand"},
        {pos: [4, 1, 0], state: "minecraft:cut_red_sandstone"},
        {pos: [4, 1, 1], state: "minecraft:cut_red_sandstone"},
        {pos: [4, 1, 2], state: "minecraft:cut_red_sandstone"},
        {pos: [4, 1, 3], state: "minecraft:red_sand"},
        {pos: [4, 1, 4], state: "minecraft:red_sand"},
        {pos: [4, 1, 5], state: "minecraft:red_sand"},
        {pos: [4, 1, 6], state: "minecraft:red_sand"},
        {pos: [4, 1, 7], state: "minecraft:red_sand"},
        {pos: [4, 1, 8], state: "minecraft:red_sand"},
        {pos: [4, 1, 11], state: "minecraft:red_sand"},
        {pos: [4, 1, 12], state: "minecraft:red_sand"},
        {pos: [4, 1, 13], state: "minecraft:red_sand"},
        {pos: [4, 1, 14], state: "minecraft:red_sand"},
        {pos: [4, 1, 15], state: "minecraft:red_sand"},
        {pos: [4, 1, 16], state: "minecraft:red_sand"},
        {pos: [4, 1, 17], state: "minecraft:red_sand"},
        {pos: [5, 1, 0], state: "minecraft:cut_red_sandstone"},
        {pos: [5, 1, 1], state: "minecraft:cut_red_sandstone"},
        {pos: [5, 1, 2], state: "minecraft:cut_red_sandstone"},
        {pos: [5, 1, 3], state: "minecraft:red_sand"},
        {pos: [5, 1, 4], state: "minecraft:red_sand"},
        {pos: [5, 1, 5], state: "minecraft:red_sand"},
        {pos: [5, 1, 10], state: "minecraft:red_sand"},
        {pos: [5, 1, 11], state: "minecraft:red_sand"},
        {pos: [5, 1, 12], state: "minecraft:red_sand"},
        {pos: [5, 1, 13], state: "minecraft:red_sandstone_stairs{facing:south,half:top,shape:straight,waterlogged:false}"},
        {pos: [5, 1, 14], state: "minecraft:cut_red_sandstone"},
        {pos: [5, 1, 15], state: "minecraft:red_sand"},
        {pos: [5, 1, 16], state: "minecraft:red_sand"},
        {pos: [5, 1, 17], state: "minecraft:red_sand"},
        {pos: [6, 1, 0], state: "minecraft:red_sand"},
        {pos: [6, 1, 1], state: "minecraft:cut_red_sandstone"},
        {pos: [6, 1, 2], state: "minecraft:red_sand"},
        {pos: [6, 1, 3], state: "minecraft:red_sand"},
        {pos: [6, 1, 4], state: "minecraft:red_sand"},
        {pos: [6, 1, 10], state: "minecraft:red_sand"},
        {pos: [6, 1, 11], state: "minecraft:red_sand"},
        {pos: [6, 1, 12], state: "minecraft:red_sand"},
        {pos: [6, 1, 13], state: "minecraft:red_terracotta"},
        {pos: [6, 1, 14], state: "minecraft:chiseled_red_sandstone"},
        {pos: [6, 1, 15], state: "minecraft:red_sand"},
        {pos: [6, 1, 16], state: "minecraft:red_sand"},
        {pos: [7, 1, 1], state: "minecraft:cut_red_sandstone"},
        {pos: [7, 1, 2], state: "minecraft:red_sand"},
        {pos: [7, 1, 3], state: "minecraft:red_sand"},
        {pos: [7, 1, 4], state: "minecraft:red_sand"},
        {pos: [7, 1, 5], state: "minecraft:red_sand"},
        {pos: [7, 1, 6], state: "minecraft:red_sand"},
        {pos: [7, 1, 7], state: "minecraft:red_sand"},
        {pos: [7, 1, 11], state: "minecraft:red_sand"},
        {pos: [7, 1, 12], state: "minecraft:red_sand"},
        {pos: [7, 1, 13], state: "minecraft:red_terracotta"},
        {pos: [7, 1, 14], state: "minecraft:cut_red_sandstone"},
        {pos: [7, 1, 15], state: "minecraft:red_sand"},
        {pos: [7, 1, 16], state: "minecraft:red_sand"},
        {pos: [8, 1, 3], state: "minecraft:red_sand"},
        {pos: [8, 1, 4], state: "minecraft:red_sand"},
        {pos: [8, 1, 5], state: "minecraft:red_sand"},
        {pos: [8, 1, 6], state: "minecraft:red_sand"},
        {pos: [8, 1, 7], state: "minecraft:red_sand"},
        {pos: [8, 1, 8], state: "minecraft:red_sand"},
        {pos: [8, 1, 10], state: "minecraft:red_sand"},
        {pos: [8, 1, 11], state: "minecraft:red_sand"},
        {pos: [8, 1, 12], state: "minecraft:red_sand"},
        {pos: [8, 1, 13], state: "minecraft:red_terracotta"},
        {pos: [8, 1, 14], state: "minecraft:cut_red_sandstone"},
        {pos: [8, 1, 15], state: "minecraft:red_sand"},
        {pos: [9, 1, 5], state: "minecraft:red_sand"},
        {pos: [9, 1, 6], state: "minecraft:red_sand"},
        {pos: [9, 1, 7], state: "minecraft:red_sand"},
        {pos: [9, 1, 8], state: "minecraft:cut_red_sandstone"},
        {pos: [9, 1, 9], state: "minecraft:cut_red_sandstone"},
        {pos: [9, 1, 10], state: "minecraft:cut_red_sandstone"},
        {pos: [9, 1, 11], state: "minecraft:red_sand"},
        {pos: [9, 1, 12], state: "minecraft:red_sand"},
        {pos: [9, 1, 13], state: "minecraft:red_sandstone_stairs{facing:south,half:top,shape:straight,waterlogged:false}"},
        {pos: [9, 1, 14], state: "minecraft:chiseled_red_sandstone"},
        {pos: [9, 1, 15], state: "minecraft:red_sand"},
        {pos: [9, 1, 16], state: "minecraft:red_sand"},
        {pos: [10, 1, 4], state: "minecraft:red_sand"},
        {pos: [10, 1, 5], state: "minecraft:red_sand"},
        {pos: [10, 1, 6], state: "minecraft:red_sand"},
        {pos: [10, 1, 7], state: "minecraft:red_sand"},
        {pos: [10, 1, 8], state: "minecraft:red_sand"},
        {pos: [10, 1, 9], state: "minecraft:red_sand"},
        {pos: [10, 1, 10], state: "minecraft:red_sand"},
        {pos: [10, 1, 11], state: "minecraft:red_sand"},
        {pos: [10, 1, 12], state: "minecraft:red_sand"},
        {pos: [10, 1, 13], state: "minecraft:red_sand"},
        {pos: [10, 1, 14], state: "minecraft:red_sand"},
        {pos: [10, 1, 15], state: "minecraft:red_sand"},
        {pos: [11, 1, 3], state: "minecraft:red_sand"},
        {pos: [11, 1, 4], state: "minecraft:red_terracotta"},
        {pos: [11, 1, 5], state: "minecraft:red_terracotta"},
        {pos: [11, 1, 6], state: "minecraft:red_sand"},
        {pos: [11, 1, 9], state: "minecraft:red_sand"},
        {pos: [11, 1, 10], state: "minecraft:red_sand"},
        {pos: [11, 1, 11], state: "minecraft:red_sand"},
        {pos: [11, 1, 12], state: "minecraft:red_sand"},
        {pos: [11, 1, 13], state: "minecraft:red_sand"},
        {pos: [11, 1, 14], state: "minecraft:red_sand"},
        {pos: [11, 1, 15], state: "minecraft:red_sand"},
        {pos: [12, 1, 3], state: "minecraft:red_sand"},
        {pos: [12, 1, 4], state: "minecraft:red_terracotta"},
        {pos: [12, 1, 5], state: "minecraft:red_terracotta"},
        {pos: [12, 1, 10], state: "minecraft:red_sand"},
        {pos: [12, 1, 11], state: "minecraft:red_sand"},
        {pos: [12, 1, 12], state: "minecraft:red_sand"},
        {pos: [12, 1, 13], state: "minecraft:red_terracotta"},
        {pos: [12, 1, 14], state: "minecraft:red_terracotta"},
        {pos: [12, 1, 15], state: "minecraft:red_sand"},
        {pos: [13, 1, 3], state: "minecraft:red_sand"},
        {pos: [13, 1, 4], state: "minecraft:red_sand"},
        {pos: [13, 1, 11], state: "minecraft:red_sand"},
        {pos: [13, 1, 12], state: "minecraft:cut_red_sandstone"},
        {pos: [13, 1, 13], state: "minecraft:red_terracotta"},
        {pos: [13, 1, 14], state: "minecraft:red_terracotta"},
        {pos: [13, 1, 15], state: "minecraft:red_sand"},
        {pos: [14, 1, 12], state: "minecraft:cut_red_sandstone"},
        {pos: [14, 1, 13], state: "minecraft:cut_red_sandstone"},
        {pos: [14, 1, 14], state: "minecraft:red_sand"},
        {pos: [0, 2, 5], state: "minecraft:red_sand"},
        {pos: [0, 2, 6], state: "minecraft:red_sand"},
        {pos: [0, 2, 7], state: "minecraft:red_sand"},
        {pos: [0, 2, 15], state: "minecraft:red_sand"},
        {pos: [0, 2, 16], state: "minecraft:red_sand"},
        {pos: [1, 2, 4], state: "minecraft:red_sand"},
        {pos: [1, 2, 5], state: "minecraft:red_sand"},
        {pos: [1, 2, 6], state: "minecraft:red_sand"},
        {pos: [1, 2, 7], state: "minecraft:red_sand"},
        {pos: [1, 2, 8], state: "minecraft:red_sand"},
        {pos: [1, 2, 14], state: "minecraft:red_sand"},
        {pos: [1, 2, 15], state: "minecraft:red_sand"},
        {pos: [1, 2, 16], state: "minecraft:red_sand"},
        {pos: [2, 2, 1], state: "minecraft:red_sand"},
        {pos: [2, 2, 2], state: "minecraft:red_sand"},
        {pos: [2, 2, 3], state: "minecraft:red_sand"},
        {pos: [2, 2, 4], state: "minecraft:red_sand"},
        {pos: [2, 2, 5], state: "minecraft:red_sand"},
        {pos: [2, 2, 6], state: "minecraft:cut_red_sandstone"},
        {pos: [2, 2, 7], state: "minecraft:cut_red_sandstone"},
        {pos: [2, 2, 8], state: "minecraft:cut_red_sandstone"},
        {pos: [2, 2, 13], state: "minecraft:red_sand"},
        {pos: [2, 2, 14], state: "minecraft:red_terracotta"},
        {pos: [2, 2, 15], state: "minecraft:red_terracotta"},
        {pos: [2, 2, 16], state: "minecraft:red_sand"},
        {pos: [2, 2, 17], state: "minecraft:red_sand"},
        {pos: [3, 2, 0], state: "minecraft:red_sand"},
        {pos: [3, 2, 1], state: "minecraft:cut_red_sandstone"},
        {pos: [3, 2, 2], state: "minecraft:red_sand"},
        {pos: [3, 2, 3], state: "minecraft:red_sand"},
        {pos: [3, 2, 4], state: "minecraft:red_sand"},
        {pos: [3, 2, 5], state: "minecraft:red_sand"},
        {pos: [3, 2, 6], state: "minecraft:red_sand"},
        {pos: [3, 2, 7], state: "minecraft:red_sand"},
        {pos: [3, 2, 8], state: "minecraft:red_sand"},
        {pos: [3, 2, 13], state: "minecraft:red_sand"},
        {pos: [3, 2, 14], state: "minecraft:red_terracotta"},
        {pos: [3, 2, 15], state: "minecraft:red_terracotta"},
        {pos: [3, 2, 16], state: "minecraft:red_sand"},
        {pos: [3, 2, 17], state: "minecraft:red_sand"},
        {pos: [4, 2, 0], state: "minecraft:cut_red_sandstone"},
        {pos: [4, 2, 1], state: "minecraft:cut_red_sandstone"},
        {pos: [4, 2, 2], state: "minecraft:red_sand"},
        {pos: [4, 2, 3], state: "minecraft:red_sand"},
        {pos: [4, 2, 4], state: "minecraft:red_sand"},
        {pos: [4, 2, 5], state: "minecraft:red_sand"},
        {pos: [4, 2, 6], state: "minecraft:red_sand"},
        {pos: [4, 2, 7], state: "minecraft:red_sand"},
        {pos: [4, 2, 8], state: "minecraft:red_sand"},
        {pos: [4, 2, 11], state: "minecraft:red_sand"},
        {pos: [4, 2, 12], state: "minecraft:red_sand"},
        {pos: [4, 2, 13], state: "minecraft:red_sand"},
        {pos: [4, 2, 14], state: "minecraft:red_sand"},
        {pos: [4, 2, 15], state: "minecraft:red_sand"},
        {pos: [4, 2, 16], state: "minecraft:red_sand"},
        {pos: [4, 2, 17], state: "minecraft:red_sand"},
        {pos: [5, 2, 0], state: "minecraft:red_sand"},
        {pos: [5, 2, 1], state: "minecraft:cut_red_sandstone"},
        {pos: [5, 2, 2], state: "minecraft:red_sand"},
        {pos: [5, 2, 3], state: "minecraft:red_sand"},
        {pos: [5, 2, 4], state: "minecraft:red_sand"},
        {pos: [5, 2, 5], state: "minecraft:red_sand"},
        {pos: [5, 2, 10], state: "minecraft:red_sand"},
        {pos: [5, 2, 11], state: "minecraft:red_sand"},
        {pos: [5, 2, 12], state: "minecraft:red_sand"},
        {pos: [5, 2, 13], state: "minecraft:red_sandstone_wall{east:tall,north:tall,south:tall,up:false,waterlogged:false,west:tall}"},
        {pos: [5, 2, 14], state: "minecraft:red_sand"},
        {pos: [5, 2, 15], state: "minecraft:red_sand"},
        {pos: [5, 2, 16], state: "minecraft:red_sand"},
        {pos: [5, 2, 17], state: "minecraft:red_sand"},
        {pos: [6, 2, 0], state: "minecraft:red_sand"},
        {pos: [6, 2, 1], state: "minecraft:red_sand"},
        {pos: [6, 2, 2], state: "minecraft:red_sand"},
        {pos: [6, 2, 3], state: "minecraft:red_sand"},
        {pos: [6, 2, 4], state: "minecraft:red_sand"},
        {pos: [6, 2, 10], state: "minecraft:red_sand"},
        {pos: [6, 2, 11], state: "minecraft:red_sand"},
        {pos: [6, 2, 12], state: "minecraft:red_sand"},
        {pos: [6, 2, 13], state: "minecraft:red_sand"},
        {pos: [6, 2, 14], state: "minecraft:red_sand"},
        {pos: [6, 2, 15], state: "minecraft:red_sand"},
        {pos: [6, 2, 16], state: "minecraft:red_sand"},
        {pos: [7, 2, 1], state: "minecraft:red_sand"},
        {pos: [7, 2, 2], state: "minecraft:red_sand"},
        {pos: [7, 2, 3], state: "minecraft:red_sand"},
        {pos: [7, 2, 4], state: "minecraft:red_sand"},
        {pos: [7, 2, 5], state: "minecraft:red_sand"},
        {pos: [7, 2, 6], state: "minecraft:red_sand"},
        {pos: [7, 2, 7], state: "minecraft:red_sand"},
        {pos: [7, 2, 11], state: "minecraft:red_sand"},
        {pos: [7, 2, 12], state: "minecraft:red_sand"},
        {pos: [7, 2, 13], state: "minecraft:red_sand"},
        {pos: [7, 2, 14], state: "minecraft:red_sand"},
        {pos: [7, 2, 15], state: "minecraft:red_sand"},
        {pos: [7, 2, 16], state: "minecraft:red_sand"},
        {pos: [8, 2, 3], state: "minecraft:red_sand"},
        {pos: [8, 2, 4], state: "minecraft:red_sand"},
        {pos: [8, 2, 5], state: "minecraft:red_sand"},
        {pos: [8, 2, 6], state: "minecraft:red_sand"},
        {pos: [8, 2, 7], state: "minecraft:red_sand"},
        {pos: [8, 2, 8], state: "minecraft:red_sand"},
        {pos: [8, 2, 10], state: "minecraft:red_sand"},
        {pos: [8, 2, 11], state: "minecraft:red_sand"},
        {pos: [8, 2, 12], state: "minecraft:red_sand"},
        {pos: [8, 2, 13], state: "minecraft:red_sand"},
        {pos: [8, 2, 14], state: "minecraft:red_sand"},
        {pos: [8, 2, 15], state: "minecraft:red_sand"},
        {pos: [9, 2, 5], state: "minecraft:red_sand"},
        {pos: [9, 2, 6], state: "minecraft:red_sand"},
        {pos: [9, 2, 7], state: "minecraft:red_sand"},
        {pos: [9, 2, 8], state: "minecraft:cut_red_sandstone"},
        {pos: [9, 2, 9], state: "minecraft:chiseled_red_sandstone"},
        {pos: [9, 2, 10], state: "minecraft:cut_red_sandstone"},
        {pos: [9, 2, 11], state: "minecraft:red_sand"},
        {pos: [9, 2, 12], state: "minecraft:red_sand"},
        {pos: [9, 2, 13], state: "minecraft:red_sandstone_wall{east:tall,north:tall,south:tall,up:false,waterlogged:false,west:tall}"},
        {pos: [9, 2, 14], state: "minecraft:red_sand"},
        {pos: [9, 2, 15], state: "minecraft:red_sand"},
        {pos: [9, 2, 16], state: "minecraft:red_sand"},
        {pos: [10, 2, 4], state: "minecraft:red_sand"},
        {pos: [10, 2, 5], state: "minecraft:red_sand"},
        {pos: [10, 2, 6], state: "minecraft:red_sand"},
        {pos: [10, 2, 7], state: "minecraft:red_sand"},
        {pos: [10, 2, 8], state: "minecraft:red_sand"},
        {pos: [10, 2, 9], state: "minecraft:red_sand"},
        {pos: [10, 2, 10], state: "minecraft:red_sand"},
        {pos: [10, 2, 11], state: "minecraft:red_sand"},
        {pos: [10, 2, 12], state: "minecraft:red_sand"},
        {pos: [10, 2, 13], state: "minecraft:red_sand"},
        {pos: [10, 2, 14], state: "minecraft:red_sand"},
        {pos: [10, 2, 15], state: "minecraft:red_sand"},
        {pos: [11, 2, 3], state: "minecraft:red_sand"},
        {pos: [11, 2, 4], state: "minecraft:red_terracotta"},
        {pos: [11, 2, 5], state: "minecraft:red_terracotta"},
        {pos: [11, 2, 6], state: "minecraft:red_sand"},
        {pos: [11, 2, 9], state: "minecraft:red_sand"},
        {pos: [11, 2, 10], state: "minecraft:red_sand"},
        {pos: [11, 2, 11], state: "minecraft:red_sand"},
        {pos: [11, 2, 12], state: "minecraft:red_sand"},
        {pos: [11, 2, 13], state: "minecraft:red_sand"},
        {pos: [11, 2, 14], state: "minecraft:red_sand"},
        {pos: [11, 2, 15], state: "minecraft:red_sand"},
        {pos: [12, 2, 3], state: "minecraft:red_sand"},
        {pos: [12, 2, 4], state: "minecraft:red_terracotta"},
        {pos: [12, 2, 5], state: "minecraft:red_terracotta"},
        {pos: [12, 2, 10], state: "minecraft:red_sand"},
        {pos: [12, 2, 11], state: "minecraft:red_sand"},
        {pos: [12, 2, 12], state: "minecraft:red_sand"},
        {pos: [12, 2, 13], state: "minecraft:red_terracotta"},
        {pos: [12, 2, 14], state: "minecraft:red_terracotta"},
        {pos: [12, 2, 15], state: "minecraft:red_sand"},
        {pos: [13, 2, 3], state: "minecraft:red_sand"},
        {pos: [13, 2, 4], state: "minecraft:red_sand"},
        {pos: [13, 2, 11], state: "minecraft:red_sand"},
        {pos: [13, 2, 12], state: "minecraft:red_sand"},
        {pos: [13, 2, 13], state: "minecraft:red_terracotta"},
        {pos: [13, 2, 14], state: "minecraft:red_terracotta"},
        {pos: [13, 2, 15], state: "minecraft:red_sand"},
        {pos: [14, 2, 12], state: "minecraft:red_sand"},
        {pos: [14, 2, 13], state: "minecraft:red_sand"},
        {pos: [14, 2, 14], state: "minecraft:red_sand"},
        {pos: [0, 3, 5], state: "minecraft:red_sand"},
        {pos: [0, 3, 6], state: "minecraft:red_sand"},
        {pos: [0, 3, 7], state: "minecraft:red_sand"},
        {pos: [0, 3, 15], state: "minecraft:red_sand"},
        {pos: [0, 3, 16], state: "minecraft:red_sand"},
        {pos: [1, 3, 4], state: "minecraft:red_sand"},
        {pos: [1, 3, 5], state: "minecraft:red_sand"},
        {pos: [1, 3, 6], state: "minecraft:red_sand"},
        {pos: [1, 3, 7], state: "minecraft:red_sand"},
        {pos: [1, 3, 8], state: "minecraft:red_sand"},
        {pos: [1, 3, 14], state: "minecraft:red_sand"},
        {pos: [1, 3, 15], state: "minecraft:red_sand"},
        {pos: [1, 3, 16], state: "minecraft:red_sand"},
        {pos: [2, 3, 1], state: "minecraft:red_sand"},
        {pos: [2, 3, 2], state: "minecraft:red_sand"},
        {pos: [2, 3, 3], state: "minecraft:red_sand"},
        {pos: [2, 3, 4], state: "minecraft:red_sand"},
        {pos: [2, 3, 5], state: "minecraft:red_sand"},
        {pos: [2, 3, 6], state: "minecraft:cut_red_sandstone"},
        {pos: [2, 3, 7], state: "minecraft:cut_red_sandstone"},
        {pos: [2, 3, 8], state: "minecraft:cut_red_sandstone"},
        {pos: [2, 3, 13], state: "minecraft:red_sand"},
        {pos: [2, 3, 14], state: "minecraft:red_terracotta"},
        {pos: [2, 3, 15], state: "minecraft:red_terracotta"},
        {pos: [2, 3, 16], state: "minecraft:red_sand"},
        {pos: [2, 3, 17], state: "minecraft:red_sand"},
        {pos: [3, 3, 0], state: "minecraft:red_sand"},
        {pos: [3, 3, 1], state: "minecraft:red_sand"},
        {pos: [3, 3, 2], state: "minecraft:red_sand"},
        {pos: [3, 3, 3], state: "minecraft:red_sand"},
        {pos: [3, 3, 4], state: "minecraft:red_sand"},
        {pos: [3, 3, 5], state: "minecraft:red_sand"},
        {pos: [3, 3, 6], state: "minecraft:red_sand"},
        {pos: [3, 3, 7], state: "minecraft:red_sand"},
        {pos: [3, 3, 8], state: "minecraft:red_sand"},
        {pos: [3, 3, 13], state: "minecraft:red_sand"},
        {pos: [3, 3, 14], state: "minecraft:cut_red_sandstone"},
        {pos: [3, 3, 15], state: "minecraft:red_terracotta"},
        {pos: [3, 3, 16], state: "minecraft:red_sand"},
        {pos: [3, 3, 17], state: "minecraft:red_sand"},
        {pos: [4, 3, 0], state: "minecraft:red_sand"},
        {pos: [4, 3, 1], state: "minecraft:cut_red_sandstone"},
        {pos: [4, 3, 2], state: "minecraft:red_sand"},
        {pos: [4, 3, 3], state: "minecraft:red_sand"},
        {pos: [4, 3, 4], state: "minecraft:red_sand"},
        {pos: [4, 3, 5], state: "minecraft:red_sand"},
        {pos: [4, 3, 6], state: "minecraft:red_sand"},
        {pos: [4, 3, 7], state: "minecraft:red_sand"},
        {pos: [4, 3, 8], state: "minecraft:red_sand"},
        {pos: [4, 3, 11], state: "minecraft:red_sand"},
        {pos: [4, 3, 12], state: "minecraft:red_sand"},
        {pos: [4, 3, 13], state: "minecraft:red_sand"},
        {pos: [4, 3, 14], state: "minecraft:red_sand"},
        {pos: [4, 3, 15], state: "minecraft:red_sand"},
        {pos: [4, 3, 16], state: "minecraft:red_sand"},
        {pos: [4, 3, 17], state: "minecraft:red_sand"},
        {pos: [5, 3, 0], state: "minecraft:red_sand"},
        {pos: [5, 3, 1], state: "minecraft:cut_red_sandstone"},
        {pos: [5, 3, 2], state: "minecraft:red_sand"},
        {pos: [5, 3, 3], state: "minecraft:red_sand"},
        {pos: [5, 3, 4], state: "minecraft:red_sand"},
        {pos: [5, 3, 5], state: "minecraft:red_sand"},
        {pos: [5, 3, 10], state: "minecraft:red_sand"},
        {pos: [5, 3, 11], state: "minecraft:red_sand"},
        {pos: [5, 3, 12], state: "minecraft:red_sand"},
        {pos: [5, 3, 13], state: "minecraft:red_sand"},
        {pos: [5, 3, 14], state: "minecraft:red_sand"},
        {pos: [5, 3, 15], state: "minecraft:red_sand"},
        {pos: [5, 3, 16], state: "minecraft:red_sand"},
        {pos: [5, 3, 17], state: "minecraft:red_sand"},
        {pos: [6, 3, 0], state: "minecraft:red_sand"},
        {pos: [6, 3, 1], state: "minecraft:red_sand"},
        {pos: [6, 3, 2], state: "minecraft:red_sand"},
        {pos: [6, 3, 3], state: "minecraft:red_sand"},
        {pos: [6, 3, 4], state: "minecraft:red_sand"},
        {pos: [6, 3, 10], state: "minecraft:red_sand"},
        {pos: [6, 3, 11], state: "minecraft:red_sand"},
        {pos: [6, 3, 12], state: "minecraft:red_sand"},
        {pos: [6, 3, 13], state: "minecraft:red_sand"},
        {pos: [6, 3, 14], state: "minecraft:red_sand"},
        {pos: [6, 3, 15], state: "minecraft:red_sand"},
        {pos: [6, 3, 16], state: "minecraft:red_sand"},
        {pos: [7, 3, 1], state: "minecraft:red_sand"},
        {pos: [7, 3, 2], state: "minecraft:red_sand"},
        {pos: [7, 3, 3], state: "minecraft:red_sand"},
        {pos: [7, 3, 4], state: "minecraft:red_sand"},
        {pos: [7, 3, 5], state: "minecraft:red_sand"},
        {pos: [7, 3, 6], state: "minecraft:red_sand"},
        {pos: [7, 3, 7], state: "minecraft:red_sand"},
        {pos: [7, 3, 9], state: "minecraft:cut_red_sandstone"},
        {pos: [7, 3, 10], state: "minecraft:cut_red_sandstone"},
        {pos: [7, 3, 11], state: "minecraft:red_sand"},
        {pos: [7, 3, 12], state: "minecraft:red_sand"},
        {pos: [7, 3, 13], state: "minecraft:red_sand"},
        {pos: [7, 3, 14], state: "minecraft:red_sand"},
        {pos: [7, 3, 15], state: "minecraft:red_sand"},
        {pos: [7, 3, 16], state: "minecraft:red_sand"},
        {pos: [8, 3, 3], state: "minecraft:red_sand"},
        {pos: [8, 3, 4], state: "minecraft:red_sand"},
        {pos: [8, 3, 5], state: "minecraft:red_sand"},
        {pos: [8, 3, 6], state: "minecraft:red_sand"},
        {pos: [8, 3, 7], state: "minecraft:red_sand"},
        {pos: [8, 3, 8], state: "minecraft:red_sand"},
        {pos: [8, 3, 9], state: "minecraft:cut_red_sandstone"},
        {pos: [8, 3, 10], state: "minecraft:cut_red_sandstone"},
        {pos: [8, 3, 11], state: "minecraft:red_sand"},
        {pos: [8, 3, 12], state: "minecraft:red_sand"},
        {pos: [8, 3, 13], state: "minecraft:red_sand"},
        {pos: [8, 3, 14], state: "minecraft:red_sand"},
        {pos: [8, 3, 15], state: "minecraft:red_sand"},
        {pos: [9, 3, 5], state: "minecraft:red_sand"},
        {pos: [9, 3, 6], state: "minecraft:red_sand"},
        {pos: [9, 3, 7], state: "minecraft:red_sand"},
        {pos: [9, 3, 8], state: "minecraft:red_sand"},
        {pos: [9, 3, 9], state: "minecraft:cut_red_sandstone"},
        {pos: [9, 3, 10], state: "minecraft:cut_red_sandstone"},
        {pos: [9, 3, 11], state: "minecraft:red_sand"},
        {pos: [9, 3, 12], state: "minecraft:red_sand"},
        {pos: [9, 3, 13], state: "minecraft:red_sand"},
        {pos: [9, 3, 14], state: "minecraft:red_sand"},
        {pos: [9, 3, 15], state: "minecraft:red_sand"},
        {pos: [9, 3, 16], state: "minecraft:red_sand"},
        {pos: [10, 3, 4], state: "minecraft:red_sand"},
        {pos: [10, 3, 5], state: "minecraft:red_sand"},
        {pos: [10, 3, 6], state: "minecraft:red_sand"},
        {pos: [10, 3, 7], state: "minecraft:red_sand"},
        {pos: [10, 3, 8], state: "minecraft:red_sand"},
        {pos: [10, 3, 9], state: "minecraft:red_sand"},
        {pos: [10, 3, 10], state: "minecraft:red_sand"},
        {pos: [10, 3, 11], state: "minecraft:red_sand"},
        {pos: [10, 3, 12], state: "minecraft:red_sand"},
        {pos: [10, 3, 13], state: "minecraft:red_sand"},
        {pos: [10, 3, 14], state: "minecraft:red_sand"},
        {pos: [10, 3, 15], state: "minecraft:red_sand"},
        {pos: [11, 3, 3], state: "minecraft:red_sand"},
        {pos: [11, 3, 4], state: "minecraft:red_terracotta"},
        {pos: [11, 3, 5], state: "minecraft:red_terracotta"},
        {pos: [11, 3, 6], state: "minecraft:red_sand"},
        {pos: [11, 3, 9], state: "minecraft:red_sand"},
        {pos: [11, 3, 10], state: "minecraft:red_sand"},
        {pos: [11, 3, 11], state: "minecraft:red_sand"},
        {pos: [11, 3, 12], state: "minecraft:red_sand"},
        {pos: [11, 3, 13], state: "minecraft:red_sand"},
        {pos: [11, 3, 14], state: "minecraft:red_sand"},
        {pos: [11, 3, 15], state: "minecraft:red_sand"},
        {pos: [12, 3, 3], state: "minecraft:red_sand"},
        {pos: [12, 3, 4], state: "minecraft:cut_red_sandstone"},
        {pos: [12, 3, 5], state: "minecraft:red_terracotta"},
        {pos: [12, 3, 10], state: "minecraft:red_sand"},
        {pos: [12, 3, 11], state: "minecraft:red_sand"},
        {pos: [12, 3, 12], state: "minecraft:red_sand"},
        {pos: [12, 3, 13], state: "minecraft:red_terracotta"},
        {pos: [12, 3, 14], state: "minecraft:red_terracotta"},
        {pos: [12, 3, 15], state: "minecraft:red_sand"},
        {pos: [13, 3, 3], state: "minecraft:red_sand"},
        {pos: [13, 3, 4], state: "minecraft:red_sand"},
        {pos: [13, 3, 11], state: "minecraft:red_sand"},
        {pos: [13, 3, 12], state: "minecraft:red_sand"},
        {pos: [13, 3, 13], state: "minecraft:cut_red_sandstone"},
        {pos: [13, 3, 14], state: "minecraft:cut_red_sandstone"},
        {pos: [13, 3, 15], state: "minecraft:red_sand"},
        {pos: [14, 3, 12], state: "minecraft:red_sand"},
        {pos: [14, 3, 13], state: "minecraft:red_sand"},
        {pos: [14, 3, 14], state: "minecraft:red_sand"},
        {pos: [1, 4, 6], state: "minecraft:red_sand"},
        {pos: [1, 4, 7], state: "minecraft:red_sand"},
        {pos: [1, 4, 14], state: "minecraft:red_sand"},
        {pos: [1, 4, 15], state: "minecraft:red_sand"},
        {pos: [1, 4, 16], state: "minecraft:red_sand"},
        {pos: [2, 4, 5], state: "minecraft:red_sand"},
        {pos: [2, 4, 6], state: "minecraft:cut_red_sandstone"},
        {pos: [2, 4, 7], state: "minecraft:cut_red_sandstone"},
        {pos: [2, 4, 8], state: "minecraft:cut_red_sandstone"},
        {pos: [2, 4, 13], state: "minecraft:red_sand"},
        {pos: [2, 4, 14], state: "minecraft:cut_red_sandstone"},
        {pos: [2, 4, 15], state: "minecraft:cut_red_sandstone"},
        {pos: [2, 4, 16], state: "minecraft:red_sand"},
        {pos: [3, 4, 2], state: "minecraft:red_sand"},
        {pos: [3, 4, 3], state: "minecraft:red_sand"},
        {pos: [3, 4, 4], state: "minecraft:red_sand"},
        {pos: [3, 4, 5], state: "minecraft:red_sand"},
        {pos: [3, 4, 6], state: "minecraft:cut_red_sandstone"},
        {pos: [3, 4, 7], state: "minecraft:cut_red_sandstone"},
        {pos: [3, 4, 8], state: "minecraft:cut_red_sandstone"},
        {pos: [3, 4, 13], state: "minecraft:red_sand"},
        {pos: [3, 4, 14], state: "minecraft:cut_red_sandstone"},
        {pos: [3, 4, 15], state: "minecraft:cut_red_sandstone"},
        {pos: [3, 4, 16], state: "minecraft:red_sand"},
        {pos: [4, 4, 1], state: "minecraft:chiseled_red_sandstone"},
        {pos: [4, 4, 2], state: "minecraft:red_sand"},
        {pos: [4, 4, 3], state: "minecraft:red_sand"},
        {pos: [4, 4, 4], state: "minecraft:red_sand"},
        {pos: [4, 4, 5], state: "minecraft:red_sand"},
        {pos: [4, 4, 6], state: "minecraft:red_sand"},
        {pos: [4, 4, 7], state: "minecraft:chiseled_red_sandstone"},
        {pos: [4, 4, 8], state: "minecraft:cut_red_sandstone"},
        {pos: [4, 4, 12], state: "minecraft:red_sand"},
        {pos: [4, 4, 13], state: "minecraft:red_sand"},
        {pos: [4, 4, 14], state: "minecraft:red_sand"},
        {pos: [4, 4, 15], state: "minecraft:red_sand"},
        {pos: [4, 4, 16], state: "minecraft:red_sand"},
        {pos: [5, 4, 1], state: "minecraft:cut_red_sandstone"},
        {pos: [5, 4, 2], state: "minecraft:cut_red_sandstone"},
        {pos: [5, 4, 3], state: "minecraft:red_sand"},
        {pos: [5, 4, 4], state: "minecraft:red_sand"},
        {pos: [5, 4, 5], state: "minecraft:red_sand"},
        {pos: [5, 4, 12], state: "minecraft:red_sand"},
        {pos: [5, 4, 13], state: "minecraft:red_sand"},
        {pos: [5, 4, 14], state: "minecraft:red_sand"},
        {pos: [6, 4, 1], state: "minecraft:cut_red_sandstone"},
        {pos: [6, 4, 2], state: "minecraft:red_sand"},
        {pos: [6, 4, 3], state: "minecraft:red_sand"},
        {pos: [6, 4, 4], state: "minecraft:red_sand"},
        {pos: [6, 4, 11], state: "minecraft:red_sand"},
        {pos: [6, 4, 12], state: "minecraft:red_sand"},
        {pos: [6, 4, 13], state: "minecraft:red_sand"},
        {pos: [6, 4, 14], state: "minecraft:red_sand"},
        {pos: [7, 4, 1], state: "minecraft:red_sand"},
        {pos: [7, 4, 2], state: "minecraft:red_sand"},
        {pos: [7, 4, 3], state: "minecraft:red_sand"},
        {pos: [7, 4, 4], state: "minecraft:red_sand"},
        {pos: [7, 4, 5], state: "minecraft:red_sand"},
        {pos: [8, 4, 3], state: "minecraft:red_sand"},
        {pos: [8, 4, 4], state: "minecraft:red_sand"},
        {pos: [8, 4, 5], state: "minecraft:red_sand"},
        {pos: [8, 4, 10], state: "minecraft:red_sand"},
        {pos: [8, 4, 11], state: "minecraft:red_sand"},
        {pos: [9, 4, 5], state: "minecraft:red_sand"},
        {pos: [9, 4, 6], state: "minecraft:red_sand"},
        {pos: [9, 4, 10], state: "minecraft:red_sand"},
        {pos: [9, 4, 11], state: "minecraft:red_sand"},
        {pos: [9, 4, 12], state: "minecraft:red_sand"},
        {pos: [9, 4, 13], state: "minecraft:red_sand"},
        {pos: [10, 4, 4], state: "minecraft:red_sand"},
        {pos: [10, 4, 5], state: "minecraft:red_sand"},
        {pos: [10, 4, 6], state: "minecraft:red_sand"},
        {pos: [10, 4, 11], state: "minecraft:red_sand"},
        {pos: [10, 4, 12], state: "minecraft:red_sand"},
        {pos: [10, 4, 13], state: "minecraft:red_sand"},
        {pos: [10, 4, 14], state: "minecraft:red_sand"},
        {pos: [11, 4, 4], state: "minecraft:red_terracotta"},
        {pos: [11, 4, 5], state: "minecraft:cut_red_sandstone"},
        {pos: [11, 4, 6], state: "minecraft:red_sand"},
        {pos: [11, 4, 11], state: "minecraft:red_sand"},
        {pos: [11, 4, 12], state: "minecraft:red_sand"},
        {pos: [11, 4, 13], state: "minecraft:red_sand"},
        {pos: [11, 4, 14], state: "minecraft:red_sand"},
        {pos: [11, 4, 15], state: "minecraft:red_sand"},
        {pos: [12, 4, 4], state: "minecraft:cut_red_sandstone"},
        {pos: [12, 4, 5], state: "minecraft:cut_red_sandstone"},
        {pos: [12, 4, 11], state: "minecraft:red_sand"},
        {pos: [12, 4, 12], state: "minecraft:red_sand"},
        {pos: [12, 4, 13], state: "minecraft:red_terracotta"},
        {pos: [12, 4, 14], state: "minecraft:cut_red_sandstone"},
        {pos: [12, 4, 15], state: "minecraft:red_sand"},
        {pos: [13, 4, 12], state: "minecraft:red_sand"},
        {pos: [13, 4, 13], state: "minecraft:cut_red_sandstone"},
        {pos: [13, 4, 14], state: "minecraft:cut_red_sandstone"},
        {pos: [13, 4, 15], state: "minecraft:red_sand"},
        {pos: [14, 4, 13], state: "minecraft:red_sand"},
        {pos: [14, 4, 14], state: "minecraft:red_sand"},
        {pos: [2, 5, 6], state: "minecraft:red_sand"},
        {pos: [2, 5, 7], state: "minecraft:red_sand"},
        {pos: [2, 5, 8], state: "minecraft:red_sand"},
        {pos: [2, 5, 14], state: "minecraft:red_sand"},
        {pos: [2, 5, 15], state: "minecraft:red_sand"},
        {pos: [2, 5, 16], state: "minecraft:red_sand"},
        {pos: [3, 5, 6], state: "minecraft:red_sand"},
        {pos: [3, 5, 7], state: "minecraft:red_sand"},
        {pos: [3, 5, 14], state: "minecraft:red_sand"},
        {pos: [3, 5, 15], state: "minecraft:red_sand"},
        {pos: [4, 5, 1], state: "minecraft:cut_red_sandstone"},
        {pos: [4, 5, 2], state: "minecraft:cut_red_sandstone"},
        {pos: [4, 5, 6], state: "minecraft:red_sand"},
        {pos: [4, 5, 7], state: "minecraft:red_sand"},
        {pos: [5, 5, 1], state: "minecraft:cut_red_sandstone"},
        {pos: [5, 5, 2], state: "minecraft:cut_red_sandstone"},
        {pos: [5, 5, 3], state: "minecraft:chiseled_red_sandstone"},
        {pos: [6, 5, 2], state: "minecraft:cut_red_sandstone"},
        {pos: [6, 5, 3], state: "minecraft:cut_red_sandstone"},
        {pos: [6, 5, 4], state: "minecraft:cut_red_sandstone"},
        {pos: [7, 5, 3], state: "minecraft:cut_red_sandstone"},
        {pos: [7, 5, 4], state: "minecraft:cut_red_sandstone"},
        {pos: [11, 5, 4], state: "minecraft:cut_red_sandstone"},
        {pos: [11, 5, 5], state: "minecraft:chiseled_red_sandstone"},
        {pos: [12, 5, 4], state: "minecraft:cut_red_sandstone"},
        {pos: [12, 5, 5], state: "minecraft:cut_red_sandstone"},
        {pos: [12, 5, 13], state: "minecraft:cut_red_sandstone"},
        {pos: [12, 5, 14], state: "minecraft:cut_red_sandstone"},
        {pos: [12, 5, 15], state: "minecraft:red_sand"},
        {pos: [13, 5, 13], state: "minecraft:chiseled_red_sandstone"},
        {pos: [13, 5, 14], state: "minecraft:cut_red_sandstone"},
        {pos: [13, 5, 15], state: "minecraft:red_sand"},
        {pos: [14, 5, 13], state: "minecraft:red_sand"},
        {pos: [14, 5, 14], state: "minecraft:red_sand"}
    ],
    entities: [],
    palette: [
        "minecraft:cut_red_sandstone",
        "minecraft:red_terracotta",
        "minecraft:red_sand",
        "minecraft:chiseled_red_sandstone",
        "minecraft:red_sandstone_stairs{facing:west,half:top,shape:straight,waterlogged:false}",
        "minecraft:red_sandstone_stairs{facing:south,half:top,shape:straight,waterlogged:false}",
        "minecraft:red_sandstone_wall{east:tall,north:tall,south:tall,up:false,waterlogged:false,west:tall}"
    ],
    trailiertales_DataVersion: 2
}
