{
    DataVersion: 3953,
    size: [4, 7, 4],
    data: [
        {pos: [0, 0, 0], state: "minecraft:cut_red_sandstone"},
        {pos: [0, 0, 1], state: "minecraft:cut_red_sandstone"},
        {pos: [0, 0, 2], state: "minecraft:cut_red_sandstone"},
        {pos: [1, 0, 0], state: "minecraft:cut_red_sandstone"},
        {pos: [1, 0, 1], state: "minecraft:yellow_glazed_terracotta{facing:north}"},
        {pos: [1, 0, 2], state: "minecraft:yellow_glazed_terracotta{facing:west}"},
        {pos: [1, 0, 3], state: "minecraft:cut_red_sandstone"},
        {pos: [2, 0, 1], state: "minecraft:yellow_glazed_terracotta{facing:east}"},
        {pos: [2, 0, 2], state: "minecraft:yellow_glazed_terracotta{facing:south}"},
        {pos: [2, 0, 3], state: "minecraft:cut_red_sandstone"},
        {pos: [3, 0, 1], state: "minecraft:cut_red_sandstone"},
        {pos: [3, 0, 2], state: "minecraft:cut_red_sandstone"},
        {pos: [3, 0, 3], state: "minecraft:cut_red_sandstone"},
        {pos: [0, 1, 0], state: "minecraft:cut_red_sandstone"},
        {pos: [0, 1, 1], state: "minecraft:cut_red_sandstone"},
        {pos: [0, 1, 2], state: "minecraft:cut_red_sandstone"},
        {pos: [1, 1, 0], state: "minecraft:red_sand"},
        {pos: [1, 1, 1], state: "minecraft:red_sand"},
        {pos: [1, 1, 2], state: "minecraft:red_sand"},
        {pos: [1, 1, 3], state: "minecraft:red_sand"},
        {pos: [2, 1, 1], state: "minecraft:red_sand"},
        {pos: [2, 1, 2], state: "minecraft:red_sand"},
        {pos: [2, 1, 3], state: "minecraft:red_sand"},
        {pos: [3, 1, 1], state: "minecraft:red_sand"},
        {pos: [3, 1, 2], state: "minecraft:red_sand"},
        {pos: [3, 1, 3], state: "minecraft:cut_red_sandstone"},
        {pos: [0, 2, 0], state: "minecraft:cut_red_sandstone"},
        {pos: [0, 2, 1], state: "minecraft:cut_red_sandstone"},
        {pos: [0, 2, 2], state: "minecraft:cut_red_sandstone"},
        {pos: [1, 2, 0], state: "minecraft:red_sand"},
        {pos: [1, 2, 1], state: "minecraft:red_sand"},
        {pos: [1, 2, 2], state: "minecraft:red_sand"},
        {pos: [1, 2, 3], state: "minecraft:red_sand"},
        {pos: [2, 2, 1], state: "minecraft:red_sand"},
        {pos: [2, 2, 2], state: "minecraft:red_sand"},
        {pos: [2, 2, 3], state: "minecraft:red_sand"},
        {pos: [3, 2, 1], state: "minecraft:red_sand"},
        {pos: [3, 2, 2], state: "minecraft:red_sand"},
        {pos: [3, 2, 3], state: "minecraft:chiseled_red_sandstone"},
        {pos: [0, 3, 0], state: "minecraft:cut_red_sandstone"},
        {pos: [0, 3, 1], state: "minecraft:cut_red_sandstone"},
        {pos: [0, 3, 2], state: "minecraft:cut_red_sandstone"},
        {pos: [1, 3, 0], state: "minecraft:red_sand"},
        {pos: [1, 3, 1], state: "minecraft:red_sand"},
        {pos: [1, 3, 2], state: "minecraft:red_sand"},
        {pos: [1, 3, 3], state: "minecraft:red_sand"},
        {pos: [2, 3, 1], state: "minecraft:red_sand"},
        {pos: [2, 3, 2], state: "minecraft:red_sand"},
        {pos: [2, 3, 3], state: "minecraft:red_sand"},
        {pos: [3, 3, 1], state: "minecraft:red_sand"},
        {pos: [3, 3, 2], state: "minecraft:red_sand"},
        {pos: [3, 3, 3], state: "minecraft:red_sand"},
        {pos: [0, 4, 1], state: "minecraft:cut_red_sandstone"},
        {pos: [0, 4, 2], state: "minecraft:cut_red_sandstone"},
        {pos: [1, 4, 1], state: "minecraft:red_sand"},
        {pos: [1, 4, 2], state: "minecraft:red_sand"},
        {pos: [2, 4, 2], state: "minecraft:red_sand"},
        {pos: [0, 5, 1], state: "minecraft:cut_red_sandstone"},
        {pos: [0, 5, 2], state: "minecraft:cut_red_sandstone"},
        {pos: [1, 5, 2], state: "minecraft:red_sand"},
        {pos: [0, 6, 1], state: "minecraft:red_sandstone_wall{east:none,north:none,south:none,up:true,waterlogged:false,west:none}"}
    ],
    entities: [],
    palette: [
        "minecraft:cut_red_sandstone",
        "minecraft:yellow_glazed_terracotta{facing:north}",
        "minecraft:yellow_glazed_terracotta{facing:west}",
        "minecraft:yellow_glazed_terracotta{facing:east}",
        "minecraft:yellow_glazed_terracotta{facing:south}",
        "minecraft:red_sand",
        "minecraft:chiseled_red_sandstone",
        "minecraft:red_sandstone_wall{east:none,north:none,south:none,up:true,waterlogged:false,west:none}"
    ],
    trailiertales_DataVersion: 2
}
