{
    DataVersion: 3953,
    size: [15, 7, 9],
    data: [
        {pos: [0, 0, 6], state: "minecraft:cut_red_sandstone"},
        {pos: [1, 0, 2], state: "minecraft:cut_red_sandstone"},
        {pos: [1, 0, 6], state: "minecraft:cut_red_sandstone"},
        {pos: [1, 0, 7], state: "minecraft:cut_red_sandstone"},
        {pos: [1, 0, 8], state: "minecraft:cut_red_sandstone"},
        {pos: [2, 0, 1], state: "minecraft:cut_red_sandstone"},
        {pos: [2, 0, 2], state: "minecraft:cut_red_sandstone"},
        {pos: [2, 0, 3], state: "minecraft:cut_red_sandstone"},
        {pos: [2, 0, 5], state: "minecraft:cut_red_sandstone"},
        {pos: [2, 0, 6], state: "minecraft:cut_red_sandstone"},
        {pos: [2, 0, 7], state: "minecraft:cut_red_sandstone"},
        {pos: [2, 0, 8], state: "minecraft:cut_red_sandstone"},
        {pos: [3, 0, 1], state: "minecraft:cut_red_sandstone"},
        {pos: [3, 0, 2], state: "minecraft:cut_red_sandstone"},
        {pos: [3, 0, 3], state: "minecraft:cut_red_sandstone"},
        {pos: [3, 0, 5], state: "minecraft:cut_red_sandstone"},
        {pos: [3, 0, 6], state: "minecraft:cut_red_sandstone"},
        {pos: [3, 0, 7], state: "minecraft:cut_red_sandstone"},
        {pos: [4, 0, 1], state: "minecraft:cut_red_sandstone"},
        {pos: [4, 0, 2], state: "minecraft:cut_red_sandstone"},
        {pos: [4, 0, 5], state: "minecraft:cut_red_sandstone"},
        {pos: [4, 0, 6], state: "minecraft:cut_red_sandstone"},
        {pos: [4, 0, 7], state: "minecraft:cut_red_sandstone"},
        {pos: [5, 0, 4], state: "minecraft:cut_red_sandstone"},
        {pos: [5, 0, 5], state: "minecraft:cut_red_sandstone"},
        {pos: [5, 0, 6], state: "minecraft:cut_red_sandstone"},
        {pos: [6, 0, 3], state: "minecraft:cut_red_sandstone"},
        {pos: [6, 0, 4], state: "minecraft:cut_red_sandstone"},
        {pos: [6, 0, 5], state: "minecraft:cut_red_sandstone"},
        {pos: [6, 0, 6], state: "minecraft:cut_red_sandstone"},
        {pos: [7, 0, 3], state: "minecraft:cut_red_sandstone"},
        {pos: [7, 0, 4], state: "minecraft:cut_red_sandstone"},
        {pos: [7, 0, 5], state: "minecraft:cut_red_sandstone"},
        {pos: [7, 0, 6], state: "minecraft:cut_red_sandstone"},
        {pos: [7, 0, 7], state: "minecraft:cut_red_sandstone"},
        {pos: [8, 0, 2], state: "minecraft:cut_red_sandstone"},
        {pos: [8, 0, 3], state: "minecraft:cut_red_sandstone"},
        {pos: [8, 0, 4], state: "minecraft:yellow_glazed_terracotta{facing:north}"},
        {pos: [8, 0, 5], state: "minecraft:cut_red_sandstone"},
        {pos: [8, 0, 6], state: "minecraft:cut_red_sandstone"},
        {pos: [8, 0, 7], state: "minecraft:cut_red_sandstone"},
        {pos: [8, 0, 8], state: "minecraft:cut_red_sandstone"},
        {pos: [9, 0, 1], state: "minecraft:cut_red_sandstone"},
        {pos: [9, 0, 2], state: "minecraft:cut_red_sandstone"},
        {pos: [9, 0, 3], state: "minecraft:cut_red_sandstone"},
        {pos: [9, 0, 4], state: "minecraft:yellow_glazed_terracotta{facing:east}"},
        {pos: [9, 0, 5], state: "minecraft:cut_red_sandstone"},
        {pos: [9, 0, 6], state: "minecraft:cut_red_sandstone"},
        {pos: [9, 0, 7], state: "minecraft:cut_red_sandstone"},
        {pos: [9, 0, 8], state: "minecraft:cut_red_sandstone"},
        {pos: [10, 0, 1], state: "minecraft:cut_red_sandstone"},
        {pos: [10, 0, 2], state: "minecraft:cut_red_sandstone"},
        {pos: [10, 0, 3], state: "minecraft:cut_red_sandstone"},
        {pos: [10, 0, 4], state: "minecraft:cut_red_sandstone"},
        {pos: [10, 0, 5], state: "minecraft:cut_red_sandstone"},
        {pos: [10, 0, 6], state: "minecraft:cut_red_sandstone"},
        {pos: [10, 0, 7], state: "minecraft:cut_red_sandstone"},
        {pos: [10, 0, 8], state: "minecraft:cut_red_sandstone"},
        {pos: [11, 0, 0], state: "minecraft:cut_red_sandstone"},
        {pos: [11, 0, 1], state: "minecraft:cut_red_sandstone"},
        {pos: [11, 0, 2], state: "minecraft:cut_red_sandstone"},
        {pos: [11, 0, 3], state: "minecraft:yellow_glazed_terracotta{facing:north}"},
        {pos: [11, 0, 4], state: "minecraft:yellow_glazed_terracotta{facing:west}"},
        {pos: [11, 0, 5], state: "minecraft:cut_red_sandstone"},
        {pos: [11, 0, 6], state: "minecraft:cut_red_sandstone"},
        {pos: [11, 0, 7], state: "minecraft:cut_red_sandstone"},
        {pos: [11, 0, 8], state: "minecraft:cut_red_sandstone"},
        {pos: [12, 0, 0], state: "minecraft:cut_red_sandstone"},
        {pos: [12, 0, 1], state: "minecraft:cut_red_sandstone"},
        {pos: [12, 0, 2], state: "minecraft:cut_red_sandstone"},
        {pos: [12, 0, 3], state: "minecraft:yellow_glazed_terracotta{facing:east}"},
        {pos: [12, 0, 4], state: "minecraft:yellow_glazed_terracotta{facing:east}"},
        {pos: [12, 0, 5], state: "minecraft:cut_red_sandstone"},
        {pos: [12, 0, 6], state: "minecraft:cut_red_sandstone"},
        {pos: [12, 0, 7], state: "minecraft:cut_red_sandstone"},
        {pos: [13, 0, 0], state: "minecraft:cut_red_sandstone"},
        {pos: [13, 0, 1], state: "minecraft:cut_red_sandstone"},
        {pos: [13, 0, 2], state: "minecraft:cut_red_sandstone"},
        {pos: [13, 0, 3], state: "minecraft:cut_red_sandstone"},
        {pos: [13, 0, 4], state: "minecraft:cut_red_sandstone"},
        {pos: [13, 0, 5], state: "minecraft:cut_red_sandstone"},
        {pos: [13, 0, 6], state: "minecraft:cut_red_sandstone"},
        {pos: [14, 0, 3], state: "minecraft:cut_red_sandstone"},
        {pos: [14, 0, 4], state: "minecraft:cut_red_sandstone"},
        {pos: [14, 0, 5], state: "minecraft:cut_red_sandstone"},
        {pos: [0, 1, 6], state: "minecraft:red_sand"},
        {pos: [1, 1, 2], state: "minecraft:cut_red_sandstone"},
        {pos: [1, 1, 6], state: "minecraft:cut_red_sandstone"},
        {pos: [1, 1, 7], state: "minecraft:red_sand"},
        {pos: [1, 1, 8], state: "minecraft:red_sand"},
        {pos: [2, 1, 1], state: "minecraft:red_sand"},
        {pos: [2, 1, 2], state: "minecraft:cut_red_sandstone"},
        {pos: [2, 1, 3], state: "minecraft:red_sand"},
        {pos: [2, 1, 5], state: "minecraft:red_sand"},
        {pos: [2, 1, 6], state: "minecraft:red_terracotta"},
        {pos: [2, 1, 7], state: "minecraft:red_sand"},
        {pos: [2, 1, 8], state: "minecraft:red_sand"},
        {pos: [3, 1, 1], state: "minecraft:red_sand"},
        {pos: [3, 1, 2], state: "minecraft:cut_red_sandstone"},
        {pos: [3, 1, 3], state: "minecraft:red_sand"},
        {pos: [3, 1, 5], state: "minecraft:red_sand"},
        {pos: [3, 1, 6], state: "minecraft:cut_red_sandstone"},
        {pos: [3, 1, 7], state: "minecraft:red_sand"},
        {pos: [4, 1, 1], state: "minecraft:red_sand"},
        {pos: [4, 1, 2], state: "minecraft:red_sand"},
        {pos: [4, 1, 5], state: "minecraft:red_sand"},
        {pos: [4, 1, 6], state: "minecraft:cut_red_sandstone"},
        {pos: [4, 1, 7], state: "minecraft:red_sand"},
        {pos: [5, 1, 4], state: "minecraft:red_sand"},
        {pos: [5, 1, 5], state: "minecraft:red_sand"},
        {pos: [5, 1, 6], state: "minecraft:red_sand"},
        {pos: [6, 1, 3], state: "minecraft:red_sand"},
        {pos: [6, 1, 4], state: "minecraft:red_sand"},
        {pos: [6, 1, 5], state: "minecraft:red_sandstone_stairs{facing:south,half:top,shape:straight,waterlogged:false}"},
        {pos: [6, 1, 6], state: "minecraft:cut_red_sandstone"},
        {pos: [7, 1, 3], state: "minecraft:red_sand"},
        {pos: [7, 1, 4], state: "minecraft:red_sand"},
        {pos: [7, 1, 5], state: "minecraft:red_sandstone_stairs{facing:south,half:top,shape:straight,waterlogged:false}"},
        {pos: [7, 1, 6], state: "minecraft:cut_red_sandstone"},
        {pos: [7, 1, 7], state: "minecraft:red_sand"},
        {pos: [8, 1, 2], state: "minecraft:cut_red_sandstone"},
        {pos: [8, 1, 3], state: "minecraft:red_sand"},
        {pos: [8, 1, 4], state: "minecraft:red_sand"},
        {pos: [8, 1, 5], state: "minecraft:red_sandstone_stairs{facing:south,half:top,shape:straight,waterlogged:false}"},
        {pos: [8, 1, 6], state: "minecraft:cut_red_sandstone"},
        {pos: [8, 1, 7], state: "minecraft:red_sand"},
        {pos: [8, 1, 8], state: "minecraft:red_sand"},
        {pos: [9, 1, 1], state: "minecraft:red_sand"},
        {pos: [9, 1, 2], state: "minecraft:cut_red_sandstone"},
        {pos: [9, 1, 3], state: "minecraft:red_sand"},
        {pos: [9, 1, 4], state: "minecraft:red_sand"},
        {pos: [9, 1, 5], state: "minecraft:red_sand"},
        {pos: [9, 1, 6], state: "minecraft:red_terracotta"},
        {pos: [9, 1, 7], state: "minecraft:red_sand"},
        {pos: [9, 1, 8], state: "minecraft:red_sand"},
        {pos: [10, 1, 1], state: "minecraft:red_sand"},
        {pos: [10, 1, 2], state: "minecraft:cut_red_sandstone"},
        {pos: [10, 1, 3], state: "minecraft:red_sand"},
        {pos: [10, 1, 4], state: "minecraft:red_sand"},
        {pos: [10, 1, 5], state: "minecraft:red_sand"},
        {pos: [10, 1, 6], state: "minecraft:red_terracotta"},
        {pos: [10, 1, 7], state: "minecraft:red_sand"},
        {pos: [10, 1, 8], state: "minecraft:red_sand"},
        {pos: [11, 1, 0], state: "minecraft:red_sand"},
        {pos: [11, 1, 1], state: "minecraft:red_sand"},
        {pos: [11, 1, 2], state: "minecraft:red_terracotta"},
        {pos: [11, 1, 3], state: "minecraft:red_sand"},
        {pos: [11, 1, 4], state: "minecraft:red_sand"},
        {pos: [11, 1, 5], state: "minecraft:red_sand"},
        {pos: [11, 1, 6], state: "minecraft:red_terracotta"},
        {pos: [11, 1, 7], state: "minecraft:red_sand"},
        {pos: [11, 1, 8], state: "minecraft:red_sand"},
        {pos: [12, 1, 0], state: "minecraft:red_sand"},
        {pos: [12, 1, 1], state: "minecraft:red_sand"},
        {pos: [12, 1, 2], state: "minecraft:cut_red_sandstone"},
        {pos: [12, 1, 3], state: "minecraft:red_sand"},
        {pos: [12, 1, 4], state: "minecraft:red_sand"},
        {pos: [12, 1, 5], state: "minecraft:red_sand"},
        {pos: [12, 1, 6], state: "minecraft:red_terracotta"},
        {pos: [12, 1, 7], state: "minecraft:red_sand"},
        {pos: [13, 1, 0], state: "minecraft:red_sand"},
        {pos: [13, 1, 1], state: "minecraft:red_sand"},
        {pos: [13, 1, 2], state: "minecraft:cut_red_sandstone"},
        {pos: [13, 1, 3], state: "minecraft:red_sand"},
        {pos: [13, 1, 4], state: "minecraft:red_sand"},
        {pos: [13, 1, 5], state: "minecraft:red_sand"},
        {pos: [13, 1, 6], state: "minecraft:cut_red_sandstone"},
        {pos: [14, 1, 3], state: "minecraft:red_sand"},
        {pos: [14, 1, 4], state: "minecraft:red_sand"},
        {pos: [14, 1, 5], state: "minecraft:red_sand"},
        {pos: [0, 2, 6], state: "minecraft:red_sand"},
        {pos: [1, 2, 2], state: "minecraft:cut_red_sandstone"},
        {pos: [1, 2, 6], state: "minecraft:red_terracotta"},
        {pos: [1, 2, 7], state: "minecraft:red_sand"},
        {pos: [1, 2, 8], state: "minecraft:red_sand"},
        {pos: [2, 2, 1], state: "minecraft:red_sand"},
        {pos: [2, 2, 2], state: "minecraft:cut_red_sandstone"},
        {pos: [2, 2, 3], state: "minecraft:red_sand"},
        {pos: [2, 2, 5], state: "minecraft:red_sand"},
        {pos: [2, 2, 6], state: "minecraft:cut_red_sandstone"},
        {pos: [2, 2, 7], state: "minecraft:red_sand"},
        {pos: [2, 2, 8], state: "minecraft:red_sand"},
        {pos: [3, 2, 1], state: "minecraft:red_sand"},
        {pos: [3, 2, 2], state: "minecraft:cut_red_sandstone"},
        {pos: [3, 2, 3], state: "minecraft:red_sand"},
        {pos: [3, 2, 5], state: "minecraft:red_sand"},
        {pos: [3, 2, 6], state: "minecraft:red_terracotta"},
        {pos: [3, 2, 7], state: "minecraft:red_sand"},
        {pos: [4, 2, 1], state: "minecraft:red_sand"},
        {pos: [4, 2, 2], state: "minecraft:red_sand"},
        {pos: [4, 2, 5], state: "minecraft:red_sand"},
        {pos: [4, 2, 6], state: "minecraft:red_sand"},
        {pos: [4, 2, 7], state: "minecraft:red_sand"},
        {pos: [5, 2, 4], state: "minecraft:red_sand"},
        {pos: [5, 2, 5], state: "minecraft:red_sand"},
        {pos: [5, 2, 6], state: "minecraft:red_sand"},
        {pos: [6, 2, 3], state: "minecraft:red_sand"},
        {pos: [6, 2, 4], state: "minecraft:red_sand"},
        {pos: [6, 2, 5], state: "minecraft:red_sand"},
        {pos: [6, 2, 6], state: "minecraft:cut_red_sandstone"},
        {pos: [7, 2, 3], state: "minecraft:red_sand"},
        {pos: [7, 2, 4], state: "minecraft:red_sand"},
        {pos: [7, 2, 5], state: "minecraft:red_sand"},
        {pos: [7, 2, 6], state: "minecraft:cut_red_sandstone"},
        {pos: [7, 2, 7], state: "minecraft:red_sand"},
        {pos: [8, 2, 2], state: "minecraft:cut_red_sandstone"},
        {pos: [8, 2, 3], state: "minecraft:red_sand"},
        {pos: [8, 2, 4], state: "minecraft:red_sand"},
        {pos: [8, 2, 5], state: "minecraft:red_sand"},
        {pos: [8, 2, 6], state: "minecraft:cut_red_sandstone"},
        {pos: [8, 2, 7], state: "minecraft:red_sand"},
        {pos: [8, 2, 8], state: "minecraft:red_sand"},
        {pos: [9, 2, 1], state: "minecraft:red_sand"},
        {pos: [9, 2, 2], state: "minecraft:cut_red_sandstone"},
        {pos: [9, 2, 3], state: "minecraft:red_sand"},
        {pos: [9, 2, 4], state: "minecraft:red_sand"},
        {pos: [9, 2, 5], state: "minecraft:red_sand"},
        {pos: [9, 2, 6], state: "minecraft:red_terracotta"},
        {pos: [9, 2, 7], state: "minecraft:red_sand"},
        {pos: [9, 2, 8], state: "minecraft:red_sand"},
        {pos: [10, 2, 1], state: "minecraft:red_sand"},
        {pos: [10, 2, 2], state: "minecraft:red_terracotta"},
        {pos: [10, 2, 3], state: "minecraft:red_sand"},
        {pos: [10, 2, 4], state: "minecraft:red_sand"},
        {pos: [10, 2, 5], state: "minecraft:red_sand"},
        {pos: [10, 2, 6], state: "minecraft:cut_red_sandstone"},
        {pos: [10, 2, 7], state: "minecraft:red_sand"},
        {pos: [10, 2, 8], state: "minecraft:red_sand"},
        {pos: [11, 2, 0], state: "minecraft:red_sand"},
        {pos: [11, 2, 1], state: "minecraft:red_sand"},
        {pos: [11, 2, 2], state: "minecraft:cut_red_sandstone"},
        {pos: [11, 2, 3], state: "minecraft:red_sand"},
        {pos: [11, 2, 4], state: "minecraft:red_sand"},
        {pos: [11, 2, 5], state: "minecraft:red_sand"},
        {pos: [11, 2, 6], state: "minecraft:cut_red_sandstone"},
        {pos: [11, 2, 7], state: "minecraft:red_sand"},
        {pos: [11, 2, 8], state: "minecraft:red_sand"},
        {pos: [12, 2, 0], state: "minecraft:red_sand"},
        {pos: [12, 2, 1], state: "minecraft:red_sand"},
        {pos: [12, 2, 2], state: "minecraft:red_terracotta"},
        {pos: [12, 2, 3], state: "minecraft:red_sand"},
        {pos: [12, 2, 4], state: "minecraft:red_sand"},
        {pos: [12, 2, 5], state: "minecraft:red_sand"},
        {pos: [12, 2, 6], state: "minecraft:red_terracotta"},
        {pos: [12, 2, 7], state: "minecraft:red_sand"},
        {pos: [13, 2, 0], state: "minecraft:red_sand"},
        {pos: [13, 2, 1], state: "minecraft:red_sand"},
        {pos: [13, 2, 2], state: "minecraft:cut_red_sandstone"},
        {pos: [13, 2, 3], state: "minecraft:red_sand"},
        {pos: [13, 2, 4], state: "minecraft:red_sand"},
        {pos: [13, 2, 5], state: "minecraft:red_sand"},
        {pos: [13, 2, 6], state: "minecraft:cut_red_sandstone"},
        {pos: [14, 2, 3], state: "minecraft:red_sand"},
        {pos: [14, 2, 4], state: "minecraft:red_sand"},
        {pos: [14, 2, 5], state: "minecraft:red_sand"},
        {pos: [0, 3, 6], state: "minecraft:red_sand"},
        {pos: [1, 3, 2], state: "minecraft:red_sand"},
        {pos: [1, 3, 6], state: "minecraft:cut_red_sandstone"},
        {pos: [1, 3, 7], state: "minecraft:red_sand"},
        {pos: [1, 3, 8], state: "minecraft:red_sand"},
        {pos: [2, 3, 1], state: "minecraft:red_sand"},
        {pos: [2, 3, 2], state: "minecraft:cut_red_sandstone"},
        {pos: [2, 3, 3], state: "minecraft:red_sand"},
        {pos: [2, 3, 5], state: "minecraft:red_sand"},
        {pos: [2, 3, 6], state: "minecraft:red_terracotta"},
        {pos: [2, 3, 7], state: "minecraft:red_sand"},
        {pos: [2, 3, 8], state: "minecraft:red_sand"},
        {pos: [3, 3, 1], state: "minecraft:red_sand"},
        {pos: [3, 3, 2], state: "minecraft:cut_red_sandstone"},
        {pos: [3, 3, 3], state: "minecraft:red_sand"},
        {pos: [3, 3, 5], state: "minecraft:red_sand"},
        {pos: [3, 3, 6], state: "minecraft:cut_red_sandstone"},
        {pos: [3, 3, 7], state: "minecraft:red_sand"},
        {pos: [4, 3, 1], state: "minecraft:red_sand"},
        {pos: [4, 3, 2], state: "minecraft:red_sand"},
        {pos: [4, 3, 5], state: "minecraft:red_sand"},
        {pos: [4, 3, 6], state: "minecraft:red_sand"},
        {pos: [4, 3, 7], state: "minecraft:red_sand"},
        {pos: [5, 3, 4], state: "minecraft:red_sand"},
        {pos: [5, 3, 5], state: "minecraft:red_sand"},
        {pos: [5, 3, 6], state: "minecraft:red_sand"},
        {pos: [6, 3, 3], state: "minecraft:red_sand"},
        {pos: [6, 3, 4], state: "minecraft:red_sand"},
        {pos: [6, 3, 5], state: "minecraft:red_sand"},
        {pos: [6, 3, 6], state: "minecraft:red_sand"},
        {pos: [7, 3, 3], state: "minecraft:red_sand"},
        {pos: [7, 3, 4], state: "minecraft:red_sand"},
        {pos: [7, 3, 5], state: "minecraft:red_sand"},
        {pos: [7, 3, 6], state: "minecraft:red_sand"},
        {pos: [7, 3, 7], state: "minecraft:red_sand"},
        {pos: [8, 3, 2], state: "minecraft:cut_red_sandstone"},
        {pos: [8, 3, 3], state: "minecraft:red_sand"},
        {pos: [8, 3, 4], state: "minecraft:red_sand"},
        {pos: [8, 3, 5], state: "minecraft:red_sand"},
        {pos: [8, 3, 6], state: "minecraft:cut_red_sandstone"},
        {pos: [8, 3, 7], state: "minecraft:red_sand"},
        {pos: [8, 3, 8], state: "minecraft:red_sand"},
        {pos: [9, 3, 1], state: "minecraft:red_sand"},
        {pos: [9, 3, 2], state: "minecraft:cut_red_sandstone"},
        {pos: [9, 3, 3], state: "minecraft:red_sand"},
        {pos: [9, 3, 4], state: "minecraft:red_sand"},
        {pos: [9, 3, 5], state: "minecraft:red_sand"},
        {pos: [9, 3, 6], state: "minecraft:red_terracotta"},
        {pos: [9, 3, 7], state: "minecraft:red_sand"},
        {pos: [9, 3, 8], state: "minecraft:red_sand"},
        {pos: [10, 3, 1], state: "minecraft:red_sand"},
        {pos: [10, 3, 2], state: "minecraft:cut_red_sandstone"},
        {pos: [10, 3, 3], state: "minecraft:red_sand"},
        {pos: [10, 3, 4], state: "minecraft:red_sand"},
        {pos: [10, 3, 5], state: "minecraft:red_sand"},
        {pos: [10, 3, 6], state: "minecraft:red_terracotta"},
        {pos: [10, 3, 7], state: "minecraft:red_sand"},
        {pos: [10, 3, 8], state: "minecraft:red_sand"},
        {pos: [11, 3, 0], state: "minecraft:red_sand"},
        {pos: [11, 3, 1], state: "minecraft:red_sand"},
        {pos: [11, 3, 2], state: "minecraft:red_terracotta"},
        {pos: [11, 3, 3], state: "minecraft:red_sand"},
        {pos: [11, 3, 4], state: "minecraft:red_sand"},
        {pos: [11, 3, 5], state: "minecraft:red_sand"},
        {pos: [11, 3, 6], state: "minecraft:red_terracotta"},
        {pos: [11, 3, 7], state: "minecraft:red_sand"},
        {pos: [11, 3, 8], state: "minecraft:red_sand"},
        {pos: [12, 3, 0], state: "minecraft:red_sand"},
        {pos: [12, 3, 1], state: "minecraft:red_sand"},
        {pos: [12, 3, 2], state: "minecraft:cut_red_sandstone"},
        {pos: [12, 3, 3], state: "minecraft:red_sand"},
        {pos: [12, 3, 4], state: "minecraft:red_sand"},
        {pos: [12, 3, 5], state: "minecraft:red_sand"},
        {pos: [12, 3, 6], state: "minecraft:red_terracotta"},
        {pos: [12, 3, 7], state: "minecraft:red_sand"},
        {pos: [13, 3, 0], state: "minecraft:red_sand"},
        {pos: [13, 3, 1], state: "minecraft:red_sand"},
        {pos: [13, 3, 2], state: "minecraft:red_sand"},
        {pos: [13, 3, 3], state: "minecraft:red_sand"},
        {pos: [13, 3, 4], state: "minecraft:red_sand"},
        {pos: [13, 3, 5], state: "minecraft:red_sand"},
        {pos: [13, 3, 6], state: "minecraft:cut_red_sandstone"},
        {pos: [14, 3, 3], state: "minecraft:red_sand"},
        {pos: [14, 3, 4], state: "minecraft:red_sand"},
        {pos: [14, 3, 5], state: "minecraft:red_sand"},
        {pos: [0, 4, 6], state: "minecraft:red_sand"},
        {pos: [1, 4, 6], state: "minecraft:cut_red_sandstone"},
        {pos: [1, 4, 7], state: "minecraft:red_sand"},
        {pos: [1, 4, 8], state: "minecraft:red_sand"},
        {pos: [2, 4, 1], state: "minecraft:red_sand"},
        {pos: [2, 4, 2], state: "minecraft:red_sand"},
        {pos: [2, 4, 5], state: "minecraft:red_sand"},
        {pos: [2, 4, 6], state: "minecraft:cut_red_sandstone"},
        {pos: [2, 4, 7], state: "minecraft:red_sand"},
        {pos: [2, 4, 8], state: "minecraft:red_sand"},
        {pos: [3, 4, 1], state: "minecraft:red_sand"},
        {pos: [3, 4, 2], state: "minecraft:red_sand"},
        {pos: [3, 4, 5], state: "minecraft:red_sand"},
        {pos: [3, 4, 6], state: "minecraft:red_sand"},
        {pos: [3, 4, 7], state: "minecraft:red_sand"},
        {pos: [9, 4, 2], state: "minecraft:cut_red_sandstone"},
        {pos: [9, 4, 5], state: "minecraft:red_sand"},
        {pos: [9, 4, 6], state: "minecraft:cut_red_sandstone"},
        {pos: [9, 4, 7], state: "minecraft:red_sand"},
        {pos: [10, 4, 2], state: "minecraft:cut_red_sandstone"},
        {pos: [10, 4, 4], state: "minecraft:red_sand"},
        {pos: [10, 4, 5], state: "minecraft:red_sand"},
        {pos: [10, 4, 6], state: "minecraft:cut_red_sandstone"},
        {pos: [10, 4, 7], state: "minecraft:red_sand"},
        {pos: [10, 4, 8], state: "minecraft:red_sand"},
        {pos: [11, 4, 1], state: "minecraft:red_sand"},
        {pos: [11, 4, 2], state: "minecraft:cut_red_sandstone"},
        {pos: [11, 4, 3], state: "minecraft:red_sand"},
        {pos: [11, 4, 4], state: "minecraft:red_sand"},
        {pos: [11, 4, 5], state: "minecraft:red_sand"},
        {pos: [11, 4, 6], state: "minecraft:cut_red_sandstone"},
        {pos: [11, 4, 7], state: "minecraft:red_sand"},
        {pos: [11, 4, 8], state: "minecraft:red_sand"},
        {pos: [12, 4, 1], state: "minecraft:red_sand"},
        {pos: [12, 4, 2], state: "minecraft:cut_red_sandstone"},
        {pos: [12, 4, 3], state: "minecraft:red_sand"},
        {pos: [12, 4, 4], state: "minecraft:red_sand"},
        {pos: [12, 4, 5], state: "minecraft:red_sand"},
        {pos: [12, 4, 6], state: "minecraft:cut_red_sandstone"},
        {pos: [12, 4, 7], state: "minecraft:red_sand"},
        {pos: [13, 4, 3], state: "minecraft:red_sand"},
        {pos: [13, 4, 4], state: "minecraft:red_sand"},
        {pos: [13, 4, 5], state: "minecraft:red_sand"},
        {pos: [13, 4, 6], state: "minecraft:cut_red_sandstone"},
        {pos: [14, 4, 4], state: "minecraft:red_sand"},
        {pos: [14, 4, 5], state: "minecraft:red_sand"},
        {pos: [0, 5, 6], state: "minecraft:red_sand"},
        {pos: [1, 5, 6], state: "minecraft:cut_red_sandstone"},
        {pos: [1, 5, 7], state: "minecraft:red_sand"},
        {pos: [2, 5, 6], state: "minecraft:red_sand"},
        {pos: [9, 5, 6], state: "minecraft:red_sandstone_wall{east:low,north:none,south:none,up:true,waterlogged:false,west:none}"},
        {pos: [10, 5, 6], state: "minecraft:red_sandstone_wall{east:low,north:none,south:none,up:false,waterlogged:false,west:low}"},
        {pos: [11, 5, 2], state: "minecraft:red_sandstone_wall{east:low,north:none,south:none,up:true,waterlogged:false,west:none}"},
        {pos: [11, 5, 6], state: "minecraft:red_sandstone_wall{east:low,north:none,south:none,up:false,waterlogged:false,west:low}"},
        {pos: [12, 5, 2], state: "minecraft:red_sandstone_wall{east:none,north:none,south:none,up:true,waterlogged:false,west:low}"},
        {pos: [12, 5, 4], state: "minecraft:red_sand"},
        {pos: [12, 5, 5], state: "minecraft:red_sand"},
        {pos: [12, 5, 6], state: "minecraft:cut_red_sandstone"},
        {pos: [13, 5, 5], state: "minecraft:red_sand"},
        {pos: [13, 5, 6], state: "minecraft:cut_red_sandstone"},
        {pos: [1, 6, 6], state: "minecraft:red_sandstone_wall{east:none,north:none,south:none,up:true,waterlogged:false,west:none}"},
        {pos: [13, 6, 6], state: "minecraft:red_sandstone_wall{east:none,north:none,south:none,up:true,waterlogged:false,west:none}"}
    ],
    entities: [],
    palette: [
        "minecraft:cut_red_sandstone",
        "minecraft:yellow_glazed_terracotta{facing:north}",
        "minecraft:yellow_glazed_terracotta{facing:east}",
        "minecraft:yellow_glazed_terracotta{facing:west}",
        "minecraft:red_sand",
        "minecraft:red_terracotta",
        "minecraft:red_sandstone_stairs{facing:south,half:top,shape:straight,waterlogged:false}",
        "minecraft:red_sandstone_wall{east:low,north:none,south:none,up:true,waterlogged:false,west:none}",
        "minecraft:red_sandstone_wall{east:low,north:none,south:none,up:false,waterlogged:false,west:low}",
        "minecraft:red_sandstone_wall{east:none,north:none,south:none,up:true,waterlogged:false,west:low}",
        "minecraft:red_sandstone_wall{east:none,north:none,south:none,up:true,waterlogged:false,west:none}"
    ],
    trailiertales_DataVersion: 2
}
