{
    DataVersion: 3953,
    size: [19, 8, 26],
    data: [
        {pos: [0, 0, 4], state: "minecraft:cut_red_sandstone"},
        {pos: [0, 0, 5], state: "minecraft:cut_red_sandstone"},
        {pos: [0, 0, 6], state: "minecraft:cut_red_sandstone"},
        {pos: [1, 0, 3], state: "minecraft:cut_red_sandstone"},
        {pos: [1, 0, 4], state: "minecraft:cut_red_sandstone"},
        {pos: [1, 0, 5], state: "minecraft:cut_red_sandstone"},
        {pos: [1, 0, 6], state: "minecraft:cut_red_sandstone"},
        {pos: [1, 0, 7], state: "minecraft:cut_red_sandstone"},
        {pos: [2, 0, 1], state: "minecraft:cut_red_sandstone"},
        {pos: [2, 0, 2], state: "minecraft:cut_red_sandstone"},
        {pos: [2, 0, 3], state: "minecraft:red_terracotta"},
        {pos: [2, 0, 4], state: "minecraft:red_terracotta"},
        {pos: [2, 0, 5], state: "minecraft:red_terracotta"},
        {pos: [2, 0, 6], state: "minecraft:cut_red_sandstone"},
        {pos: [2, 0, 7], state: "minecraft:cut_red_sandstone"},
        {pos: [2, 0, 16], state: "minecraft:cut_red_sandstone"},
        {pos: [2, 0, 17], state: "minecraft:cut_red_sandstone"},
        {pos: [2, 0, 18], state: "minecraft:cut_red_sandstone"},
        {pos: [3, 0, 1], state: "minecraft:red_terracotta"},
        {pos: [3, 0, 2], state: "minecraft:cut_red_sandstone"},
        {pos: [3, 0, 3], state: "minecraft:cut_red_sandstone"},
        {pos: [3, 0, 4], state: "minecraft:cut_red_sandstone"},
        {pos: [3, 0, 5], state: "minecraft:cut_red_sandstone"},
        {pos: [3, 0, 6], state: "minecraft:red_terracotta"},
        {pos: [3, 0, 7], state: "minecraft:cut_red_sandstone"},
        {pos: [3, 0, 15], state: "minecraft:red_terracotta"},
        {pos: [3, 0, 16], state: "minecraft:red_terracotta"},
        {pos: [3, 0, 17], state: "minecraft:red_terracotta"},
        {pos: [3, 0, 18], state: "minecraft:red_terracotta"},
        {pos: [3, 0, 19], state: "minecraft:cut_red_sandstone"},
        {pos: [4, 0, 0], state: "minecraft:red_terracotta"},
        {pos: [4, 0, 1], state: "minecraft:cut_red_sandstone"},
        {pos: [4, 0, 2], state: "minecraft:cut_red_sandstone"},
        {pos: [4, 0, 3], state: "minecraft:cut_red_sandstone"},
        {pos: [4, 0, 4], state: "minecraft:cut_red_sandstone"},
        {pos: [4, 0, 5], state: "minecraft:cut_red_sandstone"},
        {pos: [4, 0, 6], state: "minecraft:red_terracotta"},
        {pos: [4, 0, 7], state: "minecraft:cut_red_sandstone"},
        {pos: [4, 0, 14], state: "minecraft:cut_red_sandstone"},
        {pos: [4, 0, 15], state: "minecraft:cut_red_sandstone"},
        {pos: [4, 0, 16], state: "minecraft:cut_red_sandstone"},
        {pos: [4, 0, 17], state: "minecraft:cut_red_sandstone"},
        {pos: [4, 0, 18], state: "minecraft:cut_red_sandstone"},
        {pos: [4, 0, 19], state: "minecraft:cut_red_sandstone"},
        {pos: [4, 0, 20], state: "minecraft:red_terracotta"},
        {pos: [5, 0, 0], state: "minecraft:red_terracotta"},
        {pos: [5, 0, 1], state: "minecraft:cut_red_sandstone"},
        {pos: [5, 0, 2], state: "minecraft:cut_red_sandstone"},
        {pos: [5, 0, 3], state: "minecraft:orange_glazed_terracotta{facing:north}"},
        {pos: [5, 0, 4], state: "minecraft:orange_glazed_terracotta{facing:west}"},
        {pos: [5, 0, 5], state: "minecraft:cut_red_sandstone"},
        {pos: [5, 0, 6], state: "minecraft:cut_red_sandstone"},
        {pos: [5, 0, 7], state: "minecraft:cut_red_sandstone"},
        {pos: [5, 0, 12], state: "minecraft:cut_red_sandstone"},
        {pos: [5, 0, 13], state: "minecraft:cut_red_sandstone"},
        {pos: [5, 0, 14], state: "minecraft:cut_red_sandstone"},
        {pos: [5, 0, 15], state: "minecraft:cut_red_sandstone"},
        {pos: [5, 0, 16], state: "minecraft:cut_red_sandstone"},
        {pos: [5, 0, 17], state: "minecraft:cut_red_sandstone"},
        {pos: [5, 0, 18], state: "minecraft:cut_red_sandstone"},
        {pos: [5, 0, 19], state: "minecraft:cut_red_sandstone"},
        {pos: [5, 0, 20], state: "minecraft:red_terracotta"},
        {pos: [5, 0, 21], state: "minecraft:cut_red_sandstone"},
        {pos: [6, 0, 0], state: "minecraft:red_terracotta"},
        {pos: [6, 0, 1], state: "minecraft:cut_red_sandstone"},
        {pos: [6, 0, 2], state: "minecraft:cut_red_sandstone"},
        {pos: [6, 0, 3], state: "minecraft:orange_glazed_terracotta{facing:east}"},
        {pos: [6, 0, 4], state: "minecraft:cut_red_sandstone"},
        {pos: [6, 0, 5], state: "minecraft:cut_red_sandstone"},
        {pos: [6, 0, 6], state: "minecraft:cut_red_sandstone"},
        {pos: [6, 0, 7], state: "minecraft:cut_red_sandstone"},
        {pos: [6, 0, 8], state: "minecraft:cut_red_sandstone"},
        {pos: [6, 0, 11], state: "minecraft:cut_red_sandstone"},
        {pos: [6, 0, 12], state: "minecraft:cut_red_sandstone"},
        {pos: [6, 0, 13], state: "minecraft:cut_red_sandstone"},
        {pos: [6, 0, 14], state: "minecraft:cut_red_sandstone"},
        {pos: [6, 0, 15], state: "minecraft:cut_red_sandstone"},
        {pos: [6, 0, 16], state: "minecraft:cut_red_sandstone"},
        {pos: [6, 0, 17], state: "minecraft:cut_red_sandstone"},
        {pos: [6, 0, 18], state: "minecraft:cut_red_sandstone"},
        {pos: [6, 0, 19], state: "minecraft:cut_red_sandstone"},
        {pos: [6, 0, 20], state: "minecraft:red_terracotta"},
        {pos: [6, 0, 21], state: "minecraft:cut_red_sandstone"},
        {pos: [6, 0, 22], state: "minecraft:cut_red_sandstone"},
        {pos: [7, 0, 0], state: "minecraft:red_terracotta"},
        {pos: [7, 0, 1], state: "minecraft:red_terracotta"},
        {pos: [7, 0, 2], state: "minecraft:red_terracotta"},
        {pos: [7, 0, 3], state: "minecraft:red_terracotta"},
        {pos: [7, 0, 4], state: "minecraft:red_terracotta"},
        {pos: [7, 0, 5], state: "minecraft:red_terracotta"},
        {pos: [7, 0, 6], state: "minecraft:cut_red_sandstone"},
        {pos: [7, 0, 7], state: "minecraft:cut_red_sandstone"},
        {pos: [7, 0, 8], state: "minecraft:cut_red_sandstone"},
        {pos: [7, 0, 9], state: "minecraft:cut_red_sandstone"},
        {pos: [7, 0, 10], state: "minecraft:cut_red_sandstone"},
        {pos: [7, 0, 11], state: "minecraft:cut_red_sandstone"},
        {pos: [7, 0, 12], state: "minecraft:red_terracotta"},
        {pos: [7, 0, 13], state: "minecraft:red_terracotta"},
        {pos: [7, 0, 14], state: "minecraft:red_terracotta"},
        {pos: [7, 0, 15], state: "minecraft:red_terracotta"},
        {pos: [7, 0, 16], state: "minecraft:red_terracotta"},
        {pos: [7, 0, 17], state: "minecraft:cut_red_sandstone"},
        {pos: [7, 0, 18], state: "minecraft:red_terracotta"},
        {pos: [7, 0, 19], state: "minecraft:red_terracotta"},
        {pos: [7, 0, 20], state: "minecraft:red_terracotta"},
        {pos: [7, 0, 21], state: "minecraft:cut_red_sandstone"},
        {pos: [7, 0, 22], state: "minecraft:cut_red_sandstone"},
        {pos: [8, 0, 6], state: "minecraft:cut_red_sandstone"},
        {pos: [8, 0, 7], state: "minecraft:cut_red_sandstone"},
        {pos: [8, 0, 8], state: "minecraft:cut_red_sandstone"},
        {pos: [8, 0, 9], state: "minecraft:cut_red_sandstone"},
        {pos: [8, 0, 10], state: "minecraft:cut_red_sandstone"},
        {pos: [8, 0, 11], state: "minecraft:cut_red_sandstone"},
        {pos: [8, 0, 12], state: "minecraft:cut_red_sandstone"},
        {pos: [8, 0, 13], state: "minecraft:yellow_glazed_terracotta{facing:north}"},
        {pos: [8, 0, 14], state: "minecraft:yellow_glazed_terracotta{facing:south}"},
        {pos: [8, 0, 15], state: "minecraft:cut_red_sandstone"},
        {pos: [8, 0, 16], state: "minecraft:cut_red_sandstone"},
        {pos: [8, 0, 17], state: "minecraft:cut_red_sandstone"},
        {pos: [8, 0, 18], state: "minecraft:cut_red_sandstone"},
        {pos: [8, 0, 19], state: "minecraft:cut_red_sandstone"},
        {pos: [8, 0, 20], state: "minecraft:cut_red_sandstone"},
        {pos: [8, 0, 21], state: "minecraft:cut_red_sandstone"},
        {pos: [8, 0, 22], state: "minecraft:cut_red_sandstone"},
        {pos: [8, 0, 23], state: "minecraft:cut_red_sandstone"},
        {pos: [9, 0, 7], state: "minecraft:cut_red_sandstone"},
        {pos: [9, 0, 8], state: "minecraft:cut_red_sandstone"},
        {pos: [9, 0, 11], state: "minecraft:cut_red_sandstone"},
        {pos: [9, 0, 12], state: "minecraft:cut_red_sandstone"},
        {pos: [9, 0, 13], state: "minecraft:cut_red_sandstone"},
        {pos: [9, 0, 14], state: "minecraft:cut_red_sandstone"},
        {pos: [9, 0, 15], state: "minecraft:cut_red_sandstone"},
        {pos: [9, 0, 16], state: "minecraft:cut_red_sandstone"},
        {pos: [9, 0, 17], state: "minecraft:cut_red_sandstone"},
        {pos: [9, 0, 18], state: "minecraft:cut_red_sandstone"},
        {pos: [9, 0, 19], state: "minecraft:cut_red_sandstone"},
        {pos: [9, 0, 20], state: "minecraft:cut_red_sandstone"},
        {pos: [9, 0, 21], state: "minecraft:cut_red_sandstone"},
        {pos: [9, 0, 22], state: "minecraft:orange_glazed_terracotta{facing:north}"},
        {pos: [9, 0, 23], state: "minecraft:cut_red_sandstone"},
        {pos: [9, 0, 24], state: "minecraft:red_terracotta"},
        {pos: [10, 0, 7], state: "minecraft:cut_red_sandstone"},
        {pos: [10, 0, 8], state: "minecraft:cut_red_sandstone"},
        {pos: [10, 0, 9], state: "minecraft:cut_red_sandstone"},
        {pos: [10, 0, 12], state: "minecraft:cut_red_sandstone"},
        {pos: [10, 0, 13], state: "minecraft:cut_red_sandstone"},
        {pos: [10, 0, 14], state: "minecraft:cut_red_sandstone"},
        {pos: [10, 0, 15], state: "minecraft:cut_red_sandstone"},
        {pos: [10, 0, 16], state: "minecraft:yellow_glazed_terracotta{facing:north}"},
        {pos: [10, 0, 17], state: "minecraft:yellow_glazed_terracotta{facing:west}"},
        {pos: [10, 0, 18], state: "minecraft:cut_red_sandstone"},
        {pos: [10, 0, 19], state: "minecraft:cut_red_sandstone"},
        {pos: [10, 0, 20], state: "minecraft:cut_red_sandstone"},
        {pos: [10, 0, 21], state: "minecraft:cut_red_sandstone"},
        {pos: [10, 0, 22], state: "minecraft:cut_red_sandstone"},
        {pos: [10, 0, 23], state: "minecraft:cut_red_sandstone"},
        {pos: [10, 0, 24], state: "minecraft:cut_red_sandstone"},
        {pos: [10, 0, 25], state: "minecraft:cut_red_sandstone"},
        {pos: [11, 0, 9], state: "minecraft:cut_red_sandstone"},
        {pos: [11, 0, 10], state: "minecraft:cut_red_sandstone"},
        {pos: [11, 0, 11], state: "minecraft:cut_red_sandstone"},
        {pos: [11, 0, 13], state: "minecraft:cut_red_sandstone"},
        {pos: [11, 0, 14], state: "minecraft:cut_red_sandstone"},
        {pos: [11, 0, 15], state: "minecraft:cut_red_sandstone"},
        {pos: [11, 0, 16], state: "minecraft:yellow_glazed_terracotta{facing:east}"},
        {pos: [11, 0, 17], state: "minecraft:yellow_glazed_terracotta{facing:south}"},
        {pos: [11, 0, 18], state: "minecraft:cut_red_sandstone"},
        {pos: [11, 0, 19], state: "minecraft:cut_red_sandstone"},
        {pos: [11, 0, 20], state: "minecraft:cut_red_sandstone"},
        {pos: [11, 0, 23], state: "minecraft:cut_red_sandstone"},
        {pos: [11, 0, 24], state: "minecraft:cut_red_sandstone"},
        {pos: [11, 0, 25], state: "minecraft:cut_red_sandstone"},
        {pos: [12, 0, 10], state: "minecraft:cut_red_sandstone"},
        {pos: [12, 0, 11], state: "minecraft:cut_red_sandstone"},
        {pos: [12, 0, 12], state: "minecraft:cut_red_sandstone"},
        {pos: [12, 0, 13], state: "minecraft:cut_red_sandstone"},
        {pos: [12, 0, 14], state: "minecraft:red_terracotta"},
        {pos: [12, 0, 15], state: "minecraft:red_terracotta"},
        {pos: [12, 0, 16], state: "minecraft:red_terracotta"},
        {pos: [12, 0, 17], state: "minecraft:cut_red_sandstone"},
        {pos: [12, 0, 18], state: "minecraft:red_terracotta"},
        {pos: [12, 0, 19], state: "minecraft:red_terracotta"},
        {pos: [12, 0, 20], state: "minecraft:cut_red_sandstone"},
        {pos: [12, 0, 21], state: "minecraft:red_terracotta"},
        {pos: [13, 0, 7], state: "minecraft:cut_red_sandstone"},
        {pos: [13, 0, 8], state: "minecraft:cut_red_sandstone"},
        {pos: [13, 0, 10], state: "minecraft:cut_red_sandstone"},
        {pos: [13, 0, 11], state: "minecraft:cut_red_sandstone"},
        {pos: [13, 0, 12], state: "minecraft:cut_red_sandstone"},
        {pos: [13, 0, 13], state: "minecraft:red_terracotta"},
        {pos: [13, 0, 14], state: "minecraft:cut_red_sandstone"},
        {pos: [13, 0, 15], state: "minecraft:cut_red_sandstone"},
        {pos: [13, 0, 16], state: "minecraft:cut_red_sandstone"},
        {pos: [13, 0, 17], state: "minecraft:cut_red_sandstone"},
        {pos: [13, 0, 18], state: "minecraft:cut_red_sandstone"},
        {pos: [13, 0, 19], state: "minecraft:cut_red_sandstone"},
        {pos: [13, 0, 20], state: "minecraft:cut_red_sandstone"},
        {pos: [13, 0, 21], state: "minecraft:red_terracotta"},
        {pos: [14, 0, 7], state: "minecraft:cut_red_sandstone"},
        {pos: [14, 0, 8], state: "minecraft:cut_red_sandstone"},
        {pos: [14, 0, 9], state: "minecraft:cut_red_sandstone"},
        {pos: [14, 0, 11], state: "minecraft:cut_red_sandstone"},
        {pos: [14, 0, 12], state: "minecraft:orange_glazed_terracotta{facing:north}"},
        {pos: [14, 0, 13], state: "minecraft:red_terracotta"},
        {pos: [14, 0, 14], state: "minecraft:cut_red_sandstone"},
        {pos: [14, 0, 15], state: "minecraft:cut_red_sandstone"},
        {pos: [14, 0, 16], state: "minecraft:cut_red_sandstone"},
        {pos: [14, 0, 17], state: "minecraft:cut_red_sandstone"},
        {pos: [14, 0, 18], state: "minecraft:cut_red_sandstone"},
        {pos: [14, 0, 19], state: "minecraft:cut_red_sandstone"},
        {pos: [14, 0, 20], state: "minecraft:cut_red_sandstone"},
        {pos: [14, 0, 21], state: "minecraft:red_terracotta"},
        {pos: [15, 0, 7], state: "minecraft:cut_red_sandstone"},
        {pos: [15, 0, 8], state: "minecraft:cut_red_sandstone"},
        {pos: [15, 0, 9], state: "minecraft:cut_red_sandstone"},
        {pos: [15, 0, 11], state: "minecraft:cut_red_sandstone"},
        {pos: [15, 0, 12], state: "minecraft:orange_glazed_terracotta{facing:east}"},
        {pos: [15, 0, 13], state: "minecraft:cut_red_sandstone"},
        {pos: [15, 0, 14], state: "minecraft:cut_red_sandstone"},
        {pos: [15, 0, 15], state: "minecraft:cut_red_sandstone"},
        {pos: [15, 0, 16], state: "minecraft:cut_red_sandstone"},
        {pos: [15, 0, 17], state: "minecraft:cut_red_sandstone"},
        {pos: [15, 0, 18], state: "minecraft:cut_red_sandstone"},
        {pos: [15, 0, 19], state: "minecraft:cut_red_sandstone"},
        {pos: [15, 0, 20], state: "minecraft:red_terracotta"},
        {pos: [15, 0, 21], state: "minecraft:red_terracotta"},
        {pos: [16, 0, 7], state: "minecraft:red_terracotta"},
        {pos: [16, 0, 8], state: "minecraft:cut_red_sandstone"},
        {pos: [16, 0, 9], state: "minecraft:cut_red_sandstone"},
        {pos: [16, 0, 12], state: "minecraft:cut_red_sandstone"},
        {pos: [16, 0, 13], state: "minecraft:red_terracotta"},
        {pos: [16, 0, 14], state: "minecraft:red_terracotta"},
        {pos: [16, 0, 15], state: "minecraft:red_terracotta"},
        {pos: [16, 0, 16], state: "minecraft:red_terracotta"},
        {pos: [16, 0, 17], state: "minecraft:red_terracotta"},
        {pos: [16, 0, 18], state: "minecraft:cut_red_sandstone"},
        {pos: [16, 0, 19], state: "minecraft:red_terracotta"},
        {pos: [16, 0, 20], state: "minecraft:red_terracotta"},
        {pos: [16, 0, 21], state: "minecraft:red_terracotta"},
        {pos: [17, 0, 13], state: "minecraft:cut_red_sandstone"},
        {pos: [17, 0, 14], state: "minecraft:cut_red_sandstone"},
        {pos: [17, 0, 15], state: "minecraft:cut_red_sandstone"},
        {pos: [17, 0, 16], state: "minecraft:cut_red_sandstone"},
        {pos: [17, 0, 17], state: "minecraft:cut_red_sandstone"},
        {pos: [17, 0, 18], state: "minecraft:cut_red_sandstone"},
        {pos: [17, 0, 19], state: "minecraft:cut_red_sandstone"},
        {pos: [17, 0, 20], state: "minecraft:cut_red_sandstone"},
        {pos: [18, 0, 14], state: "minecraft:cut_red_sandstone"},
        {pos: [18, 0, 15], state: "minecraft:cut_red_sandstone"},
        {pos: [18, 0, 16], state: "minecraft:cut_red_sandstone"},
        {pos: [18, 0, 17], state: "minecraft:cut_red_sandstone"},
        {pos: [18, 0, 18], state: "minecraft:cut_red_sandstone"},
        {pos: [0, 1, 4], state: "minecraft:red_sand"},
        {pos: [0, 1, 5], state: "minecraft:red_sand"},
        {pos: [0, 1, 6], state: "minecraft:red_sand"},
        {pos: [1, 1, 3], state: "minecraft:red_sand"},
        {pos: [1, 1, 4], state: "minecraft:red_sand"},
        {pos: [1, 1, 5], state: "minecraft:red_sand"},
        {pos: [1, 1, 6], state: "minecraft:red_sand"},
        {pos: [1, 1, 7], state: "minecraft:red_sand"},
        {pos: [2, 1, 1], state: "minecraft:red_sand"},
        {pos: [2, 1, 2], state: "minecraft:red_sand"},
        {pos: [2, 1, 3], state: "minecraft:red_terracotta"},
        {pos: [2, 1, 4], state: "minecraft:red_terracotta"},
        {pos: [2, 1, 5], state: "minecraft:red_terracotta"},
        {pos: [2, 1, 6], state: "minecraft:red_sand"},
        {pos: [2, 1, 7], state: "minecraft:red_sand"},
        {pos: [2, 1, 16], state: "minecraft:red_sand"},
        {pos: [2, 1, 17], state: "minecraft:red_sand"},
        {pos: [2, 1, 18], state: "minecraft:red_sand"},
        {pos: [3, 1, 1], state: "minecraft:red_terracotta"},
        {pos: [3, 1, 2], state: "minecraft:red_sand"},
        {pos: [3, 1, 3], state: "minecraft:red_sand"},
        {pos: [3, 1, 4], state: "minecraft:red_sandstone_stairs{facing:west,half:top,shape:straight,waterlogged:false}"},
        {pos: [3, 1, 5], state: "minecraft:red_sandstone_stairs{facing:west,half:top,shape:straight,waterlogged:false}"},
        {pos: [3, 1, 6], state: "minecraft:red_terracotta"},
        {pos: [3, 1, 7], state: "minecraft:red_sand"},
        {pos: [3, 1, 15], state: "minecraft:red_sand"},
        {pos: [3, 1, 16], state: "minecraft:red_terracotta"},
        {pos: [3, 1, 17], state: "minecraft:red_terracotta"},
        {pos: [3, 1, 18], state: "minecraft:red_terracotta"},
        {pos: [3, 1, 19], state: "minecraft:red_terracotta"},
        {pos: [4, 1, 0], state: "minecraft:red_terracotta"},
        {pos: [4, 1, 1], state: "minecraft:red_sand"},
        {pos: [4, 1, 2], state: "minecraft:red_sand"},
        {pos: [4, 1, 3], state: "minecraft:red_sand"},
        {pos: [4, 1, 4], state: "minecraft:red_sand"},
        {pos: [4, 1, 5], state: "minecraft:red_sand"},
        {pos: [4, 1, 6], state: "minecraft:red_terracotta"},
        {pos: [4, 1, 7], state: "minecraft:red_sand"},
        {pos: [4, 1, 14], state: "minecraft:red_sand"},
        {pos: [4, 1, 15], state: "minecraft:red_sand"},
        {pos: [4, 1, 16], state: "minecraft:red_sand"},
        {pos: [4, 1, 17], state: "minecraft:red_sand"},
        {pos: [4, 1, 18], state: "minecraft:red_terracotta"},
        {pos: [4, 1, 19], state: "minecraft:red_terracotta"},
        {pos: [4, 1, 20], state: "minecraft:cut_red_sandstone"},
        {pos: [5, 1, 0], state: "minecraft:red_terracotta"},
        {pos: [5, 1, 1], state: "minecraft:red_sand"},
        {pos: [5, 1, 2], state: "minecraft:red_sand"},
        {pos: [5, 1, 3], state: "minecraft:red_sand"},
        {pos: [5, 1, 4], state: "minecraft:red_sand"},
        {pos: [5, 1, 5], state: "minecraft:red_sand"},
        {pos: [5, 1, 6], state: "minecraft:red_sand"},
        {pos: [5, 1, 7], state: "minecraft:red_sand"},
        {pos: [5, 1, 12], state: "minecraft:red_sand"},
        {pos: [5, 1, 13], state: "minecraft:red_sand"},
        {pos: [5, 1, 14], state: "minecraft:red_sand"},
        {pos: [5, 1, 15], state: "minecraft:red_sand"},
        {pos: [5, 1, 16], state: "minecraft:red_sand"},
        {pos: [5, 1, 17], state: "minecraft:red_sand"},
        {pos: [5, 1, 18], state: "minecraft:red_sand"},
        {pos: [5, 1, 19], state: "minecraft:red_sandstone_stairs{facing:south,half:top,shape:straight,waterlogged:false}"},
        {pos: [5, 1, 20], state: "minecraft:red_terracotta"},
        {pos: [5, 1, 21], state: "minecraft:red_sand"},
        {pos: [6, 1, 0], state: "minecraft:red_terracotta"},
        {pos: [6, 1, 1], state: "minecraft:red_sand"},
        {pos: [6, 1, 2], state: "minecraft:red_sand"},
        {pos: [6, 1, 3], state: "minecraft:red_sand"},
        {pos: [6, 1, 4], state: "minecraft:red_sand"},
        {pos: [6, 1, 5], state: "minecraft:red_sand"},
        {pos: [6, 1, 6], state: "minecraft:red_sand"},
        {pos: [6, 1, 7], state: "minecraft:red_sand"},
        {pos: [6, 1, 8], state: "minecraft:red_sand"},
        {pos: [6, 1, 11], state: "minecraft:red_sand"},
        {pos: [6, 1, 12], state: "minecraft:red_sand"},
        {pos: [6, 1, 13], state: "minecraft:red_sand"},
        {pos: [6, 1, 14], state: "minecraft:red_sand"},
        {pos: [6, 1, 15], state: "minecraft:red_sand"},
        {pos: [6, 1, 16], state: "minecraft:red_sand"},
        {pos: [6, 1, 17], state: "minecraft:red_sand"},
        {pos: [6, 1, 18], state: "minecraft:red_sand"},
        {pos: [6, 1, 19], state: "minecraft:red_sandstone_stairs{facing:south,half:top,shape:straight,waterlogged:false}"},
        {pos: [6, 1, 20], state: "minecraft:red_terracotta"},
        {pos: [6, 1, 21], state: "minecraft:red_sand"},
        {pos: [6, 1, 22], state: "minecraft:red_sand"},
        {pos: [7, 1, 0], state: "minecraft:red_sand"},
        {pos: [7, 1, 1], state: "minecraft:red_terracotta"},
        {pos: [7, 1, 2], state: "minecraft:red_terracotta"},
        {pos: [7, 1, 3], state: "minecraft:red_terracotta"},
        {pos: [7, 1, 4], state: "minecraft:red_sand"},
        {pos: [7, 1, 5], state: "minecraft:red_sand"},
        {pos: [7, 1, 6], state: "minecraft:red_sand"},
        {pos: [7, 1, 7], state: "minecraft:red_sand"},
        {pos: [7, 1, 8], state: "minecraft:red_sand"},
        {pos: [7, 1, 9], state: "minecraft:red_sand"},
        {pos: [7, 1, 10], state: "minecraft:red_sand"},
        {pos: [7, 1, 11], state: "minecraft:red_sand"},
        {pos: [7, 1, 12], state: "minecraft:red_terracotta"},
        {pos: [7, 1, 13], state: "minecraft:red_terracotta"},
        {pos: [7, 1, 14], state: "minecraft:red_terracotta"},
        {pos: [7, 1, 15], state: "minecraft:red_terracotta"},
        {pos: [7, 1, 16], state: "minecraft:red_terracotta"},
        {pos: [7, 1, 17], state: "minecraft:red_sand"},
        {pos: [7, 1, 18], state: "minecraft:red_terracotta"},
        {pos: [7, 1, 19], state: "minecraft:red_terracotta"},
        {pos: [7, 1, 20], state: "minecraft:red_terracotta"},
        {pos: [7, 1, 21], state: "minecraft:red_sand"},
        {pos: [7, 1, 22], state: "minecraft:red_sand"},
        {pos: [8, 1, 6], state: "minecraft:red_sand"},
        {pos: [8, 1, 7], state: "minecraft:red_sand"},
        {pos: [8, 1, 8], state: "minecraft:red_sand"},
        {pos: [8, 1, 9], state: "minecraft:red_sand"},
        {pos: [8, 1, 10], state: "minecraft:red_sand"},
        {pos: [8, 1, 11], state: "minecraft:red_sand"},
        {pos: [8, 1, 12], state: "minecraft:red_sand"},
        {pos: [8, 1, 13], state: "minecraft:red_sand"},
        {pos: [8, 1, 14], state: "minecraft:red_sand"},
        {pos: [8, 1, 15], state: "minecraft:red_sand"},
        {pos: [8, 1, 16], state: "minecraft:red_sand"},
        {pos: [8, 1, 17], state: "minecraft:red_sand"},
        {pos: [8, 1, 18], state: "minecraft:red_sand"},
        {pos: [8, 1, 19], state: "minecraft:red_sand"},
        {pos: [8, 1, 20], state: "minecraft:red_sand"},
        {pos: [8, 1, 21], state: "minecraft:red_sand"},
        {pos: [8, 1, 22], state: "minecraft:red_sand"},
        {pos: [8, 1, 23], state: "minecraft:red_sand"},
        {pos: [9, 1, 7], state: "minecraft:red_sand"},
        {pos: [9, 1, 8], state: "minecraft:red_sand"},
        {pos: [9, 1, 11], state: "minecraft:red_sand"},
        {pos: [9, 1, 12], state: "minecraft:red_sand"},
        {pos: [9, 1, 13], state: "minecraft:red_sand"},
        {pos: [9, 1, 14], state: "minecraft:red_sand"},
        {pos: [9, 1, 15], state: "minecraft:red_sand"},
        {pos: [9, 1, 16], state: "minecraft:red_sand"},
        {pos: [9, 1, 17], state: "minecraft:red_sand"},
        {pos: [9, 1, 18], state: "minecraft:red_sand"},
        {pos: [9, 1, 19], state: "minecraft:red_sand"},
        {pos: [9, 1, 20], state: "minecraft:red_sand"},
        {pos: [9, 1, 21], state: "minecraft:red_sand"},
        {pos: [9, 1, 22], state: "minecraft:red_sand"},
        {pos: [9, 1, 23], state: "minecraft:red_terracotta"},
        {pos: [9, 1, 24], state: "minecraft:red_terracotta"},
        {pos: [10, 1, 7], state: "minecraft:red_sand"},
        {pos: [10, 1, 8], state: "minecraft:red_sand"},
        {pos: [10, 1, 9], state: "minecraft:red_sand"},
        {pos: [10, 1, 12], state: "minecraft:red_sand"},
        {pos: [10, 1, 13], state: "minecraft:red_sand"},
        {pos: [10, 1, 14], state: "minecraft:red_sand"},
        {pos: [10, 1, 15], state: "minecraft:red_sand"},
        {pos: [10, 1, 16], state: "minecraft:red_sand"},
        {pos: [10, 1, 17], state: "minecraft:red_sand"},
        {pos: [10, 1, 18], state: "minecraft:red_sand"},
        {pos: [10, 1, 19], state: "minecraft:red_sand"},
        {pos: [10, 1, 20], state: "minecraft:red_sand"},
        {pos: [10, 1, 21], state: "minecraft:red_sand"},
        {pos: [10, 1, 22], state: "minecraft:red_sand"},
        {pos: [10, 1, 23], state: "minecraft:red_terracotta"},
        {pos: [10, 1, 24], state: "minecraft:red_terracotta"},
        {pos: [10, 1, 25], state: "minecraft:red_sand"},
        {pos: [11, 1, 9], state: "minecraft:red_sand"},
        {pos: [11, 1, 10], state: "minecraft:red_sand"},
        {pos: [11, 1, 11], state: "minecraft:red_sand"},
        {pos: [11, 1, 13], state: "minecraft:red_sand"},
        {pos: [11, 1, 14], state: "minecraft:red_sand"},
        {pos: [11, 1, 15], state: "minecraft:red_sand"},
        {pos: [11, 1, 16], state: "minecraft:red_sand"},
        {pos: [11, 1, 17], state: "minecraft:red_sand"},
        {pos: [11, 1, 18], state: "minecraft:red_sand"},
        {pos: [11, 1, 19], state: "minecraft:red_sand"},
        {pos: [11, 1, 20], state: "minecraft:red_sand"},
        {pos: [11, 1, 23], state: "minecraft:red_sand"},
        {pos: [11, 1, 24], state: "minecraft:red_sand"},
        {pos: [11, 1, 25], state: "minecraft:red_sand"},
        {pos: [12, 1, 10], state: "minecraft:red_sand"},
        {pos: [12, 1, 11], state: "minecraft:red_sand"},
        {pos: [12, 1, 12], state: "minecraft:red_sand"},
        {pos: [12, 1, 13], state: "minecraft:red_sand"},
        {pos: [12, 1, 14], state: "minecraft:red_terracotta"},
        {pos: [12, 1, 15], state: "minecraft:red_terracotta"},
        {pos: [12, 1, 16], state: "minecraft:red_terracotta"},
        {pos: [12, 1, 17], state: "minecraft:red_sand"},
        {pos: [12, 1, 18], state: "minecraft:red_terracotta"},
        {pos: [12, 1, 19], state: "minecraft:red_terracotta"},
        {pos: [12, 1, 20], state: "minecraft:red_sand"},
        {pos: [12, 1, 21], state: "minecraft:red_terracotta"},
        {pos: [13, 1, 7], state: "minecraft:red_sand"},
        {pos: [13, 1, 8], state: "minecraft:red_sand"},
        {pos: [13, 1, 10], state: "minecraft:red_sand"},
        {pos: [13, 1, 11], state: "minecraft:red_sand"},
        {pos: [13, 1, 12], state: "minecraft:red_sand"},
        {pos: [13, 1, 13], state: "minecraft:red_terracotta"},
        {pos: [13, 1, 14], state: "minecraft:red_sand"},
        {pos: [13, 1, 15], state: "minecraft:red_sand"},
        {pos: [13, 1, 16], state: "minecraft:red_sand"},
        {pos: [13, 1, 17], state: "minecraft:red_sand"},
        {pos: [13, 1, 18], state: "minecraft:red_sand"},
        {pos: [13, 1, 19], state: "minecraft:red_sand"},
        {pos: [13, 1, 20], state: "minecraft:red_sand"},
        {pos: [13, 1, 21], state: "minecraft:red_terracotta"},
        {pos: [14, 1, 7], state: "minecraft:red_sand"},
        {pos: [14, 1, 8], state: "minecraft:red_sand"},
        {pos: [14, 1, 9], state: "minecraft:red_sand"},
        {pos: [14, 1, 11], state: "minecraft:red_sand"},
        {pos: [14, 1, 12], state: "minecraft:red_sand"},
        {pos: [14, 1, 13], state: "minecraft:red_terracotta"},
        {pos: [14, 1, 14], state: "minecraft:red_sand"},
        {pos: [14, 1, 15], state: "minecraft:red_sand"},
        {pos: [14, 1, 16], state: "minecraft:red_sand"},
        {pos: [14, 1, 17], state: "minecraft:red_sand"},
        {pos: [14, 1, 18], state: "minecraft:red_sand"},
        {pos: [14, 1, 19], state: "minecraft:red_sand"},
        {pos: [14, 1, 20], state: "minecraft:red_sand"},
        {pos: [14, 1, 21], state: "minecraft:red_terracotta"},
        {pos: [15, 1, 7], state: "minecraft:red_terracotta"},
        {pos: [15, 1, 8], state: "minecraft:red_terracotta"},
        {pos: [15, 1, 9], state: "minecraft:red_sand"},
        {pos: [15, 1, 11], state: "minecraft:red_sand"},
        {pos: [15, 1, 12], state: "minecraft:red_sand"},
        {pos: [15, 1, 13], state: "minecraft:red_sand"},
        {pos: [15, 1, 14], state: "minecraft:red_sand"},
        {pos: [15, 1, 15], state: "minecraft:red_sand"},
        {pos: [15, 1, 16], state: "minecraft:red_sandstone_stairs{facing:east,half:top,shape:straight,waterlogged:false}"},
        {pos: [15, 1, 17], state: "minecraft:red_sandstone_stairs{facing:east,half:top,shape:straight,waterlogged:false}"},
        {pos: [15, 1, 18], state: "minecraft:red_sand"},
        {pos: [15, 1, 19], state: "minecraft:red_sand"},
        {pos: [15, 1, 20], state: "minecraft:red_terracotta"},
        {pos: [15, 1, 21], state: "minecraft:red_terracotta"},
        {pos: [16, 1, 7], state: "minecraft:red_terracotta"},
        {pos: [16, 1, 8], state: "minecraft:red_terracotta"},
        {pos: [16, 1, 9], state: "minecraft:red_sand"},
        {pos: [16, 1, 12], state: "minecraft:red_sand"},
        {pos: [16, 1, 13], state: "minecraft:red_terracotta"},
        {pos: [16, 1, 14], state: "minecraft:red_terracotta"},
        {pos: [16, 1, 15], state: "minecraft:red_terracotta"},
        {pos: [16, 1, 16], state: "minecraft:red_terracotta"},
        {pos: [16, 1, 17], state: "minecraft:red_terracotta"},
        {pos: [16, 1, 18], state: "minecraft:red_sand"},
        {pos: [16, 1, 19], state: "minecraft:red_terracotta"},
        {pos: [16, 1, 20], state: "minecraft:red_terracotta"},
        {pos: [16, 1, 21], state: "minecraft:red_terracotta"},
        {pos: [17, 1, 13], state: "minecraft:red_sand"},
        {pos: [17, 1, 14], state: "minecraft:cut_red_sandstone"},
        {pos: [17, 1, 15], state: "minecraft:cut_red_sandstone"},
        {pos: [17, 1, 16], state: "minecraft:cut_red_sandstone"},
        {pos: [17, 1, 17], state: "minecraft:red_sand"},
        {pos: [17, 1, 18], state: "minecraft:red_sand"},
        {pos: [17, 1, 19], state: "minecraft:red_sand"},
        {pos: [17, 1, 20], state: "minecraft:red_sand"},
        {pos: [18, 1, 14], state: "minecraft:red_sand"},
        {pos: [18, 1, 15], state: "minecraft:red_sand"},
        {pos: [18, 1, 16], state: "minecraft:red_sand"},
        {pos: [18, 1, 17], state: "minecraft:red_sand"},
        {pos: [18, 1, 18], state: "minecraft:red_sand"},
        {pos: [0, 2, 4], state: "minecraft:red_sand"},
        {pos: [0, 2, 5], state: "minecraft:red_sand"},
        {pos: [0, 2, 6], state: "minecraft:red_sand"},
        {pos: [1, 2, 3], state: "minecraft:red_sand"},
        {pos: [1, 2, 4], state: "minecraft:red_sand"},
        {pos: [1, 2, 5], state: "minecraft:red_sand"},
        {pos: [1, 2, 6], state: "minecraft:red_sand"},
        {pos: [1, 2, 7], state: "minecraft:red_sand"},
        {pos: [2, 2, 1], state: "minecraft:red_sand"},
        {pos: [2, 2, 2], state: "minecraft:red_sand"},
        {pos: [2, 2, 3], state: "minecraft:red_sand"},
        {pos: [2, 2, 4], state: "minecraft:red_terracotta"},
        {pos: [2, 2, 5], state: "minecraft:red_terracotta"},
        {pos: [2, 2, 6], state: "minecraft:red_sand"},
        {pos: [2, 2, 7], state: "minecraft:red_sand"},
        {pos: [2, 2, 16], state: "minecraft:red_sand"},
        {pos: [2, 2, 17], state: "minecraft:red_sand"},
        {pos: [2, 2, 18], state: "minecraft:red_sand"},
        {pos: [3, 2, 1], state: "minecraft:red_terracotta"},
        {pos: [3, 2, 2], state: "minecraft:red_sand"},
        {pos: [3, 2, 3], state: "minecraft:red_sand"},
        {pos: [3, 2, 4], state: "minecraft:red_sand"},
        {pos: [3, 2, 5], state: "minecraft:red_sand"},
        {pos: [3, 2, 6], state: "minecraft:red_terracotta"},
        {pos: [3, 2, 7], state: "minecraft:red_sand"},
        {pos: [3, 2, 15], state: "minecraft:red_sand"},
        {pos: [3, 2, 16], state: "minecraft:cut_red_sandstone"},
        {pos: [3, 2, 17], state: "minecraft:red_terracotta"},
        {pos: [3, 2, 18], state: "minecraft:red_terracotta"},
        {pos: [3, 2, 19], state: "minecraft:red_terracotta"},
        {pos: [4, 2, 0], state: "minecraft:red_terracotta"},
        {pos: [4, 2, 1], state: "minecraft:red_sand"},
        {pos: [4, 2, 2], state: "minecraft:red_sand"},
        {pos: [4, 2, 3], state: "minecraft:red_sand"},
        {pos: [4, 2, 4], state: "minecraft:red_sand"},
        {pos: [4, 2, 5], state: "minecraft:red_sand"},
        {pos: [4, 2, 6], state: "minecraft:red_terracotta"},
        {pos: [4, 2, 7], state: "minecraft:red_sand"},
        {pos: [4, 2, 14], state: "minecraft:red_sand"},
        {pos: [4, 2, 15], state: "minecraft:red_sand"},
        {pos: [4, 2, 16], state: "minecraft:red_sand"},
        {pos: [4, 2, 17], state: "minecraft:red_sand"},
        {pos: [4, 2, 18], state: "minecraft:red_terracotta"},
        {pos: [4, 2, 19], state: "minecraft:red_terracotta"},
        {pos: [4, 2, 20], state: "minecraft:red_sand"},
        {pos: [5, 2, 0], state: "minecraft:red_terracotta"},
        {pos: [5, 2, 1], state: "minecraft:red_sand"},
        {pos: [5, 2, 2], state: "minecraft:red_sand"},
        {pos: [5, 2, 3], state: "minecraft:red_sand"},
        {pos: [5, 2, 4], state: "minecraft:red_sand"},
        {pos: [5, 2, 5], state: "minecraft:red_sand"},
        {pos: [5, 2, 6], state: "minecraft:red_sand"},
        {pos: [5, 2, 7], state: "minecraft:red_sand"},
        {pos: [5, 2, 12], state: "minecraft:red_sand"},
        {pos: [5, 2, 13], state: "minecraft:red_sand"},
        {pos: [5, 2, 14], state: "minecraft:red_sand"},
        {pos: [5, 2, 15], state: "minecraft:red_sand"},
        {pos: [5, 2, 16], state: "minecraft:red_sand"},
        {pos: [5, 2, 17], state: "minecraft:red_sand"},
        {pos: [5, 2, 18], state: "minecraft:red_sand"},
        {pos: [5, 2, 19], state: "minecraft:red_sand"},
        {pos: [5, 2, 20], state: "minecraft:cut_red_sandstone"},
        {pos: [5, 2, 21], state: "minecraft:red_sand"},
        {pos: [6, 2, 0], state: "minecraft:red_sand"},
        {pos: [6, 2, 1], state: "minecraft:red_sand"},
        {pos: [6, 2, 2], state: "minecraft:red_sand"},
        {pos: [6, 2, 3], state: "minecraft:red_sand"},
        {pos: [6, 2, 4], state: "minecraft:red_sand"},
        {pos: [6, 2, 5], state: "minecraft:red_sand"},
        {pos: [6, 2, 6], state: "minecraft:red_sand"},
        {pos: [6, 2, 7], state: "minecraft:red_sand"},
        {pos: [6, 2, 8], state: "minecraft:red_sand"},
        {pos: [6, 2, 11], state: "minecraft:red_sand"},
        {pos: [6, 2, 12], state: "minecraft:red_sand"},
        {pos: [6, 2, 13], state: "minecraft:red_sand"},
        {pos: [6, 2, 14], state: "minecraft:red_sand"},
        {pos: [6, 2, 15], state: "minecraft:red_sand"},
        {pos: [6, 2, 16], state: "minecraft:red_sand"},
        {pos: [6, 2, 17], state: "minecraft:red_sand"},
        {pos: [6, 2, 18], state: "minecraft:red_sand"},
        {pos: [6, 2, 19], state: "minecraft:red_sand"},
        {pos: [6, 2, 20], state: "minecraft:cut_red_sandstone"},
        {pos: [6, 2, 21], state: "minecraft:red_sand"},
        {pos: [6, 2, 22], state: "minecraft:red_sand"},
        {pos: [7, 2, 0], state: "minecraft:red_sand"},
        {pos: [7, 2, 1], state: "minecraft:cut_red_sandstone"},
        {pos: [7, 2, 2], state: "minecraft:cut_red_sandstone"},
        {pos: [7, 2, 3], state: "minecraft:cut_red_sandstone"},
        {pos: [7, 2, 4], state: "minecraft:red_sand"},
        {pos: [7, 2, 5], state: "minecraft:red_sand"},
        {pos: [7, 2, 6], state: "minecraft:red_sand"},
        {pos: [7, 2, 7], state: "minecraft:red_sand"},
        {pos: [7, 2, 8], state: "minecraft:red_sand"},
        {pos: [7, 2, 9], state: "minecraft:red_sand"},
        {pos: [7, 2, 10], state: "minecraft:red_sand"},
        {pos: [7, 2, 11], state: "minecraft:red_sand"},
        {pos: [7, 2, 12], state: "minecraft:red_sand"},
        {pos: [7, 2, 13], state: "minecraft:red_sand"},
        {pos: [7, 2, 14], state: "minecraft:red_terracotta"},
        {pos: [7, 2, 15], state: "minecraft:red_sand"},
        {pos: [7, 2, 16], state: "minecraft:cut_red_sandstone"},
        {pos: [7, 2, 17], state: "minecraft:red_sand"},
        {pos: [7, 2, 18], state: "minecraft:cut_red_sandstone"},
        {pos: [7, 2, 19], state: "minecraft:cut_red_sandstone"},
        {pos: [7, 2, 20], state: "minecraft:red_terracotta"},
        {pos: [7, 2, 21], state: "minecraft:red_sand"},
        {pos: [7, 2, 22], state: "minecraft:red_sand"},
        {pos: [8, 2, 6], state: "minecraft:red_sand"},
        {pos: [8, 2, 7], state: "minecraft:red_sand"},
        {pos: [8, 2, 8], state: "minecraft:red_sand"},
        {pos: [8, 2, 9], state: "minecraft:red_sand"},
        {pos: [8, 2, 10], state: "minecraft:red_sand"},
        {pos: [8, 2, 11], state: "minecraft:red_sand"},
        {pos: [8, 2, 12], state: "minecraft:red_sand"},
        {pos: [8, 2, 13], state: "minecraft:red_sand"},
        {pos: [8, 2, 14], state: "minecraft:red_sand"},
        {pos: [8, 2, 15], state: "minecraft:red_sand"},
        {pos: [8, 2, 16], state: "minecraft:red_sand"},
        {pos: [8, 2, 17], state: "minecraft:red_sand"},
        {pos: [8, 2, 18], state: "minecraft:red_sand"},
        {pos: [8, 2, 19], state: "minecraft:red_sand"},
        {pos: [8, 2, 20], state: "minecraft:red_sand"},
        {pos: [8, 2, 21], state: "minecraft:red_sand"},
        {pos: [8, 2, 22], state: "minecraft:red_sand"},
        {pos: [8, 2, 23], state: "minecraft:red_sand"},
        {pos: [9, 2, 7], state: "minecraft:red_sand"},
        {pos: [9, 2, 8], state: "minecraft:red_sand"},
        {pos: [9, 2, 11], state: "minecraft:red_sand"},
        {pos: [9, 2, 12], state: "minecraft:red_sand"},
        {pos: [9, 2, 13], state: "minecraft:red_sand"},
        {pos: [9, 2, 14], state: "minecraft:red_sand"},
        {pos: [9, 2, 15], state: "minecraft:red_sand"},
        {pos: [9, 2, 16], state: "minecraft:red_sand"},
        {pos: [9, 2, 17], state: "minecraft:red_sand"},
        {pos: [9, 2, 18], state: "minecraft:red_sand"},
        {pos: [9, 2, 19], state: "minecraft:red_sand"},
        {pos: [9, 2, 20], state: "minecraft:red_sand"},
        {pos: [9, 2, 21], state: "minecraft:red_sand"},
        {pos: [9, 2, 22], state: "minecraft:red_sand"},
        {pos: [9, 2, 23], state: "minecraft:red_terracotta"},
        {pos: [9, 2, 24], state: "minecraft:red_terracotta"},
        {pos: [10, 2, 7], state: "minecraft:red_sand"},
        {pos: [10, 2, 8], state: "minecraft:red_sand"},
        {pos: [10, 2, 9], state: "minecraft:red_sand"},
        {pos: [10, 2, 12], state: "minecraft:red_sand"},
        {pos: [10, 2, 13], state: "minecraft:red_sand"},
        {pos: [10, 2, 14], state: "minecraft:red_sand"},
        {pos: [10, 2, 15], state: "minecraft:red_sand"},
        {pos: [10, 2, 16], state: "minecraft:red_sand"},
        {pos: [10, 2, 17], state: "minecraft:red_sand"},
        {pos: [10, 2, 18], state: "minecraft:red_sand"},
        {pos: [10, 2, 19], state: "minecraft:red_sand"},
        {pos: [10, 2, 20], state: "minecraft:red_sand"},
        {pos: [10, 2, 21], state: "minecraft:red_sand"},
        {pos: [10, 2, 22], state: "minecraft:red_sand"},
        {pos: [10, 2, 23], state: "minecraft:red_terracotta"},
        {pos: [10, 2, 24], state: "minecraft:red_terracotta"},
        {pos: [10, 2, 25], state: "minecraft:red_sand"},
        {pos: [11, 2, 9], state: "minecraft:red_sand"},
        {pos: [11, 2, 10], state: "minecraft:red_sand"},
        {pos: [11, 2, 11], state: "minecraft:red_sand"},
        {pos: [11, 2, 13], state: "minecraft:red_sand"},
        {pos: [11, 2, 14], state: "minecraft:red_sand"},
        {pos: [11, 2, 15], state: "minecraft:red_sand"},
        {pos: [11, 2, 16], state: "minecraft:red_sand"},
        {pos: [11, 2, 17], state: "minecraft:red_sand"},
        {pos: [11, 2, 18], state: "minecraft:red_sand"},
        {pos: [11, 2, 19], state: "minecraft:red_sand"},
        {pos: [11, 2, 20], state: "minecraft:red_sand"},
        {pos: [11, 2, 23], state: "minecraft:red_sand"},
        {pos: [11, 2, 24], state: "minecraft:red_sand"},
        {pos: [11, 2, 25], state: "minecraft:red_sand"},
        {pos: [12, 2, 10], state: "minecraft:red_sand"},
        {pos: [12, 2, 11], state: "minecraft:red_sand"},
        {pos: [12, 2, 12], state: "minecraft:red_sand"},
        {pos: [12, 2, 13], state: "minecraft:red_sand"},
        {pos: [12, 2, 14], state: "minecraft:red_sand"},
        {pos: [12, 2, 15], state: "minecraft:red_terracotta"},
        {pos: [12, 2, 16], state: "minecraft:cut_red_sandstone"},
        {pos: [12, 2, 17], state: "minecraft:red_sand"},
        {pos: [12, 2, 18], state: "minecraft:red_sand"},
        {pos: [12, 2, 19], state: "minecraft:red_terracotta"},
        {pos: [12, 2, 20], state: "minecraft:red_sand"},
        {pos: [12, 2, 21], state: "minecraft:cut_red_sandstone"},
        {pos: [13, 2, 7], state: "minecraft:red_sand"},
        {pos: [13, 2, 8], state: "minecraft:red_sand"},
        {pos: [13, 2, 10], state: "minecraft:red_sand"},
        {pos: [13, 2, 11], state: "minecraft:red_sand"},
        {pos: [13, 2, 12], state: "minecraft:red_sand"},
        {pos: [13, 2, 13], state: "minecraft:cut_red_sandstone"},
        {pos: [13, 2, 14], state: "minecraft:red_sand"},
        {pos: [13, 2, 15], state: "minecraft:red_sand"},
        {pos: [13, 2, 16], state: "minecraft:red_sand"},
        {pos: [13, 2, 17], state: "minecraft:red_sand"},
        {pos: [13, 2, 18], state: "minecraft:red_sand"},
        {pos: [13, 2, 19], state: "minecraft:red_sand"},
        {pos: [13, 2, 20], state: "minecraft:red_sand"},
        {pos: [13, 2, 21], state: "minecraft:red_sand"},
        {pos: [14, 2, 7], state: "minecraft:red_sand"},
        {pos: [14, 2, 8], state: "minecraft:red_sand"},
        {pos: [14, 2, 9], state: "minecraft:red_sand"},
        {pos: [14, 2, 11], state: "minecraft:red_sand"},
        {pos: [14, 2, 12], state: "minecraft:red_sand"},
        {pos: [14, 2, 13], state: "minecraft:red_sand"},
        {pos: [14, 2, 14], state: "minecraft:red_sand"},
        {pos: [14, 2, 15], state: "minecraft:red_sand"},
        {pos: [14, 2, 16], state: "minecraft:red_sand"},
        {pos: [14, 2, 17], state: "minecraft:red_sand"},
        {pos: [14, 2, 18], state: "minecraft:red_sand"},
        {pos: [14, 2, 19], state: "minecraft:red_sand"},
        {pos: [14, 2, 20], state: "minecraft:red_sand"},
        {pos: [14, 2, 21], state: "minecraft:red_sand"},
        {pos: [15, 2, 7], state: "minecraft:red_terracotta"},
        {pos: [15, 2, 8], state: "minecraft:red_terracotta"},
        {pos: [15, 2, 9], state: "minecraft:red_sand"},
        {pos: [15, 2, 11], state: "minecraft:red_sand"},
        {pos: [15, 2, 12], state: "minecraft:red_sand"},
        {pos: [15, 2, 13], state: "minecraft:red_sand"},
        {pos: [15, 2, 14], state: "minecraft:red_sand"},
        {pos: [15, 2, 15], state: "minecraft:red_sand"},
        {pos: [15, 2, 16], state: "minecraft:red_sand"},
        {pos: [15, 2, 17], state: "minecraft:red_sand"},
        {pos: [15, 2, 18], state: "minecraft:red_sand"},
        {pos: [15, 2, 19], state: "minecraft:red_sand"},
        {pos: [15, 2, 20], state: "minecraft:red_sand"},
        {pos: [15, 2, 21], state: "minecraft:red_sand"},
        {pos: [16, 2, 7], state: "minecraft:red_terracotta"},
        {pos: [16, 2, 8], state: "minecraft:red_terracotta"},
        {pos: [16, 2, 9], state: "minecraft:red_sand"},
        {pos: [16, 2, 12], state: "minecraft:red_sand"},
        {pos: [16, 2, 13], state: "minecraft:red_terracotta"},
        {pos: [16, 2, 14], state: "minecraft:red_terracotta"},
        {pos: [16, 2, 15], state: "minecraft:red_sand"},
        {pos: [16, 2, 16], state: "minecraft:cut_red_sandstone"},
        {pos: [16, 2, 17], state: "minecraft:red_terracotta"},
        {pos: [16, 2, 18], state: "minecraft:red_terracotta"},
        {pos: [16, 2, 19], state: "minecraft:red_sand"},
        {pos: [16, 2, 20], state: "minecraft:red_sand"},
        {pos: [16, 2, 21], state: "minecraft:red_terracotta"},
        {pos: [17, 2, 13], state: "minecraft:red_sand"},
        {pos: [17, 2, 14], state: "minecraft:red_sand"},
        {pos: [17, 2, 15], state: "minecraft:red_sand"},
        {pos: [17, 2, 16], state: "minecraft:red_sand"},
        {pos: [17, 2, 17], state: "minecraft:red_sand"},
        {pos: [17, 2, 18], state: "minecraft:red_sand"},
        {pos: [17, 2, 19], state: "minecraft:red_sand"},
        {pos: [17, 2, 20], state: "minecraft:red_sand"},
        {pos: [18, 2, 14], state: "minecraft:red_sand"},
        {pos: [18, 2, 15], state: "minecraft:red_sand"},
        {pos: [18, 2, 16], state: "minecraft:red_sand"},
        {pos: [18, 2, 17], state: "minecraft:red_sand"},
        {pos: [18, 2, 18], state: "minecraft:red_sand"},
        {pos: [0, 3, 4], state: "minecraft:red_sand"},
        {pos: [0, 3, 5], state: "minecraft:red_sand"},
        {pos: [0, 3, 6], state: "minecraft:red_sand"},
        {pos: [1, 3, 3], state: "minecraft:red_sand"},
        {pos: [1, 3, 4], state: "minecraft:red_sand"},
        {pos: [1, 3, 5], state: "minecraft:red_sand"},
        {pos: [1, 3, 6], state: "minecraft:red_sand"},
        {pos: [1, 3, 7], state: "minecraft:red_sand"},
        {pos: [2, 3, 1], state: "minecraft:red_sand"},
        {pos: [2, 3, 2], state: "minecraft:red_sand"},
        {pos: [2, 3, 3], state: "minecraft:red_sand"},
        {pos: [2, 3, 4], state: "minecraft:cut_red_sandstone"},
        {pos: [2, 3, 5], state: "minecraft:red_terracotta"},
        {pos: [2, 3, 6], state: "minecraft:red_sand"},
        {pos: [2, 3, 7], state: "minecraft:red_sand"},
        {pos: [2, 3, 16], state: "minecraft:red_sand"},
        {pos: [2, 3, 17], state: "minecraft:red_sand"},
        {pos: [2, 3, 18], state: "minecraft:red_sand"},
        {pos: [3, 3, 1], state: "minecraft:red_terracotta"},
        {pos: [3, 3, 2], state: "minecraft:red_sand"},
        {pos: [3, 3, 3], state: "minecraft:red_sand"},
        {pos: [3, 3, 4], state: "minecraft:red_sand"},
        {pos: [3, 3, 5], state: "minecraft:red_sand"},
        {pos: [3, 3, 6], state: "minecraft:red_terracotta"},
        {pos: [3, 3, 7], state: "minecraft:red_sand"},
        {pos: [3, 3, 15], state: "minecraft:red_sand"},
        {pos: [3, 3, 16], state: "minecraft:cut_red_sandstone"},
        {pos: [3, 3, 17], state: "minecraft:cut_red_sandstone"},
        {pos: [3, 3, 18], state: "minecraft:red_terracotta"},
        {pos: [3, 3, 19], state: "minecraft:red_terracotta"},
        {pos: [4, 3, 0], state: "minecraft:red_terracotta"},
        {pos: [4, 3, 1], state: "minecraft:red_sand"},
        {pos: [4, 3, 2], state: "minecraft:red_sand"},
        {pos: [4, 3, 3], state: "minecraft:red_sand"},
        {pos: [4, 3, 4], state: "minecraft:red_sand"},
        {pos: [4, 3, 5], state: "minecraft:red_sand"},
        {pos: [4, 3, 6], state: "minecraft:red_sand"},
        {pos: [4, 3, 7], state: "minecraft:red_sand"},
        {pos: [4, 3, 14], state: "minecraft:red_sand"},
        {pos: [4, 3, 15], state: "minecraft:red_sand"},
        {pos: [4, 3, 16], state: "minecraft:red_sand"},
        {pos: [4, 3, 17], state: "minecraft:red_sand"},
        {pos: [4, 3, 18], state: "minecraft:red_terracotta"},
        {pos: [4, 3, 19], state: "minecraft:red_terracotta"},
        {pos: [4, 3, 20], state: "minecraft:red_sand"},
        {pos: [5, 3, 0], state: "minecraft:cut_red_sandstone"},
        {pos: [5, 3, 1], state: "minecraft:red_sand"},
        {pos: [5, 3, 2], state: "minecraft:red_sand"},
        {pos: [5, 3, 3], state: "minecraft:red_sand"},
        {pos: [5, 3, 4], state: "minecraft:red_sand"},
        {pos: [5, 3, 5], state: "minecraft:red_sand"},
        {pos: [5, 3, 6], state: "minecraft:red_sand"},
        {pos: [5, 3, 7], state: "minecraft:red_sand"},
        {pos: [5, 3, 12], state: "minecraft:red_sand"},
        {pos: [5, 3, 13], state: "minecraft:red_sand"},
        {pos: [5, 3, 14], state: "minecraft:red_sand"},
        {pos: [5, 3, 15], state: "minecraft:red_sand"},
        {pos: [5, 3, 16], state: "minecraft:red_sand"},
        {pos: [5, 3, 17], state: "minecraft:red_sand"},
        {pos: [5, 3, 18], state: "minecraft:red_sand"},
        {pos: [5, 3, 19], state: "minecraft:red_sand"},
        {pos: [5, 3, 20], state: "minecraft:red_sand"},
        {pos: [5, 3, 21], state: "minecraft:red_sand"},
        {pos: [6, 3, 0], state: "minecraft:red_sand"},
        {pos: [6, 3, 1], state: "minecraft:red_sand"},
        {pos: [6, 3, 2], state: "minecraft:red_sand"},
        {pos: [6, 3, 3], state: "minecraft:red_sand"},
        {pos: [6, 3, 4], state: "minecraft:red_sand"},
        {pos: [6, 3, 5], state: "minecraft:red_sand"},
        {pos: [6, 3, 6], state: "minecraft:red_sand"},
        {pos: [6, 3, 7], state: "minecraft:red_sand"},
        {pos: [6, 3, 8], state: "minecraft:red_sand"},
        {pos: [6, 3, 11], state: "minecraft:red_sand"},
        {pos: [6, 3, 12], state: "minecraft:red_sand"},
        {pos: [6, 3, 13], state: "minecraft:red_sand"},
        {pos: [6, 3, 14], state: "minecraft:red_sand"},
        {pos: [6, 3, 15], state: "minecraft:red_sand"},
        {pos: [6, 3, 16], state: "minecraft:red_sand"},
        {pos: [6, 3, 17], state: "minecraft:red_sand"},
        {pos: [6, 3, 18], state: "minecraft:red_sand"},
        {pos: [6, 3, 19], state: "minecraft:red_sand"},
        {pos: [6, 3, 20], state: "minecraft:cut_red_sandstone"},
        {pos: [6, 3, 21], state: "minecraft:red_sand"},
        {pos: [6, 3, 22], state: "minecraft:red_sand"},
        {pos: [7, 3, 0], state: "minecraft:red_sand"},
        {pos: [7, 3, 1], state: "minecraft:red_sand"},
        {pos: [7, 3, 2], state: "minecraft:red_sand"},
        {pos: [7, 3, 3], state: "minecraft:red_sand"},
        {pos: [7, 3, 4], state: "minecraft:red_sand"},
        {pos: [7, 3, 5], state: "minecraft:red_sand"},
        {pos: [7, 3, 6], state: "minecraft:red_sand"},
        {pos: [7, 3, 7], state: "minecraft:red_sand"},
        {pos: [7, 3, 8], state: "minecraft:red_sand"},
        {pos: [7, 3, 9], state: "minecraft:red_sand"},
        {pos: [7, 3, 10], state: "minecraft:red_sand"},
        {pos: [7, 3, 11], state: "minecraft:red_sand"},
        {pos: [7, 3, 12], state: "minecraft:red_sand"},
        {pos: [7, 3, 13], state: "minecraft:red_terracotta"},
        {pos: [7, 3, 14], state: "minecraft:cut_red_sandstone"},
        {pos: [7, 3, 15], state: "minecraft:cut_red_sandstone"},
        {pos: [7, 3, 16], state: "minecraft:cut_red_sandstone"},
        {pos: [7, 3, 17], state: "minecraft:red_terracotta"},
        {pos: [7, 3, 18], state: "minecraft:cut_red_sandstone"},
        {pos: [7, 3, 19], state: "minecraft:cut_red_sandstone"},
        {pos: [7, 3, 20], state: "minecraft:red_sand"},
        {pos: [7, 3, 21], state: "minecraft:red_sand"},
        {pos: [7, 3, 22], state: "minecraft:red_sand"},
        {pos: [8, 3, 6], state: "minecraft:red_sand"},
        {pos: [8, 3, 7], state: "minecraft:red_sand"},
        {pos: [8, 3, 8], state: "minecraft:red_sand"},
        {pos: [8, 3, 9], state: "minecraft:red_sand"},
        {pos: [8, 3, 10], state: "minecraft:red_sand"},
        {pos: [8, 3, 11], state: "minecraft:red_sand"},
        {pos: [8, 3, 12], state: "minecraft:red_sand"},
        {pos: [8, 3, 13], state: "minecraft:red_sand"},
        {pos: [8, 3, 14], state: "minecraft:red_sand"},
        {pos: [8, 3, 15], state: "minecraft:red_sand"},
        {pos: [8, 3, 16], state: "minecraft:red_sand"},
        {pos: [8, 3, 17], state: "minecraft:red_sand"},
        {pos: [8, 3, 18], state: "minecraft:red_sand"},
        {pos: [8, 3, 19], state: "minecraft:red_sand"},
        {pos: [8, 3, 20], state: "minecraft:red_sand"},
        {pos: [8, 3, 21], state: "minecraft:red_sand"},
        {pos: [8, 3, 22], state: "minecraft:red_sand"},
        {pos: [8, 3, 23], state: "minecraft:red_sand"},
        {pos: [9, 3, 7], state: "minecraft:red_sand"},
        {pos: [9, 3, 8], state: "minecraft:red_sand"},
        {pos: [9, 3, 11], state: "minecraft:red_sand"},
        {pos: [9, 3, 12], state: "minecraft:red_sand"},
        {pos: [9, 3, 13], state: "minecraft:red_sand"},
        {pos: [9, 3, 14], state: "minecraft:red_sand"},
        {pos: [9, 3, 15], state: "minecraft:red_sand"},
        {pos: [9, 3, 16], state: "minecraft:red_sand"},
        {pos: [9, 3, 17], state: "minecraft:red_sand"},
        {pos: [9, 3, 18], state: "minecraft:red_sand"},
        {pos: [9, 3, 19], state: "minecraft:red_sand"},
        {pos: [9, 3, 20], state: "minecraft:red_sand"},
        {pos: [9, 3, 21], state: "minecraft:red_sand"},
        {pos: [9, 3, 22], state: "minecraft:red_sand"},
        {pos: [9, 3, 23], state: "minecraft:red_terracotta"},
        {pos: [9, 3, 24], state: "minecraft:red_terracotta"},
        {pos: [10, 3, 7], state: "minecraft:red_sand"},
        {pos: [10, 3, 8], state: "minecraft:red_sand"},
        {pos: [10, 3, 9], state: "minecraft:red_sand"},
        {pos: [10, 3, 12], state: "minecraft:red_sand"},
        {pos: [10, 3, 13], state: "minecraft:red_sand"},
        {pos: [10, 3, 14], state: "minecraft:red_sand"},
        {pos: [10, 3, 15], state: "minecraft:red_sand"},
        {pos: [10, 3, 16], state: "minecraft:red_sand"},
        {pos: [10, 3, 17], state: "minecraft:red_sand"},
        {pos: [10, 3, 18], state: "minecraft:red_sand"},
        {pos: [10, 3, 19], state: "minecraft:red_sand"},
        {pos: [10, 3, 20], state: "minecraft:red_sand"},
        {pos: [10, 3, 21], state: "minecraft:red_sand"},
        {pos: [10, 3, 22], state: "minecraft:red_sand"},
        {pos: [10, 3, 23], state: "minecraft:red_terracotta"},
        {pos: [10, 3, 24], state: "minecraft:red_terracotta"},
        {pos: [10, 3, 25], state: "minecraft:red_sand"},
        {pos: [11, 3, 9], state: "minecraft:red_sand"},
        {pos: [11, 3, 10], state: "minecraft:red_sand"},
        {pos: [11, 3, 11], state: "minecraft:red_sand"},
        {pos: [11, 3, 13], state: "minecraft:red_sand"},
        {pos: [11, 3, 14], state: "minecraft:red_sand"},
        {pos: [11, 3, 15], state: "minecraft:red_sand"},
        {pos: [11, 3, 16], state: "minecraft:red_sand"},
        {pos: [11, 3, 17], state: "minecraft:red_sand"},
        {pos: [11, 3, 18], state: "minecraft:red_sand"},
        {pos: [11, 3, 19], state: "minecraft:red_sand"},
        {pos: [11, 3, 20], state: "minecraft:red_sand"},
        {pos: [11, 3, 23], state: "minecraft:red_sand"},
        {pos: [11, 3, 24], state: "minecraft:red_sand"},
        {pos: [11, 3, 25], state: "minecraft:red_sand"},
        {pos: [12, 3, 10], state: "minecraft:red_sand"},
        {pos: [12, 3, 11], state: "minecraft:red_sand"},
        {pos: [12, 3, 12], state: "minecraft:red_sand"},
        {pos: [12, 3, 13], state: "minecraft:red_sand"},
        {pos: [12, 3, 14], state: "minecraft:red_sand"},
        {pos: [12, 3, 15], state: "minecraft:red_sand"},
        {pos: [12, 3, 16], state: "minecraft:cut_red_sandstone"},
        {pos: [12, 3, 17], state: "minecraft:cut_red_sandstone"},
        {pos: [12, 3, 18], state: "minecraft:red_terracotta"},
        {pos: [12, 3, 19], state: "minecraft:cut_red_sandstone"},
        {pos: [12, 3, 20], state: "minecraft:cut_red_sandstone"},
        {pos: [12, 3, 21], state: "minecraft:cut_red_sandstone"},
        {pos: [13, 3, 7], state: "minecraft:red_sand"},
        {pos: [13, 3, 8], state: "minecraft:red_sand"},
        {pos: [13, 3, 10], state: "minecraft:red_sand"},
        {pos: [13, 3, 11], state: "minecraft:red_sand"},
        {pos: [13, 3, 12], state: "minecraft:red_sand"},
        {pos: [13, 3, 13], state: "minecraft:cut_red_sandstone"},
        {pos: [13, 3, 14], state: "minecraft:red_sand"},
        {pos: [13, 3, 15], state: "minecraft:red_sand"},
        {pos: [13, 3, 16], state: "minecraft:red_sand"},
        {pos: [13, 3, 17], state: "minecraft:red_sand"},
        {pos: [13, 3, 18], state: "minecraft:red_sand"},
        {pos: [13, 3, 19], state: "minecraft:red_sand"},
        {pos: [13, 3, 20], state: "minecraft:red_sand"},
        {pos: [13, 3, 21], state: "minecraft:red_sand"},
        {pos: [14, 3, 7], state: "minecraft:red_sand"},
        {pos: [14, 3, 8], state: "minecraft:red_sand"},
        {pos: [14, 3, 9], state: "minecraft:red_sand"},
        {pos: [14, 3, 11], state: "minecraft:red_sand"},
        {pos: [14, 3, 12], state: "minecraft:red_sand"},
        {pos: [14, 3, 13], state: "minecraft:cut_red_sandstone"},
        {pos: [14, 3, 14], state: "minecraft:red_sand"},
        {pos: [14, 3, 15], state: "minecraft:red_sand"},
        {pos: [14, 3, 16], state: "minecraft:red_sand"},
        {pos: [14, 3, 17], state: "minecraft:red_sand"},
        {pos: [14, 3, 18], state: "minecraft:red_sand"},
        {pos: [14, 3, 19], state: "minecraft:red_sand"},
        {pos: [14, 3, 20], state: "minecraft:red_sand"},
        {pos: [14, 3, 21], state: "minecraft:red_sand"},
        {pos: [15, 3, 7], state: "minecraft:red_terracotta"},
        {pos: [15, 3, 8], state: "minecraft:red_terracotta"},
        {pos: [15, 3, 9], state: "minecraft:red_sand"},
        {pos: [15, 3, 11], state: "minecraft:red_sand"},
        {pos: [15, 3, 12], state: "minecraft:red_sand"},
        {pos: [15, 3, 13], state: "minecraft:cut_red_sandstone"},
        {pos: [15, 3, 14], state: "minecraft:red_sand"},
        {pos: [15, 3, 15], state: "minecraft:red_sand"},
        {pos: [15, 3, 16], state: "minecraft:red_sand"},
        {pos: [15, 3, 17], state: "minecraft:red_sand"},
        {pos: [15, 3, 18], state: "minecraft:red_sand"},
        {pos: [15, 3, 19], state: "minecraft:red_sand"},
        {pos: [15, 3, 20], state: "minecraft:red_sand"},
        {pos: [15, 3, 21], state: "minecraft:red_sand"},
        {pos: [16, 3, 7], state: "minecraft:red_terracotta"},
        {pos: [16, 3, 8], state: "minecraft:red_terracotta"},
        {pos: [16, 3, 9], state: "minecraft:red_sand"},
        {pos: [16, 3, 12], state: "minecraft:red_sand"},
        {pos: [16, 3, 13], state: "minecraft:red_terracotta"},
        {pos: [16, 3, 14], state: "minecraft:red_sand"},
        {pos: [16, 3, 15], state: "minecraft:red_terracotta"},
        {pos: [16, 3, 16], state: "minecraft:cut_red_sandstone"},
        {pos: [16, 3, 17], state: "minecraft:cut_red_sandstone"},
        {pos: [16, 3, 18], state: "minecraft:cut_red_sandstone"},
        {pos: [16, 3, 19], state: "minecraft:red_terracotta"},
        {pos: [16, 3, 20], state: "minecraft:red_sand"},
        {pos: [16, 3, 21], state: "minecraft:red_sand"},
        {pos: [17, 3, 13], state: "minecraft:red_sand"},
        {pos: [17, 3, 14], state: "minecraft:red_sand"},
        {pos: [17, 3, 15], state: "minecraft:red_sand"},
        {pos: [17, 3, 16], state: "minecraft:red_sand"},
        {pos: [17, 3, 17], state: "minecraft:red_sand"},
        {pos: [17, 3, 18], state: "minecraft:red_sand"},
        {pos: [17, 3, 19], state: "minecraft:red_sand"},
        {pos: [18, 3, 15], state: "minecraft:red_sand"},
        {pos: [18, 3, 16], state: "minecraft:red_sand"},
        {pos: [2, 4, 3], state: "minecraft:red_sand"},
        {pos: [2, 4, 4], state: "minecraft:red_sand"},
        {pos: [2, 4, 5], state: "minecraft:cut_red_sandstone"},
        {pos: [2, 4, 18], state: "minecraft:red_sand"},
        {pos: [3, 4, 1], state: "minecraft:cut_red_sandstone"},
        {pos: [3, 4, 3], state: "minecraft:red_sand"},
        {pos: [3, 4, 4], state: "minecraft:red_sand"},
        {pos: [3, 4, 5], state: "minecraft:red_sand"},
        {pos: [3, 4, 6], state: "minecraft:cut_red_sandstone"},
        {pos: [3, 4, 18], state: "minecraft:cut_red_sandstone"},
        {pos: [3, 4, 19], state: "minecraft:red_terracotta"},
        {pos: [4, 4, 0], state: "minecraft:cut_red_sandstone"},
        {pos: [4, 4, 4], state: "minecraft:red_sand"},
        {pos: [4, 4, 5], state: "minecraft:red_sand"},
        {pos: [4, 4, 6], state: "minecraft:red_sand"},
        {pos: [4, 4, 17], state: "minecraft:red_sand"},
        {pos: [4, 4, 18], state: "minecraft:red_terracotta"},
        {pos: [4, 4, 19], state: "minecraft:cut_red_sandstone"},
        {pos: [5, 4, 0], state: "minecraft:cut_red_sandstone"},
        {pos: [5, 4, 1], state: "minecraft:red_sand"},
        {pos: [5, 4, 5], state: "minecraft:red_sand"},
        {pos: [5, 4, 6], state: "minecraft:red_sand"},
        {pos: [5, 4, 15], state: "minecraft:red_sand"},
        {pos: [5, 4, 16], state: "minecraft:red_sand"},
        {pos: [5, 4, 17], state: "minecraft:red_sand"},
        {pos: [5, 4, 18], state: "minecraft:red_sand"},
        {pos: [5, 4, 19], state: "minecraft:red_sand"},
        {pos: [6, 4, 0], state: "minecraft:red_sand"},
        {pos: [6, 4, 1], state: "minecraft:red_sand"},
        {pos: [6, 4, 14], state: "minecraft:red_sand"},
        {pos: [6, 4, 15], state: "minecraft:red_sand"},
        {pos: [6, 4, 16], state: "minecraft:red_sand"},
        {pos: [6, 4, 17], state: "minecraft:red_sand"},
        {pos: [6, 4, 18], state: "minecraft:red_sand"},
        {pos: [6, 4, 19], state: "minecraft:red_sand"},
        {pos: [6, 4, 20], state: "minecraft:red_sand"},
        {pos: [7, 4, 0], state: "minecraft:red_sand"},
        {pos: [7, 4, 1], state: "minecraft:red_sand"},
        {pos: [7, 4, 2], state: "minecraft:red_sand"},
        {pos: [7, 4, 7], state: "minecraft:red_sand"},
        {pos: [7, 4, 8], state: "minecraft:red_sand"},
        {pos: [7, 4, 9], state: "minecraft:red_sand"},
        {pos: [7, 4, 13], state: "minecraft:red_sandstone_wall{east:none,north:none,south:low,up:true,waterlogged:false,west:none}"},
        {pos: [7, 4, 14], state: "minecraft:cut_red_sandstone"},
        {pos: [7, 4, 15], state: "minecraft:cut_red_sandstone"},
        {pos: [7, 4, 16], state: "minecraft:cut_red_sandstone"},
        {pos: [7, 4, 17], state: "minecraft:cut_red_sandstone"},
        {pos: [7, 4, 18], state: "minecraft:red_sand"},
        {pos: [7, 4, 19], state: "minecraft:red_sand"},
        {pos: [8, 4, 6], state: "minecraft:red_sand"},
        {pos: [8, 4, 7], state: "minecraft:red_sand"},
        {pos: [8, 4, 8], state: "minecraft:red_sand"},
        {pos: [8, 4, 9], state: "minecraft:red_sand"},
        {pos: [8, 4, 10], state: "minecraft:red_sand"},
        {pos: [8, 4, 14], state: "minecraft:red_sand"},
        {pos: [8, 4, 15], state: "minecraft:red_sand"},
        {pos: [8, 4, 16], state: "minecraft:red_sand"},
        {pos: [8, 4, 17], state: "minecraft:red_sand"},
        {pos: [8, 4, 22], state: "minecraft:red_sand"},
        {pos: [8, 4, 23], state: "minecraft:red_sand"},
        {pos: [9, 4, 7], state: "minecraft:red_sand"},
        {pos: [9, 4, 8], state: "minecraft:red_sand"},
        {pos: [9, 4, 22], state: "minecraft:red_sand"},
        {pos: [9, 4, 23], state: "minecraft:red_terracotta"},
        {pos: [9, 4, 24], state: "minecraft:red_terracotta"},
        {pos: [10, 4, 20], state: "minecraft:red_sand"},
        {pos: [10, 4, 21], state: "minecraft:red_sand"},
        {pos: [10, 4, 22], state: "minecraft:red_sand"},
        {pos: [10, 4, 23], state: "minecraft:red_terracotta"},
        {pos: [10, 4, 24], state: "minecraft:red_terracotta"},
        {pos: [10, 4, 25], state: "minecraft:red_sand"},
        {pos: [11, 4, 18], state: "minecraft:red_sand"},
        {pos: [11, 4, 19], state: "minecraft:red_sand"},
        {pos: [11, 4, 20], state: "minecraft:red_sand"},
        {pos: [11, 4, 23], state: "minecraft:red_sand"},
        {pos: [11, 4, 24], state: "minecraft:red_sand"},
        {pos: [11, 4, 25], state: "minecraft:red_sand"},
        {pos: [12, 4, 14], state: "minecraft:red_sand"},
        {pos: [12, 4, 15], state: "minecraft:red_sand"},
        {pos: [12, 4, 16], state: "minecraft:red_sand"},
        {pos: [12, 4, 17], state: "minecraft:red_sand"},
        {pos: [12, 4, 18], state: "minecraft:red_sand"},
        {pos: [12, 4, 19], state: "minecraft:cut_red_sandstone"},
        {pos: [12, 4, 20], state: "minecraft:cut_red_sandstone"},
        {pos: [12, 4, 21], state: "minecraft:cut_red_sandstone"},
        {pos: [13, 4, 7], state: "minecraft:red_sand"},
        {pos: [13, 4, 8], state: "minecraft:red_sand"},
        {pos: [13, 4, 13], state: "minecraft:red_sand"},
        {pos: [13, 4, 14], state: "minecraft:red_sand"},
        {pos: [13, 4, 15], state: "minecraft:red_sand"},
        {pos: [13, 4, 16], state: "minecraft:red_sand"},
        {pos: [13, 4, 17], state: "minecraft:red_sand"},
        {pos: [13, 4, 18], state: "minecraft:red_sand"},
        {pos: [13, 4, 19], state: "minecraft:red_sand"},
        {pos: [13, 4, 20], state: "minecraft:red_sand"},
        {pos: [13, 4, 21], state: "minecraft:red_sand"},
        {pos: [14, 4, 7], state: "minecraft:red_sand"},
        {pos: [14, 4, 8], state: "minecraft:red_sand"},
        {pos: [14, 4, 9], state: "minecraft:red_sand"},
        {pos: [14, 4, 13], state: "minecraft:cut_red_sandstone"},
        {pos: [14, 4, 14], state: "minecraft:red_sand"},
        {pos: [14, 4, 15], state: "minecraft:red_sand"},
        {pos: [14, 4, 16], state: "minecraft:red_sand"},
        {pos: [14, 4, 17], state: "minecraft:red_sand"},
        {pos: [14, 4, 18], state: "minecraft:red_sand"},
        {pos: [14, 4, 19], state: "minecraft:red_sand"},
        {pos: [14, 4, 20], state: "minecraft:red_sand"},
        {pos: [14, 4, 21], state: "minecraft:red_sand"},
        {pos: [15, 4, 7], state: "minecraft:red_terracotta"},
        {pos: [15, 4, 8], state: "minecraft:red_terracotta"},
        {pos: [15, 4, 9], state: "minecraft:red_sand"},
        {pos: [15, 4, 13], state: "minecraft:cut_red_sandstone"},
        {pos: [15, 4, 14], state: "minecraft:red_sand"},
        {pos: [15, 4, 15], state: "minecraft:red_sand"},
        {pos: [15, 4, 16], state: "minecraft:red_sand"},
        {pos: [15, 4, 17], state: "minecraft:red_sand"},
        {pos: [15, 4, 18], state: "minecraft:red_sand"},
        {pos: [15, 4, 19], state: "minecraft:red_sand"},
        {pos: [15, 4, 20], state: "minecraft:red_sand"},
        {pos: [15, 4, 21], state: "minecraft:red_sand"},
        {pos: [16, 4, 7], state: "minecraft:cut_red_sandstone"},
        {pos: [16, 4, 8], state: "minecraft:red_terracotta"},
        {pos: [16, 4, 9], state: "minecraft:red_sand"},
        {pos: [16, 4, 13], state: "minecraft:cut_red_sandstone"},
        {pos: [16, 4, 14], state: "minecraft:red_sand"},
        {pos: [16, 4, 15], state: "minecraft:red_sand"},
        {pos: [16, 4, 16], state: "minecraft:cut_red_sandstone"},
        {pos: [16, 4, 17], state: "minecraft:cut_red_sandstone"},
        {pos: [16, 4, 18], state: "minecraft:cut_red_sandstone"},
        {pos: [16, 4, 19], state: "minecraft:red_sand"},
        {pos: [16, 4, 20], state: "minecraft:red_sand"},
        {pos: [16, 4, 21], state: "minecraft:red_sand"},
        {pos: [17, 4, 14], state: "minecraft:red_sand"},
        {pos: [17, 4, 15], state: "minecraft:red_sand"},
        {pos: [17, 4, 16], state: "minecraft:red_sand"},
        {pos: [17, 4, 17], state: "minecraft:red_sand"},
        {pos: [17, 4, 18], state: "minecraft:red_sand"},
        {pos: [2, 5, 5], state: "minecraft:red_sandstone_wall{east:none,north:none,south:none,up:true,waterlogged:false,west:none}"},
        {pos: [3, 5, 6], state: "minecraft:red_sandstone_wall{east:none,north:none,south:none,up:true,waterlogged:false,west:none}"},
        {pos: [3, 5, 18], state: "minecraft:cut_red_sandstone"},
        {pos: [3, 5, 19], state: "minecraft:cut_red_sandstone"},
        {pos: [4, 5, 0], state: "minecraft:red_sandstone_wall{east:none,north:none,south:none,up:true,waterlogged:false,west:none}"},
        {pos: [4, 5, 18], state: "minecraft:cut_red_sandstone"},
        {pos: [4, 5, 19], state: "minecraft:cut_red_sandstone"},
        {pos: [5, 5, 16], state: "minecraft:red_sand"},
        {pos: [5, 5, 17], state: "minecraft:red_sand"},
        {pos: [5, 5, 18], state: "minecraft:red_sand"},
        {pos: [5, 5, 19], state: "minecraft:red_sand"},
        {pos: [6, 5, 16], state: "minecraft:red_sand"},
        {pos: [6, 5, 17], state: "minecraft:red_sand"},
        {pos: [6, 5, 18], state: "minecraft:red_sand"},
        {pos: [6, 5, 19], state: "minecraft:red_sand"},
        {pos: [7, 5, 16], state: "minecraft:red_sand"},
        {pos: [7, 5, 17], state: "minecraft:red_sand"},
        {pos: [8, 5, 22], state: "minecraft:red_sand"},
        {pos: [9, 5, 22], state: "minecraft:red_sand"},
        {pos: [9, 5, 23], state: "minecraft:red_terracotta"},
        {pos: [9, 5, 24], state: "minecraft:cut_red_sandstone"},
        {pos: [10, 5, 21], state: "minecraft:red_sand"},
        {pos: [10, 5, 22], state: "minecraft:red_sand"},
        {pos: [10, 5, 23], state: "minecraft:cut_red_sandstone"},
        {pos: [10, 5, 24], state: "minecraft:red_terracotta"},
        {pos: [10, 5, 25], state: "minecraft:red_sand"},
        {pos: [11, 5, 23], state: "minecraft:red_sand"},
        {pos: [11, 5, 24], state: "minecraft:red_sand"},
        {pos: [12, 5, 18], state: "minecraft:red_sand"},
        {pos: [12, 5, 19], state: "minecraft:red_sand"},
        {pos: [12, 5, 20], state: "minecraft:cut_red_sandstone"},
        {pos: [12, 5, 21], state: "minecraft:cut_red_sandstone"},
        {pos: [13, 5, 7], state: "minecraft:red_sand"},
        {pos: [13, 5, 17], state: "minecraft:red_sand"},
        {pos: [13, 5, 18], state: "minecraft:cut_red_sandstone"},
        {pos: [13, 5, 19], state: "minecraft:cut_red_sandstone"},
        {pos: [13, 5, 20], state: "minecraft:cut_red_sandstone"},
        {pos: [13, 5, 21], state: "minecraft:cut_red_sandstone"},
        {pos: [14, 5, 7], state: "minecraft:red_sand"},
        {pos: [14, 5, 8], state: "minecraft:red_sand"},
        {pos: [14, 5, 13], state: "minecraft:red_sandstone_wall{east:low,north:none,south:none,up:true,waterlogged:false,west:none}"},
        {pos: [14, 5, 15], state: "minecraft:cut_red_sandstone"},
        {pos: [14, 5, 16], state: "minecraft:cut_red_sandstone"},
        {pos: [14, 5, 19], state: "minecraft:red_sand"},
        {pos: [14, 5, 20], state: "minecraft:cut_red_sandstone"},
        {pos: [14, 5, 21], state: "minecraft:cut_red_sandstone"},
        {pos: [15, 5, 7], state: "minecraft:cut_red_sandstone"},
        {pos: [15, 5, 8], state: "minecraft:red_terracotta"},
        {pos: [15, 5, 9], state: "minecraft:red_sand"},
        {pos: [15, 5, 13], state: "minecraft:cut_red_sandstone"},
        {pos: [15, 5, 14], state: "minecraft:cut_red_sandstone"},
        {pos: [15, 5, 15], state: "minecraft:cut_red_sandstone"},
        {pos: [15, 5, 16], state: "minecraft:cut_red_sandstone"},
        {pos: [15, 5, 17], state: "minecraft:red_sand"},
        {pos: [15, 5, 18], state: "minecraft:red_sand"},
        {pos: [15, 5, 19], state: "minecraft:red_sand"},
        {pos: [15, 5, 20], state: "minecraft:red_sand"},
        {pos: [15, 5, 21], state: "minecraft:cut_red_sandstone"},
        {pos: [16, 5, 7], state: "minecraft:cut_red_sandstone"},
        {pos: [16, 5, 8], state: "minecraft:cut_red_sandstone"},
        {pos: [16, 5, 9], state: "minecraft:red_sand"},
        {pos: [16, 5, 13], state: "minecraft:cut_red_sandstone"},
        {pos: [16, 5, 14], state: "minecraft:cut_red_sandstone"},
        {pos: [16, 5, 15], state: "minecraft:cut_red_sandstone"},
        {pos: [16, 5, 16], state: "minecraft:cut_red_sandstone"},
        {pos: [16, 5, 17], state: "minecraft:cut_red_sandstone"},
        {pos: [16, 5, 18], state: "minecraft:red_sand"},
        {pos: [16, 5, 19], state: "minecraft:red_sand"},
        {pos: [16, 5, 20], state: "minecraft:red_sand"},
        {pos: [16, 5, 21], state: "minecraft:red_sand"},
        {pos: [9, 6, 23], state: "minecraft:red_terracotta"},
        {pos: [9, 6, 24], state: "minecraft:cut_red_sandstone"},
        {pos: [10, 6, 23], state: "minecraft:cut_red_sandstone"},
        {pos: [10, 6, 24], state: "minecraft:cut_red_sandstone"},
        {pos: [13, 6, 21], state: "minecraft:red_sandstone_wall{east:low,north:none,south:none,up:true,waterlogged:false,west:none}"},
        {pos: [14, 6, 21], state: "minecraft:red_sandstone_wall{east:low,north:none,south:none,up:false,waterlogged:false,west:low}"},
        {pos: [15, 6, 7], state: "minecraft:cut_red_sandstone"},
        {pos: [15, 6, 8], state: "minecraft:cut_red_sandstone"},
        {pos: [15, 6, 15], state: "minecraft:red_sand"},
        {pos: [15, 6, 16], state: "minecraft:red_sand"},
        {pos: [15, 6, 21], state: "minecraft:red_sandstone_wall{east:none,north:none,south:none,up:true,waterlogged:false,west:low}"},
        {pos: [16, 6, 8], state: "minecraft:cut_red_sandstone"},
        {pos: [16, 6, 14], state: "minecraft:red_sandstone_wall{east:none,north:none,south:low,up:true,waterlogged:false,west:none}"},
        {pos: [16, 6, 15], state: "minecraft:red_sandstone_wall{east:none,north:low,south:low,up:true,waterlogged:false,west:low}"},
        {pos: [16, 6, 16], state: "minecraft:red_sandstone_wall{east:none,north:low,south:low,up:true,waterlogged:false,west:low}"},
        {pos: [16, 6, 17], state: "minecraft:red_sand"},
        {pos: [9, 7, 23], state: "minecraft:cut_red_sandstone"},
        {pos: [9, 7, 24], state: "minecraft:cut_red_sandstone"},
        {pos: [10, 7, 23], state: "minecraft:cut_red_sandstone"},
        {pos: [10, 7, 24], state: "minecraft:cut_red_sandstone"}
    ],
    entities: [],
    palette: [
        "minecraft:cut_red_sandstone",
        "minecraft:red_terracotta",
        "minecraft:orange_glazed_terracotta{facing:north}",
        "minecraft:orange_glazed_terracotta{facing:west}",
        "minecraft:orange_glazed_terracotta{facing:east}",
        "minecraft:yellow_glazed_terracotta{facing:north}",
        "minecraft:yellow_glazed_terracotta{facing:south}",
        "minecraft:yellow_glazed_terracotta{facing:west}",
        "minecraft:yellow_glazed_terracotta{facing:east}",
        "minecraft:red_sand",
        "minecraft:red_sandstone_stairs{facing:west,half:top,shape:straight,waterlogged:false}",
        "minecraft:red_sandstone_stairs{facing:south,half:top,shape:straight,waterlogged:false}",
        "minecraft:red_sandstone_stairs{facing:east,half:top,shape:straight,waterlogged:false}",
        "minecraft:red_sandstone_wall{east:none,north:none,south:low,up:true,waterlogged:false,west:none}",
        "minecraft:red_sandstone_wall{east:none,north:none,south:none,up:true,waterlogged:false,west:none}",
        "minecraft:red_sandstone_wall{east:low,north:none,south:none,up:true,waterlogged:false,west:none}",
        "minecraft:red_sandstone_wall{east:low,north:none,south:none,up:false,waterlogged:false,west:low}",
        "minecraft:red_sandstone_wall{east:none,north:none,south:none,up:true,waterlogged:false,west:low}",
        "minecraft:red_sandstone_wall{east:none,north:low,south:low,up:true,waterlogged:false,west:low}"
    ],
    trailiertales_DataVersion: 2
}
