{
    DataVersion: 3953,
    size: [12, 9, 16],
    data: [
        {pos: [0, 0, 4], state: "minecraft:cut_red_sandstone"},
        {pos: [0, 0, 5], state: "minecraft:cut_red_sandstone"},
        {pos: [0, 0, 6], state: "minecraft:cut_red_sandstone"},
        {pos: [1, 0, 2], state: "minecraft:red_terracotta"},
        {pos: [1, 0, 3], state: "minecraft:red_terracotta"},
        {pos: [1, 0, 4], state: "minecraft:red_terracotta"},
        {pos: [1, 0, 5], state: "minecraft:red_terracotta"},
        {pos: [1, 0, 6], state: "minecraft:cut_red_sandstone"},
        {pos: [1, 0, 7], state: "minecraft:cut_red_sandstone"},
        {pos: [1, 0, 12], state: "minecraft:cut_red_sandstone"},
        {pos: [1, 0, 13], state: "minecraft:cut_red_sandstone"},
        {pos: [2, 0, 1], state: "minecraft:cut_red_sandstone"},
        {pos: [2, 0, 2], state: "minecraft:red_terracotta"},
        {pos: [2, 0, 3], state: "minecraft:cut_red_sandstone"},
        {pos: [2, 0, 4], state: "minecraft:cut_red_sandstone"},
        {pos: [2, 0, 5], state: "minecraft:cut_red_sandstone"},
        {pos: [2, 0, 6], state: "minecraft:red_terracotta"},
        {pos: [2, 0, 7], state: "minecraft:cut_red_sandstone"},
        {pos: [2, 0, 10], state: "minecraft:cut_red_sandstone"},
        {pos: [2, 0, 11], state: "minecraft:cut_red_sandstone"},
        {pos: [2, 0, 12], state: "minecraft:cut_red_sandstone"},
        {pos: [2, 0, 13], state: "minecraft:cut_red_sandstone"},
        {pos: [2, 0, 14], state: "minecraft:cut_red_sandstone"},
        {pos: [3, 0, 0], state: "minecraft:cut_red_sandstone"},
        {pos: [3, 0, 1], state: "minecraft:cut_red_sandstone"},
        {pos: [3, 0, 2], state: "minecraft:cut_red_sandstone"},
        {pos: [3, 0, 3], state: "minecraft:cut_red_sandstone"},
        {pos: [3, 0, 4], state: "minecraft:cut_red_sandstone"},
        {pos: [3, 0, 5], state: "minecraft:cut_red_sandstone"},
        {pos: [3, 0, 6], state: "minecraft:cut_red_sandstone"},
        {pos: [3, 0, 7], state: "minecraft:red_terracotta"},
        {pos: [3, 0, 10], state: "minecraft:cut_red_sandstone"},
        {pos: [3, 0, 11], state: "minecraft:red_terracotta"},
        {pos: [3, 0, 12], state: "minecraft:red_terracotta"},
        {pos: [3, 0, 13], state: "minecraft:red_terracotta"},
        {pos: [3, 0, 14], state: "minecraft:red_terracotta"},
        {pos: [4, 0, 0], state: "minecraft:cut_red_sandstone"},
        {pos: [4, 0, 1], state: "minecraft:cut_red_sandstone"},
        {pos: [4, 0, 2], state: "minecraft:red_terracotta"},
        {pos: [4, 0, 3], state: "minecraft:cut_red_sandstone"},
        {pos: [4, 0, 4], state: "minecraft:cut_red_sandstone"},
        {pos: [4, 0, 5], state: "minecraft:cut_red_sandstone"},
        {pos: [4, 0, 6], state: "minecraft:cut_red_sandstone"},
        {pos: [4, 0, 7], state: "minecraft:cut_red_sandstone"},
        {pos: [4, 0, 8], state: "minecraft:cut_red_sandstone"},
        {pos: [4, 0, 10], state: "minecraft:cut_red_sandstone"},
        {pos: [4, 0, 11], state: "minecraft:cut_red_sandstone"},
        {pos: [4, 0, 12], state: "minecraft:cut_red_sandstone"},
        {pos: [4, 0, 13], state: "minecraft:cut_red_sandstone"},
        {pos: [4, 0, 14], state: "minecraft:red_terracotta"},
        {pos: [5, 0, 1], state: "minecraft:cut_red_sandstone"},
        {pos: [5, 0, 2], state: "minecraft:red_terracotta"},
        {pos: [5, 0, 3], state: "minecraft:cut_red_sandstone"},
        {pos: [5, 0, 4], state: "minecraft:cut_red_sandstone"},
        {pos: [5, 0, 5], state: "minecraft:cut_red_sandstone"},
        {pos: [5, 0, 6], state: "minecraft:cut_red_sandstone"},
        {pos: [5, 0, 7], state: "minecraft:cut_red_sandstone"},
        {pos: [5, 0, 8], state: "minecraft:cut_red_sandstone"},
        {pos: [5, 0, 9], state: "minecraft:cut_red_sandstone"},
        {pos: [5, 0, 10], state: "minecraft:cut_red_sandstone"},
        {pos: [5, 0, 11], state: "minecraft:cut_red_sandstone"},
        {pos: [5, 0, 12], state: "minecraft:cut_red_sandstone"},
        {pos: [5, 0, 13], state: "minecraft:cut_red_sandstone"},
        {pos: [5, 0, 14], state: "minecraft:cut_red_sandstone"},
        {pos: [5, 0, 15], state: "minecraft:cut_red_sandstone"},
        {pos: [6, 0, 1], state: "minecraft:cut_red_sandstone"},
        {pos: [6, 0, 2], state: "minecraft:red_terracotta"},
        {pos: [6, 0, 3], state: "minecraft:cut_red_sandstone"},
        {pos: [6, 0, 4], state: "minecraft:cut_red_sandstone"},
        {pos: [6, 0, 5], state: "minecraft:cut_red_sandstone"},
        {pos: [6, 0, 6], state: "minecraft:cut_red_sandstone"},
        {pos: [6, 0, 7], state: "minecraft:cut_red_sandstone"},
        {pos: [6, 0, 8], state: "minecraft:cut_red_sandstone"},
        {pos: [6, 0, 11], state: "minecraft:red_terracotta"},
        {pos: [6, 0, 12], state: "minecraft:cut_red_sandstone"},
        {pos: [6, 0, 13], state: "minecraft:cut_red_sandstone"},
        {pos: [6, 0, 14], state: "minecraft:red_terracotta"},
        {pos: [6, 0, 15], state: "minecraft:cut_red_sandstone"},
        {pos: [7, 0, 2], state: "minecraft:cut_red_sandstone"},
        {pos: [7, 0, 3], state: "minecraft:red_terracotta"},
        {pos: [7, 0, 4], state: "minecraft:cut_red_sandstone"},
        {pos: [7, 0, 5], state: "minecraft:cut_red_sandstone"},
        {pos: [7, 0, 6], state: "minecraft:cut_red_sandstone"},
        {pos: [7, 0, 7], state: "minecraft:red_terracotta"},
        {pos: [7, 0, 8], state: "minecraft:cut_red_sandstone"},
        {pos: [7, 0, 12], state: "minecraft:red_terracotta"},
        {pos: [7, 0, 13], state: "minecraft:red_terracotta"},
        {pos: [7, 0, 14], state: "minecraft:red_terracotta"},
        {pos: [7, 0, 15], state: "minecraft:cut_red_sandstone"},
        {pos: [8, 0, 3], state: "minecraft:red_terracotta"},
        {pos: [8, 0, 4], state: "minecraft:cut_red_sandstone"},
        {pos: [8, 0, 5], state: "minecraft:cut_red_sandstone"},
        {pos: [8, 0, 6], state: "minecraft:cut_red_sandstone"},
        {pos: [8, 0, 7], state: "minecraft:red_terracotta"},
        {pos: [8, 0, 12], state: "minecraft:cut_red_sandstone"},
        {pos: [8, 0, 13], state: "minecraft:cut_red_sandstone"},
        {pos: [8, 0, 14], state: "minecraft:cut_red_sandstone"},
        {pos: [8, 0, 15], state: "minecraft:cut_red_sandstone"},
        {pos: [9, 0, 3], state: "minecraft:red_terracotta"},
        {pos: [9, 0, 4], state: "minecraft:cut_red_sandstone"},
        {pos: [9, 0, 5], state: "minecraft:cut_red_sandstone"},
        {pos: [9, 0, 6], state: "minecraft:cut_red_sandstone"},
        {pos: [9, 0, 7], state: "minecraft:red_terracotta"},
        {pos: [9, 0, 13], state: "minecraft:cut_red_sandstone"},
        {pos: [10, 0, 3], state: "minecraft:cut_red_sandstone"},
        {pos: [10, 0, 4], state: "minecraft:red_terracotta"},
        {pos: [10, 0, 5], state: "minecraft:red_terracotta"},
        {pos: [10, 0, 6], state: "minecraft:red_terracotta"},
        {pos: [11, 0, 3], state: "minecraft:cut_red_sandstone"},
        {pos: [11, 0, 4], state: "minecraft:cut_red_sandstone"},
        {pos: [11, 0, 5], state: "minecraft:cut_red_sandstone"},
        {pos: [0, 1, 4], state: "minecraft:red_sand"},
        {pos: [0, 1, 5], state: "minecraft:red_sand"},
        {pos: [0, 1, 6], state: "minecraft:red_sand"},
        {pos: [1, 1, 2], state: "minecraft:red_terracotta"},
        {pos: [1, 1, 3], state: "minecraft:red_terracotta"},
        {pos: [1, 1, 4], state: "minecraft:red_terracotta"},
        {pos: [1, 1, 5], state: "minecraft:red_terracotta"},
        {pos: [1, 1, 6], state: "minecraft:red_sand"},
        {pos: [1, 1, 7], state: "minecraft:red_sand"},
        {pos: [1, 1, 12], state: "minecraft:red_sand"},
        {pos: [1, 1, 13], state: "minecraft:red_sand"},
        {pos: [2, 1, 1], state: "minecraft:red_sand"},
        {pos: [2, 1, 2], state: "minecraft:red_terracotta"},
        {pos: [2, 1, 3], state: "minecraft:red_sand"},
        {pos: [2, 1, 4], state: "minecraft:red_sand"},
        {pos: [2, 1, 5], state: "minecraft:red_sandstone_stairs{facing:west,half:top,shape:straight,waterlogged:false}"},
        {pos: [2, 1, 6], state: "minecraft:red_terracotta"},
        {pos: [2, 1, 7], state: "minecraft:red_sand"},
        {pos: [2, 1, 10], state: "minecraft:red_sand"},
        {pos: [2, 1, 11], state: "minecraft:red_sand"},
        {pos: [2, 1, 12], state: "minecraft:red_sand"},
        {pos: [2, 1, 13], state: "minecraft:red_sand"},
        {pos: [2, 1, 14], state: "minecraft:red_sand"},
        {pos: [3, 1, 0], state: "minecraft:red_sand"},
        {pos: [3, 1, 1], state: "minecraft:red_sand"},
        {pos: [3, 1, 2], state: "minecraft:red_sand"},
        {pos: [3, 1, 3], state: "minecraft:red_sand"},
        {pos: [3, 1, 4], state: "minecraft:red_sand"},
        {pos: [3, 1, 5], state: "minecraft:red_sand"},
        {pos: [3, 1, 6], state: "minecraft:red_sand"},
        {pos: [3, 1, 7], state: "minecraft:red_terracotta"},
        {pos: [3, 1, 10], state: "minecraft:red_sand"},
        {pos: [3, 1, 11], state: "minecraft:red_terracotta"},
        {pos: [3, 1, 12], state: "minecraft:red_terracotta"},
        {pos: [3, 1, 13], state: "minecraft:red_terracotta"},
        {pos: [3, 1, 14], state: "minecraft:red_terracotta"},
        {pos: [4, 1, 0], state: "minecraft:red_sand"},
        {pos: [4, 1, 1], state: "minecraft:red_sand"},
        {pos: [4, 1, 2], state: "minecraft:red_terracotta"},
        {pos: [4, 1, 3], state: "minecraft:red_sand"},
        {pos: [4, 1, 4], state: "minecraft:red_sand"},
        {pos: [4, 1, 5], state: "minecraft:red_sand"},
        {pos: [4, 1, 6], state: "minecraft:red_sand"},
        {pos: [4, 1, 7], state: "minecraft:red_sand"},
        {pos: [4, 1, 8], state: "minecraft:red_sand"},
        {pos: [4, 1, 10], state: "minecraft:red_sand"},
        {pos: [4, 1, 11], state: "minecraft:red_sand"},
        {pos: [4, 1, 12], state: "minecraft:red_sand"},
        {pos: [4, 1, 13], state: "minecraft:red_sand"},
        {pos: [4, 1, 14], state: "minecraft:red_terracotta"},
        {pos: [5, 1, 1], state: "minecraft:red_sand"},
        {pos: [5, 1, 2], state: "minecraft:red_terracotta"},
        {pos: [5, 1, 3], state: "minecraft:red_sandstone_stairs{facing:north,half:top,shape:straight,waterlogged:false}"},
        {pos: [5, 1, 4], state: "minecraft:red_sand"},
        {pos: [5, 1, 5], state: "minecraft:red_sand"},
        {pos: [5, 1, 6], state: "minecraft:red_sand"},
        {pos: [5, 1, 7], state: "minecraft:red_sand"},
        {pos: [5, 1, 8], state: "minecraft:red_sand"},
        {pos: [5, 1, 9], state: "minecraft:red_sand"},
        {pos: [5, 1, 10], state: "minecraft:red_sand"},
        {pos: [5, 1, 11], state: "minecraft:red_sand"},
        {pos: [5, 1, 12], state: "minecraft:red_sand"},
        {pos: [5, 1, 13], state: "minecraft:red_sand"},
        {pos: [5, 1, 14], state: "minecraft:red_sand"},
        {pos: [5, 1, 15], state: "minecraft:red_sand"},
        {pos: [6, 1, 1], state: "minecraft:red_sand"},
        {pos: [6, 1, 2], state: "minecraft:red_terracotta"},
        {pos: [6, 1, 3], state: "minecraft:red_sandstone_stairs{facing:north,half:top,shape:straight,waterlogged:false}"},
        {pos: [6, 1, 4], state: "minecraft:red_sand"},
        {pos: [6, 1, 5], state: "minecraft:red_sand"},
        {pos: [6, 1, 6], state: "minecraft:red_sand"},
        {pos: [6, 1, 7], state: "minecraft:red_sand"},
        {pos: [6, 1, 8], state: "minecraft:red_sand"},
        {pos: [6, 1, 11], state: "minecraft:red_terracotta"},
        {pos: [6, 1, 12], state: "minecraft:red_sand"},
        {pos: [6, 1, 13], state: "minecraft:red_sand"},
        {pos: [6, 1, 14], state: "minecraft:red_terracotta"},
        {pos: [6, 1, 15], state: "minecraft:red_sand"},
        {pos: [7, 1, 2], state: "minecraft:red_sand"},
        {pos: [7, 1, 3], state: "minecraft:red_terracotta"},
        {pos: [7, 1, 4], state: "minecraft:red_sand"},
        {pos: [7, 1, 5], state: "minecraft:red_sand"},
        {pos: [7, 1, 6], state: "minecraft:red_sand"},
        {pos: [7, 1, 7], state: "minecraft:red_terracotta"},
        {pos: [7, 1, 8], state: "minecraft:red_sand"},
        {pos: [7, 1, 12], state: "minecraft:red_terracotta"},
        {pos: [7, 1, 13], state: "minecraft:red_terracotta"},
        {pos: [7, 1, 14], state: "minecraft:red_terracotta"},
        {pos: [7, 1, 15], state: "minecraft:red_sand"},
        {pos: [8, 1, 3], state: "minecraft:red_terracotta"},
        {pos: [8, 1, 4], state: "minecraft:red_sand"},
        {pos: [8, 1, 5], state: "minecraft:red_sand"},
        {pos: [8, 1, 6], state: "minecraft:red_sand"},
        {pos: [8, 1, 7], state: "minecraft:red_terracotta"},
        {pos: [8, 1, 12], state: "minecraft:red_sand"},
        {pos: [8, 1, 13], state: "minecraft:red_sand"},
        {pos: [8, 1, 14], state: "minecraft:red_sand"},
        {pos: [8, 1, 15], state: "minecraft:red_sand"},
        {pos: [9, 1, 3], state: "minecraft:red_terracotta"},
        {pos: [9, 1, 4], state: "minecraft:red_sand"},
        {pos: [9, 1, 5], state: "minecraft:red_sand"},
        {pos: [9, 1, 6], state: "minecraft:red_sand"},
        {pos: [9, 1, 7], state: "minecraft:red_terracotta"},
        {pos: [9, 1, 13], state: "minecraft:red_sand"},
        {pos: [10, 1, 3], state: "minecraft:red_sand"},
        {pos: [10, 1, 4], state: "minecraft:red_terracotta"},
        {pos: [10, 1, 5], state: "minecraft:red_terracotta"},
        {pos: [10, 1, 6], state: "minecraft:red_terracotta"},
        {pos: [11, 1, 3], state: "minecraft:red_sand"},
        {pos: [11, 1, 4], state: "minecraft:red_sand"},
        {pos: [11, 1, 5], state: "minecraft:red_sand"},
        {pos: [0, 2, 4], state: "minecraft:red_sand"},
        {pos: [0, 2, 5], state: "minecraft:red_sand"},
        {pos: [1, 2, 2], state: "minecraft:red_terracotta"},
        {pos: [1, 2, 3], state: "minecraft:red_terracotta"},
        {pos: [1, 2, 4], state: "minecraft:red_sand"},
        {pos: [1, 2, 5], state: "minecraft:red_sand"},
        {pos: [1, 2, 6], state: "minecraft:red_sand"},
        {pos: [1, 2, 7], state: "minecraft:red_sand"},
        {pos: [1, 2, 12], state: "minecraft:red_sand"},
        {pos: [1, 2, 13], state: "minecraft:red_sand"},
        {pos: [2, 2, 1], state: "minecraft:red_sand"},
        {pos: [2, 2, 2], state: "minecraft:red_terracotta"},
        {pos: [2, 2, 3], state: "minecraft:red_sand"},
        {pos: [2, 2, 4], state: "minecraft:red_sand"},
        {pos: [2, 2, 5], state: "minecraft:red_sand"},
        {pos: [2, 2, 6], state: "minecraft:cut_red_sandstone"},
        {pos: [2, 2, 7], state: "minecraft:red_sand"},
        {pos: [2, 2, 10], state: "minecraft:red_sand"},
        {pos: [2, 2, 11], state: "minecraft:red_sand"},
        {pos: [2, 2, 12], state: "minecraft:red_sand"},
        {pos: [2, 2, 13], state: "minecraft:red_sand"},
        {pos: [2, 2, 14], state: "minecraft:red_sand"},
        {pos: [3, 2, 0], state: "minecraft:red_sand"},
        {pos: [3, 2, 1], state: "minecraft:red_sand"},
        {pos: [3, 2, 2], state: "minecraft:red_sand"},
        {pos: [3, 2, 3], state: "minecraft:red_sand"},
        {pos: [3, 2, 4], state: "minecraft:red_sand"},
        {pos: [3, 2, 5], state: "minecraft:red_sand"},
        {pos: [3, 2, 6], state: "minecraft:red_sand"},
        {pos: [3, 2, 7], state: "minecraft:red_terracotta"},
        {pos: [3, 2, 10], state: "minecraft:red_sand"},
        {pos: [3, 2, 11], state: "minecraft:red_sand"},
        {pos: [3, 2, 12], state: "minecraft:red_sand"},
        {pos: [3, 2, 13], state: "minecraft:red_terracotta"},
        {pos: [3, 2, 14], state: "minecraft:cut_red_sandstone"},
        {pos: [4, 2, 0], state: "minecraft:red_sand"},
        {pos: [4, 2, 1], state: "minecraft:red_sand"},
        {pos: [4, 2, 2], state: "minecraft:red_sand"},
        {pos: [4, 2, 3], state: "minecraft:red_sand"},
        {pos: [4, 2, 4], state: "minecraft:red_sand"},
        {pos: [4, 2, 5], state: "minecraft:red_sand"},
        {pos: [4, 2, 6], state: "minecraft:red_sand"},
        {pos: [4, 2, 7], state: "minecraft:red_sand"},
        {pos: [4, 2, 8], state: "minecraft:red_sand"},
        {pos: [4, 2, 10], state: "minecraft:red_sand"},
        {pos: [4, 2, 11], state: "minecraft:red_sand"},
        {pos: [4, 2, 12], state: "minecraft:red_sand"},
        {pos: [4, 2, 13], state: "minecraft:red_sand"},
        {pos: [4, 2, 14], state: "minecraft:red_terracotta"},
        {pos: [5, 2, 1], state: "minecraft:red_sand"},
        {pos: [5, 2, 2], state: "minecraft:red_sand"},
        {pos: [5, 2, 3], state: "minecraft:red_sand"},
        {pos: [5, 2, 4], state: "minecraft:red_sand"},
        {pos: [5, 2, 5], state: "minecraft:red_sand"},
        {pos: [5, 2, 6], state: "minecraft:red_sand"},
        {pos: [5, 2, 7], state: "minecraft:red_sand"},
        {pos: [5, 2, 8], state: "minecraft:red_sand"},
        {pos: [5, 2, 9], state: "minecraft:red_sand"},
        {pos: [5, 2, 10], state: "minecraft:red_sand"},
        {pos: [5, 2, 11], state: "minecraft:red_sand"},
        {pos: [5, 2, 12], state: "minecraft:red_sand"},
        {pos: [5, 2, 13], state: "minecraft:red_sand"},
        {pos: [5, 2, 14], state: "minecraft:red_sand"},
        {pos: [5, 2, 15], state: "minecraft:red_sand"},
        {pos: [6, 2, 1], state: "minecraft:red_sand"},
        {pos: [6, 2, 2], state: "minecraft:red_terracotta"},
        {pos: [6, 2, 3], state: "minecraft:red_sand"},
        {pos: [6, 2, 4], state: "minecraft:red_sand"},
        {pos: [6, 2, 5], state: "minecraft:red_sand"},
        {pos: [6, 2, 6], state: "minecraft:red_sand"},
        {pos: [6, 2, 7], state: "minecraft:red_sand"},
        {pos: [6, 2, 8], state: "minecraft:red_sand"},
        {pos: [6, 2, 11], state: "minecraft:red_terracotta"},
        {pos: [6, 2, 12], state: "minecraft:red_sand"},
        {pos: [6, 2, 13], state: "minecraft:red_sand"},
        {pos: [6, 2, 14], state: "minecraft:red_terracotta"},
        {pos: [6, 2, 15], state: "minecraft:red_sand"},
        {pos: [7, 2, 2], state: "minecraft:red_sand"},
        {pos: [7, 2, 3], state: "minecraft:red_terracotta"},
        {pos: [7, 2, 4], state: "minecraft:red_sand"},
        {pos: [7, 2, 5], state: "minecraft:red_sand"},
        {pos: [7, 2, 6], state: "minecraft:red_sand"},
        {pos: [7, 2, 7], state: "minecraft:red_terracotta"},
        {pos: [7, 2, 8], state: "minecraft:red_sand"},
        {pos: [7, 2, 12], state: "minecraft:red_sand"},
        {pos: [7, 2, 13], state: "minecraft:red_terracotta"},
        {pos: [7, 2, 14], state: "minecraft:red_terracotta"},
        {pos: [7, 2, 15], state: "minecraft:red_sand"},
        {pos: [8, 2, 3], state: "minecraft:red_terracotta"},
        {pos: [8, 2, 4], state: "minecraft:red_sand"},
        {pos: [8, 2, 5], state: "minecraft:red_sand"},
        {pos: [8, 2, 6], state: "minecraft:red_sand"},
        {pos: [8, 2, 7], state: "minecraft:red_sand"},
        {pos: [8, 2, 12], state: "minecraft:red_sand"},
        {pos: [8, 2, 13], state: "minecraft:red_sand"},
        {pos: [8, 2, 14], state: "minecraft:red_sand"},
        {pos: [8, 2, 15], state: "minecraft:red_sand"},
        {pos: [9, 2, 3], state: "minecraft:red_sand"},
        {pos: [9, 2, 4], state: "minecraft:red_sand"},
        {pos: [9, 2, 5], state: "minecraft:red_sand"},
        {pos: [9, 2, 6], state: "minecraft:red_sand"},
        {pos: [9, 2, 7], state: "minecraft:cut_red_sandstone"},
        {pos: [9, 2, 13], state: "minecraft:red_sand"},
        {pos: [10, 2, 3], state: "minecraft:red_sand"},
        {pos: [10, 2, 4], state: "minecraft:red_sand"},
        {pos: [10, 2, 5], state: "minecraft:red_terracotta"},
        {pos: [10, 2, 6], state: "minecraft:red_terracotta"},
        {pos: [11, 2, 4], state: "minecraft:red_sand"},
        {pos: [11, 2, 5], state: "minecraft:red_sand"},
        {pos: [0, 3, 4], state: "minecraft:red_sand"},
        {pos: [0, 3, 5], state: "minecraft:red_sand"},
        {pos: [1, 3, 2], state: "minecraft:red_terracotta"},
        {pos: [1, 3, 3], state: "minecraft:red_terracotta"},
        {pos: [1, 3, 4], state: "minecraft:red_sand"},
        {pos: [1, 3, 5], state: "minecraft:red_sand"},
        {pos: [1, 3, 6], state: "minecraft:red_sand"},
        {pos: [1, 3, 7], state: "minecraft:red_sand"},
        {pos: [1, 3, 12], state: "minecraft:red_sand"},
        {pos: [1, 3, 13], state: "minecraft:red_sand"},
        {pos: [2, 3, 1], state: "minecraft:red_sand"},
        {pos: [2, 3, 2], state: "minecraft:cut_red_sandstone"},
        {pos: [2, 3, 3], state: "minecraft:red_terracotta"},
        {pos: [2, 3, 4], state: "minecraft:red_terracotta"},
        {pos: [2, 3, 5], state: "minecraft:cut_red_sandstone"},
        {pos: [2, 3, 6], state: "minecraft:cut_red_sandstone"},
        {pos: [2, 3, 7], state: "minecraft:red_sand"},
        {pos: [2, 3, 10], state: "minecraft:red_sand"},
        {pos: [2, 3, 11], state: "minecraft:red_sand"},
        {pos: [2, 3, 12], state: "minecraft:red_sand"},
        {pos: [2, 3, 13], state: "minecraft:red_sand"},
        {pos: [2, 3, 14], state: "minecraft:red_sand"},
        {pos: [3, 3, 0], state: "minecraft:red_sand"},
        {pos: [3, 3, 1], state: "minecraft:red_sand"},
        {pos: [3, 3, 2], state: "minecraft:cut_red_sandstone"},
        {pos: [3, 3, 3], state: "minecraft:red_terracotta"},
        {pos: [3, 3, 4], state: "minecraft:red_terracotta"},
        {pos: [3, 3, 5], state: "minecraft:red_terracotta"},
        {pos: [3, 3, 6], state: "minecraft:cut_red_sandstone"},
        {pos: [3, 3, 7], state: "minecraft:red_sand"},
        {pos: [3, 3, 10], state: "minecraft:red_sand"},
        {pos: [3, 3, 11], state: "minecraft:red_sand"},
        {pos: [3, 3, 12], state: "minecraft:red_sand"},
        {pos: [3, 3, 13], state: "minecraft:cut_red_sandstone"},
        {pos: [3, 3, 14], state: "minecraft:cut_red_sandstone"},
        {pos: [4, 3, 0], state: "minecraft:red_sand"},
        {pos: [4, 3, 1], state: "minecraft:red_sand"},
        {pos: [4, 3, 2], state: "minecraft:cut_red_sandstone"},
        {pos: [4, 3, 3], state: "minecraft:red_terracotta"},
        {pos: [4, 3, 4], state: "minecraft:red_terracotta"},
        {pos: [4, 3, 5], state: "minecraft:red_terracotta"},
        {pos: [4, 3, 6], state: "minecraft:red_terracotta"},
        {pos: [4, 3, 7], state: "minecraft:red_sand"},
        {pos: [4, 3, 8], state: "minecraft:red_sand"},
        {pos: [4, 3, 10], state: "minecraft:red_sand"},
        {pos: [4, 3, 11], state: "minecraft:red_sand"},
        {pos: [4, 3, 12], state: "minecraft:red_sand"},
        {pos: [4, 3, 13], state: "minecraft:red_sand"},
        {pos: [4, 3, 14], state: "minecraft:cut_red_sandstone"},
        {pos: [5, 3, 1], state: "minecraft:red_sand"},
        {pos: [5, 3, 2], state: "minecraft:red_sand"},
        {pos: [5, 3, 3], state: "minecraft:red_sand"},
        {pos: [5, 3, 4], state: "minecraft:red_sand"},
        {pos: [5, 3, 5], state: "minecraft:red_sand"},
        {pos: [5, 3, 6], state: "minecraft:red_sand"},
        {pos: [5, 3, 7], state: "minecraft:red_sand"},
        {pos: [5, 3, 8], state: "minecraft:red_sand"},
        {pos: [5, 3, 9], state: "minecraft:red_sand"},
        {pos: [5, 3, 10], state: "minecraft:red_sand"},
        {pos: [5, 3, 11], state: "minecraft:red_sand"},
        {pos: [5, 3, 12], state: "minecraft:red_sand"},
        {pos: [5, 3, 13], state: "minecraft:red_sand"},
        {pos: [5, 3, 14], state: "minecraft:red_sand"},
        {pos: [5, 3, 15], state: "minecraft:red_sand"},
        {pos: [6, 3, 1], state: "minecraft:red_sand"},
        {pos: [6, 3, 2], state: "minecraft:red_sand"},
        {pos: [6, 3, 3], state: "minecraft:red_sand"},
        {pos: [6, 3, 4], state: "minecraft:red_sand"},
        {pos: [6, 3, 5], state: "minecraft:red_sand"},
        {pos: [6, 3, 6], state: "minecraft:red_sand"},
        {pos: [6, 3, 7], state: "minecraft:red_sand"},
        {pos: [6, 3, 8], state: "minecraft:red_sand"},
        {pos: [6, 3, 11], state: "minecraft:cut_red_sandstone"},
        {pos: [6, 3, 12], state: "minecraft:red_sand"},
        {pos: [6, 3, 13], state: "minecraft:red_sand"},
        {pos: [6, 3, 14], state: "minecraft:red_sand"},
        {pos: [6, 3, 15], state: "minecraft:red_sand"},
        {pos: [7, 3, 2], state: "minecraft:red_sand"},
        {pos: [7, 3, 3], state: "minecraft:red_sand"},
        {pos: [7, 3, 4], state: "minecraft:red_terracotta"},
        {pos: [7, 3, 5], state: "minecraft:red_terracotta"},
        {pos: [7, 3, 6], state: "minecraft:red_sand"},
        {pos: [7, 3, 7], state: "minecraft:cut_red_sandstone"},
        {pos: [7, 3, 8], state: "minecraft:red_sand"},
        {pos: [7, 3, 12], state: "minecraft:red_sand"},
        {pos: [7, 3, 13], state: "minecraft:cut_red_sandstone"},
        {pos: [7, 3, 14], state: "minecraft:red_sand"},
        {pos: [7, 3, 15], state: "minecraft:red_sand"},
        {pos: [8, 3, 3], state: "minecraft:red_sand"},
        {pos: [8, 3, 4], state: "minecraft:red_terracotta"},
        {pos: [8, 3, 5], state: "minecraft:red_terracotta"},
        {pos: [8, 3, 6], state: "minecraft:red_terracotta"},
        {pos: [8, 3, 7], state: "minecraft:red_sand"},
        {pos: [8, 3, 12], state: "minecraft:red_sand"},
        {pos: [8, 3, 13], state: "minecraft:red_sand"},
        {pos: [8, 3, 14], state: "minecraft:red_sand"},
        {pos: [8, 3, 15], state: "minecraft:red_sand"},
        {pos: [9, 3, 3], state: "minecraft:red_sand"},
        {pos: [9, 3, 4], state: "minecraft:red_terracotta"},
        {pos: [9, 3, 5], state: "minecraft:red_terracotta"},
        {pos: [9, 3, 6], state: "minecraft:cut_red_sandstone"},
        {pos: [9, 3, 7], state: "minecraft:cut_red_sandstone"},
        {pos: [9, 3, 13], state: "minecraft:red_sand"},
        {pos: [10, 3, 3], state: "minecraft:red_sand"},
        {pos: [10, 3, 4], state: "minecraft:red_sand"},
        {pos: [10, 3, 5], state: "minecraft:red_sand"},
        {pos: [10, 3, 6], state: "minecraft:red_sand"},
        {pos: [11, 3, 5], state: "minecraft:red_sand"},
        {pos: [1, 4, 2], state: "minecraft:red_sand"},
        {pos: [1, 4, 3], state: "minecraft:red_sand"},
        {pos: [1, 4, 4], state: "minecraft:red_sand"},
        {pos: [1, 4, 5], state: "minecraft:red_sand"},
        {pos: [1, 4, 6], state: "minecraft:red_sand"},
        {pos: [1, 4, 12], state: "minecraft:red_sand"},
        {pos: [2, 4, 2], state: "minecraft:cut_red_sandstone"},
        {pos: [2, 4, 3], state: "minecraft:red_sand"},
        {pos: [2, 4, 4], state: "minecraft:red_sand"},
        {pos: [2, 4, 5], state: "minecraft:chiseled_red_sandstone"},
        {pos: [2, 4, 6], state: "minecraft:cut_red_sandstone"},
        {pos: [2, 4, 7], state: "minecraft:red_sand"},
        {pos: [2, 4, 12], state: "minecraft:red_sand"},
        {pos: [2, 4, 13], state: "minecraft:red_sand"},
        {pos: [2, 4, 14], state: "minecraft:red_sand"},
        {pos: [3, 4, 0], state: "minecraft:red_sand"},
        {pos: [3, 4, 1], state: "minecraft:red_sand"},
        {pos: [3, 4, 2], state: "minecraft:cut_red_sandstone"},
        {pos: [3, 4, 3], state: "minecraft:red_sand"},
        {pos: [3, 4, 4], state: "minecraft:red_sand"},
        {pos: [3, 4, 5], state: "minecraft:red_sand"},
        {pos: [3, 4, 6], state: "minecraft:cut_red_sandstone"},
        {pos: [3, 4, 7], state: "minecraft:red_sand"},
        {pos: [3, 4, 11], state: "minecraft:red_sand"},
        {pos: [3, 4, 12], state: "minecraft:red_sand"},
        {pos: [3, 4, 13], state: "minecraft:cut_red_sandstone"},
        {pos: [3, 4, 14], state: "minecraft:cut_red_sandstone"},
        {pos: [4, 4, 1], state: "minecraft:red_sand"},
        {pos: [4, 4, 2], state: "minecraft:cut_red_sandstone"},
        {pos: [4, 4, 3], state: "minecraft:red_sand"},
        {pos: [4, 4, 4], state: "minecraft:red_sand"},
        {pos: [4, 4, 5], state: "minecraft:red_sand"},
        {pos: [4, 4, 6], state: "minecraft:cut_red_sandstone"},
        {pos: [4, 4, 7], state: "minecraft:red_sand"},
        {pos: [4, 4, 8], state: "minecraft:red_sand"},
        {pos: [4, 4, 11], state: "minecraft:red_sand"},
        {pos: [4, 4, 12], state: "minecraft:red_sand"},
        {pos: [4, 4, 13], state: "minecraft:red_sand"},
        {pos: [4, 4, 14], state: "minecraft:cut_red_sandstone"},
        {pos: [5, 4, 1], state: "minecraft:red_sand"},
        {pos: [5, 4, 2], state: "minecraft:red_sand"},
        {pos: [5, 4, 3], state: "minecraft:red_sand"},
        {pos: [5, 4, 4], state: "minecraft:red_sand"},
        {pos: [5, 4, 5], state: "minecraft:red_sand"},
        {pos: [5, 4, 6], state: "minecraft:red_sand"},
        {pos: [5, 4, 7], state: "minecraft:red_sand"},
        {pos: [5, 4, 8], state: "minecraft:red_sand"},
        {pos: [5, 4, 9], state: "minecraft:red_sand"},
        {pos: [5, 4, 10], state: "minecraft:red_sand"},
        {pos: [5, 4, 11], state: "minecraft:red_sand"},
        {pos: [5, 4, 12], state: "minecraft:red_sand"},
        {pos: [5, 4, 13], state: "minecraft:red_sand"},
        {pos: [5, 4, 14], state: "minecraft:red_sand"},
        {pos: [5, 4, 15], state: "minecraft:red_sand"},
        {pos: [6, 4, 2], state: "minecraft:red_sand"},
        {pos: [6, 4, 3], state: "minecraft:red_sand"},
        {pos: [6, 4, 4], state: "minecraft:red_sand"},
        {pos: [6, 4, 5], state: "minecraft:red_sand"},
        {pos: [6, 4, 6], state: "minecraft:red_sand"},
        {pos: [6, 4, 7], state: "minecraft:red_sand"},
        {pos: [6, 4, 8], state: "minecraft:red_sand"},
        {pos: [6, 4, 11], state: "minecraft:cut_red_sandstone"},
        {pos: [6, 4, 12], state: "minecraft:red_sand"},
        {pos: [6, 4, 13], state: "minecraft:red_sand"},
        {pos: [6, 4, 14], state: "minecraft:red_sand"},
        {pos: [6, 4, 15], state: "minecraft:red_sand"},
        {pos: [7, 4, 2], state: "minecraft:cut_red_sandstone"},
        {pos: [7, 4, 3], state: "minecraft:red_sand"},
        {pos: [7, 4, 4], state: "minecraft:red_sand"},
        {pos: [7, 4, 5], state: "minecraft:red_sand"},
        {pos: [7, 4, 6], state: "minecraft:red_sand"},
        {pos: [7, 4, 7], state: "minecraft:cut_red_sandstone"},
        {pos: [7, 4, 11], state: "minecraft:cut_red_sandstone"},
        {pos: [7, 4, 12], state: "minecraft:red_sand"},
        {pos: [7, 4, 13], state: "minecraft:cut_red_sandstone"},
        {pos: [7, 4, 14], state: "minecraft:red_sand"},
        {pos: [8, 4, 2], state: "minecraft:cut_red_sandstone"},
        {pos: [8, 4, 3], state: "minecraft:red_sand"},
        {pos: [8, 4, 4], state: "minecraft:red_sand"},
        {pos: [8, 4, 5], state: "minecraft:red_sand"},
        {pos: [8, 4, 6], state: "minecraft:red_sand"},
        {pos: [8, 4, 7], state: "minecraft:cut_red_sandstone"},
        {pos: [8, 4, 12], state: "minecraft:red_sand"},
        {pos: [8, 4, 13], state: "minecraft:red_sand"},
        {pos: [9, 4, 3], state: "minecraft:red_sand"},
        {pos: [9, 4, 4], state: "minecraft:cut_red_sandstone"},
        {pos: [9, 4, 5], state: "minecraft:red_sand"},
        {pos: [9, 4, 6], state: "minecraft:cut_red_sandstone"},
        {pos: [9, 4, 7], state: "minecraft:cut_red_sandstone"},
        {pos: [10, 4, 4], state: "minecraft:red_sand"},
        {pos: [10, 4, 5], state: "minecraft:red_sand"},
        {pos: [10, 4, 6], state: "minecraft:red_sand"},
        {pos: [1, 5, 2], state: "minecraft:red_sand"},
        {pos: [1, 5, 3], state: "minecraft:red_sand"},
        {pos: [1, 5, 4], state: "minecraft:red_sand"},
        {pos: [1, 5, 5], state: "minecraft:red_sand"},
        {pos: [1, 5, 6], state: "minecraft:red_sand"},
        {pos: [2, 5, 2], state: "minecraft:red_sand"},
        {pos: [2, 5, 3], state: "minecraft:red_sand"},
        {pos: [2, 5, 4], state: "minecraft:red_sand"},
        {pos: [2, 5, 5], state: "minecraft:red_sand"},
        {pos: [2, 5, 6], state: "minecraft:red_sand"},
        {pos: [2, 5, 12], state: "minecraft:red_sand"},
        {pos: [2, 5, 13], state: "minecraft:red_sand"},
        {pos: [3, 5, 1], state: "minecraft:red_sand"},
        {pos: [3, 5, 2], state: "minecraft:red_sand"},
        {pos: [3, 5, 3], state: "minecraft:red_sand"},
        {pos: [3, 5, 4], state: "minecraft:red_sand"},
        {pos: [3, 5, 5], state: "minecraft:red_sand"},
        {pos: [3, 5, 6], state: "minecraft:cut_red_sandstone"},
        {pos: [3, 5, 7], state: "minecraft:red_sand"},
        {pos: [3, 5, 11], state: "minecraft:red_sand"},
        {pos: [3, 5, 12], state: "minecraft:red_sand"},
        {pos: [3, 5, 13], state: "minecraft:chiseled_red_sandstone"},
        {pos: [3, 5, 14], state: "minecraft:red_sand"},
        {pos: [4, 5, 1], state: "minecraft:red_sand"},
        {pos: [4, 5, 2], state: "minecraft:chiseled_red_sandstone"},
        {pos: [4, 5, 3], state: "minecraft:red_sand"},
        {pos: [4, 5, 4], state: "minecraft:red_sand"},
        {pos: [4, 5, 5], state: "minecraft:red_sand"},
        {pos: [4, 5, 6], state: "minecraft:cut_red_sandstone"},
        {pos: [4, 5, 7], state: "minecraft:cut_red_sandstone"},
        {pos: [4, 5, 8], state: "minecraft:red_sand"},
        {pos: [4, 5, 11], state: "minecraft:red_sand"},
        {pos: [4, 5, 12], state: "minecraft:cut_red_sandstone"},
        {pos: [4, 5, 13], state: "minecraft:cut_red_sandstone"},
        {pos: [4, 5, 14], state: "minecraft:cut_red_sandstone"},
        {pos: [5, 5, 2], state: "minecraft:cut_red_sandstone"},
        {pos: [5, 5, 3], state: "minecraft:red_sand"},
        {pos: [5, 5, 4], state: "minecraft:red_sand"},
        {pos: [5, 5, 5], state: "minecraft:red_sand"},
        {pos: [5, 5, 6], state: "minecraft:red_sand"},
        {pos: [5, 5, 7], state: "minecraft:cut_red_sandstone"},
        {pos: [5, 5, 8], state: "minecraft:red_sand"},
        {pos: [5, 5, 11], state: "minecraft:red_sand"},
        {pos: [5, 5, 12], state: "minecraft:cut_red_sandstone"},
        {pos: [5, 5, 13], state: "minecraft:cut_red_sandstone"},
        {pos: [5, 5, 14], state: "minecraft:red_sand"},
        {pos: [6, 5, 2], state: "minecraft:cut_red_sandstone"},
        {pos: [6, 5, 3], state: "minecraft:red_sand"},
        {pos: [6, 5, 4], state: "minecraft:red_sand"},
        {pos: [6, 5, 5], state: "minecraft:red_sand"},
        {pos: [6, 5, 6], state: "minecraft:red_sand"},
        {pos: [6, 5, 7], state: "minecraft:chiseled_red_sandstone"},
        {pos: [6, 5, 8], state: "minecraft:red_sand"},
        {pos: [6, 5, 11], state: "minecraft:cut_red_sandstone"},
        {pos: [6, 5, 12], state: "minecraft:cut_red_sandstone"},
        {pos: [6, 5, 13], state: "minecraft:red_sand"},
        {pos: [7, 5, 2], state: "minecraft:cut_red_sandstone"},
        {pos: [7, 5, 3], state: "minecraft:cut_red_sandstone"},
        {pos: [7, 5, 4], state: "minecraft:red_sand"},
        {pos: [7, 5, 5], state: "minecraft:red_sand"},
        {pos: [7, 5, 6], state: "minecraft:red_sand"},
        {pos: [7, 5, 7], state: "minecraft:cut_red_sandstone"},
        {pos: [7, 5, 11], state: "minecraft:cut_red_sandstone"},
        {pos: [7, 5, 12], state: "minecraft:cut_red_sandstone"},
        {pos: [7, 5, 13], state: "minecraft:cut_red_sandstone"},
        {pos: [8, 5, 2], state: "minecraft:cut_red_sandstone"},
        {pos: [8, 5, 3], state: "minecraft:cut_red_sandstone"},
        {pos: [8, 5, 4], state: "minecraft:cut_red_sandstone"},
        {pos: [8, 5, 5], state: "minecraft:red_sand"},
        {pos: [8, 5, 6], state: "minecraft:red_sand"},
        {pos: [8, 5, 7], state: "minecraft:red_sand"},
        {pos: [9, 5, 4], state: "minecraft:cut_red_sandstone"},
        {pos: [9, 5, 5], state: "minecraft:cut_red_sandstone"},
        {pos: [9, 5, 6], state: "minecraft:cut_red_sandstone"},
        {pos: [9, 5, 7], state: "minecraft:red_sand"},
        {pos: [10, 5, 5], state: "minecraft:red_sand"},
        {pos: [10, 5, 6], state: "minecraft:red_sand"},
        {pos: [1, 6, 5], state: "minecraft:red_sand"},
        {pos: [2, 6, 3], state: "minecraft:red_sand"},
        {pos: [2, 6, 4], state: "minecraft:red_sand"},
        {pos: [2, 6, 5], state: "minecraft:red_sand"},
        {pos: [2, 6, 6], state: "minecraft:red_sand"},
        {pos: [3, 6, 2], state: "minecraft:red_sand"},
        {pos: [3, 6, 3], state: "minecraft:red_sand"},
        {pos: [3, 6, 4], state: "minecraft:red_sand"},
        {pos: [3, 6, 5], state: "minecraft:red_sand"},
        {pos: [3, 6, 6], state: "minecraft:cut_red_sandstone"},
        {pos: [3, 6, 7], state: "minecraft:red_sand"},
        {pos: [3, 6, 12], state: "minecraft:red_sand"},
        {pos: [3, 6, 13], state: "minecraft:red_sand"},
        {pos: [4, 6, 2], state: "minecraft:red_sand"},
        {pos: [4, 6, 3], state: "minecraft:red_sand"},
        {pos: [4, 6, 4], state: "minecraft:red_sand"},
        {pos: [4, 6, 5], state: "minecraft:red_sand"},
        {pos: [4, 6, 6], state: "minecraft:cut_red_sandstone"},
        {pos: [4, 6, 7], state: "minecraft:cut_red_sandstone"},
        {pos: [4, 6, 12], state: "minecraft:red_sand"},
        {pos: [4, 6, 13], state: "minecraft:cut_red_sandstone"},
        {pos: [5, 6, 2], state: "minecraft:red_sand"},
        {pos: [5, 6, 3], state: "minecraft:red_sand"},
        {pos: [5, 6, 4], state: "minecraft:red_sand"},
        {pos: [5, 6, 5], state: "minecraft:red_sand"},
        {pos: [5, 6, 6], state: "minecraft:red_sand"},
        {pos: [5, 6, 7], state: "minecraft:cut_red_sandstone"},
        {pos: [5, 6, 12], state: "minecraft:red_sand"},
        {pos: [5, 6, 13], state: "minecraft:red_sand"},
        {pos: [6, 6, 2], state: "minecraft:red_sand"},
        {pos: [6, 6, 3], state: "minecraft:red_sand"},
        {pos: [6, 6, 4], state: "minecraft:red_sand"},
        {pos: [6, 6, 5], state: "minecraft:red_sand"},
        {pos: [6, 6, 6], state: "minecraft:red_sand"},
        {pos: [6, 6, 7], state: "minecraft:cut_red_sandstone"},
        {pos: [6, 6, 12], state: "minecraft:red_sand"},
        {pos: [6, 6, 13], state: "minecraft:red_sand"},
        {pos: [7, 6, 2], state: "minecraft:red_sand"},
        {pos: [7, 6, 3], state: "minecraft:red_sand"},
        {pos: [7, 6, 4], state: "minecraft:red_sand"},
        {pos: [7, 6, 5], state: "minecraft:red_sand"},
        {pos: [7, 6, 6], state: "minecraft:red_sand"},
        {pos: [7, 6, 7], state: "minecraft:red_sand"},
        {pos: [8, 6, 2], state: "minecraft:red_sand"},
        {pos: [8, 6, 3], state: "minecraft:cut_red_sandstone"},
        {pos: [8, 6, 4], state: "minecraft:cut_red_sandstone"},
        {pos: [8, 6, 5], state: "minecraft:red_sand"},
        {pos: [8, 6, 6], state: "minecraft:red_sand"},
        {pos: [8, 6, 7], state: "minecraft:red_sand"},
        {pos: [9, 6, 4], state: "minecraft:cut_red_sandstone"},
        {pos: [9, 6, 5], state: "minecraft:cut_red_sandstone"},
        {pos: [9, 6, 6], state: "minecraft:red_sand"},
        {pos: [3, 7, 5], state: "minecraft:red_sand"},
        {pos: [3, 7, 6], state: "minecraft:red_sand"},
        {pos: [3, 7, 7], state: "minecraft:red_sand"},
        {pos: [4, 7, 4], state: "minecraft:red_sand"},
        {pos: [4, 7, 5], state: "minecraft:red_sand"},
        {pos: [4, 7, 6], state: "minecraft:cut_red_sandstone"},
        {pos: [4, 7, 7], state: "minecraft:cut_red_sandstone"},
        {pos: [5, 7, 2], state: "minecraft:red_sand"},
        {pos: [5, 7, 3], state: "minecraft:red_sand"},
        {pos: [5, 7, 4], state: "minecraft:red_sand"},
        {pos: [5, 7, 5], state: "minecraft:red_sand"},
        {pos: [5, 7, 6], state: "minecraft:red_sand"},
        {pos: [5, 7, 7], state: "minecraft:cut_red_sandstone"},
        {pos: [6, 7, 2], state: "minecraft:red_sand"},
        {pos: [6, 7, 3], state: "minecraft:red_sand"},
        {pos: [6, 7, 4], state: "minecraft:red_sand"},
        {pos: [6, 7, 5], state: "minecraft:red_sand"},
        {pos: [6, 7, 6], state: "minecraft:red_sand"},
        {pos: [7, 7, 2], state: "minecraft:red_sand"},
        {pos: [7, 7, 3], state: "minecraft:red_sand"},
        {pos: [7, 7, 4], state: "minecraft:red_sand"},
        {pos: [7, 7, 5], state: "minecraft:red_sand"},
        {pos: [8, 7, 2], state: "minecraft:red_sand"},
        {pos: [8, 7, 3], state: "minecraft:cut_red_sandstone"},
        {pos: [8, 7, 4], state: "minecraft:cut_red_sandstone"},
        {pos: [8, 7, 5], state: "minecraft:red_sand"},
        {pos: [8, 7, 6], state: "minecraft:red_sand"},
        {pos: [9, 7, 4], state: "minecraft:cut_red_sandstone"},
        {pos: [9, 7, 5], state: "minecraft:cut_red_sandstone"},
        {pos: [4, 8, 6], state: "minecraft:red_sandstone_wall{east:none,north:none,south:none,up:true,waterlogged:false,west:none}"},
        {pos: [5, 8, 7], state: "minecraft:red_sandstone_wall{east:none,north:none,south:none,up:true,waterlogged:false,west:none}"},
        {pos: [8, 8, 3], state: "minecraft:red_sandstone_wall{east:none,north:none,south:none,up:true,waterlogged:false,west:none}"},
        {pos: [9, 8, 4], state: "minecraft:red_sandstone_wall{east:none,north:none,south:low,up:true,waterlogged:false,west:none}"},
        {pos: [9, 8, 5], state: "minecraft:red_sandstone_wall{east:none,north:low,south:none,up:true,waterlogged:false,west:none}"}
    ],
    entities: [],
    palette: [
        "minecraft:cut_red_sandstone",
        "minecraft:red_terracotta",
        "minecraft:red_sand",
        "minecraft:chiseled_red_sandstone",
        "minecraft:red_sandstone_stairs{facing:west,half:top,shape:straight,waterlogged:false}",
        "minecraft:red_sandstone_stairs{facing:north,half:top,shape:straight,waterlogged:false}",
        "minecraft:red_sandstone_wall{east:none,north:none,south:none,up:true,waterlogged:false,west:none}",
        "minecraft:red_sandstone_wall{east:none,north:none,south:low,up:true,waterlogged:false,west:none}",
        "minecraft:red_sandstone_wall{east:none,north:low,south:none,up:true,waterlogged:false,west:none}"
    ],
    trailiertales_DataVersion: 2
}
