{
    DataVersion: 3953,
    size: [12, 6, 18],
    data: [
        {pos: [0, 0, 12], state: "minecraft:cut_red_sandstone"},
        {pos: [0, 0, 13], state: "minecraft:cut_red_sandstone"},
        {pos: [0, 0, 14], state: "minecraft:cut_red_sandstone"},
        {pos: [1, 0, 4], state: "minecraft:cut_red_sandstone"},
        {pos: [1, 0, 5], state: "minecraft:cut_red_sandstone"},
        {pos: [1, 0, 11], state: "minecraft:cut_red_sandstone"},
        {pos: [1, 0, 12], state: "minecraft:cut_red_sandstone"},
        {pos: [1, 0, 13], state: "minecraft:cut_red_sandstone"},
        {pos: [1, 0, 14], state: "minecraft:cut_red_sandstone"},
        {pos: [2, 0, 3], state: "minecraft:cut_red_sandstone"},
        {pos: [2, 0, 4], state: "minecraft:cut_red_sandstone"},
        {pos: [2, 0, 5], state: "minecraft:cut_red_sandstone"},
        {pos: [2, 0, 6], state: "minecraft:cut_red_sandstone"},
        {pos: [2, 0, 11], state: "minecraft:cut_red_sandstone"},
        {pos: [2, 0, 12], state: "minecraft:red_terracotta"},
        {pos: [2, 0, 13], state: "minecraft:red_terracotta"},
        {pos: [2, 0, 14], state: "minecraft:cut_red_sandstone"},
        {pos: [2, 0, 15], state: "minecraft:red_terracotta"},
        {pos: [2, 0, 16], state: "minecraft:red_terracotta"},
        {pos: [2, 0, 17], state: "minecraft:red_terracotta"},
        {pos: [3, 0, 2], state: "minecraft:cut_red_sandstone"},
        {pos: [3, 0, 3], state: "minecraft:cut_red_sandstone"},
        {pos: [3, 0, 4], state: "minecraft:terracotta"},
        {pos: [3, 0, 5], state: "minecraft:terracotta"},
        {pos: [3, 0, 6], state: "minecraft:terracotta"},
        {pos: [3, 0, 7], state: "minecraft:cut_red_sandstone"},
        {pos: [3, 0, 12], state: "minecraft:red_terracotta"},
        {pos: [3, 0, 13], state: "minecraft:cut_red_sandstone"},
        {pos: [3, 0, 14], state: "minecraft:cut_red_sandstone"},
        {pos: [3, 0, 15], state: "minecraft:cut_red_sandstone"},
        {pos: [3, 0, 16], state: "minecraft:cut_red_sandstone"},
        {pos: [3, 0, 17], state: "minecraft:red_terracotta"},
        {pos: [4, 0, 2], state: "minecraft:terracotta"},
        {pos: [4, 0, 3], state: "minecraft:cut_red_sandstone"},
        {pos: [4, 0, 4], state: "minecraft:yellow_glazed_terracotta{facing:west}"},
        {pos: [4, 0, 5], state: "minecraft:yellow_glazed_terracotta{facing:west}"},
        {pos: [4, 0, 6], state: "minecraft:terracotta"},
        {pos: [4, 0, 7], state: "minecraft:cut_red_sandstone"},
        {pos: [4, 0, 9], state: "minecraft:cut_red_sandstone"},
        {pos: [4, 0, 10], state: "minecraft:cut_red_sandstone"},
        {pos: [4, 0, 11], state: "minecraft:cut_red_sandstone"},
        {pos: [4, 0, 12], state: "minecraft:red_terracotta"},
        {pos: [4, 0, 13], state: "minecraft:cut_red_sandstone"},
        {pos: [4, 0, 14], state: "minecraft:orange_glazed_terracotta{facing:west}"},
        {pos: [4, 0, 15], state: "minecraft:cut_red_sandstone"},
        {pos: [4, 0, 16], state: "minecraft:cut_red_sandstone"},
        {pos: [4, 0, 17], state: "minecraft:red_terracotta"},
        {pos: [5, 0, 2], state: "minecraft:terracotta"},
        {pos: [5, 0, 3], state: "minecraft:cut_red_sandstone"},
        {pos: [5, 0, 4], state: "minecraft:cut_red_sandstone"},
        {pos: [5, 0, 5], state: "minecraft:yellow_glazed_terracotta{facing:south}"},
        {pos: [5, 0, 6], state: "minecraft:cut_red_sandstone"},
        {pos: [5, 0, 7], state: "minecraft:cut_red_sandstone"},
        {pos: [5, 0, 8], state: "minecraft:cut_red_sandstone"},
        {pos: [5, 0, 9], state: "minecraft:cut_red_sandstone"},
        {pos: [5, 0, 10], state: "minecraft:cut_red_sandstone"},
        {pos: [5, 0, 11], state: "minecraft:cut_red_sandstone"},
        {pos: [5, 0, 12], state: "minecraft:cut_red_sandstone"},
        {pos: [5, 0, 13], state: "minecraft:orange_glazed_terracotta{facing:east}"},
        {pos: [5, 0, 14], state: "minecraft:orange_glazed_terracotta{facing:south}"},
        {pos: [5, 0, 15], state: "minecraft:cut_red_sandstone"},
        {pos: [5, 0, 16], state: "minecraft:red_terracotta"},
        {pos: [5, 0, 17], state: "minecraft:red_terracotta"},
        {pos: [6, 0, 1], state: "minecraft:cut_red_sandstone"},
        {pos: [6, 0, 2], state: "minecraft:terracotta"},
        {pos: [6, 0, 3], state: "minecraft:cut_red_sandstone"},
        {pos: [6, 0, 4], state: "minecraft:cut_red_sandstone"},
        {pos: [6, 0, 5], state: "minecraft:cut_red_sandstone"},
        {pos: [6, 0, 6], state: "minecraft:terracotta"},
        {pos: [6, 0, 7], state: "minecraft:cut_red_sandstone"},
        {pos: [6, 0, 8], state: "minecraft:cut_red_sandstone"},
        {pos: [6, 0, 9], state: "minecraft:cut_red_sandstone"},
        {pos: [6, 0, 10], state: "minecraft:cut_red_sandstone"},
        {pos: [6, 0, 11], state: "minecraft:cut_red_sandstone"},
        {pos: [6, 0, 12], state: "minecraft:red_terracotta"},
        {pos: [6, 0, 13], state: "minecraft:cut_red_sandstone"},
        {pos: [6, 0, 14], state: "minecraft:cut_red_sandstone"},
        {pos: [6, 0, 15], state: "minecraft:cut_red_sandstone"},
        {pos: [6, 0, 16], state: "minecraft:red_terracotta"},
        {pos: [6, 0, 17], state: "minecraft:red_terracotta"},
        {pos: [7, 0, 1], state: "minecraft:cut_red_sandstone"},
        {pos: [7, 0, 2], state: "minecraft:terracotta"},
        {pos: [7, 0, 3], state: "minecraft:cut_red_sandstone"},
        {pos: [7, 0, 4], state: "minecraft:cut_red_sandstone"},
        {pos: [7, 0, 5], state: "minecraft:cut_red_sandstone"},
        {pos: [7, 0, 6], state: "minecraft:terracotta"},
        {pos: [7, 0, 7], state: "minecraft:cut_red_sandstone"},
        {pos: [7, 0, 8], state: "minecraft:cut_red_sandstone"},
        {pos: [7, 0, 11], state: "minecraft:cut_red_sandstone"},
        {pos: [7, 0, 12], state: "minecraft:red_terracotta"},
        {pos: [7, 0, 13], state: "minecraft:cut_red_sandstone"},
        {pos: [7, 0, 14], state: "minecraft:cut_red_sandstone"},
        {pos: [7, 0, 15], state: "minecraft:cut_red_sandstone"},
        {pos: [7, 0, 16], state: "minecraft:red_terracotta"},
        {pos: [7, 0, 17], state: "minecraft:red_terracotta"},
        {pos: [8, 0, 0], state: "minecraft:cut_red_sandstone"},
        {pos: [8, 0, 1], state: "minecraft:cut_red_sandstone"},
        {pos: [8, 0, 2], state: "minecraft:terracotta"},
        {pos: [8, 0, 3], state: "minecraft:cut_red_sandstone"},
        {pos: [8, 0, 4], state: "minecraft:cut_red_sandstone"},
        {pos: [8, 0, 5], state: "minecraft:cut_red_sandstone"},
        {pos: [8, 0, 6], state: "minecraft:terracotta"},
        {pos: [8, 0, 7], state: "minecraft:cut_red_sandstone"},
        {pos: [8, 0, 10], state: "minecraft:cut_red_sandstone"},
        {pos: [8, 0, 11], state: "minecraft:cut_red_sandstone"},
        {pos: [8, 0, 12], state: "minecraft:red_terracotta"},
        {pos: [8, 0, 13], state: "minecraft:red_terracotta"},
        {pos: [8, 0, 14], state: "minecraft:cut_red_sandstone"},
        {pos: [8, 0, 15], state: "minecraft:cut_red_sandstone"},
        {pos: [8, 0, 16], state: "minecraft:red_terracotta"},
        {pos: [8, 0, 17], state: "minecraft:red_terracotta"},
        {pos: [9, 0, 0], state: "minecraft:cut_red_sandstone"},
        {pos: [9, 0, 1], state: "minecraft:cut_red_sandstone"},
        {pos: [9, 0, 2], state: "minecraft:terracotta"},
        {pos: [9, 0, 3], state: "minecraft:terracotta"},
        {pos: [9, 0, 4], state: "minecraft:terracotta"},
        {pos: [9, 0, 5], state: "minecraft:terracotta"},
        {pos: [9, 0, 6], state: "minecraft:terracotta"},
        {pos: [9, 0, 10], state: "minecraft:cut_red_sandstone"},
        {pos: [9, 0, 11], state: "minecraft:cut_red_sandstone"},
        {pos: [9, 0, 12], state: "minecraft:cut_red_sandstone"},
        {pos: [9, 0, 13], state: "minecraft:cut_red_sandstone"},
        {pos: [10, 0, 1], state: "minecraft:cut_red_sandstone"},
        {pos: [10, 0, 2], state: "minecraft:cut_red_sandstone"},
        {pos: [10, 0, 3], state: "minecraft:cut_red_sandstone"},
        {pos: [10, 0, 4], state: "minecraft:cut_red_sandstone"},
        {pos: [10, 0, 5], state: "minecraft:cut_red_sandstone"},
        {pos: [10, 0, 11], state: "minecraft:cut_red_sandstone"},
        {pos: [10, 0, 12], state: "minecraft:cut_red_sandstone"},
        {pos: [11, 0, 2], state: "minecraft:cut_red_sandstone"},
        {pos: [11, 0, 3], state: "minecraft:cut_red_sandstone"},
        {pos: [11, 0, 4], state: "minecraft:cut_red_sandstone"},
        {pos: [0, 1, 12], state: "minecraft:red_sand"},
        {pos: [0, 1, 13], state: "minecraft:red_sand"},
        {pos: [0, 1, 14], state: "minecraft:red_sand"},
        {pos: [1, 1, 4], state: "minecraft:red_sand"},
        {pos: [1, 1, 5], state: "minecraft:red_sand"},
        {pos: [1, 1, 11], state: "minecraft:red_sand"},
        {pos: [1, 1, 12], state: "minecraft:red_sand"},
        {pos: [1, 1, 13], state: "minecraft:red_sand"},
        {pos: [1, 1, 14], state: "minecraft:red_sand"},
        {pos: [2, 1, 3], state: "minecraft:red_sand"},
        {pos: [2, 1, 4], state: "minecraft:red_sand"},
        {pos: [2, 1, 5], state: "minecraft:red_sand"},
        {pos: [2, 1, 6], state: "minecraft:red_sand"},
        {pos: [2, 1, 11], state: "minecraft:red_sand"},
        {pos: [2, 1, 12], state: "minecraft:red_terracotta"},
        {pos: [2, 1, 13], state: "minecraft:red_terracotta"},
        {pos: [2, 1, 14], state: "minecraft:red_sand"},
        {pos: [2, 1, 15], state: "minecraft:red_terracotta"},
        {pos: [2, 1, 16], state: "minecraft:red_terracotta"},
        {pos: [2, 1, 17], state: "minecraft:red_terracotta"},
        {pos: [3, 1, 2], state: "minecraft:red_sand"},
        {pos: [3, 1, 3], state: "minecraft:red_sand"},
        {pos: [3, 1, 4], state: "minecraft:terracotta"},
        {pos: [3, 1, 5], state: "minecraft:terracotta"},
        {pos: [3, 1, 6], state: "minecraft:terracotta"},
        {pos: [3, 1, 7], state: "minecraft:red_sand"},
        {pos: [3, 1, 12], state: "minecraft:red_terracotta"},
        {pos: [3, 1, 13], state: "minecraft:red_sand"},
        {pos: [3, 1, 14], state: "minecraft:red_sand"},
        {pos: [3, 1, 15], state: "minecraft:red_sand"},
        {pos: [3, 1, 16], state: "minecraft:red_sand"},
        {pos: [3, 1, 17], state: "minecraft:red_terracotta"},
        {pos: [4, 1, 2], state: "minecraft:terracotta"},
        {pos: [4, 1, 3], state: "minecraft:red_sand"},
        {pos: [4, 1, 4], state: "minecraft:red_sand"},
        {pos: [4, 1, 5], state: "minecraft:red_sand"},
        {pos: [4, 1, 6], state: "minecraft:terracotta"},
        {pos: [4, 1, 7], state: "minecraft:red_sand"},
        {pos: [4, 1, 9], state: "minecraft:red_sand"},
        {pos: [4, 1, 10], state: "minecraft:red_sand"},
        {pos: [4, 1, 11], state: "minecraft:red_sand"},
        {pos: [4, 1, 12], state: "minecraft:red_terracotta"},
        {pos: [4, 1, 13], state: "minecraft:red_sand"},
        {pos: [4, 1, 14], state: "minecraft:red_sand"},
        {pos: [4, 1, 15], state: "minecraft:red_sand"},
        {pos: [4, 1, 16], state: "minecraft:red_sand"},
        {pos: [4, 1, 17], state: "minecraft:red_terracotta"},
        {pos: [5, 1, 2], state: "minecraft:terracotta"},
        {pos: [5, 1, 3], state: "minecraft:red_sand"},
        {pos: [5, 1, 4], state: "minecraft:red_sand"},
        {pos: [5, 1, 5], state: "minecraft:red_sand"},
        {pos: [5, 1, 6], state: "minecraft:red_sand"},
        {pos: [5, 1, 7], state: "minecraft:red_sand"},
        {pos: [5, 1, 8], state: "minecraft:red_sand"},
        {pos: [5, 1, 9], state: "minecraft:red_sand"},
        {pos: [5, 1, 10], state: "minecraft:red_sand"},
        {pos: [5, 1, 11], state: "minecraft:red_sand"},
        {pos: [5, 1, 12], state: "minecraft:red_sand"},
        {pos: [5, 1, 13], state: "minecraft:red_sand"},
        {pos: [5, 1, 14], state: "minecraft:red_sand"},
        {pos: [5, 1, 15], state: "minecraft:red_sand"},
        {pos: [5, 1, 16], state: "minecraft:red_terracotta"},
        {pos: [5, 1, 17], state: "minecraft:red_terracotta"},
        {pos: [6, 1, 1], state: "minecraft:red_sand"},
        {pos: [6, 1, 2], state: "minecraft:terracotta"},
        {pos: [6, 1, 3], state: "minecraft:red_sand"},
        {pos: [6, 1, 4], state: "minecraft:red_sand"},
        {pos: [6, 1, 5], state: "minecraft:red_sand"},
        {pos: [6, 1, 6], state: "minecraft:terracotta"},
        {pos: [6, 1, 7], state: "minecraft:red_sand"},
        {pos: [6, 1, 8], state: "minecraft:red_sand"},
        {pos: [6, 1, 9], state: "minecraft:red_sand"},
        {pos: [6, 1, 10], state: "minecraft:red_sand"},
        {pos: [6, 1, 11], state: "minecraft:red_sand"},
        {pos: [6, 1, 12], state: "minecraft:red_terracotta"},
        {pos: [6, 1, 13], state: "minecraft:red_sand"},
        {pos: [6, 1, 14], state: "minecraft:red_sand"},
        {pos: [6, 1, 15], state: "minecraft:red_sand"},
        {pos: [6, 1, 16], state: "minecraft:red_terracotta"},
        {pos: [6, 1, 17], state: "minecraft:red_terracotta"},
        {pos: [7, 1, 1], state: "minecraft:red_sand"},
        {pos: [7, 1, 2], state: "minecraft:terracotta"},
        {pos: [7, 1, 3], state: "minecraft:red_sand"},
        {pos: [7, 1, 4], state: "minecraft:red_sand"},
        {pos: [7, 1, 5], state: "minecraft:red_sandstone_stairs{facing:south,half:top,shape:straight,waterlogged:false}"},
        {pos: [7, 1, 6], state: "minecraft:terracotta"},
        {pos: [7, 1, 7], state: "minecraft:red_sand"},
        {pos: [7, 1, 8], state: "minecraft:red_sand"},
        {pos: [7, 1, 11], state: "minecraft:red_sand"},
        {pos: [7, 1, 12], state: "minecraft:red_terracotta"},
        {pos: [7, 1, 13], state: "minecraft:red_sand"},
        {pos: [7, 1, 14], state: "minecraft:red_sand"},
        {pos: [7, 1, 15], state: "minecraft:red_sand"},
        {pos: [7, 1, 16], state: "minecraft:red_terracotta"},
        {pos: [7, 1, 17], state: "minecraft:red_terracotta"},
        {pos: [8, 1, 0], state: "minecraft:red_sand"},
        {pos: [8, 1, 1], state: "minecraft:red_sand"},
        {pos: [8, 1, 2], state: "minecraft:terracotta"},
        {pos: [8, 1, 3], state: "minecraft:red_sand"},
        {pos: [8, 1, 4], state: "minecraft:red_sand"},
        {pos: [8, 1, 5], state: "minecraft:red_sandstone_stairs{facing:south,half:top,shape:straight,waterlogged:false}"},
        {pos: [8, 1, 6], state: "minecraft:terracotta"},
        {pos: [8, 1, 7], state: "minecraft:red_sand"},
        {pos: [8, 1, 10], state: "minecraft:red_sand"},
        {pos: [8, 1, 11], state: "minecraft:red_sand"},
        {pos: [8, 1, 12], state: "minecraft:red_terracotta"},
        {pos: [8, 1, 13], state: "minecraft:red_terracotta"},
        {pos: [8, 1, 14], state: "minecraft:red_sand"},
        {pos: [8, 1, 15], state: "minecraft:red_sand"},
        {pos: [8, 1, 16], state: "minecraft:red_terracotta"},
        {pos: [9, 1, 0], state: "minecraft:red_sand"},
        {pos: [9, 1, 1], state: "minecraft:red_sand"},
        {pos: [9, 1, 2], state: "minecraft:terracotta"},
        {pos: [9, 1, 3], state: "minecraft:terracotta"},
        {pos: [9, 1, 4], state: "minecraft:terracotta"},
        {pos: [9, 1, 5], state: "minecraft:terracotta"},
        {pos: [9, 1, 6], state: "minecraft:terracotta"},
        {pos: [9, 1, 10], state: "minecraft:red_sand"},
        {pos: [9, 1, 11], state: "minecraft:red_sand"},
        {pos: [9, 1, 12], state: "minecraft:red_sand"},
        {pos: [9, 1, 13], state: "minecraft:red_sand"},
        {pos: [10, 1, 1], state: "minecraft:red_sand"},
        {pos: [10, 1, 2], state: "minecraft:red_sand"},
        {pos: [10, 1, 3], state: "minecraft:red_sand"},
        {pos: [10, 1, 4], state: "minecraft:red_sand"},
        {pos: [10, 1, 5], state: "minecraft:red_sand"},
        {pos: [10, 1, 11], state: "minecraft:red_sand"},
        {pos: [10, 1, 12], state: "minecraft:red_sand"},
        {pos: [11, 1, 2], state: "minecraft:red_sand"},
        {pos: [11, 1, 3], state: "minecraft:red_sand"},
        {pos: [11, 1, 4], state: "minecraft:red_sand"},
        {pos: [0, 2, 12], state: "minecraft:red_sand"},
        {pos: [0, 2, 13], state: "minecraft:red_sand"},
        {pos: [0, 2, 14], state: "minecraft:red_sand"},
        {pos: [1, 2, 4], state: "minecraft:red_sand"},
        {pos: [1, 2, 5], state: "minecraft:red_sand"},
        {pos: [1, 2, 11], state: "minecraft:red_sand"},
        {pos: [1, 2, 12], state: "minecraft:red_sand"},
        {pos: [1, 2, 13], state: "minecraft:red_sand"},
        {pos: [1, 2, 14], state: "minecraft:red_sand"},
        {pos: [2, 2, 3], state: "minecraft:red_sand"},
        {pos: [2, 2, 4], state: "minecraft:red_sand"},
        {pos: [2, 2, 5], state: "minecraft:red_sand"},
        {pos: [2, 2, 6], state: "minecraft:red_sand"},
        {pos: [2, 2, 11], state: "minecraft:red_sand"},
        {pos: [2, 2, 12], state: "minecraft:red_terracotta"},
        {pos: [2, 2, 13], state: "minecraft:red_sand"},
        {pos: [2, 2, 14], state: "minecraft:red_sand"},
        {pos: [2, 2, 15], state: "minecraft:red_terracotta"},
        {pos: [2, 2, 16], state: "minecraft:red_sand"},
        {pos: [2, 2, 17], state: "minecraft:red_terracotta"},
        {pos: [3, 2, 2], state: "minecraft:red_sand"},
        {pos: [3, 2, 3], state: "minecraft:red_sand"},
        {pos: [3, 2, 4], state: "minecraft:red_sand"},
        {pos: [3, 2, 5], state: "minecraft:terracotta"},
        {pos: [3, 2, 6], state: "minecraft:terracotta"},
        {pos: [3, 2, 7], state: "minecraft:red_sand"},
        {pos: [3, 2, 12], state: "minecraft:red_terracotta"},
        {pos: [3, 2, 13], state: "minecraft:red_sand"},
        {pos: [3, 2, 14], state: "minecraft:red_sand"},
        {pos: [3, 2, 15], state: "minecraft:red_sand"},
        {pos: [3, 2, 16], state: "minecraft:red_sand"},
        {pos: [3, 2, 17], state: "minecraft:red_sand"},
        {pos: [4, 2, 2], state: "minecraft:terracotta"},
        {pos: [4, 2, 3], state: "minecraft:red_sand"},
        {pos: [4, 2, 4], state: "minecraft:red_sand"},
        {pos: [4, 2, 5], state: "minecraft:red_sand"},
        {pos: [4, 2, 6], state: "minecraft:terracotta"},
        {pos: [4, 2, 7], state: "minecraft:red_sand"},
        {pos: [4, 2, 9], state: "minecraft:red_sand"},
        {pos: [4, 2, 10], state: "minecraft:red_sand"},
        {pos: [4, 2, 11], state: "minecraft:red_sand"},
        {pos: [4, 2, 12], state: "minecraft:red_terracotta"},
        {pos: [4, 2, 13], state: "minecraft:red_sand"},
        {pos: [4, 2, 14], state: "minecraft:red_sand"},
        {pos: [4, 2, 15], state: "minecraft:red_sand"},
        {pos: [4, 2, 16], state: "minecraft:red_sand"},
        {pos: [4, 2, 17], state: "minecraft:red_terracotta"},
        {pos: [5, 2, 2], state: "minecraft:terracotta"},
        {pos: [5, 2, 3], state: "minecraft:red_sand"},
        {pos: [5, 2, 4], state: "minecraft:red_sand"},
        {pos: [5, 2, 5], state: "minecraft:red_sand"},
        {pos: [5, 2, 6], state: "minecraft:red_sand"},
        {pos: [5, 2, 7], state: "minecraft:red_sand"},
        {pos: [5, 2, 8], state: "minecraft:red_sand"},
        {pos: [5, 2, 9], state: "minecraft:red_sand"},
        {pos: [5, 2, 10], state: "minecraft:red_sand"},
        {pos: [5, 2, 11], state: "minecraft:red_sand"},
        {pos: [5, 2, 12], state: "minecraft:red_sand"},
        {pos: [5, 2, 13], state: "minecraft:red_sand"},
        {pos: [5, 2, 14], state: "minecraft:red_sand"},
        {pos: [5, 2, 15], state: "minecraft:red_sand"},
        {pos: [5, 2, 16], state: "minecraft:red_sand"},
        {pos: [5, 2, 17], state: "minecraft:red_terracotta"},
        {pos: [6, 2, 1], state: "minecraft:red_sand"},
        {pos: [6, 2, 2], state: "minecraft:terracotta"},
        {pos: [6, 2, 3], state: "minecraft:red_sand"},
        {pos: [6, 2, 4], state: "minecraft:red_sand"},
        {pos: [6, 2, 5], state: "minecraft:red_sand"},
        {pos: [6, 2, 6], state: "minecraft:terracotta"},
        {pos: [6, 2, 7], state: "minecraft:red_sand"},
        {pos: [6, 2, 8], state: "minecraft:red_sand"},
        {pos: [6, 2, 9], state: "minecraft:red_sand"},
        {pos: [6, 2, 10], state: "minecraft:red_sand"},
        {pos: [6, 2, 11], state: "minecraft:red_sand"},
        {pos: [6, 2, 12], state: "minecraft:red_terracotta"},
        {pos: [6, 2, 13], state: "minecraft:red_sand"},
        {pos: [6, 2, 14], state: "minecraft:red_sand"},
        {pos: [6, 2, 15], state: "minecraft:red_sand"},
        {pos: [6, 2, 16], state: "minecraft:red_sand"},
        {pos: [6, 2, 17], state: "minecraft:red_terracotta"},
        {pos: [7, 2, 1], state: "minecraft:red_sand"},
        {pos: [7, 2, 2], state: "minecraft:terracotta"},
        {pos: [7, 2, 3], state: "minecraft:red_sand"},
        {pos: [7, 2, 4], state: "minecraft:red_sand"},
        {pos: [7, 2, 5], state: "minecraft:red_sand"},
        {pos: [7, 2, 6], state: "minecraft:terracotta"},
        {pos: [7, 2, 7], state: "minecraft:red_sand"},
        {pos: [7, 2, 8], state: "minecraft:red_sand"},
        {pos: [7, 2, 11], state: "minecraft:red_sand"},
        {pos: [7, 2, 12], state: "minecraft:red_terracotta"},
        {pos: [7, 2, 13], state: "minecraft:red_sand"},
        {pos: [7, 2, 14], state: "minecraft:red_sand"},
        {pos: [7, 2, 15], state: "minecraft:red_sand"},
        {pos: [7, 2, 16], state: "minecraft:red_terracotta"},
        {pos: [8, 2, 0], state: "minecraft:red_sand"},
        {pos: [8, 2, 1], state: "minecraft:red_sand"},
        {pos: [8, 2, 2], state: "minecraft:terracotta"},
        {pos: [8, 2, 3], state: "minecraft:red_sand"},
        {pos: [8, 2, 4], state: "minecraft:red_sand"},
        {pos: [8, 2, 5], state: "minecraft:red_sand"},
        {pos: [8, 2, 6], state: "minecraft:terracotta"},
        {pos: [8, 2, 7], state: "minecraft:red_sand"},
        {pos: [8, 2, 11], state: "minecraft:red_sand"},
        {pos: [8, 2, 12], state: "minecraft:red_terracotta"},
        {pos: [8, 2, 13], state: "minecraft:red_sand"},
        {pos: [8, 2, 14], state: "minecraft:red_sand"},
        {pos: [8, 2, 15], state: "minecraft:red_sand"},
        {pos: [8, 2, 16], state: "minecraft:red_terracotta"},
        {pos: [9, 2, 0], state: "minecraft:red_sand"},
        {pos: [9, 2, 1], state: "minecraft:red_sand"},
        {pos: [9, 2, 2], state: "minecraft:terracotta"},
        {pos: [9, 2, 3], state: "minecraft:red_sand"},
        {pos: [9, 2, 4], state: "minecraft:red_sand"},
        {pos: [9, 2, 5], state: "minecraft:terracotta"},
        {pos: [9, 2, 6], state: "minecraft:red_sand"},
        {pos: [9, 2, 11], state: "minecraft:red_sand"},
        {pos: [9, 2, 12], state: "minecraft:red_sand"},
        {pos: [9, 2, 13], state: "minecraft:red_sand"},
        {pos: [10, 2, 1], state: "minecraft:red_sand"},
        {pos: [10, 2, 2], state: "minecraft:red_sand"},
        {pos: [10, 2, 3], state: "minecraft:red_sand"},
        {pos: [10, 2, 4], state: "minecraft:red_sand"},
        {pos: [10, 2, 5], state: "minecraft:red_sand"},
        {pos: [10, 2, 12], state: "minecraft:red_sand"},
        {pos: [11, 2, 2], state: "minecraft:red_sand"},
        {pos: [11, 2, 3], state: "minecraft:red_sand"},
        {pos: [11, 2, 4], state: "minecraft:red_sand"},
        {pos: [0, 3, 13], state: "minecraft:red_sand"},
        {pos: [1, 3, 4], state: "minecraft:red_sand"},
        {pos: [1, 3, 5], state: "minecraft:red_sand"},
        {pos: [1, 3, 12], state: "minecraft:red_sand"},
        {pos: [1, 3, 13], state: "minecraft:red_sand"},
        {pos: [1, 3, 14], state: "minecraft:red_sand"},
        {pos: [2, 3, 4], state: "minecraft:red_sand"},
        {pos: [2, 3, 5], state: "minecraft:red_sand"},
        {pos: [2, 3, 6], state: "minecraft:red_sand"},
        {pos: [2, 3, 11], state: "minecraft:red_sand"},
        {pos: [2, 3, 12], state: "minecraft:red_sand"},
        {pos: [2, 3, 13], state: "minecraft:red_sand"},
        {pos: [2, 3, 14], state: "minecraft:red_sand"},
        {pos: [2, 3, 15], state: "minecraft:red_terracotta"},
        {pos: [2, 3, 16], state: "minecraft:red_sand"},
        {pos: [2, 3, 17], state: "minecraft:red_sand"},
        {pos: [3, 3, 2], state: "minecraft:red_sand"},
        {pos: [3, 3, 3], state: "minecraft:red_sand"},
        {pos: [3, 3, 4], state: "minecraft:red_sand"},
        {pos: [3, 3, 5], state: "minecraft:red_sand"},
        {pos: [3, 3, 6], state: "minecraft:red_sandstone_wall{east:tall,north:tall,south:tall,up:false,waterlogged:false,west:tall}"},
        {pos: [3, 3, 7], state: "minecraft:red_sand"},
        {pos: [3, 3, 12], state: "minecraft:red_terracotta"},
        {pos: [3, 3, 13], state: "minecraft:red_sand"},
        {pos: [3, 3, 14], state: "minecraft:red_sand"},
        {pos: [3, 3, 15], state: "minecraft:red_sand"},
        {pos: [3, 3, 16], state: "minecraft:red_sand"},
        {pos: [3, 3, 17], state: "minecraft:red_sand"},
        {pos: [4, 3, 2], state: "minecraft:red_sand"},
        {pos: [4, 3, 3], state: "minecraft:red_sand"},
        {pos: [4, 3, 4], state: "minecraft:red_sand"},
        {pos: [4, 3, 5], state: "minecraft:red_sand"},
        {pos: [4, 3, 6], state: "minecraft:terracotta"},
        {pos: [4, 3, 7], state: "minecraft:red_sand"},
        {pos: [4, 3, 9], state: "minecraft:red_sand"},
        {pos: [4, 3, 10], state: "minecraft:red_sand"},
        {pos: [4, 3, 11], state: "minecraft:red_sand"},
        {pos: [4, 3, 12], state: "minecraft:cut_red_sandstone"},
        {pos: [4, 3, 13], state: "minecraft:red_sand"},
        {pos: [4, 3, 14], state: "minecraft:red_sand"},
        {pos: [4, 3, 15], state: "minecraft:red_sand"},
        {pos: [4, 3, 16], state: "minecraft:red_sand"},
        {pos: [4, 3, 17], state: "minecraft:cut_red_sandstone"},
        {pos: [5, 3, 2], state: "minecraft:red_sand"},
        {pos: [5, 3, 3], state: "minecraft:red_sand"},
        {pos: [5, 3, 4], state: "minecraft:red_sand"},
        {pos: [5, 3, 5], state: "minecraft:red_sand"},
        {pos: [5, 3, 6], state: "minecraft:terracotta"},
        {pos: [5, 3, 7], state: "minecraft:red_sand"},
        {pos: [5, 3, 8], state: "minecraft:red_sand"},
        {pos: [5, 3, 9], state: "minecraft:red_sand"},
        {pos: [5, 3, 10], state: "minecraft:red_sand"},
        {pos: [5, 3, 11], state: "minecraft:red_sand"},
        {pos: [5, 3, 12], state: "minecraft:cut_red_sandstone"},
        {pos: [5, 3, 13], state: "minecraft:red_sand"},
        {pos: [5, 3, 14], state: "minecraft:red_sand"},
        {pos: [5, 3, 15], state: "minecraft:red_sand"},
        {pos: [5, 3, 16], state: "minecraft:red_sand"},
        {pos: [5, 3, 17], state: "minecraft:red_terracotta"},
        {pos: [6, 3, 1], state: "minecraft:red_sand"},
        {pos: [6, 3, 2], state: "minecraft:terracotta"},
        {pos: [6, 3, 3], state: "minecraft:red_sand"},
        {pos: [6, 3, 4], state: "minecraft:red_sand"},
        {pos: [6, 3, 5], state: "minecraft:red_sand"},
        {pos: [6, 3, 6], state: "minecraft:cut_red_sandstone"},
        {pos: [6, 3, 7], state: "minecraft:red_sand"},
        {pos: [6, 3, 8], state: "minecraft:red_sand"},
        {pos: [6, 3, 9], state: "minecraft:red_sand"},
        {pos: [6, 3, 10], state: "minecraft:red_sand"},
        {pos: [6, 3, 11], state: "minecraft:red_sand"},
        {pos: [6, 3, 12], state: "minecraft:cut_red_sandstone"},
        {pos: [6, 3, 13], state: "minecraft:red_sand"},
        {pos: [6, 3, 14], state: "minecraft:red_sand"},
        {pos: [6, 3, 15], state: "minecraft:red_sand"},
        {pos: [6, 3, 16], state: "minecraft:red_sand"},
        {pos: [6, 3, 17], state: "minecraft:red_terracotta"},
        {pos: [7, 3, 1], state: "minecraft:red_sand"},
        {pos: [7, 3, 2], state: "minecraft:terracotta"},
        {pos: [7, 3, 3], state: "minecraft:red_sand"},
        {pos: [7, 3, 4], state: "minecraft:red_sand"},
        {pos: [7, 3, 5], state: "minecraft:red_sand"},
        {pos: [7, 3, 6], state: "minecraft:terracotta"},
        {pos: [7, 3, 7], state: "minecraft:red_sand"},
        {pos: [7, 3, 8], state: "minecraft:red_sand"},
        {pos: [7, 3, 11], state: "minecraft:red_sand"},
        {pos: [7, 3, 12], state: "minecraft:red_terracotta"},
        {pos: [7, 3, 13], state: "minecraft:red_sand"},
        {pos: [7, 3, 14], state: "minecraft:red_sand"},
        {pos: [7, 3, 15], state: "minecraft:red_sand"},
        {pos: [7, 3, 16], state: "minecraft:cut_red_sandstone"},
        {pos: [8, 3, 0], state: "minecraft:red_sand"},
        {pos: [8, 3, 1], state: "minecraft:red_sand"},
        {pos: [8, 3, 2], state: "minecraft:terracotta"},
        {pos: [8, 3, 3], state: "minecraft:red_sand"},
        {pos: [8, 3, 4], state: "minecraft:red_sand"},
        {pos: [8, 3, 5], state: "minecraft:red_sand"},
        {pos: [8, 3, 6], state: "minecraft:terracotta"},
        {pos: [8, 3, 7], state: "minecraft:red_sand"},
        {pos: [8, 3, 11], state: "minecraft:red_sand"},
        {pos: [8, 3, 12], state: "minecraft:cut_red_sandstone"},
        {pos: [8, 3, 13], state: "minecraft:red_sand"},
        {pos: [8, 3, 14], state: "minecraft:red_sand"},
        {pos: [8, 3, 15], state: "minecraft:red_sand"},
        {pos: [8, 3, 16], state: "minecraft:cut_red_sandstone"},
        {pos: [9, 3, 0], state: "minecraft:red_sand"},
        {pos: [9, 3, 1], state: "minecraft:red_sand"},
        {pos: [9, 3, 2], state: "minecraft:red_sand"},
        {pos: [9, 3, 3], state: "minecraft:red_sand"},
        {pos: [9, 3, 4], state: "minecraft:red_sand"},
        {pos: [9, 3, 5], state: "minecraft:red_sand"},
        {pos: [9, 3, 6], state: "minecraft:red_sand"},
        {pos: [9, 3, 12], state: "minecraft:red_sand"},
        {pos: [9, 3, 13], state: "minecraft:red_sand"},
        {pos: [10, 3, 1], state: "minecraft:red_sand"},
        {pos: [10, 3, 2], state: "minecraft:red_sand"},
        {pos: [10, 3, 3], state: "minecraft:red_sand"},
        {pos: [10, 3, 4], state: "minecraft:red_sand"},
        {pos: [10, 3, 5], state: "minecraft:red_sand"},
        {pos: [10, 3, 12], state: "minecraft:red_sand"},
        {pos: [11, 3, 2], state: "minecraft:red_sand"},
        {pos: [11, 3, 3], state: "minecraft:red_sand"},
        {pos: [11, 3, 4], state: "minecraft:red_sand"},
        {pos: [2, 4, 15], state: "minecraft:red_sand"},
        {pos: [2, 4, 16], state: "minecraft:red_sand"},
        {pos: [3, 4, 6], state: "minecraft:red_sand"},
        {pos: [3, 4, 12], state: "minecraft:cut_red_sandstone"},
        {pos: [3, 4, 15], state: "minecraft:red_sand"},
        {pos: [3, 4, 16], state: "minecraft:red_sand"},
        {pos: [3, 4, 17], state: "minecraft:red_sand"},
        {pos: [4, 4, 5], state: "minecraft:red_sand"},
        {pos: [4, 4, 6], state: "minecraft:cut_red_sandstone"},
        {pos: [4, 4, 7], state: "minecraft:red_sand"},
        {pos: [4, 4, 12], state: "minecraft:cut_red_sandstone"},
        {pos: [4, 4, 13], state: "minecraft:red_sand"},
        {pos: [4, 4, 16], state: "minecraft:red_sand"},
        {pos: [4, 4, 17], state: "minecraft:cut_red_sandstone"},
        {pos: [5, 4, 5], state: "minecraft:red_sand"},
        {pos: [5, 4, 6], state: "minecraft:cut_red_sandstone"},
        {pos: [5, 4, 7], state: "minecraft:red_sand"},
        {pos: [5, 4, 11], state: "minecraft:red_sand"},
        {pos: [5, 4, 12], state: "minecraft:cut_red_sandstone"},
        {pos: [5, 4, 13], state: "minecraft:red_sand"},
        {pos: [5, 4, 14], state: "minecraft:red_sand"},
        {pos: [5, 4, 17], state: "minecraft:cut_red_sandstone"},
        {pos: [6, 4, 2], state: "minecraft:red_sandstone_wall{east:none,north:none,south:none,up:true,waterlogged:false,west:none}"},
        {pos: [6, 4, 4], state: "minecraft:red_sand"},
        {pos: [6, 4, 5], state: "minecraft:red_sand"},
        {pos: [6, 4, 6], state: "minecraft:cut_red_sandstone"},
        {pos: [6, 4, 7], state: "minecraft:red_sand"},
        {pos: [6, 4, 8], state: "minecraft:red_sand"},
        {pos: [6, 4, 11], state: "minecraft:red_sand"},
        {pos: [6, 4, 12], state: "minecraft:cut_red_sandstone"},
        {pos: [6, 4, 13], state: "minecraft:red_sand"},
        {pos: [6, 4, 14], state: "minecraft:red_sand"},
        {pos: [6, 4, 15], state: "minecraft:red_sand"},
        {pos: [6, 4, 17], state: "minecraft:cut_red_sandstone"},
        {pos: [7, 4, 4], state: "minecraft:red_sand"},
        {pos: [7, 4, 5], state: "minecraft:red_sand"},
        {pos: [7, 4, 6], state: "minecraft:red_sand"},
        {pos: [7, 4, 7], state: "minecraft:red_sand"},
        {pos: [7, 4, 12], state: "minecraft:cut_red_sandstone"},
        {pos: [7, 4, 13], state: "minecraft:red_sand"},
        {pos: [7, 4, 14], state: "minecraft:red_sand"},
        {pos: [7, 4, 15], state: "minecraft:red_sand"},
        {pos: [7, 4, 16], state: "minecraft:cut_red_sandstone"},
        {pos: [8, 4, 1], state: "minecraft:red_sand"},
        {pos: [8, 4, 2], state: "minecraft:red_sand"},
        {pos: [8, 4, 3], state: "minecraft:red_sand"},
        {pos: [8, 4, 4], state: "minecraft:red_sand"},
        {pos: [8, 4, 5], state: "minecraft:red_sand"},
        {pos: [8, 4, 6], state: "minecraft:red_sand"},
        {pos: [8, 4, 11], state: "minecraft:red_sand"},
        {pos: [8, 4, 12], state: "minecraft:cut_red_sandstone"},
        {pos: [8, 4, 13], state: "minecraft:red_sand"},
        {pos: [8, 4, 14], state: "minecraft:red_sand"},
        {pos: [8, 4, 15], state: "minecraft:cut_red_sandstone"},
        {pos: [8, 4, 16], state: "minecraft:cut_red_sandstone"},
        {pos: [9, 4, 1], state: "minecraft:red_sand"},
        {pos: [9, 4, 2], state: "minecraft:red_sand"},
        {pos: [9, 4, 3], state: "minecraft:red_sand"},
        {pos: [9, 4, 4], state: "minecraft:red_sand"},
        {pos: [10, 4, 2], state: "minecraft:red_sand"},
        {pos: [10, 4, 3], state: "minecraft:red_sand"},
        {pos: [4, 5, 17], state: "minecraft:red_sandstone_wall{east:none,north:none,south:none,up:true,waterlogged:false,west:none}"},
        {pos: [7, 5, 12], state: "minecraft:red_sandstone_wall{east:low,north:none,south:none,up:true,waterlogged:false,west:none}"},
        {pos: [8, 5, 12], state: "minecraft:red_sandstone_wall{east:none,north:none,south:none,up:true,waterlogged:false,west:low}"}
    ],
    entities: [],
    palette: [
        "minecraft:cut_red_sandstone",
        "minecraft:red_terracotta",
        "minecraft:terracotta",
        "minecraft:yellow_glazed_terracotta{facing:west}",
        "minecraft:orange_glazed_terracotta{facing:west}",
        "minecraft:yellow_glazed_terracotta{facing:south}",
        "minecraft:orange_glazed_terracotta{facing:east}",
        "minecraft:orange_glazed_terracotta{facing:south}",
        "minecraft:red_sand",
        "minecraft:red_sandstone_stairs{facing:south,half:top,shape:straight,waterlogged:false}",
        "minecraft:red_sandstone_wall{east:tall,north:tall,south:tall,up:false,waterlogged:false,west:tall}",
        "minecraft:red_sandstone_wall{east:none,north:none,south:none,up:true,waterlogged:false,west:none}",
        "minecraft:red_sandstone_wall{east:low,north:none,south:none,up:true,waterlogged:false,west:none}",
        "minecraft:red_sandstone_wall{east:none,north:none,south:none,up:true,waterlogged:false,west:low}"
    ],
    trailiertales_DataVersion: 2
}
