{
    DataVersion: 3953,
    size: [15, 5, 11],
    data: [
        {pos: [0, 0, 2], state: "minecraft:sand"},
        {pos: [0, 0, 3], state: "minecraft:sand"},
        {pos: [0, 0, 4], state: "minecraft:sand"},
        {pos: [0, 0, 5], state: "minecraft:sand"},
        {pos: [0, 0, 6], state: "minecraft:sand"},
        {pos: [0, 0, 7], state: "minecraft:sand"},
        {pos: [0, 0, 8], state: "minecraft:sand"},
        {pos: [1, 0, 1], state: "minecraft:sand"},
        {pos: [1, 0, 2], state: "minecraft:sand"},
        {pos: [1, 0, 3], state: "minecraft:sand"},
        {pos: [1, 0, 4], state: "minecraft:sand"},
        {pos: [1, 0, 5], state: "minecraft:sand"},
        {pos: [1, 0, 6], state: "minecraft:sand"},
        {pos: [1, 0, 7], state: "minecraft:sand"},
        {pos: [1, 0, 8], state: "minecraft:sand"},
        {pos: [1, 0, 9], state: "minecraft:sand"},
        {pos: [1, 0, 10], state: "minecraft:sand"},
        {pos: [2, 0, 0], state: "minecraft:sand"},
        {pos: [2, 0, 1], state: "minecraft:sand"},
        {pos: [2, 0, 2], state: "minecraft:sandstone"},
        {pos: [2, 0, 3], state: "minecraft:sandstone"},
        {pos: [2, 0, 4], state: "minecraft:sandstone"},
        {pos: [2, 0, 5], state: "minecraft:sandstone"},
        {pos: [2, 0, 6], state: "minecraft:sandstone"},
        {pos: [2, 0, 7], state: "minecraft:sandstone"},
        {pos: [2, 0, 8], state: "minecraft:sandstone"},
        {pos: [2, 0, 9], state: "minecraft:sand"},
        {pos: [2, 0, 10], state: "minecraft:sand"},
        {pos: [3, 0, 0], state: "minecraft:sand"},
        {pos: [3, 0, 1], state: "minecraft:sand"},
        {pos: [3, 0, 2], state: "minecraft:sandstone"},
        {pos: [3, 0, 3], state: "minecraft:sandstone"},
        {pos: [3, 0, 4], state: "minecraft:sandstone"},
        {pos: [3, 0, 5], state: "minecraft:sandstone"},
        {pos: [3, 0, 6], state: "minecraft:sandstone"},
        {pos: [3, 0, 7], state: "minecraft:sandstone"},
        {pos: [3, 0, 8], state: "minecraft:sandstone"},
        {pos: [3, 0, 9], state: "minecraft:sand"},
        {pos: [3, 0, 10], state: "minecraft:sand"},
        {pos: [4, 0, 0], state: "minecraft:sand"},
        {pos: [4, 0, 1], state: "minecraft:sand"},
        {pos: [4, 0, 2], state: "minecraft:sandstone"},
        {pos: [4, 0, 3], state: "minecraft:sandstone"},
        {pos: [4, 0, 4], state: "minecraft:sandstone"},
        {pos: [4, 0, 5], state: "minecraft:sandstone"},
        {pos: [4, 0, 6], state: "minecraft:sandstone"},
        {pos: [4, 0, 7], state: "minecraft:sandstone"},
        {pos: [4, 0, 8], state: "minecraft:sandstone"},
        {pos: [4, 0, 9], state: "minecraft:sand"},
        {pos: [4, 0, 10], state: "minecraft:sand"},
        {pos: [5, 0, 1], state: "minecraft:sand"},
        {pos: [5, 0, 2], state: "minecraft:sandstone"},
        {pos: [5, 0, 3], state: "minecraft:sandstone"},
        {pos: [5, 0, 4], state: "minecraft:sandstone"},
        {pos: [5, 0, 5], state: "minecraft:sandstone"},
        {pos: [5, 0, 6], state: "minecraft:sandstone"},
        {pos: [5, 0, 7], state: "minecraft:sandstone"},
        {pos: [5, 0, 8], state: "minecraft:sandstone"},
        {pos: [5, 0, 9], state: "minecraft:sand"},
        {pos: [5, 0, 10], state: "minecraft:sand"},
        {pos: [6, 0, 1], state: "minecraft:sand"},
        {pos: [6, 0, 2], state: "minecraft:sandstone"},
        {pos: [6, 0, 3], state: "minecraft:sandstone"},
        {pos: [6, 0, 4], state: "minecraft:sandstone"},
        {pos: [6, 0, 5], state: "minecraft:sandstone"},
        {pos: [6, 0, 6], state: "minecraft:sandstone"},
        {pos: [6, 0, 7], state: "minecraft:sandstone"},
        {pos: [6, 0, 8], state: "minecraft:sandstone"},
        {pos: [6, 0, 9], state: "minecraft:sand"},
        {pos: [7, 0, 0], state: "minecraft:sand"},
        {pos: [7, 0, 1], state: "minecraft:sand"},
        {pos: [7, 0, 2], state: "minecraft:sandstone"},
        {pos: [7, 0, 3], state: "minecraft:sandstone"},
        {pos: [7, 0, 4], state: "minecraft:sandstone"},
        {pos: [7, 0, 5], state: "minecraft:sandstone"},
        {pos: [7, 0, 6], state: "minecraft:sandstone"},
        {pos: [7, 0, 7], state: "minecraft:sandstone"},
        {pos: [7, 0, 8], state: "minecraft:sandstone"},
        {pos: [7, 0, 9], state: "minecraft:sand"},
        {pos: [7, 0, 10], state: "minecraft:sand"},
        {pos: [8, 0, 0], state: "minecraft:sand"},
        {pos: [8, 0, 1], state: "minecraft:sand"},
        {pos: [8, 0, 2], state: "minecraft:sandstone"},
        {pos: [8, 0, 3], state: "minecraft:sandstone"},
        {pos: [8, 0, 4], state: "minecraft:sandstone"},
        {pos: [8, 0, 5], state: "minecraft:sandstone"},
        {pos: [8, 0, 6], state: "minecraft:sandstone"},
        {pos: [8, 0, 7], state: "minecraft:sandstone"},
        {pos: [8, 0, 8], state: "minecraft:sandstone"},
        {pos: [8, 0, 9], state: "minecraft:sand"},
        {pos: [8, 0, 10], state: "minecraft:sand"},
        {pos: [9, 0, 0], state: "minecraft:sand"},
        {pos: [9, 0, 1], state: "minecraft:sand"},
        {pos: [9, 0, 2], state: "minecraft:sandstone"},
        {pos: [9, 0, 3], state: "minecraft:sandstone"},
        {pos: [9, 0, 4], state: "minecraft:sandstone"},
        {pos: [9, 0, 5], state: "minecraft:sandstone"},
        {pos: [9, 0, 6], state: "minecraft:sandstone"},
        {pos: [9, 0, 7], state: "minecraft:sandstone"},
        {pos: [9, 0, 8], state: "minecraft:sandstone"},
        {pos: [9, 0, 9], state: "minecraft:sand"},
        {pos: [9, 0, 10], state: "minecraft:sand"},
        {pos: [10, 0, 1], state: "minecraft:sand"},
        {pos: [10, 0, 2], state: "minecraft:sand"},
        {pos: [10, 0, 3], state: "minecraft:sandstone"},
        {pos: [10, 0, 4], state: "minecraft:sandstone"},
        {pos: [10, 0, 5], state: "minecraft:sandstone"},
        {pos: [10, 0, 6], state: "minecraft:sandstone"},
        {pos: [10, 0, 7], state: "minecraft:sandstone"},
        {pos: [10, 0, 8], state: "minecraft:sandstone"},
        {pos: [10, 0, 9], state: "minecraft:sand"},
        {pos: [10, 0, 10], state: "minecraft:sand"},
        {pos: [11, 0, 2], state: "minecraft:sand"},
        {pos: [11, 0, 3], state: "minecraft:sandstone"},
        {pos: [11, 0, 4], state: "minecraft:sandstone"},
        {pos: [11, 0, 5], state: "minecraft:sandstone"},
        {pos: [11, 0, 6], state: "minecraft:sandstone"},
        {pos: [11, 0, 7], state: "minecraft:sandstone"},
        {pos: [11, 0, 8], state: "minecraft:sandstone"},
        {pos: [11, 0, 9], state: "minecraft:sand"},
        {pos: [11, 0, 10], state: "minecraft:sand"},
        {pos: [12, 0, 2], state: "minecraft:sandstone"},
        {pos: [12, 0, 3], state: "minecraft:sand"},
        {pos: [12, 0, 4], state: "minecraft:sandstone"},
        {pos: [12, 0, 5], state: "minecraft:sandstone"},
        {pos: [12, 0, 6], state: "minecraft:sandstone"},
        {pos: [12, 0, 7], state: "minecraft:sandstone"},
        {pos: [12, 0, 8], state: "minecraft:sandstone"},
        {pos: [12, 0, 9], state: "minecraft:sand"},
        {pos: [12, 0, 10], state: "minecraft:sand"},
        {pos: [13, 0, 2], state: "minecraft:sand"},
        {pos: [13, 0, 3], state: "minecraft:sand"},
        {pos: [13, 0, 4], state: "minecraft:sand"},
        {pos: [13, 0, 5], state: "minecraft:sand"},
        {pos: [13, 0, 6], state: "minecraft:sand"},
        {pos: [13, 0, 7], state: "minecraft:sand"},
        {pos: [13, 0, 8], state: "minecraft:sand"},
        {pos: [13, 0, 9], state: "minecraft:sand"},
        {pos: [13, 0, 10], state: "minecraft:sand"},
        {pos: [14, 0, 3], state: "minecraft:sand"},
        {pos: [14, 0, 4], state: "minecraft:sand"},
        {pos: [14, 0, 5], state: "minecraft:sand"},
        {pos: [14, 0, 6], state: "minecraft:sand"},
        {pos: [14, 0, 7], state: "minecraft:sand"},
        {pos: [14, 0, 8], state: "minecraft:sand"},
        {pos: [0, 1, 4], state: "minecraft:sand"},
        {pos: [0, 1, 5], state: "minecraft:sand"},
        {pos: [0, 1, 6], state: "minecraft:sand"},
        {pos: [1, 1, 3], state: "minecraft:sand"},
        {pos: [1, 1, 4], state: "minecraft:sand"},
        {pos: [1, 1, 5], state: "minecraft:sand"},
        {pos: [1, 1, 6], state: "minecraft:sand"},
        {pos: [1, 1, 7], state: "minecraft:sand"},
        {pos: [2, 1, 2], state: "minecraft:sand"},
        {pos: [2, 1, 3], state: "minecraft:sandstone"},
        {pos: [2, 1, 4], state: "minecraft:sandstone"},
        {pos: [2, 1, 5], state: "minecraft:sandstone"},
        {pos: [2, 1, 6], state: "minecraft:smooth_sandstone"},
        {pos: [2, 1, 7], state: "minecraft:smooth_sandstone"},
        {pos: [2, 1, 8], state: "minecraft:sandstone"},
        {pos: [3, 1, 2], state: "minecraft:sandstone"},
        {pos: [3, 1, 3], state: "minecraft:sand"},
        {pos: [3, 1, 4], state: "minecraft:sand"},
        {pos: [3, 1, 5], state: "minecraft:sand"},
        {pos: [3, 1, 6], state: "minecraft:sandstone_stairs{facing:west,half:top,shape:straight,waterlogged:false}"},
        {pos: [3, 1, 7], state: "minecraft:sandstone_stairs{facing:west,half:top,shape:straight,waterlogged:false}"},
        {pos: [3, 1, 8], state: "minecraft:sandstone"},
        {pos: [3, 1, 9], state: "minecraft:sand"},
        {pos: [4, 1, 2], state: "minecraft:sandstone"},
        {pos: [4, 1, 3], state: "minecraft:sand"},
        {pos: [4, 1, 4], state: "minecraft:sand"},
        {pos: [4, 1, 5], state: "minecraft:sand"},
        {pos: [4, 1, 6], state: "minecraft:sand"},
        {pos: [4, 1, 7], state: "minecraft:sand"},
        {pos: [4, 1, 8], state: "minecraft:sandstone"},
        {pos: [4, 1, 9], state: "minecraft:sand"},
        {pos: [5, 1, 2], state: "minecraft:sand"},
        {pos: [5, 1, 3], state: "minecraft:sand"},
        {pos: [5, 1, 4], state: "minecraft:sand"},
        {pos: [5, 1, 5], state: "minecraft:sand"},
        {pos: [5, 1, 6], state: "minecraft:sandstone_stairs{facing:east,half:bottom,shape:straight,waterlogged:false}"},
        {pos: [5, 1, 7], state: "minecraft:sandstone_stairs{facing:east,half:bottom,shape:straight,waterlogged:false}"},
        {pos: [5, 1, 8], state: "minecraft:sandstone"},
        {pos: [5, 1, 9], state: "minecraft:sand"},
        {pos: [6, 1, 2], state: "minecraft:sandstone"},
        {pos: [6, 1, 3], state: "minecraft:sand"},
        {pos: [6, 1, 4], state: "minecraft:sand"},
        {pos: [6, 1, 5], state: "minecraft:sand"},
        {pos: [6, 1, 6], state: "minecraft:sandstone"},
        {pos: [6, 1, 7], state: "minecraft:sandstone"},
        {pos: [6, 1, 8], state: "minecraft:sandstone"},
        {pos: [7, 1, 1], state: "minecraft:sand"},
        {pos: [7, 1, 2], state: "minecraft:sandstone"},
        {pos: [7, 1, 3], state: "minecraft:sand"},
        {pos: [7, 1, 4], state: "minecraft:sand"},
        {pos: [7, 1, 5], state: "minecraft:sand"},
        {pos: [7, 1, 6], state: "minecraft:sand"},
        {pos: [7, 1, 7], state: "minecraft:sandstone"},
        {pos: [7, 1, 8], state: "minecraft:sandstone"},
        {pos: [7, 1, 9], state: "minecraft:sand"},
        {pos: [8, 1, 1], state: "minecraft:sand"},
        {pos: [8, 1, 2], state: "minecraft:sandstone"},
        {pos: [8, 1, 3], state: "minecraft:sandstone"},
        {pos: [8, 1, 4], state: "minecraft:sandstone"},
        {pos: [8, 1, 5], state: "minecraft:smooth_sandstone"},
        {pos: [8, 1, 6], state: "minecraft:sandstone"},
        {pos: [8, 1, 7], state: "minecraft:sandstone"},
        {pos: [8, 1, 8], state: "minecraft:sandstone"},
        {pos: [8, 1, 9], state: "minecraft:sand"},
        {pos: [8, 1, 10], state: "minecraft:sand"},
        {pos: [9, 1, 2], state: "minecraft:sand"},
        {pos: [9, 1, 3], state: "minecraft:sand"},
        {pos: [9, 1, 4], state: "minecraft:sand"},
        {pos: [9, 1, 5], state: "minecraft:sand"},
        {pos: [9, 1, 6], state: "minecraft:sand"},
        {pos: [9, 1, 7], state: "minecraft:sand"},
        {pos: [9, 1, 8], state: "minecraft:sand"},
        {pos: [9, 1, 9], state: "minecraft:sand"},
        {pos: [9, 1, 10], state: "minecraft:sand"},
        {pos: [10, 1, 3], state: "minecraft:sand"},
        {pos: [10, 1, 4], state: "minecraft:sand"},
        {pos: [10, 1, 5], state: "minecraft:sand"},
        {pos: [10, 1, 6], state: "minecraft:sand"},
        {pos: [10, 1, 7], state: "minecraft:sand"},
        {pos: [10, 1, 8], state: "minecraft:sand"},
        {pos: [10, 1, 9], state: "minecraft:sand"},
        {pos: [10, 1, 10], state: "minecraft:sand"},
        {pos: [11, 1, 3], state: "minecraft:sand"},
        {pos: [11, 1, 4], state: "minecraft:sand"},
        {pos: [11, 1, 5], state: "minecraft:sand"},
        {pos: [11, 1, 6], state: "minecraft:sand"},
        {pos: [11, 1, 7], state: "minecraft:sand"},
        {pos: [11, 1, 8], state: "minecraft:sand"},
        {pos: [11, 1, 9], state: "minecraft:sand"},
        {pos: [11, 1, 10], state: "minecraft:sand"},
        {pos: [12, 1, 2], state: "minecraft:smooth_sandstone"},
        {pos: [12, 1, 4], state: "minecraft:sand"},
        {pos: [12, 1, 5], state: "minecraft:sand"},
        {pos: [12, 1, 6], state: "minecraft:sand"},
        {pos: [12, 1, 7], state: "minecraft:sand"},
        {pos: [12, 1, 8], state: "minecraft:smooth_sandstone"},
        {pos: [12, 1, 9], state: "minecraft:sand"},
        {pos: [13, 1, 6], state: "minecraft:sand"},
        {pos: [13, 1, 7], state: "minecraft:sand"},
        {pos: [1, 2, 4], state: "minecraft:sand"},
        {pos: [1, 2, 5], state: "minecraft:sand"},
        {pos: [1, 2, 6], state: "minecraft:sand"},
        {pos: [2, 2, 2], state: "minecraft:sand"},
        {pos: [2, 2, 3], state: "minecraft:smooth_sandstone"},
        {pos: [2, 2, 4], state: "minecraft:smooth_sandstone"},
        {pos: [2, 2, 5], state: "minecraft:smooth_sandstone"},
        {pos: [2, 2, 6], state: "minecraft:smooth_sandstone"},
        {pos: [2, 2, 7], state: "minecraft:smooth_sandstone"},
        {pos: [2, 2, 8], state: "minecraft:smooth_sandstone"},
        {pos: [3, 2, 2], state: "minecraft:sand"},
        {pos: [3, 2, 3], state: "minecraft:sand"},
        {pos: [3, 2, 4], state: "minecraft:sand"},
        {pos: [3, 2, 5], state: "minecraft:sand"},
        {pos: [3, 2, 6], state: "minecraft:sand"},
        {pos: [3, 2, 7], state: "minecraft:sand"},
        {pos: [3, 2, 8], state: "minecraft:sandstone"},
        {pos: [4, 2, 2], state: "minecraft:smooth_sandstone"},
        {pos: [4, 2, 3], state: "minecraft:sand"},
        {pos: [4, 2, 4], state: "minecraft:sand"},
        {pos: [4, 2, 5], state: "minecraft:sand"},
        {pos: [4, 2, 6], state: "minecraft:sand"},
        {pos: [4, 2, 7], state: "minecraft:sand"},
        {pos: [4, 2, 8], state: "minecraft:sand"},
        {pos: [5, 2, 2], state: "minecraft:sand"},
        {pos: [5, 2, 3], state: "minecraft:sand"},
        {pos: [5, 2, 4], state: "minecraft:sand"},
        {pos: [5, 2, 5], state: "minecraft:sand"},
        {pos: [5, 2, 6], state: "minecraft:sand"},
        {pos: [5, 2, 7], state: "minecraft:sand"},
        {pos: [5, 2, 8], state: "minecraft:sandstone"},
        {pos: [6, 2, 2], state: "minecraft:smooth_sandstone"},
        {pos: [6, 2, 3], state: "minecraft:sand"},
        {pos: [6, 2, 4], state: "minecraft:sand"},
        {pos: [6, 2, 5], state: "minecraft:sand"},
        {pos: [6, 2, 6], state: "minecraft:sandstone_stairs{facing:east,half:bottom,shape:straight,waterlogged:false}"},
        {pos: [6, 2, 7], state: "minecraft:sandstone_stairs{facing:east,half:bottom,shape:straight,waterlogged:false}"},
        {pos: [6, 2, 8], state: "minecraft:sandstone"},
        {pos: [7, 2, 2], state: "minecraft:sandstone"},
        {pos: [7, 2, 3], state: "minecraft:sand"},
        {pos: [7, 2, 4], state: "minecraft:sand"},
        {pos: [7, 2, 5], state: "minecraft:sand"},
        {pos: [7, 2, 6], state: "minecraft:sand"},
        {pos: [7, 2, 7], state: "minecraft:sandstone"},
        {pos: [7, 2, 8], state: "minecraft:sandstone"},
        {pos: [8, 2, 2], state: "minecraft:smooth_sandstone"},
        {pos: [8, 2, 3], state: "minecraft:smooth_sandstone"},
        {pos: [8, 2, 4], state: "minecraft:smooth_sandstone"},
        {pos: [8, 2, 5], state: "minecraft:sandstone"},
        {pos: [8, 2, 6], state: "minecraft:smooth_sandstone"},
        {pos: [8, 2, 7], state: "minecraft:smooth_sandstone"},
        {pos: [8, 2, 8], state: "minecraft:smooth_sandstone"},
        {pos: [8, 2, 9], state: "minecraft:sand"},
        {pos: [9, 2, 3], state: "minecraft:sand"},
        {pos: [9, 2, 4], state: "minecraft:sand"},
        {pos: [9, 2, 5], state: "minecraft:sand"},
        {pos: [9, 2, 6], state: "minecraft:sand"},
        {pos: [9, 2, 7], state: "minecraft:sand"},
        {pos: [9, 2, 8], state: "minecraft:sand"},
        {pos: [9, 2, 9], state: "minecraft:sand"},
        {pos: [10, 2, 4], state: "minecraft:sand"},
        {pos: [10, 2, 5], state: "minecraft:sand"},
        {pos: [10, 2, 6], state: "minecraft:sand"},
        {pos: [10, 2, 7], state: "minecraft:sand"},
        {pos: [10, 2, 8], state: "minecraft:sand"},
        {pos: [10, 2, 9], state: "minecraft:sand"},
        {pos: [11, 2, 5], state: "minecraft:sand"},
        {pos: [11, 2, 6], state: "minecraft:sand"},
        {pos: [11, 2, 7], state: "minecraft:sand"},
        {pos: [11, 2, 8], state: "minecraft:sand"},
        {pos: [11, 2, 9], state: "minecraft:sand"},
        {pos: [12, 2, 2], state: "minecraft:smooth_sandstone"},
        {pos: [12, 2, 8], state: "minecraft:smooth_sandstone"},
        {pos: [1, 3, 5], state: "minecraft:sand"},
        {pos: [2, 3, 3], state: "minecraft:cut_sandstone"},
        {pos: [2, 3, 4], state: "minecraft:cut_sandstone"},
        {pos: [2, 3, 5], state: "minecraft:sand"},
        {pos: [2, 3, 6], state: "minecraft:cut_sandstone"},
        {pos: [2, 3, 7], state: "minecraft:cut_sandstone"},
        {pos: [2, 3, 8], state: "minecraft:cut_sandstone"},
        {pos: [3, 3, 3], state: "minecraft:sand"},
        {pos: [3, 3, 4], state: "minecraft:sand"},
        {pos: [3, 3, 5], state: "minecraft:sand"},
        {pos: [3, 3, 6], state: "minecraft:sand"},
        {pos: [3, 3, 7], state: "minecraft:sand"},
        {pos: [3, 3, 8], state: "minecraft:cut_sandstone"},
        {pos: [4, 3, 2], state: "minecraft:cut_sandstone"},
        {pos: [4, 3, 3], state: "minecraft:sand"},
        {pos: [4, 3, 4], state: "minecraft:sand"},
        {pos: [4, 3, 5], state: "minecraft:sand"},
        {pos: [4, 3, 6], state: "minecraft:sand"},
        {pos: [4, 3, 7], state: "minecraft:sand"},
        {pos: [5, 3, 2], state: "minecraft:cut_sandstone"},
        {pos: [5, 3, 3], state: "minecraft:sand"},
        {pos: [5, 3, 4], state: "minecraft:sand"},
        {pos: [5, 3, 5], state: "minecraft:sand"},
        {pos: [5, 3, 6], state: "minecraft:sand"},
        {pos: [5, 3, 7], state: "minecraft:sand"},
        {pos: [5, 3, 8], state: "minecraft:sand"},
        {pos: [6, 3, 2], state: "minecraft:cut_sandstone"},
        {pos: [6, 3, 3], state: "minecraft:sand"},
        {pos: [6, 3, 4], state: "minecraft:sand"},
        {pos: [6, 3, 5], state: "minecraft:sand"},
        {pos: [6, 3, 6], state: "minecraft:sand"},
        {pos: [6, 3, 7], state: "minecraft:sand"},
        {pos: [6, 3, 8], state: "minecraft:cut_sandstone"},
        {pos: [7, 3, 2], state: "minecraft:cut_sandstone"},
        {pos: [7, 3, 3], state: "minecraft:sand"},
        {pos: [7, 3, 4], state: "minecraft:sand"},
        {pos: [7, 3, 5], state: "minecraft:sand"},
        {pos: [7, 3, 6], state: "minecraft:sandstone_stairs{facing:east,half:bottom,shape:straight,waterlogged:false}"},
        {pos: [7, 3, 7], state: "minecraft:sandstone_stairs{facing:east,half:bottom,shape:straight,waterlogged:false}"},
        {pos: [7, 3, 8], state: "minecraft:cut_sandstone"},
        {pos: [8, 3, 2], state: "minecraft:cut_sandstone"},
        {pos: [8, 3, 3], state: "minecraft:cut_sandstone"},
        {pos: [8, 3, 4], state: "minecraft:cut_sandstone"},
        {pos: [8, 3, 5], state: "minecraft:cut_sandstone"},
        {pos: [8, 3, 6], state: "minecraft:cut_sandstone"},
        {pos: [8, 3, 7], state: "minecraft:cut_sandstone"},
        {pos: [8, 3, 8], state: "minecraft:sand"},
        {pos: [9, 3, 2], state: "minecraft:cut_sandstone"},
        {pos: [9, 3, 3], state: "minecraft:smooth_sandstone"},
        {pos: [9, 3, 4], state: "minecraft:smooth_sandstone"},
        {pos: [9, 3, 5], state: "minecraft:sand"},
        {pos: [9, 3, 6], state: "minecraft:sand"},
        {pos: [9, 3, 7], state: "minecraft:sand"},
        {pos: [9, 3, 8], state: "minecraft:cut_sandstone"},
        {pos: [10, 3, 2], state: "minecraft:cut_sandstone"},
        {pos: [10, 3, 3], state: "minecraft:smooth_sandstone"},
        {pos: [10, 3, 4], state: "minecraft:smooth_sandstone"},
        {pos: [10, 3, 5], state: "minecraft:smooth_sandstone"},
        {pos: [10, 3, 6], state: "minecraft:sand"},
        {pos: [10, 3, 7], state: "minecraft:sand"},
        {pos: [10, 3, 8], state: "minecraft:cut_sandstone"},
        {pos: [11, 3, 2], state: "minecraft:cut_sandstone"},
        {pos: [11, 3, 3], state: "minecraft:smooth_sandstone"},
        {pos: [11, 3, 4], state: "minecraft:smooth_sandstone"},
        {pos: [11, 3, 5], state: "minecraft:smooth_sandstone"},
        {pos: [11, 3, 6], state: "minecraft:smooth_sandstone"},
        {pos: [11, 3, 7], state: "minecraft:smooth_sandstone"},
        {pos: [11, 3, 8], state: "minecraft:cut_sandstone"},
        {pos: [12, 3, 3], state: "minecraft:cut_sandstone"},
        {pos: [12, 3, 4], state: "minecraft:cut_sandstone"},
        {pos: [12, 3, 5], state: "minecraft:cut_sandstone"},
        {pos: [12, 3, 6], state: "minecraft:cut_sandstone"},
        {pos: [12, 3, 7], state: "minecraft:cut_sandstone"},
        {pos: [12, 3, 8], state: "minecraft:cut_sandstone"},
        {pos: [2, 4, 5], state: "minecraft:sand"},
        {pos: [3, 4, 4], state: "minecraft:sand"},
        {pos: [3, 4, 5], state: "minecraft:sand"},
        {pos: [3, 4, 6], state: "minecraft:sand"},
        {pos: [4, 4, 3], state: "minecraft:sand"},
        {pos: [4, 4, 4], state: "minecraft:sand"},
        {pos: [4, 4, 5], state: "minecraft:sand"},
        {pos: [4, 4, 6], state: "minecraft:sand"},
        {pos: [5, 4, 3], state: "minecraft:sand"},
        {pos: [5, 4, 4], state: "minecraft:sand"},
        {pos: [5, 4, 5], state: "minecraft:sand"},
        {pos: [5, 4, 6], state: "minecraft:sand"},
        {pos: [5, 4, 7], state: "minecraft:sand"},
        {pos: [6, 4, 4], state: "minecraft:sand"},
        {pos: [6, 4, 5], state: "minecraft:sand"},
        {pos: [6, 4, 6], state: "minecraft:sand"},
        {pos: [7, 4, 4], state: "minecraft:sand"},
        {pos: [7, 4, 5], state: "minecraft:sand"},
        {pos: [8, 4, 2], state: "minecraft:smooth_sandstone"},
        {pos: [10, 4, 2], state: "minecraft:smooth_sandstone"},
        {pos: [10, 4, 7], state: "minecraft:sand"},
        {pos: [10, 4, 8], state: "minecraft:smooth_sandstone"},
        {pos: [11, 4, 6], state: "minecraft:sand"},
        {pos: [11, 4, 7], state: "minecraft:sand"},
        {pos: [11, 4, 8], state: "minecraft:sand"},
        {pos: [12, 4, 6], state: "minecraft:smooth_sandstone"},
        {pos: [12, 4, 7], state: "minecraft:sand"},
        {pos: [12, 4, 8], state: "minecraft:smooth_sandstone"}
    ],
    entities: [],
    palette: [
        "minecraft:sand",
        "minecraft:sandstone",
        "minecraft:smooth_sandstone",
        "minecraft:cut_sandstone",
        "minecraft:sandstone_stairs{facing:west,half:top,shape:straight,waterlogged:false}",
        "minecraft:sandstone_stairs{facing:east,half:bottom,shape:straight,waterlogged:false}"
    ],
    trailiertales_DataVersion: 2
}
