{
    DataVersion: 3953,
    size: [10, 4, 7],
    data: [
        {pos: [0, 0, 2], state: "minecraft:sand"},
        {pos: [0, 0, 3], state: "minecraft:sand"},
        {pos: [0, 0, 4], state: "minecraft:sand"},
        {pos: [1, 0, 0], state: "minecraft:sand"},
        {pos: [1, 0, 1], state: "minecraft:sand"},
        {pos: [1, 0, 2], state: "minecraft:sand"},
        {pos: [1, 0, 3], state: "minecraft:sand"},
        {pos: [1, 0, 4], state: "minecraft:sand"},
        {pos: [1, 0, 5], state: "minecraft:sand"},
        {pos: [2, 0, 0], state: "minecraft:sand"},
        {pos: [2, 0, 1], state: "minecraft:sandstone"},
        {pos: [2, 0, 2], state: "minecraft:sandstone"},
        {pos: [2, 0, 3], state: "minecraft:sandstone"},
        {pos: [2, 0, 4], state: "minecraft:sandstone"},
        {pos: [2, 0, 5], state: "minecraft:smooth_sandstone"},
        {pos: [2, 0, 6], state: "minecraft:smooth_sandstone"},
        {pos: [3, 0, 1], state: "minecraft:sandstone"},
        {pos: [3, 0, 2], state: "minecraft:sand"},
        {pos: [3, 0, 3], state: "minecraft:sand"},
        {pos: [3, 0, 4], state: "minecraft:sand"},
        {pos: [3, 0, 5], state: "minecraft:sand"},
        {pos: [3, 0, 6], state: "minecraft:sand"},
        {pos: [4, 0, 1], state: "minecraft:sandstone"},
        {pos: [4, 0, 2], state: "minecraft:sand"},
        {pos: [4, 0, 3], state: "minecraft:sand"},
        {pos: [4, 0, 4], state: "minecraft:sand"},
        {pos: [5, 0, 0], state: "minecraft:sand"},
        {pos: [5, 0, 1], state: "minecraft:sand"},
        {pos: [5, 0, 2], state: "minecraft:sand"},
        {pos: [5, 0, 3], state: "minecraft:sand"},
        {pos: [5, 0, 4], state: "minecraft:sand"},
        {pos: [6, 0, 0], state: "minecraft:sand"},
        {pos: [6, 0, 1], state: "minecraft:sandstone"},
        {pos: [6, 0, 2], state: "minecraft:sand"},
        {pos: [6, 0, 3], state: "minecraft:sand"},
        {pos: [6, 0, 4], state: "minecraft:sand"},
        {pos: [6, 0, 5], state: "minecraft:sand"},
        {pos: [7, 0, 0], state: "minecraft:sand"},
        {pos: [7, 0, 1], state: "minecraft:sandstone"},
        {pos: [7, 0, 2], state: "minecraft:sand"},
        {pos: [7, 0, 3], state: "minecraft:sand"},
        {pos: [7, 0, 4], state: "minecraft:sand"},
        {pos: [7, 0, 5], state: "minecraft:sand"},
        {pos: [8, 0, 1], state: "minecraft:sandstone"},
        {pos: [8, 0, 2], state: "minecraft:sandstone"},
        {pos: [8, 0, 3], state: "minecraft:sandstone"},
        {pos: [8, 0, 4], state: "minecraft:sandstone"},
        {pos: [8, 0, 5], state: "minecraft:smooth_sandstone"},
        {pos: [9, 0, 1], state: "minecraft:sand"},
        {pos: [9, 0, 2], state: "minecraft:sand"},
        {pos: [9, 0, 3], state: "minecraft:sand"},
        {pos: [9, 0, 4], state: "minecraft:sand"},
        {pos: [1, 1, 1], state: "minecraft:sand"},
        {pos: [1, 1, 2], state: "minecraft:sand"},
        {pos: [1, 1, 3], state: "minecraft:sand"},
        {pos: [2, 1, 1], state: "minecraft:smooth_sandstone"},
        {pos: [2, 1, 2], state: "minecraft:smooth_sandstone"},
        {pos: [2, 1, 3], state: "minecraft:sandstone"},
        {pos: [2, 1, 4], state: "minecraft:smooth_sandstone"},
        {pos: [2, 1, 5], state: "minecraft:sand"},
        {pos: [3, 1, 1], state: "minecraft:sandstone"},
        {pos: [3, 1, 2], state: "minecraft:sand"},
        {pos: [3, 1, 3], state: "minecraft:sand"},
        {pos: [3, 1, 4], state: "minecraft:decorated_pot{cracked:false,facing:west,waterlogged:false}", nbt: {id: "minecraft:decorated_pot"}},
        {pos: [3, 1, 5], state: "minecraft:sand"},
        {pos: [4, 1, 1], state: "minecraft:sandstone"},
        {pos: [4, 1, 2], state: "minecraft:sand"},
        {pos: [4, 1, 3], state: "minecraft:sand"},
        {pos: [4, 1, 4], state: "minecraft:sand"},
        {pos: [5, 1, 1], state: "minecraft:sand"},
        {pos: [5, 1, 2], state: "minecraft:sand"},
        {pos: [5, 1, 3], state: "minecraft:sand"},
        {pos: [6, 1, 1], state: "minecraft:sandstone"},
        {pos: [6, 1, 2], state: "minecraft:sand"},
        {pos: [6, 1, 3], state: "minecraft:sand"},
        {pos: [7, 1, 1], state: "minecraft:smooth_sandstone"},
        {pos: [7, 1, 2], state: "minecraft:sand"},
        {pos: [7, 1, 3], state: "minecraft:sand"},
        {pos: [7, 1, 4], state: "minecraft:sand"},
        {pos: [8, 1, 1], state: "minecraft:sandstone"},
        {pos: [8, 1, 2], state: "minecraft:sandstone"},
        {pos: [8, 1, 3], state: "minecraft:sandstone"},
        {pos: [8, 1, 4], state: "minecraft:smooth_sandstone"},
        {pos: [2, 2, 1], state: "minecraft:smooth_sandstone"},
        {pos: [2, 2, 2], state: "minecraft:smooth_sandstone"},
        {pos: [2, 2, 3], state: "minecraft:sand"},
        {pos: [2, 2, 4], state: "minecraft:sand"},
        {pos: [3, 2, 1], state: "minecraft:smooth_sandstone"},
        {pos: [3, 2, 2], state: "minecraft:sand"},
        {pos: [3, 2, 3], state: "minecraft:sand"},
        {pos: [3, 2, 4], state: "minecraft:sand"},
        {pos: [4, 2, 1], state: "minecraft:smooth_sandstone"},
        {pos: [4, 2, 2], state: "minecraft:sand"},
        {pos: [4, 2, 3], state: "minecraft:sand"},
        {pos: [5, 2, 1], state: "minecraft:sand"},
        {pos: [5, 2, 2], state: "minecraft:sand"},
        {pos: [6, 2, 1], state: "minecraft:smooth_sandstone"},
        {pos: [6, 2, 2], state: "minecraft:sand"},
        {pos: [7, 2, 1], state: "minecraft:smooth_sandstone"},
        {pos: [7, 2, 2], state: "minecraft:sand"},
        {pos: [8, 2, 1], state: "minecraft:smooth_sandstone"},
        {pos: [8, 2, 2], state: "minecraft:sandstone"},
        {pos: [8, 2, 3], state: "minecraft:sand"},
        {pos: [3, 3, 1], state: "minecraft:cut_sandstone"},
        {pos: [4, 3, 1], state: "minecraft:cut_sandstone"},
        {pos: [4, 3, 2], state: "minecraft:sand"},
        {pos: [5, 3, 1], state: "minecraft:cut_sandstone"},
        {pos: [5, 3, 2], state: "minecraft:sand"},
        {pos: [6, 3, 1], state: "minecraft:cut_sandstone"},
        {pos: [7, 3, 1], state: "minecraft:cut_sandstone"}
    ],
    entities: [],
    palette: [
        "minecraft:sand",
        "minecraft:sandstone",
        "minecraft:smooth_sandstone",
        "minecraft:cut_sandstone",
        "minecraft:decorated_pot{cracked:false,facing:west,waterlogged:false}"
    ],
    trailiertales_DataVersion: 2
}
