{
    DataVersion: 3953,
    size: [11, 12, 22],
    data: [
        {pos: [2, 0, 11], state: "minecraft:cobblestone"},
        {pos: [2, 0, 12], state: "minecraft:cobblestone"},
        {pos: [3, 0, 10], state: "minecraft:cobblestone"},
        {pos: [3, 0, 11], state: "minecraft:cobblestone"},
        {pos: [3, 0, 12], state: "minecraft:cobblestone"},
        {pos: [3, 0, 13], state: "minecraft:cobblestone"},
        {pos: [4, 0, 10], state: "minecraft:cobblestone"},
        {pos: [4, 0, 11], state: "minecraft:cobblestone"},
        {pos: [4, 0, 12], state: "minecraft:cobblestone"},
        {pos: [4, 0, 13], state: "minecraft:cobblestone"},
        {pos: [5, 0, 10], state: "minecraft:cobblestone"},
        {pos: [5, 0, 11], state: "minecraft:cobblestone"},
        {pos: [5, 0, 12], state: "minecraft:cobblestone"},
        {pos: [0, 1, 3], state: "minecraft:cobblestone"},
        {pos: [0, 1, 4], state: "minecraft:cobblestone"},
        {pos: [0, 1, 5], state: "minecraft:cobblestone"},
        {pos: [0, 1, 6], state: "minecraft:cobblestone"},
        {pos: [0, 1, 7], state: "minecraft:cobblestone"},
        {pos: [1, 1, 1], state: "minecraft:cobblestone"},
        {pos: [1, 1, 2], state: "minecraft:cobblestone"},
        {pos: [1, 1, 3], state: "minecraft:cobblestone"},
        {pos: [1, 1, 4], state: "minecraft:cobblestone"},
        {pos: [1, 1, 5], state: "minecraft:cobblestone"},
        {pos: [1, 1, 6], state: "minecraft:cobblestone"},
        {pos: [1, 1, 7], state: "minecraft:cobblestone"},
        {pos: [1, 1, 8], state: "minecraft:cobblestone"},
        {pos: [1, 1, 9], state: "minecraft:cobblestone"},
        {pos: [1, 1, 10], state: "minecraft:cobblestone"},
        {pos: [1, 1, 11], state: "minecraft:cobblestone"},
        {pos: [1, 1, 12], state: "minecraft:cobblestone"},
        {pos: [1, 1, 13], state: "minecraft:cobblestone"},
        {pos: [2, 1, 1], state: "minecraft:cobblestone"},
        {pos: [2, 1, 2], state: "minecraft:cobblestone"},
        {pos: [2, 1, 3], state: "minecraft:cobblestone"},
        {pos: [2, 1, 4], state: "minecraft:cobblestone"},
        {pos: [2, 1, 5], state: "minecraft:cobblestone"},
        {pos: [2, 1, 6], state: "minecraft:cobblestone"},
        {pos: [2, 1, 7], state: "minecraft:cobblestone"},
        {pos: [2, 1, 8], state: "minecraft:cobblestone"},
        {pos: [2, 1, 9], state: "minecraft:cobblestone"},
        {pos: [2, 1, 10], state: "minecraft:cobblestone"},
        {pos: [2, 1, 11], state: "minecraft:cobblestone"},
        {pos: [2, 1, 12], state: "minecraft:cobblestone"},
        {pos: [2, 1, 13], state: "minecraft:cobblestone"},
        {pos: [2, 1, 14], state: "minecraft:cobblestone"},
        {pos: [2, 1, 15], state: "minecraft:cobblestone"},
        {pos: [2, 1, 16], state: "minecraft:cobblestone"},
        {pos: [2, 1, 17], state: "minecraft:cobblestone"},
        {pos: [2, 1, 18], state: "minecraft:cobblestone"},
        {pos: [3, 1, 1], state: "minecraft:cobblestone"},
        {pos: [3, 1, 2], state: "minecraft:cobblestone"},
        {pos: [3, 1, 3], state: "minecraft:cobblestone"},
        {pos: [3, 1, 4], state: "minecraft:cobblestone"},
        {pos: [3, 1, 5], state: "minecraft:cobblestone"},
        {pos: [3, 1, 6], state: "minecraft:cobblestone"},
        {pos: [3, 1, 7], state: "minecraft:cobblestone"},
        {pos: [3, 1, 8], state: "minecraft:cobblestone"},
        {pos: [3, 1, 9], state: "minecraft:cobblestone"},
        {pos: [3, 1, 10], state: "minecraft:cobblestone"},
        {pos: [3, 1, 11], state: "minecraft:cobblestone"},
        {pos: [3, 1, 12], state: "minecraft:cobblestone"},
        {pos: [3, 1, 13], state: "minecraft:cobblestone"},
        {pos: [3, 1, 14], state: "minecraft:cobblestone"},
        {pos: [3, 1, 15], state: "minecraft:cobblestone"},
        {pos: [3, 1, 16], state: "minecraft:cobblestone"},
        {pos: [3, 1, 17], state: "minecraft:cobblestone"},
        {pos: [3, 1, 18], state: "minecraft:cobblestone"},
        {pos: [3, 1, 19], state: "minecraft:cobblestone"},
        {pos: [3, 1, 20], state: "minecraft:cobblestone"},
        {pos: [4, 1, 0], state: "minecraft:cobblestone"},
        {pos: [4, 1, 1], state: "minecraft:cobblestone"},
        {pos: [4, 1, 2], state: "minecraft:cobblestone"},
        {pos: [4, 1, 3], state: "minecraft:cobblestone"},
        {pos: [4, 1, 4], state: "minecraft:cobblestone"},
        {pos: [4, 1, 5], state: "minecraft:cobblestone"},
        {pos: [4, 1, 6], state: "minecraft:cobblestone"},
        {pos: [4, 1, 7], state: "minecraft:cobblestone"},
        {pos: [4, 1, 8], state: "minecraft:cobblestone"},
        {pos: [4, 1, 9], state: "minecraft:cobblestone"},
        {pos: [4, 1, 10], state: "minecraft:cobblestone"},
        {pos: [4, 1, 11], state: "minecraft:repeater{delay:1,facing:east,locked:false,powered:false}"},
        {pos: [4, 1, 12], state: "minecraft:cobblestone"},
        {pos: [4, 1, 13], state: "minecraft:repeater{delay:1,facing:east,locked:false,powered:false}"},
        {pos: [4, 1, 14], state: "minecraft:cobblestone"},
        {pos: [4, 1, 15], state: "minecraft:cobblestone"},
        {pos: [4, 1, 16], state: "minecraft:cobblestone"},
        {pos: [4, 1, 17], state: "minecraft:cobblestone"},
        {pos: [4, 1, 18], state: "minecraft:cobblestone"},
        {pos: [4, 1, 19], state: "minecraft:cobblestone"},
        {pos: [4, 1, 20], state: "minecraft:cobblestone"},
        {pos: [4, 1, 21], state: "minecraft:cobblestone"},
        {pos: [5, 1, 0], state: "minecraft:cobblestone"},
        {pos: [5, 1, 1], state: "minecraft:cobblestone"},
        {pos: [5, 1, 2], state: "minecraft:cobblestone"},
        {pos: [5, 1, 3], state: "minecraft:cobblestone"},
        {pos: [5, 1, 4], state: "minecraft:cobblestone"},
        {pos: [5, 1, 5], state: "minecraft:cobblestone"},
        {pos: [5, 1, 6], state: "minecraft:cobblestone"},
        {pos: [5, 1, 7], state: "minecraft:cobblestone"},
        {pos: [5, 1, 8], state: "minecraft:cobblestone"},
        {pos: [5, 1, 9], state: "minecraft:cobblestone"},
        {pos: [5, 1, 10], state: "minecraft:cobblestone"},
        {pos: [5, 1, 11], state: "minecraft:cobblestone"},
        {pos: [5, 1, 12], state: "minecraft:cobblestone"},
        {pos: [5, 1, 13], state: "minecraft:cobblestone"},
        {pos: [5, 1, 14], state: "minecraft:cobblestone"},
        {pos: [5, 1, 15], state: "minecraft:cobblestone"},
        {pos: [5, 1, 16], state: "minecraft:cobblestone"},
        {pos: [5, 1, 17], state: "minecraft:cobblestone"},
        {pos: [5, 1, 18], state: "minecraft:cobblestone"},
        {pos: [5, 1, 19], state: "minecraft:cobblestone"},
        {pos: [5, 1, 20], state: "minecraft:cobblestone"},
        {pos: [5, 1, 21], state: "minecraft:cobblestone"},
        {pos: [6, 1, 0], state: "minecraft:cobblestone"},
        {pos: [6, 1, 1], state: "minecraft:cobblestone"},
        {pos: [6, 1, 2], state: "minecraft:cobblestone"},
        {pos: [6, 1, 3], state: "minecraft:cobblestone"},
        {pos: [6, 1, 4], state: "minecraft:cobblestone"},
        {pos: [6, 1, 5], state: "minecraft:cobblestone"},
        {pos: [6, 1, 6], state: "minecraft:cobblestone"},
        {pos: [6, 1, 7], state: "minecraft:cobblestone"},
        {pos: [6, 1, 8], state: "minecraft:cobblestone"},
        {pos: [6, 1, 9], state: "minecraft:cobblestone"},
        {pos: [6, 1, 10], state: "minecraft:cobblestone"},
        {pos: [6, 1, 12], state: "minecraft:cobblestone"},
        {pos: [6, 1, 13], state: "minecraft:cobblestone"},
        {pos: [6, 1, 14], state: "minecraft:cobblestone"},
        {pos: [6, 1, 15], state: "minecraft:cobblestone"},
        {pos: [6, 1, 16], state: "minecraft:cobblestone"},
        {pos: [6, 1, 17], state: "minecraft:cobblestone"},
        {pos: [6, 1, 18], state: "minecraft:cobblestone"},
        {pos: [6, 1, 19], state: "minecraft:cobblestone"},
        {pos: [6, 1, 20], state: "minecraft:cobblestone"},
        {pos: [6, 1, 21], state: "minecraft:cobblestone"},
        {pos: [7, 1, 0], state: "minecraft:cobblestone"},
        {pos: [7, 1, 1], state: "minecraft:cobblestone"},
        {pos: [7, 1, 2], state: "minecraft:cobblestone"},
        {pos: [7, 1, 3], state: "minecraft:cobblestone"},
        {pos: [7, 1, 4], state: "minecraft:cobblestone"},
        {pos: [7, 1, 5], state: "minecraft:cobblestone"},
        {pos: [7, 1, 6], state: "minecraft:cobblestone"},
        {pos: [7, 1, 7], state: "minecraft:cobblestone"},
        {pos: [7, 1, 8], state: "minecraft:cobblestone"},
        {pos: [7, 1, 9], state: "minecraft:cobblestone"},
        {pos: [7, 1, 15], state: "minecraft:cobblestone"},
        {pos: [7, 1, 16], state: "minecraft:cobblestone"},
        {pos: [7, 1, 17], state: "minecraft:cobblestone"},
        {pos: [7, 1, 18], state: "minecraft:cobblestone"},
        {pos: [7, 1, 19], state: "minecraft:cobblestone"},
        {pos: [7, 1, 20], state: "minecraft:cobblestone"},
        {pos: [8, 1, 1], state: "minecraft:cobblestone"},
        {pos: [8, 1, 2], state: "minecraft:cobblestone"},
        {pos: [8, 1, 3], state: "minecraft:cobblestone"},
        {pos: [8, 1, 4], state: "minecraft:cobblestone"},
        {pos: [8, 1, 5], state: "minecraft:cobblestone"},
        {pos: [8, 1, 6], state: "minecraft:cobblestone"},
        {pos: [8, 1, 7], state: "minecraft:cobblestone"},
        {pos: [8, 1, 8], state: "minecraft:cobblestone"},
        {pos: [8, 1, 9], state: "minecraft:cobblestone"},
        {pos: [8, 1, 16], state: "minecraft:cobblestone"},
        {pos: [8, 1, 17], state: "minecraft:cobblestone"},
        {pos: [8, 1, 18], state: "minecraft:cobblestone"},
        {pos: [9, 1, 1], state: "minecraft:cobblestone"},
        {pos: [9, 1, 2], state: "minecraft:cobblestone"},
        {pos: [9, 1, 3], state: "minecraft:cobblestone"},
        {pos: [9, 1, 4], state: "minecraft:cobblestone"},
        {pos: [9, 1, 5], state: "minecraft:cobblestone"},
        {pos: [9, 1, 6], state: "minecraft:cobblestone"},
        {pos: [9, 1, 7], state: "minecraft:cobblestone"},
        {pos: [9, 1, 8], state: "minecraft:cobblestone"},
        {pos: [9, 1, 9], state: "minecraft:cobblestone"},
        {pos: [10, 1, 3], state: "minecraft:cobblestone"},
        {pos: [10, 1, 4], state: "minecraft:cobblestone"},
        {pos: [10, 1, 5], state: "minecraft:cobblestone"},
        {pos: [10, 1, 6], state: "minecraft:cobblestone"},
        {pos: [0, 2, 1], state: "minecraft:cobblestone"},
        {pos: [0, 2, 2], state: "minecraft:cobblestone"},
        {pos: [0, 2, 3], state: "minecraft:cobblestone"},
        {pos: [0, 2, 4], state: "minecraft:cobblestone"},
        {pos: [0, 2, 5], state: "minecraft:cobblestone"},
        {pos: [0, 2, 6], state: "minecraft:cobblestone"},
        {pos: [0, 2, 7], state: "minecraft:gravel"},
        {pos: [0, 2, 8], state: "minecraft:cobblestone"},
        {pos: [0, 2, 9], state: "minecraft:cobblestone"},
        {pos: [1, 2, 0], state: "minecraft:cobblestone"},
        {pos: [1, 2, 1], state: "minecraft:gravel"},
        {pos: [1, 2, 2], state: "minecraft:gravel"},
        {pos: [1, 2, 3], state: "minecraft:gravel"},
        {pos: [1, 2, 4], state: "minecraft:cobblestone"},
        {pos: [1, 2, 5], state: "minecraft:gravel"},
        {pos: [1, 2, 6], state: "minecraft:cobblestone"},
        {pos: [1, 2, 7], state: "minecraft:cobblestone_stairs{facing:west,half:top,shape:straight,waterlogged:false}"},
        {pos: [1, 2, 8], state: "minecraft:cobblestone_stairs{facing:west,half:top,shape:straight,waterlogged:false}"},
        {pos: [1, 2, 9], state: "minecraft:gravel"},
        {pos: [1, 2, 10], state: "minecraft:cobblestone"},
        {pos: [1, 2, 11], state: "minecraft:cobblestone"},
        {pos: [1, 2, 12], state: "minecraft:cobblestone"},
        {pos: [1, 2, 13], state: "minecraft:cobblestone"},
        {pos: [1, 2, 14], state: "minecraft:cobblestone"},
        {pos: [2, 2, 0], state: "minecraft:cobblestone"},
        {pos: [2, 2, 1], state: "minecraft:cobblestone_stairs{facing:north,half:top,shape:straight,waterlogged:false}"},
        {pos: [2, 2, 2], state: "minecraft:gravel"},
        {pos: [2, 2, 3], state: "minecraft:gravel"},
        {pos: [2, 2, 4], state: "minecraft:gravel"},
        {pos: [2, 2, 5], state: "minecraft:gravel"},
        {pos: [2, 2, 6], state: "minecraft:gravel"},
        {pos: [2, 2, 7], state: "minecraft:gravel"},
        {pos: [2, 2, 8], state: "minecraft:gravel"},
        {pos: [2, 2, 9], state: "minecraft:gravel"},
        {pos: [2, 2, 10], state: "minecraft:cobblestone"},
        {pos: [2, 2, 11], state: "minecraft:redstone_wire{east:side,north:none,power:0,south:up,west:none}"},
        {pos: [2, 2, 12], state: "minecraft:cobblestone"},
        {pos: [2, 2, 13], state: "minecraft:redstone_wire{east:side,north:up,power:0,south:none,west:none}"},
        {pos: [2, 2, 14], state: "minecraft:cobblestone"},
        {pos: [2, 2, 15], state: "minecraft:cobblestone"},
        {pos: [2, 2, 16], state: "minecraft:cobblestone"},
        {pos: [2, 2, 17], state: "minecraft:cobblestone"},
        {pos: [2, 2, 18], state: "minecraft:cobblestone"},
        {pos: [2, 2, 19], state: "minecraft:cobblestone"},
        {pos: [2, 2, 20], state: "minecraft:cobblestone"},
        {pos: [3, 2, 0], state: "minecraft:cobblestone"},
        {pos: [3, 2, 1], state: "minecraft:cobblestone_stairs{facing:north,half:top,shape:straight,waterlogged:false}"},
        {pos: [3, 2, 2], state: "minecraft:gravel"},
        {pos: [3, 2, 3], state: "minecraft:gravel"},
        {pos: [3, 2, 4], state: "minecraft:cobblestone"},
        {pos: [3, 2, 5], state: "minecraft:cobblestone"},
        {pos: [3, 2, 6], state: "minecraft:gravel"},
        {pos: [3, 2, 7], state: "minecraft:gravel"},
        {pos: [3, 2, 8], state: "minecraft:gravel"},
        {pos: [3, 2, 9], state: "minecraft:gravel"},
        {pos: [3, 2, 10], state: "minecraft:cobblestone"},
        {pos: [3, 2, 11], state: "minecraft:redstone_wire{east:side,north:none,power:0,south:none,west:side}"},
        {pos: [3, 2, 12], state: "minecraft:cobblestone"},
        {pos: [3, 2, 13], state: "minecraft:redstone_wire{east:side,north:none,power:0,south:none,west:side}"},
        {pos: [3, 2, 14], state: "minecraft:cobblestone"},
        {pos: [3, 2, 15], state: "minecraft:cobblestone"},
        {pos: [3, 2, 16], state: "minecraft:cobblestone_stairs{facing:north,half:top,shape:straight,waterlogged:false}"},
        {pos: [3, 2, 17], state: "minecraft:gravel"},
        {pos: [3, 2, 18], state: "minecraft:gravel"},
        {pos: [3, 2, 19], state: "minecraft:gravel"},
        {pos: [3, 2, 20], state: "minecraft:gravel"},
        {pos: [3, 2, 21], state: "minecraft:cobblestone"},
        {pos: [4, 2, 0], state: "minecraft:cobblestone"},
        {pos: [4, 2, 1], state: "minecraft:cobblestone"},
        {pos: [4, 2, 2], state: "minecraft:gravel"},
        {pos: [4, 2, 3], state: "minecraft:gravel"},
        {pos: [4, 2, 4], state: "minecraft:cobblestone"},
        {pos: [4, 2, 5], state: "minecraft:cobblestone"},
        {pos: [4, 2, 6], state: "minecraft:gravel"},
        {pos: [4, 2, 7], state: "minecraft:gravel"},
        {pos: [4, 2, 8], state: "minecraft:gravel"},
        {pos: [4, 2, 9], state: "minecraft:gravel"},
        {pos: [4, 2, 10], state: "minecraft:cobblestone"},
        {pos: [4, 2, 11], state: "minecraft:cobblestone"},
        {pos: [4, 2, 12], state: "minecraft:cobblestone"},
        {pos: [4, 2, 13], state: "minecraft:cobblestone"},
        {pos: [4, 2, 14], state: "minecraft:cobblestone"},
        {pos: [4, 2, 15], state: "minecraft:cobblestone"},
        {pos: [4, 2, 16], state: "minecraft:cobblestone_stairs{facing:north,half:top,shape:straight,waterlogged:false}"},
        {pos: [4, 2, 17], state: "minecraft:gravel"},
        {pos: [4, 2, 18], state: "minecraft:gravel"},
        {pos: [4, 2, 19], state: "minecraft:gravel"},
        {pos: [4, 2, 20], state: "minecraft:gravel"},
        {pos: [4, 2, 21], state: "minecraft:cobblestone"},
        {pos: [5, 2, 0], state: "minecraft:gravel"},
        {pos: [5, 2, 1], state: "minecraft:gravel"},
        {pos: [5, 2, 2], state: "minecraft:gravel"},
        {pos: [5, 2, 3], state: "minecraft:gravel"},
        {pos: [5, 2, 4], state: "minecraft:cobblestone"},
        {pos: [5, 2, 5], state: "minecraft:cobblestone"},
        {pos: [5, 2, 6], state: "minecraft:gravel"},
        {pos: [5, 2, 7], state: "minecraft:gravel"},
        {pos: [5, 2, 8], state: "minecraft:gravel"},
        {pos: [5, 2, 9], state: "minecraft:gravel"},
        {pos: [5, 2, 10], state: "minecraft:gravel"},
        {pos: [5, 2, 11], state: "minecraft:stone_pressure_plate{powered:false}"},
        {pos: [5, 2, 12], state: "minecraft:air"},
        {pos: [5, 2, 13], state: "minecraft:stone_pressure_plate{powered:false}"},
        {pos: [5, 2, 14], state: "minecraft:air"},
        {pos: [5, 2, 15], state: "minecraft:air"},
        {pos: [5, 2, 16], state: "minecraft:air"},
        {pos: [5, 2, 17], state: "minecraft:air"},
        {pos: [5, 2, 18], state: "minecraft:air"},
        {pos: [5, 2, 19], state: "minecraft:air"},
        {pos: [5, 2, 20], state: "minecraft:gravel"},
        {pos: [5, 2, 21], state: "minecraft:cobblestone"},
        {pos: [6, 2, 0], state: "minecraft:cobblestone"},
        {pos: [6, 2, 1], state: "minecraft:cobblestone"},
        {pos: [6, 2, 2], state: "minecraft:gravel"},
        {pos: [6, 2, 3], state: "minecraft:gravel"},
        {pos: [6, 2, 4], state: "minecraft:cobblestone"},
        {pos: [6, 2, 5], state: "minecraft:cobblestone_stairs{facing:north,half:bottom,shape:straight,waterlogged:false}"},
        {pos: [6, 2, 6], state: "minecraft:gravel"},
        {pos: [6, 2, 7], state: "minecraft:gravel"},
        {pos: [6, 2, 8], state: "minecraft:gravel"},
        {pos: [6, 2, 9], state: "minecraft:gravel"},
        {pos: [6, 2, 10], state: "minecraft:cobblestone"},
        {pos: [6, 2, 11], state: "minecraft:cobblestone"},
        {pos: [6, 2, 12], state: "minecraft:cobblestone"},
        {pos: [6, 2, 13], state: "minecraft:cobblestone"},
        {pos: [6, 2, 14], state: "minecraft:cobblestone"},
        {pos: [6, 2, 15], state: "minecraft:cobblestone"},
        {pos: [6, 2, 16], state: "minecraft:gravel"},
        {pos: [6, 2, 17], state: "minecraft:gravel"},
        {pos: [6, 2, 18], state: "minecraft:air"},
        {pos: [6, 2, 19], state: "minecraft:gravel"},
        {pos: [6, 2, 20], state: "minecraft:gravel"},
        {pos: [6, 2, 21], state: "minecraft:cobblestone"},
        {pos: [7, 2, 0], state: "minecraft:cobblestone"},
        {pos: [7, 2, 1], state: "minecraft:cobblestone_stairs{facing:north,half:top,shape:straight,waterlogged:false}"},
        {pos: [7, 2, 2], state: "minecraft:gravel"},
        {pos: [7, 2, 3], state: "minecraft:gravel"},
        {pos: [7, 2, 4], state: "minecraft:gravel"},
        {pos: [7, 2, 5], state: "minecraft:gravel"},
        {pos: [7, 2, 6], state: "minecraft:gravel"},
        {pos: [7, 2, 7], state: "minecraft:gravel"},
        {pos: [7, 2, 8], state: "minecraft:gravel"},
        {pos: [7, 2, 9], state: "minecraft:gravel"},
        {pos: [7, 2, 10], state: "minecraft:cobblestone"},
        {pos: [7, 2, 13], state: "minecraft:cobblestone"},
        {pos: [7, 2, 14], state: "minecraft:cobblestone"},
        {pos: [7, 2, 15], state: "minecraft:cobblestone"},
        {pos: [7, 2, 16], state: "minecraft:gravel"},
        {pos: [7, 2, 17], state: "minecraft:cobblestone_stairs{facing:east,half:top,shape:straight,waterlogged:false}"},
        {pos: [7, 2, 18], state: "minecraft:cobblestone_stairs{facing:east,half:top,shape:straight,waterlogged:false}"},
        {pos: [7, 2, 19], state: "minecraft:cobblestone_stairs{facing:east,half:top,shape:straight,waterlogged:false}"},
        {pos: [7, 2, 20], state: "minecraft:gravel"},
        {pos: [7, 2, 21], state: "minecraft:cobblestone"},
        {pos: [8, 2, 0], state: "minecraft:cobblestone"},
        {pos: [8, 2, 1], state: "minecraft:cobblestone_stairs{facing:north,half:top,shape:straight,waterlogged:false}"},
        {pos: [8, 2, 2], state: "minecraft:gravel"},
        {pos: [8, 2, 3], state: "minecraft:gravel"},
        {pos: [8, 2, 4], state: "minecraft:gravel"},
        {pos: [8, 2, 5], state: "minecraft:gravel"},
        {pos: [8, 2, 6], state: "minecraft:gravel"},
        {pos: [8, 2, 7], state: "minecraft:gravel"},
        {pos: [8, 2, 8], state: "minecraft:gravel"},
        {pos: [8, 2, 9], state: "minecraft:gravel"},
        {pos: [8, 2, 10], state: "minecraft:cobblestone"},
        {pos: [8, 2, 16], state: "minecraft:cobblestone"},
        {pos: [8, 2, 17], state: "minecraft:cobblestone"},
        {pos: [8, 2, 18], state: "minecraft:cobblestone"},
        {pos: [8, 2, 19], state: "minecraft:cobblestone"},
        {pos: [8, 2, 20], state: "minecraft:cobblestone"},
        {pos: [9, 2, 0], state: "minecraft:cobblestone"},
        {pos: [9, 2, 1], state: "minecraft:gravel"},
        {pos: [9, 2, 2], state: "minecraft:gravel"},
        {pos: [9, 2, 3], state: "minecraft:cobblestone_stairs{facing:east,half:top,shape:straight,waterlogged:false}"},
        {pos: [9, 2, 4], state: "minecraft:cobblestone"},
        {pos: [9, 2, 5], state: "minecraft:gravel"},
        {pos: [9, 2, 6], state: "minecraft:cobblestone"},
        {pos: [9, 2, 7], state: "minecraft:cobblestone_stairs{facing:east,half:top,shape:straight,waterlogged:false}"},
        {pos: [9, 2, 8], state: "minecraft:gravel"},
        {pos: [9, 2, 9], state: "minecraft:gravel"},
        {pos: [9, 2, 10], state: "minecraft:cobblestone"},
        {pos: [10, 2, 1], state: "minecraft:cobblestone"},
        {pos: [10, 2, 2], state: "minecraft:cobblestone"},
        {pos: [10, 2, 3], state: "minecraft:cobblestone"},
        {pos: [10, 2, 4], state: "minecraft:cobblestone"},
        {pos: [10, 2, 5], state: "minecraft:cobblestone"},
        {pos: [10, 2, 6], state: "minecraft:cobblestone"},
        {pos: [10, 2, 7], state: "minecraft:cobblestone"},
        {pos: [10, 2, 8], state: "minecraft:cobblestone"},
        {pos: [10, 2, 9], state: "minecraft:cobblestone"},
        {pos: [0, 3, 1], state: "minecraft:cobblestone"},
        {pos: [0, 3, 2], state: "minecraft:cobblestone"},
        {pos: [0, 3, 3], state: "minecraft:cobblestone"},
        {pos: [0, 3, 4], state: "minecraft:cobblestone"},
        {pos: [0, 3, 5], state: "minecraft:cobblestone"},
        {pos: [0, 3, 6], state: "minecraft:gravel"},
        {pos: [0, 3, 7], state: "minecraft:cobblestone"},
        {pos: [0, 3, 8], state: "minecraft:cobblestone"},
        {pos: [0, 3, 9], state: "minecraft:gravel"},
        {pos: [0, 3, 10], state: "minecraft:cobblestone"},
        {pos: [1, 3, 0], state: "minecraft:cobblestone"},
        {pos: [1, 3, 1], state: "minecraft:gravel"},
        {pos: [1, 3, 2], state: "minecraft:gravel"},
        {pos: [1, 3, 3], state: "minecraft:gravel"},
        {pos: [1, 3, 4], state: "minecraft:cobblestone"},
        {pos: [1, 3, 6], state: "minecraft:cobblestone"},
        {pos: [1, 3, 7], state: "minecraft:gravel"},
        {pos: [1, 3, 8], state: "minecraft:gravel"},
        {pos: [1, 3, 9], state: "minecraft:gravel"},
        {pos: [1, 3, 10], state: "minecraft:cobblestone"},
        {pos: [1, 3, 11], state: "minecraft:cobblestone"},
        {pos: [1, 3, 12], state: "minecraft:gravel"},
        {pos: [1, 3, 13], state: "minecraft:gravel"},
        {pos: [2, 3, 0], state: "minecraft:cobblestone"},
        {pos: [2, 3, 1], state: "minecraft:gravel"},
        {pos: [2, 3, 2], state: "minecraft:gravel"},
        {pos: [2, 3, 3], state: "minecraft:gravel"},
        {pos: [2, 3, 4], state: "minecraft:gravel"},
        {pos: [2, 3, 5], state: "minecraft:gravel"},
        {pos: [2, 3, 6], state: "minecraft:gravel"},
        {pos: [2, 3, 7], state: "minecraft:gravel"},
        {pos: [2, 3, 8], state: "minecraft:gravel"},
        {pos: [2, 3, 9], state: "minecraft:gravel"},
        {pos: [2, 3, 10], state: "minecraft:cobblestone"},
        {pos: [2, 3, 11], state: "minecraft:air"},
        {pos: [2, 3, 12], state: "minecraft:redstone_wire{east:up,north:side,power:0,south:side,west:none}"},
        {pos: [2, 3, 13], state: "minecraft:air"},
        {pos: [2, 3, 14], state: "minecraft:cobblestone"},
        {pos: [2, 3, 15], state: "minecraft:cobblestone"},
        {pos: [2, 3, 16], state: "minecraft:cobblestone"},
        {pos: [2, 3, 17], state: "minecraft:cobblestone"},
        {pos: [2, 3, 18], state: "minecraft:cobblestone"},
        {pos: [2, 3, 19], state: "minecraft:cobblestone"},
        {pos: [2, 3, 20], state: "minecraft:cobblestone"},
        {pos: [3, 3, 0], state: "minecraft:gravel"},
        {pos: [3, 3, 1], state: "minecraft:gravel"},
        {pos: [3, 3, 2], state: "minecraft:gravel"},
        {pos: [3, 3, 3], state: "minecraft:gravel"},
        {pos: [3, 3, 4], state: "minecraft:gravel"},
        {pos: [3, 3, 5], state: "minecraft:gravel"},
        {pos: [3, 3, 6], state: "minecraft:gravel"},
        {pos: [3, 3, 7], state: "minecraft:gravel"},
        {pos: [3, 3, 8], state: "minecraft:gravel"},
        {pos: [3, 3, 9], state: "minecraft:gravel"},
        {pos: [3, 3, 10], state: "minecraft:cobblestone"},
        {pos: [3, 3, 11], state: "minecraft:dispenser{facing:east,triggered:false}", nbt: {Items: [{Slot: 2b, components: {"minecraft:potion_contents": {potion: "minecraft:long_poison"}}, count: 12, id: "minecraft:tipped_arrow"}, {Slot: 4b, components: {"minecraft:potion_contents": {potion: "minecraft:long_poison"}}, count: 11, id: "minecraft:tipped_arrow"}, {Slot: 5b, components: {"minecraft:potion_contents": {potion: "minecraft:long_poison"}}, count: 12, id: "minecraft:tipped_arrow"}, {Slot: 7b, components: {"minecraft:potion_contents": {potion: "minecraft:long_poison"}}, count: 11, id: "minecraft:tipped_arrow"}], id: "minecraft:dispenser"}},
        {pos: [3, 3, 12], state: "minecraft:cobblestone"},
        {pos: [3, 3, 13], state: "minecraft:dispenser{facing:east,triggered:false}", nbt: {Items: [{Slot: 1b, components: {"minecraft:potion_contents": {potion: "minecraft:long_poison"}}, count: 4, id: "minecraft:tipped_arrow"}, {Slot: 4b, components: {"minecraft:potion_contents": {potion: "minecraft:long_poison"}}, count: 13, id: "minecraft:tipped_arrow"}, {Slot: 5b, components: {"minecraft:potion_contents": {potion: "minecraft:long_poison"}}, count: 12, id: "minecraft:tipped_arrow"}, {Slot: 6b, components: {"minecraft:potion_contents": {potion: "minecraft:long_poison"}}, count: 6, id: "minecraft:tipped_arrow"}, {Slot: 7b, components: {"minecraft:potion_contents": {potion: "minecraft:long_poison"}}, count: 11, id: "minecraft:tipped_arrow"}], id: "minecraft:dispenser"}},
        {pos: [3, 3, 14], state: "minecraft:cobblestone"},
        {pos: [3, 3, 15], state: "minecraft:cobblestone"},
        {pos: [3, 3, 16], state: "minecraft:gravel"},
        {pos: [3, 3, 17], state: "minecraft:gravel"},
        {pos: [3, 3, 18], state: "minecraft:gravel"},
        {pos: [3, 3, 19], state: "minecraft:gravel"},
        {pos: [3, 3, 20], state: "minecraft:gravel"},
        {pos: [3, 3, 21], state: "minecraft:cobblestone"},
        {pos: [4, 3, 0], state: "minecraft:gravel"},
        {pos: [4, 3, 1], state: "minecraft:cobblestone"},
        {pos: [4, 3, 2], state: "minecraft:gravel"},
        {pos: [4, 3, 3], state: "minecraft:gravel"},
        {pos: [4, 3, 4], state: "minecraft:cobblestone"},
        {pos: [4, 3, 5], state: "minecraft:cobblestone"},
        {pos: [4, 3, 6], state: "minecraft:cobblestone"},
        {pos: [4, 3, 7], state: "minecraft:gravel"},
        {pos: [4, 3, 8], state: "minecraft:gravel"},
        {pos: [4, 3, 9], state: "minecraft:gravel"},
        {pos: [4, 3, 10], state: "minecraft:cobblestone"},
        {pos: [4, 3, 11], state: "minecraft:air"},
        {pos: [4, 3, 12], state: "minecraft:gravel"},
        {pos: [4, 3, 13], state: "minecraft:air"},
        {pos: [4, 3, 14], state: "minecraft:cobblestone"},
        {pos: [4, 3, 15], state: "minecraft:cobblestone"},
        {pos: [4, 3, 16], state: "minecraft:gravel"},
        {pos: [4, 3, 17], state: "minecraft:air"},
        {pos: [4, 3, 18], state: "minecraft:air"},
        {pos: [4, 3, 19], state: "minecraft:air"},
        {pos: [4, 3, 20], state: "minecraft:cobblestone"},
        {pos: [4, 3, 21], state: "minecraft:cobblestone"},
        {pos: [5, 3, 0], state: "minecraft:cobblestone"},
        {pos: [5, 3, 1], state: "minecraft:gravel"},
        {pos: [5, 3, 2], state: "minecraft:gravel"},
        {pos: [5, 3, 3], state: "minecraft:gravel"},
        {pos: [5, 3, 4], state: "minecraft:cobblestone_stairs{facing:west,half:bottom,shape:straight,waterlogged:false}"},
        {pos: [5, 3, 5], state: "minecraft:cobblestone"},
        {pos: [5, 3, 6], state: "minecraft:gravel"},
        {pos: [5, 3, 7], state: "minecraft:gravel"},
        {pos: [5, 3, 8], state: "minecraft:gravel"},
        {pos: [5, 3, 9], state: "minecraft:gravel"},
        {pos: [5, 3, 10], state: "minecraft:gravel"},
        {pos: [5, 3, 11], state: "minecraft:air"},
        {pos: [5, 3, 12], state: "minecraft:air"},
        {pos: [5, 3, 13], state: "minecraft:air"},
        {pos: [5, 3, 14], state: "minecraft:air"},
        {pos: [5, 3, 15], state: "minecraft:air"},
        {pos: [5, 3, 16], state: "minecraft:air"},
        {pos: [5, 3, 17], state: "minecraft:air"},
        {pos: [5, 3, 18], state: "minecraft:air"},
        {pos: [5, 3, 19], state: "minecraft:air"},
        {pos: [5, 3, 20], state: "minecraft:air"},
        {pos: [5, 3, 21], state: "minecraft:cobblestone"},
        {pos: [6, 3, 0], state: "minecraft:gravel"},
        {pos: [6, 3, 1], state: "minecraft:gravel"},
        {pos: [6, 3, 2], state: "minecraft:gravel"},
        {pos: [6, 3, 3], state: "minecraft:gravel"},
        {pos: [6, 3, 4], state: "minecraft:gravel"},
        {pos: [6, 3, 5], state: "minecraft:gravel"},
        {pos: [6, 3, 6], state: "minecraft:gravel"},
        {pos: [6, 3, 7], state: "minecraft:gravel"},
        {pos: [6, 3, 8], state: "minecraft:gravel"},
        {pos: [6, 3, 9], state: "minecraft:gravel"},
        {pos: [6, 3, 10], state: "minecraft:cobblestone"},
        {pos: [6, 3, 11], state: "minecraft:gravel"},
        {pos: [6, 3, 12], state: "minecraft:cobblestone"},
        {pos: [6, 3, 13], state: "minecraft:cobblestone"},
        {pos: [6, 3, 14], state: "minecraft:cobblestone"},
        {pos: [6, 3, 15], state: "minecraft:cobblestone"},
        {pos: [6, 3, 16], state: "minecraft:air"},
        {pos: [6, 3, 17], state: "minecraft:air"},
        {pos: [6, 3, 18], state: "minecraft:air"},
        {pos: [6, 3, 19], state: "minecraft:air"},
        {pos: [6, 3, 20], state: "minecraft:cobblestone"},
        {pos: [6, 3, 21], state: "minecraft:cobblestone"},
        {pos: [7, 3, 0], state: "minecraft:gravel"},
        {pos: [7, 3, 1], state: "minecraft:gravel"},
        {pos: [7, 3, 2], state: "minecraft:gravel"},
        {pos: [7, 3, 3], state: "minecraft:gravel"},
        {pos: [7, 3, 4], state: "minecraft:gravel"},
        {pos: [7, 3, 5], state: "minecraft:gravel"},
        {pos: [7, 3, 6], state: "minecraft:gravel"},
        {pos: [7, 3, 7], state: "minecraft:gravel"},
        {pos: [7, 3, 8], state: "minecraft:gravel"},
        {pos: [7, 3, 9], state: "minecraft:gravel"},
        {pos: [7, 3, 10], state: "minecraft:cobblestone"},
        {pos: [7, 3, 11], state: "minecraft:cobblestone"},
        {pos: [7, 3, 13], state: "minecraft:cobblestone"},
        {pos: [7, 3, 14], state: "minecraft:cobblestone"},
        {pos: [7, 3, 15], state: "minecraft:gravel"},
        {pos: [7, 3, 16], state: "minecraft:air"},
        {pos: [7, 3, 17], state: "minecraft:gravel"},
        {pos: [7, 3, 18], state: "minecraft:gravel"},
        {pos: [7, 3, 19], state: "minecraft:gravel"},
        {pos: [7, 3, 20], state: "minecraft:gravel"},
        {pos: [7, 3, 21], state: "minecraft:cobblestone"},
        {pos: [8, 3, 0], state: "minecraft:cobblestone"},
        {pos: [8, 3, 1], state: "minecraft:gravel"},
        {pos: [8, 3, 2], state: "minecraft:gravel"},
        {pos: [8, 3, 3], state: "minecraft:gravel"},
        {pos: [8, 3, 4], state: "minecraft:gravel"},
        {pos: [8, 3, 5], state: "minecraft:gravel"},
        {pos: [8, 3, 6], state: "minecraft:gravel"},
        {pos: [8, 3, 7], state: "minecraft:gravel"},
        {pos: [8, 3, 8], state: "minecraft:gravel"},
        {pos: [8, 3, 9], state: "minecraft:gravel"},
        {pos: [8, 3, 10], state: "minecraft:cobblestone"},
        {pos: [8, 3, 15], state: "minecraft:cobblestone"},
        {pos: [8, 3, 16], state: "minecraft:cobblestone"},
        {pos: [8, 3, 17], state: "minecraft:gravel"},
        {pos: [8, 3, 18], state: "minecraft:cobblestone"},
        {pos: [8, 3, 19], state: "minecraft:cobblestone"},
        {pos: [8, 3, 20], state: "minecraft:cobblestone"},
        {pos: [8, 3, 21], state: "minecraft:cobblestone"},
        {pos: [9, 3, 0], state: "minecraft:cobblestone"},
        {pos: [9, 3, 1], state: "minecraft:gravel"},
        {pos: [9, 3, 2], state: "minecraft:gravel"},
        {pos: [9, 3, 3], state: "minecraft:gravel"},
        {pos: [9, 3, 4], state: "minecraft:cobblestone"},
        {pos: [9, 3, 5], state: "minecraft:gravel"},
        {pos: [9, 3, 6], state: "minecraft:cobblestone"},
        {pos: [9, 3, 7], state: "minecraft:gravel"},
        {pos: [9, 3, 8], state: "minecraft:gravel"},
        {pos: [9, 3, 9], state: "minecraft:gravel"},
        {pos: [9, 3, 10], state: "minecraft:cobblestone"},
        {pos: [10, 3, 1], state: "minecraft:cobblestone"},
        {pos: [10, 3, 2], state: "minecraft:cobblestone"},
        {pos: [10, 3, 3], state: "minecraft:cobblestone"},
        {pos: [10, 3, 4], state: "minecraft:cobblestone"},
        {pos: [10, 3, 5], state: "minecraft:cobblestone"},
        {pos: [10, 3, 6], state: "minecraft:cobblestone"},
        {pos: [10, 3, 7], state: "minecraft:cobblestone"},
        {pos: [10, 3, 8], state: "minecraft:cobblestone"},
        {pos: [10, 3, 9], state: "minecraft:cobblestone"},
        {pos: [0, 4, 1], state: "minecraft:gravel"},
        {pos: [0, 4, 2], state: "minecraft:cobblestone"},
        {pos: [0, 4, 3], state: "minecraft:cobblestone"},
        {pos: [0, 4, 4], state: "minecraft:cobblestone"},
        {pos: [0, 4, 5], state: "minecraft:cobblestone"},
        {pos: [0, 4, 6], state: "minecraft:gravel"},
        {pos: [0, 4, 7], state: "minecraft:cobblestone"},
        {pos: [0, 4, 8], state: "minecraft:gravel"},
        {pos: [0, 4, 9], state: "minecraft:cobblestone"},
        {pos: [0, 4, 10], state: "minecraft:cobblestone"},
        {pos: [1, 4, 0], state: "minecraft:cobblestone"},
        {pos: [1, 4, 1], state: "minecraft:gravel"},
        {pos: [1, 4, 2], state: "minecraft:gravel"},
        {pos: [1, 4, 3], state: "minecraft:gravel"},
        {pos: [1, 4, 4], state: "minecraft:cobblestone"},
        {pos: [1, 4, 5], state: "minecraft:cobblestone"},
        {pos: [1, 4, 6], state: "minecraft:cobblestone"},
        {pos: [1, 4, 7], state: "minecraft:gravel"},
        {pos: [1, 4, 8], state: "minecraft:gravel"},
        {pos: [1, 4, 9], state: "minecraft:gravel"},
        {pos: [1, 4, 10], state: "minecraft:cobblestone"},
        {pos: [1, 4, 11], state: "minecraft:cobblestone"},
        {pos: [1, 4, 12], state: "minecraft:cobblestone"},
        {pos: [2, 4, 0], state: "minecraft:cobblestone"},
        {pos: [2, 4, 1], state: "minecraft:gravel"},
        {pos: [2, 4, 2], state: "minecraft:gravel"},
        {pos: [2, 4, 3], state: "minecraft:gravel"},
        {pos: [2, 4, 4], state: "minecraft:gravel"},
        {pos: [2, 4, 5], state: "minecraft:cobblestone_wall{east:tall,north:tall,south:tall,up:false,waterlogged:false,west:tall}"},
        {pos: [2, 4, 6], state: "minecraft:gravel"},
        {pos: [2, 4, 7], state: "minecraft:gravel"},
        {pos: [2, 4, 8], state: "minecraft:gravel"},
        {pos: [2, 4, 9], state: "minecraft:gravel"},
        {pos: [2, 4, 10], state: "minecraft:cobblestone"},
        {pos: [2, 4, 11], state: "minecraft:cobblestone"},
        {pos: [2, 4, 12], state: "minecraft:air"},
        {pos: [2, 4, 13], state: "minecraft:cobblestone"},
        {pos: [2, 4, 14], state: "minecraft:cobblestone"},
        {pos: [2, 4, 15], state: "minecraft:cobblestone"},
        {pos: [2, 4, 16], state: "minecraft:gravel"},
        {pos: [2, 4, 17], state: "minecraft:gravel"},
        {pos: [2, 4, 18], state: "minecraft:cobblestone"},
        {pos: [2, 4, 19], state: "minecraft:cobblestone"},
        {pos: [2, 4, 20], state: "minecraft:cobblestone"},
        {pos: [2, 4, 21], state: "minecraft:cobblestone"},
        {pos: [3, 4, 0], state: "minecraft:cobblestone"},
        {pos: [3, 4, 1], state: "minecraft:gravel"},
        {pos: [3, 4, 2], state: "minecraft:gravel"},
        {pos: [3, 4, 3], state: "minecraft:gravel"},
        {pos: [3, 4, 4], state: "minecraft:gravel"},
        {pos: [3, 4, 5], state: "minecraft:gravel"},
        {pos: [3, 4, 6], state: "minecraft:gravel"},
        {pos: [3, 4, 7], state: "minecraft:gravel"},
        {pos: [3, 4, 8], state: "minecraft:gravel"},
        {pos: [3, 4, 9], state: "minecraft:gravel"},
        {pos: [3, 4, 10], state: "minecraft:cobblestone"},
        {pos: [3, 4, 11], state: "minecraft:redstone_wire{east:none,north:side,power:0,south:side,west:none}"},
        {pos: [3, 4, 12], state: "minecraft:redstone_wire{east:none,north:side,power:0,south:side,west:side}"},
        {pos: [3, 4, 13], state: "minecraft:redstone_wire{east:none,north:side,power:0,south:side,west:none}"},
        {pos: [3, 4, 14], state: "minecraft:cobblestone"},
        {pos: [3, 4, 15], state: "minecraft:cobblestone"},
        {pos: [3, 4, 16], state: "minecraft:gravel"},
        {pos: [3, 4, 17], state: "minecraft:gravel"},
        {pos: [3, 4, 18], state: "minecraft:air"},
        {pos: [3, 4, 19], state: "minecraft:gravel"},
        {pos: [3, 4, 20], state: "minecraft:gravel"},
        {pos: [3, 4, 21], state: "minecraft:cobblestone"},
        {pos: [4, 4, 0], state: "minecraft:cobblestone"},
        {pos: [4, 4, 1], state: "minecraft:cobblestone"},
        {pos: [4, 4, 2], state: "minecraft:gravel"},
        {pos: [4, 4, 3], state: "minecraft:gravel"},
        {pos: [4, 4, 4], state: "minecraft:gravel"},
        {pos: [4, 4, 5], state: "minecraft:cobblestone_stairs{facing:south,half:bottom,shape:straight,waterlogged:false}"},
        {pos: [4, 4, 6], state: "minecraft:cobblestone"},
        {pos: [4, 4, 7], state: "minecraft:gravel"},
        {pos: [4, 4, 8], state: "minecraft:gravel"},
        {pos: [4, 4, 9], state: "minecraft:gravel"},
        {pos: [4, 4, 10], state: "minecraft:cobblestone"},
        {pos: [4, 4, 11], state: "minecraft:cobblestone"},
        {pos: [4, 4, 12], state: "minecraft:cobblestone"},
        {pos: [4, 4, 13], state: "minecraft:cobblestone"},
        {pos: [4, 4, 14], state: "minecraft:cobblestone"},
        {pos: [4, 4, 15], state: "minecraft:gravel"},
        {pos: [4, 4, 16], state: "minecraft:air"},
        {pos: [4, 4, 17], state: "minecraft:air"},
        {pos: [4, 4, 18], state: "minecraft:air"},
        {pos: [4, 4, 19], state: "minecraft:air"},
        {pos: [4, 4, 20], state: "minecraft:cobblestone"},
        {pos: [4, 4, 21], state: "minecraft:cobblestone"},
        {pos: [5, 4, 0], state: "minecraft:cobblestone"},
        {pos: [5, 4, 1], state: "minecraft:cobblestone"},
        {pos: [5, 4, 2], state: "minecraft:cobblestone_wall{east:tall,north:tall,south:tall,up:false,waterlogged:false,west:tall}"},
        {pos: [5, 4, 3], state: "minecraft:gravel"},
        {pos: [5, 4, 4], state: "minecraft:gravel"},
        {pos: [5, 4, 5], state: "minecraft:cobblestone"},
        {pos: [5, 4, 6], state: "minecraft:cobblestone"},
        {pos: [5, 4, 7], state: "minecraft:gravel"},
        {pos: [5, 4, 8], state: "minecraft:gravel"},
        {pos: [5, 4, 9], state: "minecraft:gravel"},
        {pos: [5, 4, 10], state: "minecraft:gravel"},
        {pos: [5, 4, 11], state: "minecraft:air"},
        {pos: [5, 4, 12], state: "minecraft:air"},
        {pos: [5, 4, 13], state: "minecraft:air"},
        {pos: [5, 4, 14], state: "minecraft:air"},
        {pos: [5, 4, 15], state: "minecraft:air"},
        {pos: [5, 4, 16], state: "minecraft:air"},
        {pos: [5, 4, 17], state: "minecraft:air"},
        {pos: [5, 4, 18], state: "minecraft:air"},
        {pos: [5, 4, 19], state: "minecraft:cobblestone_wall{east:none,north:none,south:low,up:true,waterlogged:false,west:none}"},
        {pos: [5, 4, 20], state: "minecraft:cobblestone"},
        {pos: [5, 4, 21], state: "minecraft:cobblestone"},
        {pos: [6, 4, 0], state: "minecraft:cobblestone"},
        {pos: [6, 4, 1], state: "minecraft:cobblestone"},
        {pos: [6, 4, 2], state: "minecraft:gravel"},
        {pos: [6, 4, 3], state: "minecraft:gravel"},
        {pos: [6, 4, 4], state: "minecraft:gravel"},
        {pos: [6, 4, 5], state: "minecraft:gravel"},
        {pos: [6, 4, 6], state: "minecraft:gravel"},
        {pos: [6, 4, 7], state: "minecraft:gravel"},
        {pos: [6, 4, 8], state: "minecraft:gravel"},
        {pos: [6, 4, 9], state: "minecraft:gravel"},
        {pos: [6, 4, 10], state: "minecraft:cobblestone"},
        {pos: [6, 4, 11], state: "minecraft:cobblestone"},
        {pos: [6, 4, 12], state: "minecraft:cobblestone"},
        {pos: [6, 4, 13], state: "minecraft:cobblestone"},
        {pos: [6, 4, 14], state: "minecraft:cobblestone"},
        {pos: [6, 4, 15], state: "minecraft:cobblestone"},
        {pos: [6, 4, 16], state: "minecraft:air"},
        {pos: [6, 4, 17], state: "minecraft:air"},
        {pos: [6, 4, 18], state: "minecraft:air"},
        {pos: [6, 4, 19], state: "minecraft:air"},
        {pos: [6, 4, 20], state: "minecraft:gravel"},
        {pos: [6, 4, 21], state: "minecraft:cobblestone"},
        {pos: [7, 4, 0], state: "minecraft:cobblestone"},
        {pos: [7, 4, 1], state: "minecraft:gravel"},
        {pos: [7, 4, 2], state: "minecraft:gravel"},
        {pos: [7, 4, 3], state: "minecraft:gravel"},
        {pos: [7, 4, 4], state: "minecraft:gravel"},
        {pos: [7, 4, 5], state: "minecraft:gravel"},
        {pos: [7, 4, 6], state: "minecraft:gravel"},
        {pos: [7, 4, 7], state: "minecraft:gravel"},
        {pos: [7, 4, 8], state: "minecraft:gravel"},
        {pos: [7, 4, 9], state: "minecraft:gravel"},
        {pos: [7, 4, 10], state: "minecraft:cobblestone"},
        {pos: [7, 4, 11], state: "minecraft:cobblestone"},
        {pos: [7, 4, 14], state: "minecraft:cobblestone"},
        {pos: [7, 4, 15], state: "minecraft:gravel"},
        {pos: [7, 4, 16], state: "minecraft:air"},
        {pos: [7, 4, 17], state: "minecraft:air"},
        {pos: [7, 4, 18], state: "minecraft:gravel"},
        {pos: [7, 4, 19], state: "minecraft:gravel"},
        {pos: [7, 4, 20], state: "minecraft:gravel"},
        {pos: [7, 4, 21], state: "minecraft:cobblestone"},
        {pos: [8, 4, 0], state: "minecraft:gravel"},
        {pos: [8, 4, 1], state: "minecraft:gravel"},
        {pos: [8, 4, 2], state: "minecraft:gravel"},
        {pos: [8, 4, 3], state: "minecraft:gravel"},
        {pos: [8, 4, 4], state: "minecraft:gravel"},
        {pos: [8, 4, 5], state: "minecraft:cobblestone_wall{east:tall,north:tall,south:tall,up:false,waterlogged:false,west:tall}"},
        {pos: [8, 4, 6], state: "minecraft:gravel"},
        {pos: [8, 4, 7], state: "minecraft:gravel"},
        {pos: [8, 4, 8], state: "minecraft:gravel"},
        {pos: [8, 4, 9], state: "minecraft:gravel"},
        {pos: [8, 4, 10], state: "minecraft:cobblestone"},
        {pos: [8, 4, 15], state: "minecraft:gravel"},
        {pos: [8, 4, 16], state: "minecraft:gravel"},
        {pos: [8, 4, 17], state: "minecraft:gravel"},
        {pos: [8, 4, 18], state: "minecraft:cobblestone"},
        {pos: [8, 4, 19], state: "minecraft:cobblestone"},
        {pos: [8, 4, 20], state: "minecraft:cobblestone"},
        {pos: [8, 4, 21], state: "minecraft:cobblestone"},
        {pos: [9, 4, 0], state: "minecraft:cobblestone"},
        {pos: [9, 4, 1], state: "minecraft:gravel"},
        {pos: [9, 4, 2], state: "minecraft:gravel"},
        {pos: [9, 4, 3], state: "minecraft:gravel"},
        {pos: [9, 4, 4], state: "minecraft:cobblestone"},
        {pos: [9, 4, 5], state: "minecraft:cobblestone"},
        {pos: [9, 4, 6], state: "minecraft:cobblestone"},
        {pos: [9, 4, 7], state: "minecraft:gravel"},
        {pos: [9, 4, 8], state: "minecraft:gravel"},
        {pos: [9, 4, 9], state: "minecraft:gravel"},
        {pos: [9, 4, 10], state: "minecraft:cobblestone"},
        {pos: [10, 4, 0], state: "minecraft:cobblestone"},
        {pos: [10, 4, 1], state: "minecraft:cobblestone"},
        {pos: [10, 4, 2], state: "minecraft:cobblestone"},
        {pos: [10, 4, 3], state: "minecraft:cobblestone"},
        {pos: [10, 4, 4], state: "minecraft:cobblestone"},
        {pos: [10, 4, 5], state: "minecraft:cobblestone"},
        {pos: [10, 4, 6], state: "minecraft:cobblestone"},
        {pos: [10, 4, 7], state: "minecraft:cobblestone"},
        {pos: [10, 4, 8], state: "minecraft:gravel"},
        {pos: [10, 4, 9], state: "minecraft:cobblestone"},
        {pos: [10, 4, 10], state: "minecraft:cobblestone"},
        {pos: [0, 5, 1], state: "minecraft:cobblestone"},
        {pos: [0, 5, 2], state: "minecraft:gravel"},
        {pos: [0, 5, 3], state: "minecraft:cobblestone"},
        {pos: [0, 5, 4], state: "minecraft:cobblestone"},
        {pos: [0, 5, 5], state: "minecraft:cobblestone"},
        {pos: [0, 5, 6], state: "minecraft:cobblestone"},
        {pos: [0, 5, 7], state: "minecraft:cobblestone"},
        {pos: [0, 5, 8], state: "minecraft:cobblestone"},
        {pos: [0, 5, 9], state: "minecraft:cobblestone"},
        {pos: [1, 5, 0], state: "minecraft:cobblestone"},
        {pos: [1, 5, 1], state: "minecraft:gravel"},
        {pos: [1, 5, 2], state: "minecraft:gravel"},
        {pos: [1, 5, 3], state: "minecraft:gravel"},
        {pos: [1, 5, 4], state: "minecraft:gravel"},
        {pos: [1, 5, 5], state: "minecraft:cobblestone"},
        {pos: [1, 5, 6], state: "minecraft:gravel"},
        {pos: [1, 5, 7], state: "minecraft:gravel"},
        {pos: [1, 5, 8], state: "minecraft:gravel"},
        {pos: [1, 5, 9], state: "minecraft:cobblestone"},
        {pos: [1, 5, 10], state: "minecraft:gravel"},
        {pos: [2, 5, 0], state: "minecraft:cobblestone"},
        {pos: [2, 5, 1], state: "minecraft:gravel"},
        {pos: [2, 5, 2], state: "minecraft:gravel"},
        {pos: [2, 5, 3], state: "minecraft:gravel"},
        {pos: [2, 5, 4], state: "minecraft:gravel"},
        {pos: [2, 5, 5], state: "minecraft:gravel"},
        {pos: [2, 5, 6], state: "minecraft:gravel"},
        {pos: [2, 5, 7], state: "minecraft:gravel"},
        {pos: [2, 5, 8], state: "minecraft:gravel"},
        {pos: [2, 5, 9], state: "minecraft:gravel"},
        {pos: [2, 5, 10], state: "minecraft:cobblestone"},
        {pos: [2, 5, 11], state: "minecraft:cobblestone"},
        {pos: [2, 5, 12], state: "minecraft:cobblestone"},
        {pos: [2, 5, 13], state: "minecraft:cobblestone"},
        {pos: [2, 5, 14], state: "minecraft:gravel"},
        {pos: [2, 5, 15], state: "minecraft:cobblestone"},
        {pos: [2, 5, 16], state: "minecraft:cobblestone"},
        {pos: [2, 5, 17], state: "minecraft:cobblestone"},
        {pos: [2, 5, 18], state: "minecraft:gravel"},
        {pos: [2, 5, 19], state: "minecraft:cobblestone"},
        {pos: [2, 5, 20], state: "minecraft:cobblestone"},
        {pos: [2, 5, 21], state: "minecraft:cobblestone"},
        {pos: [3, 5, 0], state: "minecraft:gravel"},
        {pos: [3, 5, 1], state: "minecraft:gravel"},
        {pos: [3, 5, 2], state: "minecraft:gravel"},
        {pos: [3, 5, 3], state: "minecraft:gravel"},
        {pos: [3, 5, 4], state: "minecraft:gravel"},
        {pos: [3, 5, 5], state: "minecraft:gravel"},
        {pos: [3, 5, 6], state: "minecraft:gravel"},
        {pos: [3, 5, 7], state: "minecraft:gravel"},
        {pos: [3, 5, 8], state: "minecraft:gravel"},
        {pos: [3, 5, 9], state: "minecraft:gravel"},
        {pos: [3, 5, 10], state: "minecraft:cobblestone"},
        {pos: [3, 5, 11], state: "minecraft:cobblestone"},
        {pos: [3, 5, 12], state: "minecraft:cobblestone"},
        {pos: [3, 5, 13], state: "minecraft:cobblestone"},
        {pos: [3, 5, 14], state: "minecraft:cobblestone"},
        {pos: [3, 5, 15], state: "minecraft:cobblestone"},
        {pos: [3, 5, 16], state: "minecraft:cobblestone"},
        {pos: [3, 5, 17], state: "minecraft:air"},
        {pos: [3, 5, 18], state: "minecraft:air"},
        {pos: [3, 5, 19], state: "minecraft:gravel"},
        {pos: [3, 5, 20], state: "minecraft:gravel"},
        {pos: [3, 5, 21], state: "minecraft:cobblestone"},
        {pos: [4, 5, 0], state: "minecraft:gravel"},
        {pos: [4, 5, 1], state: "minecraft:gravel"},
        {pos: [4, 5, 2], state: "minecraft:gravel"},
        {pos: [4, 5, 3], state: "minecraft:gravel"},
        {pos: [4, 5, 4], state: "minecraft:gravel"},
        {pos: [4, 5, 5], state: "minecraft:gravel"},
        {pos: [4, 5, 6], state: "minecraft:gravel"},
        {pos: [4, 5, 7], state: "minecraft:gravel"},
        {pos: [4, 5, 8], state: "minecraft:gravel"},
        {pos: [4, 5, 9], state: "minecraft:gravel"},
        {pos: [4, 5, 10], state: "minecraft:cobblestone"},
        {pos: [4, 5, 11], state: "minecraft:cobblestone"},
        {pos: [4, 5, 12], state: "minecraft:cobblestone"},
        {pos: [4, 5, 13], state: "minecraft:cobblestone"},
        {pos: [4, 5, 14], state: "minecraft:cobblestone"},
        {pos: [4, 5, 15], state: "minecraft:cobblestone"},
        {pos: [4, 5, 16], state: "minecraft:air"},
        {pos: [4, 5, 17], state: "minecraft:air"},
        {pos: [4, 5, 18], state: "minecraft:air"},
        {pos: [4, 5, 19], state: "minecraft:air"},
        {pos: [4, 5, 20], state: "minecraft:emerald_block"},
        {pos: [4, 5, 21], state: "minecraft:cobblestone"},
        {pos: [5, 5, 0], state: "minecraft:cobblestone"},
        {pos: [5, 5, 1], state: "minecraft:cobblestone"},
        {pos: [5, 5, 2], state: "minecraft:gravel"},
        {pos: [5, 5, 3], state: "minecraft:gravel"},
        {pos: [5, 5, 4], state: "minecraft:gravel"},
        {pos: [5, 5, 5], state: "minecraft:cobblestone"},
        {pos: [5, 5, 6], state: "minecraft:cobblestone_stairs{facing:east,half:bottom,shape:straight,waterlogged:false}"},
        {pos: [5, 5, 7], state: "minecraft:gravel"},
        {pos: [5, 5, 8], state: "minecraft:gravel"},
        {pos: [5, 5, 9], state: "minecraft:gravel"},
        {pos: [5, 5, 10], state: "minecraft:cobblestone"},
        {pos: [5, 5, 11], state: "minecraft:cobblestone"},
        {pos: [5, 5, 12], state: "minecraft:cobblestone"},
        {pos: [5, 5, 13], state: "minecraft:cobblestone"},
        {pos: [5, 5, 14], state: "minecraft:cobblestone"},
        {pos: [5, 5, 15], state: "minecraft:cobblestone"},
        {pos: [5, 5, 16], state: "minecraft:air"},
        {pos: [5, 5, 17], state: "minecraft:air"},
        {pos: [5, 5, 18], state: "minecraft:air"},
        {pos: [5, 5, 19], state: "minecraft:air"},
        {pos: [5, 5, 20], state: "minecraft:cobblestone"},
        {pos: [5, 5, 21], state: "minecraft:cobblestone"},
        {pos: [6, 5, 0], state: "minecraft:cobblestone"},
        {pos: [6, 5, 1], state: "minecraft:gravel"},
        {pos: [6, 5, 2], state: "minecraft:gravel"},
        {pos: [6, 5, 3], state: "minecraft:gravel"},
        {pos: [6, 5, 4], state: "minecraft:gravel"},
        {pos: [6, 5, 5], state: "minecraft:cobblestone"},
        {pos: [6, 5, 6], state: "minecraft:cobblestone"},
        {pos: [6, 5, 7], state: "minecraft:gravel"},
        {pos: [6, 5, 8], state: "minecraft:gravel"},
        {pos: [6, 5, 9], state: "minecraft:gravel"},
        {pos: [6, 5, 10], state: "minecraft:cobblestone"},
        {pos: [6, 5, 11], state: "minecraft:cobblestone"},
        {pos: [6, 5, 12], state: "minecraft:cobblestone"},
        {pos: [6, 5, 13], state: "minecraft:cobblestone"},
        {pos: [6, 5, 14], state: "minecraft:cobblestone"},
        {pos: [6, 5, 15], state: "minecraft:gravel"},
        {pos: [6, 5, 16], state: "minecraft:air"},
        {pos: [6, 5, 17], state: "minecraft:air"},
        {pos: [6, 5, 18], state: "minecraft:air"},
        {pos: [6, 5, 19], state: "minecraft:air"},
        {pos: [6, 5, 20], state: "minecraft:emerald_block"},
        {pos: [6, 5, 21], state: "minecraft:cobblestone"},
        {pos: [7, 5, 0], state: "minecraft:cobblestone"},
        {pos: [7, 5, 1], state: "minecraft:gravel"},
        {pos: [7, 5, 2], state: "minecraft:gravel"},
        {pos: [7, 5, 3], state: "minecraft:gravel"},
        {pos: [7, 5, 4], state: "minecraft:gravel"},
        {pos: [7, 5, 5], state: "minecraft:gravel"},
        {pos: [7, 5, 6], state: "minecraft:gravel"},
        {pos: [7, 5, 7], state: "minecraft:gravel"},
        {pos: [7, 5, 8], state: "minecraft:gravel"},
        {pos: [7, 5, 9], state: "minecraft:gravel"},
        {pos: [7, 5, 10], state: "minecraft:cobblestone"},
        {pos: [7, 5, 11], state: "minecraft:cobblestone"},
        {pos: [7, 5, 12], state: "minecraft:cobblestone"},
        {pos: [7, 5, 15], state: "minecraft:cobblestone"},
        {pos: [7, 5, 16], state: "minecraft:air"},
        {pos: [7, 5, 17], state: "minecraft:air"},
        {pos: [7, 5, 18], state: "minecraft:air"},
        {pos: [7, 5, 19], state: "minecraft:air"},
        {pos: [7, 5, 20], state: "minecraft:air"},
        {pos: [7, 5, 21], state: "minecraft:gravel"},
        {pos: [8, 5, 0], state: "minecraft:cobblestone"},
        {pos: [8, 5, 1], state: "minecraft:gravel"},
        {pos: [8, 5, 2], state: "minecraft:gravel"},
        {pos: [8, 5, 3], state: "minecraft:gravel"},
        {pos: [8, 5, 4], state: "minecraft:gravel"},
        {pos: [8, 5, 5], state: "minecraft:gravel"},
        {pos: [8, 5, 6], state: "minecraft:gravel"},
        {pos: [8, 5, 7], state: "minecraft:gravel"},
        {pos: [8, 5, 8], state: "minecraft:gravel"},
        {pos: [8, 5, 9], state: "minecraft:gravel"},
        {pos: [8, 5, 10], state: "minecraft:cobblestone"},
        {pos: [8, 5, 16], state: "minecraft:cobblestone"},
        {pos: [8, 5, 17], state: "minecraft:cobblestone"},
        {pos: [8, 5, 18], state: "minecraft:cobblestone"},
        {pos: [8, 5, 19], state: "minecraft:cobblestone"},
        {pos: [8, 5, 20], state: "minecraft:cobblestone"},
        {pos: [8, 5, 21], state: "minecraft:gravel"},
        {pos: [9, 5, 0], state: "minecraft:cobblestone"},
        {pos: [9, 5, 1], state: "minecraft:gravel"},
        {pos: [9, 5, 2], state: "minecraft:gravel"},
        {pos: [9, 5, 3], state: "minecraft:gravel"},
        {pos: [9, 5, 4], state: "minecraft:gravel"},
        {pos: [9, 5, 5], state: "minecraft:cobblestone"},
        {pos: [9, 5, 6], state: "minecraft:gravel"},
        {pos: [9, 5, 7], state: "minecraft:gravel"},
        {pos: [9, 5, 8], state: "minecraft:gravel"},
        {pos: [9, 5, 9], state: "minecraft:gravel"},
        {pos: [9, 5, 10], state: "minecraft:cobblestone"},
        {pos: [10, 5, 1], state: "minecraft:cobblestone"},
        {pos: [10, 5, 2], state: "minecraft:cobblestone"},
        {pos: [10, 5, 3], state: "minecraft:cobblestone"},
        {pos: [10, 5, 4], state: "minecraft:cobblestone"},
        {pos: [10, 5, 5], state: "minecraft:cobblestone"},
        {pos: [10, 5, 6], state: "minecraft:cobblestone"},
        {pos: [10, 5, 7], state: "minecraft:gravel"},
        {pos: [10, 5, 8], state: "minecraft:cobblestone"},
        {pos: [10, 5, 9], state: "minecraft:cobblestone"},
        {pos: [10, 5, 10], state: "minecraft:cobblestone"},
        {pos: [0, 6, 1], state: "minecraft:gravel"},
        {pos: [0, 6, 2], state: "minecraft:gravel"},
        {pos: [0, 6, 3], state: "minecraft:cobblestone"},
        {pos: [0, 6, 4], state: "minecraft:cobblestone"},
        {pos: [0, 6, 5], state: "minecraft:gravel"},
        {pos: [0, 6, 6], state: "minecraft:cobblestone"},
        {pos: [0, 6, 7], state: "minecraft:cobblestone"},
        {pos: [0, 6, 8], state: "minecraft:cobblestone"},
        {pos: [1, 6, 0], state: "minecraft:gravel"},
        {pos: [1, 6, 1], state: "minecraft:gravel"},
        {pos: [1, 6, 2], state: "minecraft:gravel"},
        {pos: [1, 6, 3], state: "minecraft:gravel"},
        {pos: [1, 6, 4], state: "minecraft:cobblestone"},
        {pos: [1, 6, 5], state: "minecraft:cobblestone"},
        {pos: [1, 6, 6], state: "minecraft:cobblestone"},
        {pos: [1, 6, 7], state: "minecraft:gravel"},
        {pos: [1, 6, 8], state: "minecraft:cobblestone"},
        {pos: [1, 6, 9], state: "minecraft:cobblestone"},
        {pos: [1, 6, 10], state: "minecraft:cobblestone"},
        {pos: [2, 6, 0], state: "minecraft:gravel"},
        {pos: [2, 6, 1], state: "minecraft:gravel"},
        {pos: [2, 6, 2], state: "minecraft:gravel"},
        {pos: [2, 6, 3], state: "minecraft:gravel"},
        {pos: [2, 6, 4], state: "minecraft:gravel"},
        {pos: [2, 6, 5], state: "minecraft:gravel"},
        {pos: [2, 6, 6], state: "minecraft:gravel"},
        {pos: [2, 6, 7], state: "minecraft:gravel"},
        {pos: [2, 6, 8], state: "minecraft:gravel"},
        {pos: [2, 6, 9], state: "minecraft:cobblestone"},
        {pos: [2, 6, 10], state: "minecraft:gravel"},
        {pos: [2, 6, 11], state: "minecraft:gravel"},
        {pos: [2, 6, 15], state: "minecraft:cobblestone"},
        {pos: [2, 6, 16], state: "minecraft:cobblestone"},
        {pos: [2, 6, 17], state: "minecraft:cobblestone"},
        {pos: [2, 6, 18], state: "minecraft:cobblestone"},
        {pos: [2, 6, 19], state: "minecraft:cobblestone"},
        {pos: [2, 6, 20], state: "minecraft:gravel"},
        {pos: [3, 6, 0], state: "minecraft:gravel"},
        {pos: [3, 6, 1], state: "minecraft:gravel"},
        {pos: [3, 6, 2], state: "minecraft:gravel"},
        {pos: [3, 6, 3], state: "minecraft:gravel"},
        {pos: [3, 6, 4], state: "minecraft:gravel"},
        {pos: [3, 6, 5], state: "minecraft:gravel"},
        {pos: [3, 6, 6], state: "minecraft:gravel"},
        {pos: [3, 6, 7], state: "minecraft:gravel"},
        {pos: [3, 6, 8], state: "minecraft:gravel"},
        {pos: [3, 6, 9], state: "minecraft:gravel"},
        {pos: [3, 6, 10], state: "minecraft:cobblestone"},
        {pos: [3, 6, 11], state: "minecraft:cobblestone"},
        {pos: [3, 6, 12], state: "minecraft:cobblestone"},
        {pos: [3, 6, 15], state: "minecraft:cobblestone"},
        {pos: [3, 6, 16], state: "minecraft:cobblestone"},
        {pos: [3, 6, 17], state: "minecraft:cobblestone"},
        {pos: [3, 6, 18], state: "minecraft:cobblestone"},
        {pos: [3, 6, 19], state: "minecraft:air"},
        {pos: [3, 6, 20], state: "minecraft:gravel"},
        {pos: [3, 6, 21], state: "minecraft:cobblestone"},
        {pos: [4, 6, 0], state: "minecraft:cobblestone"},
        {pos: [4, 6, 1], state: "minecraft:gravel"},
        {pos: [4, 6, 2], state: "minecraft:gravel"},
        {pos: [4, 6, 3], state: "minecraft:gravel"},
        {pos: [4, 6, 4], state: "minecraft:gravel"},
        {pos: [4, 6, 5], state: "minecraft:gravel"},
        {pos: [4, 6, 6], state: "minecraft:gravel"},
        {pos: [4, 6, 7], state: "minecraft:gravel"},
        {pos: [4, 6, 8], state: "minecraft:gravel"},
        {pos: [4, 6, 9], state: "minecraft:gravel"},
        {pos: [4, 6, 10], state: "minecraft:cobblestone"},
        {pos: [4, 6, 11], state: "minecraft:cobblestone"},
        {pos: [4, 6, 12], state: "minecraft:cobblestone"},
        {pos: [4, 6, 13], state: "minecraft:cobblestone"},
        {pos: [4, 6, 15], state: "minecraft:cobblestone"},
        {pos: [4, 6, 16], state: "minecraft:cobblestone"},
        {pos: [4, 6, 17], state: "minecraft:cobblestone"},
        {pos: [4, 6, 18], state: "minecraft:air"},
        {pos: [4, 6, 19], state: "minecraft:air"},
        {pos: [4, 6, 20], state: "minecraft:cobblestone"},
        {pos: [4, 6, 21], state: "minecraft:cobblestone"},
        {pos: [5, 6, 0], state: "minecraft:cobblestone"},
        {pos: [5, 6, 1], state: "minecraft:cobblestone"},
        {pos: [5, 6, 2], state: "minecraft:gravel"},
        {pos: [5, 6, 3], state: "minecraft:gravel"},
        {pos: [5, 6, 4], state: "minecraft:cobblestone"},
        {pos: [5, 6, 5], state: "minecraft:cobblestone"},
        {pos: [5, 6, 6], state: "minecraft:gravel"},
        {pos: [5, 6, 7], state: "minecraft:gravel"},
        {pos: [5, 6, 8], state: "minecraft:gravel"},
        {pos: [5, 6, 9], state: "minecraft:gravel"},
        {pos: [5, 6, 10], state: "minecraft:cobblestone"},
        {pos: [5, 6, 11], state: "minecraft:cobblestone"},
        {pos: [5, 6, 12], state: "minecraft:cobblestone"},
        {pos: [5, 6, 13], state: "minecraft:cobblestone"},
        {pos: [5, 6, 14], state: "minecraft:gravel"},
        {pos: [5, 6, 15], state: "minecraft:cobblestone"},
        {pos: [5, 6, 16], state: "minecraft:cobblestone"},
        {pos: [5, 6, 17], state: "minecraft:air"},
        {pos: [5, 6, 18], state: "minecraft:air"},
        {pos: [5, 6, 19], state: "minecraft:air"},
        {pos: [5, 6, 20], state: "minecraft:cobblestone"},
        {pos: [5, 6, 21], state: "minecraft:cobblestone"},
        {pos: [6, 6, 0], state: "minecraft:cobblestone"},
        {pos: [6, 6, 1], state: "minecraft:cobblestone"},
        {pos: [6, 6, 2], state: "minecraft:gravel"},
        {pos: [6, 6, 3], state: "minecraft:gravel"},
        {pos: [6, 6, 4], state: "minecraft:cobblestone"},
        {pos: [6, 6, 5], state: "minecraft:cobblestone_stairs{facing:north,half:bottom,shape:straight,waterlogged:false}"},
        {pos: [6, 6, 6], state: "minecraft:gravel"},
        {pos: [6, 6, 7], state: "minecraft:gravel"},
        {pos: [6, 6, 8], state: "minecraft:gravel"},
        {pos: [6, 6, 9], state: "minecraft:gravel"},
        {pos: [6, 6, 10], state: "minecraft:cobblestone"},
        {pos: [6, 6, 11], state: "minecraft:cobblestone"},
        {pos: [6, 6, 12], state: "minecraft:cobblestone"},
        {pos: [6, 6, 14], state: "minecraft:gravel"},
        {pos: [6, 6, 15], state: "minecraft:cobblestone"},
        {pos: [6, 6, 16], state: "minecraft:cobblestone"},
        {pos: [6, 6, 17], state: "minecraft:air"},
        {pos: [6, 6, 18], state: "minecraft:air"},
        {pos: [6, 6, 19], state: "minecraft:air"},
        {pos: [6, 6, 20], state: "minecraft:cobblestone"},
        {pos: [6, 6, 21], state: "minecraft:gravel"},
        {pos: [7, 6, 0], state: "minecraft:cobblestone"},
        {pos: [7, 6, 1], state: "minecraft:gravel"},
        {pos: [7, 6, 2], state: "minecraft:gravel"},
        {pos: [7, 6, 3], state: "minecraft:gravel"},
        {pos: [7, 6, 4], state: "minecraft:gravel"},
        {pos: [7, 6, 5], state: "minecraft:gravel"},
        {pos: [7, 6, 6], state: "minecraft:gravel"},
        {pos: [7, 6, 7], state: "minecraft:gravel"},
        {pos: [7, 6, 8], state: "minecraft:gravel"},
        {pos: [7, 6, 9], state: "minecraft:gravel"},
        {pos: [7, 6, 10], state: "minecraft:cobblestone"},
        {pos: [7, 6, 11], state: "minecraft:gravel"},
        {pos: [7, 6, 15], state: "minecraft:cobblestone"},
        {pos: [7, 6, 16], state: "minecraft:cobblestone"},
        {pos: [7, 6, 17], state: "minecraft:cobblestone"},
        {pos: [7, 6, 18], state: "minecraft:air"},
        {pos: [7, 6, 19], state: "minecraft:air"},
        {pos: [7, 6, 20], state: "minecraft:air"},
        {pos: [7, 6, 21], state: "minecraft:cobblestone"},
        {pos: [8, 6, 0], state: "minecraft:gravel"},
        {pos: [8, 6, 1], state: "minecraft:gravel"},
        {pos: [8, 6, 2], state: "minecraft:gravel"},
        {pos: [8, 6, 3], state: "minecraft:gravel"},
        {pos: [8, 6, 4], state: "minecraft:gravel"},
        {pos: [8, 6, 5], state: "minecraft:gravel"},
        {pos: [8, 6, 6], state: "minecraft:gravel"},
        {pos: [8, 6, 7], state: "minecraft:gravel"},
        {pos: [8, 6, 8], state: "minecraft:gravel"},
        {pos: [8, 6, 9], state: "minecraft:gravel"},
        {pos: [8, 6, 10], state: "minecraft:cobblestone"},
        {pos: [8, 6, 16], state: "minecraft:cobblestone"},
        {pos: [8, 6, 17], state: "minecraft:cobblestone"},
        {pos: [8, 6, 18], state: "minecraft:cobblestone"},
        {pos: [8, 6, 19], state: "minecraft:cobblestone"},
        {pos: [8, 6, 20], state: "minecraft:cobblestone"},
        {pos: [9, 6, 0], state: "minecraft:gravel"},
        {pos: [9, 6, 1], state: "minecraft:gravel"},
        {pos: [9, 6, 2], state: "minecraft:gravel"},
        {pos: [9, 6, 3], state: "minecraft:gravel"},
        {pos: [9, 6, 4], state: "minecraft:cobblestone"},
        {pos: [9, 6, 5], state: "minecraft:cobblestone"},
        {pos: [9, 6, 6], state: "minecraft:cobblestone"},
        {pos: [9, 6, 7], state: "minecraft:gravel"},
        {pos: [9, 6, 8], state: "minecraft:gravel"},
        {pos: [9, 6, 9], state: "minecraft:gravel"},
        {pos: [9, 6, 10], state: "minecraft:cobblestone"},
        {pos: [10, 6, 1], state: "minecraft:cobblestone"},
        {pos: [10, 6, 2], state: "minecraft:cobblestone"},
        {pos: [10, 6, 3], state: "minecraft:cobblestone"},
        {pos: [10, 6, 4], state: "minecraft:cobblestone"},
        {pos: [10, 6, 5], state: "minecraft:cobblestone"},
        {pos: [10, 6, 6], state: "minecraft:cobblestone"},
        {pos: [10, 6, 7], state: "minecraft:cobblestone"},
        {pos: [10, 6, 8], state: "minecraft:gravel"},
        {pos: [10, 6, 9], state: "minecraft:cobblestone"},
        {pos: [10, 6, 10], state: "minecraft:gravel"},
        {pos: [0, 7, 3], state: "minecraft:cobblestone"},
        {pos: [0, 7, 4], state: "minecraft:cobblestone"},
        {pos: [0, 7, 5], state: "minecraft:gravel"},
        {pos: [0, 7, 6], state: "minecraft:gravel"},
        {pos: [0, 7, 7], state: "minecraft:cobblestone"},
        {pos: [1, 7, 1], state: "minecraft:cobblestone"},
        {pos: [1, 7, 2], state: "minecraft:cobblestone"},
        {pos: [1, 7, 3], state: "minecraft:cobblestone"},
        {pos: [1, 7, 4], state: "minecraft:gravel"},
        {pos: [1, 7, 5], state: "minecraft:gravel"},
        {pos: [1, 7, 6], state: "minecraft:cobblestone"},
        {pos: [1, 7, 7], state: "minecraft:cobblestone"},
        {pos: [1, 7, 8], state: "minecraft:cobblestone"},
        {pos: [2, 7, 1], state: "minecraft:cobblestone"},
        {pos: [2, 7, 2], state: "minecraft:cobblestone"},
        {pos: [2, 7, 3], state: "minecraft:gravel"},
        {pos: [2, 7, 4], state: "minecraft:gravel"},
        {pos: [2, 7, 5], state: "minecraft:gravel"},
        {pos: [2, 7, 6], state: "minecraft:gravel"},
        {pos: [2, 7, 7], state: "minecraft:gravel"},
        {pos: [2, 7, 8], state: "minecraft:cobblestone"},
        {pos: [2, 7, 9], state: "minecraft:cobblestone"},
        {pos: [2, 7, 17], state: "minecraft:gravel"},
        {pos: [2, 7, 18], state: "minecraft:cobblestone"},
        {pos: [3, 7, 0], state: "minecraft:cobblestone"},
        {pos: [3, 7, 1], state: "minecraft:cobblestone"},
        {pos: [3, 7, 2], state: "minecraft:gravel"},
        {pos: [3, 7, 3], state: "minecraft:gravel"},
        {pos: [3, 7, 4], state: "minecraft:gravel"},
        {pos: [3, 7, 5], state: "minecraft:gravel"},
        {pos: [3, 7, 6], state: "minecraft:gravel"},
        {pos: [3, 7, 7], state: "minecraft:gravel"},
        {pos: [3, 7, 8], state: "minecraft:gravel"},
        {pos: [3, 7, 9], state: "minecraft:cobblestone"},
        {pos: [3, 7, 10], state: "minecraft:cobblestone"},
        {pos: [3, 7, 16], state: "minecraft:cobblestone"},
        {pos: [3, 7, 17], state: "minecraft:cobblestone"},
        {pos: [3, 7, 18], state: "minecraft:cobblestone"},
        {pos: [3, 7, 19], state: "minecraft:cobblestone"},
        {pos: [3, 7, 20], state: "minecraft:cobblestone"},
        {pos: [4, 7, 0], state: "minecraft:cobblestone"},
        {pos: [4, 7, 1], state: "minecraft:cobblestone"},
        {pos: [4, 7, 2], state: "minecraft:gravel"},
        {pos: [4, 7, 3], state: "minecraft:gravel"},
        {pos: [4, 7, 4], state: "minecraft:cobblestone"},
        {pos: [4, 7, 5], state: "minecraft:cobblestone"},
        {pos: [4, 7, 6], state: "minecraft:gravel"},
        {pos: [4, 7, 7], state: "minecraft:gravel"},
        {pos: [4, 7, 8], state: "minecraft:gravel"},
        {pos: [4, 7, 9], state: "minecraft:gravel"},
        {pos: [4, 7, 10], state: "minecraft:cobblestone"},
        {pos: [4, 7, 15], state: "minecraft:gravel"},
        {pos: [4, 7, 16], state: "minecraft:cobblestone"},
        {pos: [4, 7, 17], state: "minecraft:cobblestone"},
        {pos: [4, 7, 18], state: "minecraft:cobblestone"},
        {pos: [4, 7, 19], state: "minecraft:cobblestone"},
        {pos: [4, 7, 20], state: "minecraft:cobblestone"},
        {pos: [5, 7, 0], state: "minecraft:cobblestone"},
        {pos: [5, 7, 1], state: "minecraft:cobblestone"},
        {pos: [5, 7, 2], state: "minecraft:gravel"},
        {pos: [5, 7, 3], state: "minecraft:gravel"},
        {pos: [5, 7, 4], state: "minecraft:cobblestone_stairs{facing:west,half:bottom,shape:straight,waterlogged:false}"},
        {pos: [5, 7, 5], state: "minecraft:cobblestone"},
        {pos: [5, 7, 6], state: "minecraft:gravel"},
        {pos: [5, 7, 7], state: "minecraft:gravel"},
        {pos: [5, 7, 8], state: "minecraft:gravel"},
        {pos: [5, 7, 9], state: "minecraft:cobblestone"},
        {pos: [5, 7, 10], state: "minecraft:cobblestone"},
        {pos: [5, 7, 15], state: "minecraft:gravel"},
        {pos: [5, 7, 16], state: "minecraft:cobblestone"},
        {pos: [5, 7, 17], state: "minecraft:cobblestone"},
        {pos: [5, 7, 18], state: "minecraft:cobblestone"},
        {pos: [5, 7, 19], state: "minecraft:cobblestone"},
        {pos: [5, 7, 20], state: "minecraft:cobblestone"},
        {pos: [5, 7, 21], state: "minecraft:cobblestone"},
        {pos: [6, 7, 0], state: "minecraft:cobblestone"},
        {pos: [6, 7, 1], state: "minecraft:cobblestone"},
        {pos: [6, 7, 2], state: "minecraft:gravel"},
        {pos: [6, 7, 3], state: "minecraft:gravel"},
        {pos: [6, 7, 4], state: "minecraft:gravel"},
        {pos: [6, 7, 5], state: "minecraft:gravel"},
        {pos: [6, 7, 6], state: "minecraft:gravel"},
        {pos: [6, 7, 7], state: "minecraft:gravel"},
        {pos: [6, 7, 8], state: "minecraft:gravel"},
        {pos: [6, 7, 9], state: "minecraft:cobblestone"},
        {pos: [6, 7, 10], state: "minecraft:gravel"},
        {pos: [6, 7, 15], state: "minecraft:cobblestone"},
        {pos: [6, 7, 16], state: "minecraft:cobblestone"},
        {pos: [6, 7, 17], state: "minecraft:cobblestone"},
        {pos: [6, 7, 18], state: "minecraft:cobblestone"},
        {pos: [6, 7, 19], state: "minecraft:cobblestone"},
        {pos: [6, 7, 20], state: "minecraft:gravel"},
        {pos: [6, 7, 21], state: "minecraft:cobblestone"},
        {pos: [7, 7, 0], state: "minecraft:cobblestone"},
        {pos: [7, 7, 1], state: "minecraft:cobblestone"},
        {pos: [7, 7, 2], state: "minecraft:gravel"},
        {pos: [7, 7, 3], state: "minecraft:gravel"},
        {pos: [7, 7, 4], state: "minecraft:gravel"},
        {pos: [7, 7, 5], state: "minecraft:gravel"},
        {pos: [7, 7, 6], state: "minecraft:gravel"},
        {pos: [7, 7, 7], state: "minecraft:gravel"},
        {pos: [7, 7, 8], state: "minecraft:cobblestone"},
        {pos: [7, 7, 9], state: "minecraft:cobblestone"},
        {pos: [7, 7, 10], state: "minecraft:cobblestone"},
        {pos: [7, 7, 16], state: "minecraft:cobblestone"},
        {pos: [7, 7, 17], state: "minecraft:cobblestone"},
        {pos: [7, 7, 18], state: "minecraft:cobblestone"},
        {pos: [7, 7, 19], state: "minecraft:cobblestone"},
        {pos: [7, 7, 20], state: "minecraft:cobblestone"},
        {pos: [8, 7, 1], state: "minecraft:cobblestone"},
        {pos: [8, 7, 2], state: "minecraft:cobblestone"},
        {pos: [8, 7, 3], state: "minecraft:gravel"},
        {pos: [8, 7, 4], state: "minecraft:gravel"},
        {pos: [8, 7, 5], state: "minecraft:gravel"},
        {pos: [8, 7, 6], state: "minecraft:gravel"},
        {pos: [8, 7, 7], state: "minecraft:gravel"},
        {pos: [8, 7, 8], state: "minecraft:cobblestone"},
        {pos: [8, 7, 9], state: "minecraft:cobblestone"},
        {pos: [8, 7, 10], state: "minecraft:cobblestone"},
        {pos: [8, 7, 17], state: "minecraft:cobblestone"},
        {pos: [8, 7, 18], state: "minecraft:cobblestone"},
        {pos: [8, 7, 19], state: "minecraft:cobblestone"},
        {pos: [9, 7, 1], state: "minecraft:cobblestone"},
        {pos: [9, 7, 2], state: "minecraft:cobblestone"},
        {pos: [9, 7, 3], state: "minecraft:cobblestone"},
        {pos: [9, 7, 4], state: "minecraft:gravel"},
        {pos: [9, 7, 5], state: "minecraft:gravel"},
        {pos: [9, 7, 6], state: "minecraft:gravel"},
        {pos: [9, 7, 7], state: "minecraft:cobblestone"},
        {pos: [9, 7, 8], state: "minecraft:cobblestone"},
        {pos: [9, 7, 9], state: "minecraft:cobblestone"},
        {pos: [9, 7, 10], state: "minecraft:gravel"},
        {pos: [10, 7, 4], state: "minecraft:cobblestone"},
        {pos: [10, 7, 5], state: "minecraft:cobblestone"},
        {pos: [10, 7, 6], state: "minecraft:cobblestone"},
        {pos: [10, 7, 7], state: "minecraft:cobblestone"},
        {pos: [10, 7, 8], state: "minecraft:cobblestone"},
        {pos: [10, 7, 9], state: "minecraft:gravel"},
        {pos: [1, 8, 3], state: "minecraft:gravel"},
        {pos: [1, 8, 4], state: "minecraft:cobblestone"},
        {pos: [1, 8, 5], state: "minecraft:cobblestone"},
        {pos: [1, 8, 6], state: "minecraft:cobblestone"},
        {pos: [2, 8, 2], state: "minecraft:cobblestone"},
        {pos: [2, 8, 3], state: "minecraft:cobblestone"},
        {pos: [2, 8, 4], state: "minecraft:gravel"},
        {pos: [2, 8, 5], state: "minecraft:gravel"},
        {pos: [2, 8, 6], state: "minecraft:cobblestone"},
        {pos: [2, 8, 7], state: "minecraft:cobblestone"},
        {pos: [2, 8, 8], state: "minecraft:gravel"},
        {pos: [3, 8, 2], state: "minecraft:cobblestone"},
        {pos: [3, 8, 3], state: "minecraft:gravel"},
        {pos: [3, 8, 4], state: "minecraft:gravel"},
        {pos: [3, 8, 5], state: "minecraft:gravel"},
        {pos: [3, 8, 6], state: "minecraft:gravel"},
        {pos: [3, 8, 7], state: "minecraft:cobblestone"},
        {pos: [3, 8, 8], state: "minecraft:cobblestone"},
        {pos: [3, 8, 9], state: "minecraft:cobblestone"},
        {pos: [4, 8, 1], state: "minecraft:cobblestone"},
        {pos: [4, 8, 2], state: "minecraft:cobblestone"},
        {pos: [4, 8, 3], state: "minecraft:gravel"},
        {pos: [4, 8, 4], state: "minecraft:gravel"},
        {pos: [4, 8, 5], state: "minecraft:cobblestone_stairs{facing:south,half:bottom,shape:straight,waterlogged:false}"},
        {pos: [4, 8, 6], state: "minecraft:cobblestone"},
        {pos: [4, 8, 7], state: "minecraft:air"},
        {pos: [4, 8, 8], state: "minecraft:cobblestone"},
        {pos: [4, 8, 9], state: "minecraft:cobblestone"},
        {pos: [5, 8, 1], state: "minecraft:cobblestone"},
        {pos: [5, 8, 2], state: "minecraft:cobblestone"},
        {pos: [5, 8, 3], state: "minecraft:gravel"},
        {pos: [5, 8, 4], state: "minecraft:gravel"},
        {pos: [5, 8, 5], state: "minecraft:cobblestone"},
        {pos: [5, 8, 6], state: "minecraft:cobblestone"},
        {pos: [5, 8, 7], state: "minecraft:cobblestone"},
        {pos: [5, 8, 8], state: "minecraft:cobblestone"},
        {pos: [5, 8, 9], state: "minecraft:cobblestone"},
        {pos: [5, 8, 10], state: "minecraft:gravel"},
        {pos: [6, 8, 1], state: "minecraft:cobblestone"},
        {pos: [6, 8, 2], state: "minecraft:cobblestone"},
        {pos: [6, 8, 3], state: "minecraft:gravel"},
        {pos: [6, 8, 4], state: "minecraft:gravel"},
        {pos: [6, 8, 5], state: "minecraft:gravel"},
        {pos: [6, 8, 6], state: "minecraft:gravel"},
        {pos: [6, 8, 7], state: "minecraft:cobblestone"},
        {pos: [6, 8, 8], state: "minecraft:cobblestone"},
        {pos: [6, 8, 9], state: "minecraft:cobblestone"},
        {pos: [6, 8, 10], state: "minecraft:gravel"},
        {pos: [7, 8, 1], state: "minecraft:cobblestone"},
        {pos: [7, 8, 2], state: "minecraft:cobblestone"},
        {pos: [7, 8, 3], state: "minecraft:cobblestone"},
        {pos: [7, 8, 4], state: "minecraft:cobblestone"},
        {pos: [7, 8, 5], state: "minecraft:gravel"},
        {pos: [7, 8, 6], state: "minecraft:cobblestone"},
        {pos: [7, 8, 7], state: "minecraft:cobblestone"},
        {pos: [7, 8, 8], state: "minecraft:cobblestone"},
        {pos: [7, 8, 9], state: "minecraft:cobblestone"},
        {pos: [8, 8, 2], state: "minecraft:cobblestone"},
        {pos: [8, 8, 3], state: "minecraft:cobblestone"},
        {pos: [8, 8, 4], state: "minecraft:cobblestone"},
        {pos: [8, 8, 5], state: "minecraft:cobblestone"},
        {pos: [8, 8, 6], state: "minecraft:cobblestone"},
        {pos: [8, 8, 7], state: "minecraft:cobblestone"},
        {pos: [8, 8, 8], state: "minecraft:cobblestone"},
        {pos: [8, 8, 9], state: "minecraft:gravel"},
        {pos: [9, 8, 3], state: "minecraft:cobblestone"},
        {pos: [9, 8, 4], state: "minecraft:cobblestone"},
        {pos: [9, 8, 5], state: "minecraft:cobblestone"},
        {pos: [9, 8, 6], state: "minecraft:cobblestone"},
        {pos: [9, 8, 7], state: "minecraft:cobblestone"},
        {pos: [9, 8, 8], state: "minecraft:cobblestone"},
        {pos: [9, 8, 9], state: "minecraft:gravel"},
        {pos: [2, 9, 4], state: "minecraft:cobblestone"},
        {pos: [2, 9, 5], state: "minecraft:cobblestone"},
        {pos: [3, 9, 3], state: "minecraft:cobblestone"},
        {pos: [3, 9, 4], state: "minecraft:cobblestone"},
        {pos: [3, 9, 5], state: "minecraft:cobblestone"},
        {pos: [3, 9, 6], state: "minecraft:cobblestone"},
        {pos: [3, 9, 7], state: "minecraft:cobblestone"},
        {pos: [4, 9, 3], state: "minecraft:cobblestone"},
        {pos: [4, 9, 4], state: "minecraft:gravel"},
        {pos: [4, 9, 5], state: "minecraft:gravel"},
        {pos: [4, 9, 6], state: "minecraft:gravel"},
        {pos: [4, 9, 7], state: "minecraft:cobblestone"},
        {pos: [5, 9, 3], state: "minecraft:cobblestone"},
        {pos: [5, 9, 4], state: "minecraft:gravel"},
        {pos: [5, 9, 5], state: "minecraft:cobblestone"},
        {pos: [5, 9, 6], state: "minecraft:cobblestone_stairs{facing:east,half:bottom,shape:straight,waterlogged:false}"},
        {pos: [5, 9, 7], state: "minecraft:cobblestone"},
        {pos: [5, 9, 8], state: "minecraft:gravel"},
        {pos: [6, 9, 3], state: "minecraft:cobblestone"},
        {pos: [6, 9, 4], state: "minecraft:gravel"},
        {pos: [6, 9, 5], state: "minecraft:cobblestone"},
        {pos: [6, 9, 6], state: "minecraft:cobblestone"},
        {pos: [6, 9, 7], state: "minecraft:cobblestone"},
        {pos: [7, 9, 3], state: "minecraft:cobblestone"},
        {pos: [7, 9, 4], state: "minecraft:cobblestone"},
        {pos: [7, 9, 5], state: "minecraft:cobblestone"},
        {pos: [7, 9, 6], state: "minecraft:cobblestone"},
        {pos: [7, 9, 7], state: "minecraft:cobblestone"},
        {pos: [3, 10, 3], state: "minecraft:cobblestone"},
        {pos: [3, 10, 4], state: "minecraft:cobblestone"},
        {pos: [3, 10, 5], state: "minecraft:cobblestone"},
        {pos: [3, 10, 6], state: "minecraft:cobblestone"},
        {pos: [3, 10, 7], state: "minecraft:gravel"},
        {pos: [4, 10, 3], state: "minecraft:cobblestone"},
        {pos: [4, 10, 4], state: "minecraft:gravel"},
        {pos: [4, 10, 7], state: "minecraft:cobblestone"},
        {pos: [5, 10, 3], state: "minecraft:cobblestone"},
        {pos: [5, 10, 4], state: "minecraft:gravel"},
        {pos: [5, 10, 5], state: "minecraft:cobblestone"},
        {pos: [5, 10, 6], state: "minecraft:gravel"},
        {pos: [5, 10, 7], state: "minecraft:cobblestone"},
        {pos: [6, 10, 3], state: "minecraft:cobblestone"},
        {pos: [6, 10, 4], state: "minecraft:cobblestone"},
        {pos: [6, 10, 5], state: "minecraft:cobblestone_stairs{facing:north,half:bottom,shape:straight,waterlogged:false}"},
        {pos: [6, 10, 6], state: "minecraft:gravel"},
        {pos: [6, 10, 7], state: "minecraft:cobblestone"},
        {pos: [7, 10, 3], state: "minecraft:cobblestone"},
        {pos: [7, 10, 4], state: "minecraft:cobblestone"},
        {pos: [7, 10, 5], state: "minecraft:cobblestone"},
        {pos: [7, 10, 6], state: "minecraft:cobblestone"},
        {pos: [7, 10, 7], state: "minecraft:cobblestone"},
        {pos: [3, 11, 3], state: "minecraft:cobblestone"},
        {pos: [3, 11, 4], state: "minecraft:cobblestone"},
        {pos: [4, 11, 3], state: "minecraft:cobblestone"},
        {pos: [5, 11, 3], state: "minecraft:cobblestone"},
        {pos: [6, 11, 7], state: "minecraft:cobblestone"},
        {pos: [7, 11, 6], state: "minecraft:cobblestone"},
        {pos: [7, 11, 7], state: "minecraft:cobblestone"}
    ],
    entities: [],
    palette: [
        "minecraft:cobblestone",
        "minecraft:gravel",
        "minecraft:emerald_block",
        "minecraft:repeater{delay:1,facing:east,locked:false,powered:false}",
        "minecraft:cobblestone_stairs{facing:west,half:top,shape:straight,waterlogged:false}",
        "minecraft:cobblestone_stairs{facing:north,half:top,shape:straight,waterlogged:false}",
        "minecraft:redstone_wire{east:side,north:none,power:0,south:up,west:none}",
        "minecraft:redstone_wire{east:side,north:up,power:0,south:none,west:none}",
        "minecraft:redstone_wire{east:side,north:none,power:0,south:none,west:side}",
        "minecraft:stone_pressure_plate{powered:false}",
        "minecraft:air",
        "minecraft:cobblestone_stairs{facing:north,half:bottom,shape:straight,waterlogged:false}",
        "minecraft:cobblestone_stairs{facing:east,half:top,shape:straight,waterlogged:false}",
        "minecraft:redstone_wire{east:up,north:side,power:0,south:side,west:none}",
        "minecraft:cobblestone_stairs{facing:west,half:bottom,shape:straight,waterlogged:false}",
        "minecraft:cobblestone_wall{east:tall,north:tall,south:tall,up:false,waterlogged:false,west:tall}",
        "minecraft:redstone_wire{east:none,north:side,power:0,south:side,west:none}",
        "minecraft:redstone_wire{east:none,north:side,power:0,south:side,west:side}",
        "minecraft:cobblestone_stairs{facing:south,half:bottom,shape:straight,waterlogged:false}",
        "minecraft:cobblestone_wall{east:none,north:none,south:low,up:true,waterlogged:false,west:none}",
        "minecraft:cobblestone_stairs{facing:east,half:bottom,shape:straight,waterlogged:false}",
        "minecraft:dispenser{facing:east,triggered:false}"
    ],
    trailiertales_DataVersion: 2
}
