{
    DataVersion: 3953,
    size: [11, 10, 10],
    data: [
        {pos: [0, 0, 7], state: "minecraft:cobblestone"},
        {pos: [0, 0, 8], state: "minecraft:cobblestone"},
        {pos: [1, 0, 6], state: "minecraft:cobblestone"},
        {pos: [1, 0, 7], state: "minecraft:cobblestone"},
        {pos: [1, 0, 8], state: "minecraft:cobblestone"},
        {pos: [1, 0, 9], state: "minecraft:cobblestone"},
        {pos: [2, 0, 2], state: "minecraft:cobblestone"},
        {pos: [2, 0, 3], state: "minecraft:cobblestone"},
        {pos: [2, 0, 4], state: "minecraft:cobblestone"},
        {pos: [2, 0, 6], state: "minecraft:cobblestone"},
        {pos: [2, 0, 7], state: "minecraft:cobblestone"},
        {pos: [2, 0, 8], state: "minecraft:cobblestone"},
        {pos: [2, 0, 9], state: "minecraft:cobblestone"},
        {pos: [3, 0, 1], state: "minecraft:cobblestone"},
        {pos: [3, 0, 2], state: "minecraft:cobblestone"},
        {pos: [3, 0, 3], state: "minecraft:cobblestone"},
        {pos: [3, 0, 4], state: "minecraft:cobblestone"},
        {pos: [3, 0, 6], state: "minecraft:cobblestone"},
        {pos: [3, 0, 7], state: "minecraft:cobblestone"},
        {pos: [3, 0, 8], state: "minecraft:cobblestone"},
        {pos: [3, 0, 9], state: "minecraft:cobblestone"},
        {pos: [4, 0, 1], state: "minecraft:cobblestone"},
        {pos: [4, 0, 2], state: "minecraft:cobblestone"},
        {pos: [4, 0, 3], state: "minecraft:cobblestone"},
        {pos: [4, 0, 7], state: "minecraft:cobblestone"},
        {pos: [4, 0, 8], state: "minecraft:cobblestone"},
        {pos: [6, 0, 1], state: "minecraft:cobblestone"},
        {pos: [6, 0, 2], state: "minecraft:cobblestone"},
        {pos: [7, 0, 1], state: "minecraft:cobblestone"},
        {pos: [7, 0, 2], state: "minecraft:cobblestone"},
        {pos: [7, 0, 3], state: "minecraft:cobblestone"},
        {pos: [8, 0, 0], state: "minecraft:cobblestone"},
        {pos: [8, 0, 1], state: "minecraft:cobblestone"},
        {pos: [8, 0, 2], state: "minecraft:cobblestone"},
        {pos: [8, 0, 3], state: "minecraft:cobblestone"},
        {pos: [9, 0, 0], state: "minecraft:cobblestone"},
        {pos: [9, 0, 1], state: "minecraft:cobblestone"},
        {pos: [9, 0, 2], state: "minecraft:cobblestone"},
        {pos: [10, 0, 0], state: "minecraft:cobblestone"},
        {pos: [10, 0, 1], state: "minecraft:cobblestone"},
        {pos: [1, 1, 6], state: "minecraft:gravel"},
        {pos: [1, 1, 7], state: "minecraft:gravel"},
        {pos: [1, 1, 8], state: "minecraft:gray_glazed_terracotta{facing:west}"},
        {pos: [1, 1, 9], state: "minecraft:gray_glazed_terracotta{facing:south}"},
        {pos: [2, 1, 2], state: "minecraft:gravel"},
        {pos: [2, 1, 3], state: "minecraft:cobblestone"},
        {pos: [2, 1, 4], state: "minecraft:cobblestone"},
        {pos: [2, 1, 6], state: "minecraft:gravel"},
        {pos: [2, 1, 7], state: "minecraft:gravel"},
        {pos: [2, 1, 8], state: "minecraft:gray_glazed_terracotta{facing:north}"},
        {pos: [2, 1, 9], state: "minecraft:gray_glazed_terracotta{facing:east}"},
        {pos: [3, 1, 1], state: "minecraft:gravel"},
        {pos: [3, 1, 2], state: "minecraft:gravel"},
        {pos: [3, 1, 3], state: "minecraft:gravel"},
        {pos: [3, 1, 4], state: "minecraft:cobblestone"},
        {pos: [3, 1, 6], state: "minecraft:gravel"},
        {pos: [3, 1, 7], state: "minecraft:gravel"},
        {pos: [3, 1, 8], state: "minecraft:gravel"},
        {pos: [3, 1, 9], state: "minecraft:gravel"},
        {pos: [4, 1, 1], state: "minecraft:cobblestone"},
        {pos: [4, 1, 2], state: "minecraft:gravel"},
        {pos: [4, 1, 3], state: "minecraft:gravel"},
        {pos: [4, 1, 7], state: "minecraft:gravel"},
        {pos: [4, 1, 8], state: "minecraft:gravel"},
        {pos: [6, 1, 1], state: "minecraft:gravel"},
        {pos: [6, 1, 2], state: "minecraft:gravel"},
        {pos: [7, 1, 1], state: "minecraft:gravel"},
        {pos: [7, 1, 2], state: "minecraft:gravel"},
        {pos: [7, 1, 3], state: "minecraft:gravel"},
        {pos: [8, 1, 0], state: "minecraft:gravel"},
        {pos: [8, 1, 1], state: "minecraft:gravel"},
        {pos: [8, 1, 2], state: "minecraft:cobblestone"},
        {pos: [8, 1, 3], state: "minecraft:gravel"},
        {pos: [9, 1, 0], state: "minecraft:cobblestone"},
        {pos: [9, 1, 1], state: "minecraft:gravel"},
        {pos: [9, 1, 2], state: "minecraft:cobblestone"},
        {pos: [10, 1, 0], state: "minecraft:cobblestone"},
        {pos: [10, 1, 1], state: "minecraft:cobblestone"},
        {pos: [1, 2, 6], state: "minecraft:gravel"},
        {pos: [1, 2, 7], state: "minecraft:gravel"},
        {pos: [1, 2, 8], state: "minecraft:cobblestone"},
        {pos: [1, 2, 9], state: "minecraft:cobblestone"},
        {pos: [2, 2, 2], state: "minecraft:gravel"},
        {pos: [2, 2, 3], state: "minecraft:cobblestone"},
        {pos: [2, 2, 4], state: "minecraft:cobblestone"},
        {pos: [2, 2, 6], state: "minecraft:gravel"},
        {pos: [2, 2, 7], state: "minecraft:gravel"},
        {pos: [2, 2, 8], state: "minecraft:cobblestone"},
        {pos: [2, 2, 9], state: "minecraft:gravel"},
        {pos: [3, 2, 1], state: "minecraft:gravel"},
        {pos: [3, 2, 2], state: "minecraft:gravel"},
        {pos: [3, 2, 3], state: "minecraft:gravel"},
        {pos: [3, 2, 4], state: "minecraft:gravel"},
        {pos: [3, 2, 6], state: "minecraft:gravel"},
        {pos: [3, 2, 7], state: "minecraft:gravel"},
        {pos: [3, 2, 8], state: "minecraft:gravel"},
        {pos: [3, 2, 9], state: "minecraft:gravel"},
        {pos: [4, 2, 1], state: "minecraft:cobblestone"},
        {pos: [4, 2, 2], state: "minecraft:gravel"},
        {pos: [4, 2, 3], state: "minecraft:gravel"},
        {pos: [4, 2, 7], state: "minecraft:gravel"},
        {pos: [4, 2, 8], state: "minecraft:gravel"},
        {pos: [6, 2, 1], state: "minecraft:gravel"},
        {pos: [6, 2, 2], state: "minecraft:gravel"},
        {pos: [7, 2, 1], state: "minecraft:gravel"},
        {pos: [7, 2, 2], state: "minecraft:gravel"},
        {pos: [7, 2, 3], state: "minecraft:gravel"},
        {pos: [8, 2, 0], state: "minecraft:gravel"},
        {pos: [8, 2, 1], state: "minecraft:gravel"},
        {pos: [8, 2, 2], state: "minecraft:gravel"},
        {pos: [8, 2, 3], state: "minecraft:gravel"},
        {pos: [9, 2, 0], state: "minecraft:cobblestone"},
        {pos: [9, 2, 2], state: "minecraft:gravel"},
        {pos: [10, 2, 0], state: "minecraft:cobblestone"},
        {pos: [10, 2, 1], state: "minecraft:cobblestone"},
        {pos: [1, 3, 6], state: "minecraft:gravel"},
        {pos: [1, 3, 7], state: "minecraft:gravel"},
        {pos: [1, 3, 8], state: "minecraft:cobblestone"},
        {pos: [1, 3, 9], state: "minecraft:cobblestone"},
        {pos: [2, 3, 2], state: "minecraft:gravel"},
        {pos: [2, 3, 3], state: "minecraft:gravel"},
        {pos: [2, 3, 4], state: "minecraft:gravel"},
        {pos: [2, 3, 6], state: "minecraft:gravel"},
        {pos: [2, 3, 7], state: "minecraft:gravel"},
        {pos: [2, 3, 8], state: "minecraft:cobblestone"},
        {pos: [2, 3, 9], state: "minecraft:gravel"},
        {pos: [3, 3, 1], state: "minecraft:gravel"},
        {pos: [3, 3, 2], state: "minecraft:gravel"},
        {pos: [3, 3, 7], state: "minecraft:gravel"},
        {pos: [3, 3, 8], state: "minecraft:gravel"},
        {pos: [3, 3, 9], state: "minecraft:gravel"},
        {pos: [4, 3, 1], state: "minecraft:gravel"},
        {pos: [4, 3, 8], state: "minecraft:gravel"},
        {pos: [6, 3, 1], state: "minecraft:gravel"},
        {pos: [6, 3, 2], state: "minecraft:gravel"},
        {pos: [7, 3, 1], state: "minecraft:gravel"},
        {pos: [7, 3, 2], state: "minecraft:gravel"},
        {pos: [7, 3, 3], state: "minecraft:gravel"},
        {pos: [8, 3, 0], state: "minecraft:gravel"},
        {pos: [8, 3, 1], state: "minecraft:gravel"},
        {pos: [8, 3, 2], state: "minecraft:gravel"},
        {pos: [8, 3, 3], state: "minecraft:gravel"},
        {pos: [9, 3, 0], state: "minecraft:cobblestone"},
        {pos: [9, 3, 1], state: "minecraft:cobblestone"},
        {pos: [9, 3, 2], state: "minecraft:gravel"},
        {pos: [10, 3, 0], state: "minecraft:cobblestone"},
        {pos: [10, 3, 1], state: "minecraft:cobblestone"},
        {pos: [1, 4, 7], state: "minecraft:gravel"},
        {pos: [1, 4, 8], state: "minecraft:cobblestone"},
        {pos: [1, 4, 9], state: "minecraft:cobblestone"},
        {pos: [2, 4, 8], state: "minecraft:cobblestone"},
        {pos: [2, 4, 9], state: "minecraft:cobblestone"},
        {pos: [3, 4, 8], state: "minecraft:gravel"},
        {pos: [3, 4, 9], state: "minecraft:gravel"},
        {pos: [8, 4, 1], state: "minecraft:gravel"},
        {pos: [8, 4, 2], state: "minecraft:gravel"},
        {pos: [9, 4, 0], state: "minecraft:cobblestone"},
        {pos: [9, 4, 1], state: "minecraft:cobblestone"},
        {pos: [9, 4, 2], state: "minecraft:gravel"},
        {pos: [10, 4, 0], state: "minecraft:cobblestone"},
        {pos: [10, 4, 1], state: "minecraft:gravel"},
        {pos: [1, 5, 8], state: "minecraft:cobblestone"},
        {pos: [1, 5, 9], state: "minecraft:cobblestone"},
        {pos: [2, 5, 8], state: "minecraft:cobblestone"},
        {pos: [2, 5, 9], state: "minecraft:cobblestone"},
        {pos: [9, 5, 0], state: "minecraft:gray_glazed_terracotta{facing:north}"},
        {pos: [9, 5, 1], state: "minecraft:gray_glazed_terracotta{facing:west}"},
        {pos: [10, 5, 0], state: "minecraft:gray_glazed_terracotta{facing:east}"},
        {pos: [10, 5, 1], state: "minecraft:gray_glazed_terracotta{facing:south}"},
        {pos: [1, 6, 8], state: "minecraft:gravel"},
        {pos: [1, 6, 9], state: "minecraft:cobblestone"},
        {pos: [2, 6, 9], state: "minecraft:gravel"},
        {pos: [9, 6, 0], state: "minecraft:cobblestone"},
        {pos: [9, 6, 1], state: "minecraft:gravel"},
        {pos: [10, 6, 0], state: "minecraft:gravel"},
        {pos: [10, 6, 1], state: "minecraft:gravel"},
        {pos: [9, 7, 0], state: "minecraft:gravel"},
        {pos: [9, 7, 1], state: "minecraft:cobblestone"},
        {pos: [10, 7, 0], state: "minecraft:gravel"},
        {pos: [10, 7, 1], state: "minecraft:gravel"},
        {pos: [9, 8, 1], state: "minecraft:cobblestone"},
        {pos: [10, 8, 0], state: "minecraft:cobblestone"},
        {pos: [10, 8, 1], state: "minecraft:cobblestone"},
        {pos: [9, 9, 1], state: "minecraft:cobblestone"},
        {pos: [10, 9, 1], state: "minecraft:cobblestone"}
    ],
    entities: [],
    palette: [
        "minecraft:cobblestone",
        "minecraft:gravel",
        "minecraft:gray_glazed_terracotta{facing:west}",
        "minecraft:gray_glazed_terracotta{facing:south}",
        "minecraft:gray_glazed_terracotta{facing:north}",
        "minecraft:gray_glazed_terracotta{facing:east}"
    ],
    trailiertales_DataVersion: 2
}
