{
    DataVersion: 3953,
    size: [13, 7, 15],
    data: [
        {pos: [0, 0, 2], state: "minecraft:cobblestone"},
        {pos: [0, 0, 3], state: "minecraft:cobblestone"},
        {pos: [0, 0, 4], state: "minecraft:cobblestone"},
        {pos: [0, 0, 5], state: "minecraft:cobblestone"},
        {pos: [1, 0, 0], state: "minecraft:cobblestone"},
        {pos: [1, 0, 1], state: "minecraft:cobblestone"},
        {pos: [1, 0, 2], state: "minecraft:cobblestone"},
        {pos: [1, 0, 3], state: "minecraft:cobblestone"},
        {pos: [1, 0, 4], state: "minecraft:cobblestone"},
        {pos: [1, 0, 5], state: "minecraft:cobblestone"},
        {pos: [1, 0, 6], state: "minecraft:cobblestone"},
        {pos: [1, 0, 10], state: "minecraft:cobblestone"},
        {pos: [1, 0, 11], state: "minecraft:cobblestone"},
        {pos: [2, 0, 0], state: "minecraft:cobblestone"},
        {pos: [2, 0, 1], state: "minecraft:cobblestone"},
        {pos: [2, 0, 2], state: "minecraft:cobblestone"},
        {pos: [2, 0, 3], state: "minecraft:cobblestone"},
        {pos: [2, 0, 4], state: "minecraft:cobblestone"},
        {pos: [2, 0, 5], state: "minecraft:cobblestone"},
        {pos: [2, 0, 6], state: "minecraft:cobblestone"},
        {pos: [2, 0, 8], state: "minecraft:cobblestone"},
        {pos: [2, 0, 9], state: "minecraft:cobblestone"},
        {pos: [2, 0, 10], state: "minecraft:cobblestone"},
        {pos: [2, 0, 11], state: "minecraft:cobblestone"},
        {pos: [2, 0, 12], state: "minecraft:cobblestone"},
        {pos: [2, 0, 13], state: "minecraft:cobblestone"},
        {pos: [2, 0, 14], state: "minecraft:cobblestone"},
        {pos: [3, 0, 0], state: "minecraft:cobblestone"},
        {pos: [3, 0, 1], state: "minecraft:cobblestone"},
        {pos: [3, 0, 2], state: "minecraft:cobblestone"},
        {pos: [3, 0, 3], state: "minecraft:cobblestone"},
        {pos: [3, 0, 4], state: "minecraft:cobblestone"},
        {pos: [3, 0, 5], state: "minecraft:cobblestone"},
        {pos: [3, 0, 6], state: "minecraft:cobblestone"},
        {pos: [3, 0, 7], state: "minecraft:cobblestone"},
        {pos: [3, 0, 8], state: "minecraft:cobblestone"},
        {pos: [3, 0, 9], state: "minecraft:cobblestone"},
        {pos: [3, 0, 10], state: "minecraft:cobblestone"},
        {pos: [3, 0, 11], state: "minecraft:cobblestone"},
        {pos: [3, 0, 12], state: "minecraft:cobblestone"},
        {pos: [3, 0, 13], state: "minecraft:cobblestone"},
        {pos: [3, 0, 14], state: "minecraft:cobblestone"},
        {pos: [4, 0, 1], state: "minecraft:cobblestone"},
        {pos: [4, 0, 2], state: "minecraft:cobblestone"},
        {pos: [4, 0, 3], state: "minecraft:cobblestone"},
        {pos: [4, 0, 4], state: "minecraft:cobblestone"},
        {pos: [4, 0, 5], state: "minecraft:cobblestone"},
        {pos: [4, 0, 6], state: "minecraft:cobblestone"},
        {pos: [4, 0, 7], state: "minecraft:cobblestone"},
        {pos: [4, 0, 8], state: "minecraft:cobblestone"},
        {pos: [4, 0, 9], state: "minecraft:cobblestone"},
        {pos: [4, 0, 10], state: "minecraft:cobblestone"},
        {pos: [4, 0, 11], state: "minecraft:cobblestone"},
        {pos: [4, 0, 12], state: "minecraft:cobblestone"},
        {pos: [4, 0, 13], state: "minecraft:cobblestone"},
        {pos: [4, 0, 14], state: "minecraft:cobblestone"},
        {pos: [5, 0, 2], state: "minecraft:cobblestone"},
        {pos: [5, 0, 3], state: "minecraft:cobblestone"},
        {pos: [5, 0, 4], state: "minecraft:cobblestone"},
        {pos: [5, 0, 5], state: "minecraft:cobblestone"},
        {pos: [5, 0, 6], state: "minecraft:cobblestone"},
        {pos: [5, 0, 7], state: "minecraft:cobblestone"},
        {pos: [5, 0, 8], state: "minecraft:cobblestone"},
        {pos: [5, 0, 9], state: "minecraft:cobblestone"},
        {pos: [5, 0, 10], state: "minecraft:cobblestone"},
        {pos: [5, 0, 11], state: "minecraft:cobblestone"},
        {pos: [5, 0, 12], state: "minecraft:cobblestone"},
        {pos: [5, 0, 13], state: "minecraft:cobblestone"},
        {pos: [5, 0, 14], state: "minecraft:cobblestone"},
        {pos: [6, 0, 3], state: "minecraft:cobblestone"},
        {pos: [6, 0, 4], state: "minecraft:cobblestone"},
        {pos: [6, 0, 5], state: "minecraft:cobblestone"},
        {pos: [6, 0, 6], state: "minecraft:cobblestone"},
        {pos: [6, 0, 7], state: "minecraft:cobblestone"},
        {pos: [6, 0, 8], state: "minecraft:cobblestone"},
        {pos: [6, 0, 9], state: "minecraft:cobblestone"},
        {pos: [6, 0, 10], state: "minecraft:cobblestone"},
        {pos: [6, 0, 11], state: "minecraft:cobblestone"},
        {pos: [6, 0, 12], state: "minecraft:cobblestone"},
        {pos: [6, 0, 13], state: "minecraft:cobblestone"},
        {pos: [7, 0, 2], state: "minecraft:cobblestone"},
        {pos: [7, 0, 3], state: "minecraft:cobblestone"},
        {pos: [7, 0, 4], state: "minecraft:cobblestone"},
        {pos: [7, 0, 5], state: "minecraft:cobblestone"},
        {pos: [7, 0, 6], state: "minecraft:cobblestone"},
        {pos: [7, 0, 7], state: "minecraft:cobblestone"},
        {pos: [7, 0, 8], state: "minecraft:cobblestone"},
        {pos: [7, 0, 9], state: "minecraft:cobblestone"},
        {pos: [7, 0, 10], state: "minecraft:cobblestone"},
        {pos: [7, 0, 11], state: "minecraft:cobblestone"},
        {pos: [7, 0, 12], state: "minecraft:cobblestone"},
        {pos: [7, 0, 13], state: "minecraft:cobblestone"},
        {pos: [7, 0, 14], state: "minecraft:cobblestone"},
        {pos: [8, 0, 2], state: "minecraft:cobblestone"},
        {pos: [8, 0, 3], state: "minecraft:cobblestone"},
        {pos: [8, 0, 4], state: "minecraft:cobblestone"},
        {pos: [8, 0, 5], state: "minecraft:cobblestone"},
        {pos: [8, 0, 6], state: "minecraft:cobblestone"},
        {pos: [8, 0, 7], state: "minecraft:cobblestone"},
        {pos: [8, 0, 8], state: "minecraft:cobblestone"},
        {pos: [8, 0, 9], state: "minecraft:cobblestone"},
        {pos: [8, 0, 10], state: "minecraft:cobblestone"},
        {pos: [8, 0, 11], state: "minecraft:cobblestone"},
        {pos: [8, 0, 12], state: "minecraft:cobblestone"},
        {pos: [8, 0, 13], state: "minecraft:cobblestone"},
        {pos: [8, 0, 14], state: "minecraft:cobblestone"},
        {pos: [9, 0, 0], state: "minecraft:cobblestone"},
        {pos: [9, 0, 1], state: "minecraft:cobblestone"},
        {pos: [9, 0, 2], state: "minecraft:cobblestone"},
        {pos: [9, 0, 3], state: "minecraft:cobblestone"},
        {pos: [9, 0, 4], state: "minecraft:cobblestone"},
        {pos: [9, 0, 5], state: "minecraft:cobblestone"},
        {pos: [9, 0, 6], state: "minecraft:cobblestone"},
        {pos: [9, 0, 7], state: "minecraft:cobblestone"},
        {pos: [9, 0, 8], state: "minecraft:cobblestone"},
        {pos: [9, 0, 9], state: "minecraft:cobblestone"},
        {pos: [9, 0, 10], state: "minecraft:cobblestone"},
        {pos: [9, 0, 11], state: "minecraft:cobblestone"},
        {pos: [9, 0, 12], state: "minecraft:cobblestone"},
        {pos: [9, 0, 13], state: "minecraft:cobblestone"},
        {pos: [10, 0, 0], state: "minecraft:cobblestone"},
        {pos: [10, 0, 1], state: "minecraft:cobblestone"},
        {pos: [10, 0, 2], state: "minecraft:cobblestone"},
        {pos: [10, 0, 3], state: "minecraft:cobblestone"},
        {pos: [10, 0, 4], state: "minecraft:cobblestone"},
        {pos: [10, 0, 5], state: "minecraft:cobblestone"},
        {pos: [10, 0, 6], state: "minecraft:cobblestone"},
        {pos: [10, 0, 7], state: "minecraft:cobblestone"},
        {pos: [10, 0, 8], state: "minecraft:cobblestone"},
        {pos: [10, 0, 9], state: "minecraft:cobblestone"},
        {pos: [10, 0, 10], state: "minecraft:cobblestone"},
        {pos: [10, 0, 11], state: "minecraft:cobblestone"},
        {pos: [10, 0, 12], state: "minecraft:cobblestone"},
        {pos: [10, 0, 13], state: "minecraft:cobblestone"},
        {pos: [11, 0, 0], state: "minecraft:cobblestone"},
        {pos: [11, 0, 1], state: "minecraft:cobblestone"},
        {pos: [11, 0, 2], state: "minecraft:cobblestone"},
        {pos: [11, 0, 3], state: "minecraft:cobblestone"},
        {pos: [11, 0, 4], state: "minecraft:cobblestone"},
        {pos: [11, 0, 5], state: "minecraft:cobblestone"},
        {pos: [11, 0, 6], state: "minecraft:cobblestone"},
        {pos: [11, 0, 7], state: "minecraft:cobblestone"},
        {pos: [11, 0, 8], state: "minecraft:cobblestone"},
        {pos: [11, 0, 9], state: "minecraft:cobblestone"},
        {pos: [11, 0, 10], state: "minecraft:cobblestone"},
        {pos: [11, 0, 11], state: "minecraft:cobblestone"},
        {pos: [11, 0, 12], state: "minecraft:cobblestone"},
        {pos: [12, 0, 1], state: "minecraft:cobblestone"},
        {pos: [12, 0, 2], state: "minecraft:cobblestone"},
        {pos: [12, 0, 3], state: "minecraft:cobblestone"},
        {pos: [12, 0, 4], state: "minecraft:gravel"},
        {pos: [12, 0, 5], state: "minecraft:cobblestone"},
        {pos: [12, 0, 6], state: "minecraft:cobblestone"},
        {pos: [12, 0, 7], state: "minecraft:cobblestone"},
        {pos: [12, 0, 8], state: "minecraft:cobblestone"},
        {pos: [12, 0, 9], state: "minecraft:cobblestone"},
        {pos: [0, 1, 2], state: "minecraft:gravel"},
        {pos: [0, 1, 3], state: "minecraft:gravel"},
        {pos: [0, 1, 4], state: "minecraft:gravel"},
        {pos: [1, 1, 0], state: "minecraft:gravel"},
        {pos: [1, 1, 1], state: "minecraft:cobblestone"},
        {pos: [1, 1, 2], state: "minecraft:cobblestone"},
        {pos: [1, 1, 3], state: "minecraft:cobblestone"},
        {pos: [1, 1, 4], state: "minecraft:cobblestone"},
        {pos: [1, 1, 5], state: "minecraft:cobblestone"},
        {pos: [1, 1, 6], state: "minecraft:gravel"},
        {pos: [1, 1, 10], state: "minecraft:gravel"},
        {pos: [1, 1, 11], state: "minecraft:gravel"},
        {pos: [2, 1, 0], state: "minecraft:gravel"},
        {pos: [2, 1, 1], state: "minecraft:gravel"},
        {pos: [2, 1, 2], state: "minecraft:cobblestone"},
        {pos: [2, 1, 3], state: "minecraft:cobblestone"},
        {pos: [2, 1, 4], state: "minecraft:cobblestone"},
        {pos: [2, 1, 5], state: "minecraft:cobblestone"},
        {pos: [2, 1, 6], state: "minecraft:cobblestone"},
        {pos: [2, 1, 8], state: "minecraft:gravel"},
        {pos: [2, 1, 9], state: "minecraft:gravel"},
        {pos: [2, 1, 10], state: "minecraft:gravel"},
        {pos: [2, 1, 11], state: "minecraft:cobblestone"},
        {pos: [2, 1, 12], state: "minecraft:cobblestone"},
        {pos: [2, 1, 13], state: "minecraft:gravel"},
        {pos: [2, 1, 14], state: "minecraft:gravel"},
        {pos: [3, 1, 0], state: "minecraft:gravel"},
        {pos: [3, 1, 1], state: "minecraft:cobblestone"},
        {pos: [3, 1, 2], state: "minecraft:cobblestone"},
        {pos: [3, 1, 3], state: "minecraft:cobblestone"},
        {pos: [3, 1, 4], state: "minecraft:cobblestone"},
        {pos: [3, 1, 5], state: "minecraft:cobblestone"},
        {pos: [3, 1, 6], state: "minecraft:cobblestone"},
        {pos: [3, 1, 7], state: "minecraft:gravel"},
        {pos: [3, 1, 8], state: "minecraft:cobblestone"},
        {pos: [3, 1, 9], state: "minecraft:cobblestone"},
        {pos: [3, 1, 10], state: "minecraft:cobblestone"},
        {pos: [3, 1, 11], state: "minecraft:cobblestone"},
        {pos: [3, 1, 12], state: "minecraft:cobblestone"},
        {pos: [3, 1, 13], state: "minecraft:cobblestone"},
        {pos: [3, 1, 14], state: "minecraft:gravel"},
        {pos: [4, 1, 1], state: "minecraft:gravel"},
        {pos: [4, 1, 2], state: "minecraft:gravel"},
        {pos: [4, 1, 3], state: "minecraft:gravel"},
        {pos: [4, 1, 4], state: "minecraft:cobblestone_stairs{facing:south,half:top,shape:straight,waterlogged:false}"},
        {pos: [4, 1, 5], state: "minecraft:cobblestone"},
        {pos: [4, 1, 6], state: "minecraft:cobblestone"},
        {pos: [4, 1, 7], state: "minecraft:gravel"},
        {pos: [4, 1, 8], state: "minecraft:gravel"},
        {pos: [4, 1, 9], state: "minecraft:gravel"},
        {pos: [4, 1, 10], state: "minecraft:gravel"},
        {pos: [4, 1, 11], state: "minecraft:gravel"},
        {pos: [4, 1, 12], state: "minecraft:cobblestone"},
        {pos: [4, 1, 13], state: "minecraft:cobblestone"},
        {pos: [4, 1, 14], state: "minecraft:gravel"},
        {pos: [5, 1, 2], state: "minecraft:gravel"},
        {pos: [5, 1, 3], state: "minecraft:gravel"},
        {pos: [5, 1, 4], state: "minecraft:gravel"},
        {pos: [5, 1, 5], state: "minecraft:cobblestone"},
        {pos: [5, 1, 6], state: "minecraft:cobblestone"},
        {pos: [5, 1, 7], state: "minecraft:cobblestone"},
        {pos: [5, 1, 8], state: "minecraft:cobblestone"},
        {pos: [5, 1, 9], state: "minecraft:gravel"},
        {pos: [5, 1, 10], state: "minecraft:gravel"},
        {pos: [5, 1, 11], state: "minecraft:cobblestone_stairs{facing:south,half:top,shape:straight,waterlogged:false}"},
        {pos: [5, 1, 12], state: "minecraft:cobblestone"},
        {pos: [5, 1, 13], state: "minecraft:gravel"},
        {pos: [5, 1, 14], state: "minecraft:gravel"},
        {pos: [6, 1, 3], state: "minecraft:gravel"},
        {pos: [6, 1, 4], state: "minecraft:cobblestone_stairs{facing:south,half:top,shape:straight,waterlogged:false}"},
        {pos: [6, 1, 5], state: "minecraft:cobblestone"},
        {pos: [6, 1, 6], state: "minecraft:cobblestone"},
        {pos: [6, 1, 7], state: "minecraft:cobblestone"},
        {pos: [6, 1, 8], state: "minecraft:cobblestone"},
        {pos: [6, 1, 9], state: "minecraft:gravel"},
        {pos: [6, 1, 10], state: "minecraft:gravel"},
        {pos: [6, 1, 11], state: "minecraft:cobblestone_stairs{facing:south,half:top,shape:straight,waterlogged:false}"},
        {pos: [6, 1, 12], state: "minecraft:cobblestone"},
        {pos: [6, 1, 13], state: "minecraft:gravel"},
        {pos: [7, 1, 2], state: "minecraft:gravel"},
        {pos: [7, 1, 3], state: "minecraft:gravel"},
        {pos: [7, 1, 4], state: "minecraft:cobblestone_stairs{facing:south,half:top,shape:straight,waterlogged:false}"},
        {pos: [7, 1, 5], state: "minecraft:cobblestone"},
        {pos: [7, 1, 6], state: "minecraft:gravel"},
        {pos: [7, 1, 7], state: "minecraft:cobblestone"},
        {pos: [7, 1, 8], state: "minecraft:cobblestone"},
        {pos: [7, 1, 9], state: "minecraft:gravel"},
        {pos: [7, 1, 10], state: "minecraft:gravel"},
        {pos: [7, 1, 11], state: "minecraft:cobblestone_stairs{facing:south,half:top,shape:straight,waterlogged:false}"},
        {pos: [7, 1, 12], state: "minecraft:cobblestone"},
        {pos: [7, 1, 13], state: "minecraft:cobblestone"},
        {pos: [7, 1, 14], state: "minecraft:gravel"},
        {pos: [8, 1, 2], state: "minecraft:gravel"},
        {pos: [8, 1, 3], state: "minecraft:gravel"},
        {pos: [8, 1, 4], state: "minecraft:cobblestone_stairs{facing:south,half:top,shape:straight,waterlogged:false}"},
        {pos: [8, 1, 5], state: "minecraft:cobblestone"},
        {pos: [8, 1, 6], state: "minecraft:gravel"},
        {pos: [8, 1, 7], state: "minecraft:gravel"},
        {pos: [8, 1, 8], state: "minecraft:gravel"},
        {pos: [8, 1, 9], state: "minecraft:gravel"},
        {pos: [8, 1, 10], state: "minecraft:gravel"},
        {pos: [8, 1, 11], state: "minecraft:gravel"},
        {pos: [8, 1, 12], state: "minecraft:cobblestone"},
        {pos: [8, 1, 13], state: "minecraft:cobblestone"},
        {pos: [8, 1, 14], state: "minecraft:gravel"},
        {pos: [9, 1, 0], state: "minecraft:gravel"},
        {pos: [9, 1, 1], state: "minecraft:gravel"},
        {pos: [9, 1, 2], state: "minecraft:cobblestone"},
        {pos: [9, 1, 3], state: "minecraft:cobblestone"},
        {pos: [9, 1, 4], state: "minecraft:cobblestone"},
        {pos: [9, 1, 5], state: "minecraft:cobblestone"},
        {pos: [9, 1, 6], state: "minecraft:cobblestone"},
        {pos: [9, 1, 7], state: "minecraft:cobblestone"},
        {pos: [9, 1, 8], state: "minecraft:cobblestone"},
        {pos: [9, 1, 9], state: "minecraft:cobblestone"},
        {pos: [9, 1, 10], state: "minecraft:cobblestone"},
        {pos: [9, 1, 11], state: "minecraft:cobblestone"},
        {pos: [9, 1, 12], state: "minecraft:cobblestone"},
        {pos: [9, 1, 13], state: "minecraft:cobblestone"},
        {pos: [10, 1, 0], state: "minecraft:gravel"},
        {pos: [10, 1, 1], state: "minecraft:cobblestone"},
        {pos: [10, 1, 2], state: "minecraft:cobblestone"},
        {pos: [10, 1, 3], state: "minecraft:cobblestone"},
        {pos: [10, 1, 4], state: "minecraft:cobblestone"},
        {pos: [10, 1, 5], state: "minecraft:cobblestone"},
        {pos: [10, 1, 6], state: "minecraft:cobblestone"},
        {pos: [10, 1, 7], state: "minecraft:cobblestone"},
        {pos: [10, 1, 8], state: "minecraft:cobblestone"},
        {pos: [10, 1, 9], state: "minecraft:cobblestone"},
        {pos: [10, 1, 10], state: "minecraft:gravel"},
        {pos: [10, 1, 11], state: "minecraft:cobblestone"},
        {pos: [10, 1, 12], state: "minecraft:cobblestone"},
        {pos: [10, 1, 13], state: "minecraft:gravel"},
        {pos: [11, 1, 0], state: "minecraft:gravel"},
        {pos: [11, 1, 1], state: "minecraft:cobblestone"},
        {pos: [11, 1, 2], state: "minecraft:cobblestone"},
        {pos: [11, 1, 3], state: "minecraft:cobblestone"},
        {pos: [11, 1, 4], state: "minecraft:cobblestone"},
        {pos: [11, 1, 5], state: "minecraft:cobblestone"},
        {pos: [11, 1, 6], state: "minecraft:cobblestone"},
        {pos: [11, 1, 7], state: "minecraft:cobblestone"},
        {pos: [11, 1, 8], state: "minecraft:gravel"},
        {pos: [11, 1, 9], state: "minecraft:gravel"},
        {pos: [11, 1, 10], state: "minecraft:gravel"},
        {pos: [11, 1, 11], state: "minecraft:gravel"},
        {pos: [11, 1, 12], state: "minecraft:gravel"},
        {pos: [12, 1, 1], state: "minecraft:gravel"},
        {pos: [12, 1, 2], state: "minecraft:cobblestone"},
        {pos: [12, 1, 3], state: "minecraft:cobblestone"},
        {pos: [12, 1, 4], state: "minecraft:gravel"},
        {pos: [12, 1, 5], state: "minecraft:gravel"},
        {pos: [12, 1, 6], state: "minecraft:gravel"},
        {pos: [12, 1, 7], state: "minecraft:gravel"},
        {pos: [12, 1, 8], state: "minecraft:gravel"},
        {pos: [12, 1, 9], state: "minecraft:gravel"},
        {pos: [0, 2, 2], state: "minecraft:gravel"},
        {pos: [0, 2, 3], state: "minecraft:gravel"},
        {pos: [1, 2, 1], state: "minecraft:gravel"},
        {pos: [1, 2, 2], state: "minecraft:cobblestone"},
        {pos: [1, 2, 3], state: "minecraft:cobblestone"},
        {pos: [1, 2, 4], state: "minecraft:cobblestone"},
        {pos: [1, 2, 5], state: "minecraft:gravel"},
        {pos: [2, 2, 1], state: "minecraft:gravel"},
        {pos: [2, 2, 2], state: "minecraft:cobblestone"},
        {pos: [2, 2, 3], state: "minecraft:cobblestone"},
        {pos: [2, 2, 4], state: "minecraft:cobblestone"},
        {pos: [2, 2, 5], state: "minecraft:cobblestone"},
        {pos: [2, 2, 6], state: "minecraft:gravel"},
        {pos: [2, 2, 11], state: "minecraft:gravel"},
        {pos: [2, 2, 12], state: "minecraft:gravel"},
        {pos: [2, 2, 13], state: "minecraft:gravel"},
        {pos: [3, 2, 1], state: "minecraft:gravel"},
        {pos: [3, 2, 2], state: "minecraft:gravel"},
        {pos: [3, 2, 3], state: "minecraft:cobblestone"},
        {pos: [3, 2, 4], state: "minecraft:cobblestone"},
        {pos: [3, 2, 5], state: "minecraft:cobblestone"},
        {pos: [3, 2, 6], state: "minecraft:gravel"},
        {pos: [3, 2, 7], state: "minecraft:gravel"},
        {pos: [3, 2, 8], state: "minecraft:gravel"},
        {pos: [3, 2, 9], state: "minecraft:gravel"},
        {pos: [3, 2, 10], state: "minecraft:cobblestone"},
        {pos: [3, 2, 11], state: "minecraft:cobblestone"},
        {pos: [3, 2, 12], state: "minecraft:cobblestone"},
        {pos: [3, 2, 13], state: "minecraft:gravel"},
        {pos: [3, 2, 14], state: "minecraft:gravel"},
        {pos: [4, 2, 1], state: "minecraft:gravel"},
        {pos: [4, 2, 2], state: "minecraft:gravel"},
        {pos: [4, 2, 3], state: "minecraft:gravel"},
        {pos: [4, 2, 4], state: "minecraft:gravel"},
        {pos: [4, 2, 5], state: "minecraft:cobblestone"},
        {pos: [4, 2, 6], state: "minecraft:cobblestone"},
        {pos: [4, 2, 7], state: "minecraft:gravel"},
        {pos: [4, 2, 8], state: "minecraft:gravel"},
        {pos: [4, 2, 9], state: "minecraft:gravel"},
        {pos: [4, 2, 10], state: "minecraft:gravel"},
        {pos: [4, 2, 11], state: "minecraft:gravel"},
        {pos: [4, 2, 12], state: "minecraft:cobblestone"},
        {pos: [4, 2, 13], state: "minecraft:gravel"},
        {pos: [4, 2, 14], state: "minecraft:gravel"},
        {pos: [5, 2, 2], state: "minecraft:gravel"},
        {pos: [5, 2, 3], state: "minecraft:gravel"},
        {pos: [5, 2, 4], state: "minecraft:gravel"},
        {pos: [5, 2, 5], state: "minecraft:cobblestone"},
        {pos: [5, 2, 6], state: "minecraft:cobblestone"},
        {pos: [5, 2, 7], state: "minecraft:cobblestone"},
        {pos: [5, 2, 8], state: "minecraft:gravel"},
        {pos: [5, 2, 9], state: "minecraft:gravel"},
        {pos: [5, 2, 10], state: "minecraft:gravel"},
        {pos: [5, 2, 11], state: "minecraft:gravel"},
        {pos: [5, 2, 12], state: "minecraft:gravel"},
        {pos: [5, 2, 13], state: "minecraft:gravel"},
        {pos: [6, 2, 3], state: "minecraft:gravel"},
        {pos: [6, 2, 4], state: "minecraft:gravel"},
        {pos: [6, 2, 5], state: "minecraft:cobblestone"},
        {pos: [6, 2, 6], state: "minecraft:cobblestone"},
        {pos: [6, 2, 7], state: "minecraft:cobblestone"},
        {pos: [6, 2, 8], state: "minecraft:gravel"},
        {pos: [6, 2, 9], state: "minecraft:gravel"},
        {pos: [6, 2, 10], state: "minecraft:gravel"},
        {pos: [6, 2, 11], state: "minecraft:gravel"},
        {pos: [6, 2, 12], state: "minecraft:gravel"},
        {pos: [7, 2, 2], state: "minecraft:gravel"},
        {pos: [7, 2, 3], state: "minecraft:gravel"},
        {pos: [7, 2, 4], state: "minecraft:gravel"},
        {pos: [7, 2, 5], state: "minecraft:cobblestone"},
        {pos: [7, 2, 6], state: "minecraft:gravel"},
        {pos: [7, 2, 7], state: "minecraft:cobblestone"},
        {pos: [7, 2, 8], state: "minecraft:gravel"},
        {pos: [7, 2, 9], state: "minecraft:gravel"},
        {pos: [7, 2, 10], state: "minecraft:gravel"},
        {pos: [7, 2, 11], state: "minecraft:gravel"},
        {pos: [7, 2, 12], state: "minecraft:cobblestone"},
        {pos: [7, 2, 13], state: "minecraft:gravel"},
        {pos: [8, 2, 2], state: "minecraft:gravel"},
        {pos: [8, 2, 3], state: "minecraft:gravel"},
        {pos: [8, 2, 4], state: "minecraft:gravel"},
        {pos: [8, 2, 5], state: "minecraft:cobblestone"},
        {pos: [8, 2, 6], state: "minecraft:gravel"},
        {pos: [8, 2, 7], state: "minecraft:gravel"},
        {pos: [8, 2, 8], state: "minecraft:gravel"},
        {pos: [8, 2, 9], state: "minecraft:gravel"},
        {pos: [8, 2, 10], state: "minecraft:gravel"},
        {pos: [8, 2, 11], state: "minecraft:gravel"},
        {pos: [8, 2, 12], state: "minecraft:cobblestone"},
        {pos: [8, 2, 13], state: "minecraft:gravel"},
        {pos: [9, 2, 1], state: "minecraft:gravel"},
        {pos: [9, 2, 2], state: "minecraft:cobblestone"},
        {pos: [9, 2, 3], state: "minecraft:cobblestone"},
        {pos: [9, 2, 4], state: "minecraft:cobblestone"},
        {pos: [9, 2, 5], state: "minecraft:cobblestone"},
        {pos: [9, 2, 6], state: "minecraft:cobblestone"},
        {pos: [9, 2, 7], state: "minecraft:cobblestone"},
        {pos: [9, 2, 8], state: "minecraft:cobblestone"},
        {pos: [9, 2, 9], state: "minecraft:cobblestone"},
        {pos: [9, 2, 10], state: "minecraft:gravel"},
        {pos: [9, 2, 11], state: "minecraft:cobblestone"},
        {pos: [9, 2, 12], state: "minecraft:cobblestone"},
        {pos: [9, 2, 13], state: "minecraft:gravel"},
        {pos: [10, 2, 1], state: "minecraft:gravel"},
        {pos: [10, 2, 2], state: "minecraft:cobblestone"},
        {pos: [10, 2, 3], state: "minecraft:cobblestone"},
        {pos: [10, 2, 4], state: "minecraft:cobblestone"},
        {pos: [10, 2, 5], state: "minecraft:cobblestone"},
        {pos: [10, 2, 6], state: "minecraft:cobblestone"},
        {pos: [10, 2, 7], state: "minecraft:cobblestone"},
        {pos: [10, 2, 8], state: "minecraft:gravel"},
        {pos: [10, 2, 9], state: "minecraft:gravel"},
        {pos: [10, 2, 10], state: "minecraft:gravel"},
        {pos: [10, 2, 11], state: "minecraft:gravel"},
        {pos: [10, 2, 12], state: "minecraft:gravel"},
        {pos: [10, 2, 13], state: "minecraft:gravel"},
        {pos: [11, 2, 1], state: "minecraft:gravel"},
        {pos: [11, 2, 2], state: "minecraft:cobblestone"},
        {pos: [11, 2, 3], state: "minecraft:cobblestone"},
        {pos: [11, 2, 4], state: "minecraft:cobblestone"},
        {pos: [11, 2, 5], state: "minecraft:cobblestone"},
        {pos: [11, 2, 6], state: "minecraft:cobblestone"},
        {pos: [11, 2, 7], state: "minecraft:gravel"},
        {pos: [12, 2, 1], state: "minecraft:gravel"},
        {pos: [12, 2, 2], state: "minecraft:cobblestone"},
        {pos: [12, 2, 3], state: "minecraft:cobblestone"},
        {pos: [12, 2, 4], state: "minecraft:gravel"},
        {pos: [12, 2, 5], state: "minecraft:gravel"},
        {pos: [12, 2, 6], state: "minecraft:gravel"},
        {pos: [1, 3, 2], state: "minecraft:gravel"},
        {pos: [1, 3, 3], state: "minecraft:cobblestone"},
        {pos: [1, 3, 4], state: "minecraft:cobblestone"},
        {pos: [2, 3, 2], state: "minecraft:gravel"},
        {pos: [2, 3, 3], state: "minecraft:cobblestone"},
        {pos: [2, 3, 4], state: "minecraft:cobblestone"},
        {pos: [2, 3, 5], state: "minecraft:gravel"},
        {pos: [3, 3, 2], state: "minecraft:gravel"},
        {pos: [3, 3, 3], state: "minecraft:cobblestone"},
        {pos: [3, 3, 4], state: "minecraft:cobblestone"},
        {pos: [3, 3, 5], state: "minecraft:cobblestone"},
        {pos: [3, 3, 6], state: "minecraft:gravel"},
        {pos: [3, 3, 10], state: "minecraft:cobblestone"},
        {pos: [3, 3, 11], state: "minecraft:gravel"},
        {pos: [3, 3, 12], state: "minecraft:cobblestone"},
        {pos: [3, 3, 13], state: "minecraft:gravel"},
        {pos: [4, 3, 2], state: "minecraft:gravel"},
        {pos: [4, 3, 3], state: "minecraft:gravel"},
        {pos: [4, 3, 4], state: "minecraft:cobblestone"},
        {pos: [4, 3, 5], state: "minecraft:cobblestone"},
        {pos: [4, 3, 6], state: "minecraft:gravel"},
        {pos: [4, 3, 10], state: "minecraft:gravel"},
        {pos: [4, 3, 11], state: "minecraft:gravel"},
        {pos: [4, 3, 12], state: "minecraft:cobblestone"},
        {pos: [4, 3, 13], state: "minecraft:gravel"},
        {pos: [5, 3, 3], state: "minecraft:gravel"},
        {pos: [5, 3, 4], state: "minecraft:cobblestone"},
        {pos: [5, 3, 5], state: "minecraft:cobblestone"},
        {pos: [5, 3, 6], state: "minecraft:cobblestone"},
        {pos: [5, 3, 7], state: "minecraft:gravel"},
        {pos: [5, 3, 10], state: "minecraft:gravel"},
        {pos: [5, 3, 11], state: "minecraft:gravel"},
        {pos: [5, 3, 12], state: "minecraft:gravel"},
        {pos: [6, 3, 4], state: "minecraft:cobblestone"},
        {pos: [6, 3, 5], state: "minecraft:cobblestone"},
        {pos: [6, 3, 6], state: "minecraft:cobblestone"},
        {pos: [6, 3, 7], state: "minecraft:gravel"},
        {pos: [6, 3, 8], state: "minecraft:gravel"},
        {pos: [6, 3, 11], state: "minecraft:gravel"},
        {pos: [6, 3, 12], state: "minecraft:gravel"},
        {pos: [7, 3, 4], state: "minecraft:cobblestone"},
        {pos: [7, 3, 5], state: "minecraft:cobblestone"},
        {pos: [7, 3, 6], state: "minecraft:cobblestone"},
        {pos: [7, 3, 7], state: "minecraft:gravel"},
        {pos: [7, 3, 8], state: "minecraft:gravel"},
        {pos: [7, 3, 11], state: "minecraft:gravel"},
        {pos: [7, 3, 12], state: "minecraft:gravel"},
        {pos: [8, 3, 3], state: "minecraft:gravel"},
        {pos: [8, 3, 4], state: "minecraft:cobblestone"},
        {pos: [8, 3, 5], state: "minecraft:cobblestone"},
        {pos: [8, 3, 6], state: "minecraft:gravel"},
        {pos: [8, 3, 7], state: "minecraft:gravel"},
        {pos: [8, 3, 8], state: "minecraft:gravel"},
        {pos: [8, 3, 10], state: "minecraft:gravel"},
        {pos: [8, 3, 11], state: "minecraft:gravel"},
        {pos: [8, 3, 12], state: "minecraft:cobblestone"},
        {pos: [9, 3, 2], state: "minecraft:gravel"},
        {pos: [9, 3, 3], state: "minecraft:cobblestone"},
        {pos: [9, 3, 4], state: "minecraft:cobblestone"},
        {pos: [9, 3, 5], state: "minecraft:cobblestone"},
        {pos: [9, 3, 6], state: "minecraft:cobblestone"},
        {pos: [9, 3, 7], state: "minecraft:cobblestone"},
        {pos: [9, 3, 8], state: "minecraft:cobblestone"},
        {pos: [9, 3, 9], state: "minecraft:gravel"},
        {pos: [9, 3, 10], state: "minecraft:gravel"},
        {pos: [9, 3, 11], state: "minecraft:gravel"},
        {pos: [9, 3, 12], state: "minecraft:cobblestone"},
        {pos: [10, 3, 2], state: "minecraft:gravel"},
        {pos: [10, 3, 3], state: "minecraft:cobblestone"},
        {pos: [10, 3, 4], state: "minecraft:cobblestone"},
        {pos: [10, 3, 5], state: "minecraft:cobblestone"},
        {pos: [10, 3, 6], state: "minecraft:cobblestone"},
        {pos: [10, 3, 7], state: "minecraft:gravel"},
        {pos: [10, 3, 8], state: "minecraft:gravel"},
        {pos: [10, 3, 9], state: "minecraft:gravel"},
        {pos: [10, 3, 10], state: "minecraft:gravel"},
        {pos: [11, 3, 2], state: "minecraft:gravel"},
        {pos: [11, 3, 3], state: "minecraft:cobblestone"},
        {pos: [11, 3, 4], state: "minecraft:cobblestone"},
        {pos: [11, 3, 5], state: "minecraft:cobblestone"},
        {pos: [11, 3, 6], state: "minecraft:gravel"},
        {pos: [12, 3, 1], state: "minecraft:gravel"},
        {pos: [12, 3, 2], state: "minecraft:cobblestone"},
        {pos: [12, 3, 3], state: "minecraft:cobblestone"},
        {pos: [12, 3, 4], state: "minecraft:gravel"},
        {pos: [12, 3, 5], state: "minecraft:gravel"},
        {pos: [1, 4, 3], state: "minecraft:cobblestone"},
        {pos: [1, 4, 4], state: "minecraft:cobblestone"},
        {pos: [2, 4, 3], state: "minecraft:gravel"},
        {pos: [2, 4, 4], state: "minecraft:cobblestone"},
        {pos: [3, 4, 4], state: "minecraft:gravel"},
        {pos: [3, 4, 5], state: "minecraft:cobblestone"},
        {pos: [3, 4, 11], state: "minecraft:cobblestone"},
        {pos: [3, 4, 12], state: "minecraft:cobblestone"},
        {pos: [4, 4, 5], state: "minecraft:cobblestone"},
        {pos: [4, 4, 12], state: "minecraft:gravel"},
        {pos: [9, 4, 3], state: "minecraft:gravel"},
        {pos: [9, 4, 4], state: "minecraft:gravel"},
        {pos: [9, 4, 5], state: "minecraft:gravel"},
        {pos: [9, 4, 6], state: "minecraft:cobblestone"},
        {pos: [9, 4, 7], state: "minecraft:gravel"},
        {pos: [10, 4, 3], state: "minecraft:gravel"},
        {pos: [10, 4, 4], state: "minecraft:gravel"},
        {pos: [10, 4, 5], state: "minecraft:gravel"},
        {pos: [10, 4, 6], state: "minecraft:cobblestone"},
        {pos: [11, 4, 3], state: "minecraft:gravel"},
        {pos: [11, 4, 4], state: "minecraft:gravel"},
        {pos: [11, 4, 5], state: "minecraft:gravel"},
        {pos: [12, 4, 2], state: "minecraft:cobblestone"},
        {pos: [12, 4, 3], state: "minecraft:cobblestone"},
        {pos: [4, 5, 5], state: "minecraft:cobblestone"},
        {pos: [10, 5, 6], state: "minecraft:cobblestone"},
        {pos: [12, 5, 3], state: "minecraft:cobblestone"},
        {pos: [12, 6, 3], state: "minecraft:gravel"}
    ],
    entities: [],
    palette: [
        "minecraft:cobblestone",
        "minecraft:gravel",
        "minecraft:cobblestone_stairs{facing:south,half:top,shape:straight,waterlogged:false}"
    ],
    trailiertales_DataVersion: 2
}
