{
    DataVersion: 3953,
    size: [26, 10, 23],
    data: [
        {pos: [0, 0, 18], state: "minecraft:cobblestone"},
        {pos: [0, 0, 19], state: "minecraft:cobblestone"},
        {pos: [0, 0, 20], state: "minecraft:cobblestone"},
        {pos: [1, 0, 15], state: "minecraft:cobblestone"},
        {pos: [1, 0, 16], state: "minecraft:cobblestone"},
        {pos: [1, 0, 17], state: "minecraft:cobblestone"},
        {pos: [1, 0, 18], state: "minecraft:cobblestone"},
        {pos: [1, 0, 19], state: "minecraft:cobblestone"},
        {pos: [1, 0, 20], state: "minecraft:cobblestone"},
        {pos: [2, 0, 13], state: "minecraft:cobblestone"},
        {pos: [2, 0, 14], state: "minecraft:cobblestone"},
        {pos: [2, 0, 15], state: "minecraft:cobblestone"},
        {pos: [2, 0, 16], state: "minecraft:cobblestone"},
        {pos: [2, 0, 17], state: "minecraft:cobblestone"},
        {pos: [2, 0, 18], state: "minecraft:cobblestone"},
        {pos: [2, 0, 19], state: "minecraft:cobblestone"},
        {pos: [2, 0, 20], state: "minecraft:cobblestone"},
        {pos: [3, 0, 13], state: "minecraft:cobblestone"},
        {pos: [3, 0, 14], state: "minecraft:cobblestone"},
        {pos: [3, 0, 15], state: "minecraft:cobblestone"},
        {pos: [3, 0, 16], state: "minecraft:cobblestone"},
        {pos: [3, 0, 17], state: "minecraft:cobblestone"},
        {pos: [3, 0, 18], state: "minecraft:cobblestone"},
        {pos: [3, 0, 19], state: "minecraft:cobblestone"},
        {pos: [3, 0, 20], state: "minecraft:cobblestone"},
        {pos: [4, 0, 13], state: "minecraft:cobblestone"},
        {pos: [4, 0, 14], state: "minecraft:cobblestone"},
        {pos: [4, 0, 15], state: "minecraft:cobblestone"},
        {pos: [4, 0, 16], state: "minecraft:cobblestone"},
        {pos: [4, 0, 17], state: "minecraft:gravel"},
        {pos: [4, 0, 18], state: "minecraft:cobblestone"},
        {pos: [4, 0, 19], state: "minecraft:cobblestone"},
        {pos: [4, 0, 20], state: "minecraft:cobblestone"},
        {pos: [5, 0, 13], state: "minecraft:cobblestone"},
        {pos: [5, 0, 14], state: "minecraft:cobblestone"},
        {pos: [5, 0, 15], state: "minecraft:cobblestone"},
        {pos: [5, 0, 16], state: "minecraft:cobblestone"},
        {pos: [5, 0, 17], state: "minecraft:cobblestone"},
        {pos: [5, 0, 18], state: "minecraft:cobblestone"},
        {pos: [5, 0, 19], state: "minecraft:cobblestone"},
        {pos: [5, 0, 20], state: "minecraft:cobblestone"},
        {pos: [6, 0, 14], state: "minecraft:cobblestone"},
        {pos: [6, 0, 15], state: "minecraft:cobblestone"},
        {pos: [6, 0, 16], state: "minecraft:cobblestone"},
        {pos: [6, 0, 17], state: "minecraft:cobblestone"},
        {pos: [6, 0, 18], state: "minecraft:cobblestone"},
        {pos: [6, 0, 19], state: "minecraft:cobblestone"},
        {pos: [7, 0, 15], state: "minecraft:cobblestone"},
        {pos: [7, 0, 16], state: "minecraft:cobblestone"},
        {pos: [7, 0, 17], state: "minecraft:cobblestone"},
        {pos: [7, 0, 18], state: "minecraft:cobblestone"},
        {pos: [8, 0, 16], state: "minecraft:cobblestone"},
        {pos: [8, 0, 17], state: "minecraft:cobblestone"},
        {pos: [8, 0, 18], state: "minecraft:cobblestone"},
        {pos: [8, 0, 19], state: "minecraft:cobblestone"},
        {pos: [9, 0, 17], state: "minecraft:cobblestone"},
        {pos: [9, 0, 18], state: "minecraft:cobblestone"},
        {pos: [9, 0, 19], state: "minecraft:cobblestone"},
        {pos: [10, 0, 16], state: "minecraft:cobblestone"},
        {pos: [10, 0, 17], state: "minecraft:cobblestone"},
        {pos: [10, 0, 18], state: "minecraft:cobblestone"},
        {pos: [11, 0, 14], state: "minecraft:cobblestone"},
        {pos: [11, 0, 15], state: "minecraft:cobblestone"},
        {pos: [11, 0, 16], state: "minecraft:cobblestone"},
        {pos: [11, 0, 17], state: "minecraft:cobblestone"},
        {pos: [12, 0, 13], state: "minecraft:cobblestone"},
        {pos: [12, 0, 14], state: "minecraft:cobblestone"},
        {pos: [12, 0, 15], state: "minecraft:cobblestone"},
        {pos: [12, 0, 16], state: "minecraft:cobblestone"},
        {pos: [12, 0, 17], state: "minecraft:cobblestone"},
        {pos: [12, 0, 19], state: "minecraft:cobblestone"},
        {pos: [12, 0, 20], state: "minecraft:cobblestone"},
        {pos: [12, 0, 21], state: "minecraft:cobblestone"},
        {pos: [13, 0, 13], state: "minecraft:cobblestone"},
        {pos: [13, 0, 14], state: "minecraft:cobblestone"},
        {pos: [13, 0, 16], state: "minecraft:cobblestone"},
        {pos: [13, 0, 17], state: "minecraft:cobblestone"},
        {pos: [13, 0, 19], state: "minecraft:cobblestone"},
        {pos: [13, 0, 20], state: "minecraft:gravel"},
        {pos: [13, 0, 21], state: "minecraft:cobblestone"},
        {pos: [14, 0, 7], state: "minecraft:cobblestone"},
        {pos: [14, 0, 8], state: "minecraft:cobblestone"},
        {pos: [14, 0, 13], state: "minecraft:cobblestone"},
        {pos: [14, 0, 14], state: "minecraft:cobblestone"},
        {pos: [14, 0, 16], state: "minecraft:cobblestone"},
        {pos: [14, 0, 17], state: "minecraft:cobblestone"},
        {pos: [14, 0, 20], state: "minecraft:cobblestone"},
        {pos: [15, 0, 7], state: "minecraft:cobblestone"},
        {pos: [15, 0, 8], state: "minecraft:cobblestone"},
        {pos: [15, 0, 9], state: "minecraft:cobblestone"},
        {pos: [15, 0, 16], state: "minecraft:cobblestone"},
        {pos: [15, 0, 17], state: "minecraft:cobblestone"},
        {pos: [15, 0, 18], state: "minecraft:cobblestone"},
        {pos: [16, 0, 8], state: "minecraft:cobblestone"},
        {pos: [16, 0, 9], state: "minecraft:cobblestone"},
        {pos: [16, 0, 10], state: "minecraft:cobblestone"},
        {pos: [16, 0, 15], state: "minecraft:cobblestone"},
        {pos: [16, 0, 16], state: "minecraft:cobblestone"},
        {pos: [16, 0, 17], state: "minecraft:cobblestone"},
        {pos: [16, 0, 18], state: "minecraft:cobblestone"},
        {pos: [17, 0, 1], state: "minecraft:cobblestone"},
        {pos: [17, 0, 2], state: "minecraft:cobblestone"},
        {pos: [17, 0, 3], state: "minecraft:cobblestone"},
        {pos: [17, 0, 9], state: "minecraft:cobblestone"},
        {pos: [17, 0, 14], state: "minecraft:cobblestone"},
        {pos: [17, 0, 15], state: "minecraft:cobblestone"},
        {pos: [17, 0, 16], state: "minecraft:cobblestone"},
        {pos: [17, 0, 17], state: "minecraft:cobblestone"},
        {pos: [17, 0, 21], state: "minecraft:cobblestone"},
        {pos: [17, 0, 22], state: "minecraft:cobblestone"},
        {pos: [18, 0, 0], state: "minecraft:cobblestone"},
        {pos: [18, 0, 1], state: "minecraft:cobblestone"},
        {pos: [18, 0, 2], state: "minecraft:cobblestone"},
        {pos: [18, 0, 3], state: "minecraft:cobblestone"},
        {pos: [18, 0, 5], state: "minecraft:cobblestone"},
        {pos: [18, 0, 6], state: "minecraft:cobblestone"},
        {pos: [18, 0, 7], state: "minecraft:cobblestone"},
        {pos: [18, 0, 8], state: "minecraft:cobblestone"},
        {pos: [18, 0, 9], state: "minecraft:cobblestone"},
        {pos: [18, 0, 10], state: "minecraft:cobblestone"},
        {pos: [18, 0, 11], state: "minecraft:cobblestone"},
        {pos: [18, 0, 12], state: "minecraft:cobblestone"},
        {pos: [18, 0, 13], state: "minecraft:cobblestone"},
        {pos: [18, 0, 14], state: "minecraft:cobblestone"},
        {pos: [18, 0, 19], state: "minecraft:cobblestone"},
        {pos: [18, 0, 20], state: "minecraft:cobblestone"},
        {pos: [18, 0, 21], state: "minecraft:cobblestone"},
        {pos: [18, 0, 22], state: "minecraft:cobblestone"},
        {pos: [19, 0, 0], state: "minecraft:cobblestone"},
        {pos: [19, 0, 1], state: "minecraft:cobblestone"},
        {pos: [19, 0, 2], state: "minecraft:cobblestone"},
        {pos: [19, 0, 3], state: "minecraft:cobblestone"},
        {pos: [19, 0, 4], state: "minecraft:cobblestone"},
        {pos: [19, 0, 5], state: "minecraft:cobblestone"},
        {pos: [19, 0, 6], state: "minecraft:cobblestone"},
        {pos: [19, 0, 7], state: "minecraft:cobblestone"},
        {pos: [19, 0, 8], state: "minecraft:cobblestone"},
        {pos: [19, 0, 9], state: "minecraft:cobblestone"},
        {pos: [19, 0, 10], state: "minecraft:cobblestone"},
        {pos: [19, 0, 11], state: "minecraft:cobblestone"},
        {pos: [19, 0, 12], state: "minecraft:cobblestone"},
        {pos: [19, 0, 13], state: "minecraft:cobblestone"},
        {pos: [19, 0, 14], state: "minecraft:cobblestone"},
        {pos: [19, 0, 15], state: "minecraft:cobblestone"},
        {pos: [19, 0, 16], state: "minecraft:cobblestone"},
        {pos: [19, 0, 19], state: "minecraft:cobblestone"},
        {pos: [19, 0, 20], state: "minecraft:cobblestone"},
        {pos: [19, 0, 21], state: "minecraft:cobblestone"},
        {pos: [19, 0, 22], state: "minecraft:cobblestone"},
        {pos: [20, 0, 0], state: "minecraft:cobblestone"},
        {pos: [20, 0, 1], state: "minecraft:cobblestone"},
        {pos: [20, 0, 2], state: "minecraft:cobblestone"},
        {pos: [20, 0, 3], state: "minecraft:cobblestone"},
        {pos: [20, 0, 6], state: "minecraft:cobblestone"},
        {pos: [20, 0, 7], state: "minecraft:cobblestone"},
        {pos: [20, 0, 10], state: "minecraft:cobblestone"},
        {pos: [20, 0, 11], state: "minecraft:cobblestone"},
        {pos: [20, 0, 14], state: "minecraft:cobblestone"},
        {pos: [20, 0, 15], state: "minecraft:cobblestone"},
        {pos: [20, 0, 19], state: "minecraft:cobblestone"},
        {pos: [20, 0, 20], state: "minecraft:cobblestone"},
        {pos: [20, 0, 21], state: "minecraft:cobblestone"},
        {pos: [20, 0, 22], state: "minecraft:cobblestone"},
        {pos: [21, 0, 0], state: "minecraft:cobblestone"},
        {pos: [21, 0, 1], state: "minecraft:cobblestone"},
        {pos: [21, 0, 2], state: "minecraft:cobblestone"},
        {pos: [21, 0, 7], state: "minecraft:cobblestone"},
        {pos: [21, 0, 8], state: "minecraft:cobblestone"},
        {pos: [21, 0, 13], state: "minecraft:cobblestone"},
        {pos: [21, 0, 14], state: "minecraft:cobblestone"},
        {pos: [21, 0, 15], state: "minecraft:cobblestone"},
        {pos: [21, 0, 16], state: "minecraft:cobblestone"},
        {pos: [21, 0, 19], state: "minecraft:cobblestone"},
        {pos: [21, 0, 20], state: "minecraft:cobblestone"},
        {pos: [22, 0, 6], state: "minecraft:cobblestone"},
        {pos: [22, 0, 7], state: "minecraft:cobblestone"},
        {pos: [22, 0, 8], state: "minecraft:cobblestone"},
        {pos: [22, 0, 12], state: "minecraft:cobblestone"},
        {pos: [22, 0, 13], state: "minecraft:cobblestone"},
        {pos: [22, 0, 14], state: "minecraft:cobblestone"},
        {pos: [22, 0, 15], state: "minecraft:cobblestone"},
        {pos: [22, 0, 16], state: "minecraft:cobblestone"},
        {pos: [22, 0, 17], state: "minecraft:cobblestone"},
        {pos: [23, 0, 6], state: "minecraft:cobblestone"},
        {pos: [23, 0, 7], state: "minecraft:cobblestone"},
        {pos: [23, 0, 8], state: "minecraft:cobblestone"},
        {pos: [23, 0, 9], state: "minecraft:cobblestone"},
        {pos: [23, 0, 12], state: "minecraft:cobblestone"},
        {pos: [23, 0, 13], state: "minecraft:cobblestone"},
        {pos: [23, 0, 14], state: "minecraft:cobblestone"},
        {pos: [23, 0, 15], state: "minecraft:cobblestone"},
        {pos: [23, 0, 16], state: "minecraft:cobblestone"},
        {pos: [23, 0, 17], state: "minecraft:cobblestone"},
        {pos: [24, 0, 6], state: "minecraft:cobblestone"},
        {pos: [24, 0, 7], state: "minecraft:gravel"},
        {pos: [24, 0, 11], state: "minecraft:cobblestone"},
        {pos: [24, 0, 12], state: "minecraft:cobblestone"},
        {pos: [24, 0, 13], state: "minecraft:cobblestone"},
        {pos: [24, 0, 14], state: "minecraft:cobblestone"},
        {pos: [24, 0, 15], state: "minecraft:cobblestone"},
        {pos: [24, 0, 16], state: "minecraft:cobblestone"},
        {pos: [24, 0, 17], state: "minecraft:cobblestone"},
        {pos: [25, 0, 11], state: "minecraft:cobblestone"},
        {pos: [25, 0, 12], state: "minecraft:cobblestone"},
        {pos: [25, 0, 13], state: "minecraft:cobblestone"},
        {pos: [25, 0, 14], state: "minecraft:cobblestone"},
        {pos: [25, 0, 15], state: "minecraft:cobblestone"},
        {pos: [25, 0, 16], state: "minecraft:cobblestone"},
        {pos: [0, 1, 18], state: "minecraft:gravel"},
        {pos: [0, 1, 19], state: "minecraft:cobblestone"},
        {pos: [0, 1, 20], state: "minecraft:cobblestone"},
        {pos: [1, 1, 15], state: "minecraft:cobblestone"},
        {pos: [1, 1, 16], state: "minecraft:cobblestone"},
        {pos: [1, 1, 17], state: "minecraft:cobblestone"},
        {pos: [1, 1, 18], state: "minecraft:cobblestone"},
        {pos: [1, 1, 19], state: "minecraft:cobblestone"},
        {pos: [1, 1, 20], state: "minecraft:cobblestone"},
        {pos: [2, 1, 13], state: "minecraft:gravel"},
        {pos: [2, 1, 14], state: "minecraft:cobblestone"},
        {pos: [2, 1, 15], state: "minecraft:gravel"},
        {pos: [2, 1, 16], state: "minecraft:gravel"},
        {pos: [2, 1, 17], state: "minecraft:cobblestone_wall{east:tall,north:tall,south:tall,up:false,waterlogged:false,west:tall}"},
        {pos: [2, 1, 18], state: "minecraft:cobblestone"},
        {pos: [2, 1, 19], state: "minecraft:cobblestone"},
        {pos: [2, 1, 20], state: "minecraft:gravel"},
        {pos: [3, 1, 13], state: "minecraft:cobblestone"},
        {pos: [3, 1, 14], state: "minecraft:gray_glazed_terracotta{facing:south}"},
        {pos: [3, 1, 15], state: "minecraft:cobblestone"},
        {pos: [3, 1, 16], state: "minecraft:gravel"},
        {pos: [3, 1, 17], state: "minecraft:gravel"},
        {pos: [3, 1, 18], state: "minecraft:gravel"},
        {pos: [3, 1, 19], state: "minecraft:gravel"},
        {pos: [3, 1, 20], state: "minecraft:cobblestone"},
        {pos: [4, 1, 13], state: "minecraft:gravel"},
        {pos: [4, 1, 14], state: "minecraft:gray_glazed_terracotta{facing:west}"},
        {pos: [4, 1, 15], state: "minecraft:gray_glazed_terracotta{facing:north}"},
        {pos: [4, 1, 16], state: "minecraft:gravel"},
        {pos: [4, 1, 17], state: "minecraft:gravel"},
        {pos: [4, 1, 18], state: "minecraft:gravel"},
        {pos: [4, 1, 19], state: "minecraft:gravel"},
        {pos: [4, 1, 20], state: "minecraft:cobblestone"},
        {pos: [5, 1, 13], state: "minecraft:cobblestone"},
        {pos: [5, 1, 14], state: "minecraft:gravel"},
        {pos: [5, 1, 15], state: "minecraft:gravel"},
        {pos: [5, 1, 16], state: "minecraft:gravel"},
        {pos: [5, 1, 17], state: "minecraft:gravel"},
        {pos: [5, 1, 18], state: "minecraft:gravel"},
        {pos: [5, 1, 19], state: "minecraft:gravel"},
        {pos: [5, 1, 20], state: "minecraft:gravel"},
        {pos: [6, 1, 14], state: "minecraft:cobblestone"},
        {pos: [6, 1, 15], state: "minecraft:cobblestone"},
        {pos: [6, 1, 16], state: "minecraft:gravel"},
        {pos: [6, 1, 17], state: "minecraft:gravel"},
        {pos: [6, 1, 18], state: "minecraft:cobblestone"},
        {pos: [6, 1, 19], state: "minecraft:cobblestone"},
        {pos: [7, 1, 15], state: "minecraft:gravel"},
        {pos: [7, 1, 16], state: "minecraft:gravel"},
        {pos: [7, 1, 17], state: "minecraft:gravel"},
        {pos: [7, 1, 18], state: "minecraft:gravel"},
        {pos: [8, 1, 16], state: "minecraft:gravel"},
        {pos: [8, 1, 17], state: "minecraft:gravel"},
        {pos: [8, 1, 18], state: "minecraft:gravel"},
        {pos: [8, 1, 19], state: "minecraft:gravel"},
        {pos: [9, 1, 17], state: "minecraft:gravel"},
        {pos: [9, 1, 18], state: "minecraft:gravel"},
        {pos: [9, 1, 19], state: "minecraft:gravel"},
        {pos: [10, 1, 16], state: "minecraft:gravel"},
        {pos: [10, 1, 17], state: "minecraft:gravel"},
        {pos: [10, 1, 18], state: "minecraft:gravel"},
        {pos: [11, 1, 14], state: "minecraft:gravel"},
        {pos: [11, 1, 15], state: "minecraft:gravel"},
        {pos: [11, 1, 16], state: "minecraft:gravel"},
        {pos: [11, 1, 17], state: "minecraft:gravel"},
        {pos: [12, 1, 13], state: "minecraft:cobblestone"},
        {pos: [12, 1, 14], state: "minecraft:cobblestone"},
        {pos: [12, 1, 15], state: "minecraft:gravel"},
        {pos: [12, 1, 16], state: "minecraft:gravel"},
        {pos: [12, 1, 17], state: "minecraft:gravel"},
        {pos: [12, 1, 19], state: "minecraft:gravel"},
        {pos: [12, 1, 20], state: "minecraft:gravel"},
        {pos: [12, 1, 21], state: "minecraft:cobblestone"},
        {pos: [13, 1, 13], state: "minecraft:cobblestone"},
        {pos: [13, 1, 14], state: "minecraft:cobblestone"},
        {pos: [13, 1, 16], state: "minecraft:gravel"},
        {pos: [13, 1, 17], state: "minecraft:gravel"},
        {pos: [13, 1, 19], state: "minecraft:gravel"},
        {pos: [13, 1, 20], state: "minecraft:gravel"},
        {pos: [13, 1, 21], state: "minecraft:gravel"},
        {pos: [14, 1, 7], state: "minecraft:cobblestone"},
        {pos: [14, 1, 8], state: "minecraft:cobblestone"},
        {pos: [14, 1, 13], state: "minecraft:cobblestone"},
        {pos: [14, 1, 14], state: "minecraft:gravel"},
        {pos: [14, 1, 16], state: "minecraft:gravel"},
        {pos: [14, 1, 17], state: "minecraft:gravel"},
        {pos: [14, 1, 20], state: "minecraft:gravel"},
        {pos: [15, 1, 6], state: "minecraft:cobblestone"},
        {pos: [15, 1, 7], state: "minecraft:cobblestone"},
        {pos: [15, 1, 8], state: "minecraft:gravel"},
        {pos: [15, 1, 9], state: "minecraft:gravel"},
        {pos: [15, 1, 16], state: "minecraft:gravel"},
        {pos: [15, 1, 17], state: "minecraft:gravel"},
        {pos: [15, 1, 18], state: "minecraft:gravel"},
        {pos: [16, 1, 8], state: "minecraft:gravel"},
        {pos: [16, 1, 9], state: "minecraft:gravel"},
        {pos: [16, 1, 10], state: "minecraft:gravel"},
        {pos: [16, 1, 15], state: "minecraft:gravel"},
        {pos: [16, 1, 16], state: "minecraft:gravel"},
        {pos: [16, 1, 17], state: "minecraft:gravel"},
        {pos: [16, 1, 18], state: "minecraft:gravel"},
        {pos: [17, 1, 1], state: "minecraft:cobblestone"},
        {pos: [17, 1, 2], state: "minecraft:cobblestone"},
        {pos: [17, 1, 3], state: "minecraft:cobblestone"},
        {pos: [17, 1, 9], state: "minecraft:gravel"},
        {pos: [17, 1, 14], state: "minecraft:gravel"},
        {pos: [17, 1, 15], state: "minecraft:gravel"},
        {pos: [17, 1, 16], state: "minecraft:gravel"},
        {pos: [17, 1, 17], state: "minecraft:gravel"},
        {pos: [17, 1, 21], state: "minecraft:gravel"},
        {pos: [17, 1, 22], state: "minecraft:gravel"},
        {pos: [18, 1, 0], state: "minecraft:gravel"},
        {pos: [18, 1, 1], state: "minecraft:gravel"},
        {pos: [18, 1, 2], state: "minecraft:water_cauldron{level:3}"},
        {pos: [18, 1, 3], state: "minecraft:cobblestone"},
        {pos: [18, 1, 5], state: "minecraft:gravel"},
        {pos: [18, 1, 6], state: "minecraft:gravel"},
        {pos: [18, 1, 7], state: "minecraft:gravel"},
        {pos: [18, 1, 8], state: "minecraft:gravel"},
        {pos: [18, 1, 9], state: "minecraft:gravel"},
        {pos: [18, 1, 10], state: "minecraft:gravel"},
        {pos: [18, 1, 11], state: "minecraft:gravel"},
        {pos: [18, 1, 12], state: "minecraft:gravel"},
        {pos: [18, 1, 13], state: "minecraft:gravel"},
        {pos: [18, 1, 14], state: "minecraft:gravel"},
        {pos: [18, 1, 19], state: "minecraft:gravel"},
        {pos: [18, 1, 20], state: "minecraft:gravel"},
        {pos: [18, 1, 21], state: "minecraft:gravel"},
        {pos: [18, 1, 22], state: "minecraft:cobblestone"},
        {pos: [19, 1, 0], state: "minecraft:cobblestone"},
        {pos: [19, 1, 1], state: "minecraft:gravel"},
        {pos: [19, 1, 2], state: "minecraft:gravel"},
        {pos: [19, 1, 3], state: "minecraft:gravel"},
        {pos: [19, 1, 4], state: "minecraft:gravel"},
        {pos: [19, 1, 5], state: "minecraft:gravel"},
        {pos: [19, 1, 6], state: "minecraft:gravel"},
        {pos: [19, 1, 7], state: "minecraft:gravel"},
        {pos: [19, 1, 8], state: "minecraft:gravel"},
        {pos: [19, 1, 9], state: "minecraft:gravel"},
        {pos: [19, 1, 10], state: "minecraft:gravel"},
        {pos: [19, 1, 11], state: "minecraft:gravel"},
        {pos: [19, 1, 12], state: "minecraft:gravel"},
        {pos: [19, 1, 13], state: "minecraft:gravel"},
        {pos: [19, 1, 14], state: "minecraft:gravel"},
        {pos: [19, 1, 15], state: "minecraft:gravel"},
        {pos: [19, 1, 16], state: "minecraft:gravel"},
        {pos: [19, 1, 19], state: "minecraft:cobblestone"},
        {pos: [19, 1, 20], state: "minecraft:gravel"},
        {pos: [19, 1, 21], state: "minecraft:gravel"},
        {pos: [19, 1, 22], state: "minecraft:gravel"},
        {pos: [20, 1, 0], state: "minecraft:cobblestone"},
        {pos: [20, 1, 1], state: "minecraft:water_cauldron{level:3}"},
        {pos: [20, 1, 2], state: "minecraft:gravel"},
        {pos: [20, 1, 3], state: "minecraft:gravel"},
        {pos: [20, 1, 6], state: "minecraft:gravel"},
        {pos: [20, 1, 7], state: "minecraft:gravel"},
        {pos: [20, 1, 10], state: "minecraft:gravel"},
        {pos: [20, 1, 11], state: "minecraft:gravel"},
        {pos: [20, 1, 14], state: "minecraft:gravel"},
        {pos: [20, 1, 15], state: "minecraft:gravel"},
        {pos: [20, 1, 19], state: "minecraft:cobblestone"},
        {pos: [20, 1, 20], state: "minecraft:gray_glazed_terracotta{facing:south}"},
        {pos: [20, 1, 21], state: "minecraft:gray_glazed_terracotta{facing:north}"},
        {pos: [20, 1, 22], state: "minecraft:cobblestone"},
        {pos: [21, 1, 0], state: "minecraft:cobblestone"},
        {pos: [21, 1, 1], state: "minecraft:cobblestone"},
        {pos: [21, 1, 2], state: "minecraft:cobblestone"},
        {pos: [21, 1, 7], state: "minecraft:gravel"},
        {pos: [21, 1, 8], state: "minecraft:gravel"},
        {pos: [21, 1, 13], state: "minecraft:gravel"},
        {pos: [21, 1, 14], state: "minecraft:gravel"},
        {pos: [21, 1, 15], state: "minecraft:gravel"},
        {pos: [21, 1, 16], state: "minecraft:gravel"},
        {pos: [21, 1, 19], state: "minecraft:cobblestone"},
        {pos: [21, 1, 20], state: "minecraft:cobblestone"},
        {pos: [21, 1, 21], state: "minecraft:cobblestone"},
        {pos: [22, 1, 6], state: "minecraft:gravel"},
        {pos: [22, 1, 7], state: "minecraft:gravel"},
        {pos: [22, 1, 8], state: "minecraft:gravel"},
        {pos: [22, 1, 12], state: "minecraft:gravel"},
        {pos: [22, 1, 13], state: "minecraft:gravel"},
        {pos: [22, 1, 14], state: "minecraft:gravel"},
        {pos: [22, 1, 15], state: "minecraft:gravel"},
        {pos: [22, 1, 16], state: "minecraft:gravel"},
        {pos: [22, 1, 17], state: "minecraft:gravel"},
        {pos: [23, 1, 6], state: "minecraft:gravel"},
        {pos: [23, 1, 7], state: "minecraft:gravel"},
        {pos: [23, 1, 8], state: "minecraft:gravel"},
        {pos: [23, 1, 9], state: "minecraft:gravel"},
        {pos: [23, 1, 12], state: "minecraft:gravel"},
        {pos: [23, 1, 13], state: "minecraft:gravel"},
        {pos: [23, 1, 14], state: "minecraft:cobblestone"},
        {pos: [23, 1, 15], state: "minecraft:cobblestone"},
        {pos: [23, 1, 16], state: "minecraft:cobblestone"},
        {pos: [23, 1, 17], state: "minecraft:gravel"},
        {pos: [24, 1, 6], state: "minecraft:cobblestone"},
        {pos: [24, 1, 7], state: "minecraft:gravel"},
        {pos: [24, 1, 11], state: "minecraft:gravel"},
        {pos: [24, 1, 12], state: "minecraft:gravel"},
        {pos: [24, 1, 13], state: "minecraft:gravel"},
        {pos: [24, 1, 14], state: "minecraft:gravel"},
        {pos: [24, 1, 15], state: "minecraft:gravel"},
        {pos: [24, 1, 16], state: "minecraft:gravel"},
        {pos: [24, 1, 17], state: "minecraft:gravel"},
        {pos: [25, 1, 11], state: "minecraft:gravel"},
        {pos: [25, 1, 12], state: "minecraft:gravel"},
        {pos: [25, 1, 13], state: "minecraft:gravel"},
        {pos: [25, 1, 14], state: "minecraft:gravel"},
        {pos: [25, 1, 15], state: "minecraft:gravel"},
        {pos: [25, 1, 16], state: "minecraft:gravel"},
        {pos: [0, 2, 18], state: "minecraft:gravel"},
        {pos: [0, 2, 19], state: "minecraft:gravel"},
        {pos: [0, 2, 20], state: "minecraft:gravel"},
        {pos: [1, 2, 15], state: "minecraft:gravel"},
        {pos: [1, 2, 16], state: "minecraft:cobblestone"},
        {pos: [1, 2, 17], state: "minecraft:gravel"},
        {pos: [1, 2, 18], state: "minecraft:cobblestone"},
        {pos: [1, 2, 19], state: "minecraft:gravel"},
        {pos: [1, 2, 20], state: "minecraft:gravel"},
        {pos: [2, 2, 13], state: "minecraft:gravel"},
        {pos: [2, 2, 14], state: "minecraft:cobblestone"},
        {pos: [2, 2, 15], state: "minecraft:gravel"},
        {pos: [2, 2, 16], state: "minecraft:gravel"},
        {pos: [2, 2, 17], state: "minecraft:chiseled_stone_bricks"},
        {pos: [2, 2, 18], state: "minecraft:cobblestone"},
        {pos: [2, 2, 19], state: "minecraft:cobblestone"},
        {pos: [2, 2, 20], state: "minecraft:gravel"},
        {pos: [3, 2, 13], state: "minecraft:gravel"},
        {pos: [3, 2, 14], state: "minecraft:gravel"},
        {pos: [3, 2, 15], state: "minecraft:gravel"},
        {pos: [3, 2, 16], state: "minecraft:gravel"},
        {pos: [3, 2, 17], state: "minecraft:gravel"},
        {pos: [3, 2, 18], state: "minecraft:gravel"},
        {pos: [3, 2, 19], state: "minecraft:gravel"},
        {pos: [3, 2, 20], state: "minecraft:cobblestone"},
        {pos: [4, 2, 13], state: "minecraft:gravel"},
        {pos: [4, 2, 14], state: "minecraft:gravel"},
        {pos: [4, 2, 15], state: "minecraft:gravel"},
        {pos: [4, 2, 16], state: "minecraft:gravel"},
        {pos: [4, 2, 17], state: "minecraft:gravel"},
        {pos: [4, 2, 18], state: "minecraft:gravel"},
        {pos: [4, 2, 19], state: "minecraft:gravel"},
        {pos: [4, 2, 20], state: "minecraft:gravel"},
        {pos: [5, 2, 13], state: "minecraft:gravel"},
        {pos: [5, 2, 14], state: "minecraft:gravel"},
        {pos: [5, 2, 15], state: "minecraft:gravel"},
        {pos: [5, 2, 16], state: "minecraft:gravel"},
        {pos: [5, 2, 17], state: "minecraft:gravel"},
        {pos: [5, 2, 18], state: "minecraft:gravel"},
        {pos: [5, 2, 19], state: "minecraft:gravel"},
        {pos: [5, 2, 20], state: "minecraft:gravel"},
        {pos: [6, 2, 14], state: "minecraft:gravel"},
        {pos: [6, 2, 15], state: "minecraft:cobblestone"},
        {pos: [6, 2, 16], state: "minecraft:gravel"},
        {pos: [6, 2, 17], state: "minecraft:gravel"},
        {pos: [6, 2, 18], state: "minecraft:cobblestone"},
        {pos: [6, 2, 19], state: "minecraft:gravel"},
        {pos: [7, 2, 15], state: "minecraft:gravel"},
        {pos: [7, 2, 16], state: "minecraft:gravel"},
        {pos: [7, 2, 17], state: "minecraft:gravel"},
        {pos: [7, 2, 18], state: "minecraft:gravel"},
        {pos: [8, 2, 16], state: "minecraft:gravel"},
        {pos: [8, 2, 17], state: "minecraft:gravel"},
        {pos: [8, 2, 18], state: "minecraft:gravel"},
        {pos: [8, 2, 19], state: "minecraft:gravel"},
        {pos: [9, 2, 17], state: "minecraft:gravel"},
        {pos: [9, 2, 18], state: "minecraft:gravel"},
        {pos: [9, 2, 19], state: "minecraft:gravel"},
        {pos: [10, 2, 16], state: "minecraft:gravel"},
        {pos: [10, 2, 17], state: "minecraft:gravel"},
        {pos: [10, 2, 18], state: "minecraft:gravel"},
        {pos: [11, 2, 14], state: "minecraft:gravel"},
        {pos: [11, 2, 15], state: "minecraft:gravel"},
        {pos: [11, 2, 16], state: "minecraft:gravel"},
        {pos: [11, 2, 17], state: "minecraft:gravel"},
        {pos: [12, 2, 13], state: "minecraft:cobblestone"},
        {pos: [12, 2, 14], state: "minecraft:cobblestone"},
        {pos: [12, 2, 15], state: "minecraft:cobblestone"},
        {pos: [12, 2, 16], state: "minecraft:gravel"},
        {pos: [12, 2, 17], state: "minecraft:gravel"},
        {pos: [12, 2, 19], state: "minecraft:gravel"},
        {pos: [12, 2, 20], state: "minecraft:gravel"},
        {pos: [12, 2, 21], state: "minecraft:gravel"},
        {pos: [13, 2, 13], state: "minecraft:cobblestone"},
        {pos: [13, 2, 14], state: "minecraft:cobblestone"},
        {pos: [13, 2, 16], state: "minecraft:gravel"},
        {pos: [13, 2, 17], state: "minecraft:gravel"},
        {pos: [13, 2, 19], state: "minecraft:gravel"},
        {pos: [13, 2, 20], state: "minecraft:gravel"},
        {pos: [13, 2, 21], state: "minecraft:gravel"},
        {pos: [14, 2, 6], state: "minecraft:cobblestone"},
        {pos: [14, 2, 7], state: "minecraft:cobblestone"},
        {pos: [14, 2, 8], state: "minecraft:cobblestone"},
        {pos: [14, 2, 13], state: "minecraft:gravel"},
        {pos: [14, 2, 14], state: "minecraft:gravel"},
        {pos: [14, 2, 16], state: "minecraft:gravel"},
        {pos: [14, 2, 17], state: "minecraft:gravel"},
        {pos: [14, 2, 20], state: "minecraft:gravel"},
        {pos: [15, 2, 6], state: "minecraft:cobblestone"},
        {pos: [15, 2, 7], state: "minecraft:gravel"},
        {pos: [15, 2, 8], state: "minecraft:gravel"},
        {pos: [15, 2, 9], state: "minecraft:gravel"},
        {pos: [15, 2, 16], state: "minecraft:gravel"},
        {pos: [15, 2, 17], state: "minecraft:gravel"},
        {pos: [15, 2, 18], state: "minecraft:gravel"},
        {pos: [16, 2, 6], state: "minecraft:cobblestone"},
        {pos: [16, 2, 7], state: "minecraft:cobblestone"},
        {pos: [16, 2, 8], state: "minecraft:gravel"},
        {pos: [16, 2, 9], state: "minecraft:gravel"},
        {pos: [16, 2, 10], state: "minecraft:gravel"},
        {pos: [16, 2, 15], state: "minecraft:gravel"},
        {pos: [16, 2, 16], state: "minecraft:gravel"},
        {pos: [16, 2, 17], state: "minecraft:gravel"},
        {pos: [16, 2, 18], state: "minecraft:gravel"},
        {pos: [17, 2, 1], state: "minecraft:gravel"},
        {pos: [17, 2, 2], state: "minecraft:cobblestone"},
        {pos: [17, 2, 3], state: "minecraft:cobblestone"},
        {pos: [17, 2, 9], state: "minecraft:gravel"},
        {pos: [17, 2, 14], state: "minecraft:gravel"},
        {pos: [17, 2, 15], state: "minecraft:gravel"},
        {pos: [17, 2, 16], state: "minecraft:gravel"},
        {pos: [17, 2, 17], state: "minecraft:gravel"},
        {pos: [17, 2, 21], state: "minecraft:gravel"},
        {pos: [17, 2, 22], state: "minecraft:gravel"},
        {pos: [18, 2, 0], state: "minecraft:gravel"},
        {pos: [18, 2, 1], state: "minecraft:gravel"},
        {pos: [18, 2, 2], state: "minecraft:gravel"},
        {pos: [18, 2, 3], state: "minecraft:gravel"},
        {pos: [18, 2, 5], state: "minecraft:gravel"},
        {pos: [18, 2, 6], state: "minecraft:gravel"},
        {pos: [18, 2, 7], state: "minecraft:gravel"},
        {pos: [18, 2, 8], state: "minecraft:gravel"},
        {pos: [18, 2, 9], state: "minecraft:gravel"},
        {pos: [18, 2, 10], state: "minecraft:gravel"},
        {pos: [18, 2, 11], state: "minecraft:gravel"},
        {pos: [18, 2, 12], state: "minecraft:gravel"},
        {pos: [18, 2, 13], state: "minecraft:gravel"},
        {pos: [18, 2, 14], state: "minecraft:gravel"},
        {pos: [18, 2, 19], state: "minecraft:gravel"},
        {pos: [18, 2, 20], state: "minecraft:gravel"},
        {pos: [18, 2, 21], state: "minecraft:gravel"},
        {pos: [18, 2, 22], state: "minecraft:cobblestone"},
        {pos: [19, 2, 0], state: "minecraft:gravel"},
        {pos: [19, 2, 1], state: "minecraft:gravel"},
        {pos: [19, 2, 2], state: "minecraft:gravel"},
        {pos: [19, 2, 3], state: "minecraft:gravel"},
        {pos: [19, 2, 4], state: "minecraft:gravel"},
        {pos: [19, 2, 5], state: "minecraft:gravel"},
        {pos: [19, 2, 6], state: "minecraft:gravel"},
        {pos: [19, 2, 7], state: "minecraft:gravel"},
        {pos: [19, 2, 8], state: "minecraft:gravel"},
        {pos: [19, 2, 9], state: "minecraft:gravel"},
        {pos: [19, 2, 10], state: "minecraft:gravel"},
        {pos: [19, 2, 11], state: "minecraft:gravel"},
        {pos: [19, 2, 12], state: "minecraft:gravel"},
        {pos: [19, 2, 13], state: "minecraft:gravel"},
        {pos: [19, 2, 14], state: "minecraft:gravel"},
        {pos: [19, 2, 15], state: "minecraft:gravel"},
        {pos: [19, 2, 16], state: "minecraft:gravel"},
        {pos: [19, 2, 19], state: "minecraft:gravel"},
        {pos: [19, 2, 20], state: "minecraft:gravel"},
        {pos: [19, 2, 21], state: "minecraft:gravel"},
        {pos: [19, 2, 22], state: "minecraft:gravel"},
        {pos: [20, 2, 0], state: "minecraft:cobblestone"},
        {pos: [20, 2, 1], state: "minecraft:gravel"},
        {pos: [20, 2, 2], state: "minecraft:gravel"},
        {pos: [20, 2, 3], state: "minecraft:gravel"},
        {pos: [20, 2, 6], state: "minecraft:gravel"},
        {pos: [20, 2, 7], state: "minecraft:gravel"},
        {pos: [20, 2, 10], state: "minecraft:gravel"},
        {pos: [20, 2, 11], state: "minecraft:gravel"},
        {pos: [20, 2, 14], state: "minecraft:gravel"},
        {pos: [20, 2, 15], state: "minecraft:gravel"},
        {pos: [20, 2, 19], state: "minecraft:cobblestone"},
        {pos: [20, 2, 20], state: "minecraft:gravel"},
        {pos: [20, 2, 21], state: "minecraft:gravel"},
        {pos: [20, 2, 22], state: "minecraft:gravel"},
        {pos: [21, 2, 0], state: "minecraft:cobblestone"},
        {pos: [21, 2, 1], state: "minecraft:cobblestone"},
        {pos: [21, 2, 2], state: "minecraft:gravel"},
        {pos: [21, 2, 7], state: "minecraft:gravel"},
        {pos: [21, 2, 8], state: "minecraft:gravel"},
        {pos: [21, 2, 13], state: "minecraft:gravel"},
        {pos: [21, 2, 14], state: "minecraft:gravel"},
        {pos: [21, 2, 15], state: "minecraft:gravel"},
        {pos: [21, 2, 16], state: "minecraft:gravel"},
        {pos: [21, 2, 19], state: "minecraft:cobblestone"},
        {pos: [21, 2, 20], state: "minecraft:gravel"},
        {pos: [21, 2, 21], state: "minecraft:cobblestone"},
        {pos: [21, 2, 22], state: "minecraft:cobblestone"},
        {pos: [22, 2, 6], state: "minecraft:cobblestone"},
        {pos: [22, 2, 7], state: "minecraft:gravel"},
        {pos: [22, 2, 8], state: "minecraft:gravel"},
        {pos: [22, 2, 12], state: "minecraft:gravel"},
        {pos: [22, 2, 13], state: "minecraft:gravel"},
        {pos: [22, 2, 14], state: "minecraft:gravel"},
        {pos: [22, 2, 15], state: "minecraft:gravel"},
        {pos: [22, 2, 16], state: "minecraft:gravel"},
        {pos: [22, 2, 17], state: "minecraft:gravel"},
        {pos: [23, 2, 6], state: "minecraft:cobblestone"},
        {pos: [23, 2, 7], state: "minecraft:gravel"},
        {pos: [23, 2, 8], state: "minecraft:gravel"},
        {pos: [23, 2, 9], state: "minecraft:gravel"},
        {pos: [23, 2, 12], state: "minecraft:gravel"},
        {pos: [23, 2, 13], state: "minecraft:cobblestone"},
        {pos: [23, 2, 14], state: "minecraft:cobblestone_stairs{facing:north,half:top,shape:straight,waterlogged:false}"},
        {pos: [23, 2, 15], state: "minecraft:gravel"},
        {pos: [23, 2, 16], state: "minecraft:cobblestone_stairs{facing:south,half:top,shape:straight,waterlogged:false}"},
        {pos: [23, 2, 17], state: "minecraft:cobblestone"},
        {pos: [24, 2, 6], state: "minecraft:cobblestone"},
        {pos: [24, 2, 7], state: "minecraft:cobblestone"},
        {pos: [24, 2, 11], state: "minecraft:gravel"},
        {pos: [24, 2, 12], state: "minecraft:gravel"},
        {pos: [24, 2, 13], state: "minecraft:gravel"},
        {pos: [24, 2, 14], state: "minecraft:gravel"},
        {pos: [24, 2, 15], state: "minecraft:gravel"},
        {pos: [24, 2, 16], state: "minecraft:gravel"},
        {pos: [24, 2, 17], state: "minecraft:gravel"},
        {pos: [25, 2, 11], state: "minecraft:gravel"},
        {pos: [25, 2, 12], state: "minecraft:gravel"},
        {pos: [25, 2, 13], state: "minecraft:gravel"},
        {pos: [25, 2, 14], state: "minecraft:gravel"},
        {pos: [25, 2, 15], state: "minecraft:gravel"},
        {pos: [25, 2, 16], state: "minecraft:gravel"},
        {pos: [0, 3, 18], state: "minecraft:gravel"},
        {pos: [0, 3, 19], state: "minecraft:gravel"},
        {pos: [0, 3, 20], state: "minecraft:gravel"},
        {pos: [1, 3, 15], state: "minecraft:gravel"},
        {pos: [1, 3, 16], state: "minecraft:gravel"},
        {pos: [1, 3, 17], state: "minecraft:gravel"},
        {pos: [1, 3, 18], state: "minecraft:cobblestone"},
        {pos: [1, 3, 19], state: "minecraft:cobblestone"},
        {pos: [1, 3, 20], state: "minecraft:gravel"},
        {pos: [2, 3, 13], state: "minecraft:gravel"},
        {pos: [2, 3, 14], state: "minecraft:gravel"},
        {pos: [2, 3, 15], state: "minecraft:gravel"},
        {pos: [2, 3, 16], state: "minecraft:gravel"},
        {pos: [2, 3, 17], state: "minecraft:gravel"},
        {pos: [2, 3, 18], state: "minecraft:cobblestone"},
        {pos: [2, 3, 19], state: "minecraft:cobblestone"},
        {pos: [2, 3, 20], state: "minecraft:gravel"},
        {pos: [3, 3, 13], state: "minecraft:gravel"},
        {pos: [3, 3, 14], state: "minecraft:gravel"},
        {pos: [3, 3, 15], state: "minecraft:gravel"},
        {pos: [3, 3, 16], state: "minecraft:gravel"},
        {pos: [3, 3, 17], state: "minecraft:gravel"},
        {pos: [3, 3, 18], state: "minecraft:gravel"},
        {pos: [3, 3, 19], state: "minecraft:gravel"},
        {pos: [3, 3, 20], state: "minecraft:gravel"},
        {pos: [4, 3, 13], state: "minecraft:gravel"},
        {pos: [4, 3, 14], state: "minecraft:gravel"},
        {pos: [4, 3, 15], state: "minecraft:gravel"},
        {pos: [4, 3, 16], state: "minecraft:gravel"},
        {pos: [4, 3, 17], state: "minecraft:gravel"},
        {pos: [4, 3, 18], state: "minecraft:gravel"},
        {pos: [4, 3, 19], state: "minecraft:gravel"},
        {pos: [4, 3, 20], state: "minecraft:gravel"},
        {pos: [5, 3, 13], state: "minecraft:gravel"},
        {pos: [5, 3, 14], state: "minecraft:gravel"},
        {pos: [5, 3, 15], state: "minecraft:gravel"},
        {pos: [5, 3, 16], state: "minecraft:gravel"},
        {pos: [5, 3, 17], state: "minecraft:gravel"},
        {pos: [5, 3, 18], state: "minecraft:gravel"},
        {pos: [5, 3, 19], state: "minecraft:gravel"},
        {pos: [5, 3, 20], state: "minecraft:gravel"},
        {pos: [6, 3, 14], state: "minecraft:cobblestone"},
        {pos: [6, 3, 15], state: "minecraft:cobblestone"},
        {pos: [6, 3, 16], state: "minecraft:gravel"},
        {pos: [6, 3, 17], state: "minecraft:cobblestone"},
        {pos: [6, 3, 18], state: "minecraft:cobblestone"},
        {pos: [6, 3, 19], state: "minecraft:cobblestone"},
        {pos: [7, 3, 15], state: "minecraft:gravel"},
        {pos: [7, 3, 16], state: "minecraft:gravel"},
        {pos: [7, 3, 17], state: "minecraft:gravel"},
        {pos: [7, 3, 18], state: "minecraft:gravel"},
        {pos: [8, 3, 16], state: "minecraft:gravel"},
        {pos: [8, 3, 17], state: "minecraft:gravel"},
        {pos: [8, 3, 18], state: "minecraft:gravel"},
        {pos: [8, 3, 19], state: "minecraft:gravel"},
        {pos: [9, 3, 17], state: "minecraft:gravel"},
        {pos: [9, 3, 18], state: "minecraft:gravel"},
        {pos: [9, 3, 19], state: "minecraft:gravel"},
        {pos: [10, 3, 16], state: "minecraft:gravel"},
        {pos: [10, 3, 17], state: "minecraft:gravel"},
        {pos: [10, 3, 18], state: "minecraft:gravel"},
        {pos: [11, 3, 14], state: "minecraft:gravel"},
        {pos: [11, 3, 15], state: "minecraft:gravel"},
        {pos: [11, 3, 16], state: "minecraft:gravel"},
        {pos: [11, 3, 17], state: "minecraft:gravel"},
        {pos: [12, 3, 13], state: "minecraft:gravel"},
        {pos: [12, 3, 14], state: "minecraft:cobblestone"},
        {pos: [12, 3, 15], state: "minecraft:cobblestone"},
        {pos: [12, 3, 16], state: "minecraft:cobblestone"},
        {pos: [12, 3, 17], state: "minecraft:gravel"},
        {pos: [12, 3, 19], state: "minecraft:gravel"},
        {pos: [12, 3, 20], state: "minecraft:gravel"},
        {pos: [12, 3, 21], state: "minecraft:gravel"},
        {pos: [13, 3, 13], state: "minecraft:gravel"},
        {pos: [13, 3, 14], state: "minecraft:cobblestone"},
        {pos: [13, 3, 16], state: "minecraft:gravel"},
        {pos: [13, 3, 17], state: "minecraft:gravel"},
        {pos: [13, 3, 18], state: "minecraft:cobblestone"},
        {pos: [13, 3, 19], state: "minecraft:gravel"},
        {pos: [13, 3, 20], state: "minecraft:gravel"},
        {pos: [13, 3, 21], state: "minecraft:gravel"},
        {pos: [14, 3, 6], state: "minecraft:cobblestone"},
        {pos: [14, 3, 7], state: "minecraft:cobblestone"},
        {pos: [14, 3, 8], state: "minecraft:cobblestone"},
        {pos: [14, 3, 13], state: "minecraft:gravel"},
        {pos: [14, 3, 14], state: "minecraft:gravel"},
        {pos: [14, 3, 16], state: "minecraft:gravel"},
        {pos: [14, 3, 17], state: "minecraft:gravel"},
        {pos: [14, 3, 20], state: "minecraft:gravel"},
        {pos: [15, 3, 6], state: "minecraft:cobblestone"},
        {pos: [15, 3, 7], state: "minecraft:gravel"},
        {pos: [15, 3, 8], state: "minecraft:gravel"},
        {pos: [15, 3, 9], state: "minecraft:gravel"},
        {pos: [15, 3, 16], state: "minecraft:gravel"},
        {pos: [15, 3, 17], state: "minecraft:gravel"},
        {pos: [15, 3, 18], state: "minecraft:gravel"},
        {pos: [16, 3, 6], state: "minecraft:cobblestone"},
        {pos: [16, 3, 7], state: "minecraft:cobblestone"},
        {pos: [16, 3, 8], state: "minecraft:cobblestone"},
        {pos: [16, 3, 9], state: "minecraft:gravel"},
        {pos: [16, 3, 10], state: "minecraft:gravel"},
        {pos: [16, 3, 15], state: "minecraft:gravel"},
        {pos: [16, 3, 16], state: "minecraft:gravel"},
        {pos: [16, 3, 17], state: "minecraft:gravel"},
        {pos: [16, 3, 18], state: "minecraft:gravel"},
        {pos: [17, 3, 1], state: "minecraft:gravel"},
        {pos: [17, 3, 2], state: "minecraft:gravel"},
        {pos: [17, 3, 3], state: "minecraft:gravel"},
        {pos: [17, 3, 9], state: "minecraft:gravel"},
        {pos: [17, 3, 14], state: "minecraft:gravel"},
        {pos: [17, 3, 15], state: "minecraft:gravel"},
        {pos: [17, 3, 16], state: "minecraft:gravel"},
        {pos: [17, 3, 17], state: "minecraft:gravel"},
        {pos: [17, 3, 21], state: "minecraft:gravel"},
        {pos: [17, 3, 22], state: "minecraft:gravel"},
        {pos: [18, 3, 0], state: "minecraft:gravel"},
        {pos: [18, 3, 1], state: "minecraft:gravel"},
        {pos: [18, 3, 2], state: "minecraft:gravel"},
        {pos: [18, 3, 3], state: "minecraft:gravel"},
        {pos: [18, 3, 5], state: "minecraft:gravel"},
        {pos: [18, 3, 6], state: "minecraft:gravel"},
        {pos: [18, 3, 7], state: "minecraft:gravel"},
        {pos: [18, 3, 8], state: "minecraft:gravel"},
        {pos: [18, 3, 9], state: "minecraft:gravel"},
        {pos: [18, 3, 10], state: "minecraft:gravel"},
        {pos: [18, 3, 11], state: "minecraft:gravel"},
        {pos: [18, 3, 12], state: "minecraft:gravel"},
        {pos: [18, 3, 13], state: "minecraft:gravel"},
        {pos: [18, 3, 14], state: "minecraft:gravel"},
        {pos: [18, 3, 19], state: "minecraft:gravel"},
        {pos: [18, 3, 20], state: "minecraft:gravel"},
        {pos: [18, 3, 21], state: "minecraft:gravel"},
        {pos: [18, 3, 22], state: "minecraft:gravel"},
        {pos: [19, 3, 0], state: "minecraft:gravel"},
        {pos: [19, 3, 1], state: "minecraft:gravel"},
        {pos: [19, 3, 2], state: "minecraft:gravel"},
        {pos: [19, 3, 3], state: "minecraft:gravel"},
        {pos: [19, 3, 4], state: "minecraft:gravel"},
        {pos: [19, 3, 5], state: "minecraft:gravel"},
        {pos: [19, 3, 6], state: "minecraft:gravel"},
        {pos: [19, 3, 7], state: "minecraft:gravel"},
        {pos: [19, 3, 8], state: "minecraft:gravel"},
        {pos: [19, 3, 9], state: "minecraft:gravel"},
        {pos: [19, 3, 10], state: "minecraft:gravel"},
        {pos: [19, 3, 11], state: "minecraft:gravel"},
        {pos: [19, 3, 12], state: "minecraft:gravel"},
        {pos: [19, 3, 13], state: "minecraft:gravel"},
        {pos: [19, 3, 14], state: "minecraft:gravel"},
        {pos: [19, 3, 15], state: "minecraft:gravel"},
        {pos: [19, 3, 16], state: "minecraft:gravel"},
        {pos: [19, 3, 19], state: "minecraft:gravel"},
        {pos: [19, 3, 20], state: "minecraft:gravel"},
        {pos: [19, 3, 21], state: "minecraft:gravel"},
        {pos: [19, 3, 22], state: "minecraft:gravel"},
        {pos: [20, 3, 0], state: "minecraft:gravel"},
        {pos: [20, 3, 1], state: "minecraft:gravel"},
        {pos: [20, 3, 2], state: "minecraft:gravel"},
        {pos: [20, 3, 3], state: "minecraft:gravel"},
        {pos: [20, 3, 7], state: "minecraft:cobblestone"},
        {pos: [20, 3, 10], state: "minecraft:gravel"},
        {pos: [20, 3, 11], state: "minecraft:gravel"},
        {pos: [20, 3, 14], state: "minecraft:gravel"},
        {pos: [20, 3, 15], state: "minecraft:gravel"},
        {pos: [20, 3, 19], state: "minecraft:cobblestone"},
        {pos: [20, 3, 20], state: "minecraft:gravel"},
        {pos: [20, 3, 21], state: "minecraft:gravel"},
        {pos: [20, 3, 22], state: "minecraft:gravel"},
        {pos: [21, 3, 0], state: "minecraft:gravel"},
        {pos: [21, 3, 1], state: "minecraft:gravel"},
        {pos: [21, 3, 2], state: "minecraft:gravel"},
        {pos: [21, 3, 6], state: "minecraft:cobblestone"},
        {pos: [21, 3, 7], state: "minecraft:cobblestone"},
        {pos: [21, 3, 8], state: "minecraft:gravel"},
        {pos: [21, 3, 13], state: "minecraft:gravel"},
        {pos: [21, 3, 14], state: "minecraft:gravel"},
        {pos: [21, 3, 15], state: "minecraft:gravel"},
        {pos: [21, 3, 16], state: "minecraft:gravel"},
        {pos: [21, 3, 19], state: "minecraft:gravel"},
        {pos: [21, 3, 20], state: "minecraft:gravel"},
        {pos: [21, 3, 21], state: "minecraft:cobblestone"},
        {pos: [21, 3, 22], state: "minecraft:cobblestone"},
        {pos: [22, 3, 6], state: "minecraft:cobblestone"},
        {pos: [22, 3, 7], state: "minecraft:cobblestone"},
        {pos: [22, 3, 8], state: "minecraft:gravel"},
        {pos: [22, 3, 12], state: "minecraft:gravel"},
        {pos: [22, 3, 13], state: "minecraft:gravel"},
        {pos: [22, 3, 14], state: "minecraft:gravel"},
        {pos: [22, 3, 15], state: "minecraft:gravel"},
        {pos: [22, 3, 16], state: "minecraft:gravel"},
        {pos: [22, 3, 17], state: "minecraft:gravel"},
        {pos: [23, 3, 6], state: "minecraft:cobblestone"},
        {pos: [23, 3, 7], state: "minecraft:cobblestone"},
        {pos: [23, 3, 8], state: "minecraft:gravel"},
        {pos: [23, 3, 12], state: "minecraft:gravel"},
        {pos: [23, 3, 13], state: "minecraft:cobblestone"},
        {pos: [23, 3, 14], state: "minecraft:cobblestone_stairs{facing:east,half:top,shape:straight,waterlogged:false}"},
        {pos: [23, 3, 15], state: "minecraft:cobblestone"},
        {pos: [23, 3, 16], state: "minecraft:cobblestone_stairs{facing:east,half:top,shape:straight,waterlogged:false}"},
        {pos: [23, 3, 17], state: "minecraft:cobblestone"},
        {pos: [24, 3, 6], state: "minecraft:gravel"},
        {pos: [24, 3, 7], state: "minecraft:cobblestone"},
        {pos: [24, 3, 12], state: "minecraft:gravel"},
        {pos: [24, 3, 13], state: "minecraft:gravel"},
        {pos: [24, 3, 14], state: "minecraft:gravel"},
        {pos: [24, 3, 15], state: "minecraft:gravel"},
        {pos: [24, 3, 16], state: "minecraft:gravel"},
        {pos: [24, 3, 17], state: "minecraft:gravel"},
        {pos: [25, 3, 12], state: "minecraft:gravel"},
        {pos: [25, 3, 13], state: "minecraft:gravel"},
        {pos: [25, 3, 14], state: "minecraft:gravel"},
        {pos: [25, 3, 15], state: "minecraft:gravel"},
        {pos: [0, 4, 18], state: "minecraft:gravel"},
        {pos: [0, 4, 19], state: "minecraft:gravel"},
        {pos: [0, 4, 20], state: "minecraft:gravel"},
        {pos: [1, 4, 16], state: "minecraft:gravel"},
        {pos: [1, 4, 17], state: "minecraft:gravel"},
        {pos: [1, 4, 18], state: "minecraft:cobblestone"},
        {pos: [1, 4, 19], state: "minecraft:cobblestone"},
        {pos: [1, 4, 20], state: "minecraft:gravel"},
        {pos: [2, 4, 13], state: "minecraft:gravel"},
        {pos: [2, 4, 14], state: "minecraft:gravel"},
        {pos: [2, 4, 15], state: "minecraft:gravel"},
        {pos: [2, 4, 16], state: "minecraft:gravel"},
        {pos: [2, 4, 17], state: "minecraft:gravel"},
        {pos: [2, 4, 18], state: "minecraft:gravel"},
        {pos: [2, 4, 19], state: "minecraft:cobblestone"},
        {pos: [2, 4, 20], state: "minecraft:gravel"},
        {pos: [3, 4, 13], state: "minecraft:gravel"},
        {pos: [3, 4, 14], state: "minecraft:gravel"},
        {pos: [3, 4, 15], state: "minecraft:gravel"},
        {pos: [3, 4, 16], state: "minecraft:gravel"},
        {pos: [3, 4, 17], state: "minecraft:gravel"},
        {pos: [3, 4, 18], state: "minecraft:gravel"},
        {pos: [3, 4, 19], state: "minecraft:gravel"},
        {pos: [3, 4, 20], state: "minecraft:gravel"},
        {pos: [4, 4, 13], state: "minecraft:gravel"},
        {pos: [4, 4, 14], state: "minecraft:gravel"},
        {pos: [4, 4, 15], state: "minecraft:gravel"},
        {pos: [4, 4, 16], state: "minecraft:gravel"},
        {pos: [4, 4, 17], state: "minecraft:gravel"},
        {pos: [4, 4, 18], state: "minecraft:gravel"},
        {pos: [4, 4, 19], state: "minecraft:gravel"},
        {pos: [4, 4, 20], state: "minecraft:gravel"},
        {pos: [5, 4, 13], state: "minecraft:gravel"},
        {pos: [5, 4, 14], state: "minecraft:gravel"},
        {pos: [5, 4, 15], state: "minecraft:gravel"},
        {pos: [5, 4, 16], state: "minecraft:gravel"},
        {pos: [5, 4, 17], state: "minecraft:gravel"},
        {pos: [5, 4, 18], state: "minecraft:gravel"},
        {pos: [5, 4, 19], state: "minecraft:gravel"},
        {pos: [5, 4, 20], state: "minecraft:gravel"},
        {pos: [6, 4, 14], state: "minecraft:cobblestone"},
        {pos: [6, 4, 15], state: "minecraft:gravel"},
        {pos: [6, 4, 16], state: "minecraft:cobblestone"},
        {pos: [6, 4, 17], state: "minecraft:cobblestone"},
        {pos: [6, 4, 18], state: "minecraft:gravel"},
        {pos: [6, 4, 19], state: "minecraft:cobblestone"},
        {pos: [7, 4, 16], state: "minecraft:gravel"},
        {pos: [7, 4, 17], state: "minecraft:gravel"},
        {pos: [7, 4, 18], state: "minecraft:gravel"},
        {pos: [8, 4, 17], state: "minecraft:gravel"},
        {pos: [8, 4, 18], state: "minecraft:gravel"},
        {pos: [10, 4, 16], state: "minecraft:gravel"},
        {pos: [10, 4, 17], state: "minecraft:gravel"},
        {pos: [11, 4, 15], state: "minecraft:gravel"},
        {pos: [11, 4, 16], state: "minecraft:gravel"},
        {pos: [11, 4, 17], state: "minecraft:gravel"},
        {pos: [12, 4, 13], state: "minecraft:gravel"},
        {pos: [12, 4, 14], state: "minecraft:cobblestone"},
        {pos: [12, 4, 15], state: "minecraft:cobblestone"},
        {pos: [12, 4, 16], state: "minecraft:cobblestone"},
        {pos: [12, 4, 17], state: "minecraft:cobblestone"},
        {pos: [12, 4, 18], state: "minecraft:cobblestone"},
        {pos: [12, 4, 19], state: "minecraft:gravel"},
        {pos: [12, 4, 20], state: "minecraft:gravel"},
        {pos: [13, 4, 13], state: "minecraft:gravel"},
        {pos: [13, 4, 14], state: "minecraft:cobblestone"},
        {pos: [13, 4, 15], state: "minecraft:cobblestone"},
        {pos: [13, 4, 16], state: "minecraft:cobblestone"},
        {pos: [13, 4, 17], state: "minecraft:cobblestone"},
        {pos: [13, 4, 18], state: "minecraft:cobblestone"},
        {pos: [13, 4, 19], state: "minecraft:gravel"},
        {pos: [13, 4, 20], state: "minecraft:gravel"},
        {pos: [14, 4, 6], state: "minecraft:gravel"},
        {pos: [14, 4, 7], state: "minecraft:cobblestone"},
        {pos: [14, 4, 8], state: "minecraft:cobblestone"},
        {pos: [14, 4, 13], state: "minecraft:gravel"},
        {pos: [14, 4, 14], state: "minecraft:gravel"},
        {pos: [15, 4, 6], state: "minecraft:cobblestone"},
        {pos: [15, 4, 7], state: "minecraft:cobblestone"},
        {pos: [15, 4, 8], state: "minecraft:cobblestone"},
        {pos: [16, 4, 6], state: "minecraft:cobblestone"},
        {pos: [16, 4, 7], state: "minecraft:cobblestone"},
        {pos: [16, 4, 8], state: "minecraft:cobblestone"},
        {pos: [16, 4, 9], state: "minecraft:gravel"},
        {pos: [16, 4, 15], state: "minecraft:gravel"},
        {pos: [17, 4, 9], state: "minecraft:gravel"},
        {pos: [17, 4, 14], state: "minecraft:gravel"},
        {pos: [17, 4, 15], state: "minecraft:gravel"},
        {pos: [17, 4, 16], state: "minecraft:gravel"},
        {pos: [18, 4, 1], state: "minecraft:gravel"},
        {pos: [18, 4, 2], state: "minecraft:gravel"},
        {pos: [18, 4, 6], state: "minecraft:gravel"},
        {pos: [18, 4, 7], state: "minecraft:gravel"},
        {pos: [18, 4, 8], state: "minecraft:gravel"},
        {pos: [18, 4, 9], state: "minecraft:gravel"},
        {pos: [18, 4, 14], state: "minecraft:gravel"},
        {pos: [18, 4, 19], state: "minecraft:gravel"},
        {pos: [18, 4, 20], state: "minecraft:cobblestone"},
        {pos: [18, 4, 21], state: "minecraft:cobblestone"},
        {pos: [18, 4, 22], state: "minecraft:cobblestone"},
        {pos: [19, 4, 0], state: "minecraft:gravel"},
        {pos: [19, 4, 1], state: "minecraft:gravel"},
        {pos: [19, 4, 2], state: "minecraft:gravel"},
        {pos: [19, 4, 3], state: "minecraft:gravel"},
        {pos: [19, 4, 7], state: "minecraft:gravel"},
        {pos: [19, 4, 8], state: "minecraft:gravel"},
        {pos: [19, 4, 9], state: "minecraft:gravel"},
        {pos: [19, 4, 10], state: "minecraft:gravel"},
        {pos: [19, 4, 14], state: "minecraft:gravel"},
        {pos: [19, 4, 19], state: "minecraft:cobblestone"},
        {pos: [19, 4, 20], state: "minecraft:gravel"},
        {pos: [19, 4, 21], state: "minecraft:gravel"},
        {pos: [19, 4, 22], state: "minecraft:cobblestone"},
        {pos: [20, 4, 0], state: "minecraft:gravel"},
        {pos: [20, 4, 1], state: "minecraft:gravel"},
        {pos: [20, 4, 2], state: "minecraft:gravel"},
        {pos: [20, 4, 3], state: "minecraft:gravel"},
        {pos: [20, 4, 7], state: "minecraft:cobblestone"},
        {pos: [20, 4, 8], state: "minecraft:cobblestone"},
        {pos: [20, 4, 19], state: "minecraft:gravel"},
        {pos: [20, 4, 20], state: "minecraft:cobblestone"},
        {pos: [20, 4, 21], state: "minecraft:cobblestone"},
        {pos: [20, 4, 22], state: "minecraft:cobblestone"},
        {pos: [21, 4, 0], state: "minecraft:gravel"},
        {pos: [21, 4, 1], state: "minecraft:gravel"},
        {pos: [21, 4, 6], state: "minecraft:cobblestone"},
        {pos: [21, 4, 7], state: "minecraft:cobblestone"},
        {pos: [21, 4, 8], state: "minecraft:cobblestone"},
        {pos: [21, 4, 14], state: "minecraft:gravel"},
        {pos: [21, 4, 15], state: "minecraft:gravel"},
        {pos: [21, 4, 20], state: "minecraft:gravel"},
        {pos: [21, 4, 21], state: "minecraft:gravel"},
        {pos: [21, 4, 22], state: "minecraft:gravel"},
        {pos: [22, 4, 6], state: "minecraft:cobblestone"},
        {pos: [22, 4, 7], state: "minecraft:cobblestone"},
        {pos: [22, 4, 8], state: "minecraft:gravel"},
        {pos: [22, 4, 13], state: "minecraft:gravel"},
        {pos: [22, 4, 14], state: "minecraft:gravel"},
        {pos: [22, 4, 15], state: "minecraft:gravel"},
        {pos: [23, 4, 6], state: "minecraft:cobblestone"},
        {pos: [23, 4, 7], state: "minecraft:gravel"},
        {pos: [23, 4, 12], state: "minecraft:gravel"},
        {pos: [23, 4, 13], state: "minecraft:gravel"},
        {pos: [23, 4, 14], state: "minecraft:gravel"},
        {pos: [23, 4, 15], state: "minecraft:cobblestone"},
        {pos: [23, 4, 16], state: "minecraft:cobblestone"},
        {pos: [23, 4, 17], state: "minecraft:cobblestone"},
        {pos: [24, 4, 13], state: "minecraft:gravel"},
        {pos: [24, 4, 14], state: "minecraft:gravel"},
        {pos: [24, 4, 15], state: "minecraft:gravel"},
        {pos: [24, 4, 16], state: "minecraft:gravel"},
        {pos: [0, 5, 18], state: "minecraft:gravel"},
        {pos: [0, 5, 19], state: "minecraft:gravel"},
        {pos: [1, 5, 16], state: "minecraft:gravel"},
        {pos: [1, 5, 17], state: "minecraft:gravel"},
        {pos: [1, 5, 18], state: "minecraft:gravel"},
        {pos: [1, 5, 19], state: "minecraft:cobblestone"},
        {pos: [1, 5, 20], state: "minecraft:gravel"},
        {pos: [2, 5, 13], state: "minecraft:gravel"},
        {pos: [2, 5, 14], state: "minecraft:gravel"},
        {pos: [2, 5, 15], state: "minecraft:gravel"},
        {pos: [2, 5, 16], state: "minecraft:gravel"},
        {pos: [2, 5, 17], state: "minecraft:gravel"},
        {pos: [2, 5, 18], state: "minecraft:gravel"},
        {pos: [2, 5, 19], state: "minecraft:cobblestone"},
        {pos: [2, 5, 20], state: "minecraft:gravel"},
        {pos: [3, 5, 13], state: "minecraft:gravel"},
        {pos: [3, 5, 14], state: "minecraft:gravel"},
        {pos: [3, 5, 15], state: "minecraft:gravel"},
        {pos: [3, 5, 16], state: "minecraft:gravel"},
        {pos: [3, 5, 17], state: "minecraft:gravel"},
        {pos: [3, 5, 18], state: "minecraft:gravel"},
        {pos: [3, 5, 19], state: "minecraft:gravel"},
        {pos: [3, 5, 20], state: "minecraft:gravel"},
        {pos: [4, 5, 13], state: "minecraft:gravel"},
        {pos: [4, 5, 14], state: "minecraft:gravel"},
        {pos: [4, 5, 15], state: "minecraft:gravel"},
        {pos: [4, 5, 16], state: "minecraft:gravel"},
        {pos: [4, 5, 17], state: "minecraft:gravel"},
        {pos: [4, 5, 18], state: "minecraft:gravel"},
        {pos: [4, 5, 19], state: "minecraft:gravel"},
        {pos: [4, 5, 20], state: "minecraft:gravel"},
        {pos: [5, 5, 13], state: "minecraft:gravel"},
        {pos: [5, 5, 14], state: "minecraft:gravel"},
        {pos: [5, 5, 15], state: "minecraft:gravel"},
        {pos: [5, 5, 16], state: "minecraft:gravel"},
        {pos: [5, 5, 17], state: "minecraft:gravel"},
        {pos: [5, 5, 18], state: "minecraft:gravel"},
        {pos: [5, 5, 19], state: "minecraft:gravel"},
        {pos: [5, 5, 20], state: "minecraft:gravel"},
        {pos: [6, 5, 14], state: "minecraft:cobblestone"},
        {pos: [6, 5, 15], state: "minecraft:cobblestone"},
        {pos: [6, 5, 16], state: "minecraft:cobblestone"},
        {pos: [6, 5, 17], state: "minecraft:cobblestone"},
        {pos: [6, 5, 18], state: "minecraft:cobblestone"},
        {pos: [6, 5, 19], state: "minecraft:cobblestone"},
        {pos: [7, 5, 17], state: "minecraft:gravel"},
        {pos: [11, 5, 16], state: "minecraft:gravel"},
        {pos: [12, 5, 14], state: "minecraft:gravel"},
        {pos: [12, 5, 15], state: "minecraft:cobblestone"},
        {pos: [12, 5, 16], state: "minecraft:cobblestone"},
        {pos: [12, 5, 17], state: "minecraft:cobblestone"},
        {pos: [12, 5, 18], state: "minecraft:gravel"},
        {pos: [12, 5, 19], state: "minecraft:gravel"},
        {pos: [13, 5, 13], state: "minecraft:gravel"},
        {pos: [13, 5, 14], state: "minecraft:gravel"},
        {pos: [13, 5, 15], state: "minecraft:cobblestone"},
        {pos: [13, 5, 16], state: "minecraft:cobblestone"},
        {pos: [13, 5, 17], state: "minecraft:cobblestone"},
        {pos: [13, 5, 18], state: "minecraft:gravel"},
        {pos: [14, 5, 6], state: "minecraft:gravel"},
        {pos: [14, 5, 7], state: "minecraft:gravel"},
        {pos: [14, 5, 8], state: "minecraft:gravel"},
        {pos: [15, 5, 6], state: "minecraft:cobblestone"},
        {pos: [15, 5, 7], state: "minecraft:cobblestone"},
        {pos: [15, 5, 8], state: "minecraft:cobblestone"},
        {pos: [16, 5, 6], state: "minecraft:cobblestone"},
        {pos: [16, 5, 7], state: "minecraft:cobblestone"},
        {pos: [16, 5, 8], state: "minecraft:gravel"},
        {pos: [17, 5, 6], state: "minecraft:cobblestone"},
        {pos: [18, 5, 20], state: "minecraft:cobblestone"},
        {pos: [18, 5, 21], state: "minecraft:cobblestone"},
        {pos: [18, 5, 22], state: "minecraft:cobblestone"},
        {pos: [19, 5, 19], state: "minecraft:cobblestone"},
        {pos: [19, 5, 20], state: "minecraft:green_glazed_terracotta{facing:west}"},
        {pos: [19, 5, 21], state: "minecraft:green_glazed_terracotta{facing:north}"},
        {pos: [19, 5, 22], state: "minecraft:cobblestone"},
        {pos: [20, 5, 20], state: "minecraft:cobblestone"},
        {pos: [20, 5, 21], state: "minecraft:cobblestone"},
        {pos: [20, 5, 22], state: "minecraft:gravel"},
        {pos: [21, 5, 7], state: "minecraft:cobblestone"},
        {pos: [22, 5, 7], state: "minecraft:cobblestone"},
        {pos: [2, 6, 14], state: "minecraft:gravel"},
        {pos: [2, 6, 15], state: "minecraft:cobblestone"},
        {pos: [2, 6, 16], state: "minecraft:gravel"},
        {pos: [2, 6, 17], state: "minecraft:gravel"},
        {pos: [2, 6, 18], state: "minecraft:gravel"},
        {pos: [3, 6, 14], state: "minecraft:cobblestone"},
        {pos: [3, 6, 15], state: "minecraft:gravel"},
        {pos: [3, 6, 16], state: "minecraft:gravel"},
        {pos: [3, 6, 17], state: "minecraft:gravel"},
        {pos: [3, 6, 18], state: "minecraft:gravel"},
        {pos: [4, 6, 14], state: "minecraft:gravel"},
        {pos: [4, 6, 15], state: "minecraft:gravel"},
        {pos: [4, 6, 16], state: "minecraft:gravel"},
        {pos: [4, 6, 17], state: "minecraft:gravel"},
        {pos: [4, 6, 18], state: "minecraft:gravel"},
        {pos: [4, 6, 19], state: "minecraft:gravel"},
        {pos: [5, 6, 14], state: "minecraft:gravel"},
        {pos: [5, 6, 15], state: "minecraft:gravel"},
        {pos: [5, 6, 16], state: "minecraft:gravel"},
        {pos: [5, 6, 17], state: "minecraft:gravel"},
        {pos: [5, 6, 18], state: "minecraft:gravel"},
        {pos: [5, 6, 19], state: "minecraft:gravel"},
        {pos: [6, 6, 14], state: "minecraft:cobblestone"},
        {pos: [6, 6, 15], state: "minecraft:air"},
        {pos: [6, 6, 16], state: "minecraft:cobblestone"},
        {pos: [6, 6, 17], state: "minecraft:cobblestone"},
        {pos: [15, 6, 6], state: "minecraft:gravel"},
        {pos: [15, 6, 7], state: "minecraft:cobblestone"},
        {pos: [15, 6, 8], state: "minecraft:gravel"},
        {pos: [16, 6, 6], state: "minecraft:cobblestone"},
        {pos: [16, 6, 7], state: "minecraft:cobblestone"},
        {pos: [17, 6, 6], state: "minecraft:cobblestone"},
        {pos: [17, 6, 7], state: "minecraft:cobblestone"},
        {pos: [18, 6, 6], state: "minecraft:cobblestone"},
        {pos: [18, 6, 7], state: "minecraft:cobblestone"},
        {pos: [18, 6, 21], state: "minecraft:cobblestone"},
        {pos: [19, 6, 20], state: "minecraft:cobblestone"},
        {pos: [19, 6, 21], state: "minecraft:cobblestone"},
        {pos: [19, 6, 22], state: "minecraft:gravel"},
        {pos: [20, 6, 21], state: "minecraft:gravel"},
        {pos: [20, 6, 22], state: "minecraft:gravel"},
        {pos: [2, 7, 15], state: "minecraft:cobblestone"},
        {pos: [3, 7, 14], state: "minecraft:cobblestone"},
        {pos: [3, 7, 15], state: "minecraft:gravel"},
        {pos: [3, 7, 16], state: "minecraft:gravel"},
        {pos: [16, 7, 7], state: "minecraft:cobblestone"},
        {pos: [17, 7, 6], state: "minecraft:cobblestone"},
        {pos: [17, 7, 7], state: "minecraft:cobblestone"},
        {pos: [18, 7, 6], state: "minecraft:gravel"},
        {pos: [18, 7, 7], state: "minecraft:cobblestone"},
        {pos: [2, 8, 15], state: "minecraft:gravel"},
        {pos: [3, 8, 14], state: "minecraft:cobblestone"},
        {pos: [17, 8, 6], state: "minecraft:gravel"},
        {pos: [18, 8, 7], state: "minecraft:gravel"},
        {pos: [3, 9, 14], state: "minecraft:gravel"}
    ],
    entities: [],
    palette: [
        "minecraft:cobblestone",
        "minecraft:gravel",
        "minecraft:gray_glazed_terracotta{facing:south}",
        "minecraft:gray_glazed_terracotta{facing:west}",
        "minecraft:gray_glazed_terracotta{facing:north}",
        "minecraft:chiseled_stone_bricks",
        "minecraft:green_glazed_terracotta{facing:west}",
        "minecraft:green_glazed_terracotta{facing:north}",
        "minecraft:cobblestone_wall{east:tall,north:tall,south:tall,up:false,waterlogged:false,west:tall}",
        "minecraft:water_cauldron{level:3}",
        "minecraft:cobblestone_stairs{facing:north,half:top,shape:straight,waterlogged:false}",
        "minecraft:cobblestone_stairs{facing:south,half:top,shape:straight,waterlogged:false}",
        "minecraft:cobblestone_stairs{facing:east,half:top,shape:straight,waterlogged:false}",
        "minecraft:air"
    ],
    trailiertales_DataVersion: 2
}
