{
    DataVersion: 3953,
    size: [12, 10, 22],
    data: [
        {pos: [0, 0, 7], state: "minecraft:cobblestone"},
        {pos: [0, 0, 8], state: "minecraft:cobblestone"},
        {pos: [0, 0, 9], state: "minecraft:cobblestone"},
        {pos: [0, 0, 12], state: "minecraft:cobblestone"},
        {pos: [0, 0, 13], state: "minecraft:cobblestone"},
        {pos: [1, 0, 7], state: "minecraft:cobblestone"},
        {pos: [1, 0, 8], state: "minecraft:cobblestone"},
        {pos: [1, 0, 9], state: "minecraft:cobblestone"},
        {pos: [1, 0, 12], state: "minecraft:cobblestone"},
        {pos: [1, 0, 13], state: "minecraft:cobblestone"},
        {pos: [1, 0, 14], state: "minecraft:cobblestone"},
        {pos: [1, 0, 18], state: "minecraft:cobblestone"},
        {pos: [1, 0, 19], state: "minecraft:cobblestone"},
        {pos: [1, 0, 20], state: "minecraft:cobblestone"},
        {pos: [2, 0, 7], state: "minecraft:cobblestone"},
        {pos: [2, 0, 8], state: "minecraft:cobblestone"},
        {pos: [2, 0, 9], state: "minecraft:cobblestone"},
        {pos: [2, 0, 12], state: "minecraft:cobblestone"},
        {pos: [2, 0, 13], state: "minecraft:cobblestone"},
        {pos: [2, 0, 14], state: "minecraft:cobblestone"},
        {pos: [2, 0, 17], state: "minecraft:cobblestone"},
        {pos: [2, 0, 18], state: "minecraft:cobblestone"},
        {pos: [2, 0, 19], state: "minecraft:cobblestone"},
        {pos: [2, 0, 20], state: "minecraft:cobblestone"},
        {pos: [3, 0, 16], state: "minecraft:cobblestone"},
        {pos: [3, 0, 17], state: "minecraft:cobblestone"},
        {pos: [3, 0, 18], state: "minecraft:cobblestone"},
        {pos: [3, 0, 19], state: "minecraft:cobblestone"},
        {pos: [3, 0, 20], state: "minecraft:cobblestone"},
        {pos: [4, 0, 0], state: "minecraft:cobblestone"},
        {pos: [4, 0, 1], state: "minecraft:cobblestone"},
        {pos: [4, 0, 2], state: "minecraft:cobblestone"},
        {pos: [4, 0, 8], state: "minecraft:cobblestone"},
        {pos: [4, 0, 9], state: "minecraft:cobblestone"},
        {pos: [4, 0, 10], state: "minecraft:cobblestone"},
        {pos: [4, 0, 12], state: "minecraft:cobblestone"},
        {pos: [4, 0, 13], state: "minecraft:cobblestone"},
        {pos: [4, 0, 14], state: "minecraft:cobblestone"},
        {pos: [4, 0, 15], state: "minecraft:cobblestone"},
        {pos: [4, 0, 16], state: "minecraft:cobblestone"},
        {pos: [4, 0, 17], state: "minecraft:cobblestone"},
        {pos: [4, 0, 18], state: "minecraft:cobblestone"},
        {pos: [4, 0, 19], state: "minecraft:cobblestone"},
        {pos: [4, 0, 20], state: "minecraft:cobblestone"},
        {pos: [5, 0, 0], state: "minecraft:cobblestone"},
        {pos: [5, 0, 1], state: "minecraft:cobblestone"},
        {pos: [5, 0, 2], state: "minecraft:cobblestone"},
        {pos: [5, 0, 3], state: "minecraft:cobblestone"},
        {pos: [5, 0, 7], state: "minecraft:cobblestone"},
        {pos: [5, 0, 8], state: "minecraft:cobblestone"},
        {pos: [5, 0, 9], state: "minecraft:cobblestone"},
        {pos: [5, 0, 10], state: "minecraft:cobblestone"},
        {pos: [5, 0, 11], state: "minecraft:cobblestone"},
        {pos: [5, 0, 13], state: "minecraft:cobblestone"},
        {pos: [5, 0, 14], state: "minecraft:cobblestone"},
        {pos: [5, 0, 15], state: "minecraft:cobblestone"},
        {pos: [5, 0, 16], state: "minecraft:cobblestone"},
        {pos: [5, 0, 17], state: "minecraft:cobblestone"},
        {pos: [5, 0, 18], state: "minecraft:cobblestone"},
        {pos: [5, 0, 19], state: "minecraft:cobblestone"},
        {pos: [5, 0, 20], state: "minecraft:cobblestone"},
        {pos: [5, 0, 21], state: "minecraft:cobblestone"},
        {pos: [6, 0, 0], state: "minecraft:cobblestone"},
        {pos: [6, 0, 1], state: "minecraft:cobblestone"},
        {pos: [6, 0, 2], state: "minecraft:cobblestone"},
        {pos: [6, 0, 3], state: "minecraft:cobblestone"},
        {pos: [6, 0, 5], state: "minecraft:cobblestone"},
        {pos: [6, 0, 8], state: "minecraft:cobblestone"},
        {pos: [6, 0, 9], state: "minecraft:cobblestone"},
        {pos: [6, 0, 10], state: "minecraft:cobblestone"},
        {pos: [6, 0, 11], state: "minecraft:cobblestone"},
        {pos: [6, 0, 12], state: "minecraft:cobblestone"},
        {pos: [6, 0, 14], state: "minecraft:cobblestone"},
        {pos: [6, 0, 15], state: "minecraft:cobblestone"},
        {pos: [6, 0, 16], state: "minecraft:cobblestone"},
        {pos: [6, 0, 17], state: "minecraft:cobblestone"},
        {pos: [6, 0, 18], state: "minecraft:cobblestone"},
        {pos: [6, 0, 19], state: "minecraft:cobblestone"},
        {pos: [6, 0, 20], state: "minecraft:cobblestone"},
        {pos: [6, 0, 21], state: "minecraft:cobblestone"},
        {pos: [7, 0, 0], state: "minecraft:cobblestone"},
        {pos: [7, 0, 1], state: "minecraft:cobblestone"},
        {pos: [7, 0, 2], state: "minecraft:cobblestone"},
        {pos: [7, 0, 3], state: "minecraft:cobblestone"},
        {pos: [7, 0, 5], state: "minecraft:cobblestone"},
        {pos: [7, 0, 6], state: "minecraft:cobblestone"},
        {pos: [7, 0, 10], state: "minecraft:cobblestone"},
        {pos: [7, 0, 11], state: "minecraft:cobblestone"},
        {pos: [7, 0, 12], state: "minecraft:cobblestone"},
        {pos: [7, 0, 13], state: "minecraft:cobblestone"},
        {pos: [7, 0, 14], state: "minecraft:cobblestone"},
        {pos: [7, 0, 15], state: "minecraft:cobblestone"},
        {pos: [7, 0, 16], state: "minecraft:cobblestone"},
        {pos: [7, 0, 17], state: "minecraft:cobblestone"},
        {pos: [7, 0, 18], state: "minecraft:cobblestone"},
        {pos: [7, 0, 19], state: "minecraft:cobblestone"},
        {pos: [7, 0, 20], state: "minecraft:cobblestone"},
        {pos: [7, 0, 21], state: "minecraft:cobblestone"},
        {pos: [8, 0, 0], state: "minecraft:cobblestone"},
        {pos: [8, 0, 1], state: "minecraft:cobblestone"},
        {pos: [8, 0, 2], state: "minecraft:cobblestone"},
        {pos: [8, 0, 15], state: "minecraft:cobblestone"},
        {pos: [8, 0, 16], state: "minecraft:cobblestone"},
        {pos: [8, 0, 17], state: "minecraft:cobblestone"},
        {pos: [8, 0, 18], state: "minecraft:cobblestone"},
        {pos: [8, 0, 19], state: "minecraft:cobblestone"},
        {pos: [8, 0, 20], state: "minecraft:cobblestone"},
        {pos: [9, 0, 6], state: "minecraft:cobblestone"},
        {pos: [9, 0, 7], state: "minecraft:cobblestone"},
        {pos: [9, 0, 8], state: "minecraft:cobblestone"},
        {pos: [9, 0, 11], state: "minecraft:cobblestone"},
        {pos: [9, 0, 12], state: "minecraft:cobblestone"},
        {pos: [9, 0, 16], state: "minecraft:cobblestone"},
        {pos: [9, 0, 17], state: "minecraft:cobblestone"},
        {pos: [9, 0, 18], state: "minecraft:cobblestone"},
        {pos: [9, 0, 19], state: "minecraft:cobblestone"},
        {pos: [9, 0, 20], state: "minecraft:cobblestone"},
        {pos: [10, 0, 6], state: "minecraft:cobblestone"},
        {pos: [10, 0, 7], state: "minecraft:cobblestone"},
        {pos: [10, 0, 8], state: "minecraft:cobblestone"},
        {pos: [10, 0, 11], state: "minecraft:cobblestone"},
        {pos: [10, 0, 12], state: "minecraft:cobblestone"},
        {pos: [10, 0, 13], state: "minecraft:cobblestone"},
        {pos: [10, 0, 17], state: "minecraft:cobblestone"},
        {pos: [10, 0, 18], state: "minecraft:cobblestone"},
        {pos: [10, 0, 19], state: "minecraft:cobblestone"},
        {pos: [10, 0, 20], state: "minecraft:cobblestone"},
        {pos: [11, 0, 6], state: "minecraft:cobblestone"},
        {pos: [11, 0, 7], state: "minecraft:cobblestone"},
        {pos: [11, 0, 11], state: "minecraft:cobblestone"},
        {pos: [11, 0, 12], state: "minecraft:cobblestone"},
        {pos: [11, 0, 18], state: "minecraft:cobblestone"},
        {pos: [11, 0, 19], state: "minecraft:cobblestone"},
        {pos: [11, 0, 20], state: "minecraft:cobblestone"},
        {pos: [0, 1, 7], state: "minecraft:gravel"},
        {pos: [0, 1, 8], state: "minecraft:gravel"},
        {pos: [0, 1, 9], state: "minecraft:gravel"},
        {pos: [0, 1, 12], state: "minecraft:gravel"},
        {pos: [0, 1, 13], state: "minecraft:cobblestone"},
        {pos: [1, 1, 7], state: "minecraft:cobblestone"},
        {pos: [1, 1, 8], state: "minecraft:cobblestone"},
        {pos: [1, 1, 9], state: "minecraft:gravel"},
        {pos: [1, 1, 12], state: "minecraft:cobblestone"},
        {pos: [1, 1, 13], state: "minecraft:cobblestone"},
        {pos: [1, 1, 14], state: "minecraft:cobblestone"},
        {pos: [1, 1, 18], state: "minecraft:gravel"},
        {pos: [1, 1, 19], state: "minecraft:cobblestone"},
        {pos: [1, 1, 20], state: "minecraft:cobblestone"},
        {pos: [2, 1, 7], state: "minecraft:cobblestone"},
        {pos: [2, 1, 8], state: "minecraft:cobblestone_stairs{facing:west,half:top,shape:straight,waterlogged:false}"},
        {pos: [2, 1, 9], state: "minecraft:cobblestone"},
        {pos: [2, 1, 12], state: "minecraft:cobblestone"},
        {pos: [2, 1, 13], state: "minecraft:cobblestone_stairs{facing:west,half:top,shape:straight,waterlogged:false}"},
        {pos: [2, 1, 14], state: "minecraft:cobblestone"},
        {pos: [2, 1, 17], state: "minecraft:gravel"},
        {pos: [2, 1, 18], state: "minecraft:cobblestone"},
        {pos: [2, 1, 19], state: "minecraft:cobblestone"},
        {pos: [2, 1, 20], state: "minecraft:cobblestone"},
        {pos: [3, 1, 16], state: "minecraft:gravel"},
        {pos: [3, 1, 17], state: "minecraft:gravel"},
        {pos: [3, 1, 18], state: "minecraft:cobblestone"},
        {pos: [3, 1, 19], state: "minecraft:cobblestone"},
        {pos: [3, 1, 20], state: "minecraft:cobblestone"},
        {pos: [4, 1, 0], state: "minecraft:gravel"},
        {pos: [4, 1, 1], state: "minecraft:cobblestone"},
        {pos: [4, 1, 2], state: "minecraft:cobblestone"},
        {pos: [4, 1, 8], state: "minecraft:gravel"},
        {pos: [4, 1, 9], state: "minecraft:gravel"},
        {pos: [4, 1, 10], state: "minecraft:gravel"},
        {pos: [4, 1, 12], state: "minecraft:gravel"},
        {pos: [4, 1, 13], state: "minecraft:gravel"},
        {pos: [4, 1, 14], state: "minecraft:gravel"},
        {pos: [4, 1, 15], state: "minecraft:gravel"},
        {pos: [4, 1, 16], state: "minecraft:gravel"},
        {pos: [4, 1, 17], state: "minecraft:gravel"},
        {pos: [4, 1, 18], state: "minecraft:gravel"},
        {pos: [4, 1, 19], state: "minecraft:gravel"},
        {pos: [4, 1, 20], state: "minecraft:gravel"},
        {pos: [5, 1, 0], state: "minecraft:cobblestone"},
        {pos: [5, 1, 1], state: "minecraft:gravel"},
        {pos: [5, 1, 2], state: "minecraft:gravel"},
        {pos: [5, 1, 3], state: "minecraft:cobblestone"},
        {pos: [5, 1, 7], state: "minecraft:gravel"},
        {pos: [5, 1, 8], state: "minecraft:gravel"},
        {pos: [5, 1, 9], state: "minecraft:gravel"},
        {pos: [5, 1, 10], state: "minecraft:gravel"},
        {pos: [5, 1, 11], state: "minecraft:gravel"},
        {pos: [5, 1, 13], state: "minecraft:gravel"},
        {pos: [5, 1, 14], state: "minecraft:gravel"},
        {pos: [5, 1, 15], state: "minecraft:gravel"},
        {pos: [5, 1, 16], state: "minecraft:gravel"},
        {pos: [5, 1, 17], state: "minecraft:gravel"},
        {pos: [5, 1, 18], state: "minecraft:gravel"},
        {pos: [5, 1, 19], state: "minecraft:cobblestone"},
        {pos: [5, 1, 20], state: "minecraft:gravel"},
        {pos: [5, 1, 21], state: "minecraft:gravel"},
        {pos: [6, 1, 0], state: "minecraft:cobblestone"},
        {pos: [6, 1, 1], state: "minecraft:gravel"},
        {pos: [6, 1, 2], state: "minecraft:gravel"},
        {pos: [6, 1, 3], state: "minecraft:gravel"},
        {pos: [6, 1, 5], state: "minecraft:gravel"},
        {pos: [6, 1, 8], state: "minecraft:gravel"},
        {pos: [6, 1, 9], state: "minecraft:gravel"},
        {pos: [6, 1, 10], state: "minecraft:gravel"},
        {pos: [6, 1, 11], state: "minecraft:gravel"},
        {pos: [6, 1, 12], state: "minecraft:gravel"},
        {pos: [6, 1, 14], state: "minecraft:gravel"},
        {pos: [6, 1, 15], state: "minecraft:gravel"},
        {pos: [6, 1, 16], state: "minecraft:gravel"},
        {pos: [6, 1, 17], state: "minecraft:gravel"},
        {pos: [6, 1, 18], state: "minecraft:gravel"},
        {pos: [6, 1, 19], state: "minecraft:cobblestone_stairs{facing:south,half:top,shape:straight,waterlogged:false}"},
        {pos: [6, 1, 20], state: "minecraft:cobblestone"},
        {pos: [6, 1, 21], state: "minecraft:gravel"},
        {pos: [7, 1, 0], state: "minecraft:cobblestone"},
        {pos: [7, 1, 1], state: "minecraft:gravel"},
        {pos: [7, 1, 2], state: "minecraft:gravel"},
        {pos: [7, 1, 3], state: "minecraft:cobblestone"},
        {pos: [7, 1, 5], state: "minecraft:gravel"},
        {pos: [7, 1, 6], state: "minecraft:gravel"},
        {pos: [7, 1, 10], state: "minecraft:gravel"},
        {pos: [7, 1, 11], state: "minecraft:gravel"},
        {pos: [7, 1, 12], state: "minecraft:gravel"},
        {pos: [7, 1, 13], state: "minecraft:gravel"},
        {pos: [7, 1, 14], state: "minecraft:gravel"},
        {pos: [7, 1, 15], state: "minecraft:gravel"},
        {pos: [7, 1, 16], state: "minecraft:gravel"},
        {pos: [7, 1, 17], state: "minecraft:gravel"},
        {pos: [7, 1, 18], state: "minecraft:gravel"},
        {pos: [7, 1, 19], state: "minecraft:cobblestone"},
        {pos: [7, 1, 20], state: "minecraft:cobblestone"},
        {pos: [7, 1, 21], state: "minecraft:gravel"},
        {pos: [8, 1, 0], state: "minecraft:cobblestone"},
        {pos: [8, 1, 1], state: "minecraft:cobblestone"},
        {pos: [8, 1, 2], state: "minecraft:cobblestone"},
        {pos: [8, 1, 15], state: "minecraft:gravel"},
        {pos: [8, 1, 16], state: "minecraft:gravel"},
        {pos: [8, 1, 17], state: "minecraft:gravel"},
        {pos: [8, 1, 18], state: "minecraft:gravel"},
        {pos: [8, 1, 19], state: "minecraft:gravel"},
        {pos: [8, 1, 20], state: "minecraft:gravel"},
        {pos: [9, 1, 6], state: "minecraft:cobblestone"},
        {pos: [9, 1, 7], state: "minecraft:gravel"},
        {pos: [9, 1, 8], state: "minecraft:cobblestone"},
        {pos: [9, 1, 11], state: "minecraft:cobblestone"},
        {pos: [9, 1, 12], state: "minecraft:cobblestone_stairs{facing:east,half:top,shape:straight,waterlogged:false}"},
        {pos: [9, 1, 13], state: "minecraft:cobblestone"},
        {pos: [9, 1, 16], state: "minecraft:gravel"},
        {pos: [9, 1, 17], state: "minecraft:cobblestone"},
        {pos: [9, 1, 18], state: "minecraft:cobblestone"},
        {pos: [9, 1, 19], state: "minecraft:cobblestone"},
        {pos: [9, 1, 20], state: "minecraft:cobblestone"},
        {pos: [10, 1, 6], state: "minecraft:cobblestone"},
        {pos: [10, 1, 7], state: "minecraft:cobblestone"},
        {pos: [10, 1, 8], state: "minecraft:cobblestone"},
        {pos: [10, 1, 11], state: "minecraft:cobblestone"},
        {pos: [10, 1, 12], state: "minecraft:cobblestone"},
        {pos: [10, 1, 13], state: "minecraft:cobblestone"},
        {pos: [10, 1, 17], state: "minecraft:gravel"},
        {pos: [10, 1, 18], state: "minecraft:cobblestone"},
        {pos: [10, 1, 19], state: "minecraft:cobblestone"},
        {pos: [10, 1, 20], state: "minecraft:cobblestone"},
        {pos: [11, 1, 6], state: "minecraft:gravel"},
        {pos: [11, 1, 7], state: "minecraft:gravel"},
        {pos: [11, 1, 11], state: "minecraft:gravel"},
        {pos: [11, 1, 12], state: "minecraft:gravel"},
        {pos: [11, 1, 18], state: "minecraft:cobblestone"},
        {pos: [11, 1, 19], state: "minecraft:cobblestone"},
        {pos: [11, 1, 20], state: "minecraft:gravel"},
        {pos: [0, 2, 7], state: "minecraft:gravel"},
        {pos: [0, 2, 8], state: "minecraft:gravel"},
        {pos: [0, 2, 9], state: "minecraft:gravel"},
        {pos: [0, 2, 12], state: "minecraft:gravel"},
        {pos: [0, 2, 13], state: "minecraft:gravel"},
        {pos: [1, 2, 7], state: "minecraft:gravel"},
        {pos: [1, 2, 8], state: "minecraft:gravel"},
        {pos: [1, 2, 9], state: "minecraft:cobblestone"},
        {pos: [1, 2, 12], state: "minecraft:gravel"},
        {pos: [1, 2, 13], state: "minecraft:gravel"},
        {pos: [1, 2, 14], state: "minecraft:gravel"},
        {pos: [1, 2, 18], state: "minecraft:gravel"},
        {pos: [1, 2, 19], state: "minecraft:gravel"},
        {pos: [1, 2, 20], state: "minecraft:gravel"},
        {pos: [2, 2, 7], state: "minecraft:gravel"},
        {pos: [2, 2, 8], state: "minecraft:cobblestone"},
        {pos: [2, 2, 9], state: "minecraft:cobblestone_stairs{facing:west,half:top,shape:straight,waterlogged:false}"},
        {pos: [2, 2, 12], state: "minecraft:cobblestone_stairs{facing:west,half:top,shape:straight,waterlogged:false}"},
        {pos: [2, 2, 13], state: "minecraft:cobblestone"},
        {pos: [2, 2, 14], state: "minecraft:cobblestone_stairs{facing:west,half:top,shape:straight,waterlogged:false}"},
        {pos: [2, 2, 17], state: "minecraft:gravel"},
        {pos: [2, 2, 18], state: "minecraft:cobblestone"},
        {pos: [2, 2, 19], state: "minecraft:cobblestone"},
        {pos: [2, 2, 20], state: "minecraft:cobblestone"},
        {pos: [3, 2, 16], state: "minecraft:gravel"},
        {pos: [3, 2, 17], state: "minecraft:gravel"},
        {pos: [3, 2, 18], state: "minecraft:cobblestone"},
        {pos: [3, 2, 19], state: "minecraft:cobblestone"},
        {pos: [3, 2, 20], state: "minecraft:gravel"},
        {pos: [4, 2, 0], state: "minecraft:gravel"},
        {pos: [4, 2, 1], state: "minecraft:gravel"},
        {pos: [4, 2, 2], state: "minecraft:gravel"},
        {pos: [4, 2, 8], state: "minecraft:gravel"},
        {pos: [4, 2, 9], state: "minecraft:gravel"},
        {pos: [4, 2, 10], state: "minecraft:gravel"},
        {pos: [4, 2, 12], state: "minecraft:gravel"},
        {pos: [4, 2, 13], state: "minecraft:gravel"},
        {pos: [4, 2, 14], state: "minecraft:gravel"},
        {pos: [4, 2, 15], state: "minecraft:gravel"},
        {pos: [4, 2, 16], state: "minecraft:gravel"},
        {pos: [4, 2, 17], state: "minecraft:gravel"},
        {pos: [4, 2, 18], state: "minecraft:gravel"},
        {pos: [4, 2, 19], state: "minecraft:gravel"},
        {pos: [4, 2, 20], state: "minecraft:gravel"},
        {pos: [5, 2, 0], state: "minecraft:gravel"},
        {pos: [5, 2, 1], state: "minecraft:gravel"},
        {pos: [5, 2, 2], state: "minecraft:gravel"},
        {pos: [5, 2, 3], state: "minecraft:cobblestone_stairs{facing:north,half:top,shape:straight,waterlogged:false}"},
        {pos: [5, 2, 7], state: "minecraft:gravel"},
        {pos: [5, 2, 8], state: "minecraft:gravel"},
        {pos: [5, 2, 9], state: "minecraft:gravel"},
        {pos: [5, 2, 10], state: "minecraft:gravel"},
        {pos: [5, 2, 11], state: "minecraft:gravel"},
        {pos: [5, 2, 13], state: "minecraft:gravel"},
        {pos: [5, 2, 14], state: "minecraft:gravel"},
        {pos: [5, 2, 15], state: "minecraft:gravel"},
        {pos: [5, 2, 16], state: "minecraft:gravel"},
        {pos: [5, 2, 17], state: "minecraft:gravel"},
        {pos: [5, 2, 18], state: "minecraft:gravel"},
        {pos: [5, 2, 19], state: "minecraft:cobblestone_stairs{facing:south,half:top,shape:straight,waterlogged:false}"},
        {pos: [5, 2, 20], state: "minecraft:gravel"},
        {pos: [5, 2, 21], state: "minecraft:gravel"},
        {pos: [6, 2, 0], state: "minecraft:gravel"},
        {pos: [6, 2, 1], state: "minecraft:gravel"},
        {pos: [6, 2, 2], state: "minecraft:gravel"},
        {pos: [6, 2, 3], state: "minecraft:cobblestone"},
        {pos: [6, 2, 5], state: "minecraft:gravel"},
        {pos: [6, 2, 8], state: "minecraft:gravel"},
        {pos: [6, 2, 9], state: "minecraft:gravel"},
        {pos: [6, 2, 10], state: "minecraft:gravel"},
        {pos: [6, 2, 11], state: "minecraft:gravel"},
        {pos: [6, 2, 12], state: "minecraft:gravel"},
        {pos: [6, 2, 14], state: "minecraft:gravel"},
        {pos: [6, 2, 15], state: "minecraft:gravel"},
        {pos: [6, 2, 16], state: "minecraft:gravel"},
        {pos: [6, 2, 17], state: "minecraft:gravel"},
        {pos: [6, 2, 18], state: "minecraft:gravel"},
        {pos: [6, 2, 19], state: "minecraft:cobblestone"},
        {pos: [6, 2, 20], state: "minecraft:gravel"},
        {pos: [6, 2, 21], state: "minecraft:gravel"},
        {pos: [7, 2, 0], state: "minecraft:gravel"},
        {pos: [7, 2, 1], state: "minecraft:gravel"},
        {pos: [7, 2, 2], state: "minecraft:gravel"},
        {pos: [7, 2, 3], state: "minecraft:cobblestone_stairs{facing:north,half:top,shape:straight,waterlogged:false}"},
        {pos: [7, 2, 5], state: "minecraft:gravel"},
        {pos: [7, 2, 6], state: "minecraft:gravel"},
        {pos: [7, 2, 10], state: "minecraft:gravel"},
        {pos: [7, 2, 11], state: "minecraft:gravel"},
        {pos: [7, 2, 12], state: "minecraft:gravel"},
        {pos: [7, 2, 13], state: "minecraft:gravel"},
        {pos: [7, 2, 14], state: "minecraft:gravel"},
        {pos: [7, 2, 15], state: "minecraft:gravel"},
        {pos: [7, 2, 16], state: "minecraft:gravel"},
        {pos: [7, 2, 17], state: "minecraft:gravel"},
        {pos: [7, 2, 18], state: "minecraft:gravel"},
        {pos: [7, 2, 19], state: "minecraft:cobblestone_stairs{facing:south,half:top,shape:straight,waterlogged:false}"},
        {pos: [7, 2, 20], state: "minecraft:gravel"},
        {pos: [7, 2, 21], state: "minecraft:gravel"},
        {pos: [8, 2, 0], state: "minecraft:gravel"},
        {pos: [8, 2, 1], state: "minecraft:gravel"},
        {pos: [8, 2, 2], state: "minecraft:gravel"},
        {pos: [8, 2, 15], state: "minecraft:gravel"},
        {pos: [8, 2, 16], state: "minecraft:gravel"},
        {pos: [8, 2, 17], state: "minecraft:gravel"},
        {pos: [8, 2, 18], state: "minecraft:gravel"},
        {pos: [8, 2, 19], state: "minecraft:gravel"},
        {pos: [8, 2, 20], state: "minecraft:gravel"},
        {pos: [9, 2, 6], state: "minecraft:cobblestone_stairs{facing:east,half:top,shape:straight,waterlogged:false}"},
        {pos: [9, 2, 7], state: "minecraft:cobblestone"},
        {pos: [9, 2, 8], state: "minecraft:cobblestone_stairs{facing:east,half:top,shape:straight,waterlogged:false}"},
        {pos: [9, 2, 11], state: "minecraft:cobblestone_stairs{facing:east,half:top,shape:straight,waterlogged:false}"},
        {pos: [9, 2, 12], state: "minecraft:cobblestone"},
        {pos: [9, 2, 13], state: "minecraft:cobblestone_stairs{facing:east,half:top,shape:straight,waterlogged:false}"},
        {pos: [9, 2, 16], state: "minecraft:gravel"},
        {pos: [9, 2, 17], state: "minecraft:gravel"},
        {pos: [9, 2, 18], state: "minecraft:cobblestone"},
        {pos: [9, 2, 19], state: "minecraft:cobblestone"},
        {pos: [9, 2, 20], state: "minecraft:gravel"},
        {pos: [10, 2, 6], state: "minecraft:gravel"},
        {pos: [10, 2, 7], state: "minecraft:cobblestone"},
        {pos: [10, 2, 8], state: "minecraft:gravel"},
        {pos: [10, 2, 11], state: "minecraft:gravel"},
        {pos: [10, 2, 12], state: "minecraft:cobblestone"},
        {pos: [10, 2, 13], state: "minecraft:gravel"},
        {pos: [10, 2, 17], state: "minecraft:gravel"},
        {pos: [10, 2, 18], state: "minecraft:cobblestone"},
        {pos: [10, 2, 19], state: "minecraft:cobblestone"},
        {pos: [10, 2, 20], state: "minecraft:cobblestone"},
        {pos: [11, 2, 6], state: "minecraft:gravel"},
        {pos: [11, 2, 7], state: "minecraft:gravel"},
        {pos: [11, 2, 11], state: "minecraft:gravel"},
        {pos: [11, 2, 12], state: "minecraft:gravel"},
        {pos: [11, 2, 18], state: "minecraft:gravel"},
        {pos: [11, 2, 19], state: "minecraft:gravel"},
        {pos: [11, 2, 20], state: "minecraft:gravel"},
        {pos: [0, 3, 7], state: "minecraft:gravel"},
        {pos: [0, 3, 8], state: "minecraft:gravel"},
        {pos: [0, 3, 9], state: "minecraft:gravel"},
        {pos: [0, 3, 13], state: "minecraft:gravel"},
        {pos: [1, 3, 7], state: "minecraft:gravel"},
        {pos: [1, 3, 8], state: "minecraft:gravel"},
        {pos: [1, 3, 9], state: "minecraft:gravel"},
        {pos: [1, 3, 12], state: "minecraft:gravel"},
        {pos: [1, 3, 13], state: "minecraft:gravel"},
        {pos: [1, 3, 14], state: "minecraft:gravel"},
        {pos: [1, 3, 18], state: "minecraft:gravel"},
        {pos: [1, 3, 19], state: "minecraft:gravel"},
        {pos: [1, 3, 20], state: "minecraft:gravel"},
        {pos: [2, 3, 8], state: "minecraft:gravel"},
        {pos: [2, 3, 9], state: "minecraft:gravel"},
        {pos: [2, 3, 12], state: "minecraft:gravel"},
        {pos: [2, 3, 13], state: "minecraft:gravel"},
        {pos: [2, 3, 14], state: "minecraft:gravel"},
        {pos: [2, 3, 17], state: "minecraft:gravel"},
        {pos: [2, 3, 18], state: "minecraft:cobblestone"},
        {pos: [2, 3, 19], state: "minecraft:cobblestone"},
        {pos: [2, 3, 20], state: "minecraft:gravel"},
        {pos: [3, 3, 16], state: "minecraft:gravel"},
        {pos: [3, 3, 17], state: "minecraft:gravel"},
        {pos: [3, 3, 18], state: "minecraft:cobblestone"},
        {pos: [3, 3, 19], state: "minecraft:cobblestone"},
        {pos: [3, 3, 20], state: "minecraft:gravel"},
        {pos: [4, 3, 1], state: "minecraft:gravel"},
        {pos: [4, 3, 8], state: "minecraft:gravel"},
        {pos: [4, 3, 9], state: "minecraft:gravel"},
        {pos: [4, 3, 10], state: "minecraft:gravel"},
        {pos: [4, 3, 12], state: "minecraft:gravel"},
        {pos: [4, 3, 13], state: "minecraft:gravel"},
        {pos: [4, 3, 14], state: "minecraft:gravel"},
        {pos: [4, 3, 15], state: "minecraft:gravel"},
        {pos: [4, 3, 16], state: "minecraft:gravel"},
        {pos: [4, 3, 17], state: "minecraft:gravel"},
        {pos: [4, 3, 18], state: "minecraft:gravel"},
        {pos: [4, 3, 19], state: "minecraft:gravel"},
        {pos: [4, 3, 20], state: "minecraft:gravel"},
        {pos: [5, 3, 0], state: "minecraft:gravel"},
        {pos: [5, 3, 1], state: "minecraft:gravel"},
        {pos: [5, 3, 2], state: "minecraft:gravel"},
        {pos: [5, 3, 3], state: "minecraft:gravel"},
        {pos: [5, 3, 7], state: "minecraft:gravel"},
        {pos: [5, 3, 8], state: "minecraft:gravel"},
        {pos: [5, 3, 9], state: "minecraft:gravel"},
        {pos: [5, 3, 10], state: "minecraft:gravel"},
        {pos: [5, 3, 11], state: "minecraft:gravel"},
        {pos: [5, 3, 13], state: "minecraft:gravel"},
        {pos: [5, 3, 14], state: "minecraft:gravel"},
        {pos: [5, 3, 15], state: "minecraft:gravel"},
        {pos: [5, 3, 16], state: "minecraft:gravel"},
        {pos: [5, 3, 17], state: "minecraft:gravel"},
        {pos: [5, 3, 18], state: "minecraft:gravel"},
        {pos: [5, 3, 19], state: "minecraft:gravel"},
        {pos: [5, 3, 20], state: "minecraft:gravel"},
        {pos: [5, 3, 21], state: "minecraft:gravel"},
        {pos: [6, 3, 0], state: "minecraft:gravel"},
        {pos: [6, 3, 1], state: "minecraft:gravel"},
        {pos: [6, 3, 2], state: "minecraft:gravel"},
        {pos: [6, 3, 3], state: "minecraft:gravel"},
        {pos: [6, 3, 5], state: "minecraft:gravel"},
        {pos: [6, 3, 8], state: "minecraft:gravel"},
        {pos: [6, 3, 9], state: "minecraft:gravel"},
        {pos: [6, 3, 10], state: "minecraft:gravel"},
        {pos: [6, 3, 11], state: "minecraft:gravel"},
        {pos: [6, 3, 12], state: "minecraft:gravel"},
        {pos: [6, 3, 14], state: "minecraft:gravel"},
        {pos: [6, 3, 15], state: "minecraft:gravel"},
        {pos: [6, 3, 16], state: "minecraft:gravel"},
        {pos: [6, 3, 17], state: "minecraft:gravel"},
        {pos: [6, 3, 18], state: "minecraft:gravel"},
        {pos: [6, 3, 19], state: "minecraft:gravel"},
        {pos: [6, 3, 20], state: "minecraft:gravel"},
        {pos: [6, 3, 21], state: "minecraft:gravel"},
        {pos: [7, 3, 0], state: "minecraft:gravel"},
        {pos: [7, 3, 1], state: "minecraft:gravel"},
        {pos: [7, 3, 2], state: "minecraft:gravel"},
        {pos: [7, 3, 3], state: "minecraft:gravel"},
        {pos: [7, 3, 5], state: "minecraft:gravel"},
        {pos: [7, 3, 6], state: "minecraft:gravel"},
        {pos: [7, 3, 10], state: "minecraft:gravel"},
        {pos: [7, 3, 11], state: "minecraft:gravel"},
        {pos: [7, 3, 12], state: "minecraft:gravel"},
        {pos: [7, 3, 13], state: "minecraft:gravel"},
        {pos: [7, 3, 14], state: "minecraft:gravel"},
        {pos: [7, 3, 15], state: "minecraft:gravel"},
        {pos: [7, 3, 16], state: "minecraft:gravel"},
        {pos: [7, 3, 17], state: "minecraft:gravel"},
        {pos: [7, 3, 18], state: "minecraft:gravel"},
        {pos: [7, 3, 19], state: "minecraft:gravel"},
        {pos: [7, 3, 20], state: "minecraft:gravel"},
        {pos: [7, 3, 21], state: "minecraft:gravel"},
        {pos: [8, 3, 1], state: "minecraft:gravel"},
        {pos: [8, 3, 2], state: "minecraft:gravel"},
        {pos: [8, 3, 15], state: "minecraft:gravel"},
        {pos: [8, 3, 16], state: "minecraft:gravel"},
        {pos: [8, 3, 17], state: "minecraft:gravel"},
        {pos: [8, 3, 18], state: "minecraft:gravel"},
        {pos: [8, 3, 19], state: "minecraft:gravel"},
        {pos: [8, 3, 20], state: "minecraft:gravel"},
        {pos: [9, 3, 6], state: "minecraft:gravel"},
        {pos: [9, 3, 7], state: "minecraft:gravel"},
        {pos: [9, 3, 8], state: "minecraft:gravel"},
        {pos: [9, 3, 11], state: "minecraft:gravel"},
        {pos: [9, 3, 12], state: "minecraft:gravel"},
        {pos: [9, 3, 13], state: "minecraft:gravel"},
        {pos: [9, 3, 16], state: "minecraft:gravel"},
        {pos: [9, 3, 17], state: "minecraft:gravel"},
        {pos: [9, 3, 18], state: "minecraft:cobblestone"},
        {pos: [9, 3, 19], state: "minecraft:cobblestone"},
        {pos: [9, 3, 20], state: "minecraft:gravel"},
        {pos: [10, 3, 6], state: "minecraft:gravel"},
        {pos: [10, 3, 7], state: "minecraft:gravel"},
        {pos: [10, 3, 8], state: "minecraft:gravel"},
        {pos: [10, 3, 11], state: "minecraft:gravel"},
        {pos: [10, 3, 12], state: "minecraft:gravel"},
        {pos: [10, 3, 13], state: "minecraft:gravel"},
        {pos: [10, 3, 17], state: "minecraft:gravel"},
        {pos: [10, 3, 18], state: "minecraft:cobblestone"},
        {pos: [10, 3, 19], state: "minecraft:cobblestone"},
        {pos: [10, 3, 20], state: "minecraft:gravel"},
        {pos: [11, 3, 18], state: "minecraft:gravel"},
        {pos: [11, 3, 19], state: "minecraft:gravel"},
        {pos: [11, 3, 20], state: "minecraft:gravel"},
        {pos: [0, 4, 8], state: "minecraft:gravel"},
        {pos: [0, 4, 9], state: "minecraft:gravel"},
        {pos: [0, 4, 13], state: "minecraft:gravel"},
        {pos: [1, 4, 7], state: "minecraft:gravel"},
        {pos: [1, 4, 8], state: "minecraft:gravel"},
        {pos: [1, 4, 9], state: "minecraft:gravel"},
        {pos: [1, 4, 12], state: "minecraft:gravel"},
        {pos: [1, 4, 13], state: "minecraft:gravel"},
        {pos: [1, 4, 18], state: "minecraft:gravel"},
        {pos: [1, 4, 19], state: "minecraft:gravel"},
        {pos: [1, 4, 20], state: "minecraft:gravel"},
        {pos: [2, 4, 17], state: "minecraft:gravel"},
        {pos: [2, 4, 18], state: "minecraft:cobblestone"},
        {pos: [2, 4, 19], state: "minecraft:cobblestone"},
        {pos: [2, 4, 20], state: "minecraft:gravel"},
        {pos: [3, 4, 17], state: "minecraft:gravel"},
        {pos: [3, 4, 18], state: "minecraft:cobblestone"},
        {pos: [3, 4, 19], state: "minecraft:cobblestone"},
        {pos: [3, 4, 20], state: "minecraft:gravel"},
        {pos: [4, 4, 15], state: "minecraft:gravel"},
        {pos: [4, 4, 16], state: "minecraft:gravel"},
        {pos: [4, 4, 17], state: "minecraft:gravel"},
        {pos: [4, 4, 18], state: "minecraft:gravel"},
        {pos: [4, 4, 19], state: "minecraft:gravel"},
        {pos: [4, 4, 20], state: "minecraft:gravel"},
        {pos: [5, 4, 9], state: "minecraft:gravel"},
        {pos: [5, 4, 10], state: "minecraft:gravel"},
        {pos: [5, 4, 11], state: "minecraft:gravel"},
        {pos: [5, 4, 15], state: "minecraft:gravel"},
        {pos: [5, 4, 16], state: "minecraft:gravel"},
        {pos: [5, 4, 17], state: "minecraft:gravel"},
        {pos: [5, 4, 18], state: "minecraft:gravel"},
        {pos: [5, 4, 19], state: "minecraft:gravel"},
        {pos: [5, 4, 20], state: "minecraft:gravel"},
        {pos: [6, 4, 1], state: "minecraft:gravel"},
        {pos: [6, 4, 2], state: "minecraft:gravel"},
        {pos: [6, 4, 10], state: "minecraft:gravel"},
        {pos: [6, 4, 11], state: "minecraft:gravel"},
        {pos: [6, 4, 12], state: "minecraft:gravel"},
        {pos: [6, 4, 17], state: "minecraft:gravel"},
        {pos: [6, 4, 18], state: "minecraft:gravel"},
        {pos: [6, 4, 19], state: "minecraft:gravel"},
        {pos: [6, 4, 20], state: "minecraft:gravel"},
        {pos: [7, 4, 1], state: "minecraft:gravel"},
        {pos: [7, 4, 2], state: "minecraft:gravel"},
        {pos: [7, 4, 5], state: "minecraft:gravel"},
        {pos: [7, 4, 16], state: "minecraft:gravel"},
        {pos: [7, 4, 17], state: "minecraft:gravel"},
        {pos: [7, 4, 18], state: "minecraft:gravel"},
        {pos: [7, 4, 19], state: "minecraft:gravel"},
        {pos: [7, 4, 20], state: "minecraft:gravel"},
        {pos: [8, 4, 15], state: "minecraft:gravel"},
        {pos: [8, 4, 16], state: "minecraft:gravel"},
        {pos: [8, 4, 17], state: "minecraft:gravel"},
        {pos: [8, 4, 18], state: "minecraft:gravel"},
        {pos: [8, 4, 19], state: "minecraft:gravel"},
        {pos: [9, 4, 6], state: "minecraft:gravel"},
        {pos: [9, 4, 7], state: "minecraft:gravel"},
        {pos: [9, 4, 8], state: "minecraft:gravel"},
        {pos: [9, 4, 12], state: "minecraft:gravel"},
        {pos: [9, 4, 16], state: "minecraft:gravel"},
        {pos: [9, 4, 17], state: "minecraft:gravel"},
        {pos: [9, 4, 18], state: "minecraft:cobblestone"},
        {pos: [9, 4, 19], state: "minecraft:cobblestone"},
        {pos: [9, 4, 20], state: "minecraft:gravel"},
        {pos: [10, 4, 6], state: "minecraft:gravel"},
        {pos: [10, 4, 11], state: "minecraft:gravel"},
        {pos: [10, 4, 12], state: "minecraft:gravel"},
        {pos: [10, 4, 17], state: "minecraft:gravel"},
        {pos: [10, 4, 18], state: "minecraft:cobblestone"},
        {pos: [10, 4, 19], state: "minecraft:cobblestone"},
        {pos: [10, 4, 20], state: "minecraft:gravel"},
        {pos: [11, 4, 18], state: "minecraft:gravel"},
        {pos: [11, 4, 19], state: "minecraft:gravel"},
        {pos: [1, 5, 18], state: "minecraft:gravel"},
        {pos: [1, 5, 19], state: "minecraft:gravel"},
        {pos: [2, 5, 17], state: "minecraft:gravel"},
        {pos: [2, 5, 18], state: "minecraft:cobblestone"},
        {pos: [2, 5, 19], state: "minecraft:cobblestone"},
        {pos: [2, 5, 20], state: "minecraft:gravel"},
        {pos: [3, 5, 17], state: "minecraft:gravel"},
        {pos: [3, 5, 18], state: "minecraft:cobblestone"},
        {pos: [3, 5, 19], state: "minecraft:cobblestone"},
        {pos: [3, 5, 20], state: "minecraft:gravel"},
        {pos: [4, 5, 17], state: "minecraft:gravel"},
        {pos: [4, 5, 18], state: "minecraft:gravel"},
        {pos: [4, 5, 19], state: "minecraft:gravel"},
        {pos: [4, 5, 20], state: "minecraft:gravel"},
        {pos: [5, 5, 19], state: "minecraft:gravel"},
        {pos: [5, 5, 20], state: "minecraft:gravel"},
        {pos: [6, 5, 19], state: "minecraft:gravel"},
        {pos: [7, 5, 19], state: "minecraft:gravel"},
        {pos: [8, 5, 19], state: "minecraft:gravel"},
        {pos: [9, 5, 18], state: "minecraft:cobblestone"},
        {pos: [9, 5, 19], state: "minecraft:cobblestone"},
        {pos: [10, 5, 17], state: "minecraft:gravel"},
        {pos: [10, 5, 18], state: "minecraft:cobblestone"},
        {pos: [10, 5, 19], state: "minecraft:cobblestone"},
        {pos: [10, 5, 20], state: "minecraft:gravel"},
        {pos: [11, 5, 18], state: "minecraft:gravel"},
        {pos: [11, 5, 19], state: "minecraft:gravel"},
        {pos: [1, 6, 18], state: "minecraft:gravel"},
        {pos: [2, 6, 17], state: "minecraft:gravel"},
        {pos: [2, 6, 18], state: "minecraft:cobblestone"},
        {pos: [2, 6, 19], state: "minecraft:cobblestone"},
        {pos: [2, 6, 20], state: "minecraft:gravel"},
        {pos: [3, 6, 17], state: "minecraft:gravel"},
        {pos: [3, 6, 18], state: "minecraft:cobblestone"},
        {pos: [3, 6, 19], state: "minecraft:cobblestone"},
        {pos: [4, 6, 18], state: "minecraft:gravel"},
        {pos: [4, 6, 19], state: "minecraft:gravel"},
        {pos: [5, 6, 19], state: "minecraft:gravel"},
        {pos: [9, 6, 19], state: "minecraft:cobblestone"},
        {pos: [10, 6, 18], state: "minecraft:cobblestone"},
        {pos: [10, 6, 19], state: "minecraft:gravel"},
        {pos: [2, 7, 18], state: "minecraft:cobblestone"},
        {pos: [2, 7, 19], state: "minecraft:cobblestone"},
        {pos: [3, 7, 18], state: "minecraft:gravel"},
        {pos: [3, 7, 19], state: "minecraft:gravel"},
        {pos: [2, 8, 19], state: "minecraft:cobblestone"},
        {pos: [2, 9, 19], state: "minecraft:cobblestone"}
    ],
    entities: [],
    palette: [
        "minecraft:cobblestone",
        "minecraft:gravel",
        "minecraft:cobblestone_stairs{facing:west,half:top,shape:straight,waterlogged:false}",
        "minecraft:cobblestone_stairs{facing:south,half:top,shape:straight,waterlogged:false}",
        "minecraft:cobblestone_stairs{facing:east,half:top,shape:straight,waterlogged:false}",
        "minecraft:cobblestone_stairs{facing:north,half:top,shape:straight,waterlogged:false}"
    ],
    trailiertales_DataVersion: 2
}
