{
    DataVersion: 3953,
    size: [23, 12, 34],
    data: [
        {pos: [0, 0, 5], state: "minecraft:cobblestone"},
        {pos: [0, 0, 6], state: "minecraft:cobblestone"},
        {pos: [0, 0, 7], state: "minecraft:cobblestone"},
        {pos: [1, 0, 3], state: "minecraft:cobblestone"},
        {pos: [1, 0, 4], state: "minecraft:cobblestone"},
        {pos: [1, 0, 5], state: "minecraft:cobblestone"},
        {pos: [1, 0, 6], state: "minecraft:cobblestone"},
        {pos: [1, 0, 7], state: "minecraft:cobblestone"},
        {pos: [1, 0, 12], state: "minecraft:cobblestone"},
        {pos: [1, 0, 13], state: "minecraft:cobblestone"},
        {pos: [1, 0, 14], state: "minecraft:cobblestone"},
        {pos: [2, 0, 3], state: "minecraft:cobblestone"},
        {pos: [2, 0, 4], state: "minecraft:cobblestone"},
        {pos: [2, 0, 5], state: "minecraft:cobblestone"},
        {pos: [2, 0, 6], state: "minecraft:cobblestone"},
        {pos: [2, 0, 7], state: "minecraft:cobblestone"},
        {pos: [2, 0, 12], state: "minecraft:cobblestone"},
        {pos: [2, 0, 13], state: "minecraft:cobblestone"},
        {pos: [2, 0, 14], state: "minecraft:cobblestone"},
        {pos: [2, 0, 24], state: "minecraft:cobblestone"},
        {pos: [2, 0, 25], state: "minecraft:cobblestone"},
        {pos: [2, 0, 26], state: "minecraft:cobblestone"},
        {pos: [3, 0, 3], state: "minecraft:cobblestone"},
        {pos: [3, 0, 4], state: "minecraft:cobblestone"},
        {pos: [3, 0, 5], state: "minecraft:cobblestone"},
        {pos: [3, 0, 6], state: "minecraft:cobblestone"},
        {pos: [3, 0, 13], state: "minecraft:cobblestone"},
        {pos: [3, 0, 14], state: "minecraft:cobblestone"},
        {pos: [3, 0, 17], state: "minecraft:cobblestone"},
        {pos: [3, 0, 18], state: "minecraft:cobblestone"},
        {pos: [3, 0, 19], state: "minecraft:cobblestone"},
        {pos: [3, 0, 20], state: "minecraft:cobblestone"},
        {pos: [3, 0, 24], state: "minecraft:cobblestone"},
        {pos: [3, 0, 25], state: "minecraft:cobblestone"},
        {pos: [3, 0, 26], state: "minecraft:cobblestone"},
        {pos: [4, 0, 4], state: "minecraft:cobblestone"},
        {pos: [4, 0, 5], state: "minecraft:cobblestone"},
        {pos: [4, 0, 17], state: "minecraft:cobblestone"},
        {pos: [4, 0, 18], state: "minecraft:cobblestone"},
        {pos: [4, 0, 19], state: "minecraft:cobblestone"},
        {pos: [4, 0, 20], state: "minecraft:cobblestone"},
        {pos: [4, 0, 21], state: "minecraft:cobblestone"},
        {pos: [4, 0, 24], state: "minecraft:cobblestone"},
        {pos: [4, 0, 25], state: "minecraft:cobblestone"},
        {pos: [5, 0, 5], state: "minecraft:cobblestone"},
        {pos: [5, 0, 11], state: "minecraft:cobblestone"},
        {pos: [5, 0, 12], state: "minecraft:cobblestone"},
        {pos: [5, 0, 13], state: "minecraft:cobblestone"},
        {pos: [5, 0, 14], state: "minecraft:cobblestone"},
        {pos: [5, 0, 15], state: "minecraft:cobblestone"},
        {pos: [5, 0, 18], state: "minecraft:cobblestone"},
        {pos: [5, 0, 19], state: "minecraft:cobblestone"},
        {pos: [5, 0, 20], state: "minecraft:cobblestone"},
        {pos: [5, 0, 21], state: "minecraft:cobblestone"},
        {pos: [5, 0, 22], state: "minecraft:cobblestone"},
        {pos: [6, 0, 5], state: "minecraft:cobblestone"},
        {pos: [6, 0, 6], state: "minecraft:cobblestone"},
        {pos: [6, 0, 7], state: "minecraft:cobblestone"},
        {pos: [6, 0, 10], state: "minecraft:cobblestone"},
        {pos: [6, 0, 11], state: "minecraft:cobblestone"},
        {pos: [6, 0, 12], state: "minecraft:cobblestone"},
        {pos: [6, 0, 13], state: "minecraft:cobblestone"},
        {pos: [6, 0, 14], state: "minecraft:cobblestone"},
        {pos: [6, 0, 15], state: "minecraft:cobblestone"},
        {pos: [6, 0, 18], state: "minecraft:cobblestone"},
        {pos: [6, 0, 19], state: "minecraft:cobblestone"},
        {pos: [6, 0, 20], state: "minecraft:cobblestone"},
        {pos: [6, 0, 21], state: "minecraft:cobblestone"},
        {pos: [6, 0, 22], state: "minecraft:cobblestone"},
        {pos: [6, 0, 25], state: "minecraft:cobblestone"},
        {pos: [7, 0, 4], state: "minecraft:cobblestone"},
        {pos: [7, 0, 5], state: "minecraft:cobblestone"},
        {pos: [7, 0, 6], state: "minecraft:cobblestone"},
        {pos: [7, 0, 7], state: "minecraft:cobblestone"},
        {pos: [7, 0, 8], state: "minecraft:cobblestone"},
        {pos: [7, 0, 11], state: "minecraft:cobblestone"},
        {pos: [7, 0, 12], state: "minecraft:cobblestone"},
        {pos: [7, 0, 13], state: "minecraft:cobblestone"},
        {pos: [7, 0, 14], state: "minecraft:cobblestone"},
        {pos: [7, 0, 18], state: "minecraft:cobblestone"},
        {pos: [7, 0, 19], state: "minecraft:cobblestone"},
        {pos: [7, 0, 20], state: "minecraft:cobblestone"},
        {pos: [7, 0, 21], state: "minecraft:cobblestone"},
        {pos: [7, 0, 24], state: "minecraft:cobblestone"},
        {pos: [7, 0, 25], state: "minecraft:cobblestone"},
        {pos: [7, 0, 29], state: "minecraft:cobblestone"},
        {pos: [7, 0, 30], state: "minecraft:cobblestone"},
        {pos: [8, 0, 4], state: "minecraft:cobblestone"},
        {pos: [8, 0, 5], state: "minecraft:cobblestone"},
        {pos: [8, 0, 6], state: "minecraft:cobblestone"},
        {pos: [8, 0, 7], state: "minecraft:cobblestone"},
        {pos: [8, 0, 8], state: "minecraft:cobblestone"},
        {pos: [8, 0, 11], state: "minecraft:cobblestone"},
        {pos: [8, 0, 12], state: "minecraft:cobblestone"},
        {pos: [8, 0, 24], state: "minecraft:cobblestone"},
        {pos: [8, 0, 25], state: "minecraft:cobblestone"},
        {pos: [8, 0, 28], state: "minecraft:cobblestone"},
        {pos: [8, 0, 29], state: "minecraft:cobblestone"},
        {pos: [8, 0, 30], state: "minecraft:cobblestone"},
        {pos: [8, 0, 31], state: "minecraft:cobblestone"},
        {pos: [9, 0, 3], state: "minecraft:cobblestone"},
        {pos: [9, 0, 4], state: "minecraft:cobblestone"},
        {pos: [9, 0, 5], state: "minecraft:cobblestone"},
        {pos: [9, 0, 6], state: "minecraft:cobblestone"},
        {pos: [9, 0, 11], state: "minecraft:cobblestone"},
        {pos: [9, 0, 12], state: "minecraft:cobblestone"},
        {pos: [9, 0, 13], state: "minecraft:cobblestone"},
        {pos: [9, 0, 15], state: "minecraft:cobblestone"},
        {pos: [9, 0, 16], state: "minecraft:cobblestone"},
        {pos: [9, 0, 27], state: "minecraft:cobblestone"},
        {pos: [9, 0, 28], state: "minecraft:cobblestone"},
        {pos: [9, 0, 29], state: "minecraft:cobblestone"},
        {pos: [9, 0, 30], state: "minecraft:cobblestone"},
        {pos: [9, 0, 31], state: "minecraft:cobblestone"},
        {pos: [9, 0, 32], state: "minecraft:cobblestone"},
        {pos: [10, 0, 2], state: "minecraft:cobblestone"},
        {pos: [10, 0, 3], state: "minecraft:cobblestone"},
        {pos: [10, 0, 4], state: "minecraft:cobblestone"},
        {pos: [10, 0, 5], state: "minecraft:cobblestone"},
        {pos: [10, 0, 6], state: "minecraft:cobblestone"},
        {pos: [10, 0, 7], state: "minecraft:cobblestone"},
        {pos: [10, 0, 8], state: "minecraft:cobblestone"},
        {pos: [10, 0, 9], state: "minecraft:cobblestone"},
        {pos: [10, 0, 11], state: "minecraft:cobblestone"},
        {pos: [10, 0, 13], state: "minecraft:cobblestone"},
        {pos: [10, 0, 14], state: "minecraft:cobblestone"},
        {pos: [10, 0, 15], state: "minecraft:cobblestone"},
        {pos: [10, 0, 16], state: "minecraft:cobblestone"},
        {pos: [10, 0, 17], state: "minecraft:cobblestone"},
        {pos: [10, 0, 18], state: "minecraft:cobblestone"},
        {pos: [10, 0, 20], state: "minecraft:cobblestone"},
        {pos: [10, 0, 21], state: "minecraft:cobblestone"},
        {pos: [10, 0, 22], state: "minecraft:cobblestone"},
        {pos: [10, 0, 23], state: "minecraft:cobblestone"},
        {pos: [10, 0, 25], state: "minecraft:cobblestone"},
        {pos: [10, 0, 26], state: "minecraft:cobblestone"},
        {pos: [10, 0, 27], state: "minecraft:cobblestone"},
        {pos: [10, 0, 28], state: "minecraft:cobblestone"},
        {pos: [10, 0, 29], state: "minecraft:cobblestone"},
        {pos: [10, 0, 30], state: "minecraft:cobblestone"},
        {pos: [10, 0, 31], state: "minecraft:cobblestone"},
        {pos: [10, 0, 32], state: "minecraft:cobblestone"},
        {pos: [11, 0, 1], state: "minecraft:cobblestone"},
        {pos: [11, 0, 2], state: "minecraft:cobblestone"},
        {pos: [11, 0, 3], state: "minecraft:cobblestone"},
        {pos: [11, 0, 4], state: "minecraft:cobblestone"},
        {pos: [11, 0, 5], state: "minecraft:cobblestone"},
        {pos: [11, 0, 6], state: "minecraft:cobblestone"},
        {pos: [11, 0, 8], state: "minecraft:cobblestone"},
        {pos: [11, 0, 9], state: "minecraft:cobblestone"},
        {pos: [11, 0, 10], state: "minecraft:cobblestone"},
        {pos: [11, 0, 13], state: "minecraft:cobblestone"},
        {pos: [11, 0, 14], state: "minecraft:cobblestone"},
        {pos: [11, 0, 15], state: "minecraft:cobblestone"},
        {pos: [11, 0, 16], state: "minecraft:cobblestone"},
        {pos: [11, 0, 17], state: "minecraft:cobblestone"},
        {pos: [11, 0, 19], state: "minecraft:cobblestone"},
        {pos: [11, 0, 20], state: "minecraft:cobblestone"},
        {pos: [11, 0, 21], state: "minecraft:cobblestone"},
        {pos: [11, 0, 22], state: "minecraft:cobblestone"},
        {pos: [11, 0, 23], state: "minecraft:cobblestone"},
        {pos: [11, 0, 24], state: "minecraft:cobblestone"},
        {pos: [11, 0, 25], state: "minecraft:cobblestone"},
        {pos: [11, 0, 26], state: "minecraft:cobblestone"},
        {pos: [11, 0, 27], state: "minecraft:cobblestone"},
        {pos: [11, 0, 28], state: "minecraft:cobblestone"},
        {pos: [11, 0, 29], state: "minecraft:cobblestone"},
        {pos: [11, 0, 30], state: "minecraft:cobblestone"},
        {pos: [11, 0, 31], state: "minecraft:cobblestone"},
        {pos: [11, 0, 32], state: "minecraft:cobblestone"},
        {pos: [11, 0, 33], state: "minecraft:cobblestone"},
        {pos: [12, 0, 1], state: "minecraft:cobblestone"},
        {pos: [12, 0, 2], state: "minecraft:cobblestone"},
        {pos: [12, 0, 3], state: "minecraft:cobblestone"},
        {pos: [12, 0, 4], state: "minecraft:cobblestone"},
        {pos: [12, 0, 5], state: "minecraft:cobblestone"},
        {pos: [12, 0, 6], state: "minecraft:cobblestone"},
        {pos: [12, 0, 9], state: "minecraft:cobblestone"},
        {pos: [12, 0, 10], state: "minecraft:cobblestone"},
        {pos: [12, 0, 14], state: "minecraft:cobblestone"},
        {pos: [12, 0, 15], state: "minecraft:cobblestone"},
        {pos: [12, 0, 16], state: "minecraft:cobblestone"},
        {pos: [12, 0, 17], state: "minecraft:cobblestone"},
        {pos: [12, 0, 20], state: "minecraft:cobblestone"},
        {pos: [12, 0, 21], state: "minecraft:cobblestone"},
        {pos: [12, 0, 22], state: "minecraft:cobblestone"},
        {pos: [12, 0, 23], state: "minecraft:cobblestone"},
        {pos: [12, 0, 24], state: "minecraft:cobblestone"},
        {pos: [12, 0, 25], state: "minecraft:cobblestone"},
        {pos: [12, 0, 26], state: "minecraft:cobblestone"},
        {pos: [12, 0, 27], state: "minecraft:cobblestone"},
        {pos: [12, 0, 28], state: "minecraft:cobblestone"},
        {pos: [12, 0, 29], state: "minecraft:cobblestone"},
        {pos: [12, 0, 30], state: "minecraft:cobblestone"},
        {pos: [12, 0, 31], state: "minecraft:cobblestone"},
        {pos: [12, 0, 32], state: "minecraft:cobblestone"},
        {pos: [12, 0, 33], state: "minecraft:cobblestone"},
        {pos: [13, 0, 2], state: "minecraft:cobblestone"},
        {pos: [13, 0, 3], state: "minecraft:cobblestone"},
        {pos: [13, 0, 4], state: "minecraft:cobblestone"},
        {pos: [13, 0, 5], state: "minecraft:cobblestone"},
        {pos: [13, 0, 6], state: "minecraft:cobblestone"},
        {pos: [13, 0, 13], state: "minecraft:cobblestone"},
        {pos: [13, 0, 19], state: "minecraft:cobblestone"},
        {pos: [13, 0, 20], state: "minecraft:cobblestone"},
        {pos: [13, 0, 23], state: "minecraft:cobblestone"},
        {pos: [13, 0, 27], state: "minecraft:cobblestone"},
        {pos: [13, 0, 28], state: "minecraft:cobblestone"},
        {pos: [13, 0, 29], state: "minecraft:cobblestone"},
        {pos: [13, 0, 30], state: "minecraft:cobblestone"},
        {pos: [13, 0, 31], state: "minecraft:cobblestone"},
        {pos: [13, 0, 32], state: "minecraft:cobblestone"},
        {pos: [13, 0, 33], state: "minecraft:cobblestone"},
        {pos: [14, 0, 3], state: "minecraft:cobblestone"},
        {pos: [14, 0, 4], state: "minecraft:cobblestone"},
        {pos: [14, 0, 5], state: "minecraft:cobblestone"},
        {pos: [14, 0, 6], state: "minecraft:cobblestone"},
        {pos: [14, 0, 7], state: "minecraft:cobblestone"},
        {pos: [14, 0, 8], state: "minecraft:cobblestone"},
        {pos: [14, 0, 12], state: "minecraft:cobblestone"},
        {pos: [14, 0, 13], state: "minecraft:cobblestone"},
        {pos: [14, 0, 14], state: "minecraft:cobblestone"},
        {pos: [14, 0, 18], state: "minecraft:cobblestone"},
        {pos: [14, 0, 19], state: "minecraft:cobblestone"},
        {pos: [14, 0, 20], state: "minecraft:cobblestone"},
        {pos: [14, 0, 22], state: "minecraft:cobblestone"},
        {pos: [14, 0, 23], state: "minecraft:cobblestone"},
        {pos: [14, 0, 24], state: "minecraft:cobblestone"},
        {pos: [14, 0, 27], state: "minecraft:cobblestone"},
        {pos: [14, 0, 28], state: "minecraft:cobblestone"},
        {pos: [14, 0, 29], state: "minecraft:cobblestone"},
        {pos: [14, 0, 30], state: "minecraft:cobblestone"},
        {pos: [14, 0, 31], state: "minecraft:cobblestone"},
        {pos: [14, 0, 32], state: "minecraft:cobblestone"},
        {pos: [15, 0, 2], state: "minecraft:cobblestone"},
        {pos: [15, 0, 3], state: "minecraft:cobblestone"},
        {pos: [15, 0, 4], state: "minecraft:cobblestone"},
        {pos: [15, 0, 5], state: "minecraft:cobblestone"},
        {pos: [15, 0, 6], state: "minecraft:cobblestone"},
        {pos: [15, 0, 7], state: "minecraft:cobblestone"},
        {pos: [15, 0, 8], state: "minecraft:cobblestone"},
        {pos: [15, 0, 12], state: "minecraft:cobblestone"},
        {pos: [15, 0, 13], state: "minecraft:cobblestone"},
        {pos: [15, 0, 14], state: "minecraft:cobblestone"},
        {pos: [15, 0, 17], state: "minecraft:cobblestone"},
        {pos: [15, 0, 18], state: "minecraft:cobblestone"},
        {pos: [15, 0, 19], state: "minecraft:cobblestone"},
        {pos: [15, 0, 20], state: "minecraft:cobblestone"},
        {pos: [15, 0, 21], state: "minecraft:cobblestone"},
        {pos: [15, 0, 23], state: "minecraft:cobblestone"},
        {pos: [15, 0, 24], state: "minecraft:cobblestone"},
        {pos: [15, 0, 25], state: "minecraft:cobblestone"},
        {pos: [15, 0, 28], state: "minecraft:cobblestone"},
        {pos: [15, 0, 29], state: "minecraft:cobblestone"},
        {pos: [15, 0, 30], state: "minecraft:cobblestone"},
        {pos: [15, 0, 31], state: "minecraft:cobblestone"},
        {pos: [16, 0, 1], state: "minecraft:cobblestone"},
        {pos: [16, 0, 2], state: "minecraft:cobblestone"},
        {pos: [16, 0, 3], state: "minecraft:cobblestone"},
        {pos: [16, 0, 4], state: "minecraft:cobblestone"},
        {pos: [16, 0, 5], state: "minecraft:cobblestone"},
        {pos: [16, 0, 6], state: "minecraft:cobblestone"},
        {pos: [16, 0, 7], state: "minecraft:cobblestone"},
        {pos: [16, 0, 13], state: "minecraft:cobblestone"},
        {pos: [16, 0, 14], state: "minecraft:cobblestone"},
        {pos: [16, 0, 17], state: "minecraft:cobblestone"},
        {pos: [16, 0, 18], state: "minecraft:cobblestone"},
        {pos: [16, 0, 19], state: "minecraft:cobblestone"},
        {pos: [16, 0, 20], state: "minecraft:cobblestone"},
        {pos: [16, 0, 21], state: "minecraft:cobblestone"},
        {pos: [16, 0, 24], state: "minecraft:cobblestone"},
        {pos: [16, 0, 25], state: "minecraft:cobblestone"},
        {pos: [17, 0, 1], state: "minecraft:cobblestone"},
        {pos: [17, 0, 2], state: "minecraft:cobblestone"},
        {pos: [17, 0, 3], state: "minecraft:cobblestone"},
        {pos: [17, 0, 4], state: "minecraft:cobblestone"},
        {pos: [17, 0, 13], state: "minecraft:cobblestone"},
        {pos: [17, 0, 14], state: "minecraft:cobblestone"},
        {pos: [17, 0, 17], state: "minecraft:cobblestone"},
        {pos: [17, 0, 18], state: "minecraft:cobblestone"},
        {pos: [17, 0, 19], state: "minecraft:cobblestone"},
        {pos: [17, 0, 20], state: "minecraft:cobblestone"},
        {pos: [17, 0, 21], state: "minecraft:cobblestone"},
        {pos: [18, 0, 0], state: "minecraft:cobblestone"},
        {pos: [18, 0, 1], state: "minecraft:cobblestone"},
        {pos: [18, 0, 2], state: "minecraft:cobblestone"},
        {pos: [18, 0, 3], state: "minecraft:cobblestone"},
        {pos: [18, 0, 18], state: "minecraft:cobblestone"},
        {pos: [18, 0, 19], state: "minecraft:cobblestone"},
        {pos: [18, 0, 20], state: "minecraft:cobblestone"},
        {pos: [19, 0, 0], state: "minecraft:cobblestone"},
        {pos: [19, 0, 1], state: "minecraft:cobblestone"},
        {pos: [19, 0, 2], state: "minecraft:cobblestone"},
        {pos: [19, 0, 22], state: "minecraft:cobblestone"},
        {pos: [19, 0, 23], state: "minecraft:cobblestone"},
        {pos: [20, 0, 21], state: "minecraft:cobblestone"},
        {pos: [20, 0, 22], state: "minecraft:cobblestone"},
        {pos: [20, 0, 23], state: "minecraft:cobblestone"},
        {pos: [21, 0, 21], state: "minecraft:cobblestone"},
        {pos: [21, 0, 22], state: "minecraft:cobblestone"},
        {pos: [21, 0, 23], state: "minecraft:cobblestone"},
        {pos: [22, 0, 21], state: "minecraft:cobblestone"},
        {pos: [22, 0, 22], state: "minecraft:cobblestone"},
        {pos: [0, 1, 5], state: "minecraft:gravel"},
        {pos: [0, 1, 6], state: "minecraft:gravel"},
        {pos: [0, 1, 7], state: "minecraft:gravel"},
        {pos: [1, 1, 3], state: "minecraft:cobblestone"},
        {pos: [1, 1, 4], state: "minecraft:gravel"},
        {pos: [1, 1, 5], state: "minecraft:cobblestone"},
        {pos: [1, 1, 6], state: "minecraft:cobblestone"},
        {pos: [1, 1, 7], state: "minecraft:gravel"},
        {pos: [1, 1, 12], state: "minecraft:gravel"},
        {pos: [1, 1, 13], state: "minecraft:cobblestone"},
        {pos: [1, 1, 14], state: "minecraft:gravel"},
        {pos: [2, 1, 3], state: "minecraft:cobblestone"},
        {pos: [2, 1, 4], state: "minecraft:gravel"},
        {pos: [2, 1, 5], state: "minecraft:cobblestone"},
        {pos: [2, 1, 6], state: "minecraft:cobblestone"},
        {pos: [2, 1, 7], state: "minecraft:gravel"},
        {pos: [2, 1, 12], state: "minecraft:cobblestone"},
        {pos: [2, 1, 13], state: "minecraft:cobblestone"},
        {pos: [2, 1, 14], state: "minecraft:cobblestone"},
        {pos: [2, 1, 24], state: "minecraft:cobblestone"},
        {pos: [2, 1, 25], state: "minecraft:gravel"},
        {pos: [2, 1, 26], state: "minecraft:cobblestone"},
        {pos: [3, 1, 3], state: "minecraft:cobblestone"},
        {pos: [3, 1, 4], state: "minecraft:cobblestone"},
        {pos: [3, 1, 5], state: "minecraft:cobblestone"},
        {pos: [3, 1, 6], state: "minecraft:cobblestone"},
        {pos: [3, 1, 13], state: "minecraft:cobblestone"},
        {pos: [3, 1, 14], state: "minecraft:cobblestone"},
        {pos: [3, 1, 17], state: "minecraft:gravel"},
        {pos: [3, 1, 18], state: "minecraft:gravel"},
        {pos: [3, 1, 19], state: "minecraft:cobblestone"},
        {pos: [3, 1, 20], state: "minecraft:cobblestone"},
        {pos: [3, 1, 24], state: "minecraft:cobblestone"},
        {pos: [3, 1, 25], state: "minecraft:gravel"},
        {pos: [3, 1, 26], state: "minecraft:gravel"},
        {pos: [4, 1, 4], state: "minecraft:gravel"},
        {pos: [4, 1, 5], state: "minecraft:cobblestone"},
        {pos: [4, 1, 17], state: "minecraft:gravel"},
        {pos: [4, 1, 18], state: "minecraft:cobblestone"},
        {pos: [4, 1, 19], state: "minecraft:gravel"},
        {pos: [4, 1, 20], state: "minecraft:cobblestone_stairs{facing:west,half:top,shape:straight,waterlogged:false}"},
        {pos: [4, 1, 21], state: "minecraft:cobblestone"},
        {pos: [4, 1, 24], state: "minecraft:gravel"},
        {pos: [4, 1, 25], state: "minecraft:gravel"},
        {pos: [5, 1, 5], state: "minecraft:gravel"},
        {pos: [5, 1, 11], state: "minecraft:cobblestone"},
        {pos: [5, 1, 12], state: "minecraft:cobblestone"},
        {pos: [5, 1, 13], state: "minecraft:gravel"},
        {pos: [5, 1, 14], state: "minecraft:gravel"},
        {pos: [5, 1, 15], state: "minecraft:gravel"},
        {pos: [5, 1, 18], state: "minecraft:cobblestone"},
        {pos: [5, 1, 19], state: "minecraft:gravel"},
        {pos: [5, 1, 20], state: "minecraft:gravel"},
        {pos: [5, 1, 21], state: "minecraft:gravel"},
        {pos: [5, 1, 22], state: "minecraft:cobblestone"},
        {pos: [6, 1, 5], state: "minecraft:gravel"},
        {pos: [6, 1, 6], state: "minecraft:cobblestone"},
        {pos: [6, 1, 7], state: "minecraft:cobblestone"},
        {pos: [6, 1, 10], state: "minecraft:gravel"},
        {pos: [6, 1, 11], state: "minecraft:cobblestone"},
        {pos: [6, 1, 12], state: "minecraft:cobblestone"},
        {pos: [6, 1, 13], state: "minecraft:cobblestone"},
        {pos: [6, 1, 14], state: "minecraft:cobblestone"},
        {pos: [6, 1, 15], state: "minecraft:gravel"},
        {pos: [6, 1, 18], state: "minecraft:cobblestone"},
        {pos: [6, 1, 19], state: "minecraft:gravel"},
        {pos: [6, 1, 20], state: "minecraft:gravel"},
        {pos: [6, 1, 21], state: "minecraft:gravel"},
        {pos: [6, 1, 22], state: "minecraft:cobblestone"},
        {pos: [6, 1, 25], state: "minecraft:campfire{facing:south,lit:false,signal_fire:false,waterlogged:false}", nbt: {CookingTimes: [I; 0, 0, 0, 0], CookingTotalTimes: [I; 0, 0, 0, 0], Items: [], id: "minecraft:campfire"}},
        {pos: [7, 1, 4], state: "minecraft:cobblestone"},
        {pos: [7, 1, 5], state: "minecraft:gravel"},
        {pos: [7, 1, 6], state: "minecraft:gravel"},
        {pos: [7, 1, 7], state: "minecraft:gravel"},
        {pos: [7, 1, 8], state: "minecraft:cobblestone"},
        {pos: [7, 1, 11], state: "minecraft:gravel"},
        {pos: [7, 1, 12], state: "minecraft:gravel"},
        {pos: [7, 1, 13], state: "minecraft:gravel"},
        {pos: [7, 1, 14], state: "minecraft:gravel"},
        {pos: [7, 1, 18], state: "minecraft:gravel"},
        {pos: [7, 1, 19], state: "minecraft:gravel"},
        {pos: [7, 1, 20], state: "minecraft:gravel"},
        {pos: [7, 1, 21], state: "minecraft:gravel"},
        {pos: [7, 1, 24], state: "minecraft:gravel"},
        {pos: [7, 1, 25], state: "minecraft:gravel"},
        {pos: [7, 1, 28], state: "minecraft:cobblestone"},
        {pos: [7, 1, 29], state: "minecraft:cobblestone"},
        {pos: [7, 1, 30], state: "minecraft:cobblestone"},
        {pos: [7, 1, 31], state: "minecraft:cobblestone"},
        {pos: [8, 1, 4], state: "minecraft:cobblestone"},
        {pos: [8, 1, 5], state: "minecraft:gravel"},
        {pos: [8, 1, 6], state: "minecraft:gravel"},
        {pos: [8, 1, 7], state: "minecraft:cobblestone"},
        {pos: [8, 1, 8], state: "minecraft:cobblestone"},
        {pos: [8, 1, 11], state: "minecraft:gravel"},
        {pos: [8, 1, 12], state: "minecraft:gravel"},
        {pos: [8, 1, 24], state: "minecraft:gravel"},
        {pos: [8, 1, 25], state: "minecraft:gravel"},
        {pos: [8, 1, 27], state: "minecraft:cobblestone"},
        {pos: [8, 1, 28], state: "minecraft:cobblestone"},
        {pos: [8, 1, 29], state: "minecraft:cobblestone"},
        {pos: [8, 1, 30], state: "minecraft:gravel"},
        {pos: [8, 1, 31], state: "minecraft:cobblestone"},
        {pos: [8, 1, 32], state: "minecraft:cobblestone"},
        {pos: [9, 1, 3], state: "minecraft:cobblestone"},
        {pos: [9, 1, 4], state: "minecraft:gravel"},
        {pos: [9, 1, 5], state: "minecraft:gravel"},
        {pos: [9, 1, 6], state: "minecraft:cobblestone"},
        {pos: [9, 1, 11], state: "minecraft:gravel"},
        {pos: [9, 1, 12], state: "minecraft:gravel"},
        {pos: [9, 1, 13], state: "minecraft:gravel"},
        {pos: [9, 1, 15], state: "minecraft:gravel"},
        {pos: [9, 1, 16], state: "minecraft:gravel"},
        {pos: [9, 1, 27], state: "minecraft:cobblestone"},
        {pos: [9, 1, 28], state: "minecraft:gravel"},
        {pos: [9, 1, 29], state: "minecraft:gravel"},
        {pos: [9, 1, 30], state: "minecraft:gravel"},
        {pos: [9, 1, 31], state: "minecraft:gravel"},
        {pos: [9, 1, 32], state: "minecraft:cobblestone"},
        {pos: [10, 1, 2], state: "minecraft:gravel"},
        {pos: [10, 1, 3], state: "minecraft:cobblestone"},
        {pos: [10, 1, 4], state: "minecraft:cobblestone_stairs{facing:north,half:top,shape:straight,waterlogged:false}"},
        {pos: [10, 1, 5], state: "minecraft:gravel"},
        {pos: [10, 1, 6], state: "minecraft:gravel"},
        {pos: [10, 1, 7], state: "minecraft:gravel"},
        {pos: [10, 1, 8], state: "minecraft:gravel"},
        {pos: [10, 1, 9], state: "minecraft:gravel"},
        {pos: [10, 1, 11], state: "minecraft:gravel"},
        {pos: [10, 1, 13], state: "minecraft:gravel"},
        {pos: [10, 1, 14], state: "minecraft:gravel"},
        {pos: [10, 1, 15], state: "minecraft:gravel"},
        {pos: [10, 1, 16], state: "minecraft:gravel"},
        {pos: [10, 1, 17], state: "minecraft:gravel"},
        {pos: [10, 1, 18], state: "minecraft:gravel"},
        {pos: [10, 1, 20], state: "minecraft:gravel"},
        {pos: [10, 1, 21], state: "minecraft:gravel"},
        {pos: [10, 1, 22], state: "minecraft:gravel"},
        {pos: [10, 1, 23], state: "minecraft:gravel"},
        {pos: [10, 1, 25], state: "minecraft:gravel"},
        {pos: [10, 1, 26], state: "minecraft:gravel"},
        {pos: [10, 1, 27], state: "minecraft:gravel"},
        {pos: [10, 1, 28], state: "minecraft:gravel"},
        {pos: [10, 1, 29], state: "minecraft:gravel"},
        {pos: [10, 1, 30], state: "minecraft:gravel"},
        {pos: [10, 1, 31], state: "minecraft:cobblestone_stairs{facing:east,half:bottom,shape:straight,waterlogged:false}"},
        {pos: [10, 1, 32], state: "minecraft:cobblestone"},
        {pos: [10, 1, 33], state: "minecraft:cobblestone"},
        {pos: [11, 1, 1], state: "minecraft:gravel"},
        {pos: [11, 1, 2], state: "minecraft:gravel"},
        {pos: [11, 1, 3], state: "minecraft:cobblestone"},
        {pos: [11, 1, 4], state: "minecraft:cobblestone_stairs{facing:north,half:top,shape:straight,waterlogged:false}"},
        {pos: [11, 1, 5], state: "minecraft:campfire{facing:north,lit:false,signal_fire:false,waterlogged:false}", nbt: {CookingTimes: [I; 0, 0, 0, 0], CookingTotalTimes: [I; 0, 0, 0, 0], Items: [], id: "minecraft:campfire"}},
        {pos: [11, 1, 6], state: "minecraft:gravel"},
        {pos: [11, 1, 8], state: "minecraft:gravel"},
        {pos: [11, 1, 9], state: "minecraft:gravel"},
        {pos: [11, 1, 10], state: "minecraft:gravel"},
        {pos: [11, 1, 13], state: "minecraft:gravel"},
        {pos: [11, 1, 14], state: "minecraft:gravel"},
        {pos: [11, 1, 15], state: "minecraft:gravel"},
        {pos: [11, 1, 16], state: "minecraft:gravel"},
        {pos: [11, 1, 17], state: "minecraft:gravel"},
        {pos: [11, 1, 19], state: "minecraft:gravel"},
        {pos: [11, 1, 20], state: "minecraft:gravel"},
        {pos: [11, 1, 21], state: "minecraft:gravel"},
        {pos: [11, 1, 22], state: "minecraft:gravel"},
        {pos: [11, 1, 23], state: "minecraft:gravel"},
        {pos: [11, 1, 24], state: "minecraft:gravel"},
        {pos: [11, 1, 25], state: "minecraft:gravel"},
        {pos: [11, 1, 26], state: "minecraft:gravel"},
        {pos: [11, 1, 27], state: "minecraft:gravel"},
        {pos: [11, 1, 28], state: "minecraft:gravel"},
        {pos: [11, 1, 29], state: "minecraft:gravel"},
        {pos: [11, 1, 30], state: "minecraft:gravel"},
        {pos: [11, 1, 31], state: "minecraft:cobblestone"},
        {pos: [11, 1, 32], state: "minecraft:gravel"},
        {pos: [11, 1, 33], state: "minecraft:cobblestone"},
        {pos: [12, 1, 1], state: "minecraft:gravel"},
        {pos: [12, 1, 2], state: "minecraft:gravel"},
        {pos: [12, 1, 3], state: "minecraft:cobblestone"},
        {pos: [12, 1, 4], state: "minecraft:cobblestone_stairs{facing:north,half:top,shape:straight,waterlogged:false}"},
        {pos: [12, 1, 5], state: "minecraft:gravel"},
        {pos: [12, 1, 6], state: "minecraft:cobblestone"},
        {pos: [12, 1, 9], state: "minecraft:gravel"},
        {pos: [12, 1, 10], state: "minecraft:gravel"},
        {pos: [12, 1, 14], state: "minecraft:gravel"},
        {pos: [12, 1, 15], state: "minecraft:gravel"},
        {pos: [12, 1, 16], state: "minecraft:gravel"},
        {pos: [12, 1, 17], state: "minecraft:gravel"},
        {pos: [12, 1, 20], state: "minecraft:gravel"},
        {pos: [12, 1, 21], state: "minecraft:gravel"},
        {pos: [12, 1, 22], state: "minecraft:gravel"},
        {pos: [12, 1, 23], state: "minecraft:gravel"},
        {pos: [12, 1, 24], state: "minecraft:gravel"},
        {pos: [12, 1, 25], state: "minecraft:gravel"},
        {pos: [12, 1, 26], state: "minecraft:cobblestone"},
        {pos: [12, 1, 27], state: "minecraft:cobblestone"},
        {pos: [12, 1, 28], state: "minecraft:gravel"},
        {pos: [12, 1, 29], state: "minecraft:gravel"},
        {pos: [12, 1, 30], state: "minecraft:gravel"},
        {pos: [12, 1, 31], state: "minecraft:cobblestone_stairs{facing:west,half:bottom,shape:straight,waterlogged:false}"},
        {pos: [12, 1, 32], state: "minecraft:cobblestone"},
        {pos: [12, 1, 33], state: "minecraft:cobblestone"},
        {pos: [13, 1, 2], state: "minecraft:gravel"},
        {pos: [13, 1, 3], state: "minecraft:cobblestone"},
        {pos: [13, 1, 4], state: "minecraft:gravel"},
        {pos: [13, 1, 5], state: "minecraft:gravel"},
        {pos: [13, 1, 6], state: "minecraft:cobblestone"},
        {pos: [13, 1, 13], state: "minecraft:gravel"},
        {pos: [13, 1, 19], state: "minecraft:gravel"},
        {pos: [13, 1, 20], state: "minecraft:gravel"},
        {pos: [13, 1, 23], state: "minecraft:gravel"},
        {pos: [13, 1, 27], state: "minecraft:cobblestone"},
        {pos: [13, 1, 28], state: "minecraft:gravel"},
        {pos: [13, 1, 29], state: "minecraft:gravel"},
        {pos: [13, 1, 30], state: "minecraft:gravel"},
        {pos: [13, 1, 31], state: "minecraft:cobblestone"},
        {pos: [13, 1, 32], state: "minecraft:cobblestone"},
        {pos: [13, 1, 33], state: "minecraft:cobblestone"},
        {pos: [14, 1, 3], state: "minecraft:cobblestone"},
        {pos: [14, 1, 4], state: "minecraft:gravel"},
        {pos: [14, 1, 5], state: "minecraft:gravel"},
        {pos: [14, 1, 6], state: "minecraft:gravel"},
        {pos: [14, 1, 7], state: "minecraft:cobblestone"},
        {pos: [14, 1, 8], state: "minecraft:cobblestone"},
        {pos: [14, 1, 12], state: "minecraft:gravel"},
        {pos: [14, 1, 13], state: "minecraft:gravel"},
        {pos: [14, 1, 14], state: "minecraft:gravel"},
        {pos: [14, 1, 18], state: "minecraft:gravel"},
        {pos: [14, 1, 19], state: "minecraft:gravel"},
        {pos: [14, 1, 20], state: "minecraft:cobblestone"},
        {pos: [14, 1, 22], state: "minecraft:gravel"},
        {pos: [14, 1, 23], state: "minecraft:cobblestone"},
        {pos: [14, 1, 24], state: "minecraft:cobblestone"},
        {pos: [14, 1, 27], state: "minecraft:cobblestone"},
        {pos: [14, 1, 28], state: "minecraft:cobblestone"},
        {pos: [14, 1, 29], state: "minecraft:gravel"},
        {pos: [14, 1, 30], state: "minecraft:cobblestone"},
        {pos: [14, 1, 31], state: "minecraft:cobblestone"},
        {pos: [14, 1, 32], state: "minecraft:cobblestone"},
        {pos: [15, 1, 2], state: "minecraft:gravel"},
        {pos: [15, 1, 3], state: "minecraft:gravel"},
        {pos: [15, 1, 4], state: "minecraft:cobblestone"},
        {pos: [15, 1, 5], state: "minecraft:gravel"},
        {pos: [15, 1, 6], state: "minecraft:gravel"},
        {pos: [15, 1, 7], state: "minecraft:gravel"},
        {pos: [15, 1, 8], state: "minecraft:cobblestone"},
        {pos: [15, 1, 12], state: "minecraft:gravel"},
        {pos: [15, 1, 13], state: "minecraft:cobblestone"},
        {pos: [15, 1, 14], state: "minecraft:cobblestone"},
        {pos: [15, 1, 17], state: "minecraft:cobblestone"},
        {pos: [15, 1, 18], state: "minecraft:gravel"},
        {pos: [15, 1, 19], state: "minecraft:gravel"},
        {pos: [15, 1, 20], state: "minecraft:cobblestone"},
        {pos: [15, 1, 21], state: "minecraft:cobblestone"},
        {pos: [15, 1, 23], state: "minecraft:gravel"},
        {pos: [15, 1, 24], state: "minecraft:cobblestone"},
        {pos: [15, 1, 25], state: "minecraft:gravel"},
        {pos: [15, 1, 28], state: "minecraft:cobblestone"},
        {pos: [15, 1, 29], state: "minecraft:cobblestone"},
        {pos: [15, 1, 30], state: "minecraft:cobblestone"},
        {pos: [15, 1, 31], state: "minecraft:cobblestone"},
        {pos: [16, 1, 1], state: "minecraft:gravel"},
        {pos: [16, 1, 2], state: "minecraft:gravel"},
        {pos: [16, 1, 3], state: "minecraft:gravel"},
        {pos: [16, 1, 4], state: "minecraft:gravel"},
        {pos: [16, 1, 5], state: "minecraft:cobblestone"},
        {pos: [16, 1, 6], state: "minecraft:gravel"},
        {pos: [16, 1, 7], state: "minecraft:cobblestone"},
        {pos: [16, 1, 13], state: "minecraft:cobblestone"},
        {pos: [16, 1, 14], state: "minecraft:cobblestone"},
        {pos: [16, 1, 17], state: "minecraft:cobblestone"},
        {pos: [16, 1, 18], state: "minecraft:gravel"},
        {pos: [16, 1, 19], state: "minecraft:gravel"},
        {pos: [16, 1, 20], state: "minecraft:gravel"},
        {pos: [16, 1, 21], state: "minecraft:cobblestone"},
        {pos: [16, 1, 24], state: "minecraft:gravel"},
        {pos: [16, 1, 25], state: "minecraft:gravel"},
        {pos: [17, 1, 1], state: "minecraft:gravel"},
        {pos: [17, 1, 2], state: "minecraft:cobblestone"},
        {pos: [17, 1, 3], state: "minecraft:cobblestone"},
        {pos: [17, 1, 4], state: "minecraft:gravel"},
        {pos: [17, 1, 13], state: "minecraft:gravel"},
        {pos: [17, 1, 14], state: "minecraft:gravel"},
        {pos: [17, 1, 17], state: "minecraft:cobblestone"},
        {pos: [17, 1, 18], state: "minecraft:cobblestone"},
        {pos: [17, 1, 19], state: "minecraft:gravel"},
        {pos: [17, 1, 20], state: "minecraft:gravel"},
        {pos: [17, 1, 21], state: "minecraft:cobblestone"},
        {pos: [18, 1, 0], state: "minecraft:gravel"},
        {pos: [18, 1, 1], state: "minecraft:gravel"},
        {pos: [18, 1, 2], state: "minecraft:cobblestone"},
        {pos: [18, 1, 3], state: "minecraft:gravel"},
        {pos: [18, 1, 18], state: "minecraft:cobblestone"},
        {pos: [18, 1, 19], state: "minecraft:cobblestone"},
        {pos: [18, 1, 20], state: "minecraft:cobblestone"},
        {pos: [19, 1, 0], state: "minecraft:gravel"},
        {pos: [19, 1, 1], state: "minecraft:gravel"},
        {pos: [19, 1, 2], state: "minecraft:gravel"},
        {pos: [19, 1, 22], state: "minecraft:cobblestone"},
        {pos: [19, 1, 23], state: "minecraft:cobblestone"},
        {pos: [20, 1, 21], state: "minecraft:cobblestone"},
        {pos: [20, 1, 22], state: "minecraft:cobblestone"},
        {pos: [20, 1, 23], state: "minecraft:cobblestone"},
        {pos: [21, 1, 21], state: "minecraft:cobblestone"},
        {pos: [21, 1, 22], state: "minecraft:gravel"},
        {pos: [21, 1, 23], state: "minecraft:gravel"},
        {pos: [22, 1, 21], state: "minecraft:gravel"},
        {pos: [22, 1, 22], state: "minecraft:gravel"},
        {pos: [0, 2, 5], state: "minecraft:gravel"},
        {pos: [0, 2, 6], state: "minecraft:gravel"},
        {pos: [0, 2, 7], state: "minecraft:gravel"},
        {pos: [1, 2, 3], state: "minecraft:cobblestone"},
        {pos: [1, 2, 4], state: "minecraft:gravel"},
        {pos: [1, 2, 5], state: "minecraft:gravel"},
        {pos: [1, 2, 6], state: "minecraft:gravel"},
        {pos: [1, 2, 7], state: "minecraft:gravel"},
        {pos: [1, 2, 12], state: "minecraft:gravel"},
        {pos: [1, 2, 13], state: "minecraft:gravel"},
        {pos: [1, 2, 14], state: "minecraft:gravel"},
        {pos: [2, 2, 3], state: "minecraft:cobblestone"},
        {pos: [2, 2, 4], state: "minecraft:gravel"},
        {pos: [2, 2, 5], state: "minecraft:cobblestone"},
        {pos: [2, 2, 6], state: "minecraft:cobblestone"},
        {pos: [2, 2, 7], state: "minecraft:gravel"},
        {pos: [2, 2, 12], state: "minecraft:gravel"},
        {pos: [2, 2, 13], state: "minecraft:cobblestone"},
        {pos: [2, 2, 14], state: "minecraft:cobblestone"},
        {pos: [2, 2, 24], state: "minecraft:cobblestone"},
        {pos: [2, 2, 25], state: "minecraft:cobblestone"},
        {pos: [2, 2, 26], state: "minecraft:gravel"},
        {pos: [3, 2, 3], state: "minecraft:gravel"},
        {pos: [3, 2, 4], state: "minecraft:cobblestone"},
        {pos: [3, 2, 5], state: "minecraft:cobblestone"},
        {pos: [3, 2, 6], state: "minecraft:gravel"},
        {pos: [3, 2, 13], state: "minecraft:cobblestone"},
        {pos: [3, 2, 14], state: "minecraft:cobblestone"},
        {pos: [3, 2, 17], state: "minecraft:gravel"},
        {pos: [3, 2, 18], state: "minecraft:gravel"},
        {pos: [3, 2, 19], state: "minecraft:cobblestone"},
        {pos: [3, 2, 20], state: "minecraft:cobblestone"},
        {pos: [3, 2, 24], state: "minecraft:cobblestone"},
        {pos: [3, 2, 25], state: "minecraft:gravel"},
        {pos: [3, 2, 26], state: "minecraft:gravel"},
        {pos: [4, 2, 4], state: "minecraft:gravel"},
        {pos: [4, 2, 5], state: "minecraft:gravel"},
        {pos: [4, 2, 17], state: "minecraft:gravel"},
        {pos: [4, 2, 18], state: "minecraft:cobblestone"},
        {pos: [4, 2, 19], state: "minecraft:gravel"},
        {pos: [4, 2, 20], state: "minecraft:gravel"},
        {pos: [4, 2, 21], state: "minecraft:cobblestone"},
        {pos: [4, 2, 24], state: "minecraft:gravel"},
        {pos: [4, 2, 25], state: "minecraft:gravel"},
        {pos: [5, 2, 5], state: "minecraft:gravel"},
        {pos: [5, 2, 11], state: "minecraft:gravel"},
        {pos: [5, 2, 12], state: "minecraft:gravel"},
        {pos: [5, 2, 13], state: "minecraft:gravel"},
        {pos: [5, 2, 14], state: "minecraft:gravel"},
        {pos: [5, 2, 15], state: "minecraft:gravel"},
        {pos: [5, 2, 18], state: "minecraft:cobblestone"},
        {pos: [5, 2, 19], state: "minecraft:gravel"},
        {pos: [5, 2, 20], state: "minecraft:gravel"},
        {pos: [5, 2, 21], state: "minecraft:gravel"},
        {pos: [5, 2, 22], state: "minecraft:cobblestone"},
        {pos: [6, 2, 5], state: "minecraft:gravel"},
        {pos: [6, 2, 6], state: "minecraft:gravel"},
        {pos: [6, 2, 7], state: "minecraft:cobblestone"},
        {pos: [6, 2, 10], state: "minecraft:gravel"},
        {pos: [6, 2, 11], state: "minecraft:cobblestone"},
        {pos: [6, 2, 12], state: "minecraft:cobblestone_stairs{facing:west,half:top,shape:straight,waterlogged:false}"},
        {pos: [6, 2, 13], state: "minecraft:cobblestone_stairs{facing:west,half:top,shape:straight,waterlogged:false}"},
        {pos: [6, 2, 14], state: "minecraft:cobblestone_stairs{facing:west,half:top,shape:straight,waterlogged:false}"},
        {pos: [6, 2, 15], state: "minecraft:cobblestone"},
        {pos: [6, 2, 18], state: "minecraft:cobblestone"},
        {pos: [6, 2, 19], state: "minecraft:gravel"},
        {pos: [6, 2, 20], state: "minecraft:gravel"},
        {pos: [6, 2, 21], state: "minecraft:gravel"},
        {pos: [6, 2, 22], state: "minecraft:cobblestone"},
        {pos: [6, 2, 25], state: "minecraft:gravel"},
        {pos: [7, 2, 4], state: "minecraft:gravel"},
        {pos: [7, 2, 5], state: "minecraft:gravel"},
        {pos: [7, 2, 6], state: "minecraft:gravel"},
        {pos: [7, 2, 7], state: "minecraft:gravel"},
        {pos: [7, 2, 8], state: "minecraft:cobblestone"},
        {pos: [7, 2, 11], state: "minecraft:gravel"},
        {pos: [7, 2, 12], state: "minecraft:gravel"},
        {pos: [7, 2, 13], state: "minecraft:gravel"},
        {pos: [7, 2, 14], state: "minecraft:gravel"},
        {pos: [7, 2, 18], state: "minecraft:cobblestone"},
        {pos: [7, 2, 19], state: "minecraft:gravel"},
        {pos: [7, 2, 20], state: "minecraft:gravel"},
        {pos: [7, 2, 21], state: "minecraft:gravel"},
        {pos: [7, 2, 24], state: "minecraft:gravel"},
        {pos: [7, 2, 25], state: "minecraft:gravel"},
        {pos: [7, 2, 28], state: "minecraft:cobblestone"},
        {pos: [7, 2, 29], state: "minecraft:cobblestone"},
        {pos: [7, 2, 30], state: "minecraft:cobblestone"},
        {pos: [7, 2, 31], state: "minecraft:cobblestone"},
        {pos: [8, 2, 4], state: "minecraft:cobblestone"},
        {pos: [8, 2, 5], state: "minecraft:gravel"},
        {pos: [8, 2, 6], state: "minecraft:gravel"},
        {pos: [8, 2, 7], state: "minecraft:cobblestone"},
        {pos: [8, 2, 8], state: "minecraft:cobblestone"},
        {pos: [8, 2, 11], state: "minecraft:gravel"},
        {pos: [8, 2, 12], state: "minecraft:gravel"},
        {pos: [8, 2, 24], state: "minecraft:gravel"},
        {pos: [8, 2, 25], state: "minecraft:gravel"},
        {pos: [8, 2, 27], state: "minecraft:cobblestone"},
        {pos: [8, 2, 28], state: "minecraft:gravel"},
        {pos: [8, 2, 29], state: "minecraft:gravel"},
        {pos: [8, 2, 30], state: "minecraft:gravel"},
        {pos: [8, 2, 31], state: "minecraft:gravel"},
        {pos: [8, 2, 32], state: "minecraft:cobblestone"},
        {pos: [9, 2, 3], state: "minecraft:gravel"},
        {pos: [9, 2, 4], state: "minecraft:gravel"},
        {pos: [9, 2, 5], state: "minecraft:gravel"},
        {pos: [9, 2, 6], state: "minecraft:cobblestone"},
        {pos: [9, 2, 12], state: "minecraft:gravel"},
        {pos: [9, 2, 13], state: "minecraft:gravel"},
        {pos: [9, 2, 15], state: "minecraft:gravel"},
        {pos: [9, 2, 16], state: "minecraft:gravel"},
        {pos: [9, 2, 26], state: "minecraft:cobblestone"},
        {pos: [9, 2, 27], state: "minecraft:gravel"},
        {pos: [9, 2, 28], state: "minecraft:gravel"},
        {pos: [9, 2, 29], state: "minecraft:gravel"},
        {pos: [9, 2, 30], state: "minecraft:gravel"},
        {pos: [9, 2, 31], state: "minecraft:gravel"},
        {pos: [9, 2, 32], state: "minecraft:cobblestone"},
        {pos: [10, 2, 2], state: "minecraft:gravel"},
        {pos: [10, 2, 3], state: "minecraft:cobblestone"},
        {pos: [10, 2, 4], state: "minecraft:gravel"},
        {pos: [10, 2, 5], state: "minecraft:gravel"},
        {pos: [10, 2, 6], state: "minecraft:gravel"},
        {pos: [10, 2, 7], state: "minecraft:gravel"},
        {pos: [10, 2, 8], state: "minecraft:gravel"},
        {pos: [10, 2, 9], state: "minecraft:gravel"},
        {pos: [10, 2, 11], state: "minecraft:gravel"},
        {pos: [10, 2, 13], state: "minecraft:gravel"},
        {pos: [10, 2, 14], state: "minecraft:gravel"},
        {pos: [10, 2, 15], state: "minecraft:gravel"},
        {pos: [10, 2, 16], state: "minecraft:gravel"},
        {pos: [10, 2, 17], state: "minecraft:gravel"},
        {pos: [10, 2, 18], state: "minecraft:gravel"},
        {pos: [10, 2, 20], state: "minecraft:gravel"},
        {pos: [10, 2, 21], state: "minecraft:gravel"},
        {pos: [10, 2, 22], state: "minecraft:gravel"},
        {pos: [10, 2, 23], state: "minecraft:gravel"},
        {pos: [10, 2, 25], state: "minecraft:gravel"},
        {pos: [10, 2, 26], state: "minecraft:gravel"},
        {pos: [10, 2, 27], state: "minecraft:gravel"},
        {pos: [10, 2, 28], state: "minecraft:gravel"},
        {pos: [10, 2, 29], state: "minecraft:gravel"},
        {pos: [10, 2, 30], state: "minecraft:gravel"},
        {pos: [10, 2, 31], state: "minecraft:gravel"},
        {pos: [10, 2, 32], state: "minecraft:gravel"},
        {pos: [10, 2, 33], state: "minecraft:cobblestone"},
        {pos: [11, 2, 1], state: "minecraft:gravel"},
        {pos: [11, 2, 2], state: "minecraft:gravel"},
        {pos: [11, 2, 3], state: "minecraft:cobblestone"},
        {pos: [11, 2, 4], state: "minecraft:gravel"},
        {pos: [11, 2, 5], state: "minecraft:gravel"},
        {pos: [11, 2, 6], state: "minecraft:gravel"},
        {pos: [11, 2, 8], state: "minecraft:gravel"},
        {pos: [11, 2, 9], state: "minecraft:gravel"},
        {pos: [11, 2, 10], state: "minecraft:gravel"},
        {pos: [11, 2, 13], state: "minecraft:gravel"},
        {pos: [11, 2, 14], state: "minecraft:gravel"},
        {pos: [11, 2, 15], state: "minecraft:gravel"},
        {pos: [11, 2, 16], state: "minecraft:gravel"},
        {pos: [11, 2, 17], state: "minecraft:gravel"},
        {pos: [11, 2, 19], state: "minecraft:gravel"},
        {pos: [11, 2, 20], state: "minecraft:gravel"},
        {pos: [11, 2, 21], state: "minecraft:gravel"},
        {pos: [11, 2, 22], state: "minecraft:gravel"},
        {pos: [11, 2, 23], state: "minecraft:gravel"},
        {pos: [11, 2, 24], state: "minecraft:gravel"},
        {pos: [11, 2, 25], state: "minecraft:gravel"},
        {pos: [11, 2, 26], state: "minecraft:gravel"},
        {pos: [11, 2, 27], state: "minecraft:gravel"},
        {pos: [11, 2, 28], state: "minecraft:gravel"},
        {pos: [11, 2, 29], state: "minecraft:gravel"},
        {pos: [11, 2, 30], state: "minecraft:gravel"},
        {pos: [11, 2, 31], state: "minecraft:cobblestone"},
        {pos: [11, 2, 32], state: "minecraft:gravel"},
        {pos: [11, 2, 33], state: "minecraft:cobblestone"},
        {pos: [12, 2, 1], state: "minecraft:gravel"},
        {pos: [12, 2, 2], state: "minecraft:gravel"},
        {pos: [12, 2, 3], state: "minecraft:cobblestone"},
        {pos: [12, 2, 4], state: "minecraft:gravel"},
        {pos: [12, 2, 5], state: "minecraft:gravel"},
        {pos: [12, 2, 6], state: "minecraft:gravel"},
        {pos: [12, 2, 9], state: "minecraft:gravel"},
        {pos: [12, 2, 10], state: "minecraft:gravel"},
        {pos: [12, 2, 14], state: "minecraft:gravel"},
        {pos: [12, 2, 15], state: "minecraft:gravel"},
        {pos: [12, 2, 16], state: "minecraft:gravel"},
        {pos: [12, 2, 17], state: "minecraft:gravel"},
        {pos: [12, 2, 20], state: "minecraft:gravel"},
        {pos: [12, 2, 21], state: "minecraft:gravel"},
        {pos: [12, 2, 22], state: "minecraft:gravel"},
        {pos: [12, 2, 23], state: "minecraft:gravel"},
        {pos: [12, 2, 24], state: "minecraft:gravel"},
        {pos: [12, 2, 25], state: "minecraft:gravel"},
        {pos: [12, 2, 26], state: "minecraft:cobblestone"},
        {pos: [12, 2, 27], state: "minecraft:gravel"},
        {pos: [12, 2, 28], state: "minecraft:gravel"},
        {pos: [12, 2, 29], state: "minecraft:gravel"},
        {pos: [12, 2, 30], state: "minecraft:gravel"},
        {pos: [12, 2, 31], state: "minecraft:gravel"},
        {pos: [12, 2, 32], state: "minecraft:gravel"},
        {pos: [12, 2, 33], state: "minecraft:cobblestone"},
        {pos: [13, 2, 2], state: "minecraft:gravel"},
        {pos: [13, 2, 3], state: "minecraft:cobblestone"},
        {pos: [13, 2, 4], state: "minecraft:gravel"},
        {pos: [13, 2, 5], state: "minecraft:gravel"},
        {pos: [13, 2, 6], state: "minecraft:cobblestone"},
        {pos: [13, 2, 13], state: "minecraft:gravel"},
        {pos: [13, 2, 19], state: "minecraft:gravel"},
        {pos: [13, 2, 20], state: "minecraft:gravel"},
        {pos: [13, 2, 23], state: "minecraft:gravel"},
        {pos: [13, 2, 26], state: "minecraft:cobblestone"},
        {pos: [13, 2, 27], state: "minecraft:cobblestone"},
        {pos: [13, 2, 28], state: "minecraft:gravel"},
        {pos: [13, 2, 29], state: "minecraft:gravel"},
        {pos: [13, 2, 30], state: "minecraft:gravel"},
        {pos: [13, 2, 31], state: "minecraft:gravel"},
        {pos: [13, 2, 32], state: "minecraft:cobblestone"},
        {pos: [13, 2, 33], state: "minecraft:cobblestone"},
        {pos: [14, 2, 3], state: "minecraft:gravel"},
        {pos: [14, 2, 4], state: "minecraft:gravel"},
        {pos: [14, 2, 5], state: "minecraft:gravel"},
        {pos: [14, 2, 6], state: "minecraft:gravel"},
        {pos: [14, 2, 7], state: "minecraft:cobblestone"},
        {pos: [14, 2, 8], state: "minecraft:cobblestone"},
        {pos: [14, 2, 12], state: "minecraft:gravel"},
        {pos: [14, 2, 13], state: "minecraft:gravel"},
        {pos: [14, 2, 14], state: "minecraft:gravel"},
        {pos: [14, 2, 18], state: "minecraft:gravel"},
        {pos: [14, 2, 19], state: "minecraft:gravel"},
        {pos: [14, 2, 20], state: "minecraft:gravel"},
        {pos: [14, 2, 22], state: "minecraft:gravel"},
        {pos: [14, 2, 23], state: "minecraft:gravel"},
        {pos: [14, 2, 24], state: "minecraft:gravel"},
        {pos: [14, 2, 27], state: "minecraft:cobblestone"},
        {pos: [14, 2, 28], state: "minecraft:gravel"},
        {pos: [14, 2, 29], state: "minecraft:gravel"},
        {pos: [14, 2, 30], state: "minecraft:gravel"},
        {pos: [14, 2, 31], state: "minecraft:gravel"},
        {pos: [14, 2, 32], state: "minecraft:cobblestone"},
        {pos: [14, 2, 33], state: "minecraft:cobblestone"},
        {pos: [15, 2, 2], state: "minecraft:gravel"},
        {pos: [15, 2, 3], state: "minecraft:gravel"},
        {pos: [15, 2, 4], state: "minecraft:cobblestone"},
        {pos: [15, 2, 5], state: "minecraft:gravel"},
        {pos: [15, 2, 6], state: "minecraft:gravel"},
        {pos: [15, 2, 7], state: "minecraft:gravel"},
        {pos: [15, 2, 8], state: "minecraft:gravel"},
        {pos: [15, 2, 12], state: "minecraft:gravel"},
        {pos: [15, 2, 13], state: "minecraft:cobblestone"},
        {pos: [15, 2, 14], state: "minecraft:cobblestone"},
        {pos: [15, 2, 17], state: "minecraft:cobblestone"},
        {pos: [15, 2, 18], state: "minecraft:gravel"},
        {pos: [15, 2, 19], state: "minecraft:gravel"},
        {pos: [15, 2, 20], state: "minecraft:gravel"},
        {pos: [15, 2, 21], state: "minecraft:cobblestone"},
        {pos: [15, 2, 23], state: "minecraft:gravel"},
        {pos: [15, 2, 24], state: "minecraft:gravel"},
        {pos: [15, 2, 25], state: "minecraft:gravel"},
        {pos: [15, 2, 27], state: "minecraft:cobblestone"},
        {pos: [15, 2, 28], state: "minecraft:cobblestone"},
        {pos: [15, 2, 29], state: "minecraft:cobblestone"},
        {pos: [15, 2, 30], state: "minecraft:cobblestone"},
        {pos: [15, 2, 31], state: "minecraft:cobblestone"},
        {pos: [16, 2, 1], state: "minecraft:gravel"},
        {pos: [16, 2, 2], state: "minecraft:gravel"},
        {pos: [16, 2, 3], state: "minecraft:gravel"},
        {pos: [16, 2, 4], state: "minecraft:gravel"},
        {pos: [16, 2, 5], state: "minecraft:cobblestone"},
        {pos: [16, 2, 6], state: "minecraft:gravel"},
        {pos: [16, 2, 7], state: "minecraft:cobblestone"},
        {pos: [16, 2, 13], state: "minecraft:cobblestone"},
        {pos: [16, 2, 14], state: "minecraft:cobblestone"},
        {pos: [16, 2, 17], state: "minecraft:gravel"},
        {pos: [16, 2, 18], state: "minecraft:gravel"},
        {pos: [16, 2, 19], state: "minecraft:gravel"},
        {pos: [16, 2, 20], state: "minecraft:gravel"},
        {pos: [16, 2, 21], state: "minecraft:cobblestone"},
        {pos: [16, 2, 24], state: "minecraft:gravel"},
        {pos: [16, 2, 25], state: "minecraft:gravel"},
        {pos: [17, 2, 1], state: "minecraft:gravel"},
        {pos: [17, 2, 2], state: "minecraft:gravel"},
        {pos: [17, 2, 3], state: "minecraft:gravel"},
        {pos: [17, 2, 4], state: "minecraft:gravel"},
        {pos: [17, 2, 13], state: "minecraft:gravel"},
        {pos: [17, 2, 14], state: "minecraft:gravel"},
        {pos: [17, 2, 17], state: "minecraft:gravel"},
        {pos: [17, 2, 18], state: "minecraft:cobblestone"},
        {pos: [17, 2, 19], state: "minecraft:gravel"},
        {pos: [17, 2, 20], state: "minecraft:gravel"},
        {pos: [17, 2, 21], state: "minecraft:gravel"},
        {pos: [18, 2, 0], state: "minecraft:gravel"},
        {pos: [18, 2, 1], state: "minecraft:gravel"},
        {pos: [18, 2, 2], state: "minecraft:cobblestone"},
        {pos: [18, 2, 3], state: "minecraft:gravel"},
        {pos: [18, 2, 18], state: "minecraft:cobblestone"},
        {pos: [18, 2, 19], state: "minecraft:cobblestone"},
        {pos: [18, 2, 20], state: "minecraft:gravel"},
        {pos: [19, 2, 1], state: "minecraft:gravel"},
        {pos: [19, 2, 2], state: "minecraft:gravel"},
        {pos: [19, 2, 22], state: "minecraft:cobblestone"},
        {pos: [19, 2, 23], state: "minecraft:cobblestone"},
        {pos: [20, 2, 21], state: "minecraft:gravel"},
        {pos: [20, 2, 22], state: "minecraft:cobblestone"},
        {pos: [20, 2, 23], state: "minecraft:cobblestone"},
        {pos: [21, 2, 21], state: "minecraft:gravel"},
        {pos: [21, 2, 22], state: "minecraft:gravel"},
        {pos: [21, 2, 23], state: "minecraft:gravel"},
        {pos: [22, 2, 21], state: "minecraft:gravel"},
        {pos: [22, 2, 22], state: "minecraft:gravel"},
        {pos: [0, 3, 5], state: "minecraft:gravel"},
        {pos: [0, 3, 6], state: "minecraft:gravel"},
        {pos: [0, 3, 7], state: "minecraft:gravel"},
        {pos: [1, 3, 3], state: "minecraft:gravel"},
        {pos: [1, 3, 4], state: "minecraft:gravel"},
        {pos: [1, 3, 5], state: "minecraft:gravel"},
        {pos: [1, 3, 6], state: "minecraft:gravel"},
        {pos: [1, 3, 7], state: "minecraft:gravel"},
        {pos: [1, 3, 13], state: "minecraft:gravel"},
        {pos: [2, 3, 3], state: "minecraft:gravel"},
        {pos: [2, 3, 4], state: "minecraft:cobblestone"},
        {pos: [2, 3, 5], state: "minecraft:cobblestone"},
        {pos: [2, 3, 6], state: "minecraft:cobblestone"},
        {pos: [2, 3, 7], state: "minecraft:gravel"},
        {pos: [2, 3, 12], state: "minecraft:gravel"},
        {pos: [2, 3, 13], state: "minecraft:cobblestone"},
        {pos: [2, 3, 14], state: "minecraft:gravel"},
        {pos: [2, 3, 24], state: "minecraft:cobblestone"},
        {pos: [2, 3, 25], state: "minecraft:gravel"},
        {pos: [2, 3, 26], state: "minecraft:gravel"},
        {pos: [3, 3, 3], state: "minecraft:gravel"},
        {pos: [3, 3, 4], state: "minecraft:gravel"},
        {pos: [3, 3, 5], state: "minecraft:cobblestone"},
        {pos: [3, 3, 6], state: "minecraft:gravel"},
        {pos: [3, 3, 13], state: "minecraft:cobblestone"},
        {pos: [3, 3, 14], state: "minecraft:cobblestone"},
        {pos: [3, 3, 18], state: "minecraft:gravel"},
        {pos: [3, 3, 19], state: "minecraft:gravel"},
        {pos: [3, 3, 20], state: "minecraft:gravel"},
        {pos: [3, 3, 24], state: "minecraft:cobblestone"},
        {pos: [3, 3, 25], state: "minecraft:cobblestone"},
        {pos: [4, 3, 4], state: "minecraft:gravel"},
        {pos: [4, 3, 5], state: "minecraft:gravel"},
        {pos: [4, 3, 13], state: "minecraft:cobblestone"},
        {pos: [4, 3, 17], state: "minecraft:gravel"},
        {pos: [4, 3, 18], state: "minecraft:gravel"},
        {pos: [4, 3, 19], state: "minecraft:cobblestone"},
        {pos: [4, 3, 20], state: "minecraft:cobblestone"},
        {pos: [4, 3, 21], state: "minecraft:gravel"},
        {pos: [4, 3, 24], state: "minecraft:gravel"},
        {pos: [4, 3, 25], state: "minecraft:gravel"},
        {pos: [5, 3, 5], state: "minecraft:gravel"},
        {pos: [5, 3, 13], state: "minecraft:gravel"},
        {pos: [5, 3, 18], state: "minecraft:cobblestone"},
        {pos: [5, 3, 19], state: "minecraft:cobblestone"},
        {pos: [5, 3, 20], state: "minecraft:cobblestone"},
        {pos: [5, 3, 21], state: "minecraft:cobblestone"},
        {pos: [5, 3, 22], state: "minecraft:gravel"},
        {pos: [6, 3, 5], state: "minecraft:gravel"},
        {pos: [6, 3, 6], state: "minecraft:gravel"},
        {pos: [6, 3, 7], state: "minecraft:gravel"},
        {pos: [6, 3, 10], state: "minecraft:gravel"},
        {pos: [6, 3, 11], state: "minecraft:gravel"},
        {pos: [6, 3, 12], state: "minecraft:gravel"},
        {pos: [6, 3, 13], state: "minecraft:gravel"},
        {pos: [6, 3, 14], state: "minecraft:gravel"},
        {pos: [6, 3, 15], state: "minecraft:gravel"},
        {pos: [6, 3, 18], state: "minecraft:cobblestone"},
        {pos: [6, 3, 19], state: "minecraft:cobblestone"},
        {pos: [6, 3, 20], state: "minecraft:cobblestone"},
        {pos: [6, 3, 21], state: "minecraft:cobblestone"},
        {pos: [6, 3, 22], state: "minecraft:cobblestone"},
        {pos: [6, 3, 25], state: "minecraft:gravel"},
        {pos: [7, 3, 4], state: "minecraft:gravel"},
        {pos: [7, 3, 5], state: "minecraft:gravel"},
        {pos: [7, 3, 6], state: "minecraft:gravel"},
        {pos: [7, 3, 7], state: "minecraft:gravel"},
        {pos: [7, 3, 8], state: "minecraft:gravel"},
        {pos: [7, 3, 11], state: "minecraft:gravel"},
        {pos: [7, 3, 12], state: "minecraft:gravel"},
        {pos: [7, 3, 13], state: "minecraft:gravel"},
        {pos: [7, 3, 14], state: "minecraft:gravel"},
        {pos: [7, 3, 18], state: "minecraft:cobblestone"},
        {pos: [7, 3, 19], state: "minecraft:cobblestone"},
        {pos: [7, 3, 20], state: "minecraft:cobblestone"},
        {pos: [7, 3, 25], state: "minecraft:gravel"},
        {pos: [7, 3, 28], state: "minecraft:cobblestone"},
        {pos: [7, 3, 29], state: "minecraft:gravel"},
        {pos: [7, 3, 30], state: "minecraft:cobblestone"},
        {pos: [7, 3, 31], state: "minecraft:cobblestone"},
        {pos: [8, 3, 4], state: "minecraft:gravel"},
        {pos: [8, 3, 5], state: "minecraft:gravel"},
        {pos: [8, 3, 6], state: "minecraft:gravel"},
        {pos: [8, 3, 7], state: "minecraft:cobblestone"},
        {pos: [8, 3, 8], state: "minecraft:gravel"},
        {pos: [8, 3, 11], state: "minecraft:gravel"},
        {pos: [8, 3, 12], state: "minecraft:gravel"},
        {pos: [8, 3, 25], state: "minecraft:gravel"},
        {pos: [8, 3, 27], state: "minecraft:cobblestone"},
        {pos: [8, 3, 28], state: "minecraft:gravel"},
        {pos: [8, 3, 29], state: "minecraft:gravel"},
        {pos: [8, 3, 30], state: "minecraft:gravel"},
        {pos: [8, 3, 31], state: "minecraft:gravel"},
        {pos: [8, 3, 32], state: "minecraft:gravel"},
        {pos: [9, 3, 3], state: "minecraft:gravel"},
        {pos: [9, 3, 4], state: "minecraft:gravel"},
        {pos: [9, 3, 5], state: "minecraft:gravel"},
        {pos: [9, 3, 6], state: "minecraft:gravel"},
        {pos: [9, 3, 12], state: "minecraft:gravel"},
        {pos: [9, 3, 13], state: "minecraft:gravel"},
        {pos: [9, 3, 15], state: "minecraft:gravel"},
        {pos: [9, 3, 16], state: "minecraft:gravel"},
        {pos: [9, 3, 26], state: "minecraft:cobblestone"},
        {pos: [9, 3, 27], state: "minecraft:gravel"},
        {pos: [9, 3, 28], state: "minecraft:gravel"},
        {pos: [9, 3, 29], state: "minecraft:gravel"},
        {pos: [9, 3, 30], state: "minecraft:gravel"},
        {pos: [9, 3, 31], state: "minecraft:gravel"},
        {pos: [9, 3, 32], state: "minecraft:gravel"},
        {pos: [10, 3, 2], state: "minecraft:gravel"},
        {pos: [10, 3, 3], state: "minecraft:gravel"},
        {pos: [10, 3, 4], state: "minecraft:gravel"},
        {pos: [10, 3, 5], state: "minecraft:gravel"},
        {pos: [10, 3, 6], state: "minecraft:gravel"},
        {pos: [10, 3, 7], state: "minecraft:gravel"},
        {pos: [10, 3, 8], state: "minecraft:gravel"},
        {pos: [10, 3, 9], state: "minecraft:gravel"},
        {pos: [10, 3, 11], state: "minecraft:gravel"},
        {pos: [10, 3, 13], state: "minecraft:gravel"},
        {pos: [10, 3, 14], state: "minecraft:gravel"},
        {pos: [10, 3, 15], state: "minecraft:gravel"},
        {pos: [10, 3, 16], state: "minecraft:gravel"},
        {pos: [10, 3, 17], state: "minecraft:gravel"},
        {pos: [10, 3, 18], state: "minecraft:gravel"},
        {pos: [10, 3, 20], state: "minecraft:gravel"},
        {pos: [10, 3, 21], state: "minecraft:gravel"},
        {pos: [10, 3, 22], state: "minecraft:gravel"},
        {pos: [10, 3, 23], state: "minecraft:gravel"},
        {pos: [10, 3, 25], state: "minecraft:gravel"},
        {pos: [10, 3, 26], state: "minecraft:cobblestone"},
        {pos: [10, 3, 27], state: "minecraft:gravel"},
        {pos: [10, 3, 28], state: "minecraft:gravel"},
        {pos: [10, 3, 29], state: "minecraft:gravel"},
        {pos: [10, 3, 30], state: "minecraft:gravel"},
        {pos: [10, 3, 31], state: "minecraft:cobblestone_stairs{facing:south,half:bottom,shape:straight,waterlogged:false}"},
        {pos: [10, 3, 32], state: "minecraft:gravel"},
        {pos: [10, 3, 33], state: "minecraft:cobblestone"},
        {pos: [11, 3, 1], state: "minecraft:gravel"},
        {pos: [11, 3, 2], state: "minecraft:gravel"},
        {pos: [11, 3, 3], state: "minecraft:cobblestone"},
        {pos: [11, 3, 4], state: "minecraft:gravel"},
        {pos: [11, 3, 5], state: "minecraft:gravel"},
        {pos: [11, 3, 6], state: "minecraft:gravel"},
        {pos: [11, 3, 8], state: "minecraft:gravel"},
        {pos: [11, 3, 9], state: "minecraft:gravel"},
        {pos: [11, 3, 10], state: "minecraft:gravel"},
        {pos: [11, 3, 13], state: "minecraft:gravel"},
        {pos: [11, 3, 14], state: "minecraft:gravel"},
        {pos: [11, 3, 15], state: "minecraft:gravel"},
        {pos: [11, 3, 16], state: "minecraft:gravel"},
        {pos: [11, 3, 17], state: "minecraft:gravel"},
        {pos: [11, 3, 19], state: "minecraft:gravel"},
        {pos: [11, 3, 20], state: "minecraft:gravel"},
        {pos: [11, 3, 21], state: "minecraft:gravel"},
        {pos: [11, 3, 22], state: "minecraft:gravel"},
        {pos: [11, 3, 23], state: "minecraft:gravel"},
        {pos: [11, 3, 24], state: "minecraft:gravel"},
        {pos: [11, 3, 25], state: "minecraft:gravel"},
        {pos: [11, 3, 26], state: "minecraft:gravel"},
        {pos: [11, 3, 27], state: "minecraft:gravel"},
        {pos: [11, 3, 28], state: "minecraft:gravel"},
        {pos: [11, 3, 29], state: "minecraft:gravel"},
        {pos: [11, 3, 30], state: "minecraft:gravel"},
        {pos: [11, 3, 31], state: "minecraft:cobblestone"},
        {pos: [11, 3, 32], state: "minecraft:gravel"},
        {pos: [11, 3, 33], state: "minecraft:gravel"},
        {pos: [12, 3, 1], state: "minecraft:gravel"},
        {pos: [12, 3, 2], state: "minecraft:gravel"},
        {pos: [12, 3, 3], state: "minecraft:cobblestone"},
        {pos: [12, 3, 4], state: "minecraft:gravel"},
        {pos: [12, 3, 5], state: "minecraft:gravel"},
        {pos: [12, 3, 6], state: "minecraft:gravel"},
        {pos: [12, 3, 9], state: "minecraft:gravel"},
        {pos: [12, 3, 10], state: "minecraft:gravel"},
        {pos: [12, 3, 14], state: "minecraft:gravel"},
        {pos: [12, 3, 15], state: "minecraft:gravel"},
        {pos: [12, 3, 16], state: "minecraft:gravel"},
        {pos: [12, 3, 17], state: "minecraft:gravel"},
        {pos: [12, 3, 20], state: "minecraft:gravel"},
        {pos: [12, 3, 21], state: "minecraft:gravel"},
        {pos: [12, 3, 22], state: "minecraft:gravel"},
        {pos: [12, 3, 23], state: "minecraft:gravel"},
        {pos: [12, 3, 24], state: "minecraft:gravel"},
        {pos: [12, 3, 25], state: "minecraft:gravel"},
        {pos: [12, 3, 26], state: "minecraft:cobblestone"},
        {pos: [12, 3, 27], state: "minecraft:gravel"},
        {pos: [12, 3, 28], state: "minecraft:gravel"},
        {pos: [12, 3, 29], state: "minecraft:gravel"},
        {pos: [12, 3, 30], state: "minecraft:gravel"},
        {pos: [12, 3, 31], state: "minecraft:cobblestone_stairs{facing:south,half:bottom,shape:straight,waterlogged:false}"},
        {pos: [12, 3, 32], state: "minecraft:gravel"},
        {pos: [12, 3, 33], state: "minecraft:gravel"},
        {pos: [13, 3, 2], state: "minecraft:gravel"},
        {pos: [13, 3, 3], state: "minecraft:gravel"},
        {pos: [13, 3, 4], state: "minecraft:gravel"},
        {pos: [13, 3, 5], state: "minecraft:gravel"},
        {pos: [13, 3, 19], state: "minecraft:gravel"},
        {pos: [13, 3, 20], state: "minecraft:gravel"},
        {pos: [13, 3, 23], state: "minecraft:gravel"},
        {pos: [13, 3, 26], state: "minecraft:cobblestone"},
        {pos: [13, 3, 27], state: "minecraft:cobblestone"},
        {pos: [13, 3, 28], state: "minecraft:gravel"},
        {pos: [13, 3, 29], state: "minecraft:gravel"},
        {pos: [13, 3, 30], state: "minecraft:gravel"},
        {pos: [13, 3, 31], state: "minecraft:gravel"},
        {pos: [13, 3, 32], state: "minecraft:gravel"},
        {pos: [13, 3, 33], state: "minecraft:cobblestone"},
        {pos: [14, 3, 3], state: "minecraft:gravel"},
        {pos: [14, 3, 4], state: "minecraft:gravel"},
        {pos: [14, 3, 6], state: "minecraft:gravel"},
        {pos: [14, 3, 7], state: "minecraft:gravel"},
        {pos: [14, 3, 8], state: "minecraft:cobblestone"},
        {pos: [14, 3, 12], state: "minecraft:gravel"},
        {pos: [14, 3, 13], state: "minecraft:gravel"},
        {pos: [14, 3, 14], state: "minecraft:gravel"},
        {pos: [14, 3, 18], state: "minecraft:gravel"},
        {pos: [14, 3, 19], state: "minecraft:gravel"},
        {pos: [14, 3, 20], state: "minecraft:gravel"},
        {pos: [14, 3, 22], state: "minecraft:gravel"},
        {pos: [14, 3, 23], state: "minecraft:gravel"},
        {pos: [14, 3, 24], state: "minecraft:gravel"},
        {pos: [14, 3, 27], state: "minecraft:cobblestone"},
        {pos: [14, 3, 28], state: "minecraft:gravel"},
        {pos: [14, 3, 29], state: "minecraft:gravel"},
        {pos: [14, 3, 30], state: "minecraft:gravel"},
        {pos: [14, 3, 31], state: "minecraft:gravel"},
        {pos: [14, 3, 32], state: "minecraft:cobblestone"},
        {pos: [14, 3, 33], state: "minecraft:cobblestone"},
        {pos: [15, 3, 2], state: "minecraft:gravel"},
        {pos: [15, 3, 3], state: "minecraft:gravel"},
        {pos: [15, 3, 4], state: "minecraft:gravel"},
        {pos: [15, 3, 7], state: "minecraft:gravel"},
        {pos: [15, 3, 8], state: "minecraft:gravel"},
        {pos: [15, 3, 13], state: "minecraft:cobblestone"},
        {pos: [15, 3, 14], state: "minecraft:cobblestone"},
        {pos: [15, 3, 17], state: "minecraft:gravel"},
        {pos: [15, 3, 18], state: "minecraft:gravel"},
        {pos: [15, 3, 19], state: "minecraft:gravel"},
        {pos: [15, 3, 20], state: "minecraft:gravel"},
        {pos: [15, 3, 21], state: "minecraft:gravel"},
        {pos: [15, 3, 23], state: "minecraft:gravel"},
        {pos: [15, 3, 24], state: "minecraft:gravel"},
        {pos: [15, 3, 25], state: "minecraft:gravel"},
        {pos: [15, 3, 27], state: "minecraft:cobblestone"},
        {pos: [15, 3, 28], state: "minecraft:cobblestone"},
        {pos: [15, 3, 29], state: "minecraft:gravel"},
        {pos: [15, 3, 30], state: "minecraft:gravel"},
        {pos: [15, 3, 31], state: "minecraft:cobblestone"},
        {pos: [16, 3, 1], state: "minecraft:cobblestone"},
        {pos: [16, 3, 2], state: "minecraft:cobblestone"},
        {pos: [16, 3, 3], state: "minecraft:gravel"},
        {pos: [16, 3, 4], state: "minecraft:gravel"},
        {pos: [16, 3, 5], state: "minecraft:gravel"},
        {pos: [16, 3, 13], state: "minecraft:cobblestone"},
        {pos: [16, 3, 14], state: "minecraft:cobblestone"},
        {pos: [16, 3, 17], state: "minecraft:gravel"},
        {pos: [16, 3, 18], state: "minecraft:gravel"},
        {pos: [16, 3, 19], state: "minecraft:gravel"},
        {pos: [16, 3, 20], state: "minecraft:gravel"},
        {pos: [16, 3, 21], state: "minecraft:gravel"},
        {pos: [16, 3, 24], state: "minecraft:gravel"},
        {pos: [16, 3, 25], state: "minecraft:gravel"},
        {pos: [17, 3, 1], state: "minecraft:cobblestone"},
        {pos: [17, 3, 2], state: "minecraft:cobblestone"},
        {pos: [17, 3, 3], state: "minecraft:cobblestone"},
        {pos: [17, 3, 14], state: "minecraft:gravel"},
        {pos: [17, 3, 17], state: "minecraft:gravel"},
        {pos: [17, 3, 18], state: "minecraft:gravel"},
        {pos: [17, 3, 19], state: "minecraft:gravel"},
        {pos: [17, 3, 20], state: "minecraft:gravel"},
        {pos: [17, 3, 21], state: "minecraft:gravel"},
        {pos: [18, 3, 1], state: "minecraft:cobblestone"},
        {pos: [18, 3, 2], state: "minecraft:cobblestone"},
        {pos: [18, 3, 3], state: "minecraft:gravel"},
        {pos: [18, 3, 18], state: "minecraft:gravel"},
        {pos: [18, 3, 19], state: "minecraft:gravel"},
        {pos: [18, 3, 20], state: "minecraft:gravel"},
        {pos: [19, 3, 2], state: "minecraft:gravel"},
        {pos: [19, 3, 22], state: "minecraft:cobblestone"},
        {pos: [19, 3, 23], state: "minecraft:cobblestone"},
        {pos: [20, 3, 21], state: "minecraft:gravel"},
        {pos: [20, 3, 22], state: "minecraft:cobblestone"},
        {pos: [20, 3, 23], state: "minecraft:cobblestone"},
        {pos: [21, 3, 21], state: "minecraft:gravel"},
        {pos: [21, 3, 22], state: "minecraft:gravel"},
        {pos: [21, 3, 23], state: "minecraft:gravel"},
        {pos: [22, 3, 21], state: "minecraft:gravel"},
        {pos: [22, 3, 22], state: "minecraft:gravel"},
        {pos: [0, 4, 6], state: "minecraft:gravel"},
        {pos: [1, 4, 4], state: "minecraft:gravel"},
        {pos: [1, 4, 5], state: "minecraft:gravel"},
        {pos: [1, 4, 6], state: "minecraft:gravel"},
        {pos: [1, 4, 7], state: "minecraft:gravel"},
        {pos: [1, 4, 13], state: "minecraft:gravel"},
        {pos: [2, 4, 3], state: "minecraft:gravel"},
        {pos: [2, 4, 4], state: "minecraft:gravel"},
        {pos: [2, 4, 5], state: "minecraft:cobblestone"},
        {pos: [2, 4, 6], state: "minecraft:cobblestone"},
        {pos: [2, 4, 7], state: "minecraft:gravel"},
        {pos: [2, 4, 13], state: "minecraft:cobblestone"},
        {pos: [2, 4, 14], state: "minecraft:gravel"},
        {pos: [2, 4, 24], state: "minecraft:gravel"},
        {pos: [2, 4, 25], state: "minecraft:cobblestone"},
        {pos: [3, 4, 4], state: "minecraft:gravel"},
        {pos: [3, 4, 5], state: "minecraft:cobblestone"},
        {pos: [3, 4, 6], state: "minecraft:gravel"},
        {pos: [3, 4, 13], state: "minecraft:cobblestone"},
        {pos: [3, 4, 14], state: "minecraft:gravel"},
        {pos: [3, 4, 24], state: "minecraft:cobblestone"},
        {pos: [3, 4, 25], state: "minecraft:cobblestone"},
        {pos: [4, 4, 4], state: "minecraft:gravel"},
        {pos: [4, 4, 5], state: "minecraft:gravel"},
        {pos: [4, 4, 13], state: "minecraft:cobblestone"},
        {pos: [4, 4, 14], state: "minecraft:cobblestone"},
        {pos: [4, 4, 19], state: "minecraft:gravel"},
        {pos: [4, 4, 20], state: "minecraft:gravel"},
        {pos: [4, 4, 24], state: "minecraft:gravel"},
        {pos: [5, 4, 5], state: "minecraft:gravel"},
        {pos: [5, 4, 13], state: "minecraft:cobblestone"},
        {pos: [5, 4, 14], state: "minecraft:cobblestone"},
        {pos: [5, 4, 18], state: "minecraft:gravel"},
        {pos: [5, 4, 19], state: "minecraft:gravel"},
        {pos: [5, 4, 20], state: "minecraft:gravel"},
        {pos: [5, 4, 21], state: "minecraft:gravel"},
        {pos: [6, 4, 12], state: "minecraft:gravel"},
        {pos: [6, 4, 13], state: "minecraft:cobblestone"},
        {pos: [6, 4, 14], state: "minecraft:gravel"},
        {pos: [6, 4, 18], state: "minecraft:gravel"},
        {pos: [6, 4, 19], state: "minecraft:gravel"},
        {pos: [6, 4, 20], state: "minecraft:gravel"},
        {pos: [7, 4, 4], state: "minecraft:gravel"},
        {pos: [7, 4, 6], state: "minecraft:gravel"},
        {pos: [7, 4, 7], state: "minecraft:gravel"},
        {pos: [7, 4, 13], state: "minecraft:gravel"},
        {pos: [7, 4, 18], state: "minecraft:gravel"},
        {pos: [7, 4, 19], state: "minecraft:gravel"},
        {pos: [7, 4, 27], state: "minecraft:cobblestone"},
        {pos: [7, 4, 28], state: "minecraft:cobblestone"},
        {pos: [7, 4, 29], state: "minecraft:gravel"},
        {pos: [7, 4, 30], state: "minecraft:cobblestone"},
        {pos: [7, 4, 31], state: "minecraft:cobblestone"},
        {pos: [8, 4, 4], state: "minecraft:gravel"},
        {pos: [8, 4, 5], state: "minecraft:gravel"},
        {pos: [8, 4, 6], state: "minecraft:gravel"},
        {pos: [8, 4, 26], state: "minecraft:cobblestone"},
        {pos: [8, 4, 27], state: "minecraft:cobblestone"},
        {pos: [8, 4, 28], state: "minecraft:gravel"},
        {pos: [8, 4, 29], state: "minecraft:gravel"},
        {pos: [8, 4, 30], state: "minecraft:gravel"},
        {pos: [8, 4, 31], state: "minecraft:gravel"},
        {pos: [8, 4, 32], state: "minecraft:gravel"},
        {pos: [9, 4, 4], state: "minecraft:gravel"},
        {pos: [9, 4, 5], state: "minecraft:gravel"},
        {pos: [9, 4, 6], state: "minecraft:gravel"},
        {pos: [9, 4, 13], state: "minecraft:gravel"},
        {pos: [9, 4, 26], state: "minecraft:cobblestone"},
        {pos: [9, 4, 27], state: "minecraft:gravel"},
        {pos: [9, 4, 28], state: "minecraft:gravel"},
        {pos: [9, 4, 29], state: "minecraft:gravel"},
        {pos: [9, 4, 30], state: "minecraft:gravel"},
        {pos: [9, 4, 31], state: "minecraft:gravel"},
        {pos: [9, 4, 32], state: "minecraft:cobblestone"},
        {pos: [10, 4, 3], state: "minecraft:gravel"},
        {pos: [10, 4, 4], state: "minecraft:gravel"},
        {pos: [10, 4, 5], state: "minecraft:gravel"},
        {pos: [10, 4, 6], state: "minecraft:gravel"},
        {pos: [10, 4, 13], state: "minecraft:gravel"},
        {pos: [10, 4, 14], state: "minecraft:gravel"},
        {pos: [10, 4, 15], state: "minecraft:gravel"},
        {pos: [10, 4, 22], state: "minecraft:gravel"},
        {pos: [10, 4, 23], state: "minecraft:gravel"},
        {pos: [10, 4, 25], state: "minecraft:gravel"},
        {pos: [10, 4, 26], state: "minecraft:cobblestone"},
        {pos: [10, 4, 27], state: "minecraft:gravel"},
        {pos: [10, 4, 28], state: "minecraft:gravel"},
        {pos: [10, 4, 29], state: "minecraft:gravel"},
        {pos: [10, 4, 30], state: "minecraft:gravel"},
        {pos: [10, 4, 31], state: "minecraft:gravel"},
        {pos: [10, 4, 32], state: "minecraft:gravel"},
        {pos: [10, 4, 33], state: "minecraft:cobblestone"},
        {pos: [11, 4, 2], state: "minecraft:gravel"},
        {pos: [11, 4, 3], state: "minecraft:gravel"},
        {pos: [11, 4, 4], state: "minecraft:gravel"},
        {pos: [11, 4, 5], state: "minecraft:gravel"},
        {pos: [11, 4, 14], state: "minecraft:gravel"},
        {pos: [11, 4, 15], state: "minecraft:gravel"},
        {pos: [11, 4, 16], state: "minecraft:gravel"},
        {pos: [11, 4, 20], state: "minecraft:gravel"},
        {pos: [11, 4, 21], state: "minecraft:gravel"},
        {pos: [11, 4, 22], state: "minecraft:gravel"},
        {pos: [11, 4, 23], state: "minecraft:gravel"},
        {pos: [11, 4, 24], state: "minecraft:gravel"},
        {pos: [11, 4, 25], state: "minecraft:gravel"},
        {pos: [11, 4, 26], state: "minecraft:cobblestone"},
        {pos: [11, 4, 27], state: "minecraft:gravel"},
        {pos: [11, 4, 28], state: "minecraft:gravel"},
        {pos: [11, 4, 29], state: "minecraft:gravel"},
        {pos: [11, 4, 30], state: "minecraft:gravel"},
        {pos: [11, 4, 31], state: "minecraft:chiseled_stone_bricks"},
        {pos: [11, 4, 32], state: "minecraft:gravel"},
        {pos: [11, 4, 33], state: "minecraft:gravel"},
        {pos: [12, 4, 3], state: "minecraft:gravel"},
        {pos: [12, 4, 4], state: "minecraft:gravel"},
        {pos: [12, 4, 5], state: "minecraft:gravel"},
        {pos: [12, 4, 14], state: "minecraft:gravel"},
        {pos: [12, 4, 15], state: "minecraft:gravel"},
        {pos: [12, 4, 22], state: "minecraft:gravel"},
        {pos: [12, 4, 23], state: "minecraft:gravel"},
        {pos: [12, 4, 24], state: "minecraft:gravel"},
        {pos: [12, 4, 25], state: "minecraft:gravel"},
        {pos: [12, 4, 26], state: "minecraft:cobblestone"},
        {pos: [12, 4, 27], state: "minecraft:gravel"},
        {pos: [12, 4, 28], state: "minecraft:gravel"},
        {pos: [12, 4, 29], state: "minecraft:gravel"},
        {pos: [12, 4, 30], state: "minecraft:gravel"},
        {pos: [12, 4, 31], state: "minecraft:gravel"},
        {pos: [12, 4, 32], state: "minecraft:gravel"},
        {pos: [12, 4, 33], state: "minecraft:gravel"},
        {pos: [13, 4, 23], state: "minecraft:gravel"},
        {pos: [13, 4, 26], state: "minecraft:cobblestone"},
        {pos: [13, 4, 27], state: "minecraft:cobblestone"},
        {pos: [13, 4, 28], state: "minecraft:gravel"},
        {pos: [13, 4, 29], state: "minecraft:gravel"},
        {pos: [13, 4, 30], state: "minecraft:gravel"},
        {pos: [13, 4, 31], state: "minecraft:gravel"},
        {pos: [13, 4, 32], state: "minecraft:gravel"},
        {pos: [13, 4, 33], state: "minecraft:cobblestone"},
        {pos: [14, 4, 3], state: "minecraft:gravel"},
        {pos: [14, 4, 4], state: "minecraft:gravel"},
        {pos: [14, 4, 13], state: "minecraft:cobblestone"},
        {pos: [14, 4, 14], state: "minecraft:cobblestone"},
        {pos: [14, 4, 19], state: "minecraft:gravel"},
        {pos: [14, 4, 20], state: "minecraft:gravel"},
        {pos: [14, 4, 23], state: "minecraft:gravel"},
        {pos: [14, 4, 27], state: "minecraft:cobblestone"},
        {pos: [14, 4, 28], state: "minecraft:gravel"},
        {pos: [14, 4, 29], state: "minecraft:gravel"},
        {pos: [14, 4, 30], state: "minecraft:gravel"},
        {pos: [14, 4, 31], state: "minecraft:gravel"},
        {pos: [14, 4, 32], state: "minecraft:cobblestone"},
        {pos: [14, 4, 33], state: "minecraft:cobblestone"},
        {pos: [15, 4, 3], state: "minecraft:gravel"},
        {pos: [15, 4, 4], state: "minecraft:gravel"},
        {pos: [15, 4, 13], state: "minecraft:gravel"},
        {pos: [15, 4, 14], state: "minecraft:cobblestone"},
        {pos: [15, 4, 18], state: "minecraft:gravel"},
        {pos: [15, 4, 19], state: "minecraft:gravel"},
        {pos: [15, 4, 20], state: "minecraft:gravel"},
        {pos: [15, 4, 23], state: "minecraft:gravel"},
        {pos: [15, 4, 24], state: "minecraft:gravel"},
        {pos: [15, 4, 27], state: "minecraft:cobblestone"},
        {pos: [15, 4, 28], state: "minecraft:cobblestone"},
        {pos: [15, 4, 29], state: "minecraft:gravel"},
        {pos: [15, 4, 30], state: "minecraft:cobblestone"},
        {pos: [15, 4, 31], state: "minecraft:cobblestone"},
        {pos: [16, 4, 1], state: "minecraft:cobblestone"},
        {pos: [16, 4, 2], state: "minecraft:cobblestone"},
        {pos: [16, 4, 3], state: "minecraft:cobblestone"},
        {pos: [16, 4, 13], state: "minecraft:cobblestone"},
        {pos: [16, 4, 14], state: "minecraft:cobblestone"},
        {pos: [16, 4, 18], state: "minecraft:gravel"},
        {pos: [16, 4, 19], state: "minecraft:gravel"},
        {pos: [16, 4, 20], state: "minecraft:gravel"},
        {pos: [16, 4, 21], state: "minecraft:gravel"},
        {pos: [17, 4, 1], state: "minecraft:cobblestone"},
        {pos: [17, 4, 2], state: "minecraft:cobblestone"},
        {pos: [17, 4, 3], state: "minecraft:cobblestone"},
        {pos: [17, 4, 20], state: "minecraft:gravel"},
        {pos: [18, 4, 1], state: "minecraft:gravel"},
        {pos: [18, 4, 2], state: "minecraft:cobblestone"},
        {pos: [18, 4, 3], state: "minecraft:gravel"},
        {pos: [19, 4, 2], state: "minecraft:gravel"},
        {pos: [19, 4, 22], state: "minecraft:cobblestone"},
        {pos: [19, 4, 23], state: "minecraft:cobblestone"},
        {pos: [20, 4, 21], state: "minecraft:gravel"},
        {pos: [20, 4, 22], state: "minecraft:cobblestone"},
        {pos: [20, 4, 23], state: "minecraft:cobblestone"},
        {pos: [21, 4, 21], state: "minecraft:gravel"},
        {pos: [21, 4, 22], state: "minecraft:gravel"},
        {pos: [21, 4, 23], state: "minecraft:gravel"},
        {pos: [22, 4, 22], state: "minecraft:gravel"},
        {pos: [1, 5, 4], state: "minecraft:gravel"},
        {pos: [1, 5, 5], state: "minecraft:gravel"},
        {pos: [1, 5, 6], state: "minecraft:gravel"},
        {pos: [2, 5, 4], state: "minecraft:gravel"},
        {pos: [2, 5, 5], state: "minecraft:cobblestone"},
        {pos: [2, 5, 6], state: "minecraft:gravel"},
        {pos: [2, 5, 7], state: "minecraft:gravel"},
        {pos: [2, 5, 13], state: "minecraft:gravel"},
        {pos: [2, 5, 24], state: "minecraft:gravel"},
        {pos: [2, 5, 25], state: "minecraft:cobblestone"},
        {pos: [3, 5, 4], state: "minecraft:gravel"},
        {pos: [3, 5, 5], state: "minecraft:gravel"},
        {pos: [3, 5, 6], state: "minecraft:gravel"},
        {pos: [3, 5, 13], state: "minecraft:cobblestone"},
        {pos: [3, 5, 24], state: "minecraft:cobblestone"},
        {pos: [3, 5, 25], state: "minecraft:cobblestone"},
        {pos: [4, 5, 4], state: "minecraft:gravel"},
        {pos: [4, 5, 5], state: "minecraft:gravel"},
        {pos: [4, 5, 13], state: "minecraft:cobblestone"},
        {pos: [4, 5, 14], state: "minecraft:cobblestone"},
        {pos: [4, 5, 24], state: "minecraft:gravel"},
        {pos: [5, 5, 13], state: "minecraft:cobblestone"},
        {pos: [5, 5, 14], state: "minecraft:gravel"},
        {pos: [5, 5, 18], state: "minecraft:gravel"},
        {pos: [5, 5, 19], state: "minecraft:gravel"},
        {pos: [5, 5, 20], state: "minecraft:gravel"},
        {pos: [6, 5, 13], state: "minecraft:gravel"},
        {pos: [6, 5, 18], state: "minecraft:gravel"},
        {pos: [6, 5, 19], state: "minecraft:gravel"},
        {pos: [7, 5, 27], state: "minecraft:cobblestone"},
        {pos: [7, 5, 28], state: "minecraft:cobblestone"},
        {pos: [7, 5, 29], state: "minecraft:gravel"},
        {pos: [7, 5, 30], state: "minecraft:gravel"},
        {pos: [7, 5, 31], state: "minecraft:cobblestone"},
        {pos: [8, 5, 26], state: "minecraft:cobblestone"},
        {pos: [8, 5, 27], state: "minecraft:cobblestone"},
        {pos: [8, 5, 28], state: "minecraft:gravel"},
        {pos: [8, 5, 29], state: "minecraft:gravel"},
        {pos: [8, 5, 30], state: "minecraft:gravel"},
        {pos: [8, 5, 31], state: "minecraft:gravel"},
        {pos: [8, 5, 32], state: "minecraft:cobblestone"},
        {pos: [9, 5, 26], state: "minecraft:cobblestone"},
        {pos: [9, 5, 27], state: "minecraft:gravel"},
        {pos: [9, 5, 28], state: "minecraft:gravel"},
        {pos: [9, 5, 29], state: "minecraft:gravel"},
        {pos: [9, 5, 30], state: "minecraft:gravel"},
        {pos: [9, 5, 31], state: "minecraft:gravel"},
        {pos: [9, 5, 32], state: "minecraft:cobblestone"},
        {pos: [9, 5, 33], state: "minecraft:cobblestone"},
        {pos: [10, 5, 25], state: "minecraft:gravel"},
        {pos: [10, 5, 26], state: "minecraft:gravel"},
        {pos: [10, 5, 27], state: "minecraft:gravel"},
        {pos: [10, 5, 28], state: "minecraft:gravel"},
        {pos: [10, 5, 29], state: "minecraft:gravel"},
        {pos: [10, 5, 30], state: "minecraft:gravel"},
        {pos: [10, 5, 31], state: "minecraft:gravel"},
        {pos: [10, 5, 32], state: "minecraft:gravel"},
        {pos: [10, 5, 33], state: "minecraft:cobblestone"},
        {pos: [11, 5, 24], state: "minecraft:gravel"},
        {pos: [11, 5, 25], state: "minecraft:gravel"},
        {pos: [11, 5, 26], state: "minecraft:gravel"},
        {pos: [11, 5, 27], state: "minecraft:gravel"},
        {pos: [11, 5, 28], state: "minecraft:gravel"},
        {pos: [11, 5, 29], state: "minecraft:gravel"},
        {pos: [11, 5, 30], state: "minecraft:gravel"},
        {pos: [11, 5, 31], state: "minecraft:gravel"},
        {pos: [11, 5, 32], state: "minecraft:gravel"},
        {pos: [11, 5, 33], state: "minecraft:cobblestone"},
        {pos: [12, 5, 13], state: "minecraft:cobblestone"},
        {pos: [12, 5, 14], state: "minecraft:cobblestone"},
        {pos: [12, 5, 25], state: "minecraft:gravel"},
        {pos: [12, 5, 26], state: "minecraft:cobblestone"},
        {pos: [12, 5, 27], state: "minecraft:gravel"},
        {pos: [12, 5, 28], state: "minecraft:gravel"},
        {pos: [12, 5, 29], state: "minecraft:gravel"},
        {pos: [12, 5, 30], state: "minecraft:gravel"},
        {pos: [12, 5, 31], state: "minecraft:gravel"},
        {pos: [12, 5, 32], state: "minecraft:gravel"},
        {pos: [12, 5, 33], state: "minecraft:cobblestone"},
        {pos: [13, 5, 13], state: "minecraft:cobblestone"},
        {pos: [13, 5, 14], state: "minecraft:cobblestone"},
        {pos: [13, 5, 26], state: "minecraft:gravel"},
        {pos: [13, 5, 27], state: "minecraft:gravel"},
        {pos: [13, 5, 28], state: "minecraft:gravel"},
        {pos: [13, 5, 29], state: "minecraft:gravel"},
        {pos: [13, 5, 30], state: "minecraft:cobblestone"},
        {pos: [13, 5, 31], state: "minecraft:cobblestone"},
        {pos: [13, 5, 32], state: "minecraft:cobblestone"},
        {pos: [13, 5, 33], state: "minecraft:cobblestone"},
        {pos: [14, 5, 13], state: "minecraft:cobblestone"},
        {pos: [14, 5, 14], state: "minecraft:cobblestone"},
        {pos: [14, 5, 27], state: "minecraft:cobblestone"},
        {pos: [14, 5, 28], state: "minecraft:gravel"},
        {pos: [14, 5, 29], state: "minecraft:cobblestone"},
        {pos: [14, 5, 30], state: "minecraft:cobblestone"},
        {pos: [14, 5, 31], state: "minecraft:cobblestone"},
        {pos: [14, 5, 32], state: "minecraft:cobblestone"},
        {pos: [14, 5, 33], state: "minecraft:gravel"},
        {pos: [15, 5, 3], state: "minecraft:cobblestone"},
        {pos: [15, 5, 4], state: "minecraft:cobblestone"},
        {pos: [15, 5, 13], state: "minecraft:cobblestone"},
        {pos: [15, 5, 14], state: "minecraft:cobblestone"},
        {pos: [15, 5, 18], state: "minecraft:gravel"},
        {pos: [15, 5, 27], state: "minecraft:gravel"},
        {pos: [15, 5, 28], state: "minecraft:cobblestone"},
        {pos: [15, 5, 29], state: "minecraft:cobblestone"},
        {pos: [15, 5, 30], state: "minecraft:cobblestone"},
        {pos: [15, 5, 31], state: "minecraft:cobblestone"},
        {pos: [16, 5, 1], state: "minecraft:gravel"},
        {pos: [16, 5, 2], state: "minecraft:cobblestone"},
        {pos: [16, 5, 3], state: "minecraft:gravel"},
        {pos: [16, 5, 4], state: "minecraft:cobblestone"},
        {pos: [16, 5, 13], state: "minecraft:gravel"},
        {pos: [16, 5, 14], state: "minecraft:gravel"},
        {pos: [16, 5, 18], state: "minecraft:gravel"},
        {pos: [16, 5, 19], state: "minecraft:gravel"},
        {pos: [16, 5, 20], state: "minecraft:gravel"},
        {pos: [17, 5, 1], state: "minecraft:gravel"},
        {pos: [17, 5, 2], state: "minecraft:cobblestone"},
        {pos: [17, 5, 3], state: "minecraft:gravel"},
        {pos: [18, 5, 1], state: "minecraft:gravel"},
        {pos: [18, 5, 2], state: "minecraft:gravel"},
        {pos: [18, 5, 3], state: "minecraft:gravel"},
        {pos: [19, 5, 22], state: "minecraft:cobblestone"},
        {pos: [19, 5, 23], state: "minecraft:cobblestone"},
        {pos: [20, 5, 21], state: "minecraft:gravel"},
        {pos: [20, 5, 22], state: "minecraft:cobblestone"},
        {pos: [20, 5, 23], state: "minecraft:cobblestone"},
        {pos: [21, 5, 22], state: "minecraft:gravel"},
        {pos: [21, 5, 23], state: "minecraft:gravel"},
        {pos: [1, 6, 5], state: "minecraft:gravel"},
        {pos: [2, 6, 4], state: "minecraft:gravel"},
        {pos: [2, 6, 5], state: "minecraft:cobblestone"},
        {pos: [2, 6, 6], state: "minecraft:gravel"},
        {pos: [2, 6, 24], state: "minecraft:cobblestone"},
        {pos: [2, 6, 25], state: "minecraft:cobblestone"},
        {pos: [3, 6, 4], state: "minecraft:cobblestone"},
        {pos: [3, 6, 5], state: "minecraft:gravel"},
        {pos: [3, 6, 6], state: "minecraft:gravel"},
        {pos: [3, 6, 13], state: "minecraft:gravel"},
        {pos: [3, 6, 24], state: "minecraft:cobblestone"},
        {pos: [3, 6, 25], state: "minecraft:cobblestone"},
        {pos: [4, 6, 5], state: "minecraft:gravel"},
        {pos: [4, 6, 13], state: "minecraft:gravel"},
        {pos: [4, 6, 14], state: "minecraft:gravel"},
        {pos: [5, 6, 13], state: "minecraft:gravel"},
        {pos: [7, 6, 28], state: "minecraft:cobblestone"},
        {pos: [7, 6, 29], state: "minecraft:cobblestone"},
        {pos: [7, 6, 30], state: "minecraft:cobblestone"},
        {pos: [7, 6, 31], state: "minecraft:gravel"},
        {pos: [8, 6, 26], state: "minecraft:cobblestone"},
        {pos: [8, 6, 27], state: "minecraft:cobblestone"},
        {pos: [8, 6, 28], state: "minecraft:cobblestone"},
        {pos: [8, 6, 29], state: "minecraft:cobblestone"},
        {pos: [8, 6, 30], state: "minecraft:gravel"},
        {pos: [8, 6, 31], state: "minecraft:gravel"},
        {pos: [8, 6, 32], state: "minecraft:cobblestone"},
        {pos: [9, 6, 26], state: "minecraft:cobblestone"},
        {pos: [9, 6, 27], state: "minecraft:cobblestone"},
        {pos: [9, 6, 28], state: "minecraft:cobblestone"},
        {pos: [9, 6, 29], state: "minecraft:gravel"},
        {pos: [9, 6, 30], state: "minecraft:gravel"},
        {pos: [9, 6, 31], state: "minecraft:gravel"},
        {pos: [9, 6, 32], state: "minecraft:cobblestone"},
        {pos: [9, 6, 33], state: "minecraft:cobblestone"},
        {pos: [10, 6, 26], state: "minecraft:cobblestone"},
        {pos: [10, 6, 27], state: "minecraft:cobblestone"},
        {pos: [10, 6, 28], state: "minecraft:cobblestone"},
        {pos: [10, 6, 29], state: "minecraft:gravel"},
        {pos: [10, 6, 30], state: "minecraft:gravel"},
        {pos: [10, 6, 31], state: "minecraft:gravel"},
        {pos: [10, 6, 32], state: "minecraft:gravel"},
        {pos: [10, 6, 33], state: "minecraft:gravel"},
        {pos: [11, 6, 13], state: "minecraft:cobblestone"},
        {pos: [11, 6, 25], state: "minecraft:gravel"},
        {pos: [11, 6, 26], state: "minecraft:cobblestone"},
        {pos: [11, 6, 27], state: "minecraft:cobblestone"},
        {pos: [11, 6, 28], state: "minecraft:cobblestone"},
        {pos: [11, 6, 29], state: "minecraft:gravel"},
        {pos: [11, 6, 30], state: "minecraft:gravel"},
        {pos: [11, 6, 31], state: "minecraft:gravel"},
        {pos: [11, 6, 32], state: "minecraft:gravel"},
        {pos: [11, 6, 33], state: "minecraft:cobblestone"},
        {pos: [12, 6, 13], state: "minecraft:cobblestone"},
        {pos: [12, 6, 14], state: "minecraft:cobblestone"},
        {pos: [12, 6, 26], state: "minecraft:cobblestone"},
        {pos: [12, 6, 27], state: "minecraft:gravel"},
        {pos: [12, 6, 28], state: "minecraft:gravel"},
        {pos: [12, 6, 29], state: "minecraft:gravel"},
        {pos: [12, 6, 30], state: "minecraft:gravel"},
        {pos: [12, 6, 31], state: "minecraft:gravel"},
        {pos: [12, 6, 32], state: "minecraft:gravel"},
        {pos: [12, 6, 33], state: "minecraft:cobblestone"},
        {pos: [13, 6, 13], state: "minecraft:gravel"},
        {pos: [13, 6, 14], state: "minecraft:cobblestone"},
        {pos: [13, 6, 26], state: "minecraft:gravel"},
        {pos: [13, 6, 27], state: "minecraft:cobblestone"},
        {pos: [13, 6, 28], state: "minecraft:gravel"},
        {pos: [13, 6, 29], state: "minecraft:gravel"},
        {pos: [13, 6, 30], state: "minecraft:cobblestone"},
        {pos: [13, 6, 31], state: "minecraft:gravel"},
        {pos: [13, 6, 32], state: "minecraft:gravel"},
        {pos: [13, 6, 33], state: "minecraft:cobblestone"},
        {pos: [14, 6, 3], state: "minecraft:cobblestone"},
        {pos: [14, 6, 4], state: "minecraft:cobblestone"},
        {pos: [14, 6, 13], state: "minecraft:cobblestone"},
        {pos: [14, 6, 14], state: "minecraft:cobblestone"},
        {pos: [14, 6, 27], state: "minecraft:cobblestone"},
        {pos: [14, 6, 28], state: "minecraft:gravel"},
        {pos: [14, 6, 29], state: "minecraft:gravel"},
        {pos: [14, 6, 30], state: "minecraft:gravel"},
        {pos: [14, 6, 31], state: "minecraft:gravel"},
        {pos: [14, 6, 32], state: "minecraft:cobblestone"},
        {pos: [14, 6, 33], state: "minecraft:gravel"},
        {pos: [15, 6, 3], state: "minecraft:cobblestone"},
        {pos: [15, 6, 4], state: "minecraft:cobblestone"},
        {pos: [15, 6, 5], state: "minecraft:cobblestone"},
        {pos: [15, 6, 13], state: "minecraft:gravel"},
        {pos: [15, 6, 14], state: "minecraft:gravel"},
        {pos: [15, 6, 28], state: "minecraft:cobblestone"},
        {pos: [15, 6, 29], state: "minecraft:cobblestone"},
        {pos: [15, 6, 30], state: "minecraft:cobblestone"},
        {pos: [15, 6, 31], state: "minecraft:cobblestone"},
        {pos: [16, 6, 1], state: "minecraft:gravel"},
        {pos: [16, 6, 2], state: "minecraft:cobblestone"},
        {pos: [16, 6, 3], state: "minecraft:gravel"},
        {pos: [16, 6, 4], state: "minecraft:cobblestone"},
        {pos: [17, 6, 1], state: "minecraft:gravel"},
        {pos: [17, 6, 2], state: "minecraft:cobblestone"},
        {pos: [17, 6, 3], state: "minecraft:gravel"},
        {pos: [18, 6, 2], state: "minecraft:gravel"},
        {pos: [18, 6, 23], state: "minecraft:cobblestone"},
        {pos: [18, 6, 24], state: "minecraft:cobblestone"},
        {pos: [19, 6, 22], state: "minecraft:cobblestone"},
        {pos: [19, 6, 23], state: "minecraft:cobblestone"},
        {pos: [19, 6, 24], state: "minecraft:cobblestone"},
        {pos: [20, 6, 22], state: "minecraft:cobblestone"},
        {pos: [20, 6, 23], state: "minecraft:cobblestone"},
        {pos: [21, 6, 22], state: "minecraft:gravel"},
        {pos: [21, 6, 23], state: "minecraft:gravel"},
        {pos: [1, 7, 5], state: "minecraft:gravel"},
        {pos: [2, 7, 4], state: "minecraft:cobblestone"},
        {pos: [2, 7, 5], state: "minecraft:cobblestone"},
        {pos: [2, 7, 24], state: "minecraft:gravel"},
        {pos: [2, 7, 25], state: "minecraft:gravel"},
        {pos: [3, 7, 4], state: "minecraft:cobblestone"},
        {pos: [3, 7, 5], state: "minecraft:cobblestone"},
        {pos: [3, 7, 24], state: "minecraft:gravel"},
        {pos: [3, 7, 25], state: "minecraft:gravel"},
        {pos: [7, 7, 28], state: "minecraft:cobblestone"},
        {pos: [7, 7, 29], state: "minecraft:cobblestone"},
        {pos: [7, 7, 30], state: "minecraft:gravel"},
        {pos: [7, 7, 31], state: "minecraft:gravel"},
        {pos: [8, 7, 27], state: "minecraft:cobblestone"},
        {pos: [8, 7, 28], state: "minecraft:gravel"},
        {pos: [8, 7, 29], state: "minecraft:gravel"},
        {pos: [8, 7, 30], state: "minecraft:gravel"},
        {pos: [8, 7, 31], state: "minecraft:gravel"},
        {pos: [8, 7, 32], state: "minecraft:gravel"},
        {pos: [9, 7, 26], state: "minecraft:cobblestone"},
        {pos: [9, 7, 27], state: "minecraft:gravel"},
        {pos: [9, 7, 28], state: "minecraft:gravel"},
        {pos: [9, 7, 29], state: "minecraft:gravel"},
        {pos: [9, 7, 30], state: "minecraft:gravel"},
        {pos: [9, 7, 31], state: "minecraft:gravel"},
        {pos: [9, 7, 32], state: "minecraft:cobblestone"},
        {pos: [9, 7, 33], state: "minecraft:gravel"},
        {pos: [10, 7, 26], state: "minecraft:cobblestone"},
        {pos: [10, 7, 27], state: "minecraft:gravel"},
        {pos: [10, 7, 28], state: "minecraft:gravel"},
        {pos: [10, 7, 29], state: "minecraft:gravel"},
        {pos: [10, 7, 30], state: "minecraft:gravel"},
        {pos: [10, 7, 31], state: "minecraft:gravel"},
        {pos: [10, 7, 32], state: "minecraft:gravel"},
        {pos: [10, 7, 33], state: "minecraft:gravel"},
        {pos: [11, 7, 26], state: "minecraft:cobblestone"},
        {pos: [11, 7, 27], state: "minecraft:gravel"},
        {pos: [11, 7, 28], state: "minecraft:gravel"},
        {pos: [11, 7, 29], state: "minecraft:gravel"},
        {pos: [11, 7, 30], state: "minecraft:gravel"},
        {pos: [11, 7, 31], state: "minecraft:gravel"},
        {pos: [11, 7, 32], state: "minecraft:gravel"},
        {pos: [11, 7, 33], state: "minecraft:cobblestone"},
        {pos: [12, 7, 13], state: "minecraft:gravel"},
        {pos: [12, 7, 14], state: "minecraft:gravel"},
        {pos: [12, 7, 26], state: "minecraft:gravel"},
        {pos: [12, 7, 27], state: "minecraft:gravel"},
        {pos: [12, 7, 28], state: "minecraft:gravel"},
        {pos: [12, 7, 29], state: "minecraft:gravel"},
        {pos: [12, 7, 30], state: "minecraft:gravel"},
        {pos: [12, 7, 31], state: "minecraft:gravel"},
        {pos: [12, 7, 32], state: "minecraft:gravel"},
        {pos: [12, 7, 33], state: "minecraft:cobblestone"},
        {pos: [13, 7, 13], state: "minecraft:gravel"},
        {pos: [13, 7, 14], state: "minecraft:gravel"},
        {pos: [13, 7, 27], state: "minecraft:gravel"},
        {pos: [13, 7, 28], state: "minecraft:gravel"},
        {pos: [13, 7, 29], state: "minecraft:gravel"},
        {pos: [13, 7, 30], state: "minecraft:cobblestone"},
        {pos: [13, 7, 31], state: "minecraft:gravel"},
        {pos: [13, 7, 32], state: "minecraft:gravel"},
        {pos: [13, 7, 33], state: "minecraft:cobblestone"},
        {pos: [14, 7, 5], state: "minecraft:cobblestone"},
        {pos: [14, 7, 13], state: "minecraft:gravel"},
        {pos: [14, 7, 14], state: "minecraft:gravel"},
        {pos: [14, 7, 27], state: "minecraft:gravel"},
        {pos: [14, 7, 28], state: "minecraft:gravel"},
        {pos: [14, 7, 29], state: "minecraft:gravel"},
        {pos: [14, 7, 30], state: "minecraft:gravel"},
        {pos: [14, 7, 31], state: "minecraft:gravel"},
        {pos: [14, 7, 32], state: "minecraft:cobblestone"},
        {pos: [14, 7, 33], state: "minecraft:gravel"},
        {pos: [15, 7, 3], state: "minecraft:cobblestone"},
        {pos: [15, 7, 4], state: "minecraft:cobblestone"},
        {pos: [15, 7, 5], state: "minecraft:gravel"},
        {pos: [15, 7, 28], state: "minecraft:gravel"},
        {pos: [15, 7, 29], state: "minecraft:gravel"},
        {pos: [15, 7, 30], state: "minecraft:cobblestone"},
        {pos: [15, 7, 31], state: "minecraft:cobblestone"},
        {pos: [16, 7, 1], state: "minecraft:gravel"},
        {pos: [16, 7, 2], state: "minecraft:gravel"},
        {pos: [16, 7, 3], state: "minecraft:cobblestone"},
        {pos: [16, 7, 4], state: "minecraft:cobblestone"},
        {pos: [17, 7, 1], state: "minecraft:gravel"},
        {pos: [17, 7, 2], state: "minecraft:gravel"},
        {pos: [17, 7, 3], state: "minecraft:cobblestone"},
        {pos: [18, 7, 22], state: "minecraft:cobblestone"},
        {pos: [18, 7, 23], state: "minecraft:cobblestone"},
        {pos: [18, 7, 24], state: "minecraft:cobblestone"},
        {pos: [19, 7, 22], state: "minecraft:cobblestone"},
        {pos: [19, 7, 23], state: "minecraft:cobblestone"},
        {pos: [19, 7, 24], state: "minecraft:cobblestone"},
        {pos: [20, 7, 22], state: "minecraft:cobblestone"},
        {pos: [20, 7, 23], state: "minecraft:cobblestone"},
        {pos: [21, 7, 22], state: "minecraft:gravel"},
        {pos: [2, 8, 4], state: "minecraft:cobblestone"},
        {pos: [2, 8, 5], state: "minecraft:cobblestone"},
        {pos: [2, 8, 24], state: "minecraft:gravel"},
        {pos: [3, 8, 4], state: "minecraft:gravel"},
        {pos: [3, 8, 5], state: "minecraft:cobblestone"},
        {pos: [3, 8, 24], state: "minecraft:gravel"},
        {pos: [3, 8, 25], state: "minecraft:gravel"},
        {pos: [7, 8, 28], state: "minecraft:cobblestone"},
        {pos: [7, 8, 29], state: "minecraft:gravel"},
        {pos: [7, 8, 30], state: "minecraft:gravel"},
        {pos: [7, 8, 31], state: "minecraft:gravel"},
