{
    DataVersion: 3953,
    size: [19, 9, 25],
    data: [
        {pos: [0, 0, 6], state: "minecraft:cobblestone"},
        {pos: [0, 0, 7], state: "minecraft:cobblestone"},
        {pos: [1, 0, 5], state: "minecraft:cobblestone"},
        {pos: [1, 0, 6], state: "minecraft:cobblestone"},
        {pos: [1, 0, 7], state: "minecraft:cobblestone"},
        {pos: [1, 0, 8], state: "minecraft:cobblestone"},
        {pos: [1, 0, 11], state: "minecraft:cobblestone"},
        {pos: [1, 0, 12], state: "minecraft:cobblestone"},
        {pos: [1, 0, 13], state: "minecraft:cobblestone"},
        {pos: [1, 0, 14], state: "minecraft:cobblestone"},
        {pos: [1, 0, 15], state: "minecraft:cobblestone"},
        {pos: [2, 0, 5], state: "minecraft:cobblestone"},
        {pos: [2, 0, 6], state: "minecraft:cobblestone"},
        {pos: [2, 0, 7], state: "minecraft:cobblestone"},
        {pos: [2, 0, 8], state: "minecraft:cobblestone"},
        {pos: [2, 0, 10], state: "minecraft:cobblestone"},
        {pos: [2, 0, 11], state: "minecraft:cobblestone"},
        {pos: [2, 0, 12], state: "minecraft:cobblestone"},
        {pos: [2, 0, 13], state: "minecraft:cobblestone"},
        {pos: [2, 0, 14], state: "minecraft:cobblestone"},
        {pos: [2, 0, 15], state: "minecraft:cobblestone"},
        {pos: [2, 0, 16], state: "minecraft:cobblestone"},
        {pos: [3, 0, 6], state: "minecraft:cobblestone"},
        {pos: [3, 0, 10], state: "minecraft:cobblestone"},
        {pos: [3, 0, 11], state: "minecraft:cobblestone"},
        {pos: [3, 0, 12], state: "minecraft:cobblestone"},
        {pos: [3, 0, 13], state: "minecraft:cobblestone"},
        {pos: [3, 0, 14], state: "minecraft:cobblestone"},
        {pos: [3, 0, 15], state: "minecraft:cobblestone"},
        {pos: [3, 0, 16], state: "minecraft:cobblestone"},
        {pos: [3, 0, 17], state: "minecraft:cobblestone"},
        {pos: [4, 0, 4], state: "minecraft:cobblestone"},
        {pos: [4, 0, 5], state: "minecraft:cobblestone"},
        {pos: [4, 0, 6], state: "minecraft:cobblestone"},
        {pos: [4, 0, 10], state: "minecraft:cobblestone"},
        {pos: [4, 0, 11], state: "minecraft:cobblestone"},
        {pos: [4, 0, 12], state: "minecraft:cobblestone"},
        {pos: [4, 0, 13], state: "minecraft:cobblestone"},
        {pos: [4, 0, 14], state: "minecraft:cobblestone"},
        {pos: [4, 0, 15], state: "minecraft:cobblestone"},
        {pos: [4, 0, 16], state: "minecraft:cobblestone"},
        {pos: [4, 0, 17], state: "minecraft:cobblestone"},
        {pos: [4, 0, 19], state: "minecraft:cobblestone"},
        {pos: [4, 0, 20], state: "minecraft:cobblestone"},
        {pos: [4, 0, 21], state: "minecraft:cobblestone"},
        {pos: [5, 0, 3], state: "minecraft:cobblestone"},
        {pos: [5, 0, 4], state: "minecraft:cobblestone"},
        {pos: [5, 0, 5], state: "minecraft:cobblestone"},
        {pos: [5, 0, 6], state: "minecraft:cobblestone"},
        {pos: [5, 0, 7], state: "minecraft:cobblestone"},
        {pos: [5, 0, 8], state: "minecraft:cobblestone"},
        {pos: [5, 0, 11], state: "minecraft:cobblestone"},
        {pos: [5, 0, 12], state: "minecraft:cobblestone"},
        {pos: [5, 0, 13], state: "minecraft:cobblestone"},
        {pos: [5, 0, 14], state: "minecraft:cobblestone"},
        {pos: [5, 0, 15], state: "minecraft:cobblestone"},
        {pos: [5, 0, 16], state: "minecraft:cobblestone"},
        {pos: [5, 0, 17], state: "minecraft:cobblestone"},
        {pos: [5, 0, 19], state: "minecraft:cobblestone"},
        {pos: [5, 0, 20], state: "minecraft:cobblestone"},
        {pos: [5, 0, 21], state: "minecraft:cobblestone"},
        {pos: [6, 0, 3], state: "minecraft:cobblestone"},
        {pos: [6, 0, 4], state: "minecraft:cobblestone"},
        {pos: [6, 0, 5], state: "minecraft:cobblestone"},
        {pos: [6, 0, 6], state: "minecraft:cobblestone"},
        {pos: [6, 0, 7], state: "minecraft:cobblestone"},
        {pos: [6, 0, 8], state: "minecraft:cobblestone"},
        {pos: [6, 0, 9], state: "minecraft:cobblestone"},
        {pos: [6, 0, 11], state: "minecraft:cobblestone"},
        {pos: [6, 0, 12], state: "minecraft:cobblestone"},
        {pos: [6, 0, 13], state: "minecraft:cobblestone"},
        {pos: [6, 0, 14], state: "minecraft:cobblestone"},
        {pos: [6, 0, 19], state: "minecraft:cobblestone"},
        {pos: [6, 0, 20], state: "minecraft:cobblestone"},
        {pos: [6, 0, 21], state: "minecraft:cobblestone"},
        {pos: [7, 0, 3], state: "minecraft:cobblestone"},
        {pos: [7, 0, 4], state: "minecraft:cobblestone"},
        {pos: [7, 0, 5], state: "minecraft:cobblestone"},
        {pos: [7, 0, 6], state: "minecraft:cobblestone"},
        {pos: [7, 0, 7], state: "minecraft:cobblestone"},
        {pos: [7, 0, 8], state: "minecraft:cobblestone"},
        {pos: [7, 0, 9], state: "minecraft:cobblestone"},
        {pos: [7, 0, 12], state: "minecraft:cobblestone"},
        {pos: [7, 0, 16], state: "minecraft:cobblestone"},
        {pos: [7, 0, 17], state: "minecraft:cobblestone"},
        {pos: [7, 0, 20], state: "minecraft:cobblestone"},
        {pos: [7, 0, 23], state: "minecraft:cobblestone"},
        {pos: [8, 0, 4], state: "minecraft:cobblestone"},
        {pos: [8, 0, 5], state: "minecraft:cobblestone"},
        {pos: [8, 0, 6], state: "minecraft:cobblestone"},
        {pos: [8, 0, 7], state: "minecraft:cobblestone"},
        {pos: [8, 0, 8], state: "minecraft:cobblestone"},
        {pos: [8, 0, 9], state: "minecraft:cobblestone"},
        {pos: [8, 0, 10], state: "minecraft:cobblestone"},
        {pos: [8, 0, 11], state: "minecraft:cobblestone"},
        {pos: [8, 0, 13], state: "minecraft:cobblestone"},
        {pos: [8, 0, 14], state: "minecraft:cobblestone"},
        {pos: [8, 0, 15], state: "minecraft:cobblestone"},
        {pos: [8, 0, 16], state: "minecraft:cobblestone"},
        {pos: [8, 0, 17], state: "minecraft:cobblestone"},
        {pos: [8, 0, 18], state: "minecraft:cobblestone"},
        {pos: [8, 0, 19], state: "minecraft:cobblestone"},
        {pos: [8, 0, 20], state: "minecraft:cobblestone"},
        {pos: [8, 0, 21], state: "minecraft:cobblestone"},
        {pos: [8, 0, 22], state: "minecraft:cobblestone"},
        {pos: [8, 0, 23], state: "minecraft:cobblestone"},
        {pos: [8, 0, 24], state: "minecraft:cobblestone"},
        {pos: [9, 0, 3], state: "minecraft:cobblestone"},
        {pos: [9, 0, 4], state: "minecraft:cobblestone"},
        {pos: [9, 0, 5], state: "minecraft:cobblestone"},
        {pos: [9, 0, 6], state: "minecraft:cobblestone"},
        {pos: [9, 0, 7], state: "minecraft:cobblestone"},
        {pos: [9, 0, 8], state: "minecraft:cobblestone"},
        {pos: [9, 0, 9], state: "minecraft:cobblestone"},
        {pos: [9, 0, 10], state: "minecraft:cobblestone"},
        {pos: [9, 0, 11], state: "minecraft:cobblestone"},
        {pos: [9, 0, 12], state: "minecraft:cobblestone"},
        {pos: [9, 0, 13], state: "minecraft:cobblestone"},
        {pos: [9, 0, 14], state: "minecraft:cobblestone"},
        {pos: [9, 0, 15], state: "minecraft:cobblestone"},
        {pos: [9, 0, 16], state: "minecraft:cobblestone"},
        {pos: [9, 0, 17], state: "minecraft:cobblestone"},
        {pos: [9, 0, 18], state: "minecraft:cobblestone"},
        {pos: [9, 0, 19], state: "minecraft:cobblestone"},
        {pos: [9, 0, 20], state: "minecraft:cobblestone"},
        {pos: [9, 0, 21], state: "minecraft:cobblestone"},
        {pos: [9, 0, 22], state: "minecraft:cobblestone"},
        {pos: [10, 0, 3], state: "minecraft:cobblestone"},
        {pos: [10, 0, 4], state: "minecraft:cobblestone"},
        {pos: [10, 0, 5], state: "minecraft:cobblestone"},
        {pos: [10, 0, 6], state: "minecraft:cobblestone"},
        {pos: [10, 0, 7], state: "minecraft:cobblestone"},
        {pos: [10, 0, 8], state: "minecraft:cobblestone"},
        {pos: [10, 0, 9], state: "minecraft:cobblestone"},
        {pos: [10, 0, 10], state: "minecraft:cobblestone"},
        {pos: [10, 0, 15], state: "minecraft:cobblestone"},
        {pos: [10, 0, 16], state: "minecraft:cobblestone"},
        {pos: [10, 0, 17], state: "minecraft:cobblestone"},
        {pos: [10, 0, 18], state: "minecraft:cobblestone"},
        {pos: [11, 0, 4], state: "minecraft:cobblestone"},
        {pos: [11, 0, 5], state: "minecraft:cobblestone"},
        {pos: [11, 0, 6], state: "minecraft:cobblestone"},
        {pos: [11, 0, 7], state: "minecraft:cobblestone"},
        {pos: [11, 0, 8], state: "minecraft:cobblestone"},
        {pos: [11, 0, 11], state: "minecraft:cobblestone"},
        {pos: [11, 0, 12], state: "minecraft:cobblestone"},
        {pos: [11, 0, 13], state: "minecraft:cobblestone"},
        {pos: [11, 0, 17], state: "minecraft:cobblestone"},
        {pos: [11, 0, 20], state: "minecraft:cobblestone"},
        {pos: [11, 0, 21], state: "minecraft:cobblestone"},
        {pos: [11, 0, 22], state: "minecraft:cobblestone"},
        {pos: [12, 0, 4], state: "minecraft:cobblestone"},
        {pos: [12, 0, 5], state: "minecraft:cobblestone"},
        {pos: [12, 0, 6], state: "minecraft:cobblestone"},
        {pos: [12, 0, 7], state: "minecraft:cobblestone"},
        {pos: [12, 0, 11], state: "minecraft:cobblestone"},
        {pos: [12, 0, 12], state: "minecraft:cobblestone"},
        {pos: [12, 0, 13], state: "minecraft:cobblestone"},
        {pos: [12, 0, 14], state: "minecraft:cobblestone"},
        {pos: [12, 0, 15], state: "minecraft:cobblestone"},
        {pos: [12, 0, 16], state: "minecraft:cobblestone"},
        {pos: [12, 0, 17], state: "minecraft:cobblestone"},
        {pos: [12, 0, 20], state: "minecraft:cobblestone"},
        {pos: [12, 0, 21], state: "minecraft:gravel"},
        {pos: [12, 0, 22], state: "minecraft:cobblestone"},
        {pos: [12, 0, 23], state: "minecraft:cobblestone"},
        {pos: [13, 0, 5], state: "minecraft:cobblestone"},
        {pos: [13, 0, 6], state: "minecraft:cobblestone"},
        {pos: [13, 0, 10], state: "minecraft:cobblestone"},
        {pos: [13, 0, 11], state: "minecraft:cobblestone"},
        {pos: [13, 0, 12], state: "minecraft:cobblestone"},
        {pos: [13, 0, 13], state: "minecraft:cobblestone"},
        {pos: [13, 0, 14], state: "minecraft:cobblestone"},
        {pos: [13, 0, 15], state: "minecraft:cobblestone"},
        {pos: [13, 0, 16], state: "minecraft:cobblestone"},
        {pos: [13, 0, 17], state: "minecraft:cobblestone"},
        {pos: [13, 0, 18], state: "minecraft:cobblestone"},
        {pos: [13, 0, 20], state: "minecraft:cobblestone"},
        {pos: [13, 0, 21], state: "minecraft:cobblestone"},
        {pos: [13, 0, 22], state: "minecraft:cobblestone"},
        {pos: [14, 0, 1], state: "minecraft:cobblestone"},
        {pos: [14, 0, 2], state: "minecraft:cobblestone"},
        {pos: [14, 0, 4], state: "minecraft:cobblestone"},
        {pos: [14, 0, 5], state: "minecraft:cobblestone"},
        {pos: [14, 0, 6], state: "minecraft:cobblestone"},
        {pos: [14, 0, 9], state: "minecraft:cobblestone"},
        {pos: [14, 0, 10], state: "minecraft:cobblestone"},
        {pos: [14, 0, 11], state: "minecraft:cobblestone"},
        {pos: [14, 0, 12], state: "minecraft:cobblestone"},
        {pos: [14, 0, 13], state: "minecraft:cobblestone"},
        {pos: [14, 0, 14], state: "minecraft:cobblestone"},
        {pos: [14, 0, 15], state: "minecraft:cobblestone"},
        {pos: [14, 0, 16], state: "minecraft:cobblestone"},
        {pos: [14, 0, 17], state: "minecraft:cobblestone"},
        {pos: [14, 0, 18], state: "minecraft:cobblestone"},
        {pos: [15, 0, 2], state: "minecraft:cobblestone"},
        {pos: [15, 0, 3], state: "minecraft:cobblestone"},
        {pos: [15, 0, 4], state: "minecraft:cobblestone"},
        {pos: [15, 0, 10], state: "minecraft:cobblestone"},
        {pos: [15, 0, 11], state: "minecraft:cobblestone"},
        {pos: [15, 0, 12], state: "minecraft:cobblestone"},
        {pos: [15, 0, 13], state: "minecraft:gravel"},
        {pos: [15, 0, 14], state: "minecraft:gravel"},
        {pos: [15, 0, 15], state: "minecraft:cobblestone"},
        {pos: [15, 0, 16], state: "minecraft:cobblestone"},
        {pos: [16, 0, 0], state: "minecraft:cobblestone"},
        {pos: [16, 0, 2], state: "minecraft:cobblestone"},
        {pos: [16, 0, 3], state: "minecraft:gravel"},
        {pos: [16, 0, 4], state: "minecraft:cobblestone"},
        {pos: [16, 0, 11], state: "minecraft:cobblestone"},
        {pos: [16, 0, 13], state: "minecraft:cobblestone"},
        {pos: [16, 0, 14], state: "minecraft:cobblestone"},
        {pos: [16, 0, 15], state: "minecraft:cobblestone"},
        {pos: [17, 0, 1], state: "minecraft:cobblestone"},
        {pos: [17, 0, 2], state: "minecraft:cobblestone"},
        {pos: [17, 0, 3], state: "minecraft:cobblestone"},
        {pos: [18, 0, 3], state: "minecraft:cobblestone"},
        {pos: [0, 1, 6], state: "minecraft:gravel"},
        {pos: [0, 1, 7], state: "minecraft:gravel"},
        {pos: [1, 1, 5], state: "minecraft:cobblestone"},
        {pos: [1, 1, 6], state: "minecraft:cobblestone"},
        {pos: [1, 1, 7], state: "minecraft:cobblestone"},
        {pos: [1, 1, 8], state: "minecraft:cobblestone"},
        {pos: [1, 1, 11], state: "minecraft:gravel"},
        {pos: [1, 1, 12], state: "minecraft:gravel"},
        {pos: [1, 1, 13], state: "minecraft:gravel"},
        {pos: [1, 1, 14], state: "minecraft:gravel"},
        {pos: [1, 1, 15], state: "minecraft:gravel"},
        {pos: [2, 1, 5], state: "minecraft:gravel"},
        {pos: [2, 1, 6], state: "minecraft:cobblestone"},
        {pos: [2, 1, 7], state: "minecraft:cobblestone"},
        {pos: [2, 1, 8], state: "minecraft:gravel"},
        {pos: [2, 1, 10], state: "minecraft:gravel"},
        {pos: [2, 1, 11], state: "minecraft:gravel"},
        {pos: [2, 1, 12], state: "minecraft:cobblestone"},
        {pos: [2, 1, 13], state: "minecraft:cobblestone"},
        {pos: [2, 1, 14], state: "minecraft:gravel"},
        {pos: [2, 1, 15], state: "minecraft:gravel"},
        {pos: [2, 1, 16], state: "minecraft:gravel"},
        {pos: [3, 1, 6], state: "minecraft:gravel"},
        {pos: [3, 1, 10], state: "minecraft:gravel"},
        {pos: [3, 1, 11], state: "minecraft:cobblestone"},
        {pos: [3, 1, 12], state: "minecraft:cobblestone"},
        {pos: [3, 1, 13], state: "minecraft:cobblestone"},
        {pos: [3, 1, 14], state: "minecraft:cobblestone"},
        {pos: [3, 1, 15], state: "minecraft:cobblestone"},
        {pos: [3, 1, 16], state: "minecraft:cobblestone"},
        {pos: [3, 1, 17], state: "minecraft:cobblestone"},
        {pos: [4, 1, 4], state: "minecraft:gravel"},
        {pos: [4, 1, 5], state: "minecraft:gravel"},
        {pos: [4, 1, 6], state: "minecraft:gravel"},
        {pos: [4, 1, 10], state: "minecraft:gravel"},
        {pos: [4, 1, 11], state: "minecraft:cobblestone"},
        {pos: [4, 1, 12], state: "minecraft:clay"},
        {pos: [4, 1, 13], state: "minecraft:clay"},
        {pos: [4, 1, 14], state: "minecraft:clay"},
        {pos: [4, 1, 15], state: "minecraft:clay"},
        {pos: [4, 1, 16], state: "minecraft:clay"},
        {pos: [4, 1, 17], state: "minecraft:gravel"},
        {pos: [4, 1, 19], state: "minecraft:cobblestone"},
        {pos: [4, 1, 20], state: "minecraft:cobblestone"},
        {pos: [4, 1, 21], state: "minecraft:cobblestone"},
        {pos: [5, 1, 3], state: "minecraft:gravel"},
        {pos: [5, 1, 4], state: "minecraft:water_cauldron{level:3}"},
        {pos: [5, 1, 5], state: "minecraft:cobblestone"},
        {pos: [5, 1, 6], state: "minecraft:cobblestone"},
        {pos: [5, 1, 7], state: "minecraft:cobblestone"},
        {pos: [5, 1, 8], state: "minecraft:gravel"},
        {pos: [5, 1, 11], state: "minecraft:gravel"},
        {pos: [5, 1, 12], state: "minecraft:cobblestone_stairs{facing:west,half:top,shape:straight,waterlogged:false}"},
        {pos: [5, 1, 13], state: "minecraft:cobblestone_stairs{facing:west,half:top,shape:straight,waterlogged:false}"},
        {pos: [5, 1, 14], state: "minecraft:cobblestone"},
        {pos: [5, 1, 15], state: "minecraft:cobblestone_stairs{facing:west,half:top,shape:straight,waterlogged:false}"},
        {pos: [5, 1, 16], state: "minecraft:gravel"},
        {pos: [5, 1, 17], state: "minecraft:gravel"},
        {pos: [5, 1, 19], state: "minecraft:cobblestone"},
        {pos: [5, 1, 20], state: "minecraft:cobblestone"},
        {pos: [5, 1, 21], state: "minecraft:cobblestone"},
        {pos: [6, 1, 3], state: "minecraft:gravel"},
        {pos: [6, 1, 4], state: "minecraft:gravel"},
        {pos: [6, 1, 5], state: "minecraft:cobblestone"},
        {pos: [6, 1, 6], state: "minecraft:clay"},
        {pos: [6, 1, 7], state: "minecraft:clay"},
        {pos: [6, 1, 8], state: "minecraft:gravel"},
        {pos: [6, 1, 9], state: "minecraft:gravel"},
        {pos: [6, 1, 11], state: "minecraft:gravel"},
        {pos: [6, 1, 12], state: "minecraft:gravel"},
        {pos: [6, 1, 13], state: "minecraft:gravel"},
        {pos: [6, 1, 14], state: "minecraft:gravel"},
        {pos: [6, 1, 19], state: "minecraft:gravel"},
        {pos: [6, 1, 20], state: "minecraft:cobblestone"},
        {pos: [6, 1, 21], state: "minecraft:gravel"},
        {pos: [7, 1, 3], state: "minecraft:gravel"},
        {pos: [7, 1, 4], state: "minecraft:gravel"},
        {pos: [7, 1, 5], state: "minecraft:clay"},
        {pos: [7, 1, 6], state: "minecraft:clay"},
        {pos: [7, 1, 7], state: "minecraft:gravel"},
        {pos: [7, 1, 8], state: "minecraft:gravel"},
        {pos: [7, 1, 9], state: "minecraft:clay"},
        {pos: [7, 1, 12], state: "minecraft:gravel"},
        {pos: [7, 1, 16], state: "minecraft:gravel"},
        {pos: [7, 1, 17], state: "minecraft:gravel"},
        {pos: [7, 1, 20], state: "minecraft:gravel"},
        {pos: [7, 1, 23], state: "minecraft:gravel"},
        {pos: [8, 1, 4], state: "minecraft:gravel"},
        {pos: [8, 1, 5], state: "minecraft:gravel"},
        {pos: [8, 1, 6], state: "minecraft:gravel"},
        {pos: [8, 1, 7], state: "minecraft:gravel"},
        {pos: [8, 1, 8], state: "minecraft:clay"},
        {pos: [8, 1, 9], state: "minecraft:clay"},
        {pos: [8, 1, 10], state: "minecraft:clay"},
        {pos: [8, 1, 11], state: "minecraft:gravel"},
        {pos: [8, 1, 13], state: "minecraft:gravel"},
        {pos: [8, 1, 14], state: "minecraft:gravel"},
        {pos: [8, 1, 15], state: "minecraft:gravel"},
        {pos: [8, 1, 16], state: "minecraft:gravel"},
        {pos: [8, 1, 17], state: "minecraft:gravel"},
        {pos: [8, 1, 18], state: "minecraft:gravel"},
        {pos: [8, 1, 19], state: "minecraft:gravel"},
        {pos: [8, 1, 20], state: "minecraft:gravel"},
        {pos: [8, 1, 21], state: "minecraft:gravel"},
        {pos: [8, 1, 22], state: "minecraft:gravel"},
        {pos: [8, 1, 23], state: "minecraft:gravel"},
        {pos: [8, 1, 24], state: "minecraft:gravel"},
        {pos: [9, 1, 4], state: "minecraft:gravel"},
        {pos: [9, 1, 5], state: "minecraft:cobblestone"},
        {pos: [9, 1, 6], state: "minecraft:gravel"},
        {pos: [9, 1, 7], state: "minecraft:gravel"},
        {pos: [9, 1, 8], state: "minecraft:water_cauldron{level:3}"},
        {pos: [9, 1, 9], state: "minecraft:clay"},
        {pos: [9, 1, 10], state: "minecraft:clay"},
        {pos: [9, 1, 11], state: "minecraft:gravel"},
        {pos: [9, 1, 12], state: "minecraft:gravel"},
        {pos: [9, 1, 13], state: "minecraft:gravel"},
        {pos: [9, 1, 14], state: "minecraft:gravel"},
        {pos: [9, 1, 15], state: "minecraft:gravel"},
        {pos: [9, 1, 16], state: "minecraft:gravel"},
        {pos: [9, 1, 17], state: "minecraft:gravel"},
        {pos: [9, 1, 18], state: "minecraft:gravel"},
        {pos: [9, 1, 19], state: "minecraft:gravel"},
        {pos: [9, 1, 20], state: "minecraft:gravel"},
        {pos: [9, 1, 21], state: "minecraft:gravel"},
        {pos: [9, 1, 22], state: "minecraft:gravel"},
        {pos: [10, 1, 4], state: "minecraft:gravel"},
        {pos: [10, 1, 5], state: "minecraft:cobblestone"},
        {pos: [10, 1, 6], state: "minecraft:clay"},
        {pos: [10, 1, 7], state: "minecraft:gravel"},
        {pos: [10, 1, 8], state: "minecraft:gravel"},
        {pos: [10, 1, 9], state: "minecraft:gravel"},
        {pos: [10, 1, 10], state: "minecraft:gravel"},
        {pos: [10, 1, 15], state: "minecraft:gravel"},
        {pos: [10, 1, 16], state: "minecraft:gravel"},
        {pos: [10, 1, 17], state: "minecraft:gravel"},
        {pos: [10, 1, 18], state: "minecraft:gravel"},
        {pos: [11, 1, 4], state: "minecraft:gravel"},
        {pos: [11, 1, 5], state: "minecraft:cobblestone"},
        {pos: [11, 1, 6], state: "minecraft:clay"},
        {pos: [11, 1, 7], state: "minecraft:clay"},
        {pos: [11, 1, 8], state: "minecraft:gravel"},
        {pos: [11, 1, 11], state: "minecraft:gravel"},
        {pos: [11, 1, 12], state: "minecraft:gravel"},
        {pos: [11, 1, 13], state: "minecraft:gravel"},
        {pos: [11, 1, 17], state: "minecraft:gravel"},
        {pos: [11, 1, 20], state: "minecraft:cobblestone"},
        {pos: [11, 1, 21], state: "minecraft:cobblestone"},
        {pos: [11, 1, 22], state: "minecraft:gravel"},
        {pos: [12, 1, 4], state: "minecraft:gravel"},
        {pos: [12, 1, 5], state: "minecraft:cobblestone"},
        {pos: [12, 1, 6], state: "minecraft:cobblestone"},
        {pos: [12, 1, 7], state: "minecraft:gravel"},
        {pos: [12, 1, 11], state: "minecraft:gravel"},
        {pos: [12, 1, 12], state: "minecraft:cobblestone"},
        {pos: [12, 1, 13], state: "minecraft:cobblestone"},
        {pos: [12, 1, 14], state: "minecraft:cobblestone_stairs{facing:east,half:top,shape:straight,waterlogged:false}"},
        {pos: [12, 1, 15], state: "minecraft:cobblestone_stairs{facing:east,half:top,shape:straight,waterlogged:false}"},
        {pos: [12, 1, 16], state: "minecraft:cobblestone_stairs{facing:east,half:top,shape:straight,waterlogged:false}"},
        {pos: [12, 1, 17], state: "minecraft:cobblestone"},
        {pos: [12, 1, 20], state: "minecraft:cobblestone"},
        {pos: [12, 1, 21], state: "minecraft:gravel"},
        {pos: [12, 1, 22], state: "minecraft:gravel"},
        {pos: [12, 1, 23], state: "minecraft:gravel"},
        {pos: [13, 1, 5], state: "minecraft:gravel"},
        {pos: [13, 1, 6], state: "minecraft:gravel"},
        {pos: [13, 1, 10], state: "minecraft:gravel"},
        {pos: [13, 1, 11], state: "minecraft:gravel"},
        {pos: [13, 1, 12], state: "minecraft:clay"},
        {pos: [13, 1, 13], state: "minecraft:clay"},
        {pos: [13, 1, 14], state: "minecraft:clay"},
        {pos: [13, 1, 15], state: "minecraft:clay"},
        {pos: [13, 1, 16], state: "minecraft:clay"},
        {pos: [13, 1, 17], state: "minecraft:cobblestone"},
        {pos: [13, 1, 18], state: "minecraft:gravel"},
        {pos: [13, 1, 20], state: "minecraft:gravel"},
        {pos: [13, 1, 21], state: "minecraft:gravel"},
        {pos: [13, 1, 22], state: "minecraft:gravel"},
        {pos: [14, 1, 1], state: "minecraft:gravel"},
        {pos: [14, 1, 2], state: "minecraft:gravel"},
        {pos: [14, 1, 4], state: "minecraft:gravel"},
        {pos: [14, 1, 5], state: "minecraft:gravel"},
        {pos: [14, 1, 6], state: "minecraft:gravel"},
        {pos: [14, 1, 9], state: "minecraft:gravel"},
        {pos: [14, 1, 10], state: "minecraft:gravel"},
        {pos: [14, 1, 11], state: "minecraft:cobblestone"},
        {pos: [14, 1, 12], state: "minecraft:cobblestone"},
        {pos: [14, 1, 13], state: "minecraft:cobblestone"},
        {pos: [14, 1, 14], state: "minecraft:cobblestone"},
        {pos: [14, 1, 15], state: "minecraft:cobblestone"},
        {pos: [14, 1, 16], state: "minecraft:cobblestone"},
        {pos: [14, 1, 17], state: "minecraft:gravel"},
        {pos: [14, 1, 18], state: "minecraft:gravel"},
        {pos: [15, 1, 2], state: "minecraft:gravel"},
        {pos: [15, 1, 3], state: "minecraft:gravel"},
        {pos: [15, 1, 4], state: "minecraft:gravel"},
        {pos: [15, 1, 10], state: "minecraft:gravel"},
        {pos: [15, 1, 11], state: "minecraft:gravel"},
        {pos: [15, 1, 13], state: "minecraft:gravel"},
        {pos: [15, 1, 14], state: "minecraft:gravel"},
        {pos: [15, 1, 15], state: "minecraft:gravel"},
        {pos: [15, 1, 16], state: "minecraft:gravel"},
        {pos: [16, 1, 0], state: "minecraft:gravel"},
        {pos: [16, 1, 2], state: "minecraft:cobblestone"},
        {pos: [16, 1, 3], state: "minecraft:gravel"},
        {pos: [16, 1, 4], state: "minecraft:gravel"},
        {pos: [16, 1, 11], state: "minecraft:gravel"},
        {pos: [17, 1, 1], state: "minecraft:gravel"},
        {pos: [17, 1, 2], state: "minecraft:cobblestone"},
        {pos: [17, 1, 3], state: "minecraft:gravel"},
        {pos: [18, 1, 3], state: "minecraft:gravel"},
        {pos: [0, 2, 6], state: "minecraft:gravel"},
        {pos: [0, 2, 7], state: "minecraft:gravel"},
        {pos: [1, 2, 5], state: "minecraft:gravel"},
        {pos: [1, 2, 6], state: "minecraft:cobblestone"},
        {pos: [1, 2, 7], state: "minecraft:cobblestone"},
        {pos: [1, 2, 8], state: "minecraft:gravel"},
        {pos: [1, 2, 11], state: "minecraft:gravel"},
        {pos: [1, 2, 12], state: "minecraft:gravel"},
        {pos: [1, 2, 13], state: "minecraft:gravel"},
        {pos: [1, 2, 14], state: "minecraft:gravel"},
        {pos: [1, 2, 15], state: "minecraft:gravel"},
        {pos: [2, 2, 5], state: "minecraft:gravel"},
        {pos: [2, 2, 6], state: "minecraft:cobblestone"},
        {pos: [2, 2, 7], state: "minecraft:cobblestone"},
        {pos: [2, 2, 8], state: "minecraft:gravel"},
        {pos: [2, 2, 10], state: "minecraft:gravel"},
        {pos: [2, 2, 11], state: "minecraft:gravel"},
        {pos: [2, 2, 12], state: "minecraft:gravel"},
        {pos: [2, 2, 13], state: "minecraft:gravel"},
        {pos: [2, 2, 14], state: "minecraft:gravel"},
        {pos: [2, 2, 15], state: "minecraft:gravel"},
        {pos: [2, 2, 16], state: "minecraft:gravel"},
        {pos: [3, 2, 6], state: "minecraft:gravel"},
        {pos: [3, 2, 10], state: "minecraft:gravel"},
        {pos: [3, 2, 11], state: "minecraft:cobblestone"},
        {pos: [3, 2, 12], state: "minecraft:cobblestone"},
        {pos: [3, 2, 13], state: "minecraft:cobblestone"},
        {pos: [3, 2, 14], state: "minecraft:gravel"},
        {pos: [3, 2, 15], state: "minecraft:cobblestone"},
        {pos: [3, 2, 16], state: "minecraft:cobblestone"},
        {pos: [3, 2, 17], state: "minecraft:gravel"},
        {pos: [4, 2, 4], state: "minecraft:gravel"},
        {pos: [4, 2, 5], state: "minecraft:gravel"},
        {pos: [4, 2, 6], state: "minecraft:gravel"},
        {pos: [4, 2, 10], state: "minecraft:gravel"},
        {pos: [4, 2, 11], state: "minecraft:gravel"},
        {pos: [4, 2, 12], state: "minecraft:gravel"},
        {pos: [4, 2, 13], state: "minecraft:gravel"},
        {pos: [4, 2, 14], state: "minecraft:gravel"},
        {pos: [4, 2, 15], state: "minecraft:gravel"},
        {pos: [4, 2, 16], state: "minecraft:gravel"},
        {pos: [4, 2, 17], state: "minecraft:gravel"},
        {pos: [4, 2, 19], state: "minecraft:gravel"},
        {pos: [4, 2, 20], state: "minecraft:gravel"},
        {pos: [4, 2, 21], state: "minecraft:cobblestone"},
        {pos: [5, 2, 3], state: "minecraft:gravel"},
        {pos: [5, 2, 4], state: "minecraft:gravel"},
        {pos: [5, 2, 5], state: "minecraft:cobblestone"},
        {pos: [5, 2, 6], state: "minecraft:cobblestone"},
        {pos: [5, 2, 7], state: "minecraft:gravel"},
        {pos: [5, 2, 8], state: "minecraft:gravel"},
        {pos: [5, 2, 11], state: "minecraft:gravel"},
        {pos: [5, 2, 12], state: "minecraft:gravel"},
        {pos: [5, 2, 13], state: "minecraft:gravel"},
        {pos: [5, 2, 14], state: "minecraft:gravel"},
        {pos: [5, 2, 15], state: "minecraft:gravel"},
        {pos: [5, 2, 16], state: "minecraft:gravel"},
        {pos: [5, 2, 17], state: "minecraft:gravel"},
        {pos: [5, 2, 19], state: "minecraft:gravel"},
        {pos: [5, 2, 20], state: "minecraft:gravel"},
        {pos: [5, 2, 21], state: "minecraft:cobblestone"},
        {pos: [6, 2, 3], state: "minecraft:gravel"},
        {pos: [6, 2, 4], state: "minecraft:gravel"},
        {pos: [6, 2, 5], state: "minecraft:gravel"},
        {pos: [6, 2, 6], state: "minecraft:gravel"},
        {pos: [6, 2, 7], state: "minecraft:gravel"},
        {pos: [6, 2, 8], state: "minecraft:gravel"},
        {pos: [6, 2, 9], state: "minecraft:gravel"},
        {pos: [6, 2, 11], state: "minecraft:gravel"},
        {pos: [6, 2, 12], state: "minecraft:gravel"},
        {pos: [6, 2, 13], state: "minecraft:gravel"},
        {pos: [6, 2, 14], state: "minecraft:gravel"},
        {pos: [6, 2, 19], state: "minecraft:gravel"},
        {pos: [6, 2, 20], state: "minecraft:gravel"},
        {pos: [6, 2, 21], state: "minecraft:gravel"},
        {pos: [7, 2, 3], state: "minecraft:gravel"},
        {pos: [7, 2, 4], state: "minecraft:gravel"},
        {pos: [7, 2, 5], state: "minecraft:gravel"},
        {pos: [7, 2, 6], state: "minecraft:gravel"},
        {pos: [7, 2, 7], state: "minecraft:gravel"},
        {pos: [7, 2, 8], state: "minecraft:gravel"},
        {pos: [7, 2, 9], state: "minecraft:gravel"},
        {pos: [7, 2, 12], state: "minecraft:gravel"},
        {pos: [7, 2, 16], state: "minecraft:gravel"},
        {pos: [7, 2, 17], state: "minecraft:gravel"},
        {pos: [7, 2, 20], state: "minecraft:gravel"},
        {pos: [7, 2, 23], state: "minecraft:gravel"},
        {pos: [8, 2, 4], state: "minecraft:gravel"},
        {pos: [8, 2, 5], state: "minecraft:gravel"},
        {pos: [8, 2, 6], state: "minecraft:gravel"},
        {pos: [8, 2, 7], state: "minecraft:gravel"},
        {pos: [8, 2, 8], state: "minecraft:gravel"},
        {pos: [8, 2, 9], state: "minecraft:gravel"},
        {pos: [8, 2, 10], state: "minecraft:gravel"},
        {pos: [8, 2, 11], state: "minecraft:gravel"},
        {pos: [8, 2, 13], state: "minecraft:gravel"},
        {pos: [8, 2, 14], state: "minecraft:gravel"},
        {pos: [8, 2, 15], state: "minecraft:gravel"},
        {pos: [8, 2, 16], state: "minecraft:gravel"},
        {pos: [8, 2, 17], state: "minecraft:gravel"},
        {pos: [8, 2, 18], state: "minecraft:gravel"},
        {pos: [8, 2, 19], state: "minecraft:gravel"},
        {pos: [8, 2, 20], state: "minecraft:gravel"},
        {pos: [8, 2, 21], state: "minecraft:gravel"},
        {pos: [8, 2, 22], state: "minecraft:gravel"},
        {pos: [8, 2, 23], state: "minecraft:gravel"},
        {pos: [8, 2, 24], state: "minecraft:gravel"},
        {pos: [9, 2, 4], state: "minecraft:gravel"},
        {pos: [9, 2, 5], state: "minecraft:gravel"},
        {pos: [9, 2, 6], state: "minecraft:gravel"},
        {pos: [9, 2, 7], state: "minecraft:gravel"},
        {pos: [9, 2, 8], state: "minecraft:gravel"},
        {pos: [9, 2, 9], state: "minecraft:gravel"},
        {pos: [9, 2, 10], state: "minecraft:gravel"},
        {pos: [9, 2, 11], state: "minecraft:gravel"},
        {pos: [9, 2, 12], state: "minecraft:gravel"},
        {pos: [9, 2, 13], state: "minecraft:gravel"},
        {pos: [9, 2, 14], state: "minecraft:gravel"},
        {pos: [9, 2, 15], state: "minecraft:gravel"},
        {pos: [9, 2, 16], state: "minecraft:gravel"},
        {pos: [9, 2, 17], state: "minecraft:gravel"},
        {pos: [9, 2, 18], state: "minecraft:gravel"},
        {pos: [9, 2, 19], state: "minecraft:gravel"},
        {pos: [9, 2, 20], state: "minecraft:gravel"},
        {pos: [9, 2, 21], state: "minecraft:gravel"},
        {pos: [9, 2, 22], state: "minecraft:gravel"},
        {pos: [10, 2, 4], state: "minecraft:gravel"},
        {pos: [10, 2, 5], state: "minecraft:gravel"},
        {pos: [10, 2, 6], state: "minecraft:gravel"},
        {pos: [10, 2, 7], state: "minecraft:gravel"},
        {pos: [10, 2, 8], state: "minecraft:gravel"},
        {pos: [10, 2, 9], state: "minecraft:gravel"},
        {pos: [10, 2, 10], state: "minecraft:gravel"},
        {pos: [10, 2, 15], state: "minecraft:gravel"},
        {pos: [10, 2, 16], state: "minecraft:gravel"},
        {pos: [10, 2, 17], state: "minecraft:gravel"},
        {pos: [10, 2, 18], state: "minecraft:gravel"},
        {pos: [10, 2, 20], state: "minecraft:cobblestone"},
        {pos: [11, 2, 4], state: "minecraft:gravel"},
        {pos: [11, 2, 5], state: "minecraft:cobblestone"},
        {pos: [11, 2, 6], state: "minecraft:gravel"},
        {pos: [11, 2, 7], state: "minecraft:gravel"},
        {pos: [11, 2, 8], state: "minecraft:gravel"},
        {pos: [11, 2, 11], state: "minecraft:gravel"},
        {pos: [11, 2, 12], state: "minecraft:gravel"},
        {pos: [11, 2, 13], state: "minecraft:gravel"},
        {pos: [11, 2, 17], state: "minecraft:gravel"},
        {pos: [11, 2, 20], state: "minecraft:cobblestone"},
        {pos: [11, 2, 21], state: "minecraft:cobblestone"},
        {pos: [11, 2, 22], state: "minecraft:gravel"},
        {pos: [12, 2, 4], state: "minecraft:gravel"},
        {pos: [12, 2, 5], state: "minecraft:cobblestone"},
        {pos: [12, 2, 6], state: "minecraft:gravel"},
        {pos: [12, 2, 7], state: "minecraft:gravel"},
        {pos: [12, 2, 11], state: "minecraft:gravel"},
        {pos: [12, 2, 12], state: "minecraft:gravel"},
        {pos: [12, 2, 13], state: "minecraft:gravel"},
        {pos: [12, 2, 14], state: "minecraft:gravel"},
        {pos: [12, 2, 15], state: "minecraft:gravel"},
        {pos: [12, 2, 16], state: "minecraft:gravel"},
        {pos: [12, 2, 17], state: "minecraft:gravel"},
        {pos: [12, 2, 20], state: "minecraft:cobblestone"},
        {pos: [12, 2, 21], state: "minecraft:cobblestone"},
        {pos: [12, 2, 22], state: "minecraft:gravel"},
        {pos: [12, 2, 23], state: "minecraft:gravel"},
        {pos: [13, 2, 5], state: "minecraft:gravel"},
        {pos: [13, 2, 6], state: "minecraft:gravel"},
        {pos: [13, 2, 10], state: "minecraft:gravel"},
        {pos: [13, 2, 11], state: "minecraft:gravel"},
        {pos: [13, 2, 12], state: "minecraft:gravel"},
        {pos: [13, 2, 13], state: "minecraft:gravel"},
        {pos: [13, 2, 14], state: "minecraft:gravel"},
        {pos: [13, 2, 15], state: "minecraft:gravel"},
        {pos: [13, 2, 16], state: "minecraft:gravel"},
        {pos: [13, 2, 17], state: "minecraft:gravel"},
        {pos: [13, 2, 18], state: "minecraft:gravel"},
        {pos: [13, 2, 20], state: "minecraft:gravel"},
        {pos: [13, 2, 21], state: "minecraft:gravel"},
        {pos: [13, 2, 22], state: "minecraft:gravel"},
        {pos: [14, 2, 1], state: "minecraft:gravel"},
        {pos: [14, 2, 2], state: "minecraft:gravel"},
        {pos: [14, 2, 4], state: "minecraft:gravel"},
        {pos: [14, 2, 5], state: "minecraft:gravel"},
        {pos: [14, 2, 6], state: "minecraft:gravel"},
        {pos: [14, 2, 9], state: "minecraft:gravel"},
        {pos: [14, 2, 10], state: "minecraft:gravel"},
        {pos: [14, 2, 11], state: "minecraft:gravel"},
        {pos: [14, 2, 12], state: "minecraft:cobblestone"},
        {pos: [14, 2, 13], state: "minecraft:gravel"},
        {pos: [14, 2, 14], state: "minecraft:cobblestone"},
        {pos: [14, 2, 15], state: "minecraft:cobblestone"},
        {pos: [14, 2, 16], state: "minecraft:gravel"},
        {pos: [14, 2, 17], state: "minecraft:gravel"},
        {pos: [14, 2, 18], state: "minecraft:gravel"},
        {pos: [15, 2, 2], state: "minecraft:gravel"},
        {pos: [15, 2, 3], state: "minecraft:cobblestone"},
        {pos: [15, 2, 4], state: "minecraft:cobblestone"},
        {pos: [15, 2, 10], state: "minecraft:gravel"},
        {pos: [15, 2, 11], state: "minecraft:gravel"},
        {pos: [16, 2, 2], state: "minecraft:cobblestone"},
        {pos: [16, 2, 3], state: "minecraft:cobblestone"},
        {pos: [16, 2, 11], state: "minecraft:gravel"},
        {pos: [17, 2, 1], state: "minecraft:gravel"},
        {pos: [17, 2, 2], state: "minecraft:gravel"},
        {pos: [17, 2, 3], state: "minecraft:gravel"},
        {pos: [0, 3, 6], state: "minecraft:gravel"},
        {pos: [0, 3, 7], state: "minecraft:gravel"},
        {pos: [1, 3, 5], state: "minecraft:gravel"},
        {pos: [1, 3, 6], state: "minecraft:cobblestone"},
        {pos: [1, 3, 7], state: "minecraft:cobblestone"},
        {pos: [1, 3, 8], state: "minecraft:gravel"},
        {pos: [1, 3, 11], state: "minecraft:gravel"},
        {pos: [1, 3, 12], state: "minecraft:gravel"},
        {pos: [1, 3, 13], state: "minecraft:gravel"},
        {pos: [1, 3, 14], state: "minecraft:gravel"},
        {pos: [1, 3, 15], state: "minecraft:gravel"},
        {pos: [2, 3, 5], state: "minecraft:gravel"},
        {pos: [2, 3, 6], state: "minecraft:cobblestone"},
        {pos: [2, 3, 7], state: "minecraft:cobblestone"},
        {pos: [2, 3, 8], state: "minecraft:gravel"},
        {pos: [2, 3, 10], state: "minecraft:gravel"},
        {pos: [2, 3, 11], state: "minecraft:gravel"},
        {pos: [2, 3, 12], state: "minecraft:gravel"},
        {pos: [2, 3, 13], state: "minecraft:gravel"},
        {pos: [2, 3, 14], state: "minecraft:gravel"},
        {pos: [2, 3, 15], state: "minecraft:gravel"},
        {pos: [2, 3, 16], state: "minecraft:gravel"},
        {pos: [3, 3, 6], state: "minecraft:gravel"},
        {pos: [3, 3, 10], state: "minecraft:gravel"},
        {pos: [3, 3, 11], state: "minecraft:cobblestone"},
        {pos: [3, 3, 12], state: "minecraft:cobblestone"},
        {pos: [3, 3, 13], state: "minecraft:gravel"},
        {pos: [3, 3, 14], state: "minecraft:gravel"},
        {pos: [3, 3, 15], state: "minecraft:gravel"},
        {pos: [3, 3, 16], state: "minecraft:gravel"},
        {pos: [3, 3, 17], state: "minecraft:gravel"},
        {pos: [4, 3, 4], state: "minecraft:gravel"},
        {pos: [4, 3, 5], state: "minecraft:gravel"},
        {pos: [4, 3, 6], state: "minecraft:gravel"},
        {pos: [4, 3, 10], state: "minecraft:gravel"},
        {pos: [4, 3, 11], state: "minecraft:gravel"},
        {pos: [4, 3, 12], state: "minecraft:gravel"},
        {pos: [4, 3, 13], state: "minecraft:gravel"},
        {pos: [4, 3, 14], state: "minecraft:gravel"},
        {pos: [4, 3, 15], state: "minecraft:gravel"},
        {pos: [4, 3, 16], state: "minecraft:gravel"},
        {pos: [4, 3, 17], state: "minecraft:gravel"},
        {pos: [4, 3, 19], state: "minecraft:gravel"},
        {pos: [4, 3, 20], state: "minecraft:cobblestone"},
        {pos: [4, 3, 21], state: "minecraft:cobblestone"},
        {pos: [5, 3, 3], state: "minecraft:gravel"},
        {pos: [5, 3, 4], state: "minecraft:gravel"},
        {pos: [5, 3, 5], state: "minecraft:gravel"},
        {pos: [5, 3, 6], state: "minecraft:gravel"},
        {pos: [5, 3, 7], state: "minecraft:gravel"},
        {pos: [5, 3, 8], state: "minecraft:gravel"},
        {pos: [5, 3, 11], state: "minecraft:gravel"},
        {pos: [5, 3, 12], state: "minecraft:gravel"},
        {pos: [5, 3, 13], state: "minecraft:gravel"},
        {pos: [5, 3, 14], state: "minecraft:gravel"},
        {pos: [5, 3, 15], state: "minecraft:gravel"},
        {pos: [5, 3, 16], state: "minecraft:gravel"},
        {pos: [5, 3, 17], state: "minecraft:gravel"},
        {pos: [5, 3, 19], state: "minecraft:gravel"},
        {pos: [5, 3, 20], state: "minecraft:gravel"},
        {pos: [5, 3, 21], state: "minecraft:cobblestone"},
        {pos: [6, 3, 3], state: "minecraft:gravel"},
        {pos: [6, 3, 4], state: "minecraft:gravel"},
        {pos: [6, 3, 5], state: "minecraft:gravel"},
        {pos: [6, 3, 6], state: "minecraft:gravel"},
        {pos: [6, 3, 7], state: "minecraft:gravel"},
        {pos: [6, 3, 8], state: "minecraft:gravel"},
        {pos: [6, 3, 9], state: "minecraft:gravel"},
        {pos: [6, 3, 11], state: "minecraft:gravel"},
        {pos: [6, 3, 12], state: "minecraft:gravel"},
        {pos: [6, 3, 13], state: "minecraft:gravel"},
        {pos: [6, 3, 14], state: "minecraft:gravel"},
        {pos: [6, 3, 19], state: "minecraft:gravel"},
        {pos: [6, 3, 20], state: "minecraft:gravel"},
        {pos: [6, 3, 21], state: "minecraft:gravel"},
        {pos: [7, 3, 3], state: "minecraft:gravel"},
        {pos: [7, 3, 4], state: "minecraft:gravel"},
        {pos: [7, 3, 5], state: "minecraft:gravel"},
        {pos: [7, 3, 6], state: "minecraft:gravel"},
        {pos: [7, 3, 7], state: "minecraft:gravel"},
        {pos: [7, 3, 8], state: "minecraft:gravel"},
        {pos: [7, 3, 9], state: "minecraft:gravel"},
        {pos: [7, 3, 12], state: "minecraft:gravel"},
        {pos: [7, 3, 16], state: "minecraft:gravel"},
        {pos: [7, 3, 17], state: "minecraft:gravel"},
        {pos: [7, 3, 20], state: "minecraft:gravel"},
        {pos: [7, 3, 23], state: "minecraft:gravel"},
        {pos: [8, 3, 4], state: "minecraft:gravel"},
        {pos: [8, 3, 5], state: "minecraft:gravel"},
        {pos: [8, 3, 6], state: "minecraft:gravel"},
        {pos: [8, 3, 7], state: "minecraft:gravel"},
        {pos: [8, 3, 8], state: "minecraft:gravel"},
        {pos: [8, 3, 9], state: "minecraft:gravel"},
        {pos: [8, 3, 10], state: "minecraft:gravel"},
        {pos: [8, 3, 11], state: "minecraft:gravel"},
        {pos: [8, 3, 13], state: "minecraft:gravel"},
        {pos: [8, 3, 14], state: "minecraft:gravel"},
        {pos: [8, 3, 15], state: "minecraft:gravel"},
        {pos: [8, 3, 16], state: "minecraft:gravel"},
        {pos: [8, 3, 17], state: "minecraft:gravel"},
        {pos: [8, 3, 18], state: "minecraft:gravel"},
        {pos: [8, 3, 19], state: "minecraft:gravel"},
        {pos: [8, 3, 20], state: "minecraft:gravel"},
        {pos: [8, 3, 21], state: "minecraft:gravel"},
        {pos: [8, 3, 22], state: "minecraft:gravel"},
        {pos: [8, 3, 23], state: "minecraft:gravel"},
        {pos: [8, 3, 24], state: "minecraft:gravel"},
        {pos: [9, 3, 4], state: "minecraft:gravel"},
        {pos: [9, 3, 5], state: "minecraft:gravel"},
        {pos: [9, 3, 6], state: "minecraft:gravel"},
        {pos: [9, 3, 7], state: "minecraft:gravel"},
        {pos: [9, 3, 8], state: "minecraft:gravel"},
        {pos: [9, 3, 9], state: "minecraft:gravel"},
        {pos: [9, 3, 10], state: "minecraft:gravel"},
        {pos: [9, 3, 11], state: "minecraft:gravel"},
        {pos: [9, 3, 12], state: "minecraft:gravel"},
        {pos: [9, 3, 13], state: "minecraft:gravel"},
        {pos: [9, 3, 14], state: "minecraft:gravel"},
        {pos: [9, 3, 15], state: "minecraft:gravel"},
        {pos: [9, 3, 16], state: "minecraft:gravel"},
        {pos: [9, 3, 17], state: "minecraft:gravel"},
        {pos: [9, 3, 18], state: "minecraft:gravel"},
        {pos: [9, 3, 19], state: "minecraft:gravel"},
        {pos: [9, 3, 20], state: "minecraft:gravel"},
        {pos: [9, 3, 21], state: "minecraft:gravel"},
        {pos: [9, 3, 22], state: "minecraft:gravel"},
        {pos: [10, 3, 4], state: "minecraft:gravel"},
        {pos: [10, 3, 5], state: "minecraft:gravel"},
        {pos: [10, 3, 6], state: "minecraft:gravel"},
        {pos: [10, 3, 7], state: "minecraft:gravel"},
        {pos: [10, 3, 8], state: "minecraft:gravel"},
        {pos: [10, 3, 9], state: "minecraft:gravel"},
        {pos: [10, 3, 10], state: "minecraft:gravel"},
        {pos: [10, 3, 15], state: "minecraft:gravel"},
        {pos: [10, 3, 16], state: "minecraft:gravel"},
        {pos: [10, 3, 17], state: "minecraft:gravel"},
        {pos: [10, 3, 18], state: "minecraft:gravel"},
        {pos: [10, 3, 19], state: "minecraft:cobblestone"},
        {pos: [10, 3, 20], state: "minecraft:cobblestone"},
        {pos: [10, 3, 21], state: "minecraft:cobblestone"},
        {pos: [11, 3, 4], state: "minecraft:gravel"},
        {pos: [11, 3, 5], state: "minecraft:gravel"},
        {pos: [11, 3, 6], state: "minecraft:gravel"},
        {pos: [11, 3, 7], state: "minecraft:gravel"},
        {pos: [11, 3, 8], state: "minecraft:gravel"},
        {pos: [11, 3, 11], state: "minecraft:gravel"},
        {pos: [11, 3, 12], state: "minecraft:gravel"},
        {pos: [11, 3, 13], state: "minecraft:gravel"},
        {pos: [11, 3, 17], state: "minecraft:gravel"},
        {pos: [11, 3, 19], state: "minecraft:cobblestone"},
        {pos: [11, 3, 20], state: "minecraft:cobblestone"},
        {pos: [11, 3, 21], state: "minecraft:cobblestone"},
        {pos: [11, 3, 22], state: "minecraft:gravel"},
        {pos: [12, 3, 4], state: "minecraft:gravel"},
        {pos: [12, 3, 5], state: "minecraft:gravel"},
        {pos: [12, 3, 6], state: "minecraft:gravel"},
        {pos: [12, 3, 7], state: "minecraft:gravel"},
        {pos: [12, 3, 11], state: "minecraft:gravel"},
        {pos: [12, 3, 12], state: "minecraft:gravel"},
        {pos: [12, 3, 13], state: "minecraft:gravel"},
        {pos: [12, 3, 14], state: "minecraft:gravel"},
        {pos: [12, 3, 15], state: "minecraft:gravel"},
        {pos: [12, 3, 16], state: "minecraft:gravel"},
        {pos: [12, 3, 17], state: "minecraft:gravel"},
        {pos: [12, 3, 20], state: "minecraft:cobblestone"},
        {pos: [12, 3, 21], state: "minecraft:gravel"},
        {pos: [12, 3, 22], state: "minecraft:gravel"},
        {pos: [12, 3, 23], state: "minecraft:gravel"},
        {pos: [13, 3, 5], state: "minecraft:gravel"},
        {pos: [13, 3, 6], state: "minecraft:gravel"},
        {pos: [13, 3, 10], state: "minecraft:gravel"},
        {pos: [13, 3, 11], state: "minecraft:gravel"},
        {pos: [13, 3, 12], state: "minecraft:gravel"},
        {pos: [13, 3, 13], state: "minecraft:gravel"},
        {pos: [13, 3, 14], state: "minecraft:gravel"},
        {pos: [13, 3, 15], state: "minecraft:gravel"},
        {pos: [13, 3, 16], state: "minecraft:gravel"},
        {pos: [13, 3, 17], state: "minecraft:gravel"},
        {pos: [13, 3, 18], state: "minecraft:gravel"},
        {pos: [13, 3, 20], state: "minecraft:gravel"},
        {pos: [13, 3, 21], state: "minecraft:gravel"},
        {pos: [13, 3, 22], state: "minecraft:gravel"},
        {pos: [14, 3, 2], state: "minecraft:gravel"},
        {pos: [14, 3, 3], state: "minecraft:cobblestone"},
        {pos: [14, 3, 4], state: "minecraft:cobblestone"},
        {pos: [14, 3, 5], state: "minecraft:gravel"},
        {pos: [14, 3, 6], state: "minecraft:gravel"},
        {pos: [14, 3, 9], state: "minecraft:gravel"},
        {pos: [14, 3, 10], state: "minecraft:gravel"},
        {pos: [14, 3, 11], state: "minecraft:gravel"},
        {pos: [14, 3, 12], state: "minecraft:cobblestone"},
        {pos: [14, 3, 13], state: "minecraft:gravel"},
        {pos: [14, 3, 14], state: "minecraft:gravel"},
        {pos: [14, 3, 15], state: "minecraft:cobblestone"},
        {pos: [14, 3, 16], state: "minecraft:gravel"},
        {pos: [14, 3, 17], state: "minecraft:gravel"},
        {pos: [14, 3, 18], state: "minecraft:gravel"},
        {pos: [15, 3, 2], state: "minecraft:cobblestone"},
        {pos: [15, 3, 3], state: "minecraft:cobblestone"},
        {pos: [15, 3, 4], state: "minecraft:cobblestone"},
        {pos: [15, 3, 10], state: "minecraft:gravel"},
        {pos: [15, 3, 11], state: "minecraft:gravel"},
        {pos: [16, 3, 2], state: "minecraft:cobblestone"},
        {pos: [16, 3, 3], state: "minecraft:cobblestone"},
        {pos: [16, 3, 4], state: "minecraft:cobblestone"},
        {pos: [17, 3, 2], state: "minecraft:gravel"},
        {pos: [17, 3, 3], state: "minecraft:gravel"},
        {pos: [0, 4, 6], state: "minecraft:gravel"},
        {pos: [0, 4, 7], state: "minecraft:gravel"},
        {pos: [1, 4, 5], state: "minecraft:gravel"},
        {pos: [1, 4, 6], state: "minecraft:cobblestone"},
        {pos: [1, 4, 7], state: "minecraft:cobblestone"},
        {pos: [1, 4, 8], state: "minecraft:gravel"},
        {pos: [2, 4, 5], state: "minecraft:gravel"},
        {pos: [2, 4, 6], state: "minecraft:cobblestone"},
        {pos: [2, 4, 7], state: "minecraft:cobblestone"},
        {pos: [2, 4, 8], state: "minecraft:gravel"},
        {pos: [2, 4, 12], state: "minecraft:gravel"},
        {pos: [2, 4, 13], state: "minecraft:gravel"},
        {pos: [2, 4, 14], state: "minecraft:gravel"},
        {pos: [3, 4, 6], state: "minecraft:cobblestone"},
        {pos: [3, 4, 12], state: "minecraft:gravel"},
        {pos: [3, 4, 13], state: "minecraft:gravel"},
        {pos: [3, 4, 14], state: "minecraft:gravel"},
        {pos: [3, 4, 15], state: "minecraft:gravel"},
        {pos: [3, 4, 16], state: "minecraft:gravel"},
        {pos: [3, 4, 17], state: "minecraft:gravel"},
        {pos: [4, 4, 4], state: "minecraft:gravel"},
        {pos: [4, 4, 5], state: "minecraft:gravel"},
        {pos: [4, 4, 6], state: "minecraft:gravel"},
        {pos: [4, 4, 13], state: "minecraft:gravel"},
        {pos: [4, 4, 14], state: "minecraft:gravel"},
        {pos: [4, 4, 15], state: "minecraft:gravel"},
        {pos: [4, 4, 16], state: "minecraft:gravel"},
        {pos: [4, 4, 19], state: "minecraft:gravel"},
        {pos: [4, 4, 20], state: "minecraft:gravel"},
        {pos: [4, 4, 21], state: "minecraft:cobblestone"},
        {pos: [5, 4, 4], state: "minecraft:gravel"},
        {pos: [5, 4, 5], state: "minecraft:gravel"},
        {pos: [5, 4, 6], state: "minecraft:gravel"},
        {pos: [5, 4, 7], state: "minecraft:gravel"},
        {pos: [5, 4, 19], state: "minecraft:gravel"},
        {pos: [5, 4, 20], state: "minecraft:cobblestone"},
        {pos: [5, 4, 21], state: "minecraft:cobblestone"},
        {pos: [6, 4, 4], state: "minecraft:gravel"},
        {pos: [6, 4, 5], state: "minecraft:gravel"},
        {pos: [6, 4, 6], state: "minecraft:gravel"},
        {pos: [6, 4, 7], state: "minecraft:gravel"},
        {pos: [6, 4, 20], state: "minecraft:gravel"},
        {pos: [7, 4, 5], state: "minecraft:gravel"},
        {pos: [7, 4, 6], state: "minecraft:gravel"},
        {pos: [7, 4, 20], state: "minecraft:gravel"},
        {pos: [8, 4, 5], state: "minecraft:gravel"},
        {pos: [8, 4, 8], state: "minecraft:gravel"},
        {pos: [8, 4, 9], state: "minecraft:gravel"},
        {pos: [8, 4, 10], state: "minecraft:gravel"},
        {pos: [8, 4, 17], state: "minecraft:gravel"},
        {pos: [8, 4, 18], state: "minecraft:gravel"},
        {pos: [8, 4, 19], state: "minecraft:gravel"},
        {pos: [8, 4, 20], state: "minecraft:gravel"},
        {pos: [8, 4, 21], state: "minecraft:gravel"},
        {pos: [8, 4, 22], state: "minecraft:gravel"},
        {pos: [8, 4, 23], state: "minecraft:gravel"},
        {pos: [9, 4, 5], state: "minecraft:gravel"},
        {pos: [9, 4, 8], state: "minecraft:gravel"},
        {pos: [9, 4, 9], state: "minecraft:gravel"},
        {pos: [9, 4, 10], state: "minecraft:gravel"},
        {pos: [9, 4, 15], state: "minecraft:gravel"},
        {pos: [9, 4, 16], state: "minecraft:gravel"},
        {pos: [9, 4, 17], state: "minecraft:gravel"},
        {pos: [9, 4, 18], state: "minecraft:gravel"},
        {pos: [9, 4, 19], state: "minecraft:cobblestone"},
        {pos: [9, 4, 20], state: "minecraft:cobblestone"},
        {pos: [9, 4, 21], state: "minecraft:gravel"},
        {pos: [9, 4, 22], state: "minecraft:gravel"},
        {pos: [10, 4, 5], state: "minecraft:gravel"},
        {pos: [10, 4, 6], state: "minecraft:gravel"},
        {pos: [10, 4, 7], state: "minecraft:gravel"},
        {pos: [10, 4, 16], state: "minecraft:gravel"},
        {pos: [10, 4, 17], state: "minecraft:gravel"},
        {pos: [10, 4, 18], state: "minecraft:gravel"},
        {pos: [10, 4, 19], state: "minecraft:cobblestone"},
        {pos: [10, 4, 20], state: "minecraft:cobblestone"},
        {pos: [10, 4, 21], state: "minecraft:cobblestone"},
        {pos: [11, 4, 5], state: "minecraft:gravel"},
        {pos: [11, 4, 6], state: "minecraft:gravel"},
        {pos: [11, 4, 7], state: "minecraft:gravel"},
        {pos: [11, 4, 12], state: "minecraft:gravel"},
        {pos: [11, 4, 13], state: "minecraft:gravel"},
        {pos: [11, 4, 19], state: "minecraft:cobblestone"},
        {pos: [11, 4, 20], state: "minecraft:cobblestone"},
        {pos: [11, 4, 21], state: "minecraft:gravel"},
        {pos: [12, 4, 5], state: "minecraft:gravel"},
        {pos: [12, 4, 6], state: "minecraft:gravel"},
        {pos: [12, 4, 12], state: "minecraft:gravel"},
        {pos: [12, 4, 13], state: "minecraft:gravel"},
        {pos: [12, 4, 14], state: "minecraft:gravel"},
        {pos: [12, 4, 15], state: "minecraft:gravel"},
        {pos: [12, 4, 20], state: "minecraft:gravel"},
        {pos: [13, 4, 5], state: "minecraft:gravel"},
        {pos: [13, 4, 6], state: "minecraft:gravel"},
        {pos: [13, 4, 11], state: "minecraft:gravel"},
        {pos: [13, 4, 12], state: "minecraft:gravel"},
        {pos: [13, 4, 13], state: "minecraft:gravel"},
        {pos: [13, 4, 14], state: "minecraft:gravel"},
        {pos: [13, 4, 15], state: "minecraft:gravel"},
        {pos: [13, 4, 16], state: "minecraft:gravel"},
        {pos: [13, 4, 17], state: "minecraft:gravel"},
        {pos: [14, 4, 2], state: "minecraft:gravel"},
        {pos: [14, 4, 3], state: "minecraft:cobblestone"},
        {pos: [14, 4, 4], state: "minecraft:cobblestone"},
        {pos: [14, 4, 5], state: "minecraft:cobblestone"},
        {pos: [14, 4, 10], state: "minecraft:gravel"},
        {pos: [14, 4, 11], state: "minecraft:gravel"},
        {pos: [14, 4, 12], state: "minecraft:gravel"},
        {pos: [14, 4, 13], state: "minecraft:gravel"},
        {pos: [14, 4, 14], state: "minecraft:gravel"},
        {pos: [14, 4, 15], state: "minecraft:gravel"},
        {pos: [14, 4, 16], state: "minecraft:gravel"},
        {pos: [15, 4, 2], state: "minecraft:cobblestone"},
        {pos: [15, 4, 3], state: "minecraft:cobblestone"},
        {pos: [15, 4, 4], state: "minecraft:gravel"},
        {pos: [15, 4, 5], state: "minecraft:cobblestone"},
        {pos: [16, 4, 2], state: "minecraft:gravel"},
        {pos: [16, 4, 3], state: "minecraft:gravel"},
        {pos: [16, 4, 4], state: "minecraft:gravel"},
        {pos: [0, 5, 6], state: "minecraft:gravel"},
        {pos: [0, 5, 7], state: "minecraft:gravel"},
        {pos: [1, 5, 5], state: "minecraft:gravel"},
        {pos: [1, 5, 6], state: "minecraft:cobblestone"},
        {pos: [1, 5, 7], state: "minecraft:cobblestone"},
        {pos: [1, 5, 8], state: "minecraft:gravel"},
        {pos: [2, 5, 5], state: "minecraft:gravel"},
        {pos: [2, 5, 6], state: "minecraft:cobblestone"},
        {pos: [2, 5, 7], state: "minecraft:cobblestone"},
        {pos: [2, 5, 8], state: "minecraft:gravel"},
        {pos: [3, 5, 6], state: "minecraft:cobblestone"},
        {pos: [3, 5, 7], state: "minecraft:cobblestone"},
        {pos: [3, 5, 15], state: "minecraft:gravel"},
        {pos: [3, 5, 16], state: "minecraft:gravel"},
        {pos: [4, 5, 5], state: "minecraft:gravel"},
        {pos: [4, 5, 6], state: "minecraft:gravel"},
        {pos: [5, 5, 5], state: "minecraft:gravel"},
        {pos: [5, 5, 6], state: "minecraft:gravel"},
        {pos: [5, 5, 20], state: "minecraft:cobblestone"},
        {pos: [5, 5, 21], state: "minecraft:cobblestone"},
        {pos: [6, 5, 6], state: "minecraft:gravel"},
        {pos: [6, 5, 20], state: "minecraft:cobblestone"},
        {pos: [8, 5, 19], state: "minecraft:cobblestone"},
        {pos: [8, 5, 20], state: "minecraft:cobblestone"},
        {pos: [9, 5, 19], state: "minecraft:cobblestone"},
        {pos: [9, 5, 20], state: "minecraft:cobblestone"},
        {pos: [10, 5, 6], state: "minecraft:gravel"},
        {pos: [10, 5, 19], state: "minecraft:cobblestone"},
        {pos: [10, 5, 20], state: "minecraft:gravel"},
        {pos: [11, 5, 5], state: "minecraft:gravel"},
        {pos: [11, 5, 6], state: "minecraft:gravel"},
        {pos: [11, 5, 19], state: "minecraft:gravel"},
        {pos: [11, 5, 20], state: "minecraft:gravel"},
        {pos: [12, 5, 5], state: "minecraft:gravel"},
        {pos: [12, 5, 6], state: "minecraft:gravel"},
        {pos: [12, 5, 12], state: "minecraft:gravel"},
        {pos: [12, 5, 13], state: "minecraft:gravel"},
        {pos: [12, 5, 14], state: "minecraft:gravel"},
        {pos: [13, 5, 3], state: "minecraft:cobblestone"},
        {pos: [13, 5, 4], state: "minecraft:cobblestone"},
        {pos: [13, 5, 5], state: "minecraft:cobblestone"},
        {pos: [13, 5, 6], state: "minecraft:cobblestone"},
        {pos: [13, 5, 12], state: "minecraft:gravel"},
        {pos: [13, 5, 13], state: "minecraft:gravel"},
        {pos: [13, 5, 14], state: "minecraft:gravel"},
        {pos: [14, 5, 3], state: "minecraft:cobblestone"},
        {pos: [14, 5, 4], state: "minecraft:cobblestone"},
        {pos: [14, 5, 5], state: "minecraft:gravel"},
        {pos: [14, 5, 12], state: "minecraft:gravel"},
        {pos: [15, 5, 2], state: "minecraft:gravel"},
        {pos: [15, 5, 3], state: "minecraft:cobblestone"},
        {pos: [15, 5, 4], state: "minecraft:gravel"},
        {pos: [15, 5, 5], state: "minecraft:gravel"},
        {pos: [16, 5, 2], state: "minecraft:gravel"},
        {pos: [16, 5, 3], state: "minecraft:gravel"},
        {pos: [1, 6, 6], state: "minecraft:gravel"},
        {pos: [1, 6, 7], state: "minecraft:gravel"},
        {pos: [2, 6, 6], state: "minecraft:gravel"},
        {pos: [2, 6, 7], state: "minecraft:cobblestone"},
        {pos: [3, 6, 6], state: "minecraft:cobblestone"},
        {pos: [3, 6, 7], state: "minecraft:cobblestone"},
        {pos: [4, 6, 6], state: "minecraft:cobblestone"},
        {pos: [4, 6, 7], state: "minecraft:cobblestone"},
        {pos: [5, 6, 7], state: "minecraft:cobblestone"},
        {pos: [5, 6, 20], state: "minecraft:gravel"},
        {pos: [8, 6, 19], state: "minecraft:gravel"},
        {pos: [9, 6, 19], state: "minecraft:gravel"},
        {pos: [9, 6, 20], state: "minecraft:gravel"},
        {pos: [11, 6, 5], state: "minecraft:cobblestone"},
        {pos: [11, 6, 6], state: "minecraft:cobblestone"},
        {pos: [12, 6, 5], state: "minecraft:cobblestone"},
        {pos: [12, 6, 6], state: "minecraft:cobblestone"},
        {pos: [13, 6, 3], state: "minecraft:gravel"},
        {pos: [13, 6, 4], state: "minecraft:cobblestone"},
        {pos: [13, 6, 5], state: "minecraft:cobblestone"},
        {pos: [13, 6, 6], state: "minecraft:cobblestone"},
        {pos: [14, 6, 3], state: "minecraft:cobblestone"},
        {pos: [14, 6, 4], state: "minecraft:gravel"},
        {pos: [14, 6, 5], state: "minecraft:gravel"},
        {pos: [15, 6, 3], state: "minecraft:gravel"},
        {pos: [15, 6, 4], state: "minecraft:gravel"},
        {pos: [3, 7, 6], state: "minecraft:gravel"},
        {pos: [3, 7, 7], state: "minecraft:cobblestone"},
        {pos: [4, 7, 6], state: "minecraft:cobblestone"},
        {pos: [4, 7, 7], state: "minecraft:gravel"},
        {pos: [5, 7, 7], state: "minecraft:gravel"},
        {pos: [11, 7, 6], state: "minecraft:cobblestone"},
        {pos: [12, 7, 5], state: "minecraft:cobblestone"},
        {pos: [12, 7, 6], state: "minecraft:cobblestone"},
        {pos: [13, 7, 4], state: "minecraft:cobblestone"},
        {pos: [13, 7, 5], state: "minecraft:gravel"},
        {pos: [14, 7, 3], state: "minecraft:gravel"},
        {pos: [4, 8, 6], state: "minecraft:gravel"},
        {pos: [12, 8, 6], state: "minecraft:gravel"},
        {pos: [13, 8, 4], state: "minecraft:gravel"}
    ],
    entities: [],
    palette: [
        "minecraft:cobblestone",
        "minecraft:gravel",
        "minecraft:clay",
        "minecraft:water_cauldron{level:3}",
        "minecraft:cobblestone_stairs{facing:west,half:top,shape:straight,waterlogged:false}",
        "minecraft:cobblestone_stairs{facing:east,half:top,shape:straight,waterlogged:false}"
    ],
    trailiertales_DataVersion: 2
}
