{
    DataVersion: 3953,
    size: [19, 9, 11],
    data: [
        {pos: [0, 0, 3], state: "minecraft:cobblestone"},
        {pos: [0, 0, 4], state: "minecraft:cobblestone"},
        {pos: [0, 0, 5], state: "minecraft:cobblestone"},
        {pos: [0, 0, 6], state: "minecraft:cobblestone"},
        {pos: [0, 0, 7], state: "minecraft:cobblestone"},
        {pos: [0, 0, 8], state: "minecraft:cobblestone"},
        {pos: [1, 0, 1], state: "minecraft:cobblestone"},
        {pos: [1, 0, 2], state: "minecraft:cobblestone"},
        {pos: [1, 0, 3], state: "minecraft:cobblestone"},
        {pos: [1, 0, 4], state: "minecraft:cobblestone"},
        {pos: [1, 0, 5], state: "minecraft:cobblestone"},
        {pos: [1, 0, 6], state: "minecraft:cobblestone"},
        {pos: [1, 0, 7], state: "minecraft:cobblestone"},
        {pos: [1, 0, 8], state: "minecraft:cobblestone"},
        {pos: [1, 0, 9], state: "minecraft:cobblestone"},
        {pos: [2, 0, 0], state: "minecraft:cobblestone"},
        {pos: [2, 0, 1], state: "minecraft:cobblestone"},
        {pos: [2, 0, 2], state: "minecraft:cobblestone"},
        {pos: [2, 0, 3], state: "minecraft:cobblestone"},
        {pos: [2, 0, 4], state: "minecraft:cobblestone"},
        {pos: [2, 0, 5], state: "minecraft:cobblestone"},
        {pos: [2, 0, 6], state: "minecraft:cobblestone"},
        {pos: [2, 0, 7], state: "minecraft:cobblestone"},
        {pos: [2, 0, 8], state: "minecraft:cobblestone"},
        {pos: [2, 0, 9], state: "minecraft:cobblestone"},
        {pos: [3, 0, 0], state: "minecraft:cobblestone"},
        {pos: [3, 0, 1], state: "minecraft:cobblestone"},
        {pos: [3, 0, 2], state: "minecraft:cobblestone"},
        {pos: [3, 0, 3], state: "minecraft:cobblestone"},
        {pos: [3, 0, 4], state: "minecraft:cobblestone"},
        {pos: [3, 0, 5], state: "minecraft:cobblestone"},
        {pos: [3, 0, 6], state: "minecraft:cobblestone"},
        {pos: [3, 0, 7], state: "minecraft:cobblestone"},
        {pos: [3, 0, 8], state: "minecraft:cobblestone"},
        {pos: [3, 0, 9], state: "minecraft:cobblestone"},
        {pos: [3, 0, 10], state: "minecraft:cobblestone"},
        {pos: [4, 0, 0], state: "minecraft:cobblestone"},
        {pos: [4, 0, 1], state: "minecraft:cobblestone"},
        {pos: [4, 0, 2], state: "minecraft:cobblestone"},
        {pos: [4, 0, 3], state: "minecraft:cobblestone"},
        {pos: [4, 0, 4], state: "minecraft:cobblestone"},
        {pos: [4, 0, 5], state: "minecraft:cobblestone"},
        {pos: [4, 0, 6], state: "minecraft:cobblestone"},
        {pos: [4, 0, 7], state: "minecraft:cobblestone"},
        {pos: [4, 0, 8], state: "minecraft:cobblestone"},
        {pos: [4, 0, 9], state: "minecraft:cobblestone"},
        {pos: [4, 0, 10], state: "minecraft:cobblestone"},
        {pos: [5, 0, 0], state: "minecraft:cobblestone"},
        {pos: [5, 0, 1], state: "minecraft:cobblestone"},
        {pos: [5, 0, 2], state: "minecraft:cobblestone"},
        {pos: [5, 0, 3], state: "minecraft:cobblestone"},
        {pos: [5, 0, 4], state: "minecraft:cobblestone"},
        {pos: [5, 0, 5], state: "minecraft:cobblestone_stairs{facing:west,half:top,shape:straight,waterlogged:false}"},
        {pos: [5, 0, 6], state: "minecraft:cobblestone_stairs{facing:west,half:top,shape:straight,waterlogged:false}"},
        {pos: [5, 0, 7], state: "minecraft:cobblestone"},
        {pos: [5, 0, 8], state: "minecraft:cobblestone"},
        {pos: [5, 0, 9], state: "minecraft:cobblestone"},
        {pos: [5, 0, 10], state: "minecraft:cobblestone"},
        {pos: [6, 0, 1], state: "minecraft:cobblestone"},
        {pos: [6, 0, 2], state: "minecraft:cobblestone"},
        {pos: [6, 0, 3], state: "minecraft:cobblestone"},
        {pos: [6, 0, 7], state: "minecraft:cobblestone"},
        {pos: [6, 0, 8], state: "minecraft:cobblestone"},
        {pos: [6, 0, 9], state: "minecraft:cobblestone"},
        {pos: [7, 0, 1], state: "minecraft:cobblestone"},
        {pos: [7, 0, 2], state: "minecraft:cobblestone"},
        {pos: [7, 0, 3], state: "minecraft:cobblestone"},
        {pos: [7, 0, 7], state: "minecraft:cobblestone"},
        {pos: [7, 0, 8], state: "minecraft:cobblestone"},
        {pos: [11, 0, 1], state: "minecraft:cobblestone"},
        {pos: [11, 0, 2], state: "minecraft:cobblestone"},
        {pos: [11, 0, 7], state: "minecraft:cobblestone"},
        {pos: [11, 0, 8], state: "minecraft:cobblestone"},
        {pos: [12, 0, 1], state: "minecraft:cobblestone"},
        {pos: [12, 0, 2], state: "minecraft:cobblestone"},
        {pos: [12, 0, 3], state: "minecraft:cobblestone"},
        {pos: [12, 0, 7], state: "minecraft:cobblestone"},
        {pos: [12, 0, 8], state: "minecraft:cobblestone"},
        {pos: [12, 0, 9], state: "minecraft:cobblestone"},
        {pos: [13, 0, 0], state: "minecraft:cobblestone_stairs{facing:south,half:top,shape:straight,waterlogged:false}"},
        {pos: [13, 0, 1], state: "minecraft:cobblestone"},
        {pos: [13, 0, 2], state: "minecraft:cobblestone"},
        {pos: [13, 0, 3], state: "minecraft:cobblestone"},
        {pos: [13, 0, 4], state: "minecraft:cobblestone_stairs{facing:east,half:top,shape:straight,waterlogged:false}"},
        {pos: [13, 0, 6], state: "minecraft:cobblestone_stairs{facing:east,half:top,shape:straight,waterlogged:false}"},
        {pos: [13, 0, 7], state: "minecraft:cobblestone"},
        {pos: [13, 0, 8], state: "minecraft:cobblestone"},
        {pos: [13, 0, 9], state: "minecraft:cobblestone"},
        {pos: [14, 0, 0], state: "minecraft:cobblestone_stairs{facing:south,half:top,shape:straight,waterlogged:false}"},
        {pos: [14, 0, 1], state: "minecraft:cobblestone"},
        {pos: [14, 0, 2], state: "minecraft:cobblestone"},
        {pos: [14, 0, 3], state: "minecraft:cobblestone"},
        {pos: [14, 0, 4], state: "minecraft:cobblestone"},
        {pos: [14, 0, 5], state: "minecraft:cobblestone"},
        {pos: [14, 0, 6], state: "minecraft:cobblestone"},
        {pos: [14, 0, 7], state: "minecraft:cobblestone"},
        {pos: [14, 0, 8], state: "minecraft:cobblestone"},
        {pos: [14, 0, 9], state: "minecraft:cobblestone"},
        {pos: [15, 0, 0], state: "minecraft:cobblestone_stairs{facing:south,half:top,shape:straight,waterlogged:false}"},
        {pos: [15, 0, 1], state: "minecraft:cobblestone"},
        {pos: [15, 0, 2], state: "minecraft:cobblestone"},
        {pos: [15, 0, 3], state: "minecraft:cobblestone"},
        {pos: [15, 0, 4], state: "minecraft:cobblestone"},
        {pos: [15, 0, 5], state: "minecraft:cobblestone"},
        {pos: [15, 0, 6], state: "minecraft:cobblestone"},
        {pos: [15, 0, 7], state: "minecraft:cobblestone"},
        {pos: [15, 0, 8], state: "minecraft:cobblestone"},
        {pos: [15, 0, 9], state: "minecraft:cobblestone"},
        {pos: [15, 0, 10], state: "minecraft:cobblestone"},
        {pos: [16, 0, 0], state: "minecraft:cobblestone"},
        {pos: [16, 0, 1], state: "minecraft:cobblestone"},
        {pos: [16, 0, 2], state: "minecraft:cobblestone"},
        {pos: [16, 0, 3], state: "minecraft:cobblestone"},
        {pos: [16, 0, 4], state: "minecraft:cobblestone"},
        {pos: [16, 0, 5], state: "minecraft:cobblestone"},
        {pos: [16, 0, 6], state: "minecraft:cobblestone"},
        {pos: [16, 0, 7], state: "minecraft:cobblestone"},
        {pos: [16, 0, 8], state: "minecraft:cobblestone"},
        {pos: [16, 0, 9], state: "minecraft:cobblestone"},
        {pos: [16, 0, 10], state: "minecraft:cobblestone"},
        {pos: [17, 0, 0], state: "minecraft:cobblestone"},
        {pos: [17, 0, 1], state: "minecraft:cobblestone"},
        {pos: [17, 0, 2], state: "minecraft:cobblestone"},
        {pos: [17, 0, 3], state: "minecraft:cobblestone"},
        {pos: [17, 0, 4], state: "minecraft:cobblestone"},
        {pos: [17, 0, 7], state: "minecraft:cobblestone"},
        {pos: [17, 0, 8], state: "minecraft:cobblestone"},
        {pos: [17, 0, 9], state: "minecraft:cobblestone"},
        {pos: [0, 1, 2], state: "minecraft:cobblestone"},
        {pos: [0, 1, 3], state: "minecraft:cobblestone"},
        {pos: [0, 1, 4], state: "minecraft:cobblestone"},
        {pos: [0, 1, 5], state: "minecraft:cobblestone"},
        {pos: [0, 1, 6], state: "minecraft:cobblestone"},
        {pos: [0, 1, 7], state: "minecraft:cobblestone"},
        {pos: [0, 1, 8], state: "minecraft:cobblestone"},
        {pos: [0, 1, 9], state: "minecraft:cobblestone"},
        {pos: [1, 1, 0], state: "minecraft:cobblestone"},
        {pos: [1, 1, 1], state: "minecraft:cobblestone"},
        {pos: [1, 1, 2], state: "minecraft:cobblestone"},
        {pos: [1, 1, 3], state: "minecraft:cobblestone"},
        {pos: [1, 1, 4], state: "minecraft:cobblestone"},
        {pos: [1, 1, 5], state: "minecraft:gravel"},
        {pos: [1, 1, 6], state: "minecraft:cobblestone"},
        {pos: [1, 1, 7], state: "minecraft:cobblestone"},
        {pos: [1, 1, 8], state: "minecraft:cobblestone"},
        {pos: [1, 1, 9], state: "minecraft:cobblestone"},
        {pos: [2, 1, 0], state: "minecraft:cobblestone"},
        {pos: [2, 1, 1], state: "minecraft:cobblestone"},
        {pos: [2, 1, 2], state: "minecraft:cobblestone"},
        {pos: [2, 1, 3], state: "minecraft:cobblestone"},
        {pos: [2, 1, 4], state: "minecraft:gravel"},
        {pos: [2, 1, 5], state: "minecraft:gravel"},
        {pos: [2, 1, 6], state: "minecraft:gravel"},
        {pos: [2, 1, 7], state: "minecraft:cobblestone"},
        {pos: [2, 1, 8], state: "minecraft:cobblestone"},
        {pos: [2, 1, 9], state: "minecraft:cobblestone"},
        {pos: [2, 1, 10], state: "minecraft:cobblestone"},
        {pos: [3, 1, 0], state: "minecraft:cobblestone"},
        {pos: [3, 1, 1], state: "minecraft:cobblestone"},
        {pos: [3, 1, 2], state: "minecraft:cobblestone"},
        {pos: [3, 1, 3], state: "minecraft:cobblestone"},
        {pos: [3, 1, 4], state: "minecraft:cobblestone"},
        {pos: [3, 1, 5], state: "minecraft:gravel"},
        {pos: [3, 1, 6], state: "minecraft:cobblestone"},
        {pos: [3, 1, 7], state: "minecraft:cobblestone"},
        {pos: [3, 1, 8], state: "minecraft:cobblestone"},
        {pos: [3, 1, 9], state: "minecraft:cobblestone"},
        {pos: [3, 1, 10], state: "minecraft:cobblestone"},
        {pos: [4, 1, 0], state: "minecraft:cobblestone"},
        {pos: [4, 1, 1], state: "minecraft:cobblestone"},
        {pos: [4, 1, 2], state: "minecraft:cobblestone"},
        {pos: [4, 1, 3], state: "minecraft:cobblestone"},
        {pos: [4, 1, 4], state: "minecraft:gravel"},
        {pos: [4, 1, 5], state: "minecraft:gravel"},
        {pos: [4, 1, 6], state: "minecraft:cobblestone"},
        {pos: [4, 1, 7], state: "minecraft:cobblestone"},
        {pos: [4, 1, 8], state: "minecraft:cobblestone"},
        {pos: [4, 1, 9], state: "minecraft:cobblestone"},
        {pos: [4, 1, 10], state: "minecraft:cobblestone"},
        {pos: [5, 1, 0], state: "minecraft:gravel"},
        {pos: [5, 1, 1], state: "minecraft:cobblestone"},
        {pos: [5, 1, 2], state: "minecraft:cobblestone"},
        {pos: [5, 1, 3], state: "minecraft:cobblestone"},
        {pos: [5, 1, 4], state: "minecraft:gravel"},
        {pos: [5, 1, 5], state: "minecraft:gravel"},
        {pos: [5, 1, 6], state: "minecraft:gravel"},
        {pos: [5, 1, 7], state: "minecraft:cobblestone"},
        {pos: [5, 1, 8], state: "minecraft:cobblestone"},
        {pos: [5, 1, 9], state: "minecraft:cobblestone"},
        {pos: [5, 1, 10], state: "minecraft:gravel"},
        {pos: [6, 1, 1], state: "minecraft:gravel"},
        {pos: [6, 1, 2], state: "minecraft:gravel"},
        {pos: [6, 1, 3], state: "minecraft:gravel"},
        {pos: [6, 1, 7], state: "minecraft:cobblestone"},
        {pos: [6, 1, 8], state: "minecraft:cobblestone"},
        {pos: [6, 1, 9], state: "minecraft:cobblestone"},
        {pos: [7, 1, 1], state: "minecraft:gravel"},
        {pos: [7, 1, 2], state: "minecraft:gravel"},
        {pos: [7, 1, 3], state: "minecraft:gravel"},
        {pos: [7, 1, 7], state: "minecraft:gravel"},
        {pos: [7, 1, 8], state: "minecraft:gravel"},
        {pos: [11, 1, 1], state: "minecraft:gravel"},
        {pos: [11, 1, 2], state: "minecraft:gravel"},
        {pos: [11, 1, 7], state: "minecraft:gravel"},
        {pos: [11, 1, 8], state: "minecraft:gravel"},
        {pos: [12, 1, 1], state: "minecraft:cobblestone"},
        {pos: [12, 1, 2], state: "minecraft:cobblestone"},
        {pos: [12, 1, 3], state: "minecraft:cobblestone"},
        {pos: [12, 1, 7], state: "minecraft:cobblestone"},
        {pos: [12, 1, 8], state: "minecraft:cobblestone"},
        {pos: [12, 1, 9], state: "minecraft:cobblestone"},
        {pos: [13, 1, 0], state: "minecraft:gravel"},
        {pos: [13, 1, 1], state: "minecraft:cobblestone"},
        {pos: [13, 1, 2], state: "minecraft:gravel"},
        {pos: [13, 1, 3], state: "minecraft:cobblestone"},
        {pos: [13, 1, 4], state: "minecraft:gravel"},
        {pos: [13, 1, 6], state: "minecraft:gravel"},
        {pos: [13, 1, 7], state: "minecraft:cobblestone"},
        {pos: [13, 1, 8], state: "minecraft:cobblestone"},
        {pos: [13, 1, 9], state: "minecraft:cobblestone"},
        {pos: [14, 1, 0], state: "minecraft:gravel"},
        {pos: [14, 1, 1], state: "minecraft:cobblestone"},
        {pos: [14, 1, 2], state: "minecraft:cobblestone"},
        {pos: [14, 1, 3], state: "minecraft:cobblestone"},
        {pos: [14, 1, 4], state: "minecraft:cobblestone"},
        {pos: [14, 1, 5], state: "minecraft:cobblestone"},
        {pos: [14, 1, 6], state: "minecraft:cobblestone"},
        {pos: [14, 1, 7], state: "minecraft:cobblestone"},
        {pos: [14, 1, 8], state: "minecraft:cobblestone"},
        {pos: [14, 1, 9], state: "minecraft:cobblestone"},
        {pos: [14, 1, 10], state: "minecraft:cobblestone"},
        {pos: [15, 1, 0], state: "minecraft:gravel"},
        {pos: [15, 1, 1], state: "minecraft:cobblestone"},
        {pos: [15, 1, 2], state: "minecraft:cobblestone"},
        {pos: [15, 1, 3], state: "minecraft:cobblestone"},
        {pos: [15, 1, 4], state: "minecraft:cobblestone"},
        {pos: [15, 1, 5], state: "minecraft:cobblestone"},
        {pos: [15, 1, 6], state: "minecraft:cobblestone"},
        {pos: [15, 1, 7], state: "minecraft:cobblestone"},
        {pos: [15, 1, 8], state: "minecraft:cobblestone"},
        {pos: [15, 1, 9], state: "minecraft:cobblestone"},
        {pos: [15, 1, 10], state: "minecraft:cobblestone"},
        {pos: [16, 1, 0], state: "minecraft:cobblestone"},
        {pos: [16, 1, 1], state: "minecraft:cobblestone"},
        {pos: [16, 1, 2], state: "minecraft:cobblestone"},
        {pos: [16, 1, 3], state: "minecraft:cobblestone"},
        {pos: [16, 1, 4], state: "minecraft:cobblestone"},
        {pos: [16, 1, 5], state: "minecraft:gravel"},
        {pos: [16, 1, 6], state: "minecraft:cobblestone"},
        {pos: [16, 1, 7], state: "minecraft:cobblestone"},
        {pos: [16, 1, 8], state: "minecraft:cobblestone"},
        {pos: [16, 1, 9], state: "minecraft:cobblestone"},
        {pos: [16, 1, 10], state: "minecraft:cobblestone"},
        {pos: [17, 1, 0], state: "minecraft:cobblestone"},
        {pos: [17, 1, 1], state: "minecraft:cobblestone"},
        {pos: [17, 1, 2], state: "minecraft:cobblestone"},
        {pos: [17, 1, 3], state: "minecraft:cobblestone"},
        {pos: [17, 1, 4], state: "minecraft:cobblestone"},
        {pos: [17, 1, 5], state: "minecraft:cobblestone"},
        {pos: [17, 1, 6], state: "minecraft:cobblestone"},
        {pos: [17, 1, 7], state: "minecraft:cobblestone"},
        {pos: [17, 1, 8], state: "minecraft:cobblestone"},
        {pos: [17, 1, 9], state: "minecraft:cobblestone"},
        {pos: [18, 1, 1], state: "minecraft:cobblestone"},
        {pos: [18, 1, 7], state: "minecraft:cobblestone"},
        {pos: [18, 1, 8], state: "minecraft:cobblestone"},
        {pos: [0, 2, 1], state: "minecraft:cobblestone"},
        {pos: [0, 2, 2], state: "minecraft:cobblestone"},
        {pos: [0, 2, 3], state: "minecraft:cobblestone"},
        {pos: [0, 2, 4], state: "minecraft:cobblestone"},
        {pos: [0, 2, 5], state: "minecraft:cobblestone"},
        {pos: [0, 2, 6], state: "minecraft:cobblestone"},
        {pos: [0, 2, 7], state: "minecraft:cobblestone"},
        {pos: [0, 2, 8], state: "minecraft:cobblestone"},
        {pos: [0, 2, 9], state: "minecraft:cobblestone"},
        {pos: [1, 2, 0], state: "minecraft:cobblestone"},
        {pos: [1, 2, 1], state: "minecraft:cobblestone"},
        {pos: [1, 2, 2], state: "minecraft:cobblestone"},
        {pos: [1, 2, 3], state: "minecraft:cobblestone"},
        {pos: [1, 2, 4], state: "minecraft:cobblestone"},
        {pos: [1, 2, 5], state: "minecraft:cobblestone"},
        {pos: [1, 2, 6], state: "minecraft:cobblestone"},
        {pos: [1, 2, 7], state: "minecraft:cobblestone"},
        {pos: [1, 2, 8], state: "minecraft:cobblestone"},
        {pos: [1, 2, 9], state: "minecraft:cobblestone"},
        {pos: [1, 2, 10], state: "minecraft:cobblestone"},
        {pos: [2, 2, 0], state: "minecraft:cobblestone"},
        {pos: [2, 2, 1], state: "minecraft:cobblestone"},
        {pos: [2, 2, 2], state: "minecraft:cobblestone"},
        {pos: [2, 2, 3], state: "minecraft:cobblestone"},
        {pos: [2, 2, 4], state: "minecraft:gravel"},
        {pos: [2, 2, 5], state: "minecraft:gravel"},
        {pos: [2, 2, 6], state: "minecraft:gravel"},
        {pos: [2, 2, 7], state: "minecraft:cobblestone"},
        {pos: [2, 2, 8], state: "minecraft:cobblestone"},
        {pos: [2, 2, 9], state: "minecraft:cobblestone"},
        {pos: [2, 2, 10], state: "minecraft:cobblestone"},
        {pos: [3, 2, 0], state: "minecraft:cobblestone"},
        {pos: [3, 2, 1], state: "minecraft:cobblestone"},
        {pos: [3, 2, 2], state: "minecraft:cobblestone"},
        {pos: [3, 2, 3], state: "minecraft:cobblestone"},
        {pos: [3, 2, 4], state: "minecraft:cobblestone"},
        {pos: [3, 2, 5], state: "minecraft:gravel"},
        {pos: [3, 2, 6], state: "minecraft:cobblestone"},
        {pos: [3, 2, 7], state: "minecraft:cobblestone"},
        {pos: [3, 2, 8], state: "minecraft:cobblestone"},
        {pos: [3, 2, 9], state: "minecraft:cobblestone"},
        {pos: [3, 2, 10], state: "minecraft:cobblestone"},
        {pos: [4, 2, 0], state: "minecraft:cobblestone"},
        {pos: [4, 2, 1], state: "minecraft:cobblestone"},
        {pos: [4, 2, 2], state: "minecraft:cobblestone"},
        {pos: [4, 2, 3], state: "minecraft:cobblestone"},
        {pos: [4, 2, 4], state: "minecraft:cobblestone"},
        {pos: [4, 2, 5], state: "minecraft:cobblestone"},
        {pos: [4, 2, 6], state: "minecraft:cobblestone"},
        {pos: [4, 2, 7], state: "minecraft:cobblestone"},
        {pos: [4, 2, 8], state: "minecraft:cobblestone"},
        {pos: [4, 2, 9], state: "minecraft:cobblestone"},
        {pos: [4, 2, 10], state: "minecraft:cobblestone"},
        {pos: [5, 2, 0], state: "minecraft:gravel"},
        {pos: [5, 2, 1], state: "minecraft:cobblestone"},
        {pos: [5, 2, 2], state: "minecraft:gravel"},
        {pos: [5, 2, 3], state: "minecraft:cobblestone"},
        {pos: [5, 2, 4], state: "minecraft:gravel"},
        {pos: [5, 2, 5], state: "minecraft:gravel"},
        {pos: [5, 2, 6], state: "minecraft:gravel"},
        {pos: [5, 2, 7], state: "minecraft:cobblestone"},
        {pos: [5, 2, 8], state: "minecraft:cobblestone"},
        {pos: [5, 2, 9], state: "minecraft:cobblestone"},
        {pos: [5, 2, 10], state: "minecraft:gravel"},
        {pos: [6, 2, 1], state: "minecraft:gravel"},
        {pos: [6, 2, 2], state: "minecraft:gravel"},
        {pos: [6, 2, 3], state: "minecraft:gravel"},
        {pos: [6, 2, 7], state: "minecraft:gravel"},
        {pos: [6, 2, 8], state: "minecraft:gravel"},
        {pos: [6, 2, 9], state: "minecraft:gravel"},
        {pos: [7, 2, 1], state: "minecraft:gravel"},
        {pos: [7, 2, 2], state: "minecraft:gravel"},
        {pos: [7, 2, 3], state: "minecraft:gravel"},
        {pos: [7, 2, 7], state: "minecraft:gravel"},
        {pos: [7, 2, 8], state: "minecraft:gravel"},
        {pos: [11, 2, 1], state: "minecraft:gravel"},
        {pos: [11, 2, 2], state: "minecraft:gravel"},
        {pos: [11, 2, 7], state: "minecraft:gravel"},
        {pos: [11, 2, 8], state: "minecraft:gravel"},
        {pos: [12, 2, 1], state: "minecraft:gravel"},
        {pos: [12, 2, 2], state: "minecraft:gravel"},
        {pos: [12, 2, 3], state: "minecraft:gravel"},
        {pos: [12, 2, 7], state: "minecraft:gravel"},
        {pos: [12, 2, 8], state: "minecraft:gravel"},
        {pos: [12, 2, 9], state: "minecraft:gravel"},
        {pos: [13, 2, 0], state: "minecraft:gravel"},
        {pos: [13, 2, 1], state: "minecraft:gravel"},
        {pos: [13, 2, 2], state: "minecraft:gravel"},
        {pos: [13, 2, 3], state: "minecraft:cobblestone"},
        {pos: [13, 2, 4], state: "minecraft:gravel"},
        {pos: [13, 2, 6], state: "minecraft:gravel"},
        {pos: [13, 2, 7], state: "minecraft:cobblestone"},
        {pos: [13, 2, 8], state: "minecraft:cobblestone"},
        {pos: [13, 2, 9], state: "minecraft:cobblestone"},
        {pos: [13, 2, 10], state: "minecraft:cobblestone"},
        {pos: [14, 2, 0], state: "minecraft:gravel"},
        {pos: [14, 2, 1], state: "minecraft:cobblestone"},
        {pos: [14, 2, 2], state: "minecraft:gravel"},
        {pos: [14, 2, 3], state: "minecraft:cobblestone"},
        {pos: [14, 2, 4], state: "minecraft:cobblestone"},
        {pos: [14, 2, 5], state: "minecraft:gravel"},
        {pos: [14, 2, 6], state: "minecraft:cobblestone"},
        {pos: [14, 2, 7], state: "minecraft:cobblestone"},
        {pos: [14, 2, 8], state: "minecraft:cobblestone"},
        {pos: [14, 2, 9], state: "minecraft:cobblestone"},
        {pos: [14, 2, 10], state: "minecraft:cobblestone"},
        {pos: [15, 2, 0], state: "minecraft:cobblestone"},
        {pos: [15, 2, 1], state: "minecraft:cobblestone"},
        {pos: [15, 2, 2], state: "minecraft:cobblestone"},
        {pos: [15, 2, 3], state: "minecraft:cobblestone"},
        {pos: [15, 2, 4], state: "minecraft:gravel"},
        {pos: [15, 2, 5], state: "minecraft:gravel"},
        {pos: [15, 2, 6], state: "minecraft:cobblestone"},
        {pos: [15, 2, 7], state: "minecraft:cobblestone"},
        {pos: [15, 2, 8], state: "minecraft:cobblestone"},
        {pos: [15, 2, 9], state: "minecraft:gravel"},
        {pos: [15, 2, 10], state: "minecraft:cobblestone"},
        {pos: [16, 2, 0], state: "minecraft:cobblestone"},
        {pos: [16, 2, 1], state: "minecraft:cobblestone"},
        {pos: [16, 2, 2], state: "minecraft:cobblestone"},
        {pos: [16, 2, 3], state: "minecraft:cobblestone"},
        {pos: [16, 2, 4], state: "minecraft:cobblestone"},
        {pos: [16, 2, 5], state: "minecraft:gravel"},
        {pos: [16, 2, 6], state: "minecraft:cobblestone"},
        {pos: [16, 2, 7], state: "minecraft:cobblestone"},
        {pos: [16, 2, 8], state: "minecraft:gravel"},
        {pos: [16, 2, 9], state: "minecraft:gravel"},
        {pos: [16, 2, 10], state: "minecraft:cobblestone"},
        {pos: [17, 2, 0], state: "minecraft:cobblestone"},
        {pos: [17, 2, 1], state: "minecraft:cobblestone"},
        {pos: [17, 2, 2], state: "minecraft:cobblestone"},
        {pos: [17, 2, 3], state: "minecraft:cobblestone"},
        {pos: [17, 2, 4], state: "minecraft:gravel"},
        {pos: [17, 2, 5], state: "minecraft:cobblestone"},
        {pos: [17, 2, 6], state: "minecraft:cobblestone"},
        {pos: [17, 2, 7], state: "minecraft:gravel"},
        {pos: [17, 2, 8], state: "minecraft:gravel"},
        {pos: [17, 2, 9], state: "minecraft:gravel"},
        {pos: [17, 2, 10], state: "minecraft:cobblestone"},
        {pos: [18, 2, 0], state: "minecraft:cobblestone"},
        {pos: [18, 2, 1], state: "minecraft:cobblestone"},
        {pos: [18, 2, 2], state: "minecraft:cobblestone"},
        {pos: [18, 2, 7], state: "minecraft:cobblestone"},
        {pos: [18, 2, 8], state: "minecraft:cobblestone"},
        {pos: [18, 2, 9], state: "minecraft:cobblestone"},
        {pos: [0, 3, 1], state: "minecraft:cobblestone"},
        {pos: [0, 3, 2], state: "minecraft:cobblestone"},
        {pos: [0, 3, 3], state: "minecraft:cobblestone"},
        {pos: [0, 3, 4], state: "minecraft:gravel"},
        {pos: [0, 3, 5], state: "minecraft:green_glazed_terracotta{facing:north}"},
        {pos: [0, 3, 6], state: "minecraft:gravel"},
        {pos: [0, 3, 7], state: "minecraft:cobblestone"},
        {pos: [0, 3, 8], state: "minecraft:cobblestone"},
        {pos: [0, 3, 9], state: "minecraft:gravel"},
        {pos: [1, 3, 0], state: "minecraft:cobblestone"},
        {pos: [1, 3, 1], state: "minecraft:cobblestone"},
        {pos: [1, 3, 2], state: "minecraft:cobblestone_stairs{facing:west,half:top,shape:straight,waterlogged:false}"},
        {pos: [1, 3, 3], state: "minecraft:cobblestone_stairs{facing:west,half:top,shape:straight,waterlogged:false}"},
        {pos: [1, 3, 4], state: "minecraft:gravel"},
        {pos: [1, 3, 5], state: "minecraft:gravel"},
        {pos: [1, 3, 6], state: "minecraft:gravel"},
        {pos: [1, 3, 7], state: "minecraft:cobblestone_stairs{facing:west,half:top,shape:straight,waterlogged:false}"},
        {pos: [1, 3, 8], state: "minecraft:cobblestone_stairs{facing:west,half:top,shape:straight,waterlogged:false}"},
        {pos: [1, 3, 9], state: "minecraft:gravel"},
        {pos: [1, 3, 10], state: "minecraft:cobblestone"},
        {pos: [2, 3, 0], state: "minecraft:cobblestone"},
        {pos: [2, 3, 1], state: "minecraft:gravel"},
        {pos: [2, 3, 2], state: "minecraft:gravel"},
        {pos: [2, 3, 3], state: "minecraft:gravel"},
        {pos: [2, 3, 4], state: "minecraft:gravel"},
        {pos: [2, 3, 5], state: "minecraft:gravel"},
        {pos: [2, 3, 6], state: "minecraft:gravel"},
        {pos: [2, 3, 7], state: "minecraft:gravel"},
        {pos: [2, 3, 8], state: "minecraft:gravel"},
        {pos: [2, 3, 9], state: "minecraft:gravel"},
        {pos: [2, 3, 10], state: "minecraft:gravel"},
        {pos: [3, 3, 0], state: "minecraft:gravel"},
        {pos: [3, 3, 1], state: "minecraft:gravel"},
        {pos: [3, 3, 2], state: "minecraft:gravel"},
        {pos: [3, 3, 3], state: "minecraft:gravel"},
        {pos: [3, 3, 4], state: "minecraft:cobblestone_stairs{facing:east,half:top,shape:straight,waterlogged:false}"},
        {pos: [3, 3, 5], state: "minecraft:gravel"},
        {pos: [3, 3, 6], state: "minecraft:gravel"},
        {pos: [3, 3, 7], state: "minecraft:gravel"},
        {pos: [3, 3, 8], state: "minecraft:gravel"},
        {pos: [3, 3, 9], state: "minecraft:gravel"},
        {pos: [3, 3, 10], state: "minecraft:cobblestone"},
        {pos: [4, 3, 0], state: "minecraft:cobblestone"},
        {pos: [4, 3, 1], state: "minecraft:gravel"},
        {pos: [4, 3, 2], state: "minecraft:gravel"},
        {pos: [4, 3, 3], state: "minecraft:gravel"},
        {pos: [4, 3, 4], state: "minecraft:cobblestone"},
        {pos: [4, 3, 5], state: "minecraft:cobblestone"},
        {pos: [4, 3, 6], state: "minecraft:cobblestone"},
        {pos: [4, 3, 7], state: "minecraft:gravel"},
        {pos: [4, 3, 8], state: "minecraft:gravel"},
        {pos: [4, 3, 9], state: "minecraft:gravel"},
        {pos: [4, 3, 10], state: "minecraft:cobblestone"},
        {pos: [5, 3, 0], state: "minecraft:gravel"},
        {pos: [5, 3, 1], state: "minecraft:gravel"},
        {pos: [5, 3, 2], state: "minecraft:gravel"},
        {pos: [5, 3, 3], state: "minecraft:gravel"},
        {pos: [5, 3, 4], state: "minecraft:gravel"},
        {pos: [5, 3, 5], state: "minecraft:gravel"},
        {pos: [5, 3, 6], state: "minecraft:gravel"},
        {pos: [5, 3, 7], state: "minecraft:gravel"},
        {pos: [5, 3, 8], state: "minecraft:gravel"},
        {pos: [5, 3, 9], state: "minecraft:gravel"},
        {pos: [5, 3, 10], state: "minecraft:gravel"},
        {pos: [6, 3, 1], state: "minecraft:gravel"},
        {pos: [6, 3, 2], state: "minecraft:gravel"},
        {pos: [6, 3, 3], state: "minecraft:gravel"},
        {pos: [6, 3, 7], state: "minecraft:gravel"},
        {pos: [6, 3, 8], state: "minecraft:gravel"},
        {pos: [6, 3, 9], state: "minecraft:gravel"},
        {pos: [7, 3, 1], state: "minecraft:gravel"},
        {pos: [7, 3, 2], state: "minecraft:gravel"},
        {pos: [7, 3, 3], state: "minecraft:gravel"},
        {pos: [11, 3, 1], state: "minecraft:gravel"},
        {pos: [11, 3, 2], state: "minecraft:gravel"},
        {pos: [12, 3, 1], state: "minecraft:gravel"},
        {pos: [12, 3, 2], state: "minecraft:gravel"},
        {pos: [12, 3, 3], state: "minecraft:gravel"},
        {pos: [12, 3, 7], state: "minecraft:gravel"},
        {pos: [12, 3, 8], state: "minecraft:gravel"},
        {pos: [12, 3, 9], state: "minecraft:gravel"},
        {pos: [13, 3, 0], state: "minecraft:gravel"},
        {pos: [13, 3, 1], state: "minecraft:gravel"},
        {pos: [13, 3, 2], state: "minecraft:gravel"},
        {pos: [13, 3, 3], state: "minecraft:gravel"},
        {pos: [13, 3, 4], state: "minecraft:gravel"},
        {pos: [13, 3, 6], state: "minecraft:gravel"},
        {pos: [13, 3, 7], state: "minecraft:gravel"},
        {pos: [13, 3, 8], state: "minecraft:gravel"},
        {pos: [13, 3, 9], state: "minecraft:gravel"},
        {pos: [13, 3, 10], state: "minecraft:cobblestone"},
        {pos: [14, 3, 0], state: "minecraft:gravel"},
        {pos: [14, 3, 1], state: "minecraft:gravel"},
        {pos: [14, 3, 2], state: "minecraft:gravel"},
        {pos: [14, 3, 3], state: "minecraft:gravel"},
        {pos: [14, 3, 4], state: "minecraft:cobblestone"},
        {pos: [14, 3, 5], state: "minecraft:gravel"},
        {pos: [14, 3, 6], state: "minecraft:cobblestone"},
        {pos: [14, 3, 7], state: "minecraft:gravel"},
        {pos: [14, 3, 8], state: "minecraft:gravel"},
        {pos: [14, 3, 9], state: "minecraft:gravel"},
        {pos: [14, 3, 10], state: "minecraft:cobblestone"},
        {pos: [15, 3, 0], state: "minecraft:cobblestone"},
        {pos: [15, 3, 1], state: "minecraft:gravel"},
        {pos: [15, 3, 2], state: "minecraft:gravel"},
        {pos: [15, 3, 3], state: "minecraft:gravel"},
        {pos: [15, 3, 4], state: "minecraft:gravel"},
        {pos: [15, 3, 5], state: "minecraft:gravel"},
        {pos: [15, 3, 6], state: "minecraft:gravel"},
        {pos: [15, 3, 7], state: "minecraft:gravel"},
        {pos: [15, 3, 8], state: "minecraft:gravel"},
        {pos: [15, 3, 9], state: "minecraft:gravel"},
        {pos: [15, 3, 10], state: "minecraft:gravel"},
        {pos: [16, 3, 0], state: "minecraft:cobblestone"},
        {pos: [16, 3, 1], state: "minecraft:gravel"},
        {pos: [16, 3, 2], state: "minecraft:gravel"},
        {pos: [16, 3, 3], state: "minecraft:gravel"},
        {pos: [16, 3, 4], state: "minecraft:gravel"},
        {pos: [16, 3, 5], state: "minecraft:gravel"},
        {pos: [16, 3, 6], state: "minecraft:gravel"},
        {pos: [16, 3, 7], state: "minecraft:gravel"},
        {pos: [16, 3, 8], state: "minecraft:gravel"},
        {pos: [16, 3, 9], state: "minecraft:gravel"},
        {pos: [16, 3, 10], state: "minecraft:cobblestone"},
        {pos: [17, 3, 0], state: "minecraft:cobblestone"},
        {pos: [17, 3, 1], state: "minecraft:gravel"},
        {pos: [17, 3, 2], state: "minecraft:gravel"},
        {pos: [17, 3, 3], state: "minecraft:gravel"},
        {pos: [17, 3, 4], state: "minecraft:gravel"},
        {pos: [17, 3, 5], state: "minecraft:gravel"},
        {pos: [17, 3, 6], state: "minecraft:gravel"},
        {pos: [17, 3, 7], state: "minecraft:gravel"},
        {pos: [17, 3, 8], state: "minecraft:gravel"},
        {pos: [17, 3, 9], state: "minecraft:gravel"},
        {pos: [17, 3, 10], state: "minecraft:cobblestone"},
        {pos: [18, 3, 0], state: "minecraft:cobblestone"},
        {pos: [18, 3, 1], state: "minecraft:cobblestone"},
        {pos: [18, 3, 2], state: "minecraft:gravel"},
        {pos: [18, 3, 5], state: "minecraft:cobblestone"},
        {pos: [18, 3, 6], state: "minecraft:cobblestone"},
        {pos: [18, 3, 7], state: "minecraft:cobblestone"},
        {pos: [18, 3, 8], state: "minecraft:cobblestone"},
        {pos: [18, 3, 9], state: "minecraft:gravel"},
        {pos: [0, 4, 1], state: "minecraft:gravel"},
        {pos: [0, 4, 2], state: "minecraft:cobblestone"},
        {pos: [0, 4, 3], state: "minecraft:gravel"},
        {pos: [0, 4, 4], state: "minecraft:gravel"},
        {pos: [0, 4, 5], state: "minecraft:green_glazed_terracotta{facing:north}"},
        {pos: [0, 4, 6], state: "minecraft:gravel"},
        {pos: [0, 4, 7], state: "minecraft:gravel"},
        {pos: [0, 4, 8], state: "minecraft:gravel"},
        {pos: [0, 4, 9], state: "minecraft:gravel"},
        {pos: [1, 4, 0], state: "minecraft:gravel"},
        {pos: [1, 4, 1], state: "minecraft:gravel"},
        {pos: [1, 4, 2], state: "minecraft:gray_glazed_terracotta{facing:east}"},
        {pos: [1, 4, 3], state: "minecraft:gravel"},
        {pos: [1, 4, 4], state: "minecraft:gravel"},
        {pos: [1, 4, 5], state: "minecraft:gravel"},
        {pos: [1, 4, 6], state: "minecraft:gravel"},
        {pos: [1, 4, 7], state: "minecraft:gravel"},
        {pos: [1, 4, 8], state: "minecraft:gravel"},
        {pos: [1, 4, 9], state: "minecraft:gravel"},
        {pos: [1, 4, 10], state: "minecraft:cobblestone"},
        {pos: [2, 4, 0], state: "minecraft:gravel"},
        {pos: [2, 4, 1], state: "minecraft:gravel"},
        {pos: [2, 4, 2], state: "minecraft:gravel"},
        {pos: [2, 4, 3], state: "minecraft:gravel"},
        {pos: [2, 4, 4], state: "minecraft:gravel"},
        {pos: [2, 4, 5], state: "minecraft:gravel"},
        {pos: [2, 4, 6], state: "minecraft:gravel"},
        {pos: [2, 4, 7], state: "minecraft:gravel"},
        {pos: [2, 4, 8], state: "minecraft:gravel"},
        {pos: [2, 4, 9], state: "minecraft:gravel"},
        {pos: [2, 4, 10], state: "minecraft:gravel"},
        {pos: [3, 4, 0], state: "minecraft:gravel"},
        {pos: [3, 4, 1], state: "minecraft:gravel"},
        {pos: [3, 4, 2], state: "minecraft:gravel"},
        {pos: [3, 4, 3], state: "minecraft:gravel"},
        {pos: [3, 4, 4], state: "minecraft:gravel"},
        {pos: [3, 4, 5], state: "minecraft:gravel"},
        {pos: [3, 4, 6], state: "minecraft:gravel"},
        {pos: [3, 4, 7], state: "minecraft:gravel"},
        {pos: [3, 4, 8], state: "minecraft:gravel"},
        {pos: [3, 4, 9], state: "minecraft:gravel"},
        {pos: [3, 4, 10], state: "minecraft:gravel"},
        {pos: [4, 4, 0], state: "minecraft:gravel"},
        {pos: [4, 4, 1], state: "minecraft:gravel"},
        {pos: [4, 4, 2], state: "minecraft:gravel"},
        {pos: [4, 4, 3], state: "minecraft:gravel"},
        {pos: [4, 4, 4], state: "minecraft:gravel"},
        {pos: [4, 4, 5], state: "minecraft:gravel"},
        {pos: [4, 4, 6], state: "minecraft:cobblestone"},
        {pos: [4, 4, 7], state: "minecraft:gravel"},
        {pos: [4, 4, 8], state: "minecraft:gravel"},
        {pos: [4, 4, 9], state: "minecraft:gravel"},
        {pos: [4, 4, 10], state: "minecraft:gravel"},
        {pos: [5, 4, 0], state: "minecraft:gravel"},
        {pos: [5, 4, 1], state: "minecraft:gravel"},
        {pos: [5, 4, 2], state: "minecraft:gravel"},
        {pos: [5, 4, 3], state: "minecraft:gravel"},
        {pos: [5, 4, 4], state: "minecraft:gravel"},
        {pos: [5, 4, 5], state: "minecraft:gravel"},
        {pos: [5, 4, 6], state: "minecraft:gravel"},
        {pos: [5, 4, 7], state: "minecraft:gravel"},
        {pos: [5, 4, 8], state: "minecraft:gravel"},
        {pos: [5, 4, 9], state: "minecraft:gravel"},
        {pos: [6, 4, 1], state: "minecraft:gravel"},
        {pos: [6, 4, 2], state: "minecraft:gravel"},
        {pos: [6, 4, 3], state: "minecraft:gravel"},
        {pos: [12, 4, 2], state: "minecraft:gravel"},
        {pos: [13, 4, 0], state: "minecraft:gravel"},
        {pos: [13, 4, 1], state: "minecraft:gravel"},
        {pos: [13, 4, 2], state: "minecraft:gravel"},
        {pos: [13, 4, 3], state: "minecraft:gravel"},
        {pos: [13, 4, 4], state: "minecraft:gravel"},
        {pos: [13, 4, 7], state: "minecraft:gravel"},
        {pos: [13, 4, 8], state: "minecraft:gravel"},
        {pos: [13, 4, 9], state: "minecraft:gravel"},
        {pos: [13, 4, 10], state: "minecraft:gravel"},
        {pos: [14, 4, 0], state: "minecraft:gravel"},
        {pos: [14, 4, 1], state: "minecraft:gravel"},
        {pos: [14, 4, 2], state: "minecraft:gravel"},
        {pos: [14, 4, 3], state: "minecraft:gravel"},
        {pos: [14, 4, 4], state: "minecraft:cobblestone"},
        {pos: [14, 4, 5], state: "minecraft:gravel"},
        {pos: [14, 4, 6], state: "minecraft:gravel"},
        {pos: [14, 4, 7], state: "minecraft:gravel"},
        {pos: [14, 4, 8], state: "minecraft:gravel"},
        {pos: [14, 4, 9], state: "minecraft:gravel"},
        {pos: [14, 4, 10], state: "minecraft:cobblestone"},
        {pos: [15, 4, 0], state: "minecraft:gravel"},
        {pos: [15, 4, 1], state: "minecraft:gravel"},
        {pos: [15, 4, 2], state: "minecraft:gravel"},
        {pos: [15, 4, 3], state: "minecraft:gravel"},
        {pos: [15, 4, 4], state: "minecraft:gravel"},
        {pos: [15, 4, 5], state: "minecraft:gravel"},
        {pos: [15, 4, 6], state: "minecraft:gravel"},
        {pos: [15, 4, 7], state: "minecraft:gravel"},
        {pos: [15, 4, 8], state: "minecraft:gravel"},
        {pos: [15, 4, 9], state: "minecraft:gravel"},
        {pos: [15, 4, 10], state: "minecraft:gravel"},
        {pos: [16, 4, 0], state: "minecraft:gravel"},
        {pos: [16, 4, 1], state: "minecraft:gravel"},
        {pos: [16, 4, 2], state: "minecraft:gravel"},
        {pos: [16, 4, 3], state: "minecraft:gravel"},
        {pos: [16, 4, 4], state: "minecraft:gravel"},
        {pos: [16, 4, 5], state: "minecraft:gravel"},
        {pos: [16, 4, 6], state: "minecraft:gravel"},
        {pos: [16, 4, 7], state: "minecraft:gravel"},
        {pos: [16, 4, 8], state: "minecraft:gravel"},
        {pos: [16, 4, 9], state: "minecraft:gravel"},
        {pos: [16, 4, 10], state: "minecraft:cobblestone"},
        {pos: [17, 4, 0], state: "minecraft:gravel"},
        {pos: [17, 4, 1], state: "minecraft:gravel"},
        {pos: [17, 4, 2], state: "minecraft:gravel"},
        {pos: [17, 4, 3], state: "minecraft:gravel"},
        {pos: [17, 4, 4], state: "minecraft:gravel"},
        {pos: [17, 4, 5], state: "minecraft:gravel"},
        {pos: [17, 4, 6], state: "minecraft:gravel"},
        {pos: [17, 4, 7], state: "minecraft:gravel"},
        {pos: [17, 4, 8], state: "minecraft:gravel"},
        {pos: [17, 4, 9], state: "minecraft:gravel"},
        {pos: [17, 4, 10], state: "minecraft:gravel"},
        {pos: [18, 4, 0], state: "minecraft:gravel"},
        {pos: [18, 4, 1], state: "minecraft:gravel"},
        {pos: [18, 4, 5], state: "minecraft:cobblestone"},
        {pos: [18, 4, 6], state: "minecraft:gravel"},
        {pos: [18, 4, 7], state: "minecraft:gravel"},
        {pos: [18, 4, 8], state: "minecraft:gravel"},
        {pos: [18, 4, 9], state: "minecraft:gravel"},
        {pos: [0, 5, 5], state: "minecraft:chiseled_stone_bricks"},
        {pos: [0, 5, 8], state: "minecraft:gravel"},
        {pos: [0, 5, 9], state: "minecraft:gravel"},
        {pos: [1, 5, 2], state: "minecraft:gravel"},
        {pos: [1, 5, 8], state: "minecraft:gravel"},
        {pos: [1, 5, 9], state: "minecraft:gravel"},
        {pos: [1, 5, 10], state: "minecraft:gravel"},
        {pos: [2, 5, 1], state: "minecraft:gravel"},
        {pos: [2, 5, 2], state: "minecraft:gravel"},
        {pos: [2, 5, 3], state: "minecraft:gravel"},
        {pos: [2, 5, 8], state: "minecraft:gravel"},
        {pos: [2, 5, 9], state: "minecraft:gravel"},
        {pos: [3, 5, 1], state: "minecraft:gravel"},
        {pos: [3, 5, 2], state: "minecraft:gravel"},
        {pos: [3, 5, 3], state: "minecraft:gravel"},
        {pos: [3, 5, 4], state: "minecraft:gravel"},
        {pos: [3, 5, 5], state: "minecraft:gravel"},
        {pos: [3, 5, 6], state: "minecraft:gravel"},
        {pos: [4, 5, 1], state: "minecraft:gravel"},
        {pos: [4, 5, 2], state: "minecraft:gravel"},
        {pos: [4, 5, 3], state: "minecraft:gravel"},
        {pos: [4, 5, 4], state: "minecraft:gravel"},
        {pos: [4, 5, 5], state: "minecraft:gravel"},
        {pos: [4, 5, 6], state: "minecraft:cobblestone"},
        {pos: [4, 5, 7], state: "minecraft:cobblestone"},
        {pos: [5, 5, 2], state: "minecraft:gravel"},
        {pos: [5, 5, 3], state: "minecraft:gravel"},
        {pos: [14, 5, 4], state: "minecraft:cobblestone"},
        {pos: [14, 5, 5], state: "minecraft:cobblestone"},
        {pos: [14, 5, 6], state: "minecraft:cobblestone"},
        {pos: [14, 5, 7], state: "minecraft:gravel"},
        {pos: [15, 5, 1], state: "minecraft:gravel"},
        {pos: [15, 5, 2], state: "minecraft:gravel"},
        {pos: [15, 5, 5], state: "minecraft:gravel"},
        {pos: [15, 5, 6], state: "minecraft:gravel"},
        {pos: [15, 5, 7], state: "minecraft:gravel"},
        {pos: [15, 5, 8], state: "minecraft:gravel"},
        {pos: [16, 5, 1], state: "minecraft:cobblestone"},
        {pos: [16, 5, 2], state: "minecraft:gravel"},
        {pos: [16, 5, 3], state: "minecraft:gravel"},
        {pos: [16, 5, 7], state: "minecraft:gravel"},
        {pos: [16, 5, 8], state: "minecraft:gravel"},
        {pos: [16, 5, 10], state: "minecraft:gravel"},
        {pos: [17, 5, 1], state: "minecraft:cobblestone"},
        {pos: [17, 5, 2], state: "minecraft:cobblestone"},
        {pos: [17, 5, 3], state: "minecraft:gravel"},
        {pos: [0, 6, 5], state: "minecraft:gravel"},
        {pos: [4, 6, 7], state: "minecraft:gravel"},
        {pos: [14, 6, 6], state: "minecraft:gravel"},
        {pos: [17, 6, 1], state: "minecraft:cobblestone"},
        {pos: [17, 6, 2], state: "minecraft:gravel"},
        {pos: [17, 7, 1], state: "minecraft:gravel"},
        {pos: [0, 8, 0], state: "minecraft:air"},
        {pos: [0, 8, 1], state: "minecraft:air"},
        {pos: [0, 8, 2], state: "minecraft:air"},
        {pos: [0, 8, 3], state: "minecraft:air"},
        {pos: [0, 8, 4], state: "minecraft:air"},
        {pos: [0, 8, 5], state: "minecraft:air"},
        {pos: [0, 8, 6], state: "minecraft:air"},
        {pos: [0, 8, 7], state: "minecraft:air"},
        {pos: [0, 8, 8], state: "minecraft:air"},
        {pos: [0, 8, 9], state: "minecraft:air"},
        {pos: [0, 8, 10], state: "minecraft:air"},
        {pos: [1, 8, 0], state: "minecraft:air"},
        {pos: [1, 8, 1], state: "minecraft:air"},
        {pos: [1, 8, 2], state: "minecraft:air"},
        {pos: [1, 8, 3], state: "minecraft:air"},
        {pos: [1, 8, 4], state: "minecraft:air"},
        {pos: [1, 8, 5], state: "minecraft:air"},
        {pos: [1, 8, 6], state: "minecraft:air"},
        {pos: [1, 8, 7], state: "minecraft:air"},
        {pos: [1, 8, 8], state: "minecraft:air"},
        {pos: [1, 8, 9], state: "minecraft:air"},
        {pos: [1, 8, 10], state: "minecraft:air"},
        {pos: [2, 8, 0], state: "minecraft:air"},
        {pos: [2, 8, 1], state: "minecraft:air"},
        {pos: [2, 8, 2], state: "minecraft:air"},
        {pos: [2, 8, 3], state: "minecraft:air"},
        {pos: [2, 8, 4], state: "minecraft:air"},
        {pos: [2, 8, 5], state: "minecraft:air"},
        {pos: [2, 8, 6], state: "minecraft:air"},
        {pos: [2, 8, 7], state: "minecraft:air"},
        {pos: [2, 8, 8], state: "minecraft:air"},
        {pos: [2, 8, 9], state: "minecraft:air"},
        {pos: [2, 8, 10], state: "minecraft:air"},
        {pos: [3, 8, 0], state: "minecraft:air"},
        {pos: [3, 8, 1], state: "minecraft:air"},
        {pos: [3, 8, 2], state: "minecraft:air"},
        {pos: [3, 8, 3], state: "minecraft:air"},
        {pos: [3, 8, 4], state: "minecraft:air"},
        {pos: [3, 8, 5], state: "minecraft:air"},
        {pos: [3, 8, 6], state: "minecraft:air"},
        {pos: [3, 8, 7], state: "minecraft:air"},
        {pos: [3, 8, 8], state: "minecraft:air"},
        {pos: [3, 8, 9], state: "minecraft:air"},
        {pos: [3, 8, 10], state: "minecraft:air"},
        {pos: [4, 8, 0], state: "minecraft:air"},
        {pos: [4, 8, 1], state: "minecraft:air"},
        {pos: [4, 8, 2], state: "minecraft:air"},
        {pos: [4, 8, 3], state: "minecraft:air"},
        {pos: [4, 8, 4], state: "minecraft:air"},
        {pos: [4, 8, 5], state: "minecraft:air"},
        {pos: [4, 8, 6], state: "minecraft:air"},
        {pos: [4, 8, 7], state: "minecraft:air"},
        {pos: [4, 8, 8], state: "minecraft:air"},
        {pos: [4, 8, 9], state: "minecraft:air"},
        {pos: [4, 8, 10], state: "minecraft:air"},
        {pos: [5, 8, 0], state: "minecraft:air"},
        {pos: [5, 8, 1], state: "minecraft:air"},
        {pos: [5, 8, 2], state: "minecraft:air"},
        {pos: [5, 8, 3], state: "minecraft:air"},
        {pos: [5, 8, 4], state: "minecraft:air"},
        {pos: [5, 8, 5], state: "minecraft:air"},
        {pos: [5, 8, 6], state: "minecraft:air"},
        {pos: [5, 8, 7], state: "minecraft:air"},
        {pos: [5, 8, 8], state: "minecraft:air"},
        {pos: [5, 8, 9], state: "minecraft:air"},
        {pos: [5, 8, 10], state: "minecraft:air"},
        {pos: [6, 8, 0], state: "minecraft:air"},
        {pos: [6, 8, 1], state: "minecraft:air"},
        {pos: [6, 8, 2], state: "minecraft:air"},
        {pos: [6, 8, 3], state: "minecraft:air"},
        {pos: [6, 8, 4], state: "minecraft:air"},
        {pos: [6, 8, 5], state: "minecraft:air"},
        {pos: [6, 8, 6], state: "minecraft:air"},
        {pos: [6, 8, 7], state: "minecraft:air"},
        {pos: [6, 8, 8], state: "minecraft:air"},
        {pos: [6, 8, 9], state: "minecraft:air"},
        {pos: [6, 8, 10], state: "minecraft:air"},
        {pos: [7, 8, 0], state: "minecraft:air"},
        {pos: [7, 8, 1], state: "minecraft:air"},
        {pos: [7, 8, 2], state: "minecraft:air"},
        {pos: [7, 8, 3], state: "minecraft:air"},
        {pos: [7, 8, 4], state: "minecraft:air"},
        {pos: [7, 8, 5], state: "minecraft:air"},
        {pos: [7, 8, 6], state: "minecraft:air"},
        {pos: [7, 8, 7], state: "minecraft:air"},
        {pos: [7, 8, 8], state: "minecraft:air"},
        {pos: [7, 8, 9], state: "minecraft:air"},
        {pos: [7, 8, 10], state: "minecraft:air"},
        {pos: [8, 8, 0], state: "minecraft:air"},
        {pos: [8, 8, 1], state: "minecraft:air"},
        {pos: [8, 8, 2], state: "minecraft:air"},
        {pos: [8, 8, 3], state: "minecraft:air"},
        {pos: [8, 8, 4], state: "minecraft:air"},
        {pos: [8, 8, 5], state: "minecraft:air"},
        {pos: [8, 8, 6], state: "minecraft:air"},
        {pos: [8, 8, 7], state: "minecraft:air"},
        {pos: [8, 8, 8], state: "minecraft:air"},
        {pos: [8, 8, 9], state: "minecraft:air"},
        {pos: [8, 8, 10], state: "minecraft:air"},
        {pos: [9, 8, 0], state: "minecraft:air"},
        {pos: [9, 8, 1], state: "minecraft:air"},
        {pos: [9, 8, 2], state: "minecraft:air"},
        {pos: [9, 8, 3], state: "minecraft:air"},
        {pos: [9, 8, 4], state: "minecraft:air"},
        {pos: [9, 8, 5], state: "minecraft:air"},
        {pos: [9, 8, 6], state: "minecraft:air"},
        {pos: [9, 8, 7], state: "minecraft:air"},
        {pos: [9, 8, 8], state: "minecraft:air"},
        {pos: [9, 8, 9], state: "minecraft:air"},
        {pos: [9, 8, 10], state: "minecraft:air"},
        {pos: [10, 8, 0], state: "minecraft:air"},
        {pos: [10, 8, 1], state: "minecraft:air"},
        {pos: [10, 8, 2], state: "minecraft:air"},
        {pos: [10, 8, 3], state: "minecraft:air"},
        {pos: [10, 8, 4], state: "minecraft:air"},
        {pos: [10, 8, 5], state: "minecraft:air"},
        {pos: [10, 8, 6], state: "minecraft:air"},
        {pos: [10, 8, 7], state: "minecraft:air"},
        {pos: [10, 8, 8], state: "minecraft:air"},
        {pos: [10, 8, 9], state: "minecraft:air"},
        {pos: [10, 8, 10], state: "minecraft:air"},
        {pos: [11, 8, 0], state: "minecraft:air"},
        {pos: [11, 8, 1], state: "minecraft:air"},
        {pos: [11, 8, 2], state: "minecraft:air"},
        {pos: [11, 8, 3], state: "minecraft:air"},
        {pos: [11, 8, 4], state: "minecraft:air"},
        {pos: [11, 8, 5], state: "minecraft:air"},
        {pos: [11, 8, 6], state: "minecraft:air"},
        {pos: [11, 8, 7], state: "minecraft:air"},
        {pos: [11, 8, 8], state: "minecraft:air"},
        {pos: [11, 8, 9], state: "minecraft:air"},
        {pos: [11, 8, 10], state: "minecraft:air"},
        {pos: [12, 8, 0], state: "minecraft:air"},
        {pos: [12, 8, 1], state: "minecraft:air"},
        {pos: [12, 8, 2], state: "minecraft:air"},
        {pos: [12, 8, 3], state: "minecraft:air"},
        {pos: [12, 8, 4], state: "minecraft:air"},
        {pos: [12, 8, 5], state: "minecraft:air"},
        {pos: [12, 8, 6], state: "minecraft:air"},
        {pos: [12, 8, 7], state: "minecraft:air"},
        {pos: [12, 8, 8], state: "minecraft:air"},
        {pos: [12, 8, 9], state: "minecraft:air"},
        {pos: [12, 8, 10], state: "minecraft:air"},
        {pos: [13, 8, 0], state: "minecraft:air"},
        {pos: [13, 8, 1], state: "minecraft:air"},
        {pos: [13, 8, 2], state: "minecraft:air"},
        {pos: [13, 8, 3], state: "minecraft:air"},
        {pos: [13, 8, 4], state: "minecraft:air"},
        {pos: [13, 8, 5], state: "minecraft:air"},
        {pos: [13, 8, 6], state: "minecraft:air"},
        {pos: [13, 8, 7], state: "minecraft:air"},
        {pos: [13, 8, 8], state: "minecraft:air"},
        {pos: [13, 8, 9], state: "minecraft:air"},
        {pos: [13, 8, 10], state: "minecraft:air"},
        {pos: [14, 8, 0], state: "minecraft:air"},
        {pos: [14, 8, 1], state: "minecraft:air"},
        {pos: [14, 8, 2], state: "minecraft:air"},
        {pos: [14, 8, 3], state: "minecraft:air"},
        {pos: [14, 8, 4], state: "minecraft:air"},
        {pos: [14, 8, 5], state: "minecraft:air"},
        {pos: [14, 8, 6], state: "minecraft:air"},
        {pos: [14, 8, 7], state: "minecraft:air"},
        {pos: [14, 8, 8], state: "minecraft:air"},
        {pos: [14, 8, 9], state: "minecraft:air"},
        {pos: [14, 8, 10], state: "minecraft:air"},
        {pos: [15, 8, 0], state: "minecraft:air"},
        {pos: [15, 8, 1], state: "minecraft:air"},
        {pos: [15, 8, 2], state: "minecraft:air"},
        {pos: [15, 8, 3], state: "minecraft:air"},
        {pos: [15, 8, 4], state: "minecraft:air"},
        {pos: [15, 8, 5], state: "minecraft:air"},
        {pos: [15, 8, 6], state: "minecraft:air"},
        {pos: [15, 8, 7], state: "minecraft:air"},
        {pos: [15, 8, 8], state: "minecraft:air"},
        {pos: [15, 8, 9], state: "minecraft:air"},
        {pos: [15, 8, 10], state: "minecraft:air"},
        {pos: [16, 8, 0], state: "minecraft:air"},
        {pos: [16, 8, 1], state: "minecraft:air"},
        {pos: [16, 8, 2], state: "minecraft:air"},
        {pos: [16, 8, 3], state: "minecraft:air"},
        {pos: [16, 8, 4], state: "minecraft:air"},
        {pos: [16, 8, 5], state: "minecraft:air"},
        {pos: [16, 8, 6], state: "minecraft:air"},
        {pos: [16, 8, 7], state: "minecraft:air"},
        {pos: [16, 8, 8], state: "minecraft:air"},
        {pos: [16, 8, 9], state: "minecraft:air"},
        {pos: [16, 8, 10], state: "minecraft:air"},
        {pos: [17, 8, 0], state: "minecraft:air"},
        {pos: [17, 8, 1], state: "minecraft:air"},
        {pos: [17, 8, 2], state: "minecraft:air"},
        {pos: [17, 8, 3], state: "minecraft:air"},
        {pos: [17, 8, 4], state: "minecraft:air"},
        {pos: [17, 8, 5], state: "minecraft:air"},
        {pos: [17, 8, 6], state: "minecraft:air"},
        {pos: [17, 8, 7], state: "minecraft:air"},
        {pos: [17, 8, 8], state: "minecraft:air"},
        {pos: [17, 8, 9], state: "minecraft:air"},
        {pos: [17, 8, 10], state: "minecraft:air"},
        {pos: [18, 8, 0], state: "minecraft:air"},
        {pos: [18, 8, 1], state: "minecraft:air"},
        {pos: [18, 8, 2], state: "minecraft:air"},
        {pos: [18, 8, 3], state: "minecraft:air"},
        {pos: [18, 8, 4], state: "minecraft:air"},
        {pos: [18, 8, 5], state: "minecraft:air"},
        {pos: [18, 8, 6], state: "minecraft:air"},
        {pos: [18, 8, 7], state: "minecraft:air"},
        {pos: [18, 8, 8], state: "minecraft:air"},
        {pos: [18, 8, 9], state: "minecraft:air"},
        {pos: [18, 8, 10], state: "minecraft:air"}
    ],
    entities: [],
    palette: [
        "minecraft:cobblestone",
        "minecraft:gravel",
        "minecraft:green_glazed_terracotta{facing:north}",
        "minecraft:gray_glazed_terracotta{facing:east}",
        "minecraft:chiseled_stone_bricks",
        "minecraft:cobblestone_stairs{facing:west,half:top,shape:straight,waterlogged:false}",
        "minecraft:cobblestone_stairs{facing:south,half:top,shape:straight,waterlogged:false}",
        "minecraft:cobblestone_stairs{facing:east,half:top,shape:straight,waterlogged:false}",
        "minecraft:air"
    ],
    trailiertales_DataVersion: 2
}
