{
    DataVersion: 3953,
    size: [11, 8, 10],
    data: [
        {pos: [0, 0, 0], state: "minecraft:sand"},
        {pos: [0, 0, 1], state: "minecraft:sand"},
        {pos: [0, 0, 2], state: "minecraft:sand"},
        {pos: [0, 0, 3], state: "minecraft:sand"},
        {pos: [1, 0, 0], state: "minecraft:sand"},
        {pos: [1, 0, 1], state: "minecraft:sandstone"},
        {pos: [1, 0, 2], state: "minecraft:sandstone"},
        {pos: [1, 0, 3], state: "minecraft:sandstone"},
        {pos: [1, 0, 4], state: "minecraft:sandstone"},
        {pos: [1, 0, 5], state: "minecraft:sand"},
        {pos: [1, 0, 6], state: "minecraft:sand"},
        {pos: [2, 0, 0], state: "minecraft:sand"},
        {pos: [2, 0, 1], state: "minecraft:sandstone"},
        {pos: [2, 0, 2], state: "minecraft:sandstone"},
        {pos: [2, 0, 3], state: "minecraft:sandstone"},
        {pos: [2, 0, 4], state: "minecraft:sandstone"},
        {pos: [2, 0, 5], state: "minecraft:sandstone"},
        {pos: [2, 0, 6], state: "minecraft:sandstone"},
        {pos: [2, 0, 7], state: "minecraft:sand"},
        {pos: [3, 0, 1], state: "minecraft:sand"},
        {pos: [3, 0, 2], state: "minecraft:sand"},
        {pos: [3, 0, 3], state: "minecraft:sandstone"},
        {pos: [3, 0, 4], state: "minecraft:sandstone"},
        {pos: [3, 0, 5], state: "minecraft:sandstone"},
        {pos: [3, 0, 6], state: "minecraft:sandstone"},
        {pos: [3, 0, 7], state: "minecraft:sandstone"},
        {pos: [3, 0, 8], state: "minecraft:sand"},
        {pos: [4, 0, 3], state: "minecraft:sand"},
        {pos: [4, 0, 4], state: "minecraft:sandstone"},
        {pos: [4, 0, 5], state: "minecraft:sandstone"},
        {pos: [4, 0, 6], state: "minecraft:sandstone"},
        {pos: [4, 0, 7], state: "minecraft:sandstone"},
        {pos: [4, 0, 8], state: "minecraft:sand"},
        {pos: [5, 0, 3], state: "minecraft:sandstone"},
        {pos: [5, 0, 4], state: "minecraft:sandstone"},
        {pos: [5, 0, 5], state: "minecraft:sandstone"},
        {pos: [5, 0, 6], state: "minecraft:sandstone"},
        {pos: [5, 0, 7], state: "minecraft:sandstone"},
        {pos: [5, 0, 8], state: "minecraft:sand"},
        {pos: [6, 0, 2], state: "minecraft:sandstone"},
        {pos: [6, 0, 3], state: "minecraft:sandstone"},
        {pos: [6, 0, 4], state: "minecraft:sandstone"},
        {pos: [6, 0, 5], state: "minecraft:sandstone"},
        {pos: [6, 0, 6], state: "minecraft:sandstone"},
        {pos: [6, 0, 7], state: "minecraft:sandstone"},
        {pos: [7, 0, 1], state: "minecraft:sand"},
        {pos: [7, 0, 2], state: "minecraft:sandstone"},
        {pos: [7, 0, 3], state: "minecraft:sandstone"},
        {pos: [7, 0, 4], state: "minecraft:sandstone"},
        {pos: [7, 0, 5], state: "minecraft:sandstone"},
        {pos: [7, 0, 6], state: "minecraft:sandstone"},
        {pos: [7, 0, 7], state: "minecraft:sandstone"},
        {pos: [8, 0, 1], state: "minecraft:sand"},
        {pos: [8, 0, 2], state: "minecraft:sandstone"},
        {pos: [8, 0, 3], state: "minecraft:sandstone"},
        {pos: [8, 0, 4], state: "minecraft:sand"},
        {pos: [8, 0, 5], state: "minecraft:sand"},
        {pos: [8, 0, 6], state: "minecraft:sand"},
        {pos: [9, 0, 3], state: "minecraft:sand"},
        {pos: [9, 0, 4], state: "minecraft:sand"},
        {pos: [9, 0, 5], state: "minecraft:sand"},
        {pos: [0, 1, 1], state: "minecraft:sand"},
        {pos: [0, 1, 2], state: "minecraft:sand"},
        {pos: [0, 1, 3], state: "minecraft:sand"},
        {pos: [1, 1, 0], state: "minecraft:sand"},
        {pos: [1, 1, 1], state: "minecraft:sandstone"},
        {pos: [1, 1, 2], state: "minecraft:sandstone"},
        {pos: [1, 1, 3], state: "minecraft:sandstone"},
        {pos: [1, 1, 4], state: "minecraft:sandstone"},
        {pos: [1, 1, 5], state: "minecraft:sand"},
        {pos: [2, 1, 0], state: "minecraft:sand"},
        {pos: [2, 1, 1], state: "minecraft:sandstone"},
        {pos: [2, 1, 2], state: "minecraft:sandstone"},
        {pos: [2, 1, 3], state: "minecraft:sandstone"},
        {pos: [2, 1, 4], state: "minecraft:sandstone"},
        {pos: [2, 1, 5], state: "minecraft:sandstone"},
        {pos: [2, 1, 6], state: "minecraft:sandstone"},
        {pos: [3, 1, 1], state: "minecraft:sand"},
        {pos: [3, 1, 2], state: "minecraft:sand"},
        {pos: [3, 1, 3], state: "minecraft:sand"},
        {pos: [3, 1, 4], state: "minecraft:sand"},
        {pos: [3, 1, 5], state: "minecraft:sand"},
        {pos: [3, 1, 6], state: "minecraft:sand"},
        {pos: [3, 1, 7], state: "minecraft:sandstone"},
        {pos: [4, 1, 3], state: "minecraft:sand"},
        {pos: [4, 1, 4], state: "minecraft:sand"},
        {pos: [4, 1, 5], state: "minecraft:sand"},
        {pos: [4, 1, 6], state: "minecraft:sandstone_stairs{facing:south,half:top,shape:straight,waterlogged:false}"},
        {pos: [4, 1, 7], state: "minecraft:sandstone"},
        {pos: [4, 1, 8], state: "minecraft:sand"},
        {pos: [5, 1, 3], state: "minecraft:sand"},
        {pos: [5, 1, 4], state: "minecraft:sand"},
        {pos: [5, 1, 5], state: "minecraft:sand"},
        {pos: [5, 1, 6], state: "minecraft:sandstone_stairs{facing:south,half:top,shape:straight,waterlogged:false}"},
        {pos: [5, 1, 7], state: "minecraft:sandstone"},
        {pos: [6, 1, 2], state: "minecraft:sand"},
        {pos: [6, 1, 3], state: "minecraft:sand"},
        {pos: [6, 1, 4], state: "minecraft:sand"},
        {pos: [6, 1, 5], state: "minecraft:sand"},
        {pos: [6, 1, 6], state: "minecraft:sand"},
        {pos: [6, 1, 7], state: "minecraft:sandstone"},
        {pos: [7, 1, 1], state: "minecraft:sand"},
        {pos: [7, 1, 2], state: "minecraft:sandstone"},
        {pos: [7, 1, 3], state: "minecraft:sandstone"},
        {pos: [7, 1, 4], state: "minecraft:sandstone"},
        {pos: [7, 1, 5], state: "minecraft:sandstone"},
        {pos: [7, 1, 6], state: "minecraft:sandstone"},
        {pos: [7, 1, 7], state: "minecraft:sandstone"},
        {pos: [8, 1, 1], state: "minecraft:sand"},
        {pos: [8, 1, 2], state: "minecraft:sandstone"},
        {pos: [8, 1, 3], state: "minecraft:sandstone"},
        {pos: [8, 1, 4], state: "minecraft:sand"},
        {pos: [8, 1, 5], state: "minecraft:sand"},
        {pos: [8, 1, 6], state: "minecraft:sand"},
        {pos: [9, 1, 3], state: "minecraft:sand"},
        {pos: [9, 1, 4], state: "minecraft:sand"},
        {pos: [9, 1, 5], state: "minecraft:sand"},
        {pos: [0, 2, 1], state: "minecraft:sand"},
        {pos: [0, 2, 2], state: "minecraft:sand"},
        {pos: [1, 2, 0], state: "minecraft:sand"},
        {pos: [1, 2, 1], state: "minecraft:sandstone"},
        {pos: [1, 2, 2], state: "minecraft:smooth_sandstone"},
        {pos: [1, 2, 3], state: "minecraft:sandstone"},
        {pos: [1, 2, 4], state: "minecraft:sand"},
        {pos: [2, 2, 0], state: "minecraft:sand"},
        {pos: [2, 2, 1], state: "minecraft:smooth_sandstone"},
        {pos: [2, 2, 2], state: "minecraft:sandstone"},
        {pos: [2, 2, 3], state: "minecraft:sandstone"},
        {pos: [2, 2, 4], state: "minecraft:sandstone"},
        {pos: [2, 2, 5], state: "minecraft:smooth_sandstone"},
        {pos: [2, 2, 6], state: "minecraft:smooth_sandstone"},
        {pos: [3, 2, 1], state: "minecraft:sand"},
        {pos: [3, 2, 2], state: "minecraft:sand"},
        {pos: [3, 2, 3], state: "minecraft:sand"},
        {pos: [3, 2, 4], state: "minecraft:sand"},
        {pos: [3, 2, 5], state: "minecraft:sand"},
        {pos: [3, 2, 6], state: "minecraft:sand"},
        {pos: [3, 2, 7], state: "minecraft:smooth_sandstone"},
        {pos: [4, 2, 3], state: "minecraft:sand"},
        {pos: [4, 2, 4], state: "minecraft:sand"},
        {pos: [4, 2, 5], state: "minecraft:sand"},
        {pos: [4, 2, 6], state: "minecraft:sand"},
        {pos: [4, 2, 7], state: "minecraft:sandstone"},
        {pos: [5, 2, 3], state: "minecraft:sand"},
        {pos: [5, 2, 4], state: "minecraft:sand"},
        {pos: [5, 2, 5], state: "minecraft:sand"},
        {pos: [5, 2, 6], state: "minecraft:sand"},
        {pos: [5, 2, 7], state: "minecraft:smooth_sandstone"},
        {pos: [6, 2, 2], state: "minecraft:sand"},
        {pos: [6, 2, 3], state: "minecraft:sand"},
        {pos: [6, 2, 4], state: "minecraft:sand"},
        {pos: [6, 2, 5], state: "minecraft:sand"},
        {pos: [6, 2, 6], state: "minecraft:sand"},
        {pos: [6, 2, 7], state: "minecraft:smooth_sandstone"},
        {pos: [7, 2, 1], state: "minecraft:sand"},
        {pos: [7, 2, 2], state: "minecraft:sandstone"},
        {pos: [7, 2, 3], state: "minecraft:smooth_sandstone"},
        {pos: [7, 2, 4], state: "minecraft:sand"},
        {pos: [7, 2, 5], state: "minecraft:sandstone"},
        {pos: [7, 2, 6], state: "minecraft:smooth_sandstone"},
        {pos: [7, 2, 7], state: "minecraft:smooth_sandstone"},
        {pos: [8, 2, 2], state: "minecraft:sandstone"},
        {pos: [8, 2, 3], state: "minecraft:smooth_sandstone"},
        {pos: [8, 2, 4], state: "minecraft:sand"},
        {pos: [8, 2, 5], state: "minecraft:sand"},
        {pos: [8, 2, 6], state: "minecraft:sand"},
        {pos: [9, 2, 3], state: "minecraft:sand"},
        {pos: [9, 2, 4], state: "minecraft:sand"},
        {pos: [9, 2, 5], state: "minecraft:sand"},
        {pos: [0, 3, 2], state: "minecraft:sand"},
        {pos: [1, 3, 1], state: "minecraft:sandstone"},
        {pos: [1, 3, 2], state: "minecraft:smooth_sandstone"},
        {pos: [1, 3, 3], state: "minecraft:sand"},
        {pos: [1, 3, 4], state: "minecraft:sand"},
        {pos: [2, 3, 1], state: "minecraft:smooth_sandstone"},
        {pos: [2, 3, 2], state: "minecraft:smooth_sandstone"},
        {pos: [2, 3, 3], state: "minecraft:smooth_sandstone"},
        {pos: [2, 3, 4], state: "minecraft:smooth_sandstone"},
        {pos: [2, 3, 5], state: "minecraft:smooth_sandstone"},
        {pos: [2, 3, 6], state: "minecraft:smooth_sandstone"},
        {pos: [3, 3, 2], state: "minecraft:sand"},
        {pos: [3, 3, 3], state: "minecraft:sand"},
        {pos: [3, 3, 4], state: "minecraft:sand"},
        {pos: [3, 3, 5], state: "minecraft:sand"},
        {pos: [3, 3, 6], state: "minecraft:sand"},
        {pos: [3, 3, 7], state: "minecraft:smooth_sandstone"},
        {pos: [4, 3, 4], state: "minecraft:sand"},
        {pos: [4, 3, 5], state: "minecraft:sand"},
        {pos: [4, 3, 6], state: "minecraft:sand"},
        {pos: [4, 3, 7], state: "minecraft:smooth_sandstone"},
        {pos: [5, 3, 3], state: "minecraft:sand"},
        {pos: [5, 3, 4], state: "minecraft:sand"},
        {pos: [5, 3, 5], state: "minecraft:sand"},
        {pos: [5, 3, 6], state: "minecraft:sand"},
        {pos: [5, 3, 7], state: "minecraft:smooth_sandstone"},
        {pos: [6, 3, 2], state: "minecraft:sand"},
        {pos: [6, 3, 3], state: "minecraft:sand"},
        {pos: [6, 3, 4], state: "minecraft:sand"},
        {pos: [6, 3, 5], state: "minecraft:sand"},
        {pos: [6, 3, 6], state: "minecraft:sand"},
        {pos: [6, 3, 7], state: "minecraft:smooth_sandstone"},
        {pos: [7, 3, 2], state: "minecraft:sandstone"},
        {pos: [7, 3, 3], state: "minecraft:smooth_sandstone"},
        {pos: [7, 3, 4], state: "minecraft:smooth_sandstone"},
        {pos: [7, 3, 5], state: "minecraft:smooth_sandstone"},
        {pos: [7, 3, 6], state: "minecraft:smooth_sandstone"},
        {pos: [8, 3, 2], state: "minecraft:smooth_sandstone"},
        {pos: [8, 3, 3], state: "minecraft:smooth_sandstone"},
        {pos: [8, 3, 4], state: "minecraft:sand"},
        {pos: [8, 3, 5], state: "minecraft:sand"},
        {pos: [8, 3, 6], state: "minecraft:sand"},
        {pos: [9, 3, 3], state: "minecraft:sand"},
        {pos: [9, 3, 4], state: "minecraft:sand"},
        {pos: [1, 4, 1], state: "minecraft:smooth_sandstone"},
        {pos: [1, 4, 2], state: "minecraft:smooth_sandstone"},
        {pos: [1, 4, 3], state: "minecraft:sand"},
        {pos: [1, 4, 4], state: "minecraft:sand"},
        {pos: [2, 4, 1], state: "minecraft:smooth_sandstone"},
        {pos: [2, 4, 2], state: "minecraft:smooth_sandstone"},
        {pos: [2, 4, 3], state: "minecraft:cut_sandstone"},
        {pos: [2, 4, 4], state: "minecraft:cut_sandstone"},
        {pos: [2, 4, 5], state: "minecraft:cut_sandstone"},
        {pos: [2, 4, 6], state: "minecraft:cut_sandstone"},
        {pos: [3, 4, 3], state: "minecraft:sand"},
        {pos: [3, 4, 4], state: "minecraft:sand"},
        {pos: [3, 4, 5], state: "minecraft:sand"},
        {pos: [3, 4, 6], state: "minecraft:sand"},
        {pos: [3, 4, 7], state: "minecraft:cut_sandstone"},
        {pos: [4, 4, 5], state: "minecraft:sand"},
        {pos: [4, 4, 6], state: "minecraft:sand"},
        {pos: [4, 4, 7], state: "minecraft:cut_sandstone"},
        {pos: [5, 4, 4], state: "minecraft:sand"},
        {pos: [5, 4, 5], state: "minecraft:sand"},
        {pos: [5, 4, 6], state: "minecraft:sand"},
        {pos: [5, 4, 7], state: "minecraft:cut_sandstone"},
        {pos: [6, 4, 4], state: "minecraft:sand"},
        {pos: [6, 4, 5], state: "minecraft:sand"},
        {pos: [6, 4, 6], state: "minecraft:sand"},
        {pos: [7, 4, 2], state: "minecraft:smooth_sandstone"},
        {pos: [7, 4, 3], state: "minecraft:smooth_sandstone"},
        {pos: [7, 4, 4], state: "minecraft:cut_sandstone"},
        {pos: [7, 4, 5], state: "minecraft:cut_sandstone"},
        {pos: [7, 4, 6], state: "minecraft:cut_sandstone"},
        {pos: [8, 4, 2], state: "minecraft:smooth_sandstone"},
        {pos: [8, 4, 3], state: "minecraft:sandstone"},
        {pos: [8, 4, 4], state: "minecraft:sand"},
        {pos: [8, 4, 5], state: "minecraft:sand"},
        {pos: [1, 5, 1], state: "minecraft:smooth_sandstone"},
        {pos: [1, 5, 2], state: "minecraft:sandstone"},
        {pos: [1, 5, 3], state: "minecraft:sand"},
        {pos: [2, 5, 1], state: "minecraft:smooth_sandstone"},
        {pos: [2, 5, 2], state: "minecraft:smooth_sandstone"},
        {pos: [2, 5, 3], state: "minecraft:sand"},
        {pos: [2, 5, 4], state: "minecraft:sand"},
        {pos: [2, 5, 5], state: "minecraft:sand"},
        {pos: [3, 5, 3], state: "minecraft:sand"},
        {pos: [3, 5, 4], state: "minecraft:sand"},
        {pos: [6, 5, 4], state: "minecraft:sand"},
        {pos: [6, 5, 5], state: "minecraft:sand"},
        {pos: [7, 5, 2], state: "minecraft:cut_sandstone"},
        {pos: [7, 5, 3], state: "minecraft:cut_sandstone"},
        {pos: [7, 5, 4], state: "minecraft:sand"},
        {pos: [7, 5, 5], state: "minecraft:sand"},
        {pos: [8, 5, 2], state: "minecraft:cut_sandstone"},
        {pos: [8, 5, 3], state: "minecraft:cut_sandstone"},
        {pos: [1, 6, 1], state: "minecraft:sandstone"},
        {pos: [1, 6, 2], state: "minecraft:sandstone"},
        {pos: [2, 6, 1], state: "minecraft:smooth_sandstone"},
        {pos: [2, 6, 2], state: "minecraft:sandstone"},
        {pos: [2, 6, 3], state: "minecraft:sand"},
        {pos: [1, 7, 1], state: "minecraft:cut_sandstone"},
        {pos: [1, 7, 2], state: "minecraft:cut_sandstone"},
        {pos: [2, 7, 1], state: "minecraft:cut_sandstone"},
        {pos: [2, 7, 2], state: "minecraft:cut_sandstone"}
    ],
    entities: [],
    palette: [
        "minecraft:sand",
        "minecraft:sandstone",
        "minecraft:smooth_sandstone",
        "minecraft:cut_sandstone",
        "minecraft:sandstone_stairs{facing:south,half:top,shape:straight,waterlogged:false}"
    ],
    trailiertales_DataVersion: 2
}
