{
    DataVersion: 3953,
    size: [5, 4, 5],
    data: [
        {pos: [0, 0, 0], state: "minecraft:deepslate_bricks"},
        {pos: [0, 0, 1], state: "minecraft:deepslate_bricks"},
        {pos: [0, 0, 2], state: "minecraft:deepslate_bricks"},
        {pos: [0, 0, 3], state: "minecraft:deepslate_bricks"},
        {pos: [0, 0, 4], state: "minecraft:deepslate_bricks"},
        {pos: [1, 0, 0], state: "minecraft:deepslate_bricks"},
        {pos: [1, 0, 1], state: "minecraft:cave_air"},
        {pos: [1, 0, 2], state: "minecraft:cave_air"},
        {pos: [1, 0, 3], state: "minecraft:cave_air"},
        {pos: [1, 0, 4], state: "minecraft:deepslate_bricks"},
        {pos: [2, 0, 0], state: "minecraft:deepslate_bricks"},
        {pos: [2, 0, 1], state: "minecraft:deepslate_tile_stairs{facing:east,half:bottom,shape:straight,waterlogged:false}"},
        {pos: [2, 0, 2], state: "minecraft:jigsaw{orientation:down_north}", nbt: {final_state: "minecraft:cave_air", id: "minecraft:jigsaw", joint: "aligned", name: "trailiertales:staircase_bottom", placement_priority: 1, pool: "trailiertales:catacombs/staircase_down", selection_priority: 1, target: "trailiertales:staircase_top"}},
        {pos: [2, 0, 3], state: "minecraft:cave_air"},
        {pos: [2, 0, 4], state: "minecraft:deepslate_bricks"},
        {pos: [3, 0, 0], state: "minecraft:deepslate_bricks"},
        {pos: [3, 0, 1], state: "minecraft:deepslate_tiles"},
        {pos: [3, 0, 2], state: "minecraft:deepslate_tile_stairs{facing:north,half:top,shape:straight,waterlogged:false}"},
        {pos: [3, 0, 3], state: "minecraft:cave_air"},
        {pos: [3, 0, 4], state: "minecraft:deepslate_bricks"},
        {pos: [4, 0, 0], state: "minecraft:deepslate_bricks"},
        {pos: [4, 0, 1], state: "minecraft:deepslate_bricks"},
        {pos: [4, 0, 2], state: "minecraft:deepslate_bricks"},
        {pos: [4, 0, 3], state: "minecraft:deepslate_bricks"},
        {pos: [4, 0, 4], state: "minecraft:deepslate_bricks"},
        {pos: [0, 1, 0], state: "minecraft:deepslate_bricks"},
        {pos: [0, 1, 1], state: "minecraft:deepslate_bricks"},
        {pos: [0, 1, 2], state: "minecraft:deepslate_bricks"},
        {pos: [0, 1, 3], state: "minecraft:deepslate_bricks"},
        {pos: [0, 1, 4], state: "minecraft:deepslate_bricks"},
        {pos: [1, 1, 0], state: "minecraft:deepslate_bricks"},
        {pos: [1, 1, 1], state: "minecraft:cave_air"},
        {pos: [1, 1, 2], state: "minecraft:cave_air"},
        {pos: [1, 1, 3], state: "minecraft:cave_air"},
        {pos: [1, 1, 4], state: "minecraft:deepslate_bricks"},
        {pos: [2, 1, 0], state: "minecraft:deepslate_bricks"},
        {pos: [2, 1, 1], state: "minecraft:cave_air"},
        {pos: [2, 1, 2], state: "minecraft:cave_air"},
        {pos: [2, 1, 3], state: "minecraft:deepslate_tile_stairs{facing:east,half:top,shape:straight,waterlogged:false}"},
        {pos: [2, 1, 4], state: "minecraft:deepslate_bricks"},
        {pos: [3, 1, 0], state: "minecraft:deepslate_bricks"},
        {pos: [3, 1, 1], state: "minecraft:cave_air"},
        {pos: [3, 1, 2], state: "minecraft:deepslate_tile_stairs{facing:south,half:bottom,shape:straight,waterlogged:false}"},
        {pos: [3, 1, 3], state: "minecraft:deepslate_tiles"},
        {pos: [3, 1, 4], state: "minecraft:deepslate_bricks"},
        {pos: [4, 1, 0], state: "minecraft:deepslate_bricks"},
        {pos: [4, 1, 1], state: "minecraft:deepslate_bricks"},
        {pos: [4, 1, 2], state: "minecraft:deepslate_bricks"},
        {pos: [4, 1, 3], state: "minecraft:deepslate_bricks"},
        {pos: [4, 1, 4], state: "minecraft:deepslate_bricks"},
        {pos: [0, 2, 0], state: "minecraft:deepslate_bricks"},
        {pos: [0, 2, 1], state: "minecraft:deepslate_bricks"},
        {pos: [0, 2, 2], state: "minecraft:deepslate_bricks"},
        {pos: [0, 2, 3], state: "minecraft:deepslate_bricks"},
        {pos: [0, 2, 4], state: "minecraft:deepslate_bricks"},
        {pos: [1, 2, 0], state: "minecraft:deepslate_bricks"},
        {pos: [1, 2, 1], state: "minecraft:cave_air"},
        {pos: [1, 2, 2], state: "minecraft:deepslate_tile_stairs{facing:south,half:top,shape:straight,waterlogged:false}"},
        {pos: [1, 2, 3], state: "minecraft:deepslate_tiles"},
        {pos: [1, 2, 4], state: "minecraft:deepslate_bricks"},
        {pos: [2, 2, 0], state: "minecraft:deepslate_bricks"},
        {pos: [2, 2, 1], state: "minecraft:cave_air"},
        {pos: [2, 2, 2], state: "minecraft:cave_air"},
        {pos: [2, 2, 3], state: "minecraft:deepslate_tile_stairs{facing:west,half:bottom,shape:straight,waterlogged:false}"},
        {pos: [2, 2, 4], state: "minecraft:deepslate_bricks"},
        {pos: [3, 2, 0], state: "minecraft:deepslate_bricks"},
        {pos: [3, 2, 1], state: "minecraft:cave_air"},
        {pos: [3, 2, 2], state: "minecraft:cave_air"},
        {pos: [3, 2, 3], state: "minecraft:cave_air"},
        {pos: [3, 2, 4], state: "minecraft:deepslate_bricks"},
        {pos: [4, 2, 0], state: "minecraft:deepslate_bricks"},
        {pos: [4, 2, 1], state: "minecraft:deepslate_bricks"},
        {pos: [4, 2, 2], state: "minecraft:deepslate_bricks"},
        {pos: [4, 2, 3], state: "minecraft:deepslate_bricks"},
        {pos: [4, 2, 4], state: "minecraft:deepslate_bricks"},
        {pos: [0, 3, 0], state: "minecraft:deepslate_bricks"},
        {pos: [0, 3, 1], state: "minecraft:deepslate_bricks"},
        {pos: [0, 3, 2], state: "minecraft:deepslate_bricks"},
        {pos: [0, 3, 3], state: "minecraft:deepslate_bricks"},
        {pos: [0, 3, 4], state: "minecraft:deepslate_bricks"},
        {pos: [1, 3, 0], state: "minecraft:deepslate_bricks"},
        {pos: [1, 3, 1], state: "minecraft:deepslate_tiles"},
        {pos: [1, 3, 2], state: "minecraft:deepslate_tile_stairs{facing:north,half:bottom,shape:straight,waterlogged:false}"},
        {pos: [1, 3, 3], state: "minecraft:cave_air"},
        {pos: [1, 3, 4], state: "minecraft:deepslate_bricks"},
        {pos: [2, 3, 0], state: "minecraft:deepslate_bricks"},
        {pos: [2, 3, 1], state: "minecraft:deepslate_tile_stairs{facing:west,half:top,shape:straight,waterlogged:false}"},
        {pos: [2, 3, 2], state: "minecraft:jigsaw{orientation:up_north}", nbt: {final_state: "minecraft:cave_air", id: "minecraft:jigsaw", joint: "aligned", name: "trailiertales:staircase_top", placement_priority: 1, pool: "trailiertales:catacombs/staircase_up", selection_priority: 1, target: "trailiertales:staircase_bottom"}},
        {pos: [2, 3, 3], state: "minecraft:cave_air"},
        {pos: [2, 3, 4], state: "minecraft:deepslate_bricks"},
        {pos: [3, 3, 0], state: "minecraft:deepslate_bricks"},
        {pos: [3, 3, 1], state: "minecraft:cave_air"},
        {pos: [3, 3, 2], state: "minecraft:cave_air"},
        {pos: [3, 3, 3], state: "minecraft:cave_air"},
        {pos: [3, 3, 4], state: "minecraft:deepslate_bricks"},
        {pos: [4, 3, 0], state: "minecraft:deepslate_bricks"},
        {pos: [4, 3, 1], state: "minecraft:deepslate_bricks"},
        {pos: [4, 3, 2], state: "minecraft:deepslate_bricks"},
        {pos: [4, 3, 3], state: "minecraft:deepslate_bricks"},
        {pos: [4, 3, 4], state: "minecraft:deepslate_bricks"}
    ],
    entities: [],
    palette: [
        "minecraft:deepslate_bricks",
        "minecraft:deepslate_tiles",
        "minecraft:cave_air",
        "minecraft:deepslate_tile_stairs{facing:east,half:bottom,shape:straight,waterlogged:false}",
        "minecraft:deepslate_tile_stairs{facing:north,half:top,shape:straight,waterlogged:false}",
        "minecraft:deepslate_tile_stairs{facing:east,half:top,shape:straight,waterlogged:false}",
        "minecraft:deepslate_tile_stairs{facing:south,half:bottom,shape:straight,waterlogged:false}",
        "minecraft:deepslate_tile_stairs{facing:south,half:top,shape:straight,waterlogged:false}",
        "minecraft:deepslate_tile_stairs{facing:west,half:bottom,shape:straight,waterlogged:false}",
        "minecraft:deepslate_tile_stairs{facing:north,half:bottom,shape:straight,waterlogged:false}",
        "minecraft:deepslate_tile_stairs{facing:west,half:top,shape:straight,waterlogged:false}",
        "minecraft:jigsaw{orientation:down_north}",
        "minecraft:jigsaw{orientation:up_north}"
    ],
    trailiertales_DataVersion: 3
}
