{
    DataVersion: 3953,
    size: [17, 11, 7],
    data: [
        {pos: [0, 0, 2], state: "minecraft:sand"},
        {pos: [0, 0, 3], state: "minecraft:sand"},
        {pos: [0, 0, 4], state: "minecraft:sand"},
        {pos: [1, 0, 1], state: "minecraft:sand"},
        {pos: [1, 0, 2], state: "minecraft:sand"},
        {pos: [1, 0, 3], state: "minecraft:sand"},
        {pos: [1, 0, 4], state: "minecraft:sand"},
        {pos: [1, 0, 5], state: "minecraft:sand"},
        {pos: [2, 0, 0], state: "minecraft:sand"},
        {pos: [2, 0, 1], state: "minecraft:sand"},
        {pos: [2, 0, 2], state: "minecraft:sandstone"},
        {pos: [2, 0, 3], state: "minecraft:sandstone"},
        {pos: [2, 0, 4], state: "minecraft:sandstone"},
        {pos: [2, 0, 5], state: "minecraft:sand"},
        {pos: [2, 0, 6], state: "minecraft:sand"},
        {pos: [3, 0, 0], state: "minecraft:sand"},
        {pos: [3, 0, 1], state: "minecraft:sand"},
        {pos: [3, 0, 2], state: "minecraft:sandstone"},
        {pos: [3, 0, 3], state: "minecraft:smooth_sandstone"},
        {pos: [3, 0, 4], state: "minecraft:sandstone"},
        {pos: [3, 0, 5], state: "minecraft:sand"},
        {pos: [3, 0, 6], state: "minecraft:sand"},
        {pos: [4, 0, 0], state: "minecraft:sand"},
        {pos: [4, 0, 1], state: "minecraft:sand"},
        {pos: [4, 0, 2], state: "minecraft:sandstone"},
        {pos: [4, 0, 3], state: "minecraft:sandstone"},
        {pos: [4, 0, 4], state: "minecraft:sandstone"},
        {pos: [4, 0, 5], state: "minecraft:sand"},
        {pos: [4, 0, 6], state: "minecraft:sand"},
        {pos: [5, 0, 1], state: "minecraft:sand"},
        {pos: [5, 0, 2], state: "minecraft:sand"},
        {pos: [5, 0, 3], state: "minecraft:sand"},
        {pos: [5, 0, 4], state: "minecraft:sand"},
        {pos: [5, 0, 5], state: "minecraft:sand"},
        {pos: [6, 0, 2], state: "minecraft:sand"},
        {pos: [6, 0, 3], state: "minecraft:sand"},
        {pos: [6, 0, 4], state: "minecraft:sand"},
        {pos: [9, 0, 2], state: "minecraft:sand"},
        {pos: [9, 0, 3], state: "minecraft:sand"},
        {pos: [10, 0, 1], state: "minecraft:sand"},
        {pos: [10, 0, 2], state: "minecraft:sand"},
        {pos: [10, 0, 3], state: "minecraft:sand"},
        {pos: [10, 0, 4], state: "minecraft:sand"},
        {pos: [11, 0, 0], state: "minecraft:sand"},
        {pos: [11, 0, 1], state: "minecraft:sand"},
        {pos: [11, 0, 2], state: "minecraft:sand"},
        {pos: [11, 0, 3], state: "minecraft:sand"},
        {pos: [11, 0, 4], state: "minecraft:sand"},
        {pos: [11, 0, 5], state: "minecraft:sand"},
        {pos: [12, 0, 0], state: "minecraft:sand"},
        {pos: [12, 0, 1], state: "minecraft:sand"},
        {pos: [12, 0, 2], state: "minecraft:sandstone"},
        {pos: [12, 0, 3], state: "minecraft:sandstone"},
        {pos: [12, 0, 4], state: "minecraft:sandstone"},
        {pos: [12, 0, 5], state: "minecraft:sand"},
        {pos: [12, 0, 6], state: "minecraft:sand"},
        {pos: [13, 0, 0], state: "minecraft:sand"},
        {pos: [13, 0, 1], state: "minecraft:sand"},
        {pos: [13, 0, 2], state: "minecraft:sandstone"},
        {pos: [13, 0, 3], state: "minecraft:smooth_sandstone"},
        {pos: [13, 0, 4], state: "minecraft:sandstone"},
        {pos: [13, 0, 5], state: "minecraft:sand"},
        {pos: [13, 0, 6], state: "minecraft:sand"},
        {pos: [14, 0, 0], state: "minecraft:sand"},
        {pos: [14, 0, 1], state: "minecraft:sand"},
        {pos: [14, 0, 2], state: "minecraft:sandstone"},
        {pos: [14, 0, 3], state: "minecraft:sandstone"},
        {pos: [14, 0, 4], state: "minecraft:sandstone"},
        {pos: [14, 0, 5], state: "minecraft:sand"},
        {pos: [14, 0, 6], state: "minecraft:sand"},
        {pos: [15, 0, 1], state: "minecraft:sand"},
        {pos: [15, 0, 2], state: "minecraft:sand"},
        {pos: [15, 0, 3], state: "minecraft:sand"},
        {pos: [15, 0, 4], state: "minecraft:sand"},
        {pos: [15, 0, 5], state: "minecraft:sand"},
        {pos: [15, 0, 6], state: "minecraft:sand"},
        {pos: [16, 0, 2], state: "minecraft:sand"},
        {pos: [16, 0, 3], state: "minecraft:sand"},
        {pos: [16, 0, 4], state: "minecraft:sand"},
        {pos: [16, 0, 5], state: "minecraft:sand"},
        {pos: [1, 1, 2], state: "minecraft:sand"},
        {pos: [1, 1, 3], state: "minecraft:sand"},
        {pos: [1, 1, 4], state: "minecraft:sand"},
        {pos: [2, 1, 2], state: "minecraft:sandstone"},
        {pos: [2, 1, 3], state: "minecraft:sandstone"},
        {pos: [2, 1, 4], state: "minecraft:sandstone"},
        {pos: [2, 1, 5], state: "minecraft:sand"},
        {pos: [3, 1, 2], state: "minecraft:sandstone"},
        {pos: [3, 1, 3], state: "minecraft:smooth_sandstone"},
        {pos: [3, 1, 4], state: "minecraft:sandstone"},
        {pos: [3, 1, 5], state: "minecraft:sand"},
        {pos: [4, 1, 3], state: "minecraft:sandstone"},
        {pos: [4, 1, 4], state: "minecraft:sandstone"},
        {pos: [4, 1, 5], state: "minecraft:sand"},
        {pos: [5, 1, 3], state: "minecraft:sand"},
        {pos: [5, 1, 4], state: "minecraft:sand"},
        {pos: [5, 1, 5], state: "minecraft:sand"},
        {pos: [6, 1, 4], state: "minecraft:sand"},
        {pos: [10, 1, 2], state: "minecraft:sand"},
        {pos: [11, 1, 1], state: "minecraft:sand"},
        {pos: [11, 1, 2], state: "minecraft:sand"},
        {pos: [11, 1, 3], state: "minecraft:sand"},
        {pos: [11, 1, 4], state: "minecraft:sand"},
        {pos: [12, 1, 1], state: "minecraft:sand"},
        {pos: [12, 1, 2], state: "minecraft:sandstone"},
        {pos: [12, 1, 3], state: "minecraft:sandstone"},
        {pos: [12, 1, 4], state: "minecraft:sandstone"},
        {pos: [12, 1, 5], state: "minecraft:sand"},
        {pos: [13, 1, 0], state: "minecraft:sand"},
        {pos: [13, 1, 1], state: "minecraft:sand"},
        {pos: [13, 1, 2], state: "minecraft:sandstone"},
        {pos: [13, 1, 3], state: "minecraft:smooth_sandstone"},
        {pos: [13, 1, 4], state: "minecraft:sandstone"},
        {pos: [13, 1, 5], state: "minecraft:sand"},
        {pos: [14, 1, 1], state: "minecraft:sand"},
        {pos: [14, 1, 2], state: "minecraft:sandstone"},
        {pos: [14, 1, 3], state: "minecraft:sandstone"},
        {pos: [14, 1, 4], state: "minecraft:sandstone"},
        {pos: [14, 1, 5], state: "minecraft:sand"},
        {pos: [15, 1, 2], state: "minecraft:sand"},
        {pos: [15, 1, 3], state: "minecraft:sand"},
        {pos: [15, 1, 4], state: "minecraft:sand"},
        {pos: [2, 2, 2], state: "minecraft:smooth_sandstone"},
        {pos: [2, 2, 3], state: "minecraft:sandstone"},
        {pos: [2, 2, 4], state: "minecraft:smooth_sandstone"},
        {pos: [3, 2, 2], state: "minecraft:sand"},
        {pos: [3, 2, 3], state: "minecraft:sandstone"},
        {pos: [3, 2, 4], state: "minecraft:sandstone"},
        {pos: [4, 2, 3], state: "minecraft:smooth_sandstone"},
        {pos: [4, 2, 4], state: "minecraft:sandstone"},
        {pos: [5, 2, 3], state: "minecraft:sand"},
        {pos: [5, 2, 4], state: "minecraft:sand"},
        {pos: [12, 2, 2], state: "minecraft:sandstone"},
        {pos: [12, 2, 3], state: "minecraft:sandstone"},
        {pos: [12, 2, 4], state: "minecraft:smooth_sandstone"},
        {pos: [13, 2, 2], state: "minecraft:smooth_sandstone"},
        {pos: [13, 2, 3], state: "minecraft:smooth_sandstone"},
        {pos: [13, 2, 4], state: "minecraft:sandstone"},
        {pos: [13, 2, 5], state: "minecraft:sand"},
        {pos: [14, 2, 2], state: "minecraft:sand"},
        {pos: [14, 2, 3], state: "minecraft:sandstone"},
        {pos: [14, 2, 4], state: "minecraft:sandstone"},
        {pos: [14, 2, 5], state: "minecraft:sand"},
        {pos: [15, 2, 4], state: "minecraft:sand"},
        {pos: [2, 3, 2], state: "minecraft:smooth_sandstone"},
        {pos: [2, 3, 3], state: "minecraft:sandstone"},
        {pos: [3, 3, 3], state: "minecraft:sandstone"},
        {pos: [4, 3, 3], state: "minecraft:smooth_sandstone"},
        {pos: [4, 3, 4], state: "minecraft:smooth_sandstone"},
        {pos: [12, 3, 2], state: "minecraft:blue_terracotta"},
        {pos: [12, 3, 3], state: "minecraft:blue_terracotta"},
        {pos: [12, 3, 4], state: "minecraft:blue_terracotta"},
        {pos: [13, 3, 2], state: "minecraft:blue_terracotta"},
        {pos: [13, 3, 3], state: "minecraft:blue_terracotta"},
        {pos: [13, 3, 4], state: "minecraft:blue_terracotta"},
        {pos: [14, 3, 4], state: "minecraft:sand"},
        {pos: [2, 4, 2], state: "minecraft:blue_terracotta"},
        {pos: [2, 4, 3], state: "minecraft:blue_terracotta"},
        {pos: [3, 4, 2], state: "minecraft:blue_terracotta"},
        {pos: [3, 4, 3], state: "minecraft:blue_terracotta"},
        {pos: [3, 4, 4], state: "minecraft:chiseled_sandstone"},
        {pos: [4, 4, 3], state: "minecraft:blue_terracotta"},
        {pos: [4, 4, 4], state: "minecraft:blue_terracotta"},
        {pos: [12, 4, 2], state: "minecraft:chiseled_sandstone"},
        {pos: [12, 4, 3], state: "minecraft:chiseled_sandstone"},
        {pos: [12, 4, 4], state: "minecraft:chiseled_sandstone"},
        {pos: [13, 4, 2], state: "minecraft:chiseled_sandstone"},
        {pos: [13, 4, 3], state: "minecraft:chiseled_sandstone"},
        {pos: [13, 4, 4], state: "minecraft:chiseled_sandstone"},
        {pos: [2, 5, 2], state: "minecraft:chiseled_sandstone"},
        {pos: [2, 5, 3], state: "minecraft:chiseled_sandstone"},
        {pos: [2, 5, 4], state: "minecraft:chiseled_sandstone"},
        {pos: [3, 5, 2], state: "minecraft:chiseled_sandstone"},
        {pos: [3, 5, 3], state: "minecraft:sandstone"},
        {pos: [3, 5, 4], state: "minecraft:chiseled_sandstone"},
        {pos: [4, 5, 2], state: "minecraft:chiseled_sandstone"},
        {pos: [4, 5, 3], state: "minecraft:chiseled_sandstone"},
        {pos: [4, 5, 4], state: "minecraft:chiseled_sandstone"},
        {pos: [12, 5, 2], state: "minecraft:yellow_terracotta"},
        {pos: [12, 5, 3], state: "minecraft:yellow_terracotta"},
        {pos: [13, 5, 2], state: "minecraft:yellow_terracotta"},
        {pos: [13, 5, 3], state: "minecraft:yellow_terracotta"},
        {pos: [13, 5, 4], state: "minecraft:yellow_terracotta"},
        {pos: [14, 5, 2], state: "minecraft:yellow_terracotta"},
        {pos: [14, 5, 4], state: "minecraft:yellow_terracotta"},
        {pos: [2, 6, 2], state: "minecraft:yellow_terracotta"},
        {pos: [2, 6, 3], state: "minecraft:yellow_terracotta"},
        {pos: [2, 6, 4], state: "minecraft:yellow_terracotta"},
        {pos: [3, 6, 2], state: "minecraft:yellow_terracotta"},
        {pos: [3, 6, 3], state: "minecraft:smooth_sandstone"},
        {pos: [3, 6, 4], state: "minecraft:yellow_terracotta"},
        {pos: [4, 6, 2], state: "minecraft:yellow_terracotta"},
        {pos: [4, 6, 3], state: "minecraft:yellow_terracotta"},
        {pos: [5, 6, 2], state: "minecraft:yellow_terracotta"},
        {pos: [5, 6, 3], state: "minecraft:yellow_terracotta"},
        {pos: [11, 6, 3], state: "minecraft:sandstone"},
        {pos: [12, 6, 3], state: "minecraft:sandstone"},
        {pos: [12, 6, 4], state: "minecraft:smooth_sandstone"},
        {pos: [13, 6, 2], state: "minecraft:smooth_sandstone"},
        {pos: [13, 6, 3], state: "minecraft:smooth_sandstone"},
        {pos: [13, 6, 4], state: "minecraft:smooth_sandstone"},
        {pos: [14, 6, 2], state: "minecraft:smooth_sandstone"},
        {pos: [14, 6, 3], state: "minecraft:smooth_sandstone"},
        {pos: [14, 6, 4], state: "minecraft:smooth_sandstone"},
        {pos: [3, 7, 2], state: "minecraft:smooth_sandstone"},
        {pos: [3, 7, 3], state: "minecraft:smooth_sandstone"},
        {pos: [3, 7, 4], state: "minecraft:smooth_sandstone"},
        {pos: [4, 7, 2], state: "minecraft:smooth_sandstone"},
        {pos: [4, 7, 3], state: "minecraft:smooth_sandstone"},
        {pos: [4, 7, 4], state: "minecraft:smooth_sandstone"},
        {pos: [5, 7, 2], state: "minecraft:sandstone"},
        {pos: [5, 7, 3], state: "minecraft:sandstone"},
        {pos: [6, 7, 2], state: "minecraft:sandstone"},
        {pos: [6, 7, 3], state: "minecraft:sandstone"},
        {pos: [10, 7, 3], state: "minecraft:sandstone"},
        {pos: [11, 7, 3], state: "minecraft:sandstone"},
        {pos: [12, 7, 2], state: "minecraft:smooth_sandstone"},
        {pos: [12, 7, 3], state: "minecraft:smooth_sandstone"},
        {pos: [12, 7, 4], state: "minecraft:smooth_sandstone"},
        {pos: [13, 7, 2], state: "minecraft:smooth_sandstone"},
        {pos: [13, 7, 3], state: "minecraft:smooth_sandstone"},
        {pos: [13, 7, 4], state: "minecraft:smooth_sandstone"},
        {pos: [14, 7, 3], state: "minecraft:sand"},
        {pos: [14, 7, 4], state: "minecraft:sand"},
        {pos: [3, 8, 3], state: "minecraft:smooth_sandstone"},
        {pos: [3, 8, 4], state: "minecraft:smooth_sandstone"},
        {pos: [4, 8, 2], state: "minecraft:smooth_sandstone"},
        {pos: [4, 8, 3], state: "minecraft:smooth_sandstone"},
        {pos: [4, 8, 4], state: "minecraft:smooth_sandstone"},
        {pos: [5, 8, 2], state: "minecraft:smooth_sandstone"},
        {pos: [5, 8, 3], state: "minecraft:sandstone"},
        {pos: [6, 8, 2], state: "minecraft:sandstone"},
        {pos: [6, 8, 3], state: "minecraft:smooth_sandstone"},
        {pos: [6, 8, 4], state: "minecraft:smooth_sandstone"},
        {pos: [7, 8, 2], state: "minecraft:sandstone"},
        {pos: [7, 8, 3], state: "minecraft:smooth_sandstone"},
        {pos: [7, 8, 4], state: "minecraft:smooth_sandstone"},
        {pos: [8, 8, 2], state: "minecraft:smooth_sandstone"},
        {pos: [8, 8, 3], state: "minecraft:smooth_sandstone"},
        {pos: [8, 8, 4], state: "minecraft:smooth_sandstone"},
        {pos: [9, 8, 2], state: "minecraft:smooth_sandstone"},
        {pos: [9, 8, 3], state: "minecraft:smooth_sandstone"},
        {pos: [10, 8, 2], state: "minecraft:smooth_sandstone"},
        {pos: [10, 8, 3], state: "minecraft:smooth_sandstone"},
        {pos: [11, 8, 3], state: "minecraft:sandstone"},
        {pos: [12, 8, 2], state: "minecraft:smooth_sandstone"},
        {pos: [12, 8, 3], state: "minecraft:smooth_sandstone"},
        {pos: [12, 8, 4], state: "minecraft:smooth_sandstone"},
        {pos: [13, 8, 2], state: "minecraft:smooth_sandstone"},
        {pos: [13, 8, 3], state: "minecraft:smooth_sandstone"},
        {pos: [4, 9, 3], state: "minecraft:smooth_sandstone"},
        {pos: [4, 9, 4], state: "minecraft:smooth_sandstone"},
        {pos: [5, 9, 3], state: "minecraft:smooth_sandstone"},
        {pos: [5, 9, 4], state: "minecraft:smooth_sandstone"},
        {pos: [6, 9, 2], state: "minecraft:smooth_sandstone"},
        {pos: [6, 9, 3], state: "minecraft:smooth_sandstone"},
        {pos: [6, 9, 4], state: "minecraft:smooth_sandstone"},
        {pos: [7, 9, 2], state: "minecraft:smooth_sandstone"},
        {pos: [7, 9, 3], state: "minecraft:smooth_sandstone"},
        {pos: [7, 9, 4], state: "minecraft:smooth_sandstone"},
        {pos: [8, 9, 2], state: "minecraft:smooth_sandstone"},
        {pos: [8, 9, 3], state: "minecraft:smooth_sandstone"},
        {pos: [8, 9, 4], state: "minecraft:smooth_sandstone"},
        {pos: [9, 9, 2], state: "minecraft:smooth_sandstone"},
        {pos: [9, 9, 3], state: "minecraft:smooth_sandstone"},
        {pos: [9, 9, 4], state: "minecraft:smooth_sandstone"},
        {pos: [10, 9, 2], state: "minecraft:smooth_sandstone"},
        {pos: [10, 9, 3], state: "minecraft:smooth_sandstone"},
        {pos: [11, 9, 2], state: "minecraft:smooth_sandstone"},
        {pos: [11, 9, 3], state: "minecraft:smooth_sandstone"},
        {pos: [11, 9, 4], state: "minecraft:smooth_sandstone"},
        {pos: [12, 9, 2], state: "minecraft:smooth_sandstone"},
        {pos: [12, 9, 3], state: "minecraft:smooth_sandstone"},
        {pos: [13, 9, 2], state: "minecraft:sand"},
        {pos: [5, 10, 3], state: "minecraft:cut_sandstone"},
        {pos: [5, 10, 4], state: "minecraft:cut_sandstone"},
        {pos: [6, 10, 3], state: "minecraft:cut_sandstone"},
        {pos: [6, 10, 4], state: "minecraft:cut_sandstone"},
        {pos: [7, 10, 2], state: "minecraft:cut_sandstone"},
        {pos: [7, 10, 3], state: "minecraft:sand"},
        {pos: [7, 10, 4], state: "minecraft:cut_sandstone"},
        {pos: [8, 10, 2], state: "minecraft:cut_sandstone"},
        {pos: [8, 10, 3], state: "minecraft:sand"},
        {pos: [8, 10, 4], state: "minecraft:sand"},
        {pos: [9, 10, 2], state: "minecraft:cut_sandstone"},
        {pos: [9, 10, 3], state: "minecraft:sand"},
        {pos: [9, 10, 4], state: "minecraft:cut_sandstone"},
        {pos: [10, 10, 2], state: "minecraft:cut_sandstone"},
        {pos: [10, 10, 3], state: "minecraft:sand"},
        {pos: [10, 10, 4], state: "minecraft:cut_sandstone"},
        {pos: [11, 10, 2], state: "minecraft:cut_sandstone"},
        {pos: [11, 10, 3], state: "minecraft:cut_sandstone"},
        {pos: [11, 10, 4], state: "minecraft:cut_sandstone"}
    ],
    entities: [],
    palette: [
        "minecraft:sand",
        "minecraft:sandstone",
        "minecraft:smooth_sandstone",
        "minecraft:blue_terracotta",
        "minecraft:chiseled_sandstone",
        "minecraft:yellow_terracotta",
        "minecraft:cut_sandstone"
    ],
    trailiertales_DataVersion: 2
}
