{
    DataVersion: 3953,
    size: [26, 10, 26],
    data: [
        {pos: [0, 0, 8], state: "minecraft:sand"},
        {pos: [0, 0, 9], state: "minecraft:sand"},
        {pos: [0, 0, 10], state: "minecraft:sand"},
        {pos: [0, 0, 11], state: "minecraft:sand"},
        {pos: [0, 0, 12], state: "minecraft:sand"},
        {pos: [0, 0, 13], state: "minecraft:sand"},
        {pos: [0, 0, 14], state: "minecraft:sand"},
        {pos: [0, 0, 15], state: "minecraft:sand"},
        {pos: [0, 0, 16], state: "minecraft:sand"},
        {pos: [0, 0, 17], state: "minecraft:sand"},
        {pos: [0, 0, 18], state: "minecraft:sand"},
        {pos: [1, 0, 7], state: "minecraft:sand"},
        {pos: [1, 0, 8], state: "minecraft:sand"},
        {pos: [1, 0, 9], state: "minecraft:sand"},
        {pos: [1, 0, 10], state: "minecraft:sand"},
        {pos: [1, 0, 11], state: "minecraft:sand"},
        {pos: [1, 0, 12], state: "minecraft:sand"},
        {pos: [1, 0, 13], state: "minecraft:sand"},
        {pos: [1, 0, 14], state: "minecraft:sand"},
        {pos: [1, 0, 15], state: "minecraft:sand"},
        {pos: [1, 0, 16], state: "minecraft:sand"},
        {pos: [1, 0, 17], state: "minecraft:sand"},
        {pos: [1, 0, 18], state: "minecraft:sand"},
        {pos: [1, 0, 19], state: "minecraft:sand"},
        {pos: [1, 0, 20], state: "minecraft:sand"},
        {pos: [2, 0, 5], state: "minecraft:sand"},
        {pos: [2, 0, 6], state: "minecraft:sand"},
        {pos: [2, 0, 7], state: "minecraft:sand"},
        {pos: [2, 0, 8], state: "minecraft:sand"},
        {pos: [2, 0, 9], state: "minecraft:sand"},
        {pos: [2, 0, 10], state: "minecraft:sand"},
        {pos: [2, 0, 11], state: "minecraft:sand"},
        {pos: [2, 0, 12], state: "minecraft:sand"},
        {pos: [2, 0, 13], state: "minecraft:sand"},
        {pos: [2, 0, 14], state: "minecraft:sand"},
        {pos: [2, 0, 15], state: "minecraft:sand"},
        {pos: [2, 0, 16], state: "minecraft:sand"},
        {pos: [2, 0, 17], state: "minecraft:sand"},
        {pos: [2, 0, 18], state: "minecraft:sand"},
        {pos: [2, 0, 19], state: "minecraft:sand"},
        {pos: [2, 0, 20], state: "minecraft:sand"},
        {pos: [2, 0, 21], state: "minecraft:sand"},
        {pos: [3, 0, 3], state: "minecraft:sand"},
        {pos: [3, 0, 4], state: "minecraft:sand"},
        {pos: [3, 0, 5], state: "minecraft:sandstone"},
        {pos: [3, 0, 6], state: "minecraft:sandstone"},
        {pos: [3, 0, 7], state: "minecraft:sandstone"},
        {pos: [3, 0, 8], state: "minecraft:sandstone"},
        {pos: [3, 0, 9], state: "minecraft:sandstone"},
        {pos: [3, 0, 10], state: "minecraft:sandstone"},
        {pos: [3, 0, 11], state: "minecraft:sandstone"},
        {pos: [3, 0, 12], state: "minecraft:sandstone"},
        {pos: [3, 0, 13], state: "minecraft:sandstone"},
        {pos: [3, 0, 14], state: "minecraft:sandstone"},
        {pos: [3, 0, 15], state: "minecraft:sandstone"},
        {pos: [3, 0, 16], state: "minecraft:sandstone"},
        {pos: [3, 0, 17], state: "minecraft:sandstone"},
        {pos: [3, 0, 18], state: "minecraft:sandstone"},
        {pos: [3, 0, 19], state: "minecraft:sandstone"},
        {pos: [3, 0, 20], state: "minecraft:sandstone"},
        {pos: [3, 0, 21], state: "minecraft:sand"},
        {pos: [3, 0, 22], state: "minecraft:sand"},
        {pos: [4, 0, 2], state: "minecraft:sand"},
        {pos: [4, 0, 3], state: "minecraft:sand"},
        {pos: [4, 0, 4], state: "minecraft:sand"},
        {pos: [4, 0, 5], state: "minecraft:sandstone"},
        {pos: [4, 0, 6], state: "minecraft:sandstone"},
        {pos: [4, 0, 7], state: "minecraft:sandstone"},
        {pos: [4, 0, 8], state: "minecraft:sandstone"},
        {pos: [4, 0, 9], state: "minecraft:sandstone"},
        {pos: [4, 0, 10], state: "minecraft:sandstone"},
        {pos: [4, 0, 11], state: "minecraft:sandstone"},
        {pos: [4, 0, 12], state: "minecraft:sandstone"},
        {pos: [4, 0, 13], state: "minecraft:sandstone"},
        {pos: [4, 0, 14], state: "minecraft:sandstone"},
        {pos: [4, 0, 15], state: "minecraft:sandstone"},
        {pos: [4, 0, 16], state: "minecraft:sandstone"},
        {pos: [4, 0, 17], state: "minecraft:sandstone"},
        {pos: [4, 0, 18], state: "minecraft:sandstone"},
        {pos: [4, 0, 19], state: "minecraft:sandstone"},
        {pos: [4, 0, 20], state: "minecraft:sandstone"},
        {pos: [4, 0, 21], state: "minecraft:sandstone"},
        {pos: [4, 0, 22], state: "minecraft:sandstone"},
        {pos: [4, 0, 23], state: "minecraft:sand"},
        {pos: [5, 0, 1], state: "minecraft:sand"},
        {pos: [5, 0, 2], state: "minecraft:sand"},
        {pos: [5, 0, 3], state: "minecraft:sand"},
        {pos: [5, 0, 4], state: "minecraft:sand"},
        {pos: [5, 0, 5], state: "minecraft:sandstone"},
        {pos: [5, 0, 6], state: "minecraft:sandstone"},
        {pos: [5, 0, 7], state: "minecraft:sandstone"},
        {pos: [5, 0, 8], state: "minecraft:sandstone"},
        {pos: [5, 0, 9], state: "minecraft:sandstone"},
        {pos: [5, 0, 10], state: "minecraft:sandstone"},
        {pos: [5, 0, 11], state: "minecraft:sandstone"},
        {pos: [5, 0, 12], state: "minecraft:sandstone"},
        {pos: [5, 0, 13], state: "minecraft:sandstone"},
        {pos: [5, 0, 14], state: "minecraft:sandstone"},
        {pos: [5, 0, 15], state: "minecraft:sandstone"},
        {pos: [5, 0, 16], state: "minecraft:sandstone"},
        {pos: [5, 0, 17], state: "minecraft:sandstone"},
        {pos: [5, 0, 18], state: "minecraft:sandstone"},
        {pos: [5, 0, 19], state: "minecraft:sandstone"},
        {pos: [5, 0, 20], state: "minecraft:sandstone"},
        {pos: [5, 0, 21], state: "minecraft:sandstone"},
        {pos: [5, 0, 22], state: "minecraft:sandstone"},
        {pos: [5, 0, 23], state: "minecraft:sand"},
        {pos: [5, 0, 24], state: "minecraft:sand"},
        {pos: [6, 0, 0], state: "minecraft:sand"},
        {pos: [6, 0, 1], state: "minecraft:sand"},
        {pos: [6, 0, 2], state: "minecraft:sand"},
        {pos: [6, 0, 3], state: "minecraft:sand"},
        {pos: [6, 0, 4], state: "minecraft:sand"},
        {pos: [6, 0, 5], state: "minecraft:sandstone"},
        {pos: [6, 0, 6], state: "minecraft:sandstone"},
        {pos: [6, 0, 7], state: "minecraft:sandstone"},
        {pos: [6, 0, 8], state: "minecraft:sandstone"},
        {pos: [6, 0, 9], state: "minecraft:sandstone"},
        {pos: [6, 0, 10], state: "minecraft:sandstone"},
        {pos: [6, 0, 11], state: "minecraft:sandstone"},
        {pos: [6, 0, 12], state: "minecraft:sandstone"},
        {pos: [6, 0, 13], state: "minecraft:sandstone"},
        {pos: [6, 0, 14], state: "minecraft:sandstone"},
        {pos: [6, 0, 15], state: "minecraft:sandstone"},
        {pos: [6, 0, 16], state: "minecraft:sandstone"},
        {pos: [6, 0, 17], state: "minecraft:sandstone"},
        {pos: [6, 0, 18], state: "minecraft:sandstone"},
        {pos: [6, 0, 19], state: "minecraft:sandstone"},
        {pos: [6, 0, 20], state: "minecraft:sandstone"},
        {pos: [6, 0, 21], state: "minecraft:sandstone"},
        {pos: [6, 0, 22], state: "minecraft:sandstone"},
        {pos: [6, 0, 23], state: "minecraft:sand"},
        {pos: [6, 0, 24], state: "minecraft:sand"},
        {pos: [7, 0, 0], state: "minecraft:sand"},
        {pos: [7, 0, 1], state: "minecraft:sand"},
        {pos: [7, 0, 2], state: "minecraft:sand"},
        {pos: [7, 0, 3], state: "minecraft:sandstone"},
        {pos: [7, 0, 4], state: "minecraft:sandstone"},
        {pos: [7, 0, 5], state: "minecraft:sandstone"},
        {pos: [7, 0, 6], state: "minecraft:sandstone"},
        {pos: [7, 0, 7], state: "minecraft:sandstone"},
        {pos: [7, 0, 8], state: "minecraft:sandstone"},
        {pos: [7, 0, 9], state: "minecraft:sandstone"},
        {pos: [7, 0, 10], state: "minecraft:sandstone"},
        {pos: [7, 0, 11], state: "minecraft:sandstone"},
        {pos: [7, 0, 12], state: "minecraft:sandstone"},
        {pos: [7, 0, 13], state: "minecraft:sandstone"},
        {pos: [7, 0, 14], state: "minecraft:sandstone"},
        {pos: [7, 0, 15], state: "minecraft:sandstone"},
        {pos: [7, 0, 16], state: "minecraft:sandstone"},
        {pos: [7, 0, 17], state: "minecraft:sandstone"},
        {pos: [7, 0, 18], state: "minecraft:sandstone"},
        {pos: [7, 0, 19], state: "minecraft:sandstone"},
        {pos: [7, 0, 20], state: "minecraft:sandstone"},
        {pos: [7, 0, 21], state: "minecraft:sandstone"},
        {pos: [7, 0, 22], state: "minecraft:sandstone"},
        {pos: [7, 0, 23], state: "minecraft:sand"},
        {pos: [7, 0, 24], state: "minecraft:sand"},
        {pos: [7, 0, 25], state: "minecraft:sand"},
        {pos: [8, 0, 0], state: "minecraft:sand"},
        {pos: [8, 0, 1], state: "minecraft:sand"},
        {pos: [8, 0, 2], state: "minecraft:sand"},
        {pos: [8, 0, 3], state: "minecraft:sandstone"},
        {pos: [8, 0, 4], state: "minecraft:sandstone"},
        {pos: [8, 0, 5], state: "minecraft:sandstone"},
        {pos: [8, 0, 6], state: "minecraft:sandstone"},
        {pos: [8, 0, 7], state: "minecraft:sandstone"},
        {pos: [8, 0, 8], state: "minecraft:sandstone"},
        {pos: [8, 0, 9], state: "minecraft:sandstone"},
        {pos: [8, 0, 10], state: "minecraft:sandstone"},
        {pos: [8, 0, 11], state: "minecraft:sandstone"},
        {pos: [8, 0, 12], state: "minecraft:sandstone"},
        {pos: [8, 0, 13], state: "minecraft:sandstone"},
        {pos: [8, 0, 14], state: "minecraft:sandstone"},
        {pos: [8, 0, 15], state: "minecraft:sandstone"},
        {pos: [8, 0, 16], state: "minecraft:sandstone"},
        {pos: [8, 0, 17], state: "minecraft:sandstone"},
        {pos: [8, 0, 18], state: "minecraft:sandstone"},
        {pos: [8, 0, 19], state: "minecraft:sandstone"},
        {pos: [8, 0, 20], state: "minecraft:sandstone"},
        {pos: [8, 0, 21], state: "minecraft:sandstone"},
        {pos: [8, 0, 22], state: "minecraft:sandstone"},
        {pos: [8, 0, 23], state: "minecraft:sand"},
        {pos: [8, 0, 24], state: "minecraft:sand"},
        {pos: [8, 0, 25], state: "minecraft:sand"},
        {pos: [9, 0, 1], state: "minecraft:sand"},
        {pos: [9, 0, 2], state: "minecraft:sand"},
        {pos: [9, 0, 3], state: "minecraft:sandstone"},
        {pos: [9, 0, 4], state: "minecraft:sandstone"},
        {pos: [9, 0, 5], state: "minecraft:sandstone"},
        {pos: [9, 0, 6], state: "minecraft:sandstone"},
        {pos: [9, 0, 7], state: "minecraft:sandstone"},
        {pos: [9, 0, 8], state: "minecraft:sandstone"},
        {pos: [9, 0, 9], state: "minecraft:sandstone"},
        {pos: [9, 0, 10], state: "minecraft:sandstone"},
        {pos: [9, 0, 11], state: "minecraft:sandstone"},
        {pos: [9, 0, 12], state: "minecraft:sandstone"},
        {pos: [9, 0, 13], state: "minecraft:sandstone"},
        {pos: [9, 0, 14], state: "minecraft:sandstone"},
        {pos: [9, 0, 15], state: "minecraft:sandstone"},
        {pos: [9, 0, 16], state: "minecraft:sandstone"},
        {pos: [9, 0, 17], state: "minecraft:sandstone"},
        {pos: [9, 0, 18], state: "minecraft:sandstone"},
        {pos: [9, 0, 19], state: "minecraft:sandstone"},
        {pos: [9, 0, 20], state: "minecraft:sandstone"},
        {pos: [9, 0, 21], state: "minecraft:sandstone"},
        {pos: [9, 0, 22], state: "minecraft:sandstone"},
        {pos: [9, 0, 23], state: "minecraft:sand"},
        {pos: [9, 0, 24], state: "minecraft:sand"},
        {pos: [9, 0, 25], state: "minecraft:sand"},
        {pos: [10, 0, 2], state: "minecraft:sand"},
        {pos: [10, 0, 3], state: "minecraft:sand"},
        {pos: [10, 0, 4], state: "minecraft:sandstone"},
        {pos: [10, 0, 5], state: "minecraft:sandstone"},
        {pos: [10, 0, 6], state: "minecraft:sandstone"},
        {pos: [10, 0, 7], state: "minecraft:sandstone"},
        {pos: [10, 0, 8], state: "minecraft:sandstone"},
        {pos: [10, 0, 9], state: "minecraft:sandstone"},
        {pos: [10, 0, 10], state: "minecraft:sandstone"},
        {pos: [10, 0, 11], state: "minecraft:sandstone"},
        {pos: [10, 0, 12], state: "minecraft:sandstone"},
        {pos: [10, 0, 13], state: "minecraft:sandstone"},
        {pos: [10, 0, 14], state: "minecraft:sandstone"},
        {pos: [10, 0, 15], state: "minecraft:sandstone"},
        {pos: [10, 0, 16], state: "minecraft:sandstone"},
        {pos: [10, 0, 17], state: "minecraft:sandstone"},
        {pos: [10, 0, 18], state: "minecraft:sandstone"},
        {pos: [10, 0, 19], state: "minecraft:sandstone"},
        {pos: [10, 0, 20], state: "minecraft:sandstone"},
        {pos: [10, 0, 21], state: "minecraft:sandstone"},
        {pos: [10, 0, 22], state: "minecraft:sandstone"},
        {pos: [10, 0, 23], state: "minecraft:sand"},
        {pos: [10, 0, 24], state: "minecraft:sand"},
        {pos: [10, 0, 25], state: "minecraft:sand"},
        {pos: [11, 0, 2], state: "minecraft:sand"},
        {pos: [11, 0, 3], state: "minecraft:sand"},
        {pos: [11, 0, 4], state: "minecraft:sandstone"},
        {pos: [11, 0, 5], state: "minecraft:sandstone"},
        {pos: [11, 0, 6], state: "minecraft:sandstone"},
        {pos: [11, 0, 7], state: "minecraft:sandstone"},
        {pos: [11, 0, 8], state: "minecraft:sandstone"},
        {pos: [11, 0, 9], state: "minecraft:sandstone"},
        {pos: [11, 0, 10], state: "minecraft:sandstone"},
        {pos: [11, 0, 11], state: "minecraft:sandstone"},
        {pos: [11, 0, 12], state: "minecraft:sandstone"},
        {pos: [11, 0, 13], state: "minecraft:sandstone"},
        {pos: [11, 0, 14], state: "minecraft:sandstone"},
        {pos: [11, 0, 15], state: "minecraft:sandstone"},
        {pos: [11, 0, 16], state: "minecraft:sandstone"},
        {pos: [11, 0, 17], state: "minecraft:sandstone"},
        {pos: [11, 0, 18], state: "minecraft:sandstone"},
        {pos: [11, 0, 19], state: "minecraft:sandstone"},
        {pos: [11, 0, 20], state: "minecraft:sandstone"},
        {pos: [11, 0, 21], state: "minecraft:sandstone"},
        {pos: [11, 0, 22], state: "minecraft:sandstone"},
        {pos: [11, 0, 23], state: "minecraft:sand"},
        {pos: [11, 0, 24], state: "minecraft:sand"},
        {pos: [11, 0, 25], state: "minecraft:sand"},
        {pos: [12, 0, 2], state: "minecraft:sand"},
        {pos: [12, 0, 3], state: "minecraft:sand"},
        {pos: [12, 0, 4], state: "minecraft:sandstone"},
        {pos: [12, 0, 5], state: "minecraft:sandstone"},
        {pos: [12, 0, 6], state: "minecraft:sandstone"},
        {pos: [12, 0, 7], state: "minecraft:sandstone"},
        {pos: [12, 0, 8], state: "minecraft:sandstone"},
        {pos: [12, 0, 9], state: "minecraft:sandstone"},
        {pos: [12, 0, 10], state: "minecraft:sandstone"},
        {pos: [12, 0, 11], state: "minecraft:sandstone"},
        {pos: [12, 0, 12], state: "minecraft:sandstone"},
        {pos: [12, 0, 13], state: "minecraft:sandstone"},
        {pos: [12, 0, 14], state: "minecraft:sandstone"},
        {pos: [12, 0, 15], state: "minecraft:sandstone"},
        {pos: [12, 0, 16], state: "minecraft:sandstone"},
        {pos: [12, 0, 17], state: "minecraft:sandstone"},
        {pos: [12, 0, 18], state: "minecraft:sandstone"},
        {pos: [12, 0, 19], state: "minecraft:sandstone"},
        {pos: [12, 0, 20], state: "minecraft:sandstone"},
        {pos: [12, 0, 21], state: "minecraft:sandstone"},
        {pos: [12, 0, 22], state: "minecraft:sandstone"},
        {pos: [12, 0, 23], state: "minecraft:sand"},
        {pos: [12, 0, 24], state: "minecraft:sand"},
        {pos: [12, 0, 25], state: "minecraft:sand"},
        {pos: [13, 0, 1], state: "minecraft:sand"},
        {pos: [13, 0, 2], state: "minecraft:sand"},
        {pos: [13, 0, 3], state: "minecraft:sand"},
        {pos: [13, 0, 4], state: "minecraft:sandstone"},
        {pos: [13, 0, 5], state: "minecraft:sandstone"},
        {pos: [13, 0, 6], state: "minecraft:sandstone"},
        {pos: [13, 0, 7], state: "minecraft:sandstone"},
        {pos: [13, 0, 8], state: "minecraft:sandstone"},
        {pos: [13, 0, 9], state: "minecraft:sandstone"},
        {pos: [13, 0, 10], state: "minecraft:sandstone"},
        {pos: [13, 0, 11], state: "minecraft:sandstone"},
        {pos: [13, 0, 12], state: "minecraft:sandstone"},
        {pos: [13, 0, 13], state: "minecraft:sandstone"},
        {pos: [13, 0, 14], state: "minecraft:sandstone"},
        {pos: [13, 0, 15], state: "minecraft:sandstone"},
        {pos: [13, 0, 16], state: "minecraft:sandstone"},
        {pos: [13, 0, 17], state: "minecraft:sandstone"},
        {pos: [13, 0, 18], state: "minecraft:sandstone"},
        {pos: [13, 0, 19], state: "minecraft:sandstone"},
        {pos: [13, 0, 20], state: "minecraft:sandstone"},
        {pos: [13, 0, 21], state: "minecraft:sandstone"},
        {pos: [13, 0, 22], state: "minecraft:sandstone"},
        {pos: [13, 0, 23], state: "minecraft:sand"},
        {pos: [13, 0, 24], state: "minecraft:sand"},
        {pos: [13, 0, 25], state: "minecraft:sand"},
        {pos: [14, 0, 1], state: "minecraft:sand"},
        {pos: [14, 0, 2], state: "minecraft:sand"},
        {pos: [14, 0, 3], state: "minecraft:sand"},
        {pos: [14, 0, 4], state: "minecraft:sandstone"},
        {pos: [14, 0, 5], state: "minecraft:sandstone"},
        {pos: [14, 0, 6], state: "minecraft:sandstone"},
        {pos: [14, 0, 7], state: "minecraft:sandstone"},
        {pos: [14, 0, 8], state: "minecraft:sandstone"},
        {pos: [14, 0, 9], state: "minecraft:sandstone"},
        {pos: [14, 0, 10], state: "minecraft:sandstone"},
        {pos: [14, 0, 11], state: "minecraft:sandstone"},
        {pos: [14, 0, 12], state: "minecraft:sandstone"},
        {pos: [14, 0, 13], state: "minecraft:sandstone"},
        {pos: [14, 0, 14], state: "minecraft:sandstone"},
        {pos: [14, 0, 15], state: "minecraft:sandstone"},
        {pos: [14, 0, 16], state: "minecraft:sandstone"},
        {pos: [14, 0, 17], state: "minecraft:sandstone"},
        {pos: [14, 0, 18], state: "minecraft:sandstone"},
        {pos: [14, 0, 19], state: "minecraft:sandstone"},
        {pos: [14, 0, 20], state: "minecraft:sandstone"},
        {pos: [14, 0, 21], state: "minecraft:sandstone"},
        {pos: [14, 0, 22], state: "minecraft:sandstone"},
        {pos: [14, 0, 23], state: "minecraft:sand"},
        {pos: [14, 0, 24], state: "minecraft:sand"},
        {pos: [14, 0, 25], state: "minecraft:sand"},
        {pos: [15, 0, 0], state: "minecraft:sand"},
        {pos: [15, 0, 1], state: "minecraft:sand"},
        {pos: [15, 0, 2], state: "minecraft:sand"},
        {pos: [15, 0, 3], state: "minecraft:sand"},
        {pos: [15, 0, 4], state: "minecraft:sandstone"},
        {pos: [15, 0, 5], state: "minecraft:sandstone"},
        {pos: [15, 0, 6], state: "minecraft:sandstone"},
        {pos: [15, 0, 7], state: "minecraft:sandstone"},
        {pos: [15, 0, 8], state: "minecraft:sandstone"},
        {pos: [15, 0, 9], state: "minecraft:sandstone"},
        {pos: [15, 0, 10], state: "minecraft:sandstone"},
        {pos: [15, 0, 11], state: "minecraft:sandstone"},
        {pos: [15, 0, 12], state: "minecraft:sandstone"},
        {pos: [15, 0, 13], state: "minecraft:sandstone"},
        {pos: [15, 0, 14], state: "minecraft:sandstone"},
        {pos: [15, 0, 15], state: "minecraft:sandstone"},
        {pos: [15, 0, 16], state: "minecraft:sandstone"},
        {pos: [15, 0, 17], state: "minecraft:sandstone"},
        {pos: [15, 0, 18], state: "minecraft:sandstone"},
        {pos: [15, 0, 19], state: "minecraft:sandstone"},
        {pos: [15, 0, 20], state: "minecraft:sandstone"},
        {pos: [15, 0, 21], state: "minecraft:sandstone"},
        {pos: [15, 0, 22], state: "minecraft:sandstone"},
        {pos: [15, 0, 23], state: "minecraft:sand"},
        {pos: [15, 0, 24], state: "minecraft:sand"},
        {pos: [15, 0, 25], state: "minecraft:sand"},
        {pos: [16, 0, 0], state: "minecraft:sand"},
        {pos: [16, 0, 1], state: "minecraft:sand"},
        {pos: [16, 0, 2], state: "minecraft:sand"},
        {pos: [16, 0, 3], state: "minecraft:sand"},
        {pos: [16, 0, 4], state: "minecraft:sandstone"},
        {pos: [16, 0, 5], state: "minecraft:sandstone"},
        {pos: [16, 0, 6], state: "minecraft:sandstone"},
        {pos: [16, 0, 7], state: "minecraft:sandstone"},
        {pos: [16, 0, 8], state: "minecraft:sandstone"},
        {pos: [16, 0, 9], state: "minecraft:sandstone"},
        {pos: [16, 0, 10], state: "minecraft:sandstone"},
        {pos: [16, 0, 11], state: "minecraft:sandstone"},
        {pos: [16, 0, 12], state: "minecraft:sandstone"},
        {pos: [16, 0, 13], state: "minecraft:sandstone"},
        {pos: [16, 0, 14], state: "minecraft:sandstone"},
        {pos: [16, 0, 15], state: "minecraft:sandstone"},
        {pos: [16, 0, 16], state: "minecraft:sandstone"},
        {pos: [16, 0, 17], state: "minecraft:sandstone"},
        {pos: [16, 0, 18], state: "minecraft:sandstone"},
        {pos: [16, 0, 19], state: "minecraft:sandstone"},
        {pos: [16, 0, 20], state: "minecraft:sandstone"},
        {pos: [16, 0, 21], state: "minecraft:sandstone"},
        {pos: [16, 0, 22], state: "minecraft:sandstone"},
        {pos: [16, 0, 23], state: "minecraft:sand"},
        {pos: [16, 0, 24], state: "minecraft:sand"},
        {pos: [16, 0, 25], state: "minecraft:sand"},
        {pos: [17, 0, 0], state: "minecraft:sand"},
        {pos: [17, 0, 1], state: "minecraft:sand"},
        {pos: [17, 0, 2], state: "minecraft:sand"},
        {pos: [17, 0, 3], state: "minecraft:sandstone"},
        {pos: [17, 0, 4], state: "minecraft:sandstone"},
        {pos: [17, 0, 5], state: "minecraft:sandstone"},
        {pos: [17, 0, 6], state: "minecraft:sandstone"},
        {pos: [17, 0, 7], state: "minecraft:sandstone"},
        {pos: [17, 0, 8], state: "minecraft:sandstone"},
        {pos: [17, 0, 9], state: "minecraft:sandstone"},
        {pos: [17, 0, 10], state: "minecraft:sandstone"},
        {pos: [17, 0, 11], state: "minecraft:sandstone"},
        {pos: [17, 0, 12], state: "minecraft:sandstone"},
        {pos: [17, 0, 13], state: "minecraft:sandstone"},
        {pos: [17, 0, 14], state: "minecraft:sandstone"},
        {pos: [17, 0, 15], state: "minecraft:sandstone"},
        {pos: [17, 0, 16], state: "minecraft:sandstone"},
        {pos: [17, 0, 17], state: "minecraft:sandstone"},
        {pos: [17, 0, 18], state: "minecraft:sandstone"},
        {pos: [17, 0, 19], state: "minecraft:sandstone"},
        {pos: [17, 0, 20], state: "minecraft:sandstone"},
        {pos: [17, 0, 21], state: "minecraft:sandstone"},
        {pos: [17, 0, 22], state: "minecraft:sandstone"},
        {pos: [17, 0, 23], state: "minecraft:sand"},
        {pos: [17, 0, 24], state: "minecraft:sand"},
        {pos: [18, 0, 1], state: "minecraft:sand"},
        {pos: [18, 0, 2], state: "minecraft:sand"},
        {pos: [18, 0, 3], state: "minecraft:sandstone"},
        {pos: [18, 0, 4], state: "minecraft:sandstone"},
        {pos: [18, 0, 5], state: "minecraft:sandstone"},
        {pos: [18, 0, 6], state: "minecraft:sandstone"},
        {pos: [18, 0, 7], state: "minecraft:sandstone"},
        {pos: [18, 0, 8], state: "minecraft:sandstone"},
        {pos: [18, 0, 9], state: "minecraft:sandstone"},
        {pos: [18, 0, 10], state: "minecraft:sandstone"},
        {pos: [18, 0, 11], state: "minecraft:sandstone"},
        {pos: [18, 0, 12], state: "minecraft:sandstone"},
        {pos: [18, 0, 13], state: "minecraft:sandstone"},
        {pos: [18, 0, 14], state: "minecraft:sandstone"},
        {pos: [18, 0, 15], state: "minecraft:sandstone"},
        {pos: [18, 0, 16], state: "minecraft:sandstone"},
        {pos: [18, 0, 17], state: "minecraft:sandstone"},
        {pos: [18, 0, 18], state: "minecraft:sandstone"},
        {pos: [18, 0, 19], state: "minecraft:sandstone"},
        {pos: [18, 0, 20], state: "minecraft:sandstone"},
        {pos: [18, 0, 21], state: "minecraft:sandstone"},
        {pos: [18, 0, 22], state: "minecraft:sandstone"},
        {pos: [18, 0, 23], state: "minecraft:sand"},
        {pos: [18, 0, 24], state: "minecraft:sand"},
        {pos: [19, 0, 1], state: "minecraft:sand"},
        {pos: [19, 0, 2], state: "minecraft:sand"},
        {pos: [19, 0, 3], state: "minecraft:sandstone"},
        {pos: [19, 0, 4], state: "minecraft:sandstone"},
        {pos: [19, 0, 5], state: "minecraft:sandstone"},
        {pos: [19, 0, 6], state: "minecraft:sandstone"},
        {pos: [19, 0, 7], state: "minecraft:sandstone"},
        {pos: [19, 0, 8], state: "minecraft:sandstone"},
        {pos: [19, 0, 9], state: "minecraft:sandstone"},
        {pos: [19, 0, 10], state: "minecraft:sandstone"},
        {pos: [19, 0, 11], state: "minecraft:sandstone"},
        {pos: [19, 0, 12], state: "minecraft:sandstone"},
        {pos: [19, 0, 13], state: "minecraft:sandstone"},
        {pos: [19, 0, 14], state: "minecraft:sandstone"},
        {pos: [19, 0, 15], state: "minecraft:sandstone"},
        {pos: [19, 0, 16], state: "minecraft:sandstone"},
        {pos: [19, 0, 17], state: "minecraft:sandstone"},
        {pos: [19, 0, 18], state: "minecraft:sandstone"},
        {pos: [19, 0, 19], state: "minecraft:sandstone"},
        {pos: [19, 0, 20], state: "minecraft:sandstone"},
        {pos: [19, 0, 21], state: "minecraft:sandstone"},
        {pos: [19, 0, 22], state: "minecraft:sand"},
        {pos: [19, 0, 23], state: "minecraft:sand"},
        {pos: [19, 0, 24], state: "minecraft:sand"},
        {pos: [20, 0, 2], state: "minecraft:sand"},
        {pos: [20, 0, 3], state: "minecraft:sand"},
        {pos: [20, 0, 4], state: "minecraft:sand"},
        {pos: [20, 0, 5], state: "minecraft:sand"},
        {pos: [20, 0, 6], state: "minecraft:sandstone"},
        {pos: [20, 0, 7], state: "minecraft:sandstone"},
        {pos: [20, 0, 8], state: "minecraft:sandstone"},
        {pos: [20, 0, 9], state: "minecraft:sandstone"},
        {pos: [20, 0, 10], state: "minecraft:sandstone"},
        {pos: [20, 0, 11], state: "minecraft:sandstone"},
        {pos: [20, 0, 12], state: "minecraft:sandstone"},
        {pos: [20, 0, 13], state: "minecraft:sandstone"},
        {pos: [20, 0, 14], state: "minecraft:sandstone"},
        {pos: [20, 0, 15], state: "minecraft:sandstone"},
        {pos: [20, 0, 16], state: "minecraft:sandstone"},
        {pos: [20, 0, 17], state: "minecraft:sandstone"},
        {pos: [20, 0, 18], state: "minecraft:sandstone"},
        {pos: [20, 0, 19], state: "minecraft:sandstone"},
        {pos: [20, 0, 20], state: "minecraft:sandstone"},
        {pos: [20, 0, 21], state: "minecraft:sandstone"},
        {pos: [20, 0, 22], state: "minecraft:sand"},
        {pos: [20, 0, 23], state: "minecraft:sand"},
        {pos: [21, 0, 3], state: "minecraft:sand"},
        {pos: [21, 0, 4], state: "minecraft:sand"},
        {pos: [21, 0, 5], state: "minecraft:sand"},
        {pos: [21, 0, 6], state: "minecraft:sandstone"},
        {pos: [21, 0, 7], state: "minecraft:sandstone"},
        {pos: [21, 0, 8], state: "minecraft:sandstone"},
        {pos: [21, 0, 9], state: "minecraft:sandstone"},
        {pos: [21, 0, 10], state: "minecraft:sandstone"},
        {pos: [21, 0, 11], state: "minecraft:sandstone"},
        {pos: [21, 0, 12], state: "minecraft:sandstone"},
        {pos: [21, 0, 13], state: "minecraft:sandstone"},
        {pos: [21, 0, 14], state: "minecraft:sandstone"},
        {pos: [21, 0, 15], state: "minecraft:sandstone"},
        {pos: [21, 0, 16], state: "minecraft:sandstone"},
        {pos: [21, 0, 17], state: "minecraft:sandstone"},
        {pos: [21, 0, 18], state: "minecraft:sandstone"},
        {pos: [21, 0, 19], state: "minecraft:sandstone"},
        {pos: [21, 0, 20], state: "minecraft:sandstone"},
        {pos: [21, 0, 21], state: "minecraft:sand"},
        {pos: [21, 0, 22], state: "minecraft:sand"},
        {pos: [21, 0, 23], state: "minecraft:sand"},
        {pos: [22, 0, 4], state: "minecraft:sand"},
        {pos: [22, 0, 5], state: "minecraft:sand"},
        {pos: [22, 0, 6], state: "minecraft:sandstone"},
        {pos: [22, 0, 7], state: "minecraft:sandstone"},
        {pos: [22, 0, 8], state: "minecraft:sandstone"},
        {pos: [22, 0, 9], state: "minecraft:sandstone"},
        {pos: [22, 0, 10], state: "minecraft:sandstone"},
        {pos: [22, 0, 11], state: "minecraft:sandstone"},
        {pos: [22, 0, 12], state: "minecraft:sandstone"},
        {pos: [22, 0, 13], state: "minecraft:sandstone"},
        {pos: [22, 0, 14], state: "minecraft:sandstone"},
        {pos: [22, 0, 15], state: "minecraft:sandstone"},
        {pos: [22, 0, 16], state: "minecraft:sandstone"},
        {pos: [22, 0, 17], state: "minecraft:sandstone"},
        {pos: [22, 0, 18], state: "minecraft:sandstone"},
        {pos: [22, 0, 19], state: "minecraft:sandstone"},
        {pos: [22, 0, 20], state: "minecraft:sand"},
        {pos: [22, 0, 21], state: "minecraft:sand"},
        {pos: [22, 0, 22], state: "minecraft:sand"},
        {pos: [23, 0, 5], state: "minecraft:sand"},
        {pos: [23, 0, 6], state: "minecraft:sand"},
        {pos: [23, 0, 7], state: "minecraft:sand"},
        {pos: [23, 0, 8], state: "minecraft:sand"},
        {pos: [23, 0, 9], state: "minecraft:sand"},
        {pos: [23, 0, 10], state: "minecraft:sand"},
        {pos: [23, 0, 11], state: "minecraft:sand"},
        {pos: [23, 0, 12], state: "minecraft:sand"},
        {pos: [23, 0, 13], state: "minecraft:sand"},
        {pos: [23, 0, 14], state: "minecraft:sand"},
        {pos: [23, 0, 15], state: "minecraft:sand"},
        {pos: [23, 0, 16], state: "minecraft:sand"},
        {pos: [23, 0, 17], state: "minecraft:sand"},
        {pos: [23, 0, 18], state: "minecraft:sand"},
        {pos: [23, 0, 19], state: "minecraft:sand"},
        {pos: [23, 0, 20], state: "minecraft:sand"},
        {pos: [23, 0, 21], state: "minecraft:sand"},
        {pos: [23, 0, 22], state: "minecraft:sand"},
        {pos: [24, 0, 7], state: "minecraft:sand"},
        {pos: [24, 0, 8], state: "minecraft:sand"},
        {pos: [24, 0, 9], state: "minecraft:sand"},
        {pos: [24, 0, 10], state: "minecraft:sand"},
        {pos: [24, 0, 11], state: "minecraft:sand"},
        {pos: [24, 0, 12], state: "minecraft:sand"},
        {pos: [24, 0, 13], state: "minecraft:sand"},
        {pos: [24, 0, 14], state: "minecraft:sand"},
        {pos: [24, 0, 15], state: "minecraft:sand"},
        {pos: [24, 0, 16], state: "minecraft:sand"},
        {pos: [24, 0, 17], state: "minecraft:sand"},
        {pos: [24, 0, 18], state: "minecraft:sand"},
        {pos: [24, 0, 19], state: "minecraft:sand"},
        {pos: [24, 0, 20], state: "minecraft:sand"},
        {pos: [25, 0, 8], state: "minecraft:sand"},
        {pos: [25, 0, 9], state: "minecraft:sand"},
        {pos: [25, 0, 10], state: "minecraft:sand"},
        {pos: [25, 0, 11], state: "minecraft:sand"},
        {pos: [25, 0, 12], state: "minecraft:sand"},
        {pos: [25, 0, 13], state: "minecraft:sand"},
        {pos: [25, 0, 14], state: "minecraft:sand"},
        {pos: [25, 0, 15], state: "minecraft:sand"},
        {pos: [25, 0, 16], state: "minecraft:sand"},
        {pos: [1, 1, 9], state: "minecraft:sand"},
        {pos: [1, 1, 10], state: "minecraft:sand"},
        {pos: [1, 1, 11], state: "minecraft:sand"},
        {pos: [1, 1, 12], state: "minecraft:sand"},
        {pos: [1, 1, 13], state: "minecraft:sand"},
        {pos: [1, 1, 14], state: "minecraft:sand"},
        {pos: [1, 1, 15], state: "minecraft:sand"},
        {pos: [1, 1, 16], state: "minecraft:sand"},
        {pos: [1, 1, 17], state: "minecraft:sand"},
        {pos: [2, 1, 5], state: "minecraft:sand"},
        {pos: [2, 1, 6], state: "minecraft:sand"},
        {pos: [2, 1, 7], state: "minecraft:sand"},
        {pos: [2, 1, 8], state: "minecraft:sand"},
        {pos: [2, 1, 9], state: "minecraft:sand"},
        {pos: [2, 1, 10], state: "minecraft:sand"},
        {pos: [2, 1, 11], state: "minecraft:sand"},
        {pos: [2, 1, 12], state: "minecraft:sand"},
        {pos: [2, 1, 13], state: "minecraft:sand"},
        {pos: [2, 1, 14], state: "minecraft:sand"},
        {pos: [2, 1, 15], state: "minecraft:sand"},
        {pos: [2, 1, 16], state: "minecraft:sand"},
        {pos: [2, 1, 17], state: "minecraft:sand"},
        {pos: [2, 1, 18], state: "minecraft:sand"},
        {pos: [2, 1, 19], state: "minecraft:sand"},
        {pos: [2, 1, 20], state: "minecraft:sand"},
        {pos: [3, 1, 5], state: "minecraft:sand"},
        {pos: [3, 1, 6], state: "minecraft:sandstone"},
        {pos: [3, 1, 7], state: "minecraft:sandstone"},
        {pos: [3, 1, 8], state: "minecraft:sand"},
        {pos: [3, 1, 9], state: "minecraft:sand"},
        {pos: [3, 1, 10], state: "minecraft:sandstone"},
        {pos: [3, 1, 11], state: "minecraft:sandstone"},
        {pos: [3, 1, 12], state: "minecraft:sand"},
        {pos: [3, 1, 13], state: "minecraft:sand"},
        {pos: [3, 1, 14], state: "minecraft:sand"},
        {pos: [3, 1, 15], state: "minecraft:sand"},
        {pos: [3, 1, 16], state: "minecraft:sandstone"},
        {pos: [3, 1, 17], state: "minecraft:sandstone"},
        {pos: [3, 1, 18], state: "minecraft:sand"},
        {pos: [3, 1, 19], state: "minecraft:sand"},
        {pos: [3, 1, 20], state: "minecraft:sand"},
        {pos: [3, 1, 21], state: "minecraft:sand"},
        {pos: [4, 1, 4], state: "minecraft:sand"},
        {pos: [4, 1, 5], state: "minecraft:sand"},
        {pos: [4, 1, 6], state: "minecraft:sandstone"},
        {pos: [4, 1, 7], state: "minecraft:sandstone"},
        {pos: [4, 1, 8], state: "minecraft:sandstone"},
        {pos: [4, 1, 9], state: "minecraft:sand"},
        {pos: [4, 1, 10], state: "minecraft:sandstone"},
        {pos: [4, 1, 11], state: "minecraft:sandstone"},
        {pos: [4, 1, 12], state: "minecraft:sandstone"},
        {pos: [4, 1, 13], state: "minecraft:sand"},
        {pos: [4, 1, 14], state: "minecraft:sand"},
        {pos: [4, 1, 15], state: "minecraft:sandstone"},
        {pos: [4, 1, 16], state: "minecraft:sandstone"},
        {pos: [4, 1, 17], state: "minecraft:sandstone"},
        {pos: [4, 1, 18], state: "minecraft:sand"},
        {pos: [4, 1, 19], state: "minecraft:sand"},
        {pos: [4, 1, 20], state: "minecraft:sand"},
        {pos: [4, 1, 21], state: "minecraft:sand"},
        {pos: [4, 1, 22], state: "minecraft:sand"},
        {pos: [5, 1, 4], state: "minecraft:sand"},
        {pos: [5, 1, 5], state: "minecraft:sand"},
        {pos: [5, 1, 6], state: "minecraft:sandstone"},
        {pos: [5, 1, 7], state: "minecraft:sandstone"},
        {pos: [5, 1, 8], state: "minecraft:sandstone"},
        {pos: [5, 1, 9], state: "minecraft:sandstone"},
        {pos: [5, 1, 10], state: "minecraft:sand"},
        {pos: [5, 1, 11], state: "minecraft:sandstone"},
        {pos: [5, 1, 12], state: "minecraft:sandstone"},
        {pos: [5, 1, 13], state: "minecraft:sand"},
        {pos: [5, 1, 14], state: "minecraft:sand"},
        {pos: [5, 1, 15], state: "minecraft:sandstone"},
        {pos: [5, 1, 16], state: "minecraft:sandstone"},
        {pos: [5, 1, 17], state: "minecraft:sand"},
        {pos: [5, 1, 18], state: "minecraft:sand"},
        {pos: [5, 1, 19], state: "minecraft:sand"},
        {pos: [5, 1, 20], state: "minecraft:sand"},
        {pos: [5, 1, 21], state: "minecraft:sand"},
        {pos: [5, 1, 22], state: "minecraft:sand"},
        {pos: [6, 1, 3], state: "minecraft:sand"},
        {pos: [6, 1, 4], state: "minecraft:sand"},
        {pos: [6, 1, 5], state: "minecraft:sand"},
        {pos: [6, 1, 6], state: "minecraft:sand"},
        {pos: [6, 1, 7], state: "minecraft:sandstone"},
        {pos: [6, 1, 8], state: "minecraft:sandstone"},
        {pos: [6, 1, 9], state: "minecraft:sandstone"},
        {pos: [6, 1, 10], state: "minecraft:sand"},
        {pos: [6, 1, 11], state: "minecraft:sand"},
        {pos: [6, 1, 12], state: "minecraft:sand"},
        {pos: [6, 1, 13], state: "minecraft:sand"},
        {pos: [6, 1, 14], state: "minecraft:sand"},
        {pos: [6, 1, 15], state: "minecraft:sand"},
        {pos: [6, 1, 16], state: "minecraft:sand"},
        {pos: [6, 1, 17], state: "minecraft:sand"},
        {pos: [6, 1, 18], state: "minecraft:sand"},
        {pos: [6, 1, 19], state: "minecraft:sandstone"},
        {pos: [6, 1, 20], state: "minecraft:sandstone"},
        {pos: [6, 1, 21], state: "minecraft:sand"},
        {pos: [6, 1, 22], state: "minecraft:sand"},
        {pos: [7, 1, 2], state: "minecraft:sand"},
        {pos: [7, 1, 3], state: "minecraft:smooth_sandstone"},
        {pos: [7, 1, 4], state: "minecraft:smooth_sandstone"},
        {pos: [7, 1, 5], state: "minecraft:smooth_sandstone"},
        {pos: [7, 1, 6], state: "minecraft:sand"},
        {pos: [7, 1, 7], state: "minecraft:sand"},
        {pos: [7, 1, 8], state: "minecraft:sand"},
        {pos: [7, 1, 9], state: "minecraft:sand"},
        {pos: [7, 1, 10], state: "minecraft:sand"},
        {pos: [7, 1, 11], state: "minecraft:sand"},
        {pos: [7, 1, 12], state: "minecraft:sand"},
        {pos: [7, 1, 13], state: "minecraft:sand"},
        {pos: [7, 1, 14], state: "minecraft:sand"},
        {pos: [7, 1, 15], state: "minecraft:sand"},
        {pos: [7, 1, 16], state: "minecraft:sand"},
        {pos: [7, 1, 17], state: "minecraft:sand"},
        {pos: [7, 1, 18], state: "minecraft:sandstone"},
        {pos: [7, 1, 19], state: "minecraft:sandstone"},
        {pos: [7, 1, 20], state: "minecraft:sandstone"},
        {pos: [7, 1, 21], state: "minecraft:sand"},
        {pos: [7, 1, 22], state: "minecraft:sand"},
        {pos: [8, 1, 2], state: "minecraft:sand"},
        {pos: [8, 1, 3], state: "minecraft:smooth_sandstone"},
        {pos: [8, 1, 4], state: "minecraft:sandstone"},
        {pos: [8, 1, 5], state: "minecraft:smooth_sandstone"},
        {pos: [8, 1, 6], state: "minecraft:sand"},
        {pos: [8, 1, 7], state: "minecraft:sand"},
        {pos: [8, 1, 8], state: "minecraft:sand"},
        {pos: [8, 1, 9], state: "minecraft:sand"},
        {pos: [8, 1, 10], state: "minecraft:sand"},
        {pos: [8, 1, 11], state: "minecraft:sand"},
        {pos: [8, 1, 12], state: "minecraft:sand"},
        {pos: [8, 1, 13], state: "minecraft:sand"},
        {pos: [8, 1, 14], state: "minecraft:sand"},
        {pos: [8, 1, 15], state: "minecraft:sand"},
        {pos: [8, 1, 16], state: "minecraft:sand"},
        {pos: [8, 1, 17], state: "minecraft:sand"},
        {pos: [8, 1, 18], state: "minecraft:sandstone"},
        {pos: [8, 1, 19], state: "minecraft:sandstone"},
        {pos: [8, 1, 20], state: "minecraft:sand"},
        {pos: [8, 1, 21], state: "minecraft:sand"},
        {pos: [8, 1, 22], state: "minecraft:sand"},
        {pos: [8, 1, 23], state: "minecraft:sand"},
        {pos: [9, 1, 2], state: "minecraft:sand"},
        {pos: [9, 1, 3], state: "minecraft:sandstone"},
        {pos: [9, 1, 4], state: "minecraft:sandstone"},
        {pos: [9, 1, 5], state: "minecraft:smooth_sandstone"},
        {pos: [9, 1, 6], state: "minecraft:sand"},
        {pos: [9, 1, 7], state: "minecraft:sand"},
        {pos: [9, 1, 8], state: "minecraft:sand"},
        {pos: [9, 1, 9], state: "minecraft:sand"},
        {pos: [9, 1, 10], state: "minecraft:sand"},
        {pos: [9, 1, 11], state: "minecraft:sand"},
        {pos: [9, 1, 12], state: "minecraft:sand"},
        {pos: [9, 1, 13], state: "minecraft:sand"},
        {pos: [9, 1, 14], state: "minecraft:sand"},
        {pos: [9, 1, 15], state: "minecraft:sand"},
        {pos: [9, 1, 16], state: "minecraft:sand"},
        {pos: [9, 1, 17], state: "minecraft:sand"},
        {pos: [9, 1, 18], state: "minecraft:sand"},
        {pos: [9, 1, 19], state: "minecraft:sand"},
        {pos: [9, 1, 20], state: "minecraft:sand"},
        {pos: [9, 1, 21], state: "minecraft:sand"},
        {pos: [9, 1, 22], state: "minecraft:sand"},
        {pos: [9, 1, 23], state: "minecraft:sand"},
        {pos: [10, 1, 3], state: "minecraft:sand"},
        {pos: [10, 1, 4], state: "minecraft:sandstone"},
        {pos: [10, 1, 5], state: "minecraft:sand"},
        {pos: [10, 1, 6], state: "minecraft:sand"},
        {pos: [10, 1, 7], state: "minecraft:sand"},
        {pos: [10, 1, 8], state: "minecraft:sand"},
        {pos: [10, 1, 9], state: "minecraft:sand"},
        {pos: [10, 1, 10], state: "minecraft:sand"},
        {pos: [10, 1, 11], state: "minecraft:sand"},
        {pos: [10, 1, 12], state: "minecraft:sandstone"},
        {pos: [10, 1, 13], state: "minecraft:sandstone"},
        {pos: [10, 1, 14], state: "minecraft:sandstone"},
        {pos: [10, 1, 15], state: "minecraft:sand"},
        {pos: [10, 1, 16], state: "minecraft:sand"},
        {pos: [10, 1, 17], state: "minecraft:sand"},
        {pos: [10, 1, 18], state: "minecraft:sand"},
        {pos: [10, 1, 19], state: "minecraft:sand"},
        {pos: [10, 1, 20], state: "minecraft:sand"},
        {pos: [10, 1, 21], state: "minecraft:sand"},
        {pos: [10, 1, 22], state: "minecraft:sand"},
        {pos: [10, 1, 23], state: "minecraft:sand"},
        {pos: [11, 1, 3], state: "minecraft:sand"},
        {pos: [11, 1, 4], state: "minecraft:sandstone"},
        {pos: [11, 1, 5], state: "minecraft:sand"},
        {pos: [11, 1, 6], state: "minecraft:sand"},
        {pos: [11, 1, 7], state: "minecraft:sand"},
        {pos: [11, 1, 8], state: "minecraft:sand"},
        {pos: [11, 1, 9], state: "minecraft:sand"},
        {pos: [11, 1, 10], state: "minecraft:sand"},
        {pos: [11, 1, 11], state: "minecraft:sand"},
        {pos: [11, 1, 12], state: "minecraft:sandstone"},
        {pos: [11, 1, 13], state: "minecraft:sandstone"},
        {pos: [11, 1, 14], state: "minecraft:sandstone"},
        {pos: [11, 1, 15], state: "minecraft:sand"},
        {pos: [11, 1, 16], state: "minecraft:sand"},
        {pos: [11, 1, 17], state: "minecraft:sand"},
        {pos: [11, 1, 18], state: "minecraft:sand"},
        {pos: [11, 1, 19], state: "minecraft:sand"},
        {pos: [11, 1, 20], state: "minecraft:sand"},
        {pos: [11, 1, 21], state: "minecraft:sand"},
        {pos: [11, 1, 22], state: "minecraft:sand"},
        {pos: [11, 1, 23], state: "minecraft:sand"},
        {pos: [12, 1, 3], state: "minecraft:sand"},
        {pos: [12, 1, 4], state: "minecraft:sand"},
        {pos: [12, 1, 5], state: "minecraft:sand"},
        {pos: [12, 1, 6], state: "minecraft:sand"},
        {pos: [12, 1, 7], state: "minecraft:sand"},
        {pos: [12, 1, 8], state: "minecraft:sand"},
        {pos: [12, 1, 9], state: "minecraft:sand"},
        {pos: [12, 1, 10], state: "minecraft:sand"},
        {pos: [12, 1, 11], state: "minecraft:sand"},
        {pos: [12, 1, 12], state: "minecraft:sand"},
        {pos: [12, 1, 13], state: "minecraft:sandstone"},
        {pos: [12, 1, 14], state: "minecraft:sandstone"},
        {pos: [12, 1, 15], state: "minecraft:sand"},
        {pos: [12, 1, 16], state: "minecraft:sand"},
        {pos: [12, 1, 17], state: "minecraft:sand"},
        {pos: [12, 1, 18], state: "minecraft:sand"},
        {pos: [12, 1, 19], state: "minecraft:sandstone"},
        {pos: [12, 1, 20], state: "minecraft:sandstone"},
        {pos: [12, 1, 21], state: "minecraft:sand"},
        {pos: [12, 1, 22], state: "minecraft:sand"},
        {pos: [12, 1, 23], state: "minecraft:sand"},
        {pos: [13, 1, 4], state: "minecraft:sand"},
        {pos: [13, 1, 5], state: "minecraft:sand"},
        {pos: [13, 1, 6], state: "minecraft:sand"},
        {pos: [13, 1, 7], state: "minecraft:sand"},
        {pos: [13, 1, 8], state: "minecraft:sand"},
        {pos: [13, 1, 9], state: "minecraft:sand"},
        {pos: [13, 1, 10], state: "minecraft:sand"},
        {pos: [13, 1, 11], state: "minecraft:sand"},
        {pos: [13, 1, 12], state: "minecraft:sand"},
        {pos: [13, 1, 13], state: "minecraft:sand"},
        {pos: [13, 1, 14], state: "minecraft:sand"},
        {pos: [13, 1, 15], state: "minecraft:sand"},
        {pos: [13, 1, 16], state: "minecraft:sand"},
        {pos: [13, 1, 17], state: "minecraft:sand"},
        {pos: [13, 1, 18], state: "minecraft:sand"},
        {pos: [13, 1, 19], state: "minecraft:sandstone"},
        {pos: [13, 1, 20], state: "minecraft:sandstone"},
        {pos: [13, 1, 21], state: "minecraft:sandstone"},
        {pos: [13, 1, 22], state: "minecraft:sand"},
        {pos: [13, 1, 23], state: "minecraft:sand"},
        {pos: [14, 1, 4], state: "minecraft:sand"},
        {pos: [14, 1, 5], state: "minecraft:sand"},
        {pos: [14, 1, 6], state: "minecraft:sand"},
        {pos: [14, 1, 7], state: "minecraft:sand"},
        {pos: [14, 1, 8], state: "minecraft:sandstone"},
        {pos: [14, 1, 9], state: "minecraft:sandstone"},
        {pos: [14, 1, 10], state: "minecraft:sand"},
        {pos: [14, 1, 11], state: "minecraft:sand"},
        {pos: [14, 1, 12], state: "minecraft:sand"},
        {pos: [14, 1, 13], state: "minecraft:sand"},
        {pos: [14, 1, 14], state: "minecraft:sand"},
        {pos: [14, 1, 15], state: "minecraft:sand"},
        {pos: [14, 1, 16], state: "minecraft:sand"},
        {pos: [14, 1, 17], state: "minecraft:sand"},
        {pos: [14, 1, 18], state: "minecraft:sand"},
        {pos: [14, 1, 19], state: "minecraft:sandstone"},
        {pos: [14, 1, 20], state: "minecraft:sandstone"},
        {pos: [14, 1, 21], state: "minecraft:sandstone"},
        {pos: [14, 1, 22], state: "minecraft:sand"},
        {pos: [14, 1, 23], state: "minecraft:sand"},
        {pos: [15, 1, 3], state: "minecraft:sand"},
        {pos: [15, 1, 4], state: "minecraft:smooth_sandstone"},
        {pos: [15, 1, 5], state: "minecraft:sand"},
        {pos: [15, 1, 6], state: "minecraft:sand"},
        {pos: [15, 1, 7], state: "minecraft:sand"},
        {pos: [15, 1, 8], state: "minecraft:sandstone"},
        {pos: [15, 1, 9], state: "minecraft:sandstone"},
        {pos: [15, 1, 10], state: "minecraft:sand"},
        {pos: [15, 1, 11], state: "minecraft:sand"},
        {pos: [15, 1, 12], state: "minecraft:sand"},
        {pos: [15, 1, 13], state: "minecraft:sand"},
        {pos: [15, 1, 14], state: "minecraft:sand"},
        {pos: [15, 1, 15], state: "minecraft:sand"},
        {pos: [15, 1, 16], state: "minecraft:sand"},
        {pos: [15, 1, 17], state: "minecraft:sand"},
        {pos: [15, 1, 18], state: "minecraft:sand"},
        {pos: [15, 1, 19], state: "minecraft:sandstone"},
        {pos: [15, 1, 20], state: "minecraft:sandstone"},
        {pos: [15, 1, 21], state: "minecraft:sandstone"},
        {pos: [15, 1, 22], state: "minecraft:sand"},
        {pos: [15, 1, 23], state: "minecraft:sand"},
        {pos: [16, 1, 2], state: "minecraft:sand"},
        {pos: [16, 1, 3], state: "minecraft:sand"},
        {pos: [16, 1, 4], state: "minecraft:sandstone"},
        {pos: [16, 1, 5], state: "minecraft:sand"},
        {pos: [16, 1, 6], state: "minecraft:sand"},
        {pos: [16, 1, 7], state: "minecraft:sand"},
        {pos: [16, 1, 8], state: "minecraft:sand"},
        {pos: [16, 1, 9], state: "minecraft:sand"},
        {pos: [16, 1, 10], state: "minecraft:sand"},
        {pos: [16, 1, 11], state: "minecraft:sand"},
        {pos: [16, 1, 12], state: "minecraft:sand"},
        {pos: [16, 1, 13], state: "minecraft:sand"},
        {pos: [16, 1, 14], state: "minecraft:sand"},
        {pos: [16, 1, 15], state: "minecraft:sand"},
        {pos: [16, 1, 16], state: "minecraft:sand"},
        {pos: [16, 1, 17], state: "minecraft:sand"},
        {pos: [16, 1, 18], state: "minecraft:sand"},
        {pos: [16, 1, 19], state: "minecraft:sand"},
        {pos: [16, 1, 20], state: "minecraft:sandstone"},
        {pos: [16, 1, 21], state: "minecraft:sand"},
        {pos: [16, 1, 22], state: "minecraft:sand"},
        {pos: [17, 1, 1], state: "minecraft:sand"},
        {pos: [17, 1, 2], state: "minecraft:sand"},
        {pos: [17, 1, 3], state: "minecraft:smooth_sandstone"},
        {pos: [17, 1, 4], state: "minecraft:sandstone"},
        {pos: [17, 1, 5], state: "minecraft:sandstone"},
        {pos: [17, 1, 6], state: "minecraft:sand"},
        {pos: [17, 1, 7], state: "minecraft:sand"},
        {pos: [17, 1, 8], state: "minecraft:sand"},
        {pos: [17, 1, 9], state: "minecraft:sand"},
        {pos: [17, 1, 10], state: "minecraft:sand"},
        {pos: [17, 1, 11], state: "minecraft:sand"},
        {pos: [17, 1, 12], state: "minecraft:sand"},
        {pos: [17, 1, 13], state: "minecraft:sand"},
        {pos: [17, 1, 14], state: "minecraft:sand"},
        {pos: [17, 1, 15], state: "minecraft:sand"},
        {pos: [17, 1, 16], state: "minecraft:sand"},
        {pos: [17, 1, 17], state: "minecraft:sand"},
        {pos: [17, 1, 18], state: "minecraft:sand"},
        {pos: [17, 1, 19], state: "minecraft:sand"},
        {pos: [17, 1, 20], state: "minecraft:sand"},
        {pos: [17, 1, 21], state: "minecraft:sand"},
        {pos: [17, 1, 22], state: "minecraft:sand"},
        {pos: [18, 1, 2], state: "minecraft:sand"},
        {pos: [18, 1, 3], state: "minecraft:sandstone"},
        {pos: [18, 1, 4], state: "minecraft:sandstone"},
        {pos: [18, 1, 5], state: "minecraft:sandstone"},
        {pos: [18, 1, 6], state: "minecraft:sand"},
        {pos: [18, 1, 7], state: "minecraft:sand"},
        {pos: [18, 1, 8], state: "minecraft:sand"},
        {pos: [18, 1, 9], state: "minecraft:sand"},
        {pos: [18, 1, 10], state: "minecraft:sand"},
        {pos: [18, 1, 11], state: "minecraft:sand"},
        {pos: [18, 1, 12], state: "minecraft:sand"},
        {pos: [18, 1, 13], state: "minecraft:sand"},
        {pos: [18, 1, 14], state: "minecraft:sand"},
        {pos: [18, 1, 15], state: "minecraft:sand"},
        {pos: [18, 1, 16], state: "minecraft:sand"},
        {pos: [18, 1, 17], state: "minecraft:sand"},
        {pos: [18, 1, 18], state: "minecraft:sandstone"},
        {pos: [18, 1, 19], state: "minecraft:sandstone"},
        {pos: [18, 1, 20], state: "minecraft:sand"},
        {pos: [18, 1, 21], state: "minecraft:sand"},
        {pos: [18, 1, 22], state: "minecraft:sand"},
        {pos: [19, 1, 2], state: "minecraft:sand"},
        {pos: [19, 1, 3], state: "minecraft:sandstone"},
        {pos: [19, 1, 4], state: "minecraft:sandstone"},
        {pos: [19, 1, 5], state: "minecraft:smooth_sandstone"},
        {pos: [19, 1, 6], state: "minecraft:sand"},
        {pos: [19, 1, 7], state: "minecraft:sand"},
        {pos: [19, 1, 8], state: "minecraft:sand"},
        {pos: [19, 1, 9], state: "minecraft:sandstone"},
        {pos: [19, 1, 10], state: "minecraft:sandstone"},
        {pos: [19, 1, 11], state: "minecraft:sandstone"},
        {pos: [19, 1, 12], state: "minecraft:sand"},
        {pos: [19, 1, 13], state: "minecraft:sand"},
        {pos: [19, 1, 14], state: "minecraft:sand"},
        {pos: [19, 1, 15], state: "minecraft:sand"},
        {pos: [19, 1, 16], state: "minecraft:sand"},
        {pos: [19, 1, 17], state: "minecraft:sandstone"},
        {pos: [19, 1, 18], state: "minecraft:sandstone"},
        {pos: [19, 1, 19], state: "minecraft:sandstone"},
        {pos: [19, 1, 20], state: "minecraft:sand"},
        {pos: [19, 1, 21], state: "minecraft:sand"},
        {pos: [20, 1, 3], state: "minecraft:sand"},
        {pos: [20, 1, 4], state: "minecraft:sand"},
        {pos: [20, 1, 5], state: "minecraft:sand"},
        {pos: [20, 1, 6], state: "minecraft:sand"},
        {pos: [20, 1, 7], state: "minecraft:sandstone"},
        {pos: [20, 1, 8], state: "minecraft:sandstone"},
        {pos: [20, 1, 9], state: "minecraft:sandstone"},
        {pos: [20, 1, 10], state: "minecraft:sandstone"},
        {pos: [20, 1, 11], state: "minecraft:sandstone"},
        {pos: [20, 1, 12], state: "minecraft:sand"},
        {pos: [20, 1, 13], state: "minecraft:sandstone"},
        {pos: [20, 1, 14], state: "minecraft:sandstone"},
        {pos: [20, 1, 15], state: "minecraft:sandstone"},
        {pos: [20, 1, 16], state: "minecraft:sandstone"},
        {pos: [20, 1, 17], state: "minecraft:sandstone"},
        {pos: [20, 1, 18], state: "minecraft:sandstone"},
        {pos: [20, 1, 19], state: "minecraft:sand"},
        {pos: [20, 1, 20], state: "minecraft:sand"},
        {pos: [20, 1, 21], state: "minecraft:sand"},
        {pos: [21, 1, 4], state: "minecraft:sand"},
        {pos: [21, 1, 5], state: "minecraft:sand"},
        {pos: [21, 1, 6], state: "minecraft:sandstone"},
        {pos: [21, 1, 7], state: "minecraft:sandstone"},
        {pos: [21, 1, 8], state: "minecraft:sandstone"},
        {pos: [21, 1, 9], state: "minecraft:sand"},
        {pos: [21, 1, 10], state: "minecraft:sandstone"},
        {pos: [21, 1, 11], state: "minecraft:sandstone"},
        {pos: [21, 1, 12], state: "minecraft:sandstone"},
        {pos: [21, 1, 13], state: "minecraft:sandstone"},
        {pos: [21, 1, 14], state: "minecraft:sandstone"},
        {pos: [21, 1, 15], state: "minecraft:sandstone"},
        {pos: [21, 1, 16], state: "minecraft:sandstone"},
        {pos: [21, 1, 17], state: "minecraft:sand"},
        {pos: [21, 1, 18], state: "minecraft:sand"},
        {pos: [21, 1, 19], state: "minecraft:sand"},
        {pos: [21, 1, 20], state: "minecraft:sand"},
        {pos: [21, 1, 21], state: "minecraft:sand"},
        {pos: [22, 1, 5], state: "minecraft:sand"},
        {pos: [22, 1, 6], state: "minecraft:sandstone"},
        {pos: [22, 1, 7], state: "minecraft:sandstone"},
        {pos: [22, 1, 8], state: "minecraft:sand"},
        {pos: [22, 1, 9], state: "minecraft:sand"},
        {pos: [22, 1, 10], state: "minecraft:sand"},
        {pos: [22, 1, 11], state: "minecraft:sand"},
        {pos: [22, 1, 12], state: "minecraft:sandstone"},
        {pos: [22, 1, 13], state: "minecraft:sandstone"},
        {pos: [22, 1, 14], state: "minecraft:sand"},
        {pos: [22, 1, 15], state: "minecraft:sand"},
        {pos: [22, 1, 16], state: "minecraft:sand"},
        {pos: [22, 1, 17], state: "minecraft:sand"},
        {pos: [22, 1, 18], state: "minecraft:sand"},
        {pos: [22, 1, 19], state: "minecraft:sand"},
        {pos: [23, 1, 7], state: "minecraft:sand"},
        {pos: [23, 1, 8], state: "minecraft:sand"},
        {pos: [23, 1, 12], state: "minecraft:sand"},
        {pos: [23, 1, 13], state: "minecraft:sand"},
        {pos: [23, 1, 14], state: "minecraft:sand"},
        {pos: [23, 1, 15], state: "minecraft:sand"},
        {pos: [23, 1, 16], state: "minecraft:sand"},
        {pos: [2, 2, 15], state: "minecraft:sand"},
        {pos: [2, 2, 16], state: "minecraft:sand"},
        {pos: [2, 2, 17], state: "minecraft:sand"},
        {pos: [2, 2, 18], state: "minecraft:sand"},
        {pos: [3, 2, 6], state: "minecraft:sandstone"},
        {pos: [3, 2, 7], state: "minecraft:sandstone"},
        {pos: [3, 2, 8], state: "minecraft:sand"},
        {pos: [3, 2, 9], state: "minecraft:sand"},
        {pos: [3, 2, 10], state: "minecraft:sandstone"},
        {pos: [3, 2, 11], state: "minecraft:sandstone"},
        {pos: [3, 2, 12], state: "minecraft:sand"},
        {pos: [3, 2, 14], state: "minecraft:sand"},
        {pos: [3, 2, 15], state: "minecraft:sand"},
        {pos: [3, 2, 16], state: "minecraft:sandstone"},
        {pos: [3, 2, 17], state: "minecraft:sandstone"},
        {pos: [3, 2, 18], state: "minecraft:sand"},
        {pos: [3, 2, 19], state: "minecraft:sand"},
        {pos: [4, 2, 5], state: "minecraft:sand"},
        {pos: [4, 2, 6], state: "minecraft:sandstone"},
        {pos: [4, 2, 7], state: "minecraft:sandstone"},
        {pos: [4, 2, 8], state: "minecraft:sandstone"},
        {pos: [4, 2, 9], state: "minecraft:sand"},
        {pos: [4, 2, 10], state: "minecraft:sandstone"},
        {pos: [4, 2, 11], state: "minecraft:sandstone"},
        {pos: [4, 2, 12], state: "minecraft:sandstone"},
        {pos: [4, 2, 13], state: "minecraft:sand"},
        {pos: [4, 2, 14], state: "minecraft:sand"},
        {pos: [4, 2, 15], state: "minecraft:sandstone"},
        {pos: [4, 2, 16], state: "minecraft:sandstone"},
        {pos: [4, 2, 17], state: "minecraft:sandstone"},
        {pos: [4, 2, 18], state: "minecraft:sand"},
        {pos: [4, 2, 19], state: "minecraft:sand"},
        {pos: [5, 2, 5], state: "minecraft:sand"},
        {pos: [5, 2, 6], state: "minecraft:sandstone"},
        {pos: [5, 2, 7], state: "minecraft:sandstone"},
        {pos: [5, 2, 8], state: "minecraft:sandstone"},
        {pos: [5, 2, 9], state: "minecraft:sandstone"},
        {pos: [5, 2, 10], state: "minecraft:sand"},
        {pos: [5, 2, 11], state: "minecraft:sandstone"},
        {pos: [5, 2, 12], state: "minecraft:sandstone"},
        {pos: [5, 2, 13], state: "minecraft:sand"},
        {pos: [5, 2, 14], state: "minecraft:sand"},
        {pos: [5, 2, 15], state: "minecraft:sandstone"},
        {pos: [5, 2, 16], state: "minecraft:sandstone"},
        {pos: [5, 2, 17], state: "minecraft:sand"},
        {pos: [5, 2, 18], state: "minecraft:sand"},
        {pos: [5, 2, 19], state: "minecraft:sand"},
        {pos: [5, 2, 20], state: "minecraft:sand"},
        {pos: [6, 2, 4], state: "minecraft:sand"},
        {pos: [6, 2, 5], state: "minecraft:sand"},
        {pos: [6, 2, 6], state: "minecraft:sand"},
        {pos: [6, 2, 7], state: "minecraft:sandstone"},
        {pos: [6, 2, 8], state: "minecraft:sandstone"},
        {pos: [6, 2, 9], state: "minecraft:sandstone"},
        {pos: [6, 2, 10], state: "minecraft:sand"},
        {pos: [6, 2, 11], state: "minecraft:sand"},
        {pos: [6, 2, 12], state: "minecraft:sand"},
        {pos: [6, 2, 13], state: "minecraft:sand"},
        {pos: [6, 2, 14], state: "minecraft:sand"},
        {pos: [6, 2, 15], state: "minecraft:sand"},
        {pos: [6, 2, 16], state: "minecraft:sand"},
        {pos: [6, 2, 17], state: "minecraft:sand"},
        {pos: [6, 2, 18], state: "minecraft:sand"},
        {pos: [6, 2, 19], state: "minecraft:sandstone"},
        {pos: [6, 2, 20], state: "minecraft:sandstone"},
        {pos: [7, 2, 3], state: "minecraft:smooth_sandstone"},
        {pos: [7, 2, 4], state: "minecraft:smooth_sandstone"},
        {pos: [7, 2, 5], state: "minecraft:smooth_sandstone"},
        {pos: [7, 2, 6], state: "minecraft:sand"},
        {pos: [7, 2, 7], state: "minecraft:sand"},
        {pos: [7, 2, 8], state: "minecraft:sand"},
        {pos: [7, 2, 9], state: "minecraft:sand"},
        {pos: [7, 2, 10], state: "minecraft:sand"},
        {pos: [7, 2, 11], state: "minecraft:sand"},
        {pos: [7, 2, 12], state: "minecraft:sand"},
        {pos: [7, 2, 13], state: "minecraft:sand"},
        {pos: [7, 2, 14], state: "minecraft:sand"},
        {pos: [7, 2, 15], state: "minecraft:sand"},
        {pos: [7, 2, 16], state: "minecraft:sand"},
        {pos: [7, 2, 17], state: "minecraft:sand"},
        {pos: [7, 2, 18], state: "minecraft:sandstone"},
        {pos: [7, 2, 19], state: "minecraft:sandstone"},
        {pos: [7, 2, 20], state: "minecraft:sandstone"},
        {pos: [8, 2, 3], state: "minecraft:smooth_sandstone"},
        {pos: [8, 2, 4], state: "minecraft:smooth_sandstone"},
        {pos: [8, 2, 5], state: "minecraft:smooth_sandstone"},
        {pos: [8, 2, 6], state: "minecraft:sand"},
        {pos: [8, 2, 7], state: "minecraft:sand"},
        {pos: [8, 2, 10], state: "minecraft:sand"},
        {pos: [8, 2, 11], state: "minecraft:sand"},
        {pos: [8, 2, 12], state: "minecraft:sand"},
        {pos: [8, 2, 13], state: "minecraft:sand"},
        {pos: [8, 2, 14], state: "minecraft:sand"},
        {pos: [8, 2, 15], state: "minecraft:sand"},
        {pos: [8, 2, 16], state: "minecraft:sand"},
        {pos: [8, 2, 17], state: "minecraft:sand"},
        {pos: [8, 2, 18], state: "minecraft:sandstone"},
        {pos: [8, 2, 19], state: "minecraft:sandstone"},
        {pos: [8, 2, 20], state: "minecraft:sand"},
        {pos: [8, 2, 21], state: "minecraft:sand"},
        {pos: [9, 2, 3], state: "minecraft:smooth_sandstone"},
        {pos: [9, 2, 4], state: "minecraft:sandstone"},
        {pos: [9, 2, 5], state: "minecraft:smooth_sandstone"},
        {pos: [9, 2, 6], state: "minecraft:sand"},
        {pos: [9, 2, 10], state: "minecraft:sand"},
        {pos: [9, 2, 11], state: "minecraft:sand"},
        {pos: [9, 2, 12], state: "minecraft:sand"},
        {pos: [9, 2, 13], state: "minecraft:sand"},
        {pos: [9, 2, 14], state: "minecraft:sand"},
        {pos: [9, 2, 15], state: "minecraft:sand"},
        {pos: [9, 2, 16], state: "minecraft:sand"},
        {pos: [9, 2, 17], state: "minecraft:sand"},
        {pos: [9, 2, 18], state: "minecraft:sand"},
        {pos: [9, 2, 19], state: "minecraft:sand"},
        {pos: [9, 2, 20], state: "minecraft:sand"},
        {pos: [10, 2, 4], state: "minecraft:smooth_sandstone"},
        {pos: [10, 2, 5], state: "minecraft:sand"},
        {pos: [10, 2, 6], state: "minecraft:sand"},
        {pos: [10, 2, 11], state: "minecraft:sand"},
        {pos: [10, 2, 12], state: "minecraft:sandstone"},
        {pos: [10, 2, 13], state: "minecraft:sandstone"},
        {pos: [10, 2, 14], state: "minecraft:sandstone"},
        {pos: [10, 2, 15], state: "minecraft:sand"},
        {pos: [10, 2, 16], state: "minecraft:sand"},
        {pos: [10, 2, 17], state: "minecraft:sand"},
        {pos: [11, 2, 4], state: "minecraft:smooth_sandstone"},
        {pos: [11, 2, 5], state: "minecraft:sand"},
        {pos: [11, 2, 11], state: "minecraft:sand"},
        {pos: [11, 2, 12], state: "minecraft:sandstone"},
        {pos: [11, 2, 13], state: "minecraft:sandstone"},
        {pos: [11, 2, 14], state: "minecraft:sandstone"},
        {pos: [11, 2, 15], state: "minecraft:sand"},
        {pos: [11, 2, 16], state: "minecraft:sand"},
        {pos: [12, 2, 11], state: "minecraft:sand"},
        {pos: [12, 2, 12], state: "minecraft:sand"},
        {pos: [12, 2, 13], state: "minecraft:sandstone"},
        {pos: [12, 2, 14], state: "minecraft:sandstone"},
        {pos: [12, 2, 15], state: "minecraft:sand"},
        {pos: [12, 2, 19], state: "minecraft:sandstone"},
        {pos: [12, 2, 20], state: "minecraft:sandstone"},
        {pos: [13, 2, 7], state: "minecraft:sand"},
        {pos: [13, 2, 8], state: "minecraft:sand"},
        {pos: [13, 2, 9], state: "minecraft:sand"},
        {pos: [13, 2, 12], state: "minecraft:sand"},
        {pos: [13, 2, 13], state: "minecraft:sand"},
        {pos: [13, 2, 14], state: "minecraft:sand"},
        {pos: [13, 2, 15], state: "minecraft:sand"},
        {pos: [13, 2, 19], state: "minecraft:sandstone"},
        {pos: [13, 2, 20], state: "minecraft:sandstone"},
        {pos: [13, 2, 21], state: "minecraft:sandstone"},
        {pos: [14, 2, 6], state: "minecraft:sand"},
        {pos: [14, 2, 7], state: "minecraft:sand"},
        {pos: [14, 2, 8], state: "minecraft:sandstone"},
        {pos: [14, 2, 9], state: "minecraft:sandstone"},
        {pos: [14, 2, 10], state: "minecraft:sand"},
        {pos: [14, 2, 13], state: "minecraft:sand"},
        {pos: [14, 2, 14], state: "minecraft:sand"},
        {pos: [14, 2, 19], state: "minecraft:sandstone"},
        {pos: [14, 2, 20], state: "minecraft:sandstone"},
        {pos: [14, 2, 21], state: "minecraft:sandstone"},
        {pos: [15, 2, 4], state: "minecraft:smooth_sandstone"},
        {pos: [15, 2, 5], state: "minecraft:sand"},
        {pos: [15, 2, 6], state: "minecraft:sand"},
        {pos: [15, 2, 7], state: "minecraft:sand"},
        {pos: [15, 2, 8], state: "minecraft:sandstone"},
        {pos: [15, 2, 9], state: "minecraft:sandstone"},
        {pos: [15, 2, 10], state: "minecraft:sand"},
        {pos: [15, 2, 19], state: "minecraft:sandstone"},
        {pos: [15, 2, 20], state: "minecraft:sandstone"},
        {pos: [15, 2, 21], state: "minecraft:sandstone"},
        {pos: [16, 2, 3], state: "minecraft:sand"},
        {pos: [16, 2, 4], state: "minecraft:sandstone"},
        {pos: [16, 2, 5], state: "minecraft:sand"},
        {pos: [16, 2, 6], state: "minecraft:sand"},
        {pos: [16, 2, 7], state: "minecraft:sand"},
        {pos: [16, 2, 8], state: "minecraft:sand"},
        {pos: [16, 2, 9], state: "minecraft:sand"},
        {pos: [16, 2, 10], state: "minecraft:sand"},
        {pos: [16, 2, 11], state: "minecraft:sand"},
        {pos: [16, 2, 17], state: "minecraft:sand"},
        {pos: [16, 2, 18], state: "minecraft:sand"},
        {pos: [16, 2, 19], state: "minecraft:sand"},
        {pos: [16, 2, 20], state: "minecraft:sandstone"},
        {pos: [17, 2, 2], state: "minecraft:sand"},
        {pos: [17, 2, 3], state: "minecraft:smooth_sandstone"},
        {pos: [17, 2, 4], state: "minecraft:smooth_sandstone"},
        {pos: [17, 2, 5], state: "minecraft:smooth_sandstone"},
        {pos: [17, 2, 6], state: "minecraft:sand"},
        {pos: [17, 2, 7], state: "minecraft:sand"},
        {pos: [17, 2, 8], state: "minecraft:sand"},
        {pos: [17, 2, 9], state: "minecraft:sand"},
        {pos: [17, 2, 10], state: "minecraft:sand"},
        {pos: [17, 2, 11], state: "minecraft:sand"},
        {pos: [17, 2, 12], state: "minecraft:sand"},
        {pos: [17, 2, 13], state: "minecraft:sand"},
        {pos: [17, 2, 16], state: "minecraft:sand"},
        {pos: [17, 2, 17], state: "minecraft:sand"},
        {pos: [17, 2, 18], state: "minecraft:sand"},
        {pos: [17, 2, 19], state: "minecraft:sand"},
        {pos: [17, 2, 20], state: "minecraft:sand"},
        {pos: [18, 2, 2], state: "minecraft:sand"},
        {pos: [18, 2, 3], state: "minecraft:smooth_sandstone"},
        {pos: [18, 2, 4], state: "minecraft:smooth_sandstone"},
        {pos: [18, 2, 5], state: "minecraft:sandstone"},
        {pos: [18, 2, 6], state: "minecraft:sand"},
        {pos: [18, 2, 7], state: "minecraft:sand"},
        {pos: [18, 2, 8], state: "minecraft:sand"},
        {pos: [18, 2, 9], state: "minecraft:sand"},
        {pos: [18, 2, 10], state: "minecraft:sand"},
        {pos: [18, 2, 11], state: "minecraft:sand"},
        {pos: [18, 2, 12], state: "minecraft:sand"},
        {pos: [18, 2, 13], state: "minecraft:sand"},
        {pos: [18, 2, 14], state: "minecraft:sand"},
        {pos: [18, 2, 16], state: "minecraft:sand"},
        {pos: [18, 2, 17], state: "minecraft:sand"},
        {pos: [18, 2, 18], state: "minecraft:sandstone"},
        {pos: [18, 2, 19], state: "minecraft:sandstone"},
        {pos: [18, 2, 20], state: "minecraft:sand"},
        {pos: [19, 2, 3], state: "minecraft:smooth_sandstone"},
        {pos: [19, 2, 4], state: "minecraft:smooth_sandstone"},
        {pos: [19, 2, 5], state: "minecraft:smooth_sandstone"},
        {pos: [19, 2, 6], state: "minecraft:sand"},
        {pos: [19, 2, 7], state: "minecraft:sand"},
        {pos: [19, 2, 8], state: "minecraft:sand"},
        {pos: [19, 2, 9], state: "minecraft:sandstone"},
        {pos: [19, 2, 10], state: "minecraft:sandstone"},
        {pos: [19, 2, 11], state: "minecraft:sandstone"},
        {pos: [19, 2, 12], state: "minecraft:sand"},
        {pos: [19, 2, 13], state: "minecraft:sand"},
        {pos: [19, 2, 14], state: "minecraft:sand"},
        {pos: [19, 2, 15], state: "minecraft:sand"},
        {pos: [19, 2, 16], state: "minecraft:sand"},
        {pos: [19, 2, 17], state: "minecraft:sandstone"},
        {pos: [19, 2, 18], state: "minecraft:sandstone"},
        {pos: [19, 2, 19], state: "minecraft:sandstone"},
        {pos: [19, 2, 20], state: "minecraft:sand"},
        {pos: [20, 2, 4], state: "minecraft:sand"},
        {pos: [20, 2, 5], state: "minecraft:sand"},
        {pos: [20, 2, 6], state: "minecraft:sand"},
        {pos: [20, 2, 7], state: "minecraft:sandstone"},
        {pos: [20, 2, 8], state: "minecraft:sandstone"},
        {pos: [20, 2, 9], state: "minecraft:sandstone"},
        {pos: [20, 2, 10], state: "minecraft:sandstone"},
        {pos: [20, 2, 11], state: "minecraft:sandstone"},
        {pos: [20, 2, 12], state: "minecraft:sand"},
        {pos: [20, 2, 13], state: "minecraft:sandstone"},
        {pos: [20, 2, 14], state: "minecraft:sandstone"},
        {pos: [20, 2, 15], state: "minecraft:sandstone"},
        {pos: [20, 2, 16], state: "minecraft:sandstone"},
        {pos: [20, 2, 17], state: "minecraft:sandstone"},
        {pos: [20, 2, 18], state: "minecraft:sandstone"},
        {pos: [20, 2, 19], state: "minecraft:sand"},
        {pos: [21, 2, 5], state: "minecraft:sand"},
        {pos: [21, 2, 6], state: "minecraft:sandstone"},
        {pos: [21, 2, 7], state: "minecraft:sandstone"},
        {pos: [21, 2, 8], state: "minecraft:sandstone"},
        {pos: [21, 2, 9], state: "minecraft:sand"},
        {pos: [21, 2, 10], state: "minecraft:sandstone"},
        {pos: [21, 2, 11], state: "minecraft:sandstone"},
        {pos: [21, 2, 12], state: "minecraft:sandstone"},
        {pos: [21, 2, 13], state: "minecraft:sandstone"},
        {pos: [21, 2, 14], state: "minecraft:sandstone"},
        {pos: [21, 2, 15], state: "minecraft:sandstone"},
        {pos: [21, 2, 16], state: "minecraft:sandstone"},
        {pos: [21, 2, 17], state: "minecraft:sand"},
        {pos: [21, 2, 18], state: "minecraft:sand"},
        {pos: [22, 2, 6], state: "minecraft:sandstone"},
        {pos: [22, 2, 7], state: "minecraft:sandstone"},
        {pos: [22, 2, 8], state: "minecraft:sand"},
        {pos: [22, 2, 11], state: "minecraft:sand"},
        {pos: [22, 2, 12], state: "minecraft:sandstone"},
        {pos: [22, 2, 13], state: "minecraft:sandstone"},
        {pos: [22, 2, 14], state: "minecraft:sand"},
        {pos: [22, 2, 15], state: "minecraft:sand"},
        {pos: [3, 3, 16], state: "minecraft:sand"},
        {pos: [3, 3, 17], state: "minecraft:sandstone"},
        {pos: [4, 3, 6], state: "minecraft:sand"},
        {pos: [4, 3, 7], state: "minecraft:sandstone"},
        {pos: [4, 3, 8], state: "minecraft:sandstone"},
        {pos: [4, 3, 10], state: "minecraft:sandstone"},
        {pos: [4, 3, 11], state: "minecraft:sandstone"},
        {pos: [4, 3, 15], state: "minecraft:smooth_sandstone"},
        {pos: [4, 3, 16], state: "minecraft:sandstone"},
        {pos: [4, 3, 17], state: "minecraft:sandstone"},
        {pos: [5, 3, 6], state: "minecraft:sand"},
        {pos: [5, 3, 7], state: "minecraft:sandstone"},
        {pos: [5, 3, 8], state: "minecraft:sandstone"},
        {pos: [5, 3, 15], state: "minecraft:sandstone"},
        {pos: [5, 3, 16], state: "minecraft:sandstone"},
        {pos: [6, 3, 5], state: "minecraft:sand"},
        {pos: [6, 3, 6], state: "minecraft:sand"},
        {pos: [6, 3, 7], state: "minecraft:sand"},
        {pos: [6, 3, 8], state: "minecraft:sandstone"},
        {pos: [6, 3, 19], state: "minecraft:sandstone"},
        {pos: [6, 3, 20], state: "minecraft:smooth_sandstone"},
        {pos: [7, 3, 3], state: "minecraft:smooth_sandstone"},
        {pos: [7, 3, 4], state: "minecraft:smooth_sandstone"},
        {pos: [7, 3, 5], state: "minecraft:smooth_sandstone"},
        {pos: [7, 3, 6], state: "minecraft:sand"},
        {pos: [7, 3, 7], state: "minecraft:sand"},
        {pos: [7, 3, 18], state: "minecraft:sandstone"},
        {pos: [7, 3, 19], state: "minecraft:sandstone"},
        {pos: [7, 3, 20], state: "minecraft:sandstone"},
        {pos: [8, 3, 3], state: "minecraft:smooth_sandstone"},
        {pos: [8, 3, 4], state: "minecraft:smooth_sandstone"},
        {pos: [8, 3, 5], state: "minecraft:smooth_sandstone"},
        {pos: [8, 3, 6], state: "minecraft:sand"},
        {pos: [8, 3, 12], state: "minecraft:sand"},
        {pos: [8, 3, 13], state: "minecraft:sand"},
        {pos: [8, 3, 14], state: "minecraft:sand"},
        {pos: [8, 3, 18], state: "minecraft:sandstone"},
        {pos: [8, 3, 19], state: "minecraft:sandstone"},
        {pos: [9, 3, 3], state: "minecraft:smooth_sandstone"},
        {pos: [9, 3, 4], state: "minecraft:smooth_sandstone"},
        {pos: [9, 3, 5], state: "minecraft:smooth_sandstone"},
        {pos: [9, 3, 6], state: "minecraft:sand"},
        {pos: [9, 3, 12], state: "minecraft:sand"},
        {pos: [9, 3, 13], state: "minecraft:sand"},
        {pos: [9, 3, 14], state: "minecraft:sand"},
        {pos: [9, 3, 15], state: "minecraft:sand"},
        {pos: [10, 3, 4], state: "minecraft:blue_terracotta"},
        {pos: [10, 3, 5], state: "minecraft:sand"},
        {pos: [10, 3, 12], state: "minecraft:sandstone"},
        {pos: [10, 3, 13], state: "minecraft:sandstone"},
        {pos: [10, 3, 14], state: "minecraft:sandstone"},
        {pos: [10, 3, 15], state: "minecraft:sand"},
        {pos: [11, 3, 4], state: "minecraft:blue_terracotta"},
        {pos: [11, 3, 12], state: "minecraft:sand"},
        {pos: [11, 3, 13], state: "minecraft:sandstone"},
        {pos: [11, 3, 14], state: "minecraft:sandstone"},
        {pos: [11, 3, 15], state: "minecraft:sand"},
        {pos: [12, 3, 13], state: "minecraft:sand"},
        {pos: [12, 3, 14], state: "minecraft:sand"},
        {pos: [12, 3, 20], state: "minecraft:sandstone"},
        {pos: [13, 3, 20], state: "minecraft:sandstone"},
        {pos: [13, 3, 21], state: "minecraft:sandstone"},
        {pos: [14, 3, 8], state: "minecraft:smooth_sandstone"},
        {pos: [14, 3, 9], state: "minecraft:sandstone"},
        {pos: [14, 3, 19], state: "minecraft:sandstone"},
        {pos: [14, 3, 20], state: "minecraft:sandstone"},
        {pos: [14, 3, 21], state: "minecraft:sandstone"},
        {pos: [15, 3, 4], state: "minecraft:blue_terracotta"},
        {pos: [15, 3, 8], state: "minecraft:smooth_sandstone"},
        {pos: [15, 3, 9], state: "minecraft:sandstone"},
        {pos: [15, 3, 19], state: "minecraft:sandstone"},
        {pos: [15, 3, 20], state: "minecraft:sandstone"},
        {pos: [16, 3, 4], state: "minecraft:blue_terracotta"},
        {pos: [16, 3, 5], state: "minecraft:sand"},
        {pos: [16, 3, 6], state: "minecraft:sand"},
        {pos: [17, 3, 3], state: "minecraft:smooth_sandstone"},
        {pos: [17, 3, 4], state: "minecraft:smooth_sandstone"},
        {pos: [17, 3, 5], state: "minecraft:smooth_sandstone"},
        {pos: [17, 3, 6], state: "minecraft:sand"},
        {pos: [17, 3, 7], state: "minecraft:sand"},
        {pos: [18, 3, 3], state: "minecraft:smooth_sandstone"},
        {pos: [18, 3, 4], state: "minecraft:smooth_sandstone"},
        {pos: [18, 3, 5], state: "minecraft:smooth_sandstone"},
        {pos: [18, 3, 6], state: "minecraft:sand"},
        {pos: [18, 3, 7], state: "minecraft:sand"},
        {pos: [18, 3, 8], state: "minecraft:sand"},
        {pos: [18, 3, 9], state: "minecraft:sand"},
        {pos: [18, 3, 10], state: "minecraft:sand"},
        {pos: [18, 3, 18], state: "minecraft:sandstone"},
        {pos: [18, 3, 19], state: "minecraft:sandstone"},
        {pos: [19, 3, 3], state: "minecraft:smooth_sandstone"},
        {pos: [19, 3, 4], state: "minecraft:smooth_sandstone"},
        {pos: [19, 3, 5], state: "minecraft:smooth_sandstone"},
        {pos: [19, 3, 6], state: "minecraft:sand"},
        {pos: [19, 3, 7], state: "minecraft:sand"},
        {pos: [19, 3, 8], state: "minecraft:sand"},
        {pos: [19, 3, 9], state: "minecraft:sandstone"},
        {pos: [19, 3, 10], state: "minecraft:sandstone"},
        {pos: [19, 3, 11], state: "minecraft:sandstone"},
        {pos: [19, 3, 12], state: "minecraft:sand"},
        {pos: [19, 3, 18], state: "minecraft:sandstone"},
        {pos: [19, 3, 19], state: "minecraft:sandstone"},
        {pos: [20, 3, 7], state: "minecraft:sandstone"},
        {pos: [20, 3, 8], state: "minecraft:sandstone"},
        {pos: [20, 3, 9], state: "minecraft:sandstone"},
        {pos: [20, 3, 10], state: "minecraft:sandstone"},
        {pos: [20, 3, 11], state: "minecraft:sand"},
        {pos: [20, 3, 12], state: "minecraft:sand"},
        {pos: [20, 3, 13], state: "minecraft:smooth_sandstone"},
        {pos: [20, 3, 14], state: "minecraft:sand"},
        {pos: [20, 3, 15], state: "minecraft:sandstone"},
        {pos: [20, 3, 16], state: "minecraft:sandstone"},
        {pos: [20, 3, 17], state: "minecraft:sand"},
        {pos: [20, 3, 18], state: "minecraft:sand"},
        {pos: [21, 3, 6], state: "minecraft:sandstone"},
        {pos: [21, 3, 7], state: "minecraft:sandstone"},
        {pos: [21, 3, 8], state: "minecraft:smooth_sandstone"},
        {pos: [21, 3, 10], state: "minecraft:sand"},
        {pos: [21, 3, 11], state: "minecraft:sand"},
        {pos: [21, 3, 12], state: "minecraft:sandstone"},
        {pos: [21, 3, 13], state: "minecraft:smooth_sandstone"},
        {pos: [21, 3, 14], state: "minecraft:smooth_sandstone"},
        {pos: [21, 3, 15], state: "minecraft:sandstone"},
        {pos: [21, 3, 16], state: "minecraft:sandstone"},
        {pos: [22, 3, 12], state: "minecraft:sandstone"},
        {pos: [22, 3, 13], state: "minecraft:smooth_sandstone"},
        {pos: [4, 4, 7], state: "minecraft:sandstone"},
        {pos: [4, 4, 8], state: "minecraft:sandstone"},
        {pos: [4, 4, 15], state: "minecraft:smooth_sandstone"},
        {pos: [4, 4, 16], state: "minecraft:smooth_sandstone"},
        {pos: [5, 4, 7], state: "minecraft:sandstone"},
        {pos: [5, 4, 8], state: "minecraft:sandstone"},
        {pos: [5, 4, 15], state: "minecraft:smooth_sandstone"},
        {pos: [5, 4, 16], state: "minecraft:sandstone"},
        {pos: [6, 4, 19], state: "minecraft:sandstone"},
        {pos: [6, 4, 20], state: "minecraft:smooth_sandstone"},
        {pos: [7, 4, 3], state: "minecraft:smooth_sandstone"},
        {pos: [7, 4, 4], state: "minecraft:smooth_sandstone"},
        {pos: [7, 4, 5], state: "minecraft:sandstone"},
        {pos: [7, 4, 19], state: "minecraft:smooth_sandstone"},
        {pos: [7, 4, 20], state: "minecraft:smooth_sandstone"},
        {pos: [8, 4, 3], state: "minecraft:smooth_sandstone"},
        {pos: [8, 4, 4], state: "minecraft:smooth_sandstone"},
        {pos: [8, 4, 5], state: "minecraft:smooth_sandstone"},
        {pos: [9, 4, 3], state: "minecraft:smooth_sandstone"},
        {pos: [9, 4, 4], state: "minecraft:smooth_sandstone"},
        {pos: [9, 4, 5], state: "minecraft:smooth_sandstone"},
        {pos: [10, 4, 4], state: "minecraft:chiseled_sandstone"},
        {pos: [10, 4, 13], state: "minecraft:smooth_sandstone"},
        {pos: [10, 4, 14], state: "minecraft:smooth_sandstone"},
        {pos: [11, 4, 4], state: "minecraft:chiseled_sandstone"},
        {pos: [11, 4, 13], state: "minecraft:sandstone"},
        {pos: [11, 4, 14], state: "minecraft:smooth_sandstone"},
        {pos: [13, 4, 20], state: "minecraft:smooth_sandstone"},
        {pos: [13, 4, 21], state: "minecraft:sandstone"},
        {pos: [14, 4, 8], state: "minecraft:cut_sandstone"},
        {pos: [14, 4, 9], state: "minecraft:cut_sandstone"},
        {pos: [14, 4, 20], state: "minecraft:sandstone"},
        {pos: [14, 4, 21], state: "minecraft:sandstone"},
        {pos: [15, 4, 4], state: "minecraft:chiseled_sandstone"},
        {pos: [15, 4, 8], state: "minecraft:cut_sandstone"},
        {pos: [15, 4, 9], state: "minecraft:cut_sandstone"},
        {pos: [16, 4, 4], state: "minecraft:chiseled_sandstone"},
        {pos: [17, 4, 3], state: "minecraft:smooth_sandstone"},
        {pos: [17, 4, 4], state: "minecraft:smooth_sandstone"},
        {pos: [17, 4, 5], state: "minecraft:smooth_sandstone"},
        {pos: [18, 4, 3], state: "minecraft:smooth_sandstone"},
        {pos: [18, 4, 4], state: "minecraft:smooth_sandstone"},
        {pos: [18, 4, 5], state: "minecraft:smooth_sandstone"},
        {pos: [18, 4, 18], state: "minecraft:sandstone"},
        {pos: [18, 4, 19], state: "minecraft:smooth_sandstone"},
        {pos: [19, 4, 3], state: "minecraft:smooth_sandstone"},
        {pos: [19, 4, 4], state: "minecraft:smooth_sandstone"},
        {pos: [19, 4, 5], state: "minecraft:smooth_sandstone"},
        {pos: [19, 4, 18], state: "minecraft:sandstone"},
        {pos: [19, 4, 19], state: "minecraft:smooth_sandstone"},
        {pos: [20, 4, 7], state: "minecraft:smooth_sandstone"},
        {pos: [20, 4, 8], state: "minecraft:smooth_sandstone"},
        {pos: [21, 4, 7], state: "minecraft:sandstone"},
        {pos: [21, 4, 8], state: "minecraft:smooth_sandstone"},
        {pos: [21, 4, 12], state: "minecraft:smooth_sandstone"},
        {pos: [21, 4, 13], state: "minecraft:smooth_sandstone"},
        {pos: [22, 4, 12], state: "minecraft:sandstone"},
        {pos: [22, 4, 13], state: "minecraft:smooth_sandstone"},
        {pos: [4, 5, 7], state: "minecraft:smooth_sandstone"},
        {pos: [4, 5, 8], state: "minecraft:smooth_sandstone"},
        {pos: [4, 5, 15], state: "minecraft:smooth_sandstone"},
        {pos: [4, 5, 16], state: "minecraft:smooth_sandstone"},
        {pos: [5, 5, 7], state: "minecraft:sandstone"},
        {pos: [5, 5, 8], state: "minecraft:smooth_sandstone"},
        {pos: [5, 5, 15], state: "minecraft:smooth_sandstone"},
        {pos: [5, 5, 16], state: "minecraft:smooth_sandstone"},
        {pos: [6, 5, 19], state: "minecraft:smooth_sandstone"},
        {pos: [6, 5, 20], state: "minecraft:sandstone"},
        {pos: [7, 5, 3], state: "minecraft:smooth_sandstone"},
        {pos: [7, 5, 4], state: "minecraft:sandstone"},
        {pos: [7, 5, 5], state: "minecraft:sandstone"},
        {pos: [7, 5, 19], state: "minecraft:smooth_sandstone"},
        {pos: [7, 5, 20], state: "minecraft:smooth_sandstone"},
        {pos: [8, 5, 3], state: "minecraft:smooth_sandstone"},
        {pos: [8, 5, 4], state: "minecraft:smooth_sandstone"},
        {pos: [8, 5, 5], state: "minecraft:smooth_sandstone"},
        {pos: [9, 5, 3], state: "minecraft:smooth_sandstone"},
        {pos: [9, 5, 4], state: "minecraft:smooth_sandstone"},
        {pos: [9, 5, 5], state: "minecraft:smooth_sandstone"},
        {pos: [10, 5, 4], state: "minecraft:yellow_terracotta"},
        {pos: [10, 5, 13], state: "minecraft:smooth_sandstone"},
        {pos: [10, 5, 14], state: "minecraft:smooth_sandstone"},
        {pos: [11, 5, 4], state: "minecraft:yellow_terracotta"},
        {pos: [11, 5, 13], state: "minecraft:smooth_sandstone"},
        {pos: [11, 5, 14], state: "minecraft:smooth_sandstone"},
        {pos: [13, 5, 20], state: "minecraft:smooth_sandstone"},
        {pos: [13, 5, 21], state: "minecraft:smooth_sandstone"},
        {pos: [14, 5, 20], state: "minecraft:sandstone"},
        {pos: [14, 5, 21], state: "minecraft:smooth_sandstone"},
        {pos: [15, 5, 4], state: "minecraft:yellow_terracotta"},
        {pos: [16, 5, 4], state: "minecraft:yellow_terracotta"},
        {pos: [17, 5, 3], state: "minecraft:sandstone"},
        {pos: [17, 5, 4], state: "minecraft:smooth_sandstone"},
        {pos: [17, 5, 5], state: "minecraft:smooth_sandstone"},
        {pos: [18, 5, 3], state: "minecraft:smooth_sandstone"},
        {pos: [18, 5, 4], state: "minecraft:smooth_sandstone"},
        {pos: [18, 5, 5], state: "minecraft:smooth_sandstone"},
        {pos: [18, 5, 18], state: "minecraft:smooth_sandstone"},
        {pos: [18, 5, 19], state: "minecraft:smooth_sandstone"},
        {pos: [19, 5, 3], state: "minecraft:smooth_sandstone"},
        {pos: [19, 5, 4], state: "minecraft:smooth_sandstone"},
        {pos: [19, 5, 5], state: "minecraft:smooth_sandstone"},
        {pos: [19, 5, 18], state: "minecraft:smooth_sandstone"},
        {pos: [19, 5, 19], state: "minecraft:smooth_sandstone"},
        {pos: [20, 5, 7], state: "minecraft:smooth_sandstone"},
        {pos: [20, 5, 8], state: "minecraft:smooth_sandstone"},
        {pos: [21, 5, 7], state: "minecraft:smooth_sandstone"},
        {pos: [21, 5, 8], state: "minecraft:smooth_sandstone"},
        {pos: [21, 5, 12], state: "minecraft:smooth_sandstone"},
        {pos: [21, 5, 13], state: "minecraft:smooth_sandstone"},
        {pos: [22, 5, 12], state: "minecraft:smooth_sandstone"},
        {pos: [22, 5, 13], state: "minecraft:smooth_sandstone"},
        {pos: [4, 6, 7], state: "minecraft:smooth_sandstone"},
        {pos: [4, 6, 8], state: "minecraft:smooth_sandstone"},
        {pos: [4, 6, 15], state: "minecraft:sandstone"},
        {pos: [4, 6, 16], state: "minecraft:smooth_sandstone"},
        {pos: [5, 6, 7], state: "minecraft:smooth_sandstone"},
        {pos: [5, 6, 8], state: "minecraft:smooth_sandstone"},
        {pos: [5, 6, 15], state: "minecraft:smooth_sandstone"},
        {pos: [5, 6, 16], state: "minecraft:smooth_sandstone"},
        {pos: [6, 6, 19], state: "minecraft:sandstone"},
        {pos: [6, 6, 20], state: "minecraft:sandstone"},
        {pos: [7, 6, 3], state: "minecraft:sandstone"},
        {pos: [7, 6, 4], state: "minecraft:sandstone"},
        {pos: [7, 6, 5], state: "minecraft:sandstone"},
        {pos: [7, 6, 19], state: "minecraft:smooth_sandstone"},
        {pos: [7, 6, 20], state: "minecraft:sandstone"},
        {pos: [8, 6, 3], state: "minecraft:smooth_sandstone"},
        {pos: [8, 6, 4], state: "minecraft:sandstone"},
        {pos: [8, 6, 5], state: "minecraft:sandstone"},
        {pos: [9, 6, 3], state: "minecraft:smooth_sandstone"},
        {pos: [9, 6, 4], state: "minecraft:smooth_sandstone"},
        {pos: [9, 6, 5], state: "minecraft:smooth_sandstone"},
        {pos: [10, 6, 4], state: "minecraft:smooth_sandstone"},
        {pos: [10, 6, 13], state: "minecraft:smooth_sandstone"},
        {pos: [10, 6, 14], state: "minecraft:smooth_sandstone"},
        {pos: [11, 6, 4], state: "minecraft:smooth_sandstone"},
        {pos: [11, 6, 13], state: "minecraft:smooth_sandstone"},
        {pos: [11, 6, 14], state: "minecraft:smooth_sandstone"},
        {pos: [13, 6, 20], state: "minecraft:smooth_sandstone"},
        {pos: [13, 6, 21], state: "minecraft:smooth_sandstone"},
        {pos: [14, 6, 20], state: "minecraft:smooth_sandstone"},
        {pos: [14, 6, 21], state: "minecraft:smooth_sandstone"},
        {pos: [15, 6, 4], state: "minecraft:smooth_sandstone"},
        {pos: [16, 6, 4], state: "minecraft:smooth_sandstone"},
        {pos: [17, 6, 3], state: "minecraft:sandstone"},
        {pos: [17, 6, 4], state: "minecraft:smooth_sandstone"},
        {pos: [17, 6, 5], state: "minecraft:sandstone"},
        {pos: [18, 6, 3], state: "minecraft:smooth_sandstone"},
        {pos: [18, 6, 4], state: "minecraft:smooth_sandstone"},
        {pos: [18, 6, 5], state: "minecraft:smooth_sandstone"},
        {pos: [18, 6, 18], state: "minecraft:smooth_sandstone"},
        {pos: [18, 6, 19], state: "minecraft:smooth_sandstone"},
        {pos: [19, 6, 3], state: "minecraft:smooth_sandstone"},
        {pos: [19, 6, 4], state: "minecraft:smooth_sandstone"},
        {pos: [19, 6, 5], state: "minecraft:sandstone"},
        {pos: [19, 6, 18], state: "minecraft:smooth_sandstone"},
        {pos: [19, 6, 19], state: "minecraft:smooth_sandstone"},
        {pos: [20, 6, 7], state: "minecraft:cut_sandstone"},
        {pos: [20, 6, 8], state: "minecraft:cut_sandstone"},
        {pos: [21, 6, 7], state: "minecraft:cut_sandstone"},
        {pos: [21, 6, 8], state: "minecraft:cut_sandstone"},
        {pos: [21, 6, 12], state: "minecraft:smooth_sandstone"},
        {pos: [21, 6, 13], state: "minecraft:smooth_sandstone"},
        {pos: [22, 6, 12], state: "minecraft:smooth_sandstone"},
        {pos: [22, 6, 13], state: "minecraft:smooth_sandstone"},
        {pos: [4, 7, 7], state: "minecraft:cut_sandstone"},
        {pos: [4, 7, 8], state: "minecraft:cut_sandstone"},
        {pos: [4, 7, 15], state: "minecraft:sandstone"},
        {pos: [4, 7, 16], state: "minecraft:sandstone"},
        {pos: [5, 7, 7], state: "minecraft:cut_sandstone"},
        {pos: [5, 7, 8], state: "minecraft:cut_sandstone"},
        {pos: [5, 7, 15], state: "minecraft:sandstone"},
        {pos: [5, 7, 16], state: "minecraft:smooth_sandstone"},
        {pos: [6, 7, 19], state: "minecraft:cut_sandstone"},
        {pos: [6, 7, 20], state: "minecraft:cut_sandstone"},
        {pos: [7, 7, 3], state: "minecraft:smooth_sandstone"},
        {pos: [7, 7, 4], state: "minecraft:sandstone"},
        {pos: [7, 7, 5], state: "minecraft:sandstone"},
        {pos: [7, 7, 19], state: "minecraft:cut_sandstone"},
        {pos: [7, 7, 20], state: "minecraft:cut_sandstone"},
        {pos: [8, 7, 3], state: "minecraft:smooth_sandstone"},
        {pos: [8, 7, 4], state: "minecraft:sandstone"},
        {pos: [8, 7, 5], state: "minecraft:sandstone"},
        {pos: [9, 7, 3], state: "minecraft:sandstone"},
        {pos: [9, 7, 4], state: "minecraft:sandstone"},
        {pos: [9, 7, 5], state: "minecraft:sandstone"},
        {pos: [10, 7, 4], state: "minecraft:cut_sandstone"},
        {pos: [10, 7, 13], state: "minecraft:smooth_sandstone"},
        {pos: [10, 7, 14], state: "minecraft:smooth_sandstone"},
        {pos: [11, 7, 4], state: "minecraft:cut_sandstone"},
        {pos: [11, 7, 13], state: "minecraft:smooth_sandstone"},
        {pos: [11, 7, 14], state: "minecraft:smooth_sandstone"},
        {pos: [12, 7, 4], state: "minecraft:smooth_sandstone"},
        {pos: [13, 7, 4], state: "minecraft:smooth_sandstone"},
        {pos: [13, 7, 20], state: "minecraft:smooth_sandstone"},
        {pos: [13, 7, 21], state: "minecraft:smooth_sandstone"},
        {pos: [14, 7, 4], state: "minecraft:smooth_sandstone"},
        {pos: [14, 7, 20], state: "minecraft:smooth_sandstone"},
        {pos: [14, 7, 21], state: "minecraft:smooth_sandstone"},
        {pos: [15, 7, 4], state: "minecraft:cut_sandstone"},
        {pos: [16, 7, 4], state: "minecraft:cut_sandstone"},
        {pos: [17, 7, 3], state: "minecraft:sandstone"},
        {pos: [17, 7, 4], state: "minecraft:sandstone"},
        {pos: [17, 7, 5], state: "minecraft:sandstone"},
        {pos: [18, 7, 3], state: "minecraft:sandstone"},
        {pos: [18, 7, 4], state: "minecraft:smooth_sandstone"},
        {pos: [18, 7, 5], state: "minecraft:sandstone"},
        {pos: [18, 7, 18], state: "minecraft:smooth_sandstone"},
        {pos: [18, 7, 19], state: "minecraft:smooth_sandstone"},
        {pos: [19, 7, 3], state: "minecraft:sandstone"},
        {pos: [19, 7, 4], state: "minecraft:sandstone"},
        {pos: [19, 7, 5], state: "minecraft:sandstone"},
        {pos: [19, 7, 18], state: "minecraft:smooth_sandstone"},
        {pos: [19, 7, 19], state: "minecraft:smooth_sandstone"},
        {pos: [21, 7, 12], state: "minecraft:cut_sandstone"},
        {pos: [21, 7, 13], state: "minecraft:cut_sandstone"},
        {pos: [22, 7, 12], state: "minecraft:cut_sandstone"},
        {pos: [22, 7, 13], state: "minecraft:cut_sandstone"},
        {pos: [4, 8, 15], state: "minecraft:cut_sandstone"},
        {pos: [4, 8, 16], state: "minecraft:cut_sandstone"},
        {pos: [5, 8, 15], state: "minecraft:cut_sandstone"},
        {pos: [5, 8, 16], state: "minecraft:cut_sandstone"},
        {pos: [6, 8, 2], state: "minecraft:smooth_sandstone"},
        {pos: [6, 8, 3], state: "minecraft:smooth_sandstone"},
        {pos: [6, 8, 4], state: "minecraft:smooth_sandstone"},
        {pos: [6, 8, 5], state: "minecraft:smooth_sandstone"},
        {pos: [6, 8, 6], state: "minecraft:smooth_sandstone"},
        {pos: [7, 8, 2], state: "minecraft:smooth_sandstone"},
        {pos: [7, 8, 3], state: "minecraft:smooth_sandstone"},
        {pos: [7, 8, 4], state: "minecraft:smooth_sandstone"},
        {pos: [7, 8, 5], state: "minecraft:smooth_sandstone"},
        {pos: [7, 8, 6], state: "minecraft:smooth_sandstone"},
        {pos: [8, 8, 2], state: "minecraft:smooth_sandstone"},
        {pos: [8, 8, 3], state: "minecraft:smooth_sandstone"},
        {pos: [8, 8, 4], state: "minecraft:smooth_sandstone"},
        {pos: [8, 8, 5], state: "minecraft:smooth_sandstone"},
        {pos: [8, 8, 6], state: "minecraft:smooth_sandstone"},
        {pos: [9, 8, 2], state: "minecraft:smooth_sandstone"},
        {pos: [9, 8, 3], state: "minecraft:smooth_sandstone"},
        {pos: [9, 8, 4], state: "minecraft:smooth_sandstone"},
        {pos: [9, 8, 5], state: "minecraft:smooth_sandstone"},
        {pos: [9, 8, 6], state: "minecraft:smooth_sandstone"},
        {pos: [10, 8, 2], state: "minecraft:smooth_sandstone"},
        {pos: [10, 8, 3], state: "minecraft:smooth_sandstone"},
        {pos: [10, 8, 4], state: "minecraft:smooth_sandstone"},
        {pos: [10, 8, 5], state: "minecraft:smooth_sandstone"},
        {pos: [10, 8, 6], state: "minecraft:smooth_sandstone"},
        {pos: [10, 8, 13], state: "minecraft:cut_sandstone"},
        {pos: [10, 8, 14], state: "minecraft:cut_sandstone"},
        {pos: [11, 8, 13], state: "minecraft:cut_sandstone"},
        {pos: [11, 8, 14], state: "minecraft:cut_sandstone"},
        {pos: [12, 8, 4], state: "minecraft:cut_sandstone"},
        {pos: [13, 8, 4], state: "minecraft:cut_sandstone"},
        {pos: [13, 8, 20], state: "minecraft:smooth_sandstone"},
        {pos: [13, 8, 21], state: "minecraft:smooth_sandstone"},
        {pos: [14, 8, 4], state: "minecraft:cut_sandstone"},
        {pos: [14, 8, 20], state: "minecraft:smooth_sandstone"},
        {pos: [14, 8, 21], state: "minecraft:smooth_sandstone"},
        {pos: [16, 8, 2], state: "minecraft:smooth_sandstone"},
        {pos: [16, 8, 3], state: "minecraft:smooth_sandstone"},
        {pos: [16, 8, 4], state: "minecraft:smooth_sandstone"},
        {pos: [16, 8, 5], state: "minecraft:smooth_sandstone"},
        {pos: [16, 8, 6], state: "minecraft:smooth_sandstone"},
        {pos: [17, 8, 2], state: "minecraft:smooth_sandstone"},
        {pos: [17, 8, 3], state: "minecraft:smooth_sandstone"},
        {pos: [17, 8, 4], state: "minecraft:smooth_sandstone"},
        {pos: [17, 8, 5], state: "minecraft:smooth_sandstone"},
        {pos: [17, 8, 6], state: "minecraft:smooth_sandstone"},
        {pos: [18, 8, 2], state: "minecraft:smooth_sandstone"},
        {pos: [18, 8, 3], state: "minecraft:smooth_sandstone"},
        {pos: [18, 8, 4], state: "minecraft:smooth_sandstone"},
        {pos: [18, 8, 5], state: "minecraft:smooth_sandstone"},
        {pos: [18, 8, 6], state: "minecraft:smooth_sandstone"},
        {pos: [18, 8, 18], state: "minecraft:cut_sandstone"},
        {pos: [18, 8, 19], state: "minecraft:cut_sandstone"},
        {pos: [19, 8, 2], state: "minecraft:smooth_sandstone"},
        {pos: [19, 8, 3], state: "minecraft:smooth_sandstone"},
        {pos: [19, 8, 4], state: "minecraft:smooth_sandstone"},
        {pos: [19, 8, 5], state: "minecraft:smooth_sandstone"},
        {pos: [19, 8, 6], state: "minecraft:smooth_sandstone"},
        {pos: [19, 8, 18], state: "minecraft:cut_sandstone"},
        {pos: [19, 8, 19], state: "minecraft:cut_sandstone"},
        {pos: [20, 8, 2], state: "minecraft:smooth_sandstone"},
        {pos: [20, 8, 3], state: "minecraft:smooth_sandstone"},
        {pos: [20, 8, 4], state: "minecraft:smooth_sandstone"},
        {pos: [20, 8, 5], state: "minecraft:smooth_sandstone"},
        {pos: [20, 8, 6], state: "minecraft:smooth_sandstone"},
        {pos: [6, 9, 2], state: "minecraft:cut_sandstone"},
        {pos: [6, 9, 3], state: "minecraft:cut_sandstone"},
        {pos: [6, 9, 4], state: "minecraft:cut_sandstone"},
        {pos: [6, 9, 5], state: "minecraft:cut_sandstone"},
        {pos: [6, 9, 6], state: "minecraft:cut_sandstone"},
        {pos: [7, 9, 2], state: "minecraft:cut_sandstone"},
        {pos: [7, 9, 3], state: "minecraft:cut_sandstone"},
        {pos: [7, 9, 4], state: "minecraft:cut_sandstone"},
        {pos: [7, 9, 5], state: "minecraft:sand"},
        {pos: [7, 9, 6], state: "minecraft:cut_sandstone"},
        {pos: [8, 9, 2], state: "minecraft:sand"},
        {pos: [8, 9, 3], state: "minecraft:cut_sandstone"},
        {pos: [8, 9, 4], state: "minecraft:cut_sandstone"},
        {pos: [8, 9, 5], state: "minecraft:cut_sandstone"},
        {pos: [8, 9, 6], state: "minecraft:cut_sandstone"},
        {pos: [9, 9, 2], state: "minecraft:sand"},
        {pos: [9, 9, 3], state: "minecraft:sand"},
        {pos: [9, 9, 4], state: "minecraft:cut_sandstone"},
        {pos: [9, 9, 5], state: "minecraft:cut_sandstone"},
        {pos: [9, 9, 6], state: "minecraft:cut_sandstone"},
        {pos: [10, 9, 3], state: "minecraft:sand"},
        {pos: [10, 9, 4], state: "minecraft:cut_sandstone"},
        {pos: [10, 9, 5], state: "minecraft:cut_sandstone"},
        {pos: [10, 9, 6], state: "minecraft:cut_sandstone"},
        {pos: [13, 9, 20], state: "minecraft:cut_sandstone"},
        {pos: [13, 9, 21], state: "minecraft:cut_sandstone"},
        {pos: [14, 9, 20], state: "minecraft:cut_sandstone"},
        {pos: [14, 9, 21], state: "minecraft:cut_sandstone"},
        {pos: [16, 9, 2], state: "minecraft:cut_sandstone"},
        {pos: [16, 9, 3], state: "minecraft:cut_sandstone"},
        {pos: [16, 9, 4], state: "minecraft:cut_sandstone"},
        {pos: [16, 9, 5], state: "minecraft:sand"},
        {pos: [16, 9, 6], state: "minecraft:cut_sandstone"},
        {pos: [17, 9, 2], state: "minecraft:cut_sandstone"},
        {pos: [17, 9, 3], state: "minecraft:cut_sandstone"},
        {pos: [17, 9, 4], state: "minecraft:sand"},
        {pos: [17, 9, 5], state: "minecraft:cut_sandstone"},
        {pos: [17, 9, 6], state: "minecraft:cut_sandstone"},
        {pos: [18, 9, 2], state: "minecraft:cut_sandstone"},
        {pos: [18, 9, 3], state: "minecraft:cut_sandstone"},
        {pos: [18, 9, 4], state: "minecraft:sand"},
        {pos: [18, 9, 5], state: "minecraft:cut_sandstone"},
        {pos: [18, 9, 6], state: "minecraft:cut_sandstone"},
        {pos: [19, 9, 2], state: "minecraft:cut_sandstone"},
        {pos: [19, 9, 3], state: "minecraft:cut_sandstone"},
        {pos: [19, 9, 4], state: "minecraft:cut_sandstone"},
        {pos: [19, 9, 5], state: "minecraft:cut_sandstone"},
        {pos: [19, 9, 6], state: "minecraft:cut_sandstone"},
        {pos: [20, 9, 2], state: "minecraft:cut_sandstone"},
        {pos: [20, 9, 3], state: "minecraft:cut_sandstone"},
        {pos: [20, 9, 4], state: "minecraft:cut_sandstone"},
        {pos: [20, 9, 5], state: "minecraft:cut_sandstone"},
        {pos: [20, 9, 6], state: "minecraft:cut_sandstone"}
    ],
    entities: [],
    palette: [
        "minecraft:sand",
        "minecraft:sandstone",
        "minecraft:smooth_sandstone",
        "minecraft:blue_terracotta",
        "minecraft:chiseled_sandstone",
        "minecraft:cut_sandstone",
        "minecraft:yellow_terracotta"
    ],
    trailiertales_DataVersion: 2
}
