{
    DataVersion: 3953,
    size: [8, 10, 7],
    data: [
        {pos: [0, 0, 2], state: "minecraft:sand"},
        {pos: [0, 0, 3], state: "minecraft:sand"},
        {pos: [0, 0, 4], state: "minecraft:sand"},
        {pos: [1, 0, 1], state: "minecraft:sand"},
        {pos: [1, 0, 2], state: "minecraft:sand"},
        {pos: [1, 0, 3], state: "minecraft:sand"},
        {pos: [1, 0, 4], state: "minecraft:sand"},
        {pos: [1, 0, 5], state: "minecraft:sand"},
        {pos: [2, 0, 1], state: "minecraft:sand"},
        {pos: [2, 0, 2], state: "minecraft:sand"},
        {pos: [2, 0, 3], state: "minecraft:sand"},
        {pos: [2, 0, 4], state: "minecraft:sand"},
        {pos: [2, 0, 5], state: "minecraft:sand"},
        {pos: [2, 0, 6], state: "minecraft:sand"},
        {pos: [3, 0, 0], state: "minecraft:sand"},
        {pos: [3, 0, 1], state: "minecraft:sand"},
        {pos: [3, 0, 2], state: "minecraft:sandstone"},
        {pos: [3, 0, 3], state: "minecraft:sandstone"},
        {pos: [3, 0, 4], state: "minecraft:sandstone"},
        {pos: [3, 0, 5], state: "minecraft:sand"},
        {pos: [3, 0, 6], state: "minecraft:sand"},
        {pos: [4, 0, 0], state: "minecraft:sand"},
        {pos: [4, 0, 1], state: "minecraft:sand"},
        {pos: [4, 0, 2], state: "minecraft:sandstone"},
        {pos: [4, 0, 3], state: "minecraft:sandstone"},
        {pos: [4, 0, 4], state: "minecraft:sandstone"},
        {pos: [4, 0, 5], state: "minecraft:sand"},
        {pos: [4, 0, 6], state: "minecraft:sand"},
        {pos: [5, 0, 1], state: "minecraft:sand"},
        {pos: [5, 0, 2], state: "minecraft:sandstone"},
        {pos: [5, 0, 3], state: "minecraft:sandstone"},
        {pos: [5, 0, 4], state: "minecraft:sandstone"},
        {pos: [5, 0, 5], state: "minecraft:sand"},
        {pos: [5, 0, 6], state: "minecraft:sand"},
        {pos: [6, 0, 1], state: "minecraft:sand"},
        {pos: [6, 0, 2], state: "minecraft:sandstone"},
        {pos: [6, 0, 3], state: "minecraft:sandstone"},
        {pos: [6, 0, 4], state: "minecraft:sandstone"},
        {pos: [6, 0, 5], state: "minecraft:sand"},
        {pos: [6, 0, 6], state: "minecraft:sand"},
        {pos: [7, 0, 1], state: "minecraft:sand"},
        {pos: [7, 0, 2], state: "minecraft:sand"},
        {pos: [7, 0, 3], state: "minecraft:sand"},
        {pos: [7, 0, 4], state: "minecraft:sand"},
        {pos: [1, 1, 3], state: "minecraft:sand"},
        {pos: [2, 1, 2], state: "minecraft:sand"},
        {pos: [2, 1, 3], state: "minecraft:sand"},
        {pos: [3, 1, 1], state: "minecraft:sand"},
        {pos: [3, 1, 2], state: "minecraft:sandstone"},
        {pos: [3, 1, 3], state: "minecraft:sandstone"},
        {pos: [3, 1, 4], state: "minecraft:sandstone"},
        {pos: [3, 1, 5], state: "minecraft:sand"},
        {pos: [4, 1, 1], state: "minecraft:sand"},
        {pos: [4, 1, 2], state: "minecraft:sandstone"},
        {pos: [4, 1, 3], state: "minecraft:sandstone"},
        {pos: [4, 1, 4], state: "minecraft:sandstone"},
        {pos: [4, 1, 5], state: "minecraft:sand"},
        {pos: [4, 1, 6], state: "minecraft:sand"},
        {pos: [5, 1, 2], state: "minecraft:sandstone"},
        {pos: [5, 1, 3], state: "minecraft:sandstone"},
        {pos: [5, 1, 4], state: "minecraft:sandstone"},
        {pos: [5, 1, 5], state: "minecraft:sand"},
        {pos: [5, 1, 6], state: "minecraft:sand"},
        {pos: [6, 1, 2], state: "minecraft:sandstone"},
        {pos: [6, 1, 3], state: "minecraft:sandstone"},
        {pos: [6, 1, 4], state: "minecraft:sandstone"},
        {pos: [2, 2, 2], state: "minecraft:sandstone"},
        {pos: [2, 2, 3], state: "minecraft:sandstone"},
        {pos: [2, 2, 4], state: "minecraft:sandstone"},
        {pos: [3, 2, 2], state: "minecraft:sandstone"},
        {pos: [3, 2, 3], state: "minecraft:sandstone"},
        {pos: [3, 2, 4], state: "minecraft:sandstone"},
        {pos: [4, 2, 2], state: "minecraft:sandstone"},
        {pos: [4, 2, 3], state: "minecraft:sandstone"},
        {pos: [4, 2, 4], state: "minecraft:sandstone"},
        {pos: [5, 2, 2], state: "minecraft:smooth_sandstone"},
        {pos: [5, 2, 3], state: "minecraft:sandstone"},
        {pos: [5, 2, 4], state: "minecraft:sandstone"},
        {pos: [6, 2, 2], state: "minecraft:sand"},
        {pos: [6, 2, 3], state: "minecraft:sand"},
        {pos: [2, 3, 2], state: "minecraft:smooth_sandstone"},
        {pos: [2, 3, 3], state: "minecraft:sandstone"},
        {pos: [2, 3, 4], state: "minecraft:sandstone"},
        {pos: [3, 3, 2], state: "minecraft:smooth_sandstone"},
        {pos: [3, 3, 3], state: "minecraft:sandstone"},
        {pos: [3, 3, 4], state: "minecraft:sandstone"},
        {pos: [4, 3, 2], state: "minecraft:sandstone"},
        {pos: [4, 3, 3], state: "minecraft:sandstone"},
        {pos: [4, 3, 4], state: "minecraft:sandstone"},
        {pos: [5, 3, 2], state: "minecraft:smooth_sandstone"},
        {pos: [5, 3, 3], state: "minecraft:smooth_sandstone"},
        {pos: [5, 3, 4], state: "minecraft:sandstone"},
        {pos: [1, 4, 2], state: "minecraft:smooth_sandstone"},
        {pos: [1, 4, 3], state: "minecraft:sandstone"},
        {pos: [1, 4, 4], state: "minecraft:sandstone"},
        {pos: [2, 4, 2], state: "minecraft:smooth_sandstone"},
        {pos: [2, 4, 3], state: "minecraft:sandstone"},
        {pos: [2, 4, 4], state: "minecraft:sandstone"},
        {pos: [3, 4, 2], state: "minecraft:smooth_sandstone"},
        {pos: [3, 4, 3], state: "minecraft:sandstone"},
        {pos: [3, 4, 4], state: "minecraft:sandstone"},
        {pos: [4, 4, 2], state: "minecraft:smooth_sandstone"},
        {pos: [4, 4, 3], state: "minecraft:smooth_sandstone"},
        {pos: [4, 4, 4], state: "minecraft:sandstone"},
        {pos: [1, 5, 2], state: "minecraft:smooth_sandstone"},
        {pos: [1, 5, 3], state: "minecraft:sandstone"},
        {pos: [1, 5, 4], state: "minecraft:sandstone"},
        {pos: [2, 5, 2], state: "minecraft:sandstone"},
        {pos: [2, 5, 3], state: "minecraft:sandstone"},
        {pos: [2, 5, 4], state: "minecraft:smooth_sandstone"},
        {pos: [3, 5, 2], state: "minecraft:smooth_sandstone"},
        {pos: [3, 5, 3], state: "minecraft:sandstone"},
        {pos: [3, 5, 4], state: "minecraft:sandstone"},
        {pos: [4, 5, 2], state: "minecraft:sand"},
        {pos: [4, 5, 3], state: "minecraft:smooth_sandstone"},
        {pos: [4, 5, 4], state: "minecraft:smooth_sandstone"},
        {pos: [0, 6, 2], state: "minecraft:smooth_sandstone"},
        {pos: [0, 6, 3], state: "minecraft:smooth_sandstone"},
        {pos: [0, 6, 4], state: "minecraft:smooth_sandstone"},
        {pos: [1, 6, 2], state: "minecraft:sandstone"},
        {pos: [1, 6, 3], state: "minecraft:sandstone"},
        {pos: [1, 6, 4], state: "minecraft:smooth_sandstone"},
        {pos: [2, 6, 2], state: "minecraft:sandstone"},
        {pos: [2, 6, 3], state: "minecraft:sandstone"},
        {pos: [2, 6, 4], state: "minecraft:smooth_sandstone"},
        {pos: [3, 6, 2], state: "minecraft:sandstone"},
        {pos: [3, 6, 3], state: "minecraft:smooth_sandstone"},
        {pos: [3, 6, 4], state: "minecraft:smooth_sandstone"},
        {pos: [0, 7, 2], state: "minecraft:smooth_sandstone"},
        {pos: [0, 7, 3], state: "minecraft:smooth_sandstone"},
        {pos: [0, 7, 4], state: "minecraft:smooth_sandstone"},
        {pos: [1, 7, 2], state: "minecraft:sandstone"},
        {pos: [1, 7, 3], state: "minecraft:sandstone"},
        {pos: [1, 7, 4], state: "minecraft:smooth_sandstone"},
        {pos: [2, 7, 2], state: "minecraft:sandstone"},
        {pos: [2, 7, 3], state: "minecraft:sandstone"},
        {pos: [2, 7, 4], state: "minecraft:smooth_sandstone"},
        {pos: [3, 7, 2], state: "minecraft:sandstone"},
        {pos: [3, 7, 3], state: "minecraft:sandstone"},
        {pos: [3, 7, 4], state: "minecraft:sand"},
        {pos: [0, 8, 2], state: "minecraft:smooth_sandstone"},
        {pos: [0, 8, 3], state: "minecraft:smooth_sandstone"},
        {pos: [0, 8, 4], state: "minecraft:smooth_sandstone"},
        {pos: [1, 8, 2], state: "minecraft:smooth_sandstone"},
        {pos: [1, 8, 3], state: "minecraft:sandstone"},
        {pos: [1, 8, 4], state: "minecraft:smooth_sandstone"},
        {pos: [2, 8, 2], state: "minecraft:sandstone"},
        {pos: [2, 8, 3], state: "minecraft:smooth_sandstone"},
        {pos: [2, 8, 4], state: "minecraft:smooth_sandstone"},
        {pos: [0, 9, 2], state: "minecraft:cut_sandstone"},
        {pos: [0, 9, 3], state: "minecraft:sand"},
        {pos: [1, 9, 2], state: "minecraft:cut_sandstone"},
        {pos: [1, 9, 3], state: "minecraft:cut_sandstone"},
        {pos: [1, 9, 4], state: "minecraft:sand"},
        {pos: [2, 9, 2], state: "minecraft:cut_sandstone"},
        {pos: [2, 9, 3], state: "minecraft:cut_sandstone"},
        {pos: [2, 9, 4], state: "minecraft:cut_sandstone"}
    ],
    entities: [],
    palette: [
        "minecraft:sand",
        "minecraft:sandstone",
        "minecraft:smooth_sandstone",
        "minecraft:cut_sandstone"
    ],
    trailiertales_DataVersion: 2
}
