{
    DataVersion: 3953,
    size: [5, 11, 5],
    data: [
        {pos: [0, 0, 0], state: "minecraft:sand"},
        {pos: [0, 0, 1], state: "minecraft:sand"},
        {pos: [0, 0, 2], state: "minecraft:sand"},
        {pos: [0, 0, 3], state: "minecraft:sand"},
        {pos: [0, 0, 4], state: "minecraft:sand"},
        {pos: [1, 0, 0], state: "minecraft:sand"},
        {pos: [1, 0, 1], state: "minecraft:sand"},
        {pos: [1, 0, 2], state: "minecraft:sandstone"},
        {pos: [1, 0, 3], state: "minecraft:sandstone"},
        {pos: [1, 0, 4], state: "minecraft:sand"},
        {pos: [2, 0, 0], state: "minecraft:sand"},
        {pos: [2, 0, 1], state: "minecraft:sand"},
        {pos: [2, 0, 2], state: "minecraft:sandstone"},
        {pos: [2, 0, 3], state: "minecraft:sandstone"},
        {pos: [2, 0, 4], state: "minecraft:sand"},
        {pos: [3, 0, 0], state: "minecraft:sand"},
        {pos: [3, 0, 1], state: "minecraft:sand"},
        {pos: [3, 0, 2], state: "minecraft:sand"},
        {pos: [3, 0, 3], state: "minecraft:sand"},
        {pos: [3, 0, 4], state: "minecraft:sand"},
        {pos: [4, 0, 0], state: "minecraft:sand"},
        {pos: [4, 0, 1], state: "minecraft:sand"},
        {pos: [4, 0, 2], state: "minecraft:sand"},
        {pos: [4, 0, 3], state: "minecraft:sand"},
        {pos: [0, 1, 2], state: "minecraft:sand"},
        {pos: [0, 1, 3], state: "minecraft:sand"},
        {pos: [1, 1, 1], state: "minecraft:sand"},
        {pos: [1, 1, 2], state: "minecraft:sandstone"},
        {pos: [1, 1, 3], state: "minecraft:sandstone"},
        {pos: [1, 1, 4], state: "minecraft:sand"},
        {pos: [2, 1, 0], state: "minecraft:sand"},
        {pos: [2, 1, 1], state: "minecraft:sand"},
        {pos: [2, 1, 2], state: "minecraft:sandstone"},
        {pos: [2, 1, 3], state: "minecraft:sandstone"},
        {pos: [3, 1, 1], state: "minecraft:sand"},
        {pos: [3, 1, 2], state: "minecraft:sand"},
        {pos: [3, 1, 3], state: "minecraft:sand"},
        {pos: [1, 2, 2], state: "minecraft:sandstone"},
        {pos: [1, 2, 3], state: "minecraft:sandstone"},
        {pos: [2, 2, 2], state: "minecraft:sandstone"},
        {pos: [2, 2, 3], state: "minecraft:sandstone"},
        {pos: [1, 3, 2], state: "minecraft:smooth_sandstone"},
        {pos: [1, 3, 3], state: "minecraft:smooth_sandstone"},
        {pos: [2, 3, 2], state: "minecraft:smooth_sandstone"},
        {pos: [2, 3, 3], state: "minecraft:sandstone"},
        {pos: [1, 4, 2], state: "minecraft:smooth_sandstone"},
        {pos: [1, 4, 3], state: "minecraft:smooth_sandstone"},
        {pos: [2, 4, 2], state: "minecraft:smooth_sandstone"},
        {pos: [2, 4, 3], state: "minecraft:smooth_sandstone"},
        {pos: [1, 5, 2], state: "minecraft:sandstone"},
        {pos: [1, 5, 3], state: "minecraft:smooth_sandstone"},
        {pos: [2, 5, 2], state: "minecraft:smooth_sandstone"},
        {pos: [2, 5, 3], state: "minecraft:smooth_sandstone"},
        {pos: [1, 6, 2], state: "minecraft:sandstone"},
        {pos: [1, 6, 3], state: "minecraft:smooth_sandstone"},
        {pos: [2, 6, 2], state: "minecraft:sandstone"},
        {pos: [2, 6, 3], state: "minecraft:smooth_sandstone"},
        {pos: [1, 7, 2], state: "minecraft:sandstone"},
        {pos: [1, 7, 3], state: "minecraft:sandstone"},
        {pos: [2, 7, 2], state: "minecraft:sandstone"},
        {pos: [2, 7, 3], state: "minecraft:sandstone"},
        {pos: [1, 8, 2], state: "minecraft:smooth_sandstone"},
        {pos: [1, 8, 3], state: "minecraft:smooth_sandstone"},
        {pos: [2, 8, 2], state: "minecraft:smooth_sandstone"},
        {pos: [2, 8, 3], state: "minecraft:sandstone"},
        {pos: [0, 9, 1], state: "minecraft:smooth_sandstone"},
        {pos: [0, 9, 2], state: "minecraft:smooth_sandstone"},
        {pos: [0, 9, 3], state: "minecraft:smooth_sandstone"},
        {pos: [0, 9, 4], state: "minecraft:smooth_sandstone"},
        {pos: [1, 9, 1], state: "minecraft:smooth_sandstone"},
        {pos: [1, 9, 2], state: "minecraft:smooth_sandstone"},
        {pos: [1, 9, 3], state: "minecraft:smooth_sandstone"},
        {pos: [1, 9, 4], state: "minecraft:smooth_sandstone"},
        {pos: [2, 9, 1], state: "minecraft:smooth_sandstone"},
        {pos: [2, 9, 2], state: "minecraft:smooth_sandstone"},
        {pos: [2, 9, 3], state: "minecraft:smooth_sandstone"},
        {pos: [2, 9, 4], state: "minecraft:smooth_sandstone"},
        {pos: [3, 9, 1], state: "minecraft:smooth_sandstone"},
        {pos: [3, 9, 2], state: "minecraft:smooth_sandstone"},
        {pos: [3, 9, 3], state: "minecraft:smooth_sandstone"},
        {pos: [3, 9, 4], state: "minecraft:smooth_sandstone"},
        {pos: [0, 10, 1], state: "minecraft:cut_sandstone"},
        {pos: [0, 10, 2], state: "minecraft:sand"},
        {pos: [0, 10, 3], state: "minecraft:cut_sandstone"},
        {pos: [0, 10, 4], state: "minecraft:cut_sandstone"},
        {pos: [1, 10, 1], state: "minecraft:cut_sandstone"},
        {pos: [1, 10, 2], state: "minecraft:cut_sandstone"},
        {pos: [1, 10, 3], state: "minecraft:cut_sandstone"},
        {pos: [1, 10, 4], state: "minecraft:cut_sandstone"},
        {pos: [2, 10, 1], state: "minecraft:sand"},
        {pos: [2, 10, 2], state: "minecraft:sand"},
        {pos: [2, 10, 3], state: "minecraft:sand"},
        {pos: [2, 10, 4], state: "minecraft:cut_sandstone"},
        {pos: [3, 10, 2], state: "minecraft:sand"},
        {pos: [3, 10, 3], state: "minecraft:cut_sandstone"},
        {pos: [3, 10, 4], state: "minecraft:cut_sandstone"}
    ],
    entities: [],
    palette: [
        "minecraft:sand",
        "minecraft:sandstone",
        "minecraft:smooth_sandstone",
        "minecraft:cut_sandstone"
    ],
    trailiertales_DataVersion: 2
}
