{
    DataVersion: 3953,
    size: [13, 6, 8],
    data: [
        {pos: [0, 0, 3], state: "minecraft:cobblestone"},
        {pos: [1, 0, 1], state: "minecraft:cobblestone"},
        {pos: [1, 0, 2], state: "minecraft:cobblestone"},
        {pos: [1, 0, 3], state: "minecraft:cobblestone"},
        {pos: [1, 0, 4], state: "minecraft:cobblestone"},
        {pos: [2, 0, 1], state: "minecraft:cobblestone"},
        {pos: [2, 0, 2], state: "minecraft:gravel"},
        {pos: [2, 0, 3], state: "minecraft:gravel"},
        {pos: [2, 0, 4], state: "minecraft:gravel"},
        {pos: [2, 0, 5], state: "minecraft:cobblestone"},
        {pos: [3, 0, 0], state: "minecraft:cobblestone"},
        {pos: [3, 0, 1], state: "minecraft:gravel"},
        {pos: [3, 0, 2], state: "minecraft:gravel"},
        {pos: [3, 0, 3], state: "minecraft:gravel"},
        {pos: [3, 0, 4], state: "minecraft:gravel"},
        {pos: [3, 0, 5], state: "minecraft:gravel"},
        {pos: [3, 0, 6], state: "minecraft:cobblestone"},
        {pos: [4, 0, 0], state: "minecraft:gravel"},
        {pos: [4, 0, 1], state: "minecraft:gravel"},
        {pos: [4, 0, 2], state: "minecraft:gravel"},
        {pos: [4, 0, 3], state: "minecraft:gravel"},
        {pos: [4, 0, 4], state: "minecraft:gravel"},
        {pos: [4, 0, 5], state: "minecraft:gravel"},
        {pos: [4, 0, 6], state: "minecraft:cobblestone"},
        {pos: [5, 0, 0], state: "minecraft:gravel"},
        {pos: [5, 0, 1], state: "minecraft:gravel"},
        {pos: [5, 0, 2], state: "minecraft:gravel"},
        {pos: [5, 0, 3], state: "minecraft:gravel"},
        {pos: [5, 0, 4], state: "minecraft:gravel"},
        {pos: [5, 0, 5], state: "minecraft:gravel"},
        {pos: [5, 0, 6], state: "minecraft:cobblestone"},
        {pos: [5, 0, 7], state: "minecraft:cobblestone"},
        {pos: [6, 0, 0], state: "minecraft:cobblestone"},
        {pos: [6, 0, 1], state: "minecraft:gravel"},
        {pos: [6, 0, 2], state: "minecraft:gravel"},
        {pos: [6, 0, 3], state: "minecraft:gravel"},
        {pos: [6, 0, 4], state: "minecraft:gravel"},
        {pos: [6, 0, 5], state: "minecraft:gravel"},
        {pos: [6, 0, 6], state: "minecraft:cobblestone"},
        {pos: [6, 0, 7], state: "minecraft:cobblestone"},
        {pos: [7, 0, 0], state: "minecraft:cobblestone"},
        {pos: [7, 0, 1], state: "minecraft:cobblestone"},
        {pos: [7, 0, 2], state: "minecraft:gravel"},
        {pos: [7, 0, 3], state: "minecraft:gravel"},
        {pos: [7, 0, 4], state: "minecraft:gravel"},
        {pos: [7, 0, 5], state: "minecraft:gravel"},
        {pos: [7, 0, 6], state: "minecraft:cobblestone"},
        {pos: [7, 0, 7], state: "minecraft:cobblestone"},
        {pos: [8, 0, 1], state: "minecraft:cobblestone"},
        {pos: [8, 0, 2], state: "minecraft:gravel"},
        {pos: [8, 0, 3], state: "minecraft:gravel"},
        {pos: [8, 0, 4], state: "minecraft:gravel"},
        {pos: [8, 0, 5], state: "minecraft:gravel"},
        {pos: [8, 0, 6], state: "minecraft:cobblestone"},
        {pos: [8, 0, 7], state: "minecraft:cobblestone"},
        {pos: [9, 0, 1], state: "minecraft:cobblestone"},
        {pos: [9, 0, 2], state: "minecraft:gravel"},
        {pos: [9, 0, 3], state: "minecraft:gravel"},
        {pos: [9, 0, 4], state: "minecraft:cobblestone_slab{type:bottom,waterlogged:true}"},
        {pos: [9, 0, 5], state: "minecraft:gravel"},
        {pos: [9, 0, 6], state: "minecraft:cobblestone"},
        {pos: [9, 0, 7], state: "minecraft:cobblestone"},
        {pos: [10, 0, 1], state: "minecraft:cobblestone"},
        {pos: [10, 0, 2], state: "minecraft:gravel"},
        {pos: [10, 0, 3], state: "minecraft:gravel"},
        {pos: [10, 0, 4], state: "minecraft:gravel"},
        {pos: [10, 0, 5], state: "minecraft:gravel"},
        {pos: [10, 0, 6], state: "minecraft:cobblestone"},
        {pos: [11, 0, 1], state: "minecraft:cobblestone"},
        {pos: [11, 0, 2], state: "minecraft:gravel"},
        {pos: [11, 0, 3], state: "minecraft:gravel"},
        {pos: [11, 0, 4], state: "minecraft:gravel"},
        {pos: [11, 0, 5], state: "minecraft:gravel"},
        {pos: [11, 0, 6], state: "minecraft:cobblestone"},
        {pos: [12, 0, 1], state: "minecraft:cobblestone"},
        {pos: [12, 0, 2], state: "minecraft:cobblestone"},
        {pos: [12, 0, 3], state: "minecraft:gravel"},
        {pos: [12, 0, 4], state: "minecraft:gravel"},
        {pos: [12, 0, 5], state: "minecraft:gravel"},
        {pos: [12, 0, 6], state: "minecraft:cobblestone"},
        {pos: [0, 1, 2], state: "minecraft:cobblestone"},
        {pos: [0, 1, 3], state: "minecraft:cobblestone"},
        {pos: [0, 1, 4], state: "minecraft:cobblestone"},
        {pos: [1, 1, 1], state: "minecraft:cobblestone"},
        {pos: [1, 1, 2], state: "minecraft:cobblestone"},
        {pos: [1, 1, 3], state: "minecraft:cobblestone"},
        {pos: [1, 1, 4], state: "minecraft:cobblestone"},
        {pos: [1, 1, 5], state: "minecraft:cobblestone"},
        {pos: [2, 1, 0], state: "minecraft:cobblestone"},
        {pos: [2, 1, 1], state: "minecraft:cobblestone"},
        {pos: [2, 1, 2], state: "minecraft:cobblestone_stairs{facing:west,half:top,shape:straight,waterlogged:false}"},
        {pos: [2, 1, 3], state: "minecraft:cobblestone_stairs{facing:west,half:top,shape:straight,waterlogged:false}"},
        {pos: [2, 1, 4], state: "minecraft:cobblestone_stairs{facing:west,half:top,shape:straight,waterlogged:false}"},
        {pos: [2, 1, 5], state: "minecraft:cobblestone"},
        {pos: [2, 1, 6], state: "minecraft:cobblestone"},
        {pos: [3, 1, 0], state: "minecraft:cobblestone"},
        {pos: [3, 1, 1], state: "minecraft:gravel"},
        {pos: [3, 1, 2], state: "minecraft:gravel"},
        {pos: [3, 1, 3], state: "minecraft:gravel"},
        {pos: [3, 1, 4], state: "minecraft:gravel"},
        {pos: [3, 1, 5], state: "minecraft:cobblestone"},
        {pos: [3, 1, 6], state: "minecraft:cobblestone"},
        {pos: [4, 1, 0], state: "minecraft:gravel"},
        {pos: [4, 1, 1], state: "minecraft:gravel"},
        {pos: [4, 1, 2], state: "minecraft:cobblestone"},
        {pos: [4, 1, 3], state: "minecraft:gravel"},
        {pos: [4, 1, 4], state: "minecraft:gravel"},
        {pos: [4, 1, 5], state: "minecraft:gravel"},
        {pos: [4, 1, 6], state: "minecraft:cobblestone"},
        {pos: [4, 1, 7], state: "minecraft:cobblestone"},
        {pos: [5, 1, 0], state: "minecraft:gravel"},
        {pos: [5, 1, 1], state: "minecraft:gravel"},
        {pos: [5, 1, 2], state: "minecraft:gravel"},
        {pos: [5, 1, 3], state: "minecraft:gravel"},
        {pos: [5, 1, 4], state: "minecraft:gravel"},
        {pos: [5, 1, 5], state: "minecraft:cobblestone_stairs{facing:south,half:top,shape:straight,waterlogged:false}"},
        {pos: [5, 1, 6], state: "minecraft:cobblestone"},
        {pos: [5, 1, 7], state: "minecraft:cobblestone"},
        {pos: [6, 1, 0], state: "minecraft:cobblestone"},
        {pos: [6, 1, 1], state: "minecraft:gravel"},
        {pos: [6, 1, 2], state: "minecraft:gravel"},
        {pos: [6, 1, 3], state: "minecraft:cobblestone"},
        {pos: [6, 1, 4], state: "minecraft:gravel"},
        {pos: [6, 1, 5], state: "minecraft:cobblestone_stairs{facing:south,half:top,shape:straight,waterlogged:false}"},
        {pos: [6, 1, 6], state: "minecraft:cobblestone"},
        {pos: [6, 1, 7], state: "minecraft:cobblestone"},
        {pos: [7, 1, 0], state: "minecraft:cobblestone"},
        {pos: [7, 1, 1], state: "minecraft:cobblestone"},
        {pos: [7, 1, 2], state: "minecraft:gravel"},
        {pos: [7, 1, 3], state: "minecraft:gravel"},
        {pos: [7, 1, 4], state: "minecraft:gravel"},
        {pos: [7, 1, 5], state: "minecraft:cobblestone_stairs{facing:south,half:top,shape:straight,waterlogged:false}"},
        {pos: [7, 1, 6], state: "minecraft:cobblestone"},
        {pos: [7, 1, 7], state: "minecraft:cobblestone"},
        {pos: [8, 1, 0], state: "minecraft:cobblestone"},
        {pos: [8, 1, 1], state: "minecraft:cobblestone"},
        {pos: [8, 1, 2], state: "minecraft:gravel"},
        {pos: [8, 1, 3], state: "minecraft:gravel"},
        {pos: [8, 1, 4], state: "minecraft:gravel"},
        {pos: [8, 1, 5], state: "minecraft:gravel"},
        {pos: [8, 1, 6], state: "minecraft:cobblestone"},
        {pos: [8, 1, 7], state: "minecraft:cobblestone"},
        {pos: [9, 1, 0], state: "minecraft:cobblestone"},
        {pos: [9, 1, 1], state: "minecraft:cobblestone"},
        {pos: [9, 1, 2], state: "minecraft:gravel"},
        {pos: [9, 1, 3], state: "minecraft:cobblestone_slab{type:bottom,waterlogged:false}"},
        {pos: [9, 1, 4], state: "minecraft:gravel"},
        {pos: [9, 1, 5], state: "minecraft:cobblestone_slab{type:bottom,waterlogged:false}"},
        {pos: [9, 1, 6], state: "minecraft:cobblestone"},
        {pos: [9, 1, 7], state: "minecraft:cobblestone"},
        {pos: [10, 1, 1], state: "minecraft:cobblestone"},
        {pos: [10, 1, 2], state: "minecraft:gravel"},
        {pos: [10, 1, 3], state: "minecraft:gravel"},
        {pos: [10, 1, 4], state: "minecraft:cobblestone"},
        {pos: [10, 1, 5], state: "minecraft:gravel"},
        {pos: [10, 1, 6], state: "minecraft:cobblestone"},
        {pos: [11, 1, 1], state: "minecraft:cobblestone"},
        {pos: [11, 1, 2], state: "minecraft:gravel"},
        {pos: [11, 1, 3], state: "minecraft:gravel"},
        {pos: [11, 1, 4], state: "minecraft:gravel"},
        {pos: [11, 1, 5], state: "minecraft:gravel"},
        {pos: [11, 1, 6], state: "minecraft:gravel"},
        {pos: [12, 1, 1], state: "minecraft:gravel"},
        {pos: [12, 1, 2], state: "minecraft:gravel"},
        {pos: [12, 1, 3], state: "minecraft:gravel"},
        {pos: [12, 1, 4], state: "minecraft:gravel"},
        {pos: [12, 1, 5], state: "minecraft:gravel"},
        {pos: [12, 1, 6], state: "minecraft:gravel"},
        {pos: [0, 2, 2], state: "minecraft:cobblestone"},
        {pos: [0, 2, 3], state: "minecraft:cobblestone"},
        {pos: [0, 2, 4], state: "minecraft:cobblestone"},
        {pos: [1, 2, 1], state: "minecraft:cobblestone"},
        {pos: [1, 2, 2], state: "minecraft:cobblestone"},
        {pos: [1, 2, 3], state: "minecraft:cobblestone"},
        {pos: [1, 2, 4], state: "minecraft:cobblestone"},
        {pos: [1, 2, 5], state: "minecraft:cobblestone"},
        {pos: [2, 2, 0], state: "minecraft:gravel"},
        {pos: [2, 2, 1], state: "minecraft:cobblestone"},
        {pos: [2, 2, 2], state: "minecraft:gravel"},
        {pos: [2, 2, 3], state: "minecraft:gravel"},
        {pos: [2, 2, 4], state: "minecraft:gravel"},
        {pos: [2, 2, 5], state: "minecraft:cobblestone"},
        {pos: [2, 2, 6], state: "minecraft:gravel"},
        {pos: [3, 2, 0], state: "minecraft:cobblestone"},
        {pos: [3, 2, 1], state: "minecraft:gravel"},
        {pos: [3, 2, 2], state: "minecraft:gravel"},
        {pos: [3, 2, 3], state: "minecraft:gravel"},
        {pos: [3, 2, 4], state: "minecraft:gravel"},
        {pos: [3, 2, 5], state: "minecraft:cobblestone"},
        {pos: [3, 2, 6], state: "minecraft:cobblestone"},
        {pos: [4, 2, 0], state: "minecraft:gravel"},
        {pos: [4, 2, 1], state: "minecraft:gravel"},
        {pos: [4, 2, 2], state: "minecraft:gravel"},
        {pos: [4, 2, 3], state: "minecraft:gravel"},
        {pos: [4, 2, 4], state: "minecraft:gravel"},
        {pos: [4, 2, 5], state: "minecraft:air"},
        {pos: [4, 2, 6], state: "minecraft:cobblestone"},
        {pos: [4, 2, 7], state: "minecraft:gravel"},
        {pos: [5, 2, 0], state: "minecraft:gravel"},
        {pos: [5, 2, 1], state: "minecraft:gravel"},
        {pos: [5, 2, 2], state: "minecraft:gravel"},
        {pos: [5, 2, 3], state: "minecraft:gravel"},
        {pos: [5, 2, 4], state: "minecraft:gravel"},
        {pos: [5, 2, 5], state: "minecraft:gravel"},
        {pos: [5, 2, 6], state: "minecraft:cobblestone"},
        {pos: [5, 2, 7], state: "minecraft:cobblestone"},
        {pos: [6, 2, 0], state: "minecraft:cobblestone"},
        {pos: [6, 2, 1], state: "minecraft:gravel"},
        {pos: [6, 2, 2], state: "minecraft:gravel"},
        {pos: [6, 2, 3], state: "minecraft:gravel"},
        {pos: [6, 2, 4], state: "minecraft:gravel"},
        {pos: [6, 2, 5], state: "minecraft:gravel"},
        {pos: [6, 2, 6], state: "minecraft:cobblestone"},
        {pos: [6, 2, 7], state: "minecraft:cobblestone"},
        {pos: [7, 2, 0], state: "minecraft:cobblestone"},
        {pos: [7, 2, 1], state: "minecraft:cobblestone"},
        {pos: [7, 2, 2], state: "minecraft:gravel"},
        {pos: [7, 2, 3], state: "minecraft:gravel"},
        {pos: [7, 2, 4], state: "minecraft:gravel"},
        {pos: [7, 2, 5], state: "minecraft:gravel"},
        {pos: [7, 2, 6], state: "minecraft:cobblestone"},
        {pos: [7, 2, 7], state: "minecraft:cobblestone"},
        {pos: [8, 2, 0], state: "minecraft:cobblestone"},
        {pos: [8, 2, 1], state: "minecraft:cobblestone"},
        {pos: [8, 2, 2], state: "minecraft:gravel"},
        {pos: [8, 2, 3], state: "minecraft:gravel"},
        {pos: [8, 2, 4], state: "minecraft:gravel"},
        {pos: [8, 2, 5], state: "minecraft:gravel"},
        {pos: [8, 2, 6], state: "minecraft:cobblestone"},
        {pos: [8, 2, 7], state: "minecraft:cobblestone"},
        {pos: [9, 2, 0], state: "minecraft:gravel"},
        {pos: [9, 2, 1], state: "minecraft:cobblestone"},
        {pos: [9, 2, 2], state: "minecraft:gravel"},
        {pos: [9, 2, 3], state: "minecraft:gravel"},
        {pos: [9, 2, 4], state: "minecraft:gravel"},
        {pos: [9, 2, 5], state: "minecraft:gravel"},
        {pos: [9, 2, 6], state: "minecraft:cobblestone"},
        {pos: [9, 2, 7], state: "minecraft:gravel"},
        {pos: [10, 2, 1], state: "minecraft:cobblestone"},
        {pos: [10, 2, 2], state: "minecraft:cobblestone"},
        {pos: [10, 2, 3], state: "minecraft:gravel"},
        {pos: [10, 2, 4], state: "minecraft:chiseled_stone_bricks"},
        {pos: [10, 2, 5], state: "minecraft:gravel"},
        {pos: [10, 2, 6], state: "minecraft:cobblestone"},
        {pos: [11, 2, 1], state: "minecraft:gravel"},
        {pos: [11, 2, 2], state: "minecraft:gravel"},
        {pos: [11, 2, 3], state: "minecraft:gravel"},
        {pos: [11, 2, 4], state: "minecraft:gravel"},
        {pos: [11, 2, 5], state: "minecraft:gravel"},
        {pos: [11, 2, 6], state: "minecraft:gravel"},
        {pos: [12, 2, 3], state: "minecraft:gravel"},
        {pos: [12, 2, 4], state: "minecraft:gravel"},
        {pos: [12, 2, 5], state: "minecraft:gravel"},
        {pos: [12, 2, 6], state: "minecraft:cobblestone"},
        {pos: [0, 3, 2], state: "minecraft:gravel"},
        {pos: [0, 3, 3], state: "minecraft:cobblestone"},
        {pos: [0, 3, 4], state: "minecraft:gravel"},
        {pos: [1, 3, 1], state: "minecraft:gravel"},
        {pos: [1, 3, 2], state: "minecraft:cobblestone"},
        {pos: [1, 3, 3], state: "minecraft:cobblestone"},
        {pos: [1, 3, 4], state: "minecraft:cobblestone"},
        {pos: [1, 3, 5], state: "minecraft:gravel"},
        {pos: [2, 3, 0], state: "minecraft:gravel"},
        {pos: [2, 3, 1], state: "minecraft:cobblestone"},
        {pos: [2, 3, 2], state: "minecraft:cobblestone"},
        {pos: [2, 3, 3], state: "minecraft:cobblestone"},
        {pos: [2, 3, 4], state: "minecraft:cobblestone"},
        {pos: [2, 3, 5], state: "minecraft:cobblestone"},
        {pos: [2, 3, 6], state: "minecraft:gravel"},
        {pos: [3, 3, 0], state: "minecraft:cobblestone"},
        {pos: [3, 3, 1], state: "minecraft:cobblestone"},
        {pos: [3, 3, 2], state: "minecraft:gravel"},
        {pos: [3, 3, 3], state: "minecraft:gravel"},
        {pos: [3, 3, 4], state: "minecraft:cobblestone"},
        {pos: [3, 3, 5], state: "minecraft:cobblestone"},
        {pos: [3, 3, 6], state: "minecraft:cobblestone"},
        {pos: [4, 3, 0], state: "minecraft:cobblestone"},
        {pos: [4, 3, 1], state: "minecraft:gravel"},
        {pos: [4, 3, 2], state: "minecraft:gravel"},
        {pos: [4, 3, 3], state: "minecraft:gravel"},
        {pos: [4, 3, 4], state: "minecraft:gravel"},
        {pos: [4, 3, 5], state: "minecraft:cobblestone"},
        {pos: [4, 3, 6], state: "minecraft:cobblestone"},
        {pos: [5, 3, 0], state: "minecraft:cobblestone"},
        {pos: [5, 3, 1], state: "minecraft:gravel"},
        {pos: [5, 3, 2], state: "minecraft:gravel"},
        {pos: [5, 3, 3], state: "minecraft:gravel"},
        {pos: [5, 3, 4], state: "minecraft:gravel"},
        {pos: [5, 3, 5], state: "minecraft:gravel"},
        {pos: [5, 3, 6], state: "minecraft:cobblestone"},
        {pos: [5, 3, 7], state: "minecraft:gravel"},
        {pos: [6, 3, 0], state: "minecraft:cobblestone"},
        {pos: [6, 3, 1], state: "minecraft:gravel"},
        {pos: [6, 3, 2], state: "minecraft:gravel"},
        {pos: [6, 3, 3], state: "minecraft:gravel"},
        {pos: [6, 3, 4], state: "minecraft:gravel"},
        {pos: [6, 3, 5], state: "minecraft:gravel"},
        {pos: [6, 3, 6], state: "minecraft:cobblestone"},
        {pos: [6, 3, 7], state: "minecraft:gravel"},
        {pos: [7, 3, 0], state: "minecraft:cobblestone"},
        {pos: [7, 3, 1], state: "minecraft:cobblestone"},
        {pos: [7, 3, 2], state: "minecraft:gravel"},
        {pos: [7, 3, 3], state: "minecraft:gravel"},
        {pos: [7, 3, 4], state: "minecraft:gravel"},
        {pos: [7, 3, 5], state: "minecraft:gravel"},
        {pos: [7, 3, 6], state: "minecraft:cobblestone"},
        {pos: [7, 3, 7], state: "minecraft:gravel"},
        {pos: [8, 3, 0], state: "minecraft:gravel"},
        {pos: [8, 3, 1], state: "minecraft:cobblestone"},
        {pos: [8, 3, 2], state: "minecraft:cobblestone"},
        {pos: [8, 3, 3], state: "minecraft:gravel"},
        {pos: [8, 3, 4], state: "minecraft:gravel"},
        {pos: [8, 3, 5], state: "minecraft:cobblestone"},
        {pos: [8, 3, 6], state: "minecraft:cobblestone"},
        {pos: [8, 3, 7], state: "minecraft:gravel"},
        {pos: [9, 3, 0], state: "minecraft:gravel"},
        {pos: [9, 3, 1], state: "minecraft:cobblestone"},
        {pos: [9, 3, 2], state: "minecraft:cobblestone"},
        {pos: [9, 3, 3], state: "minecraft:gravel"},
        {pos: [9, 3, 4], state: "minecraft:cobblestone"},
        {pos: [9, 3, 5], state: "minecraft:cobblestone"},
        {pos: [9, 3, 6], state: "minecraft:cobblestone"},
        {pos: [10, 3, 1], state: "minecraft:cobblestone"},
        {pos: [10, 3, 2], state: "minecraft:cobblestone"},
        {pos: [10, 3, 3], state: "minecraft:cobblestone"},
        {pos: [10, 3, 4], state: "minecraft:cobblestone"},
        {pos: [10, 3, 5], state: "minecraft:cobblestone"},
        {pos: [10, 3, 6], state: "minecraft:cobblestone"},
        {pos: [11, 3, 2], state: "minecraft:gravel"},
        {pos: [11, 3, 3], state: "minecraft:cobblestone"},
        {pos: [11, 3, 4], state: "minecraft:cobblestone"},
        {pos: [11, 3, 5], state: "minecraft:cobblestone"},
        {pos: [11, 3, 6], state: "minecraft:cobblestone"},
        {pos: [12, 3, 3], state: "minecraft:gravel"},
        {pos: [12, 3, 4], state: "minecraft:gravel"},
        {pos: [12, 3, 5], state: "minecraft:cobblestone"},
        {pos: [12, 3, 6], state: "minecraft:cobblestone"},
        {pos: [0, 4, 3], state: "minecraft:gravel"},
        {pos: [1, 4, 2], state: "minecraft:gravel"},
        {pos: [1, 4, 3], state: "minecraft:gravel"},
        {pos: [1, 4, 4], state: "minecraft:cobblestone"},
        {pos: [2, 4, 1], state: "minecraft:gravel"},
        {pos: [2, 4, 2], state: "minecraft:cobblestone"},
        {pos: [2, 4, 3], state: "minecraft:cobblestone"},
        {pos: [2, 4, 4], state: "minecraft:gravel"},
        {pos: [2, 4, 5], state: "minecraft:gravel"},
        {pos: [3, 4, 0], state: "minecraft:gravel"},
        {pos: [3, 4, 1], state: "minecraft:gravel"},
        {pos: [3, 4, 2], state: "minecraft:cobblestone"},
        {pos: [3, 4, 3], state: "minecraft:cobblestone"},
        {pos: [3, 4, 4], state: "minecraft:cobblestone"},
        {pos: [3, 4, 5], state: "minecraft:cobblestone"},
        {pos: [3, 4, 6], state: "minecraft:gravel"},
        {pos: [4, 4, 0], state: "minecraft:gravel"},
        {pos: [4, 4, 1], state: "minecraft:cobblestone"},
        {pos: [4, 4, 2], state: "minecraft:cobblestone"},
        {pos: [4, 4, 3], state: "minecraft:cobblestone"},
        {pos: [4, 4, 4], state: "minecraft:cobblestone"},
        {pos: [4, 4, 5], state: "minecraft:cobblestone"},
        {pos: [4, 4, 6], state: "minecraft:cobblestone"},
        {pos: [5, 4, 0], state: "minecraft:gravel"},
        {pos: [5, 4, 1], state: "minecraft:cobblestone"},
        {pos: [5, 4, 2], state: "minecraft:gravel"},
        {pos: [5, 4, 3], state: "minecraft:gravel"},
        {pos: [5, 4, 4], state: "minecraft:cobblestone"},
        {pos: [5, 4, 5], state: "minecraft:cobblestone"},
        {pos: [5, 4, 6], state: "minecraft:cobblestone"},
        {pos: [5, 4, 7], state: "minecraft:cobblestone"},
        {pos: [6, 4, 0], state: "minecraft:gravel"},
        {pos: [6, 4, 1], state: "minecraft:cobblestone"},
        {pos: [6, 4, 2], state: "minecraft:gravel"},
        {pos: [6, 4, 3], state: "minecraft:gravel"},
        {pos: [6, 4, 4], state: "minecraft:gravel"},
        {pos: [6, 4, 5], state: "minecraft:cobblestone"},
        {pos: [6, 4, 6], state: "minecraft:gravel"},
        {pos: [7, 4, 0], state: "minecraft:gravel"},
        {pos: [7, 4, 1], state: "minecraft:cobblestone"},
        {pos: [7, 4, 2], state: "minecraft:gravel"},
        {pos: [7, 4, 3], state: "minecraft:gravel"},
        {pos: [7, 4, 4], state: "minecraft:cobblestone"},
        {pos: [7, 4, 5], state: "minecraft:cobblestone"},
        {pos: [7, 4, 6], state: "minecraft:cobblestone"},
        {pos: [8, 4, 1], state: "minecraft:gravel"},
        {pos: [8, 4, 2], state: "minecraft:cobblestone"},
        {pos: [8, 4, 3], state: "minecraft:cobblestone"},
        {pos: [8, 4, 4], state: "minecraft:cobblestone"},
        {pos: [8, 4, 5], state: "minecraft:cobblestone"},
        {pos: [8, 4, 6], state: "minecraft:gravel"},
        {pos: [9, 4, 1], state: "minecraft:gravel"},
        {pos: [9, 4, 2], state: "minecraft:cobblestone"},
        {pos: [9, 4, 3], state: "minecraft:cobblestone"},
        {pos: [9, 4, 4], state: "minecraft:cobblestone"},
        {pos: [9, 4, 5], state: "minecraft:cobblestone"},
        {pos: [9, 4, 6], state: "minecraft:gravel"},
        {pos: [10, 4, 1], state: "minecraft:gravel"},
        {pos: [10, 4, 2], state: "minecraft:gravel"},
        {pos: [10, 4, 3], state: "minecraft:gravel"},
        {pos: [10, 4, 4], state: "minecraft:cobblestone"},
        {pos: [10, 4, 5], state: "minecraft:cobblestone"},
        {pos: [10, 4, 6], state: "minecraft:gravel"},
        {pos: [11, 4, 3], state: "minecraft:gravel"},
        {pos: [11, 4, 4], state: "minecraft:gravel"},
        {pos: [11, 4, 5], state: "minecraft:gravel"},
        {pos: [11, 4, 6], state: "minecraft:gravel"},
        {pos: [12, 4, 5], state: "minecraft:gravel"},
        {pos: [12, 4, 6], state: "minecraft:gravel"},
        {pos: [2, 5, 2], state: "minecraft:gravel"},
        {pos: [2, 5, 3], state: "minecraft:gravel"},
        {pos: [3, 5, 2], state: "minecraft:gravel"},
        {pos: [3, 5, 3], state: "minecraft:gravel"},
        {pos: [3, 5, 4], state: "minecraft:cobblestone"},
        {pos: [4, 5, 1], state: "minecraft:gravel"},
        {pos: [4, 5, 2], state: "minecraft:cobblestone"},
        {pos: [5, 5, 1], state: "minecraft:cobblestone"},
        {pos: [5, 5, 6], state: "minecraft:cobblestone"},
        {pos: [7, 5, 1], state: "minecraft:cobblestone"},
        {pos: [7, 5, 2], state: "minecraft:gravel"},
        {pos: [7, 5, 4], state: "minecraft:cobblestone"},
        {pos: [8, 5, 2], state: "minecraft:cobblestone"},
        {pos: [8, 5, 3], state: "minecraft:cobblestone"},
        {pos: [8, 5, 4], state: "minecraft:gravel"},
        {pos: [8, 5, 5], state: "minecraft:gravel"},
        {pos: [9, 5, 3], state: "minecraft:gravel"},
        {pos: [9, 5, 4], state: "minecraft:gravel"},
        {pos: [9, 5, 5], state: "minecraft:gravel"}
    ],
    entities: [],
    palette: [
        "minecraft:cobblestone",
        "minecraft:gravel",
        "minecraft:chiseled_stone_bricks",
        "minecraft:cobblestone_slab{type:bottom,waterlogged:true}",
        "minecraft:cobblestone_stairs{facing:west,half:top,shape:straight,waterlogged:false}",
        "minecraft:cobblestone_stairs{facing:south,half:top,shape:straight,waterlogged:false}",
        "minecraft:cobblestone_slab{type:bottom,waterlogged:false}",
        "minecraft:air"
    ],
    trailiertales_DataVersion: 2
}
