{
    DataVersion: 3953,
    size: [14, 8, 19],
    data: [
        {pos: [0, 0, 10], state: "minecraft:mud_bricks"},
        {pos: [0, 0, 11], state: "minecraft:mud_bricks"},
        {pos: [1, 0, 8], state: "minecraft:mud_bricks"},
        {pos: [1, 0, 9], state: "minecraft:mud_bricks"},
        {pos: [1, 0, 10], state: "minecraft:mud_bricks"},
        {pos: [1, 0, 11], state: "minecraft:mud_bricks"},
        {pos: [1, 0, 12], state: "minecraft:mud_bricks"},
        {pos: [1, 0, 15], state: "minecraft:mud_bricks"},
        {pos: [1, 0, 16], state: "minecraft:mud_bricks"},
        {pos: [2, 0, 7], state: "minecraft:mud_bricks"},
        {pos: [2, 0, 8], state: "minecraft:mud_bricks"},
        {pos: [2, 0, 9], state: "minecraft:mud_bricks"},
        {pos: [2, 0, 10], state: "minecraft:mud_bricks"},
        {pos: [2, 0, 11], state: "minecraft:mud_bricks"},
        {pos: [2, 0, 12], state: "minecraft:mud_bricks"},
        {pos: [2, 0, 13], state: "minecraft:mud_bricks"},
        {pos: [2, 0, 14], state: "minecraft:mud_bricks"},
        {pos: [2, 0, 15], state: "minecraft:mud_bricks"},
        {pos: [2, 0, 16], state: "minecraft:mud_bricks"},
        {pos: [3, 0, 7], state: "minecraft:mud_bricks"},
        {pos: [3, 0, 8], state: "minecraft:mud_bricks"},
        {pos: [3, 0, 9], state: "minecraft:mud_bricks"},
        {pos: [3, 0, 10], state: "minecraft:mud_bricks"},
        {pos: [3, 0, 11], state: "minecraft:mud_bricks"},
        {pos: [3, 0, 12], state: "minecraft:mud_bricks"},
        {pos: [3, 0, 13], state: "minecraft:mud_bricks"},
        {pos: [3, 0, 14], state: "minecraft:mud_bricks"},
        {pos: [3, 0, 15], state: "minecraft:mud_bricks"},
        {pos: [3, 0, 16], state: "minecraft:mud_bricks"},
        {pos: [3, 0, 17], state: "minecraft:mud_bricks"},
        {pos: [4, 0, 6], state: "minecraft:mud_bricks"},
        {pos: [4, 0, 7], state: "minecraft:mud_bricks"},
        {pos: [4, 0, 8], state: "minecraft:mud_bricks"},
        {pos: [4, 0, 9], state: "minecraft:mud_bricks"},
        {pos: [4, 0, 10], state: "minecraft:mud_bricks"},
        {pos: [4, 0, 11], state: "minecraft:mud_bricks"},
        {pos: [4, 0, 12], state: "minecraft:mud_bricks"},
        {pos: [4, 0, 13], state: "minecraft:mud_bricks"},
        {pos: [4, 0, 14], state: "minecraft:mud_bricks"},
        {pos: [4, 0, 15], state: "minecraft:mud_bricks"},
        {pos: [5, 0, 6], state: "minecraft:mud_bricks"},
        {pos: [5, 0, 7], state: "minecraft:mud_bricks"},
        {pos: [5, 0, 8], state: "minecraft:mud_bricks"},
        {pos: [5, 0, 9], state: "minecraft:mud_bricks"},
        {pos: [5, 0, 10], state: "minecraft:mud_bricks"},
        {pos: [5, 0, 11], state: "minecraft:mud_bricks"},
        {pos: [5, 0, 12], state: "minecraft:mud_bricks"},
        {pos: [5, 0, 13], state: "minecraft:mud_bricks"},
        {pos: [5, 0, 14], state: "minecraft:mud_bricks"},
        {pos: [5, 0, 15], state: "minecraft:mud_bricks"},
        {pos: [5, 0, 16], state: "minecraft:mud_bricks"},
        {pos: [6, 0, 1], state: "minecraft:mud_bricks"},
        {pos: [6, 0, 2], state: "minecraft:mud_bricks"},
        {pos: [6, 0, 3], state: "minecraft:mud_bricks"},
        {pos: [6, 0, 4], state: "minecraft:mud_bricks"},
        {pos: [6, 0, 5], state: "minecraft:mud_bricks"},
        {pos: [6, 0, 6], state: "minecraft:mud_bricks"},
        {pos: [6, 0, 7], state: "minecraft:mud_bricks"},
        {pos: [6, 0, 8], state: "minecraft:mud_bricks"},
        {pos: [6, 0, 9], state: "minecraft:mud_bricks"},
        {pos: [6, 0, 10], state: "minecraft:mud_bricks"},
        {pos: [6, 0, 11], state: "minecraft:mud_bricks"},
        {pos: [6, 0, 12], state: "minecraft:mud_bricks"},
        {pos: [6, 0, 13], state: "minecraft:mud_bricks"},
        {pos: [6, 0, 14], state: "minecraft:mud_bricks"},
        {pos: [6, 0, 15], state: "minecraft:mud_bricks"},
        {pos: [6, 0, 16], state: "minecraft:mud_bricks"},
        {pos: [6, 0, 17], state: "minecraft:mud_bricks"},
        {pos: [6, 0, 18], state: "minecraft:mud_bricks"},
        {pos: [7, 0, 0], state: "minecraft:mud_bricks"},
        {pos: [7, 0, 1], state: "minecraft:mud_bricks"},
        {pos: [7, 0, 2], state: "minecraft:mud_bricks"},
        {pos: [7, 0, 3], state: "minecraft:mud_bricks"},
        {pos: [7, 0, 4], state: "minecraft:mud_bricks"},
        {pos: [7, 0, 5], state: "minecraft:mud_bricks"},
        {pos: [7, 0, 6], state: "minecraft:mud_bricks"},
        {pos: [7, 0, 7], state: "minecraft:mud_bricks"},
        {pos: [7, 0, 8], state: "minecraft:yellow_glazed_terracotta{facing:west}"},
        {pos: [7, 0, 9], state: "minecraft:mud_bricks"},
        {pos: [7, 0, 10], state: "minecraft:mud_bricks"},
        {pos: [7, 0, 11], state: "minecraft:yellow_glazed_terracotta{facing:north}"},
        {pos: [7, 0, 12], state: "minecraft:yellow_glazed_terracotta{facing:west}"},
        {pos: [7, 0, 13], state: "minecraft:mud_bricks"},
        {pos: [7, 0, 14], state: "minecraft:mud_bricks"},
        {pos: [7, 0, 15], state: "minecraft:mud_bricks"},
        {pos: [7, 0, 16], state: "minecraft:mud_bricks"},
        {pos: [7, 0, 17], state: "minecraft:mud_bricks"},
        {pos: [7, 0, 18], state: "minecraft:mud_bricks"},
        {pos: [8, 0, 0], state: "minecraft:mud_bricks"},
        {pos: [8, 0, 1], state: "minecraft:mud_bricks"},
        {pos: [8, 0, 2], state: "minecraft:mud_bricks"},
        {pos: [8, 0, 3], state: "minecraft:mud_bricks"},
        {pos: [8, 0, 6], state: "minecraft:mud_bricks"},
        {pos: [8, 0, 7], state: "minecraft:mud_bricks"},
        {pos: [8, 0, 8], state: "minecraft:yellow_glazed_terracotta{facing:south}"},
        {pos: [8, 0, 9], state: "minecraft:mud_bricks"},
        {pos: [8, 0, 10], state: "minecraft:mud_bricks"},
        {pos: [8, 0, 11], state: "minecraft:mud_bricks"},
        {pos: [8, 0, 12], state: "minecraft:yellow_glazed_terracotta{facing:south}"},
        {pos: [8, 0, 13], state: "minecraft:mud_bricks"},
        {pos: [8, 0, 14], state: "minecraft:mud_bricks"},
        {pos: [8, 0, 15], state: "minecraft:mud_bricks"},
        {pos: [8, 0, 16], state: "minecraft:mud_bricks"},
        {pos: [8, 0, 17], state: "minecraft:mud_bricks"},
        {pos: [9, 0, 0], state: "minecraft:mud_bricks"},
        {pos: [9, 0, 1], state: "minecraft:mud_bricks"},
        {pos: [9, 0, 8], state: "minecraft:mud_bricks"},
        {pos: [9, 0, 9], state: "minecraft:mud_bricks"},
        {pos: [9, 0, 10], state: "minecraft:mud_bricks"},
        {pos: [9, 0, 11], state: "minecraft:mud_bricks"},
        {pos: [9, 0, 12], state: "minecraft:mud_bricks"},
        {pos: [9, 0, 13], state: "minecraft:mud_bricks"},
        {pos: [9, 0, 14], state: "minecraft:mud_bricks"},
        {pos: [9, 0, 15], state: "minecraft:mud_bricks"},
        {pos: [9, 0, 16], state: "minecraft:mud_bricks"},
        {pos: [10, 0, 9], state: "minecraft:mud_bricks"},
        {pos: [10, 0, 10], state: "minecraft:mud_bricks"},
        {pos: [10, 0, 11], state: "minecraft:mud_bricks"},
        {pos: [10, 0, 12], state: "minecraft:mud_bricks"},
        {pos: [10, 0, 13], state: "minecraft:mud_bricks"},
        {pos: [10, 0, 14], state: "minecraft:mud_bricks"},
        {pos: [10, 0, 15], state: "minecraft:mud_bricks"},
        {pos: [11, 0, 7], state: "minecraft:mud_bricks"},
        {pos: [11, 0, 8], state: "minecraft:mud_bricks"},
        {pos: [11, 0, 9], state: "minecraft:mud_bricks"},
        {pos: [11, 0, 10], state: "minecraft:mud_bricks"},
        {pos: [11, 0, 12], state: "minecraft:mud_bricks"},
        {pos: [11, 0, 13], state: "minecraft:mud_bricks"},
        {pos: [11, 0, 14], state: "minecraft:mud_bricks"},
        {pos: [11, 0, 15], state: "minecraft:mud_bricks"},
        {pos: [11, 0, 16], state: "minecraft:mud_bricks"},
        {pos: [11, 0, 17], state: "minecraft:mud_bricks"},
        {pos: [12, 0, 7], state: "minecraft:mud_bricks"},
        {pos: [12, 0, 8], state: "minecraft:mud_bricks"},
        {pos: [12, 0, 9], state: "minecraft:mud_bricks"},
        {pos: [12, 0, 10], state: "minecraft:mud_bricks"},
        {pos: [12, 0, 13], state: "minecraft:mud_bricks"},
        {pos: [12, 0, 14], state: "minecraft:mud_bricks"},
        {pos: [12, 0, 15], state: "minecraft:mud_bricks"},
        {pos: [12, 0, 16], state: "minecraft:mud_bricks"},
        {pos: [13, 0, 8], state: "minecraft:mud_bricks"},
        {pos: [13, 0, 9], state: "minecraft:mud_bricks"},
        {pos: [13, 0, 14], state: "minecraft:mud_bricks"},
        {pos: [13, 0, 15], state: "minecraft:mud_bricks"},
        {pos: [0, 1, 10], state: "minecraft:gravel"},
        {pos: [0, 1, 11], state: "minecraft:gravel"},
        {pos: [1, 1, 8], state: "minecraft:gravel"},
        {pos: [1, 1, 9], state: "minecraft:gravel"},
        {pos: [1, 1, 10], state: "minecraft:gravel"},
        {pos: [1, 1, 11], state: "minecraft:gravel"},
        {pos: [1, 1, 12], state: "minecraft:gravel"},
        {pos: [1, 1, 15], state: "minecraft:gravel"},
        {pos: [1, 1, 16], state: "minecraft:gravel"},
        {pos: [2, 1, 7], state: "minecraft:gravel"},
        {pos: [2, 1, 8], state: "minecraft:gravel"},
        {pos: [2, 1, 9], state: "minecraft:mud_bricks"},
        {pos: [2, 1, 10], state: "minecraft:mud_bricks"},
        {pos: [2, 1, 11], state: "minecraft:mud_bricks"},
        {pos: [2, 1, 12], state: "minecraft:mud_bricks"},
        {pos: [2, 1, 13], state: "minecraft:mud_bricks"},
        {pos: [2, 1, 14], state: "minecraft:mud_bricks"},
        {pos: [2, 1, 15], state: "minecraft:mud_bricks"},
        {pos: [2, 1, 16], state: "minecraft:gravel"},
        {pos: [3, 1, 7], state: "minecraft:gravel"},
        {pos: [3, 1, 8], state: "minecraft:gravel"},
        {pos: [3, 1, 9], state: "minecraft:mud_bricks"},
        {pos: [3, 1, 10], state: "minecraft:mud_bricks"},
        {pos: [3, 1, 11], state: "minecraft:mud_brick_stairs{facing:west,half:top,shape:straight,waterlogged:false}"},
        {pos: [3, 1, 12], state: "minecraft:mud_brick_stairs{facing:west,half:top,shape:straight,waterlogged:false}"},
        {pos: [3, 1, 13], state: "minecraft:mud_brick_stairs{facing:west,half:top,shape:straight,waterlogged:false}"},
        {pos: [3, 1, 14], state: "minecraft:mud_bricks"},
        {pos: [3, 1, 15], state: "minecraft:mud_bricks"},
        {pos: [3, 1, 16], state: "minecraft:gravel"},
        {pos: [3, 1, 17], state: "minecraft:gravel"},
        {pos: [4, 1, 6], state: "minecraft:gravel"},
        {pos: [4, 1, 7], state: "minecraft:gravel"},
        {pos: [4, 1, 8], state: "minecraft:gravel"},
        {pos: [4, 1, 9], state: "minecraft:mud_brick_stairs{facing:west,half:top,shape:straight,waterlogged:false}"},
        {pos: [4, 1, 10], state: "minecraft:gravel"},
        {pos: [4, 1, 11], state: "minecraft:gravel"},
        {pos: [4, 1, 12], state: "minecraft:gravel"},
        {pos: [4, 1, 13], state: "minecraft:gravel"},
        {pos: [4, 1, 14], state: "minecraft:gravel"},
        {pos: [4, 1, 15], state: "minecraft:gravel"},
        {pos: [5, 1, 6], state: "minecraft:gravel"},
        {pos: [5, 1, 7], state: "minecraft:gravel"},
        {pos: [5, 1, 8], state: "minecraft:gravel"},
        {pos: [5, 1, 9], state: "minecraft:gravel"},
        {pos: [5, 1, 10], state: "minecraft:gravel"},
        {pos: [5, 1, 11], state: "minecraft:gravel"},
        {pos: [5, 1, 12], state: "minecraft:gravel"},
        {pos: [5, 1, 13], state: "minecraft:gravel"},
        {pos: [5, 1, 14], state: "minecraft:gravel"},
        {pos: [5, 1, 15], state: "minecraft:gravel"},
        {pos: [5, 1, 16], state: "minecraft:gravel"},
        {pos: [6, 1, 1], state: "minecraft:mud_bricks"},
        {pos: [6, 1, 2], state: "minecraft:mud_bricks"},
        {pos: [6, 1, 3], state: "minecraft:mud_bricks"},
        {pos: [6, 1, 4], state: "minecraft:gravel"},
        {pos: [6, 1, 5], state: "minecraft:gravel"},
        {pos: [6, 1, 6], state: "minecraft:gravel"},
        {pos: [6, 1, 7], state: "minecraft:gravel"},
        {pos: [6, 1, 8], state: "minecraft:gravel"},
        {pos: [6, 1, 9], state: "minecraft:gravel"},
        {pos: [6, 1, 10], state: "minecraft:gravel"},
        {pos: [6, 1, 11], state: "minecraft:gravel"},
        {pos: [6, 1, 12], state: "minecraft:gravel"},
        {pos: [6, 1, 13], state: "minecraft:gravel"},
        {pos: [6, 1, 14], state: "minecraft:gravel"},
        {pos: [6, 1, 15], state: "minecraft:gravel"},
        {pos: [6, 1, 16], state: "minecraft:gravel"},
        {pos: [6, 1, 17], state: "minecraft:mud_bricks"},
        {pos: [6, 1, 18], state: "minecraft:gravel"},
        {pos: [7, 1, 0], state: "minecraft:gravel"},
        {pos: [7, 1, 1], state: "minecraft:mud_bricks"},
        {pos: [7, 1, 2], state: "minecraft:gravel"},
        {pos: [7, 1, 3], state: "minecraft:gravel"},
        {pos: [7, 1, 4], state: "minecraft:gravel"},
        {pos: [7, 1, 5], state: "minecraft:gravel"},
        {pos: [7, 1, 6], state: "minecraft:gravel"},
        {pos: [7, 1, 7], state: "minecraft:gravel"},
        {pos: [7, 1, 8], state: "minecraft:gravel"},
        {pos: [7, 1, 9], state: "minecraft:gravel"},
        {pos: [7, 1, 10], state: "minecraft:gravel"},
        {pos: [7, 1, 11], state: "minecraft:gravel"},
        {pos: [7, 1, 12], state: "minecraft:gravel"},
        {pos: [7, 1, 13], state: "minecraft:gravel"},
        {pos: [7, 1, 14], state: "minecraft:gravel"},
        {pos: [7, 1, 15], state: "minecraft:gravel"},
        {pos: [7, 1, 16], state: "minecraft:gravel"},
        {pos: [7, 1, 17], state: "minecraft:mud_bricks"},
        {pos: [7, 1, 18], state: "minecraft:gravel"},
        {pos: [8, 1, 0], state: "minecraft:gravel"},
        {pos: [8, 1, 1], state: "minecraft:mud_bricks"},
        {pos: [8, 1, 2], state: "minecraft:mud_bricks"},
        {pos: [8, 1, 3], state: "minecraft:mud_bricks"},
        {pos: [8, 1, 6], state: "minecraft:gravel"},
        {pos: [8, 1, 7], state: "minecraft:gravel"},
        {pos: [8, 1, 8], state: "minecraft:gravel"},
        {pos: [8, 1, 9], state: "minecraft:gravel"},
        {pos: [8, 1, 10], state: "minecraft:gravel"},
        {pos: [8, 1, 11], state: "minecraft:gravel"},
        {pos: [8, 1, 12], state: "minecraft:gravel"},
        {pos: [8, 1, 13], state: "minecraft:gravel"},
        {pos: [8, 1, 14], state: "minecraft:gravel"},
        {pos: [8, 1, 15], state: "minecraft:gravel"},
        {pos: [8, 1, 16], state: "minecraft:gravel"},
        {pos: [8, 1, 17], state: "minecraft:mud_bricks"},
        {pos: [9, 1, 0], state: "minecraft:gravel"},
        {pos: [9, 1, 1], state: "minecraft:gravel"},
        {pos: [9, 1, 8], state: "minecraft:gravel"},
        {pos: [9, 1, 9], state: "minecraft:gravel"},
        {pos: [9, 1, 10], state: "minecraft:gravel"},
        {pos: [9, 1, 11], state: "minecraft:gravel"},
        {pos: [9, 1, 12], state: "minecraft:gravel"},
        {pos: [9, 1, 13], state: "minecraft:gravel"},
        {pos: [9, 1, 14], state: "minecraft:gravel"},
        {pos: [9, 1, 15], state: "minecraft:gravel"},
        {pos: [9, 1, 16], state: "minecraft:gravel"},
        {pos: [9, 1, 17], state: "minecraft:mud_brick_stairs{facing:west,half:top,shape:straight,waterlogged:false}"},
        {pos: [10, 1, 9], state: "minecraft:mud_brick_stairs{facing:east,half:top,shape:straight,waterlogged:false}"},
        {pos: [10, 1, 10], state: "minecraft:mud_brick_stairs{facing:east,half:top,shape:straight,waterlogged:false}"},
        {pos: [10, 1, 11], state: "minecraft:gravel"},
        {pos: [10, 1, 12], state: "minecraft:gravel"},
        {pos: [10, 1, 13], state: "minecraft:gravel"},
        {pos: [10, 1, 14], state: "minecraft:gravel"},
        {pos: [10, 1, 15], state: "minecraft:gravel"},
        {pos: [11, 1, 7], state: "minecraft:gravel"},
        {pos: [11, 1, 8], state: "minecraft:gravel"},
        {pos: [11, 1, 9], state: "minecraft:mud_bricks"},
        {pos: [11, 1, 10], state: "minecraft:mud_bricks"},
        {pos: [11, 1, 11], state: "minecraft:mud_brick_stairs{facing:north,half:top,shape:straight,waterlogged:false}"},
        {pos: [11, 1, 12], state: "minecraft:gravel"},
        {pos: [11, 1, 13], state: "minecraft:gravel"},
        {pos: [11, 1, 14], state: "minecraft:mud_bricks"},
        {pos: [11, 1, 15], state: "minecraft:mud_bricks"},
        {pos: [11, 1, 16], state: "minecraft:gravel"},
        {pos: [11, 1, 17], state: "minecraft:gravel"},
        {pos: [12, 1, 7], state: "minecraft:gravel"},
        {pos: [12, 1, 8], state: "minecraft:gravel"},
        {pos: [12, 1, 9], state: "minecraft:mud_bricks"},
        {pos: [12, 1, 10], state: "minecraft:mud_bricks"},
        {pos: [12, 1, 11], state: "minecraft:mud_brick_stairs{facing:north,half:top,shape:straight,waterlogged:false}"},
        {pos: [12, 1, 13], state: "minecraft:gravel"},
        {pos: [12, 1, 14], state: "minecraft:mud_bricks"},
        {pos: [12, 1, 15], state: "minecraft:mud_bricks"},
        {pos: [12, 1, 16], state: "minecraft:gravel"},
        {pos: [13, 1, 8], state: "minecraft:gravel"},
        {pos: [13, 1, 9], state: "minecraft:gravel"},
        {pos: [13, 1, 14], state: "minecraft:gravel"},
        {pos: [13, 1, 15], state: "minecraft:gravel"},
        {pos: [0, 2, 10], state: "minecraft:gravel"},
        {pos: [0, 2, 11], state: "minecraft:gravel"},
        {pos: [1, 2, 8], state: "minecraft:gravel"},
        {pos: [1, 2, 9], state: "minecraft:gravel"},
        {pos: [1, 2, 10], state: "minecraft:gravel"},
        {pos: [1, 2, 11], state: "minecraft:gravel"},
        {pos: [1, 2, 12], state: "minecraft:gravel"},
        {pos: [1, 2, 15], state: "minecraft:gravel"},
        {pos: [1, 2, 16], state: "minecraft:gravel"},
        {pos: [2, 2, 7], state: "minecraft:gravel"},
        {pos: [2, 2, 8], state: "minecraft:gravel"},
        {pos: [2, 2, 9], state: "minecraft:mud_bricks"},
        {pos: [2, 2, 10], state: "minecraft:mud_bricks"},
        {pos: [2, 2, 11], state: "minecraft:gravel"},
        {pos: [2, 2, 12], state: "minecraft:gravel"},
        {pos: [2, 2, 13], state: "minecraft:gravel"},
        {pos: [2, 2, 14], state: "minecraft:mud_bricks"},
        {pos: [2, 2, 15], state: "minecraft:mud_bricks"},
        {pos: [2, 2, 16], state: "minecraft:gravel"},
        {pos: [3, 2, 7], state: "minecraft:gravel"},
        {pos: [3, 2, 8], state: "minecraft:gravel"},
        {pos: [3, 2, 9], state: "minecraft:mud_bricks"},
        {pos: [3, 2, 10], state: "minecraft:mud_bricks"},
        {pos: [3, 2, 11], state: "minecraft:gravel"},
        {pos: [3, 2, 12], state: "minecraft:gravel"},
        {pos: [3, 2, 13], state: "minecraft:gravel"},
        {pos: [3, 2, 14], state: "minecraft:mud_bricks"},
        {pos: [3, 2, 15], state: "minecraft:mud_bricks"},
        {pos: [3, 2, 16], state: "minecraft:gravel"},
        {pos: [3, 2, 17], state: "minecraft:gravel"},
        {pos: [4, 2, 6], state: "minecraft:gravel"},
        {pos: [4, 2, 7], state: "minecraft:gravel"},
        {pos: [4, 2, 8], state: "minecraft:gravel"},
        {pos: [4, 2, 9], state: "minecraft:gravel"},
        {pos: [4, 2, 10], state: "minecraft:gravel"},
        {pos: [4, 2, 11], state: "minecraft:gravel"},
        {pos: [4, 2, 12], state: "minecraft:gravel"},
        {pos: [4, 2, 13], state: "minecraft:gravel"},
        {pos: [4, 2, 14], state: "minecraft:gravel"},
        {pos: [4, 2, 15], state: "minecraft:gravel"},
        {pos: [5, 2, 6], state: "minecraft:gravel"},
        {pos: [5, 2, 7], state: "minecraft:gravel"},
        {pos: [5, 2, 8], state: "minecraft:gravel"},
        {pos: [5, 2, 9], state: "minecraft:gravel"},
        {pos: [5, 2, 10], state: "minecraft:gravel"},
        {pos: [5, 2, 11], state: "minecraft:gravel"},
        {pos: [5, 2, 12], state: "minecraft:gravel"},
        {pos: [5, 2, 13], state: "minecraft:gravel"},
        {pos: [5, 2, 14], state: "minecraft:gravel"},
        {pos: [5, 2, 15], state: "minecraft:gravel"},
        {pos: [5, 2, 16], state: "minecraft:gravel"},
        {pos: [5, 2, 17], state: "minecraft:mud_brick_stairs{facing:east,half:top,shape:straight,waterlogged:false}"},
        {pos: [6, 2, 1], state: "minecraft:mud_bricks"},
        {pos: [6, 2, 2], state: "minecraft:mud_bricks"},
        {pos: [6, 2, 3], state: "minecraft:mud_bricks"},
        {pos: [6, 2, 4], state: "minecraft:gravel"},
        {pos: [6, 2, 5], state: "minecraft:gravel"},
        {pos: [6, 2, 6], state: "minecraft:gravel"},
        {pos: [6, 2, 7], state: "minecraft:gravel"},
        {pos: [6, 2, 8], state: "minecraft:gravel"},
        {pos: [6, 2, 9], state: "minecraft:gravel"},
        {pos: [6, 2, 10], state: "minecraft:gravel"},
        {pos: [6, 2, 11], state: "minecraft:gravel"},
        {pos: [6, 2, 12], state: "minecraft:gravel"},
        {pos: [6, 2, 13], state: "minecraft:gravel"},
        {pos: [6, 2, 14], state: "minecraft:gravel"},
        {pos: [6, 2, 15], state: "minecraft:gravel"},
        {pos: [6, 2, 16], state: "minecraft:gravel"},
        {pos: [6, 2, 17], state: "minecraft:mud_bricks"},
        {pos: [6, 2, 18], state: "minecraft:gravel"},
        {pos: [7, 2, 0], state: "minecraft:gravel"},
        {pos: [7, 2, 1], state: "minecraft:mud_bricks"},
        {pos: [7, 2, 2], state: "minecraft:gravel"},
        {pos: [7, 2, 3], state: "minecraft:gravel"},
        {pos: [7, 2, 4], state: "minecraft:gravel"},
        {pos: [7, 2, 5], state: "minecraft:gravel"},
        {pos: [7, 2, 6], state: "minecraft:gravel"},
        {pos: [7, 2, 7], state: "minecraft:gravel"},
        {pos: [7, 2, 8], state: "minecraft:gravel"},
        {pos: [7, 2, 9], state: "minecraft:gravel"},
        {pos: [7, 2, 10], state: "minecraft:gravel"},
        {pos: [7, 2, 11], state: "minecraft:gravel"},
        {pos: [7, 2, 12], state: "minecraft:gravel"},
        {pos: [7, 2, 13], state: "minecraft:gravel"},
        {pos: [7, 2, 14], state: "minecraft:gravel"},
        {pos: [7, 2, 15], state: "minecraft:gravel"},
        {pos: [7, 2, 16], state: "minecraft:gravel"},
        {pos: [7, 2, 17], state: "minecraft:orange_glazed_terracotta{facing:north}"},
        {pos: [7, 2, 18], state: "minecraft:gravel"},
        {pos: [8, 2, 0], state: "minecraft:gravel"},
        {pos: [8, 2, 1], state: "minecraft:mud_bricks"},
        {pos: [8, 2, 2], state: "minecraft:mud_bricks"},
        {pos: [8, 2, 3], state: "minecraft:mud_bricks"},
        {pos: [8, 2, 6], state: "minecraft:gravel"},
        {pos: [8, 2, 7], state: "minecraft:gravel"},
        {pos: [8, 2, 8], state: "minecraft:gravel"},
        {pos: [8, 2, 9], state: "minecraft:gravel"},
        {pos: [8, 2, 10], state: "minecraft:gravel"},
        {pos: [8, 2, 11], state: "minecraft:gravel"},
        {pos: [8, 2, 12], state: "minecraft:gravel"},
        {pos: [8, 2, 13], state: "minecraft:gravel"},
        {pos: [8, 2, 14], state: "minecraft:gravel"},
        {pos: [8, 2, 15], state: "minecraft:gravel"},
        {pos: [8, 2, 16], state: "minecraft:gravel"},
        {pos: [8, 2, 17], state: "minecraft:orange_glazed_terracotta{facing:east}"},
        {pos: [9, 2, 0], state: "minecraft:gravel"},
        {pos: [9, 2, 1], state: "minecraft:gravel"},
        {pos: [9, 2, 8], state: "minecraft:gravel"},
        {pos: [9, 2, 9], state: "minecraft:gravel"},
        {pos: [9, 2, 10], state: "minecraft:gravel"},
        {pos: [9, 2, 11], state: "minecraft:gravel"},
        {pos: [9, 2, 12], state: "minecraft:gravel"},
        {pos: [9, 2, 13], state: "minecraft:gravel"},
        {pos: [9, 2, 14], state: "minecraft:gravel"},
        {pos: [9, 2, 15], state: "minecraft:gravel"},
        {pos: [9, 2, 16], state: "minecraft:gravel"},
        {pos: [9, 2, 17], state: "minecraft:mud_bricks"},
        {pos: [10, 2, 9], state: "minecraft:gravel"},
        {pos: [10, 2, 10], state: "minecraft:gravel"},
        {pos: [10, 2, 11], state: "minecraft:gravel"},
        {pos: [10, 2, 12], state: "minecraft:gravel"},
        {pos: [10, 2, 13], state: "minecraft:gravel"},
        {pos: [10, 2, 14], state: "minecraft:gravel"},
        {pos: [10, 2, 15], state: "minecraft:gravel"},
        {pos: [10, 2, 17], state: "minecraft:mud_brick_stairs{facing:west,half:top,shape:straight,waterlogged:false}"},
        {pos: [11, 2, 7], state: "minecraft:gravel"},
        {pos: [11, 2, 8], state: "minecraft:gravel"},
        {pos: [11, 2, 9], state: "minecraft:mud_bricks"},
        {pos: [11, 2, 10], state: "minecraft:mud_bricks"},
        {pos: [11, 2, 11], state: "minecraft:gravel"},
        {pos: [11, 2, 12], state: "minecraft:gravel"},
        {pos: [11, 2, 13], state: "minecraft:gravel"},
        {pos: [11, 2, 14], state: "minecraft:mud_bricks"},
        {pos: [11, 2, 15], state: "minecraft:mud_bricks"},
        {pos: [11, 2, 16], state: "minecraft:gravel"},
        {pos: [11, 2, 17], state: "minecraft:gravel"},
        {pos: [12, 2, 8], state: "minecraft:gravel"},
        {pos: [12, 2, 9], state: "minecraft:mud_bricks"},
        {pos: [12, 2, 10], state: "minecraft:mud_bricks"},
        {pos: [12, 2, 11], state: "minecraft:gravel"},
        {pos: [12, 2, 13], state: "minecraft:gravel"},
        {pos: [12, 2, 14], state: "minecraft:mud_bricks"},
        {pos: [12, 2, 15], state: "minecraft:mud_bricks"},
        {pos: [12, 2, 16], state: "minecraft:gravel"},
        {pos: [13, 2, 8], state: "minecraft:gravel"},
        {pos: [13, 2, 9], state: "minecraft:gravel"},
        {pos: [13, 2, 14], state: "minecraft:gravel"},
        {pos: [13, 2, 15], state: "minecraft:gravel"},
        {pos: [0, 3, 11], state: "minecraft:gravel"},
        {pos: [1, 3, 8], state: "minecraft:gravel"},
        {pos: [1, 3, 9], state: "minecraft:gravel"},
        {pos: [1, 3, 10], state: "minecraft:gravel"},
        {pos: [1, 3, 11], state: "minecraft:gravel"},
        {pos: [1, 3, 12], state: "minecraft:gravel"},
        {pos: [1, 3, 15], state: "minecraft:gravel"},
        {pos: [1, 3, 16], state: "minecraft:gravel"},
        {pos: [2, 3, 7], state: "minecraft:gravel"},
        {pos: [2, 3, 8], state: "minecraft:gravel"},
        {pos: [2, 3, 9], state: "minecraft:mud_bricks"},
        {pos: [2, 3, 10], state: "minecraft:mud_bricks"},
        {pos: [2, 3, 11], state: "minecraft:gravel"},
        {pos: [2, 3, 12], state: "minecraft:gravel"},
        {pos: [2, 3, 13], state: "minecraft:gravel"},
        {pos: [2, 3, 14], state: "minecraft:mud_bricks"},
        {pos: [2, 3, 15], state: "minecraft:mud_bricks"},
        {pos: [2, 3, 16], state: "minecraft:gravel"},
        {pos: [3, 3, 7], state: "minecraft:gravel"},
        {pos: [3, 3, 8], state: "minecraft:gravel"},
        {pos: [3, 3, 9], state: "minecraft:mud_bricks"},
        {pos: [3, 3, 10], state: "minecraft:mud_bricks"},
        {pos: [3, 3, 11], state: "minecraft:gravel"},
        {pos: [3, 3, 12], state: "minecraft:gravel"},
        {pos: [3, 3, 13], state: "minecraft:gravel"},
        {pos: [3, 3, 14], state: "minecraft:mud_bricks"},
        {pos: [3, 3, 15], state: "minecraft:mud_bricks"},
        {pos: [3, 3, 16], state: "minecraft:gravel"},
        {pos: [3, 3, 17], state: "minecraft:gravel"},
        {pos: [4, 3, 6], state: "minecraft:gravel"},
        {pos: [4, 3, 7], state: "minecraft:gravel"},
        {pos: [4, 3, 8], state: "minecraft:gravel"},
        {pos: [4, 3, 9], state: "minecraft:gravel"},
        {pos: [4, 3, 10], state: "minecraft:gravel"},
        {pos: [4, 3, 11], state: "minecraft:gravel"},
        {pos: [4, 3, 12], state: "minecraft:gravel"},
        {pos: [4, 3, 13], state: "minecraft:gravel"},
        {pos: [4, 3, 14], state: "minecraft:gravel"},
        {pos: [4, 3, 15], state: "minecraft:gravel"},
        {pos: [5, 3, 6], state: "minecraft:gravel"},
        {pos: [5, 3, 7], state: "minecraft:gravel"},
        {pos: [5, 3, 8], state: "minecraft:gravel"},
        {pos: [5, 3, 9], state: "minecraft:gravel"},
        {pos: [5, 3, 10], state: "minecraft:gravel"},
        {pos: [5, 3, 11], state: "minecraft:gravel"},
        {pos: [5, 3, 12], state: "minecraft:gravel"},
        {pos: [5, 3, 13], state: "minecraft:gravel"},
        {pos: [5, 3, 14], state: "minecraft:gravel"},
        {pos: [5, 3, 15], state: "minecraft:gravel"},
        {pos: [5, 3, 16], state: "minecraft:gravel"},
        {pos: [5, 3, 17], state: "minecraft:gravel"},
        {pos: [6, 3, 1], state: "minecraft:mud_bricks"},
        {pos: [6, 3, 2], state: "minecraft:mud_bricks"},
        {pos: [6, 3, 3], state: "minecraft:mud_bricks"},
        {pos: [6, 3, 4], state: "minecraft:gravel"},
        {pos: [6, 3, 5], state: "minecraft:gravel"},
        {pos: [6, 3, 6], state: "minecraft:gravel"},
        {pos: [6, 3, 7], state: "minecraft:gravel"},
        {pos: [6, 3, 8], state: "minecraft:gravel"},
        {pos: [6, 3, 9], state: "minecraft:gravel"},
        {pos: [6, 3, 10], state: "minecraft:gravel"},
        {pos: [6, 3, 11], state: "minecraft:gravel"},
        {pos: [6, 3, 12], state: "minecraft:gravel"},
        {pos: [6, 3, 13], state: "minecraft:gravel"},
        {pos: [6, 3, 14], state: "minecraft:gravel"},
        {pos: [6, 3, 15], state: "minecraft:gravel"},
        {pos: [6, 3, 16], state: "minecraft:gravel"},
        {pos: [6, 3, 17], state: "minecraft:mud_bricks"},
        {pos: [6, 3, 18], state: "minecraft:gravel"},
        {pos: [7, 3, 0], state: "minecraft:gravel"},
        {pos: [7, 3, 1], state: "minecraft:mud_bricks"},
        {pos: [7, 3, 2], state: "minecraft:gravel"},
        {pos: [7, 3, 3], state: "minecraft:mud_bricks"},
        {pos: [7, 3, 4], state: "minecraft:gravel"},
        {pos: [7, 3, 5], state: "minecraft:gravel"},
        {pos: [7, 3, 6], state: "minecraft:gravel"},
        {pos: [7, 3, 7], state: "minecraft:gravel"},
        {pos: [7, 3, 8], state: "minecraft:gravel"},
        {pos: [7, 3, 9], state: "minecraft:gravel"},
        {pos: [7, 3, 10], state: "minecraft:gravel"},
        {pos: [7, 3, 11], state: "minecraft:gravel"},
        {pos: [7, 3, 12], state: "minecraft:gravel"},
        {pos: [7, 3, 13], state: "minecraft:gravel"},
        {pos: [7, 3, 14], state: "minecraft:gravel"},
        {pos: [7, 3, 15], state: "minecraft:gravel"},
        {pos: [7, 3, 16], state: "minecraft:gravel"},
        {pos: [7, 3, 17], state: "minecraft:mud_bricks"},
        {pos: [7, 3, 18], state: "minecraft:gravel"},
        {pos: [8, 3, 0], state: "minecraft:gravel"},
        {pos: [8, 3, 1], state: "minecraft:mud_bricks"},
        {pos: [8, 3, 2], state: "minecraft:mud_bricks"},
        {pos: [8, 3, 3], state: "minecraft:mud_bricks"},
        {pos: [8, 3, 6], state: "minecraft:gravel"},
        {pos: [8, 3, 7], state: "minecraft:gravel"},
        {pos: [8, 3, 8], state: "minecraft:gravel"},
        {pos: [8, 3, 9], state: "minecraft:gravel"},
        {pos: [8, 3, 10], state: "minecraft:gravel"},
        {pos: [8, 3, 11], state: "minecraft:gravel"},
        {pos: [8, 3, 12], state: "minecraft:gravel"},
        {pos: [8, 3, 13], state: "minecraft:gravel"},
        {pos: [8, 3, 14], state: "minecraft:gravel"},
        {pos: [8, 3, 15], state: "minecraft:gravel"},
        {pos: [8, 3, 16], state: "minecraft:gravel"},
        {pos: [8, 3, 17], state: "minecraft:mud_bricks"},
        {pos: [9, 3, 0], state: "minecraft:gravel"},
        {pos: [9, 3, 1], state: "minecraft:gravel"},
        {pos: [9, 3, 8], state: "minecraft:gravel"},
        {pos: [9, 3, 9], state: "minecraft:gravel"},
        {pos: [9, 3, 10], state: "minecraft:gravel"},
        {pos: [9, 3, 11], state: "minecraft:gravel"},
        {pos: [9, 3, 12], state: "minecraft:gravel"},
        {pos: [9, 3, 13], state: "minecraft:gravel"},
        {pos: [9, 3, 14], state: "minecraft:gravel"},
        {pos: [9, 3, 15], state: "minecraft:gravel"},
        {pos: [9, 3, 16], state: "minecraft:gravel"},
        {pos: [9, 3, 17], state: "minecraft:mud_brick_stairs{facing:south,half:bottom,shape:straight,waterlogged:false}"},
        {pos: [10, 3, 9], state: "minecraft:gravel"},
        {pos: [10, 3, 10], state: "minecraft:gravel"},
        {pos: [10, 3, 11], state: "minecraft:gravel"},
        {pos: [10, 3, 12], state: "minecraft:gravel"},
        {pos: [10, 3, 13], state: "minecraft:gravel"},
        {pos: [10, 3, 14], state: "minecraft:gravel"},
        {pos: [10, 3, 15], state: "minecraft:gravel"},
        {pos: [10, 3, 17], state: "minecraft:gravel"},
        {pos: [11, 3, 8], state: "minecraft:gravel"},
        {pos: [11, 3, 9], state: "minecraft:mud_bricks"},
        {pos: [11, 3, 10], state: "minecraft:mud_bricks"},
        {pos: [11, 3, 11], state: "minecraft:gravel"},
        {pos: [11, 3, 12], state: "minecraft:gravel"},
        {pos: [11, 3, 13], state: "minecraft:gravel"},
        {pos: [11, 3, 14], state: "minecraft:mud_bricks"},
        {pos: [11, 3, 15], state: "minecraft:mud_bricks"},
        {pos: [11, 3, 16], state: "minecraft:gravel"},
        {pos: [11, 3, 17], state: "minecraft:gravel"},
        {pos: [12, 3, 8], state: "minecraft:gravel"},
        {pos: [12, 3, 9], state: "minecraft:gravel"},
        {pos: [12, 3, 10], state: "minecraft:mud_bricks"},
        {pos: [12, 3, 11], state: "minecraft:gravel"},
        {pos: [12, 3, 13], state: "minecraft:gravel"},
        {pos: [12, 3, 14], state: "minecraft:mud_bricks"},
        {pos: [12, 3, 15], state: "minecraft:mud_bricks"},
        {pos: [12, 3, 16], state: "minecraft:gravel"},
        {pos: [13, 3, 9], state: "minecraft:gravel"},
        {pos: [13, 3, 14], state: "minecraft:gravel"},
        {pos: [13, 3, 15], state: "minecraft:gravel"},
        {pos: [1, 4, 9], state: "minecraft:gravel"},
        {pos: [1, 4, 10], state: "minecraft:gravel"},
        {pos: [1, 4, 11], state: "minecraft:gravel"},
        {pos: [2, 4, 8], state: "minecraft:gravel"},
        {pos: [2, 4, 9], state: "minecraft:mud_bricks"},
        {pos: [2, 4, 10], state: "minecraft:mud_bricks"},
        {pos: [2, 4, 11], state: "minecraft:gravel"},
        {pos: [2, 4, 12], state: "minecraft:gravel"},
        {pos: [2, 4, 13], state: "minecraft:gravel"},
        {pos: [2, 4, 14], state: "minecraft:gravel"},
        {pos: [2, 4, 15], state: "minecraft:mud_bricks"},
        {pos: [2, 4, 16], state: "minecraft:gravel"},
        {pos: [3, 4, 8], state: "minecraft:gravel"},
        {pos: [3, 4, 9], state: "minecraft:mud_bricks"},
        {pos: [3, 4, 10], state: "minecraft:mud_bricks"},
        {pos: [3, 4, 11], state: "minecraft:gravel"},
        {pos: [3, 4, 12], state: "minecraft:gravel"},
        {pos: [3, 4, 13], state: "minecraft:gravel"},
        {pos: [3, 4, 14], state: "minecraft:mud_bricks"},
        {pos: [3, 4, 15], state: "minecraft:mud_bricks"},
        {pos: [3, 4, 16], state: "minecraft:gravel"},
        {pos: [4, 4, 7], state: "minecraft:gravel"},
        {pos: [4, 4, 8], state: "minecraft:gravel"},
        {pos: [4, 4, 9], state: "minecraft:mud_bricks"},
        {pos: [4, 4, 10], state: "minecraft:mud_bricks"},
        {pos: [4, 4, 11], state: "minecraft:gravel"},
        {pos: [4, 4, 12], state: "minecraft:gravel"},
        {pos: [4, 4, 13], state: "minecraft:gravel"},
        {pos: [4, 4, 14], state: "minecraft:mud_bricks"},
        {pos: [4, 4, 15], state: "minecraft:mud_bricks"},
        {pos: [5, 4, 7], state: "minecraft:gravel"},
        {pos: [5, 4, 8], state: "minecraft:gravel"},
        {pos: [5, 4, 9], state: "minecraft:gravel"},
        {pos: [5, 4, 10], state: "minecraft:mud_bricks"},
        {pos: [5, 4, 11], state: "minecraft:gravel"},
        {pos: [5, 4, 12], state: "minecraft:gravel"},
        {pos: [5, 4, 13], state: "minecraft:gravel"},
        {pos: [5, 4, 14], state: "minecraft:gravel"},
        {pos: [5, 4, 15], state: "minecraft:gravel"},
        {pos: [5, 4, 16], state: "minecraft:gravel"},
        {pos: [5, 4, 17], state: "minecraft:gravel"},
        {pos: [6, 4, 1], state: "minecraft:mud_bricks"},
        {pos: [6, 4, 2], state: "minecraft:mud_bricks"},
        {pos: [6, 4, 3], state: "minecraft:mud_bricks"},
        {pos: [6, 4, 4], state: "minecraft:gravel"},
        {pos: [6, 4, 5], state: "minecraft:gravel"},
        {pos: [6, 4, 6], state: "minecraft:gravel"},
        {pos: [6, 4, 7], state: "minecraft:gravel"},
        {pos: [6, 4, 8], state: "minecraft:gravel"},
        {pos: [6, 4, 9], state: "minecraft:gravel"},
        {pos: [6, 4, 10], state: "minecraft:gravel"},
        {pos: [6, 4, 11], state: "minecraft:gravel"},
        {pos: [6, 4, 12], state: "minecraft:gravel"},
        {pos: [6, 4, 13], state: "minecraft:gravel"},
        {pos: [6, 4, 14], state: "minecraft:gravel"},
        {pos: [6, 4, 15], state: "minecraft:gravel"},
        {pos: [6, 4, 16], state: "minecraft:gravel"},
        {pos: [6, 4, 17], state: "minecraft:gravel"},
        {pos: [6, 4, 18], state: "minecraft:gravel"},
        {pos: [7, 4, 0], state: "minecraft:gravel"},
        {pos: [7, 4, 1], state: "minecraft:mud_bricks"},
        {pos: [7, 4, 2], state: "minecraft:gravel"},
        {pos: [7, 4, 3], state: "minecraft:mud_bricks"},
        {pos: [7, 4, 4], state: "minecraft:gravel"},
        {pos: [7, 4, 5], state: "minecraft:gravel"},
        {pos: [7, 4, 6], state: "minecraft:gravel"},
        {pos: [7, 4, 7], state: "minecraft:gravel"},
        {pos: [7, 4, 8], state: "minecraft:gravel"},
        {pos: [7, 4, 9], state: "minecraft:gravel"},
        {pos: [7, 4, 10], state: "minecraft:gravel"},
        {pos: [7, 4, 11], state: "minecraft:gravel"},
        {pos: [7, 4, 12], state: "minecraft:gravel"},
        {pos: [7, 4, 13], state: "minecraft:gravel"},
        {pos: [7, 4, 14], state: "minecraft:gravel"},
        {pos: [7, 4, 15], state: "minecraft:gravel"},
        {pos: [7, 4, 16], state: "minecraft:gravel"},
        {pos: [7, 4, 17], state: "minecraft:gravel"},
        {pos: [7, 4, 18], state: "minecraft:gravel"},
        {pos: [8, 4, 0], state: "minecraft:gravel"},
        {pos: [8, 4, 1], state: "minecraft:mud_bricks"},
        {pos: [8, 4, 2], state: "minecraft:mud_bricks"},
        {pos: [8, 4, 3], state: "minecraft:mud_bricks"},
        {pos: [8, 4, 7], state: "minecraft:gravel"},
        {pos: [8, 4, 8], state: "minecraft:gravel"},
        {pos: [8, 4, 9], state: "minecraft:gravel"},
        {pos: [8, 4, 10], state: "minecraft:gravel"},
        {pos: [8, 4, 11], state: "minecraft:gravel"},
        {pos: [8, 4, 12], state: "minecraft:gravel"},
        {pos: [8, 4, 13], state: "minecraft:gravel"},
        {pos: [8, 4, 14], state: "minecraft:gravel"},
        {pos: [8, 4, 15], state: "minecraft:gravel"},
        {pos: [8, 4, 16], state: "minecraft:gravel"},
        {pos: [8, 4, 17], state: "minecraft:gravel"},
        {pos: [9, 4, 0], state: "minecraft:gravel"},
        {pos: [9, 4, 1], state: "minecraft:gravel"},
        {pos: [9, 4, 8], state: "minecraft:gravel"},
        {pos: [9, 4, 9], state: "minecraft:gravel"},
        {pos: [9, 4, 10], state: "minecraft:gravel"},
        {pos: [9, 4, 11], state: "minecraft:gravel"},
        {pos: [9, 4, 12], state: "minecraft:gravel"},
        {pos: [9, 4, 13], state: "minecraft:gravel"},
        {pos: [9, 4, 14], state: "minecraft:gravel"},
        {pos: [9, 4, 15], state: "minecraft:gravel"},
        {pos: [9, 4, 16], state: "minecraft:gravel"},
        {pos: [9, 4, 17], state: "minecraft:gravel"},
        {pos: [10, 4, 9], state: "minecraft:gravel"},
        {pos: [10, 4, 10], state: "minecraft:mud_bricks"},
        {pos: [10, 4, 11], state: "minecraft:gravel"},
        {pos: [10, 4, 12], state: "minecraft:gravel"},
        {pos: [10, 4, 13], state: "minecraft:gravel"},
        {pos: [10, 4, 14], state: "minecraft:mud_bricks"},
        {pos: [10, 4, 15], state: "minecraft:mud_bricks"},
        {pos: [10, 4, 17], state: "minecraft:gravel"},
        {pos: [11, 4, 8], state: "minecraft:gravel"},
        {pos: [11, 4, 9], state: "minecraft:mud_bricks"},
        {pos: [11, 4, 10], state: "minecraft:mud_bricks"},
        {pos: [11, 4, 11], state: "minecraft:gravel"},
        {pos: [11, 4, 12], state: "minecraft:gravel"},
        {pos: [11, 4, 13], state: "minecraft:gravel"},
        {pos: [11, 4, 14], state: "minecraft:mud_bricks"},
        {pos: [11, 4, 15], state: "minecraft:mud_bricks"},
        {pos: [11, 4, 16], state: "minecraft:gravel"},
        {pos: [11, 4, 17], state: "minecraft:gravel"},
        {pos: [12, 4, 9], state: "minecraft:gravel"},
        {pos: [12, 4, 10], state: "minecraft:gravel"},
        {pos: [12, 4, 11], state: "minecraft:gravel"},
        {pos: [12, 4, 13], state: "minecraft:gravel"},
        {pos: [12, 4, 14], state: "minecraft:mud_bricks"},
        {pos: [12, 4, 15], state: "minecraft:mud_bricks"},
        {pos: [12, 4, 16], state: "minecraft:gravel"},
        {pos: [13, 4, 14], state: "minecraft:gravel"},
        {pos: [13, 4, 15], state: "minecraft:gravel"},
        {pos: [2, 5, 8], state: "minecraft:gravel"},
        {pos: [2, 5, 9], state: "minecraft:mud_bricks"},
        {pos: [2, 5, 10], state: "minecraft:mud_bricks"},
        {pos: [2, 5, 14], state: "minecraft:gravel"},
        {pos: [2, 5, 15], state: "minecraft:gravel"},
        {pos: [3, 5, 8], state: "minecraft:gravel"},
        {pos: [3, 5, 9], state: "minecraft:mud_bricks"},
        {pos: [3, 5, 10], state: "minecraft:mud_bricks"},
        {pos: [3, 5, 11], state: "minecraft:gravel"},
        {pos: [3, 5, 12], state: "minecraft:gravel"},
        {pos: [3, 5, 13], state: "minecraft:gravel"},
        {pos: [3, 5, 14], state: "minecraft:mud_bricks"},
        {pos: [3, 5, 15], state: "minecraft:mud_bricks"},
        {pos: [4, 5, 8], state: "minecraft:gravel"},
        {pos: [4, 5, 9], state: "minecraft:mud_bricks"},
        {pos: [4, 5, 10], state: "minecraft:mud_bricks"},
        {pos: [4, 5, 11], state: "minecraft:gravel"},
        {pos: [4, 5, 12], state: "minecraft:gravel"},
        {pos: [4, 5, 13], state: "minecraft:gravel"},
        {pos: [4, 5, 14], state: "minecraft:mud_bricks"},
        {pos: [4, 5, 15], state: "minecraft:mud_bricks"},
        {pos: [5, 5, 7], state: "minecraft:gravel"},
        {pos: [5, 5, 8], state: "minecraft:gravel"},
        {pos: [5, 5, 9], state: "minecraft:mud_bricks"},
        {pos: [5, 5, 10], state: "minecraft:mud_bricks"},
        {pos: [5, 5, 11], state: "minecraft:gravel"},
        {pos: [5, 5, 12], state: "minecraft:gravel"},
        {pos: [5, 5, 13], state: "minecraft:gravel"},
        {pos: [5, 5, 14], state: "minecraft:mud_bricks"},
        {pos: [5, 5, 15], state: "minecraft:mud_bricks"},
        {pos: [5, 5, 16], state: "minecraft:gravel"},
        {pos: [6, 5, 1], state: "minecraft:mud_bricks"},
        {pos: [6, 5, 2], state: "minecraft:mud_bricks"},
        {pos: [6, 5, 3], state: "minecraft:mud_bricks"},
        {pos: [6, 5, 4], state: "minecraft:gravel"},
        {pos: [6, 5, 5], state: "minecraft:gravel"},
        {pos: [6, 5, 7], state: "minecraft:gravel"},
        {pos: [6, 5, 8], state: "minecraft:gravel"},
        {pos: [6, 5, 9], state: "minecraft:mud_bricks"},
        {pos: [6, 5, 10], state: "minecraft:mud_bricks"},
        {pos: [6, 5, 11], state: "minecraft:gravel"},
        {pos: [6, 5, 12], state: "minecraft:gravel"},
        {pos: [6, 5, 13], state: "minecraft:gravel"},
        {pos: [6, 5, 14], state: "minecraft:gravel"},
        {pos: [6, 5, 15], state: "minecraft:mud_bricks"},
        {pos: [6, 5, 16], state: "minecraft:gravel"},
        {pos: [6, 5, 17], state: "minecraft:gravel"},
        {pos: [7, 5, 0], state: "minecraft:gravel"},
        {pos: [7, 5, 1], state: "minecraft:mud_bricks"},
        {pos: [7, 5, 2], state: "minecraft:gravel"},
        {pos: [7, 5, 3], state: "minecraft:mud_bricks"},
        {pos: [7, 5, 4], state: "minecraft:gravel"},
        {pos: [7, 5, 6], state: "minecraft:gravel"},
        {pos: [7, 5, 7], state: "minecraft:gravel"},
        {pos: [7, 5, 8], state: "minecraft:gravel"},
        {pos: [7, 5, 9], state: "minecraft:gravel"},
        {pos: [7, 5, 10], state: "minecraft:gravel"},
        {pos: [7, 5, 11], state: "minecraft:gravel"},
        {pos: [7, 5, 12], state: "minecraft:gravel"},
        {pos: [7, 5, 13], state: "minecraft:gravel"},
        {pos: [7, 5, 14], state: "minecraft:gravel"},
        {pos: [7, 5, 15], state: "minecraft:gravel"},
        {pos: [7, 5, 16], state: "minecraft:gravel"},
        {pos: [7, 5, 17], state: "minecraft:gravel"},
        {pos: [7, 5, 18], state: "minecraft:gravel"},
        {pos: [8, 5, 0], state: "minecraft:gravel"},
        {pos: [8, 5, 1], state: "minecraft:mud_bricks"},
        {pos: [8, 5, 2], state: "minecraft:mud_bricks"},
        {pos: [8, 5, 3], state: "minecraft:mud_bricks"},
        {pos: [8, 5, 8], state: "minecraft:gravel"},
        {pos: [8, 5, 9], state: "minecraft:gravel"},
        {pos: [8, 5, 10], state: "minecraft:gravel"},
        {pos: [8, 5, 11], state: "minecraft:gravel"},
        {pos: [8, 5, 12], state: "minecraft:gravel"},
        {pos: [8, 5, 13], state: "minecraft:gravel"},
        {pos: [8, 5, 14], state: "minecraft:gravel"},
        {pos: [8, 5, 15], state: "minecraft:gravel"},
        {pos: [8, 5, 16], state: "minecraft:gravel"},
        {pos: [8, 5, 17], state: "minecraft:gravel"},
        {pos: [9, 5, 0], state: "minecraft:gravel"},
        {pos: [9, 5, 9], state: "minecraft:gravel"},
        {pos: [9, 5, 10], state: "minecraft:gravel"},
        {pos: [9, 5, 11], state: "minecraft:gravel"},
        {pos: [9, 5, 12], state: "minecraft:gravel"},
        {pos: [9, 5, 13], state: "minecraft:gravel"},
        {pos: [9, 5, 14], state: "minecraft:mud_bricks"},
        {pos: [9, 5, 15], state: "minecraft:mud_bricks"},
        {pos: [9, 5, 16], state: "minecraft:gravel"},
        {pos: [9, 5, 17], state: "minecraft:gravel"},
        {pos: [10, 5, 9], state: "minecraft:mud_bricks"},
        {pos: [10, 5, 10], state: "minecraft:mud_bricks"},
        {pos: [10, 5, 11], state: "minecraft:gravel"},
        {pos: [10, 5, 12], state: "minecraft:gravel"},
        {pos: [10, 5, 13], state: "minecraft:gravel"},
        {pos: [10, 5, 14], state: "minecraft:mud_bricks"},
        {pos: [10, 5, 15], state: "minecraft:mud_bricks"},
        {pos: [10, 5, 17], state: "minecraft:gravel"},
        {pos: [11, 5, 8], state: "minecraft:gravel"},
        {pos: [11, 5, 9], state: "minecraft:mud_bricks"},
        {pos: [11, 5, 10], state: "minecraft:mud_bricks"},
        {pos: [11, 5, 11], state: "minecraft:gravel"},
        {pos: [11, 5, 13], state: "minecraft:gravel"},
        {pos: [11, 5, 14], state: "minecraft:mud_bricks"},
        {pos: [11, 5, 15], state: "minecraft:mud_bricks"},
        {pos: [11, 5, 16], state: "minecraft:gravel"},
        {pos: [11, 5, 17], state: "minecraft:gravel"},
        {pos: [12, 5, 9], state: "minecraft:gravel"},
        {pos: [12, 5, 10], state: "minecraft:gravel"},
        {pos: [12, 5, 13], state: "minecraft:gravel"},
        {pos: [12, 5, 14], state: "minecraft:gravel"},
        {pos: [12, 5, 15], state: "minecraft:gravel"},
        {pos: [12, 5, 16], state: "minecraft:gravel"},
        {pos: [13, 5, 14], state: "minecraft:gravel"},
        {pos: [3, 6, 9], state: "minecraft:gravel"},
        {pos: [3, 6, 10], state: "minecraft:mud_bricks"},
        {pos: [3, 6, 14], state: "minecraft:gravel"},
        {pos: [3, 6, 15], state: "minecraft:gravel"},
        {pos: [4, 6, 8], state: "minecraft:gravel"},
        {pos: [4, 6, 9], state: "minecraft:mud_bricks"},
        {pos: [4, 6, 10], state: "minecraft:mud_bricks"},
        {pos: [4, 6, 11], state: "minecraft:gravel"},
        {pos: [4, 6, 12], state: "minecraft:gravel"},
        {pos: [4, 6, 13], state: "minecraft:gravel"},
        {pos: [4, 6, 14], state: "minecraft:mud_bricks"},
        {pos: [4, 6, 15], state: "minecraft:mud_bricks"},
        {pos: [5, 6, 8], state: "minecraft:gravel"},
        {pos: [5, 6, 9], state: "minecraft:mud_bricks"},
        {pos: [5, 6, 10], state: "minecraft:mud_bricks"},
        {pos: [5, 6, 11], state: "minecraft:gravel"},
        {pos: [5, 6, 12], state: "minecraft:gravel"},
        {pos: [5, 6, 13], state: "minecraft:gravel"},
        {pos: [5, 6, 14], state: "minecraft:mud_bricks"},
        {pos: [5, 6, 15], state: "minecraft:mud_bricks"},
        {pos: [6, 6, 1], state: "minecraft:mud_bricks"},
        {pos: [6, 6, 2], state: "minecraft:mud_bricks"},
        {pos: [6, 6, 3], state: "minecraft:mud_bricks"},
        {pos: [6, 6, 4], state: "minecraft:gravel"},
        {pos: [6, 6, 8], state: "minecraft:gravel"},
        {pos: [6, 6, 9], state: "minecraft:mud_bricks"},
        {pos: [6, 6, 10], state: "minecraft:mud_bricks"},
        {pos: [6, 6, 11], state: "minecraft:gravel"},
        {pos: [6, 6, 12], state: "minecraft:gravel"},
        {pos: [6, 6, 13], state: "minecraft:gravel"},
        {pos: [6, 6, 14], state: "minecraft:mud_bricks"},
        {pos: [6, 6, 15], state: "minecraft:mud_bricks"},
        {pos: [6, 6, 16], state: "minecraft:gravel"},
        {pos: [7, 6, 0], state: "minecraft:gravel"},
        {pos: [7, 6, 1], state: "minecraft:mud_bricks"},
        {pos: [7, 6, 2], state: "minecraft:gravel"},
        {pos: [7, 6, 3], state: "minecraft:mud_bricks"},
        {pos: [7, 6, 4], state: "minecraft:gravel"},
        {pos: [7, 6, 9], state: "minecraft:mud_bricks"},
        {pos: [7, 6, 10], state: "minecraft:mud_bricks"},
        {pos: [7, 6, 11], state: "minecraft:gravel"},
        {pos: [7, 6, 12], state: "minecraft:gravel"},
        {pos: [7, 6, 13], state: "minecraft:gravel"},
        {pos: [7, 6, 14], state: "minecraft:gravel"},
        {pos: [7, 6, 15], state: "minecraft:gravel"},
        {pos: [7, 6, 16], state: "minecraft:gravel"},
        {pos: [8, 6, 1], state: "minecraft:mud_bricks"},
        {pos: [8, 6, 2], state: "minecraft:mud_bricks"},
        {pos: [8, 6, 3], state: "minecraft:mud_bricks"},
        {pos: [8, 6, 10], state: "minecraft:gravel"},
        {pos: [8, 6, 11], state: "minecraft:gravel"},
        {pos: [8, 6, 12], state: "minecraft:gravel"},
        {pos: [8, 6, 13], state: "minecraft:gravel"},
        {pos: [8, 6, 14], state: "minecraft:gravel"},
        {pos: [8, 6, 15], state: "minecraft:gravel"},
        {pos: [8, 6, 16], state: "minecraft:gravel"},
        {pos: [9, 6, 10], state: "minecraft:gravel"},
        {pos: [9, 6, 11], state: "minecraft:gravel"},
        {pos: [9, 6, 12], state: "minecraft:gravel"},
        {pos: [9, 6, 13], state: "minecraft:gravel"},
        {pos: [9, 6, 14], state: "minecraft:mud_bricks"},
        {pos: [9, 6, 15], state: "minecraft:mud_bricks"},
        {pos: [9, 6, 16], state: "minecraft:gravel"},
        {pos: [10, 6, 9], state: "minecraft:mud_bricks"},
        {pos: [10, 6, 10], state: "minecraft:mud_bricks"},
        {pos: [10, 6, 11], state: "minecraft:gravel"},
        {pos: [10, 6, 14], state: "minecraft:mud_bricks"},
        {pos: [10, 6, 15], state: "minecraft:mud_bricks"},
        {pos: [11, 6, 9], state: "minecraft:gravel"},
        {pos: [11, 6, 10], state: "minecraft:gravel"},
        {pos: [11, 6, 13], state: "minecraft:gravel"},
        {pos: [11, 6, 14], state: "minecraft:gravel"},
        {pos: [11, 6, 15], state: "minecraft:mud_bricks"},
        {pos: [11, 6, 16], state: "minecraft:gravel"},
        {pos: [12, 6, 14], state: "minecraft:gravel"},
        {pos: [4, 7, 9], state: "minecraft:gravel"},
        {pos: [5, 7, 9], state: "minecraft:mud_bricks"},
        {pos: [5, 7, 10], state: "minecraft:gravel"},
        {pos: [5, 7, 14], state: "minecraft:mud_bricks"},
        {pos: [5, 7, 15], state: "minecraft:mud_bricks"},
        {pos: [6, 7, 1], state: "minecraft:mud_bricks"},
        {pos: [6, 7, 2], state: "minecraft:mud_bricks"},
        {pos: [6, 7, 3], state: "minecraft:mud_bricks"},
        {pos: [6, 7, 9], state: "minecraft:mud_bricks"},
        {pos: [6, 7, 10], state: "minecraft:mud_bricks"},
        {pos: [6, 7, 14], state: "minecraft:mud_bricks"},
        {pos: [6, 7, 15], state: "minecraft:mud_bricks"},
        {pos: [7, 7, 1], state: "minecraft:mud_bricks"},
        {pos: [7, 7, 3], state: "minecraft:mud_bricks"},
        {pos: [7, 7, 9], state: "minecraft:mud_bricks"},
        {pos: [7, 7, 10], state: "minecraft:mud_bricks"},
        {pos: [7, 7, 14], state: "minecraft:mud_bricks"},
        {pos: [7, 7, 15], state: "minecraft:mud_bricks"},
        {pos: [8, 7, 3], state: "minecraft:mud_bricks"},
        {pos: [8, 7, 9], state: "minecraft:mud_bricks"},
        {pos: [9, 7, 15], state: "minecraft:mud_bricks"},
        {pos: [10, 7, 14], state: "minecraft:mud_bricks"},
        {pos: [10, 7, 15], state: "minecraft:gravel"}
    ],
    entities: [],
    palette: [
        "minecraft:mud_bricks",
        "minecraft:yellow_glazed_terracotta{facing:west}",
        "minecraft:yellow_glazed_terracotta{facing:north}",
        "minecraft:yellow_glazed_terracotta{facing:south}",
        "minecraft:gravel",
        "minecraft:orange_glazed_terracotta{facing:north}",
        "minecraft:orange_glazed_terracotta{facing:east}",
        "minecraft:mud_brick_stairs{facing:west,half:top,shape:straight,waterlogged:false}",
        "minecraft:mud_brick_stairs{facing:east,half:top,shape:straight,waterlogged:false}",
        "minecraft:mud_brick_stairs{facing:north,half:top,shape:straight,waterlogged:false}",
        "minecraft:mud_brick_stairs{facing:south,half:bottom,shape:straight,waterlogged:false}"
    ],
    trailiertales_DataVersion: 2
}
