{
    DataVersion: 3953,
    size: [21, 7, 16],
    data: [
        {pos: [0, 0, 7], state: "minecraft:mud_bricks"},
        {pos: [0, 0, 8], state: "minecraft:mud_bricks"},
        {pos: [0, 0, 9], state: "minecraft:mud_bricks"},
        {pos: [0, 0, 10], state: "minecraft:mud_bricks"},
        {pos: [0, 0, 11], state: "minecraft:mud_bricks"},
        {pos: [0, 0, 12], state: "minecraft:mud_bricks"},
        {pos: [0, 0, 13], state: "minecraft:mud_bricks"},
        {pos: [1, 0, 6], state: "minecraft:mud_bricks"},
        {pos: [1, 0, 7], state: "minecraft:mud_bricks"},
        {pos: [1, 0, 8], state: "minecraft:mud_bricks"},
        {pos: [1, 0, 9], state: "minecraft:mud_bricks"},
        {pos: [1, 0, 10], state: "minecraft:mud_bricks"},
        {pos: [1, 0, 11], state: "minecraft:mud_bricks"},
        {pos: [1, 0, 12], state: "minecraft:mud_bricks"},
        {pos: [1, 0, 13], state: "minecraft:mud_bricks"},
        {pos: [1, 0, 14], state: "minecraft:mud_bricks"},
        {pos: [2, 0, 6], state: "minecraft:mud_bricks"},
        {pos: [2, 0, 7], state: "minecraft:mud_bricks"},
        {pos: [2, 0, 8], state: "minecraft:mud_bricks"},
        {pos: [2, 0, 9], state: "minecraft:mud_bricks"},
        {pos: [2, 0, 10], state: "minecraft:mud_bricks"},
        {pos: [2, 0, 11], state: "minecraft:mud_bricks"},
        {pos: [2, 0, 12], state: "minecraft:mud_bricks"},
        {pos: [2, 0, 13], state: "minecraft:mud_bricks"},
        {pos: [2, 0, 14], state: "minecraft:mud_bricks"},
        {pos: [3, 0, 7], state: "minecraft:mud_bricks"},
        {pos: [3, 0, 8], state: "minecraft:mud_bricks"},
        {pos: [3, 0, 9], state: "minecraft:mud_bricks"},
        {pos: [3, 0, 10], state: "minecraft:mud_bricks"},
        {pos: [3, 0, 11], state: "minecraft:mud_bricks"},
        {pos: [3, 0, 12], state: "minecraft:mud_bricks"},
        {pos: [3, 0, 13], state: "minecraft:mud_bricks"},
        {pos: [3, 0, 14], state: "minecraft:mud_bricks"},
        {pos: [3, 0, 15], state: "minecraft:mud_bricks"},
        {pos: [4, 0, 7], state: "minecraft:mud_bricks"},
        {pos: [4, 0, 8], state: "minecraft:mud_bricks"},
        {pos: [4, 0, 9], state: "minecraft:mud_bricks"},
        {pos: [4, 0, 10], state: "minecraft:mud_bricks"},
        {pos: [4, 0, 11], state: "minecraft:mud_bricks"},
        {pos: [4, 0, 12], state: "minecraft:mud_bricks"},
        {pos: [4, 0, 13], state: "minecraft:mud_bricks"},
        {pos: [4, 0, 14], state: "minecraft:mud_bricks"},
        {pos: [4, 0, 15], state: "minecraft:mud_bricks"},
        {pos: [5, 0, 7], state: "minecraft:mud_bricks"},
        {pos: [5, 0, 8], state: "minecraft:mud_bricks"},
        {pos: [5, 0, 9], state: "minecraft:mud_bricks"},
        {pos: [5, 0, 10], state: "minecraft:mud_bricks"},
        {pos: [5, 0, 11], state: "minecraft:mud_bricks"},
        {pos: [5, 0, 12], state: "minecraft:mud_bricks"},
        {pos: [5, 0, 13], state: "minecraft:mud_bricks"},
        {pos: [5, 0, 14], state: "minecraft:mud_bricks"},
        {pos: [6, 0, 6], state: "minecraft:mud_bricks"},
        {pos: [6, 0, 7], state: "minecraft:mud_bricks"},
        {pos: [6, 0, 8], state: "minecraft:mud_bricks"},
        {pos: [6, 0, 9], state: "minecraft:mud_bricks"},
        {pos: [6, 0, 10], state: "minecraft:mud_bricks"},
        {pos: [6, 0, 11], state: "minecraft:mud_bricks"},
        {pos: [6, 0, 12], state: "minecraft:mud_bricks"},
        {pos: [6, 0, 13], state: "minecraft:mud_bricks"},
        {pos: [6, 0, 14], state: "minecraft:mud_bricks"},
        {pos: [6, 0, 15], state: "minecraft:mud_bricks"},
        {pos: [7, 0, 6], state: "minecraft:mud_bricks"},
        {pos: [7, 0, 7], state: "minecraft:mud_bricks"},
        {pos: [7, 0, 8], state: "minecraft:mud_bricks"},
        {pos: [7, 0, 9], state: "minecraft:mud_bricks"},
        {pos: [7, 0, 10], state: "minecraft:mud_bricks"},
        {pos: [7, 0, 11], state: "minecraft:mud_bricks"},
        {pos: [7, 0, 12], state: "minecraft:mud_bricks"},
        {pos: [7, 0, 13], state: "minecraft:mud_bricks"},
        {pos: [7, 0, 14], state: "minecraft:mud_bricks"},
        {pos: [7, 0, 15], state: "minecraft:mud_bricks"},
        {pos: [8, 0, 5], state: "minecraft:mud_bricks"},
        {pos: [8, 0, 6], state: "minecraft:mud_bricks"},
        {pos: [8, 0, 7], state: "minecraft:mud_bricks"},
        {pos: [8, 0, 8], state: "minecraft:mud_bricks"},
        {pos: [8, 0, 9], state: "minecraft:mud_bricks"},
        {pos: [8, 0, 10], state: "minecraft:mud_bricks"},
        {pos: [8, 0, 11], state: "minecraft:mud_bricks"},
        {pos: [8, 0, 12], state: "minecraft:mud_bricks"},
        {pos: [8, 0, 13], state: "minecraft:mud_bricks"},
        {pos: [8, 0, 14], state: "minecraft:mud_bricks"},
        {pos: [8, 0, 15], state: "minecraft:mud_bricks"},
        {pos: [9, 0, 3], state: "minecraft:mud_bricks"},
        {pos: [9, 0, 4], state: "minecraft:mud_bricks"},
        {pos: [9, 0, 5], state: "minecraft:mud_bricks"},
        {pos: [9, 0, 6], state: "minecraft:mud_bricks"},
        {pos: [9, 0, 7], state: "minecraft:mud_bricks"},
        {pos: [9, 0, 8], state: "minecraft:mud_bricks"},
        {pos: [9, 0, 9], state: "minecraft:mud_bricks"},
        {pos: [9, 0, 10], state: "minecraft:mud_bricks"},
        {pos: [9, 0, 11], state: "minecraft:mud_bricks"},
        {pos: [9, 0, 12], state: "minecraft:mud_bricks"},
        {pos: [9, 0, 13], state: "minecraft:mud_bricks"},
        {pos: [9, 0, 14], state: "minecraft:mud_bricks"},
        {pos: [9, 0, 15], state: "minecraft:mud_bricks"},
        {pos: [10, 0, 1], state: "minecraft:mud_bricks"},
        {pos: [10, 0, 2], state: "minecraft:mud_bricks"},
        {pos: [10, 0, 3], state: "minecraft:mud_bricks"},
        {pos: [10, 0, 4], state: "minecraft:mud_bricks"},
        {pos: [10, 0, 5], state: "minecraft:mud_bricks"},
        {pos: [10, 0, 6], state: "minecraft:mud_bricks"},
        {pos: [10, 0, 7], state: "minecraft:mud_bricks"},
        {pos: [10, 0, 8], state: "minecraft:mud_bricks"},
        {pos: [10, 0, 9], state: "minecraft:mud_bricks"},
        {pos: [10, 0, 10], state: "minecraft:mud_bricks"},
        {pos: [10, 0, 11], state: "minecraft:mud_bricks"},
        {pos: [10, 0, 12], state: "minecraft:mud_bricks"},
        {pos: [10, 0, 13], state: "minecraft:mud_bricks"},
        {pos: [10, 0, 14], state: "minecraft:mud_bricks"},
        {pos: [10, 0, 15], state: "minecraft:mud_bricks"},
        {pos: [11, 0, 1], state: "minecraft:mud_bricks"},
        {pos: [11, 0, 2], state: "minecraft:mud_bricks"},
        {pos: [11, 0, 3], state: "minecraft:mud_bricks"},
        {pos: [11, 0, 4], state: "minecraft:mud_bricks"},
        {pos: [11, 0, 5], state: "minecraft:mud_bricks"},
        {pos: [11, 0, 6], state: "minecraft:mud_bricks"},
        {pos: [11, 0, 7], state: "minecraft:mud_bricks"},
        {pos: [11, 0, 8], state: "minecraft:mud_bricks"},
        {pos: [11, 0, 9], state: "minecraft:mud_bricks"},
        {pos: [11, 0, 10], state: "minecraft:mud_bricks"},
        {pos: [11, 0, 11], state: "minecraft:mud_bricks"},
        {pos: [11, 0, 12], state: "minecraft:mud_bricks"},
        {pos: [11, 0, 13], state: "minecraft:mud_bricks"},
        {pos: [11, 0, 14], state: "minecraft:mud_bricks"},
        {pos: [11, 0, 15], state: "minecraft:mud_bricks"},
        {pos: [12, 0, 0], state: "minecraft:mud_bricks"},
        {pos: [12, 0, 1], state: "minecraft:mud_bricks"},
        {pos: [12, 0, 2], state: "minecraft:mud_bricks"},
        {pos: [12, 0, 3], state: "minecraft:mud_bricks"},
        {pos: [12, 0, 4], state: "minecraft:mud_bricks"},
        {pos: [12, 0, 5], state: "minecraft:mud_bricks"},
        {pos: [12, 0, 6], state: "minecraft:mud_bricks"},
        {pos: [12, 0, 7], state: "minecraft:mud_bricks"},
        {pos: [12, 0, 8], state: "minecraft:mud_bricks"},
        {pos: [12, 0, 9], state: "minecraft:mud_bricks"},
        {pos: [12, 0, 10], state: "minecraft:mud_bricks"},
        {pos: [12, 0, 11], state: "minecraft:mud_bricks"},
        {pos: [12, 0, 12], state: "minecraft:mud_bricks"},
        {pos: [12, 0, 13], state: "minecraft:mud_bricks"},
        {pos: [12, 0, 14], state: "minecraft:mud_bricks"},
        {pos: [12, 0, 15], state: "minecraft:mud_bricks"},
        {pos: [13, 0, 0], state: "minecraft:mud_bricks"},
        {pos: [13, 0, 1], state: "minecraft:mud_bricks"},
        {pos: [13, 0, 2], state: "minecraft:mud_bricks"},
        {pos: [13, 0, 3], state: "minecraft:mud_bricks"},
        {pos: [13, 0, 4], state: "minecraft:mud_bricks"},
        {pos: [13, 0, 5], state: "minecraft:mud_bricks"},
        {pos: [13, 0, 6], state: "minecraft:mud_bricks"},
        {pos: [13, 0, 7], state: "minecraft:mud_bricks"},
        {pos: [13, 0, 8], state: "minecraft:mud_bricks"},
        {pos: [13, 0, 9], state: "minecraft:mud_bricks"},
        {pos: [13, 0, 10], state: "minecraft:mud_bricks"},
        {pos: [13, 0, 11], state: "minecraft:mud_bricks"},
        {pos: [13, 0, 12], state: "minecraft:mud_bricks"},
        {pos: [13, 0, 13], state: "minecraft:mud_bricks"},
        {pos: [13, 0, 14], state: "minecraft:mud_bricks"},
        {pos: [14, 0, 0], state: "minecraft:mud_bricks"},
        {pos: [14, 0, 1], state: "minecraft:mud_bricks"},
        {pos: [14, 0, 2], state: "minecraft:mud_bricks"},
        {pos: [14, 0, 3], state: "minecraft:mud_bricks"},
        {pos: [14, 0, 4], state: "minecraft:mud_bricks"},
        {pos: [14, 0, 5], state: "minecraft:mud_bricks"},
        {pos: [14, 0, 6], state: "minecraft:yellow_glazed_terracotta{facing:north}"},
        {pos: [14, 0, 7], state: "minecraft:yellow_glazed_terracotta{facing:west}"},
        {pos: [14, 0, 8], state: "minecraft:mud_bricks"},
        {pos: [14, 0, 9], state: "minecraft:mud_bricks"},
        {pos: [14, 0, 10], state: "minecraft:mud_bricks"},
        {pos: [14, 0, 11], state: "minecraft:mud_bricks"},
        {pos: [14, 0, 12], state: "minecraft:mud_bricks"},
        {pos: [14, 0, 13], state: "minecraft:mud_bricks"},
        {pos: [14, 0, 14], state: "minecraft:mud_bricks"},
        {pos: [15, 0, 0], state: "minecraft:mud_bricks"},
        {pos: [15, 0, 1], state: "minecraft:mud_bricks"},
        {pos: [15, 0, 2], state: "minecraft:mud_bricks"},
        {pos: [15, 0, 3], state: "minecraft:mud_bricks"},
        {pos: [15, 0, 4], state: "minecraft:mud_bricks"},
        {pos: [15, 0, 5], state: "minecraft:mud_bricks"},
        {pos: [15, 0, 6], state: "minecraft:yellow_glazed_terracotta{facing:east}"},
        {pos: [15, 0, 7], state: "minecraft:yellow_glazed_terracotta{facing:south}"},
        {pos: [15, 0, 8], state: "minecraft:mud_bricks"},
        {pos: [15, 0, 9], state: "minecraft:mud_bricks"},
        {pos: [15, 0, 10], state: "minecraft:mud_bricks"},
        {pos: [15, 0, 11], state: "minecraft:mud_bricks"},
        {pos: [15, 0, 12], state: "minecraft:mud_bricks"},
        {pos: [15, 0, 13], state: "minecraft:mud_bricks"},
        {pos: [15, 0, 14], state: "minecraft:mud_bricks"},
        {pos: [16, 0, 1], state: "minecraft:mud_bricks"},
        {pos: [16, 0, 2], state: "minecraft:mud_bricks"},
        {pos: [16, 0, 3], state: "minecraft:mud_bricks"},
        {pos: [16, 0, 4], state: "minecraft:mud_bricks"},
        {pos: [16, 0, 5], state: "minecraft:mud_bricks"},
        {pos: [16, 0, 6], state: "minecraft:mud_bricks"},
        {pos: [16, 0, 7], state: "minecraft:mud_bricks"},
        {pos: [16, 0, 8], state: "minecraft:mud_bricks"},
        {pos: [16, 0, 9], state: "minecraft:mud_bricks"},
        {pos: [16, 0, 10], state: "minecraft:mud_bricks"},
        {pos: [16, 0, 11], state: "minecraft:mud_bricks"},
        {pos: [16, 0, 12], state: "minecraft:mud_bricks"},
        {pos: [16, 0, 13], state: "minecraft:mud_bricks"},
        {pos: [16, 0, 14], state: "minecraft:mud_bricks"},
        {pos: [17, 0, 1], state: "minecraft:mud_bricks"},
        {pos: [17, 0, 2], state: "minecraft:mud_bricks"},
        {pos: [17, 0, 3], state: "minecraft:mud_bricks"},
        {pos: [17, 0, 4], state: "minecraft:mud_bricks"},
        {pos: [17, 0, 5], state: "minecraft:mud_bricks"},
        {pos: [17, 0, 6], state: "minecraft:mud_bricks"},
        {pos: [17, 0, 7], state: "minecraft:mud_bricks"},
        {pos: [17, 0, 8], state: "minecraft:mud_bricks"},
        {pos: [17, 0, 9], state: "minecraft:mud_bricks"},
        {pos: [17, 0, 10], state: "minecraft:mud_bricks"},
        {pos: [17, 0, 11], state: "minecraft:mud_bricks"},
        {pos: [17, 0, 12], state: "minecraft:mud_bricks"},
        {pos: [17, 0, 13], state: "minecraft:mud_bricks"},
        {pos: [18, 0, 2], state: "minecraft:mud_bricks"},
        {pos: [18, 0, 3], state: "minecraft:mud_bricks"},
        {pos: [18, 0, 4], state: "minecraft:mud_bricks"},
        {pos: [18, 0, 5], state: "minecraft:mud_bricks"},
        {pos: [18, 0, 6], state: "minecraft:mud_bricks"},
        {pos: [18, 0, 7], state: "minecraft:mud_bricks"},
        {pos: [18, 0, 8], state: "minecraft:mud_bricks"},
        {pos: [18, 0, 9], state: "minecraft:mud_bricks"},
        {pos: [18, 0, 10], state: "minecraft:mud_bricks"},
        {pos: [18, 0, 11], state: "minecraft:mud_bricks"},
        {pos: [18, 0, 12], state: "minecraft:mud_bricks"},
        {pos: [19, 0, 3], state: "minecraft:mud_bricks"},
        {pos: [19, 0, 4], state: "minecraft:mud_bricks"},
        {pos: [19, 0, 5], state: "minecraft:mud_bricks"},
        {pos: [19, 0, 6], state: "minecraft:mud_bricks"},
        {pos: [19, 0, 7], state: "minecraft:mud_bricks"},
        {pos: [19, 0, 8], state: "minecraft:mud_bricks"},
        {pos: [19, 0, 9], state: "minecraft:mud_bricks"},
        {pos: [19, 0, 10], state: "minecraft:mud_bricks"},
        {pos: [20, 0, 6], state: "minecraft:mud_bricks"},
        {pos: [20, 0, 7], state: "minecraft:mud_bricks"},
        {pos: [20, 0, 8], state: "minecraft:mud_bricks"},
        {pos: [20, 0, 9], state: "minecraft:mud_bricks"},
        {pos: [0, 1, 7], state: "minecraft:gravel"},
        {pos: [0, 1, 8], state: "minecraft:gravel"},
        {pos: [0, 1, 9], state: "minecraft:gravel"},
        {pos: [0, 1, 10], state: "minecraft:gravel"},
        {pos: [0, 1, 11], state: "minecraft:gravel"},
        {pos: [0, 1, 12], state: "minecraft:mud_bricks"},
        {pos: [0, 1, 13], state: "minecraft:gravel"},
        {pos: [1, 1, 6], state: "minecraft:gravel"},
        {pos: [1, 1, 7], state: "minecraft:gravel"},
        {pos: [1, 1, 8], state: "minecraft:mud_bricks"},
        {pos: [1, 1, 9], state: "minecraft:mud_bricks"},
        {pos: [1, 1, 10], state: "minecraft:mud_bricks"},
        {pos: [1, 1, 11], state: "minecraft:gravel"},
        {pos: [1, 1, 12], state: "minecraft:mud_bricks"},
        {pos: [1, 1, 13], state: "minecraft:gravel"},
        {pos: [1, 1, 14], state: "minecraft:gravel"},
        {pos: [2, 1, 6], state: "minecraft:gravel"},
        {pos: [2, 1, 7], state: "minecraft:gravel"},
        {pos: [2, 1, 8], state: "minecraft:mud_bricks"},
        {pos: [2, 1, 9], state: "minecraft:mud_bricks"},
        {pos: [2, 1, 10], state: "minecraft:mud_bricks"},
        {pos: [2, 1, 11], state: "minecraft:gravel"},
        {pos: [2, 1, 12], state: "minecraft:mud_bricks"},
        {pos: [2, 1, 13], state: "minecraft:gravel"},
        {pos: [2, 1, 14], state: "minecraft:gravel"},
        {pos: [3, 1, 7], state: "minecraft:gravel"},
        {pos: [3, 1, 8], state: "minecraft:mud_bricks"},
        {pos: [3, 1, 9], state: "minecraft:mud_bricks"},
        {pos: [3, 1, 10], state: "minecraft:mud_bricks"},
        {pos: [3, 1, 11], state: "minecraft:mud_bricks"},
        {pos: [3, 1, 12], state: "minecraft:mud_bricks"},
        {pos: [3, 1, 13], state: "minecraft:mud_bricks"},
        {pos: [3, 1, 14], state: "minecraft:gravel"},
        {pos: [3, 1, 15], state: "minecraft:gravel"},
        {pos: [4, 1, 7], state: "minecraft:gravel"},
        {pos: [4, 1, 8], state: "minecraft:mud_bricks"},
        {pos: [4, 1, 9], state: "minecraft:mud_bricks"},
        {pos: [4, 1, 10], state: "minecraft:mud_bricks"},
        {pos: [4, 1, 11], state: "minecraft:mud_bricks"},
        {pos: [4, 1, 12], state: "minecraft:mud_bricks"},
        {pos: [4, 1, 13], state: "minecraft:mud_bricks"},
        {pos: [4, 1, 14], state: "minecraft:gravel"},
        {pos: [4, 1, 15], state: "minecraft:gravel"},
        {pos: [5, 1, 7], state: "minecraft:gravel"},
        {pos: [5, 1, 8], state: "minecraft:mud_bricks"},
        {pos: [5, 1, 9], state: "minecraft:mud_bricks"},
        {pos: [5, 1, 10], state: "minecraft:mud_bricks"},
        {pos: [5, 1, 11], state: "minecraft:mud_bricks"},
        {pos: [5, 1, 12], state: "minecraft:mud_bricks"},
        {pos: [5, 1, 13], state: "minecraft:mud_bricks"},
        {pos: [5, 1, 14], state: "minecraft:gravel"},
        {pos: [6, 1, 6], state: "minecraft:gravel"},
        {pos: [6, 1, 7], state: "minecraft:gravel"},
        {pos: [6, 1, 8], state: "minecraft:mud_bricks"},
        {pos: [6, 1, 9], state: "minecraft:mud_bricks"},
        {pos: [6, 1, 10], state: "minecraft:mud_bricks"},
        {pos: [6, 1, 11], state: "minecraft:mud_bricks"},
        {pos: [6, 1, 12], state: "minecraft:mud_bricks"},
        {pos: [6, 1, 13], state: "minecraft:mud_brick_stairs{facing:north,half:top,shape:straight,waterlogged:false}"},
        {pos: [6, 1, 14], state: "minecraft:gravel"},
        {pos: [6, 1, 15], state: "minecraft:gravel"},
        {pos: [7, 1, 6], state: "minecraft:gravel"},
        {pos: [7, 1, 7], state: "minecraft:gravel"},
        {pos: [7, 1, 8], state: "minecraft:gravel"},
        {pos: [7, 1, 9], state: "minecraft:gravel"},
        {pos: [7, 1, 10], state: "minecraft:gravel"},
        {pos: [7, 1, 11], state: "minecraft:mud_bricks"},
        {pos: [7, 1, 12], state: "minecraft:mud_bricks"},
        {pos: [7, 1, 13], state: "minecraft:mud_brick_stairs{facing:north,half:top,shape:straight,waterlogged:false}"},
        {pos: [7, 1, 14], state: "minecraft:gravel"},
        {pos: [7, 1, 15], state: "minecraft:gravel"},
        {pos: [8, 1, 5], state: "minecraft:gravel"},
        {pos: [8, 1, 6], state: "minecraft:gravel"},
        {pos: [8, 1, 7], state: "minecraft:gravel"},
        {pos: [8, 1, 8], state: "minecraft:mud_bricks"},
        {pos: [8, 1, 9], state: "minecraft:gravel"},
        {pos: [8, 1, 10], state: "minecraft:gravel"},
        {pos: [8, 1, 11], state: "minecraft:mud_bricks"},
        {pos: [8, 1, 12], state: "minecraft:mud_bricks"},
        {pos: [8, 1, 13], state: "minecraft:mud_bricks"},
        {pos: [8, 1, 14], state: "minecraft:gravel"},
        {pos: [8, 1, 15], state: "minecraft:gravel"},
        {pos: [9, 1, 3], state: "minecraft:gravel"},
        {pos: [9, 1, 4], state: "minecraft:gravel"},
        {pos: [9, 1, 5], state: "minecraft:gravel"},
        {pos: [9, 1, 6], state: "minecraft:gravel"},
        {pos: [9, 1, 7], state: "minecraft:gravel"},
        {pos: [9, 1, 8], state: "minecraft:mud_bricks"},
        {pos: [9, 1, 9], state: "minecraft:gravel"},
        {pos: [9, 1, 10], state: "minecraft:gravel"},
        {pos: [9, 1, 11], state: "minecraft:gravel"},
        {pos: [9, 1, 12], state: "minecraft:mud_bricks"},
        {pos: [9, 1, 13], state: "minecraft:gravel"},
        {pos: [9, 1, 14], state: "minecraft:gravel"},
        {pos: [9, 1, 15], state: "minecraft:gravel"},
        {pos: [10, 1, 1], state: "minecraft:gravel"},
        {pos: [10, 1, 2], state: "minecraft:gravel"},
        {pos: [10, 1, 3], state: "minecraft:gravel"},
        {pos: [10, 1, 4], state: "minecraft:gravel"},
        {pos: [10, 1, 5], state: "minecraft:gravel"},
        {pos: [10, 1, 6], state: "minecraft:gravel"},
        {pos: [10, 1, 7], state: "minecraft:gravel"},
        {pos: [10, 1, 8], state: "minecraft:mud_bricks"},
        {pos: [10, 1, 9], state: "minecraft:mud_bricks"},
        {pos: [10, 1, 10], state: "minecraft:gravel"},
        {pos: [10, 1, 11], state: "minecraft:gravel"},
        {pos: [10, 1, 12], state: "minecraft:mud_bricks"},
        {pos: [10, 1, 13], state: "minecraft:mud_bricks"},
        {pos: [10, 1, 14], state: "minecraft:gravel"},
        {pos: [10, 1, 15], state: "minecraft:gravel"},
        {pos: [11, 1, 1], state: "minecraft:gravel"},
        {pos: [11, 1, 2], state: "minecraft:mud_bricks"},
        {pos: [11, 1, 3], state: "minecraft:mud_bricks"},
        {pos: [11, 1, 4], state: "minecraft:mud_bricks"},
        {pos: [11, 1, 5], state: "minecraft:mud_bricks"},
        {pos: [11, 1, 6], state: "minecraft:mud_bricks"},
        {pos: [11, 1, 7], state: "minecraft:mud_bricks"},
        {pos: [11, 1, 8], state: "minecraft:mud_bricks"},
        {pos: [11, 1, 9], state: "minecraft:mud_bricks"},
        {pos: [11, 1, 10], state: "minecraft:gravel"},
        {pos: [11, 1, 11], state: "minecraft:mud_brick_stairs{facing:south,half:top,shape:straight,waterlogged:false}"},
        {pos: [11, 1, 12], state: "minecraft:mud_bricks"},
        {pos: [11, 1, 13], state: "minecraft:gravel"},
        {pos: [11, 1, 14], state: "minecraft:gravel"},
        {pos: [11, 1, 15], state: "minecraft:gravel"},
        {pos: [12, 1, 0], state: "minecraft:gravel"},
        {pos: [12, 1, 1], state: "minecraft:gravel"},
        {pos: [12, 1, 2], state: "minecraft:mud_bricks"},
        {pos: [12, 1, 3], state: "minecraft:mud_bricks"},
        {pos: [12, 1, 4], state: "minecraft:mud_bricks"},
        {pos: [12, 1, 5], state: "minecraft:gravel"},
        {pos: [12, 1, 6], state: "minecraft:gravel"},
        {pos: [12, 1, 7], state: "minecraft:mud_bricks"},
        {pos: [12, 1, 8], state: "minecraft:mud_bricks"},
        {pos: [12, 1, 9], state: "minecraft:mud_bricks"},
        {pos: [12, 1, 10], state: "minecraft:gravel"},
        {pos: [12, 1, 11], state: "minecraft:mud_brick_stairs{facing:south,half:top,shape:straight,waterlogged:false}"},
        {pos: [12, 1, 12], state: "minecraft:mud_bricks"},
        {pos: [12, 1, 13], state: "minecraft:mud_bricks"},
        {pos: [12, 1, 14], state: "minecraft:gravel"},
        {pos: [12, 1, 15], state: "minecraft:gravel"},
        {pos: [13, 1, 0], state: "minecraft:gravel"},
        {pos: [13, 1, 1], state: "minecraft:gravel"},
        {pos: [13, 1, 2], state: "minecraft:mud_bricks"},
        {pos: [13, 1, 3], state: "minecraft:mud_bricks"},
        {pos: [13, 1, 4], state: "minecraft:gravel"},
        {pos: [13, 1, 5], state: "minecraft:yellow_glazed_terracotta{facing:south}"},
        {pos: [13, 1, 6], state: "minecraft:gravel"},
        {pos: [13, 1, 7], state: "minecraft:gravel"},
        {pos: [13, 1, 8], state: "minecraft:mud_brick_stairs{facing:west,half:top,shape:straight,waterlogged:false}"},
        {pos: [13, 1, 9], state: "minecraft:gravel"},
        {pos: [13, 1, 10], state: "minecraft:gravel"},
        {pos: [13, 1, 11], state: "minecraft:mud_brick_stairs{facing:south,half:top,shape:straight,waterlogged:false}"},
        {pos: [13, 1, 12], state: "minecraft:mud_bricks"},
        {pos: [13, 1, 13], state: "minecraft:mud_bricks"},
        {pos: [13, 1, 14], state: "minecraft:mud_bricks"},
        {pos: [14, 1, 0], state: "minecraft:gravel"},
        {pos: [14, 1, 1], state: "minecraft:gravel"},
        {pos: [14, 1, 2], state: "minecraft:mud_bricks"},
        {pos: [14, 1, 3], state: "minecraft:yellow_glazed_terracotta{facing:south}"},
        {pos: [14, 1, 4], state: "minecraft:gravel"},
        {pos: [14, 1, 5], state: "minecraft:gravel"},
        {pos: [14, 1, 6], state: "minecraft:gravel"},
        {pos: [14, 1, 7], state: "minecraft:gravel"},
        {pos: [14, 1, 8], state: "minecraft:gravel"},
        {pos: [14, 1, 9], state: "minecraft:gravel"},
        {pos: [14, 1, 10], state: "minecraft:gravel"},
        {pos: [14, 1, 11], state: "minecraft:gravel"},
        {pos: [14, 1, 12], state: "minecraft:mud_bricks"},
        {pos: [14, 1, 13], state: "minecraft:mud_bricks"},
        {pos: [14, 1, 14], state: "minecraft:gravel"},
        {pos: [15, 1, 0], state: "minecraft:gravel"},
        {pos: [15, 1, 1], state: "minecraft:gravel"},
        {pos: [15, 1, 2], state: "minecraft:mud_bricks"},
        {pos: [15, 1, 3], state: "minecraft:mud_bricks"},
        {pos: [15, 1, 4], state: "minecraft:mud_bricks"},
        {pos: [15, 1, 5], state: "minecraft:gravel"},
        {pos: [15, 1, 6], state: "minecraft:gravel"},
        {pos: [15, 1, 7], state: "minecraft:gravel"},
        {pos: [15, 1, 8], state: "minecraft:gravel"},
        {pos: [15, 1, 9], state: "minecraft:gravel"},
        {pos: [15, 1, 10], state: "minecraft:mud_bricks"},
        {pos: [15, 1, 11], state: "minecraft:mud_bricks"},
        {pos: [15, 1, 12], state: "minecraft:mud_bricks"},
        {pos: [15, 1, 13], state: "minecraft:gravel"},
        {pos: [15, 1, 14], state: "minecraft:gravel"},
        {pos: [16, 1, 1], state: "minecraft:gravel"},
        {pos: [16, 1, 2], state: "minecraft:mud_bricks"},
        {pos: [16, 1, 3], state: "minecraft:mud_bricks"},
        {pos: [16, 1, 4], state: "minecraft:mud_bricks"},
        {pos: [16, 1, 5], state: "minecraft:mud_bricks"},
        {pos: [16, 1, 6], state: "minecraft:gravel"},
        {pos: [16, 1, 7], state: "minecraft:gravel"},
        {pos: [16, 1, 8], state: "minecraft:gravel"},
        {pos: [16, 1, 9], state: "minecraft:mud_bricks"},
        {pos: [16, 1, 10], state: "minecraft:mud_bricks"},
        {pos: [16, 1, 11], state: "minecraft:mud_bricks"},
        {pos: [16, 1, 12], state: "minecraft:mud_bricks"},
        {pos: [16, 1, 13], state: "minecraft:gravel"},
        {pos: [16, 1, 14], state: "minecraft:gravel"},
        {pos: [17, 1, 1], state: "minecraft:gravel"},
        {pos: [17, 1, 2], state: "minecraft:mud_bricks"},
        {pos: [17, 1, 3], state: "minecraft:mud_bricks"},
        {pos: [17, 1, 4], state: "minecraft:mud_bricks"},
        {pos: [17, 1, 5], state: "minecraft:mud_bricks"},
        {pos: [17, 1, 6], state: "minecraft:mud_bricks"},
        {pos: [17, 1, 7], state: "minecraft:mud_bricks"},
        {pos: [17, 1, 8], state: "minecraft:mud_bricks"},
        {pos: [17, 1, 9], state: "minecraft:mud_bricks"},
        {pos: [17, 1, 10], state: "minecraft:mud_bricks"},
        {pos: [17, 1, 11], state: "minecraft:mud_bricks"},
        {pos: [17, 1, 12], state: "minecraft:mud_bricks"},
        {pos: [17, 1, 13], state: "minecraft:gravel"},
        {pos: [18, 1, 2], state: "minecraft:gravel"},
        {pos: [18, 1, 3], state: "minecraft:mud_bricks"},
        {pos: [18, 1, 4], state: "minecraft:mud_bricks"},
        {pos: [18, 1, 5], state: "minecraft:mud_bricks"},
        {pos: [18, 1, 6], state: "minecraft:mud_bricks"},
        {pos: [18, 1, 7], state: "minecraft:gravel"},
        {pos: [18, 1, 8], state: "minecraft:gravel"},
        {pos: [18, 1, 9], state: "minecraft:mud_bricks"},
        {pos: [18, 1, 10], state: "minecraft:mud_bricks"},
        {pos: [18, 1, 11], state: "minecraft:mud_bricks"},
        {pos: [18, 1, 12], state: "minecraft:gravel"},
        {pos: [19, 1, 3], state: "minecraft:gravel"},
        {pos: [19, 1, 4], state: "minecraft:mud_bricks"},
        {pos: [19, 1, 5], state: "minecraft:mud_bricks"},
        {pos: [19, 1, 6], state: "minecraft:gravel"},
        {pos: [19, 1, 7], state: "minecraft:gravel"},
        {pos: [19, 1, 8], state: "minecraft:gravel"},
        {pos: [19, 1, 9], state: "minecraft:gravel"},
        {pos: [19, 1, 10], state: "minecraft:gravel"},
        {pos: [20, 1, 6], state: "minecraft:gravel"},
        {pos: [20, 1, 7], state: "minecraft:gravel"},
        {pos: [20, 1, 8], state: "minecraft:gravel"},
        {pos: [20, 1, 9], state: "minecraft:gravel"},
        {pos: [0, 2, 9], state: "minecraft:gravel"},
        {pos: [0, 2, 10], state: "minecraft:gravel"},
        {pos: [0, 2, 11], state: "minecraft:gravel"},
        {pos: [0, 2, 12], state: "minecraft:gravel"},
        {pos: [0, 2, 13], state: "minecraft:gravel"},
        {pos: [1, 2, 8], state: "minecraft:gravel"},
        {pos: [1, 2, 9], state: "minecraft:mud_bricks"},
        {pos: [1, 2, 10], state: "minecraft:mud_bricks"},
        {pos: [1, 2, 11], state: "minecraft:gravel"},
        {pos: [1, 2, 12], state: "minecraft:mud_bricks"},
        {pos: [1, 2, 13], state: "minecraft:gravel"},
        {pos: [2, 2, 7], state: "minecraft:gravel"},
        {pos: [2, 2, 8], state: "minecraft:gravel"},
        {pos: [2, 2, 9], state: "minecraft:mud_bricks"},
        {pos: [2, 2, 10], state: "minecraft:mud_bricks"},
        {pos: [2, 2, 11], state: "minecraft:gravel"},
        {pos: [2, 2, 12], state: "minecraft:mud_bricks"},
        {pos: [2, 2, 13], state: "minecraft:gravel"},
        {pos: [2, 2, 14], state: "minecraft:gravel"},
        {pos: [3, 2, 7], state: "minecraft:gravel"},
        {pos: [3, 2, 8], state: "minecraft:gravel"},
        {pos: [3, 2, 9], state: "minecraft:mud_bricks"},
        {pos: [3, 2, 10], state: "minecraft:mud_bricks"},
        {pos: [3, 2, 11], state: "minecraft:mud_bricks"},
        {pos: [3, 2, 12], state: "minecraft:mud_bricks"},
        {pos: [3, 2, 13], state: "minecraft:gravel"},
        {pos: [3, 2, 14], state: "minecraft:gravel"},
        {pos: [3, 2, 15], state: "minecraft:gravel"},
        {pos: [4, 2, 7], state: "minecraft:gravel"},
        {pos: [4, 2, 8], state: "minecraft:mud_bricks"},
        {pos: [4, 2, 9], state: "minecraft:mud_bricks"},
        {pos: [4, 2, 10], state: "minecraft:mud_bricks"},
        {pos: [4, 2, 11], state: "minecraft:mud_bricks"},
        {pos: [4, 2, 12], state: "minecraft:mud_bricks"},
        {pos: [4, 2, 13], state: "minecraft:mud_bricks"},
        {pos: [4, 2, 14], state: "minecraft:gravel"},
        {pos: [4, 2, 15], state: "minecraft:gravel"},
        {pos: [5, 2, 7], state: "minecraft:gravel"},
        {pos: [5, 2, 8], state: "minecraft:gravel"},
        {pos: [5, 2, 9], state: "minecraft:gravel"},
        {pos: [5, 2, 10], state: "minecraft:mud_bricks"},
        {pos: [5, 2, 11], state: "minecraft:mud_bricks"},
        {pos: [5, 2, 12], state: "minecraft:mud_bricks"},
        {pos: [5, 2, 13], state: "minecraft:mud_bricks"},
        {pos: [5, 2, 14], state: "minecraft:gravel"},
        {pos: [6, 2, 7], state: "minecraft:gravel"},
        {pos: [6, 2, 8], state: "minecraft:mud_bricks"},
        {pos: [6, 2, 9], state: "minecraft:gravel"},
        {pos: [6, 2, 10], state: "minecraft:gravel"},
        {pos: [6, 2, 11], state: "minecraft:mud_bricks"},
        {pos: [6, 2, 12], state: "minecraft:mud_bricks"},
        {pos: [6, 2, 13], state: "minecraft:gravel"},
        {pos: [6, 2, 14], state: "minecraft:gravel"},
        {pos: [6, 2, 15], state: "minecraft:gravel"},
        {pos: [7, 2, 6], state: "minecraft:gravel"},
        {pos: [7, 2, 7], state: "minecraft:gravel"},
        {pos: [7, 2, 8], state: "minecraft:gravel"},
        {pos: [7, 2, 9], state: "minecraft:gravel"},
        {pos: [7, 2, 10], state: "minecraft:gravel"},
        {pos: [7, 2, 11], state: "minecraft:mud_bricks"},
        {pos: [7, 2, 12], state: "minecraft:mud_bricks"},
        {pos: [7, 2, 13], state: "minecraft:gravel"},
        {pos: [7, 2, 14], state: "minecraft:gravel"},
        {pos: [7, 2, 15], state: "minecraft:gravel"},
        {pos: [8, 2, 5], state: "minecraft:gravel"},
        {pos: [8, 2, 6], state: "minecraft:gravel"},
        {pos: [8, 2, 7], state: "minecraft:gravel"},
        {pos: [8, 2, 8], state: "minecraft:mud_bricks"},
        {pos: [8, 2, 9], state: "minecraft:gravel"},
        {pos: [8, 2, 10], state: "minecraft:gravel"},
        {pos: [8, 2, 11], state: "minecraft:gravel"},
        {pos: [8, 2, 12], state: "minecraft:mud_bricks"},
        {pos: [8, 2, 13], state: "minecraft:mud_bricks"},
        {pos: [8, 2, 14], state: "minecraft:gravel"},
        {pos: [8, 2, 15], state: "minecraft:gravel"},
        {pos: [9, 2, 4], state: "minecraft:gravel"},
        {pos: [9, 2, 5], state: "minecraft:gravel"},
        {pos: [9, 2, 6], state: "minecraft:gravel"},
        {pos: [9, 2, 7], state: "minecraft:gravel"},
        {pos: [9, 2, 8], state: "minecraft:gravel"},
        {pos: [9, 2, 9], state: "minecraft:gravel"},
        {pos: [9, 2, 10], state: "minecraft:gravel"},
        {pos: [9, 2, 11], state: "minecraft:gravel"},
        {pos: [9, 2, 12], state: "minecraft:mud_bricks"},
        {pos: [9, 2, 13], state: "minecraft:gravel"},
        {pos: [9, 2, 14], state: "minecraft:gravel"},
        {pos: [9, 2, 15], state: "minecraft:gravel"},
        {pos: [10, 2, 1], state: "minecraft:gravel"},
        {pos: [10, 2, 2], state: "minecraft:gravel"},
        {pos: [10, 2, 3], state: "minecraft:gravel"},
        {pos: [10, 2, 4], state: "minecraft:gravel"},
        {pos: [10, 2, 5], state: "minecraft:gravel"},
        {pos: [10, 2, 6], state: "minecraft:gravel"},
        {pos: [10, 2, 7], state: "minecraft:gravel"},
        {pos: [10, 2, 8], state: "minecraft:mud_bricks"},
        {pos: [10, 2, 9], state: "minecraft:gravel"},
        {pos: [10, 2, 10], state: "minecraft:gravel"},
        {pos: [10, 2, 11], state: "minecraft:gravel"},
        {pos: [10, 2, 12], state: "minecraft:mud_bricks"},
        {pos: [10, 2, 13], state: "minecraft:mud_bricks"},
        {pos: [10, 2, 14], state: "minecraft:gravel"},
        {pos: [10, 2, 15], state: "minecraft:gravel"},
        {pos: [11, 2, 1], state: "minecraft:gravel"},
        {pos: [11, 2, 2], state: "minecraft:gravel"},
        {pos: [11, 2, 3], state: "minecraft:mud_bricks"},
        {pos: [11, 2, 4], state: "minecraft:mud_bricks"},
        {pos: [11, 2, 5], state: "minecraft:gravel"},
        {pos: [11, 2, 6], state: "minecraft:mud_bricks"},
        {pos: [11, 2, 7], state: "minecraft:mud_bricks"},
        {pos: [11, 2, 8], state: "minecraft:mud_bricks"},
        {pos: [11, 2, 9], state: "minecraft:mud_bricks"},
        {pos: [11, 2, 10], state: "minecraft:gravel"},
        {pos: [11, 2, 11], state: "minecraft:gravel"},
        {pos: [11, 2, 12], state: "minecraft:mud_bricks"},
        {pos: [11, 2, 13], state: "minecraft:gravel"},
        {pos: [11, 2, 14], state: "minecraft:gravel"},
        {pos: [11, 2, 15], state: "minecraft:gravel"},
        {pos: [12, 2, 0], state: "minecraft:gravel"},
        {pos: [12, 2, 1], state: "minecraft:gravel"},
        {pos: [12, 2, 2], state: "minecraft:gravel"},
        {pos: [12, 2, 3], state: "minecraft:gravel"},
        {pos: [12, 2, 4], state: "minecraft:gravel"},
        {pos: [12, 2, 5], state: "minecraft:gravel"},
        {pos: [12, 2, 6], state: "minecraft:gravel"},
        {pos: [12, 2, 7], state: "minecraft:gravel"},
        {pos: [12, 2, 8], state: "minecraft:mud_bricks"},
        {pos: [12, 2, 9], state: "minecraft:mud_bricks"},
        {pos: [12, 2, 10], state: "minecraft:gravel"},
        {pos: [12, 2, 11], state: "minecraft:gravel"},
        {pos: [12, 2, 12], state: "minecraft:mud_bricks"},
        {pos: [12, 2, 13], state: "minecraft:gravel"},
        {pos: [12, 2, 14], state: "minecraft:gravel"},
        {pos: [13, 2, 0], state: "minecraft:gravel"},
        {pos: [13, 2, 1], state: "minecraft:gravel"},
        {pos: [13, 2, 2], state: "minecraft:mud_bricks"},
        {pos: [13, 2, 3], state: "minecraft:gravel"},
        {pos: [13, 2, 4], state: "minecraft:gravel"},
        {pos: [13, 2, 5], state: "minecraft:gravel"},
        {pos: [13, 2, 6], state: "minecraft:gravel"},
        {pos: [13, 2, 7], state: "minecraft:gravel"},
        {pos: [13, 2, 8], state: "minecraft:gravel"},
        {pos: [13, 2, 9], state: "minecraft:gravel"},
        {pos: [13, 2, 10], state: "minecraft:gravel"},
        {pos: [13, 2, 11], state: "minecraft:gravel"},
        {pos: [13, 2, 12], state: "minecraft:mud_bricks"},
        {pos: [13, 2, 13], state: "minecraft:mud_bricks"},
        {pos: [13, 2, 14], state: "minecraft:gravel"},
        {pos: [14, 2, 0], state: "minecraft:gravel"},
        {pos: [14, 2, 1], state: "minecraft:gravel"},
        {pos: [14, 2, 2], state: "minecraft:mud_bricks"},
        {pos: [14, 2, 3], state: "minecraft:gravel"},
        {pos: [14, 2, 4], state: "minecraft:gravel"},
        {pos: [14, 2, 5], state: "minecraft:gravel"},
        {pos: [14, 2, 6], state: "minecraft:gravel"},
        {pos: [14, 2, 7], state: "minecraft:gravel"},
        {pos: [14, 2, 8], state: "minecraft:gravel"},
        {pos: [14, 2, 9], state: "minecraft:gravel"},
        {pos: [14, 2, 10], state: "minecraft:gravel"},
        {pos: [14, 2, 11], state: "minecraft:gravel"},
        {pos: [14, 2, 12], state: "minecraft:mud_bricks"},
        {pos: [14, 2, 13], state: "minecraft:mud_bricks"},
        {pos: [14, 2, 14], state: "minecraft:gravel"},
        {pos: [15, 2, 0], state: "minecraft:gravel"},
        {pos: [15, 2, 1], state: "minecraft:gravel"},
        {pos: [15, 2, 2], state: "minecraft:mud_bricks"},
        {pos: [15, 2, 3], state: "minecraft:gravel"},
        {pos: [15, 2, 4], state: "minecraft:gravel"},
        {pos: [15, 2, 5], state: "minecraft:gravel"},
        {pos: [15, 2, 6], state: "minecraft:gravel"},
        {pos: [15, 2, 7], state: "minecraft:gravel"},
        {pos: [15, 2, 8], state: "minecraft:gravel"},
        {pos: [15, 2, 9], state: "minecraft:gravel"},
        {pos: [15, 2, 10], state: "minecraft:gravel"},
        {pos: [15, 2, 11], state: "minecraft:mud_bricks"},
        {pos: [15, 2, 12], state: "minecraft:mud_bricks"},
        {pos: [15, 2, 13], state: "minecraft:gravel"},
        {pos: [15, 2, 14], state: "minecraft:gravel"},
        {pos: [16, 2, 1], state: "minecraft:gravel"},
        {pos: [16, 2, 2], state: "minecraft:mud_bricks"},
        {pos: [16, 2, 3], state: "minecraft:mud_bricks"},
        {pos: [16, 2, 4], state: "minecraft:mud_bricks"},
        {pos: [16, 2, 5], state: "minecraft:mud_bricks"},
        {pos: [16, 2, 6], state: "minecraft:gravel"},
        {pos: [16, 2, 7], state: "minecraft:gravel"},
        {pos: [16, 2, 8], state: "minecraft:gravel"},
        {pos: [16, 2, 9], state: "minecraft:gravel"},
        {pos: [16, 2, 10], state: "minecraft:mud_bricks"},
        {pos: [16, 2, 11], state: "minecraft:mud_bricks"},
        {pos: [16, 2, 12], state: "minecraft:mud_bricks"},
        {pos: [16, 2, 13], state: "minecraft:gravel"},
        {pos: [16, 2, 14], state: "minecraft:gravel"},
        {pos: [17, 2, 1], state: "minecraft:gravel"},
        {pos: [17, 2, 2], state: "minecraft:mud_bricks"},
        {pos: [17, 2, 3], state: "minecraft:mud_bricks"},
        {pos: [17, 2, 4], state: "minecraft:mud_bricks"},
        {pos: [17, 2, 5], state: "minecraft:mud_bricks"},
        {pos: [17, 2, 6], state: "minecraft:mud_bricks"},
        {pos: [17, 2, 7], state: "minecraft:gravel"},
        {pos: [17, 2, 8], state: "minecraft:gravel"},
        {pos: [17, 2, 9], state: "minecraft:mud_bricks"},
        {pos: [17, 2, 10], state: "minecraft:mud_bricks"},
        {pos: [17, 2, 11], state: "minecraft:mud_bricks"},
        {pos: [17, 2, 12], state: "minecraft:mud_bricks"},
        {pos: [17, 2, 13], state: "minecraft:gravel"},
        {pos: [18, 2, 2], state: "minecraft:gravel"},
        {pos: [18, 2, 3], state: "minecraft:gravel"},
        {pos: [18, 2, 4], state: "minecraft:mud_bricks"},
        {pos: [18, 2, 5], state: "minecraft:mud_bricks"},
        {pos: [18, 2, 6], state: "minecraft:gravel"},
        {pos: [18, 2, 7], state: "minecraft:gravel"},
        {pos: [18, 2, 8], state: "minecraft:gravel"},
        {pos: [18, 2, 9], state: "minecraft:gravel"},
        {pos: [18, 2, 10], state: "minecraft:mud_bricks"},
        {pos: [18, 2, 11], state: "minecraft:mud_bricks"},
        {pos: [18, 2, 12], state: "minecraft:gravel"},
        {pos: [19, 2, 4], state: "minecraft:gravel"},
        {pos: [19, 2, 5], state: "minecraft:gravel"},
        {pos: [19, 2, 6], state: "minecraft:gravel"},
        {pos: [19, 2, 7], state: "minecraft:gravel"},
        {pos: [19, 2, 8], state: "minecraft:gravel"},
        {pos: [19, 2, 9], state: "minecraft:gravel"},
        {pos: [19, 2, 10], state: "minecraft:gravel"},
        {pos: [20, 2, 7], state: "minecraft:gravel"},
        {pos: [20, 2, 8], state: "minecraft:gravel"},
        {pos: [20, 2, 9], state: "minecraft:gravel"},
        {pos: [0, 3, 9], state: "minecraft:gravel"},
        {pos: [0, 3, 10], state: "minecraft:gravel"},
        {pos: [0, 3, 11], state: "minecraft:gravel"},
        {pos: [0, 3, 12], state: "minecraft:gravel"},
        {pos: [1, 3, 9], state: "minecraft:gravel"},
        {pos: [1, 3, 10], state: "minecraft:mud_bricks"},
        {pos: [1, 3, 11], state: "minecraft:mud_bricks"},
        {pos: [1, 3, 12], state: "minecraft:mud_bricks"},
        {pos: [1, 3, 13], state: "minecraft:gravel"},
        {pos: [2, 3, 8], state: "minecraft:gravel"},
        {pos: [2, 3, 9], state: "minecraft:gravel"},
        {pos: [2, 3, 10], state: "minecraft:mud_bricks"},
        {pos: [2, 3, 11], state: "minecraft:mud_bricks"},
        {pos: [2, 3, 12], state: "minecraft:mud_bricks"},
        {pos: [2, 3, 13], state: "minecraft:gravel"},
        {pos: [2, 3, 14], state: "minecraft:gravel"},
        {pos: [3, 3, 7], state: "minecraft:gravel"},
        {pos: [3, 3, 8], state: "minecraft:gravel"},
        {pos: [3, 3, 9], state: "minecraft:gravel"},
        {pos: [3, 3, 10], state: "minecraft:mud_bricks"},
        {pos: [3, 3, 11], state: "minecraft:mud_bricks"},
        {pos: [3, 3, 12], state: "minecraft:mud_bricks"},
        {pos: [3, 3, 13], state: "minecraft:gravel"},
        {pos: [3, 3, 14], state: "minecraft:gravel"},
        {pos: [4, 3, 7], state: "minecraft:gravel"},
        {pos: [4, 3, 8], state: "minecraft:mud_bricks"},
        {pos: [4, 3, 9], state: "minecraft:mud_bricks"},
        {pos: [4, 3, 10], state: "minecraft:mud_bricks"},
        {pos: [4, 3, 11], state: "minecraft:mud_bricks"},
        {pos: [4, 3, 12], state: "minecraft:mud_bricks"},
        {pos: [4, 3, 13], state: "minecraft:gravel"},
        {pos: [4, 3, 14], state: "minecraft:gravel"},
        {pos: [4, 3, 15], state: "minecraft:gravel"},
        {pos: [5, 3, 7], state: "minecraft:gravel"},
        {pos: [5, 3, 8], state: "minecraft:mud_bricks"},
        {pos: [5, 3, 9], state: "minecraft:gravel"},
        {pos: [5, 3, 10], state: "minecraft:mud_bricks"},
        {pos: [5, 3, 11], state: "minecraft:mud_bricks"},
        {pos: [5, 3, 12], state: "minecraft:mud_bricks"},
        {pos: [5, 3, 13], state: "minecraft:gravel"},
        {pos: [5, 3, 14], state: "minecraft:gravel"},
        {pos: [6, 3, 7], state: "minecraft:gravel"},
        {pos: [6, 3, 8], state: "minecraft:mud_bricks"},
        {pos: [6, 3, 9], state: "minecraft:gravel"},
        {pos: [6, 3, 10], state: "minecraft:mud_bricks"},
        {pos: [6, 3, 11], state: "minecraft:mud_bricks"},
        {pos: [6, 3, 12], state: "minecraft:mud_bricks"},
        {pos: [6, 3, 13], state: "minecraft:gravel"},
        {pos: [6, 3, 14], state: "minecraft:gravel"},
        {pos: [6, 3, 15], state: "minecraft:gravel"},
        {pos: [7, 3, 7], state: "minecraft:gravel"},
        {pos: [7, 3, 8], state: "minecraft:mud_bricks"},
        {pos: [7, 3, 9], state: "minecraft:gravel"},
        {pos: [7, 3, 10], state: "minecraft:gravel"},
        {pos: [7, 3, 11], state: "minecraft:mud_bricks"},
        {pos: [7, 3, 12], state: "minecraft:mud_bricks"},
        {pos: [7, 3, 13], state: "minecraft:gravel"},
        {pos: [7, 3, 14], state: "minecraft:gravel"},
        {pos: [7, 3, 15], state: "minecraft:gravel"},
        {pos: [8, 3, 5], state: "minecraft:gravel"},
        {pos: [8, 3, 6], state: "minecraft:gravel"},
        {pos: [8, 3, 7], state: "minecraft:gravel"},
        {pos: [8, 3, 8], state: "minecraft:mud_bricks"},
        {pos: [8, 3, 9], state: "minecraft:gravel"},
        {pos: [8, 3, 10], state: "minecraft:gravel"},
        {pos: [8, 3, 11], state: "minecraft:gravel"},
        {pos: [8, 3, 12], state: "minecraft:mud_bricks"},
        {pos: [8, 3, 13], state: "minecraft:mud_bricks"},
        {pos: [8, 3, 14], state: "minecraft:gravel"},
        {pos: [8, 3, 15], state: "minecraft:gravel"},
        {pos: [9, 3, 5], state: "minecraft:gravel"},
        {pos: [9, 3, 6], state: "minecraft:gravel"},
        {pos: [9, 3, 7], state: "minecraft:gravel"},
        {pos: [9, 3, 8], state: "minecraft:mud_bricks"},
        {pos: [9, 3, 9], state: "minecraft:gravel"},
        {pos: [9, 3, 10], state: "minecraft:gravel"},
        {pos: [9, 3, 11], state: "minecraft:gravel"},
        {pos: [9, 3, 12], state: "minecraft:mud_bricks"},
        {pos: [9, 3, 13], state: "minecraft:mud_bricks"},
        {pos: [9, 3, 14], state: "minecraft:gravel"},
        {pos: [9, 3, 15], state: "minecraft:gravel"},
        {pos: [10, 3, 1], state: "minecraft:gravel"},
        {pos: [10, 3, 2], state: "minecraft:gravel"},
        {pos: [10, 3, 3], state: "minecraft:gravel"},
        {pos: [10, 3, 4], state: "minecraft:gravel"},
        {pos: [10, 3, 5], state: "minecraft:gravel"},
        {pos: [10, 3, 6], state: "minecraft:gravel"},
        {pos: [10, 3, 7], state: "minecraft:gravel"},
        {pos: [10, 3, 8], state: "minecraft:mud_bricks"},
        {pos: [10, 3, 9], state: "minecraft:gravel"},
        {pos: [10, 3, 10], state: "minecraft:gravel"},
        {pos: [10, 3, 11], state: "minecraft:gravel"},
        {pos: [10, 3, 12], state: "minecraft:mud_bricks"},
        {pos: [10, 3, 13], state: "minecraft:mud_bricks"},
        {pos: [10, 3, 14], state: "minecraft:gravel"},
        {pos: [11, 3, 1], state: "minecraft:gravel"},
        {pos: [11, 3, 2], state: "minecraft:mud_bricks"},
        {pos: [11, 3, 3], state: "minecraft:mud_bricks"},
        {pos: [11, 3, 4], state: "minecraft:mud_bricks"},
        {pos: [11, 3, 5], state: "minecraft:mud_bricks"},
        {pos: [11, 3, 6], state: "minecraft:mud_bricks"},
        {pos: [11, 3, 7], state: "minecraft:mud_bricks"},
        {pos: [11, 3, 8], state: "minecraft:mud_bricks"},
        {pos: [11, 3, 9], state: "minecraft:mud_bricks"},
        {pos: [11, 3, 10], state: "minecraft:mud_bricks"},
        {pos: [11, 3, 11], state: "minecraft:gravel"},
        {pos: [11, 3, 12], state: "minecraft:mud_bricks"},
        {pos: [11, 3, 13], state: "minecraft:mud_bricks"},
        {pos: [11, 3, 14], state: "minecraft:gravel"},
        {pos: [12, 3, 0], state: "minecraft:gravel"},
        {pos: [12, 3, 1], state: "minecraft:gravel"},
        {pos: [12, 3, 2], state: "minecraft:mud_bricks"},
        {pos: [12, 3, 3], state: "minecraft:gravel"},
        {pos: [12, 3, 4], state: "minecraft:gravel"},
        {pos: [12, 3, 5], state: "minecraft:gravel"},
        {pos: [12, 3, 6], state: "minecraft:gravel"},
        {pos: [12, 3, 7], state: "minecraft:gravel"},
        {pos: [12, 3, 8], state: "minecraft:mud_bricks"},
        {pos: [12, 3, 9], state: "minecraft:mud_bricks"},
        {pos: [12, 3, 10], state: "minecraft:mud_bricks"},
        {pos: [12, 3, 11], state: "minecraft:gravel"},
        {pos: [12, 3, 12], state: "minecraft:mud_bricks"},
        {pos: [12, 3, 13], state: "minecraft:mud_bricks"},
        {pos: [12, 3, 14], state: "minecraft:gravel"},
        {pos: [13, 3, 0], state: "minecraft:gravel"},
        {pos: [13, 3, 1], state: "minecraft:gravel"},
        {pos: [13, 3, 2], state: "minecraft:mud_bricks"},
        {pos: [13, 3, 3], state: "minecraft:gravel"},
        {pos: [13, 3, 4], state: "minecraft:gravel"},
        {pos: [13, 3, 5], state: "minecraft:gravel"},
        {pos: [13, 3, 6], state: "minecraft:gravel"},
        {pos: [13, 3, 7], state: "minecraft:gravel"},
        {pos: [13, 3, 8], state: "minecraft:gravel"},
        {pos: [13, 3, 9], state: "minecraft:mud_bricks"},
        {pos: [13, 3, 10], state: "minecraft:gravel"},
        {pos: [13, 3, 11], state: "minecraft:gravel"},
        {pos: [13, 3, 12], state: "minecraft:mud_bricks"},
        {pos: [13, 3, 13], state: "minecraft:mud_bricks"},
        {pos: [13, 3, 14], state: "minecraft:gravel"},
        {pos: [14, 3, 0], state: "minecraft:gravel"},
        {pos: [14, 3, 1], state: "minecraft:gravel"},
        {pos: [14, 3, 2], state: "minecraft:mud_bricks"},
        {pos: [14, 3, 3], state: "minecraft:gravel"},
        {pos: [14, 3, 4], state: "minecraft:gravel"},
        {pos: [14, 3, 5], state: "minecraft:gravel"},
        {pos: [14, 3, 6], state: "minecraft:gravel"},
        {pos: [14, 3, 7], state: "minecraft:gravel"},
        {pos: [14, 3, 8], state: "minecraft:gravel"},
        {pos: [14, 3, 9], state: "minecraft:gravel"},
        {pos: [14, 3, 10], state: "minecraft:gravel"},
        {pos: [14, 3, 11], state: "minecraft:mud_bricks"},
        {pos: [14, 3, 12], state: "minecraft:mud_bricks"},
        {pos: [14, 3, 13], state: "minecraft:mud_bricks"},
        {pos: [14, 3, 14], state: "minecraft:gravel"},
        {pos: [15, 3, 1], state: "minecraft:gravel"},
        {pos: [15, 3, 2], state: "minecraft:mud_bricks"},
        {pos: [15, 3, 3], state: "minecraft:mud_bricks"},
        {pos: [15, 3, 4], state: "minecraft:gravel"},
        {pos: [15, 3, 5], state: "minecraft:gravel"},
        {pos: [15, 3, 6], state: "minecraft:gravel"},
        {pos: [15, 3, 7], state: "minecraft:gravel"},
        {pos: [15, 3, 8], state: "minecraft:gravel"},
        {pos: [15, 3, 9], state: "minecraft:gravel"},
        {pos: [15, 3, 10], state: "minecraft:mud_bricks"},
        {pos: [15, 3, 11], state: "minecraft:mud_bricks"},
        {pos: [15, 3, 12], state: "minecraft:mud_bricks"},
        {pos: [15, 3, 13], state: "minecraft:gravel"},
        {pos: [16, 3, 1], state: "minecraft:gravel"},
        {pos: [16, 3, 2], state: "minecraft:mud_bricks"},
        {pos: [16, 3, 3], state: "minecraft:mud_bricks"},
        {pos: [16, 3, 4], state: "minecraft:mud_bricks"},
        {pos: [16, 3, 5], state: "minecraft:mud_bricks"},
        {pos: [16, 3, 6], state: "minecraft:mud_bricks"},
        {pos: [16, 3, 7], state: "minecraft:gravel"},
        {pos: [16, 3, 8], state: "minecraft:gravel"},
        {pos: [16, 3, 9], state: "minecraft:gravel"},
        {pos: [16, 3, 10], state: "minecraft:mud_bricks"},
        {pos: [16, 3, 11], state: "minecraft:mud_bricks"},
        {pos: [16, 3, 12], state: "minecraft:mud_bricks"},
        {pos: [16, 3, 13], state: "minecraft:gravel"},
        {pos: [17, 3, 1], state: "minecraft:gravel"},
        {pos: [17, 3, 2], state: "minecraft:mud_bricks"},
        {pos: [17, 3, 3], state: "minecraft:mud_bricks"},
        {pos: [17, 3, 4], state: "minecraft:mud_bricks"},
        {pos: [17, 3, 5], state: "minecraft:mud_bricks"},
        {pos: [17, 3, 6], state: "minecraft:mud_bricks"},
        {pos: [17, 3, 7], state: "minecraft:gravel"},
        {pos: [17, 3, 8], state: "minecraft:gravel"},
        {pos: [17, 3, 9], state: "minecraft:mud_bricks"},
        {pos: [17, 3, 10], state: "minecraft:mud_bricks"},
        {pos: [17, 3, 11], state: "minecraft:mud_bricks"},
        {pos: [17, 3, 12], state: "minecraft:mud_bricks"},
        {pos: [17, 3, 13], state: "minecraft:gravel"},
        {pos: [18, 3, 2], state: "minecraft:gravel"},
        {pos: [18, 3, 3], state: "minecraft:gravel"},
        {pos: [18, 3, 4], state: "minecraft:gravel"},
        {pos: [18, 3, 5], state: "minecraft:gravel"},
        {pos: [18, 3, 6], state: "minecraft:gravel"},
        {pos: [18, 3, 7], state: "minecraft:gravel"},
        {pos: [18, 3, 8], state: "minecraft:gravel"},
        {pos: [18, 3, 9], state: "minecraft:gravel"},
        {pos: [18, 3, 10], state: "minecraft:gravel"},
        {pos: [18, 3, 11], state: "minecraft:gravel"},
        {pos: [18, 3, 12], state: "minecraft:gravel"},
        {pos: [19, 3, 5], state: "minecraft:gravel"},
        {pos: [19, 3, 6], state: "minecraft:gravel"},
        {pos: [19, 3, 7], state: "minecraft:gravel"},
        {pos: [19, 3, 8], state: "minecraft:gravel"},
        {pos: [19, 3, 9], state: "minecraft:gravel"},
        {pos: [0, 4, 11], state: "minecraft:gravel"},
        {pos: [0, 4, 12], state: "minecraft:gravel"},
        {pos: [1, 4, 10], state: "minecraft:gravel"},
        {pos: [1, 4, 11], state: "minecraft:mud_bricks"},
        {pos: [1, 4, 12], state: "minecraft:mud_bricks"},
        {pos: [1, 4, 13], state: "minecraft:gravel"},
        {pos: [2, 4, 9], state: "minecraft:gravel"},
        {pos: [2, 4, 10], state: "minecraft:gravel"},
        {pos: [2, 4, 11], state: "minecraft:mud_bricks"},
        {pos: [2, 4, 12], state: "minecraft:mud_bricks"},
        {pos: [2, 4, 13], state: "minecraft:gravel"},
        {pos: [3, 4, 8], state: "minecraft:gravel"},
        {pos: [3, 4, 9], state: "minecraft:gravel"},
        {pos: [3, 4, 10], state: "minecraft:gravel"},
        {pos: [3, 4, 11], state: "minecraft:mud_bricks"},
        {pos: [3, 4, 12], state: "minecraft:mud_bricks"},
        {pos: [3, 4, 13], state: "minecraft:gravel"},
        {pos: [4, 4, 7], state: "minecraft:gravel"},
        {pos: [4, 4, 8], state: "minecraft:mud_bricks"},
        {pos: [4, 4, 9], state: "minecraft:mud_bricks"},
        {pos: [4, 4, 10], state: "minecraft:mud_bricks"},
        {pos: [4, 4, 11], state: "minecraft:mud_bricks"},
        {pos: [4, 4, 12], state: "minecraft:mud_bricks"},
        {pos: [4, 4, 13], state: "minecraft:gravel"},
        {pos: [4, 4, 14], state: "minecraft:gravel"},
        {pos: [5, 4, 7], state: "minecraft:gravel"},
        {pos: [5, 4, 8], state: "minecraft:mud_bricks"},
        {pos: [5, 4, 9], state: "minecraft:mud_bricks"},
        {pos: [5, 4, 10], state: "minecraft:mud_bricks"},
        {pos: [5, 4, 11], state: "minecraft:mud_bricks"},
        {pos: [5, 4, 12], state: "minecraft:mud_bricks"},
        {pos: [5, 4, 13], state: "minecraft:gravel"},
        {pos: [5, 4, 14], state: "minecraft:gravel"},
        {pos: [6, 4, 8], state: "minecraft:mud_bricks"},
        {pos: [6, 4, 9], state: "minecraft:mud_bricks"},
        {pos: [6, 4, 10], state: "minecraft:mud_bricks"},
        {pos: [6, 4, 11], state: "minecraft:mud_bricks"},
        {pos: [6, 4, 12], state: "minecraft:mud_bricks"},
        {pos: [6, 4, 13], state: "minecraft:gravel"},
        {pos: [6, 4, 14], state: "minecraft:gravel"},
        {pos: [7, 4, 7], state: "minecraft:gravel"},
        {pos: [7, 4, 8], state: "minecraft:mud_bricks"},
        {pos: [7, 4, 9], state: "minecraft:mud_bricks"},
        {pos: [7, 4, 10], state: "minecraft:mud_bricks"},
        {pos: [7, 4, 11], state: "minecraft:mud_bricks"},
        {pos: [7, 4, 12], state: "minecraft:mud_bricks"},
        {pos: [7, 4, 13], state: "minecraft:gravel"},
        {pos: [7, 4, 14], state: "minecraft:gravel"},
        {pos: [8, 4, 7], state: "minecraft:gravel"},
        {pos: [8, 4, 8], state: "minecraft:mud_bricks"},
        {pos: [8, 4, 9], state: "minecraft:gravel"},
        {pos: [8, 4, 10], state: "minecraft:mud_bricks"},
        {pos: [8, 4, 11], state: "minecraft:mud_bricks"},
        {pos: [8, 4, 12], state: "minecraft:mud_bricks"},
        {pos: [8, 4, 13], state: "minecraft:gravel"},
        {pos: [8, 4, 14], state: "minecraft:gravel"},
        {pos: [9, 4, 6], state: "minecraft:gravel"},
        {pos: [9, 4, 7], state: "minecraft:gravel"},
        {pos: [9, 4, 8], state: "minecraft:mud_bricks"},
        {pos: [9, 4, 9], state: "minecraft:mud_bricks"},
        {pos: [9, 4, 10], state: "minecraft:gravel"},
        {pos: [9, 4, 11], state: "minecraft:mud_bricks"},
        {pos: [9, 4, 12], state: "minecraft:mud_bricks"},
        {pos: [9, 4, 13], state: "minecraft:gravel"},
        {pos: [10, 4, 2], state: "minecraft:gravel"},
        {pos: [10, 4, 3], state: "minecraft:gravel"},
        {pos: [10, 4, 4], state: "minecraft:gravel"},
        {pos: [10, 4, 5], state: "minecraft:gravel"},
        {pos: [10, 4, 6], state: "minecraft:gravel"},
        {pos: [10, 4, 7], state: "minecraft:gravel"},
        {pos: [10, 4, 8], state: "minecraft:mud_bricks"},
        {pos: [10, 4, 9], state: "minecraft:mud_bricks"},
        {pos: [10, 4, 10], state: "minecraft:mud_bricks"},
        {pos: [10, 4, 11], state: "minecraft:mud_bricks"},
        {pos: [10, 4, 12], state: "minecraft:mud_bricks"},
        {pos: [10, 4, 13], state: "minecraft:mud_bricks"},
        {pos: [11, 4, 2], state: "minecraft:mud_bricks"},
        {pos: [11, 4, 3], state: "minecraft:mud_bricks"},
        {pos: [11, 4, 4], state: "minecraft:mud_bricks"},
        {pos: [11, 4, 5], state: "minecraft:mud_bricks"},
        {pos: [11, 4, 6], state: "minecraft:mud_bricks"},
        {pos: [11, 4, 7], state: "minecraft:mud_bricks"},
        {pos: [11, 4, 8], state: "minecraft:mud_bricks"},
        {pos: [11, 4, 9], state: "minecraft:mud_bricks"},
        {pos: [11, 4, 10], state: "minecraft:mud_bricks"},
        {pos: [11, 4, 11], state: "minecraft:mud_bricks"},
        {pos: [11, 4, 12], state: "minecraft:mud_bricks"},
        {pos: [11, 4, 13], state: "minecraft:mud_bricks"},
        {pos: [11, 4, 14], state: "minecraft:gravel"},
        {pos: [12, 4, 1], state: "minecraft:gravel"},
        {pos: [12, 4, 2], state: "minecraft:mud_bricks"},
        {pos: [12, 4, 3], state: "minecraft:mud_bricks"},
        {pos: [12, 4, 4], state: "minecraft:mud_bricks"},
        {pos: [12, 4, 5], state: "minecraft:mud_bricks"},
        {pos: [12, 4, 6], state: "minecraft:mud_bricks"},
        {pos: [12, 4, 7], state: "minecraft:mud_bricks"},
        {pos: [12, 4, 8], state: "minecraft:mud_bricks"},
        {pos: [12, 4, 9], state: "minecraft:mud_bricks"},
        {pos: [12, 4, 10], state: "minecraft:mud_bricks"},
        {pos: [12, 4, 11], state: "minecraft:mud_bricks"},
        {pos: [12, 4, 12], state: "minecraft:mud_bricks"},
        {pos: [12, 4, 13], state: "minecraft:gravel"},
        {pos: [12, 4, 14], state: "minecraft:gravel"},
        {pos: [13, 4, 0], state: "minecraft:gravel"},
        {pos: [13, 4, 1], state: "minecraft:gravel"},
        {pos: [13, 4, 2], state: "minecraft:mud_bricks"},
        {pos: [13, 4, 3], state: "minecraft:gravel"},
        {pos: [13, 4, 4], state: "minecraft:mud_bricks"},
        {pos: [13, 4, 5], state: "minecraft:gravel"},
        {pos: [13, 4, 6], state: "minecraft:mud_bricks"},
        {pos: [13, 4, 7], state: "minecraft:mud_bricks"},
        {pos: [13, 4, 8], state: "minecraft:mud_bricks"},
        {pos: [13, 4, 9], state: "minecraft:mud_bricks"},
        {pos: [13, 4, 10], state: "minecraft:mud_bricks"},
        {pos: [13, 4, 11], state: "minecraft:mud_bricks"},
        {pos: [13, 4, 12], state: "minecraft:mud_bricks"},
        {pos: [13, 4, 13], state: "minecraft:gravel"},
        {pos: [14, 4, 0], state: "minecraft:gravel"},
        {pos: [14, 4, 1], state: "minecraft:gravel"},
        {pos: [14, 4, 2], state: "minecraft:mud_bricks"},
        {pos: [14, 4, 3], state: "minecraft:mud_bricks"},
        {pos: [14, 4, 4], state: "minecraft:mud_bricks"},
        {pos: [14, 4, 5], state: "minecraft:gravel"},
        {pos: [14, 4, 6], state: "minecraft:gravel"},
        {pos: [14, 4, 7], state: "minecraft:gravel"},
        {pos: [14, 4, 8], state: "minecraft:mud_bricks"},
        {pos: [14, 4, 9], state: "minecraft:mud_bricks"},
        {pos: [14, 4, 10], state: "minecraft:mud_bricks"},
        {pos: [14, 4, 11], state: "minecraft:mud_bricks"},
        {pos: [14, 4, 12], state: "minecraft:mud_bricks"},
        {pos: [14, 4, 13], state: "minecraft:gravel"},
        {pos: [15, 4, 1], state: "minecraft:gravel"},
        {pos: [15, 4, 2], state: "minecraft:mud_bricks"},
        {pos: [15, 4, 3], state: "minecraft:mud_bricks"},
        {pos: [15, 4, 4], state: "minecraft:mud_bricks"},
        {pos: [15, 4, 5], state: "minecraft:gravel"},
        {pos: [15, 4, 6], state: "minecraft:gravel"},
        {pos: [15, 4, 7], state: "minecraft:mud_bricks"},
        {pos: [15, 4, 8], state: "minecraft:mud_bricks"},
        {pos: [15, 4, 9], state: "minecraft:mud_bricks"},
        {pos: [15, 4, 10], state: "minecraft:mud_bricks"},
        {pos: [15, 4, 11], state: "minecraft:mud_bricks"},
        {pos: [15, 4, 12], state: "minecraft:mud_bricks"},
        {pos: [15, 4, 13], state: "minecraft:gravel"},
        {pos: [16, 4, 1], state: "minecraft:gravel"},
        {pos: [16, 4, 2], state: "minecraft:mud_bricks"},
        {pos: [16, 4, 3], state: "minecraft:mud_bricks"},
        {pos: [16, 4, 4], state: "minecraft:mud_bricks"},
        {pos: [16, 4, 5], state: "minecraft:mud_bricks"},
        {pos: [16, 4, 6], state: "minecraft:mud_bricks"},
        {pos: [16, 4, 7], state: "minecraft:mud_bricks"},
        {pos: [16, 4, 8], state: "minecraft:mud_bricks"},
        {pos: [16, 4, 9], state: "minecraft:mud_bricks"},
        {pos: [16, 4, 10], state: "minecraft:mud_bricks"},
        {pos: [16, 4, 11], state: "minecraft:mud_bricks"},
        {pos: [16, 4, 12], state: "minecraft:mud_bricks"},
        {pos: [16, 4, 13], state: "minecraft:gravel"},
        {pos: [17, 4, 1], state: "minecraft:gravel"},
        {pos: [17, 4, 2], state: "minecraft:mud_bricks"},
        {pos: [17, 4, 3], state: "minecraft:mud_bricks"},
        {pos: [17, 4, 4], state: "minecraft:mud_bricks"},
        {pos: [17, 4, 5], state: "minecraft:mud_bricks"},
        {pos: [17, 4, 6], state: "minecraft:mud_bricks"},
        {pos: [17, 4, 7], state: "minecraft:mud_bricks"},
        {pos: [17, 4, 8], state: "minecraft:gravel"},
        {pos: [17, 4, 9], state: "minecraft:mud_bricks"},
        {pos: [17, 4, 10], state: "minecraft:mud_bricks"},
        {pos: [17, 4, 11], state: "minecraft:mud_bricks"},
        {pos: [17, 4, 12], state: "minecraft:mud_bricks"},
        {pos: [17, 4, 13], state: "minecraft:gravel"},
        {pos: [18, 4, 4], state: "minecraft:gravel"},
        {pos: [18, 4, 5], state: "minecraft:gravel"},
        {pos: [18, 4, 6], state: "minecraft:gravel"},
        {pos: [18, 4, 7], state: "minecraft:gravel"},
        {pos: [18, 4, 8], state: "minecraft:gravel"},
        {pos: [18, 4, 9], state: "minecraft:gravel"},
        {pos: [18, 4, 10], state: "minecraft:gravel"},
        {pos: [18, 4, 11], state: "minecraft:gravel"},
        {pos: [18, 4, 12], state: "minecraft:gravel"},
        {pos: [19, 4, 7], state: "minecraft:gravel"},
        {pos: [19, 4, 8], state: "minecraft:gravel"},
        {pos: [0, 5, 12], state: "minecraft:gravel"},
        {pos: [1, 5, 11], state: "minecraft:gravel"},
        {pos: [1, 5, 12], state: "minecraft:mud_bricks"},
        {pos: [1, 5, 13], state: "minecraft:gravel"},
        {pos: [2, 5, 11], state: "minecraft:gravel"},
        {pos: [2, 5, 12], state: "minecraft:mud_bricks"},
        {pos: [2, 5, 13], state: "minecraft:gravel"},
        {pos: [3, 5, 8], state: "minecraft:gravel"},
        {pos: [3, 5, 9], state: "minecraft:gravel"},
        {pos: [3, 5, 11], state: "minecraft:gravel"},
        {pos: [3, 5, 12], state: "minecraft:mud_bricks"},
        {pos: [4, 5, 8], state: "minecraft:mud_bricks"},
        {pos: [4, 5, 9], state: "minecraft:gravel"},
        {pos: [4, 5, 10], state: "minecraft:gravel"},
        {pos: [4, 5, 11], state: "minecraft:gravel"},
        {pos: [4, 5, 12], state: "minecraft:mud_bricks"},
        {pos: [5, 5, 8], state: "minecraft:mud_bricks"},
        {pos: [5, 5, 9], state: "minecraft:gravel"},
        {pos: [5, 5, 10], state: "minecraft:gravel"},
        {pos: [5, 5, 11], state: "minecraft:gravel"},
        {pos: [5, 5, 12], state: "minecraft:mud_bricks"},
        {pos: [5, 5, 13], state: "minecraft:gravel"},
        {pos: [6, 5, 8], state: "minecraft:gravel"},
        {pos: [6, 5, 9], state: "minecraft:gravel"},
        {pos: [6, 5, 10], state: "minecraft:gravel"},
        {pos: [6, 5, 11], state: "minecraft:gravel"},
        {pos: [6, 5, 12], state: "minecraft:mud_bricks"},
        {pos: [6, 5, 13], state: "minecraft:gravel"},
        {pos: [7, 5, 9], state: "minecraft:gravel"},
        {pos: [7, 5, 10], state: "minecraft:gravel"},
        {pos: [7, 5, 11], state: "minecraft:gravel"},
        {pos: [7, 5, 12], state: "minecraft:mud_bricks"},
        {pos: [7, 5, 13], state: "minecraft:gravel"},
        {pos: [8, 5, 8], state: "minecraft:mud_bricks"},
        {pos: [8, 5, 9], state: "minecraft:gravel"},
        {pos: [8, 5, 10], state: "minecraft:gravel"},
        {pos: [8, 5, 11], state: "minecraft:gravel"},
        {pos: [8, 5, 12], state: "minecraft:gravel"},
        {pos: [9, 5, 7], state: "minecraft:gravel"},
        {pos: [9, 5, 8], state: "minecraft:mud_bricks"},
        {pos: [9, 5, 9], state: "minecraft:gravel"},
        {pos: [9, 5, 10], state: "minecraft:gravel"},
        {pos: [9, 5, 11], state: "minecraft:gravel"},
        {pos: [9, 5, 12], state: "minecraft:mud_bricks"},
        {pos: [10, 5, 2], state: "minecraft:gravel"},
        {pos: [10, 5, 4], state: "minecraft:gravel"},
        {pos: [10, 5, 5], state: "minecraft:gravel"},
        {pos: [10, 5, 6], state: "minecraft:gravel"},
        {pos: [10, 5, 7], state: "minecraft:gravel"},
        {pos: [10, 5, 8], state: "minecraft:mud_bricks"},
        {pos: [10, 5, 9], state: "minecraft:gravel"},
        {pos: [10, 5, 10], state: "minecraft:gravel"},
        {pos: [10, 5, 11], state: "minecraft:gravel"},
        {pos: [10, 5, 12], state: "minecraft:mud_bricks"},
        {pos: [10, 5, 13], state: "minecraft:gravel"},
        {pos: [11, 5, 2], state: "minecraft:mud_bricks"},
        {pos: [11, 5, 3], state: "minecraft:gravel"},
        {pos: [11, 5, 4], state: "minecraft:mud_bricks"},
        {pos: [11, 5, 5], state: "minecraft:gravel"},
        {pos: [11, 5, 6], state: "minecraft:mud_bricks"},
        {pos: [11, 5, 7], state: "minecraft:mud_bricks"},
        {pos: [11, 5, 8], state: "minecraft:mud_bricks"},
        {pos: [11, 5, 9], state: "minecraft:gravel"},
        {pos: [11, 5, 10], state: "minecraft:gravel"},
        {pos: [11, 5, 11], state: "minecraft:gravel"},
        {pos: [11, 5, 12], state: "minecraft:mud_bricks"},
        {pos: [11, 5, 13], state: "minecraft:gravel"},
        {pos: [12, 5, 2], state: "minecraft:mud_bricks"},
        {pos: [12, 5, 3], state: "minecraft:gravel"},
        {pos: [12, 5, 4], state: "minecraft:gravel"},
        {pos: [12, 5, 5], state: "minecraft:gravel"},
        {pos: [12, 5, 6], state: "minecraft:gravel"},
        {pos: [12, 5, 7], state: "minecraft:gravel"},
        {pos: [12, 5, 8], state: "minecraft:gravel"},
        {pos: [12, 5, 9], state: "minecraft:gravel"},
        {pos: [12, 5, 10], state: "minecraft:gravel"},
        {pos: [12, 5, 11], state: "minecraft:gravel"},
        {pos: [12, 5, 12], state: "minecraft:gravel"},
        {pos: [13, 5, 1], state: "minecraft:gravel"},
        {pos: [13, 5, 2], state: "minecraft:mud_bricks"},
        {pos: [13, 5, 3], state: "minecraft:gravel"},
        {pos: [13, 5, 4], state: "minecraft:gravel"},
        {pos: [13, 5, 5], state: "minecraft:gravel"},
        {pos: [13, 5, 6], state: "minecraft:gravel"},
        {pos: [13, 5, 7], state: "minecraft:gravel"},
        {pos: [13, 5, 8], state: "minecraft:gravel"},
        {pos: [13, 5, 9], state: "minecraft:gravel"},
        {pos: [13, 5, 10], state: "minecraft:gravel"},
        {pos: [13, 5, 11], state: "minecraft:gravel"},
        {pos: [13, 5, 12], state: "minecraft:mud_bricks"},
        {pos: [14, 5, 1], state: "minecraft:gravel"},
        {pos: [14, 5, 2], state: "minecraft:mud_bricks"},
        {pos: [14, 5, 3], state: "minecraft:gravel"},
        {pos: [14, 5, 4], state: "minecraft:gravel"},
        {pos: [14, 5, 5], state: "minecraft:gravel"},
        {pos: [14, 5, 6], state: "minecraft:gravel"},
        {pos: [14, 5, 7], state: "minecraft:gravel"},
        {pos: [14, 5, 8], state: "minecraft:gravel"},
        {pos: [14, 5, 9], state: "minecraft:gravel"},
        {pos: [14, 5, 10], state: "minecraft:gravel"},
        {pos: [14, 5, 11], state: "minecraft:gravel"},
        {pos: [14, 5, 12], state: "minecraft:mud_bricks"},
        {pos: [15, 5, 1], state: "minecraft:gravel"},
        {pos: [15, 5, 2], state: "minecraft:mud_bricks"},
        {pos: [15, 5, 3], state: "minecraft:gravel"},
        {pos: [15, 5, 4], state: "minecraft:gravel"},
        {pos: [15, 5, 5], state: "minecraft:gravel"},
        {pos: [15, 5, 6], state: "minecraft:gravel"},
        {pos: [15, 5, 7], state: "minecraft:gravel"},
        {pos: [15, 5, 8], state: "minecraft:gravel"},
        {pos: [15, 5, 9], state: "minecraft:gravel"},
        {pos: [15, 5, 10], state: "minecraft:gravel"},
        {pos: [15, 5, 11], state: "minecraft:gravel"},
        {pos: [15, 5, 12], state: "minecraft:mud_bricks"},
        {pos: [15, 5, 13], state: "minecraft:gravel"},
        {pos: [16, 5, 1], state: "minecraft:gravel"},
        {pos: [16, 5, 2], state: "minecraft:mud_bricks"},
        {pos: [16, 5, 3], state: "minecraft:gravel"},
        {pos: [16, 5, 4], state: "minecraft:gravel"},
        {pos: [16, 5, 5], state: "minecraft:gravel"},
        {pos: [16, 5, 6], state: "minecraft:gravel"},
        {pos: [16, 5, 7], state: "minecraft:gravel"},
        {pos: [16, 5, 8], state: "minecraft:gravel"},
        {pos: [16, 5, 9], state: "minecraft:gravel"},
        {pos: [16, 5, 10], state: "minecraft:gravel"},
        {pos: [16, 5, 11], state: "minecraft:gravel"},
        {pos: [16, 5, 12], state: "minecraft:mud_bricks"},
        {pos: [16, 5, 13], state: "minecraft:gravel"},
        {pos: [17, 5, 2], state: "minecraft:mud_bricks"},
        {pos: [17, 5, 3], state: "minecraft:mud_bricks"},
        {pos: [17, 5, 4], state: "minecraft:mud_bricks"},
        {pos: [17, 5, 5], state: "minecraft:gravel"},
        {pos: [17, 5, 7], state: "minecraft:mud_bricks"},
        {pos: [17, 5, 8], state: "minecraft:mud_bricks"},
        {pos: [17, 5, 9], state: "minecraft:gravel"},
        {pos: [17, 5, 10], state: "minecraft:mud_bricks"},
        {pos: [17, 5, 11], state: "minecraft:mud_bricks"},
        {pos: [17, 5, 12], state: "minecraft:mud_bricks"},
        {pos: [17, 5, 13], state: "minecraft:gravel"},
        {pos: [18, 5, 7], state: "minecraft:gravel"},
        {pos: [18, 5, 8], state: "minecraft:gravel"},
        {pos: [18, 5, 10], state: "minecraft:gravel"},
        {pos: [18, 5, 11], state: "minecraft:gravel"},
        {pos: [0, 6, 12], state: "minecraft:gravel"},
        {pos: [1, 6, 11], state: "minecraft:gravel"},
        {pos: [1, 6, 12], state: "minecraft:mud_bricks"},
        {pos: [2, 6, 11], state: "minecraft:gravel"},
        {pos: [2, 6, 12], state: "minecraft:mud_bricks"},
        {pos: [4, 6, 8], state: "minecraft:mud_bricks"},
        {pos: [4, 6, 9], state: "minecraft:gravel"},
        {pos: [5, 6, 8], state: "minecraft:mud_bricks"},
        {pos: [5, 6, 9], state: "minecraft:gravel"},
        {pos: [5, 6, 12], state: "minecraft:gravel"},
        {pos: [6, 6, 9], state: "minecraft:gravel"},
        {pos: [6, 6, 12], state: "minecraft:mud_bricks"},
        {pos: [9, 6, 11], state: "minecraft:gravel"},
        {pos: [9, 6, 12], state: "minecraft:gravel"},
        {pos: [10, 6, 8], state: "minecraft:mud_bricks"},
        {pos: [10, 6, 11], state: "minecraft:gravel"},
        {pos: [10, 6, 12], state: "minecraft:mud_bricks"},
        {pos: [11, 6, 2], state: "minecraft:mud_bricks"},
        {pos: [11, 6, 4], state: "minecraft:gravel"},
        {pos: [11, 6, 5], state: "minecraft:gravel"},
        {pos: [11, 6, 6], state: "minecraft:gravel"},
        {pos: [11, 6, 7], state: "minecraft:mud_bricks"},
        {pos: [11, 6, 8], state: "minecraft:mud_bricks"},
        {pos: [12, 6, 5], state: "minecraft:gravel"},
        {pos: [12, 6, 6], state: "minecraft:gravel"},
        {pos: [12, 6, 7], state: "minecraft:gravel"},
        {pos: [13, 6, 11], state: "minecraft:gravel"},
        {pos: [13, 6, 12], state: "minecraft:mud_bricks"},
        {pos: [14, 6, 10], state: "minecraft:gravel"},
        {pos: [14, 6, 11], state: "minecraft:gravel"},
        {pos: [14, 6, 12], state: "minecraft:mud_bricks"},
        {pos: [15, 6, 2], state: "minecraft:gravel"},
        {pos: [15, 6, 3], state: "minecraft:gravel"},
        {pos: [15, 6, 8], state: "minecraft:gravel"},
        {pos: [15, 6, 9], state: "minecraft:gravel"},
        {pos: [15, 6, 10], state: "minecraft:gravel"},
        {pos: [15, 6, 11], state: "minecraft:gravel"},
        {pos: [15, 6, 12], state: "minecraft:gravel"},
        {pos: [16, 6, 2], state: "minecraft:mud_bricks"},
        {pos: [16, 6, 3], state: "minecraft:gravel"},
        {pos: [16, 6, 4], state: "minecraft:gravel"},
        {pos: [16, 6, 7], state: "minecraft:gravel"},
        {pos: [16, 6, 8], state: "minecraft:gravel"},
        {pos: [16, 6, 9], state: "minecraft:gravel"},
        {pos: [16, 6, 10], state: "minecraft:gravel"},
        {pos: [16, 6, 11], state: "minecraft:gravel"},
        {pos: [17, 6, 2], state: "minecraft:mud_bricks"},
        {pos: [17, 6, 4], state: "minecraft:mud_bricks"},
        {pos: [17, 6, 7], state: "minecraft:mud_bricks"},
        {pos: [17, 6, 8], state: "minecraft:mud_bricks"},
        {pos: [17, 6, 10], state: "minecraft:gravel"},
        {pos: [17, 6, 11], state: "minecraft:gravel"}
    ],
    entities: [],
    palette: [
        "minecraft:mud_bricks",
        "minecraft:yellow_glazed_terracotta{facing:north}",
        "minecraft:yellow_glazed_terracotta{facing:west}",
        "minecraft:yellow_glazed_terracotta{facing:east}",
        "minecraft:yellow_glazed_terracotta{facing:south}",
        "minecraft:gravel",
        "minecraft:mud_brick_stairs{facing:north,half:top,shape:straight,waterlogged:false}",
        "minecraft:mud_brick_stairs{facing:south,half:top,shape:straight,waterlogged:false}",
        "minecraft:mud_brick_stairs{facing:west,half:top,shape:straight,waterlogged:false}"
    ],
    trailiertales_DataVersion: 2
}
